Workbook
Name Sectors: '[1]Sector Impact'!$K$4:$K$16
Name Sectors: 'Sector Impact'!$K$4:$K$16

Sheet OP
B2: 45039 | C2: Team 1 | E2: =Inputs!H3 -> #VALUE! | L2: NYSE | M2: SIC:
D3: COMPANY DESCRIPTION | H3: CEO & BOARD OF DIRECTORS
D4: {=_FV(Inputs!H3,"Description")} -> Advanced Micro Devices, Inc. is a global semiconductor company. The Company is focused on high-performance computing, graphics and visualization technologies. Its segments include Data Center, Client, Gaming and Embedded. The Data Center segment includes server central processing unit (CPUs), graphics processing units (GPUs), accelerated processing units (APUs), data processing units (DPUs), field programmable gate arrays (FPGAs), smart network interface cards (SmartNICs), artificial intelligence (AI) accelerators and adaptive system-on-chip (SoC) products for data centers. The Client segment includes CPUs, APUs, and chipsets for desktop, notebook and handheld personal computers. The Gaming segment includes discrete GPUs, semi-custom SoC products and development services. The Embedded segment includes embedded CPUs, GPUs, APUs, FPGAs, system on modules (SOMs), and adaptive SoC products. The Company's products include AMD Ryzen AI, Radeon PRO and AMD Advantage Premium. | H4: Name | I4: Gender | J4: Age | K4: Tenure | L4: Executive? | M4: Other roles
B17: USD MILLIONS
B18: COMPANY OVERVIEW
B19: Stock | D19: Liquidity and Solvency | F19: Segments | I19: Profitability (2022) | L19: Multiples
B20: Last Price | C20: {=_FV(E2,"Price")} -> 146.64 | D20: Total Assets | E20: =_xlfn.XLOOKUP(D20,'Fin. Data'!A:A,'Fin. Data'!B:B,,0) -> 67885 | F20: Regions | H20: % Sales | I20: Reporting Year | J20: 2023 | L20: Float
B21: Outstanding Shares | C21: {=_FV(E2,"Shares outstanding",TRUE)} -> 1616140000 | D21: Total Liabilities | E21: =_xlfn.XLOOKUP(D21,'Fin. Data'!A:A,'Fin. Data'!B:B,,0) -> 11993 | F21: =Segments!C5 -> United States | H21: =Segments!B5 -> 0.34554674 | I21: End of Year | J21: 45291 | L21: Insiders Own
B22: Market Cap. | C22: =C20*C21/1000000 -> 236990.77 | D22: Cash/Share | E22: =_xlfn.XLOOKUP("Cash & Eq.",'Fin. Data'!A:A,'Fin. Data'!B:B,,0)*1000000/C21 -> 2.4335763 | F22: =Segments!C6 -> Japan | H22: =Segments!B6 -> 0.20410053 | I22: EBITDA | K22: =_xlfn.XLOOKUP(I22,'Fin. Data'!A:A,'Fin. Data'!B:B,,0) -> 3846 | L22: b (Yahoo)
B23: +Total Debt | C23: ='Fin. Data'!B58 -> 2252 | D23: EBITDA/Net Financial Cost (NFC) | E23: =_xlfn.XLOOKUP("EBITDA",'Fin. Data'!A:A,'Fin. Data'!B:B,,0)/_xlfn.XLOOKUP("Net Financial Cost",'Fin. Data'!A:A,'Fin. Data'!B:B,,0) -> 38.848485 | F23: =Segments!C7 -> China (including Hong Kong) | H23: =Segments!B7 -> 0.15066138 | I23: Depreciation & Amortization | K23: =_xlfn.XLOOKUP(I23,'Fin. Data'!A:A,'Fin. Data'!B:B,,0) -> 3453 | L23: Score (S&P)
B24: -Cash | C24: ='Fin. Data'!B39 -> 3933 | D24: Debt/EBITDA | E24: =_xlfn.XLOOKUP("Total Debt",'Fin. Data'!A:A,'Fin. Data'!B:B,,0)/_xlfn.XLOOKUP("EBITDA",'Fin. Data'!A:A,'Fin. Data'!B:B,,0) -> 0.58554342 | F24: =Segments!C8 -> Singapore | H24: =Segments!B8 -> 0.098368607 | I24: EBIT | K24: =_xlfn.XLOOKUP(I24,'Fin. Data'!A:A,'Fin. Data'!B:B,,0) -> 393 | L24: Price/Book Value | M24: =IFERROR((C20*C21/(E20-E21))/1000000,"") -> 4.2401555
B25: =Enterprise Value | C25: =C22+C23-C24 -> 235309.77 | D25: "Others Assets"/Asset | E25: =_xlfn.XLOOKUP("Other Assets",'Fin. Data'!A:A,'Fin. Data'!B:B,,0)/_xlfn.XLOOKUP("Total Assets",'Fin. Data'!A:A,'Fin. Data'!B:B,,0) -> 0.76458717 | F25: =Segments!C9 -> Europe | H25: =Segments!B9 -> 0.089506173 | I25: Net Income | K25: =_xlfn.XLOOKUP(I25,'Fin. Data'!A:A,'Fin. Data'!B:B,,0) -> 854 | L25: NCF(3y avg)/Asset | M25: =IFERROR(K31/E20,"") -> 0.026201174
B26: Holdings (nac/int'l) | C26: - | D26: Debt/Assets | E26: =_xlfn.XLOOKUP(D26,'Fin. Data'!A:A,'Fin. Data'!B:B,,0) -> 0.03317375 | F26: Categories | H26: % Sales | I26: EPS | K26: =1000000*K25/C21 -> 0.52841957 | L26: Price/Net Inc. (3y avg) | M26: =IFERROR(C22/K30,"") -> 133.24069
B27: t liq. (Holdings/Vol.) | C27: - | D27: EBITDA Margin (average) | E27: =AVERAGE(_xlfn.XLOOKUP("EBITDA Margin",'Fin. Data'!A:A,'Fin. Data'!B:D,,0)) -> 0.21508695 | F27: =Segments!C19 -> Data Center | H27: =Segments!B19 -> 0.28641975 | I27: ROA | K27: =K25/E20 -> 0.012580099 | L27: EV/Asset | M27: =IFERROR(C25/E20,"") -> 3.4662999
B28: % Short | D28: Operating Margin (average) | E28: =AVERAGE(_xlfn.XLOOKUP("Operating Margin",'Fin. Data'!A:A,'Fin. Data'!B:D,,0)) -> 0.097596902 | F28: =Segments!C21 -> Gaming | H28: =Segments!B21 -> 0.27389771 | I28: ROIC | K28: =Peers!C18 -> 0.012515762 | L28: EV/Ebitda (3y average) | M28: =IFERROR(C25/K29,"") -> 53.041499
B29: Traffic ESG | D29: Net Income Margin (average) | E29: =AVERAGE(_xlfn.XLOOKUP("Net Income Margin",'Fin. Data'!A:A,'Fin. Data'!B:D,,0)) -> 0.095330047 | F29: =Segments!C22 -> Embedded | H29: =Segments!B22 -> 0.23461199 | I29: EBITDA (3y average) | K29: =AVERAGE(_xlfn.XLOOKUP("EBITDA",'Fin. Data'!A:A,'Fin. Data'!B:D,,0)) -> 4436.3333 | L29: Price/NCF (3y average) | M29: =IFERROR(C22/K31,"") -> 133.24069
B30: E | F30: =Segments!C20 -> Client | H30: =Segments!B20 -> 0.20507055 | I30: Net Income (3y average) | K30: =AVERAGE(_xlfn.XLOOKUP("Net Income",'Fin. Data'!A:A,'Fin. Data'!B:D,,0)) -> 1778.6667 | L30: Bonds 1,3,5a (USD) | M30: -
B31: S | D31: Net Financial Cost/Avg Net Debt | E31: =-_xlfn.XLOOKUP("Net Financial Cost",'Fin. Data'!A:A,'Fin. Data'!B:B,,0)/AVERAGE(_xlfn.XLOOKUP("Net Debt",'Fin. Data'!A:A,'Fin. Data'!B:D,,0)) -> 0.050864874 | F31: =Segments!#REF! -> #REF! | H31: =Segments!#REF! -> #REF! | I31: NCF (3y average) | K31: =AVERAGE(_xlfn.XLOOKUP("Net Income",'Fin. Data'!A:A,'Fin. Data'!B:D,,0)) -> 1778.6667 | L31: Div+Rep.(3y avg)/Price | M31: =-IFERROR(SUM(E52:E54)/(3*C22),"") -> 0.0090706768
B32: G | L32: Div. Yield | M32: =-IFERROR(L53/C22,"") -> 0
B33: INVESTMENT THESIS
B34: Pillars of Recommendation | H34: Recommendation | I34: Valuation Assumptions
B35: Pillar | C35: Explanation
B39: Risks of Investment | H39: Price Target | I39: Valuation
B40: Risk | C40: Explanation | H40: =DCF!D75 -> #DIV/0! | I40: Discount Rate | J40: =DCF!F50 -> 0 | L40: Price M. Upside | M40: =SARD!AJ14 -> #NUM!
I42: Upside | J42: =DCF!D74 -> #DIV/0! | L42: EV M. Upside | M42: =SARD!AM14 -> #NUM!
B44: FINANCIAL PERFORMANCE
B45: Year | C45: Net Sales | D45: Operating Margin | E45: Dividends + Share Buyback | F45: Net Cash Flow | G45: Debt/Assets | H45: Depreciation & Amortization | I45: Capex + Investments | J45: Cash Flow
B46: =B47-1 -> 2015 | C46: {=_xlfn.SORTBY(TRANSPOSE(_xlfn.XLOOKUP(C$45,'Fin. Data'!$A:$A,'Fin. Data'!$B:$J,,0)),$B$46:$B$54,-1)} -> 3991 | D46: {=_xlfn.SORTBY(TRANSPOSE(_xlfn.XLOOKUP(D$45,'Fin. Data'!$A:$A,'Fin. Data'!$B:$J,,0)),$B$46:$B$54,-1)} -> -0.12052117 | E46: {=_xlfn.SORTBY(TRANSPOSE(_xlfn.XLOOKUP(E$45,'Fin. Data'!$A:$A,'Fin. Data'!$B:$J,,0)),$B$46:$B$54,-1)} -> 0 | F46: =Inputs!J77 -> -20 | G46: {=_xlfn.SORTBY(TRANSPOSE(_xlfn.XLOOKUP(G$45,'Fin. Data'!$A:$A,'Fin. Data'!$B:$J,,0)),$B$46:$B$54,-1)} -> 0.72535668 | H46: {=_xlfn.SORTBY(TRANSPOSE(_xlfn.XLOOKUP(H$45,'Fin. Data'!$A:$A,'Fin. Data'!$B:$J,,0)),$B$46:$B$54,-1)} -> 167 | I46: {=_xlfn.SORTBY(TRANSPOSE(_xlfn.XLOOKUP(I$45,'Fin. Data'!$A:$A,'Fin. Data'!$B:$J,,0)),$B$46:$B$54,-1)} -> 147 | L46: =J20 -> 2023 | M46: =L46-1 -> 2022
B47: =B48-1 -> 2016 | C47: 4272 | D47: -0.10299625 | E47: 0 | F47: =Inputs!I77 -> 479 | G47: 0.43209877 | H47: 133 | I47: 265 | J47: Net Income | L47: =_xlfn.XLOOKUP($J47,'Fin. Data'!$A:$A,'Fin. Data'!B:B,,0) -> 854 | M47: =_xlfn.XLOOKUP($J47,'Fin. Data'!$A:$A,'Fin. Data'!C:C,,0) -> 1320 | N47: =(C47/C46)-1 -> 0.070408419 | O47: =(D47/D46)-1 -> -0.14540945
B48: =B49-1 -> 2017 | C48: 5253 | D48: 0.021892252 | E48: 0 | F48: =Inputs!H77 -> -75 | G48: 0.39273649 | H48: 144 | I48: -112 | J48: Operating CF | L48: =_xlfn.XLOOKUP($J48,'Fin. Data'!$A:$A,'Fin. Data'!B:B,,0) -> 1667 | M48: =_xlfn.XLOOKUP($J48,'Fin. Data'!$A:$A,'Fin. Data'!C:C,,0) -> 3565 | N48: =(C48/C47)-1 -> 0.22963483 | O48: =(D48/D47)-1 -> -1.2125539 | Q48: =F48/F47-1 -> -1.1565762 | R48: =H48/H47-1 -> 0.082706767 | S48: =I48/I47-1 -> -1.4226415
B49: =B50-1 -> 2018 | C49: 6475 | D49: 0.067799228 | E49: 0 | F49: =Inputs!G77 -> -108 | G49: 0.27436348 | H49: 170 | I49: -241 | J49: Investing CF | L49: =_xlfn.XLOOKUP($J49,'Fin. Data'!$A:$A,'Fin. Data'!B:B,,0) -> -1423 | M49: =_xlfn.XLOOKUP($J49,'Fin. Data'!$A:$A,'Fin. Data'!C:C,,0) -> 1999 | N49: =(C49/C48)-1 -> 0.23262897 | O49: =(D49/D48)-1 -> 2.0969508 | Q49: =F49/F48-1 -> 0.44 | R49: =H49/H48-1 -> 0.18055556 | S49: =I49/I48-1 -> 1.1517857
B50: =B51-1 -> 2019 | C50: 6731 | D50: 0.067597682 | E50: 0 | F50: =Inputs!F77 -> 387 | G50: 0.11363636 | H50: 222 | I50: -176 | J50: Net Capex | L50: =_xlfn.XLOOKUP($J50,'Fin. Data'!$A:$A,'Fin. Data'!B:B,,0) -> -546 | M50: =_xlfn.XLOOKUP($J50,'Fin. Data'!$A:$A,'Fin. Data'!C:C,,0) -> -450 | N50: =(C50/C49)-1 -> 0.03953668 | O50: =(D50/D49)-1 -> -0.0029726804 | Q50: =F50/F49-1 -> -4.5833333 | R50: =H50/H49-1 -> 0.30588235 | S50: =I50/I49-1 -> -0.26970954
B51: =B52-1 -> 2020 | C51: 9763 | D51: 0.13469221 | E51: 0 | F51: =Inputs!E77 -> 125 | G51: 0.059250167 | H51: 312 | I51: -952 | J51: Investments & Acquisitions | L51: =_xlfn.XLOOKUP($J51,'Fin. Data'!$A:$A,'Fin. Data'!B:B,,0) -> -866 | M51: =_xlfn.XLOOKUP($J51,'Fin. Data'!$A:$A,'Fin. Data'!C:C,,0) -> 2465 | N51: =(C51/C50)-1 -> 0.45045313 | O51: =(D51/D50)-1 -> 0.99255656 | Q51: =F51/F50-1 -> -0.67700258 | R51: =H51/H50-1 -> 0.40540541 | S51: =I51/I50-1 -> 4.4090909
B52: =B53-1 -> 2021 | C52: 16434 | D52: 0.22155288 | E52: -1762 | F52: =Inputs!D77 -> 940 | G52: 0.028102102 | H52: 407 | I52: -679 | J52: Financing CF | L52: =_xlfn.XLOOKUP($J52,'Fin. Data'!$A:$A,'Fin. Data'!B:B,,0) -> -1146 | M52: =_xlfn.XLOOKUP($J52,'Fin. Data'!$A:$A,'Fin. Data'!C:C,,0) -> -3264 | N52: =(C52/C51)-1 -> 0.68329407 | O52: =(D52/D51)-1 -> 0.6448827 | Q52: =F52/F51-1 -> 6.52 | R52: =H52/H51-1 -> 0.30448718 | S52: =I52/I51-1 -> -0.28676471
B53: =B54-1 -> 2022 | C53: 23601 | D53: 0.053557053 | E53: -3702 | F53: =Inputs!C$77 -> 2300 | G53: 0.042364605 | H53: 4174 | I53: 2015 | J53: Dividends | L53: =_xlfn.XLOOKUP($J53,'Fin. Data'!$A:$A,'Fin. Data'!B:B,,0) -> 0 | M53: =_xlfn.XLOOKUP($J53,'Fin. Data'!$A:$A,'Fin. Data'!C:C,,0) -> 0 | N53: =(C53/C52)-1 -> 0.43610807 | O53: =(D53/D52)-1 -> -0.75826515 | Q53: =F53/F52-1 -> 1.4468085 | R53: =H53/H52-1 -> 9.2555283 | S53: =I53/I52-1 -> -3.9675994
B54: =J20 -> 2023 | C54: 22680 | D54: 0.017680776 | E54: -985 | F54: =Inputs!B77 -> -902 | G54: 0.03317375 | H54: 3453 | I54: -1412 | J54: Share Buyback | L54: =_xlfn.XLOOKUP($J54,'Fin. Data'!$A:$A,'Fin. Data'!B:B,,0) -> -985 | M54: =_xlfn.XLOOKUP($J54,'Fin. Data'!$A:$A,'Fin. Data'!C:C,,0) -> -3702 | N54: =(C54/C53)-1 -> -0.03902377 | O54: =(D54/D53)-1 -> -0.66987026 | Q54: =F54/F53-1 -> -1.3921739 | R54: =H54/H53-1 -> -0.17273598 | S54: =I54/I53-1 -> -1.7007444
B55: Annual Growth Rate | C55: =IFERROR((C54/C46)^(1/8)-1,"") -> 0.242568 | D55: =IFERROR((D54/D46)^(1/8)-1,"") | F55: =IFERROR((F54/F46)^(1/8)-1,"") -> 0.60980054 | H55: =IFERROR((H54/H46)^(1/8)-1,"") -> 0.46027622 | J55: FX | L55: =_xlfn.XLOOKUP($J55,'Fin. Data'!$A:$A,'Fin. Data'!B:B,,0) -> 0 | M55: =_xlfn.XLOOKUP($J55,'Fin. Data'!$A:$A,'Fin. Data'!C:C,,0) -> 0 | N55: =(C55/C54)-1 -> -0.9999893 | O55: =(D55/D54)-1 -> #VALUE!
B56: Average Growth Rate | C56: =IFERROR(AVERAGE(N47:N54),"") -> 0.26288005 | D56: =IFERROR(AVERAGE(O47:O54),"") -> 0.11816483 | F56: =IFERROR(AVERAGE(Q47:Q54),"") -> 0.085388926 | H56: =IFERROR(AVERAGE(S47:S54),"") -> -0.29808328 | J56: Changes in Cash | L56: =L48-L49+L52-L53-L54 -> 2929 | M56: =M48-M49+M52-M53-M54 -> 2004
B57: CVAR | C57: =IFERROR(STDEV(C47:C54)/AVERAGE(C47:C54),"") -> 0.66372218 | D57: =IFERROR(STDEV(D46:D54)/AVERAGE(D46:D54),"") -> 2.6525091 | F57: =IFERROR(STDEV(F46:F54)/AVERAGE(F46:F54),"") -> 2.5577588 | H57: =IFERROR(STDEV(H46:H54)/AVERAGE(H46:H54),"") -> 1.5646555 | J57: Inventory/D Revenues | L57: =IFERROR(SUM(I51:I54)/(C54-C50),"") -> -0.064455452 | M57: =IFERROR((SUM(I51:I54)-SUM(H51:H54))/(C54-C50),"") -> -0.58774845
B58: Last Year | C58: =IFERROR(C54/C53-1,"") -> -0.03902377 | D58: =IFERROR(D54/D53-1,"") -> -0.66987026 | F58: =IFERROR(1-(F54/F53),"") -> 1.3921739 | H58: =IFERROR(1-(H54/H53),"") -> 0.17273598 | J58: t inversiones; t adq. neto dep. | L58: =IFERROR(L57/E27,"") -> -0.29967161 | M58: =IFERROR(M57/E27,"") -> -2.7326086
...

Sheet Segments
B2: ="Regions "&"("&OP!$J$20&")" -> Regions (2023) | Q2: Products
D3: Nominal value | K3: YoY Growth
B4: Weight | C4: Region | D4: =OP!J20 -> 2023 | E4: =D4-1 -> 2022 | F4: =E4-1 -> 2021 | G4: =F4-1 -> 2020 | H4: =G4-1 -> 2019 | I4: =H4-1 -> 2018 | K4: =OP!J20 -> 2023 | L4: =K4-1 -> 2022 | M4: =L4-1 -> 2021 | N4: =M4-1 -> 2020 | O4: =N4-1 -> 2019 | P4: =O4-1 -> 2018
B5: =IFERROR(D5/$D$14,"") -> 0.34554674 | C5: United States | D5: 7837 | E5: 8049 | F5: 4656 | G5: 2294 | H5: 1764 | I5: 1327 | K5: =(D5-E5)/E5 -> -0.026338676 | L5: =(E5-F5)/F5 -> 0.72873711 | M5: =(F5-G5)/G5 -> 1.0296425 | N5: =(G5-H5)/H5 -> 0.30045351 | O5: =(H5-I5)/I5 -> 0.32931424 | P5: -
B6: =IFERROR(D6/$D$14,"") -> 0.20410053 | C6: Japan | D6: 4629 | E6: 4177 | F6: 2381 | G6: 1033 | H6: 840 | I6: 1225 | K6: =(D6-E6)/E6 -> 0.10821164 | L6: =(E6-F6)/F6 -> 0.75430491 | M6: =(F6-G6)/G6 -> 1.3049371 | N6: =(G6-H6)/H6 -> 0.2297619 | O6: =(H6-I6)/I6 -> -0.31428571 | P6: -
B7: =IFERROR(D7/$D$14,"") -> 0.15066138 | C7: China (including Hong Kong) | D7: 3417 | E7: 5207 | F7: 4096 | G7: 2329 | H7: 1736 | I7: 1319 | K7: =(D7-E7)/E7 -> -0.343768 | L7: =(E7-F7)/F7 -> 0.27124023 | M7: =(F7-G7)/G7 -> 0.75869472 | N7: =(G7-H7)/H7 -> 0.34158986 | O7: =(H7-I7)/I7 -> 0.3161486 | P7: -
B8: =IFERROR(D8/$D$14,"") -> 0.098368607 | C8: Singapore | D8: 2231 | E8: 1380 | F8: 1389 | G8: 1096 | H8: 597 | I8: 728 | K8: =(D8-E8)/E8 -> 0.61666667 | L8: =(E8-F8)/F8 -> -0.0064794816 | M8: =(F8-G8)/G8 -> 0.26733577 | N8: =(G8-H8)/H8 -> 0.8358459 | O8: =(H8-I8)/I8 -> -0.17994505 | P8: -
B9: =IFERROR(D9/$D$14,"") -> 0.089506173 | C9: Europe | D9: 2030 | E9: 1773 | F9: 1249 | G9: 1108 | H9: 762 | I9: 470 | K9: =(D9-E9)/E9 -> 0.14495206 | L9: =(E9-F9)/F9 -> 0.41953563 | M9: =(F9-G9)/G9 -> 0.12725632 | N9: =(G9-H9)/H9 -> 0.45406824 | O9: =(H9-I9)/I9 -> 0.6212766 | P9: -
B10: =IFERROR(D10/$D$14,"") -> 0.08117284 | C10: Taiwan | D10: 1841 | E10: 2369 | F10: 2091 | G10: 1187 | H10: 719 | I10: 1197 | K10: =(D10-E10)/E10 -> -0.22287885 | L10: =(E10-F10)/F10 -> 0.13295074 | M10: =(F10-G10)/G10 -> 0.76158382 | N10: =(G10-H10)/H10 -> 0.65090403 | O10: =(H10-I10)/I10 -> -0.39933166 | P10: -
B11: =IFERROR(D11/$D$14,"") -> 0 | C11: Taiwan | K11: =(D11-E11)/E11 -> #DIV/0! | L11: =(E11-F11)/F11 -> #DIV/0! | M11: =(F11-G11)/G11 -> #DIV/0! | N11: =(G11-H11)/H11 -> #DIV/0! | O11: =(H11-I11)/I11 -> #DIV/0!
B12: =IFERROR(D12/$D$14,"") -> 0 | C12: Taiwan | K12: =(D12-E12)/E12 -> #DIV/0! | L12: =(E12-F12)/F12 -> #DIV/0! | M12: =(F12-G12)/G12 -> #DIV/0! | N12: =(G12-H12)/H12 -> #DIV/0! | O12: =(H12-I12)/I12 -> #DIV/0!
B13: =IFERROR(D13/$D$14,"") -> 0.030643739 | C13: Other countries | D13: 695 | E13: 646 | F13: 572 | G13: 716 | H13: 313 | I13: 0 | K13: =(D13-E13)/E13 -> 0.075851393 | L13: =(E13-F13)/F13 -> 0.12937063 | M13: =(F13-G13)/G13 -> -0.20111732 | N13: =(G13-H13)/H13 -> 1.2875399 | O13: =(H13-I13)/I13 -> #DIV/0! | P13: -
B14: =SUM(B5:B12) -> 0.96935626 | C14: TOTAL | D14: =SUM(D5:D13) -> 22680 | E14: =SUM(E5:E13) -> 23601 | F14: =SUM(F5:F13) -> 16434 | G14: =SUM(G5:G13) -> 9763 | H14: =SUM(H5:H13) -> 6731 | I14: =SUM(I5:I13) -> 6266 | K14: =(D14-E14)/E14 -> -0.03902377 | L14: =(E14-F14)/F14 -> 0.43610807 | M14: =(F14-G14)/G14 -> 0.68329407 | N14: =(G14-H14)/H14 -> 0.45045313 | O14: =(H14-I14)/I14 -> 0.074210022 | P14: -
B16: ="Categories "&"("&OP!$J$20&")" -> Categories (2023)
D17: Nominal value | K17: YoY Growth
B18: Weight | C18: Category | D18: =OP!J20 -> 2023 | E18: =D18-1 -> 2022 | F18: =E18-1 -> 2021 | G18: =F18-1 -> 2020 | H18: =G18-1 -> 2019 | I18: =H18-1 -> 2018 | K18: =OP!J20 -> 2023 | L18: =K18-1 -> 2022 | M18: =L18-1 -> 2021 | N18: =M18-1 -> 2020 | O18: =N18-1 -> 2019 | P18: =O18-1 -> 2018
B19: =IFERROR(D19/$D$23,"") -> 0.28641975 | C19: Data Center | D19: 6496 | E19: 6043 | F19: 3694 | K19: =(D19-E19)/E19 -> 0.074962767 | L19: =(E19-F19)/F19 -> 0.63589605 | M19: =(F19-G19)/G19 -> #DIV/0! | N19: =(G19-H19)/H19 -> #DIV/0! | O19: =(H19-I19)/I19 -> #DIV/0! | P19: -
B20: =IFERROR(D20/$D$23,"") -> 0.20507055 | C20: Client | D20: 4651 | E20: 6201 | F20: 6887 | K20: =(D20-E20)/E20 -> -0.24995968 | L20: =(E20-F20)/F20 -> -0.099607957 | M20: =(F20-G20)/G20 -> #DIV/0! | N20: =(G20-H20)/H20 -> #DIV/0! | O20: =(H20-I20)/I20 -> #DIV/0! | P20: -
B21: =IFERROR(D21/$D$23,"") -> 0.27389771 | C21: Gaming | D21: 6212 | E21: 6805 | F21: 5607 | K21: =(D21-E21)/E21 -> -0.087141807 | L21: =(E21-F21)/F21 -> 0.21366149 | M21: =(F21-G21)/G21 -> #DIV/0! | N21: =(G21-H21)/H21 -> #DIV/0! | O21: =(H21-I21)/I21 -> #DIV/0! | P21: -
B22: =IFERROR(D22/$D$23,"") -> 0.23461199 | C22: Embedded | D22: 5321 | E22: 4552 | F22: 246 | K22: =(D22-E22)/E22 -> 0.16893673 | L22: =(E22-F22)/F22 -> 17.504065 | M22: =(F22-G22)/G22 -> #DIV/0! | N22: =(G22-H22)/H22 -> #DIV/0! | O22: =(H22-I22)/I22 -> #DIV/0! | P22: -
B23: =SUM(B19:B22) -> 1 | C23: TOTAL | D23: =SUM(D19:D22) -> 22680 | E23: =SUM(E19:E22) -> 23601 | F23: =SUM(F19:F22) -> 16434 | G23: =SUM(G19:G22) -> 0 | H23: =SUM(H19:H22) -> 0 | I23: =SUM(I19:I22) -> 0 | K23: =(D23-E23)/E23 -> -0.03902377 | L23: =(E23-F23)/F23 -> 0.43610807 | M23: =(F23-G23)/G23 -> #DIV/0! | N23: =(G23-H23)/H23 -> #DIV/0! | O23: =(H23-I23)/I23 -> #DIV/0! | P23: -
B25: Categories | D25: Description | I25: Graphs
B26: Data Center | D26: Data Center segment offers products for data center market to address the computational, visual data processing and AI workload acceleration needs. Data centers require high performance, energy efficient, scalable and adaptable compute engines to meet the demand driven by the growing amount of data. Products are Server CPU, Data Center GPUs, FPGAs and Adaptive SoCs, and DPUs.
B27: Client
B28: Gaming
B29: Embedded
B32: Industry | J32: Graphs (Industry Forecasts)
B33: Drivers | D33: Description
B36: Sales forecast
B37: Source | D37: Market Growth CAGR | G37: Period
B41: Average | D41: =AVERAGE(D38:F40) -> #DIV/0!
B42: Company's Strategy / Extra Notes

Sheet Acuerdo
A1: Invertir
A2: NO invertir
A3: Mantener sin elevar posición
A4: Mantener (y seguir comprando)
A5: Liquidar
A6: PENDIENTE

Sheet Peers
B1: Peer Logo | C1: Peer Name | D1: Description
B2: #VALUE! | C2: nvidia | D2: {=_FV(C2,"Description")} -> #VALUE!
A3: Intel Corporation is an American multinational corporation and technology company headquartered in Santa Clara, California, and incorporated in Delaware.[3] Intel is one of the world's largest semiconductor chip manufacturers by revenue[4][5] and ranked in the Fortune 500 list of the largest United States corporations by revenue for nearly a decade, from 2007 to 2016 fiscal years, until it was removed from the ranking in 2018.[6] In 2020, it was reinstated and ranked 45th, being the 7th-largest technology company in the ranking. | B3: #VALUE! | C3: intel | D3: {=_FV(C3,"Description")} -> #VALUE!
A4: Intel supplies microprocessors for most manufacturers of computer systems, and is one of the developers of the x86 series of instruction sets found in most personal computers (PCs). It also manufactures chipsets, network interface controllers, flash memory, graphics processing units (GPUs), field-programmable gate arrays (FPGAs), and other devices related to communications and computing. Intel has a strong presence in the high-performance general-purpose and gaming PC market with its Intel Core line of CPUs, whose high-end models are among the fastest consumer CPUs, as well as its Intel Arc series of GPUs, and sponsors the Intel Extreme Masters, a series of international esports tournaments. The Open Source Technology Center at Intel hosts PowerTOP and LatencyTOP, and supports other open source projects such as Wayland, Mesa, Threading Building Blocks (TBB), and Xen.[7] | D4: {=_FV(C4,"Description")} -> #VALUE!
A5: Intel (Integrated electronics) was founded on July 18, 1968, by semiconductor pioneers Gordon Moore (of Moore's law) and Robert Noyce, along with investor Arthur Rock, and is associated with the executive leadership and vision of Andrew Grove.[ | D5: {=_FV(C5,"Description")} -> #VALUE!
D6: {=_FV(C6,"Description")} -> #VALUE!
B8: In Millions USD | C8: =OP!E2 -> #VALUE! | D8: =C2 -> nvidia | E8: =C3 -> intel | F8: =C4 -> 0 | G8: =C5 -> 0 | H8: =C6 -> 0 | I8: AVERAGE | J8: Deviation from Average
B9: Company Info | I9: =IFERROR(AVERAGE(C9:H9),"") | L9: TRAFFIC
B10: Market Cap | C10: {=_FV(C8,"Market cap",TRUE)/1000000} -> 236990.8 | D10: {=_FV(D8,"Market cap",TRUE)/1000000} -> #VALUE! | E10: =4228*E45 -> 212457 | F10: {=_FV(F8,"Market cap",TRUE)/1000000} -> #VALUE! | G10: {=_FV(G8,"Market cap",TRUE)/1000000} -> #VALUE! | H10: {=_FV(H8,"Market cap",TRUE)/1000000} -> #VALUE! | I10: =IFERROR(AVERAGE(C10:H10),"") | J10: =SQRT((C10-I10)^2) -> #VALUE! | M10: Best Value
B11: Net Sales (current) | C11: =C56 -> 22680 | D11: =D56 -> 60922 | E11: =E56 -> 54228 | F11: =F56 -> 0 | G11: =G56 -> 0 | H11: =H56 -> 0 | I11: =IFERROR(AVERAGE(C11:H11),"") -> 22971.667 | J11: =SQRT((C11-I11)^2) -> 291.66667
B12: Profitability | I12: =IFERROR(AVERAGE(C12:H12),"") | M12: Important Value
B13: Sales Growth (ttm) | C13: =C56/C55-1 -> -0.03902377 | D13: =D56/D55-1 -> 1.2585453 | E13: =E56/E55-1 -> -0.13997526 | F13: =F56/F55-1 -> #DIV/0! | G13: =G56/G55-1 -> #DIV/0! | H13: =H56/H55-1 -> #DIV/0! | I13: =IFERROR(AVERAGE(C13:H13),"") | J13: =SQRT((C13-I13)^2) -> #VALUE!
B14: Sales Growth (36m) | C14: =C56/C54-1 -> 1.3230564 | D14: =D56/D54-1 -> #DIV/0! | E14: =E56/E54-1 -> -0.30358175 | F14: =F56/F54-1 -> #DIV/0! | G14: =G56/G54-1 -> #DIV/0! | H14: =H56/H54-1 -> #DIV/0! | I14: =IFERROR(AVERAGE(C14:H14),"") | J14: =SQRT((C14-I14)^2) -> #VALUE! | M14: Worst Value
B15: Operating Margin | C15: =C59/C56 -> 0.017680776 | D15: =D59/D56 -> 0 | E15: =E59/E56 -> 0.0017149812 | F15: =F59/F56 -> #DIV/0! | G15: =G59/G56 -> #DIV/0! | H15: =H59/H56 -> #DIV/0! | I15: =IFERROR(AVERAGE(C15:H15),"") | J15: =SQRT((C15-I15)^2) -> #VALUE!
B16: Net Income Margin | C16: =C62/C56 -> 0.037654321 | D16: =D62/D56 -> 0 | E16: =E62/E56 -> 0.030888102 | F16: =F62/F56 -> #DIV/0! | G16: =G62/G56 -> #DIV/0! | H16: =H62/H56 -> #DIV/0! | I16: =IFERROR(AVERAGE(C16:H16),"") | J16: =SQRT((C16-I16)^2) -> #VALUE!
B17: Return on Equity (RoE) | C17: =C62/C74 -> 0.015279468 | D17: =D62/D74 -> #DIV/0! | E17: =E62/E74 -> 0.015863245 | F17: =F62/F74 -> #DIV/0! | G17: =G62/G74 -> #DIV/0! | H17: =H62/H74 -> #DIV/0! | I17: =IFERROR(AVERAGE(C17:H17),"") | J17: =SQRT((C17-I17)^2) -> #VALUE!
B18: Return on Invested Capital (ROIC) | C18: =(1+C61/(C59+C60))*C59/(C73+C74-C65) -> 0.012515762 | D18: =(1+D61/(D59+D60))*D59/(D73+D74-D65) -> #DIV/0! | E18: =(1+E61/(E59+E60))*E59/(E73+E74-E65) -> 0.0014251372 | F18: =(1+F61/(F59+F60))*F59/(F73+F74-F65) -> #DIV/0! | G18: =(1+G61/(G59+G60))*G59/(G73+G74-G65) -> #DIV/0! | H18: =(1+H61/(H59+H60))*H59/(H73+H74-H65) -> #DIV/0! | I18: =IFERROR(AVERAGE(C18:H18),"") | J18: =SQRT((C18-I18)^2) -> #VALUE!
B19: Solvency | I19: =IFERROR(AVERAGE(C19:H19),"")
B20: Debt/Assets | C20: =C73/C70 -> 0.03317375 | D20: =D73/D70 -> #DIV/0! | E20: =E73/E70 -> 0.25716702 | F20: =F73/F70 -> #DIV/0! | G20: =G73/G70 -> #DIV/0! | H20: =H73/H70 -> #DIV/0! | I20: =IFERROR(AVERAGE(C20:H20),"") | J20: =SQRT((C20-I20)^2) -> #VALUE!
B21: Net Debt/EBITDA | C21: =(C73-C65)/C58 -> -0.43707748 | D21: =(D73-D65)/D58 -> #DIV/0! | E21: =(E73-E65)/E58 -> 5.3132242 | F21: =(F73-F65)/F58 -> #DIV/0! | G21: =(G73-G65)/G58 -> #DIV/0! | H21: =(H73-H65)/H58 -> #DIV/0! | I21: =IFERROR(AVERAGE(C21:H21),"") | J21: =SQRT((C21-I21)^2) -> #VALUE!
B22: Interest Coverage Ratio | C22: =-C58/C60 -> -38.848485 | D22: =-D58/D60 -> #DIV/0! | E22: =-E58/E60 -> -12.623211 | F22: =-F58/F60 -> #DIV/0! | G22: =-G58/G60 -> #DIV/0! | H22: =-H58/H60 -> #DIV/0! | I22: =IFERROR(AVERAGE(C22:H22),"") | J22: =SQRT((C22-I22)^2) -> #VALUE!
B23: Liquidity
B24: Current Ratio | C24: =C68/C72 -> 2.5068022 | D24: =D68/D72 -> #DIV/0! | E24: =E68/E72 -> 1.5424019 | F24: =F68/F72 -> #DIV/0! | G24: =G68/G72 -> #DIV/0! | H24: =H68/H72 -> #DIV/0! | I24: =IFERROR(AVERAGE(C24:H24),"") | J24: =SQRT((C24-I24)^2) -> #VALUE!
B25: Quick Ratio | C25: =(C65+C66)/C72 -> 1.3916878 | D25: =(D65+D66)/D72 -> #DIV/0! | E25: =(E65+E66)/E72 -> 0.37361423 | F25: =(F65+F66)/F72 -> #DIV/0! | G25: =(G65+G66)/G72 -> #DIV/0! | H25: =(H65+H66)/H72 -> #DIV/0! | I25: =IFERROR(AVERAGE(C25:H25),"") | J25: =SQRT((C25-I25)^2) -> #VALUE!
B26: Activity | I26: =IFERROR(AVERAGE(C26:H26),"")
B27: Inventory Turnover | C27: =C57/C67 -> 2.8085498 | D27: =D57/D67 -> #DIV/0! | E27: =E57/E67 -> 2.922351 | F27: =F57/F67 -> #DIV/0! | G27: =G57/G67 -> #DIV/0! | H27: =H57/H67 -> #DIV/0! | I27: =IFERROR(AVERAGE(C27:H27),"") | J27: =SQRT((C27-I27)^2) -> #VALUE!
B28: Acc. Receivable Turnover | C28: =C56/C66 -> 4.21875 | D28: =D56/D66 -> #DIV/0! | E28: =E56/E66 -> 15.940035 | F28: =F56/F66 -> #DIV/0! | G28: =G56/G66 -> #DIV/0! | H28: =H56/H66 -> #DIV/0! | I28: =IFERROR(AVERAGE(C28:H28),"") | J28: =SQRT((C28-I28)^2) -> #VALUE!
A29: Price/Sales | B29: Payables Turnover | C29: =C57/C71 -> 5.0537634 | D29: =D57/D71 -> #DIV/0! | E29: =E57/E71 -> 3.7907438 | F29: =F57/F71 -> #DIV/0! | G29: =G57/G71 -> #DIV/0! | H29: =H57/H71 -> #DIV/0! | I29: =IFERROR(AVERAGE(C29:H29),"") | J29: =SQRT((C29-I29)^2) -> #VALUE!
B30: Fixed Asset Turnover | C30: =C56/C69 -> 14.273128 | D30: =D56/D69 -> #DIV/0! | E30: =E56/E69 -> 0.56109346 | F30: =F56/F69 -> #DIV/0! | G30: =G56/G69 -> #DIV/0! | H30: =H56/H69 -> #DIV/0! | I30: =IFERROR(AVERAGE(C30:H30),"") | J30: =SQRT((C30-I30)^2) -> #VALUE!
B31: Total Asset Turnover | C31: =C56/C70 -> 0.33409442 | D31: =D56/D70 -> #DIV/0! | E31: =E56/E70 -> 0.28306851 | F31: =F56/F70 -> #DIV/0! | G31: =G56/G70 -> #DIV/0! | H31: =H56/H70 -> #DIV/0! | I31: =IFERROR(AVERAGE(C31:H31),"") | J31: =SQRT((C31-I31)^2) -> #VALUE!
B32: Valuation | I32: =IFERROR(AVERAGE(C32:H32),"")
B33: Price/Earnings | C33: =C10/C62 -> 277.50679 | D33: =D10/D62 -> #VALUE! | E33: =E10/E62 -> 126.84 | F33: =F10/F62 -> #VALUE! | G33: =G10/G62 -> #VALUE! | H33: =H10/H62 -> #VALUE! | I33: =IFERROR(AVERAGE(C33:H33),"") | J33: =SQRT((C33-I33)^2) -> #VALUE!
B34: Price/Sales | C34: =C10/C56 -> 10.44933 | D34: =D10/D56 -> #VALUE! | E34: =E10/E56 -> 3.9178469 | F34: =F10/F56 -> #VALUE! | G34: =G10/G56 -> #VALUE! | H34: =H10/H56 -> #VALUE! | I34: =IFERROR(AVERAGE(C34:H34),"") | J34: =SQRT((C34-I34)^2) -> #VALUE!
B35: Price/Book | C35: =C10/C74 -> 4.240156 | D35: =D10/D74 -> #VALUE! | E35: =E10/E74 -> 2.0120939 | F35: =F10/F74 -> #VALUE! | G35: =G10/G74 -> #VALUE! | H35: =H10/H74 -> #VALUE! | I35: =IFERROR(AVERAGE(C35:H35),"") | J35: =SQRT((C35-I35)^2) -> #VALUE!
B36: EV/Sales | C36: =(C73+C10-C65)/C56 -> 10.375212 | D36: =(D73+D10-D65)/D56 -> #VALUE! | E36: =(E73+E10-E65)/E56 -> 4.6958029 | F36: =(F73+F10-F65)/F56 -> #VALUE! | G36: =(G73+G10-G65)/G56 -> #VALUE! | H36: =(H73+H10-H65)/H56 -> #VALUE! | I36: =IFERROR(AVERAGE(C36:H36),"") | J36: =SQRT((C36-I36)^2) -> #VALUE!
B37: EV/EBITDA | C37: =(C73+C10-C65)/C58 -> 61.182995 | D37: =(D73+D10-D65)/D58 -> #VALUE! | E37: =(E73+E10-E65)/E58 -> 32.071033 | F37: =(F73+F10-F65)/F58 -> #VALUE! | G37: =(G73+G10-G65)/G58 -> #VALUE! | H37: =(H73+H10-H65)/H58 -> #VALUE! | I37: =IFERROR(AVERAGE(C37:H37),"") | J37: =SQRT((C37-I37)^2) -> #VALUE!
B38: Stock Info | I38: =IFERROR(AVERAGE(C38:H38),"")
B39: Float | C39: =1.6/1.62 -> 0.98765432 | E39: =4.22/4.26 -> 0.99061033 | I39: =IFERROR(AVERAGE(C39:H39),"") -> 0.98913232 | J39: =SQRT((C39-I39)^2) -> 0.0014780038
B40: b (Yahoo) | C40: 1.63 | E40: 1.01 | I40: =IFERROR(AVERAGE(C40:H40),"") -> 1.32 | J40: =SQRT((C40-I40)^2) -> 0.31
B41: Dividend Yield (yahoo finance) | C41: =OP!M32 -> 0 | E41: 0.0211 | I41: =IFERROR(AVERAGE(C41:H41),"") -> 0.01055 | J41: =SQRT((C41-I41)^2) -> 0.01055
...

Sheet SARD
F1: Variables | K1: Rankings | P1: Difference | U1: Results | Y1: Additional Information | AD1: =B3 -> 0 | AE1: Selected Peers | AJ1: Price Multiples (TTM) | AM1: Enterprise Value Multiples (TTM)
B2: Ticker | C2: Company Name | D2: TRBC Industry | E2: Country | F2: ROE | G2: DEBT/EBIT | H2: Market Cap | I2: EPS Growth (2019-2023) (Refinitiv Smart Estimate) | J2: EBIT Margin | K2: ROE | L2: DEBT/EBIT | M2: Market Cap | N2: EPS Growth | O2: EBIT Margin | P2: ROE | Q2: DEBT/EBIT | R2: Market Cap | S2: EPS Growth | T2: EBIT Margin | U2: SARD Result | V2: SARD Peers | W2: SARD Peers adjusted Rank | Y2: Suitability | Z2: Relevant Information Missing | AA2: Author's Override | AB2: Observations | AE2: SARD Peers adjusted Rank | AF2: SARD Result | AG2: Ticker | AH2: Company Name | AI2: Country | AJ2: P / E | AK2: P / B | AL2: Price / Sales | AM2: EV / Sales | AN2: EV / EBITDA
A3: Benchmark | K3: =IFERROR(_xlfn.RANK.EQ(F3,F$3:F$61),"N/A") -> N/A | L3: =IFERROR(_xlfn.RANK.EQ(G3,G$3:G$61),"N/A") -> N/A | M3: =IFERROR(_xlfn.RANK.EQ(H3,H$3:H$61),"N/A") -> N/A | N3: =IFERROR(_xlfn.RANK.EQ(I3,I$3:I$61),"N/A") -> N/A | O3: =IFERROR(_xlfn.RANK.EQ(J3,J$3:J$61),"N/A") -> N/A | P3: - | Q3: - | R3: - | S3: - | T3: - | U3: - | V3: - | W3: - | Y3: =IF(OR(Z3="Y",AA3="Y"),"Not suitable","") -> Not suitable | Z3: =IF(N3="N/A","Y","") -> Y | AE3: {=_xlfn._xlws.SORT(_xlfn._xlws.FILTER(SARD!W3:W61,SARD!W3:W61<=SMALL(W3:W61,6)),,1)} -> #NUM! | AF3: =_xlfn.XLOOKUP($AE3,$W:$W,U:U,,0) -> #NUM! | AG3: =_xlfn.XLOOKUP($AE3,$W:$W,B:B,,0) -> #NUM! | AH3: =_xlfn.XLOOKUP($AE3,$W:$W,C:C,,0) -> #NUM! | AI3: =_xlfn.XLOOKUP($AE3,$W:$W,E:E,,0) -> #NUM!
A4: Comparison | K4: =IFERROR(_xlfn.RANK.EQ(F4,F$3:F$61),"N/A") -> N/A | L4: =IFERROR(_xlfn.RANK.EQ(G4,G$3:G$61),"N/A") -> N/A | M4: =IFERROR(_xlfn.RANK.EQ(H4,H$3:H$61),"N/A") -> N/A | N4: =IFERROR(_xlfn.RANK.EQ(I4,I$3:I$61),"N/A") -> N/A | O4: =IFERROR(_xlfn.RANK.EQ(J4,J$3:J$61),"N/A") -> N/A | P4: =IFERROR(ABS(K$3-K4),"N/A") -> N/A | Q4: =IFERROR(ABS(L$3-L4),"N/A") -> N/A | R4: =IFERROR(ABS(M$3-M4),"N/A") -> N/A | S4: =IFERROR(ABS(N$3-N4),"N/A") -> N/A | T4: =IFERROR(ABS(O$3-O4),"N/A") -> N/A | U4: =SUM(P4:T4) -> 0 | V4: =_xlfn.RANK.EQ(U4,$U$4:$U$61,1) -> 1 | W4: =IF(Y4="Not suitable","-",V4) -> - | Y4: =IF(OR(Z4="Y",AA4="Y"),"Not suitable","") -> Not suitable | Z4: =IF(N4="N/A","Y","") -> Y | AF4: =_xlfn.XLOOKUP($AE4,$W:$W,U:U,,0) -> Results | AG4: =_xlfn.XLOOKUP($AE4,$W:$W,B:B,,0) -> 0 | AH4: =_xlfn.XLOOKUP($AE4,$W:$W,C:C,,0) -> 0 | AI4: =_xlfn.XLOOKUP($AE4,$W:$W,E:E,,0) -> 0
K5: =IFERROR(_xlfn.RANK.EQ(F5,F$3:F$61),"N/A") -> N/A | L5: =IFERROR(_xlfn.RANK.EQ(G5,G$3:G$61),"N/A") -> N/A | M5: =IFERROR(_xlfn.RANK.EQ(H5,H$3:H$61),"N/A") -> N/A | N5: =IFERROR(_xlfn.RANK.EQ(I5,I$3:I$61),"N/A") -> N/A | O5: =IFERROR(_xlfn.RANK.EQ(J5,J$3:J$61),"N/A") -> N/A | P5: =IFERROR(ABS(K$3-K5),"N/A") -> N/A | Q5: =IFERROR(ABS(L$3-L5),"N/A") -> N/A | R5: =IFERROR(ABS(M$3-M5),"N/A") -> N/A | S5: =IFERROR(ABS(N$3-N5),"N/A") -> N/A | T5: =IFERROR(ABS(O$3-O5),"N/A") -> N/A | U5: =SUM(P5:T5) -> 0 | V5: =_xlfn.RANK.EQ(U5,$U$4:$U$61,1) -> 1 | W5: =IF(Y5="Not suitable","-",V5) -> - | Y5: =IF(OR(Z5="Y",AA5="Y"),"Not suitable","") -> Not suitable | Z5: =IF(N5="N/A","Y","") -> Y | AF5: =_xlfn.XLOOKUP($AE5,$W:$W,U:U,,0) -> Results | AG5: =_xlfn.XLOOKUP($AE5,$W:$W,B:B,,0) -> 0 | AH5: =_xlfn.XLOOKUP($AE5,$W:$W,C:C,,0) -> 0 | AI5: =_xlfn.XLOOKUP($AE5,$W:$W,E:E,,0) -> 0
K6: =IFERROR(_xlfn.RANK.EQ(F6,F$3:F$61),"N/A") -> N/A | L6: =IFERROR(_xlfn.RANK.EQ(G6,G$3:G$61),"N/A") -> N/A | M6: =IFERROR(_xlfn.RANK.EQ(H6,H$3:H$61),"N/A") -> N/A | N6: =IFERROR(_xlfn.RANK.EQ(I6,I$3:I$61),"N/A") -> N/A | O6: =IFERROR(_xlfn.RANK.EQ(J6,J$3:J$61),"N/A") -> N/A | P6: =IFERROR(ABS(K$3-K6),"N/A") -> N/A | Q6: =IFERROR(ABS(L$3-L6),"N/A") -> N/A | R6: =IFERROR(ABS(M$3-M6),"N/A") -> N/A | S6: =IFERROR(ABS(N$3-N6),"N/A") -> N/A | T6: =IFERROR(ABS(O$3-O6),"N/A") -> N/A | U6: =SUM(P6:T6) -> 0 | V6: =_xlfn.RANK.EQ(U6,$U$4:$U$61,1) -> 1 | W6: =IF(Y6="Not suitable","-",V6) -> - | Y6: =IF(OR(Z6="Y",AA6="Y"),"Not suitable","") -> Not suitable | Z6: =IF(N6="N/A","Y","") -> Y | AF6: =_xlfn.XLOOKUP($AE6,$W:$W,U:U,,0) -> Results | AG6: =_xlfn.XLOOKUP($AE6,$W:$W,B:B,,0) -> 0 | AH6: =_xlfn.XLOOKUP($AE6,$W:$W,C:C,,0) -> 0 | AI6: =_xlfn.XLOOKUP($AE6,$W:$W,E:E,,0) -> 0
K7: =IFERROR(_xlfn.RANK.EQ(F7,F$3:F$61),"N/A") -> N/A | L7: =IFERROR(_xlfn.RANK.EQ(G7,G$3:G$61),"N/A") -> N/A | M7: =IFERROR(_xlfn.RANK.EQ(H7,H$3:H$61),"N/A") -> N/A | N7: =IFERROR(_xlfn.RANK.EQ(I7,I$3:I$61),"N/A") -> N/A | O7: =IFERROR(_xlfn.RANK.EQ(J7,J$3:J$61),"N/A") -> N/A | P7: =IFERROR(ABS(K$3-K7),"N/A") -> N/A | Q7: =IFERROR(ABS(L$3-L7),"N/A") -> N/A | R7: =IFERROR(ABS(M$3-M7),"N/A") -> N/A | S7: =IFERROR(ABS(N$3-N7),"N/A") -> N/A | T7: =IFERROR(ABS(O$3-O7),"N/A") -> N/A | U7: =SUM(P7:T7) -> 0 | V7: =_xlfn.RANK.EQ(U7,$U$4:$U$61,1) -> 1 | W7: =IF(Y7="Not suitable","-",V7) -> - | Y7: =IF(OR(Z7="Y",AA7="Y"),"Not suitable","") -> Not suitable | Z7: =IF(N7="N/A","Y","") -> Y | AF7: =_xlfn.XLOOKUP($AE7,$W:$W,U:U,,0) -> Results | AG7: =_xlfn.XLOOKUP($AE7,$W:$W,B:B,,0) -> 0 | AH7: =_xlfn.XLOOKUP($AE7,$W:$W,C:C,,0) -> 0 | AI7: =_xlfn.XLOOKUP($AE7,$W:$W,E:E,,0) -> 0
K8: =IFERROR(_xlfn.RANK.EQ(F8,F$3:F$61),"N/A") -> N/A | L8: =IFERROR(_xlfn.RANK.EQ(G8,G$3:G$61),"N/A") -> N/A | M8: =IFERROR(_xlfn.RANK.EQ(H8,H$3:H$61),"N/A") -> N/A | N8: =IFERROR(_xlfn.RANK.EQ(I8,I$3:I$61),"N/A") -> N/A | O8: =IFERROR(_xlfn.RANK.EQ(J8,J$3:J$61),"N/A") -> N/A | P8: =IFERROR(ABS(K$3-K8),"N/A") -> N/A | Q8: =IFERROR(ABS(L$3-L8),"N/A") -> N/A | R8: =IFERROR(ABS(M$3-M8),"N/A") -> N/A | S8: =IFERROR(ABS(N$3-N8),"N/A") -> N/A | T8: =IFERROR(ABS(O$3-O8),"N/A") -> N/A | U8: =SUM(P8:T8) -> 0 | V8: =_xlfn.RANK.EQ(U8,$U$4:$U$61,1) -> 1 | W8: =IF(Y8="Not suitable","-",V8) -> - | Y8: =IF(OR(Z8="Y",AA8="Y"),"Not suitable","") -> Not suitable | Z8: =IF(N8="N/A","Y","") -> Y | AF8: =_xlfn.XLOOKUP($AE8,$W:$W,U:U,,0) -> Results | AG8: =_xlfn.XLOOKUP($AE8,$W:$W,B:B,,0) -> 0 | AH8: =_xlfn.XLOOKUP($AE8,$W:$W,C:C,,0) -> 0 | AI8: =_xlfn.XLOOKUP($AE8,$W:$W,E:E,,0) -> 0
K9: =IFERROR(_xlfn.RANK.EQ(F9,F$3:F$61),"N/A") -> N/A | L9: =IFERROR(_xlfn.RANK.EQ(G9,G$3:G$61),"N/A") -> N/A | M9: =IFERROR(_xlfn.RANK.EQ(H9,H$3:H$61),"N/A") -> N/A | N9: =IFERROR(_xlfn.RANK.EQ(I9,I$3:I$61),"N/A") -> N/A | O9: =IFERROR(_xlfn.RANK.EQ(J9,J$3:J$61),"N/A") -> N/A | P9: =IFERROR(ABS(K$3-K9),"N/A") -> N/A | Q9: =IFERROR(ABS(L$3-L9),"N/A") -> N/A | R9: =IFERROR(ABS(M$3-M9),"N/A") -> N/A | S9: =IFERROR(ABS(N$3-N9),"N/A") -> N/A | T9: =IFERROR(ABS(O$3-O9),"N/A") -> N/A | U9: =SUM(P9:T9) -> 0 | V9: =_xlfn.RANK.EQ(U9,$U$4:$U$61,1) -> 1 | W9: =IF(Y9="Not suitable","-",V9) -> - | Y9: =IF(OR(Z9="Y",AA9="Y"),"Not suitable","") -> Not suitable | Z9: =IF(N9="N/A","Y","") -> Y | AE9: Median | AJ9: =MEDIAN(AJ3:AJ8) -> #NUM! | AK9: =MEDIAN(AK3:AK8) -> #NUM! | AL9: =MEDIAN(AL3:AL8) -> #NUM! | AM9: =MEDIAN(AM3:AM8) -> #NUM! | AN9: =MEDIAN(AN3:AN8) -> #NUM!
K10: =IFERROR(_xlfn.RANK.EQ(F10,F$3:F$61),"N/A") -> N/A | L10: =IFERROR(_xlfn.RANK.EQ(G10,G$3:G$61),"N/A") -> N/A | M10: =IFERROR(_xlfn.RANK.EQ(H10,H$3:H$61),"N/A") -> N/A | N10: =IFERROR(_xlfn.RANK.EQ(I10,I$3:I$61),"N/A") -> N/A | O10: =IFERROR(_xlfn.RANK.EQ(J10,J$3:J$61),"N/A") -> N/A | P10: =IFERROR(ABS(K$3-K10),"N/A") -> N/A | Q10: =IFERROR(ABS(L$3-L10),"N/A") -> N/A | R10: =IFERROR(ABS(M$3-M10),"N/A") -> N/A | S10: =IFERROR(ABS(N$3-N10),"N/A") -> N/A | T10: =IFERROR(ABS(O$3-O10),"N/A") -> N/A | U10: =SUM(P10:T10) -> 0 | V10: =_xlfn.RANK.EQ(U10,$U$4:$U$61,1) -> 1 | W10: =IF(Y10="Not suitable","-",V10) -> - | Y10: =IF(OR(Z10="Y",AA10="Y"),"Not suitable","") -> Not suitable | Z10: =IF(N10="N/A","Y","") -> Y | AE10: Benchmark Data | AJ10: Price / Share
K11: =IFERROR(_xlfn.RANK.EQ(F11,F$3:F$61),"N/A") -> N/A | L11: =IFERROR(_xlfn.RANK.EQ(G11,G$3:G$61),"N/A") -> N/A | M11: =IFERROR(_xlfn.RANK.EQ(H11,H$3:H$61),"N/A") -> N/A | N11: =IFERROR(_xlfn.RANK.EQ(I11,I$3:I$61),"N/A") -> N/A | O11: =IFERROR(_xlfn.RANK.EQ(J11,J$3:J$61),"N/A") -> N/A | P11: =IFERROR(ABS(K$3-K11),"N/A") -> N/A | Q11: =IFERROR(ABS(L$3-L11),"N/A") -> N/A | R11: =IFERROR(ABS(M$3-M11),"N/A") -> N/A | S11: =IFERROR(ABS(N$3-N11),"N/A") -> N/A | T11: =IFERROR(ABS(O$3-O11),"N/A") -> N/A | U11: =SUM(P11:T11) -> 0 | V11: =_xlfn.RANK.EQ(U11,$U$4:$U$61,1) -> 1 | W11: =IF(Y11="Not suitable","-",V11) -> - | Y11: =IF(OR(Z11="Y",AA11="Y"),"Not suitable","") -> Not suitable | Z11: =IF(N11="N/A","Y","") -> Y | AE11: Benchmark | AF11: Multiplier | AG11: # Shares | AH11: -Debt + Cash | AJ11: P / E | AK11: P / B | AL11: Price / Sales | AM11: EV / Sales | AN11: EV / EBITDA
K12: =IFERROR(_xlfn.RANK.EQ(F12,F$3:F$61),"N/A") -> N/A | L12: =IFERROR(_xlfn.RANK.EQ(G12,G$3:G$61),"N/A") -> N/A | M12: =IFERROR(_xlfn.RANK.EQ(H12,H$3:H$61),"N/A") -> N/A | N12: =IFERROR(_xlfn.RANK.EQ(I12,I$3:I$61),"N/A") -> N/A | O12: =IFERROR(_xlfn.RANK.EQ(J12,J$3:J$61),"N/A") -> N/A | P12: =IFERROR(ABS(K$3-K12),"N/A") -> N/A | Q12: =IFERROR(ABS(L$3-L12),"N/A") -> N/A | R12: =IFERROR(ABS(M$3-M12),"N/A") -> N/A | S12: =IFERROR(ABS(N$3-N12),"N/A") -> N/A | T12: =IFERROR(ABS(O$3-O12),"N/A") -> N/A | U12: =SUM(P12:T12) -> 0 | V12: =_xlfn.RANK.EQ(U12,$U$4:$U$61,1) -> 1 | W12: =IF(Y12="Not suitable","-",V12) -> - | Y12: =IF(OR(Z12="Y",AA12="Y"),"Not suitable","") -> Not suitable | Z12: =IF(N12="N/A","Y","") -> Y | AE12: =C3 -> 0 | AF12: 1000000 | AG12: =OP!C21 -> 1616140000 | AH12: =-'Fin. Data'!B58*SARD!AF12+'Fin. Data'!B39*SARD!AF12 -> 1681000000 | AJ12: =AJ9*'Fin. Data'!B23*AF$12/AG$12 -> #NUM! | AK12: =AK9*'Fin. Data'!B64*AF$12/AG$12 -> #NUM! | AL12: =AL9*'Fin. Data'!B5*AF$12/AG$12 -> #NUM! | AM12: =(AM9*'Fin. Data'!B5*$AF12+$AH12)/$AG12 -> #NUM! | AN12: =(AN9*'Fin. Data'!B19*$AF12+$AH12)/$AG12 -> #NUM!
K13: =IFERROR(_xlfn.RANK.EQ(F13,F$3:F$61),"N/A") -> N/A | L13: =IFERROR(_xlfn.RANK.EQ(G13,G$3:G$61),"N/A") -> N/A | M13: =IFERROR(_xlfn.RANK.EQ(H13,H$3:H$61),"N/A") -> N/A | N13: =IFERROR(_xlfn.RANK.EQ(I13,I$3:I$61),"N/A") -> N/A | O13: =IFERROR(_xlfn.RANK.EQ(J13,J$3:J$61),"N/A") -> N/A | P13: =IFERROR(ABS(K$3-K13),"N/A") -> N/A | Q13: =IFERROR(ABS(L$3-L13),"N/A") -> N/A | R13: =IFERROR(ABS(M$3-M13),"N/A") -> N/A | S13: =IFERROR(ABS(N$3-N13),"N/A") -> N/A | T13: =IFERROR(ABS(O$3-O13),"N/A") -> N/A | U13: =SUM(P13:T13) -> 0 | V13: =_xlfn.RANK.EQ(U13,$U$4:$U$61,1) -> 1 | W13: =IF(Y13="Not suitable","-",V13) -> - | Y13: =IF(OR(Z13="Y",AA13="Y"),"Not suitable","") -> Not suitable | Z13: =IF(N13="N/A","Y","") -> Y | AE13: By Consolidated Average | AJ13: =AVERAGE(AJ12:AL12) -> #NUM! | AM13: =AVERAGE(AM12:AN12) -> #NUM!
K14: =IFERROR(_xlfn.RANK.EQ(F14,F$3:F$61),"N/A") -> N/A | L14: =IFERROR(_xlfn.RANK.EQ(G14,G$3:G$61),"N/A") -> N/A | M14: =IFERROR(_xlfn.RANK.EQ(H14,H$3:H$61),"N/A") -> N/A | N14: =IFERROR(_xlfn.RANK.EQ(I14,I$3:I$61),"N/A") -> N/A | O14: =IFERROR(_xlfn.RANK.EQ(J14,J$3:J$61),"N/A") -> N/A | P14: =IFERROR(ABS(K$3-K14),"N/A") -> N/A | Q14: =IFERROR(ABS(L$3-L14),"N/A") -> N/A | R14: =IFERROR(ABS(M$3-M14),"N/A") -> N/A | S14: =IFERROR(ABS(N$3-N14),"N/A") -> N/A | T14: =IFERROR(ABS(O$3-O14),"N/A") -> N/A | U14: =SUM(P14:T14) -> 0 | V14: =_xlfn.RANK.EQ(U14,$U$4:$U$61,1) -> 1 | W14: =IF(Y14="Not suitable","-",V14) -> - | Y14: =IF(OR(Z14="Y",AA14="Y"),"Not suitable","") -> Not suitable | Z14: =IF(N14="N/A","Y","") -> Y | AE14: Upside | AJ14: =AJ13/OP!C20-1 -> #NUM! | AM14: =AM13/OP!C20-1 -> #NUM!
K15: =IFERROR(_xlfn.RANK.EQ(F15,F$3:F$61),"N/A") -> N/A | L15: =IFERROR(_xlfn.RANK.EQ(G15,G$3:G$61),"N/A") -> N/A | M15: =IFERROR(_xlfn.RANK.EQ(H15,H$3:H$61),"N/A") -> N/A | N15: =IFERROR(_xlfn.RANK.EQ(I15,I$3:I$61),"N/A") -> N/A | O15: =IFERROR(_xlfn.RANK.EQ(J15,J$3:J$61),"N/A") -> N/A | P15: =IFERROR(ABS(K$3-K15),"N/A") -> N/A | Q15: =IFERROR(ABS(L$3-L15),"N/A") -> N/A | R15: =IFERROR(ABS(M$3-M15),"N/A") -> N/A | S15: =IFERROR(ABS(N$3-N15),"N/A") -> N/A | T15: =IFERROR(ABS(O$3-O15),"N/A") -> N/A | U15: =SUM(P15:T15) -> 0 | V15: =_xlfn.RANK.EQ(U15,$U$4:$U$61,1) -> 1 | W15: =IF(Y15="Not suitable","-",V15) -> - | Y15: =IF(OR(Z15="Y",AA15="Y"),"Not suitable","") -> Not suitable | Z15: =IF(N15="N/A","Y","") -> Y
K16: =IFERROR(_xlfn.RANK.EQ(F16,F$3:F$61),"N/A") -> N/A | L16: =IFERROR(_xlfn.RANK.EQ(G16,G$3:G$61),"N/A") -> N/A | M16: =IFERROR(_xlfn.RANK.EQ(H16,H$3:H$61),"N/A") -> N/A | N16: =IFERROR(_xlfn.RANK.EQ(I16,I$3:I$61),"N/A") -> N/A | O16: =IFERROR(_xlfn.RANK.EQ(J16,J$3:J$61),"N/A") -> N/A | P16: =IFERROR(ABS(K$3-K16),"N/A") -> N/A | Q16: =IFERROR(ABS(L$3-L16),"N/A") -> N/A | R16: =IFERROR(ABS(M$3-M16),"N/A") -> N/A | S16: =IFERROR(ABS(N$3-N16),"N/A") -> N/A | T16: =IFERROR(ABS(O$3-O16),"N/A") -> N/A | U16: =SUM(P16:T16) -> 0 | V16: =_xlfn.RANK.EQ(U16,$U$4:$U$61,1) -> 1 | W16: =IF(Y16="Not suitable","-",V16) -> - | Y16: =IF(OR(Z16="Y",AA16="Y"),"Not suitable","") -> Not suitable | Z16: =IF(N16="N/A","Y","") -> Y
K17: =IFERROR(_xlfn.RANK.EQ(F17,F$3:F$61),"N/A") -> N/A | L17: =IFERROR(_xlfn.RANK.EQ(G17,G$3:G$61),"N/A") -> N/A | M17: =IFERROR(_xlfn.RANK.EQ(H17,H$3:H$61),"N/A") -> N/A | N17: =IFERROR(_xlfn.RANK.EQ(I17,I$3:I$61),"N/A") -> N/A | O17: =IFERROR(_xlfn.RANK.EQ(J17,J$3:J$61),"N/A") -> N/A | P17: =IFERROR(ABS(K$3-K17),"N/A") -> N/A | Q17: =IFERROR(ABS(L$3-L17),"N/A") -> N/A | R17: =IFERROR(ABS(M$3-M17),"N/A") -> N/A | S17: =IFERROR(ABS(N$3-N17),"N/A") -> N/A | T17: =IFERROR(ABS(O$3-O17),"N/A") -> N/A | U17: =SUM(P17:T17) -> 0 | V17: =_xlfn.RANK.EQ(U17,$U$4:$U$61,1) -> 1 | W17: =IF(Y17="Not suitable","-",V17) -> - | Y17: =IF(OR(Z17="Y",AA17="Y"),"Not suitable","") -> Not suitable | Z17: =IF(N17="N/A","Y","") -> Y
K18: =IFERROR(_xlfn.RANK.EQ(F18,F$3:F$61),"N/A") -> N/A | L18: =IFERROR(_xlfn.RANK.EQ(G18,G$3:G$61),"N/A") -> N/A | M18: =IFERROR(_xlfn.RANK.EQ(H18,H$3:H$61),"N/A") -> N/A | N18: =IFERROR(_xlfn.RANK.EQ(I18,I$3:I$61),"N/A") -> N/A | O18: =IFERROR(_xlfn.RANK.EQ(J18,J$3:J$61),"N/A") -> N/A | P18: =IFERROR(ABS(K$3-K18),"N/A") -> N/A | Q18: =IFERROR(ABS(L$3-L18),"N/A") -> N/A | R18: =IFERROR(ABS(M$3-M18),"N/A") -> N/A | S18: =IFERROR(ABS(N$3-N18),"N/A") -> N/A | T18: =IFERROR(ABS(O$3-O18),"N/A") -> N/A | U18: =SUM(P18:T18) -> 0 | V18: =_xlfn.RANK.EQ(U18,$U$4:$U$61,1) -> 1 | W18: =IF(Y18="Not suitable","-",V18) -> - | Y18: =IF(OR(Z18="Y",AA18="Y"),"Not suitable","") -> Not suitable | Z18: =IF(N18="N/A","Y","") -> Y
K19: =IFERROR(_xlfn.RANK.EQ(F19,F$3:F$61),"N/A") -> N/A | L19: =IFERROR(_xlfn.RANK.EQ(G19,G$3:G$61),"N/A") -> N/A | M19: =IFERROR(_xlfn.RANK.EQ(H19,H$3:H$61),"N/A") -> N/A | N19: =IFERROR(_xlfn.RANK.EQ(I19,I$3:I$61),"N/A") -> N/A | O19: =IFERROR(_xlfn.RANK.EQ(J19,J$3:J$61),"N/A") -> N/A | P19: =IFERROR(ABS(K$3-K19),"N/A") -> N/A | Q19: =IFERROR(ABS(L$3-L19),"N/A") -> N/A | R19: =IFERROR(ABS(M$3-M19),"N/A") -> N/A | S19: =IFERROR(ABS(N$3-N19),"N/A") -> N/A | T19: =IFERROR(ABS(O$3-O19),"N/A") -> N/A | U19: =SUM(P19:T19) -> 0 | V19: =_xlfn.RANK.EQ(U19,$U$4:$U$61,1) -> 1 | W19: =IF(Y19="Not suitable","-",V19) -> - | Y19: =IF(OR(Z19="Y",AA19="Y"),"Not suitable","") -> Not suitable | Z19: =IF(N19="N/A","Y","") -> Y
K20: =IFERROR(_xlfn.RANK.EQ(F20,F$3:F$61),"N/A") -> N/A | L20: =IFERROR(_xlfn.RANK.EQ(G20,G$3:G$61),"N/A") -> N/A | M20: =IFERROR(_xlfn.RANK.EQ(H20,H$3:H$61),"N/A") -> N/A | N20: =IFERROR(_xlfn.RANK.EQ(I20,I$3:I$61),"N/A") -> N/A | O20: =IFERROR(_xlfn.RANK.EQ(J20,J$3:J$61),"N/A") -> N/A | P20: =IFERROR(ABS(K$3-K20),"N/A") -> N/A | Q20: =IFERROR(ABS(L$3-L20),"N/A") -> N/A | R20: =IFERROR(ABS(M$3-M20),"N/A") -> N/A | S20: =IFERROR(ABS(N$3-N20),"N/A") -> N/A | T20: =IFERROR(ABS(O$3-O20),"N/A") -> N/A | U20: =SUM(P20:T20) -> 0 | V20: =_xlfn.RANK.EQ(U20,$U$4:$U$61,1) -> 1 | W20: =IF(Y20="Not suitable","-",V20) -> - | Y20: =IF(OR(Z20="Y",AA20="Y"),"Not suitable","") -> Not suitable | Z20: =IF(N20="N/A","Y","") -> Y
K21: =IFERROR(_xlfn.RANK.EQ(F21,F$3:F$61),"N/A") -> N/A | L21: =IFERROR(_xlfn.RANK.EQ(G21,G$3:G$61),"N/A") -> N/A | M21: =IFERROR(_xlfn.RANK.EQ(H21,H$3:H$61),"N/A") -> N/A | N21: =IFERROR(_xlfn.RANK.EQ(I21,I$3:I$61),"N/A") -> N/A | O21: =IFERROR(_xlfn.RANK.EQ(J21,J$3:J$61),"N/A") -> N/A | P21: =IFERROR(ABS(K$3-K21),"N/A") -> N/A | Q21: =IFERROR(ABS(L$3-L21),"N/A") -> N/A | R21: =IFERROR(ABS(M$3-M21),"N/A") -> N/A | S21: =IFERROR(ABS(N$3-N21),"N/A") -> N/A | T21: =IFERROR(ABS(O$3-O21),"N/A") -> N/A | U21: =SUM(P21:T21) -> 0 | V21: =_xlfn.RANK.EQ(U21,$U$4:$U$61,1) -> 1 | W21: =IF(Y21="Not suitable","-",V21) -> - | Y21: =IF(OR(Z21="Y",AA21="Y"),"Not suitable","") -> Not suitable | Z21: =IF(N21="N/A","Y","") -> Y
K22: =IFERROR(_xlfn.RANK.EQ(F22,F$3:F$61),"N/A") -> N/A | L22: =IFERROR(_xlfn.RANK.EQ(G22,G$3:G$61),"N/A") -> N/A | M22: =IFERROR(_xlfn.RANK.EQ(H22,H$3:H$61),"N/A") -> N/A | N22: =IFERROR(_xlfn.RANK.EQ(I22,I$3:I$61),"N/A") -> N/A | O22: =IFERROR(_xlfn.RANK.EQ(J22,J$3:J$61),"N/A") -> N/A | P22: =IFERROR(ABS(K$3-K22),"N/A") -> N/A | Q22: =IFERROR(ABS(L$3-L22),"N/A") -> N/A | R22: =IFERROR(ABS(M$3-M22),"N/A") -> N/A | S22: =IFERROR(ABS(N$3-N22),"N/A") -> N/A | T22: =IFERROR(ABS(O$3-O22),"N/A") -> N/A | U22: =SUM(P22:T22) -> 0 | V22: =_xlfn.RANK.EQ(U22,$U$4:$U$61,1) -> 1 | W22: =IF(Y22="Not suitable","-",V22) -> - | Y22: =IF(OR(Z22="Y",AA22="Y"),"Not suitable","") -> Not suitable | Z22: =IF(N22="N/A","Y","") -> Y
K23: =IFERROR(_xlfn.RANK.EQ(F23,F$3:F$61),"N/A") -> N/A | L23: =IFERROR(_xlfn.RANK.EQ(G23,G$3:G$61),"N/A") -> N/A | M23: =IFERROR(_xlfn.RANK.EQ(H23,H$3:H$61),"N/A") -> N/A | N23: =IFERROR(_xlfn.RANK.EQ(I23,I$3:I$61),"N/A") -> N/A | O23: =IFERROR(_xlfn.RANK.EQ(J23,J$3:J$61),"N/A") -> N/A | P23: =IFERROR(ABS(K$3-K23),"N/A") -> N/A | Q23: =IFERROR(ABS(L$3-L23),"N/A") -> N/A | R23: =IFERROR(ABS(M$3-M23),"N/A") -> N/A | S23: =IFERROR(ABS(N$3-N23),"N/A") -> N/A | T23: =IFERROR(ABS(O$3-O23),"N/A") -> N/A | U23: =SUM(P23:T23) -> 0 | V23: =_xlfn.RANK.EQ(U23,$U$4:$U$61,1) -> 1 | W23: =IF(Y23="Not suitable","-",V23) -> - | Y23: =IF(OR(Z23="Y",AA23="Y"),"Not suitable","") -> Not suitable | Z23: =IF(N23="N/A","Y","") -> Y
K24: =IFERROR(_xlfn.RANK.EQ(F24,F$3:F$61),"N/A") -> N/A | L24: =IFERROR(_xlfn.RANK.EQ(G24,G$3:G$61),"N/A") -> N/A | M24: =IFERROR(_xlfn.RANK.EQ(H24,H$3:H$61),"N/A") -> N/A | N24: =IFERROR(_xlfn.RANK.EQ(I24,I$3:I$61),"N/A") -> N/A | O24: =IFERROR(_xlfn.RANK.EQ(J24,J$3:J$61),"N/A") -> N/A | P24: =IFERROR(ABS(K$3-K24),"N/A") -> N/A | Q24: =IFERROR(ABS(L$3-L24),"N/A") -> N/A | R24: =IFERROR(ABS(M$3-M24),"N/A") -> N/A | S24: =IFERROR(ABS(N$3-N24),"N/A") -> N/A | T24: =IFERROR(ABS(O$3-O24),"N/A") -> N/A | U24: =SUM(P24:T24) -> 0 | V24: =_xlfn.RANK.EQ(U24,$U$4:$U$61,1) -> 1 | W24: =IF(Y24="Not suitable","-",V24) -> - | Y24: =IF(OR(Z24="Y",AA24="Y"),"Not suitable","") -> Not suitable | Z24: =IF(N24="N/A","Y","") -> Y
K25: =IFERROR(_xlfn.RANK.EQ(F25,F$3:F$61),"N/A") -> N/A | L25: =IFERROR(_xlfn.RANK.EQ(G25,G$3:G$61),"N/A") -> N/A | M25: =IFERROR(_xlfn.RANK.EQ(H25,H$3:H$61),"N/A") -> N/A | N25: =IFERROR(_xlfn.RANK.EQ(I25,I$3:I$61),"N/A") -> N/A | O25: =IFERROR(_xlfn.RANK.EQ(J25,J$3:J$61),"N/A") -> N/A | P25: =IFERROR(ABS(K$3-K25),"N/A") -> N/A | Q25: =IFERROR(ABS(L$3-L25),"N/A") -> N/A | R25: =IFERROR(ABS(M$3-M25),"N/A") -> N/A | S25: =IFERROR(ABS(N$3-N25),"N/A") -> N/A | T25: =IFERROR(ABS(O$3-O25),"N/A") -> N/A | U25: =SUM(P25:T25) -> 0 | V25: =_xlfn.RANK.EQ(U25,$U$4:$U$61,1) -> 1 | W25: =IF(Y25="Not suitable","-",V25) -> - | Y25: =IF(OR(Z25="Y",AA25="Y"),"Not suitable","") -> Not suitable | Z25: =IF(N25="N/A","Y","") -> Y
K26: =IFERROR(_xlfn.RANK.EQ(F26,F$3:F$61),"N/A") -> N/A | L26: =IFERROR(_xlfn.RANK.EQ(G26,G$3:G$61),"N/A") -> N/A | M26: =IFERROR(_xlfn.RANK.EQ(H26,H$3:H$61),"N/A") -> N/A | N26: =IFERROR(_xlfn.RANK.EQ(I26,I$3:I$61),"N/A") -> N/A | O26: =IFERROR(_xlfn.RANK.EQ(J26,J$3:J$61),"N/A") -> N/A | P26: =IFERROR(ABS(K$3-K26),"N/A") -> N/A | Q26: =IFERROR(ABS(L$3-L26),"N/A") -> N/A | R26: =IFERROR(ABS(M$3-M26),"N/A") -> N/A | S26: =IFERROR(ABS(N$3-N26),"N/A") -> N/A | T26: =IFERROR(ABS(O$3-O26),"N/A") -> N/A | U26: =SUM(P26:T26) -> 0 | V26: =_xlfn.RANK.EQ(U26,$U$4:$U$61,1) -> 1 | W26: =IF(Y26="Not suitable","-",V26) -> - | Y26: =IF(OR(Z26="Y",AA26="Y"),"Not suitable","") -> Not suitable | Z26: =IF(N26="N/A","Y","") -> Y
... K100: =IFERROR(_xlfn.RANK.EQ(F100,F$3:F$61),"N/A") -> N/A | L100: =IFERROR(_xlfn.RANK.EQ(G100,G$3:G$61),"N/A") -> N/A | M100: =IFERROR(_xlfn.RANK.EQ(H100,H$3:H$61),"N/A") -> N/A | N100: =IFERROR(_xlfn.RANK.EQ(I100,I$3:I$61),"N/A") -> N/A | O100: =IFERROR(_xlfn.RANK.EQ(J100,J$3:J$61),"N/A") -> N/A | P100: =IFERROR(ABS(K$3-K100),"N/A") -> N/A | Q100: =IFERROR(ABS(L$3-L100),"N/A") -> N/A | R100: =IFERROR(ABS(M$3-M100),"N/A") -> N/A | S100: =IFERROR(ABS(N$3-N100),"N/A") -> N/A | T100: =IFERROR(ABS(O$3-O100),"N/A") -> N/A | U100: =SUM(P100:T100) -> 0 | V100: =_xlfn.RANK.EQ(U100,$U$4:$U$61,1) -> 1 | W100: =IF(Y100="Not suitable","-",V100) -> - | Y100: =IF(OR(Z100="Y",AA100="Y"),"Not suitable","") -> Not suitable | Z100: =IF(N100="N/A","Y","") -> Y

Sheet ESG
B1: Company GICS Sector: | T1: Yes
B2: Renewable Energy | C2: <- Select Industry | T2: No
B3: ESG Analysis | K3: Relative ESG Analysis
B4: Parameters | C4: Impact | D4: Do they report? | E4: Ranking | F4: Mitigation Plan | G4: Traffic Lights | H4: Improvement over time? | I4: Targets / Goals? | J4: Comments | K4: Parameters | L4: =Peers!C8 -> #VALUE! | M4: =Peers!D8 -> nvidia | N4: =Peers!E8 -> intel | O4: =Peers!F8 -> 0 | P4: =Peers!G8 -> 0 | Q4: =Peers!H8 -> 0 | R4: AVERAGE
B5: Environmental | K5: Ratios
A6: 1 | B6: CO2 Direct Emissions | C6: =VLOOKUP($B$2,'Sector Impact'!$K$4:$AA$16,A6+1,FALSE) -> Low | K6: CO2 Emissions/$M Sales | L6: =L12/L$11 -> #DIV/0! | M6: =M12/M$11 -> #DIV/0! | N6: =N12/N$11 -> #DIV/0! | O6: =O12/O$11 -> #DIV/0! | P6: =P12/P$11 -> #DIV/0! | Q6: =Q12/Q$11 -> #DIV/0! | R6: =IFERROR(AVERAGE(L6:Q6),"")
A7: 2 | B7: Total Water Consumption | C7: =VLOOKUP($B$2,'Sector Impact'!$K$4:$AA$16,A7+1,FALSE) -> Low | K7: Water Consumption/$M Sales | L7: =L13/L$11 -> #DIV/0! | M7: =M13/M$11 -> #DIV/0! | N7: =N13/N$11 -> #DIV/0! | O7: =O13/O$11 -> #DIV/0! | P7: =P13/P$11 -> #DIV/0! | Q7: =Q13/Q$11 -> #DIV/0! | R7: =IFERROR(AVERAGE(L7:Q7),"")
A8: 3 | B8: Total Energy Consumption | C8: =VLOOKUP($B$2,'Sector Impact'!$K$4:$AA$16,A8+1,FALSE) -> Low | K8: Energy Consumption/$M Sales | L8: =L14/L$11 -> #DIV/0! | M8: =M14/M$11 -> #DIV/0! | N8: =N14/N$11 -> #DIV/0! | O8: =O14/O$11 -> #DIV/0! | P8: =P14/P$11 -> #DIV/0! | Q8: =Q14/Q$11 -> #DIV/0! | R8: =IFERROR(AVERAGE(L8:Q8),"")
A9: 4 | B9: Waste Management | C9: =VLOOKUP($B$2,'Sector Impact'!$K$4:$AA$16,A9+1,FALSE) -> Medium | K9: Waste Production/$M Sales | L9: =L15/L$11 -> #DIV/0! | M9: =M15/M$11 -> #DIV/0! | N9: =N15/N$11 -> #DIV/0! | O9: =O15/O$11 -> #DIV/0! | P9: =P15/P$11 -> #DIV/0! | Q9: =Q15/Q$11 -> #DIV/0! | R9: =IFERROR(AVERAGE(L9:Q9),"")
A10: 5 | B10: Land Degradation/Deforestation/Biodiversity loss/Animal sufering/… | C10: =VLOOKUP($B$2,'Sector Impact'!$K$4:$AA$16,A10+1,FALSE) -> Medium | K10: Inputs
B11: Social | K11: Net Sales ($M)
A12: 6 | B12: Employee Turnover % | C12: =VLOOKUP($B$2,'Sector Impact'!$K$4:$AA$16,A12+1,FALSE) -> Low | K12: CO2 Emissions Total (Tonnes)
A13: 7 | B13: Salaries & Compensation | C13: =VLOOKUP($B$2,'Sector Impact'!$K$4:$AA$16,A13+1,FALSE) -> Medium | K13: Water Consumption Total (Cubic Meters)
A14: 8 | B14: Reputation | C14: =VLOOKUP($B$2,'Sector Impact'!$K$4:$AA$16,A14+1,FALSE) -> Medium | K14: Energy Consumption Total (Gigajoules)
A15: 9 | B15: Discrimination Events | C15: =VLOOKUP($B$2,'Sector Impact'!$K$4:$AA$16,A15+1,FALSE) -> High | F15: Yes | K15: Waste Production Total (Tonnes)
A16: 10 | B16: Work Safety | C16: =VLOOKUP($B$2,'Sector Impact'!$K$4:$AA$16,A16+1,FALSE) -> Medium | K16: ESG Scores
A17: 11 | B17: Damage to consumer health | C17: =VLOOKUP($B$2,'Sector Impact'!$K$4:$AA$16,A17+1,FALSE) -> Low | K17: Refinitiv
A18: 12 | B18: PXP? | C18: =VLOOKUP($B$2,'Sector Impact'!$K$4:$AA$16,A18+1,FALSE) -> Low | K18: Sustainalytics
A19: 13 | B19: Supply chain | C19: =VLOOKUP($B$2,'Sector Impact'!$K$4:$AA$16,A19+1,FALSE) -> Medium | K19: ISS
A20: 14 | B20: Community involvement | C20: =VLOOKUP($B$2,'Sector Impact'!$K$4:$AA$16,A20+1,FALSE) -> Medium | K20: CDP
A21: 15 | B21: Public Sector | C21: =VLOOKUP($B$2,'Sector Impact'!$K$4:$AA$16,A21+1,FALSE) -> High
A22: 16 | B22: Litigation | C22: =VLOOKUP($B$2,'Sector Impact'!$K$4:$AA$16,A22+1,FALSE) -> Low | D22: Yes
B23: Corporate Governance | K23: PARAMETERS
A24: 17 | B24: Diversity (Gender, Age, Industry, Region) | K24: IMPACT | L24: RANKING | M24: MITIGATION PLAN | O24: TRAFFIC
A25: 18 | B25: % Independence | K25: Low | L25: "Best in class" | M25: Is there evidence of a plan/program ?
A26: 19 | B26: average time as independent directors | K26: Medium | L26: Medium High
A27: 20 | B27: Recent departures of directors / C-level executives? | K27: High | L27: Medium
A28: 21 | B28: CEO/Chairman duality | K28: Very high | L28: "Villain"
A29: 22 | B29: Transparency (ESG, segments, acquisitions, other)
A30: 23 | B30: Time taken to report after the end of the quarter / year
A31: 24 | B31: Additional participation of the CEO in other boards or excessive participation of Ch.
A32: 25 | B32: Audit / Consulting
A33: 26 | B33: ESG-compensation related
A34: 27 | B34: Management compensation schemes

Sheet DCF
A1: VALUATION MODEL
G3: Short Term | K3: Long Term
A4: Section | B4: Line # | C4: ITEM | D4: 2021 (Real) | E4: 2022 (Real) | F4: 2023 (Real) | G4: 2024 | H4: =G4+1 -> 2025 | I4: =H4+1 -> 2026 | J4: =I4+1 -> 2027 | K4: =J4+1 -> 2028 | L4: =K4+1 -> 2029 | M4: =L4+1 -> 2030 | N4: =M4+1 -> 2031 | O4: =N4+1 -> 2032 | ... AF4: =AE4+1 -> 2049
A5: INCOME STATEMENT | B5: 1 | C5: Growth | D5: ='Fin. Data'!D6 -> 0.68329407 | E5: =+E6/D6-1 -> 0.43610807 | F5: =+F6/E6-1 -> -0.03902377 | G5: =+G6/F6-1 -> -1 | H5: =+H6/G6-1 -> #DIV/0! | I5: =+I6/H6-1 -> #DIV/0! | J5: =+J6/I6-1 -> #DIV/0! | K5: =+K6/J6-1 -> #DIV/0! | L5: =+L6/K6-1 -> #DIV/0! | ... AF5: =+AF6/AE6-1 -> #DIV/0!
B6: 2 | C6: Revenues/Sales | D6: =Inputs!D6 -> 16434 | E6: =Inputs!C6 -> 23601 | F6: =Inputs!B6 -> 22680
B7: 3 | C7: EBIT/Operating Margin | D7: =D8/D6 -> 0.22155288 | E7: =E8/E6 -> 0.053557053 | F7: =F8/F6 -> 0.017680776
B8: 4 | C8: EBIT | D8: ='Fin. Data'!D11 -> 3641 | E8: ='Fin. Data'!C11 -> 1264 | F8: ='Fin. Data'!B11 -> 401 | G8: =G7*G6 -> 0 | H8: =H7*H6 -> 0 | I8: =I7*I6 -> 0 | J8: =J7*J6 -> 0 | K8: =K7*K6 -> 0 | L8: =L7*L6 -> 0 | M8: =M7*M6 -> 0 | N8: =N7*N6 -> 0 | ... AF8: =AF7*AF6 -> 0
B9: 5a | C9: (Dep) | G9: =$D$53*DCF!F40 -> 0 | H9: =$D$53*DCF!G40 -> 0 | I9: =$D$53*DCF!H40 -> 0 | J9: =$D$53*DCF!I40 -> 0 | K9: =$E$53*DCF!J40 -> 0 | L9: =$E$53*DCF!K40 -> 0 | M9: =$E$53*DCF!L40 -> 0 | N9: =$E$53*DCF!M40 -> 0 | O9: =$E$53*DCF!N40 -> 0 | P9: =$E$53*DCF!O40 -> 0 | Q9: =$E$53*DCF!P40 -> 0 | R9: =$E$53*DCF!Q40 -> 0 | ... AF9: =$E$53*DCF!AE40 -> 0 | AG9: =SUM(D9:AF9) -> 0
B10: 5b | C10: (Amort) | G10: =F38*$D$54 -> 0 | H10: =G38*$D$54 -> 0 | I10: =H38*$D$54 -> 0 | J10: =I38*$D$54 -> 0 | K10: =J38*$E$54 -> 0 | L10: =K38*$E$54 -> 0 | M10: =L38*$E$54 -> 0 | N10: =M38*$E$54 -> 0 | O10: =N38*$E$54 -> 0 | P10: =O38*$E$54 -> 0 | Q10: =P38*$E$54 -> 0 | R10: =Q38*$E$54 -> 0 | ... AF10: =AE38*$E$54 -> 0
B11: 5c | C11: (Stock based compensation) | D11: =D20 -> 0 | E11: =E20 -> 0 | F11: =F20 -> 0 | G11: =G6*$D$55 -> 0 | H11: =H6*$D$55 -> 0 | I11: =I6*$D$55 -> 0 | J11: =J6*$D$55 -> 0 | K11: =K6*$D$55 -> 0 | L11: =L6*$D$55 -> 0 | M11: =M6*$D$55 -> 0 | N11: =N6*$D$55 -> 0 | ... AF11: =AF6*$D$55 -> 0
B12: 6 | C12: EBITDA | D12: =D8-D9-D10 -> 3641 | E12: =E8-E9-E10 -> 1264 | F12: =F8-F9-F10 -> 401 | G12: =G8-G9-G10 -> 0 | H12: =H8-H9-H10 -> 0 | I12: =I8-I9-I10 -> 0 | J12: =J8-J9-J10 -> 0 | K12: =K8-K9-K10 -> 0 | ... AF12: =AF8-AF9-AF10 -> 0
B13: 7 | C13: (Net financing cost) | D13: ='Fin. Data'!D14 -> 30 | E13: ='Fin. Data'!C14 -> -85 | F13: ='Fin. Data'!B14 -> 99 | G13: =F43*$D$58-F44*$D$57 -> 0 | H13: =G43*$D$58-G44*$D$57 -> 0 | I13: =H43*$D$58-H44*$D$57 -> #DIV/0! | J13: =I43*$D$58-I44*$D$57 -> #DIV/0! | K13: =J43*$E$58-J44*$E$57 -> #DIV/0! | L13: =K43*$E$58-K44*$E$57 -> #DIV/0! | M13: =L43*$E$58-L44*$E$57 -> #DIV/0! | N13: =M43*$E$58-M44*$E$57 -> #DIV/0! | O13: =N43*$E$58-N44*$E$57 -> #DIV/0! | P13: =O43*$E$58-O44*$E$57 -> #DIV/0! | Q13: =P43*$E$58-P44*$E$57 -> #DIV/0! | R13: =Q43*$E$58-Q44*$E$57 -> #DIV/0! | ... AF13: =AE43*$E$58-AE44*$E$57 -> #DIV/0!
B14: 8 | C14: Other income/(cost) | D14: ='Fin. Data'!D15 -> 4 | E14: ='Fin. Data'!C15 -> 19 | F14: ='Fin. Data'!B15 -> 8 | G14: =AVERAGE(D14:F14)*(1+G5) -> 0 | H14: =AVERAGE(E14:G14)*(1+H5) -> #DIV/0! | I14: =AVERAGE(F14:H14)*(1+I5) -> #DIV/0! | J14: =AVERAGE(G14:I14)*(1+J5) -> #DIV/0! | K14: =AVERAGE(H14:J14)*(1+K5) -> #DIV/0! | L14: =AVERAGE(I14:K14)*(1+L5) -> #DIV/0! | M14: =AVERAGE(J14:L14)*(1+M5) -> #DIV/0! | N14: =AVERAGE(K14:M14)*(1+N5) -> #DIV/0! | ... AF14: =AVERAGE(AC14:AE14)*(1+AF5) -> #DIV/0!
B15: 9 | C15: Earnings before taxes | D15: =D8+D13+D14 -> 3675 | E15: =E8+E13+E14 -> 1198 | F15: =F8+F13+F14 -> 508 | G15: =G8+G13+G14 -> 0 | H15: =H8+H13+H14 -> #DIV/0! | I15: =I8+I13+I14 -> #DIV/0! | J15: =J8+J13+J14 -> #DIV/0! | K15: =K8+K13+K14 -> #DIV/0! | ... AF15: =AF8+AF13+AF14 -> #DIV/0!
B16: 10 | C16: (Income tax) | D16: ='Fin. Data'!D21 -> -513 | E16: ='Fin. Data'!C21 -> 122 | F16: ='Fin. Data'!B21 -> 346 | G16: =-$D$56*G15 -> 0 | H16: =-$D$56*H15 -> #DIV/0! | I16: =-$D$56*I15 -> #DIV/0! | J16: =-$D$56*J15 -> #DIV/0! | K16: =-$E$56*K15 -> #DIV/0! | L16: =-$E$56*L15 -> #DIV/0! | M16: =-$E$56*M15 -> #DIV/0! | N16: =-$E$56*N15 -> #DIV/0! | O16: =-$E$56*O15 -> #DIV/0! | P16: =-$E$56*P15 -> #DIV/0! | Q16: =-$E$56*Q15 -> #DIV/0! | R16: =-$E$56*R15 -> #DIV/0! | ... AF16: =-$E$56*AF15 -> #DIV/0!
B17: 11 | C17: Net income | D17: ='Fin. Data'!D23 -> 3162 | E17: ='Fin. Data'!C23 -> 1320 | F17: ='Fin. Data'!B23 -> 854 | G17: =G16+G15 -> 0 | H17: =H16+H15 -> #DIV/0! | I17: =I16+I15 -> #DIV/0! | J17: =J16+J15 -> #DIV/0! | K17: =K16+K15 -> #DIV/0! | L17: =L16+L15 -> #DIV/0! | M17: =M16+M15 -> #DIV/0! | N17: =N16+N15 -> #DIV/0! | ... AF17: =AF16+AF15 -> #DIV/0!
A19: CASH FLOW STATEMENT | B19: 12 | C19: Operating cash flows before WK | G19: =G17-G10-G9-G11 -> 0 | H19: =H17-H10-H9-H11 -> #DIV/0! | I19: =I17-I10-I9-I11 -> #DIV/0! | J19: =J17-J10-J9-J11 -> #DIV/0! | K19: =K17-K10-K9-K11 -> #DIV/0! | L19: =L17-L10-L9-L11 -> #DIV/0! | M19: =M17-M10-M9-M11 -> #DIV/0! | N19: =N17-N10-N9-N11 -> #DIV/0! | ... AF19: =AF17-AF10-AF9-AF11 -> #DIV/0!
B20: 13 | C20: (Stock-based compensation) | G20: =G11 -> 0 | H20: =H11 -> 0 | I20: =I11 -> 0 | J20: =J11 -> 0 | K20: =K11 -> 0 | L20: =L11 -> 0 | M20: =M11 -> 0 | N20: =N11 -> 0 | ... AF20: =AF11 -> 0
B21: 14 | C21: (Working Capital Flows) | D21: =Inputs!D62 -> -774 | E21: =Inputs!C62 -> -1846 | F21: =Inputs!B62 -> -3049 | G21: =$D$60*(G6-F6) -> 0 | H21: =$D$60*(H6-G6) -> 0 | I21: =$D$60*(I6-H6) -> 0 | J21: =$D$60*(J6-I6) -> 0 | K21: =$E$60*(K6-J6) -> 0 | L21: =$E$60*(L6-K6) -> 0 | M21: =$E$60*(M6-L6) -> 0 | N21: =$E$60*(N6-M6) -> 0 | O21: =$E$60*(O6-N6) -> 0 | P21: =$E$60*(P6-O6) -> 0 | Q21: =$E$60*(Q6-P6) -> 0 | R21: =$E$60*(R6-Q6) -> 0 | ... AF21: =$E$60*(AF6-AE6) -> 0
B22: 15 | C22: -Total Operating Cash Flow | D22: =D19+D20+D21 -> -774 | E22: =E19+E20+E21 -> -1846 | F22: =F19+F20+F21 -> -3049 | G22: =G19+G20+G21 -> 0 | H22: =H19+H20+H21 -> #DIV/0! | I22: =I19+I20+I21 -> #DIV/0! | J22: =J19+J20+J21 -> #DIV/0! | K22: =K19+K20+K21 -> #DIV/0! | ... AF22: =AF19+AF20+AF21 -> #DIV/0!
B23: 16 | C23: (CAPEX) | D23: ='Fin. Data'!D32 -> -301 | E23: ='Fin. Data'!C32 -> -450 | F23: ='Fin. Data'!B32 -> -546 | G23: =G6*$D$62 -> 0 | H23: =H6*$D$62 -> 0 | I23: =I6*$D$62 -> 0 | J23: =J6*$D$62 -> 0 | K23: =K6*$E$62 -> 0 | L23: =L6*$E$62 -> 0 | M23: =M6*$E$62 -> 0 | N23: =N6*$E$62 -> 0 | O23: =O6*$E$62 -> 0 | P23: =P6*$E$62 -> 0 | Q23: =Q6*$E$62 -> 0 | R23: =R6*$E$62 -> 0 | ... AF23: =AF6*$E$62 -> 0 | AG23: =SUM(D23:AF23) -> -1297
B24: 17 | C24: Adq | D24: =Inputs!D66 -> -378 | E24: ='Fin. Data'!C33 -> 2465 | F24: ='Fin. Data'!B33 -> -866 | G24: =G6*$D$63 -> 0 | H24: =H6*$D$63 -> 0 | I24: =I6*$D$63 -> 0 | J24: =J6*$D$63 -> 0 | K24: =K6*$E$63 -> 0 | L24: =L6*$E$63 -> 0 | M24: =M6*$E$63 -> 0 | N24: =N6*$E$63 -> 0 | O24: =O6*$E$63 -> 0 | P24: =P6*$E$63 -> 0 | Q24: =Q6*$E$63 -> 0 | R24: =R6*$E$63 -> 0 | ... AF24: =AF6*$E$63 -> 0 | AH24: =AG9-AG23 -> 1297
