Workbook
Name Sectors: '[1]Sector Impact'!$K$4:$K$16
Name Sectors: 'Sector Impact'!$K$4:$K$16

Sheet OP
B2: 45039 | C2: Team 1 | E2: =Inputs!H3 -> #VALUE! | L2: NYSE | M2: SIC:
D3: COMPANY DESCRIPTION | H3: CEO & BOARD OF DIRECTORS
D4: {=_FV(Inputs!H3,"Description")} -> Advanced Micro Devices, Inc. is a global semiconductor company. It is focused on high-performance computing, graphics and visualization technologies. It operates in four segments. The Data Center segment includes artificial intelligence (AI) accelerators, server central processing units (CPUs), graphics processing units (GPUs), accelerated processing units (APUs), data processing units (DPUs), field programmable gate arrays (FPGAs), smart network interface cards (SmartNICs), and Adaptive system-on-chip (SoC) products for data centers. The Client segment primarily includes CPUs, APUs, and chipsets for desktops and notebooks. The Gaming segment primarily includes discrete GPUs, semi-custom SoC products and development services. The Embedded segment includes embedded CPUs, GPUs, APUs, FPGAs, system on modules (SOMs), and Adaptive SoC products. It markets and sells its products under the AMD trademark. Its products include AMD EPYC, AMD Ryzen, AMD Ryzen PRO, Virtex UltraScale+ and others. | H4: Name | I4: Gender | J4: Age | K4: Tenure | L4: Executive? | M4: Other roles
H5: Dr. Lisa T. Su | I5: Female | J5: 54 | K5: 12 years | L5: MD’s Chair, President and Chief Executive Officer | M5: Chief Operating Officer, Senior Vice President and General Manager,
H6: Nora M. Denzel | I6: Female | J6: 61 | K6: 10 years | M6: Lead Independent Director
H7: Mark Durcan | I7: Male | J7: 62 | K7: 7 years | M7: Independent Director
H8: Mike P. Gregoire | I8: Male | J8: 58 | K8: 5 years | M8: Independent Director
H9: Joseph A. Householder | I9: Male | J9: 64 | K9: 10 years | M9: Independent Director
H10: John Marren | I10: Male | J10: 57 | K10: 7 years | M10: Independent Director
H11: Jon A. Olson | I11: Male | J11: 70 | K11: 2 years | M11: Independent Director
H12: Abhi Talwalkar | I12: Male | J12: 59 | K12: 7 years | M12: Independent Director
H13: Elizabeth (Beth) Vanderslice | I13: Female | J13: 59 | K13: 2 years | M13: Independent Director
B17: USD MILLIONS
B18: COMPANY OVERVIEW
B19: Stock | D19: Liquidity and Solvency | F19: Segments | I19: Profitability (2022) | L19: Multiples
B20: Last Price | C20: {=_FV(E2,"Price")} -> 78.21 | D20: Total Assets | E20: =_xlfn.XLOOKUP(D20,'Fin. Data'!A:A,'Fin. Data'!B:B,,0) -> 67885 | F20: Regions | H20: % Sales | I20: Reporting Year | J20: 2023 | L20: Float
B21: Outstanding Shares | C21: {=_FV(E2,"Shares outstanding",TRUE)} -> 1616297000 | D21: Total Liabilities | E21: =_xlfn.XLOOKUP(D21,'Fin. Data'!A:A,'Fin. Data'!B:B,,0) -> 11993 | F21: =Segments!C5 -> United States | H21: =Segments!B5 -> 0.34554674 | I21: End of Year | J21: 45291 | L21: Insiders Own
B22: Market Cap. | C22: =C20*C21/1000000 -> 126410.59 | D22: Cash/Share | E22: =_xlfn.XLOOKUP("Cash & Eq.",'Fin. Data'!A:A,'Fin. Data'!B:B,,0)*1000000/C21 -> 2.4333399 | F22: =Segments!C6 -> Japan | H22: =Segments!B6 -> 0.20410053 | I22: EBITDA | K22: =_xlfn.XLOOKUP(I22,'Fin. Data'!A:A,'Fin. Data'!B:B,,0) -> 3846 | L22: b (Yahoo)
B23: +Total Debt | C23: ='Fin. Data'!B58 -> 2252 | D23: EBITDA/Net Financial Cost (NFC) | E23: =_xlfn.XLOOKUP("EBITDA",'Fin. Data'!A:A,'Fin. Data'!B:B,,0)/_xlfn.XLOOKUP("Net Financial Cost",'Fin. Data'!A:A,'Fin. Data'!B:B,,0) -> 38.848485 | F23: =Segments!C7 -> China (including Hong Kong) | H23: =Segments!B7 -> 0.15066138 | I23: Depreciation & Amortization | K23: =_xlfn.XLOOKUP(I23,'Fin. Data'!A:A,'Fin. Data'!B:B,,0) -> 3453 | L23: Score (S&P)
B24: -Cash | C24: ='Fin. Data'!B39 -> 3933 | D24: Debt/EBITDA | E24: =_xlfn.XLOOKUP("Total Debt",'Fin. Data'!A:A,'Fin. Data'!B:B,,0)/_xlfn.XLOOKUP("EBITDA",'Fin. Data'!A:A,'Fin. Data'!B:B,,0) -> 0.58554342 | F24: =Segments!C8 -> Singapore | H24: =Segments!B8 -> 0.098368607 | I24: EBIT | K24: =_xlfn.XLOOKUP(I24,'Fin. Data'!A:A,'Fin. Data'!B:B,,0) -> 393 | L24: Price/Book Value | M24: =IFERROR((C20*C21/(E20-E21))/1000000,"") -> 2.2616938
B25: =Enterprise Value | C25: =C22+C23-C24 -> 124729.59 | D25: "Others Assets"/Asset | E25: =_xlfn.XLOOKUP("Other Assets",'Fin. Data'!A:A,'Fin. Data'!B:B,,0)/_xlfn.XLOOKUP("Total Assets",'Fin. Data'!A:A,'Fin. Data'!B:B,,0) -> 0.76458717 | F25: =Segments!C9 -> Europe | H25: =Segments!B9 -> 0.089506173 | I25: Net Income | K25: =_xlfn.XLOOKUP(I25,'Fin. Data'!A:A,'Fin. Data'!B:B,,0) -> 854 | L25: NCF(3y avg)/Asset | M25: =IFERROR(K31/E20,"") -> 0.026201174
B26: Holdings (nac/int'l) | C26: - | D26: Debt/Assets | E26: =_xlfn.XLOOKUP(D26,'Fin. Data'!A:A,'Fin. Data'!B:B,,0) -> 0.03317375 | F26: Categories | H26: % Sales | I26: EPS | K26: =1000000*K25/C21 -> 0.52836824 | L26: Price/Net Inc. (3y avg) | M26: =IFERROR(C22/K30,"") -> 71.070421
B27: t liq. (Holdings/Vol.) | C27: - | D27: EBITDA Margin (average) | E27: =AVERAGE(_xlfn.XLOOKUP("EBITDA Margin",'Fin. Data'!A:A,'Fin. Data'!B:D,,0)) -> 0.21508695 | F27: =Segments!C19 -> Data Center | H27: =Segments!B19 -> 0.28641975 | I27: ROA | K27: =K25/E20 -> 0.012580099 | L27: EV/Asset | M27: =IFERROR(C25/E20,"") -> 1.837366
B28: % Short | D28: Operating Margin (average) | E28: =AVERAGE(_xlfn.XLOOKUP("Operating Margin",'Fin. Data'!A:A,'Fin. Data'!B:D,,0)) -> 0.097596902 | F28: =Segments!C21 -> Gaming | H28: =Segments!B21 -> 0.27389771 | I28: ROIC | K28: =Peers!C16 -> 0.016072853 | L28: EV/Ebitda (3y average) | M28: =IFERROR(C25/K29,"") -> 28.115468
B29: Traffic ESG | D29: Net Income Margin (average) | E29: =AVERAGE(_xlfn.XLOOKUP("Net Income Margin",'Fin. Data'!A:A,'Fin. Data'!B:D,,0)) -> 0.095330047 | F29: =Segments!C22 -> Embedded | H29: =Segments!B22 -> 0.23461199 | I29: EBITDA (3y average) | K29: =AVERAGE(_xlfn.XLOOKUP("EBITDA",'Fin. Data'!A:A,'Fin. Data'!B:D,,0)) -> 4436.3333 | L29: Price/NCF (3y average) | M29: =IFERROR(C22/K31,"") -> 71.070421
B30: E | F30: =Segments!C20 -> Client | H30: =Segments!B20 -> 0.20507055 | I30: Net Income (3y average) | K30: =AVERAGE(_xlfn.XLOOKUP("Net Income",'Fin. Data'!A:A,'Fin. Data'!B:D,,0)) -> 1778.6667 | L30: Bonds 1,3,5a (USD) | M30: -
B31: S | D31: Net Financial Cost/Avg Net Debt | E31: =-_xlfn.XLOOKUP("Net Financial Cost",'Fin. Data'!A:A,'Fin. Data'!B:B,,0)/AVERAGE(_xlfn.XLOOKUP("Net Debt",'Fin. Data'!A:A,'Fin. Data'!B:D,,0)) -> 0.050864874 | F31: =Segments!#REF! -> #REF! | H31: =Segments!#REF! -> #REF! | I31: NCF (3y average) | K31: =AVERAGE(_xlfn.XLOOKUP("Net Income",'Fin. Data'!A:A,'Fin. Data'!B:D,,0)) -> 1778.6667 | L31: Div+Rep.(3y avg)/Price | M31: =-IFERROR(SUM(E52:E54)/(3*C22),"") -> 0.017005432
B32: G | L32: Div. Yield | M32: =-IFERROR(L53/C22,"") -> 0
B33: INVESTMENT THESIS
B34: Pillars of Recommendation | H34: Recommendation | I34: Valuation Assumptions
B35: Pillar | C35: Explanation | H35: Buy
B36: High growth potential | C36: Increase in demand for AI chips to feed computing needs for generative lenguage models
B37: Special positioning in AI | C37: The company is posing itself to compete with NVIDIA and breaking it's competitive advantage of vertical integration of software and hardware
B38: Future technologies | C38: The company is posed to capitalize on future technologies such as Quantum computers or VR hardware chips might be capitlized and can't be counted on for current projections.
B39: Risks of Investment | H39: Price Target | I39: Valuation
B40: Risk | C40: Explanation | H40: ='Base Case'!D76 -> 183.58063 | I40: Discount Rate | J40: 0.18 | L40: Price M. Upside | M40: =SARD!AJ14 -> #NUM!
B41: Uncertainty | C41: The AI chips industry is not estabeished and the market dynamics projections are merely based on scenarios
B42: High valuation | C42: If the company fails to position itself in the datacenter segment, it's current valuation is too high | I42: Upside | J42: ='Base Case'!D75 -> 1.3472782 | L42: EV M. Upside | M42: =SARD!AM14 -> #NUM!
B43: Geopolitical | C43: High relience on TSMC to outsource production and exposure to chinese market
B44: FINANCIAL PERFORMANCE
...

Sheet Segments
B2: ="Regions "&"("&OP!$J$20&")" -> Regions (2023) | Q2: Products
D3: Nominal value | K3: YoY Growth
B4: Weight | C4: Region | D4: =OP!J20 -> 2023 | E4: =D4-1 -> 2022 | F4: =E4-1 -> 2021 | G4: =F4-1 -> 2020 | H4: =G4-1 -> 2019 | I4: =H4-1 -> 2018 | K4: =OP!J20 -> 2023 | L4: =K4-1 -> 2022 | M4: =L4-1 -> 2021 | N4: =M4-1 -> 2020 | O4: =N4-1 -> 2019 | P4: =O4-1 -> 2018
B5: =IFERROR(D5/$D$14,"") -> 0.34554674 | C5: United States | D5: 7837 | E5: 8049 | F5: 4656 | G5: 2294 | H5: 1764 | I5: 1327 | K5: =(D5-E5)/E5 -> -0.026338676 | L5: =(E5-F5)/F5 -> 0.72873711 | M5: =(F5-G5)/G5 -> 1.0296425 | N5: =(G5-H5)/H5 -> 0.30045351 | O5: =(H5-I5)/I5 -> 0.32931424 | P5: -
B6: =IFERROR(D6/$D$14,"") -> 0.20410053 | C6: Japan | D6: 4629 | E6: 4177 | F6: 2381 | G6: 1033 | H6: 840 | I6: 1225 | K6: =(D6-E6)/E6 -> 0.10821164 | L6: =(E6-F6)/F6 -> 0.75430491 | M6: =(F6-G6)/G6 -> 1.3049371 | N6: =(G6-H6)/H6 -> 0.2297619 | O6: =(H6-I6)/I6 -> -0.31428571 | P6: -
B7: =IFERROR(D7/$D$14,"") -> 0.15066138 | C7: China (including Hong Kong) | D7: 3417 | E7: 5207 | F7: 4096 | G7: 2329 | H7: 1736 | I7: 1319 | K7: =(D7-E7)/E7 -> -0.343768 | L7: =(E7-F7)/F7 -> 0.27124023 | M7: =(F7-G7)/G7 -> 0.75869472 | N7: =(G7-H7)/H7 -> 0.34158986 | O7: =(H7-I7)/I7 -> 0.3161486 | P7: -
B8: =IFERROR(D8/$D$14,"") -> 0.098368607 | C8: Singapore | D8: 2231 | E8: 1380 | F8: 1389 | G8: 1096 | H8: 597 | I8: 728 | K8: =(D8-E8)/E8 -> 0.61666667 | L8: =(E8-F8)/F8 -> -0.0064794816 | M8: =(F8-G8)/G8 -> 0.26733577 | N8: =(G8-H8)/H8 -> 0.8358459 | O8: =(H8-I8)/I8 -> -0.17994505 | P8: -
B9: =IFERROR(D9/$D$14,"") -> 0.089506173 | C9: Europe | D9: 2030 | E9: 1773 | F9: 1249 | G9: 1108 | H9: 762 | I9: 470 | K9: =(D9-E9)/E9 -> 0.14495206 | L9: =(E9-F9)/F9 -> 0.41953563 | M9: =(F9-G9)/G9 -> 0.12725632 | N9: =(G9-H9)/H9 -> 0.45406824 | O9: =(H9-I9)/I9 -> 0.6212766 | P9: -
B10: =IFERROR(D10/$D$14,"") -> 0.08117284 | C10: Taiwan | D10: 1841 | E10: 2369 | F10: 2091 | G10: 1187 | H10: 719 | I10: 1197 | K10: =(D10-E10)/E10 -> -0.22287885 | L10: =(E10-F10)/F10 -> 0.13295074 | M10: =(F10-G10)/G10 -> 0.76158382 | N10: =(G10-H10)/H10 -> 0.65090403 | O10: =(H10-I10)/I10 -> -0.39933166 | P10: -
B11: =IFERROR(D11/$D$14,"") -> 0 | C11: Taiwan | K11: =(D11-E11)/E11 -> #DIV/0! | L11: =(E11-F11)/F11 -> #DIV/0! | M11: =(F11-G11)/G11 -> #DIV/0! | N11: =(G11-H11)/H11 -> #DIV/0! | O11: =(H11-I11)/I11 -> #DIV/0!
B12: =IFERROR(D12/$D$14,"") -> 0 | C12: Taiwan | K12: =(D12-E12)/E12 -> #DIV/0! | L12: =(E12-F12)/F12 -> #DIV/0! | M12: =(F12-G12)/G12 -> #DIV/0! | N12: =(G12-H12)/H12 -> #DIV/0! | O12: =(H12-I12)/I12 -> #DIV/0!
B13: =IFERROR(D13/$D$14,"") -> 0.030643739 | C13: Other countries | D13: 695 | E13: 646 | F13: 572 | G13: 716 | H13: 313 | I13: 0 | K13: =(D13-E13)/E13 -> 0.075851393 | L13: =(E13-F13)/F13 -> 0.12937063 | M13: =(F13-G13)/G13 -> -0.20111732 | N13: =(G13-H13)/H13 -> 1.2875399 | O13: =(H13-I13)/I13 -> #DIV/0! | P13: -
B14: =SUM(B5:B12) -> 0.96935626 | C14: TOTAL | D14: =SUM(D5:D13) -> 22680 | E14: =SUM(E5:E13) -> 23601 | F14: =SUM(F5:F13) -> 16434 | G14: =SUM(G5:G13) -> 9763 | H14: =SUM(H5:H13) -> 6731 | I14: =SUM(I5:I13) -> 6266 | K14: =(D14-E14)/E14 -> -0.03902377 | L14: =(E14-F14)/F14 -> 0.43610807 | M14: =(F14-G14)/G14 -> 0.68329407 | N14: =(G14-H14)/H14 -> 0.45045313 | O14: =(H14-I14)/I14 -> 0.074210022 | P14: -
B16: ="Categories "&"("&OP!$J$20&")" -> Categories (2023)
D17: Nominal value | K17: YoY Growth
B18: Weight | C18: Category | D18: =OP!J20 -> 2023 | E18: =D18-1 -> 2022 | F18: =E18-1 -> 2021 | G18: =F18-1 -> 2020 | H18: =G18-1 -> 2019 | I18: =H18-1 -> 2018 | K18: =OP!J20 -> 2023 | L18: =K18-1 -> 2022 | M18: =L18-1 -> 2021 | N18: =M18-1 -> 2020 | O18: =N18-1 -> 2019 | P18: =O18-1 -> 2018
B19: =IFERROR(D19/$D$23,"") -> 0.28641975 | C19: Data Center | D19: 6496 | E19: 6043 | F19: 3694 | K19: =(D19-E19)/E19 -> 0.074962767 | L19: =(E19-F19)/F19 -> 0.63589605 | M19: =(F19-G19)/G19 -> #DIV/0! | N19: =(G19-H19)/H19 -> #DIV/0! | O19: =(H19-I19)/I19 -> #DIV/0! | P19: -
B20: =IFERROR(D20/$D$23,"") -> 0.20507055 | C20: Client | D20: 4651 | E20: 6201 | F20: 6887 | K20: =(D20-E20)/E20 -> -0.24995968 | L20: =(E20-F20)/F20 -> -0.099607957 | M20: =(F20-G20)/G20 -> #DIV/0! | N20: =(G20-H20)/H20 -> #DIV/0! | O20: =(H20-I20)/I20 -> #DIV/0! | P20: -
B21: =IFERROR(D21/$D$23,"") -> 0.27389771 | C21: Gaming | D21: 6212 | E21: 6805 | F21: 5607 | K21: =(D21-E21)/E21 -> -0.087141807 | L21: =(E21-F21)/F21 -> 0.21366149 | M21: =(F21-G21)/G21 -> #DIV/0! | N21: =(G21-H21)/H21 -> #DIV/0! | O21: =(H21-I21)/I21 -> #DIV/0! | P21: -
B22: =IFERROR(D22/$D$23,"") -> 0.23461199 | C22: Embedded | D22: 5321 | E22: 4552 | F22: 246 | K22: =(D22-E22)/E22 -> 0.16893673 | L22: =(E22-F22)/F22 -> 17.504065 | M22: =(F22-G22)/G22 -> #DIV/0! | N22: =(G22-H22)/H22 -> #DIV/0! | O22: =(H22-I22)/I22 -> #DIV/0! | P22: -
B23: =SUM(B19:B22) -> 1 | C23: TOTAL | D23: =SUM(D19:D22) -> 22680 | E23: =SUM(E19:E22) -> 23601 | F23: =SUM(F19:F22) -> 16434 | G23: =G14 -> 9763 | H23: =H14 -> 6731 | I23: =I14 -> 6266 | K23: =(D23-E23)/E23 -> -0.03902377 | L23: =(E23-F23)/F23 -> 0.43610807 | M23: =(F23-G23)/G23 -> 0.68329407 | N23: =(G23-H23)/H23 -> 0.45045313 | O23: =(H23-I23)/I23 -> 0.074210022 | P23: -
B25: Categories | D25: Description | I25: Graphs
B26: Data Center | D26: Data Center segment offers products for data center market to address the computational, visual data processing and AI workload acceleration needs. Products are Server CPU, Data Center GPUs, FPGAs and Adaptive SoCs, and DPUs.
B27: Client | D27: Client segment offers CPUs and chipsets for computing platforms such as desktops, notebooks, and commercial PCs solutions.
B28: Gaming | D28: AMD produces GPUs and CPUs for gaming industry specifically adressing graphic improvements.
B29: Embedded | D29: The Embedded segment primarily includes embedded CPUs, GPUs, APUs, FPGAs, and Adaptive SoC products. Embedded products address specific computing needs in automotive, industrial, medical and 12 other markets.
B32: Industry | J32: Graphs (Industry Forecasts)
B33: Drivers | D33: Description
B34: Automative industry | D34: The automotive industry's increasing demand for chips, driven by electric vehicles and autonomous features, is a major force in the semiconductor sector. Semiconductors are essential for powering functions like sensors, connectivity systems, and advanced driver-assistance systems. Regulatory mandates for electric vehicle production and the trend towards vehicle electrification further propel this reliance on semiconductors. Consequently, automotive applications have become a crucial focus area for semiconductor companies, expected to drive significant revenue growth in the industry.
B35: AI Chips | D35: AI chips represent a key driver in the semiconductor industry, catering to the growing demand for artificial intelligence (AI) technologies across various sectors. These specialized chips are designed to optimize the performance of AI algorithms, enabling faster processing speeds and energy efficiency for tasks like machine learning, deep learning, and neural network computations. The increasing adoption of AI in applications such as data centers, autonomous vehicles, healthcare, and smart devices has fueled the demand for AI chips.
B36: Wireless Industries | D36: Semiconductors play a crucial role in enabling wireless communication technologies such as Wi-Fi, Bluetooth, cellular networks, and emerging standards like 5G. With the proliferation of mobile devices, smart homes, Internet of Things (IoT) devices, and the digitization of industries, the demand for wireless semiconductor solutions continues to grow.
B37: Cloud/Data Centers | D37: Semiconductors are essential components in the infrastructure of cloud computing and data centers, powering servers, networking equipment, storage devices, and other critical systems. As businesses and consumers rely more on cloud services for data storage, processing, and analytics, the demand for high-performance and energy-efficient semiconductor solutions continues to rise.
B38: Sales forecast
B39: Source | D39: Market Growth CAGR | G39: Period
B40: Statista | D40: 0.063 | G40: 2024-2027
B41: Precedence Research | D41: 0.0764 | G41: 2024-2033
B42: DataHorizzon Research | D42: 0.08 | G42: 2023-2032
B43: Average | D43: =AVERAGE(D40:F42) -> 0.073133333
B44: Company's Strategy / Extra Notes
B47: AMD's strategy is focused on five strategic pillars: extend leadership in foundational technology and IP, provide competitive software, tools and open-source enablement, re-use core technology across platforms to achieve economies of scale, build effective ecosystems with disciplined partnerships, and drive customer-centric go-to-market that leverages all of AMD’s capabilities. They understand the potential of AI and expect this part of their business to grow. AMD offers products that include capabilities to support AI deployment. With the acquisitions of Mipsology SAS and Nod, Inc. in 2023, they expanded their AI software capabilities to accelerate their AI growth strategy centered on an open software ecosystem to help lower the barriers of entry for customers through developer tools, libraries and models. Moreover, AMD develop software platforms that are used to enable high-performance products. These software platforms include development tools, compilers, and drivers for our CPUs, APUs, GPUs and FPGAs. They work closely with customers to define and develop customized solutions to precisely match their requirements. In other words, they focus on industry specific customer orientation.

Sheet Acuerdo
A1: Invertir
A2: NO invertir
A3: Mantener sin elevar posición
A4: Mantener (y seguir comprando)
A5: Liquidar
A6: PENDIENTE

Sheet Peers
B1: Peer Logo | C1: Peer Name | D1: Description
B2: #VALUE! | C2: #VALUE! | D2: Nvidia Corporation is an American multinational corporation and technology company headquartered in Santa Clara, California. It is a software and fabless company which designs and supplies GPUs, APIs for data science and high-performance computing as well as system on a chip unit for the mobile computing and automotive market. Nvidia is also a dominant supplier of artificial intelligence, hardware and software.
A3: Intel Corporation is an American multinational corporation and technology company headquartered in Santa Clara, California, and incorporated in Delaware.[3] Intel is one of the world's largest semiconductor chip manufacturers by revenue[4][5] and ranked in the Fortune 500 list of the largest United States corporations by revenue for nearly a decade, from 2007 to 2016 fiscal years, until it was removed from the ranking in 2018.[6] In 2020, it was reinstated and ranked 45th, being the 7th-largest technology company in the ranking. | B3: #VALUE! | C3: #VALUE! | D3: Intel Corporation is an American multinational corporation and technology company founded in 1968 headquartered in Santa Clara, California. Intel supplies microprocessors for most manufacturers of computer systems, and is one of the developers of the x86 series of instruction sets found in most personal computers (PCs). It also manufactures chipsets, network interface controllers, flash memory, GPUs, FPGAs, it has a strong presence in the high-performance general-purpose and gaming PC market.
A4: Intel supplies microprocessors for most manufacturers of computer systems, and is one of the developers of the x86 series of instruction sets found in most personal computers (PCs). It also manufactures chipsets, network interface controllers, flash memory, graphics processing units (GPUs), field-programmable gate arrays (FPGAs), and other devices related to communications and computing. Intel has a strong presence in the high-performance general-purpose and gaming PC market with its Intel Core line of CPUs, whose high-end models are among the fastest consumer CPUs, as well as its Intel Arc series of GPUs, and sponsors the Intel Extreme Masters, a series of international esports tournaments. The Open Source Technology Center at Intel hosts PowerTOP and LatencyTOP, and supports other open source projects such as Wayland, Mesa, Threading Building Blocks (TBB), and Xen.[7] | B4: #VALUE! | C4: #VALUE! | D4: Qualcomm Incorporated is an American multinational corporation headquartered in San Diego, California. It creates semiconductors, software, and services related to wireless technology. It owns patents critical to the 5G, 4G, CDMA2000, TD-SCDMA and WCDMA mobile communications standards. Over the years, Qualcomm has expanded into selling semiconductor products in a predominantly fabless manufacturing model. It also developed semiconductor components or software for vehicles, watches, laptops, wi-fi, smartphones, and other devices.
B6: In Millions USD | C6: =OP!E2 -> #VALUE! | D6: =C2 -> #VALUE! | E6: =C3 -> #VALUE! | F6: =C4 -> #VALUE! | G6: AVERAGE | H6: Deviation from Average
B7: Company Info | F7: =1113*F43 -> 138746.58 | G7: =IFERROR(AVERAGE(C7:F7),"") -> 138746.58 | K7: TRAFFIC
B8: Market Cap | C8: {=_FV(C6,"Market cap",TRUE)/1000000} -> 126410.59 | D8: =2500.75*D43 -> 240822.23 | E8: =4264*E43 -> 77306.32 | G8: =IFERROR(AVERAGE(C8:F8),"") -> 148179.71 | H8: =SQRT((C8-G8)^2) -> 21769.123 | L8: Best Value
B9: Net Sales (current) | C9: =C55 -> 22680 | D9: =D55 -> 60922 | E9: =E55 -> 54228 | F9: =F55 -> 35820 | G9: =IFERROR(AVERAGE(C9:F9),"") -> 43412.5 | H9: =SQRT((C9-G9)^2) -> 20732.5
B10: Profitability | G10: =IFERROR(AVERAGE(C10:F10),"") | L10: Important Value
B11: Sales Growth (ttm) | C11: =C55/C54-1 -> -0.03902377 | D11: =D55/D54-1 -> 1.2585453 | E11: =E55/E54-1 -> -0.13997526 | F11: =F55/F54-1 -> -0.18959276 | G11: =IFERROR(AVERAGE(C11:F11),"") -> 0.22248837 | H11: =SQRT((C11-G11)^2) -> 0.26151214
B12: Sales Growth (36m) | C12: =C55/C53-1 -> 1.3230564 | D12: =D55/D53-1 -> 2.6534933 | E12: =E55/E53-1 -> -0.30358175 | F12: =F55/F53-1 -> 0.52224725 | G12: =IFERROR(AVERAGE(C12:F12),"") -> 1.0488038 | H12: =SQRT((C12-G12)^2) -> 0.27425264 | L12: Worst Value
B13: Operating Margin | C13: =C59/C55 -> 0.017680776 | D13: =D59/D55 -> 0.54121664 | E13: =E59/E55 -> 0.0017149812 | F13: =F59/F55 -> 0.21742044 | G13: =IFERROR(AVERAGE(C13:F13),"") -> 0.19450821 | H13: =SQRT((C13-G13)^2) -> 0.17682743
B14: Net Income Margin | C14: =C62/C55 -> 0.037654321 | D14: =D62/D55 -> 0.48849348 | E14: =E62/E55 -> 0.030888102 | F14: =F62/F55 -> 0.20189838 | G14: =IFERROR(AVERAGE(C14:F14),"") -> 0.18973357 | H14: =SQRT((C14-G14)^2) -> 0.15207925
B15: Return on Equity (RoE) | C15: =C62/C75 -> 0.015279468 | D15: =D62/D75 -> 0.6924473 | E15: =E62/E75 -> 0.015232119 | F15: =F62/F75 -> 0.33510959 | G15: =IFERROR(AVERAGE(C15:F15),"") -> 0.26451712 | H15: =SQRT((C15-G15)^2) -> 0.24923765
B16: Return on Invested Capital (ROIC) | C16: =(1+C61/(C59+C60))*C59/(C74+C75-C66) -> 0.016072853 | D16: =(1+D61/(D59+D60))*D59/(D74+D75-D66) -> 0.79658424 | E16: =(1+E61/(E59+E60))*E59/(E74+E75-E66) -> -9.9665671e-05 | F16: =(1+F61/(F59+F60))*F59/(F74+F75-F66) -> 0.27490604 | G16: =IFERROR(AVERAGE(C16:F16),"") -> 0.27186587 | H16: =SQRT((C16-G16)^2) -> 0.25579302
B17: Solvency | G17: =IFERROR(AVERAGE(C17:F17),"")
B18: Debt/Assets | C18: =C74/C71 -> 0.03317375 | D18: =D74/D71 -> 0.16473953 | E18: =E74/E71 -> 0.25716702 | F18: =F74/F71 -> 0.30591693 | G18: =IFERROR(AVERAGE(C18:F18),"") -> 0.19024931 | H18: =SQRT((C18-G18)^2) -> 0.15707556
B19: Net Debt/EBITDA | C19: =(C74-C66)/C58 -> -0.43707748 | D19: =(D74-D66)/D58 -> 0.10290023 | E19: =(E74-E66)/E58 -> 5.3132242 | F19: =(F74-F66)/F58 -> 0.74648328 | G19: =IFERROR(AVERAGE(C19:F19),"") -> 1.4313826 | H19: =SQRT((C19-G19)^2) -> 1.86846
B20: Interest Coverage Ratio | C20: =-C58/C60 -> 36.283019 | D20: =-D58/D60 -> 134.16342 | E20: =-E58/E60 -> 9.0432802 | F20: =-F58/F60 -> 13.82853 | G20: =IFERROR(AVERAGE(C20:F20),"") -> 48.329563 | H20: =SQRT((C20-G20)^2) -> 12.046544
B21: Liquidity
B22: Current Ratio | C22: =C69/C73 -> 2.5068022 | D22: =D69/D73 -> 4.1712915 | E22: =E69/E73 -> 1.5424019 | F22: =F69/F73 -> 2.3331948 | G22: =IFERROR(AVERAGE(C22:F22),"") -> 2.6384226 | H22: =SQRT((C22-G22)^2) -> 0.1316204
B23: Quick Ratio | C23: =(C66+C67)/C73 -> 1.3916878 | D23: =(D66+D67)/D73 -> 1.625341 | E23: =(E66+E67)/E73 -> 0.37361423 | F23: =(F66+F67)/F73 -> 1.2082468 | G23: =IFERROR(AVERAGE(C23:F23),"") -> 1.1497225 | H23: =SQRT((C23-G23)^2) -> 0.24196539
B24: Activity | G24: =IFERROR(AVERAGE(C24:F24),"")
B25: Inventory Turnover | C25: =C56/C68 -> 2.8085498 | D25: =D56/D68 -> 3.1467247 | E25: =E56/E68 -> 2.922351 | F25: =F56/F68 -> 2.4710371 | G25: =IFERROR(AVERAGE(C25:F25),"") -> 2.8371656 | H25: =SQRT((C25-G25)^2) -> 0.028615887
B26: Acc. Receivable Turnover | C26: =C55/C67 -> 4.21875 | D26: =D55/D67 -> 6.0928093 | E26: =E55/E67 -> 15.940035 | F26: =F55/F67 -> 11.253534 | G26: =IFERROR(AVERAGE(C26:F26),"") -> 9.3762822 | H26: =SQRT((C26-G26)^2) -> 5.1575322
A27: Price/Sales | B27: Payables Turnover | C27: =C56/C72 -> 5.0537634 | D27: =D56/D72 -> 6.1582067 | E27: =E56/E72 -> 3.7907438 | F27: =F56/F72 -> 8.2996862 | G27: =IFERROR(AVERAGE(C27:F27),"") -> 5.8256 | H27: =SQRT((C27-G27)^2) -> 0.77183659
B28: Fixed Asset Turnover | C28: =C55/C70 -> 14.273128 | D28: =D55/D70 -> 15.565151 | E28: =E55/E70 -> 0.56109346 | F28: =F55/F70 -> 7.1043237 | G28: =IFERROR(AVERAGE(C28:F28),"") -> 9.3759239 | H28: =SQRT((C28-G28)^2) -> 4.8972038
B29: Total Asset Turnover | C29: =C55/C71 -> 0.33409442 | D29: =D55/D71 -> 0.92688048 | E29: =E55/E71 -> 0.28306851 | F29: =F55/F71 -> 0.70180251 | G29: =IFERROR(AVERAGE(C29:F29),"") -> 0.56146148 | H29: =SQRT((C29-G29)^2) -> 0.22736705
B30: Valuation | G30: =IFERROR(AVERAGE(C30:F30),"")
B31: Price/Earnings | C31: =C8/C62 -> 148.02177 | D31: =D8/D62 -> 8.0921447 | E31: =E8/E62 -> 46.153027 | F31: =F7/F62 -> 19.185091 | G31: =IFERROR(AVERAGE(C31:F31),"") -> 55.363007 | H31: =SQRT((C31-G31)^2) -> 92.658759
B32: Price/Sales | C32: =C8/C55 -> 5.5736591 | D32: =D8/D55 -> 3.9529599 | E32: =E8/E55 -> 1.4255794 | F32: =F7/F55 -> 3.8734389 | G32: =IFERROR(AVERAGE(C32:F32),"") -> 3.7064093 | H32: =SQRT((C32-G32)^2) -> 1.8672498
B33: Price/Book | C33: =C8/C75 -> 2.2616938 | D33: =D8/D75 -> 5.6033837 | E33: =E8/E75 -> 0.70300841 | F33: =F7/F75 -> 6.429108 | G33: =IFERROR(AVERAGE(C33:F33),"") -> 3.7492985 | H33: =SQRT((C33-G33)^2) -> 1.4876047
B34: EV/Sales | C34: =(C74+C8-C66)/C55 -> 5.4995409 | D34: =(D74+D8-D66)/D55 -> 4.0111983 | E34: =(E74+E8-E66)/E55 -> 2.2035354 | F34: =(F74+F7-F66)/F55 -> 4.0734389 | G34: =IFERROR(AVERAGE(C34:F34),"") -> 3.9469284 | H34: =SQRT((C34-G34)^2) -> 1.5526125
B35: EV/EBITDA | C35: =(C74+C8-C66)/C58 -> 32.43099 | D35: =(D74+D8-D66)/D58 -> 7.0873035 | E35: =(E74+E8-E66)/E58 -> 15.049537 | F35: =(F74+F7-F66)/F58 -> 15.20377 | G35: =IFERROR(AVERAGE(C35:F35),"") -> 17.4429 | H35: =SQRT((C35-G35)^2) -> 14.98809
B36: Stock Info | G36: =IFERROR(AVERAGE(C36:F36),"")
B37: Float | C37: =1.6/1.62 -> 0.98765432 | D37: =2.4/2.5 -> 0.96 | E37: =4.22/4.26 -> 0.99061033 | F37: =1.11/1.12 -> 0.99107143 | G37: =IFERROR(AVERAGE(C37:F37),"") -> 0.98233402 | H37: =SQRT((C37-G37)^2) -> 0.0053203014
B38: b (Yahoo) | C38: 1.63 | D38: 1.74 | E38: 1.01 | F38: 1.34 | G38: =IFERROR(AVERAGE(C38:F38),"") -> 1.43 | H38: =SQRT((C38-G38)^2) -> 0.2
B39: Dividend Yield (yahoo finance) | C39: =OP!M32 -> 0 | D39: 0.0002 | E39: 0.0211 | F39: 0.02 | G39: =IFERROR(AVERAGE(C39:F39),"") -> 0.010325 | H39: =SQRT((C39-G39)^2) -> 0.010325
B40: Stock Performance
B41: 1y | C41: =(C43-87.44)/87.44 -> -0.1055581 | D41: =(D43-272.26)/272.26 -> -0.64629398 | E41: =(E43-29.86)/29.86 -> -0.39283322 | F41: =(F43-113.92)/113.92 -> 0.094276685 | G41: =IFERROR(AVERAGE(C41:F41),"") -> -0.26260215 | H41: =SQRT((C41-G41)^2) -> 0.15704406
...

Sheet SARD
F1: Variables | K1: Rankings | P1: Difference | U1: Results | Y1: Additional Information | AD1: =B3 -> 0 | AE1: Selected Peers | AJ1: Price Multiples (TTM) | AM1: Enterprise Value Multiples (TTM)
B2: Ticker | C2: Company Name | D2: TRBC Industry | E2: Country | F2: ROE | G2: DEBT/EBIT | H2: Market Cap | I2: EPS Growth (2019-2023) (Refinitiv Smart Estimate) | J2: EBIT Margin | K2: ROE | L2: DEBT/EBIT | M2: Market Cap | N2: EPS Growth | O2: EBIT Margin | P2: ROE | Q2: DEBT/EBIT | R2: Market Cap | S2: EPS Growth | T2: EBIT Margin | U2: SARD Result | V2: SARD Peers | W2: SARD Peers adjusted Rank | Y2: Suitability | Z2: Relevant Information Missing | AA2: Author's Override | AB2: Observations | AE2: SARD Peers adjusted Rank | AF2: SARD Result | AG2: Ticker | AH2: Company Name | AI2: Country | AJ2: P / E | AK2: P / B | AL2: Price / Sales | AM2: EV / Sales | AN2: EV / EBITDA
A3: Benchmark | K3: =IFERROR(_xlfn.RANK.EQ(F3,F$3:F$61),"N/A") -> N/A | L3: =IFERROR(_xlfn.RANK.EQ(G3,G$3:G$61),"N/A") -> N/A | M3: =IFERROR(_xlfn.RANK.EQ(H3,H$3:H$61),"N/A") -> N/A | N3: =IFERROR(_xlfn.RANK.EQ(I3,I$3:I$61),"N/A") -> N/A | O3: =IFERROR(_xlfn.RANK.EQ(J3,J$3:J$61),"N/A") -> N/A | P3: - | Q3: - | R3: - | S3: - | T3: - | U3: - | V3: - | W3: - | Y3: =IF(OR(Z3="Y",AA3="Y"),"Not suitable","") -> Not suitable | Z3: =IF(N3="N/A","Y","") -> Y | AE3: {=_xlfn._xlws.SORT(_xlfn._xlws.FILTER(SARD!W3:W61,SARD!W3:W61<=SMALL(W3:W61,6)),,1)} -> #NUM! | AF3: =_xlfn.XLOOKUP($AE3,$W:$W,U:U,,0) -> #NUM! | AG3: =_xlfn.XLOOKUP($AE3,$W:$W,B:B,,0) -> #NUM! | AH3: =_xlfn.XLOOKUP($AE3,$W:$W,C:C,,0) -> #NUM! | AI3: =_xlfn.XLOOKUP($AE3,$W:$W,E:E,,0) -> #NUM!
A4: Comparison | K4: =IFERROR(_xlfn.RANK.EQ(F4,F$3:F$61),"N/A") -> N/A | L4: =IFERROR(_xlfn.RANK.EQ(G4,G$3:G$61),"N/A") -> N/A | M4: =IFERROR(_xlfn.RANK.EQ(H4,H$3:H$61),"N/A") -> N/A | N4: =IFERROR(_xlfn.RANK.EQ(I4,I$3:I$61),"N/A") -> N/A | O4: =IFERROR(_xlfn.RANK.EQ(J4,J$3:J$61),"N/A") -> N/A | P4: =IFERROR(ABS(K$3-K4),"N/A") -> N/A | Q4: =IFERROR(ABS(L$3-L4),"N/A") -> N/A | R4: =IFERROR(ABS(M$3-M4),"N/A") -> N/A | S4: =IFERROR(ABS(N$3-N4),"N/A") -> N/A | T4: =IFERROR(ABS(O$3-O4),"N/A") -> N/A | U4: =SUM(P4:T4) -> 0 | V4: =_xlfn.RANK.EQ(U4,$U$4:$U$61,1) -> 1 | W4: =IF(Y4="Not suitable","-",V4) -> - | Y4: =IF(OR(Z4="Y",AA4="Y"),"Not suitable","") -> Not suitable | Z4: =IF(N4="N/A","Y","") -> Y | AF4: =_xlfn.XLOOKUP($AE4,$W:$W,U:U,,0) -> Results | AG4: =_xlfn.XLOOKUP($AE4,$W:$W,B:B,,0) -> 0 | AH4: =_xlfn.XLOOKUP($AE4,$W:$W,C:C,,0) -> 0 | AI4: =_xlfn.XLOOKUP($AE4,$W:$W,E:E,,0) -> 0
K5: =IFERROR(_xlfn.RANK.EQ(F5,F$3:F$61),"N/A") -> N/A | L5: =IFERROR(_xlfn.RANK.EQ(G5,G$3:G$61),"N/A") -> N/A | M5: =IFERROR(_xlfn.RANK.EQ(H5,H$3:H$61),"N/A") -> N/A | N5: =IFERROR(_xlfn.RANK.EQ(I5,I$3:I$61),"N/A") -> N/A | O5: =IFERROR(_xlfn.RANK.EQ(J5,J$3:J$61),"N/A") -> N/A | P5: =IFERROR(ABS(K$3-K5),"N/A") -> N/A | Q5: =IFERROR(ABS(L$3-L5),"N/A") -> N/A | R5: =IFERROR(ABS(M$3-M5),"N/A") -> N/A | S5: =IFERROR(ABS(N$3-N5),"N/A") -> N/A | T5: =IFERROR(ABS(O$3-O5),"N/A") -> N/A | U5: =SUM(P5:T5) -> 0 | V5: =_xlfn.RANK.EQ(U5,$U$4:$U$61,1) -> 1 | W5: =IF(Y5="Not suitable","-",V5) -> - | Y5: =IF(OR(Z5="Y",AA5="Y"),"Not suitable","") -> Not suitable | Z5: =IF(N5="N/A","Y","") -> Y | AF5: =_xlfn.XLOOKUP($AE5,$W:$W,U:U,,0) -> Results | AG5: =_xlfn.XLOOKUP($AE5,$W:$W,B:B,,0) -> 0 | AH5: =_xlfn.XLOOKUP($AE5,$W:$W,C:C,,0) -> 0 | AI5: =_xlfn.XLOOKUP($AE5,$W:$W,E:E,,0) -> 0
K6: =IFERROR(_xlfn.RANK.EQ(F6,F$3:F$61),"N/A") -> N/A | L6: =IFERROR(_xlfn.RANK.EQ(G6,G$3:G$61),"N/A") -> N/A | M6: =IFERROR(_xlfn.RANK.EQ(H6,H$3:H$61),"N/A") -> N/A | N6: =IFERROR(_xlfn.RANK.EQ(I6,I$3:I$61),"N/A") -> N/A | O6: =IFERROR(_xlfn.RANK.EQ(J6,J$3:J$61),"N/A") -> N/A | P6: =IFERROR(ABS(K$3-K6),"N/A") -> N/A | Q6: =IFERROR(ABS(L$3-L6),"N/A") -> N/A | R6: =IFERROR(ABS(M$3-M6),"N/A") -> N/A | S6: =IFERROR(ABS(N$3-N6),"N/A") -> N/A | T6: =IFERROR(ABS(O$3-O6),"N/A") -> N/A | U6: =SUM(P6:T6) -> 0 | V6: =_xlfn.RANK.EQ(U6,$U$4:$U$61,1) -> 1 | W6: =IF(Y6="Not suitable","-",V6) -> - | Y6: =IF(OR(Z6="Y",AA6="Y"),"Not suitable","") -> Not suitable | Z6: =IF(N6="N/A","Y","") -> Y | AF6: =_xlfn.XLOOKUP($AE6,$W:$W,U:U,,0) -> Results | AG6: =_xlfn.XLOOKUP($AE6,$W:$W,B:B,,0) -> 0 | AH6: =_xlfn.XLOOKUP($AE6,$W:$W,C:C,,0) -> 0 | AI6: =_xlfn.XLOOKUP($AE6,$W:$W,E:E,,0) -> 0
K7: =IFERROR(_xlfn.RANK.EQ(F7,F$3:F$61),"N/A") -> N/A | L7: =IFERROR(_xlfn.RANK.EQ(G7,G$3:G$61),"N/A") -> N/A | M7: =IFERROR(_xlfn.RANK.EQ(H7,H$3:H$61),"N/A") -> N/A | N7: =IFERROR(_xlfn.RANK.EQ(I7,I$3:I$61),"N/A") -> N/A | O7: =IFERROR(_xlfn.RANK.EQ(J7,J$3:J$61),"N/A") -> N/A | P7: =IFERROR(ABS(K$3-K7),"N/A") -> N/A | Q7: =IFERROR(ABS(L$3-L7),"N/A") -> N/A | R7: =IFERROR(ABS(M$3-M7),"N/A") -> N/A | S7: =IFERROR(ABS(N$3-N7),"N/A") -> N/A | T7: =IFERROR(ABS(O$3-O7),"N/A") -> N/A | U7: =SUM(P7:T7) -> 0 | V7: =_xlfn.RANK.EQ(U7,$U$4:$U$61,1) -> 1 | W7: =IF(Y7="Not suitable","-",V7) -> - | Y7: =IF(OR(Z7="Y",AA7="Y"),"Not suitable","") -> Not suitable | Z7: =IF(N7="N/A","Y","") -> Y | AF7: =_xlfn.XLOOKUP($AE7,$W:$W,U:U,,0) -> Results | AG7: =_xlfn.XLOOKUP($AE7,$W:$W,B:B,,0) -> 0 | AH7: =_xlfn.XLOOKUP($AE7,$W:$W,C:C,,0) -> 0 | AI7: =_xlfn.XLOOKUP($AE7,$W:$W,E:E,,0) -> 0
K8: =IFERROR(_xlfn.RANK.EQ(F8,F$3:F$61),"N/A") -> N/A | L8: =IFERROR(_xlfn.RANK.EQ(G8,G$3:G$61),"N/A") -> N/A | M8: =IFERROR(_xlfn.RANK.EQ(H8,H$3:H$61),"N/A") -> N/A | N8: =IFERROR(_xlfn.RANK.EQ(I8,I$3:I$61),"N/A") -> N/A | O8: =IFERROR(_xlfn.RANK.EQ(J8,J$3:J$61),"N/A") -> N/A | P8: =IFERROR(ABS(K$3-K8),"N/A") -> N/A | Q8: =IFERROR(ABS(L$3-L8),"N/A") -> N/A | R8: =IFERROR(ABS(M$3-M8),"N/A") -> N/A | S8: =IFERROR(ABS(N$3-N8),"N/A") -> N/A | T8: =IFERROR(ABS(O$3-O8),"N/A") -> N/A | U8: =SUM(P8:T8) -> 0 | V8: =_xlfn.RANK.EQ(U8,$U$4:$U$61,1) -> 1 | W8: =IF(Y8="Not suitable","-",V8) -> - | Y8: =IF(OR(Z8="Y",AA8="Y"),"Not suitable","") -> Not suitable | Z8: =IF(N8="N/A","Y","") -> Y | AF8: =_xlfn.XLOOKUP($AE8,$W:$W,U:U,,0) -> Results | AG8: =_xlfn.XLOOKUP($AE8,$W:$W,B:B,,0) -> 0 | AH8: =_xlfn.XLOOKUP($AE8,$W:$W,C:C,,0) -> 0 | AI8: =_xlfn.XLOOKUP($AE8,$W:$W,E:E,,0) -> 0
K9: =IFERROR(_xlfn.RANK.EQ(F9,F$3:F$61),"N/A") -> N/A | L9: =IFERROR(_xlfn.RANK.EQ(G9,G$3:G$61),"N/A") -> N/A | M9: =IFERROR(_xlfn.RANK.EQ(H9,H$3:H$61),"N/A") -> N/A | N9: =IFERROR(_xlfn.RANK.EQ(I9,I$3:I$61),"N/A") -> N/A | O9: =IFERROR(_xlfn.RANK.EQ(J9,J$3:J$61),"N/A") -> N/A | P9: =IFERROR(ABS(K$3-K9),"N/A") -> N/A | Q9: =IFERROR(ABS(L$3-L9),"N/A") -> N/A | R9: =IFERROR(ABS(M$3-M9),"N/A") -> N/A | S9: =IFERROR(ABS(N$3-N9),"N/A") -> N/A | T9: =IFERROR(ABS(O$3-O9),"N/A") -> N/A | U9: =SUM(P9:T9) -> 0 | V9: =_xlfn.RANK.EQ(U9,$U$4:$U$61,1) -> 1 | W9: =IF(Y9="Not suitable","-",V9) -> - | Y9: =IF(OR(Z9="Y",AA9="Y"),"Not suitable","") -> Not suitable | Z9: =IF(N9="N/A","Y","") -> Y | AE9: Median | AJ9: =MEDIAN(AJ3:AJ8) -> #NUM! | AK9: =MEDIAN(AK3:AK8) -> #NUM! | AL9: =MEDIAN(AL3:AL8) -> #NUM! | AM9: =MEDIAN(AM3:AM8) -> #NUM! | AN9: =MEDIAN(AN3:AN8) -> #NUM!
K10: =IFERROR(_xlfn.RANK.EQ(F10,F$3:F$61),"N/A") -> N/A | L10: =IFERROR(_xlfn.RANK.EQ(G10,G$3:G$61),"N/A") -> N/A | M10: =IFERROR(_xlfn.RANK.EQ(H10,H$3:H$61),"N/A") -> N/A | N10: =IFERROR(_xlfn.RANK.EQ(I10,I$3:I$61),"N/A") -> N/A | O10: =IFERROR(_xlfn.RANK.EQ(J10,J$3:J$61),"N/A") -> N/A | P10: =IFERROR(ABS(K$3-K10),"N/A") -> N/A | Q10: =IFERROR(ABS(L$3-L10),"N/A") -> N/A | R10: =IFERROR(ABS(M$3-M10),"N/A") -> N/A | S10: =IFERROR(ABS(N$3-N10),"N/A") -> N/A | T10: =IFERROR(ABS(O$3-O10),"N/A") -> N/A | U10: =SUM(P10:T10) -> 0 | V10: =_xlfn.RANK.EQ(U10,$U$4:$U$61,1) -> 1 | W10: =IF(Y10="Not suitable","-",V10) -> - | Y10: =IF(OR(Z10="Y",AA10="Y"),"Not suitable","") -> Not suitable | Z10: =IF(N10="N/A","Y","") -> Y | AE10: Benchmark Data | AJ10: Price / Share
K11: =IFERROR(_xlfn.RANK.EQ(F11,F$3:F$61),"N/A") -> N/A | L11: =IFERROR(_xlfn.RANK.EQ(G11,G$3:G$61),"N/A") -> N/A | M11: =IFERROR(_xlfn.RANK.EQ(H11,H$3:H$61),"N/A") -> N/A | N11: =IFERROR(_xlfn.RANK.EQ(I11,I$3:I$61),"N/A") -> N/A | O11: =IFERROR(_xlfn.RANK.EQ(J11,J$3:J$61),"N/A") -> N/A | P11: =IFERROR(ABS(K$3-K11),"N/A") -> N/A | Q11: =IFERROR(ABS(L$3-L11),"N/A") -> N/A | R11: =IFERROR(ABS(M$3-M11),"N/A") -> N/A | S11: =IFERROR(ABS(N$3-N11),"N/A") -> N/A | T11: =IFERROR(ABS(O$3-O11),"N/A") -> N/A | U11: =SUM(P11:T11) -> 0 | V11: =_xlfn.RANK.EQ(U11,$U$4:$U$61,1) -> 1 | W11: =IF(Y11="Not suitable","-",V11) -> - | Y11: =IF(OR(Z11="Y",AA11="Y"),"Not suitable","") -> Not suitable | Z11: =IF(N11="N/A","Y","") -> Y | AE11: Benchmark | AF11: Multiplier | AG11: # Shares | AH11: -Debt + Cash | AJ11: P / E | AK11: P / B | AL11: Price / Sales | AM11: EV / Sales | AN11: EV / EBITDA
K12: =IFERROR(_xlfn.RANK.EQ(F12,F$3:F$61),"N/A") -> N/A | L12: =IFERROR(_xlfn.RANK.EQ(G12,G$3:G$61),"N/A") -> N/A | M12: =IFERROR(_xlfn.RANK.EQ(H12,H$3:H$61),"N/A") -> N/A | N12: =IFERROR(_xlfn.RANK.EQ(I12,I$3:I$61),"N/A") -> N/A | O12: =IFERROR(_xlfn.RANK.EQ(J12,J$3:J$61),"N/A") -> N/A | P12: =IFERROR(ABS(K$3-K12),"N/A") -> N/A | Q12: =IFERROR(ABS(L$3-L12),"N/A") -> N/A | R12: =IFERROR(ABS(M$3-M12),"N/A") -> N/A | S12: =IFERROR(ABS(N$3-N12),"N/A") -> N/A | T12: =IFERROR(ABS(O$3-O12),"N/A") -> N/A | U12: =SUM(P12:T12) -> 0 | V12: =_xlfn.RANK.EQ(U12,$U$4:$U$61,1) -> 1 | W12: =IF(Y12="Not suitable","-",V12) -> - | Y12: =IF(OR(Z12="Y",AA12="Y"),"Not suitable","") -> Not suitable | Z12: =IF(N12="N/A","Y","") -> Y | AE12: =C3 -> 0 | AF12: 1000000 | AG12: =OP!C21 -> 1616297000 | AH12: =-'Fin. Data'!B58*SARD!AF12+'Fin. Data'!B39*SARD!AF12 -> 1681000000 | AJ12: =AJ9*'Fin. Data'!B23*AF$12/AG$12 -> #NUM! | AK12: =AK9*'Fin. Data'!B64*AF$12/AG$12 -> #NUM! | AL12: =AL9*'Fin. Data'!B5*AF$12/AG$12 -> #NUM! | AM12: =(AM9*'Fin. Data'!B5*$AF12+$AH12)/$AG12 -> #NUM! | AN12: =(AN9*'Fin. Data'!B19*$AF12+$AH12)/$AG12 -> #NUM!
K13: =IFERROR(_xlfn.RANK.EQ(F13,F$3:F$61),"N/A") -> N/A | L13: =IFERROR(_xlfn.RANK.EQ(G13,G$3:G$61),"N/A") -> N/A | M13: =IFERROR(_xlfn.RANK.EQ(H13,H$3:H$61),"N/A") -> N/A | N13: =IFERROR(_xlfn.RANK.EQ(I13,I$3:I$61),"N/A") -> N/A | O13: =IFERROR(_xlfn.RANK.EQ(J13,J$3:J$61),"N/A") -> N/A | P13: =IFERROR(ABS(K$3-K13),"N/A") -> N/A | Q13: =IFERROR(ABS(L$3-L13),"N/A") -> N/A | R13: =IFERROR(ABS(M$3-M13),"N/A") -> N/A | S13: =IFERROR(ABS(N$3-N13),"N/A") -> N/A | T13: =IFERROR(ABS(O$3-O13),"N/A") -> N/A | U13: =SUM(P13:T13) -> 0 | V13: =_xlfn.RANK.EQ(U13,$U$4:$U$61,1) -> 1 | W13: =IF(Y13="Not suitable","-",V13) -> - | Y13: =IF(OR(Z13="Y",AA13="Y"),"Not suitable","") -> Not suitable | Z13: =IF(N13="N/A","Y","") -> Y | AE13: By Consolidated Average | AJ13: =AVERAGE(AJ12:AL12) -> #NUM! | AM13: =AVERAGE(AM12:AN12) -> #NUM!
K14: =IFERROR(_xlfn.RANK.EQ(F14,F$3:F$61),"N/A") -> N/A | L14: =IFERROR(_xlfn.RANK.EQ(G14,G$3:G$61),"N/A") -> N/A | M14: =IFERROR(_xlfn.RANK.EQ(H14,H$3:H$61),"N/A") -> N/A | N14: =IFERROR(_xlfn.RANK.EQ(I14,I$3:I$61),"N/A") -> N/A | O14: =IFERROR(_xlfn.RANK.EQ(J14,J$3:J$61),"N/A") -> N/A | P14: =IFERROR(ABS(K$3-K14),"N/A") -> N/A | Q14: =IFERROR(ABS(L$3-L14),"N/A") -> N/A | R14: =IFERROR(ABS(M$3-M14),"N/A") -> N/A | S14: =IFERROR(ABS(N$3-N14),"N/A") -> N/A | T14: =IFERROR(ABS(O$3-O14),"N/A") -> N/A | U14: =SUM(P14:T14) -> 0 | V14: =_xlfn.RANK.EQ(U14,$U$4:$U$61,1) -> 1 | W14: =IF(Y14="Not suitable","-",V14) -> - | Y14: =IF(OR(Z14="Y",AA14="Y"),"Not suitable","") -> Not suitable | Z14: =IF(N14="N/A","Y","") -> Y | AE14: Upside | AJ14: =AJ13/OP!C20-1 -> #NUM! | AM14: =AM13/OP!C20-1 -> #NUM!
K15: =IFERROR(_xlfn.RANK.EQ(F15,F$3:F$61),"N/A") -> N/A | L15: =IFERROR(_xlfn.RANK.EQ(G15,G$3:G$61),"N/A") -> N/A | M15: =IFERROR(_xlfn.RANK.EQ(H15,H$3:H$61),"N/A") -> N/A | N15: =IFERROR(_xlfn.RANK.EQ(I15,I$3:I$61),"N/A") -> N/A | O15: =IFERROR(_xlfn.RANK.EQ(J15,J$3:J$61),"N/A") -> N/A | P15: =IFERROR(ABS(K$3-K15),"N/A") -> N/A | Q15: =IFERROR(ABS(L$3-L15),"N/A") -> N/A | R15: =IFERROR(ABS(M$3-M15),"N/A") -> N/A | S15: =IFERROR(ABS(N$3-N15),"N/A") -> N/A | T15: =IFERROR(ABS(O$3-O15),"N/A") -> N/A | U15: =SUM(P15:T15) -> 0 | V15: =_xlfn.RANK.EQ(U15,$U$4:$U$61,1) -> 1 | W15: =IF(Y15="Not suitable","-",V15) -> - | Y15: =IF(OR(Z15="Y",AA15="Y"),"Not suitable","") -> Not suitable | Z15: =IF(N15="N/A","Y","") -> Y
K16: =IFERROR(_xlfn.RANK.EQ(F16,F$3:F$61),"N/A") -> N/A | L16: =IFERROR(_xlfn.RANK.EQ(G16,G$3:G$61),"N/A") -> N/A | M16: =IFERROR(_xlfn.RANK.EQ(H16,H$3:H$61),"N/A") -> N/A | N16: =IFERROR(_xlfn.RANK.EQ(I16,I$3:I$61),"N/A") -> N/A | O16: =IFERROR(_xlfn.RANK.EQ(J16,J$3:J$61),"N/A") -> N/A | P16: =IFERROR(ABS(K$3-K16),"N/A") -> N/A | Q16: =IFERROR(ABS(L$3-L16),"N/A") -> N/A | R16: =IFERROR(ABS(M$3-M16),"N/A") -> N/A | S16: =IFERROR(ABS(N$3-N16),"N/A") -> N/A | T16: =IFERROR(ABS(O$3-O16),"N/A") -> N/A | U16: =SUM(P16:T16) -> 0 | V16: =_xlfn.RANK.EQ(U16,$U$4:$U$61,1) -> 1 | W16: =IF(Y16="Not suitable","-",V16) -> - | Y16: =IF(OR(Z16="Y",AA16="Y"),"Not suitable","") -> Not suitable | Z16: =IF(N16="N/A","Y","") -> Y
K17: =IFERROR(_xlfn.RANK.EQ(F17,F$3:F$61),"N/A") -> N/A | L17: =IFERROR(_xlfn.RANK.EQ(G17,G$3:G$61),"N/A") -> N/A | M17: =IFERROR(_xlfn.RANK.EQ(H17,H$3:H$61),"N/A") -> N/A | N17: =IFERROR(_xlfn.RANK.EQ(I17,I$3:I$61),"N/A") -> N/A | O17: =IFERROR(_xlfn.RANK.EQ(J17,J$3:J$61),"N/A") -> N/A | P17: =IFERROR(ABS(K$3-K17),"N/A") -> N/A | Q17: =IFERROR(ABS(L$3-L17),"N/A") -> N/A | R17: =IFERROR(ABS(M$3-M17),"N/A") -> N/A | S17: =IFERROR(ABS(N$3-N17),"N/A") -> N/A | T17: =IFERROR(ABS(O$3-O17),"N/A") -> N/A | U17: =SUM(P17:T17) -> 0 | V17: =_xlfn.RANK.EQ(U17,$U$4:$U$61,1) -> 1 | W17: =IF(Y17="Not suitable","-",V17) -> - | Y17: =IF(OR(Z17="Y",AA17="Y"),"Not suitable","") -> Not suitable | Z17: =IF(N17="N/A","Y","") -> Y
K18: =IFERROR(_xlfn.RANK.EQ(F18,F$3:F$61),"N/A") -> N/A | L18: =IFERROR(_xlfn.RANK.EQ(G18,G$3:G$61),"N/A") -> N/A | M18: =IFERROR(_xlfn.RANK.EQ(H18,H$3:H$61),"N/A") -> N/A | N18: =IFERROR(_xlfn.RANK.EQ(I18,I$3:I$61),"N/A") -> N/A | O18: =IFERROR(_xlfn.RANK.EQ(J18,J$3:J$61),"N/A") -> N/A | P18: =IFERROR(ABS(K$3-K18),"N/A") -> N/A | Q18: =IFERROR(ABS(L$3-L18),"N/A") -> N/A | R18: =IFERROR(ABS(M$3-M18),"N/A") -> N/A | S18: =IFERROR(ABS(N$3-N18),"N/A") -> N/A | T18: =IFERROR(ABS(O$3-O18),"N/A") -> N/A | U18: =SUM(P18:T18) -> 0 | V18: =_xlfn.RANK.EQ(U18,$U$4:$U$61,1) -> 1 | W18: =IF(Y18="Not suitable","-",V18) -> - | Y18: =IF(OR(Z18="Y",AA18="Y"),"Not suitable","") -> Not suitable | Z18: =IF(N18="N/A","Y","") -> Y
K19: =IFERROR(_xlfn.RANK.EQ(F19,F$3:F$61),"N/A") -> N/A | L19: =IFERROR(_xlfn.RANK.EQ(G19,G$3:G$61),"N/A") -> N/A | M19: =IFERROR(_xlfn.RANK.EQ(H19,H$3:H$61),"N/A") -> N/A | N19: =IFERROR(_xlfn.RANK.EQ(I19,I$3:I$61),"N/A") -> N/A | O19: =IFERROR(_xlfn.RANK.EQ(J19,J$3:J$61),"N/A") -> N/A | P19: =IFERROR(ABS(K$3-K19),"N/A") -> N/A | Q19: =IFERROR(ABS(L$3-L19),"N/A") -> N/A | R19: =IFERROR(ABS(M$3-M19),"N/A") -> N/A | S19: =IFERROR(ABS(N$3-N19),"N/A") -> N/A | T19: =IFERROR(ABS(O$3-O19),"N/A") -> N/A | U19: =SUM(P19:T19) -> 0 | V19: =_xlfn.RANK.EQ(U19,$U$4:$U$61,1) -> 1 | W19: =IF(Y19="Not suitable","-",V19) -> - | Y19: =IF(OR(Z19="Y",AA19="Y"),"Not suitable","") -> Not suitable | Z19: =IF(N19="N/A","Y","") -> Y
K20: =IFERROR(_xlfn.RANK.EQ(F20,F$3:F$61),"N/A") -> N/A | L20: =IFERROR(_xlfn.RANK.EQ(G20,G$3:G$61),"N/A") -> N/A | M20: =IFERROR(_xlfn.RANK.EQ(H20,H$3:H$61),"N/A") -> N/A | N20: =IFERROR(_xlfn.RANK.EQ(I20,I$3:I$61),"N/A") -> N/A | O20: =IFERROR(_xlfn.RANK.EQ(J20,J$3:J$61),"N/A") -> N/A | P20: =IFERROR(ABS(K$3-K20),"N/A") -> N/A | Q20: =IFERROR(ABS(L$3-L20),"N/A") -> N/A | R20: =IFERROR(ABS(M$3-M20),"N/A") -> N/A | S20: =IFERROR(ABS(N$3-N20),"N/A") -> N/A | T20: =IFERROR(ABS(O$3-O20),"N/A") -> N/A | U20: =SUM(P20:T20) -> 0 | V20: =_xlfn.RANK.EQ(U20,$U$4:$U$61,1) -> 1 | W20: =IF(Y20="Not suitable","-",V20) -> - | Y20: =IF(OR(Z20="Y",AA20="Y"),"Not suitable","") -> Not suitable | Z20: =IF(N20="N/A","Y","") -> Y
K21: =IFERROR(_xlfn.RANK.EQ(F21,F$3:F$61),"N/A") -> N/A | L21: =IFERROR(_xlfn.RANK.EQ(G21,G$3:G$61),"N/A") -> N/A | M21: =IFERROR(_xlfn.RANK.EQ(H21,H$3:H$61),"N/A") -> N/A | N21: =IFERROR(_xlfn.RANK.EQ(I21,I$3:I$61),"N/A") -> N/A | O21: =IFERROR(_xlfn.RANK.EQ(J21,J$3:J$61),"N/A") -> N/A | P21: =IFERROR(ABS(K$3-K21),"N/A") -> N/A | Q21: =IFERROR(ABS(L$3-L21),"N/A") -> N/A | R21: =IFERROR(ABS(M$3-M21),"N/A") -> N/A | S21: =IFERROR(ABS(N$3-N21),"N/A") -> N/A | T21: =IFERROR(ABS(O$3-O21),"N/A") -> N/A | U21: =SUM(P21:T21) -> 0 | V21: =_xlfn.RANK.EQ(U21,$U$4:$U$61,1) -> 1 | W21: =IF(Y21="Not suitable","-",V21) -> - | Y21: =IF(OR(Z21="Y",AA21="Y"),"Not suitable","") -> Not suitable | Z21: =IF(N21="N/A","Y","") -> Y
K22: =IFERROR(_xlfn.RANK.EQ(F22,F$3:F$61),"N/A") -> N/A | L22: =IFERROR(_xlfn.RANK.EQ(G22,G$3:G$61),"N/A") -> N/A | M22: =IFERROR(_xlfn.RANK.EQ(H22,H$3:H$61),"N/A") -> N/A | N22: =IFERROR(_xlfn.RANK.EQ(I22,I$3:I$61),"N/A") -> N/A | O22: =IFERROR(_xlfn.RANK.EQ(J22,J$3:J$61),"N/A") -> N/A | P22: =IFERROR(ABS(K$3-K22),"N/A") -> N/A | Q22: =IFERROR(ABS(L$3-L22),"N/A") -> N/A | R22: =IFERROR(ABS(M$3-M22),"N/A") -> N/A | S22: =IFERROR(ABS(N$3-N22),"N/A") -> N/A | T22: =IFERROR(ABS(O$3-O22),"N/A") -> N/A | U22: =SUM(P22:T22) -> 0 | V22: =_xlfn.RANK.EQ(U22,$U$4:$U$61,1) -> 1 | W22: =IF(Y22="Not suitable","-",V22) -> - | Y22: =IF(OR(Z22="Y",AA22="Y"),"Not suitable","") -> Not suitable | Z22: =IF(N22="N/A","Y","") -> Y
K23: =IFERROR(_xlfn.RANK.EQ(F23,F$3:F$61),"N/A") -> N/A | L23: =IFERROR(_xlfn.RANK.EQ(G23,G$3:G$61),"N/A") -> N/A | M23: =IFERROR(_xlfn.RANK.EQ(H23,H$3:H$61),"N/A") -> N/A | N23: =IFERROR(_xlfn.RANK.EQ(I23,I$3:I$61),"N/A") -> N/A | O23: =IFERROR(_xlfn.RANK.EQ(J23,J$3:J$61),"N/A") -> N/A | P23: =IFERROR(ABS(K$3-K23),"N/A") -> N/A | Q23: =IFERROR(ABS(L$3-L23),"N/A") -> N/A | R23: =IFERROR(ABS(M$3-M23),"N/A") -> N/A | S23: =IFERROR(ABS(N$3-N23),"N/A") -> N/A | T23: =IFERROR(ABS(O$3-O23),"N/A") -> N/A | U23: =SUM(P23:T23) -> 0 | V23: =_xlfn.RANK.EQ(U23,$U$4:$U$61,1) -> 1 | W23: =IF(Y23="Not suitable","-",V23) -> - | Y23: =IF(OR(Z23="Y",AA23="Y"),"Not suitable","") -> Not suitable | Z23: =IF(N23="N/A","Y","") -> Y
K24: =IFERROR(_xlfn.RANK.EQ(F24,F$3:F$61),"N/A") -> N/A | L24: =IFERROR(_xlfn.RANK.EQ(G24,G$3:G$61),"N/A") -> N/A | M24: =IFERROR(_xlfn.RANK.EQ(H24,H$3:H$61),"N/A") -> N/A | N24: =IFERROR(_xlfn.RANK.EQ(I24,I$3:I$61),"N/A") -> N/A | O24: =IFERROR(_xlfn.RANK.EQ(J24,J$3:J$61),"N/A") -> N/A | P24: =IFERROR(ABS(K$3-K24),"N/A") -> N/A | Q24: =IFERROR(ABS(L$3-L24),"N/A") -> N/A | R24: =IFERROR(ABS(M$3-M24),"N/A") -> N/A | S24: =IFERROR(ABS(N$3-N24),"N/A") -> N/A | T24: =IFERROR(ABS(O$3-O24),"N/A") -> N/A | U24: =SUM(P24:T24) -> 0 | V24: =_xlfn.RANK.EQ(U24,$U$4:$U$61,1) -> 1 | W24: =IF(Y24="Not suitable","-",V24) -> - | Y24: =IF(OR(Z24="Y",AA24="Y"),"Not suitable","") -> Not suitable | Z24: =IF(N24="N/A","Y","") -> Y
K25: =IFERROR(_xlfn.RANK.EQ(F25,F$3:F$61),"N/A") -> N/A | L25: =IFERROR(_xlfn.RANK.EQ(G25,G$3:G$61),"N/A") -> N/A | M25: =IFERROR(_xlfn.RANK.EQ(H25,H$3:H$61),"N/A") -> N/A | N25: =IFERROR(_xlfn.RANK.EQ(I25,I$3:I$61),"N/A") -> N/A | O25: =IFERROR(_xlfn.RANK.EQ(J25,J$3:J$61),"N/A") -> N/A | P25: =IFERROR(ABS(K$3-K25),"N/A") -> N/A | Q25: =IFERROR(ABS(L$3-L25),"N/A") -> N/A | R25: =IFERROR(ABS(M$3-M25),"N/A") -> N/A | S25: =IFERROR(ABS(N$3-N25),"N/A") -> N/A | T25: =IFERROR(ABS(O$3-O25),"N/A") -> N/A | U25: =SUM(P25:T25) -> 0 | V25: =_xlfn.RANK.EQ(U25,$U$4:$U$61,1) -> 1 | W25: =IF(Y25="Not suitable","-",V25) -> - | Y25: =IF(OR(Z25="Y",AA25="Y"),"Not suitable","") -> Not suitable | Z25: =IF(N25="N/A","Y","") -> Y
K26: =IFERROR(_xlfn.RANK.EQ(F26,F$3:F$61),"N/A") -> N/A | L26: =IFERROR(_xlfn.RANK.EQ(G26,G$3:G$61),"N/A") -> N/A | M26: =IFERROR(_xlfn.RANK.EQ(H26,H$3:H$61),"N/A") -> N/A | N26: =IFERROR(_xlfn.RANK.EQ(I26,I$3:I$61),"N/A") -> N/A | O26: =IFERROR(_xlfn.RANK.EQ(J26,J$3:J$61),"N/A") -> N/A | P26: =IFERROR(ABS(K$3-K26),"N/A") -> N/A | Q26: =IFERROR(ABS(L$3-L26),"N/A") -> N/A | R26: =IFERROR(ABS(M$3-M26),"N/A") -> N/A | S26: =IFERROR(ABS(N$3-N26),"N/A") -> N/A | T26: =IFERROR(ABS(O$3-O26),"N/A") -> N/A | U26: =SUM(P26:T26) -> 0 | V26: =_xlfn.RANK.EQ(U26,$U$4:$U$61,1) -> 1 | W26: =IF(Y26="Not suitable","-",V26) -> - | Y26: =IF(OR(Z26="Y",AA26="Y"),"Not suitable","") -> Not suitable | Z26: =IF(N26="N/A","Y","") -> Y
... K100: =IFERROR(_xlfn.RANK.EQ(F100,F$3:F$61),"N/A") -> N/A | L100: =IFERROR(_xlfn.RANK.EQ(G100,G$3:G$61),"N/A") -> N/A | M100: =IFERROR(_xlfn.RANK.EQ(H100,H$3:H$61),"N/A") -> N/A | N100: =IFERROR(_xlfn.RANK.EQ(I100,I$3:I$61),"N/A") -> N/A | O100: =IFERROR(_xlfn.RANK.EQ(J100,J$3:J$61),"N/A") -> N/A | P100: =IFERROR(ABS(K$3-K100),"N/A") -> N/A | Q100: =IFERROR(ABS(L$3-L100),"N/A") -> N/A | R100: =IFERROR(ABS(M$3-M100),"N/A") -> N/A | S100: =IFERROR(ABS(N$3-N100),"N/A") -> N/A | T100: =IFERROR(ABS(O$3-O100),"N/A") -> N/A | U100: =SUM(P100:T100) -> 0 | V100: =_xlfn.RANK.EQ(U100,$U$4:$U$61,1) -> 1 | W100: =IF(Y100="Not suitable","-",V100) -> - | Y100: =IF(OR(Z100="Y",AA100="Y"),"Not suitable","") -> Not suitable | Z100: =IF(N100="N/A","Y","") -> Y

Sheet ESG
B1: Company GICS Sector: | T1: Yes
B2: Information Technology | C2: <- Select Industry | T2: No
B3: ESG Analysis | K3: Relative ESG Analysis
B4: Parameters | C4: Impact | D4: Do they report? | E4: Ranking | F4: Mitigation Plan | G4: Traffic Lights | H4: Improvement over time? | I4: Targets / Goals? | J4: Comments | K4: Parameters | L4: =Peers!C6 -> #VALUE! | M4: =Peers!D6 -> #VALUE! | N4: =Peers!E6 -> #VALUE! | O4: =Peers!F6 -> #VALUE! | P4: =Peers!#REF! -> #REF! | Q4: =Peers!#REF! -> #REF! | R4: AVERAGE
B5: Environmental | K5: Ratios
A6: 1 | B6: CO2 Direct Emissions | C6: =VLOOKUP($B$2,'Sector Impact'!$K$4:$AA$16,A6+1,FALSE) -> Medium | D6: Yes | E6: Medium High | F6: Yes | H6: Scope 1 emissions stayed almost the same in 2021 compared with 2020 but increased 30% in 2022. Consistant decrease in scope 2 emissions over the 3 years | I6: 50% absolute reduction in greenhouse gas (GHG) emissions from AMD operations (Scope 1 and 2) by 2030 (base year 2020). 100% of AMD direct manufacturing suppliers to have a public GHG emissions reduction goal by 2025. | K6: CO2 Emissions/$M Sales | L6: =L12/L$11 -> 2.6546341 | M6: =M12/M$11 -> 6.4955322 | N6: =N12/N$11 -> 54.009112 | O6: =O12/O$11 -> 8.2997974 | P6: =P12/P$11 -> #DIV/0! | Q6: =Q12/Q$11 -> #DIV/0! | R6: =IFERROR(AVERAGE(L6:Q6),"") | X6: 2018 | Y6: 2019 | Z6: 2020 | AA6: 2021 | AB6: 2022
A7: 2 | B7: Total Water Consumption | C7: =VLOOKUP($B$2,'Sector Impact'!$K$4:$AA$16,A7+1,FALSE) -> Low | H7: Decreased between 2018-2021, increased in 2022 | I7: Aiming to reduce water use by a goal of at least 5 percent or more per AMD MI by 2025 compared to 2020. | K7: Water Consumption/$M Sales | L7: =L13/L$11 -> 4.5731707 | M7: =M13/M$11 -> 21.583268 | N7: =N13/N$11 -> 766.00861 | O7: =O13/O$11 -> 87.175118 | P7: =P13/P$11 -> #DIV/0! | Q7: =Q13/Q$11 -> #DIV/0! | R7: =IFERROR(AVERAGE(L7:Q7),"") | X7: 435600 | Y7: 457200 | Z7: 446400 | AA7: 388800 | AB7: 748800
A8: 3 | B8: Total Energy Consumption | C8: =VLOOKUP($B$2,'Sector Impact'!$K$4:$AA$16,A8+1,FALSE) -> High | D8: Yes | E8: Medium High | F8: Yes | H8: Almost the same between 2018-2021, increased in 2022 | I8: 30x increase in energy efficiency for AMD processors and accelerators powering servers for artificial intelligencetraining and high-performance computing by 2025 (base year 2020). 80% of AMD direct manufacturing suppliers to source renewable energy by 2025 | K8: Energy Consumption/$M Sales | L8: =L14/L$11 -> 23.707317 | M8: =M14/M$11 -> 70.35922 | N8: =N14/N$11 -> 530.24551 | O8: =O14/O$11 -> 97.97563 | P8: =P14/P$11 -> #DIV/0! | Q8: =Q14/Q$11 -> #DIV/0! | R8: =IFERROR(AVERAGE(L8:Q8),"") | X8: 192000 | Y8: 175000 | Z8: 151000 | AA8: 75000 | AB8: 183000
A9: 4 | B9: Waste Management | C9: =VLOOKUP($B$2,'Sector Impact'!$K$4:$AA$16,A9+1,FALSE) -> Low | H9: Decreased between 2019-2021, increased in 2022 | K9: Waste Production/$M Sales | L9: =L15/L$11 -> 0.027804878 | M9: =M15/M$11 -> 0.1665967 | N9: =N15/N$11 -> 4.3470008 | O9: =O15/O$11 -> 0.10305071 | P9: =P15/P$11 -> #DIV/0! | Q9: =Q15/Q$11 -> #DIV/0! | R9: =IFERROR(AVERAGE(L9:Q9),"") | X9: 3207 | Y9: 3358 | Z9: 2335 | AA9: 2892 | AB9: 8145
A10: 5 | B10: Land Degradation/Deforestation/Biodiversity loss/Animal sufering/… | C10: =VLOOKUP($B$2,'Sector Impact'!$K$4:$AA$16,A10+1,FALSE) -> Low | K10: Inputs | X10: 643 | Y10: 697 | Z10: 491 | AA10: 456 | AB10: 840
B11: Social | K11: Net Sales ($M) (2021) | L11: 16400 | M11: 16675 | N11: 79020 | O11: 33566
A12: 6 | B12: Employee Turnover % | C12: =VLOOKUP($B$2,'Sector Impact'!$K$4:$AA$16,A12+1,FALSE) -> Low | H12: In absolute terms no. The percentage of total turnover is is the same compared with 2021 (previous year). The turnover is at 10.6% wich is relatively high. | K12: CO2 Emissions Total (Tonnes) | L12: 43536 | M12: 108313 | N12: 4267800 | O12: 278591
A13: 7 | B13: Salaries & Compensation | C13: =VLOOKUP($B$2,'Sector Impact'!$K$4:$AA$16,A13+1,FALSE) -> Low | H13: N/A | I13: N/A | K13: Water Withdrawal Total (Cubic Meters) | L13: 75000 | M13: 359901 | N13: 60530000 | O13: 2926120
A14: 8 | B14: Reputation | C14: =VLOOKUP($B$2,'Sector Impact'!$K$4:$AA$16,A14+1,FALSE) -> Low | H14: N/A | I14: N/A | K14: Energy Consumption Total (Gigajoules) | L14: 388800 | M14: 1173240 | N14: 41900000 | O14: 3288650
A15: 9 | B15: Discrimination Events | C15: =VLOOKUP($B$2,'Sector Impact'!$K$4:$AA$16,A15+1,FALSE) -> Low | F15: Yes | K15: Waste Production Total (Tonnes) | L15: 456 | M15: 2778 | N15: 343500 | O15: 3459
A16: 10 | B16: Work Safety | C16: =VLOOKUP($B$2,'Sector Impact'!$K$4:$AA$16,A16+1,FALSE) -> High | D16: Yes | E16: "Best in class" | F16: Yes | H16: Yes, only 3 injured employees in 2023 | K16: ESG Scores
A17: 11 | B17: Damage to consumer health | C17: =VLOOKUP($B$2,'Sector Impact'!$K$4:$AA$16,A17+1,FALSE) -> Low | H17: N/A | I17: N/A | K17: Refinitiv | L17: 68 (42/255) 70/70/62 | M17: 76 (11/255) 67/73/90 | N17: 92 (1/255) 89/90/96 | O17: 73 (20/255) 70/90/48
A18: 12 | B18: PXP? | C18: =VLOOKUP($B$2,'Sector Impact'!$K$4:$AA$16,A18+1,FALSE) -> Low | K18: Sustainalytics | L18: 15.0 (low risk) | M18: 13.5 (low risk) | N18: 17.5 (low risk) | O18: 15.3 (low risk)
A19: 13 | B19: Supply chain | C19: =VLOOKUP($B$2,'Sector Impact'!$K$4:$AA$16,A19+1,FALSE) -> Low | I19: 100 percent of AMD direct supplier manufacturing factories to have a Responsible Business Alliance (RBA) audit or equivalent by 2025 (base year 2020) 80% of AMD direct manufacturing suppliers by spend to participate in a capacitybuilding activity by 2025 | K19: ISS | L19: B- | M19: C+ | N19: B- | O19: B-
A20: 14 | B20: Community involvement | C20: =VLOOKUP($B$2,'Sector Impact'!$K$4:$AA$16,A20+1,FALSE) -> Low | K20: CDP | L20: B/B | M20: B/B | N20: A/A/A | O20: B/B
A21: 15 | B21: Public Sector | C21: =VLOOKUP($B$2,'Sector Impact'!$K$4:$AA$16,A21+1,FALSE) -> Medium | D21: No | E21: Medium High | F21: No | H21: N/A | I21: N/A
A22: 16 | B22: Litigation | C22: =VLOOKUP($B$2,'Sector Impact'!$K$4:$AA$16,A22+1,FALSE) -> Very High | D22: No | E22: Medium High | F22: No | H22: N/A | I22: N/A | J22: Found several lawsuits against AMD in recent years but no signs of conviction
B23: Corporate Governance | K23: PARAMETERS
A24: 17 | B24: Diversity (Gender, Age, Industry, Region) | E24: "Villain" | F24: No | J24: 67% of the board is composed by males. 78% of the board is white and the other 22% is asian. All ages range between 53-69 year old (most members are between 57-62 years old) | K24: IMPACT | L24: RANKING | M24: MITIGATION PLAN | O24: TRAFFIC
A25: 18 | B25: % Independence | F25: No | H25: N/A | I25: N/A | K25: Low | L25: "Best in class" | M25: Is there evidence of a plan/program ?
A26: 19 | B26: average time as independent directors | E26: "Best in class" | F26: No | H26: N/A | I26: N/A | J26: 6.3 is the average tenure at AMD what is positive. | K26: Medium | L26: Medium High
A27: 20 | B27: Recent departures of directors / C-level executives? | E27: "Best in class" | F27: No | H27: N/A | I27: N/A | K27: High | L27: Medium
A28: 21 | B28: CEO/Chairman duality | E28: "Villain" | F28: No | H28: N/A | I28: N/A | J28: Before February 2022 the CEO and Chairman were different persons, since that date Lisa T. Su acummulated her CEO functions with "chair of the board" functions | K28: Very high | L28: "Villain"
A29: 22 | B29: Transparency (ESG, segments, acquisitions, other) | E29: Medium | F29: No | H29: N/A | I29: N/A | J29: The reports are complete and easy to read
A30: 23 | B30: Time taken to report after the end of the quarter / year | E30: "Villain" | F30: No | H30: N/A | I30: N/A | J30: The 2024 report (regarding the year 2023) hasn't been published
A31: 24 | B31: Additional participation of the CEO in other boards or excessive participation of Ch. | E31: "Best in class" | F31: No | H31: N/A | I31: N/A
A32: 25 | B32: Audit / Consulting | D32: Yes | E32: Medium | F32: No | H32: N/A | I32: N/A | J32: Bureau Veritas does the ESG audit. Other Audits are made internally. Consulted with Omdia for AI purposes and with BSR for ESG purposes
A33: 26 | B33: ESG-compensation related | D33: No | E33: "Villain" | F33: No | H33: N/A | I33: N/A
A34: 27 | B34: Management compensation schemes | D34: Yes | E34: Medium High | F34: Yes | H34: N/A | I34: N/A

Sheet Multiples valuation
L1: Enterprise Value Calculation
L2: In millions, except per share price | P2: Intel | R2: NVIDIA | T2: Qualcomm | V2: AMD
P3: 2022 | Q3: 2023 | R3: 2022 | S3: 2023 | T3: 2022 | U3: 2023 | V3: 2022 | W3: 2023
L4: Release date of 10-K report | P4: 45657 | Q4: 45657 | R4: 45322 | S4: 45322 | T4: 45565 | U4: 45565 | V4: 45565 | W4: 45565
B5: In millions, except ratio | C5: Intel | E5: NVIDIA | G5: Qualcomm | I5: AMD
C6: 2022 | D6: 2023 | E6: 2022 | F6: 2023 | G6: 2022 | H6: 2023 | I6: 2022 | J6: 2023 | L6: Closing price of shares ~7 days after report release | P6: 28.56 | Q6: 48.31 | R6: 221.62 | S6: 700.96 | T6: 116.42 | U6: 110.53 | V6: 85.91 | W6: 170.94
B7: Operating Cash Flow | C7: 15433 | D7: 11471 | E7: 5641 | F7: 28090 | G7: 9096 | H7: 11299 | I7: 3565 | J7: 1667 | L7: x Fully Diluted Shares Outstanding: | P7: 4456 | Q7: 4579 | R7: 2860 | S7: 2887 | T7: 1186 | U7: 1220 | V7: 1611388.2 | W7: 1615786.8
B8: Less: Capital Expenditure | C8: 25050 | D8: 25750 | E8: 1833 | F8: 1069 | G8: 2262 | H8: 1450 | I8: -450 | J8: -546 | M8: Basic shares outstanding | P8: 4137 | Q8: 4228 | R8: 2470 | S8: 2500 | T8: 1121 | U8: 1113
B9: Enterprise Value (see calc.) | C9: 159989 | D9: 267785 | E9: 642475 | F9: 2027448 | G9: 150783 | H9: 141795 | I9: 138432.68 | J9: 276200.63 | M9: Employee Equity Incentive Plan | P9: 119 | Q9: 194 | R9: 160 | S9: 160 | T9: 43 | U9: 88
B10: Free Cash Flow | C10: -9617 | D10: -14279 | E10: 3808 | F10: 27021 | G10: 6834 | H10: 9849 | I10: =I7+I8 -> 3115 | J10: =J7+J8 -> 1121 | M10: Employee Stock Purchase Plan | P10: 200 | Q10: 157 | R10: 230 | S10: 227 | T10: 22 | U10: 19
B11: EV/FCF | C11: -16.64 | D11: -18.75 | E11: 168.72 | F11: 75.03 | G11: 22.06 | H11: 14.4 | I11: =I9/I10 -> 44.440668 | J11: =J9/J10 -> 246.38772 | L11: Market Capitalization | P11: 127263.36 | Q11: 221211.49 | R11: 633833.2 | S11: 2023671.5 | T11: 138074.12 | U11: 134846.6 | V11: =V7*V6 -> 1.3843436e+08 | W11: =W6*W7 -> 2.762026e+08
B12: EV/FCF/Growth | D12: =D11/(D10/C10-1) -> -38.678411 | F12: =F11/(F10/E10-1) -> 12.308372 | H12: =H11/(H10/G10-1) -> 32.64 | J12: =J11/(J10/I10-1) -> -384.90358 | L12: Plus: Total Debt | P12: 42007 | Q12: 49278 | R12: 12031 | S12: 11056 | T12: 15482 | U12: 15398 | V12: 2252 | W12: 2863
L13: Plus: Noncontrolling Interest | P13: 1863 | Q13: 4375 | R13: 0 | S13: 0 | T13: 0 | U13: 0 | V13: 0 | W13: 0
L14: Less: Cash and Cash Equivalents | P14: 11144 | Q14: 7079 | R14: 3389 | S14: 7280 | T14: 2773 | U14: 8450 | V14: 3933 | W14: 4835
L15: Enterprise Value | P15: 159989.36 | Q15: 267785.49 | R15: 642475.2 | S15: 2027447.5 | T15: 150783.12 | U15: 141794.6 | V15: =V11+V12-V14 -> 1.3843268e+08 | W15: =W11+W12-W14 -> 2.7620063e+08

Sheet Assumptions
B2: Assumptions
B4: Prospects:
B6: Links:
C8: 2023 | D8: =C8-1 -> 2022 | E8: =D8-1 -> 2021 | F8: =E8-1 -> 2020 | G8: =F8-1 -> 2019 | H8: =G8-1 -> 2018 | I8: =H8-1 -> 2017 | J8: =I8-1 -> 2016 | K8: =J8-1 -> 2015 | ... M8: =L8-1 -> 2013 | O8: 10Y Average | P8: 5Y Average | Q8: 3Y Average | S8: Short Term Forecast | T8: Long Term Forecast
