Workbook
Name COOLFUCNTION: _xlfn.LAMBDA(_xldudf_BOARDFLARE_EXEC("workbook-settings:coolfucntion"))
Name COOLFUCNTION: _xlfn.LAMBDA(_xldudf_BOARDFLARE_EXEC("workbook-settings:coolfucntion"))
Name COOLFUCNTION: _xlfn.LAMBDA(_xldudf_BOARDFLARE_EXEC("workbook-settings:coolfucntion"))
Name COOLFUCNTION: _xlfn.LAMBDA(_xldudf_BOARDFLARE_EXEC("workbook-settings:coolfucntion"))
Name COOLFUCNTION: _xlfn.LAMBDA(_xldudf_BOARDFLARE_EXEC("workbook-settings:coolfucntion"))
Name COOLFUCNTION: _xlfn.LAMBDA(_xldudf_BOARDFLARE_EXEC("workbook-settings:coolfucntion"))
Name COOLFUCNTION: _xlfn.LAMBDA(_xldudf_BOARDFLARE_EXEC("workbook-settings:coolfucntion"))
Name COOLFUCNTION: _xlfn.LAMBDA(_xldudf_BOARDFLARE_EXEC("workbook-settings:coolfucntion"))
Name COOLFUCNTION: _xlfn.LAMBDA(_xldudf_BOARDFLARE_EXEC("workbook-settings:coolfucntion"))
Name COOLFUCNTION: _xlfn.LAMBDA(_xldudf_BOARDFLARE_EXEC("workbook-settings:coolfucntion"))
Name Sectors: #REF!
Name Sectors: #REF!
Name Sectors: #REF!

Sheet Summary
E2: | EQUITY RESEARCH | U2: Lisbon Investment Society Equity Research
U3: April 5, 2025
D6: {=+_FV(DCF!R4,"Name")} -> ADOBE INC. | U6: Buy
D8: Adobe Inc. develops and sells software for creative design, document management, and digital marketing. Its core operations focus on subscription-based services through Creative Cloud (like Photoshop and Illustrator) and Experience Cloud for data-driven marketing. The company generates most of its revenue from digital media tools and operates globally, with a strong presence in the Americas, Europe, and Asia. | U8: EXCHANGE:(TICKER)
U9: {=+"Price (7 Mar 25): $"&_FV(DCF!$R$4,"Price")} -> Price (7 Mar 25): $365.9
D10: Investment Thesis | U10: ="Price Target: $" & ROUND(IF(Summary!G25="FCFF",DCF!Q208,IF(Summary!G25="FCFE",DCF!Q236,IF(Summary!G25="Tax Shield",DCF!#REF!,DCF!Q267))),2) &" "&IF(Summary!G25="FCFF","(FCFF)",IF(Summary!G25="FCFE","(FCFE)",IF(Summary!G25="Tax Shield","(APV)","(DDM)"))) -> Price Target: $669.54 (FCFF)
D11: Adobe Inc. is a market leader in creative and digital media software with a resilient subscription-based business model, strong free revenue generation, and growing digital solutions. The company's strategic integration of generative AI through Firefly, alongside continued expansion in Document and Experience Cloud, positions it to drive sustainable long-term growth. Despite short-term market volatility, Adobe’s innovation pipeline and pricing power support a favorable profile. | U11: =+"Upside (Downside): "&ROUND((DCF!$Q$211*100),2)&"%" -> Upside (Downside): 82.98%
U14: =+Industry!E28&", "&ESG!C9 -> USA,
U15: =+ESG!C10 -> Software Development
D17: Operating Metrics | F17: 2023 | G17: =+F17+1 -> 2024 | H17: =+G17+1 -> 2025 | I17: =+H17+1 -> 2026 | K17: Valuation Multiples | N17: 2022 | O17: =+N17+1 -> 2023 | P17: =+O17+1 -> 2024 | Q17: =+P17+1 -> 2025 | R17: =+Q17+1 -> 2026 | U17: Pedro Bordalo
K18: EV / Sales | N18: =IFERROR(_xlfn.XLOOKUP($K18,Multiples!$B:$B,Multiples!N:N),"") -> 0.66701863 | O18: =IFERROR(_xlfn.XLOOKUP($K18,Multiples!$B:$B,Multiples!O:O),"") -> 0.88313743 | P18: =IFERROR(_xlfn.XLOOKUP($K18,Multiples!$B:$B,Multiples!P:P),"") -> 9.1579614 | Q18: =IFERROR(_xlfn.XLOOKUP($K18,Multiples!$B:$B,Multiples!Q:Q),"") -> 12.668342 | R18: =IFERROR(_xlfn.XLOOKUP($K18,Multiples!$B:$B,Multiples!R:R),"") -> 12.303307
K19: Price / Sales | N19: =IFERROR(_xlfn.XLOOKUP($K19,Multiples!$B:$B,Multiples!N:N),"") -> 0.7501153 | O19: =IFERROR(_xlfn.XLOOKUP($K19,Multiples!$B:$B,Multiples!O:O),"") -> 1.076965 | P19: =IFERROR(_xlfn.XLOOKUP($K19,Multiples!$B:$B,Multiples!P:P),"") -> 9.2430579 | Q19: =IFERROR(_xlfn.XLOOKUP($K19,Multiples!$B:$B,Multiples!Q:Q),"") -> 13.509842 | R19: =IFERROR(_xlfn.XLOOKUP($K19,Multiples!$B:$B,Multiples!R:R),"") -> 13.658861
K20: EV / EBITDA | N20: =IFERROR(_xlfn.XLOOKUP($K20,Multiples!$B:$B,Multiples!N:N),"") -> 1.8984045 | O20: =IFERROR(_xlfn.XLOOKUP($K20,Multiples!$B:$B,Multiples!O:O),"") -> 2.5140532 | P20: =IFERROR(_xlfn.XLOOKUP($K20,Multiples!$B:$B,Multiples!P:P),"") -> 25.477614 | Q20: =IFERROR(_xlfn.XLOOKUP($K20,Multiples!$B:$B,Multiples!Q:Q),"") -> 22.20597 | R20: =IFERROR(_xlfn.XLOOKUP($K20,Multiples!$B:$B,Multiples!R:R),"") -> 21.35184 | U20: Patrícia Franco
K21: EV / EBIT | N21: =IFERROR(_xlfn.XLOOKUP($K21,Multiples!$B:$B,Multiples!N:N),"") -> 1.9258003 | O21: =IFERROR(_xlfn.XLOOKUP($K21,Multiples!$B:$B,Multiples!O:O),"") -> 2.8827471 | P21: =IFERROR(_xlfn.XLOOKUP($K21,Multiples!$B:$B,Multiples!P:P),"") -> 28.654439 | Q21: =IFERROR(_xlfn.XLOOKUP($K21,Multiples!$B:$B,Multiples!Q:Q),"") -> 23.694591 | R21: =IFERROR(_xlfn.XLOOKUP($K21,Multiples!$B:$B,Multiples!R:R),"") -> 23.074834
K22: Price / Earnings | N22: =IFERROR(_xlfn.XLOOKUP($K22,Multiples!$B:$B,Multiples!N:N),"") -> 2.7768146 | O22: =IFERROR(_xlfn.XLOOKUP($K22,Multiples!$B:$B,Multiples!O:O),"") -> 3.8509238 | P22: =IFERROR(_xlfn.XLOOKUP($K22,Multiples!$B:$B,Multiples!P:P),"") -> 35.750353 | Q22: =IFERROR(_xlfn.XLOOKUP($K22,Multiples!$B:$B,Multiples!Q:Q),"") -> 25.119795 | R22: =IFERROR(_xlfn.XLOOKUP($K22,Multiples!$B:$B,Multiples!R:R),"") -> 25.597311
K23: Price / Book | N23: =IFERROR(_xlfn.XLOOKUP($K23,Multiples!$B:$B,Multiples!N:N),"") -> 0.94745175 | O23: =IFERROR(_xlfn.XLOOKUP($K23,Multiples!$B:$B,Multiples!O:O),"") -> 1.2537677 | P23: =IFERROR(_xlfn.XLOOKUP($K23,Multiples!$B:$B,Multiples!P:P),"") -> 14.730396 | Q23: =IFERROR(_xlfn.XLOOKUP($K23,Multiples!$B:$B,Multiples!Q:Q),"") | R23: =IFERROR(_xlfn.XLOOKUP($K23,Multiples!$B:$B,Multiples!R:R),"") | U23: Alexandra Gonçalves
D25: Year | E25: Net Sales | F25: EBIT Margin | G25: FCFF | H25: =+IF(Summary!$G$25="FCFF",DCF!AB6,IF(Summary!$G$25="FCFE",DCF!AC6,DCF!AD6)) -> NOPAT | I25: Net Capex | K25: Profitability Ratios | N25: 2022 | O25: =+N25+1 -> 2023 | P25: =+O25+1 -> 2024 | Q25: =+P25+1 -> 2025 | R25: =+Q25+1 -> 2026
D26: 2022 | E26: =+DCF!E30 -> 17606 | F26: =+DCF!E60 -> 0.3463592 | G26: =+INDEX(DCF!X7:AA7,MATCH(Summary!$G$25,{"FCFF","FCFE","Tax Shield","Total Payout"},0)) -> 8662.8478 | H26: =+IF(Summary!$G$25="FCFF",DCF!AB7,IF(Summary!$G$25="FCFE",DCF!AC7,DCF!AD7)) -> 6076.8478 | I26: =+DCF!E134 -> -442 | K26: Return on Assets | N26: =IFERROR(_xlfn.XLOOKUP($K26,Multiples!$B:$B,Multiples!N:N),"") -> 0.17507823 | O26: =IFERROR(_xlfn.XLOOKUP($K26,Multiples!$B:$B,Multiples!O:O),"") -> 0.18215376 | P26: =IFERROR(_xlfn.XLOOKUP($K26,Multiples!$B:$B,Multiples!P:P),"") -> 0.18532098 | Q26: =IFERROR(_xlfn.XLOOKUP($K26,Multiples!$B:$B,Multiples!Q:Q),"") -> 0.25730394 | R26: =IFERROR(_xlfn.XLOOKUP($K26,Multiples!$B:$B,Multiples!R:R),"") -> 0.27311256 | U26: Manuel Jacó
D27: =+D26+1 -> 2023 | E27: =+DCF!F30 -> 19409 | F27: =+DCF!F60 -> 0.30635272 | G27: =+INDEX(DCF!X8:AA8,MATCH(Summary!$G$25,{"FCFF","FCFE","Tax Shield","Total Payout"},0)) -> 0 | H27: =+IF(Summary!$G$25="FCFF",DCF!AB8,IF(Summary!$G$25="FCFE",DCF!AC8,DCF!AD8)) -> 0 | I27: =+DCF!F134 -> -360 | K27: Return on Equity | N27: =IFERROR(_xlfn.XLOOKUP($K27,Multiples!$B:$B,Multiples!N:N),"") -> 0.34120095 | O27: =IFERROR(_xlfn.XLOOKUP($K27,Multiples!$B:$B,Multiples!O:O),"") -> 0.32557582 | P27: =IFERROR(_xlfn.XLOOKUP($K27,Multiples!$B:$B,Multiples!P:P),"") -> 0.41203498 | R27: =IFERROR(_xlfn.XLOOKUP($K27,Multiples!$B:$B,Multiples!R:R),"") -> -1.179012e-11
D28: =+D27+1 -> 2024 | E28: =+DCF!G30 -> 21505 | F28: =+DCF!G60 -> 0.31960009 | G28: =+INDEX(DCF!X9:AA9,MATCH(Summary!$G$25,{"FCFF","FCFE","Tax Shield","Total Payout"},0)) -> 9504.3855 | H28: =+IF(Summary!$G$25="FCFF",DCF!AB9,IF(Summary!$G$25="FCFE",DCF!AC9,DCF!AD9)) -> 6853.3855 | I28: =+DCF!G134 -> -183 | K28: Return on Total Capital | N28: =IFERROR(_xlfn.XLOOKUP($K28,Multiples!$B:$B,Multiples!N:N),"") -> 0.25992058 | O28: =IFERROR(_xlfn.XLOOKUP($K28,Multiples!$B:$B,Multiples!O:O),"") -> 0.22874928 | P28: =IFERROR(_xlfn.XLOOKUP($K28,Multiples!$B:$B,Multiples!P:P),"") -> 0.28201907 | Q28: =IFERROR(_xlfn.XLOOKUP($K28,Multiples!$B:$B,Multiples!Q:Q),"") -> -1.100811e-11 | R28: =IFERROR(_xlfn.XLOOKUP($K28,Multiples!$B:$B,Multiples!R:R),"") -> -1.1745971e-11
D29: =+D28+1 -> 2025 | E29: =+DCF!H30 -> 23001.039 | F29: =+DCF!H60 -> 0.53465122 | G29: =+INDEX(DCF!X10:AA10,MATCH(Summary!$G$25,{"FCFF","FCFE","Tax Shield","Total Payout"},0)) -> 17212.553 | H29: =+IF(Summary!$G$25="FCFF",DCF!AB10,IF(Summary!$G$25="FCFE",DCF!AC10,DCF!AD10)) -> 12259.462 | I29: =+DCF!H134 -> -1242.3248 | K29: EBITDA Margin | N29: =IFERROR(_xlfn.XLOOKUP($K29,Multiples!$B:$B,Multiples!N:N),"") -> 0.35135749 | O29: =IFERROR(_xlfn.XLOOKUP($K29,Multiples!$B:$B,Multiples!O:O),"") -> 0.35128033 | P29: =IFERROR(_xlfn.XLOOKUP($K29,Multiples!$B:$B,Multiples!P:P),"") -> 0.35945129 | Q29: =IFERROR(_xlfn.XLOOKUP($K29,Multiples!$B:$B,Multiples!Q:Q),"") -> 0.57049261 | R29: =IFERROR(_xlfn.XLOOKUP($K29,Multiples!$B:$B,Multiples!R:R),"") -> 0.57621766
D30: =+D29+1 -> 2026 | E30: =+DCF!I30 -> 24606.891 | F30: =+DCF!I60 -> 0.53319159 | G30: =+INDEX(DCF!X11:AA11,MATCH(Summary!$G$25,{"FCFF","FCFE","Tax Shield","Total Payout"},0)) -> 14132.394 | H30: =+IF(Summary!$G$25="FCFF",DCF!AB11,IF(Summary!$G$25="FCFE",DCF!AC11,DCF!AD11)) -> 13081.199 | I30: =+DCF!I134 -> -1333.3023 | K30: EBIT Margin | N30: =IFERROR(_xlfn.XLOOKUP($K30,Multiples!$B:$B,Multiples!N:N),"") -> 0.3463592 | O30: =IFERROR(_xlfn.XLOOKUP($K30,Multiples!$B:$B,Multiples!O:O),"") -> 0.30635272 | P30: =IFERROR(_xlfn.XLOOKUP($K30,Multiples!$B:$B,Multiples!P:P),"") -> 0.31960009 | Q30: =IFERROR(_xlfn.XLOOKUP($K30,Multiples!$B:$B,Multiples!Q:Q),"") -> 0.53465122 | R30: =IFERROR(_xlfn.XLOOKUP($K30,Multiples!$B:$B,Multiples!R:R),"") -> 0.53319159 | U30: Statistics
D31: =+D30+1 -> 2027 | E31: =+DCF!J30 -> 26330.095 | F31: =+DCF!J60 -> 0.51800526 | G31: =+INDEX(DCF!X12:AA12,MATCH(Summary!$G$25,{"FCFF","FCFE","Tax Shield","Total Payout"},0)) -> 14676.144 | H31: =+IF(Summary!$G$25="FCFF",DCF!AB12,IF(Summary!$G$25="FCFE",DCF!AC12,DCF!AD12)) -> 13598.568 | I31: =+DCF!J134 -> -1430.6334 | K31: Gross Profit Margin | N31: =IFERROR(_xlfn.XLOOKUP($K31,Multiples!$B:$B,Multiples!N:N),"") -> 0.87703056 | O31: =IFERROR(_xlfn.XLOOKUP($K31,Multiples!$B:$B,Multiples!O:O),"") -> 0.87871606 | P31: =IFERROR(_xlfn.XLOOKUP($K31,Multiples!$B:$B,Multiples!P:P),"") -> 0.88198093 | Q31: =IFERROR(_xlfn.XLOOKUP($K31,Multiples!$B:$B,Multiples!Q:Q),"") -> 0.87924252 | R31: =IFERROR(_xlfn.XLOOKUP($K31,Multiples!$B:$B,Multiples!R:R),"") -> 0.87997984 | U31: Beta | V31: =Peers!D73 -> 1.4977
D32: =+D31+1 -> 2028 | E32: =+DCF!K30 -> 28178.877 | F32: =+DCF!K60 -> 0.51876899 | G32: =+INDEX(DCF!X13:AA13,MATCH(Summary!$G$25,{"FCFF","FCFE","Tax Shield","Total Payout"},0)) -> 17527.7 | H32: =+IF(Summary!$G$25="FCFF",DCF!AB13,IF(Summary!$G$25="FCFE",DCF!AC13,DCF!AD13)) -> 14574.271 | I32: =+DCF!K134 -> -1535.0696 | K32: SG&A Margin | N32: =IFERROR(_xlfn.XLOOKUP($K32,Multiples!$B:$B,Multiples!N:N),"") -> 0.29364989 | O32: =IFERROR(_xlfn.XLOOKUP($K32,Multiples!$B:$B,Multiples!O:O),"") -> 0.34849812 | P32: =IFERROR(_xlfn.XLOOKUP($K32,Multiples!$B:$B,Multiples!P:P),"") -> 0.26803069 | Q32: =IFERROR(_xlfn.XLOOKUP($K32,Multiples!$B:$B,Multiples!Q:Q),"") -> 0.17 | R32: =IFERROR(_xlfn.XLOOKUP($K32,Multiples!$B:$B,Multiples!R:R),"") -> 0.26217627 | U32: % Float | V32: 0.1277
D33: =+D32+1 -> 2029 | E33: =+DCF!L30 -> 30162.063 | F33: =+DCF!L60 -> 0.51435356 | G33: =+INDEX(DCF!X14:AA14,MATCH(Summary!$G$25,{"FCFF","FCFE","Tax Shield","Total Payout"},0)) -> 17742.679 | H33: =+IF(Summary!$G$25="FCFF",DCF!AB14,IF(Summary!$G$25="FCFE",DCF!AC14,DCF!AD14)) -> 15467.633 | I33: =+DCF!L134 -> -1647.1297 | K33: Net Income Margin | N33: =IFERROR(_xlfn.XLOOKUP($K33,Multiples!$B:$B,Multiples!N:N),"") -> 0.27013518 | O33: =IFERROR(_xlfn.XLOOKUP($K33,Multiples!$B:$B,Multiples!O:O),"") -> 0.27966407 | P33: =IFERROR(_xlfn.XLOOKUP($K33,Multiples!$B:$B,Multiples!P:P),"") -> 0.25854452 | Q33: =IFERROR(_xlfn.XLOOKUP($K33,Multiples!$B:$B,Multiples!Q:Q),"") -> 0.53781657 | R33: =IFERROR(_xlfn.XLOOKUP($K33,Multiples!$B:$B,Multiples!R:R),"") -> 0.53360529 | U33: % Held by Insiders | V33: 0.0023
U34: % Held by Institutions | V34: 0.87
D35: SWOT Analysis | K35: Liquidity Ratios | N35: 2022 | O35: =+N35+1 -> 2023 | P35: =+O35+1 -> 2024 | Q35: =+P35+1 -> 2025 | R35: =+Q35+1 -> 2026 | U35: Short % of Float | V35: 0.0189
D36: Strengths | G36: Weaknesses | K36: Cash Ratio | N36: =IFERROR(_xlfn.XLOOKUP($K36,Multiples!$B:$B,Multiples!N:N),"") -> 0.52116142 | O36: =IFERROR(_xlfn.XLOOKUP($K36,Multiples!$B:$B,Multiples!O:O),"") -> 0.86547085 | P36: =IFERROR(_xlfn.XLOOKUP($K36,Multiples!$B:$B,Multiples!P:P),"") -> 0.72360042 | Q36: =IFERROR(_xlfn.XLOOKUP($K36,Multiples!$B:$B,Multiples!Q:Q),"") -> 1.7122454 | R36: =IFERROR(_xlfn.XLOOKUP($K36,Multiples!$B:$B,Multiples!R:R),"") -> 2.6823803 | W36: 120.87
D37: Market Leadership: The company is a market leader Financial Health: Srong debt management Subscription revenue: Sucessfully transitioned to subscription-based models. Strong profitability performance. | G37: High prices: Software complexity: | K37: Quick Ratio | N37: =IFERROR(_xlfn.XLOOKUP($K37,Multiples!$B:$B,Multiples!N:N),"") -> 1.00406 | O37: =IFERROR(_xlfn.XLOOKUP($K37,Multiples!$B:$B,Multiples!O:O),"") -> 1.2199733 | P37: =IFERROR(_xlfn.XLOOKUP($K37,Multiples!$B:$B,Multiples!P:P),"") -> 0.94648798 | Q37: =IFERROR(_xlfn.XLOOKUP($K37,Multiples!$B:$B,Multiples!Q:Q),"") -> 1.9056776 | R37: =IFERROR(_xlfn.XLOOKUP($K37,Multiples!$B:$B,Multiples!R:R),"") -> 2.8835673 | U37: Major Holders | W37: 113.63
K38: Current Ratio | N38: =IFERROR(_xlfn.XLOOKUP($K38,Multiples!$B:$B,Multiples!N:N),"") -> 1.1067913 | O38: =IFERROR(_xlfn.XLOOKUP($K38,Multiples!$B:$B,Multiples!O:O),"") -> 1.3433523 | P38: =IFERROR(_xlfn.XLOOKUP($K38,Multiples!$B:$B,Multiples!P:P),"") -> 1.0675791 | Q38: =IFERROR(_xlfn.XLOOKUP($K38,Multiples!$B:$B,Multiples!Q:Q),"") -> 1.9829281 | R38: =IFERROR(_xlfn.XLOOKUP($K38,Multiples!$B:$B,Multiples!R:R),"") -> 1.9829281 | U38: Vanguard Group | V38: 0.0961
U39: Blackrock Inc. | V39: 0.095
D40: Opportunities | G40: Threats | K40: Cash Flow Ratios | N40: 2022 | O40: =+N40+1 -> 2023 | P40: =+O40+1 -> 2024 | Q40: =+P40+1 -> 2025 | R40: =+Q40+1 -> 2026 | U40: State Street Corp. | V40: 0.0482
D41: Strenghtening mobile ecossystem: Importance of the digital world in real world applications is rising. Leveraging AI: for example, to reduce complexity of the programs Emerging needs of digital content: more diverse income streams in the digital world. | G41: Intense competition: Cybersecurity risks: Fast technological changes in the industry: The software industry is one of the most fast paced industries. | K41: Cash Conversion Cycle | N41: =IFERROR(_xlfn.XLOOKUP($K41,Multiples!$B:$B,Multiples!N:N),"") -> 34.953425 | O41: =IFERROR(_xlfn.XLOOKUP($K41,Multiples!$B:$B,Multiples!O:O),"") -> 35.918904 | P41: =IFERROR(_xlfn.XLOOKUP($K41,Multiples!$B:$B,Multiples!P:P),"") -> 29.040456 | Q41: =IFERROR(_xlfn.XLOOKUP($K41,Multiples!$B:$B,Multiples!Q:Q),"") -> -14.914648 | R41: =IFERROR(_xlfn.XLOOKUP($K41,Multiples!$B:$B,Multiples!R:R),"") -> -12.857737 | U41: Geode Capital | V41: 0.0251
K42: Net Income / Op Cash Flow | N42: =IFERROR(_xlfn.XLOOKUP($K42,Multiples!$B:$B,Multiples!N:N),"") -> 0.60678745 | O42: =IFERROR(_xlfn.XLOOKUP($K42,Multiples!$B:$B,Multiples!O:O),"") -> 0.74335798 | P42: =IFERROR(_xlfn.XLOOKUP($K42,Multiples!$B:$B,Multiples!P:P),"") -> 0.69016882 | Q42: =IFERROR(_xlfn.XLOOKUP($K42,Multiples!$B:$B,Multiples!Q:Q),"") -> 0.67885256 | R42: =IFERROR(_xlfn.XLOOKUP($K42,Multiples!$B:$B,Multiples!R:R),"") -> 0.87362437 | U42: Morgan Stanley | V42: 0.0195
K43: Chg in Cash / Op Cash Flow | N43: =IFERROR(_xlfn.XLOOKUP($K43,Multiples!$B:$B,Multiples!N:N),"") -> 0.050012758 | O43: =IFERROR(_xlfn.XLOOKUP($K43,Multiples!$B:$B,Multiples!O:O),"") -> 0.39783621 | P43: =IFERROR(_xlfn.XLOOKUP($K43,Multiples!$B:$B,Multiples!P:P),"") -> 0.058589871 | Q43: =IFERROR(_xlfn.XLOOKUP($K43,Multiples!$B:$B,Multiples!Q:Q),"") -> 0.93826075 | R43: =IFERROR(_xlfn.XLOOKUP($K43,Multiples!$B:$B,Multiples!R:R),"") -> 0.93152295 | U43: FMR | V43: 0.018
U44: NORGES BANK | V44: 0.0135
D45: Revenue by Region | G45: Revenue by Segment | K45: Leverage Ratios | N45: 2022 | O45: =+N45+1 -> 2023 | P45: =+O45+1 -> 2024 | Q45: =+P45+1 -> 2025 | R45: =+Q45+1 -> 2026 | U45: Bank of New York Mellon C. | V45: 0.0134
K46: Total Debt / Equity | N46: =IFERROR(_xlfn.XLOOKUP($K46,Multiples!$B:$B,Multiples!N:N),"") -> 332.37678 | O46: =IFERROR(_xlfn.XLOOKUP($K46,Multiples!$B:$B,Multiples!O:O),"") -> 244.72169 | P46: =IFERROR(_xlfn.XLOOKUP($K46,Multiples!$B:$B,Multiples!P:P),"") -> 448.79206 | Q46: =IFERROR(_xlfn.XLOOKUP($K46,Multiples!$B:$B,Multiples!Q:Q),"") -> -5.4378501e-12 | R46: =IFERROR(_xlfn.XLOOKUP($K46,Multiples!$B:$B,Multiples!R:R),"") -> -5.5458283e-12 | U46: Primecap Management | V46: 0.0129
K47: Total Debt / Capital | N47: =IFERROR(_xlfn.XLOOKUP($K47,Multiples!$B:$B,Multiples!N:N),"") -> 0.99700039 | O47: =IFERROR(_xlfn.XLOOKUP($K47,Multiples!$B:$B,Multiples!O:O),"") -> 0.99593036 | P47: =IFERROR(_xlfn.XLOOKUP($K47,Multiples!$B:$B,Multiples!P:P),"") -> 0.99777675 | Q47: =IFERROR(_xlfn.XLOOKUP($K47,Multiples!$B:$B,Multiples!Q:Q),"") -> -5.4378501e-12 | R47: =IFERROR(_xlfn.XLOOKUP($K47,Multiples!$B:$B,Multiples!R:R),"") -> -5.5458283e-12 | U47: UBS AM | V47: 0.0125
K48: Total Liabilities / Total Assets | N48: =IFERROR(_xlfn.XLOOKUP($K48,Multiples!$B:$B,Multiples!N:N),"") -> 0.4868765 | O48: =IFERROR(_xlfn.XLOOKUP($K48,Multiples!$B:$B,Multiples!O:O),"") -> 0.44051814 | P48: =IFERROR(_xlfn.XLOOKUP($K48,Multiples!$B:$B,Multiples!P:P),"") -> 0.55022998 | Q48: =IFERROR(_xlfn.XLOOKUP($K48,Multiples!$B:$B,Multiples!Q:Q),"") -> 2.3164527e+10 | R48: =IFERROR(_xlfn.XLOOKUP($K48,Multiples!$B:$B,Multiples!R:R),"") -> 2.3164527e+10
...

Sheet Segments
B2: Segments
B4: Regions | D4: Weight | E4: 2020 | F4: =+E4+1 -> 2021 | G4: =+F4+1 -> 2022 | H4: =+G4+1 -> 2023 | I4: =+H4+1 -> 2024 | J4: ="CAGR "&$G$4&" - "&$I$4 -> CAGR 2022 - 2024 | K4: 2021 | L4: =+K4+1 -> 2022 | M4: =+L4+1 -> 2023 | N4: =+M4+1 -> 2024
B6: North and South America | D6: =IFERROR(I6/SUM($I$6:$I$12),"") -> 0.59944199 | G6: 10251 | H6: 11654 | I6: 12891 | J6: =IFERROR((I6/G6)^(1/COUNT($G$4:$I$4))-1,"") -> 0.079377742 | L6: =IFERROR(G6-F6/F6,"") | M6: =IFERROR((H6-G6)/G6,"") -> 0.1368647 | N6: =IFERROR((I6-H6)/H6,"") -> 0.10614381
B7: APAC | D7: =IFERROR(I7/SUM($I$6:$I$12),"") -> 0.14229249 | G7: 2762 | H7: 2874 | I7: 3060 | J7: =IFERROR((I7/G7)^(1/COUNT($G$4:$I$4))-1,"") -> 0.034743207 | L7: =IFERROR(G7-F7/F7,"") | M7: =IFERROR((H7-G7)/G7,"") -> 0.040550326 | N7: =IFERROR((I7-H7)/H7,"") -> 0.064718163
B8: EMEA | D8: =IFERROR(I8/SUM($I$6:$I$12),"") -> 0.25826552 | G8: 4593 | H8: 4881 | I8: 5554 | J8: =IFERROR((I8/G8)^(1/COUNT($G$4:$I$4))-1,"") -> 0.065376575 | L8: =IFERROR(G8-F8/F8,"") | M8: =IFERROR((H8-G8)/G8,"") -> 0.062704115 | N8: =IFERROR((I8-H8)/H8,"") -> 0.13788158
J9: =IFERROR((I9/E9)^(1/COUNT($E$4:$I$4))-1,"") | L9: =IFERROR(G9-F9/F9,"") | M9: =IFERROR(H9-G9/G9,"") | N9: =IFERROR((I9-H9)/H9,"")
J10: =IFERROR((I10/E10)^(1/COUNT($E$4:$I$4))-1,"") | K10: =IFERROR(F10-E10/E10,"") | L10: =IFERROR(G10-F10/F10,"") | M10: =IFERROR(H10-G10/G10,"") | N10: =IFERROR((I10-H10)/H10,"")
B13: Total | D13: =SUM(D6:D12) -> 1 | E13: =SUM(E6:E10) -> 0 | F13: =SUM(F6:F10) -> 0 | G13: =SUM(G6:G10) -> 17606 | H13: =SUM(H6:H10) -> 19409 | I13: =SUM(I6:I10) -> 21505 | J13: =IFERROR((I13/G13)^(1/COUNT($G$4:$I$4))-1,"") -> 0.068955394 | K13: =IFERROR(F13-E13/E13,"") | L13: =IFERROR(G13-F13/F13,"") | M13: =IFERROR((H13-G13)/G13,"") -> 0.10240827 | N13: =IFERROR((I13-H13)/H13,"") -> 0.10799114
B15: Segments | D15: Weight | E15: 2020 | F15: =+E15+1 -> 2021 | G15: =+F15+1 -> 2022 | H15: =+G15+1 -> 2023 | I15: =+H15+1 -> 2024 | J15: ="CAGR "&$E$4&" - "&$I$4 -> CAGR 2020 - 2024 | K15: 2021 | L15: =+K15+1 -> 2022 | M15: =+L15+1 -> 2023 | N15: =+M15+1 -> 2024
B17: Digital Media | D17: =IFERROR(I17/SUM($I$17:$I$21),"") -> 0.73768891 | G17: 12842 | H17: 14216 | I17: 15864 | J17: =IFERROR((I17/G17)^(1/COUNT($G$4:$I$4))-1,"") -> 0.072984245 | K17: =IFERROR((F17-E17)/E17,"") | L17: =IFERROR((G17-F17)/F17,"") | M17: =IFERROR((H17-G17)/G17,"") -> 0.10699268 | N17: =IFERROR((I17-H17)/H17,"") -> 0.11592572
B18: Digital Experience | D18: =IFERROR(I18/SUM($I$17:$I$21),"") -> 0.24952337 | G18: 4422 | H18: 4893 | I18: 5366 | J18: =IFERROR((I18/G18)^(1/COUNT($G$4:$I$4))-1,"") -> 0.066622261 | K18: =IFERROR((F18-E18)/E18,"") | L18: =IFERROR((G18-F18)/F18,"") | M18: =IFERROR((H18-G18)/G18,"") -> 0.10651289 | N18: =IFERROR((I18-H18)/H18,"") -> 0.09666871
B19: Publishing & Advertising | D19: =IFERROR(I19/SUM($I$17:$I$21),"") -> 0.012787724 | G19: 342 | H19: 300 | I19: 275 | J19: =IFERROR((I19/G19)^(1/COUNT($G$4:$I$4))-1,"") -> -0.070101538 | K19: =IFERROR((F19-E19)/E19,"") | L19: =IFERROR((G19-F19)/F19,"") | M19: =IFERROR((H19-G19)/G19,"") -> -0.12280702 | N19: =IFERROR((I19-H19)/H19,"") -> -0.083333333
J20: =IFERROR((I20/E20)^(1/COUNT($E$4:$I$4))-1,"") | K20: =IFERROR((F20-E20)/E20,"") | L20: =IFERROR((G20-F20)/F20,"") | M20: =IFERROR((H20-G20)/G20,"") | N20: =IFERROR((I20-H20)/H20,"")
J21: =IFERROR((I21/E21)^(1/COUNT($E$4:$I$4))-1,"") | K21: =IFERROR((F21-E21)/E21,"") | L21: =IFERROR((G21-F21)/F21,"") | M21: =IFERROR((H21-G21)/G21,"") | N21: =IFERROR((I21-H21)/H21,"")
B22: Total | D22: =SUM(D17:D21) -> 1 | E22: =SUM(E17:E21) -> 0 | F22: =SUM(F17:F21) -> 0 | G22: =SUM(G17:G21) -> 17606 | H22: =SUM(H17:H21) -> 19409 | I22: =SUM(I17:I21) -> 21505 | J22: =IFERROR((I22/E22)^(1/COUNT($E$4:$I$4))-1,"") | K22: =IFERROR((F22-E22)/E22,"") | L22: =IFERROR((G22-F22)/F22,"") | M22: =IFERROR((H22-G22)/G22,"") -> 0.10240827 | N22: =IFERROR((I22-H22)/H22,"") -> 0.10799114
B24: Categories | D24: Description | J24: Graphs
B26: Content management | D26: Adobe offers enterprise-level content management through Adobe Experience Manager, which enables organizations to efficiently manage and deliver personalized digital content across web, mobile, and other platforms. It integrates seamlessly with Adobe’s creative and data platforms, helping brands deliver cohesive customer experiences.
B27: Creativity and Design | D27: Adobe’s Creativity and Design category, primarily delivered through Creative Cloud, includes industry-leading tools for graphic design, photography, video editing, illustration, 3D content, and generative AI. These applications empower individuals, teams, and enterprises to produce compelling digital content across platforms and formats.
B28: Data and analytics | D28: Adobe’s Data and Analytics solutions, offered through Adobe Experience Cloud, help businesses collect, analyze, and activate real-time customer data to deliver personalized digital experiences. These tools enable marketers and analysts to drive insights and optimize customer journeys at scale.
B29: =IF(B20=0,"",B20)
B30: =IF(B21=0,"",B21)
B31: Campaign management | D31: Adobe’s Campaign Management tools, led by Adobe Campaign, empower brands to design, orchestrate, and deliver personalized cross-channel marketing campaigns. These solutions enable marketers to automate messaging across email, mobile, web, and offline channels, optimizing engagement and customer lifecycle strategies.
B32: Document Productivity | D32: Adobe’s Document Productivity solutions, delivered through Adobe Document Cloud, streamline the creation, editing, sharing, and signing of digital documents. Powered by Adobe Acrobat and Adobe Sign, these tools help individuals and businesses accelerate workflows, reduce paperwork, and ensure secure, compliant document handling across devices.
B33: Workflow management | D33: This segment derives its revenue from software solutions that help enterprises streamline, coordinate, and automate work processes across teams. Adobe’s workflow management capabilities are primarily delivered through tools such as Adobe Workfront, enabling companies to plan projects, manage digital content workflows, and collaborate efficiently across marketing and creative departments.
B35: Products | D35: Weight | E35: 2020 | F35: =+E35+1 -> 2021 | G35: =+F35+1 -> 2022 | H35: =+G35+1 -> 2023 | I35: =+H35+1 -> 2024 | J35: =I35+1 -> 2025 | K35: =+J35+1 -> 2026 | L35: =+K35+1 -> 2027 | M35: =+L35+1 -> 2028 | N35: =+M35+1 -> 2029 | O35: =+N35+1 -> 2030 | P35: =+O35+1 -> 2031 | Q35: =+P35+1 -> 2032 | R35: =+Q35+1 -> 2033 | ... T35: =+S35+1 -> 2035
B37: Creative Cloud | D37: =I37/I$40 -> 0.79942007 | G37: 10459 | H37: 11517 | I37: 12682
B38: Document Cloud | D38: =I38/I$40 -> 0.20057993 | G38: 2383 | H38: 2699 | I38: 3182
B40: Total | D40: =SUM(D37:D39) -> 1 | E40: =SUM(E37:E39) -> 0 | F40: =SUM(F37:F39) -> 0 | G40: =SUM(G37:G39) -> 12842 | H40: =SUM(H37:H39) -> 14216 | I40: =SUM(I37:I39) -> 15864 | J40: =SUM(J37:J39) -> 0 | K40: =SUM(K37:K39) -> 0 | ... T40: =SUM(T37:T39) -> 0
B42: Company's Strategy / Extra Notes
B44: Dividends | E44: Adobe does not anticipate paying any cash dividends in the foreseeable future.
B45: Expansion | D45: Adobe is expanding product accessibility in regions like Southeast Asia, Latin America, and Africa through localized pricing, web-based tools, and mobile-first solutions.
B46: AI Investment | D46: The company’s flagship generative AI tool, trained on licensed and public domain content. It powers features like: Text-to-image generation Generative fill (Photoshop) Text-to-vector (Illustrator) Video extension and editing tools (Premiere Pro)

Sheet Industry
J1: Média
B2: Industry Overview | G2: =G11/F11-1 -> 0.097186701 | H2: =H11/G11-1 -> 0.1013986 | I2: =I11/H11-1 -> 0.076895944 | J2: =SUM(G2:I2)/3 -> 0.091827082
B4: Sales Growth Forecast | E4: Weight | F4: 2025 | G4: =+F4+1 -> 2026 | H4: =+G4+1 -> 2027 | I4: =+H4+1 -> 2028 | J4: =+I4+1 -> 2029 | K4: =+J4+1 -> 2030 | L4: =+K4+1 -> 2031 | M4: =+L4+1 -> 2032 | N4: =+M4+1 -> 2033 | ... P4: =+O4+1 -> 2035 | Q4: ="CAGR "&$F$4&" - "&$P$4 -> CAGR 2025 - 2035 | R4: Sources
B6: Digital Media | E6: =Segments!D17 -> 0.73768891 | F6: 17306.182 | G6: 18988.113 | H6: 20913.481 | I6: 22521.642 | J6: =I6*(1+$J$2) -> 24589.739 | K6: =J6*(1+$J$2) -> 26847.743 | L6: =K6*(1+$J$2) -> 29313.093 | M6: =L6*(1+$J$2) -> 32004.829 | N6: =M6*(1+$J$2) -> 34943.739 | O6: =N6*(1+$J$2) -> 38152.52 | P6: =O6*(1+$J$2) -> 41655.955 | Q6: =IFERROR((P6/F6)^(1/COUNT($F$4:$P$4))-1,"") -> 0.083127597 | R6: https://elite.finviz.com/quote.ashx?t=ADBE&p=m&ty=ea
B7: Digital Experience | E7: =Segments!D18 -> 0.24952337 | F7: 5853.8182 | G7: 6422.7315 | H7: 7073.9874 | I7: 7617.9484 | J7: =I7*(1+$J$2) -> 8317.4824 | K7: =J7*(1+$J$2) -> 9081.2525 | L7: =K7*(1+$J$2) -> 9915.1574 | M7: =L7*(1+$J$2) -> 10825.637 | N7: =M7*(1+$J$2) -> 11819.724 | O7: =N7*(1+$J$2) -> 12905.095 | P7: =O7*(1+$J$2) -> 14090.132 | Q7: =IFERROR((P7/F7)^(1/COUNT($F$4:$P$4))-1,"") -> 0.083127597
B8: Publishing & Advertising | E8: =Segments!D19 -> 0.012787724 | F8: 300 | G8: 329.15601 | H8: 362.53197 | I8: 390.40921 | J8: =I8*(1+$J$2) -> 426.25935 | K8: =J8*(1+$J$2) -> 465.4015 | L8: =K8*(1+$J$2) -> 508.13796 | M8: =L8*(1+$J$2) -> 554.79878 | N8: =M8*(1+$J$2) -> 605.74434 | O8: =N8*(1+$J$2) -> 661.36807 | P8: =O8*(1+$J$2) -> 722.09957 | Q8: =IFERROR((P8/F8)^(1/COUNT($F$4:$P$4))-1,"") -> 0.083127597
Q9: =IFERROR((P9/F9)^(1/COUNT($F$4:$P$4))-1,"")
D10: Total | Q10: =IFERROR((P10/F10)^(1/COUNT($F$4:$P$4))-1,"")
B11: Weighted Average | E11: =SUM(E6:E10) -> 1 | F11: =SUM(F6:F10) -> 23460 | G11: =SUM(G6:G10) -> 25740 | H11: =SUM(H6:H10) -> 28350 | I11: =SUM(I6:I10) -> 30530 | J11: =SUM(J6:J10) -> 33333.481 | K11: =SUM(K6:K10) -> 36394.397 | L11: =SUM(L6:L10) -> 39736.388 | ... P11: =SUM(P6:P10) -> 56468.187 | Q11: =IFERROR((P11/F11)^(1/COUNT($F$4:$P$4))-1,"") -> 0.083127597
B13: Key Drivers | E13: Description
B15: Creative Cloud Dominance | E15: Adobe's Creative Cloud (Photoshop, Illustrator, Premiere Pro, etc.) continues to be its core revenue engine. Subscriptions provide a recurring revenue model with high margins. The dominance in creative industries (design, video editing, digital media) gives Adobe a near-monopoly in many niches
B16: Digital Experience & Marketing Cloud | E16: Adobe's enterprise tools for data-driven marketing, AI personalization, and customer analytics are gaining traction. Competes with Salesforce and Oracle in this space. More businesses are investing in customer experience platforms, which boosts Adobe’s position.
B17: Strong Brand & Ecosystem Lock-in | E17: High brand loyalty + steep learning curves = low churn. Many users are deeply embedded in the Adobe ecosystem, making switching expensive or impractical.
B18: Global Expansion & Education Sector | E18: Growth in emerging markets and widespread adoption in schools/universities builds long-term user loyalty.
B20: Industry Trends | E20: Description
B22: Rise of the Creator Economy | E22: Millions of individuals now earn income as creators — from YouTubers and TikTokers to freelancers and educators which increases the demand for Adobe Creative Cloud tools like Photoshop, Premiere Pro, Illustrator, and Adobe Express.
B23: Shift Toward Paperless, Digital Workflows | E23: Remote work, regulatory compliance, and ESG goals are pushing businesses to digitize forms, contracts, and approvals. Supports growth of Adobe Document Cloud (Acrobat and Adobe Sign).
B25: Emerging Market Expansion | E25: Adobe is expanding product accessibility in regions like Southeast Asia, Latin America, and Africa through localized pricing, web-based tools, and mobile-first solutions. Growth opportunity for Adobe Express and mobile Acrobat.
B26: Market Share | E26: Headquarters | G26: Revenues | H26: (in MM of USD) | I26: Market Share
B28: =Peers!D91 -> #VALUE! | E28: USA | G28: {=TRANSPOSE(Peers!D97:N97)} -> 21505 | I28: =IFERROR(G28/$G$40,"") -> 0.053883603
B29: #VALUE! | G29: 37895 | I29: =IFERROR(G29/$G$40,"") -> 0.094950902
B30: #VALUE! | G30: 16285 | I30: =IFERROR(G30/$G$40,"") -> 0.040804207
B31: #VALUE! | G31: 8446 | I31: =IFERROR(G31/$G$40,"") -> 0.021162563
B32: #VALUE! | G32: 2684 | I32: =IFERROR(G32/$G$40,"") -> 0.0067251147
B33: #VALUE! | G33: 2628 | I33: =IFERROR(G33/$G$40,"") -> 0.0065847993
B34: #VALUE! | G34: 35543.04 | I34: =IFERROR(G34/$G$40,"") -> 0.089057757
B35: #VALUE! | G35: 10984 | I35: =IFERROR(G35/$G$40,"") -> 0.027521855
B36: #VALUE! | G36: 6131 | I36: =IFERROR(G36/$G$40,"") -> 0.015362026
B37: #VALUE! | G37: 3626 | I37: =IFERROR(G37/$G$40,"") -> 0.0090854195
B38: #VALUE! | G38: 4359 | I38: =IFERROR(G38/$G$40,"") -> 0.010922047
B39: Others | E39: -- | G39: =G40-SUM(G28:G38) -> 249014.96 | I39: =IFERROR(G39/$G$40,"") -> 0.6239397
B40: Industry Size | E40: -- | G40: 399101 | I40: =SUM(I28:I39) -> 1
B42: Porter's Five Forces Analysis | E42: Rating | H42: Graph
B44: Threat of New Entrants | E44: =IFERROR(AVERAGE(E45:E50),"") -> 1.8333333
B45: Economies of scale | E45: 2
B46: Product differentiation | E46: 2
B47: Capital requirements | E47: 2
B48: Access to distribution channels | E48: 2
B49: Regulations | E49: 1
B50: Switching costs | E50: 2
...

Sheet Peers
Q2: Market Cap
D3: Revenue Growth | F3: EBITDA Margin | H3: Profit Margin | J3: EV / Revenue | L3: EV / EBITDA | N3: Price / Earnings
B4: Peers | C4: Ticker | D4: =+Inputs!O4&"-"&Inputs!P4 -> 2022-2023 | E4: =+Inputs!P4&"-"&Inputs!Q4 -> 2023-2024 | F4: 2023 | G4: 2024 | H4: =+Inputs!O4&"-"&Inputs!P4 -> 2022-2023 | I4: =+Inputs!P4&"-"&Inputs!Q4 -> 2023-2024 | J4: 2023 | K4: 2024 | L4: 2023 | M4: 2024 | N4: 2023 | O4: 2024
A6: =+D91 -> #VALUE! | B6: {=IFERROR(_FV(A6,"Name"),"")} -> ADOBE INC. | C6: {=IFERROR(_FV(A6,"Ticker symbol",TRUE),"")} -> ADBE | D6: =IFERROR(D94/D93-1,"") -> 0.10240827 | E6: =IFERROR(D97/D94-1,"") -> 0.10799114 | F6: =IFERROR(D95/D94,"") -> 0.35128033 | G6: =IFERROR(D100/D97,"") -> 0.35945129 | H6: =IFERROR(D96/D94,"") -> 0.27966407 | I6: =IFERROR(D105/D97,"") -> 0.25854452 | J6: {=IFERROR((_FV(A6,"Market cap",TRUE)/1000000+D$121-D$111)/D$94,"")} -> 7.9168324 | K6: {=IFERROR((_FV(A6,"Market cap",TRUE)/1000000+D$121-D$111)/D$97,"")} -> 7.1452127 | L6: {=+IFERROR((_FV(A6,"Market cap",TRUE)/1000000+D$121-D$111)/D$95,"")} -> 22.537078 | M6: {=IFERROR((_FV(A6,"Market cap",TRUE)/1000000+D$121-D$111)/D$100,"")} -> 19.878111 | N6: {=IFERROR((_FV(A6,"Market cap",TRUE)/1000000)/D$96,"")} -> 28.59521 | O6: {=IFERROR((_FV(A6,"Market cap",TRUE)/1000000)/D$105,"")} -> 27.916331 | Q6: 150005000
A7: =+E91 -> #VALUE! | B7: {=IFERROR(_FV(A7,"Nome"),"")} -> SALESFORCE, INC. | C7: CRM | D7: =+IFERROR(E94/E93-1,"") -> 0.1117951 | E7: =IFERROR(E97/E94-1,"") -> 0.087156095 | F7: =IFERROR(E95/E94,"") -> 0.2856815 | G7: =+IFERROR(E100/E97,"") -> 0.29404935 | H7: =IFERROR(E96/E94,"") -> 0.11865622 | I7: =+IFERROR(E105/E97,"") -> 0.16353081 | J7: =+IFERROR((Q7/1000000+E$121-E$111)/E$94,"") -> 6.9786557 | K7: =IFERROR(+(Q7/1000000+E$121-E$111)/E$97,"") -> 6.4191846 | L7: =IFERROR(+(Q7/1000000+E$121-E$111)/E$95,"") -> 24.428098 | M7: =IFERROR(+(Q7/1000000+E$121-E$111)/E$100,"") -> 21.830297 | N7: =IFERROR(+(Q7/1000000)/E$96,"") -> 58.198985 | O7: =IFERROR(+(Q7/1000000)/E$105,"") -> 38.84315 | Q7: 240711000000
A8: =+F91 -> #VALUE! | B8: {=IFERROR(_FV(A8,"Nome"),"")} -> INTUIT INC. | C8: INTU | D8: =IFERROR(F94/F93-1,"") -> 0.12902719 | E8: =IFERROR(+F97/F94-1,"") -> 0.13342149 | F8: =IFERROR(F95/F94,"") -> 0.2813892 | G8: =IFERROR(F100/F97,"") -> 0.28130181 | H8: =IFERROR(F96/F94,"") -> 0.16592428 | I8: =+IFERROR(F105/F97,"") -> 0.18194658 | J8: =+IFERROR((Q8/1000000+E$121-E$111)/E$94,"") -> 4.8534584 | K8: =IFERROR(+(Q8/1000000+E$121-E$111)/E$97,"") -> 4.4643621 | L8: =IFERROR(+(Q8/1000000+E$121-E$111)/E$95,"") -> 16.989054 | M8: =IFERROR(+(Q8/1000000+E$121-E$111)/E$100,"") -> 15.182357 | N8: =IFERROR(+(Q8/1000000)/E$96,"") -> 40.288443 | O8: =IFERROR(+(Q8/1000000)/E$105,"") -> 26.889301 | Q8: 166633000000
A9: =+G91 -> #VALUE! | B9: {=IFERROR(_FV(A9,"Nome"),"")} -> WORKDAY, INC. | C9: WDAY | D9: =+IFERROR(G94/G93-1,"") -> 0.16779279 | E9: =IFERROR(G97/G94-1,"") -> 0.16352115 | F9: =IFERROR(G95/G94,"") -> 0.10359554 | G9: =IFERROR(G100/G97,"") -> 0.12763438 | H9: =IFERROR(G96/G94,"") -> 0.19024659 | I9: =+IFERROR(G105/G97,"") -> 0.062278001 | J9: =+IFERROR((Q9/1000000+E$121-E$111)/E$94,"") -> 1.788995 | K9: =IFERROR(+(Q9/1000000+E$121-E$111)/E$97,"") -> 1.6455733 | L9: =IFERROR(+(Q9/1000000+E$121-E$111)/E$95,"") -> 6.2622012 | M9: =IFERROR(+(Q9/1000000+E$121-E$111)/E$100,"") -> 5.5962488 | N9: =IFERROR(+(Q9/1000000)/E$96,"") -> 14.462041 | O9: =IFERROR(+(Q9/1000000)/E$105,"") -> 9.6522511 | Q9: 59815000000
A10: =+H91 -> #VALUE! | B10: {=IFERROR(_FV(A10,"Nome"),"")} -> DATADOG, INC. | C10: DDOG | D10: =IFERROR(H94/H93-1,"") -> 0.27044776 | E10: =IFERROR(H97/H94-1,"") -> 0.2612782 | F10: =IFERROR(H95/H94,"") -> 0.052161654 | G10: =IFERROR(H100/H97,"") -> 0.099105812 | H10: =IFERROR(H96/H94,"") -> 0.022556391 | I10: =+IFERROR(H105/H97,"") -> 0.068554396 | J10: =+IFERROR((Q10/1000000+E$121-E$111)/E$94,"") -> 1.0100123 | K10: =IFERROR(+(Q10/1000000+E$121-E$111)/E$97,"") -> 0.92904077 | L10: =IFERROR(+(Q10/1000000+E$121-E$111)/E$95,"") -> 3.5354489 | M10: =IFERROR(+(Q10/1000000+E$121-E$111)/E$100,"") -> 3.1594723 | N10: =IFERROR(+(Q10/1000000)/E$96,"") -> 7.8970019 | O10: =IFERROR(+(Q10/1000000)/E$105,"") -> 5.2706148 | Q10: 32662000000
A11: =+I91 -> #VALUE! | B11: {=IFERROR(_FV(A11,"Nome"),"")} -> HUBSPOT, INC. | C11: HUBS | D11: =+IFERROR(I94/I93-1,"") -> 0.25361063 | E11: =IFERROR(I97/I94-1,"") -> 0.21105991 | F11: =IFERROR(I95/I94,"") -> -0.034101382 | G11: =IFERROR(I100/I97,"") -> 0.049086758 | H11: =IFERROR(I96/I94,"") -> -0.076036866 | I11: =+IFERROR(I105/I97,"") -> 0.0019025875 | J11: =+IFERROR((Q11/1000000+E$121-E$111)/E$94,"") -> 0.91978656 | K11: =IFERROR(+(Q11/1000000+E$121-E$111)/E$97,"") -> 0.84604829 | L11: =IFERROR(+(Q11/1000000+E$121-E$111)/E$95,"") -> 3.2196224 | M11: =IFERROR(+(Q11/1000000+E$121-E$111)/E$100,"") -> 2.8772323 | N11: =IFERROR(+(Q11/1000000)/E$96,"") -> 7.1366054 | O11: =IFERROR(+(Q11/1000000)/E$105,"") -> 4.7631112 | Q11: 29517000000
A12: =+J91 -> #VALUE! | B12: {=IFERROR(_FV(A12,"Nome"),"")} -> Sap Se | C12: SAP | D12: =IFERROR(J94/J93-1,"") -> 0.086824168 | E12: =IFERROR(J97/J94-1,"") -> 0.035404061 | F12: =IFERROR(J95/J94,"") -> 0.24039478 | G12: =IFERROR(J100/J97,"") -> 0.1893434 | H12: =IFERROR(J96/J94,"") -> 0.10010575 | I12: =+IFERROR(J105/J97,"") -> 0.091409176 | J12: =+IFERROR((Q12/1000000+E$121-E$111)/E$94,"") -> 9.3438047 | K12: =IFERROR(+(Q12/1000000+E$121-E$111)/E$97,"") -> 8.5947223 | L12: =IFERROR(+(Q12/1000000+E$121-E$111)/E$95,"") -> 32.70707 | M12: =IFERROR(+(Q12/1000000+E$121-E$111)/E$100,"") -> 29.228843 | N12: =IFERROR(+(Q12/1000000)/E$96,"") -> 78.13177 | O12: =IFERROR(+(Q12/1000000)/E$105,"") -> 52.146684 | Q12: 323153000000
A13: =+K91 -> #VALUE! | B13: {=IFERROR(_FV(A13,"Nome"),"")} -> SERVICENOW, INC. | C13: NOW | D13: =IFERROR(K94/K93-1,"") -> 0.23823326 | E13: =IFERROR(K97/K94-1,"") -> 0.2243897 | F13: =+IFERROR(K95/K94,"") -> 0.17768365 | G13: =IFERROR(K100/K97,"") -> 0.21167152 | H13: =IFERROR(K96/K94,"") -> 0.19295508 | I13: =+IFERROR(K105/K97,"") -> 0.12973416 | J13: =+IFERROR((Q13/1000000+E$121-E$111)/E$94,"") -> 1.6889004 | K13: =IFERROR(+(Q13/1000000+E$121-E$111)/E$97,"") -> 1.5535031 | L13: =IFERROR(+(Q13/1000000+E$121-E$111)/E$95,"") -> 5.9118297 | M13: =IFERROR(+(Q13/1000000+E$121-E$111)/E$100,"") -> 5.2831374 | N13: =IFERROR(+(Q13/1000000)/E$96,"") -> 13.618472 | O13: =IFERROR(+(Q13/1000000)/E$105,"") -> 9.0892367 | Q13: 56326000000
A14: =+L91 -> #VALUE! | B14: {=IFERROR(_FV(A14,"Nome"),"")} -> AUTODESK, INC. | C14: ADSK | D14: =IFERROR(K94/K93-1,"") -> 0.23823326 | E14: =IFERROR(L97/L94-1,"") -> 0.11533564 | F14: =IFERROR(L95/L94,"") -> 0.22175732 | G14: =IFERROR(L100/L97,"") -> 0.25265046 | H14: =IFERROR(L96/L94,"") -> 0.16481717 | I14: =+IFERROR(L105/L97,"") -> 0.18137335 | J14: =+IFERROR((Q14/1000000+E$121-E$111)/E$94,"") -> 4.8993029 | K14: =IFERROR(+(Q14/1000000+E$121-E$111)/E$97,"") -> 4.5065312 | L14: =IFERROR(+(Q14/1000000+E$121-E$111)/E$95,"") -> 17.149528 | M14: =IFERROR(+(Q14/1000000+E$121-E$111)/E$100,"") -> 15.325765 | N14: =IFERROR(+(Q14/1000000)/E$96,"") -> 40.674807 | O14: =IFERROR(+(Q14/1000000)/E$105,"") -> 27.147168 | Q14: 168231000000
A15: =+M91 -> #VALUE! | B15: {=IFERROR(_FV(A15,"Nome"),"")} -> SNOWFLAKE INC. | C15: SNOW | D15: =IFERROR(M94/M93-1,"") -> 0.35818006 | E15: =IFERROR(M97/M94-1,"") -> 0.29223093 | F15: =IFERROR(M95/M94,"") -> -0.25980043 | G15: =IFERROR(M100/M97,"") -> -0.30336459 | H15: =IFERROR(M96/M94,"") -> -0.297933 | I15: =+IFERROR(M105/M97,"") -> -0.34721456 | J15: =+IFERROR((Q15/1000000+E$121-E$111)/E$94,"") -> 1.4856987 | K15: =IFERROR(+(Q15/1000000+E$121-E$111)/E$97,"") -> 1.3665919 | L15: =IFERROR(+(Q15/1000000+E$121-E$111)/E$95,"") -> 5.2005423 | M15: =IFERROR(+(Q15/1000000+E$121-E$111)/E$100,"") -> 4.6474917 | N15: =IFERROR(+(Q15/1000000)/E$96,"") -> 11.905948 | O15: =IFERROR(+(Q15/1000000)/E$105,"") -> 7.9462643 | Q15: 49243000000
A16: =+N91 -> #VALUE! | B16: {=IFERROR(_FV(A16,"Nome"),"")} -> ATLASSIAN CORPORATION | C16: TEAM | D16: =IFERROR(N94/N93-1,"") -> 0.26150553 | E16: =IFERROR(N97/N94-1,"") -> 0.23274887 | F16: =IFERROR(N95/N94,"") -> -0.056561086 | G16: =IFERROR(N100/N97,"") -> 0.0061940812 | H16: =IFERROR(N96/N94,"") -> -0.085124434 | I16: =+IFERROR(N105/N97,"") -> -0.069052535 | J16: =+IFERROR((Q16/1000000+E$121-E$111)/E$94,"") -> 1.638437 | K16: =IFERROR(+(Q16/1000000+E$121-E$111)/E$97,"") -> 1.5070854 | L16: =IFERROR(+(Q16/1000000+E$121-E$111)/E$95,"") -> 5.7351878 | M16: =IFERROR(+(Q16/1000000+E$121-E$111)/E$100,"") -> 5.1252804 | N16: =IFERROR(+(Q16/1000000)/E$96,"") -> 13.193182 | O16: =IFERROR(+(Q16/1000000)/E$105,"") -> 8.8053897 | Q16: 54567000000
B17: Average | C17: {=IFERROR(_FV(A17,"Ticker symbol",TRUE),"")} | D17: =IFERROR(AVERAGE(D6:D16),"") -> 0.20164164 | E17: =IFERROR(AVERAGE(E6:E16),"") -> 0.16950338 | F17: =IFERROR(AVERAGE(F6:F16),"") -> 0.12395283 | G17: =IFERROR(AVERAGE(G6:G16),"") -> 0.14246584 | H17: =IFERROR(AVERAGE(H6:H16),"") -> 0.070530114 | I17: =IFERROR(AVERAGE(I6:I16),"") -> 0.065727862 | J17: =IFERROR(AVERAGE(J6:J16),"") -> 3.8658076 | K17: =IFERROR(AVERAGE(K6:K16),"") -> 3.5434414 | ... O17: =IFERROR(AVERAGE(O6:O16),"") -> 19.860864
B18: Deviation from Average | D18: =IFERROR(+D17-D6,"") -> 0.099233369 | E18: =IFERROR(E17-E6,"") -> 0.061512242 | F18: =+IFERROR(F17-F6,"") -> -0.22732751 | G18: =IFERROR(G17-G6,"") -> -0.21698545 | H18: =IFERROR(+H6-H17,"") -> 0.20913396 | I18: =+IFERROR(I6-I17,"") -> 0.19281666 | J18: =+IFERROR(J6-J17,"") -> 4.0510248 | K18: =+IFERROR(K6-K17,"") -> 3.6017713 | L18: =IFERROR(+L6-L17,"") -> 9.4756547 | M18: =IFERROR(M6-M17,"") -> 8.2295443 | N18: =IFERROR(+N6-N17,"") -> 0.040440621 | O18: =IFERROR(+O6-O17,"") -> 8.0554671
D20: Trading Multiple | G20: Net | H20: Preferred | I20: Non-Controlling | J20: Equity Value | M20: Implied Upside (Downside)
B21: Implied Share Price | D21: Revenue | E21: EBITDA | F21: P/E | G21: Debt | H21: Stock | I21: Interest | J21: Revenue | K21: EBITDA | L21: P/E | M21: Revenue | N21: EBITDA | O21: P/E | Q21: Current Price
B23: Second Minimum | D23: =IFERROR(SMALL(K6:K16,2),"") -> 0.92904077 | E23: =IFERROR(SMALL(M6:M16,2),"") -> 3.1594723 | F23: =IFERROR(SMALL(O6:O16,2),"") -> 5.2706148 | G23: =-Inputs!$Q$99+Inputs!$Q$100 -> -1830 | H23: =+Inputs!$Q$101 -> 0 | I23: =+Inputs!$Q$102 -> 0 | J23: =IFERROR(+D23*$D$97+G23+H23+I23,"") -> 18149.022 | K23: =IFERROR(E23*$D$100+G23+H23+I23,"") -> 22592.721 | L23: =IFERROR(F23*$D$105,"") -> 29304.618 | M23: {=IFERROR(+(J23/_FV($A$6,"Shares outstanding",TRUE)*1000000)/$Q$23-1,"")} -> -0.88307156 | N23: {=IFERROR((+K23/_FV($A$6,"Shares outstanding",TRUE)*1000000)/$Q$23-1,"")} -> -0.85444221 | O23: {=IFERROR(+(L23/_FV($A$6,"Shares outstanding",TRUE)*1000000)/$Q$23-1,"")} -> -0.81119956 | Q23: {=+_FV(A6,"Price")} -> 365.9
B24: Average | D24: =+IFERROR(AVERAGE(K6:K16),"") -> 3.5434414 | E24: =IFERROR(+AVERAGE(M6:M16),"") -> 11.648567 | F24: =IFERROR(+AVERAGE(O6:O16),"") -> 19.860864 | G24: =-Inputs!$Q$99+Inputs!$Q$100 -> -1830 | H24: =+Inputs!$Q$101 -> 0 | I24: =+Inputs!$Q$102 -> 0 | J24: =IFERROR(+D24*$D$97+G24+H24+I24,"") -> 74371.708 | K24: =IFERROR(E24*$D$100+G24+H24+I24,"") -> 88213.422 | L24: =IFERROR(+F24*$D$105,"") -> 110426.4 | M24: {=IFERROR(+(J24/_FV($A$6,"Shares outstanding",TRUE)*1000000)/$Q$23-1,"")} -> -0.52084648 | N24: {=IFERROR((+K24/_FV($A$6,"Shares outstanding",TRUE)*1000000)/$Q$23-1,"")} -> -0.43166867 | O24: {=IFERROR(+(L24/_FV($A$6,"Shares outstanding",TRUE)*1000000)/$Q$23-1,"")} -> -0.28855743
B25: Median | D25: =IFERROR(MEDIAN(K6:K16),"") -> 1.6455733 | E25: =IFERROR(MEDIAN(M6:M16),"") -> 5.5962488 | F25: =IFERROR(MEDIAN(O6:O16),"") -> 9.6522511 | G25: =-Inputs!$Q$99+Inputs!$Q$100 -> -1830 | H25: =+Inputs!$Q$101 -> 0 | I25: =+Inputs!$Q$102 -> 0 | J25: =IFERROR(D25*$D$97+G25+H25+I25,"") -> 33558.054 | K25: =IFERROR(E25*$D$100+G25+H25+I25,"") -> 41429.003 | L25: =IFERROR(+F25*$D$105,"") -> 53666.516 | M25: {=IFERROR(+(J25/_FV($A$6,"Shares outstanding",TRUE)*1000000)/$Q$23-1,"")} -> -0.78379602 | N25: {=IFERROR((+K25/_FV($A$6,"Shares outstanding",TRUE)*1000000)/$Q$23-1,"")} -> -0.73308597 | O25: {=+IFERROR((L25/_FV($A$6,"Shares outstanding",TRUE)*1000000)/$Q$23-1,"")} -> -0.65424352
B26: Second Maximum | D26: =IFERROR(LARGE(K6:K16,2),"") -> 7.1452127 | E26: =IFERROR(LARGE(M6:M16,2),"") -> 21.830297 | F26: =IFERROR(LARGE(O6:O16,2),"") -> 38.84315 | G26: =-Inputs!$Q$99+Inputs!$Q$100 -> -1830 | H26: =+Inputs!$Q$101 -> 0 | I26: =+Inputs!$Q$102 -> 0 | J26: =IFERROR(+D26*$D$97+G26+H26+I26,"") -> 151827.8 | K26: =IFERROR(E26*$D$100+G26+H26+I26,"") -> 166918.2 | L26: =IFERROR(+F26*$D$105,"") -> 215967.91 | M26: {=IFERROR(+(J26/_FV($A$6,"Shares outstanding",TRUE)*1000000)/$Q$23-1,"")} -> -0.021821247 | N26: {=IFERROR((+K26/_FV($A$6,"Shares outstanding",TRUE)*1000000)/$Q$23-1,"")} -> 0.075401429 | O26: {=IFERROR(+(L26/_FV($A$6,"Shares outstanding",TRUE)*1000000)/$Q$23-1,"")} -> 0.39141333
B28: Profitability | D28: =+LEFT(B6, FIND(" ", B6 & " ") - 1) -> ADOBE | E28: =+LEFT(B7, FIND(" ", B7 & " ") - 1) -> SALESFORCE, | F28: =+LEFT(B8, FIND(" ", B8 & " ") - 1) -> INTUIT | G28: =+LEFT(B9, FIND(" ", B9 & " ") - 1) -> WORKDAY, | H28: =+LEFT(B10, FIND(" ", B10 & " ") - 1) -> DATADOG, | I28: =+LEFT(B11, FIND(" ", B11 & " ") - 1) -> HUBSPOT, | J28: =B12 -> Sap Se | K28: =+LEFT(B13, FIND(" ", B13 & " ") - 1) -> SERVICENOW, | L28: =+LEFT(B14, FIND(" ", B14 & " ") - 1) -> AUTODESK, | M28: =+LEFT(B15, FIND(" ", B15 & " ") - 1) -> SNOWFLAKE | N28: =+LEFT(B16, FIND(" ", B16 & " ") - 1) -> ATLASSIAN | O28: Average
B30: Operating Margin | D30: =IFERROR(D101/D97,"") -> 0.31960009 | E30: =IFERROR(E101/E97,"") -> 0.20229582 | F30: =IFERROR(F101/F97,"") -> 0.23807185 | G30: =IFERROR(G101/G97,"") -> 0.08903623 | H30: =IFERROR(H101/H97,"") -> 0.078614009 | I30: =IFERROR(I101/I97,"") -> 0.01217656 | J30: =IFERROR(J101/J97,"") -> 0.15189022 | K30: =IFERROR(K101/K97,"") -> 0.16032411 | ... N30: =IFERROR(N101/N97,"") -> -0.026841019 | O30: =IFERROR(+AVERAGE(D30:N30),"") -> 0.099536517
B31: Net Income Margin | D31: =IFERROR(D105/D97,"") -> 0.25854452 | E31: =IFERROR(E105/E97,"") -> 0.16353081 | F31: =IFERROR(F105/F97,"") -> 0.18194658 | G31: =IFERROR(G105/G97,"") -> 0.062278001 | H31: =IFERROR(H105/H97,"") -> 0.068554396 | I31: =IFERROR(I105/I97,"") -> 0.0019025875 | J31: =IFERROR(J105/J97,"") -> 0.091409176 | K31: =IFERROR(K105/K97,"") -> 0.12973416 | ... N31: =IFERROR(N105/N97,"") -> -0.069052535 | O31: =IFERROR(+AVERAGE(D31:N31),"") -> 0.065727862
B32: ROA (%) | D32: =IFERROR(D105/D117,"") -> 0.18532098 | E32: =IFERROR(E105/E117,"") -> 0.060207135 | F32: =IFERROR(F105/F117,"") -> 0.09221337 | G32: =IFERROR(G105/G117,"") -> 0.02925961 | H32: =IFERROR(H105/H117,"") -> 0.031806396 | I32: =IFERROR(I105/I117,"") -> 0.001317176 | J32: =IFERROR(J105/J117,"") -> 0.042146731 | K32: =IFERROR(K105/K117,"") -> 0.069911201 | ... N32: =IFERROR(N105/N117,"") -> -0.057751343 | O32: =IFERROR(+AVERAGE(D32:N32),"") -> 0.037974378
B33: Financial Cost of Debt | D33: =IFERROR(+(D102/D121)*(1-(D104/D103)),"") -> -0.022783554 | E33: =IFERROR(+(E102/E121)*(1-(E104/E103)),"") -> 0 | F33: =IFERROR(+(F102/F121)*(1-(F104/F103)),"") -> 0.012074242 | G33: =IFERROR(+(G102/G121)*(1-(G104/G103)),"") -> 0.057873448 | H33: =IFERROR(+(H102/H121)*(1-(H104/H103)),"") -> 0.072470248 | I33: =IFERROR(+(I102/I121)*(1-(I104/I103)),"") -> 0.018282805 | J33: =IFERROR(+(J102/J121)*(1-(J104/J103)),"") -> 0.014216212 | K33: =IFERROR(+(K102/K121)*(1-(K104/K103)),"") -> 0.14253009 | ... N33: =IFERROR(+(N102/N121)*(1-(N104/N103)),"") -> 0.17802477 | O33: =IFERROR(+AVERAGE(D33:N33),"") -> 0.048997672
B34: Return on Equity (RoE) | D34: =IFERROR(+D105/D122,"") -> 0.41203498 | E34: =IFERROR(+E105/E122,"") -> 0.10130286 | F34: =IFERROR(+F105/F122,"") -> 0.16071816 | G34: =IFERROR(+G105/G122,"") -> 0.058224485 | H34: =IFERROR(+H105/H122,"") -> 0.06779661 | I34: =IFERROR(+I105/I122,"") -> 0.0026205451 | J34: =IFERROR(+J105/J122,"") -> 0.06875 | K34: =IFERROR(+K105/K122,"") -> 0.14834478 | ... N34: =IFERROR(+N105/N122,"") -> -0.29138432 | O34: =IFERROR(+AVERAGE(D34:N34),"") -> 0.066636999
B35: Return on Invested Capital (ROIC) | D35: =IFERROR(+D105/(D121+D122),"") -> 0.28439898 | E35: =IFERROR(+E105/(E121+E122),"") -> 0.085399297 | F35: =IFERROR(+F105/(F121+F122),"") -> 0.11850578 | G35: =IFERROR(+G105/(G121+G122),"") -> 0.042433043 | H35: =IFERROR(+H105/(H121+H122),"") -> 0.040386304 | I35: =IFERROR(+I105/(I121+I122),"") -> 0.0018846589 | J35: =IFERROR(+J105/(J121+J122),"") -> 0.05569521 | K35: =IFERROR(+K105/(K121+K122),"") -> 0.11990912 | ... N35: =IFERROR(+N105/(N121+N122),"") -> -0.13190184 | O35: =IFERROR(+AVERAGE(D35:N35),"") -> 0.055447489
B37: Solvency | D37: =+D28 -> ADOBE | E37: =+E28 -> SALESFORCE, | F37: =+F28 -> INTUIT | G37: =+G28 -> WORKDAY, | H37: =+H28 -> DATADOG, | I37: =+I28 -> HUBSPOT, | J37: =+J28 -> Sap Se | K37: =+K28 -> SERVICENOW, | ... O37: =+O28 -> Average
B39: Debt/Assets | D39: =IFERROR(D121/D117,"") -> 0.20185321 | E39: =IFERROR(E121/E117,"") -> 0.11067931 | F39: =IFERROR(F121/F117,"") -> 0.2043757 | G39: =IFERROR(G121/G117,"") -> 0.18701674 | H39: =IFERROR(H121/H117,"") -> 0.31840968 | I39: =IFERROR(I121/I117,"") -> 0.19625922 | J39: =IFERROR(J121/J117,"") -> 0.14369553 | K39: =IFERROR(K121/K117,"") -> 0.1117598 | ... N39: =IFERROR(N121/N117,"") -> 0.23963929 | O39: =IFERROR(+AVERAGE(D39:N39),"") -> 0.20428379
B40: Net Debt/EBITDA | D40: =IFERROR(+(D121-D111)/D100,"") -> -0.20142303 | E40: =IFERROR(+(E121-E111)/E100,"") -> 0.22830477 | F40: =IFERROR(+(F121-F111)/F100,"") -> 0.64571054 | G40: =IFERROR(+(G121-G111)/G100,"") -> 1.687384 | H40: =IFERROR(+(H121-H111)/H100,"") -> 2.2368421 | I40: =IFERROR(+(I121-I111)/I100,"") -> -10.263566 | J40: =IFERROR(+(J121-J111)/J100,"") -> 0.16102612 | K40: =IFERROR(+(K121-K111)/K100,"") -> -0.011182796 | ... N40: =IFERROR(+(N121-N111)/N100,"") -> -34.37037 | O40: =IFERROR(+AVERAGE(D40:N40),"") -> -3.5744026
B41: Interest Coverage Ratio | D41: =IFERROR(D101/D102,"") -> -39.959302 | E41: =IFERROR(E101/E102,"") | F41: =IFERROR(F101/F102,"") -> 40.810526 | G41: =IFERROR(G101/G102,"") -> 3.1864407 | H41: =IFERROR(H101/H102,"") -> 1.4256757 | I41: =IFERROR(I101/I102,"") -> 0.40506329 | J41: =IFERROR(J101/J102,"") -> 22.668122 | K41: =IFERROR(K101/K102,"") -> 4.4469697 | ... N41: =IFERROR(N101/N102,"") -> -1.8571429 | O41: =IFERROR(+AVERAGE(D41:N41),"") -> -1.5361654
B43: Liquidity | D43: =+D28 -> ADOBE | E43: =+E28 -> SALESFORCE, | F43: =+F28 -> INTUIT | G43: =+G28 -> WORKDAY, | H43: =+H28 -> DATADOG, | I43: =+I28 -> HUBSPOT, | J43: =+J28 -> Sap Se | K43: =+K28 -> SERVICENOW, | ... O43: =+O28 -> Average
B45: Cash Ratio | D45: =IFERROR(D111/D119,"") -> 0.72360042 | E45: =IFERROR(E111/E119,"") -> 0.31622588 | F45: =IFERROR(F111/F119,"") -> 0.48177813 | G45: =IFERROR(G111/G119,"") -> 0.27811824 | H45: =IFERROR(H111/H119,"") -> 0.66935051 | I45: =IFERROR(I111/I119,"") -> 1.315321 | J45: =IFERROR(J111/J119,"") -> 0.50364275 | K45: =IFERROR(K111/K119,"") -> 0.27566403 | ... N45: =IFERROR(N111/N119,"") -> 0.83409962 | O45: =IFERROR(+AVERAGE(D45:N45),"") -> 0.59133192
B46: Quick Ratio | D46: =IFERROR(+(D111+D112)/D119,"") -> 0.92053987 | E46: =IFERROR(+(E111+E112)/E119,"") -> 0.74313796 | F46: =IFERROR(+(F111+F112)/F119,"") -> 0.54278467 | G46: =IFERROR(+(G111+G112)/G119,"") -> 0.62959625 | H46: =IFERROR(+(H111+H112)/H119,"") -> 0.99087493 | I46: =IFERROR(+(I111+I112)/I119,"") -> 1.5282899 | J46: =IFERROR(+(J111+J112)/J119,"") -> 0.83023219 | K46: =IFERROR(+(K111+K112)/K119,"") -> 0.54367073 | ... N46: =IFERROR(+(N111+N112)/N119,"") -> 1.0747126 | O46: =IFERROR(+AVERAGE(D46:N46),"") -> 0.853272
B47: Current Ratio | D47: =IFERROR(D115/D119,"") -> 1.0675791 | E47: =IFERROR(E115/E119,"") -> 1.0624375 | F47: =IFERROR(F115/F119,"") -> 1.2919503 | G47: =IFERROR(G115/G119,"") -> 1.9006849 | H47: =IFERROR(H115/H119,"") -> 2.6360709 | I47: =IFERROR(I115/I119,"") -> 1.6745073 | J47: =IFERROR(J115/J119,"") -> 1.1217045 | K47: =IFERROR(K115/K119,"") -> 1.0991864 | ... N47: =IFERROR(N115/N119,"") -> 1.1785441 | O47: =IFERROR(+AVERAGE(D47:N47),"") -> 1.4078724
B49: Activity | D49: =+D28 -> ADOBE | E49: =+E28 -> SALESFORCE, | F49: =+F28 -> INTUIT | G49: =+G28 -> WORKDAY, | H49: =+H28 -> DATADOG, | I49: =+I28 -> HUBSPOT, | J49: =+J28 -> Sap Se | K49: =+K28 -> SERVICENOW, | ... O49: =+O28 -> Average
B51: Inventory Turnover | D51: =IFERROR(D98/(AVERAGE(D113:D114)),"") | E51: =IFERROR(E98/(AVERAGE(E113:E114)),"") | F51: =IFERROR(F98/(AVERAGE(F113:F114)),"") | G51: =IFERROR(G98/(AVERAGE(G113:G114)),"") | H51: =IFERROR(H98/(AVERAGE(H113:H114)),"") | I51: =IFERROR(I98/(AVERAGE(I113:I114)),"") | J51: =IFERROR(J98/(AVERAGE(J113:J114)),"") | K51: =IFERROR(K98/(AVERAGE(K113:K114)),"") | ... N51: =IFERROR(N98/(AVERAGE(N113:N114)),"") | O51: =IFERROR(+AVERAGE(D51:N51),"")
B52: Acc. Receivable Turnover | D52: =IFERROR(D97/D112,"") -> 10.378861 | E52: =IFERROR(E97/E112,"") -> 3.1724571 | F52: =IFERROR(F97/F112,"") -> 35.634573 | G52: =IFERROR(G97/G112,"") -> 4.3312821 | H52: =IFERROR(H97/H112,"") -> 4.4808013 | I52: =IFERROR(I97/I112,"") -> 7.8447761 | J52: =IFERROR(J97/J112,"") -> 5.4848339 | K52: =IFERROR(K97/K112,"") -> 4.9035714 | ... N52: =IFERROR(N97/N112,"") -> 6.9410828 | O52: =IFERROR(+AVERAGE(D52:N52),"") -> 8.4711886
...

Sheet ESG
B2: Environmental, Social and Governance Analysis
B4: Author: | C4: Alexandra Gonçalves | E4: Highlights | N4: Recent News
B6: Overview | D6: .
B7: Last Update | C7: 45122 | D7: .
B8: Latest year with data | C8: 2023
B9: GICS Sector
B10: GICS Industry Group | C10: Software Development
B11: Final Review
B13: ESG Scores
B14: LSEG ESG Score | C14: 68
B15: E-Score | C15: 75
B16: S-Score | C16: 77 | E16: GHG Scope 1 and 2 Emissions: | N16: Water, Waste, Energy Management:
B17: G-Score | C17: 59
B18: S&P Global ESG Score | C18: 55
B19: Environmental | C19: 66
B20: Social | C20: 45
B21: Governance & Economic | C21: 63
B22: Sustainalytics | C22: 14.2
B23: ISS ESG Corporate Rating | C23: B
B24: SDG Impact Rating | C24: 4.7
B25: Governance Quality Score | C25: 2
B26: MSCI ESG Ratings
B29: Industry ESG Overview:
E33: ENVIRONMENTAL
G35: Overview | H35: Targets | K35: Improvements | O35: Comments
E36: GHG (or CO2) Scope 1 Emissions | H36: 42% reduction in absolute Scope 1 and 2 GHG emissions by FY 2030 from a FY 2022 base year | K36: Significant reduction in overall emissions | O36: Mantaining emissions but increasing revenues
E38: Water Consumption | H38: 25% reduction in global water usage per full time employee by 2025 | K38: Water usage going up
E40: Energy Consumption | H40: 80% of Adobe buildings, by square footage, are LEED or green building certified | K40: There isnt a relevant improvement
E42: Waste Management | H42: 90% global waste diversion rate annually through a combination of waste reduction, composting, reusing and responsible recycling | K42: There isnt a relevant improvement
E44: Other
E46: SOCIAL
B48: Important Sources: | G48: Overview | H48: Targets | K48: Improvements | O48: Comments
B49: Annual Report | C49: https://www.sec.gov/ix?doc=/Archives/edgar/data/0000796343/000079634325000004/adbe-20241129.htm | E49: Employee Turnover % | G49: Not reported | H49: Improve turnover and satisfaction | O49: 87% Employee satisfaction
B50: Sustainability Report | C50: https://www.adobe.com/corporate-responsibility/sustainability/corporate-policy.html | D50: .
B51: Proxy Statement | C51: https://www.sec.gov/ix?doc=/Archives/edgar/data/0000796343/000079634325000048/adbe-20250227.htm | D51: . | E51: Salaries & Compensation
E53: Reputation | O53: The brand has a very strong reputation
E55: Discrimination Events | G55: Not reported
E57: Work Safety | O57: There are no recent accidents to be reported
E59: Damage to consumer health | O59: Adobe's product does not cause harm to consumers
E61: Pension Plan | O61: Retired savings plan for US employees
...

Sheet ESG Inputs
B2: ESG Inputs
A4: x | B4: Total GHG Scope 1 Emissions | G4: 2014 | H4: =+G4+1 -> 2015 | I4: =+H4+1 -> 2016 | J4: =+I4+1 -> 2017 | K4: =+J4+1 -> 2018 | L4: =+K4+1 -> 2019 | M4: =+L4+1 -> 2020 | N4: =+M4+1 -> 2021 | O4: =+N4+1 -> 2022 | ... Q4: =+P4+1 -> 2024 | R4: ="CAGR "&$G$4&" - "&$Q$4 -> CAGR 2014 - 2024
B6: =+Peers!B6 -> ADOBE INC. | G6: 10976 | H6: 12365 | I6: 11082 | J6: 14177 | K6: 12199 | L6: 11817 | M6: 9842 | N6: 4911 | O6: 6586 | P6: 7649 | Q6: 7649 | R6: =IFERROR((Q6/G6)^(1/COUNT($G$4:$Q$4))-1,"") -> -0.032297486
B7: =+Peers!B7 -> SALESFORCE, INC. | G7: 6000 | H7: 5000 | I7: 3000 | J7: 0 | K7: 0 | L7: 0 | M7: 6000 | N7: 1000 | O7: 6000 | P7: 4000 | Q7: 3000 | R7: =IFERROR((Q7/G7)^(1/COUNT($G$4:$Q$4))-1,"") -> -0.061069089
B8: =+Peers!B8 -> INTUIT INC. | R8: =IFERROR((Q8/G8)^(1/COUNT($G$4:$Q$4))-1,"")
B9: =+Peers!B9 -> WORKDAY, INC. | G9: 1186 | H9: 1186 | I9: 1186 | J9: 1420 | K9: 1816 | L9: 2040 | M9: 1730 | N9: 1471 | O9: 1834 | P9: 2660 | Q9: 2752 | R9: =IFERROR((Q9/G9)^(1/COUNT($G$4:$Q$4))-1,"") -> 0.079525902
B10: =+Peers!B10 -> DATADOG, INC. | R10: =IFERROR((Q10/G10)^(1/COUNT($G$4:$Q$4))-1,"")
B11: =+Peers!B11 -> HUBSPOT, INC. | R11: =IFERROR((Q11/G11)^(1/COUNT($G$4:$Q$4))-1,"")
B12: =+Peers!B12 -> Sap Se | R12: =IFERROR((Q12/G12)^(1/COUNT($G$4:$Q$4))-1,"")
B13: =+Peers!B13 -> SERVICENOW, INC. | R13: =IFERROR((Q13/G13)^(1/COUNT($G$4:$Q$4))-1,"")
B14: =+Peers!B14 -> AUTODESK, INC. | R14: =IFERROR((Q14/G14)^(1/COUNT($G$4:$Q$4))-1,"")
B15: =+Peers!B15 -> SNOWFLAKE INC. | R15: =IFERROR((Q15/G15)^(1/COUNT($G$4:$Q$4))-1,"")
B16: =+Peers!B16 -> ATLASSIAN CORPORATION | R16: =IFERROR((Q16/G16)^(1/COUNT($G$4:$Q$4))-1,"")
A18: x | B18: Total GHG Scope 2 (Location-Based) Emissions | G18: 2014 | H18: =+G18+1 -> 2015 | I18: =+H18+1 -> 2016 | J18: =+I18+1 -> 2017 | K18: =+J18+1 -> 2018 | L18: =+K18+1 -> 2019 | M18: =+L18+1 -> 2020 | N18: =+M18+1 -> 2021 | O18: =+N18+1 -> 2022 | ... Q18: =+P18+1 -> 2024 | R18: ="CAGR "&$G$4&" - "&$Q$4 -> CAGR 2014 - 2024
B20: =+$B$6 -> ADOBE INC. | G20: 61425 | H20: 64352 | I20: 61875 | J20: 66288 | K20: 58874 | L20: 56128 | M20: 51176 | N20: 61220 | O20: 57168 | P20: 62662 | Q20: 62662 | R20: =IFERROR((Q20/G20)^(1/COUNT($G$4:$Q$4))-1,"") -> 0.0018142151
B21: =+$B$7 -> SALESFORCE, INC. | G21: 48000 | H21: 71000 | I21: 132000 | J21: 138000 | K21: 143000 | L21: 163000 | M21: 291000 | N21: 292000 | O21: 286000 | P21: 280000 | Q21: 315000 | R21: =IFERROR((Q21/G21)^(1/COUNT($G$4:$Q$4))-1,"") -> 0.18653083
B22: =+$B$8 -> INTUIT INC. | R22: =IFERROR((Q22/G22)^(1/COUNT($G$4:$Q$4))-1,"")
B23: =+$B$9 -> WORKDAY, INC. | G23: 17743 | H23: 17743 | I23: 17743 | J23: 27792 | K23: 33894 | L23: 34330 | M23: 36811 | N23: 40584 | O23: 45821 | P23: 60927 | Q23: 67557 | R23: =IFERROR((Q23/G23)^(1/COUNT($G$4:$Q$4))-1,"") -> 0.1292387
B24: =+$B$10 -> DATADOG, INC. | R24: =IFERROR((Q24/G24)^(1/COUNT($G$4:$Q$4))-1,"")
B25: =+$B$11 -> HUBSPOT, INC. | R25: =IFERROR((Q25/G25)^(1/COUNT($G$4:$Q$4))-1,"")
B26: =+$B$12 -> Sap Se | R26: =IFERROR((Q26/G26)^(1/COUNT($G$4:$Q$4))-1,"")
B27: =+$B$13 -> SERVICENOW, INC. | R27: =IFERROR((Q27/G27)^(1/COUNT($G$4:$Q$4))-1,"")
B28: =+$B$14 -> AUTODESK, INC. | R28: =IFERROR((Q28/G28)^(1/COUNT($G$4:$Q$4))-1,"")
B29: =+$B$15 -> SNOWFLAKE INC. | R29: =IFERROR((Q29/G29)^(1/COUNT($G$4:$Q$4))-1,"")
B30: =+$B$16 -> ATLASSIAN CORPORATION | R30: =IFERROR((Q30/G30)^(1/COUNT($G$4:$Q$4))-1,"")
A32: x | B32: Total Energy Usage | G32: 2014 | H32: =+G32+1 -> 2015 | I32: =+H32+1 -> 2016 | J32: =+I32+1 -> 2017 | K32: =+J32+1 -> 2018 | L32: =+K32+1 -> 2019 | M32: =+L32+1 -> 2020 | N32: =+M32+1 -> 2021 | O32: =+N32+1 -> 2022 | ... Q32: =+P32+1 -> 2024 | R32: ="CAGR "&$G$4&" - "&$Q$4 -> CAGR 2014 - 2024
B34: =+$B$6 -> ADOBE INC. | G34: 214736 | H34: 211345 | I34: 212931 | J34: 236956 | K34: 223248 | L34: 221486 | M34: 208187 | N34: 240344 | O34: 213082 | P34: 230771 | Q34: 230771 | R34: =IFERROR((Q34/G34)^(1/COUNT($G$4:$Q$4))-1,"") -> 0.0065684336
B35: =+$B$7 -> SALESFORCE, INC. | G35: 265000 | H35: 140000 | I35: 101000 | J35: 371000 | K35: 514000 | L35: 628000 | M35: 710000 | N35: 777000 | O35: 826000 | P35: 869000 | Q35: 945000 | R35: =IFERROR((Q35/G35)^(1/COUNT($G$4:$Q$4))-1,"") -> 0.12253198
B36: =+$B$8 -> INTUIT INC. | R36: =IFERROR((Q36/G36)^(1/COUNT($G$4:$Q$4))-1,"")
B37: =+$B$9 -> WORKDAY, INC. | G37: 46840 | H37: 46840 | I37: 46840 | J37: 66138 | K37: 80471 | L37: 106084 | M37: 108245 | N37: 132423 | O37: 160889 | P37: 212489 | Q37: 228188 | R37: =IFERROR((Q37/G37)^(1/COUNT($G$4:$Q$4))-1,"") -> 0.15482451
B38: AUTODESK INC | G38: 42000 | H38: 37800 | I38: 55600 | J38: 71900 | K38: 57500 | L38: 57800 | M38: 85600 | N38: 118000 | O38: 118000 | P38: 141000 | Q38: 60500 | R38: =IFERROR((Q38/G38)^(1/COUNT($G$4:$Q$4))-1,"") -> 0.033736007
B39: DATADOG INC | R39: =IFERROR((Q39/G39)^(1/COUNT($G$4:$Q$4))-1,"")
B40: =+$B$12 -> Sap Se | R40: =IFERROR((Q40/G40)^(1/COUNT($G$4:$Q$4))-1,"")
B41: =+$B$13 -> SERVICENOW, INC. | R41: =IFERROR((Q41/G41)^(1/COUNT($G$4:$Q$4))-1,"")
B42: HUBSPOT | R42: =IFERROR((Q42/G42)^(1/COUNT($G$4:$Q$4))-1,"")
B43: =+$B$15 -> SNOWFLAKE INC. | R43: =IFERROR((Q43/G43)^(1/COUNT($G$4:$Q$4))-1,"")
B44: =+$B$16 -> ATLASSIAN CORPORATION | R44: =IFERROR((Q44/G44)^(1/COUNT($G$4:$Q$4))-1,"")
