Workbook
Name COOLFUCNTION: _xlfn.LAMBDA(_xldudf_BOARDFLARE_EXEC("workbook-settings:coolfucntion"))
Name COOLFUCNTION: _xlfn.LAMBDA(_xldudf_BOARDFLARE_EXEC("workbook-settings:coolfucntion"))
Name COOLFUCNTION: _xlfn.LAMBDA(_xldudf_BOARDFLARE_EXEC("workbook-settings:coolfucntion"))
Name COOLFUCNTION: _xlfn.LAMBDA(_xldudf_BOARDFLARE_EXEC("workbook-settings:coolfucntion"))
Name COOLFUCNTION: _xlfn.LAMBDA(_xldudf_BOARDFLARE_EXEC("workbook-settings:coolfucntion"))
Name COOLFUCNTION: _xlfn.LAMBDA(_xldudf_BOARDFLARE_EXEC("workbook-settings:coolfucntion"))
Name COOLFUCNTION: _xlfn.LAMBDA(_xldudf_BOARDFLARE_EXEC("workbook-settings:coolfucntion"))
Name COOLFUCNTION: _xlfn.LAMBDA(_xldudf_BOARDFLARE_EXEC("workbook-settings:coolfucntion"))
Name COOLFUCNTION: _xlfn.LAMBDA(_xldudf_BOARDFLARE_EXEC("workbook-settings:coolfucntion"))
Name COOLFUCNTION: _xlfn.LAMBDA(_xldudf_BOARDFLARE_EXEC("workbook-settings:coolfucntion"))
Name Sectors: #REF!
Name Sectors: #REF!
Name Sectors: #REF!

Sheet Summary
E2: | EQUITY RESEARCH | U2: Lisbon Investment Society Equity Research
U3: March XX, 2025
D6: {=+_FV(DCF!R4,"Name")} -> ADVANCED MICRO DEVICES, INC. | U6: Hold
U8: EXCHANGE:(TICKER)
U9: {=+"Price (7 Mar 25): $"&_FV(DCF!$R$4,"Price")} -> Price (7 Mar 25): $156,6514
D10: Investment Thesis | U10: ="Price Target: $" & ROUND(IF(Summary!G25="FCFF",DCF!Q208,IF(Summary!G25="FCFE",DCF!Q251,IF(Summary!G25="Tax Shield",DCF!Q224,DCF!Q267))),2) &" "&IF(Summary!G25="FCFF","(FCFF)",IF(Summary!G25="FCFE","(FCFE)",IF(Summary!G25="Tax Shield","(APV)","(DDM)"))) -> Price Target: $0 (FCFF)
U11: =+"Upside (Downside): "&ROUND((DCF!$Q$211*100),2)&"%" -> Upside (Downside): -100%
U14: =+Industry!E28&", "&ESG!C9 -> ,
U15: =+ESG!C10 -> 0
D17: Operating Metrics | F17: 2023 | G17: =+F17+1 -> 2024 | H17: =+G17+1 -> 2025 | I17: =+H17+1 -> 2026 | K17: Valuation Multiples | N17: 2022 | O17: =+N17+1 -> 2023 | P17: =+O17+1 -> 2024 | Q17: =+P17+1 -> 2025 | R17: =+Q17+1 -> 2026 | U17: Team Leader
K18: EV / Sales | N18: =IFERROR(_xlfn.XLOOKUP($K18,Multiples!$B:$B,Multiples!N:N),"") | O18: =IFERROR(_xlfn.XLOOKUP($K18,Multiples!$B:$B,Multiples!O:O),"") | P18: =IFERROR(_xlfn.XLOOKUP($K18,Multiples!$B:$B,Multiples!P:P),"") | Q18: =IFERROR(_xlfn.XLOOKUP($K18,Multiples!$B:$B,Multiples!Q:Q),"") | R18: =IFERROR(_xlfn.XLOOKUP($K18,Multiples!$B:$B,Multiples!R:R),"") | U18: email
K19: Price / Sales | N19: =IFERROR(_xlfn.XLOOKUP($K19,Multiples!$B:$B,Multiples!N:N),"") | O19: =IFERROR(_xlfn.XLOOKUP($K19,Multiples!$B:$B,Multiples!O:O),"") | P19: =IFERROR(_xlfn.XLOOKUP($K19,Multiples!$B:$B,Multiples!P:P),"") | Q19: =IFERROR(_xlfn.XLOOKUP($K19,Multiples!$B:$B,Multiples!Q:Q),"") | R19: =IFERROR(_xlfn.XLOOKUP($K19,Multiples!$B:$B,Multiples!R:R),"") | U19: (+351) 999 999 999
K20: EV / EBITDA | N20: =IFERROR(_xlfn.XLOOKUP($K20,Multiples!$B:$B,Multiples!N:N),"") | O20: =IFERROR(_xlfn.XLOOKUP($K20,Multiples!$B:$B,Multiples!O:O),"") | P20: =IFERROR(_xlfn.XLOOKUP($K20,Multiples!$B:$B,Multiples!P:P),"") | Q20: =IFERROR(_xlfn.XLOOKUP($K20,Multiples!$B:$B,Multiples!Q:Q),"") | R20: =IFERROR(_xlfn.XLOOKUP($K20,Multiples!$B:$B,Multiples!R:R),"") | U20: Analyst 1
K21: EV / EBIT | N21: =IFERROR(_xlfn.XLOOKUP($K21,Multiples!$B:$B,Multiples!N:N),"") | O21: =IFERROR(_xlfn.XLOOKUP($K21,Multiples!$B:$B,Multiples!O:O),"") | P21: =IFERROR(_xlfn.XLOOKUP($K21,Multiples!$B:$B,Multiples!P:P),"") | Q21: =IFERROR(_xlfn.XLOOKUP($K21,Multiples!$B:$B,Multiples!Q:Q),"") | R21: =IFERROR(_xlfn.XLOOKUP($K21,Multiples!$B:$B,Multiples!R:R),"") | U21: email
K22: Price / Earnings | N22: =IFERROR(_xlfn.XLOOKUP($K22,Multiples!$B:$B,Multiples!N:N),"") | O22: =IFERROR(_xlfn.XLOOKUP($K22,Multiples!$B:$B,Multiples!O:O),"") | P22: =IFERROR(_xlfn.XLOOKUP($K22,Multiples!$B:$B,Multiples!P:P),"") | Q22: =IFERROR(_xlfn.XLOOKUP($K22,Multiples!$B:$B,Multiples!Q:Q),"") | R22: =IFERROR(_xlfn.XLOOKUP($K22,Multiples!$B:$B,Multiples!R:R),"") | U22: (+351) 999 999 999
K23: Price / Book | N23: =IFERROR(_xlfn.XLOOKUP($K23,Multiples!$B:$B,Multiples!N:N),"") | O23: =IFERROR(_xlfn.XLOOKUP($K23,Multiples!$B:$B,Multiples!O:O),"") | P23: =IFERROR(_xlfn.XLOOKUP($K23,Multiples!$B:$B,Multiples!P:P),"") | Q23: =IFERROR(_xlfn.XLOOKUP($K23,Multiples!$B:$B,Multiples!Q:Q),"") | R23: =IFERROR(_xlfn.XLOOKUP($K23,Multiples!$B:$B,Multiples!R:R),"") | U23: Analyst 2
U24: email
D25: Year | E25: Net Sales | F25: EBIT Margin | G25: FCFF | H25: =+IF(Summary!$G$25="FCFF",DCF!AB6,IF(Summary!$G$25="FCFE",DCF!AC6,DCF!AD6)) -> NOPAT | I25: Net Capex | K25: Profitability Ratios | N25: 2022 | O25: =+N25+1 -> 2023 | P25: =+O25+1 -> 2024 | Q25: =+P25+1 -> 2025 | R25: =+Q25+1 -> 2026 | U25: (+351) 999 999 999
D26: 2022 | E26: =+DCF!E30 -> 0 | F26: =+DCF!E60 | G26: =+INDEX(DCF!X7:AA7,MATCH(Summary!$G$25,{"FCFF","FCFE","Tax Shield","Total Payout"},0)) | H26: =+IF(Summary!$G$25="FCFF",DCF!AB7,IF(Summary!$G$25="FCFE",DCF!AC7,DCF!AD7)) | I26: =+DCF!E134 -> 0 | K26: Return on Assets | N26: =IFERROR(_xlfn.XLOOKUP($K26,Multiples!$B:$B,Multiples!N:N),"") | O26: =IFERROR(_xlfn.XLOOKUP($K26,Multiples!$B:$B,Multiples!O:O),"") | P26: =IFERROR(_xlfn.XLOOKUP($K26,Multiples!$B:$B,Multiples!P:P),"") | Q26: =IFERROR(_xlfn.XLOOKUP($K26,Multiples!$B:$B,Multiples!Q:Q),"") | R26: =IFERROR(_xlfn.XLOOKUP($K26,Multiples!$B:$B,Multiples!R:R),"") | U26: Analyst 3
D27: =+D26+1 -> 2023 | E27: =+DCF!F30 -> 0 | F27: =+DCF!F60 | G27: =+INDEX(DCF!X8:AA8,MATCH(Summary!$G$25,{"FCFF","FCFE","Tax Shield","Total Payout"},0)) | H27: =+IF(Summary!$G$25="FCFF",DCF!AB8,IF(Summary!$G$25="FCFE",DCF!AC8,DCF!AD8)) | I27: =+DCF!F134 -> 0 | K27: Return on Equity | N27: =IFERROR(_xlfn.XLOOKUP($K27,Multiples!$B:$B,Multiples!N:N),"") | O27: =IFERROR(_xlfn.XLOOKUP($K27,Multiples!$B:$B,Multiples!O:O),"") | P27: =IFERROR(_xlfn.XLOOKUP($K27,Multiples!$B:$B,Multiples!P:P),"") | Q27: =IFERROR(_xlfn.XLOOKUP($K27,Multiples!$B:$B,Multiples!Q:Q),"") | R27: =IFERROR(_xlfn.XLOOKUP($K27,Multiples!$B:$B,Multiples!R:R),"") | U27: email
D28: =+D27+1 -> 2024 | E28: =+DCF!G30 -> 0 | F28: =+DCF!G60 | G28: =+INDEX(DCF!X9:AA9,MATCH(Summary!$G$25,{"FCFF","FCFE","Tax Shield","Total Payout"},0)) | H28: =+IF(Summary!$G$25="FCFF",DCF!AB9,IF(Summary!$G$25="FCFE",DCF!AC9,DCF!AD9)) | I28: =+DCF!G134 -> 0 | K28: Return on Total Capital | N28: =IFERROR(_xlfn.XLOOKUP($K28,Multiples!$B:$B,Multiples!N:N),"") | O28: =IFERROR(_xlfn.XLOOKUP($K28,Multiples!$B:$B,Multiples!O:O),"") | P28: =IFERROR(_xlfn.XLOOKUP($K28,Multiples!$B:$B,Multiples!P:P),"") | Q28: =IFERROR(_xlfn.XLOOKUP($K28,Multiples!$B:$B,Multiples!Q:Q),"") | R28: =IFERROR(_xlfn.XLOOKUP($K28,Multiples!$B:$B,Multiples!R:R),"") | U28: (+351) 999 999 999
D29: =+D28+1 -> 2025 | E29: =+DCF!H30 -> 0 | F29: =+DCF!H60 | G29: =+INDEX(DCF!X10:AA10,MATCH(Summary!$G$25,{"FCFF","FCFE","Tax Shield","Total Payout"},0)) | H29: =+IF(Summary!$G$25="FCFF",DCF!AB10,IF(Summary!$G$25="FCFE",DCF!AC10,DCF!AD10)) | I29: =+DCF!H134 | K29: EBITDA Margin | N29: =IFERROR(_xlfn.XLOOKUP($K29,Multiples!$B:$B,Multiples!N:N),"") | O29: =IFERROR(_xlfn.XLOOKUP($K29,Multiples!$B:$B,Multiples!O:O),"") | P29: =IFERROR(_xlfn.XLOOKUP($K29,Multiples!$B:$B,Multiples!P:P),"") | Q29: =IFERROR(_xlfn.XLOOKUP($K29,Multiples!$B:$B,Multiples!Q:Q),"") | R29: =IFERROR(_xlfn.XLOOKUP($K29,Multiples!$B:$B,Multiples!R:R),"")
D30: =+D29+1 -> 2026 | E30: =+DCF!I30 -> 0 | F30: =+DCF!I60 | G30: =+INDEX(DCF!X11:AA11,MATCH(Summary!$G$25,{"FCFF","FCFE","Tax Shield","Total Payout"},0)) | H30: =+IF(Summary!$G$25="FCFF",DCF!AB11,IF(Summary!$G$25="FCFE",DCF!AC11,DCF!AD11)) | I30: =+DCF!I134 | K30: EBIT Margin | N30: =IFERROR(_xlfn.XLOOKUP($K30,Multiples!$B:$B,Multiples!N:N),"") | O30: =IFERROR(_xlfn.XLOOKUP($K30,Multiples!$B:$B,Multiples!O:O),"") | P30: =IFERROR(_xlfn.XLOOKUP($K30,Multiples!$B:$B,Multiples!P:P),"") | Q30: =IFERROR(_xlfn.XLOOKUP($K30,Multiples!$B:$B,Multiples!Q:Q),"") | R30: =IFERROR(_xlfn.XLOOKUP($K30,Multiples!$B:$B,Multiples!R:R),"") | U30: Statistics
D31: =+D30+1 -> 2027 | E31: =+DCF!J30 -> 0 | F31: =+DCF!J60 | G31: =+INDEX(DCF!X12:AA12,MATCH(Summary!$G$25,{"FCFF","FCFE","Tax Shield","Total Payout"},0)) | H31: =+IF(Summary!$G$25="FCFF",DCF!AB12,IF(Summary!$G$25="FCFE",DCF!AC12,DCF!AD12)) | I31: =+DCF!J134 | K31: Gross Profit Margin | N31: =IFERROR(_xlfn.XLOOKUP($K31,Multiples!$B:$B,Multiples!N:N),"") | O31: =IFERROR(_xlfn.XLOOKUP($K31,Multiples!$B:$B,Multiples!O:O),"") | P31: =IFERROR(_xlfn.XLOOKUP($K31,Multiples!$B:$B,Multiples!P:P),"") | Q31: =IFERROR(_xlfn.XLOOKUP($K31,Multiples!$B:$B,Multiples!Q:Q),"") | R31: =IFERROR(_xlfn.XLOOKUP($K31,Multiples!$B:$B,Multiples!R:R),"") | U31: Beta | V31: =Peers!D74 -> 1.898
D32: =+D31+1 -> 2028 | E32: =+DCF!K30 -> 0 | F32: =+DCF!K60 | G32: =+INDEX(DCF!X13:AA13,MATCH(Summary!$G$25,{"FCFF","FCFE","Tax Shield","Total Payout"},0)) | H32: =+IF(Summary!$G$25="FCFF",DCF!AB13,IF(Summary!$G$25="FCFE",DCF!AC13,DCF!AD13)) | I32: =+DCF!K134 | K32: SG&A Margin | N32: =IFERROR(_xlfn.XLOOKUP($K32,Multiples!$B:$B,Multiples!N:N),"") | O32: =IFERROR(_xlfn.XLOOKUP($K32,Multiples!$B:$B,Multiples!O:O),"") | P32: =IFERROR(_xlfn.XLOOKUP($K32,Multiples!$B:$B,Multiples!P:P),"") | Q32: =IFERROR(_xlfn.XLOOKUP($K32,Multiples!$B:$B,Multiples!Q:Q),"") | R32: =IFERROR(_xlfn.XLOOKUP($K32,Multiples!$B:$B,Multiples!R:R),"") | U32: % Float | V32: =+Peers!D73 -> 0
D33: =+D32+1 -> 2029 | E33: =+DCF!L30 -> 0 | F33: =+DCF!L60 | G33: =+INDEX(DCF!X14:AA14,MATCH(Summary!$G$25,{"FCFF","FCFE","Tax Shield","Total Payout"},0)) | H33: =+IF(Summary!$G$25="FCFF",DCF!AB14,IF(Summary!$G$25="FCFE",DCF!AC14,DCF!AD14)) | I33: =+DCF!L134 | K33: Net Income Margin | N33: =IFERROR(_xlfn.XLOOKUP($K33,Multiples!$B:$B,Multiples!N:N),"") | O33: =IFERROR(_xlfn.XLOOKUP($K33,Multiples!$B:$B,Multiples!O:O),"") | P33: =IFERROR(_xlfn.XLOOKUP($K33,Multiples!$B:$B,Multiples!P:P),"") | Q33: =IFERROR(_xlfn.XLOOKUP($K33,Multiples!$B:$B,Multiples!Q:Q),"") | R33: =IFERROR(_xlfn.XLOOKUP($K33,Multiples!$B:$B,Multiples!R:R),"") | U33: % Held by Insiders | V33: =+Peers!D76 -> 0
U34: % Held by Institutions | V34: =+Peers!D77 -> 0
D35: SWOT Analysis | K35: Liquidity Ratios | N35: 2022 | O35: =+N35+1 -> 2023 | P35: =+O35+1 -> 2024 | Q35: =+P35+1 -> 2025 | R35: =+Q35+1 -> 2026 | U35: Short % of Float | V35: =+Peers!D78 -> 0
D36: Strengths | G36: Weaknesses | K36: Cash Ratio | N36: =IFERROR(_xlfn.XLOOKUP($K36,Multiples!$B:$B,Multiples!N:N),"") | O36: =IFERROR(_xlfn.XLOOKUP($K36,Multiples!$B:$B,Multiples!O:O),"") | P36: =IFERROR(_xlfn.XLOOKUP($K36,Multiples!$B:$B,Multiples!P:P),"") | Q36: =IFERROR(_xlfn.XLOOKUP($K36,Multiples!$B:$B,Multiples!Q:Q),"") | R36: =IFERROR(_xlfn.XLOOKUP($K36,Multiples!$B:$B,Multiples!R:R),"") | W36: 120.87
K37: Quick Ratio | N37: =IFERROR(_xlfn.XLOOKUP($K37,Multiples!$B:$B,Multiples!N:N),"") | O37: =IFERROR(_xlfn.XLOOKUP($K37,Multiples!$B:$B,Multiples!O:O),"") | P37: =IFERROR(_xlfn.XLOOKUP($K37,Multiples!$B:$B,Multiples!P:P),"") | Q37: =IFERROR(_xlfn.XLOOKUP($K37,Multiples!$B:$B,Multiples!Q:Q),"") | R37: =IFERROR(_xlfn.XLOOKUP($K37,Multiples!$B:$B,Multiples!R:R),"") | U37: Major Holders | W37: 113.63
K38: Current Ratio | N38: =IFERROR(_xlfn.XLOOKUP($K38,Multiples!$B:$B,Multiples!N:N),"") | O38: =IFERROR(_xlfn.XLOOKUP($K38,Multiples!$B:$B,Multiples!O:O),"") | P38: =IFERROR(_xlfn.XLOOKUP($K38,Multiples!$B:$B,Multiples!P:P),"") | Q38: =IFERROR(_xlfn.XLOOKUP($K38,Multiples!$B:$B,Multiples!Q:Q),"") | R38: =IFERROR(_xlfn.XLOOKUP($K38,Multiples!$B:$B,Multiples!R:R),"")
D40: Opportunities | G40: Threats | K40: Cash Flow Ratios | N40: 2022 | O40: =+N40+1 -> 2023 | P40: =+O40+1 -> 2024 | Q40: =+P40+1 -> 2025 | R40: =+Q40+1 -> 2026
K41: Cash Conversion Cycle | N41: =IFERROR(_xlfn.XLOOKUP($K41,Multiples!$B:$B,Multiples!N:N),"") | O41: =IFERROR(_xlfn.XLOOKUP($K41,Multiples!$B:$B,Multiples!O:O),"") | P41: =IFERROR(_xlfn.XLOOKUP($K41,Multiples!$B:$B,Multiples!P:P),"") | Q41: =IFERROR(_xlfn.XLOOKUP($K41,Multiples!$B:$B,Multiples!Q:Q),"") | R41: =IFERROR(_xlfn.XLOOKUP($K41,Multiples!$B:$B,Multiples!R:R),"")
K42: Net Income / Op Cash Flow | N42: =IFERROR(_xlfn.XLOOKUP($K42,Multiples!$B:$B,Multiples!N:N),"") | O42: =IFERROR(_xlfn.XLOOKUP($K42,Multiples!$B:$B,Multiples!O:O),"") | P42: =IFERROR(_xlfn.XLOOKUP($K42,Multiples!$B:$B,Multiples!P:P),"") | Q42: =IFERROR(_xlfn.XLOOKUP($K42,Multiples!$B:$B,Multiples!Q:Q),"") | R42: =IFERROR(_xlfn.XLOOKUP($K42,Multiples!$B:$B,Multiples!R:R),"")
K43: Chg in Cash / Op Cash Flow | N43: =IFERROR(_xlfn.XLOOKUP($K43,Multiples!$B:$B,Multiples!N:N),"") | O43: =IFERROR(_xlfn.XLOOKUP($K43,Multiples!$B:$B,Multiples!O:O),"") | P43: =IFERROR(_xlfn.XLOOKUP($K43,Multiples!$B:$B,Multiples!P:P),"") | Q43: =IFERROR(_xlfn.XLOOKUP($K43,Multiples!$B:$B,Multiples!Q:Q),"") | R43: =IFERROR(_xlfn.XLOOKUP($K43,Multiples!$B:$B,Multiples!R:R),"")
D45: Revenue by Region | G45: Revenue by Segment | K45: Leverage Ratios | N45: 2022 | O45: =+N45+1 -> 2023 | P45: =+O45+1 -> 2024 | Q45: =+P45+1 -> 2025 | R45: =+Q45+1 -> 2026
K46: Total Debt / Equity | N46: =IFERROR(_xlfn.XLOOKUP($K46,Multiples!$B:$B,Multiples!N:N),"") | O46: =IFERROR(_xlfn.XLOOKUP($K46,Multiples!$B:$B,Multiples!O:O),"") | P46: =IFERROR(_xlfn.XLOOKUP($K46,Multiples!$B:$B,Multiples!P:P),"") | Q46: =IFERROR(_xlfn.XLOOKUP($K46,Multiples!$B:$B,Multiples!Q:Q),"") | R46: =IFERROR(_xlfn.XLOOKUP($K46,Multiples!$B:$B,Multiples!R:R),"")
K47: Total Debt / Capital | N47: =IFERROR(_xlfn.XLOOKUP($K47,Multiples!$B:$B,Multiples!N:N),"") | O47: =IFERROR(_xlfn.XLOOKUP($K47,Multiples!$B:$B,Multiples!O:O),"") | P47: =IFERROR(_xlfn.XLOOKUP($K47,Multiples!$B:$B,Multiples!P:P),"") | Q47: =IFERROR(_xlfn.XLOOKUP($K47,Multiples!$B:$B,Multiples!Q:Q),"") | R47: =IFERROR(_xlfn.XLOOKUP($K47,Multiples!$B:$B,Multiples!R:R),"")
K48: Total Liabilities / Total Assets | N48: =IFERROR(_xlfn.XLOOKUP($K48,Multiples!$B:$B,Multiples!N:N),"") | O48: =IFERROR(_xlfn.XLOOKUP($K48,Multiples!$B:$B,Multiples!O:O),"") | P48: =IFERROR(_xlfn.XLOOKUP($K48,Multiples!$B:$B,Multiples!P:P),"") | Q48: =IFERROR(_xlfn.XLOOKUP($K48,Multiples!$B:$B,Multiples!Q:Q),"") | R48: =IFERROR(_xlfn.XLOOKUP($K48,Multiples!$B:$B,Multiples!R:R),"")
K49: Total Debt / EBITDA | N49: =IFERROR(_xlfn.XLOOKUP($K49,Multiples!$B:$B,Multiples!N:N),"") | O49: =IFERROR(_xlfn.XLOOKUP($K49,Multiples!$B:$B,Multiples!O:O),"") | P49: =IFERROR(_xlfn.XLOOKUP($K49,Multiples!$B:$B,Multiples!P:P),"") | Q49: =IFERROR(_xlfn.XLOOKUP($K49,Multiples!$B:$B,Multiples!Q:Q),"") | R49: =IFERROR(_xlfn.XLOOKUP($K49,Multiples!$B:$B,Multiples!R:R),"") | U49: Board of Directors
...

Sheet Segments
B2: Segments
B4: Regions | D4: Weight | E4: 2020 | F4: =+E4+1 -> 2021 | G4: =+F4+1 -> 2022 | H4: =+G4+1 -> 2023 | I4: =+H4+1 -> 2024 | J4: ="CAGR "&$G$4&" - "&$I$4 -> CAGR 2022 - 2024 | K4: 2021 | L4: =+K4+1 -> 2022 | M4: =+L4+1 -> 2023 | N4: =+M4+1 -> 2024
D6: =IFERROR(I6/SUM($I$6:$I$12),"") | J6: =IFERROR((I6/G6)^(1/COUNT($G$4:$I$4))-1,"") | K6: =IFERROR(F6-E6/E6,"") | L6: =IFERROR(G6-F6/F6,"") | M6: =IFERROR((H6-G6)/G6,"") | N6: =IFERROR((I6-H6)/H6,"")
D7: =IFERROR(I7/SUM($I$6:$I$12),"") | J7: =IFERROR((I7/G7)^(1/COUNT($G$4:$I$4))-1,"") | K7: =IFERROR(F7-E7/E7,"") | L7: =IFERROR(G7-F7/F7,"") | M7: =IFERROR((H7-G7)/G7,"") | N7: =IFERROR((I7-H7)/H7,"")
D8: =IFERROR(I8/SUM($I$6:$I$12),"") | J8: =IFERROR((I8/E8)^(1/COUNT($E$4:$I$4))-1,"") | K8: =IFERROR(F8-E8/E8,"") | L8: =IFERROR(G8-F8/F8,"") | M8: =IFERROR(H8-G8/G8,"") | N8: =IFERROR((I8-H8)/H8,"")
D9: =IFERROR(I9/SUM($I$6:$I$12),"") | J9: =IFERROR((I9/E9)^(1/COUNT($E$4:$I$4))-1,"") | K9: =IFERROR(F9-E9/E9,"") | L9: =IFERROR(G9-F9/F9,"") | M9: =IFERROR(H9-G9/G9,"") | N9: =IFERROR((I9-H9)/H9,"")
D10: =IFERROR(I10/SUM($I$6:$I$12),"") | J10: =IFERROR((I10/E10)^(1/COUNT($E$4:$I$4))-1,"") | K10: =IFERROR(F10-E10/E10,"") | L10: =IFERROR(G10-F10/F10,"") | M10: =IFERROR(H10-G10/G10,"") | N10: =IFERROR((I10-H10)/H10,"")
D11: =IFERROR(I11/SUM($I$6:$I$12),"")
D12: =IFERROR(I12/SUM($I$6:$I$12),"")
B13: Total | D13: =SUM(D6:D12) -> 0 | E13: =SUM(E6:E10) -> 0 | F13: =SUM(F6:F10) -> 0 | G13: =SUM(G6:G10) -> 0 | H13: =SUM(H6:H10) -> 0 | I13: =SUM(I6:I10) -> 0 | J13: =IFERROR((I13/G13)^(1/COUNT($G$4:$I$4))-1,"") | K13: =IFERROR(F13-E13/E13,"") | L13: =IFERROR(G13-F13/F13,"") | M13: =IFERROR((H13-G13)/G13,"") | N13: =IFERROR((I13-H13)/H13,"")
B15: Segments | D15: Weight | E15: 2020 | F15: =+E15+1 -> 2021 | G15: =+F15+1 -> 2022 | H15: =+G15+1 -> 2023 | I15: =+H15+1 -> 2024 | J15: ="CAGR "&$E$4&" - "&$I$4 -> CAGR 2020 - 2024 | K15: 2021 | L15: =+K15+1 -> 2022 | M15: =+L15+1 -> 2023 | N15: =+M15+1 -> 2024
D17: =IFERROR(I17/SUM($I$17:$I$21),"") | J17: =IFERROR((I17/E17)^(1/COUNT($E$4:$I$4))-1,"") | K17: =IFERROR((F17-E17)/E17,"") | L17: =IFERROR((G17-F17)/F17,"") | M17: =IFERROR((H17-G17)/G17,"") | N17: =IFERROR((I17-H17)/H17,"")
D18: =IFERROR(I18/SUM($I$17:$I$21),"") | J18: =IFERROR((I18/E18)^(1/COUNT($E$4:$I$4))-1,"") | K18: =IFERROR((F18-E18)/E18,"") | L18: =IFERROR((G18-F18)/F18,"") | M18: =IFERROR((H18-G18)/G18,"") | N18: =IFERROR((I18-H18)/H18,"")
D19: =IFERROR(I19/SUM($I$17:$I$21),"") | J19: =IFERROR((I19/E19)^(1/COUNT($E$4:$I$4))-1,"") | K19: =IFERROR((F19-E19)/E19,"") | L19: =IFERROR((G19-F19)/F19,"") | M19: =IFERROR((H19-G19)/G19,"") | N19: =IFERROR((I19-H19)/H19,"")
D20: =IFERROR(I20/SUM($I$17:$I$21),"") | J20: =IFERROR((I20/E20)^(1/COUNT($E$4:$I$4))-1,"") | K20: =IFERROR((F20-E20)/E20,"") | L20: =IFERROR((G20-F20)/F20,"") | M20: =IFERROR((H20-G20)/G20,"") | N20: =IFERROR((I20-H20)/H20,"")
D21: =IFERROR(I21/SUM($I$17:$I$21),"") | J21: =IFERROR((I21/E21)^(1/COUNT($E$4:$I$4))-1,"") | K21: =IFERROR((F21-E21)/E21,"") | L21: =IFERROR((G21-F21)/F21,"") | M21: =IFERROR((H21-G21)/G21,"") | N21: =IFERROR((I21-H21)/H21,"")
B22: Total | D22: =SUM(D17:D21) -> 0 | E22: =SUM(E17:E21) -> 0 | F22: =SUM(F17:F21) -> 0 | G22: =SUM(G17:G21) -> 0 | H22: =SUM(H17:H21) -> 0 | I22: =SUM(I17:I21) -> 0 | J22: =IFERROR((I22/E22)^(1/COUNT($E$4:$I$4))-1,"") | K22: =IFERROR((F22-E22)/E22,"") | L22: =IFERROR((G22-F22)/F22,"") | M22: =IFERROR((H22-G22)/G22,"") | N22: =IFERROR((I22-H22)/H22,"")
B24: Categories | D24: Description | J24: Graphs
B29: =IF(B20=0,"",B20)
B30: =IF(B21=0,"",B21)
B32: Products | D32: Weight | E32: 2020 | F32: =+E32+1 -> 2021 | G32: =+F32+1 -> 2022 | H32: =+G32+1 -> 2023 | I32: =+H32+1 -> 2024 | J32: =I32+1 -> 2025 | K32: =+J32+1 -> 2026 | L32: =+K32+1 -> 2027 | M32: =+L32+1 -> 2028 | N32: =+M32+1 -> 2029 | O32: =+N32+1 -> 2030 | P32: =+O32+1 -> 2031 | Q32: =+P32+1 -> 2032 | R32: =+Q32+1 -> 2033 | ... T32: =+S32+1 -> 2035
D34: =IFERROR(I34/$I$13,"")
D36: =IFERROR(I36/$I$13,"")
F37: =IFERROR((F36-E36)/E36,"") | G37: =IFERROR((G36-F36)/F36,"") | H37: =IFERROR((H36-G36)/G36,"") | I37: =IFERROR((I36-H36)/H36,"")
B38: Product 3 | D38: =IFERROR(I38/$I$13,"") | J38: =I38*(1+J39) -> 0 | K38: =J38*(1+K39) -> 0 | L38: =K38*(1+L39) -> 0 | M38: =L38*(1+M39) -> 0 | N38: =M38*(1+N39) -> 0 | O38: =N38*(1+O39) -> 0 | P38: =O38*(1+P39) -> 0 | Q38: =P38*(1+Q39) -> 0 | ... T38: =S38*(1+T39) -> 0
F39: =IFERROR(F38-E38/E38,"") | G39: =IFERROR(G38-F38/F38,"") | H39: =IFERROR(H38-G38/G38,"") | I39: =IFERROR(I38-H38/H38,"")
B40: Product 4 | D40: =IFERROR(I40/$I$13,"") | J40: =I40*(1+J41) -> 0 | K40: =J40*(1+K41) -> 0 | L40: =K40*(1+L41) -> 0 | M40: =L40*(1+M41) -> 0 | N40: =M40*(1+N41) -> 0 | O40: =N40*(1+O41) -> 0 | P40: =O40*(1+P41) -> 0 | Q40: =P40*(1+Q41) -> 0 | ... T40: =S40*(1+T41) -> 0
F41: =IFERROR(F40-E40/E40,"") | G41: =IFERROR(G40-F40/F40,"") | H41: =IFERROR(H40-G40/G40,"") | I41: =IFERROR(I40-H40/H40,"")
B42: Product 5 | D42: =IFERROR(I42/$I$13,"") | J42: =I42*(1+J43) -> 0 | K42: =J42*(1+K43) -> 0 | L42: =K42*(1+L43) -> 0 | M42: =L42*(1+M43) -> 0 | N42: =M42*(1+N43) -> 0 | O42: =N42*(1+O43) -> 0 | P42: =O42*(1+P43) -> 0 | Q42: =P42*(1+Q43) -> 0 | ... T42: =S42*(1+T43) -> 0
F43: =IFERROR(F42-E42/E42,"") | G43: =IFERROR(G42-F42/F42,"") | H43: =IFERROR(H42-G42/G42,"") | I43: =IFERROR(I42-H42/H42,"")
B44: Total | D44: =SUM(D34:D42) -> 0 | E44: =SUM(E34:E42) -> 0 | F44: =SUM(F34:F42) -> 0 | G44: =SUM(G34:G42) -> 0 | H44: =SUM(H34:H42) -> 0 | I44: =SUM(I34:I42) -> 0 | J44: =SUM(J34:J42) -> 0 | K44: =SUM(K34:K42) -> 0 | ... T44: =SUM(T34:T42) -> 0
B46: Company's Strategy / Extra Notes

Sheet Industry
B2: Industry Overview
B4: Sales Growth Forecast | E4: Weight | F4: 2025 | G4: =+F4+1 -> 2026 | H4: =+G4+1 -> 2027 | I4: =+H4+1 -> 2028 | J4: =+I4+1 -> 2029 | K4: =+J4+1 -> 2030 | L4: =+K4+1 -> 2031 | M4: =+L4+1 -> 2032 | N4: =+M4+1 -> 2033 | ... P4: =+O4+1 -> 2035 | Q4: ="CAGR "&$F$4&" - "&$P$4 -> CAGR 2025 - 2035 | R4: Sources
B11: Weighted Average | E11: =SUM(E6:E10) -> 0 | F11: =SUMPRODUCT(F6:F10,$E$6:$E$10) -> 0 | G11: =SUMPRODUCT(G6:G10,$E$6:$E$10) -> 0 | H11: =SUMPRODUCT(H6:H10,$E$6:$E$10) -> 0 | I11: =SUMPRODUCT(I6:I10,$E$6:$E$10) -> 0 | J11: =SUMPRODUCT(J6:J10,$E$6:$E$10) -> 0 | K11: =SUMPRODUCT(K6:K10,$E$6:$E$10) -> 0 | L11: =SUMPRODUCT(L6:L10,$E$6:$E$10) -> 0 | M11: =SUMPRODUCT(M6:M10,$E$6:$E$10) -> 0 | ... P11: =SUMPRODUCT(P6:P10,$E$6:$E$10) -> 0 | Q11: =IFERROR(((1+F11)*(1+G11)*(1+H11)*(1+I11)*(1+J11)*(1+K11)*(1+L11)*(1+M11)*(1+N11)*(1+O11)*(1+P11))^(1/COUNT($F$4:$P$4))-1,"") -> 0
B13: Key Drivers | E13: Description
B20: Industry Trends | E20: Description
B26: Market Share | E26: Headquarters | G26: Revenues | H26: (in MM of USD) | I26: Market Share
B28: {=+_FV(DCF!R4,"Name")} -> ADVANCED MICRO DEVICES, INC. | G28: {=TRANSPOSE(Peers!D97:N97)} -> 0 | I28: =IFERROR(G28/$G$40,"")
B29: {=+_FV(Peers!A8,"Name")} -> #VALUE! | G29: 0 | I29: =IFERROR(G29/$G$40,"")
B30: {=+_FV(Peers!A9,"Name")} -> #VALUE! | G30: 0 | I30: =IFERROR(G30/$G$40,"")
B31: {=+_FV(Peers!A10,"Name")} -> #VALUE! | G31: 0 | I31: =IFERROR(G31/$G$40,"")
B32: {=+_FV(Peers!A11,"Name")} -> #VALUE! | G32: 0 | I32: =IFERROR(G32/$G$40,"")
B33: {=+_FV(Peers!A12,"Name")} -> #VALUE! | G33: 0 | I33: =IFERROR(G33/$G$40,"")
B34: {=+_FV(Peers!A13,"Name")} -> #VALUE! | G34: 0 | I34: =IFERROR(G34/$G$40,"")
B35: {=+_FV(Peers!A14,"Name")} -> #VALUE! | G35: 0 | I35: =IFERROR(G35/$G$40,"")
B36: {=+_FV(Peers!A15,"Name")} -> #VALUE! | G36: 0 | I36: =IFERROR(G36/$G$40,"")
B37: {=+_FV(Peers!A16,"Name")} -> #VALUE! | G37: 0 | I37: =IFERROR(G37/$G$40,"")
B38: {=+_FV(Peers!A17,"Name")} -> #VALUE! | G38: 0 | I38: =IFERROR(G38/$G$40,"")
B39: Others | E39: -- | G39: =G40-SUM(G28:G38) -> 0 | I39: =IFERROR(G39/$G$40,"")
B40: Industry Size | E40: -- | I40: 1
B42: Porter's Five Forces Analysis | E42: Rating | H42: Graph
B44: Threat of New Entrants | E44: =IFERROR(AVERAGE(E45:E50),"")
B45: Economies of scale
B46: Product differentiation
B47: Capital requirements
B48: Access to distribution channels
B49: Regulations
B50: Switching costs
B51: Bargaining Power of Suppliers | E51: =IFERROR(AVERAGE(E52:E56),"")
B52: Number of suppliers
B53: Uniqueness
B54: Switching Costs
B55: Forward Integration
B56: Industry Importance
B57: Bargaining Power of Customers | E57: =IFERROR(AVERAGE(E58:E62),"")
B58: Number of buyers
B59: Purchase size
B60: Switching costs
B61: Price sensitivity
B62: Informed buyers
B63: Competitive Rivalry | E63: =IFERROR(AVERAGE(E64:E68),"")
...

Sheet Peers
D3: Revenue Growth | F3: EBITDA Margin | H3: Profit Margin | J3: EV / Revenue | L3: EV / EBITDA | N3: Price / Earnings
B4: Peers | C4: Ticker | D4: =+Inputs!O4&"-"&Inputs!P4 -> 2022-2023 | E4: =+Inputs!P4&"-"&Inputs!Q4 -> 2023-2024 | F4: 2023 | G4: 2024 | H4: =+Inputs!O4&"-"&Inputs!P4 -> 2022-2023 | I4: =+Inputs!P4&"-"&Inputs!Q4 -> 2023-2024 | J4: 2023 | K4: 2024 | L4: 2023 | M4: 2024 | N4: 2023 | O4: 2024
A6: =+D91 -> #VALUE! | B6: {=IFERROR(_FV(A6,"Name"),"")} -> ADVANCED MICRO DEVICES, INC. | C6: {=IFERROR(_FV(A6,"Ticker symbol",TRUE),"")} -> AMD | D6: =IFERROR(D94/D93-1,"") | E6: =IFERROR(D97/D94-1,"") | F6: =IFERROR(D95/D94,"") | G6: =IFERROR(D100/D97,"") | H6: =IFERROR(D96/D94,"") | I6: =IFERROR(D105/D97,"") | J6: {=IFERROR((_FV(A6,"Market cap",TRUE)/1000000+D$121-D$111)/D$94,"")} | K6: {=IFERROR((_FV(A6,"Market cap",TRUE)/1000000+D$121-D$111)/D$97,"")} | L6: {=+IFERROR((_FV(A6,"Market cap",TRUE)/1000000+D$121-D$111)/D$95,"")} | M6: {=IFERROR((_FV(A6,"Market cap",TRUE)/1000000+D$121-D$111)/D$100,"")} | N6: {=IFERROR((_FV(A6,"Market cap",TRUE)/1000000)/D$96,"")} | O6: {=IFERROR((_FV(A6,"Market cap",TRUE)/1000000)/D$105,"")}
A8: =+E91 -> PEER 1 | B8: {=IFERROR(_FV(A8,"Name"),"")} | C8: {=+IFERROR(_FV(A8,"Ticker symbol",TRUE),"")} | D8: =+IFERROR(E94/E93-1,"") | E8: =IFERROR(E97/E94-1,"") | F8: =IFERROR(E95/E94,"") | G8: =+IFERROR(E100/E97,"") | H8: =IFERROR(E96/E94,"") | I8: =+IFERROR(D105/D99,"") | J8: {=+IFERROR((_FV(A8,"Market cap",TRUE)/1000000+E$121-E$111)/E$94,"")} | K8: {=IFERROR(+(_FV(A8,"Market cap",TRUE)/1000000+E$121-E$111)/E$97,"")} | L8: {=IFERROR(+(_FV(A8,"Market cap",TRUE)/1000000+E$121-E$111)/E$95,"")} | M8: {=IFERROR(+(_FV(A8,"Market cap",TRUE)/1000000+E$121-E$111)/E$100,"")} | N8: {=IFERROR(+(_FV(A8,"Market cap",TRUE)/1000000)/E$96,"")} | O8: {=IFERROR(+(_FV(A8,"Market cap",TRUE)/1000000)/E$105,"")}
A9: =+F91 -> PEER 2 | B9: {=IFERROR(_FV(A9,"Name"),"")} | C9: {=+IFERROR(_FV(A9,"Ticker symbol",TRUE),"")} | D9: =IFERROR(F94/F93-1,"") | E9: =IFERROR(+F97/F94-1,"") | F9: =IFERROR(F95/F94,"") | G9: =IFERROR(F100/F97,"") | H9: =IFERROR(F96/F94,"") | I9: =+IFERROR(F105/F97,"") | J9: {=IFERROR(+(_FV(A9,"Market cap",TRUE)/1000000+F$121-F$111)/F$94,"")} | K9: {=IFERROR(+(_FV(A9,"Market cap",TRUE)/1000000+F$121-F$111)/F$97,"")} | L9: {=IFERROR(+(_FV(A9,"Market cap",TRUE)/1000000+F$121-F$111)/F$95,"")} | M9: {=IFERROR(+(_FV(A9,"Market cap",TRUE)/1000000+F$121-F$111)/F$100,"")} | N9: {=IFERROR(+(_FV(A9,"Market cap",TRUE)/1000000)/F$96,"")} | O9: {=IFERROR(+(_FV(A9,"Market cap",TRUE)/1000000)/F$105,"")}
A10: =+G91 -> PEER 3 | B10: {=IFERROR(_FV(A10,"Name"),"")} | C10: {=IFERROR(_FV(A10,"Ticker symbol",TRUE),"")} | D10: =+IFERROR(G94/G93-1,"") | E10: =IFERROR(G97/G94-1,"") | F10: =IFERROR(G95/G94,"") | G10: =IFERROR(G100/G97,"") | H10: =IFERROR(G96/G94,"") | I10: =+IFERROR(G105/G97,"") | J10: {=IFERROR(+(_FV(A10,"Market cap",TRUE)/1000000+G$121-G$111)/G$94,"")} | K10: {=IFERROR(+(_FV(A10,"Market cap",TRUE)/1000000+G$121-G$111)/G$97,"")} | L10: {=IFERROR(+(_FV(A10,"Market cap",TRUE)/1000000+G$121-G$111)/G$95,"")} | M10: {=IFERROR(+(_FV(A10,"Market cap",TRUE)/1000000+G$121-G$111)/G$100,"")} | N10: {=IFERROR(+(_FV(A10,"Market cap",TRUE)/1000000)/G$96,"")} | O10: {=IFERROR(+(_FV(A10,"Market cap",TRUE)/1000000)/G$105,"")}
A11: =+H91 -> PEER 4 | B11: {=IFERROR(_FV(A11,"Name"),"")} | C11: {=IFERROR(_FV(A11,"Ticker symbol",TRUE),"")} | D11: =IFERROR(H94/H93-1,"") | E11: =IFERROR(H97/H94-1,"") | F11: =IFERROR(H95/H94,"") | G11: =IFERROR(H100/H97,"") | H11: =IFERROR(H96/H94,"") | I11: =+IFERROR(H105/H102,"") | J11: {=IFERROR((_FV(A11,"Market cap",TRUE)/1000000+H$121-H$111)/H$94,"")} | K11: {=IFERROR(+(_FV(A11,"Market cap",TRUE)/1000000+H$121-H$111)/H$97,"")} | L11: {=IFERROR(+(_FV(A11,"Market cap",TRUE)/1000000+H$121-H$111)/H$95,"")} | M11: {=IFERROR(+(_FV(A11,"Market cap",TRUE)/1000000+H$121-H$111)/H$100,"")} | N11: {=IFERROR(+(_FV(A11,"Market cap",TRUE)/1000000)/H$96,"")} | O11: {=IFERROR(+(_FV(A11,"Market cap",TRUE)/1000000)/H$105,"")}
A12: =+I91 -> PEER 5 | B12: {=IFERROR(_FV(A12,"Name"),"")} | C12: {=IFERROR(_FV(A12,"Ticker symbol",TRUE),"")} | D12: =+IFERROR(I94/I93-1,"") | E12: =IFERROR(I97/I94-1,"") | F12: =IFERROR(I95/I94,"") | G12: =IFERROR(I100/I97,"") | H12: =IFERROR(I96/I94,"") | I12: =+IFERROR(I105/I97,"") | J12: {=IFERROR((_FV(A12,"Market cap",TRUE)/1000000+I$121-I$111)/I$94,"")} | K12: {=IFERROR(+(_FV(A12,"Market cap",TRUE)/1000000+I$121-I$111)/I$97,"")} | L12: {=IFERROR(+(_FV(A12,"Market cap",TRUE)/1000000+I$121-I$111)/I$95,"")} | M12: {=IFERROR(+(_FV(A12,"Market cap",TRUE)/1000000+I$121-I$111)/I$100,"")} | N12: {=IFERROR(+(_FV(A12,"Market cap",TRUE)/1000000)/I$96,"")} | O12: {=IFERROR(+(_FV(A12,"Market cap",TRUE)/1000000)/I$105,"")}
A13: =+J91 -> PEER 6 | B13: {=IFERROR(_FV(A13,"Name"),"")} | C13: {=IFERROR(_FV(A13,"Ticker symbol",TRUE),"")} | D13: =IFERROR(J94/J93-1,"") | E13: =IFERROR(J97/J94-1,"") | F13: =IFERROR(J95/J94,"") | G13: =IFERROR(J100/J97,"") | H13: =IFERROR(J96/J94,"") | I13: =+IFERROR(J105/J97,"") | J13: {=IFERROR(+(_FV(A13,"Market cap",TRUE)/1000000+J$121-J$111)/J$94,"")} | K13: {=IFERROR(+(_FV(A13,"Market cap",TRUE)/1000000+J$121-J$111)/J$97,"")} | L13: {=IFERROR(+(_FV(A13,"Market cap",TRUE)/1000000+J$121-J$111)/J$95,"")} | M13: {=IFERROR(+(_FV(A13,"Market cap",TRUE)/1000000+J$121-J$111)/J$100,"")} | N13: {=IFERROR(+(_FV(A13,"Market cap",TRUE)/1000000)/J$96,"")} | O13: {=IFERROR(+(_FV(A13,"Market cap",TRUE)/1000000)/J$105,"")}
A14: =+K91 -> PEER 7 | B14: {=IFERROR(_FV(A14,"Name"),"")} | C14: {=IFERROR(_FV(A14,"Ticker symbol",TRUE),"")} | D14: =IFERROR(K94/K93-1,"") | E14: =IFERROR(K97/K94-1,"") | F14: =+IFERROR(K95/K94,"") | G14: =IFERROR(K100/K97,"") | H14: =IFERROR(K96/K94,"") | I14: =+IFERROR(K105/K97,"") | J14: {=IFERROR((_FV(A14,"Market cap",TRUE)/1000000+D$121-K$111)/K$94,"")} | K14: {=IFERROR(+(_FV(A14,"Market cap",TRUE)/1000000+D$121-K$111)/K$97,"")} | L14: {=IFERROR(+(_FV(A14,"Market cap",TRUE)/1000000+D$121-K$111)/K$95,"")} | M14: {=IFERROR(+(_FV(A14,"Market cap",TRUE)/1000000+D$121-K$111)/K$100,"")} | N14: {=IFERROR(+(_FV(A14,"Market cap",TRUE)/1000000)/K$96,"")} | O14: {=IFERROR(+(_FV(A14,"Market cap",TRUE)/1000000)/K$105,"")}
A15: =+L91 -> PEER 8 | B15: {=IFERROR(_FV(A15,"Name"),"")} | C15: {=IFERROR(_FV(A15,"Ticker symbol",TRUE),"")} | D15: =+IFERROR(L94/L93,"") | E15: =IFERROR(L97/L94,"") | F15: =IFERROR(L95/L94,"") | G15: =IFERROR(L100/L97,"") | H15: =IFERROR(L96/L94,"") | I15: =+IFERROR(L105/L97,"") | J15: {=IFERROR(+(_FV(A15,"Market cap",TRUE)/1000000+L$121-L$111)/L$94,"")} | K15: {=IFERROR(+(_FV(A15,"Market cap",TRUE)/1000000+L$121-L$111)/L$97,"")} | L15: {=IFERROR(+(_FV(A15,"Market cap",TRUE)/1000000+L$121-L$111)/L$95,"")} | M15: {=IFERROR(+(_FV(A15,"Market cap",TRUE)/1000000+L$121-L$111)/L$100,"")} | N15: {=IFERROR(+(_FV(A15,"Market cap",TRUE)/1000000)/L$96,"")} | O15: {=IFERROR(+(_FV(A15,"Market cap",TRUE)/1000000)/L$105,"")}
A16: =+M91 -> PEER 9 | B16: {=IFERROR(_FV(A16,"Name"),"")} | C16: {=IFERROR(_FV(A16,"Ticker symbol",TRUE),"")} | D16: =IFERROR(M94/M93-1,"") | E16: =IFERROR(M97/M94-1,"") | F16: =IFERROR(M95/M94,"") | G16: =IFERROR(M100/M97,"") | H16: =IFERROR(M96/M94,"") | I16: =+IFERROR(M105/M97,"") | J16: {=IFERROR(+(_FV(A16,"Market cap",TRUE)/1000000+M$121-M$111)/M$94,"")} | K16: {=IFERROR(+(_FV(A16,"Market cap",TRUE)/1000000+M$121-M$111)/M$97,"")} | L16: {=IFERROR(+(_FV(A16,"Market cap",TRUE)/1000000+M$121-M$111)/M$95,"")} | M16: {=IFERROR(+(_FV(A16,"Market cap",TRUE)/1000000+M$121-M$111)/M$100,"")} | N16: {=IFERROR(+(_FV(A16,"Market cap",TRUE)/1000000)/M$96,"")} | O16: {=IFERROR(+(_FV(A16,"Market cap",TRUE)/1000000)/M$105,"")}
A17: =+N91 -> PEER 10 | B17: {=IFERROR(_FV(A17,"Name"),"")} | C17: {=+IFERROR(_FV(A17,"Ticker symbol",TRUE),"")} | D17: =IFERROR(N94/N93-1,"") | E17: =IFERROR(N97/N94-1,"") | F17: =IFERROR(N95/N94,"") | G17: =IFERROR(N100/N97,"") | H17: =IFERROR(N96/N94,"") | I17: =+IFERROR(N105/N97,"") | J17: {=IFERROR(+(_FV(A17,"Market cap",TRUE)/1000000+N$121-N$111)/N$94,"")} | K17: {=IFERROR(+(_FV(A17,"Market cap",TRUE)/1000000+N$121-N$111)/N$97,"")} | L17: {=IFERROR(+(_FV(A17,"Market cap",TRUE)/1000000+N$121-N$111)/N$95,"")} | M17: {=IFERROR(+(_FV(A17,"Market cap",TRUE)/1000000+N$121-N$111)/N$100,"")} | N17: {=IFERROR(+(_FV(A17,"Market cap",TRUE)/1000000)/N$96,"")} | O17: {=IFERROR(+(_FV(A17,"Market cap",TRUE)/1000000)/N$105,"")}
B18: Average | D18: =IFERROR(AVERAGE(D6:D17),"") | E18: =IFERROR(AVERAGE(E6:E17),"") | F18: =IFERROR(AVERAGE(F6:F17),"") | G18: =IFERROR(AVERAGE(G6:G17),"") | H18: =IFERROR(AVERAGE(H6:H17),"") | I18: =IFERROR(AVERAGE(I6:I17),"") | J18: =IFERROR(AVERAGE(J6:J17),"") | K18: =IFERROR(AVERAGE(K6:K17),"") | ... O18: =IFERROR(AVERAGE(O6:O17),"")
B19: Deviation from Average | D19: =IFERROR(+D18-D6,"") | E19: =IFERROR(E18-E6,"") | F19: =+IFERROR(F18-F6,"") | G19: =IFERROR(G18-G6,"") | H19: =IFERROR(+H6-H18,"") | I19: =+IFERROR(I6-I18,"") | J19: =+IFERROR(J6-J18,"") | K19: =+IFERROR(K6-K18,"") | L19: =IFERROR(+L6-L18,"") | M19: =IFERROR(M6-M18,"") | N19: =IFERROR(+N6-N18,"") | O19: =IFERROR(+O6-O18,"")
D21: Trading Multiple | G21: Net | H21: Preferred | I21: Non-Controlling | J21: Equity Value | M21: Implied Upside (Downside)
B22: Implied Share Price | D22: Revenue | E22: EBITDA | F22: P/E | G22: Debt | H22: Stock | I22: Interest | J22: Revenue | K22: EBITDA | L22: P/E | M22: Revenue | N22: EBITDA | O22: P/E | P22: Current Price
B24: Second Minimum | D24: =IFERROR(SMALL(K6:K17,2),"") | E24: =IFERROR(SMALL(M6:M17,2),"") | F24: =IFERROR(SMALL(O6:O17,2),"") | G24: =-Inputs!$Q$99+Inputs!$Q$100 -> 0 | H24: =+Inputs!$Q$101 -> 0 | I24: =+Inputs!$Q$102 -> 0 | J24: =IFERROR(+D24*$D$97+G24+H24+I24,"") | K24: =IFERROR(E24*$D$100+G24+H24+I24,"") | L24: =IFERROR(F24*$D$105,"") | M24: {=IFERROR(+(J24/_FV($A$6,"Shares outstanding",TRUE)*1000000)/$P$24-1,"")} | N24: {=IFERROR((+K24/_FV($A$6,"Shares outstanding",TRUE)*1000000)/$P$24-1,"")} | O24: {=IFERROR(+(L24/_FV($A$6,"Shares outstanding",TRUE)*1000000)/$P$24-1,"")} | P24: {=+_FV(A6,"Price")} -> 156.6514
B25: Average | D25: =+IFERROR(AVERAGE(K6:K17),"") | E25: =IFERROR(+AVERAGE(M6:M17),"") | F25: =IFERROR(+AVERAGE(O6:O17),"") | G25: =-Inputs!$Q$99+Inputs!$Q$100 -> 0 | H25: =+Inputs!$Q$101 -> 0 | I25: =+Inputs!$Q$102 -> 0 | J25: =IFERROR(+D25*$D$97+G25+H25+I25,"") | K25: =IFERROR(E25*$D$100+G25+H25+I25,"") | L25: =IFERROR(+F25*$D$105,"") | M25: {=IFERROR(+(J25/_FV($A$6,"Shares outstanding",TRUE)*1000000)/$P$24-1,"")} | N25: {=IFERROR((+K25/_FV($A$6,"Shares outstanding",TRUE)*1000000)/$P$24-1,"")} | O25: {=IFERROR(+(L25/_FV($A$6,"Shares outstanding",TRUE)*1000000)/$P$24-1,"")}
B26: Median | D26: =IFERROR(MEDIAN(K6:K17),"") | E26: =IFERROR(MEDIAN(M6:M17),"") | F26: =IFERROR(MEDIAN(O6:O17),"") | G26: =-Inputs!$Q$99+Inputs!$Q$100 -> 0 | H26: =+Inputs!$Q$101 -> 0 | I26: =+Inputs!$Q$102 -> 0 | J26: =IFERROR(D26*$D$97+G26+H26+I26,"") | K26: =IFERROR(E26*$D$100+G26+H26+I26,"") | L26: =IFERROR(+F26*$D$105,"") | M26: {=IFERROR(+(J26/_FV($A$6,"Shares outstanding",TRUE)*1000000)/$P$24-1,"")} | N26: {=IFERROR((+K26/_FV($A$6,"Shares outstanding",TRUE)*1000000)/$P$24-1,"")} | O26: {=+IFERROR((L26/_FV($A$6,"Shares outstanding",TRUE)*1000000)/$P$24-1,"")}
B27: Second Maximum | D27: =IFERROR(LARGE(K6:K17,2),"") | E27: =IFERROR(LARGE(M6:M17,2),"") | F27: =IFERROR(LARGE(O6:O17,2),"") | G27: =-Inputs!$Q$99+Inputs!$Q$100 -> 0 | H27: =+Inputs!$Q$101 -> 0 | I27: =+Inputs!$Q$102 -> 0 | J27: =IFERROR(+D27*$D$97+G27+H27+I27,"") | K27: =IFERROR(E27*$D$100+G27+H27+I27,"") | L27: =IFERROR(+F27*$D$105,"") | M27: {=IFERROR(+(J27/_FV($A$6,"Shares outstanding",TRUE)*1000000)/$P$24-1,"")} | N27: {=IFERROR((+K27/_FV($A$6,"Shares outstanding",TRUE)*1000000)/$P$24-1,"")} | O27: {=IFERROR(+(L27/_FV($A$6,"Shares outstanding",TRUE)*1000000)/$P$24-1,"")}
B29: Profitability | D29: =+LEFT(B6, FIND(" ", B6 & " ") - 1) -> ADVANCED | E29: =+LEFT(B8, FIND(" ", B8 & " ") - 1) | F29: =+LEFT(B9, FIND(" ", B9 & " ") - 1) | G29: =+LEFT(B10, FIND(" ", B10 & " ") - 1) | H29: =+LEFT(B11, FIND(" ", B11 & " ") - 1) | I29: =+LEFT(B12, FIND(" ", B12 & " ") - 1) | J29: =+LEFT(C12, FIND(" ", C12 & " ") - 1) | K29: =+LEFT(B14, FIND(" ", B14 & " ") - 1) | L29: =+LEFT(B15, FIND(" ", B15 & " ") - 1) | M29: =+LEFT(B16, FIND(" ", B16 & " ") - 1) | N29: =+LEFT(B17, FIND(" ", B17 & " ") - 1) | O29: Average
B31: Operating Margin | D31: =IFERROR(D101/D97,"") | E31: =IFERROR(E101/E97,"") | F31: =IFERROR(F101/F97,"") | G31: =IFERROR(G101/G97,"") | H31: =IFERROR(H101/H97,"") | I31: =IFERROR(I101/I97,"") | J31: =IFERROR(J101/J97,"") | K31: =IFERROR(K101/K97,"") | ... N31: =IFERROR(N101/N97,"") | O31: =IFERROR(+AVERAGE(D31:N31),"")
B32: Net Income Margin | D32: =IFERROR(D105/D97,"") | E32: =IFERROR(E105/E97,"") | F32: =IFERROR(F105/F97,"") | G32: =IFERROR(G105/G97,"") | H32: =IFERROR(H105/H97,"") | I32: =IFERROR(I105/I97,"") | J32: =IFERROR(J105/J97,"") | K32: =IFERROR(K105/K97,"") | ... N32: =IFERROR(N105/N97,"") | O32: =IFERROR(+AVERAGE(D32:N32),"")
B33: ROA (%) | D33: =IFERROR(D105/D117,"") | E33: =IFERROR(E105/E117,"") | F33: =IFERROR(F105/F117,"") | G33: =IFERROR(G105/G117,"") | H33: =IFERROR(H105/H117,"") | I33: =IFERROR(I105/I117,"") | J33: =IFERROR(J105/J117,"") | K33: =IFERROR(K105/K117,"") | ... N33: =IFERROR(N105/N117,"") | O33: =IFERROR(+AVERAGE(D33:N33),"")
B34: Financial Cost of Debt | D34: =IFERROR(+(D102/D121)*(1-(D104/D103)),"") | E34: =IFERROR(+(E102/E121)*(1-(E104/E103)),"") | F34: =IFERROR(+(F102/F121)*(1-(F104/F103)),"") | G34: =IFERROR(+(G102/G121)*(1-(G104/G103)),"") | H34: =IFERROR(+(H102/H121)*(1-(H104/H103)),"") | I34: =IFERROR(+(I102/I121)*(1-(I104/I103)),"") | J34: =IFERROR(+(J102/J121)*(1-(J104/J103)),"") | K34: =IFERROR(+(K102/K121)*(1-(K104/K103)),"") | ... N34: =IFERROR(+(N102/N121)*(1-(N104/N103)),"") | O34: =IFERROR(+AVERAGE(D34:N34),"")
B35: Return on Equity (RoE) | D35: =IFERROR(+D105/D122,"") | E35: =IFERROR(+E105/E122,"") | F35: =IFERROR(+F105/F122,"") | G35: =IFERROR(+G105/G122,"") | H35: =IFERROR(+H105/H122,"") | I35: =IFERROR(+I105/I122,"") | J35: =IFERROR(+J105/J122,"") | K35: =IFERROR(+K105/K122,"") | ... N35: =IFERROR(+N105/N122,"") | O35: =IFERROR(+AVERAGE(D35:N35),"")
B36: Return on Invested Capital (ROIC) | D36: =IFERROR(+D105/(D121+D122),"") | E36: =IFERROR(+E105/(E121+E122),"") | F36: =IFERROR(+F105/(F121+F122),"") | G36: =IFERROR(+G105/(G121+G122),"") | H36: =IFERROR(+H105/(H121+H122),"") | I36: =IFERROR(+I105/(I121+I122),"") | J36: =IFERROR(+J105/(J121+J122),"") | K36: =IFERROR(+K105/(K121+K122),"") | ... N36: =IFERROR(+N105/(N121+N122),"") | O36: =IFERROR(+AVERAGE(D36:N36),"")
B38: Solvency | D38: =+D29 -> ADVANCED | E38: =+E29 | F38: =+F29 | G38: =+G29 | H38: =+H29 | I38: =+I29 | J38: =+J29 | K38: =+K29 | ... O38: =+O29 -> Average
B40: Debt/Assets | D40: =IFERROR(D121/D117,"") | E40: =IFERROR(E121/E117,"") | F40: =IFERROR(F121/F117,"") | G40: =IFERROR(G121/G117,"") | H40: =IFERROR(H121/H117,"") | I40: =IFERROR(I121/I117,"") | J40: =IFERROR(J121/J117,"") | K40: =IFERROR(K121/K117,"") | ... N40: =IFERROR(N121/N117,"") | O40: =IFERROR(+AVERAGE(D40:N40),"")
B41: Net Debt/EBITDA | D41: =IFERROR(+(D121-D111)/D100,"") | E41: =IFERROR(+(E121-E111)/E100,"") | F41: =IFERROR(+(F121-F111)/F100,"") | G41: =IFERROR(+(G121-G111)/G100,"") | H41: =IFERROR(+(H121-H111)/H100,"") | I41: =IFERROR(+(I121-I111)/I100,"") | J41: =IFERROR(+(J121-J111)/J100,"") | K41: =IFERROR(+(K121-K111)/K100,"") | ... N41: =IFERROR(+(N121-N111)/N100,"") | O41: =IFERROR(+AVERAGE(D41:N41),"")
B42: Interest Coverage Ratio | D42: =IFERROR(D101/D102,"") | E42: =IFERROR(E101/E102,"") | F42: =IFERROR(F101/F102,"") | G42: =IFERROR(G101/G102,"") | H42: =IFERROR(H101/H102,"") | I42: =IFERROR(I101/I102,"") | J42: =IFERROR(J101/J102,"") | K42: =IFERROR(K101/K102,"") | ... N42: =IFERROR(N101/N102,"") | O42: =IFERROR(+AVERAGE(D42:N42),"")
B44: Liquidity | D44: =+D29 -> ADVANCED | E44: =+E29 | F44: =+F29 | G44: =+G29 | H44: =+H29 | I44: =+I29 | J44: =+J29 | K44: =+K29 | ... O44: =+O29 -> Average
B46: Cash Ratio | D46: =IFERROR(D111/D119,"") | E46: =IFERROR(E111/E119,"") | F46: =IFERROR(F111/F119,"") | G46: =IFERROR(G111/G119,"") | H46: =IFERROR(H111/H119,"") | I46: =IFERROR(I111/I119,"") | J46: =IFERROR(J111/J119,"") | K46: =IFERROR(K111/K119,"") | ... N46: =IFERROR(N111/N119,"") | O46: =IFERROR(+AVERAGE(D46:N46),"")
B47: Quick Ratio | D47: =IFERROR(+(D111+D112)/D119,"") | E47: =IFERROR(+(E111+E112)/E119,"") | F47: =IFERROR(+(F111+F112)/F119,"") | G47: =IFERROR(+(G111+G112)/G119,"") | H47: =IFERROR(+(H111+H112)/H119,"") | I47: =IFERROR(+(I111+I112)/I119,"") | J47: =IFERROR(+(J111+J112)/J119,"") | K47: =IFERROR(+(K111+K112)/K119,"") | ... N47: =IFERROR(+(N111+N112)/N119,"") | O47: =IFERROR(+AVERAGE(D47:N47),"")
B48: Current Ratio | D48: =IFERROR(D115/D119,"") | E48: =IFERROR(E115/E119,"") | F48: =IFERROR(F115/F119,"") | G48: =IFERROR(G115/G119,"") | H48: =IFERROR(H115/H119,"") | I48: =IFERROR(I115/I119,"") | J48: =IFERROR(J115/J119,"") | K48: =IFERROR(K115/K119,"") | ... N48: =IFERROR(N115/N119,"") | O48: =IFERROR(+AVERAGE(D48:N48),"")
B50: Activity | D50: =+D29 -> ADVANCED | E50: =+E29 | F50: =+F29 | G50: =+G29 | H50: =+H29 | I50: =+I29 | J50: =+J29 | K50: =+K29 | ... O50: =+O29 -> Average
B52: Inventory Turnover | D52: =IFERROR(D98/(AVERAGE(D113:D114)),"") | E52: =IFERROR(E98/(AVERAGE(E113:E114)),"") | F52: =IFERROR(F98/(AVERAGE(F113:F114)),"") | G52: =IFERROR(G98/(AVERAGE(G113:G114)),"") | H52: =IFERROR(H98/(AVERAGE(H113:H114)),"") | I52: =IFERROR(I98/(AVERAGE(I113:I114)),"") | J52: =IFERROR(J98/(AVERAGE(J113:J114)),"") | K52: =IFERROR(K98/(AVERAGE(K113:K114)),"") | ... N52: =IFERROR(N98/(AVERAGE(N113:N114)),"") | O52: =IFERROR(+AVERAGE(D52:N52),"")
B53: Acc. Receivable Turnover | D53: =IFERROR(D97/D112,"") | E53: =IFERROR(E97/E112,"") | F53: =IFERROR(F97/F112,"") | G53: =IFERROR(G97/G112,"") | H53: =IFERROR(H97/H112,"") | I53: =IFERROR(I97/I112,"") | J53: =IFERROR(J97/J112,"") | K53: =IFERROR(K97/K112,"") | ... N53: =IFERROR(N97/N112,"") | O53: =IFERROR(+AVERAGE(D53:N53),"")
B54: Payables Turnover | D54: =IFERROR(D98/D118,"") | E54: =IFERROR(E98/E118,"") | F54: =IFERROR(F98/F118,"") | G54: =IFERROR(G98/G118,"") | H54: =IFERROR(H98/H118,"") | I54: =IFERROR(I98/I118,"") | J54: =IFERROR(J98/J118,"") | K54: =IFERROR(K98/K118,"") | ... N54: =IFERROR(N98/N118,"") | O54: =IFERROR(+AVERAGE(D54:N54),"")
...

Sheet ESG
B2: Environmental, Social and Governance Analysis
B4: Author: | E4: Highlights | N4: Recent News
B6: Overview | D6: .
B7: Last Update | D7: .
B8: Latest year with data
B9: GICS Sector
B10: GICS Industry Group
B11: Final Review
B13: ESG Scores
B14: LSEG ESG Score
B15: E-Score
B16: S-Score | E16: GHG Scope 1 and 2 Emissions: | N16: Water, Waste, Energy Management:
B17: G-Score
B18: S&P Global ESG Score
B19: Environmental
B20: Social
B21: Governance & Economic
B22: Sustainalytics
B23: ISS ESG Corporate Rating
B24: SDG Impact Rating
B25: Governance Quality Score
B26: MSCI ESG Ratings
B29: Industry ESG Overview:
E33: ENVIRONMENTAL
G35: Overview | H35: Targets | K35: Improvements | O35: Comments
E36: GHG (or CO2) Scope 1 Emissions
E38: Water Consumption
E40: Energy Consumption
E42: Waste Management
E44: Other
E46: SOCIAL
B48: Important Sources: | G48: Overview | H48: Targets | K48: Improvements | O48: Comments
B49: Annual Report | E49: Employee Turnover %
B50: Sustainability Report | D50: .
B51: Proxy Statement | D51: . | E51: Salaries & Compensation
E53: Reputation
E55: Discrimination Events
E57: Work Safety
E59: Damage to consumer health
E61: Pension Plan
...

Sheet ESG Inputs
B2: ESG Inputs
A4: x | B4: Total GHG Scope 1 Emissions | G4: 2014 | H4: =+G4+1 -> 2015 | I4: =+H4+1 -> 2016 | J4: =+I4+1 -> 2017 | K4: =+J4+1 -> 2018 | L4: =+K4+1 -> 2019 | M4: =+L4+1 -> 2020 | N4: =+M4+1 -> 2021 | O4: =+N4+1 -> 2022 | ... Q4: =+P4+1 -> 2024 | R4: ="CAGR "&$G$4&" - "&$Q$4 -> CAGR 2014 - 2024
B6: =+Peers!B6 -> ADVANCED MICRO DEVICES, INC. | R6: =IFERROR((Q6/G6)^(1/COUNT($G$4:$Q$4))-1,"")
B7: =+Peers!B8 | R7: =IFERROR((Q7/G7)^(1/COUNT($G$4:$Q$4))-1,"")
B8: =+Peers!B9 | R8: =IFERROR((Q8/G8)^(1/COUNT($G$4:$Q$4))-1,"")
B9: =+Peers!B10 | R9: =IFERROR((Q9/G9)^(1/COUNT($G$4:$Q$4))-1,"")
B10: =+Peers!B11 | R10: =IFERROR((Q10/G10)^(1/COUNT($G$4:$Q$4))-1,"")
B11: =+Peers!B12 | R11: =IFERROR((Q11/G11)^(1/COUNT($G$4:$Q$4))-1,"")
B12: =+Peers!B13 | R12: =IFERROR((Q12/G12)^(1/COUNT($G$4:$Q$4))-1,"")
B13: =+Peers!B14 | R13: =IFERROR((Q13/G13)^(1/COUNT($G$4:$Q$4))-1,"")
B14: =+Peers!B15 | R14: =IFERROR((Q14/G14)^(1/COUNT($G$4:$Q$4))-1,"")
B15: =+Peers!B16 | R15: =IFERROR((Q15/G15)^(1/COUNT($G$4:$Q$4))-1,"")
B16: =+Peers!B17 | R16: =IFERROR((Q16/G16)^(1/COUNT($G$4:$Q$4))-1,"")
A18: x | B18: Total GHG Scope 2 (Location-Based) Emissions | G18: 2014 | H18: =+G18+1 -> 2015 | I18: =+H18+1 -> 2016 | J18: =+I18+1 -> 2017 | K18: =+J18+1 -> 2018 | L18: =+K18+1 -> 2019 | M18: =+L18+1 -> 2020 | N18: =+M18+1 -> 2021 | O18: =+N18+1 -> 2022 | ... Q18: =+P18+1 -> 2024 | R18: ="CAGR "&$G$4&" - "&$Q$4 -> CAGR 2014 - 2024
B20: =+$B$6 -> ADVANCED MICRO DEVICES, INC. | R20: =IFERROR((Q20/G20)^(1/COUNT($G$4:$Q$4))-1,"")
B21: =+$B$7 | R21: =IFERROR((Q21/G21)^(1/COUNT($G$4:$Q$4))-1,"")
B22: =+$B$8 | R22: =IFERROR((Q22/G22)^(1/COUNT($G$4:$Q$4))-1,"")
B23: =+$B$9 | R23: =IFERROR((Q23/G23)^(1/COUNT($G$4:$Q$4))-1,"")
B24: =+$B$10 | R24: =IFERROR((Q24/G24)^(1/COUNT($G$4:$Q$4))-1,"")
B25: =+$B$11 | R25: =IFERROR((Q25/G25)^(1/COUNT($G$4:$Q$4))-1,"")
B26: =+$B$12 | R26: =IFERROR((Q26/G26)^(1/COUNT($G$4:$Q$4))-1,"")
B27: =+$B$13 | R27: =IFERROR((Q27/G27)^(1/COUNT($G$4:$Q$4))-1,"")
B28: =+$B$14 | R28: =IFERROR((Q28/G28)^(1/COUNT($G$4:$Q$4))-1,"")
B29: =+$B$15 | R29: =IFERROR((Q29/G29)^(1/COUNT($G$4:$Q$4))-1,"")
B30: =+$B$16 | R30: =IFERROR((Q30/G30)^(1/COUNT($G$4:$Q$4))-1,"")
A32: x | B32: Total Energy Usage | G32: 2014 | H32: =+G32+1 -> 2015 | I32: =+H32+1 -> 2016 | J32: =+I32+1 -> 2017 | K32: =+J32+1 -> 2018 | L32: =+K32+1 -> 2019 | M32: =+L32+1 -> 2020 | N32: =+M32+1 -> 2021 | O32: =+N32+1 -> 2022 | ... Q32: =+P32+1 -> 2024 | R32: ="CAGR "&$G$4&" - "&$Q$4 -> CAGR 2014 - 2024
B34: =+$B$6 -> ADVANCED MICRO DEVICES, INC. | R34: =IFERROR((Q34/G34)^(1/COUNT($G$4:$Q$4))-1,"")
B35: =+$B$7 | R35: =IFERROR((Q35/G35)^(1/COUNT($G$4:$Q$4))-1,"")
B36: =+$B$8 | R36: =IFERROR((Q36/G36)^(1/COUNT($G$4:$Q$4))-1,"")
B37: =+$B$9 | R37: =IFERROR((Q37/G37)^(1/COUNT($G$4:$Q$4))-1,"")
B38: =+$B$10 | R38: =IFERROR((Q38/G38)^(1/COUNT($G$4:$Q$4))-1,"")
B39: =+$B$11 | R39: =IFERROR((Q39/G39)^(1/COUNT($G$4:$Q$4))-1,"")
B40: =+$B$12 | R40: =IFERROR((Q40/G40)^(1/COUNT($G$4:$Q$4))-1,"")
B41: =+$B$13 | R41: =IFERROR((Q41/G41)^(1/COUNT($G$4:$Q$4))-1,"")
B42: =+$B$14 | R42: =IFERROR((Q42/G42)^(1/COUNT($G$4:$Q$4))-1,"")
B43: =+$B$15 | R43: =IFERROR((Q43/G43)^(1/COUNT($G$4:$Q$4))-1,"")
B44: =+$B$16 | R44: =IFERROR((Q44/G44)^(1/COUNT($G$4:$Q$4))-1,"")
A46: x | B46: Total Water Consumption | G46: 2014 | H46: =+G46+1 -> 2015 | I46: =+H46+1 -> 2016 | J46: =+I46+1 -> 2017 | K46: =+J46+1 -> 2018 | L46: =+K46+1 -> 2019 | M46: =+L46+1 -> 2020 | N46: =+M46+1 -> 2021 | O46: =+N46+1 -> 2022 | ... Q46: =+P46+1 -> 2024 | R46: ="CAGR "&$G$4&" - "&$Q$4 -> CAGR 2014 - 2024
B48: =+$B$6 -> ADVANCED MICRO DEVICES, INC. | R48: =IFERROR((Q48/G48)^(1/COUNT($G$4:$Q$4))-1,"")
B49: =+$B$7 | R49: =IFERROR((Q49/G49)^(1/COUNT($G$4:$Q$4))-1,"")
...

Sheet DCF
B2: DCF
A4: x | B4: Key Assumptions | R4: #VALUE!
B6: Switches | E6: Bear Case | H6: Base Case | K6: Bull Case | X6: FCFF | Y6: FCFE | Z6: Tax Shield | AA6: Total Payout | AB6: NOPAT | AC6: Debt Borrowing | AD6: Cash Balance | AE6: Total Assets | AF6: Total Liabilities | AG6: Shareholder's Equity | AH6: Current Liabilities | AI6: Current Assets
B7: Revenue | C7: 2 | E7: Revenue | F7: -0.02 | H7: Revenue | K7: Revenue | L7: 0.02 | S7: Most Recent Fiscal Year | W7: 2022 | X7: =+E192 | Y7: =+E244 -> 0 | Z7: =+H216 | AA7: =+E257 -> 0 | AB7: =+E182 | AC7: =+E242 -> 0 | AD7: =+E88 -> 0
B8: EBIT | C8: 2 | E8: EBIT | F8: -0.01 | H8: EBIT | K8: EBIT | L8: 0.01 | S8: End of Fiscal Year | W8: =+W7+1 -> 2023 | X8: =+F192 | Y8: =+F244 -> 0 | Z8: =+I216 | AA8: =+F257 -> 0 | AB8: =+F182 | AC8: =+F242 -> 0 | AD8: =+F88 -> 0
B9: WACC | C9: 2 | E9: WACC | F9: =IFERROR(+I9+0.5%,"") | H9: WACC | I9: =WACC!G25 | K9: WACC | L9: =IFERROR(I9-0.5%,"") | S9: Most Recent Quarter End Date | W9: =+W8+1 -> 2024 | X9: =+G192 | Y9: =+G244 -> 0 | Z9: =+J216 | AA9: =+G257 -> 0 | AB9: =+G182 | AC9: =+G242 -> 0 | AD9: =+G88 -> 0 | AE9: =Inputs!Q48 -> 0 | AF9: =+Inputs!Q60 -> 0 | AG9: =+AE9-AF9 -> 0 | AH9: =+Inputs!Q54 -> 0 | AI9: =+Inputs!Q38 -> 0
B10: TGR | C10: 2 | E10: TGR | F10: =+I10-0.5% -> -0.005 | H10: TGR | K10: TGR | L10: =+I10+0.5% -> 0.005 | S10: Valuation Date | W10: =+W9+1 -> 2025 | X10: =+H192 | Y10: =+H244 | Z10: =+K216 | AA10: =+H257 | AB10: =+H182 | AC10: =+H242 -> 0 | AD10: =+H88 | AE10: =Inputs!Q48+DCF!H88+DCF!H90+DCF!H93+DCF!H96+DCF!H99+DCF!H105-DCF!G88-DCF!G90-DCF!G93-DCF!G96-DCF!G99-DCF!G105 -> #VALUE! | AF10: =+Inputs!Q60+(DCF!H110+DCF!H113+DCF!H116+DCF!H118*DCF!G110*DCF!G113*DCF!G116*DCF!G118) -> #VALUE! | AG10: =+AE10-AF10 -> #VALUE! | AH10: =+AH9+H110+H113-G110-G113 -> #VALUE! | AI10: =+H88+H90+H93+H96 -> #VALUE!
W11: =+W10+1 -> 2026 | X11: =+I192 | Y11: =+I244 | Z11: =+L216 | AA11: =+I257 | AB11: =+I182 | AC11: =+I242 | AD11: =+I88 | AE11: =AE10+DCF!I88+DCF!I90+DCF!I93+DCF!I96+DCF!I99+DCF!I105-DCF!H88-DCF!H90-DCF!H93-DCF!H96-DCF!H99-DCF!H105 -> #VALUE! | AF11: =AF10+(DCF!I110+DCF!I113+DCF!I116+DCF!I118*DCF!H110*DCF!H113*DCF!H116*DCF!H118) -> #VALUE! | AG11: =+AE11-AF11 -> #VALUE! | AH11: =+AH10+I110+I113-H110-H113 -> #VALUE! | AI11: =+I88+I90+I93+I96 -> #VALUE!
B12: WACC | C12: =CHOOSE(C9,F9,I9,L9) | W12: =+W11+1 -> 2027 | X12: =+J192 | Y12: =+J244 | Z12: =+M216 | AA12: =+J257 | AB12: =+J182 | AC12: =+J242 | AD12: =+J88
B13: TGR | C13: =CHOOSE(C10,F10,I10,L10) -> 0 | W13: =+W12+1 -> 2028 | X13: =+K192 | Y13: =+K244 | Z13: =+N216 | AA13: =+K257 | AB13: =+K182 | AC13: =+K242 | AD13: =+K88
W14: =+W13+1 -> 2029 | X14: =+L192 | Y14: =+L244 | Z14: =+O216 | AA14: =+L257 | AB14: =+L182 | AC14: =+L242 | AD14: =+L88
A15: x | B15: Operating Assumptions | E15: 2022 | F15: =+E15+1 -> 2023 | G15: =+F15+1 -> 2024 | H15: =+G15+1 -> 2025 | I15: =+H15+1 -> 2026 | J15: =+I15+1 -> 2027 | K15: =+J15+1 -> 2028 | L15: =+K15+1 -> 2029 | M15: =+L15+1 -> 2030 | ... Q15: =+P15+1 -> 2034
B17: Number of Locations (Beginning)
B18: Net Locations Opened/Acquired
B19: Capex per Net Additions
B20: Locations Opened/Acquired
B21: Locations Closed/Sold
B22: Number of Locations (End)
B23: Average Sales per Location
B24: Same Store Sales Growth
B25: Beginning Locations Total Sales
B26: New Locations Total Sales (Estimate)
B27: In millions of USD
A28: x | B28: Income Statement | E28: 2022 | F28: =+E28+1 -> 2023 | G28: =+F28+1 -> 2024 | H28: =+G28+1 -> 2025 | I28: =+H28+1 -> 2026 | J28: =+I28+1 -> 2027 | K28: =+J28+1 -> 2028 | L28: =+K28+1 -> 2029 | M28: =+L28+1 -> 2030 | ... Q28: =+P28+1 -> 2034
B30: Revenue (Sales) | D30: =+_xlfn.XLOOKUP($B30,Inputs!$B:$B,Inputs!N:N) -> 0 | E30: =+_xlfn.XLOOKUP($B30,Inputs!$B:$B,Inputs!O:O) -> 0 | F30: =+_xlfn.XLOOKUP($B30,Inputs!$B:$B,Inputs!P:P) -> 0 | G30: =+_xlfn.XLOOKUP($B30,Inputs!$B:$B,Inputs!Q:Q) -> 0 | H30: =+H25+H26 -> 0 | I30: =+I25+I26 -> 0 | J30: =+J25+J26 -> 0 | K30: =+K25+K26 -> 0 | L30: =+L25+L26 -> 0 | M30: =+M25+M26 -> 0 | N30: =+N25+N26 -> 0 | O30: =+O25+O26 -> 0 | ... Q30: =+Q25+Q26 -> 0
B31: % of growth | E31: =IFERROR((E30-D30)/D30,"") | F31: =IFERROR((F30-E30)/E30,"") | G31: =IFERROR((G30-F30)/F30,"") | H31: =IFERROR(H30/G30-1,"") | I31: =IFERROR(I30/H30-1,"") | J31: =IFERROR(J30/I30-1,"") | K31: =IFERROR(K30/J30-1,"") | L31: =IFERROR(L30/K30-1,"") | M31: =IFERROR(M30/L30-1,"") | N31: =IFERROR(N30/M30-1,"") | O31: =IFERROR(O30/N30-1,"") | ... Q31: =IFERROR(Q30/P30-1,"")
B33: COGS (Cost of Goods Sold) | E33: =+_xlfn.XLOOKUP($B33,Inputs!$B:$B,Inputs!O:O) -> 0 | F33: =+_xlfn.XLOOKUP($B33,Inputs!$B:$B,Inputs!P:P) -> 0 | G33: =+_xlfn.XLOOKUP($B33,Inputs!$B:$B,Inputs!Q:Q) -> 0 | H33: =H34*H$30 -> 0 | I33: =I34*I$30 -> 0 | J33: =J34*J$30 -> 0 | K33: =K34*K$30 -> 0 | L33: =L34*L$30 -> 0 | M33: =M34*M$30 -> 0 | N33: =N34*N$30 -> 0 | O33: =O34*O$30 -> 0 | ... Q33: =Q34*Q$30 -> 0
B34: % of revenue | E34: =IFERROR(E33/E$30,"") | F34: =IFERROR(F33/F$30,"") | G34: =IFERROR(G33/G$30,"")
B36: Gross Profit | E36: =+_xlfn.XLOOKUP($B36,Inputs!$B:$B,Inputs!O:O) -> 0 | F36: =+_xlfn.XLOOKUP($B36,Inputs!$B:$B,Inputs!P:P) -> 0 | G36: =+_xlfn.XLOOKUP($B36,Inputs!$B:$B,Inputs!Q:Q) -> 0 | H36: =+H30-H33 -> 0 | I36: =+I30-I33 -> 0 | J36: =+J30-J33 -> 0 | K36: =+K30-K33 -> 0 | L36: =+L30-L33 -> 0 | M36: =+M30-M33 -> 0 | N36: =+N30-N33 -> 0 | O36: =+O30-O33 -> 0 | ... Q36: =+Q30-Q33 -> 0
B37: Gross Profit Margin | E37: =IFERROR(E36/E$30,"") | F37: =IFERROR(F36/F$30,"") | G37: =IFERROR(G36/G$30,"") | H37: =IFERROR(H36/H$30,"") | I37: =IFERROR(I36/I$30,"") | J37: =IFERROR(J36/J$30,"") | K37: =IFERROR(K36/K$30,"") | L37: =IFERROR(L36/L$30,"") | ... Q37: =IFERROR(Q36/Q$30,"")
B39: SG&A (Selling, General & Administrative) | E39: =+_xlfn.XLOOKUP($B39,Inputs!$B:$B,Inputs!O:O) -> 0 | F39: =+_xlfn.XLOOKUP($B39,Inputs!$B:$B,Inputs!P:P) -> 0 | G39: =+_xlfn.XLOOKUP($B39,Inputs!$B:$B,Inputs!Q:Q) -> 0 | H39: =IFERROR(G39*(1+H31),"") | I39: =IFERROR(H39*(1+I31),"") | J39: =IFERROR(I39*(1+J31),"") | K39: =IFERROR(J39*(1+K31),"") | L39: =IFERROR(K39*(1+L31),"") | M39: =IFERROR(L39*(1+M31),"") | N39: =IFERROR(M39*(1+N31),"") | O39: =IFERROR(N39*(1+O31),"") | ... Q39: =IFERROR(P39*(1+Q31),"")
B40: SG&A Margin | E40: =IFERROR(E39/E$30,"") | F40: =IFERROR(F39/F$30,"") | G40: =IFERROR(G39/G$30,"") | H40: =IFERROR(AVERAGE(E40:G40),"") | I40: =IFERROR(AVERAGE(F40:H40),"") | J40: =IFERROR(AVERAGE(G40:I40),"") | K40: =IFERROR(AVERAGE(H40:J40),"") | L40: =IFERROR(AVERAGE(I40:K40),"") | M40: =IFERROR(AVERAGE(J40:L40),"") | N40: =IFERROR(AVERAGE(K40:M40),"") | O40: =IFERROR(AVERAGE(L40:N40),"") | ... Q40: =IFERROR(AVERAGE(N40:P40),"")
B42: R&D (Research & Development) | E42: =+_xlfn.XLOOKUP($B42,Inputs!$B:$B,Inputs!O:O) -> 0 | F42: =+_xlfn.XLOOKUP($B42,Inputs!$B:$B,Inputs!P:P) -> 0 | G42: =+_xlfn.XLOOKUP($B42,Inputs!$B:$B,Inputs!Q:Q) -> 0 | H42: =H43*H$30 -> 0 | I42: =I43*I$30 -> 0 | J42: =J43*J$30 -> 0 | K42: =K43*K$30 -> 0 | L42: =L43*L$30 -> 0 | M42: =M43*M$30 -> 0 | N42: =N43*N$30 -> 0 | O42: =O43*O$30 -> 0 | ... Q42: =Q43*Q$30 -> 0
B43: % of revenue | E43: =IFERROR(E42/E30,"") | F43: =IFERROR(F42/F30,"") | G43: =IFERROR(G42/G30,"")
B45: Other Operating (Income) Expenses | E45: =+_xlfn.XLOOKUP($B45,Inputs!$B:$B,Inputs!O:O) -> 0 | F45: =+_xlfn.XLOOKUP($B45,Inputs!$B:$B,Inputs!P:P) -> 0 | G45: =+_xlfn.XLOOKUP($B45,Inputs!$B:$B,Inputs!Q:Q) -> 0 | H45: =IFERROR(AVERAGE(E45:G45)*(1+H31),"") | I45: =IFERROR(AVERAGE(F45:H45)*(1+I31),"") | J45: =IFERROR(AVERAGE(G45:I45)*(1+J31),"") | K45: =IFERROR(AVERAGE(H45:J45)*(1+K31),"") | L45: =IFERROR(AVERAGE(I45:K45)*(1+L31),"") | M45: =IFERROR(AVERAGE(J45:L45)*(1+M31),"") | N45: =IFERROR(AVERAGE(K45:M45)*(1+N31),"") | O45: =IFERROR(AVERAGE(L45:N45)*(1+O31),"") | ... Q45: =IFERROR(AVERAGE(N45:P45)*(1+Q31),"")
B47: EBITDA | E47: =+_xlfn.XLOOKUP($B47,Inputs!$B:$B,Inputs!O:O) -> 0 | F47: =+_xlfn.XLOOKUP($B47,Inputs!$B:$B,Inputs!P:P) -> 0 | G47: =+_xlfn.XLOOKUP($B47,Inputs!$B:$B,Inputs!Q:Q) -> 0 | H47: =IFERROR(H36-H39-H42-H45,"") | I47: =IFERROR(I36-I39-I42-I45,"") | J47: =IFERROR(J36-J39-J42-J45,"") | K47: =IFERROR(K36-K39-K42-K45,"") | L47: =IFERROR(L36-L39-L42-L45,"") | M47: =IFERROR(M36-M39-M42-M45,"") | N47: =IFERROR(N36-N39-N42-N45,"") | O47: =IFERROR(O36-O39-O42-O45,"") | ... Q47: =IFERROR(Q36-Q39-Q42-Q45,"")
B48: EBITDA Margin | E48: =IFERROR(E47/E$30,"") | F48: =IFERROR(F47/F$30,"") | G48: =IFERROR(G47/G$30,"") | H48: =IFERROR(H47/H$30,"") | I48: =IFERROR(I47/I$30,"") | J48: =IFERROR(J47/J$30,"") | K48: =IFERROR(K47/K$30,"") | L48: =IFERROR(L47/L$30,"") | ... Q48: =IFERROR(Q47/Q$30,"")
B50: D&A (Depreciation & Amortization) | E50: =+_xlfn.XLOOKUP($B50,Inputs!$B:$B,Inputs!O:O) -> 0 | F50: =+_xlfn.XLOOKUP($B50,Inputs!$B:$B,Inputs!P:P) -> 0 | G50: =+_xlfn.XLOOKUP($B50,Inputs!$B:$B,Inputs!Q:Q) -> 0 | H50: =+IFERROR(H53+H56,"") | I50: =+IFERROR(I53+I56,"") | J50: =+IFERROR(J53+J56,"") | K50: =+IFERROR(K53+K56,"") | L50: =+IFERROR(L53+L56,"") | M50: =+IFERROR(M53+M56,"") | N50: =+IFERROR(N53+N56,"") | O50: =+IFERROR(O53+O56,"") | ... Q50: =+IFERROR(Q53+Q56,"")
B51: % of PP&E+ROU Assets+Intangibles excl. Goodwill | E51: =IFERROR(E50/AVERAGE(Inputs!O39+Inputs!O42+Inputs!O44,Inputs!N39+Inputs!N42+Inputs!N44),"") | F51: =IFERROR(F50/AVERAGE(Inputs!P39+Inputs!P42+Inputs!P44,Inputs!O39+Inputs!O42+Inputs!O44),"") | G51: =IFERROR(G50/AVERAGE(Inputs!Q39+Inputs!Q42+Inputs!Q44,Inputs!P39+Inputs!P42+Inputs!P44),"") | H51: =IFERROR(H50/(G99+G105),"") | I51: =IFERROR(I50/(H99+H105),"") | J51: =IFERROR(J50/(I99+I105),"") | K51: =IFERROR(K50/(J99+J105),"") | L51: =IFERROR(L50/(K99+K105),"") | M51: =IFERROR(M50/(L99+L105),"") | N51: =IFERROR(N50/(M99+M105),"") | O51: =IFERROR(O50/(N99+N105),"") | ... Q51: =IFERROR(Q50/(P99+P105),"")
B53: Depreciation Expense | E53: =+_xlfn.XLOOKUP($B53,Inputs!$B:$B,Inputs!O:O) -> 0 | F53: =+_xlfn.XLOOKUP($B53,Inputs!$B:$B,Inputs!P:P) -> 0 | G53: =+_xlfn.XLOOKUP($B53,Inputs!$B:$B,Inputs!Q:Q) -> 0 | H53: =IFERROR(H54*(G100+G101),"") | I53: =IFERROR(I54*(H100+H101),"") | J53: =IFERROR(J54*(I100+I101),"") | K53: =IFERROR(K54*(J100+J101),"") | L53: =IFERROR(L54*(K100+K101),"") | M53: =IFERROR(M54*(L100+L101),"") | N53: =IFERROR(N54*(M100+M101),"") | O53: =IFERROR(O54*(N100+N101),"") | ... Q53: =IFERROR(Q54*(P100+P101),"")
...

Sheet Inputs
B2: Inputs
B3: in millions of USD
A4: x | B4: Income Statement | G4: 2014 | H4: =+G4+1 -> 2015 | I4: =+H4+1 -> 2016 | J4: =+I4+1 -> 2017 | K4: =+J4+1 -> 2018 | L4: =+K4+1 -> 2019 | M4: =+L4+1 -> 2020 | N4: =+M4+1 -> 2021 | O4: =+N4+1 -> 2022 | ... Q4: =+P4+1 -> 2024 | R4: ="CAGR "&$G$4&" - "&$Q$4 -> CAGR 2014 - 2024
B6: Revenue (Sales) | R6: =IFERROR((Q6/G6)^(1/COUNT($G$4:$Q$4))-1,"")
B7: COGS (Cost of Goods Sold) | R7: =IFERROR((Q7/G7)^(1/COUNT($G$4:$Q$4))-1,"")
B8: Gross Profit | G8: =G6-G7 -> 0 | H8: =H6-H7 -> 0 | I8: =I6-I7 -> 0 | J8: =J6-J7 -> 0 | K8: =K6-K7 -> 0 | L8: =L6-L7 -> 0 | M8: =M6-M7 -> 0 | N8: =N6-N7 -> 0 | ... Q8: =Q6-Q7 -> 0 | R8: =IFERROR((Q8/G8)^(1/COUNT($G$4:$Q$4))-1,"")
B9: SG&A (Selling, General & Administrative) | R9: =IFERROR((Q9/G9)^(1/COUNT($G$4:$Q$4))-1,"")
B10: R&D (Research & Development) | R10: =IFERROR((Q10/G10)^(1/COUNT($G$4:$Q$4))-1,"")
B11: Other Operating (Income) Expenses | R11: =IFERROR((Q11/G11)^(1/COUNT($G$4:$Q$4))-1,"")
B12: EBITDA | G12: =+G8-G9-G10-G11 -> 0 | H12: =+H8-H9-H10-H11 -> 0 | I12: =+I8-I9-I10-I11 -> 0 | J12: =+J8-J9-J10-J11 -> 0 | K12: =+K8-K9-K10-K11 -> 0 | L12: =+L8-L9-L10-L11 -> 0 | M12: =+M8-M9-M10-M11 -> 0 | N12: =+N8-N9-N10-N11 -> 0 | ... Q12: =+Q8-Q9-Q10-Q11 -> 0 | R12: =IFERROR((Q12/G12)^(1/COUNT($G$4:$Q$4))-1,"")
B13: D&A (Depreciation & Amortization) | G13: =+SUM(G14:G15) -> 0 | H13: =+SUM(H14:H15) -> 0 | I13: =+SUM(I14:I15) -> 0 | J13: =+SUM(J14:J15) -> 0 | K13: =+SUM(K14:K15) -> 0 | L13: =+SUM(L14:L15) -> 0 | M13: =+SUM(M14:M15) -> 0 | N13: =+SUM(N14:N15) -> 0 | ... Q13: =+SUM(Q14:Q15) -> 0 | R13: =IFERROR((Q13/G13)^(1/COUNT($G$4:$Q$4))-1,"")
B14: Depreciation Expense | R14: =IFERROR((Q14/G14)^(1/COUNT($G$4:$Q$4))-1,"")
B15: Amortization Expense | R15: =IFERROR((Q15/G15)^(1/COUNT($G$4:$Q$4))-1,"")
B16: Operating Income (EBIT) | G16: =+G12-G13 -> 0 | H16: =+H12-H13 -> 0 | I16: =+I12-I13 -> 0 | J16: =+J12-J13 -> 0 | K16: =+K12-K13 -> 0 | L16: =+L12-L13 -> 0 | M16: =+M12-M13 -> 0 | N16: =+N12-N13 -> 0 | ... Q16: =+Q12-Q13 -> 0 | R16: =IFERROR((Q16/G16)^(1/COUNT($G$4:$Q$4))-1,"")
B17: Net Interest Expense (Income) | G17: =+G18-G19 -> 0 | H17: =+H18-H19 -> 0 | I17: =+I18-I19 -> 0 | J17: =+J18-J19 -> 0 | K17: =+K18-K19 -> 0 | L17: =+L18-L19 -> 0 | M17: =+M18-M19 -> 0 | N17: =+N18-N19 -> 0 | ... Q17: =+Q18-Q19 -> 0 | R17: =IFERROR((Q17/G17)^(1/COUNT($G$4:$Q$4))-1,"")
B18: Interest Expense | R18: =IFERROR((Q18/G18)^(1/COUNT($G$4:$Q$4))-1,"")
B19: Interest Income | R19: =IFERROR((Q19/G19)^(1/COUNT($G$4:$Q$4))-1,"")
B20: FX (Gain) Loss | R20: =IFERROR((Q20/G20)^(1/COUNT($G$4:$Q$4))-1,"")
B21: Other Non-Operating (Income) Expenses | R21: =IFERROR((Q21/G21)^(1/COUNT($G$4:$Q$4))-1,"")
B22: Pre-Tax Income (EBT) | G22: =+G16-G17-G20-G21 -> 0 | H22: =+H16-H17-H20-H21 -> 0 | I22: =+I16-I17-I20-I21 -> 0 | J22: =+J16-J17-J20-J21 -> 0 | K22: =+K16-K17-K20-K21 -> 0 | L22: =+L16-L17-L20-L21 -> 0 | M22: =+M16-M17-M20-M21 -> 0 | N22: =+N16-N17-N20-N21 -> 0 | ... Q22: =+Q16-Q17-Q20-Q21 -> 0 | R22: =IFERROR((Q22/G22)^(1/COUNT($G$4:$Q$4))-1,"")
B23: Tax Expense (Benefits) | R23: =IFERROR((Q23/G23)^(1/COUNT($G$4:$Q$4))-1,"")
B24: Net Income | G24: =+G22-G23 -> 0 | H24: =+H22-H23 -> 0 | I24: =+I22-I23 -> 0 | J24: =+J22-J23 -> 0 | K24: =+K22-K23 -> 0 | L24: =+L22-L23 -> 0 | M24: =+M22-M23 -> 0 | N24: =+N22-N23 -> 0 | ... Q24: =+Q22-Q23 -> 0 | R24: =IFERROR((Q24/G24)^(1/COUNT($G$4:$Q$4))-1,"")
B25: EPS basic | R25: =IFERROR((Q25/G25)^(1/COUNT($G$4:$Q$4))-1,"")
B26: EPS diluted | R26: =IFERROR((Q26/G26)^(1/COUNT($G$4:$Q$4))-1,"")
B27: Basic Weighted Average Shares
B28: Diluted Weighted Average Shares | R28: =IFERROR((Q28/G28)^(1/COUNT($G$4:$Q$4))-1,"")
