Workbook
Name COOLFUCNTION: _xlfn.LAMBDA(_xldudf_BOARDFLARE_EXEC("workbook-settings:coolfucntion"))
Name COOLFUCNTION: _xlfn.LAMBDA(_xldudf_BOARDFLARE_EXEC("workbook-settings:coolfucntion"))
Name COOLFUCNTION: _xlfn.LAMBDA(_xldudf_BOARDFLARE_EXEC("workbook-settings:coolfucntion"))
Name COOLFUCNTION: _xlfn.LAMBDA(_xldudf_BOARDFLARE_EXEC("workbook-settings:coolfucntion"))
Name COOLFUCNTION: _xlfn.LAMBDA(_xldudf_BOARDFLARE_EXEC("workbook-settings:coolfucntion"))
Name COOLFUCNTION: _xlfn.LAMBDA(_xldudf_BOARDFLARE_EXEC("workbook-settings:coolfucntion"))
Name COOLFUCNTION: _xlfn.LAMBDA(_xldudf_BOARDFLARE_EXEC("workbook-settings:coolfucntion"))
Name COOLFUCNTION: _xlfn.LAMBDA(_xldudf_BOARDFLARE_EXEC("workbook-settings:coolfucntion"))
Name COOLFUCNTION: _xlfn.LAMBDA(_xldudf_BOARDFLARE_EXEC("workbook-settings:coolfucntion"))
Name COOLFUCNTION: _xlfn.LAMBDA(_xldudf_BOARDFLARE_EXEC("workbook-settings:coolfucntion"))
Name Sectors: #REF!
Name Sectors: #REF!
Name Sectors: #REF!

Sheet Summary
E2: | EQUITY RESEARCH | U2: Lisbon Investment Society Equity Research
U3: March XX, 2025
D6: {=+_FV(DCF!R4,"Name")} -> ANALOG DEVICES, INC. | U6: Hold
U8: EXCHANGE:(TICKER)
U9: {=+"Price (7 Mar 25): $"&_FV(DCF!$R$4,"Price")} -> Price (7 Mar 25): $245,56
D10: Investment Thesis | U10: ="Price Target: $" & ROUND(IF(Summary!G25="FCFF",DCF!Q208,IF(Summary!G25="FCFE",DCF!Q251,IF(Summary!G25="Tax Shield",DCF!Q224,DCF!Q267))),2) &" "&IF(Summary!G25="FCFF","(FCFF)",IF(Summary!G25="FCFE","(FCFE)",IF(Summary!G25="Tax Shield","(APV)","(DDM)"))) -> Price Target: $127,94 (FCFF)
U11: =+"Upside (Downside): "&ROUND((DCF!$Q$211*100),2)&"%" -> Upside (Downside): -47,9%
U14: =+Industry!E28&", "&ESG!C9 -> , Semiconductor & Semiconductor components
U15: =+ESG!C10 -> Information technology
D17: Operating Metrics | F17: 2023 | G17: =+F17+1 -> 2024 | H17: =+G17+1 -> 2025 | I17: =+H17+1 -> 2026 | K17: Valuation Multiples | N17: 2022 | O17: =+N17+1 -> 2023 | P17: =+O17+1 -> 2024 | Q17: =+P17+1 -> 2025 | R17: =+Q17+1 -> 2026 | U17: Team Leader
K18: EV / Sales | N18: =IFERROR(_xlfn.XLOOKUP($K18,Multiples!$B:$B,Multiples!N:N),"") -> 7.5092738 | O18: =IFERROR(_xlfn.XLOOKUP($K18,Multiples!$B:$B,Multiples!O:O),"") -> 8.5902671 | P18: =IFERROR(_xlfn.XLOOKUP($K18,Multiples!$B:$B,Multiples!P:P),"") -> 11.736375 | Q18: =IFERROR(_xlfn.XLOOKUP($K18,Multiples!$B:$B,Multiples!Q:Q),"") -> 6.2024187 | R18: =IFERROR(_xlfn.XLOOKUP($K18,Multiples!$B:$B,Multiples!R:R),"") -> 5.625376 | U18: email
K19: Price / Sales | N19: =IFERROR(_xlfn.XLOOKUP($K19,Multiples!$B:$B,Multiples!N:N),"") -> 7.0866003 | O19: =IFERROR(_xlfn.XLOOKUP($K19,Multiples!$B:$B,Multiples!O:O),"") -> 8.103436 | P19: =IFERROR(_xlfn.XLOOKUP($K19,Multiples!$B:$B,Multiples!P:P),"") -> 11.182817 | Q19: =IFERROR(_xlfn.XLOOKUP($K19,Multiples!$B:$B,Multiples!Q:Q),"") | R19: =IFERROR(_xlfn.XLOOKUP($K19,Multiples!$B:$B,Multiples!R:R),"") | U19: (+351) 999 999 999
K20: EV / EBITDA | N20: =IFERROR(_xlfn.XLOOKUP($K20,Multiples!$B:$B,Multiples!N:N),"") -> 19.759169 | O20: =IFERROR(_xlfn.XLOOKUP($K20,Multiples!$B:$B,Multiples!O:O),"") -> 21.383568 | P20: =IFERROR(_xlfn.XLOOKUP($K20,Multiples!$B:$B,Multiples!P:P),"") -> 39.166396 | Q20: =IFERROR(_xlfn.XLOOKUP($K20,Multiples!$B:$B,Multiples!Q:Q),"") -> 17.89259 | R20: =IFERROR(_xlfn.XLOOKUP($K20,Multiples!$B:$B,Multiples!R:R),"") -> 15.997209 | U20: Analyst 1
K21: EV / EBIT | N21: =IFERROR(_xlfn.XLOOKUP($K21,Multiples!$B:$B,Multiples!N:N),"") -> 39.7727 | O21: =IFERROR(_xlfn.XLOOKUP($K21,Multiples!$B:$B,Multiples!O:O),"") -> 39.885119 | P21: =IFERROR(_xlfn.XLOOKUP($K21,Multiples!$B:$B,Multiples!P:P),"") -> 153.54032 | Q21: =IFERROR(_xlfn.XLOOKUP($K21,Multiples!$B:$B,Multiples!Q:Q),"") -> 40.042324 | R21: =IFERROR(_xlfn.XLOOKUP($K21,Multiples!$B:$B,Multiples!R:R),"") -> 31.014882 | U21: email
K22: Price / Earnings | N22: =IFERROR(_xlfn.XLOOKUP($K22,Multiples!$B:$B,Multiples!N:N),"") -> 42.893051 | O22: =IFERROR(_xlfn.XLOOKUP($K22,Multiples!$B:$B,Multiples!O:O),"") -> 41.431291 | P22: =IFERROR(_xlfn.XLOOKUP($K22,Multiples!$B:$B,Multiples!P:P),"") -> 163.62355 | Q22: =IFERROR(_xlfn.XLOOKUP($K22,Multiples!$B:$B,Multiples!Q:Q),"") | R22: =IFERROR(_xlfn.XLOOKUP($K22,Multiples!$B:$B,Multiples!R:R),"") | U22: (+351) 999 999 999
K23: Price / Book | N23: =IFERROR(_xlfn.XLOOKUP($K23,Multiples!$B:$B,Multiples!N:N),"") -> 2.334779 | O23: =IFERROR(_xlfn.XLOOKUP($K23,Multiples!$B:$B,Multiples!O:O),"") -> 2.8037833 | P23: =IFERROR(_xlfn.XLOOKUP($K23,Multiples!$B:$B,Multiples!P:P),"") -> 2.9969796 | Q23: =IFERROR(_xlfn.XLOOKUP($K23,Multiples!$B:$B,Multiples!Q:Q),"") | R23: =IFERROR(_xlfn.XLOOKUP($K23,Multiples!$B:$B,Multiples!R:R),"") | U23: Analyst 2
U24: email
D25: Year | E25: Net Sales | F25: EBIT Margin | G25: FCFF | H25: =+IF(Summary!$G$25="FCFF",DCF!AB6,IF(Summary!$G$25="FCFE",DCF!AC6,DCF!AD6)) -> NOPAT | I25: Net Capex | K25: Profitability Ratios | N25: 2022 | O25: =+N25+1 -> 2023 | P25: =+O25+1 -> 2024 | Q25: =+P25+1 -> 2025 | R25: =+Q25+1 -> 2026 | U25: (+351) 999 999 999
D26: 2022 | E26: =+DCF!E30 -> 12014 | F26: =+DCF!E60 -> 0.18880473 | G26: =+INDEX(DCF!X7:AA7,MATCH(Summary!$G$25,{"FCFF","FCFE","Tax Shield","Total Payout"},0)) -> 3743.8181 | H26: =+IF(Summary!$G$25="FCFF",DCF!AB7,IF(Summary!$G$25="FCFE",DCF!AC7,DCF!AD7)) -> 1928.1181 | I26: =+DCF!E134 -> -699 | K26: Return on Assets | N26: =IFERROR(_xlfn.XLOOKUP($K26,Multiples!$B:$B,Multiples!N:N),"") -> 0.03945935 | O26: =IFERROR(_xlfn.XLOOKUP($K26,Multiples!$B:$B,Multiples!O:O),"") -> 0.049325231 | P26: =IFERROR(_xlfn.XLOOKUP($K26,Multiples!$B:$B,Multiples!P:P),"") -> 0.013359376 | Q26: =IFERROR(_xlfn.XLOOKUP($K26,Multiples!$B:$B,Multiples!Q:Q),"") -> 0.026078652 | R26: =IFERROR(_xlfn.XLOOKUP($K26,Multiples!$B:$B,Multiples!R:R),"") -> 0.034349512 | U26: Analyst 3
D27: =+D26+1 -> 2023 | E27: =+DCF!F30 -> 12305.5 | F27: =+DCF!F60 -> 0.21537524 | G27: =+INDEX(DCF!X8:AA8,MATCH(Summary!$G$25,{"FCFF","FCFE","Tax Shield","Total Payout"},0)) -> 3404.7221 | H27: =+IF(Summary!$G$25="FCFF",DCF!AB8,IF(Summary!$G$25="FCFE",DCF!AC8,DCF!AD8)) -> 2362.3221 | I27: =+DCF!F134 -> -1261 | K27: Return on Equity | N27: =IFERROR(_xlfn.XLOOKUP($K27,Multiples!$B:$B,Multiples!N:N),"") -> 0.05443257 | O27: =IFERROR(_xlfn.XLOOKUP($K27,Multiples!$B:$B,Multiples!O:O),"") -> 0.067673084 | P27: =IFERROR(_xlfn.XLOOKUP($K27,Multiples!$B:$B,Multiples!P:P),"") -> 0.01831631 | Q27: =IFERROR(_xlfn.XLOOKUP($K27,Multiples!$B:$B,Multiples!Q:Q),"") | R27: =IFERROR(_xlfn.XLOOKUP($K27,Multiples!$B:$B,Multiples!R:R),"") | U27: email
D28: =+D27+1 -> 2024 | E28: =+DCF!G30 -> 9427.2 | F28: =+DCF!G60 -> 0.076438391 | G28: =+INDEX(DCF!X9:AA9,MATCH(Summary!$G$25,{"FCFF","FCFE","Tax Shield","Total Payout"},0)) -> 2284.4899 | H28: =+IF(Summary!$G$25="FCFF",DCF!AB9,IF(Summary!$G$25="FCFE",DCF!AC9,DCF!AD9)) -> 590.38985 | I28: =+DCF!G134 -> -730 | K28: Return on Total Capital | N28: =IFERROR(_xlfn.XLOOKUP($K28,Multiples!$B:$B,Multiples!N:N),"") -> 0.044825467 | O28: =IFERROR(_xlfn.XLOOKUP($K28,Multiples!$B:$B,Multiples!O:O),"") -> 0.055565875 | P28: =IFERROR(_xlfn.XLOOKUP($K28,Multiples!$B:$B,Multiples!P:P),"") -> 0.013807737 | Q28: =IFERROR(_xlfn.XLOOKUP($K28,Multiples!$B:$B,Multiples!Q:Q),"") | R28: =IFERROR(_xlfn.XLOOKUP($K28,Multiples!$B:$B,Multiples!R:R),"") | U28: (+351) 999 999 999
D29: =+D28+1 -> 2025 | E29: =+DCF!H30 -> 10336 | F29: =+DCF!H60 -> 0.15489657 | G29: =+INDEX(DCF!X10:AA10,MATCH(Summary!$G$25,{"FCFF","FCFE","Tax Shield","Total Payout"},0)) -> 3929.6086 | H29: =+IF(Summary!$G$25="FCFF",DCF!AB10,IF(Summary!$G$25="FCFE",DCF!AC10,DCF!AD10)) -> 1366.5525 | I29: =+DCF!H134 -> 0 | K29: EBITDA Margin | N29: =IFERROR(_xlfn.XLOOKUP($K29,Multiples!$B:$B,Multiples!N:N),"") -> 0.38003995 | O29: =IFERROR(_xlfn.XLOOKUP($K29,Multiples!$B:$B,Multiples!O:O),"") -> 0.40172281 | P29: =IFERROR(_xlfn.XLOOKUP($K29,Multiples!$B:$B,Multiples!P:P),"") -> 0.29965419 | Q29: =IFERROR(_xlfn.XLOOKUP($K29,Multiples!$B:$B,Multiples!Q:Q),"") -> 0.34664735 | R29: =IFERROR(_xlfn.XLOOKUP($K29,Multiples!$B:$B,Multiples!R:R),"") -> 0.35164735
D30: =+D29+1 -> 2026 | E30: =+DCF!I30 -> 11641.437 | F30: =+DCF!I60 -> 0.18137667 | G30: =+INDEX(DCF!X11:AA11,MATCH(Summary!$G$25,{"FCFF","FCFE","Tax Shield","Total Payout"},0)) -> 3827.6097 | H30: =+IF(Summary!$G$25="FCFF",DCF!AB11,IF(Summary!$G$25="FCFE",DCF!AC11,DCF!AD11)) -> 1804.7549 | I30: =+DCF!I134 -> 0 | K30: EBIT Margin | N30: =IFERROR(_xlfn.XLOOKUP($K30,Multiples!$B:$B,Multiples!N:N),"") -> 0.18880473 | O30: =IFERROR(_xlfn.XLOOKUP($K30,Multiples!$B:$B,Multiples!O:O),"") -> 0.21537524 | P30: =IFERROR(_xlfn.XLOOKUP($K30,Multiples!$B:$B,Multiples!P:P),"") -> 0.076438391 | Q30: =IFERROR(_xlfn.XLOOKUP($K30,Multiples!$B:$B,Multiples!Q:Q),"") -> 0.15489657 | R30: =IFERROR(_xlfn.XLOOKUP($K30,Multiples!$B:$B,Multiples!R:R),"") -> 0.18137667 | U30: Statistics
D31: =+D30+1 -> 2027 | E31: =+DCF!J30 -> 12772.984 | F31: =+DCF!J60 -> 0.19836328 | G31: =+INDEX(DCF!X12:AA12,MATCH(Summary!$G$25,{"FCFF","FCFE","Tax Shield","Total Payout"},0)) -> 4273.3142 | H31: =+IF(Summary!$G$25="FCFF",DCF!AB12,IF(Summary!$G$25="FCFE",DCF!AC12,DCF!AD12)) -> 2134.7109 | I31: =+DCF!J134 -> 0 | K31: Gross Profit Margin | N31: =IFERROR(_xlfn.XLOOKUP($K31,Multiples!$B:$B,Multiples!N:N),"") -> 0.62697686 | O31: =IFERROR(_xlfn.XLOOKUP($K31,Multiples!$B:$B,Multiples!O:O),"") -> 0.64013652 | P31: =IFERROR(_xlfn.XLOOKUP($K31,Multiples!$B:$B,Multiples!P:P),"") -> 0.57083758 | Q31: =IFERROR(_xlfn.XLOOKUP($K31,Multiples!$B:$B,Multiples!Q:Q),"") -> 0.62 | R31: =IFERROR(_xlfn.XLOOKUP($K31,Multiples!$B:$B,Multiples!R:R),"") -> 0.625 | U31: Beta | V31: =Peers!D74 -> 1.0961
D32: =+D31+1 -> 2028 | E32: =+DCF!K30 -> 13232.812 | F32: =+DCF!K60 -> 0.21058883 | G32: =+INDEX(DCF!X13:AA13,MATCH(Summary!$G$25,{"FCFF","FCFE","Tax Shield","Total Payout"},0)) -> 4670.9362 | H32: =+IF(Summary!$G$25="FCFF",DCF!AB13,IF(Summary!$G$25="FCFE",DCF!AC13,DCF!AD13)) -> 2369.4404 | I32: =+DCF!K134 -> 0 | K32: SG&A Margin | N32: =IFERROR(_xlfn.XLOOKUP($K32,Multiples!$B:$B,Multiples!N:N),"") -> 0.10539371 | O32: =IFERROR(_xlfn.XLOOKUP($K32,Multiples!$B:$B,Multiples!O:O),"") -> 0.10349844 | P32: =IFERROR(_xlfn.XLOOKUP($K32,Multiples!$B:$B,Multiples!P:P),"") -> 0.11335285 | Q32: =IFERROR(_xlfn.XLOOKUP($K32,Multiples!$B:$B,Multiples!Q:Q),"") -> 0.107415 | R32: =IFERROR(_xlfn.XLOOKUP($K32,Multiples!$B:$B,Multiples!R:R),"") -> 0.10808876 | U32: % Float | V32: =+Peers!D73 -> 0
D33: =+D32+1 -> 2029 | E33: =+DCF!L30 -> 13709.193 | F33: =+DCF!L60 -> 0.24093974 | G33: =+INDEX(DCF!X14:AA14,MATCH(Summary!$G$25,{"FCFF","FCFE","Tax Shield","Total Payout"},0)) -> 4757.8869 | H33: =+IF(Summary!$G$25="FCFF",DCF!AB14,IF(Summary!$G$25="FCFE",DCF!AC14,DCF!AD14)) -> 2804.9124 | I33: =+DCF!L134 -> 0 | K33: Net Income Margin | N33: =IFERROR(_xlfn.XLOOKUP($K33,Multiples!$B:$B,Multiples!N:N),"") -> 0.16521558 | O33: =IFERROR(_xlfn.XLOOKUP($K33,Multiples!$B:$B,Multiples!O:O),"") -> 0.19558734 | P33: =IFERROR(_xlfn.XLOOKUP($K33,Multiples!$B:$B,Multiples!P:P),"") -> 0.06834479 | Q33: =IFERROR(_xlfn.XLOOKUP($K33,Multiples!$B:$B,Multiples!Q:Q),"") -> 0.13255964 | R33: =IFERROR(_xlfn.XLOOKUP($K33,Multiples!$B:$B,Multiples!R:R),"") -> 0.15502176 | U33: % Held by Insiders | V33: =+Peers!D76 -> 0
U34: % Held by Institutions | V34: =+Peers!D77 -> 0
D35: SWOT Analysis | K35: Liquidity Ratios | N35: 2022 | O35: =+N35+1 -> 2023 | P35: =+O35+1 -> 2024 | Q35: =+P35+1 -> 2025 | R35: =+Q35+1 -> 2026 | U35: Short % of Float | V35: =+Peers!D78 -> 0
D36: Strengths | G36: Weaknesses | K36: Cash Ratio | N36: =IFERROR(_xlfn.XLOOKUP($K36,Multiples!$B:$B,Multiples!N:N),"") -> 0.60203873 | O36: =IFERROR(_xlfn.XLOOKUP($K36,Multiples!$B:$B,Multiples!O:O),"") -> 0.29931271 | P36: =IFERROR(_xlfn.XLOOKUP($K36,Multiples!$B:$B,Multiples!P:P),"") -> 0.66636549 | Q36: =IFERROR(_xlfn.XLOOKUP($K36,Multiples!$B:$B,Multiples!Q:Q),"") -> 2.0464792 | R36: =IFERROR(_xlfn.XLOOKUP($K36,Multiples!$B:$B,Multiples!R:R),"") -> 3.566234 | W36: 120.87
K37: Quick Ratio | N37: =IFERROR(_xlfn.XLOOKUP($K37,Multiples!$B:$B,Multiples!N:N),"") -> 1.3391329 | O37: =IFERROR(_xlfn.XLOOKUP($K37,Multiples!$B:$B,Multiples!O:O),"") -> 0.75845048 | P37: =IFERROR(_xlfn.XLOOKUP($K37,Multiples!$B:$B,Multiples!P:P),"") -> 1.2379614 | Q37: =IFERROR(_xlfn.XLOOKUP($K37,Multiples!$B:$B,Multiples!Q:Q),"") -> 2.5926227 | R37: =IFERROR(_xlfn.XLOOKUP($K37,Multiples!$B:$B,Multiples!R:R),"") -> 4.1519566 | U37: Major Holders | W37: 113.63
K38: Current Ratio | N38: =IFERROR(_xlfn.XLOOKUP($K38,Multiples!$B:$B,Multiples!N:N),"") -> 2.0215335 | O38: =IFERROR(_xlfn.XLOOKUP($K38,Multiples!$B:$B,Multiples!O:O),"") -> 1.369572 | P38: =IFERROR(_xlfn.XLOOKUP($K38,Multiples!$B:$B,Multiples!P:P),"") -> 1.8353914 | Q38: =IFERROR(_xlfn.XLOOKUP($K38,Multiples!$B:$B,Multiples!Q:Q),"") -> 3.1110933 | R38: =IFERROR(_xlfn.XLOOKUP($K38,Multiples!$B:$B,Multiples!R:R),"") -> 3.1110933
D40: Opportunities | G40: Threats | K40: Cash Flow Ratios | N40: 2022 | O40: =+N40+1 -> 2023 | P40: =+O40+1 -> 2024 | Q40: =+P40+1 -> 2025 | R40: =+Q40+1 -> 2026
K41: Cash Conversion Cycle | N41: =IFERROR(_xlfn.XLOOKUP($K41,Multiples!$B:$B,Multiples!N:N),"") -> 151.02962 | O41: =IFERROR(_xlfn.XLOOKUP($K41,Multiples!$B:$B,Multiples!O:O),"") -> 164.32778 | P41: =IFERROR(_xlfn.XLOOKUP($K41,Multiples!$B:$B,Multiples!P:P),"") -> 163.4708 | Q41: =IFERROR(_xlfn.XLOOKUP($K41,Multiples!$B:$B,Multiples!Q:Q),"") -> 132.6672 | R41: =IFERROR(_xlfn.XLOOKUP($K41,Multiples!$B:$B,Multiples!R:R),"") -> 136.45635
K42: Net Income / Op Cash Flow | N42: =IFERROR(_xlfn.XLOOKUP($K42,Multiples!$B:$B,Multiples!N:N),"") -> 0.44351343 | O42: =IFERROR(_xlfn.XLOOKUP($K42,Multiples!$B:$B,Multiples!O:O),"") -> 0.49958486 | P42: =IFERROR(_xlfn.XLOOKUP($K42,Multiples!$B:$B,Multiples!P:P),"") -> 0.16724205 | Q42: =IFERROR(_xlfn.XLOOKUP($K42,Multiples!$B:$B,Multiples!Q:Q),"") -> 0.32237277 | R42: =IFERROR(_xlfn.XLOOKUP($K42,Multiples!$B:$B,Multiples!R:R),"") -> 0.4215321
K43: Chg in Cash / Op Cash Flow | N43: =IFERROR(_xlfn.XLOOKUP($K43,Multiples!$B:$B,Multiples!N:N),"") -> -0.11337534 | O43: =IFERROR(_xlfn.XLOOKUP($K43,Multiples!$B:$B,Multiples!O:O),"") -> -0.10638077 | P43: =IFERROR(_xlfn.XLOOKUP($K43,Multiples!$B:$B,Multiples!P:P),"") -> 0.26821544 | Q43: =IFERROR(_xlfn.XLOOKUP($K43,Multiples!$B:$B,Multiples!Q:Q),"") -> 1.1090482 | R43: =IFERROR(_xlfn.XLOOKUP($K43,Multiples!$B:$B,Multiples!R:R),"") -> 1.1630332
D45: Revenue by Region | G45: Revenue by Segment | K45: Leverage Ratios | N45: 2022 | O45: =+N45+1 -> 2023 | P45: =+O45+1 -> 2024 | Q45: =+P45+1 -> 2025 | R45: =+Q45+1 -> 2026
K46: Total Debt / Equity | N46: =IFERROR(_xlfn.XLOOKUP($K46,Multiples!$B:$B,Multiples!N:N),"") -> 179.58443 | O46: =IFERROR(_xlfn.XLOOKUP($K46,Multiples!$B:$B,Multiples!O:O),"") -> 195.38255 | P46: =IFERROR(_xlfn.XLOOKUP($K46,Multiples!$B:$B,Multiples!P:P),"") -> 215.53148 | Q46: =IFERROR(_xlfn.XLOOKUP($K46,Multiples!$B:$B,Multiples!Q:Q),"") | R46: =IFERROR(_xlfn.XLOOKUP($K46,Multiples!$B:$B,Multiples!R:R),"")
K47: Total Debt / Capital | N47: =IFERROR(_xlfn.XLOOKUP($K47,Multiples!$B:$B,Multiples!N:N),"") -> 0.99446242 | O47: =IFERROR(_xlfn.XLOOKUP($K47,Multiples!$B:$B,Multiples!O:O),"") -> 0.9949079 | P47: =IFERROR(_xlfn.XLOOKUP($K47,Multiples!$B:$B,Multiples!P:P),"") -> 0.99538173 | Q47: =IFERROR(_xlfn.XLOOKUP($K47,Multiples!$B:$B,Multiples!Q:Q),"") | R47: =IFERROR(_xlfn.XLOOKUP($K47,Multiples!$B:$B,Multiples!R:R),"")
K48: Total Liabilities / Total Assets | N48: =IFERROR(_xlfn.XLOOKUP($K48,Multiples!$B:$B,Multiples!N:N),"") -> 0.27507833 | O48: =IFERROR(_xlfn.XLOOKUP($K48,Multiples!$B:$B,Multiples!O:O),"") -> 0.27112482 | P48: =IFERROR(_xlfn.XLOOKUP($K48,Multiples!$B:$B,Multiples!P:P),"") -> 0.27062949 | Q48: =IFERROR(_xlfn.XLOOKUP($K48,Multiples!$B:$B,Multiples!Q:Q),"") | R48: =IFERROR(_xlfn.XLOOKUP($K48,Multiples!$B:$B,Multiples!R:R),"")
K49: Total Debt / EBITDA | N49: =IFERROR(_xlfn.XLOOKUP($K49,Multiples!$B:$B,Multiples!N:N),"") -> 1.4342722 | O49: =IFERROR(_xlfn.XLOOKUP($K49,Multiples!$B:$B,Multiples!O:O),"") -> 1.4056722 | P49: =IFERROR(_xlfn.XLOOKUP($K49,Multiples!$B:$B,Multiples!P:P),"") -> 2.6838472 | Q49: =IFERROR(_xlfn.XLOOKUP($K49,Multiples!$B:$B,Multiples!Q:Q),"") | R49: =IFERROR(_xlfn.XLOOKUP($K49,Multiples!$B:$B,Multiples!R:R),"") | U49: Board of Directors
...

Sheet Segments
B2: Segments
B4: Regions | D4: Weight | E4: 2020 | F4: =+E4+1 -> 2021 | G4: =+F4+1 -> 2022 | H4: =+G4+1 -> 2023 | I4: =+H4+1 -> 2024 | J4: ="CAGR "&$G$4&" - "&$I$4 -> CAGR 2022 - 2024 | K4: 2021 | L4: =+K4+1 -> 2022 | M4: =+L4+1 -> 2023 | N4: =+M4+1 -> 2024
B6: China | D6: =IFERROR(I6/SUM($I$6:$I$12),"") -> 0.22581945 | E6: 1348 | F6: 1614.4 | G6: 2563.5 | H6: 2229.6 | I6: 2128.8 | J6: =IFERROR((I6/G6)^(1/COUNT($G$4:$I$4))-1,"") -> -0.060059174 | K6: =IFERROR(F6-E6/E6,"") -> 1613.4 | L6: =IFERROR(G6-F6/F6,"") -> 2562.5 | M6: =IFERROR((H6-G6)/G6,"") -> -0.13025161 | N6: =IFERROR((I6-H6)/H6,"") -> -0.045209903
B7: Europe | D7: =IFERROR(I7/SUM($I$6:$I$12),"") -> 0.22377214 | E7: 1245.7 | F7: 1593 | G7: 2534.4 | H7: 3001.9 | I7: 2109.5 | J7: =IFERROR((I7/G7)^(1/COUNT($G$4:$I$4))-1,"") -> -0.059335423 | K7: =IFERROR(F7-E7/E7,"") -> 1592 | L7: =IFERROR(G7-F7/F7,"") -> 2533.4 | M7: =IFERROR((H7-G7)/G7,"") -> 0.18446181 | N7: =IFERROR((I7-H7)/H7,"") -> -0.29727839
B8: Rest of Asia | D8: =IFERROR(I8/SUM($I$6:$I$12),"") -> 0.12733637 | E8: 558.9 | F8: 890.7 | G8: 1596.6 | H8: 1423 | I8: 1200.4 | J8: =IFERROR((I8/E8)^(1/COUNT($E$4:$I$4))-1,"") -> 0.16519436 | K8: =IFERROR(F8-E8/E8,"") -> 889.7 | L8: =IFERROR(G8-F8/F8,"") -> 1595.6 | M8: =IFERROR(H8-G8/G8,"") -> 1422 | N8: =IFERROR((I8-H8)/H8,"") -> -0.15643008
B9: Japan | D9: =IFERROR(I9/SUM($I$6:$I$12),"") -> 0.11515859 | E9: 521.7 | F9: 788 | G9: 1221.5 | H9: 1397.1 | I9: 1085.6 | J9: =IFERROR((I9/E9)^(1/COUNT($E$4:$I$4))-1,"") -> 0.15784333 | K9: =IFERROR(F9-E9/E9,"") -> 787 | L9: =IFERROR(G9-F9/F9,"") -> 1220.5 | M9: =IFERROR(H9-G9/G9,"") -> 1396.1 | N9: =IFERROR((I9-H9)/H9,"") -> -0.22296185
B10: Rest of North & South America | D10: =IFERROR(I10/SUM($I$6:$I$12),"") -> 0.0066086772 | E10: 41.3 | F10: 42.8 | G10: 72.5 | H10: 88.6 | I10: 62.3 | J10: =IFERROR((I10/E10)^(1/COUNT($E$4:$I$4))-1,"") -> 0.085694403 | K10: =IFERROR(F10-E10/E10,"") -> 41.8 | L10: =IFERROR(G10-F10/F10,"") -> 71.5 | M10: =IFERROR(H10-G10/G10,"") -> 87.6 | N10: =IFERROR((I10-H10)/H10,"") -> -0.29683973
B11: United States | D11: =IFERROR(I11/SUM($I$6:$I$12),"") -> 0.30130476 | E11: 1887.4 | F11: 2389.4 | G11: 4025.4 | H11: 4165.3 | I11: 2840.4 | J11: =IFERROR((I11/E11)^(1/COUNT($E$4:$I$4))-1,"") -> 0.085183322 | K11: =IFERROR(F11-E11/E11,"") -> 2388.4 | L11: =IFERROR(G11-F11/F11,"") -> 4024.4 | M11: =IFERROR(H11-G11/G11,"") -> 4164.3 | N11: =IFERROR((I11-H11)/H11,"") -> -0.31808033
D12: =IFERROR(I12/SUM($I$6:$I$12),"") -> 0
B13: Total | D13: =SUM(D6:D12) -> 1 | E13: =SUM(E6:E10) -> 3715.6 | F13: =SUM(F6:F10) -> 4928.9 | G13: =SUM(G6:G10) -> 7988.5 | H13: =SUM(H6:H10) -> 8140.2 | I13: =SUM(I6:I10) -> 6586.6 | J13: =IFERROR((I13/G13)^(1/COUNT($G$4:$I$4))-1,"") -> -0.062296904 | K13: =IFERROR(F13-E13/E13,"") -> 4927.9 | L13: =IFERROR(G13-F13/F13,"") -> 7987.5 | M13: =IFERROR((H13-G13)/G13,"") -> 0.018989798 | N13: =IFERROR((I13-H13)/H13,"") -> -0.19085526
B15: Segments | D15: Weight | E15: 2020 | F15: =+E15+1 -> 2021 | G15: =+F15+1 -> 2022 | H15: =+G15+1 -> 2023 | I15: =+H15+1 -> 2024 | J15: ="CAGR "&$E$4&" - "&$I$4 -> CAGR 2020 - 2024 | K15: 2021 | L15: =+K15+1 -> 2022 | M15: =+L15+1 -> 2023 | N15: =+M15+1 -> 2024
B17: Industrial | D17: =IFERROR(I17/SUM($I$17:$I$21),"") -> 0.45764869 | E17: 2998.3 | F17: 4026.9 | G17: 6069.3 | H17: 6555.2 | I17: 4314.3 | J17: =IFERROR((I17/E17)^(1/COUNT($E$4:$I$4))-1,"") -> 0.075491671 | K17: =IFERROR((F17-E17)/E17,"") -> 0.34306107 | L17: =IFERROR((G17-F17)/F17,"") -> 0.50718915 | M17: =IFERROR((H17-G17)/G17,"") -> 0.080058656 | N17: =IFERROR((I17-H17)/H17,"") -> -0.34185074
B18: Communications | D18: =IFERROR(I18/SUM($I$17:$I$21),"") -> 0.11461637 | E18: 1191.2 | F18: 1206.9 | G18: 1880.7 | H18: 1619.5 | I18: 1080.5 | J18: =IFERROR((I18/E18)^(1/COUNT($E$4:$I$4))-1,"") -> -0.019318422 | K18: =IFERROR((F18-E18)/E18,"") -> 0.013179987 | L18: =IFERROR((G18-F18)/F18,"") -> 0.55828983 | M18: =IFERROR((H18-G18)/G18,"") -> -0.13888446 | N18: =IFERROR((I18-H18)/H18,"") -> -0.33281877
B19: Consumer | D19: =IFERROR(I19/SUM($I$17:$I$21),"") -> 0.12781237 | E19: 635.3 | F19: 836.3 | G19: 1548.4 | H19: 1215.6 | I19: 1204.9 | J19: =IFERROR((I19/E19)^(1/COUNT($E$4:$I$4))-1,"") -> 0.1365654 | K19: =IFERROR((F19-E19)/E19,"") -> 0.31638596 | L19: =IFERROR((G19-F19)/F19,"") -> 0.8514887 | M19: =IFERROR((H19-G19)/G19,"") -> -0.21493154 | N19: =IFERROR((I19-H19)/H19,"") -> -0.0088022376
B20: Automotive | D20: =IFERROR(I20/SUM($I$17:$I$21),"") -> 0.29992256 | E20: 778.3 | F20: 1248.2 | G20: 2515.5 | H20: 2915.2 | I20: 2827.4 | J20: =IFERROR((I20/E20)^(1/COUNT($E$4:$I$4))-1,"") -> 0.29433902 | K20: =IFERROR((F20-E20)/E20,"") -> 0.60375177 | L20: =IFERROR((G20-F20)/F20,"") -> 1.015302 | M20: =IFERROR((H20-G20)/G20,"") -> 0.15889485 | N20: =IFERROR((I20-H20)/H20,"") -> -0.030118002
D21: =IFERROR(I21/SUM($I$17:$I$21),"") -> 0 | J21: =IFERROR((I21/E21)^(1/COUNT($E$4:$I$4))-1,"") | K21: =IFERROR((F21-E21)/E21,"") | L21: =IFERROR((G21-F21)/F21,"") | M21: =IFERROR((H21-G21)/G21,"") | N21: =IFERROR((I21-H21)/H21,"")
B22: Total | D22: =SUM(D17:D21) -> 1 | E22: =SUM(E17:E21) -> 5603.1 | F22: =SUM(F17:F21) -> 7318.3 | G22: =SUM(G17:G21) -> 12013.9 | H22: =SUM(H17:H21) -> 12305.5 | I22: =SUM(I17:I21) -> 9427.1 | J22: =IFERROR((I22/E22)^(1/COUNT($E$4:$I$4))-1,"") -> 0.10966004 | K22: =IFERROR((F22-E22)/E22,"") -> 0.30611626 | L22: =IFERROR((G22-F22)/F22,"") -> 0.64162442 | M22: =IFERROR((H22-G22)/G22,"") -> 0.024271885 | N22: =IFERROR((I22-H22)/H22,"") -> -0.23391167
B24: Categories | D24: Description | J24: Graphs
B26: Industrial | D26: Factory automation, energy systems, healthcare instrumentation.
B27: Automotive | D27: Advanced driver-assistance systems (ADAS), infotainment, vehicle electrification.
B28: Consumer | D28: Smartphones, wearable devices, smart home applications.
B29: =IF(B20=0,"",B20) -> Automotive
B30: =IF(B21=0,"",B21)

Sheet Industry
B2: Industry Overview
B4: Sales Growth Forecast | E4: Weight | F4: 2025 | G4: =+F4+1 -> 2026 | H4: =+G4+1 -> 2027 | I4: =+H4+1 -> 2028 | J4: =+I4+1 -> 2029 | K4: =+J4+1 -> 2030 | L4: =+K4+1 -> 2031 | M4: =+L4+1 -> 2032 | N4: =+M4+1 -> 2033 | ... P4: =+O4+1 -> 2035 | Q4: ="CAGR "&$F$4&" - "&$P$4 -> CAGR 2025 - 2035 | R4: Sources
B11: Weighted Average | E11: =SUM(E6:E10) -> 0 | F11: =SUMPRODUCT(F6:F10,$E$6:$E$10) -> 0 | G11: =SUMPRODUCT(G6:G10,$E$6:$E$10) -> 0 | H11: =SUMPRODUCT(H6:H10,$E$6:$E$10) -> 0 | I11: =SUMPRODUCT(I6:I10,$E$6:$E$10) -> 0 | J11: =SUMPRODUCT(J6:J10,$E$6:$E$10) -> 0 | K11: =SUMPRODUCT(K6:K10,$E$6:$E$10) -> 0 | L11: =SUMPRODUCT(L6:L10,$E$6:$E$10) -> 0 | M11: =SUMPRODUCT(M6:M10,$E$6:$E$10) -> 0 | ... P11: =SUMPRODUCT(P6:P10,$E$6:$E$10) -> 0 | Q11: =IFERROR(((1+F11)*(1+G11)*(1+H11)*(1+I11)*(1+J11)*(1+K11)*(1+L11)*(1+M11)*(1+N11)*(1+O11)*(1+P11))^(1/COUNT($F$4:$P$4))-1,"") -> 0
B13: Key Drivers | E13: Description
B15: Recovery in Industrial and Automotive Demand | E15: After a period of inventory corrections, demand in the industrial and automotive sectors is rebounding. Analog Devices is experiencing sequential growth in these markets, positioning the company to benefit from a multi-year semiconductor upcycle.
B16: Expansion in Consumer Electronics | E16: The consumer segment has shown robust growth, driven by increased demand for AI-driven devices, premium smartphones, and smart home products. In Q1 2025, Analog Devices' consumer segment revenue rose by 19%, highlighting the company's strength in this area.
B17: Advancements in AI and IoT Applications | E17: The proliferation of AI and IoT technologies is increasing the demand for analog and mixed-signal solutions. ADI's portfolio is well-suited to support these applications, providing opportunities for growth in various end markets.
B18: Strategic Acquisitions Enhancing Product Portfolio | E18: ADI's acquisitions, such as Maxim Integrated, have expanded its product offerings and market reach, particularly in power management and signal conditioning, strengthening its position in the analog semiconductor market.
B20: Industry Trends | E20: Description
B22: Growth in Analog Semiconductor Market | E22: The analog semiconductor market is projected to grow significantly, with an estimated increase of USD 35.1 billion from 2025 to 2029, at a CAGR of 6.9%. This growth is driven by demand across automotive, industrial, and consumer electronics sectors.
B23: Integration of AI in Edge Devices | E23: The integration of AI capabilities into edge devices, such as smartphones and IoT gadgets, is transforming the semiconductor landscape. This trend necessitates advanced analog solutions for efficient processing, an area where ADI is actively involve
B26: Market Share | E26: Headquarters | G26: Revenues | H26: (in MM of USD) | I26: Market Share
B28: {=+_FV(DCF!R4,"Name")} -> ANALOG DEVICES, INC. | G28: {=TRANSPOSE(Peers!D97:N97)} -> 9427.2 | I28: =IFERROR(G28/$G$40,"") -> 0.10059972
B29: {=+_FV(Peers!A8,"Name")} -> TEXAS INSTRUMENTS INCORPORATED | G29: 15641 | I29: =IFERROR(G29/$G$40,"") -> 0.16690855
B30: {=+_FV(Peers!A9,"Name")} -> MICROCHIP TECHNOLOGY INCORPORATED | G30: 7634.4 | I30: =IFERROR(G30/$G$40,"") -> 0.08146836
B31: {=+_FV(Peers!A10,"Name")} -> MONOLITHIC POWER SYSTEMS, INC. | G31: 2207.1 | I31: =IFERROR(G31/$G$40,"") -> 0.023552449
B32: {=+_FV(Peers!A11,"Name")} -> SKYWORKS SOLUTIONS, INC. | G32: 4178 | I32: =IFERROR(G32/$G$40,"") -> 0.044584356
B33: {=+_FV(Peers!A12,"Name")} -> MACOM TECHNOLOGY SOLUTIONS HOLDINGS, INC. | G33: 729.578 | I33: =IFERROR(G33/$G$40,"") -> 0.0077854871
B34: {=+_FV(Peers!A13,"Name")} -> MARVELL TECHNOLOGY, INC. | G34: 5508 | I34: =IFERROR(G34/$G$40,"") -> 0.058777078
B35: {=+_FV(Peers!A14,"Name")} -> #VALUE! | G35: 0 | I35: =IFERROR(G35/$G$40,"") -> 0
B36: {=+_FV(Peers!A15,"Name")} -> #VALUE! | G36: 0 | I36: =IFERROR(G36/$G$40,"") -> 0
B37: {=+_FV(Peers!A16,"Name")} -> #VALUE! | G37: 0 | I37: =IFERROR(G37/$G$40,"") -> 0
B38: {=+_FV(Peers!A17,"Name")} -> #VALUE! | G38: 0 | I38: =IFERROR(G38/$G$40,"") -> 0
B39: Others | E39: -- | G39: =G40-SUM(G28:G38) -> 48384.722 | I39: =IFERROR(G39/$G$40,"") -> 0.516324
B40: Industry Size | E40: -- | G40: 93710 | I40: 1
B42: Porter's Five Forces Analysis | E42: Rating | H42: Graph
B44: Threat of New Entrants | E44: =IFERROR(AVERAGE(E45:E50),"") -> 4
B45: Economies of scale | E45: 5
B46: Product differentiation | E46: 5
B47: Capital requirements | E47: 5
B48: Access to distribution channels | E48: 3
B49: Regulations | E49: 3
B50: Switching costs | E50: 3
B51: Bargaining Power of Suppliers | E51: =IFERROR(AVERAGE(E52:E56),"") -> 3
B52: Number of suppliers | E52: 3
B53: Uniqueness | E53: 3
B54: Switching Costs | E54: 3
B55: Forward Integration | E55: 1
B56: Industry Importance | E56: 5
B57: Bargaining Power of Customers | E57: =IFERROR(AVERAGE(E58:E62),"") -> 3
...

Sheet Peers
D3: Revenue Growth | F3: EBITDA Margin | H3: Profit Margin | J3: EV / Revenue | L3: EV / EBITDA | N3: Price / Earnings
B4: Peers | C4: Ticker | D4: =+Inputs!O4&"-"&Inputs!P4 -> 2022-2023 | E4: =+Inputs!P4&"-"&Inputs!Q4 -> 2023-2024 | F4: 2023 | G4: 2024 | H4: =+Inputs!O4&"-"&Inputs!P4 -> 2022-2023 | I4: =+Inputs!P4&"-"&Inputs!Q4 -> 2023-2024 | J4: 2023 | K4: 2024 | L4: 2023 | M4: 2024 | N4: 2023 | O4: 2024
A6: =+D91 -> #VALUE! | B6: {=IFERROR(_FV(A6,"Name"),"")} -> ANALOG DEVICES, INC. | C6: {=IFERROR(_FV(A6,"Ticker symbol",TRUE),"")} -> ADI | D6: =IFERROR(D94/D93-1,"") -> 0.024263359 | E6: =IFERROR(D97/D94-1,"") -> -0.23390354 | F6: =IFERROR(D95/D94,"") -> 0.40172281 | G6: =IFERROR(D100/D97,"") -> 0.29965419 | H6: =IFERROR(D96/D94,"") -> 0.19558734 | I6: =IFERROR(D105/D97,"") -> 0.06834479 | J6: {=IFERROR((_FV(A6,"Market cap",TRUE)/1000000+D$121-D$111)/D$94,"")} -> 10.271413 | K6: {=IFERROR((_FV(A6,"Market cap",TRUE)/1000000+D$121-D$111)/D$97,"")} -> 13.407466 | L6: {=+IFERROR((_FV(A6,"Market cap",TRUE)/1000000+D$121-D$111)/D$95,"")} -> 25.568408 | M6: {=IFERROR((_FV(A6,"Market cap",TRUE)/1000000+D$121-D$111)/D$100,"")} -> 44.74313 | N6: {=IFERROR((_FV(A6,"Market cap",TRUE)/1000000)/D$96,"")} -> 50.193023 | O6: {=IFERROR((_FV(A6,"Market cap",TRUE)/1000000)/D$105,"")} -> 187.49739
A8: =+E91 -> #VALUE! | B8: {=IFERROR(_FV(A8,"Name"),"")} -> TEXAS INSTRUMENTS INCORPORATED | C8: {=+IFERROR(_FV(A8,"Ticker symbol",TRUE),"")} -> TXN | D8: =+IFERROR(E94/E93-1,"") -> -0.12527462 | E8: =IFERROR(E97/E94-1,"") -> -0.1071979 | F8: =IFERROR(E95/E94,"") -> 0.51424168 | G8: =+IFERROR(E100/E97,"") -> 0.4821303 | H8: =IFERROR(E96/E94,"") -> 0.37159655 | I8: =+IFERROR(D105/D99,"") -> 0.11972721 | J8: {=+IFERROR((_FV(A8,"Market cap",TRUE)/1000000+E$121-E$111)/E$94,"")} -> 9.8996265 | K8: {=IFERROR(+(_FV(A8,"Market cap",TRUE)/1000000+E$121-E$111)/E$97,"")} -> 11.088265 | L8: {=IFERROR(+(_FV(A8,"Market cap",TRUE)/1000000+E$121-E$111)/E$95,"")} -> 19.250922 | M8: {=IFERROR(+(_FV(A8,"Market cap",TRUE)/1000000+E$121-E$111)/E$100,"")} -> 22.998482 | N8: {=IFERROR(+(_FV(A8,"Market cap",TRUE)/1000000)/E$96,"")} -> 25.043864 | O8: {=IFERROR(+(_FV(A8,"Market cap",TRUE)/1000000)/E$105,"")} -> 33.972819
A9: =+F91 -> #VALUE! | B9: {=IFERROR(_FV(A9,"Name"),"")} -> MICROCHIP TECHNOLOGY INCORPORATED | C9: {=+IFERROR(_FV(A9,"Ticker symbol",TRUE),"")} -> MCHP | D9: =IFERROR(F94/F93-1,"") -> 0.23718278 | E9: =IFERROR(+F97/F94-1,"") -> -0.095310889 | F9: =IFERROR(F95/F94,"") -> 0.4946852 | G9: =IFERROR(F100/F97,"") -> 0.45870009 | H9: =IFERROR(F96/F94,"") -> 0.26517118 | I9: =+IFERROR(F105/F97,"") -> 0.24977732 | J9: {=IFERROR(+(_FV(A9,"Market cap",TRUE)/1000000+F$122-F$112)/F$94,"")} -> 4.7879056 | K9: {=IFERROR(+(_FV(A9,"Market cap",TRUE)/1000000+F$122-F$112)/F$97,"")} -> 5.2923215 | L9: {=IFERROR(+(_FV(A9,"Market cap",TRUE)/1000000+F$122-F$112)/F$95,"")} -> 9.6786918 | M9: {=IFERROR(+(_FV(A9,"Market cap",TRUE)/1000000+F$122-F$112)/F$100,"")} -> 11.537651 | N9: {=IFERROR(+(_FV(A9,"Market cap",TRUE)/1000000)/F$96,"")} -> 15.58721 | O9: {=IFERROR(+(_FV(A9,"Market cap",TRUE)/1000000)/F$105,"")} -> 18.291205
A10: =+G91 -> #VALUE! | B10: {=IFERROR(_FV(A10,"Name"),"")} -> MONOLITHIC POWER SYSTEMS, INC. | C10: {=IFERROR(_FV(A10,"Ticker symbol",TRUE),"")} -> MPWR | D10: =+IFERROR(G94/G93-1,"") -> 0.015006566 | E10: =IFERROR(G97/G94-1,"") -> 0.21197844 | F10: =IFERROR(G95/G94,"") -> 0.28830107 | G10: =IFERROR(G100/G97,"") -> 0.26264827 | H10: =IFERROR(G96/G94,"") -> 0.23468265 | I10: =+IFERROR(G105/G97,"") -> 0.80952381 | J10: {=IFERROR(+(_FV(A10,"Market cap",TRUE)/1000000+G$122-G$112)/G$94,"")} -> 24.026317 | K10: {=IFERROR(+(_FV(A10,"Market cap",TRUE)/1000000+G$122-G$112)/G$97,"")} -> 19.824046 | L10: {=IFERROR(+(_FV(A10,"Market cap",TRUE)/1000000+G$122-G$112)/G$95,"")} -> 83.337592 | M10: {=IFERROR(+(_FV(A10,"Market cap",TRUE)/1000000+G$122-G$112)/G$100,"")} -> 75.477543 | N10: {=IFERROR(+(_FV(A10,"Market cap",TRUE)/1000000)/G$96,"")} -> 102.3779 | O10: {=IFERROR(+(_FV(A10,"Market cap",TRUE)/1000000)/G$105,"")} -> 24.488528
A11: =+H91 -> #VALUE! | B11: {=IFERROR(_FV(A11,"Name"),"")} -> SKYWORKS SOLUTIONS, INC. | C11: {=IFERROR(_FV(A11,"Ticker symbol",TRUE),"")} -> SWKS | D11: =IFERROR(H94/H93-1,"") -> -0.12999727 | E11: =IFERROR(H97/H94-1,"") -> -0.12454949 | F11: =IFERROR(H95/H94,"") -> 0.39173162 | G11: =IFERROR(H100/H97,"") -> 0.34214935 | H11: =IFERROR(H96/H94,"") -> 0.20593412 | I11: =+IFERROR(H105/H102,"") -> 19.413681 | J11: {=IFERROR((_FV(A11,"Market cap",TRUE)/1000000+H$122-H$112)/H$94,"")} -> 2.4075477 | K11: {=IFERROR(+(_FV(A11,"Market cap",TRUE)/1000000+H$122-H$112)/H$97,"")} -> 2.7500671 | L11: {=IFERROR(+(_FV(A11,"Market cap",TRUE)/1000000+H$122-H$112)/H$95,"")} -> 6.1459109 | M11: {=IFERROR(+(_FV(A11,"Market cap",TRUE)/1000000+H$122-H$112)/H$100,"")} -> 8.0376219 | N11: {=IFERROR(+(_FV(A11,"Market cap",TRUE)/1000000)/H$96,"")} -> 11.690863 | O11: {=IFERROR(+(_FV(A11,"Market cap",TRUE)/1000000)/H$105,"")} -> 19.278155
A12: =+I91 -> #VALUE! | B12: {=IFERROR(_FV(A12,"Name"),"")} -> MACOM TECHNOLOGY SOLUTIONS HOLDINGS, INC. | C12: {=IFERROR(_FV(A12,"Ticker symbol",TRUE),"")} -> MTSI | D12: =+IFERROR(I94/I93-1,"") -> -0.039638906 | E12: =IFERROR(I97/I94-1,"") -> 0.12518526 | F12: =IFERROR(I95/I94,"") -> 0.27309853 | G12: =IFERROR(I100/I97,"") -> 0.23116788 | H12: =IFERROR(I96/I94,"") -> 0.14123382 | I12: =+IFERROR(I105/I97,"") -> 0.1053472 | J12: {=IFERROR((_FV(A12,"Market cap",TRUE)/1000000+I$122-I$112)/I$94,"")} -> 14.826906 | K12: {=IFERROR(+(_FV(A12,"Market cap",TRUE)/1000000+I$122-I$112)/I$97,"")} -> 13.177302 | L12: {=IFERROR(+(_FV(A12,"Market cap",TRUE)/1000000+I$122-I$112)/I$95,"")} -> 54.291417 | M12: {=IFERROR(+(_FV(A12,"Market cap",TRUE)/1000000+I$122-I$112)/I$100,"")} -> 57.003172 | N12: {=IFERROR(+(_FV(A12,"Market cap",TRUE)/1000000)/I$96,"")} -> 104.98127 | O12: {=IFERROR(+(_FV(A12,"Market cap",TRUE)/1000000)/I$105,"")} -> 125.0845
A13: =+J91 -> #VALUE! | B13: {=IFERROR(_FV(A13,"Name"),"")} -> MARVELL TECHNOLOGY, INC. | C13: {=IFERROR(_FV(A13,"Ticker symbol",TRUE),"")} -> MRVL | D13: =IFERROR(J94/J93-1,"") -> 0.3267593 | E13: =IFERROR(J97/J94-1,"") -> -0.069594595 | F13: =IFERROR(J95/J94,"") -> 0.27837838 | G13: =IFERROR(J100/J97,"") -> 0.15450254 | H13: =IFERROR(J96/J94,"") -> -0.027702703 | I13: =+IFERROR(J105/J97,"") -> -0.16938998 | J13: {=IFERROR(+(_FV(A13,"Market cap",TRUE)/1000000+J$121-J$111)/J$94,"")} -> 11.3542 | K13: {=IFERROR(+(_FV(A13,"Market cap",TRUE)/1000000+J$121-J$111)/J$97,"")} -> 12.203498 | L13: {=IFERROR(+(_FV(A13,"Market cap",TRUE)/1000000+J$121-J$111)/J$95,"")} -> 40.786932 | M13: {=IFERROR(+(_FV(A13,"Market cap",TRUE)/1000000+J$121-J$111)/J$100,"")} -> 78.98574 | N13: {=IFERROR(+(_FV(A13,"Market cap",TRUE)/1000000)/J$96,"")} -> -388.82234 | O13: {=IFERROR(+(_FV(A13,"Market cap",TRUE)/1000000)/J$105,"")} -> -68.34605
A14: =+K91 -> #VALUE! | B14: {=IFERROR(_FV(A14,"Nome"),"")} -> INTEL CORPORATION | C14: {=IFERROR(_FV(A14,"Símbolo do ticker",TRUE),"")} -> INTC | D14: =IFERROR(K94/K93-1,"") | E14: =IFERROR(K97/K94-1,"") | F14: =+IFERROR(K95/K94,"") | G14: =IFERROR(K100/K97,"") | H14: =IFERROR(K96/K94,"") | I14: =+IFERROR(K105/K97,"") | J14: {=IFERROR((_FV(A14,"Market cap",TRUE)/1000000+D$121-K$111)/K$94,"")} | K14: {=IFERROR(+(_FV(A14,"Market cap",TRUE)/1000000+D$121-K$111)/K$97,"")} | L14: {=IFERROR(+(_FV(A14,"Market cap",TRUE)/1000000+D$121-K$111)/K$95,"")} | M14: {=IFERROR(+(_FV(A14,"Market cap",TRUE)/1000000+D$121-K$111)/K$100,"")} | N14: {=IFERROR(+(_FV(A14,"Market cap",TRUE)/1000000)/K$96,"")} | O14: {=IFERROR(+(_FV(A14,"Market cap",TRUE)/1000000)/K$105,"")}
A15: =+L91 -> #VALUE! | B15: {=IFERROR(_FV(A15,"Nome"),"")} -> MICRON TECHNOLOGY, INC. | C15: {=IFERROR(_FV(A15,"Símbolo do ticker",TRUE),"")} -> MU | D15: =+IFERROR(L94/L93,"") | E15: =IFERROR(L97/L94,"") | F15: =IFERROR(L95/L94,"") | G15: =IFERROR(L100/L97,"") | H15: =IFERROR(L96/L94,"") | I15: =+IFERROR(L105/L97,"") | J15: {=IFERROR(+(_FV(A15,"Market cap",TRUE)/1000000+L$121-L$111)/L$94,"")} | K15: {=IFERROR(+(_FV(A15,"Market cap",TRUE)/1000000+L$121-L$111)/L$97,"")} | L15: {=IFERROR(+(_FV(A15,"Market cap",TRUE)/1000000+L$121-L$111)/L$95,"")} | M15: {=IFERROR(+(_FV(A15,"Market cap",TRUE)/1000000+L$121-L$111)/L$100,"")} | N15: {=IFERROR(+(_FV(A15,"Market cap",TRUE)/1000000)/L$96,"")} | O15: {=IFERROR(+(_FV(A15,"Market cap",TRUE)/1000000)/L$105,"")}
A16: =+M91 -> #VALUE! | B16: {=IFERROR(_FV(A16,"Nome"),"")} -> FIRST SOLAR, INC. | C16: {=IFERROR(_FV(A16,"Símbolo do ticker",TRUE),"")} -> FSLR | D16: =IFERROR(M94/M93-1,"") | E16: =IFERROR(M97/M94-1,"") | F16: =IFERROR(M95/M94,"") | G16: =IFERROR(M100/M97,"") | H16: =IFERROR(M96/M94,"") | I16: =+IFERROR(M105/M97,"") | J16: {=IFERROR(+(_FV(A16,"Market cap",TRUE)/1000000+M$121-M$111)/M$94,"")} | K16: {=IFERROR(+(_FV(A16,"Market cap",TRUE)/1000000+M$121-M$111)/M$97,"")} | L16: {=IFERROR(+(_FV(A16,"Market cap",TRUE)/1000000+M$121-M$111)/M$95,"")} | M16: {=IFERROR(+(_FV(A16,"Market cap",TRUE)/1000000+M$121-M$111)/M$100,"")} | N16: {=IFERROR(+(_FV(A16,"Market cap",TRUE)/1000000)/M$96,"")} | O16: {=IFERROR(+(_FV(A16,"Market cap",TRUE)/1000000)/M$105,"")}
A17: =+N91 -> #VALUE! | B17: {=IFERROR(_FV(A17,"Nome"),"")} -> ALTRI, S.G.P.S., S.A. | C17: {=+IFERROR(_FV(A17,"Símbolo do ticker",TRUE),"")} -> ALTR | D17: =IFERROR(N94/N93-1,"") | E17: =IFERROR(N97/N94-1,"") | F17: =IFERROR(N95/N94,"") | G17: =IFERROR(N100/N97,"") | H17: =IFERROR(N96/N94,"") | I17: =+IFERROR(N105/N97,"") | J17: {=IFERROR(+(_FV(A17,"Market cap",TRUE)/1000000+N$121-N$111)/N$94,"")} | K17: {=IFERROR(+(_FV(A17,"Market cap",TRUE)/1000000+N$121-N$111)/N$97,"")} | L17: {=IFERROR(+(_FV(A17,"Market cap",TRUE)/1000000+N$121-N$111)/N$95,"")} | M17: {=IFERROR(+(_FV(A17,"Market cap",TRUE)/1000000+N$121-N$111)/N$100,"")} | N17: {=IFERROR(+(_FV(A17,"Market cap",TRUE)/1000000)/N$96,"")} | O17: {=IFERROR(+(_FV(A17,"Market cap",TRUE)/1000000)/N$105,"")}
B18: Average | D18: =IFERROR(AVERAGE(D6:D17),"") -> 0.044043031 | E18: =IFERROR(AVERAGE(E6:E17),"") -> -0.041913245 | F18: =IFERROR(AVERAGE(F6:F17),"") -> 0.37745133 | G18: =IFERROR(AVERAGE(G6:G17),"") -> 0.31870752 | H18: =IFERROR(AVERAGE(H6:H17),"") -> 0.19807185 | I18: =IFERROR(AVERAGE(I6:I17),"") -> 2.9424302 | J18: =IFERROR(AVERAGE(J6:J17),"") -> 11.081988 | K18: =IFERROR(AVERAGE(K6:K17),"") -> 11.106138 | ... O18: =IFERROR(AVERAGE(O6:O17),"") -> 48.609507
B19: Deviation from Average | D19: =IFERROR(+D18-D6,"") -> 0.019779671 | E19: =IFERROR(E18-E6,"") -> 0.19199029 | F19: =+IFERROR(F18-F6,"") -> -0.02427148 | G19: =IFERROR(G18-G6,"") -> 0.019053327 | H19: =IFERROR(+H6-H18,"") -> -0.0024845121 | I19: =+IFERROR(I6-I18,"") -> -2.8740854 | J19: =+IFERROR(J6-J18,"") -> -0.81057529 | K19: =+IFERROR(K6-K18,"") -> 2.3013284 | L19: =IFERROR(+L6-L18,"") -> -8.5830026 | M19: =IFERROR(M6-M18,"") -> 2.0597959 | N19: =IFERROR(+N6-N18,"") -> 61.471339 | O19: =IFERROR(+O6-O18,"") -> 138.88788
D21: Trading Multiple | G21: Net | H21: Preferred | I21: Non-Controlling | J21: Equity Value | M21: Implied Upside (Downside)
B22: Implied Share Price | D22: Revenue | E22: EBITDA | F22: P/E | G22: Debt | H22: Stock | I22: Interest | J22: Revenue | K22: EBITDA | L22: P/E | M22: Revenue | N22: EBITDA | O22: P/E | P22: Current Price
B24: Second Minimum | D24: =IFERROR(SMALL(K6:K17,2),"") -> 5.2923215 | E24: =IFERROR(SMALL(M6:M17,2),"") -> 11.537651 | F24: =IFERROR(SMALL(O6:O17,2),"") -> 18.291205 | G24: =-Inputs!$Q$99+Inputs!$Q$100 -> 5218.5 | H24: =+Inputs!$Q$101 -> 0 | I24: =+Inputs!$Q$102 -> 0 | J24: =IFERROR(+D24*$D$97+G24+H24+I24,"") -> 55110.273 | K24: =IFERROR(E24*$D$100+G24+H24+I24,"") -> 37811.209 | L24: =IFERROR(F24*$D$105,"") -> 11785.023 | M24: {=IFERROR(+(J24/_FV($A$6,"Shares outstanding",TRUE)*1000000)/$P$24-1,"")} -> -0.54380638 | N24: {=IFERROR((+K24/_FV($A$6,"Shares outstanding",TRUE)*1000000)/$P$24-1,"")} -> -0.68700513 | O24: {=IFERROR(+(L24/_FV($A$6,"Shares outstanding",TRUE)*1000000)/$P$24-1,"")} -> -0.90244555 | P24: {=+_FV(A6,"Price")} -> 245.56
B25: Average | D25: =+IFERROR(AVERAGE(K6:K17),"") -> 11.106138 | E25: =IFERROR(+AVERAGE(M6:M17),"") -> 42.683334 | F25: =IFERROR(+AVERAGE(O6:O17),"") -> 48.609507 | G25: =-Inputs!$Q$99+Inputs!$Q$100 -> 5218.5 | H25: =+Inputs!$Q$101 -> 0 | I25: =+Inputs!$Q$102 -> 0 | J25: =IFERROR(+D25*$D$97+G25+H25+I25,"") -> 109918.28 | K25: =IFERROR(E25*$D$100+G25+H25+I25,"") -> 125794.65 | L25: =IFERROR(+F25*$D$105,"") -> 31319.105 | M25: {=IFERROR(+(J25/_FV($A$6,"Shares outstanding",TRUE)*1000000)/$P$24-1,"")} -> -0.090114832 | N25: {=IFERROR((+K25/_FV($A$6,"Shares outstanding",TRUE)*1000000)/$P$24-1,"")} -> 0.041307069 | O25: {=IFERROR(+(L25/_FV($A$6,"Shares outstanding",TRUE)*1000000)/$P$24-1,"")} -> -0.74074569
B26: Median | D26: =IFERROR(MEDIAN(K6:K17),"") -> 12.203498 | E26: =IFERROR(MEDIAN(M6:M17),"") -> 44.74313 | F26: =IFERROR(MEDIAN(O6:O17),"") -> 24.488528 | G26: =-Inputs!$Q$99+Inputs!$Q$100 -> 5218.5 | H26: =+Inputs!$Q$101 -> 0 | I26: =+Inputs!$Q$102 -> 0 | J26: =IFERROR(D26*$D$97+G26+H26+I26,"") -> 120263.31 | K26: =IFERROR(E26*$D$100+G26+H26+I26,"") -> 131613.37 | L26: =IFERROR(+F26*$D$105,"") -> 15777.958 | M26: {=IFERROR(+(J26/_FV($A$6,"Shares outstanding",TRUE)*1000000)/$P$24-1,"")} -> -0.0044804262 | N26: {=IFERROR((+K26/_FV($A$6,"Shares outstanding",TRUE)*1000000)/$P$24-1,"")} -> 0.089473438 | O26: {=+IFERROR((L26/_FV($A$6,"Shares outstanding",TRUE)*1000000)/$P$24-1,"")} -> -0.8693927
B27: Second Maximum | D27: =IFERROR(LARGE(K6:K17,2),"") -> 13.407466 | E27: =IFERROR(LARGE(M6:M17,2),"") -> 75.477543 | F27: =IFERROR(LARGE(O6:O17,2),"") -> 125.0845 | G27: =-Inputs!$Q$99+Inputs!$Q$100 -> 5218.5 | H27: =+Inputs!$Q$101 -> 0 | I27: =+Inputs!$Q$102 -> 0 | J27: =IFERROR(+D27*$D$97+G27+H27+I27,"") -> 131613.37 | K27: =IFERROR(E27*$D$100+G27+H27+I27,"") -> 218435.01 | L27: =IFERROR(+F27*$D$105,"") -> 80591.946 | M27: {=IFERROR(+(J27/_FV($A$6,"Shares outstanding",TRUE)*1000000)/$P$24-1,"")} -> 0.089473438 | N27: {=IFERROR((+K27/_FV($A$6,"Shares outstanding",TRUE)*1000000)/$P$24-1,"")} -> 0.80816847 | O27: {=IFERROR(+(L27/_FV($A$6,"Shares outstanding",TRUE)*1000000)/$P$24-1,"")} -> -0.33287336
B29: Profitability | D29: =+LEFT(B6, FIND(" ", B6 & " ") - 1) -> ANALOG | E29: =+LEFT(B8, FIND(" ", B8 & " ") - 1) -> TEXAS | F29: =+LEFT(B9, FIND(" ", B9 & " ") - 1) -> MICROCHIP | G29: =+LEFT(B10, FIND(" ", B10 & " ") - 1) -> MONOLITHIC | H29: =+LEFT(B11, FIND(" ", B11 & " ") - 1) -> SKYWORKS | I29: =+LEFT(B12, FIND(" ", B12 & " ") - 1) -> MACOM | J29: =+LEFT(C12, FIND(" ", C12 & " ") - 1) -> MTSI | K29: =+LEFT(B14, FIND(" ", B14 & " ") - 1) -> INTEL | L29: =+LEFT(B15, FIND(" ", B15 & " ") - 1) -> MICRON | M29: =+LEFT(B16, FIND(" ", B16 & " ") - 1) -> FIRST | N29: =+LEFT(B17, FIND(" ", B17 & " ") - 1) -> ALTRI, | O29: Average
B31: Operating Margin | D31: =IFERROR(D101/D97,"") -> 0.076438391 | E31: =IFERROR(E101/E97,"") -> 0.38111374 | F31: =IFERROR(F101/F97,"") -> 0.33558629 | G31: =IFERROR(G101/G97,"") -> 0.24437407 | H31: =IFERROR(H101/H97,"") -> 0.22565821 | I31: =IFERROR(I101/I97,"") -> 0.12671709 | J31: =IFERROR(J101/J97,"") -> -0.099491649 | K31: =IFERROR(K101/K97,"") | ... N31: =IFERROR(N101/N97,"") | O31: =IFERROR(+AVERAGE(D31:N31),"") -> 0.18434231
B32: Net Income Margin | D32: =IFERROR(D105/D97,"") -> 0.06834479 | E32: =IFERROR(E105/E97,"") -> 0.30682181 | F32: =IFERROR(F105/F97,"") -> 0.24977732 | G32: =IFERROR(G105/G97,"") -> 0.80952381 | H32: =IFERROR(H105/H97,"") -> 0.14265199 | I32: =IFERROR(I105/I97,"") -> 0.1053472 | J32: =IFERROR(J105/J97,"") -> -0.16938998 | K32: =IFERROR(K105/K97,"") | ... N32: =IFERROR(N105/N97,"") | O32: =IFERROR(+AVERAGE(D32:N32),"") -> 0.21615385
B33: ROA (%) | D33: =IFERROR(D105/D117,"") -> 0.013359376 | E33: =IFERROR(E105/E117,"") -> 0.13514884 | F33: =IFERROR(F105/F118,"") -> 8.9525822 | G33: =IFERROR(G105/G118,"") | H33: =IFERROR(H105/H118,"") | I33: =IFERROR(I105/I118,"") | J33: =IFERROR(J105/J117,"") -> -0.043949315 | K33: =IFERROR(K105/K117,"") | L33: =IFERROR(L105/L117,"") | M33: =IFERROR(M105/M117,"") | N33: =IFERROR(N105/N117,"") | O33: =IFERROR(+AVERAGE(D33:N33),"") -> 2.2642853
B34: Financial Cost of Debt | D34: =IFERROR(+(D102/D121)*(1-(D104/D103)),"") -> -0.0085154965 | E34: =IFERROR(+(E102/E121)*(1-(E104/E103)),"") -> 0.032882726 | F34: =IFERROR(+(F102/F122)*(1-(F104/F103)),"") -> 0.017662659 | G34: =IFERROR(+(G102/G122)*(1-(G104/G103)),"") | H34: =IFERROR(+(H102/H122)*(1-(H104/H103)),"") | I34: =IFERROR(+(I102/I122)*(1-(I104/I103)),"") | J34: =IFERROR(+(J102/J121)*(1-(J104/J103)),"") -> 0.053405637 | K34: =IFERROR(+(K102/K121)*(1-(K104/K103)),"") | L34: =IFERROR(+(L102/L121)*(1-(L104/L103)),"") | M34: =IFERROR(+(M102/M121)*(1-(M104/M103)),"") | N34: =IFERROR(+(N102/N121)*(1-(N104/N103)),"") | O34: =IFERROR(+AVERAGE(D34:N34),"") -> 0.023858881
B35: Return on Equity (RoE) | D35: =IFERROR(+D105/D122,"") -> 0.01831631 | E35: =IFERROR(+E105/E122,"") -> 0.2839141 | F35: =IFERROR(+F105/#REF!,"") | G35: =IFERROR(+G105/#REF!,"") | H35: =IFERROR(+H105/#REF!,"") | I35: =IFERROR(+I105/#REF!,"") | J35: =IFERROR(+J105/J122,"") -> -0.062908772 | K35: =IFERROR(+K105/K122,"") | L35: =IFERROR(+L105/L122,"") | M35: =IFERROR(+M105/M122,"") | N35: =IFERROR(+N105/N122,"") | O35: =IFERROR(+AVERAGE(D35:N35),"") -> 0.079773878
B36: Return on Invested Capital (ROIC) | D36: =IFERROR(+D105/(D121+D122),"") -> 0.01506856 | E36: =IFERROR(+E105/(E121+E122),"") -> 0.15734942 | F36: =IFERROR(+F105/(F122+#REF!),"") | G36: =IFERROR(+G105/(G122+#REF!),"") | H36: =IFERROR(+H105/(H122+#REF!),"") | I36: =IFERROR(+I105/(I122+#REF!),"") | J36: =IFERROR(+J105/(J121+J122),"") -> -0.048512895 | K36: =IFERROR(+K105/(K121+K122),"") | L36: =IFERROR(+L105/(L121+L122),"") | M36: =IFERROR(+M105/(M121+M122),"") | N36: =IFERROR(+N105/(N121+N122),"") | O36: =IFERROR(+AVERAGE(D36:N36),"") -> 0.041301696
B38: Solvency | D38: =+D29 -> ANALOG | E38: =+E29 -> TEXAS | F38: =+F29 -> MICROCHIP | G38: =+G29 -> MONOLITHIC | H38: =+H29 -> SKYWORKS | I38: =+I29 -> MACOM | J38: =+J29 -> MTSI | K38: =+K29 -> INTEL | ... O38: =+O29 -> Average
B40: Debt/Assets | D40: =IFERROR(D121/D117,"") -> 0.15720231 | E40: =IFERROR(E121/E117,"") -> 0.38288885 | F40: =IFERROR(F122/F118,"") -> 31.257277 | G40: =IFERROR(G122/G118,"") | H40: =IFERROR(H122/H118,"") | I40: =IFERROR(I122/I118,"") | J40: =IFERROR(J121/J117,"") -> 0.20731075 | K40: =IFERROR(K121/K117,"") | L40: =IFERROR(L121/L117,"") | M40: =IFERROR(M121/M117,"") | N40: =IFERROR(N121/N117,"") | O40: =IFERROR(+AVERAGE(D40:N40),"") -> 8.0011697
B41: Net Debt/EBITDA | D41: =IFERROR(+(D121-D111)/D100,"") -> 1.9789373 | E41: =IFERROR(+(E121-E111)/E100,"") -> 1.378597 | F41: =IFERROR(+(F122-F112)/F100,"") -> 1.5774865 | G41: =IFERROR(+(G122-G112)/G100,"") -> 0 | H41: =IFERROR(+(H122-H112)/H100,"") -> 0 | I41: =IFERROR(+(I122-I112)/I100,"") -> 0 | J41: =IFERROR(+(J121-J111)/J100,"") -> 4.0540541 | K41: =IFERROR(+(K121-K111)/K100,"") | L41: =IFERROR(+(L121-L111)/L100,"") | M41: =IFERROR(+(M121-M111)/M100,"") | N41: =IFERROR(+(N121-N111)/N100,"") | O41: =IFERROR(+AVERAGE(D41:N41),"") -> 1.2841536
B42: Interest Coverage Ratio | D42: =IFERROR(D101/D102,"") -> -9.1446701 | E42: =IFERROR(E101/E102,"") -> 11.734252 | F42: =IFERROR(F101/F102,"") -> 17.559973 | G42: =IFERROR(G101/G102,"") | H42: =IFERROR(H101/H102,"") -> 30.710098 | I42: =IFERROR(I101/I102,"") -> -5.1792717 | J42: =IFERROR(J101/J102,"") -> -2.8691099 | K42: =IFERROR(K101/K102,"") | ... N42: =IFERROR(N101/N102,"") | O42: =IFERROR(+AVERAGE(D42:N42),"") -> 7.1352118
B44: Liquidity | D44: =+D29 -> ANALOG | E44: =+E29 -> TEXAS | F44: =+F29 -> MICROCHIP | G44: =+G29 -> MONOLITHIC | H44: =+H29 -> SKYWORKS | I44: =+I29 -> MACOM | J44: =+J29 -> MTSI | K44: =+K29 -> INTEL | ... O44: =+O29 -> Average
B46: Cash Ratio | D46: =IFERROR(D111/D119,"") -> 0.66636549 | E46: =IFERROR(E111/E119,"") -> 0.87839693 | F46: =IFERROR(F112/F120,"") -> 0.22101343 | G46: =IFERROR(G112/G120,"") | H46: =IFERROR(H112/H120,"") | I46: =IFERROR(I112/I120,"") | J46: =IFERROR(J111/J119,"") -> 0.52425579 | K46: =IFERROR(K111/K119,"") | L46: =IFERROR(L111/L119,"") | M46: =IFERROR(M111/M119,"") | N46: =IFERROR(N111/N119,"") | O46: =IFERROR(+AVERAGE(D46:N46),"") -> 0.57250791
B47: Quick Ratio | D47: =IFERROR(+(D111+D112)/D119,"") -> 1.1135428 | E47: =IFERROR(+(E111+E112)/E119,"") -> 1.3502608 | F47: =IFERROR(+(F112+F113)/F120,"") -> 0.22101343 | G47: =IFERROR(+(G112+G113)/G120,"") | H47: =IFERROR(+(H112+H113)/H120,"") | I47: =IFERROR(+(I112+I113)/I120,"") | J47: =IFERROR(+(J111+J112)/J119,"") -> 1.1427784 | K47: =IFERROR(+(K111+K112)/K119,"") | L47: =IFERROR(+(L111+L112)/L119,"") | M47: =IFERROR(+(M111+M112)/M119,"") | N47: =IFERROR(+(N111+N112)/N119,"") | O47: =IFERROR(+AVERAGE(D47:N47),"") -> 0.95689885
B48: Current Ratio | D48: =IFERROR(D115/D119,"") -> 1.8353914 | E48: =IFERROR(E115/E119,"") -> 4.1246226 | F48: =IFERROR(F116/F120,"") -> 0.26337954 | G48: =IFERROR(G116/G120,"") | H48: =IFERROR(H116/H120,"") | I48: =IFERROR(I116/I120,"") | J48: =IFERROR(J115/J119,"") -> 1.6885336 | K48: =IFERROR(K115/K119,"") | L48: =IFERROR(L115/L119,"") | M48: =IFERROR(M115/M119,"") | N48: =IFERROR(N115/N119,"") | O48: =IFERROR(+AVERAGE(D48:N48),"") -> 1.9779818
B50: Activity | D50: =+D29 -> ANALOG | E50: =+E29 -> TEXAS | F50: =+F29 -> MICROCHIP | G50: =+G29 -> MONOLITHIC | H50: =+H29 -> SKYWORKS | I50: =+I29 -> MACOM | J50: =+J29 -> MTSI | K50: =+K29 -> INTEL | ... O50: =+O29 -> Average
B52: Inventory Turnover | D52: =IFERROR(D98/(AVERAGE(D113:D114)),"") -> 2.6187255 | E52: =IFERROR(E98/(AVERAGE(E113:E114)),"") -> 1.5357729 | F52: =IFERROR(F98/(AVERAGE(F114:F115)),"") -> 0.85037061 | G52: =IFERROR(G98/(AVERAGE(G114:G115)),"") | H52: =IFERROR(H98/(AVERAGE(H114:H115)),"") | I52: =IFERROR(I98/(AVERAGE(I114:I115)),"") | J52: =IFERROR(J98/(AVERAGE(J113:J114)),"") -> 3.3271222 | K52: =IFERROR(K98/(AVERAGE(K113:K114)),"") | L52: =IFERROR(L98/(AVERAGE(L113:L114)),"") | M52: =IFERROR(M98/(AVERAGE(M113:M114)),"") | N52: =IFERROR(N98/(AVERAGE(N113:N114)),"") | O52: =IFERROR(+AVERAGE(D52:N52),"") -> 2.0829978
B53: Acc. Receivable Turnover | D53: =IFERROR(D97/D112,"") -> 7.0547033 | E53: =IFERROR(E97/E112,"") -> 9.0988947 | F53: =IFERROR(F97/F113,"") | G53: =IFERROR(G97/G113,"") | H53: =IFERROR(H97/H113,"") | I53: =IFERROR(I97/I113,"") | J53: =IFERROR(J97/J112,"") -> 4.9090909 | K53: =IFERROR(K97/K112,"") | L53: =IFERROR(L97/L112,"") | M53: =IFERROR(M97/M112,"") | N53: =IFERROR(N97/N112,"") | O53: =IFERROR(+AVERAGE(D53:N53),"") -> 7.0208963
B54: Payables Turnover | D54: =IFERROR(D98/D118,"") -> 8.2990769 | E54: =IFERROR(E98/E118,"") -> 7.9841463 | F54: =IFERROR(F98/F119,"") -> 1.0475189 | G54: =IFERROR(G98/G119,"") | H54: =IFERROR(H98/H119,"") | I54: =IFERROR(I98/I119,"") | J54: =IFERROR(J98/J118,"") -> 7.8199513 | K54: =IFERROR(K98/K118,"") | L54: =IFERROR(L98/L118,"") | M54: =IFERROR(M98/M118,"") | N54: =IFERROR(N98/N118,"") | O54: =IFERROR(+AVERAGE(D54:N54),"") -> 6.2876734
...

Sheet ESG
B2: Environmental, Social and Governance Analysis
B4: Author: | C4: Cristina Lin | E4: Highlights
G5: Analog is in a industry that faces some challenges to reduce its emissions and consumption. However, there is notable commitment of Analog Devices and significant improvement on emissions and water and energy cinsumption
B6: Overview | D6: . | E6: Environmental commitment
B7: Last Update | D7: . | G7: Analog Devices has a good interaction with their employees and has organized many activities and projects within the local community.
B8: Latest year with data | C8: 2024 | E8: Community involvement
B9: GICS Sector | C9: Semiconductor & Semiconductor components
B10: GICS Industry Group | C10: Information technology
B11: Final Review | C11: Good
B13: ESG Scores
B14: LSEG ESG Score | C14: 70
B15: E-Score | C15: 61
B16: S-Score | C16: 71 | E16: GHG Scope 1 and 2 Emissions: | N16: Water, Waste, Energy Management:
B17: G-Score | C17: 80
B18: S&P Global ESG Score | C18: 50
B19: Environmental | C19: 54
B20: Social | C20: 47
B21: Governance & Economic | C21: 47
B22: Sustainalytics | C22: 16.7
B23: ISS ESG Corporate Rating | C23: C+
B24: SDG Impact Rating | C24: 2.5
B25: Governance Quality Score | C25: 9
B26: MSCI ESG Ratings | C26: A
B29: Industry ESG Overview:
B30: While the IT and Semiconductor Components sectors face significant ESG challenges—ranging from high energy consumption and resource scarcity to labor practices and supply chain transparency—the industry is making notable progress in addressing these issues. Companies are increasingly adopting renewable energy, promoting diversity, improving supply chain traceability, and enhancing community engagement efforts. As ESG factors become more integral to the sector’s strategy, companies are thriving to achieve better sustainability performance and align with global ethical standards.
E33: ENVIRONMENTAL
G35: Overview | H35: Targets | K35: Improvements | O35: Comments
E36: GHG (or CO2) Scope 1 Emissions | H36: N/A | K36: Emissions have decreased 20% in scope 1, 6% in scope 2 and 12% in scope 3, in 2023 vs. 2022 | O36: N/A
E38: Water Consumption | H38: N/A | K38: Decreased significantly in 2023 and 2024. | O38: water withdrawn generally decreased.
E40: Energy Consumption | H40: N/a | K40: Renewable electricity from the purchase of unbundled Environmental Attribute Certificates increased 186% | O40: Natural gas heating consumption increased 3%, total electricity used increased 4%, non-renewable energy decreased 5.5%.
E42: Waste Management | H42: N/A | K42: N/A | O42: Total waste has increased 10%
E44: Other | H44: N/A | K44: N/a | O44: N/A
E46: SOCIAL
B48: Important Sources: | G48: Overview | H48: Targets | K48: Improvements | O48: Comments
B49: Annual Report | C49: https://investor.analog.com/static-files/cc2bbf08-9ebc-490b-8be3-e396d9ef5934 | E49: Employee Turnover % | H49: N/A | K49: N/A | O49: The company only discloses new hires percentage.
B50: Sustainability Report | C50: https://www.analog.com/media/en/company-csr/2023-esg-report.pdf | D50: .
B51: Proxy Statement | C51: https://investor.analog.com/static-files/8d9dcc9b-f9e5-492e-8a73-0b5ffc6a6c23 | D51: . | E51: Salaries & Compensation | H51: N/A | K51: In July 2023, implemented a new harmonized Global Recognition Program that resulted in more than 10,000 recorded recognition moments globally for the second half of 2023. Most recently, it has maintained a <1% pay equity difference for females and males globally. | O51: A portion of employees at professional levels are eligible for stock awards and Corporate Bonus Plans and Sales Incentive Plan link employees’ compensation to ADI’s revenue and operational performance goals.
E53: Reputation | H53: N/A | K53: N/A | O53: The company had some lawsuits related to semiconductor patent infringement with AMD, in 2022, and with Analog Technologies in 2024. (https://law.justia.com/cases/federal/appellate-courts/ca1/23-1822/23-1822-2024-06-18.html)
E55: Discrimination Events | H55: N/A | K55: N/A | O55: Analog Devices Inc. has settled with a former sales specialist who said a manager discriminated against her and the company retaliated against her for reporting it, in 2023.
E57: Work Safety | H57: N/A | K57: N/A | O57: Injury and illness recordable rate decreased 0.1 and lost workday incident rate decreased 0.04.
...

Sheet ESG Inputs
B2: ESG Inputs
A4: x | B4: Total GHG Scope 1 Emissions | G4: 2014 | H4: =+G4+1 -> 2015 | I4: =+H4+1 -> 2016 | J4: =+I4+1 -> 2017 | K4: =+J4+1 -> 2018 | L4: =+K4+1 -> 2019 | M4: =+L4+1 -> 2020 | N4: =+M4+1 -> 2021 | O4: =+N4+1 -> 2022 | ... Q4: =+P4+1 -> 2024 | R4: ="CAGR "&$G$4&" - "&$Q$4 -> CAGR 2014 - 2024
B6: =+Peers!B6 -> ANALOG DEVICES, INC. | G6: — | H6: 133 | I6: 135 | J6: 50 | K6: 54 | L6: — | M6: — | N6: — | O6: 176 | P6: 138 | Q6: — | R6: =IFERROR((Q6/G6)^(1/COUNT($G$4:$Q$4))-1,"")
B7: =+Peers!B8 -> TEXAS INSTRUMENTS INCORPORATED | G7: 1056 | H7: 1086 | I7: 1077 | J7: 1162 | K7: 1130 | L7: 970 | M7: 940 | N7: 1040 | O7: 1112 | P7: 1120 | Q7: — | R7: =IFERROR((Q7/G7)^(1/COUNT($G$4:$Q$4))-1,"")
B8: =+Peers!B9 -> MICROCHIP TECHNOLOGY INCORPORATED | G8: 1041 | H8: 1053 | I8: 976 | J8: 1490 | K8: 940 | L8: 900 | M8: 1040 | N8: 1150 | O8: 1180 | P8: 845 | Q8: — | R8: =IFERROR((Q8/G8)^(1/COUNT($G$4:$Q$4))-1,"")
B9: =+Peers!B10 -> MONOLITHIC POWER SYSTEMS, INC. | G9: — | H9: 1415 | I9: 1724 | J9: 2844 | K9: 2946 | L9: 3195 | M9: 3048 | N9: 3340 | O9: 3478 | P9: 2699 | Q9: — | R9: =IFERROR((Q9/G9)^(1/COUNT($G$4:$Q$4))-1,"")
B10: =+Peers!B11 -> SKYWORKS SOLUTIONS, INC. | G10: — | H10: — | I10: — | J10: — | K10: — | L10: — | M10: — | N10: — | O10: — | P10: — | Q10: — | R10: =IFERROR((Q10/G10)^(1/COUNT($G$4:$Q$4))-1,"")
B11: =+Peers!B12 -> MACOM TECHNOLOGY SOLUTIONS HOLDINGS, INC. | G11: — | H11: — | I11: — | J11: 0 | K11: 0 | L11: 0 | M11: 0 | N11: 2 | O11: 4 | P11: 3 | Q11: — | R11: =IFERROR((Q11/G11)^(1/COUNT($G$4:$Q$4))-1,"")
B12: =+Peers!B13 -> MARVELL TECHNOLOGY, INC. | G12: 133 | H12: 170 | I12: 193 | J12: 451 | K12: 488 | L12: 529 | M12: 426 | N12: 348 | O12: 408 | P12: 424 | Q12: 440 | R12: =IFERROR((Q12/G12)^(1/COUNT($G$4:$Q$4))-1,"") -> 0.11490139
B13: =+Peers!B14 -> INTEL CORPORATION | G13: 11 | H13: 12 | I13: 15 | J13: 16 | K13: 22 | L13: 27 | M13: 7 | N13: 9 | O13: 8 | P13: 12 | Q13: — | R13: =IFERROR((Q13/G13)^(1/COUNT($G$4:$Q$4))-1,"")
B14: =+Peers!B15 -> MICRON TECHNOLOGY, INC. | G14: — | H14: — | I14: — | J14: — | K14: — | L14: — | M14: — | N14: — | O14: — | P14: — | Q14: — | R14: =IFERROR((Q14/G14)^(1/COUNT($G$4:$Q$4))-1,"")
B15: =+Peers!B16 -> FIRST SOLAR, INC. | G15: — | H15: — | I15: — | J15: — | K15: — | L15: — | M15: — | N15: — | O15: 38 | P15: 30 | Q15: — | R15: =IFERROR((Q15/G15)^(1/COUNT($G$4:$Q$4))-1,"")
B16: =+Peers!B17 -> ALTRI, S.G.P.S., S.A. | G16: — | H16: — | I16: — | J16: — | K16: — | L16: 11 | M16: 10 | N16: 9 | O16: 20 | P16: 21 | Q16: — | R16: =IFERROR((Q16/G16)^(1/COUNT($G$4:$Q$4))-1,"")
A18: x | B18: Total GHG Scope 2 (Location-Based) Emissions | G18: 2014 | H18: =+G18+1 -> 2015 | I18: =+H18+1 -> 2016 | J18: =+I18+1 -> 2017 | K18: =+J18+1 -> 2018 | L18: =+K18+1 -> 2019 | M18: =+L18+1 -> 2020 | N18: =+M18+1 -> 2021 | O18: =+N18+1 -> 2022 | ... Q18: =+P18+1 -> 2024 | R18: ="CAGR "&$G$4&" - "&$Q$4 -> CAGR 2014 - 2024
B20: =+$B$6 -> ANALOG DEVICES, INC. | G20: — | H20: 86 | I20: 83 | J20: 94 | K20: 94 | L20: — | M20: — | N20: — | O20: 149 | P20: 140 | Q20: — | R20: =IFERROR((Q20/G20)^(1/COUNT($G$4:$Q$4))-1,"")
B21: =+$B$7 -> TEXAS INSTRUMENTS INCORPORATED | G21: — | H21: 1385 | I21: 0 | J21: 22 | K21: 1120 | L21: 1100 | M21: 1010 | N21: 1040 | O21: 1057 | P21: 1100 | Q21: — | R21: =IFERROR((Q21/G21)^(1/COUNT($G$4:$Q$4))-1,"")
B22: =+$B$8 -> MICROCHIP TECHNOLOGY INCORPORATED | G22: — | H22: 946 | I22: 647 | J22: 971 | K22: 660 | L22: 660 | M22: 280 | N22: 350 | O22: 350 | P22: 48 | Q22: — | R22: =IFERROR((Q22/G22)^(1/COUNT($G$4:$Q$4))-1,"")
B23: =+$B$9 -> MONOLITHIC POWER SYSTEMS, INC. | G23: — | H23: 1755 | I23: 2060 | J23: 2997 | K23: 3178 | L23: 3503 | M23: 3622 | N23: 3807 | O23: 4132 | P23: 4138 | Q23: — | R23: =IFERROR((Q23/G23)^(1/COUNT($G$4:$Q$4))-1,"")
B24: =+$B$10 -> SKYWORKS SOLUTIONS, INC. | G24: — | H24: — | I24: — | J24: — | K24: — | L24: — | M24: — | N24: — | O24: — | P24: — | Q24: — | R24: =IFERROR((Q24/G24)^(1/COUNT($G$4:$Q$4))-1,"")
B25: =+$B$11 -> MACOM TECHNOLOGY SOLUTIONS HOLDINGS, INC. | G25: — | H25: — | I25: — | J25: — | K25: — | L25: — | M25: — | N25: 17 | O25: 26 | P25: 24 | Q25: — | R25: =IFERROR((Q25/G25)^(1/COUNT($G$4:$Q$4))-1,"")
B26: =+$B$12 -> MARVELL TECHNOLOGY, INC. | G26: — | H26: — | I26: — | J26: — | K26: — | L26: — | M26: — | N26: — | O26: — | P26: — | Q26: 274 | R26: =IFERROR((Q26/G26)^(1/COUNT($G$4:$Q$4))-1,"")
B27: =+$B$13 -> INTEL CORPORATION | G27: — | H27: 300 | I27: 391 | J27: 309 | K27: 334 | L27: 442 | M27: 345 | N27: 552 | O27: 564 | P27: 777 | Q27: — | R27: =IFERROR((Q27/G27)^(1/COUNT($G$4:$Q$4))-1,"")
B28: =+$B$14 -> MICRON TECHNOLOGY, INC. | G28: — | H28: — | I28: — | J28: — | K28: — | L28: — | M28: — | N28: — | O28: — | P28: — | Q28: — | R28: =IFERROR((Q28/G28)^(1/COUNT($G$4:$Q$4))-1,"")
B29: =+$B$15 -> FIRST SOLAR, INC. | G29: — | H29: — | I29: — | J29: — | K29: — | L29: — | M29: — | N29: — | O29: 120 | P29: 92 | Q29: — | R29: =IFERROR((Q29/G29)^(1/COUNT($G$4:$Q$4))-1,"")
B30: =+$B$16 -> ALTRI, S.G.P.S., S.A. | G30: — | H30: — | I30: — | J30: — | K30: — | L30: — | M30: — | N30: — | O30: — | P30: — | Q30: — | R30: =IFERROR((Q30/G30)^(1/COUNT($G$4:$Q$4))-1,"")
A32: x | B32: Total Energy Usage | G32: 2014 | H32: =+G32+1 -> 2015 | I32: =+H32+1 -> 2016 | J32: =+I32+1 -> 2017 | K32: =+J32+1 -> 2018 | L32: =+K32+1 -> 2019 | M32: =+L32+1 -> 2020 | N32: =+M32+1 -> 2021 | O32: =+N32+1 -> 2022 | ... Q32: =+P32+1 -> 2024 | R32: ="CAGR "&$G$4&" - "&$Q$4 -> CAGR 2014 - 2024
B34: =+$B$6 -> ANALOG DEVICES, INC. | G34: — | H34: — | I34: — | J34: — | K34: — | L34: — | M34: — | N34: — | O34: 1109 | P34: 833 | Q34: — | R34: =IFERROR((Q34/G34)^(1/COUNT($G$4:$Q$4))-1,"")
