Workbook
Name COOLFUCNTION: _xlfn.LAMBDA(_xldudf_BOARDFLARE_EXEC("workbook-settings:coolfucntion"))
Name COOLFUCNTION: _xlfn.LAMBDA(_xldudf_BOARDFLARE_EXEC("workbook-settings:coolfucntion"))
Name COOLFUCNTION: _xlfn.LAMBDA(_xldudf_BOARDFLARE_EXEC("workbook-settings:coolfucntion"))
Name COOLFUCNTION: _xlfn.LAMBDA(_xldudf_BOARDFLARE_EXEC("workbook-settings:coolfucntion"))
Name COOLFUCNTION: _xlfn.LAMBDA(_xldudf_BOARDFLARE_EXEC("workbook-settings:coolfucntion"))
Name COOLFUCNTION: _xlfn.LAMBDA(_xldudf_BOARDFLARE_EXEC("workbook-settings:coolfucntion"))
Name COOLFUCNTION: _xlfn.LAMBDA(_xldudf_BOARDFLARE_EXEC("workbook-settings:coolfucntion"))
Name COOLFUCNTION: _xlfn.LAMBDA(_xldudf_BOARDFLARE_EXEC("workbook-settings:coolfucntion"))
Name COOLFUCNTION: _xlfn.LAMBDA(_xldudf_BOARDFLARE_EXEC("workbook-settings:coolfucntion"))
Name COOLFUCNTION: _xlfn.LAMBDA(_xldudf_BOARDFLARE_EXEC("workbook-settings:coolfucntion"))
Name Sectors: #REF!
Name Sectors: #REF!
Name Sectors: #REF!

Sheet Summary
E2: | EQUITY RESEARCH | U2: Lisbon Investment Society Equity Research
U3: March XX, 2025
D6: {=+_FV(DCF!R4,"Name")} -> D-WAVE QUANTUM INC. | U6: Hold
U8: EXCHANGE:(TICKER)
U9: {=+"Price (7 Mar 25): $"&_FV(DCF!$R$4,"Price")} -> Price (7 Mar 25): $24,7
D10: Investment Thesis | U10: ="Price Target: $" & ROUND(IF(Summary!G25="FCFF",DCF!Q207,IF(Summary!G25="FCFE",DCF!Q250,IF(Summary!G25="Tax Shield",DCF!Q223,DCF!Q266))),2) &" "&IF(Summary!G25="FCFF","(FCFF)",IF(Summary!G25="FCFE","(FCFE)",IF(Summary!G25="Tax Shield","(APV)","(DDM)"))) -> Price Target: $0 (FCFF)
U11: =+"Upside (Downside): "&ROUND((DCF!$Q$210*100),2)&"%" -> Upside (Downside): 0%
U14: =+Industry!E28&", "&ESG!C9 -> Canada,
U15: =+ESG!C10 -> 0
D17: Operating Metrics | F17: 2023 | G17: =+F17+1 -> 2024 | H17: =+G17+1 -> 2025 | I17: =+H17+1 -> 2026 | K17: Valuation Multiples | N17: 2022 | O17: =+N17+1 -> 2023 | P17: =+O17+1 -> 2024 | Q17: =+P17+1 -> 2025 | R17: =+Q17+1 -> 2026 | U17: Team Leader
K18: EV / Sales | N18: =IFERROR(_xlfn.XLOOKUP($K18,Multiples!$B:$B,Multiples!N:N),"") -> 24.922219 | O18: =IFERROR(_xlfn.XLOOKUP($K18,Multiples!$B:$B,Multiples!O:O),"") -> 10.296131 | P18: =IFERROR(_xlfn.XLOOKUP($K18,Multiples!$B:$B,Multiples!P:P),"") -> 167.01944 | Q18: =IFERROR(_xlfn.XLOOKUP($K18,Multiples!$B:$B,Multiples!Q:Q),"") -> 816.67187 | R18: =IFERROR(_xlfn.XLOOKUP($K18,Multiples!$B:$B,Multiples!R:R),"") -> 1811.9274 | U18: email
K19: Price / Sales | N19: =IFERROR(_xlfn.XLOOKUP($K19,Multiples!$B:$B,Multiples!N:N),"") -> 24.35328 | O19: =IFERROR(_xlfn.XLOOKUP($K19,Multiples!$B:$B,Multiples!O:O),"") -> 13.867152 | P19: =IFERROR(_xlfn.XLOOKUP($K19,Multiples!$B:$B,Multiples!P:P),"") -> 182.83489 | Q19: =IFERROR(_xlfn.XLOOKUP($K19,Multiples!$B:$B,Multiples!Q:Q),"") -> 0 | R19: =IFERROR(_xlfn.XLOOKUP($K19,Multiples!$B:$B,Multiples!R:R),"") -> 0 | U19: (+351) 999 999 999
K20: EV / EBITDA | N20: =IFERROR(_xlfn.XLOOKUP($K20,Multiples!$B:$B,Multiples!N:N),"") -> -3.1294018 | O20: =IFERROR(_xlfn.XLOOKUP($K20,Multiples!$B:$B,Multiples!O:O),"") -> -1.1955706 | P20: =IFERROR(_xlfn.XLOOKUP($K20,Multiples!$B:$B,Multiples!P:P),"") -> -21.275732 | Q20: =IFERROR(_xlfn.XLOOKUP($K20,Multiples!$B:$B,Multiples!Q:Q),"") -> -139.41592 | R20: =IFERROR(_xlfn.XLOOKUP($K20,Multiples!$B:$B,Multiples!R:R),"") -> -390.87 | U20: Analyst 1
K21: EV / EBIT | N21: =IFERROR(_xlfn.XLOOKUP($K21,Multiples!$B:$B,Multiples!N:N),"") -> 22.345885 | O21: =IFERROR(_xlfn.XLOOKUP($K21,Multiples!$B:$B,Multiples!O:O),"") -> -1.1670228 | P21: =IFERROR(_xlfn.XLOOKUP($K21,Multiples!$B:$B,Multiples!P:P),"") -> -20.255002 | Q21: =IFERROR(_xlfn.XLOOKUP($K21,Multiples!$B:$B,Multiples!Q:Q),"") -> -139.41592 | R21: =IFERROR(_xlfn.XLOOKUP($K21,Multiples!$B:$B,Multiples!R:R),"") -> -390.87 | U21: email
K22: Price / Earnings | N22: =IFERROR(_xlfn.XLOOKUP($K22,Multiples!$B:$B,Multiples!N:N),"") -> -3.2528785 | O22: =IFERROR(_xlfn.XLOOKUP($K22,Multiples!$B:$B,Multiples!O:O),"") -> -1.4682768 | P22: =IFERROR(_xlfn.XLOOKUP($K22,Multiples!$B:$B,Multiples!P:P),"") -> -11.21695 | Q22: =IFERROR(_xlfn.XLOOKUP($K22,Multiples!$B:$B,Multiples!Q:Q),"") -> 0 | R22: =IFERROR(_xlfn.XLOOKUP($K22,Multiples!$B:$B,Multiples!R:R),"") -> 0 | U22: (+351) 999 999 999
K23: Price / Book | N23: =IFERROR(_xlfn.XLOOKUP($K23,Multiples!$B:$B,Multiples!N:N),"") -> -5.9289984 | O23: =IFERROR(_xlfn.XLOOKUP($K23,Multiples!$B:$B,Multiples!O:O),"") -> -4.9609297 | P23: =IFERROR(_xlfn.XLOOKUP($K23,Multiples!$B:$B,Multiples!P:P),"") -> 25.761958 | Q23: =IFERROR(_xlfn.XLOOKUP($K23,Multiples!$B:$B,Multiples!Q:Q),"") -> 0 | R23: =IFERROR(_xlfn.XLOOKUP($K23,Multiples!$B:$B,Multiples!R:R),"") -> 0 | U23: Analyst 2
U24: email
D25: Year | E25: Net Sales | F25: EBIT Margin | G25: FCFF | H25: =+IF(Summary!$G$25="FCFF",DCF!AB6,IF(Summary!$G$25="FCFE",DCF!AC6,DCF!AD6)) -> NOPAT | I25: Net Capex | K25: Profitability Ratios | N25: 2022 | O25: =+N25+1 -> 2023 | P25: =+O25+1 -> 2024 | Q25: =+P25+1 -> 2025 | R25: =+Q25+1 -> 2026 | U25: (+351) 999 999 999
D26: 2022 | E26: =+DCF!E28 -> 7.173 | F26: =+DCF!E58 -> 1.1152935 | G26: =+INDEX(DCF!X7:AA7,MATCH(Summary!$G$25,{"FCFF","FCFE","Tax Shield","Total Payout"},0)) -> 22.096 | H26: =+IF(Summary!$G$25="FCFF",DCF!AB7,IF(Summary!$G$25="FCFE",DCF!AC7,DCF!AD7)) -> 8 | I26: =+DCF!E132 -> -0.423 | K26: Return on Assets | N26: =IFERROR(_xlfn.XLOOKUP($K26,Multiples!$B:$B,Multiples!N:N),"") -> -1.9928749 | O26: =IFERROR(_xlfn.XLOOKUP($K26,Multiples!$B:$B,Multiples!O:O),"") -> -1.3935407 | P26: =IFERROR(_xlfn.XLOOKUP($K26,Multiples!$B:$B,Multiples!P:P),"") -> -0.71992414 | Q26: =IFERROR(_xlfn.XLOOKUP($K26,Multiples!$B:$B,Multiples!Q:Q),"") -> -0.49141907 | R26: =IFERROR(_xlfn.XLOOKUP($K26,Multiples!$B:$B,Multiples!R:R),"") -> -0.68204232 | U26: Analyst 3
D27: =+D26+1 -> 2023 | E27: =+DCF!F28 -> 8.758 | F27: =+DCF!F58 -> -8.8225622 | G27: =+INDEX(DCF!X8:AA8,MATCH(Summary!$G$25,{"FCFF","FCFE","Tax Shield","Total Payout"},0)) -> -56.785 | H27: =+IF(Summary!$G$25="FCFF",DCF!AB8,IF(Summary!$G$25="FCFE",DCF!AC8,DCF!AD8)) -> -77.268 | I27: =+DCF!F132 -> -0.583 | K27: Return on Equity | N27: =IFERROR(_xlfn.XLOOKUP($K27,Multiples!$B:$B,Multiples!N:N),"") -> 1.8226929 | O27: =IFERROR(_xlfn.XLOOKUP($K27,Multiples!$B:$B,Multiples!O:O),"") -> 3.3787427 | P27: =IFERROR(_xlfn.XLOOKUP($K27,Multiples!$B:$B,Multiples!P:P),"") -> -2.2966989 | Q27: =IFERROR(_xlfn.XLOOKUP($K27,Multiples!$B:$B,Multiples!Q:Q),"") -> 0.011408475 | R27: =IFERROR(_xlfn.XLOOKUP($K27,Multiples!$B:$B,Multiples!R:R),"") -> 0.015833864 | U27: email
D28: =+D27+1 -> 2024 | E28: =+DCF!G28 -> 8.827 | F28: =+DCF!G58 -> -8.2458366 | G28: =+INDEX(DCF!X9:AA9,MATCH(Summary!$G$25,{"FCFF","FCFE","Tax Shield","Total Payout"},0)) -> -36.726 | H28: =+IF(Summary!$G$25="FCFF",DCF!AB9,IF(Summary!$G$25="FCFE",DCF!AC9,DCF!AD9)) -> -72.786 | I28: =+DCF!G132 -> -2.395 | K28: Return on Total Capital | N28: =IFERROR(_xlfn.XLOOKUP($K28,Multiples!$B:$B,Multiples!N:N),"") -> -0.43675274 | O28: =IFERROR(_xlfn.XLOOKUP($K28,Multiples!$B:$B,Multiples!O:O),"") -> 5.3476365 | P28: =IFERROR(_xlfn.XLOOKUP($K28,Multiples!$B:$B,Multiples!P:P),"") -> -0.72048939 | Q28: =IFERROR(_xlfn.XLOOKUP($K28,Multiples!$B:$B,Multiples!Q:Q),"") -> 0.0087592764 | R28: =IFERROR(_xlfn.XLOOKUP($K28,Multiples!$B:$B,Multiples!R:R),"") -> 0.011116745 | U28: (+351) 999 999 999
D29: =+D28+1 -> 2025 | E29: =+DCF!H28 -> 14.1232 | F29: =+DCF!H58 -> -5.8578094 | G29: =+INDEX(DCF!X10:AA10,MATCH(Summary!$G$25,{"FCFF","FCFE","Tax Shield","Total Payout"},0)) -> -70.28795 | H29: =+IF(Summary!$G$25="FCFF",DCF!AB10,IF(Summary!$G$25="FCFE",DCF!AC10,DCF!AD10)) -> -82.731013 | I29: =+DCF!H132 -> 0 | K29: EBITDA Margin | N29: =IFERROR(_xlfn.XLOOKUP($K29,Multiples!$B:$B,Multiples!N:N),"") -> -7.9638924 | O29: =IFERROR(_xlfn.XLOOKUP($K29,Multiples!$B:$B,Multiples!O:O),"") -> -8.6118977 | P29: =IFERROR(_xlfn.XLOOKUP($K29,Multiples!$B:$B,Multiples!P:P),"") -> -7.8502322 | Q29: =IFERROR(_xlfn.XLOOKUP($K29,Multiples!$B:$B,Multiples!Q:Q),"") -> -5.8578094 | R29: =IFERROR(_xlfn.XLOOKUP($K29,Multiples!$B:$B,Multiples!R:R),"") -> -4.6356267
D30: =+D29+1 -> 2026 | E30: =+DCF!I28 -> 22.59712 | F30: =+DCF!I58 -> -4.6356267 | G30: =+INDEX(DCF!X11:AA11,MATCH(Summary!$G$25,{"FCFF","FCFE","Tax Shield","Total Payout"},0)) -> -83.004918 | H30: =+IF(Summary!$G$25="FCFF",DCF!AB11,IF(Summary!$G$25="FCFE",DCF!AC11,DCF!AD11)) -> -104.75181 | I30: =+DCF!I132 -> 0 | K30: EBIT Margin | N30: =IFERROR(_xlfn.XLOOKUP($K30,Multiples!$B:$B,Multiples!N:N),"") -> 1.1152935 | O30: =IFERROR(_xlfn.XLOOKUP($K30,Multiples!$B:$B,Multiples!O:O),"") -> -8.8225622 | P30: =IFERROR(_xlfn.XLOOKUP($K30,Multiples!$B:$B,Multiples!P:P),"") -> -8.2458366 | Q30: =IFERROR(_xlfn.XLOOKUP($K30,Multiples!$B:$B,Multiples!Q:Q),"") -> -5.8578094 | R30: =IFERROR(_xlfn.XLOOKUP($K30,Multiples!$B:$B,Multiples!R:R),"") -> -4.6356267 | U30: Statistics
D31: =+D30+1 -> 2027 | E31: =+DCF!J28 -> 36.155392 | F31: =+DCF!J58 -> -3.6759376 | G31: =+INDEX(DCF!X12:AA12,MATCH(Summary!$G$25,{"FCFF","FCFE","Tax Shield","Total Payout"},0)) -> -108.3403 | H31: =+IF(Summary!$G$25="FCFF",DCF!AB12,IF(Summary!$G$25="FCFE",DCF!AC12,DCF!AD12)) -> -132.90496 | I31: =+DCF!J132 -> 0 | K31: Gross Profit Margin | N31: =IFERROR(_xlfn.XLOOKUP($K31,Multiples!$B:$B,Multiples!N:N),"") -> 0.59249965 | O31: =IFERROR(_xlfn.XLOOKUP($K31,Multiples!$B:$B,Multiples!O:O),"") -> 0.52774606 | P31: =IFERROR(_xlfn.XLOOKUP($K31,Multiples!$B:$B,Multiples!P:P),"") -> 0.63022544 | Q31: =IFERROR(_xlfn.XLOOKUP($K31,Multiples!$B:$B,Multiples!Q:Q),"") -> 0.6 | R31: =IFERROR(_xlfn.XLOOKUP($K31,Multiples!$B:$B,Multiples!R:R),"") -> 0.6 | U31: Beta | V31: =Peers!D74 -> 1.4737
D32: =+D31+1 -> 2028 | E32: =+DCF!K28 -> 57.848627 | F32: =+DCF!K58 -> -2.9140843 | G32: =+INDEX(DCF!X14:AA14,MATCH(Summary!$G$25,{"FCFF","FCFE","Tax Shield","Total Payout"},0)) -> -146.4819 | H32: =+IF(Summary!$G$25="FCFF",DCF!AB14,IF(Summary!$G$25="FCFE",DCF!AC14,DCF!AD14)) -> -168.57578 | I32: =+DCF!K132 -> 0 | K32: SG&A Margin | N32: =IFERROR(_xlfn.XLOOKUP($K32,Multiples!$B:$B,Multiples!N:N),"") -> 4.4063851 | O32: =IFERROR(_xlfn.XLOOKUP($K32,Multiples!$B:$B,Multiples!O:O),"") -> 5.3996346 | P32: =IFERROR(_xlfn.XLOOKUP($K32,Multiples!$B:$B,Multiples!P:P),"") -> 5.3796307 | Q32: =IFERROR(_xlfn.XLOOKUP($K32,Multiples!$B:$B,Multiples!Q:Q),"") -> 3 | R32: =IFERROR(_xlfn.XLOOKUP($K32,Multiples!$B:$B,Multiples!R:R),"") -> 2 | U32: % Float | V32: =+Peers!D73 -> 0.959
D33: =+D32+1 -> 2029 | E33: =+DCF!L28 -> 92.557804 | F33: =+DCF!L58 -> -2.1042317 | G33: =+INDEX(DCF!X15:AA15,MATCH(Summary!$G$25,{"FCFF","FCFE","Tax Shield","Total Payout"},0)) -> -171.10265 | H33: =+IF(Summary!$G$25="FCFF",DCF!AB15,IF(Summary!$G$25="FCFE",DCF!AC15,DCF!AD15)) -> -194.76307 | I33: =+DCF!L132 -> 0 | K33: Net Income Margin | N33: =IFERROR(_xlfn.XLOOKUP($K33,Multiples!$B:$B,Multiples!N:N),"") -> -7.4866862 | O33: =IFERROR(_xlfn.XLOOKUP($K33,Multiples!$B:$B,Multiples!O:O),"") -> -9.4445079 | P33: =IFERROR(_xlfn.XLOOKUP($K33,Multiples!$B:$B,Multiples!P:P),"") -> -16.299875 | Q33: =IFERROR(_xlfn.XLOOKUP($K33,Multiples!$B:$B,Multiples!Q:Q),"") -> -7.7556772 | R33: =IFERROR(_xlfn.XLOOKUP($K33,Multiples!$B:$B,Multiples!R:R),"") -> -6.7275829 | U33: % Held by Insiders | V33: =+Peers!D76 -> 0.0176
U34: % Held by Institutions | V34: =+Peers!D77 -> 0.1936
D35: SWOT Analysis | K35: Liquidity Ratios | N35: 2022 | O35: =+N35+1 -> 2023 | P35: =+O35+1 -> 2024 | Q35: =+P35+1 -> 2025 | R35: =+Q35+1 -> 2026 | U35: Short % of Float | V35: =+Peers!D78 -> 0.231
D36: Strengths | G36: Weaknesses | K36: Cash Ratio | N36: =IFERROR(_xlfn.XLOOKUP($K36,Multiples!$B:$B,Multiples!N:N),"") -> 0.44046135 | O36: =IFERROR(_xlfn.XLOOKUP($K36,Multiples!$B:$B,Multiples!O:O),"") -> 3.6717333 | P36: =IFERROR(_xlfn.XLOOKUP($K36,Multiples!$B:$B,Multiples!P:P),"") -> 5.90413 | Q36: =IFERROR(_xlfn.XLOOKUP($K36,Multiples!$B:$B,Multiples!Q:Q),"") -> 6.1449261 | R36: =IFERROR(_xlfn.XLOOKUP($K36,Multiples!$B:$B,Multiples!R:R),"") -> 4.2334192 | W36: 120.87
D37: Strong partnerships; Strategic facilities in North America; Business model transformation; Innovative partnerships; Intellectual property access; Improved financial position. | G37: History of net losses and expectation of continued financial losses; Dependence on securing additional financing to continue operations; Identified material weakness in internal control over financial reporting, leading to restatements; Risk of failure to secure or protect intellectual property, affecting competitive position; Obligations under government-funded IP development may limit asset flexibility; Anti-takeover provisions may limit shareholder influence and takeover opportunitie; Challenges in scaling supply chain, retaining talent, and maintaining equipment | K37: Quick Ratio | N37: =IFERROR(_xlfn.XLOOKUP($K37,Multiples!$B:$B,Multiples!N:N),"") -> 0.48765586 | O37: =IFERROR(_xlfn.XLOOKUP($K37,Multiples!$B:$B,Multiples!O:O),"") -> 3.8185778 | P37: =IFERROR(_xlfn.XLOOKUP($K37,Multiples!$B:$B,Multiples!P:P),"") -> 5.9512357 | Q37: =IFERROR(_xlfn.XLOOKUP($K37,Multiples!$B:$B,Multiples!Q:Q),"") -> 6.21416 | R37: =IFERROR(_xlfn.XLOOKUP($K37,Multiples!$B:$B,Multiples!R:R),"") -> 4.3554515 | U37: Major Holders | W37: 113.63
K38: Current Ratio | N38: =IFERROR(_xlfn.XLOOKUP($K38,Multiples!$B:$B,Multiples!N:N),"") -> 0.86814214 | O38: =IFERROR(_xlfn.XLOOKUP($K38,Multiples!$B:$B,Multiples!O:O),"") -> 4.1818667 | P38: =IFERROR(_xlfn.XLOOKUP($K38,Multiples!$B:$B,Multiples!P:P),"") -> 6.1383314 | Q38: =IFERROR(_xlfn.XLOOKUP($K38,Multiples!$B:$B,Multiples!Q:Q),"") -> 6.4917593 | R38: =IFERROR(_xlfn.XLOOKUP($K38,Multiples!$B:$B,Multiples!R:R),"") -> 6.4917593 | U38: Public Sector Pension Investment Board | V38: 0.1375
U39: Blackrock Inc. | V39: 0.0296
D40: Opportunities | G40: Threats | K40: Cash Flow Ratios | N40: 2022 | O40: =+N40+1 -> 2023 | P40: =+O40+1 -> 2024 | Q40: =+P40+1 -> 2025 | R40: =+Q40+1 -> 2026 | U40: Vanguard Group Inc | V40: 0.0244
D41: Growing global demand for quantum computing solutions across both private and public sectors; Unique positioning to deliver real-world applications with measurable value through annealing-based optimization; Future expansion into high-impact fields like generative AI, machine learning; increasing adoption of QCaaS (Quantum Computing as a Service) via the Leap™ platform, offering scalability and real-time access; Growing industry acknowledgment of quantum computing’s commercial viability in the near term (12–18 months) | G41: Uncertainty around meeting Term Loan conditions and covenants, despite current compliance; Material weakness in internal controls over financial reporting due to insufficient accounting expertise; Exposure to stock market volatility as a NYSE-listed company, including fluctuations in price and trading volume; Risks linked to government contracts, including audits, sanctions, early termination, and strict compliance requirements; Ongoing cybersecurity threats, including potential data breaches and system disruptions; Possibility of becoming a "controlled company" under NYSE rules, which could reduce transparency and weaken corporate governance standards | K41: Cash Conversion Cycle | N41: =IFERROR(_xlfn.XLOOKUP($K41,Multiples!$B:$B,Multiples!N:N),"") -> 121.61336 | O41: =IFERROR(_xlfn.XLOOKUP($K41,Multiples!$B:$B,Multiples!O:O),"") -> 191.17594 | P41: =IFERROR(_xlfn.XLOOKUP($K41,Multiples!$B:$B,Multiples!P:P),"") -> 213.5556 | Q41: =IFERROR(_xlfn.XLOOKUP($K41,Multiples!$B:$B,Multiples!Q:Q),"") -> 40.898488 | R41: =IFERROR(_xlfn.XLOOKUP($K41,Multiples!$B:$B,Multiples!R:R),"") -> 106.62456 | U41: UBS Group AG | V41: 0.0149
K42: Net Income / Op Cash Flow | N42: =IFERROR(_xlfn.XLOOKUP($K42,Multiples!$B:$B,Multiples!N:N),"") -> 1.1874143 | O42: =IFERROR(_xlfn.XLOOKUP($K42,Multiples!$B:$B,Multiples!O:O),"") -> 1.3638312 | P42: =IFERROR(_xlfn.XLOOKUP($K42,Multiples!$B:$B,Multiples!P:P),"") -> 3.3740356 | Q42: =IFERROR(_xlfn.XLOOKUP($K42,Multiples!$B:$B,Multiples!Q:Q),"") -> 1.6521533 | R42: =IFERROR(_xlfn.XLOOKUP($K42,Multiples!$B:$B,Multiples!R:R),"") -> 1.9041722 | U42: State Street Corporation | V42: 0.0106
K43: Chg in Cash / Op Cash Flow | N43: =IFERROR(_xlfn.XLOOKUP($K43,Multiples!$B:$B,Multiples!N:N),"") -> 0.053464821 | O43: =IFERROR(_xlfn.XLOOKUP($K43,Multiples!$B:$B,Multiples!O:O),"") -> -0.56459299 | P43: =IFERROR(_xlfn.XLOOKUP($K43,Multiples!$B:$B,Multiples!P:P),"") -> -3.2050512 | Q43: =IFERROR(_xlfn.XLOOKUP($K43,Multiples!$B:$B,Multiples!Q:Q),"") -> -0.18604821 | R43: =IFERROR(_xlfn.XLOOKUP($K43,Multiples!$B:$B,Multiples!R:R),"") -> 0.74152459 | U43: Geode Capital Management, LLC | V43: 0.0102
U44: Penserra Capital Management LLC | V44: 0.0097
D45: Revenue by Region | G45: Revenue by Segment | K45: Leverage Ratios | N45: 2022 | O45: =+N45+1 -> 2023 | P45: =+O45+1 -> 2024 | Q45: =+P45+1 -> 2025 | R45: =+Q45+1 -> 2026 | U45: Millennium Management Llc | V45: 0.0095
K46: Total Debt / Equity | N46: =IFERROR(_xlfn.XLOOKUP($K46,Multiples!$B:$B,Multiples!N:N),"") -> -378.30499 | O46: =IFERROR(_xlfn.XLOOKUP($K46,Multiples!$B:$B,Multiples!O:O),"") -> -409.78718 | P46: =IFERROR(_xlfn.XLOOKUP($K46,Multiples!$B:$B,Multiples!P:P),"") -> 612.60096 | Q46: =IFERROR(_xlfn.XLOOKUP($K46,Multiples!$B:$B,Multiples!Q:Q),"") -> -0.0073442844 | R46: =IFERROR(_xlfn.XLOOKUP($K46,Multiples!$B:$B,Multiples!R:R),"") -> -0.016272381 | U46: Bank of America Corporation | V46: 0.0087
K47: Total Debt / Capital | N47: =IFERROR(_xlfn.XLOOKUP($K47,Multiples!$B:$B,Multiples!N:N),"") -> 1.0026504 | O47: =IFERROR(_xlfn.XLOOKUP($K47,Multiples!$B:$B,Multiples!O:O),"") -> 1.0024463 | P47: =IFERROR(_xlfn.XLOOKUP($K47,Multiples!$B:$B,Multiples!P:P),"") -> 0.99837028 | Q47: =IFERROR(_xlfn.XLOOKUP($K47,Multiples!$B:$B,Multiples!Q:Q),"") -> -0.007398622 | R47: =IFERROR(_xlfn.XLOOKUP($K47,Multiples!$B:$B,Multiples!R:R),"") -> -0.016541551 | U47: Unicom Systems, Inc. | V47: 0.0083
...

Sheet Segments
B2: Segments | C2: (in thousands)
B4: Regions | D4: Weight | E4: 2020 | F4: =+E4+1 -> 2021 | G4: =+F4+1 -> 2022 | H4: =+G4+1 -> 2023 | I4: =+H4+1 -> 2024 | J4: ="CAGR "&$E$4&" - "&$I$4 -> CAGR 2020 - 2024 | K4: 2021 | L4: =+K4+1 -> 2022 | M4: =+L4+1 -> 2023 | N4: =+M4+1 -> 2024
B6: United States | D6: =IFERROR(I6/SUM($I$6:$I$12),"") -> 0.24368415 | E6: 3119 | F6: 3425 | G6: 3342 | H6: 3325 | I6: 2151 | J6: =IFERROR((I6/E6)^(1/COUNT($E$4:$I$4))-1,"") -> -0.071621643 | K6: =IFERROR((F6-E6)/E6,"") -> 0.098108368 | L6: =IFERROR((G6-F6)/F6,"") -> -0.024233577 | M6: =IFERROR((H6-G6)/G6,"") -> -0.0050867744 | N6: =IFERROR((I6-H6)/H6,"") -> -0.35308271
B7: Germany | D7: =IFERROR(I7/SUM($I$6:$I$12),"") -> 0.21456894 | E7: 155 | F7: 741 | G7: 1150 | H7: 1268 | I7: 1894 | J7: =IFERROR((I7/E7)^(1/COUNT($E$4:$I$4))-1,"") -> 0.64971778 | K7: =IFERROR((F7-E7)/E7,"") -> 3.7806452 | L7: =IFERROR((G7-F7)/F7,"") -> 0.55195682 | M7: =IFERROR((H7-G7)/G7,"") -> 0.1026087 | N7: =IFERROR((I7-H7)/H7,"") -> 0.49369085
B8: Japan | D8: =IFERROR(I8/SUM($I$6:$I$12),"") -> 0.12835618 | E8: 1630 | F8: 1614 | G8: 1241 | H8: 909 | I8: 1133 | J8: =IFERROR((I8/E8)^(1/COUNT($E$4:$I$4))-1,"") -> -0.070159494 | K8: =IFERROR((F8-E8)/E8,"") -> -0.0098159509 | L8: =IFERROR((G8-F8)/F8,"") -> -0.23110285 | M8: =IFERROR((H8-G8)/G8,"") -> -0.26752619 | N8: =IFERROR((I8-H8)/H8,"") -> 0.24642464
B9: Canada | D9: =IFERROR(I9/SUM($I$6:$I$12),"") -> 0.12473094 | E9: N/A | F9: N/A | G9: N/A | H9: N/A | I9: 1101 | J9: =IFERROR((I9/E9)^(1/COUNT($E$4:$I$4))-1,"") | K9: =IFERROR(F9-E9/E9,"") | L9: =IFERROR(G9-F9/F9,"") | M9: =IFERROR(H9-G9/G9,"") | N9: =IFERROR((I9-H9)/H9,"")
B10: Other | D10: =IFERROR(I10/SUM($I$6:$I$12),"") -> 0.28865979 | E10: 256 | F10: 499 | G10: 1440 | H10: 3256 | I10: 2548 | J10: =IFERROR((I10/E10)^(1/COUNT($E$4:$I$4))-1,"") -> 0.58340456 | K10: =IFERROR((F10-E10)/E10,"") -> 0.94921875 | L10: =IFERROR((G10-F10)/F10,"") -> 1.8857715 | M10: =IFERROR((H10-G10)/G10,"") -> 1.2611111 | N10: =IFERROR((I10-H10)/H10,"") -> -0.21744472
B11: - | D11: =IFERROR(I11/SUM($I$6:$I$12),"") -> 0
B12: - | D12: =IFERROR(I12/SUM($I$6:$I$12),"") -> 0
B13: Total | D13: =SUM(D6:D12) -> 1 | E13: =SUM(E6:E10) -> 5160 | F13: =SUM(F6:F10) -> 6279 | G13: =SUM(G6:G10) -> 7173 | H13: =SUM(H6:H10) -> 8758 | I13: =SUM(I6:I10) -> 8827 | J13: =IFERROR((I13/G13)^(1/COUNT($G$4:$I$4))-1,"") -> 0.071611664 | K13: =IFERROR(F13-E13/E13,"") -> 6278 | L13: =IFERROR(G13-F13/F13,"") -> 7172 | M13: =IFERROR((H13-G13)/G13,"") -> 0.22096752 | N13: =IFERROR((I13-H13)/H13,"") -> 0.0078785111
B15: Segments | D15: Weight | E15: 2020 | F15: =+E15+1 -> 2021 | G15: =+F15+1 -> 2022 | H15: =+G15+1 -> 2023 | I15: =+H15+1 -> 2024 | J15: ="CAGR "&$E$4&" - "&$I$4 -> CAGR 2020 - 2024 | K15: 2021 | L15: =+K15+1 -> 2022 | M15: =+L15+1 -> 2023 | N15: =+M15+1 -> 2024
B17: QCaaS | D17: =IFERROR(I17/SUM($I$17:$I$21),"") -> 0.76413277 | E17: 4313 | F17: 4424 | G17: 5616 | H17: 4895 | I17: 6745 | J17: =IFERROR((I17/E17)^(1/COUNT($E$4:$I$4))-1,"") -> 0.093554669 | K17: =IFERROR((F17-E17)/E17,"") -> 0.025736147 | L17: =IFERROR((G17-F17)/F17,"") -> 0.26943942 | M17: =IFERROR((H17-G17)/G17,"") -> -0.12838319 | N17: =IFERROR((I17-H17)/H17,"") -> 0.37793667
B18: Professional services | D18: =IFERROR(I18/SUM($I$17:$I$21),"") -> 0.21955364 | E18: 426 | F18: 1786 | G18: 1478 | H18: 3816 | I18: 1938 | J18: =IFERROR((I18/E18)^(1/COUNT($E$4:$I$4))-1,"") -> 0.353907 | K18: =IFERROR((F18-E18)/E18,"") -> 3.1924883 | L18: =IFERROR((G18-F18)/F18,"") -> -0.17245241 | M18: =IFERROR((H18-G18)/G18,"") -> 1.5818674 | N18: =IFERROR((I18-H18)/H18,"") -> -0.49213836
B19: Other | D19: =IFERROR(I19/SUM($I$17:$I$21),"") -> 0.016313583 | E19: 421 | F19: 69 | G19: 79 | H19: 47 | I19: 144 | J19: =IFERROR((I19/E19)^(1/COUNT($E$4:$I$4))-1,"") -> -0.19310676 | K19: =IFERROR((F19-E19)/E19,"") -> -0.83610451 | L19: =IFERROR((G19-F19)/F19,"") -> 0.14492754 | M19: =IFERROR((H19-G19)/G19,"") -> -0.40506329 | N19: =IFERROR((I19-H19)/H19,"") -> 2.0638298
D20: =IFERROR(I20/SUM($I$17:$I$21),"") -> 0 | J20: =IFERROR((I20/E20)^(1/COUNT($E$4:$I$4))-1,"") | K20: =IFERROR((F20-E20)/E20,"") | L20: =IFERROR((G20-F20)/F20,"") | M20: =IFERROR((H20-G20)/G20,"") | N20: =IFERROR((I20-H20)/H20,"")
D21: =IFERROR(I21/SUM($I$17:$I$21),"") -> 0 | J21: =IFERROR((I21/E21)^(1/COUNT($E$4:$I$4))-1,"") | K21: =IFERROR((F21-E21)/E21,"") | L21: =IFERROR((G21-F21)/F21,"") | M21: =IFERROR((H21-G21)/G21,"") | N21: =IFERROR((I21-H21)/H21,"")
B22: Total | D22: =SUM(D17:D21) -> 1 | E22: =SUM(E17:E21) -> 5160 | F22: =SUM(F17:F21) -> 6279 | G22: =SUM(G17:G21) -> 7173 | H22: =SUM(H17:H21) -> 8758 | I22: =SUM(I17:I21) -> 8827 | J22: =IFERROR((I22/E22)^(1/COUNT($E$4:$I$4))-1,"") -> 0.11335249 | K22: =IFERROR((F22-E22)/E22,"") -> 0.21686047 | L22: =IFERROR((G22-F22)/F22,"") -> 0.14237936 | M22: =IFERROR((H22-G22)/G22,"") -> 0.22096752 | N22: =IFERROR((I22-H22)/H22,"") -> 0.0078785111
B24: Categories | D24: Description | J24: Graphs
B26: QCaaS | D26: QCaaS stands for Quantum Computing as a Service and it provides cloud-based access to quantum computing resources, enabling users to run quantum algorithms without owning quantum hardware.
B27: Professional services | D27: This segment includes quantum consulting, custom algorithm development, and application integration. They also provide training, workshops, and technical support for leveraging quantum computing.
B28: Other | D28: This section often includes strategic partnerships, educational initiatives, and miscellaneous revenue streams. This covers collaborations, training programs, and experimental projects beyond core quantum products and services.
B29: =IF(B20=0,"",B20)
B30: =IF(B21=0,"",B21)
B32: Products | D32: Weight | E32: 2020 | F32: =+E32+1 -> 2021 | G32: =+F32+1 -> 2022 | H32: =+G32+1 -> 2023 | I32: =+H32+1 -> 2024 | J32: =I32+1 -> 2025 | K32: =+J32+1 -> 2026 | L32: =+K32+1 -> 2027 | M32: =+L32+1 -> 2028 | N32: =+M32+1 -> 2029 | O32: =+N32+1 -> 2030 | P32: =+O32+1 -> 2031 | Q32: =+P32+1 -> 2032 | R32: =+Q32+1 -> 2033 | ... T32: =+S32+1 -> 2035
B34: QCaaS | D34: =IFERROR(I34/$I$13,"") -> 0.76413277 | E34: =E17 -> 4313 | F34: =F17 -> 4424 | G34: =G17 -> 5616 | H34: =H17 -> 4895 | I34: =I17 -> 6745
B36: Professional services | D36: =IFERROR(I36/$I$13,"") -> 0.21955364 | E36: =E18 -> 426 | F36: =F18 -> 1786 | G36: =G18 -> 1478 | H36: =H18 -> 3816 | I36: =I18 -> 1938
D37: =IFERROR(I37/$I$13,"") -> -5.5753752e-05 | F37: =IFERROR((F36-E36)/E36,"") -> 3.1924883 | G37: =IFERROR((G36-F36)/F36,"") -> -0.17245241 | H37: =IFERROR((H36-G36)/G36,"") -> 1.5818674 | I37: =IFERROR((I36-H36)/H36,"") -> -0.49213836
B38: Product 3 | D38: =IFERROR(I38/$I$13,"") -> 0 | J38: =I38*(1+J39) -> 0 | K38: =J38*(1+K39) -> 0 | L38: =K38*(1+L39) -> 0 | M38: =L38*(1+M39) -> 0 | N38: =M38*(1+N39) -> 0 | O38: =N38*(1+O39) -> 0 | P38: =O38*(1+P39) -> 0 | Q38: =P38*(1+Q39) -> 0 | ... T38: =S38*(1+T39) -> 0
D39: =IFERROR(I39/$I$13,"") | F39: =IFERROR(F38-E38/E38,"") | G39: =IFERROR(G38-F38/F38,"") | H39: =IFERROR(H38-G38/G38,"") | I39: =IFERROR(I38-H38/H38,"")
B40: Product 4 | D40: =IFERROR(I40/$I$13,"") -> 0 | J40: =I40*(1+J41) -> 0 | K40: =J40*(1+K41) -> 0 | L40: =K40*(1+L41) -> 0 | M40: =L40*(1+M41) -> 0 | N40: =M40*(1+N41) -> 0 | O40: =N40*(1+O41) -> 0 | P40: =O40*(1+P41) -> 0 | Q40: =P40*(1+Q41) -> 0 | ... T40: =S40*(1+T41) -> 0
D41: =IFERROR(I41/$I$13,"") | F41: =IFERROR(F40-E40/E40,"") | G41: =IFERROR(G40-F40/F40,"") | H41: =IFERROR(H40-G40/G40,"") | I41: =IFERROR(I40-H40/H40,"")
B42: Product 5 | D42: =IFERROR(I42/$I$13,"") -> 0 | J42: =I42*(1+J43) -> 0 | K42: =J42*(1+K43) -> 0 | L42: =K42*(1+L43) -> 0 | M42: =L42*(1+M43) -> 0 | N42: =M42*(1+N43) -> 0 | O42: =N42*(1+O43) -> 0 | P42: =O42*(1+P43) -> 0 | Q42: =P42*(1+Q43) -> 0 | ... T42: =S42*(1+T43) -> 0
D43: =IFERROR(I43/$I$13,"") | F43: =IFERROR(F42-E42/E42,"") | G43: =IFERROR(G42-F42/F42,"") | H43: =IFERROR(H42-G42/G42,"") | I43: =IFERROR(I42-H42/H42,"")
B44: Other | D44: =IFERROR(I44/$I$13,"") -> 0.016313583 | E44: =E19 -> 421 | F44: =F19 -> 69 | G44: =G19 -> 79 | H44: =H19 -> 47 | I44: =I19 -> 144
B45: Total | D45: =SUM(D34:D44) -> 0.99994425 | E45: =SUM(E34:E42) -> 4739 | F45: =SUM(F34:F42) -> 6213.1925 | G45: =SUM(G34:G42) -> 7093.8275 | H45: =SUM(H34:H42) -> 8712.5819 | I45: =SUM(I34:I42) -> 8682.5079 | J45: =SUM(J34:J42) -> 0 | K45: =SUM(K34:K42) -> 0 | L45: =SUM(L34:L42) -> 0 | ... T45: =SUM(T34:T42) -> 0
B47: Company's Strategy / Extra Notes
B49: Expanding Quantum Computing Accessibility | D49: D-Wave provides cloud-based quantum services via their Leap™ platform, making quantum computing accessible to a broader range of users, including those without their own quantum hardware.
B50: Hybrid Quantum-Classical Solutions | D50: D-Wave has been pushing for hybrid solutions that combine quantum and classical computing to tackle complex problems that neither technology can handle alone, which is central to their business model.
B51: Partnerships and Collaborations | D51: D-Wave has formed collaborations with companies, academic institutions, and government entities to drive the adoption of quantum computing in various industries.
B52: Continuous Hardware Advancements | D52: D-Wave continues to improve their quantum annealing technology, focusing on increasing the size and capabilities of their quantum processors (like their Advantage system).

Sheet Industry
B2: Industry Overview
B4: Sales Growth Forecast | E4: Weight | F4: 2025 | G4: =+F4+1 -> 2026 | H4: =+G4+1 -> 2027 | I4: =+H4+1 -> 2028 | J4: =+I4+1 -> 2029 | K4: =+J4+1 -> 2030 | L4: =+K4+1 -> 2031 | M4: =+L4+1 -> 2032 | N4: =+M4+1 -> 2033 | ... P4: =+O4+1 -> 2035 | Q4: ="CAGR "&$F$4&" - "&$P$4 -> CAGR 2025 - 2035 | R4: Sources
B6: QCaaS | E6: 0.764 | Q6: 0.1938 | R6: Mordor Intelligence
B7: Professional Services | E7: 0.22 | Q7: 0
B11: Weighted Average | E11: =SUM(E6:E10) -> 0.984 | F11: =SUMPRODUCT(F6:F10,$E$6:$E$10) -> 0 | G11: =SUMPRODUCT(G6:G10,$E$6:$E$10) -> 0 | H11: =SUMPRODUCT(H6:H10,$E$6:$E$10) -> 0 | I11: =SUMPRODUCT(I6:I10,$E$6:$E$10) -> 0 | J11: =SUMPRODUCT(J6:J10,$E$6:$E$10) -> 0 | K11: =SUMPRODUCT(K6:K10,$E$6:$E$10) -> 0 | L11: =SUMPRODUCT(L6:L10,$E$6:$E$10) -> 0 | M11: =SUMPRODUCT(M6:M10,$E$6:$E$10) -> 0 | ... P11: =SUMPRODUCT(P6:P10,$E$6:$E$10) -> 0 | Q11: =IFERROR(((1+F11)*(1+G11)*(1+H11)*(1+I11)*(1+J11)*(1+K11)*(1+L11)*(1+M11)*(1+N11)*(1+O11)*(1+P11))^(1/COUNT($F$4:$P$4))-1,"") -> 0
B13: Key Drivers | E13: Description
B15: Advancements in Quantum Hardware | E15: Continuous improvements in qubit coherence, error correction, and scalability are driving the growth of quantum c
B16: Investment in Research and Development | E16: Both private companies (like D-Wave, IBM, Google) and governments are heavily investing in quantum computing R&D to unlock its potential for solving complex problems across industries.
B17: Hybrid Quantum-Classical Computing | E17: As pure quantum solutions are still maturing, hybrid systems that combine classical and quantum computing are becoming critical, enabling practical problem-solving with current technology.
B18: Quantum Software Development | E18: Progress in developing quantum algorithms, software tools, and quantum programming languages is vital for making quantum computing accessible and usable in various industries like cryptography, logistics, and pharmaceuticals.
B20: Industry Trends | E20: Description
B22: Increased Commercialization | E22: Companies are shifting from research-focused quantum solutions to commercial offerings, with platforms like D-Wave's Leap™ and IBM's Qiskit enabling businesses to access quantum computing as a service (QCaaS) for specific use cases.
B23: Government and Corporate Support | E23: Governments worldwide, particularly in the U.S., Europe, and China, are heavily funding quantum initiatives, recognizing the potential for quantum to revolutionize industries and national security (e.g., cryptography).
B26: Market Share | E26: Headquarters | G26: Revenues | H26: (in MM of USD) | I26: Market Share
B28: {=+_FV(DCF!R4,"Name")} -> D-WAVE QUANTUM INC. | E28: Canada | G28: 8.75 | I28: =IFERROR(G28/$G$40,"") -> 0.20325203
B29: IONQ INC. | E29: United States | G29: 22.04 | I29: =IFERROR(G29/$G$40,"") -> 0.51196283
B30: RIGETTI COMPUTING INC. | E30: United States | G30: 12 | I30: =IFERROR(G30/$G$40,"") -> 0.27874564
B31: QUANTUM COMPUTING INC. | E31: United States | G31: 0.3 | I31: =IFERROR(G31/$G$40,"") -> 0.0069686411
I32: =IFERROR(G32/$G$40,"") -> 0
I33: =IFERROR(G33/$G$40,"") -> 0
I34: =IFERROR(G34/$G$40,"") -> 0
I35: =IFERROR(G35/$G$40,"") -> 0
I36: =IFERROR(G36/$G$40,"") -> 0
I37: =IFERROR(G37/$G$40,"") -> 0
I38: =IFERROR(G38/$G$40,"") -> 0
B39: Others | E39: -- | G39: =G40-SUM(G28:G38) -> -0.04 | I39: =IFERROR(G39/$G$40,"") -> -0.00092915215
B40: Industry Size | E40: -- | G40: 43.05 | I40: 1
B42: Porter's Five Forces Analysis | E42: Rating | H42: Graph
B44: Threat of New Entrants | E44: 3.8
B45: Economies of scale | E45: 3
B46: Product differentiation | E46: 4
B47: Capital requirements | E47: 5
B48: Access to distribution channels | E48: 3
B49: Regulations | E49: 4
B50: Switching costs | E50: 3
B51: Bargaining Power of Suppliers | E51: 3.25
B52: Number of suppliers | E52: 4
B53: Uniqueness | E53: 3
B54: Switching Costs | E54: 3
B55: Forward Integration | E55: 2
...

Sheet Peers
D3: Revenue Growth | F3: EBITDA Margin | H3: Profit Margin | J3: EV / Revenue | L3: EV / EBITDA | N3: Price / Earnings
B4: Peers | C4: Ticker | D4: =+Inputs!O4&"-"&Inputs!P4 -> 2022-2023 | E4: =+Inputs!P4&"-"&Inputs!Q4 -> 2023-2024 | F4: 2023 | G4: 2024 | H4: =+Inputs!O4&"-"&Inputs!P4 -> 2022-2023 | I4: =+Inputs!P4&"-"&Inputs!Q4 -> 2023-2024 | J4: 2023 | K4: 2024 | L4: 2023 | M4: 2024 | N4: 2023 | O4: 2024
A6: =+D91 -> #VALUE! | B6: {=IFERROR(_FV(A6,"Name"),"")} -> D-WAVE QUANTUM INC. | C6: {=IFERROR(_FV(A6,"Ticker symbol",TRUE),"")} -> QBTS | D6: =IFERROR(D94/D93-1,"") -> 0.22096752 | E6: =IFERROR(D97/D94-1,"") -> 0.0078785111 | F6: =IFERROR(D95/D94,"") -> -8.6118977 | G6: =IFERROR(D100/D97,"") -> -7.8502322 | H6: =IFERROR(D96/D94,"") -> -9.4445079 | I6: =IFERROR(D105/D97,"") -> -16.299875 | J6: {=IFERROR((_FV(A6,"Market cap",TRUE)/1000000+D$121-D$111)/D$94,"")} -> -14.975468 | K6: {=IFERROR((_FV(A6,"Market cap",TRUE)/1000000+D$121-D$111)/D$97,"")} -> -14.858406 | L6: {=+IFERROR((_FV(A6,"Market cap",TRUE)/1000000+D$121-D$111)/D$95,"")} -> 1.7389278 | M6: {=IFERROR((_FV(A6,"Market cap",TRUE)/1000000+D$121-D$111)/D$100,"")} -> 1.8927346 | N6: {=IFERROR((_FV(A6,"Market cap",TRUE)/1000000)/D$96,"")} -> -0.10213204 | O6: {=IFERROR((_FV(A6,"Market cap",TRUE)/1000000)/D$105,"")} -> -0.058714976
A8: =+E91 -> #VALUE! | B8: IONQ INC. | C8: IONQ | D8: =+IFERROR(E94/E93-1,"") -> 0.98023538 | E8: =IFERROR(E97/E94-1,"") -> 0.95413302 | F8: =IFERROR(E95/E94,"") -> -6.6862807 | G8: =+IFERROR(E100/E97,"") -> -4.9636896 | H8: =IFERROR(E96/E94,"") -> -7.1577443 | I8: =+IFERROR(E105/E97,"") -> -7.6996494 | J8: {=IFERROR((_FV(A8,"Capitalização de mercado",TRUE)/1000000+E$121-E$111)/E$94,"")} -> -0.76277399 | K8: {=IFERROR(+(_FV(A8,"Capitalização de mercado",TRUE)/1000000+E$121-E$111)/E$97,"")} -> -0.39033883 | L8: {=IFERROR(+(_FV(A8,"Capitalização de mercado",TRUE)/1000000+E$121-E$111)/E$95,"")} -> 0.11408046 | M8: {=IFERROR(+(_FV(A8,"Capitalização de mercado",TRUE)/1000000+E$121-E$111)/E$100,"")} -> 0.078638848 | N8: {=IFERROR(+(_FV(A8,"Capitalização de mercado",TRUE)/1000000)/E$96,"")} -> -0.12584655 | O8: {=IFERROR(+(_FV(A8,"Capitalização de mercado",TRUE)/1000000)/E$105,"")} -> -0.059867678
A9: =+F91 -> #VALUE! | B9: RIGETTI COMPUTING INC. | C9: RGTI | D9: =IFERROR(F94/F93-1,"") -> -0.083498702 | E9: =IFERROR(F97/F94-1,"") -> -0.10143238 | F9: =IFERROR(F95/F94,"") -> -5.1550633 | G9: =IFERROR(F100/F97,"") -> -17.685542 | H9: =IFERROR(F96/F94,"") -> -6.2547468 | I9: =+IFERROR(F105/F97,"") -> -18.627247 | J9: {=IFERROR((_FV(A9,"Capitalização de mercado",TRUE)/1000000+E$121-E$111)/E$94,"")} -> -1.2254386 | K9: {=IFERROR(+(_FV(A9,"Capitalização de mercado",TRUE)/1000000+E$121-E$111)/E$97,"")} -> -0.62710094 | L9: {=IFERROR(+(_FV(A9,"Capitalização de mercado",TRUE)/1000000+E$121-E$111)/E$95,"")} -> 0.18327658 | M9: {=IFERROR(+(_FV(A9,"Capitalização de mercado",TRUE)/1000000+E$121-E$111)/E$100,"")} -> 0.12633766 | N9: {=IFERROR(+(_FV(A9,"Capitalização de mercado",TRUE)/1000000)/E$96,"")} -> -0.061208215 | O9: {=IFERROR(+(_FV(A9,"Capitalização de mercado",TRUE)/1000000)/E$105,"")} -> -0.029117952
A10: =+G91 -> #VALUE! | B10: QUANTUM COMPUTING INC. | C10: QUBT | D10: =+IFERROR(G94/G93-1,"") -> 1.6323529 | E10: =+IFERROR(G97/G94-1,"") -> 0.041899441 | F10: =IFERROR(G95/G94,"") -> -71.005587 | G10: =IFERROR(G100/G97,"") -> -166.88472 | H10: =IFERROR(G96/G94,"") -> -75.480447 | I10: =+IFERROR(G105/G97,"") -> -183.75871 | J10: {=IFERROR((_FV(A10,"Capitalização de mercado",TRUE)/1000000+E$121-E$111)/E$94,"")} -> -1.507573 | K10: {=IFERROR(+(_FV(A10,"Capitalização de mercado",TRUE)/1000000+E$121-E$111)/E$97,"")} -> -0.77147919 | L10: {=IFERROR(+(_FV(A10,"Capitalização de mercado",TRUE)/1000000+E$121-E$111)/E$95,"")} -> 0.22547258 | M10: {=IFERROR(+(_FV(A10,"Capitalização de mercado",TRUE)/1000000+E$121-E$111)/E$100,"")} -> 0.15542455 | N10: {=IFERROR(+(_FV(A10,"Capitalização de mercado",TRUE)/1000000)/E$96,"")} -> -0.021791563 | O10: {=IFERROR(+(_FV(A10,"Capitalização de mercado",TRUE)/1000000)/E$105,"")} -> -0.010366675
A11: =+H91 -> PEER 4 | B11: {=IFERROR(_FV(A11,"Name"),"")} | C11: {=IFERROR(_FV(A11,"Ticker symbol",TRUE),"")} | D11: =IFERROR(H94/H93-1,"") | E11: =IFERROR(H97/H94-1,"") | F11: =IFERROR(H95/H94,"") | G11: =IFERROR(H100/H97,"") | H11: =IFERROR(H96/H94,"") | I11: =+IFERROR(H105/H102,"") | J11: {=IFERROR((_FV(A11,"Market cap",TRUE)/1000000+H$121-H$111)/H$94,"")} | K11: {=IFERROR(+(_FV(A11,"Market cap",TRUE)/1000000+H$121-H$111)/H$97,"")} | L11: {=IFERROR(+(_FV(A11,"Market cap",TRUE)/1000000+H$121-H$111)/H$95,"")} | M11: {=IFERROR(+(_FV(A11,"Market cap",TRUE)/1000000+H$121-H$111)/H$100,"")} | N11: {=IFERROR(+(_FV(A11,"Market cap",TRUE)/1000000)/H$96,"")} | O11: {=IFERROR(+(_FV(A11,"Market cap",TRUE)/1000000)/H$105,"")}
A12: =+I91 -> PEER 5 | B12: {=IFERROR(_FV(A12,"Name"),"")} | C12: {=IFERROR(_FV(A12,"Ticker symbol",TRUE),"")} | D12: =+IFERROR(I94/I93-1,"") | E12: =IFERROR(I97/I94-1,"") | F12: =IFERROR(I95/I94,"") | G12: =IFERROR(I100/I97,"") | H12: =IFERROR(I96/I94,"") | I12: =+IFERROR(I105/I97,"") | J12: {=IFERROR((_FV(A12,"Market cap",TRUE)/1000000+I$121-I$111)/I$94,"")} | K12: {=IFERROR(+(_FV(A12,"Market cap",TRUE)/1000000+I$121-I$111)/I$97,"")} | L12: {=IFERROR(+(_FV(A12,"Market cap",TRUE)/1000000+I$121-I$111)/I$95,"")} | M12: {=IFERROR(+(_FV(A12,"Market cap",TRUE)/1000000+I$121-I$111)/I$100,"")} | N12: {=IFERROR(+(_FV(A12,"Market cap",TRUE)/1000000)/I$96,"")} | O12: {=IFERROR(+(_FV(A12,"Market cap",TRUE)/1000000)/I$105,"")}
A13: =+J91 -> PEER 6 | B13: {=IFERROR(_FV(A13,"Name"),"")} | C13: {=IFERROR(_FV(A13,"Ticker symbol",TRUE),"")} | D13: =IFERROR(J94/J93-1,"") | E13: =IFERROR(J97/J94-1,"") | G13: =IFERROR(J100/J97,"") | H13: =IFERROR(J96/J94,"") | I13: =+IFERROR(J105/J97,"") | J13: {=IFERROR(+(_FV(A13,"Market cap",TRUE)/1000000+J$121-J$111)/J$94,"")} | K13: {=IFERROR(+(_FV(A13,"Market cap",TRUE)/1000000+J$121-J$111)/J$97,"")} | L13: {=IFERROR(+(_FV(A13,"Market cap",TRUE)/1000000+J$121-J$111)/J$95,"")} | M13: {=IFERROR(+(_FV(A13,"Market cap",TRUE)/1000000+J$121-J$111)/J$100,"")} | N13: {=IFERROR(+(_FV(A13,"Market cap",TRUE)/1000000)/J$96,"")} | O13: {=IFERROR(+(_FV(A13,"Market cap",TRUE)/1000000)/J$105,"")}
A14: =+K91 -> PEER 7 | B14: {=IFERROR(_FV(A14,"Name"),"")} | C14: {=IFERROR(_FV(A14,"Ticker symbol",TRUE),"")} | D14: =IFERROR(K94/K93-1,"") | E14: =IFERROR(K97/K94-1,"") | F14: =+IFERROR(K95/K94,"") | G14: =IFERROR(K100/K97,"") | H14: =IFERROR(K96/K94,"") | I14: =+IFERROR(K105/K97,"") | J14: {=IFERROR((_FV(A14,"Market cap",TRUE)/1000000+D$121-K$111)/K$94,"")} | K14: {=IFERROR(+(_FV(A14,"Market cap",TRUE)/1000000+D$121-K$111)/K$97,"")} | L14: {=IFERROR(+(_FV(A14,"Market cap",TRUE)/1000000+D$121-K$111)/K$95,"")} | M14: {=IFERROR(+(_FV(A14,"Market cap",TRUE)/1000000+D$121-K$111)/K$100,"")} | N14: {=IFERROR(+(_FV(A14,"Market cap",TRUE)/1000000)/K$96,"")} | O14: {=IFERROR(+(_FV(A14,"Market cap",TRUE)/1000000)/K$105,"")}
A15: =+L91 -> PEER 8 | B15: {=IFERROR(_FV(A15,"Name"),"")} | C15: {=IFERROR(_FV(A15,"Ticker symbol",TRUE),"")} | D15: =+IFERROR(L94/L93,"") | E15: =IFERROR(L97/L94,"") | F15: =IFERROR(L95/L94,"") | G15: =IFERROR(L100/L97,"") | H15: =IFERROR(L96/L94,"") | I15: =+IFERROR(L105/L97,"") | J15: {=IFERROR(+(_FV(A15,"Market cap",TRUE)/1000000+L$121-L$111)/L$94,"")} | K15: {=IFERROR(+(_FV(A15,"Market cap",TRUE)/1000000+L$121-L$111)/L$97,"")} | L15: {=IFERROR(+(_FV(A15,"Market cap",TRUE)/1000000+L$121-L$111)/L$95,"")} | M15: {=IFERROR(+(_FV(A15,"Market cap",TRUE)/1000000+L$121-L$111)/L$100,"")} | N15: {=IFERROR(+(_FV(A15,"Market cap",TRUE)/1000000)/L$96,"")} | O15: {=IFERROR(+(_FV(A15,"Market cap",TRUE)/1000000)/L$105,"")}
A16: =+M91 -> PEER 9 | B16: {=IFERROR(_FV(A16,"Name"),"")} | C16: {=IFERROR(_FV(A16,"Ticker symbol",TRUE),"")} | D16: =IFERROR(M94/M93-1,"") | E16: =IFERROR(M97/M94-1,"") | F16: =IFERROR(M95/M94,"") | G16: =IFERROR(M100/M97,"") | H16: =IFERROR(M96/M94,"") | I16: =+IFERROR(M105/M97,"") | J16: {=IFERROR(+(_FV(A16,"Market cap",TRUE)/1000000+M$121-M$111)/M$94,"")} | K16: {=IFERROR(+(_FV(A16,"Market cap",TRUE)/1000000+M$121-M$111)/M$97,"")} | L16: {=IFERROR(+(_FV(A16,"Market cap",TRUE)/1000000+M$121-M$111)/M$95,"")} | M16: {=IFERROR(+(_FV(A16,"Market cap",TRUE)/1000000+M$121-M$111)/M$100,"")} | N16: {=IFERROR(+(_FV(A16,"Market cap",TRUE)/1000000)/M$96,"")} | O16: {=IFERROR(+(_FV(A16,"Market cap",TRUE)/1000000)/M$105,"")}
A17: =+N91 -> PEER 10 | B17: {=IFERROR(_FV(A17,"Name"),"")} | C17: {=+IFERROR(_FV(A17,"Ticker symbol",TRUE),"")} | D17: =IFERROR(N94/N93-1,"") | E17: =IFERROR(N97/N94-1,"") | F17: =IFERROR(N95/N94,"") | G17: =IFERROR(N100/N97,"") | H17: =IFERROR(N96/N94,"") | I17: =+IFERROR(N105/N97,"") | J17: {=IFERROR(+(_FV(A17,"Market cap",TRUE)/1000000+N$121-N$111)/N$94,"")} | K17: {=IFERROR(+(_FV(A17,"Market cap",TRUE)/1000000+N$121-N$111)/N$97,"")} | L17: {=IFERROR(+(_FV(A17,"Market cap",TRUE)/1000000+N$121-N$111)/N$95,"")} | M17: {=IFERROR(+(_FV(A17,"Market cap",TRUE)/1000000+N$121-N$111)/N$100,"")} | N17: {=IFERROR(+(_FV(A17,"Market cap",TRUE)/1000000)/N$96,"")} | O17: {=IFERROR(+(_FV(A17,"Market cap",TRUE)/1000000)/N$105,"")}
B18: Average | D18: =IFERROR(AVERAGE(D6:D17),"") -> 0.68751428 | E18: =IFERROR(AVERAGE(E6:E17),"") -> 0.22561965 | F18: =IFERROR(AVERAGE(F6:F17),"") -> -22.864707 | G18: =IFERROR(AVERAGE(G6:G17),"") -> -49.346046 | H18: =IFERROR(AVERAGE(H6:H17),"") -> -24.584361 | I18: =IFERROR(AVERAGE(I6:I17),"") -> -56.596371 | J18: =IFERROR(AVERAGE(J6:J17),"") -> -4.6178134 | K18: =IFERROR(AVERAGE(K6:K17),"") -> -4.1618312 | ... O18: =IFERROR(AVERAGE(O6:O17),"") -> -0.03951682
B19: Deviation from Average | D19: =IFERROR(+D18-D6,"") -> 0.46654677 | E19: =IFERROR(E18-E6,"") -> 0.21774114 | F19: =+IFERROR(F18-F6,"") -> -14.252809 | G19: =IFERROR(G18-G6,"") -> -41.495813 | H19: =IFERROR(+H6-H18,"") -> 15.139854 | I19: =+IFERROR(I6-I18,"") -> 40.296496 | J19: =+IFERROR(J6-J18,"") -> -10.357655 | K19: =+IFERROR(K6-K18,"") -> -10.696575 | L19: =IFERROR(+L6-L18,"") -> 1.1734884 | M19: =IFERROR(M6-M18,"") -> 1.3294506 | N19: =IFERROR(+N6-N18,"") -> -0.024387451 | O19: =IFERROR(+O6-O18,"") -> -0.019198156
D21: Trading Multiple | G21: Net | H21: Preferred | I21: Non-Controlling | J21: Equity Value | M21: Implied Upside (Downside)
B22: Implied Share Price | D22: Revenue | E22: EBITDA | F22: P/E | G22: Debt | H22: Stock | I22: Interest | J22: Revenue | K22: EBITDA | L22: P/E | M22: Revenue | N22: EBITDA | O22: P/E | P22: Current Price
B24: Second Minimum | D24: =IFERROR(SMALL(K6:K17,2),"") -> -0.77147919 | E24: =IFERROR(SMALL(M6:M17,2),"") -> 0.12633766 | F24: =IFERROR(SMALL(O6:O17,2),"") -> -0.058714976 | G24: =-Inputs!$Q$99+Inputs!$Q$100 -> -139.603 | H24: =+Inputs!$Q$101 -> 0 | I24: =+Inputs!$Q$102 -> 0 | J24: =IFERROR(+D24*$D$97+G24+H24+I24,"") -> -6949.4498 | K24: =IFERROR(E24*$D$100+G24+H24+I24,"") -> -8894.045 | L24: =IFERROR(F24*$D$105,"") -> 8447.852 | M24: {=IFERROR(+(J24/_FV($A$6,"Shares outstanding",TRUE)*1000000)/$P$24-1,"")} -> -1.8226292 | N24: {=IFERROR((+K24/_FV($A$6,"Shares outstanding",TRUE)*1000000)/$P$24-1,"")} -> -2.0528173 | O24: {=IFERROR(+(L24/_FV($A$6,"Shares outstanding",TRUE)*1000000)/$P$24-1,"")} -> 0 | P24: {=+_FV(A6,"Price")} -> 24.7
B25: Average | D25: =+IFERROR(AVERAGE(K6:K17),"") -> -4.1618312 | E25: =IFERROR(+AVERAGE(M6:M17),"") -> 0.5632839 | F25: =IFERROR(+AVERAGE(O6:O17),"") -> -0.03951682 | G25: =-Inputs!$Q$99+Inputs!$Q$100 -> -139.603 | H25: =+Inputs!$Q$101 -> 0 | I25: =+Inputs!$Q$102 -> 0 | J25: =IFERROR(+D25*$D$97+G25+H25+I25,"") -> -36876.087 | K25: =IFERROR(E25*$D$100+G25+H25+I25,"") -> -39171.798 | L25: =IFERROR(+F25*$D$105,"") -> 5685.6406 | M25: {=IFERROR(+(J25/_FV($A$6,"Shares outstanding",TRUE)*1000000)/$P$24-1,"")} -> -5.3651436 | N25: {=IFERROR((+K25/_FV($A$6,"Shares outstanding",TRUE)*1000000)/$P$24-1,"")} -> -5.6368944 | O25: {=IFERROR(+(L25/_FV($A$6,"Shares outstanding",TRUE)*1000000)/$P$24-1,"")} -> -0.32697205
B26: Median | D26: =IFERROR(MEDIAN(K6:K17),"") -> -0.69929007 | E26: =IFERROR(MEDIAN(M6:M17),"") -> 0.1408811 | F26: =IFERROR(MEDIAN(O6:O17),"") -> -0.043916464 | G26: =-Inputs!$Q$99+Inputs!$Q$100 -> -139.603 | H26: =+Inputs!$Q$101 -> 0 | I26: =+Inputs!$Q$102 -> 0 | J26: =IFERROR(D26*$D$97+G26+H26+I26,"") -> -6312.2364 | K26: =IFERROR(E26*$D$100+G26+H26+I26,"") -> -9901.8182 | L26: =IFERROR(+F26*$D$105,"") -> 6318.6569 | M26: {=IFERROR(+(J26/_FV($A$6,"Shares outstanding",TRUE)*1000000)/$P$24-1,"")} -> -1.7472002 | N26: {=IFERROR((+K26/_FV($A$6,"Shares outstanding",TRUE)*1000000)/$P$24-1,"")} -> -2.1721108 | O26: {=+IFERROR((L26/_FV($A$6,"Shares outstanding",TRUE)*1000000)/$P$24-1,"")} -> -0.25203982
B27: Second Maximum | D27: =IFERROR(LARGE(K6:K17,2),"") -> -0.62710094 | E27: =IFERROR(LARGE(M6:M17,2),"") -> 0.15542455 | F27: =IFERROR(LARGE(O6:O17,2),"") -> -0.029117952 | G27: =-Inputs!$Q$99+Inputs!$Q$100 -> -139.603 | H27: =+Inputs!$Q$101 -> 0 | I27: =+Inputs!$Q$102 -> 0 | J27: =IFERROR(+D27*$D$97+G27+H27+I27,"") -> -5675.023 | K27: =IFERROR(E27*$D$100+G27+H27+I27,"") -> -10909.591 | L27: =IFERROR(+F27*$D$105,"") -> 4189.4618 | M27: {=IFERROR(+(J27/_FV($A$6,"Shares outstanding",TRUE)*1000000)/$P$24-1,"")} -> -1.6717711 | N27: {=IFERROR((+K27/_FV($A$6,"Shares outstanding",TRUE)*1000000)/$P$24-1,"")} -> -2.2914042 | O27: {=IFERROR(+(L27/_FV($A$6,"Shares outstanding",TRUE)*1000000)/$P$24-1,"")} -> -0.50407965
B29: Profitability | D29: =+LEFT(B6, FIND(" ", B6 & " ") - 1) -> D-WAVE | E29: =+LEFT(B8, FIND(" ", B8 & " ") - 1) -> IONQ | F29: =+LEFT(B9, FIND(" ", B9 & " ") - 1) -> RIGETTI | G29: =+LEFT(B10, FIND(" ", B10 & " ") - 1) -> QUANTUM | H29: =+LEFT(B11, FIND(" ", B11 & " ") - 1) | I29: =+LEFT(B12, FIND(" ", B12 & " ") - 1) | J29: =+LEFT(C12, FIND(" ", C12 & " ") - 1) | K29: =+LEFT(B14, FIND(" ", B14 & " ") - 1) | L29: =+LEFT(B15, FIND(" ", B15 & " ") - 1) | M29: =+LEFT(B16, FIND(" ", B16 & " ") - 1) | N29: =+LEFT(B17, FIND(" ", B17 & " ") - 1) | O29: Average
B31: Operating Margin | D31: =IFERROR(D101/D97,"") -> -8.2458366 | E31: =IFERROR(E101/E97,"") -> -5.3967683 | F31: =IFERROR(F101/F97,"") -> -18.325579 | G31: =IFERROR(G101/G97,"") -> -177.06702 | H31: =IFERROR(H101/H97,"") | I31: =IFERROR(I101/I97,"") | J31: =IFERROR(J101/J97,"") | K31: =IFERROR(K101/K97,"") | ... N31: =IFERROR(N101/N97,"") | O31: =IFERROR(+AVERAGE(D31:N31),"") -> -52.258802
B32: Net Income Margin | D32: =IFERROR(D105/D97,"") -> -16.299875 | E32: =IFERROR(E105/E97,"") -> -7.6996494 | F32: =IFERROR(F105/F97,"") -> -18.627247 | G32: =IFERROR(G105/G97,"") -> -183.75871 | H32: =IFERROR(H105/H97,"") | I32: =IFERROR(I105/I97,"") | J32: =IFERROR(J105/J97,"") | K32: =IFERROR(K105/K97,"") | ... N32: =IFERROR(N105/N97,"") | O32: =IFERROR(+AVERAGE(D32:N32),"") -> -56.596371
B33: ROA (%) | D33: =IFERROR(D105/D117,"") -> -0.71992414 | E33: =IFERROR(E105/E117,"") -> -0.65235017 | F33: =IFERROR(F105/F117,"") -> -0.70574851 | G33: =IFERROR(G105/G117,"") -> -0.44635612 | H33: =IFERROR(H105/H117,"") | I33: =IFERROR(I105/I117,"") | J33: =IFERROR(J105/J117,"") | K33: =IFERROR(K105/K117,"") | ... N33: =IFERROR(N105/N117,"") | O33: =IFERROR(+AVERAGE(D33:N33),"") -> -0.63109474
B34: Financial Cost of Debt | D34: =IFERROR((D102/D121)*(1-(D104/D103)),(D102/D121)) -> 0.1015452 | E34: =IFERROR(+(E102/E121)*(1-(E104/E103)),+(E102/E121)*(1-(0.1/E103))) -> 0.0010155151 | F34: =IFERROR(+(F102/F121)*(1-(F104/F103)),+(F102/F121)) -> 0.36988636 | G34: =IFERROR(+(G102/G121)*(1-(G104/G103)),+(G102/G121)) -> -1.7552921 | H34: =IFERROR(+(H102/H121)*(1-(H104/H103)),"") | I34: =IFERROR(+(I102/I121)*(1-(I104/I103)),"") | J34: =IFERROR(+(J102/J121)*(1-(J104/J103)),"") | K34: =IFERROR(+(K102/K121)*(1-(K104/K103)),"") | L34: =IFERROR(+(L102/L121)*(1-(L104/L103)),"") | M34: =IFERROR(+(M102/M121)*(1-(M104/M103)),"") | N34: =IFERROR(+(N102/N121)*(1-(N104/N103)),"") | O34: =IFERROR(+AVERAGE(D34:N34),"") -> -0.32071126
B35: Return on Equity (RoE) | D35: =IFERROR(+D105/D122,"") -> -2.2966989 | E35: =IFERROR(+E105/E122,"") -> -0.86397455 | F35: =IFERROR(+F105/F122,"") -> -1.5877209 | G35: =IFERROR(+G105/G122,"") -> -0.63886585 | H35: =IFERROR(+H105/H122,"") | I35: =IFERROR(+I105/I122,"") | J35: =IFERROR(+J105/J122,"") | K35: =IFERROR(+K105/K122,"") | ... N35: =IFERROR(+N105/N122,"") | O35: =IFERROR(+AVERAGE(D35:N35),"") -> -1.3468151
B36: Return on Invested Capital (ROIC) | D36: =IFERROR(+D105/(D121+D122),"") -> -1.4242202 | E36: =IFERROR(+E105/(E121+E122),"") -> -0.82584098 | F36: =IFERROR(+F105/(F121+F122),"") -> -1.4845224 | G36: =IFERROR(+G105/(G121+G122),"") -> -0.63190987 | H36: =IFERROR(+H105/(H121+H122),"") | I36: =IFERROR(+I105/(I121+I122),"") | J36: =IFERROR(+J105/(J121+J122),"") | K36: =IFERROR(+K105/(K121+K122),"") | ... N36: =IFERROR(+N105/(N121+N122),"") | O36: =IFERROR(+AVERAGE(D36:N36),"") -> -1.0916234
B38: Solvency | D38: =+D29 -> D-WAVE | E38: =+E29 -> IONQ | F38: =+F29 -> RIGETTI | G38: =+G29 -> QUANTUM | H38: =+H29 | I38: =+I29 | J38: =+J29 | K38: =+K29 | ... O38: =+O29 -> Average
B40: Debt/Assets | D40: =IFERROR(D121/D117,"") -> 0.19202614 | E40: =IFERROR(E121/E117,"") -> 0.034865103 | F40: =IFERROR(F121/F117,"") -> 0.030900287 | G40: =IFERROR(G121/G117,"") -> 0.007690855 | H40: =IFERROR(H121/H117,"") | I40: =IFERROR(I121/I117,"") | J40: =IFERROR(J121/J117,"") | K40: =IFERROR(K121/K117,"") | ... N40: =IFERROR(N121/N117,"") | O40: =IFERROR(+AVERAGE(D40:N40),"") -> 0.066370596
B41: Net Debt/EBITDA | D41: =IFERROR(+(D121-D111)/D100,"") -> 2.0146477 | E41: =IFERROR(+(E121-E111)/E100,"") -> 0.17150528 | F41: =IFERROR(+(F121-F111)/F100,"") -> 0.30852028 | G41: =IFERROR(+(G121-G111)/G100,"") -> 1.249261 | H41: =IFERROR(+(H121-H111)/H100,"") | I41: =IFERROR(+(I121-I111)/I100,"") | J41: =IFERROR(+(J121-J111)/J100,"") | K41: =IFERROR(+(K121-K111)/K100,"") | ... N41: =IFERROR(+(N121-N111)/N100,"") | O41: =IFERROR(+AVERAGE(D41:N41),"") -> 0.93598358
B42: Interest Coverage Ratio | D42: =IFERROR(D101/D102,"") -> -18.677444 | E42: =IFERROR(E101/E102,"") -> -12914.167 | F42: =IFERROR(F101/F102,"") -> -60.747465 | G42: =IFERROR(G101/G102,"") -> 31.860106 | H42: =IFERROR(H101/H102,"") | I42: =IFERROR(I101/I102,"") | J42: =IFERROR(J101/J102,"") | K42: =IFERROR(K101/K102,"") | ... N42: =IFERROR(N101/N102,"") | O42: =IFERROR(+AVERAGE(D42:N42),"") -> -3240.4329
B44: Liquidity | D44: =+D29 -> D-WAVE | E44: =+E29 -> IONQ | F44: =+F29 -> RIGETTI | G44: =+G29 -> QUANTUM | H44: =+H29 | I44: =+I29 | J44: =+J29 | K44: =+K29 | ... O44: =+O29 -> Average
B46: Cash Ratio | D46: =IFERROR(D111/D119,"") -> 5.90413 | E46: =IFERROR(E111/E119,"") -> 1507.3576 | F46: =IFERROR(F111/F119,"") -> 5702.705 | G46: =IFERROR(G111/G119,"") -> 17316.297 | H46: =IFERROR(H111/H119,"") | I46: =IFERROR(I111/I119,"") | J46: =IFERROR(J111/J119,"") | K46: =IFERROR(K111/K119,"") | ... N46: =IFERROR(N111/N119,"") | O46: =IFERROR(+AVERAGE(D46:N46),"") -> 6133.066
B47: Quick Ratio | D47: =IFERROR(+(D111+D112)/D119,"") -> 5.9512357 | E47: =IFERROR(+(E111+E112)/E119,"") -> 1687.9313 | F47: =IFERROR(+(F111+F112)/F119,"") -> 5907.2217 | G47: =IFERROR(+(G111+G112)/G119,"") -> 17322.22 | H47: =IFERROR(+(H111+H112)/H119,"") | I47: =IFERROR(+(I111+I112)/I119,"") | J47: =IFERROR(+(J111+J112)/J119,"") | K47: =IFERROR(+(K111+K112)/K119,"") | ... N47: =IFERROR(+(N111+N112)/N119,"") | O47: =IFERROR(+AVERAGE(D47:N47),"") -> 6230.831
B48: Current Ratio | D48: =IFERROR(D115/D119,"") -> 6.1383314 | E48: =IFERROR(E115/E119,"") -> 10497.492 | F48: =IFERROR(F115/F119,"") -> 17422.938 | G48: =IFERROR(G115/G119,"") -> 17361.483 | H48: =IFERROR(H115/H119,"") | I48: =IFERROR(I115/I119,"") | J48: =IFERROR(J115/J119,"") | K48: =IFERROR(K115/K119,"") | ... N48: =IFERROR(N115/N119,"") | O48: =IFERROR(+AVERAGE(D48:N48),"") -> 11322.013
B50: Activity | D50: =+D29 -> D-WAVE | E50: =+E29 -> IONQ | F50: =+F29 -> RIGETTI | G50: =+G29 -> QUANTUM | H50: =+H29 | I50: =+I29 | J50: =+J29 | K50: =+K29 | ... O50: =+O29 -> Average
B52: Inventory Turnover | D52: =IFERROR(D98/(AVERAGE(D113:D114)),"") -> 1.7343252 | E52: =IFERROR(E98/(AVERAGE(E113:E114)),"") -> 1.3490075 | F52: =IFERROR(F98/(AVERAGE(F113:F114)),"") | G52: =IFERROR(G98/(AVERAGE(G113:G114)),"") -> 5.7142857 | H52: =IFERROR(H98/(AVERAGE(H113:H114)),"") | I52: =IFERROR(I98/(AVERAGE(I113:I114)),"") | J52: =IFERROR(J98/(AVERAGE(J113:J114)),"") | K52: =IFERROR(K98/(AVERAGE(K113:K114)),"") | ... N52: =IFERROR(N98/(AVERAGE(N113:N114)),"") | O52: =IFERROR(+AVERAGE(D52:N52),"") -> 2.9325395
B53: Acc. Receivable Turnover | D53: =IFERROR(D97/D112,"") -> 6.2161972 | E53: =IFERROR(E97/E112,"") -> 6.6103438 | F53: =IFERROR(F97/F112,"") -> 4.4458179 | G53: =IFERROR(G97/G112,"") -> 13.814815 | H53: =IFERROR(H97/H112,"") | I53: =IFERROR(I97/I112,"") | J53: =IFERROR(J97/J112,"") | K53: =IFERROR(K97/K112,"") | ... N53: =IFERROR(N97/N112,"") | O53: =IFERROR(+AVERAGE(D53:N53),"") -> 7.7717934
B54: Payables Turnover | D54: =IFERROR(D98/D118,"") -> 4.004908 | E54: =IFERROR(E98/E118,"") -> 4015.2964 | F54: =IFERROR(F98/F118,"") -> 2574.4573 | G54: =IFERROR(G98/G118,"") -> 189.50437 | H54: =IFERROR(H98/H118,"") | I54: =IFERROR(I98/I118,"") | J54: =IFERROR(J98/J118,"") | K54: =IFERROR(K98/K118,"") | ... N54: =IFERROR(N98/N118,"") | O54: =IFERROR(+AVERAGE(D54:N54),"") -> 1695.8157
...

Sheet ESG
B2: Environmental, Social and Governance Analysis
B4: Author: | E4: Highlights | N4: Recent News
N5: In January 2025, D-Wave partnered with Carahsoft to expand the distribution of its quantum computing solutions to the public sector. This collaboration aims to increase accessibility and adoption of D-Wave's annealing quantum computing technology among U.S. government agencies, facilitating advancements in areas such as national defense, emergency response, and infrastructure optimization.
B6: Overview | D6: . | E6: D-Wave stands out for its stable executive leadership, strong board governance, and meaningful community involvement.
B7: Last Update | D7: . | E7: However, it lacks transparency on environmental impact and has no ESG-linked compensation or clear DEI policies.
B8: Latest year with data | E8: Concerns around workplace culture and inclusion also remain, highlighting areas for improvement in social governance.
B9: GICS Sector
B10: GICS Industry Group
B11: Final Review
B13: ESG Scores
B14: LSEG ESG Score
B15: E-Score
B16: S-Score | E16: GHG Scope 1 and 2 Emissions: | N16: Water, Waste, Energy Management:
B17: G-Score
B18: S&P Global ESG Score
B19: Environmental
B20: Social
B21: Governance & Economic
B22: Sustainalytics
B23: ISS ESG Corporate Rating
B24: SDG Impact Rating
B25: Governance Quality Score
B26: MSCI ESG Ratings
B29: Industry ESG Overview:
E33: ENVIRONMENTAL
G35: Overview | H35: Targets | K35: Improvements | O35: Comments
E36: GHG (or CO2) Scope 1 Emissions
E38: Water Consumption
E40: Energy Consumption
E42: Waste Management
E44: Other
E46: SOCIAL
B48: Important Sources: | G48: Overview | H48: Targets | K48: Improvements | O48: Comments
B49: Annual Report | E49: Employee Turnover % | H49: Maintain or improve employee retention and satisfaction. | K49: Despite a 6.98% headcount reduction, D-Wave maintains its employee satisfaction score. | O49: While D-Wave reports high employee satisfaction, there remains room for improvement, particularly given signs of instability within specific departments.
B50: Sustainability Report | D50: .
B51: Proxy Statement | D51: . | E51: Salaries & Compensation | H51: Implement diversity, equity, and inclusion (DEI) metrics into compensation plans to foster a more inclusive workplace. | K51: D-Wave offers competitive salaries across various roles, indicating a commitment to fair compensation. | O51: As of 2024, there is no public evidence that D-Wave has integrated DEI or other social metrics into its compensation structures.
B52: Financial Times
B53: GlassDoor | E53: Reputation | H53: D-Wave aims to prove that its quantum optimization technology can outperform classical systems in real-word problems. | K53: Analysts gave positive ratings after strong revenue growth and product progress. | O53: Despite advancements, D-Wave faces skepticism from parts of the scientific community about the broader applicability of its quantum optimization method and the extent of its advantage.
B54: dwavequantum.com
B55: dwavefederal.com | E55: Discrimination Events | H55: Create and maintain an inclusive and ethical culture where equal opportunity is promoted. | K55: D-Wave has implemented a Code of Conduct and community guidelines that explicitly prohibit discrimination and harassment. | O55: There are anonymous reviews alleging that feedback and questions were "not well-received" especially if it came from a women.
...

Sheet ESG Inputs
B2: ESG Inputs
A4: x | B4: Total GHG Scope 1 Emissions | G4: 2014 | H4: =+G4+1 -> 2015 | I4: =+H4+1 -> 2016 | J4: =+I4+1 -> 2017 | K4: =+J4+1 -> 2018 | L4: =+K4+1 -> 2019 | M4: =+L4+1 -> 2020 | N4: =+M4+1 -> 2021 | O4: =+N4+1 -> 2022 | ... Q4: =+P4+1 -> 2024 | R4: ="CAGR "&$G$4&" - "&$Q$4 -> CAGR 2014 - 2024
B6: =+Peers!B6 -> D-WAVE QUANTUM INC. | R6: =IFERROR((Q6/G6)^(1/COUNT($G$4:$Q$4))-1,"")
B7: =+Peers!B8 -> IONQ INC. | R7: =IFERROR((Q7/G7)^(1/COUNT($G$4:$Q$4))-1,"")
B8: =+Peers!B9 -> RIGETTI COMPUTING INC. | R8: =IFERROR((Q8/G8)^(1/COUNT($G$4:$Q$4))-1,"")
B9: =+Peers!B10 -> QUANTUM COMPUTING INC. | R9: =IFERROR((Q9/G9)^(1/COUNT($G$4:$Q$4))-1,"")
B10: =+Peers!B11 | R10: =IFERROR((Q10/G10)^(1/COUNT($G$4:$Q$4))-1,"")
B11: =+Peers!B12 | R11: =IFERROR((Q11/G11)^(1/COUNT($G$4:$Q$4))-1,"")
B12: =+Peers!B13 | R12: =IFERROR((Q12/G12)^(1/COUNT($G$4:$Q$4))-1,"")
B13: =+Peers!B14 | R13: =IFERROR((Q13/G13)^(1/COUNT($G$4:$Q$4))-1,"")
B14: =+Peers!B15 | R14: =IFERROR((Q14/G14)^(1/COUNT($G$4:$Q$4))-1,"")
B15: =+Peers!B16 | R15: =IFERROR((Q15/G15)^(1/COUNT($G$4:$Q$4))-1,"")
B16: =+Peers!B17 | R16: =IFERROR((Q16/G16)^(1/COUNT($G$4:$Q$4))-1,"")
A18: x | B18: Total GHG Scope 2 (Location-Based) Emissions | G18: 2014 | H18: =+G18+1 -> 2015 | I18: =+H18+1 -> 2016 | J18: =+I18+1 -> 2017 | K18: =+J18+1 -> 2018 | L18: =+K18+1 -> 2019 | M18: =+L18+1 -> 2020 | N18: =+M18+1 -> 2021 | O18: =+N18+1 -> 2022 | ... Q18: =+P18+1 -> 2024 | R18: ="CAGR "&$G$4&" - "&$Q$4 -> CAGR 2014 - 2024
B20: =+$B$6 -> D-WAVE QUANTUM INC. | R20: =IFERROR((Q20/G20)^(1/COUNT($G$4:$Q$4))-1,"")
B21: =+$B$7 -> IONQ INC. | R21: =IFERROR((Q21/G21)^(1/COUNT($G$4:$Q$4))-1,"")
B22: =+$B$8 -> RIGETTI COMPUTING INC. | R22: =IFERROR((Q22/G22)^(1/COUNT($G$4:$Q$4))-1,"")
B23: =+$B$9 -> QUANTUM COMPUTING INC. | R23: =IFERROR((Q23/G23)^(1/COUNT($G$4:$Q$4))-1,"")
B24: =+$B$10 | R24: =IFERROR((Q24/G24)^(1/COUNT($G$4:$Q$4))-1,"")
B25: =+$B$11 | R25: =IFERROR((Q25/G25)^(1/COUNT($G$4:$Q$4))-1,"")
B26: =+$B$12 | R26: =IFERROR((Q26/G26)^(1/COUNT($G$4:$Q$4))-1,"")
B27: =+$B$13 | R27: =IFERROR((Q27/G27)^(1/COUNT($G$4:$Q$4))-1,"")
B28: =+$B$14 | R28: =IFERROR((Q28/G28)^(1/COUNT($G$4:$Q$4))-1,"")
B29: =+$B$15 | R29: =IFERROR((Q29/G29)^(1/COUNT($G$4:$Q$4))-1,"")
B30: =+$B$16 | R30: =IFERROR((Q30/G30)^(1/COUNT($G$4:$Q$4))-1,"")
A32: x | B32: Total Energy Usage | G32: 2014 | H32: =+G32+1 -> 2015 | I32: =+H32+1 -> 2016 | J32: =+I32+1 -> 2017 | K32: =+J32+1 -> 2018 | L32: =+K32+1 -> 2019 | M32: =+L32+1 -> 2020 | N32: =+M32+1 -> 2021 | O32: =+N32+1 -> 2022 | ... Q32: =+P32+1 -> 2024 | R32: ="CAGR "&$G$4&" - "&$Q$4 -> CAGR 2014 - 2024
B34: =+$B$6 -> D-WAVE QUANTUM INC. | R34: =IFERROR((Q34/G34)^(1/COUNT($G$4:$Q$4))-1,"")
B35: =+$B$7 -> IONQ INC. | R35: =IFERROR((Q35/G35)^(1/COUNT($G$4:$Q$4))-1,"")
B36: =+$B$8 -> RIGETTI COMPUTING INC. | R36: =IFERROR((Q36/G36)^(1/COUNT($G$4:$Q$4))-1,"")
B37: =+$B$9 -> QUANTUM COMPUTING INC. | R37: =IFERROR((Q37/G37)^(1/COUNT($G$4:$Q$4))-1,"")
B38: =+$B$10 | R38: =IFERROR((Q38/G38)^(1/COUNT($G$4:$Q$4))-1,"")
B39: =+$B$11 | R39: =IFERROR((Q39/G39)^(1/COUNT($G$4:$Q$4))-1,"")
B40: =+$B$12 | R40: =IFERROR((Q40/G40)^(1/COUNT($G$4:$Q$4))-1,"")
B41: =+$B$13 | R41: =IFERROR((Q41/G41)^(1/COUNT($G$4:$Q$4))-1,"")
B42: =+$B$14 | R42: =IFERROR((Q42/G42)^(1/COUNT($G$4:$Q$4))-1,"")
B43: =+$B$15 | R43: =IFERROR((Q43/G43)^(1/COUNT($G$4:$Q$4))-1,"")
B44: =+$B$16 | R44: =IFERROR((Q44/G44)^(1/COUNT($G$4:$Q$4))-1,"")
A46: x | B46: Total Water Consumption | G46: 2014 | H46: =+G46+1 -> 2015 | I46: =+H46+1 -> 2016 | J46: =+I46+1 -> 2017 | K46: =+J46+1 -> 2018 | L46: =+K46+1 -> 2019 | M46: =+L46+1 -> 2020 | N46: =+M46+1 -> 2021 | O46: =+N46+1 -> 2022 | ... Q46: =+P46+1 -> 2024 | R46: ="CAGR "&$G$4&" - "&$Q$4 -> CAGR 2014 - 2024
B48: =+$B$6 -> D-WAVE QUANTUM INC. | R48: =IFERROR((Q48/G48)^(1/COUNT($G$4:$Q$4))-1,"")
B49: =+$B$7 -> IONQ INC. | R49: =IFERROR((Q49/G49)^(1/COUNT($G$4:$Q$4))-1,"")
...

Sheet DCF
B2: DCF
A4: x | B4: Key Assumptions | R4: #VALUE!
B6: Switches | E6: Bear Case | H6: Base Case | K6: Bull Case | X6: FCFF | Y6: FCFE | Z6: Tax Shield | AA6: Total Payout | AB6: NOPAT | AC6: Debt Borrowing | AD6: Cash Balance | AE6: Total Assets | AF6: Total Liabilities | AG6: Shareholder's Equity | AH6: Current Liabilities | AI6: Current Assets
