Workbook
Name blablabla: _xlfn.LAMBDA(_xldudf_BOARDFLARE_EXEC("workbook-settings:coolfucntion"))
Name blablabla: _xlfn.LAMBDA(_xldudf_BOARDFLARE_EXEC("workbook-settings:coolfucntion"))
Name blablabla: _xlfn.LAMBDA(_xldudf_BOARDFLARE_EXEC("workbook-settings:coolfucntion"))
Name COOLFUCNTION: _xlfn.LAMBDA(_xldudf_BOARDFLARE_EXEC("workbook-settings:coolfucntion"))
Name COOLFUCNTION: _xlfn.LAMBDA(_xldudf_BOARDFLARE_EXEC("workbook-settings:coolfucntion"))
Name COOLFUCNTION: _xlfn.LAMBDA(_xldudf_BOARDFLARE_EXEC("workbook-settings:coolfucntion"))
Name COOLFUCNTION: _xlfn.LAMBDA(_xldudf_BOARDFLARE_EXEC("workbook-settings:coolfucntion"))
Name COOLFUCNTION: _xlfn.LAMBDA(_xldudf_BOARDFLARE_EXEC("workbook-settings:coolfucntion"))
Name COOLFUCNTION: _xlfn.LAMBDA(_xldudf_BOARDFLARE_EXEC("workbook-settings:coolfucntion"))
Name COOLFUCNTION: _xlfn.LAMBDA(_xldudf_BOARDFLARE_EXEC("workbook-settings:coolfucntion"))
Name COOLFUCNTION: _xlfn.LAMBDA(_xldudf_BOARDFLARE_EXEC("workbook-settings:coolfucntion"))
Name COOLFUCNTION: _xlfn.LAMBDA(_xldudf_BOARDFLARE_EXEC("workbook-settings:coolfucntion"))
Name COOLFUCNTION: _xlfn.LAMBDA(_xldudf_BOARDFLARE_EXEC("workbook-settings:coolfucntion"))
Name COOLFUCNTION: _xlfn.LAMBDA(_xldudf_BOARDFLARE_EXEC("workbook-settings:coolfucntion"))
Name COOLFUCNTION: _xlfn.LAMBDA(_xldudf_BOARDFLARE_EXEC("workbook-settings:coolfucntion"))
Name COOLFUCNTION: _xlfn.LAMBDA(_xldudf_BOARDFLARE_EXEC("workbook-settings:coolfucntion"))
Name DCF_2: _xlfn.LAMBDA(_xldudf_BOARDFLARE_EXEC("workbook-settings:coolfucntion"))
Name DCF_2: _xlfn.LAMBDA(_xldudf_BOARDFLARE_EXEC("workbook-settings:coolfucntion"))
Name DCF_2: _xlfn.LAMBDA(_xldudf_BOARDFLARE_EXEC("workbook-settings:coolfucntion"))
Name DCF_2: _xlfn.LAMBDA(_xldudf_BOARDFLARE_EXEC("workbook-settings:coolfucntion"))
Name Sectors: #REF!
Name Sectors: #REF!
Name Sectors: #REF!
Name Sectors: #REF!

Sheet Summary
E2: | EQUITY RESEARCH | U2: Lisbon Investment Society Equity Research
U3: April 8, 2025
D6: {=+_FV(DCF!R4,"Name")} -> E.L.F. BEAUTY, INC. | U6: Buy
D8: E.L.F. Beauty is an American cosmetics company known for its affordable, cruelty-free, and vegan makeup and skincare products. It offers a wide range of items including foundations, lipsticks, primers, and skincare treatments, all designed to deliver high quality at accessible prices. Being extremely popular on social media, it has been growing rapidely for the past years. | U8: EXCHANGE:(TICKER)
U9: {=+"Price (19 April 25): $"&_FV(DCF!$R$4,"Price")} -> Price (19 April 25): $135.91
D10: Investment Thesis | U10: ="Price Target: $" & ROUND(IF(Summary!G25="FCFF",DCF!Q226,IF(Summary!G25="FCFE",DCF!Q269,IF(Summary!G25="Tax Shield",DCF!Q242,DCF!Q285))),2) &" "&IF(Summary!G25="FCFF","(FCFF)",IF(Summary!G25="FCFE","(FCFE)",IF(Summary!G25="Tax Shield","(APV)","(DDM)"))) -> Price Target: $107.57 (FCFF)
D11: We rate E.L.F Beauty as a Buy, supported by strong growth, fundamentals, digital presence and future stategy in a fast-growing beauty sector. For the base of your DCF, we estimated E.L.F's future market share in their main market (USA) and also in the international market individualy in order to forecast their future revenues. After carefull consideration of each estimate, we reach a fair stock price of $110,06. We believe that E.L.F is well positioned to continue capturing value in a sector undergoing structural digital transformation and that it will continue to outperform the market and that although tarriffs are a big concern, the stock price has overreacted, creating an interesting opportunity to buy. At the same time, we are not confortable setting a strong buy rating due to global uncertainty. | U11: =+"Upside (Downside): "&ROUND((DCF!$Q$229*100),2)&"%" -> Upside (Downside): -20.85%
U14: =+Industry!E28&", "&ESG!C9 -> United States, Consumer Staples
U15: =+ESG!C10 -> Personal Care Products
D17: Operating Metrics | F17: 2023 | G17: =+F17+1 -> 2024 | H17: =+G17+1 -> 2025 | I17: =+H17+1 -> 2026 | K17: Valuation Multiples | N17: 2022 | O17: =+N17+1 -> 2023 | P17: =+O17+1 -> 2024 | Q17: =+P17+1 -> 2025 | R17: =+Q17+1 -> 2026 | U17: Miguel Wever
D18: Market Share (US only) | F18: =DCF!F34 -> 0.0083067616 | G18: =DCF!G34 -> 0.013151746 | H18: =DCF!H34 -> 0.016383066 | I18: =DCF!I34 -> 0.017106453 | K18: EV / Sales | N18: =IFERROR(_xlfn.XLOOKUP($K18,Multiples!$B:$B,Multiples!N:N),"") -> 3.5253621 | O18: =IFERROR(_xlfn.XLOOKUP($K18,Multiples!$B:$B,Multiples!O:O),"") -> 7.3930114 | P18: =IFERROR(_xlfn.XLOOKUP($K18,Multiples!$B:$B,Multiples!P:P),"") -> 10.335833 | Q18: =IFERROR(_xlfn.XLOOKUP($K18,Multiples!$B:$B,Multiples!Q:Q),"") -> 5.0181315 | R18: =IFERROR(_xlfn.XLOOKUP($K18,Multiples!$B:$B,Multiples!R:R),"") -> 4.5757923 | U18: l61728@aln.iseg.ulisboa.pt
D19: Market Share (non-US) | F19: =DCF!F39 -> 0.00037643627 | G19: =DCF!G39 -> 0.00081384972 | H19: =DCF!H39 -> 0.00081140927 | I19: =DCF!I39 -> 0.0010491274 | K19: Price / Sales | N19: =IFERROR(_xlfn.XLOOKUP($K19,Multiples!$B:$B,Multiples!N:N),"") -> 3.3522361 | O19: =IFERROR(_xlfn.XLOOKUP($K19,Multiples!$B:$B,Multiples!O:O),"") -> 7.4695491 | P19: =IFERROR(_xlfn.XLOOKUP($K19,Multiples!$B:$B,Multiples!P:P),"") -> 10.255649 | Q19: =IFERROR(_xlfn.XLOOKUP($K19,Multiples!$B:$B,Multiples!Q:Q),"") -> 4.9661552 | R19: =IFERROR(_xlfn.XLOOKUP($K19,Multiples!$B:$B,Multiples!R:R),"") -> 4.6350116 | U19: (+351) 935 248 695
K20: EV / EBITDA | N20: =IFERROR(_xlfn.XLOOKUP($K20,Multiples!$B:$B,Multiples!N:N),"") -> 47.02881 | O20: =IFERROR(_xlfn.XLOOKUP($K20,Multiples!$B:$B,Multiples!O:O),"") -> 62.835169 | P20: =IFERROR(_xlfn.XLOOKUP($K20,Multiples!$B:$B,Multiples!P:P),"") -> 70.693781 | Q20: =IFERROR(_xlfn.XLOOKUP($K20,Multiples!$B:$B,Multiples!Q:Q),"") -> 56.481906 | R20: =IFERROR(_xlfn.XLOOKUP($K20,Multiples!$B:$B,Multiples!R:R),"") -> 40.154923 | U20: Mariana Gomes
K21: EV / EBIT | N21: =IFERROR(_xlfn.XLOOKUP($K21,Multiples!$B:$B,Multiples!N:N),"") -> 601.15087 | O21: =IFERROR(_xlfn.XLOOKUP($K21,Multiples!$B:$B,Multiples!O:O),"") -> 93.226035 | P21: =IFERROR(_xlfn.XLOOKUP($K21,Multiples!$B:$B,Multiples!P:P),"") -> 92.995246 | Q21: =IFERROR(_xlfn.XLOOKUP($K21,Multiples!$B:$B,Multiples!Q:Q),"") -> 83.137541 | R21: =IFERROR(_xlfn.XLOOKUP($K21,Multiples!$B:$B,Multiples!R:R),"") -> 51.719216 | U21: l63852@aln.iseg.ulisboa.pt
K22: Price / Earnings | N22: =IFERROR(_xlfn.XLOOKUP($K22,Multiples!$B:$B,Multiples!N:N),"") -> 60.03411 | O22: =IFERROR(_xlfn.XLOOKUP($K22,Multiples!$B:$B,Multiples!O:O),"") -> 70.29878 | P22: =IFERROR(_xlfn.XLOOKUP($K22,Multiples!$B:$B,Multiples!P:P),"") -> 82.229906 | Q22: =IFERROR(_xlfn.XLOOKUP($K22,Multiples!$B:$B,Multiples!Q:Q),"") -> 104.73521 | R22: =IFERROR(_xlfn.XLOOKUP($K22,Multiples!$B:$B,Multiples!R:R),"") -> 63.351551 | U22: (+351) 917 778 745
K23: Price / Book | N23: =IFERROR(_xlfn.XLOOKUP($K23,Multiples!$B:$B,Multiples!N:N),"") -> 4.2085371 | O23: =IFERROR(_xlfn.XLOOKUP($K23,Multiples!$B:$B,Multiples!O:O),"") -> 10.519161 | P23: =IFERROR(_xlfn.XLOOKUP($K23,Multiples!$B:$B,Multiples!P:P),"") -> 16.34105 | Q23: =IFERROR(_xlfn.XLOOKUP($K23,Multiples!$B:$B,Multiples!Q:Q),"") -> 9.6851816 | R23: =IFERROR(_xlfn.XLOOKUP($K23,Multiples!$B:$B,Multiples!R:R),"") -> 9.7175503 | U23: Dmitriy Zaev
U24: l61121@aln.iseg.ulisboa.pt
D25: Year | E25: Net Sales | F25: EBIT Margin | G25: FCFF | H25: =+IF(Summary!$G$25="FCFF",DCF!AB6,IF(Summary!$G$25="FCFE",DCF!AC6,DCF!AD6)) -> NOPAT | I25: Net Capex | K25: Profitability Ratios | N25: 2022 | O25: =+N25+1 -> 2023 | P25: =+O25+1 -> 2024 | Q25: =+P25+1 -> 2025 | R25: =+Q25+1 -> 2026 | U25: (+7) 981 806-15-95
D26: 2022 | E26: =+DCF!E48 -> 392.2 | F26: =+DCF!E78 -> 0.0058643549 | G26: =+INDEX(DCF!X7:AA7,MATCH(Summary!$G$25,{"FCFF","FCFE","Tax Shield","Total Payout"},0)) -> 7.4733333 | H26: =+IF(Summary!$G$25="FCFF",DCF!AB7,IF(Summary!$G$25="FCFE",DCF!AC7,DCF!AD7)) -> 7.9733333 | I26: =+DCF!E152 -> -4.8 | K26: Return on Assets | N26: =IFERROR(_xlfn.XLOOKUP($K26,Multiples!$B:$B,Multiples!N:N),"") -> 0.044278205 | O26: =IFERROR(_xlfn.XLOOKUP($K26,Multiples!$B:$B,Multiples!O:O),"") -> 0.10325722 | P26: =IFERROR(_xlfn.XLOOKUP($K26,Multiples!$B:$B,Multiples!P:P),"") -> 0.1130789 | Q26: =IFERROR(_xlfn.XLOOKUP($K26,Multiples!$B:$B,Multiples!Q:Q),"") -> 0.051614206 | R26: =IFERROR(_xlfn.XLOOKUP($K26,Multiples!$B:$B,Multiples!R:R),"") -> 0.091052147 | U26: José Godinho
D27: =+D26+1 -> 2023 | E27: =+DCF!F48 -> 578.8 | F27: =+DCF!F78 -> 0.079302004 | G27: =+INDEX(DCF!X8:AA8,MATCH(Summary!$G$25,{"FCFF","FCFE","Tax Shield","Total Payout"},0)) -> 91.954785 | H27: =+IF(Summary!$G$25="FCFF",DCF!AB8,IF(Summary!$G$25="FCFE",DCF!AC8,DCF!AD8)) -> 43.154785 | I27: =+DCF!F152 -> -1.7 | K27: Return on Equity | N27: =IFERROR(_xlfn.XLOOKUP($K27,Multiples!$B:$B,Multiples!N:N),"") -> 0.070102433 | O27: =IFERROR(_xlfn.XLOOKUP($K27,Multiples!$B:$B,Multiples!O:O),"") -> 0.14963504 | P27: =IFERROR(_xlfn.XLOOKUP($K27,Multiples!$B:$B,Multiples!P:P),"") -> 0.19872393 | Q27: =IFERROR(_xlfn.XLOOKUP($K27,Multiples!$B:$B,Multiples!Q:Q),"") -> -1.6230198e-08 | R27: =IFERROR(_xlfn.XLOOKUP($K27,Multiples!$B:$B,Multiples!R:R),"") -> -2.8631544e-08 | U27: l61474@aln.iseg.ulisboa.pt
D28: =+D27+1 -> 2024 | E28: =+DCF!G48 -> 1023.9 | F28: =+DCF!G78 -> 0.11114367 | G28: =+INDEX(DCF!X9:AA9,MATCH(Summary!$G$25,{"FCFF","FCFE","Tax Shield","Total Payout"},0)) -> 49.699049 | H28: =+IF(Summary!$G$25="FCFF",DCF!AB9,IF(Summary!$G$25="FCFE",DCF!AC9,DCF!AD9)) -> 99.399049 | I28: =+DCF!G152 -> -8.7 | K28: Return on Total Capital | N28: =IFERROR(_xlfn.XLOOKUP($K28,Multiples!$B:$B,Multiples!N:N),"") -> 0.018818346 | O28: =IFERROR(_xlfn.XLOOKUP($K28,Multiples!$B:$B,Multiples!O:O),"") -> 0.088522635 | P28: =IFERROR(_xlfn.XLOOKUP($K28,Multiples!$B:$B,Multiples!P:P),"") -> 0.11934092 | Q28: =IFERROR(_xlfn.XLOOKUP($K28,Multiples!$B:$B,Multiples!Q:Q),"") -> -1.8735422e-08 | R28: =IFERROR(_xlfn.XLOOKUP($K28,Multiples!$B:$B,Multiples!R:R),"") -> -3.1274562e-08 | U28: (+351) 934 684 550
D29: =+D28+1 -> 2025 | E29: =+DCF!H48 -> 1308.9 | F29: =+DCF!H78 -> 0.060359393 | G29: =+INDEX(DCF!X10:AA10,MATCH(Summary!$G$25,{"FCFF","FCFE","Tax Shield","Total Payout"},0)) -> 8.5855595 | H29: =+IF(Summary!$G$25="FCFF",DCF!AB10,IF(Summary!$G$25="FCFE",DCF!AC10,DCF!AD10)) -> 71.642986 | I29: =+DCF!H152 -> -8.7 | K29: EBITDA Margin | N29: =IFERROR(_xlfn.XLOOKUP($K29,Multiples!$B:$B,Multiples!N:N),"") -> 0.074961754 | O29: =IFERROR(_xlfn.XLOOKUP($K29,Multiples!$B:$B,Multiples!O:O),"") -> 0.11765722 | P29: =IFERROR(_xlfn.XLOOKUP($K29,Multiples!$B:$B,Multiples!P:P),"") -> 0.14620568 | Q29: =IFERROR(_xlfn.XLOOKUP($K29,Multiples!$B:$B,Multiples!Q:Q),"") -> 0.088844939 | R29: =IFERROR(_xlfn.XLOOKUP($K29,Multiples!$B:$B,Multiples!R:R),"") -> 0.11395346
D30: =+D29+1 -> 2026 | E30: =+DCF!I48 -> 1496.4472 | F30: =+DCF!I78 -> 0.088473737 | G30: =+INDEX(DCF!X11:AA11,MATCH(Summary!$G$25,{"FCFF","FCFE","Tax Shield","Total Payout"},0)) -> 216.4966 | H30: =+IF(Summary!$G$25="FCFF",DCF!AB11,IF(Summary!$G$25="FCFE",DCF!AC11,DCF!AD11)) -> 119.59181 | I30: =+DCF!I152 -> -9.36 | K30: EBIT Margin | N30: =IFERROR(_xlfn.XLOOKUP($K30,Multiples!$B:$B,Multiples!N:N),"") -> 0.0058643549 | O30: =IFERROR(_xlfn.XLOOKUP($K30,Multiples!$B:$B,Multiples!O:O),"") -> 0.079302004 | P30: =IFERROR(_xlfn.XLOOKUP($K30,Multiples!$B:$B,Multiples!P:P),"") -> 0.11114367 | Q30: =IFERROR(_xlfn.XLOOKUP($K30,Multiples!$B:$B,Multiples!Q:Q),"") -> 0.060359393 | R30: =IFERROR(_xlfn.XLOOKUP($K30,Multiples!$B:$B,Multiples!R:R),"") -> 0.088473737 | U30: Statistics
D31: =+D30+1 -> 2027 | E31: =+DCF!J48 -> 1683.4559 | F31: =+DCF!J78 -> 0.1030754 | G31: =+INDEX(DCF!X12:AA12,MATCH(Summary!$G$25,{"FCFF","FCFE","Tax Shield","Total Payout"},0)) -> 236.39083 | H31: =+IF(Summary!$G$25="FCFF",DCF!AB12,IF(Summary!$G$25="FCFE",DCF!AC12,DCF!AD12)) -> 156.19555 | I31: =+DCF!J152 -> -9.888 | K31: Gross Profit Margin | N31: =IFERROR(_xlfn.XLOOKUP($K31,Multiples!$B:$B,Multiples!N:N),"") -> 0.64201938 | O31: =IFERROR(_xlfn.XLOOKUP($K31,Multiples!$B:$B,Multiples!O:O),"") -> 0.67449896 | P31: =IFERROR(_xlfn.XLOOKUP($K31,Multiples!$B:$B,Multiples!P:P),"") -> 0.70719797 | Q31: =IFERROR(_xlfn.XLOOKUP($K31,Multiples!$B:$B,Multiples!Q:Q),"") -> 0.65 | R31: =IFERROR(_xlfn.XLOOKUP($K31,Multiples!$B:$B,Multiples!R:R),"") -> 0.675 | U31: Beta | V31: =Peers!D68 -> 1.6084
D32: =+D31+1 -> 2028 | E32: =+DCF!K48 -> 1867.7453 | F32: =+DCF!K78 -> 0.11086001 | G32: =+INDEX(DCF!X13:AA13,MATCH(Summary!$G$25,{"FCFF","FCFE","Tax Shield","Total Payout"},0)) -> 256.05524 | H32: =+IF(Summary!$G$25="FCFF",DCF!AB13,IF(Summary!$G$25="FCFE",DCF!AC13,DCF!AD13)) -> 185.80374 | I32: =+DCF!K152 -> -10.3104 | K32: SG&A Margin | N32: =IFERROR(_xlfn.XLOOKUP($K32,Multiples!$B:$B,Multiples!N:N),"") -> 0.56578276 | O32: =IFERROR(_xlfn.XLOOKUP($K32,Multiples!$B:$B,Multiples!O:O),"") -> 0.55684174 | P32: =IFERROR(_xlfn.XLOOKUP($K32,Multiples!$B:$B,Multiples!P:P),"") -> 0.56099228 | Q32: =IFERROR(_xlfn.XLOOKUP($K32,Multiples!$B:$B,Multiples!Q:Q),"") -> 0.5612056 | R32: =IFERROR(_xlfn.XLOOKUP($K32,Multiples!$B:$B,Multiples!R:R),"") -> 0.55967987 | U32: % Float | V32: =+Peers!D67 -> 0.97925532
D33: =+D32+1 -> 2029 | E33: =+DCF!L48 -> 2051.2897 | F33: =+DCF!L78 -> 0.11529763 | G33: =+INDEX(DCF!X14:AA14,MATCH(Summary!$G$25,{"FCFF","FCFE","Tax Shield","Total Payout"},0)) -> 309.19978 | H33: =+IF(Summary!$G$25="FCFF",DCF!AB14,IF(Summary!$G$25="FCFE",DCF!AC14,DCF!AD14)) -> 211.64388 | I33: =+DCF!L152 -> -10.64832 | K33: Net Income Margin | N33: =IFERROR(_xlfn.XLOOKUP($K33,Multiples!$B:$B,Multiples!N:N),"") -> 0.055838858 | O33: =IFERROR(_xlfn.XLOOKUP($K33,Multiples!$B:$B,Multiples!O:O),"") -> 0.10625432 | P33: =IFERROR(_xlfn.XLOOKUP($K33,Multiples!$B:$B,Multiples!P:P),"") -> 0.12471921 | Q33: =IFERROR(_xlfn.XLOOKUP($K33,Multiples!$B:$B,Multiples!Q:Q),"") -> 0.047416291 | R33: =IFERROR(_xlfn.XLOOKUP($K33,Multiples!$B:$B,Multiples!R:R),"") -> 0.073163348 | U33: % Held by Insiders | V33: =Peers!D70 -> 0.0264
U34: % Held by Institutions | V34: =Peers!D71 -> 0.9616
D35: SWOT Analysis | K35: Liquidity Ratios | N35: 2022 | O35: =+N35+1 -> 2023 | P35: =+O35+1 -> 2024 | Q35: =+P35+1 -> 2025 | R35: =+Q35+1 -> 2026 | U35: Short % of Float | V35: =+Peers!D72 -> 0.1837
D36: Strengths | G36: Weaknesses | K36: Cash Ratio | N36: =IFERROR(_xlfn.XLOOKUP($K36,Multiples!$B:$B,Multiples!N:N),"") -> 0.66769231 | O36: =IFERROR(_xlfn.XLOOKUP($K36,Multiples!$B:$B,Multiples!O:O),"") -> 1.1185185 | P36: =IFERROR(_xlfn.XLOOKUP($K36,Multiples!$B:$B,Multiples!P:P),"") -> 0.36175192 | Q36: =IFERROR(_xlfn.XLOOKUP($K36,Multiples!$B:$B,Multiples!Q:Q),"") -> 0.34007724 | R36: =IFERROR(_xlfn.XLOOKUP($K36,Multiples!$B:$B,Multiples!R:R),"") -> 1.0788852 | W36: 120.87
D37: Affordable and High-Quality Products; Strong Brand Identity and Digital Presence: Huge on TikTok and has big influencer support, digital sales account for 22% of revenue; Cruelty-Free and Vegan Products; | G37: Tarriff implications: China is a big supplier; Dependence on Third-Party Retailers; Brand Perception: Some consumers may associate low price with lower quality | K37: Quick Ratio | N37: =IFERROR(_xlfn.XLOOKUP($K37,Multiples!$B:$B,Multiples!N:N),"") -> 1.3692308 | O37: =IFERROR(_xlfn.XLOOKUP($K37,Multiples!$B:$B,Multiples!O:O),"") -> 1.7472222 | P37: =IFERROR(_xlfn.XLOOKUP($K37,Multiples!$B:$B,Multiples!P:P),"") -> 0.77566031 | Q37: =IFERROR(_xlfn.XLOOKUP($K37,Multiples!$B:$B,Multiples!Q:Q),"") -> 1.004404 | R37: =IFERROR(_xlfn.XLOOKUP($K37,Multiples!$B:$B,Multiples!R:R),"") -> 1.8426952 | U37: Major Holders | W37: 113.63
K38: Current Ratio | N38: =IFERROR(_xlfn.XLOOKUP($K38,Multiples!$B:$B,Multiples!N:N),"") -> 2.9692308 | O38: =IFERROR(_xlfn.XLOOKUP($K38,Multiples!$B:$B,Multiples!O:O),"") -> 2.8083333 | P38: =IFERROR(_xlfn.XLOOKUP($K38,Multiples!$B:$B,Multiples!P:P),"") -> 1.5951187 | Q38: =IFERROR(_xlfn.XLOOKUP($K38,Multiples!$B:$B,Multiples!Q:Q),"") -> 2.2947213 | R38: =IFERROR(_xlfn.XLOOKUP($K38,Multiples!$B:$B,Multiples!R:R),"") -> 2.2947213 | U38: Baillie Gifford & Co | V38: 0.1422
U39: Vanguard Group Inc. | V39: 0.0976
D40: Opportunities | G40: Threats | K40: Cash Flow Ratios | N40: 2022 | O40: =+N40+1 -> 2023 | P40: =+O40+1 -> 2024 | Q40: =+P40+1 -> 2025 | R40: =+Q40+1 -> 2026 | U40: BlackRock Inc. | V40: 0.0948
D41: Growing E-commerce Market; Global Expansion; Product Innovation: Developing new products in response to trends | G41: Intense Competition: The beauty industry is highly competitive with huge giants; Economic Downturns; Changing Consumer Preferences: Shifts in consumer preferences towards premium or luxury brands | K41: Cash Conversion Cycle | N41: =IFERROR(_xlfn.XLOOKUP($K41,Multiples!$B:$B,Multiples!N:N),"") -> 244.24502 | O41: =IFERROR(_xlfn.XLOOKUP($K41,Multiples!$B:$B,Multiples!O:O),"") -> 180.52541 | P41: =IFERROR(_xlfn.XLOOKUP($K41,Multiples!$B:$B,Multiples!P:P),"") -> 248.3688 | Q41: =IFERROR(_xlfn.XLOOKUP($K41,Multiples!$B:$B,Multiples!Q:Q),"") -> 176.69485 | R41: =IFERROR(_xlfn.XLOOKUP($K41,Multiples!$B:$B,Multiples!R:R),"") -> 164.86016 | U41: JPMorgan Chase & Co. | V41: 0.0505
K42: Net Income / Op Cash Flow | N42: =IFERROR(_xlfn.XLOOKUP($K42,Multiples!$B:$B,Multiples!N:N),"") -> 1.1230769 | O42: =IFERROR(_xlfn.XLOOKUP($K42,Multiples!$B:$B,Multiples!O:O),"") -> 0.60353288 | P42: =IFERROR(_xlfn.XLOOKUP($K42,Multiples!$B:$B,Multiples!P:P),"") -> 1.7935393 | Q42: =IFERROR(_xlfn.XLOOKUP($K42,Multiples!$B:$B,Multiples!Q:Q),"") -> -10.245195 | R42: =IFERROR(_xlfn.XLOOKUP($K42,Multiples!$B:$B,Multiples!R:R),"") -> 0.54538404 | U42: William Blair Inv. Man LLC. | V42: 0.0409
K43: Chg in Cash / Op Cash Flow | N43: =IFERROR(_xlfn.XLOOKUP($K43,Multiples!$B:$B,Multiples!N:N),"") -> -0.73846154 | O43: =IFERROR(_xlfn.XLOOKUP($K43,Multiples!$B:$B,Multiples!O:O),"") -> 0.7595682 | P43: =IFERROR(_xlfn.XLOOKUP($K43,Multiples!$B:$B,Multiples!P:P),"") -> -0.17696629 | Q43: =IFERROR(_xlfn.XLOOKUP($K43,Multiples!$B:$B,Multiples!Q:Q),"") -> 4.7792657 | R43: =IFERROR(_xlfn.XLOOKUP($K43,Multiples!$B:$B,Multiples!R:R),"") -> 0.85761241 | U43: Wellington Management Group LLP | V43: 0.0397
U44: Champlain Investment Partners LLC | V44: 0.0395
D45: Revenue by Region | G45: Revenue by Segment | K45: Leverage Ratios | N45: 2022 | O45: =+N45+1 -> 2023 | P45: =+O45+1 -> 2024 | Q45: =+P45+1 -> 2025 | R45: =+Q45+1 -> 2026 | U45: Clearbridge Investments LLC | V45: 0.0325
K46: Total Debt / Equity | N46: =IFERROR(_xlfn.XLOOKUP($K46,Multiples!$B:$B,Multiples!N:N),"") -> 356.27401 | O46: =IFERROR(_xlfn.XLOOKUP($K46,Multiples!$B:$B,Multiples!O:O),"") -> 186.13139 | P46: =IFERROR(_xlfn.XLOOKUP($K46,Multiples!$B:$B,Multiples!P:P),"") -> 296.14068 | Q46: =IFERROR(_xlfn.XLOOKUP($K46,Multiples!$B:$B,Multiples!Q:Q),"") -> -4.9765523e-08 | R46: =IFERROR(_xlfn.XLOOKUP($K46,Multiples!$B:$B,Multiples!R:R),"") -> -5.1188147e-08 | U46: State Street Corporation | V46: 0.031
K47: Total Debt / Capital | N47: =IFERROR(_xlfn.XLOOKUP($K47,Multiples!$B:$B,Multiples!N:N),"") -> 0.99720103 | O47: =IFERROR(_xlfn.XLOOKUP($K47,Multiples!$B:$B,Multiples!O:O),"") -> 0.99465616 | P47: =IFERROR(_xlfn.XLOOKUP($K47,Multiples!$B:$B,Multiples!P:P),"") -> 0.99663459 | Q47: =IFERROR(_xlfn.XLOOKUP($K47,Multiples!$B:$B,Multiples!Q:Q),"") -> -4.9765525e-08 | R47: =IFERROR(_xlfn.XLOOKUP($K47,Multiples!$B:$B,Multiples!R:R),"") -> -5.1188149e-08 | U47: Morgan Stanley | V47: 0.0211
...

Sheet Segments
B2: Segments
B4: Regions | D4: Weight | E4: 2020 | F4: =+E4+1 -> 2021 | G4: =+F4+1 -> 2022 | H4: =+G4+1 -> 2023 | I4: =+H4+1 -> 2024 | J4: ="CAGR "&$G$4&" - "&$I$4 -> CAGR 2022 - 2024 | K4: 2021 | L4: =+K4+1 -> 2022 | M4: =+L4+1 -> 2023 | N4: =+M4+1 -> 2024
B6: United States | D6: =IFERROR(I6/SUM($I$6:$I$12),"") -> 0.84775391 | E6: 255.3 | F6: 284.2 | G6: 347.5 | H6: 506.8 | I6: 868.1 | J6: =IFERROR((I6/G6)^(1/COUNT($G$4:$I$4))-1,"") -> 0.35687024 | K6: =IFERROR((F6-E6)/E6,"") -> 0.11320016 | L6: =IFERROR((G6-F6)/F6,"") -> 0.22273047 | M6: =IFERROR((H6-G6)/G6,"") -> 0.45841727 | N6: =IFERROR((I6-H6)/H6,"") -> 0.7129045 | AB6: United States | AC6: 0.848
B7: Other International | D7: =IFERROR(I7/SUM($I$6:$I$12),"") -> 0.15224609 | E7: 27.6 | F7: 33.9 | G7: 44.7 | H7: 72.1 | I7: 155.9 | J7: =IFERROR((I7/G7)^(1/COUNT($G$4:$I$4))-1,"") -> 0.51651321 | K7: =IFERROR((F7-E7)/E7,"") -> 0.22826087 | L7: =IFERROR((G7-F7)/F7,"") -> 0.31858407 | M7: =IFERROR((H7-G7)/G7,"") -> 0.61297539 | N7: =IFERROR((I7-H7)/H7,"") -> 1.1622746 | AB7: Canada | AC7: =15.2%/3 -> 0.050666667
D8: =IFERROR(I8/SUM($I$6:$I$12),"") -> 0 | J8: =IFERROR((I8/E8)^(1/COUNT($E$4:$I$4))-1,"") | K8: =IFERROR(F8-E8/E8,"") | L8: =IFERROR(G8-F8/F8,"") | M8: =IFERROR(H8-G8/G8,"") | N8: =IFERROR((I8-H8)/H8,"") | AB8: Australia | AC8: =15.2%/(13*3) -> 0.0038974359
D9: =IFERROR(I9/SUM($I$6:$I$12),"") -> 0 | J9: =IFERROR((I9/E9)^(1/COUNT($E$4:$I$4))-1,"") | K9: =IFERROR(F9-E9/E9,"") | L9: =IFERROR(G9-F9/F9,"") | M9: =IFERROR(H9-G9/G9,"") | N9: =IFERROR((I9-H9)/H9,"") | AB9: United Kingdom | AC9: =15.2%/3 -> 0.050666667
D10: =IFERROR(I10/SUM($I$6:$I$12),"") -> 0 | J10: =IFERROR((I10/E10)^(1/COUNT($E$4:$I$4))-1,"") | K10: =IFERROR(F10-E10/E10,"") | L10: =IFERROR(G10-F10/F10,"") | M10: =IFERROR(H10-G10/G10,"") | N10: =IFERROR((I10-H10)/H10,"") | AB10: Saudi Arabia | AC10: =15.2%/(13*3) -> 0.0038974359
D11: =IFERROR(I11/SUM($I$6:$I$12),"") -> 0 | AB11: France | AC11: =15.2%/(13*3) -> 0.0038974359
D12: =IFERROR(I12/SUM($I$6:$I$12),"") -> 0 | AB12: Colombia | AC12: =15.2%/(13*3) -> 0.0038974359
B13: Total | D13: =SUM(D6:D12) -> 1 | E13: =SUM(E6:E10) -> 282.9 | F13: =SUM(F6:F10) -> 318.1 | G13: =SUM(G6:G10) -> 392.2 | H13: =SUM(H6:H10) -> 578.9 | I13: =SUM(I6:I10) -> 1024 | J13: =IFERROR((I13/G13)^(1/COUNT($G$4:$I$4))-1,"") -> 0.37699001 | K13: =IFERROR(F13-E13/E13,"") -> 317.1 | L13: =IFERROR(G13-F13/F13,"") -> 391.2 | M13: =IFERROR((H13-G13)/G13,"") -> 0.47603264 | N13: =IFERROR((I13-H13)/H13,"") -> 0.768872 | AB13: Spain | AC13: =15.2%/(13*3) -> 0.0038974359
AB14: Germany | AC14: =15.2%/(13*3) -> 0.0038974359
B15: Segments | D15: Weight | E15: 2020 | F15: =+E15+1 -> 2021 | G15: =+F15+1 -> 2022 | H15: =+G15+1 -> 2023 | I15: =+H15+1 -> 2024 | J15: ="CAGR "&$E$4&" - "&$I$4 -> CAGR 2020 - 2024 | K15: 2021 | L15: =+K15+1 -> 2022 | M15: =+L15+1 -> 2023 | N15: =+M15+1 -> 2024 | AB15: Mexico | AC15: =15.2%/(13*3) -> 0.0038974359
AB16: Italy | AC16: =15.2%/(13*3) -> 0.0038974359
B17: Beauty and Cosmetics | D17: =IFERROR(I17/SUM($I$17:$I$21),"") -> 1 | E17: 283 | F17: 318 | G17: 392 | H17: 579 | I17: 1024 | J17: =IFERROR((I17/E17)^(1/COUNT($E$4:$I$4))-1,"") -> 0.2933102 | K17: =IFERROR((F17-E17)/E17,"") -> 0.12367491 | L17: =IFERROR((G17-F17)/F17,"") -> 0.2327044 | M17: =IFERROR((H17-G17)/G17,"") -> 0.47704082 | N17: =IFERROR((I17-H17)/H17,"") -> 0.76856649 | AB17: Netherlands | AC17: =15.2%/(13*3) -> 0.0038974359
D18: =IFERROR(I18/SUM($I$17:$I$21),"") -> 0 | J18: =IFERROR((I18/E18)^(1/COUNT($E$4:$I$4))-1,"") | K18: =IFERROR((F18-E18)/E18,"") | L18: =IFERROR((G18-F18)/F18,"") | M18: =IFERROR((H18-G18)/G18,"") | N18: =IFERROR((I18-H18)/H18,"") | AB18: Sweden | AC18: =15.2%/(13*3) -> 0.0038974359
D19: =IFERROR(I19/SUM($I$17:$I$21),"") -> 0 | J19: =IFERROR((I19/E19)^(1/COUNT($E$4:$I$4))-1,"") | K19: =IFERROR((F19-E19)/E19,"") | L19: =IFERROR((G19-F19)/F19,"") | M19: =IFERROR((H19-G19)/G19,"") | N19: =IFERROR((I19-H19)/H19,"") | AB19: Norway | AC19: =15.2%/(13*3) -> 0.0038974359
D20: =IFERROR(I20/SUM($I$17:$I$21),"") -> 0 | J20: =IFERROR((I20/E20)^(1/COUNT($E$4:$I$4))-1,"") | K20: =IFERROR((F20-E20)/E20,"") | L20: =IFERROR((G20-F20)/F20,"") | M20: =IFERROR((H20-G20)/G20,"") | N20: =IFERROR((I20-H20)/H20,"") | AB20: Denmark | AC20: =15.2%/(13*3) -> 0.0038974359
D21: =IFERROR(I21/SUM($I$17:$I$21),"") -> 0 | J21: =IFERROR((I21/E21)^(1/COUNT($E$4:$I$4))-1,"") | K21: =IFERROR((F21-E21)/E21,"") | L21: =IFERROR((G21-F21)/F21,"") | M21: =IFERROR((H21-G21)/G21,"") | N21: =IFERROR((I21-H21)/H21,"") | AB21: Finland | AC21: =15.2%/(13*3) -> 0.0038974359
B22: Total | D22: =SUM(D17:D21) -> 1 | E22: =SUM(E17:E21) -> 283 | F22: =SUM(F17:F21) -> 318 | G22: =SUM(G17:G21) -> 392 | H22: =SUM(H17:H21) -> 579 | I22: =SUM(I17:I21) -> 1024 | J22: =IFERROR((I22/E22)^(1/COUNT($E$4:$I$4))-1,"") -> 0.2933102 | K22: =IFERROR((F22-E22)/E22,"") -> 0.12367491 | L22: =IFERROR((G22-F22)/F22,"") -> 0.2327044 | M22: =IFERROR((H22-G22)/G22,"") -> 0.47704082 | N22: =IFERROR((I22-H22)/H22,"") -> 0.76856649 | AC22: 0
B24: Categories | D24: Description | J24: Graphs | AC24: =SUM(AC6:AC21) -> 1
B26: Eye, lip and face makeup | D26: Includes products designed to enhance and alter appearance, helping individuals achieve various looks. It can be divided in three subcategorys: eye makeup, lip makeup and face makeup.
B27: Skin care | D27: Promotes healthy skin, offering a range of products to various skin concerns, including acne, sensitivity and dryness. The products are designed to cleanse, treat, hydrate and protect the skin.
B28: Beauty tools and acessories | D28: Includes products designed to enhance the application, blending and maintenance of makeup and skincare. Help users achieve professional-looking results and improve the overall effectiveness of beauty routines.
B29: =IF(B20=0,"",B20)
B30: =IF(B21=0,"",B21)
B32: Products | D32: Weight | E32: 2020 | F32: =+E32+1 -> 2021 | G32: =+F32+1 -> 2022 | H32: =+G32+1 -> 2023 | I32: =+H32+1 -> 2024 | J32: =I32+1 -> 2025 | K32: =+J32+1 -> 2026 | L32: =+K32+1 -> 2027 | M32: =+L32+1 -> 2028 | N32: =+M32+1 -> 2029 | O32: =+N32+1 -> 2030 | P32: =+O32+1 -> 2031 | Q32: =+P32+1 -> 2032 | R32: =+Q32+1 -> 2033 | ... T32: =+S32+1 -> 2035
D34: =IFERROR(I34/$I$13,"") -> 0
D36: =IFERROR(I36/$I$13,"") -> 0
F37: =IFERROR((F36-E36)/E36,"") | G37: =IFERROR((G36-F36)/F36,"") | H37: =IFERROR((H36-G36)/G36,"") | I37: =IFERROR((I36-H36)/H36,"")
B38: Product 3 | D38: =IFERROR(I38/$I$13,"") -> 0 | J38: =I38*(1+J39) -> 0 | K38: =J38*(1+K39) -> 0 | L38: =K38*(1+L39) -> 0 | M38: =L38*(1+M39) -> 0 | N38: =M38*(1+N39) -> 0 | O38: =N38*(1+O39) -> 0 | P38: =O38*(1+P39) -> 0 | Q38: =P38*(1+Q39) -> 0 | ... T38: =S38*(1+T39) -> 0
F39: =IFERROR(F38-E38/E38,"") | G39: =IFERROR(G38-F38/F38,"") | H39: =IFERROR(H38-G38/G38,"") | I39: =IFERROR(I38-H38/H38,"")
B40: Product 4 | D40: =IFERROR(I40/$I$13,"") -> 0 | J40: =I40*(1+J41) -> 0 | K40: =J40*(1+K41) -> 0 | L40: =K40*(1+L41) -> 0 | M40: =L40*(1+M41) -> 0 | N40: =M40*(1+N41) -> 0 | O40: =N40*(1+O41) -> 0 | P40: =O40*(1+P41) -> 0 | Q40: =P40*(1+Q41) -> 0 | ... T40: =S40*(1+T41) -> 0
F41: =IFERROR(F40-E40/E40,"") | G41: =IFERROR(G40-F40/F40,"") | H41: =IFERROR(H40-G40/G40,"") | I41: =IFERROR(I40-H40/H40,"")
B42: Product 5 | D42: =IFERROR(I42/$I$13,"") -> 0 | J42: =I42*(1+J43) -> 0 | K42: =J42*(1+K43) -> 0 | L42: =K42*(1+L43) -> 0 | M42: =L42*(1+M43) -> 0 | N42: =M42*(1+N43) -> 0 | O42: =N42*(1+O43) -> 0 | P42: =O42*(1+P43) -> 0 | Q42: =P42*(1+Q43) -> 0 | ... T42: =S42*(1+T43) -> 0
F43: =IFERROR(F42-E42/E42,"") | G43: =IFERROR(G42-F42/F42,"") | H43: =IFERROR(H42-G42/G42,"") | I43: =IFERROR(I42-H42/H42,"")
B44: Total | D44: =SUM(D34:D42) -> 0 | E44: =SUM(E34:E42) -> 0 | F44: =SUM(F34:F42) -> 0 | G44: =SUM(G34:G42) -> 0 | H44: =SUM(H34:H42) -> 0 | I44: =SUM(I34:I42) -> 0 | J44: =SUM(J34:J42) -> 0 | K44: =SUM(K34:K42) -> 0 | ... T44: =SUM(T34:T42) -> 0
B46: Company's Strategy / Extra Notes
B48: Business strategy relies on offering affordable, innovative and high-quality products to achieve high, sustainable and profitable growth.
B49: Strategic focus areas: value proposition, digital leadership, powerhouse innovation, disruptive marketing engine.
B50: Geographic expansion is a top priority, including both retail and online international distribution, having recently expanded to Mexico and Germany.
...

Sheet Industry
B2: Industry Overview
B4: Sales Growth Forecast | E4: Weight | F4: 2025 | G4: =+F4+1 -> 2026 | H4: =+G4+1 -> 2027 | I4: =+H4+1 -> 2028 | J4: =+I4+1 -> 2029 | K4: =+J4+1 -> 2030 | L4: =+K4+1 -> 2031 | M4: =+L4+1 -> 2032 | N4: =+M4+1 -> 2033 | ... P4: =+O4+1 -> 2035 | Q4: ="CAGR "&$F$4&" - "&$P$4 -> CAGR 2025 - 2035 | R4: Sources
B6: Color Cosmetics | E6: 0.524 | F6: 0.148 | G6: 0.125 | H6: 0.107 | I6: 0.093 | J6: 0.082 | K6: 0.075 | L6: 0.068 | M6: 0.063 | N6: 0.058 | O6: 0.055 | P6: 0.052 | Q6: 0.072 | R6: Grand View Research
B7: Skincare | E7: 0.287 | F7: 0.189 | G7: 0.162 | H7: 0.138 | I7: 0.116 | J7: 0.102 | K7: 0.094 | L7: 0.087 | M7: 0.081 | N7: 0.076 | O7: 0.072 | P7: 0.068 | Q7: 0.0353 | R7: Statista
B8: Personal care | E8: 0.189 | F8: 0.087 | G8: 0.073 | H8: 0.065 | I8: 0.058 | J8: 0.052 | K8: 0.048 | L8: 0.045 | M8: 0.043 | N8: 0.041 | O8: 0.039 | P8: 0.038 | Q8: 0.0298 | R8: Statista
B11: Weighted Average | E11: =SUM(E6:E10) -> 1 | F11: =SUMPRODUCT(F6:F10,$E$6:$E$10) -> 0.148238 | G11: =SUMPRODUCT(G6:G10,$E$6:$E$10) -> 0.125791 | H11: =SUMPRODUCT(H6:H10,$E$6:$E$10) -> 0.107959 | I11: =SUMPRODUCT(I6:I10,$E$6:$E$10) -> 0.092986 | J11: =SUMPRODUCT(J6:J10,$E$6:$E$10) -> 0.08207 | K11: =SUMPRODUCT(K6:K10,$E$6:$E$10) -> 0.07535 | L11: =SUMPRODUCT(L6:L10,$E$6:$E$10) -> 0.069106 | M11: =SUMPRODUCT(M6:M10,$E$6:$E$10) -> 0.064386 | ... P11: =SUMPRODUCT(P6:P10,$E$6:$E$10) -> 0.053946 | Q11: =IFERROR(((1+F11)*(1+G11)*(1+H11)*(1+I11)*(1+J11)*(1+K11)*(1+L11)*(1+M11)*(1+N11)*(1+O11)*(1+P11))^(1/COUNT($F$4:$P$4))-1,"") -> 0.084760722
B13: Key Drivers | E13: Description
B15: Inclusive and Accessible Products | E15: Focuses on clean, vegan, cruelty-free products at affordable price points, disrupting industry norms.
B16: Powerhouse Innovation | E16: Recognized for rapid product development and first-to-market launches, including dermatologist-developed formulas
B17: Digital Marketing Leadership | E17: Leverages social media platforms to connect with consumers and drive engagement.
B18: Retail Partnerships | E18: Strong relationships with major retailers like Target, Walmart, and Ulta Beauty expand distribution channels domestically and internationally.
B20: Industry Trends | E20: Description
B22: Increased Premiumization | E22: Consumers trading up for high-quality, prestige-inspired products at accessible price points.
B23: Sustainability and Corporate Social Responsibility | E23: Growing consumer demand for clean ingredients, cruelty-free formulations, and environmentally friendly packaging.
B26: Market Share | E26: Headquarters | G26: Revenues | H26: (in MM of USD) | I26: Market Share
B28: {=+_FV(DCF!R4,"Name")} -> E.L.F. BEAUTY, INC. | E28: United States | G28: {=TRANSPOSE(Peers!D91:N91)} -> 1023.9 | I28: =IFERROR(G28/$G$40,"") -> 0.0053889474
B29: L'Oréal S.A. | E29: France | G29: 43486 | I29: =IFERROR(G29/$G$40,"") -> 0.22887368
B30: Estee Lauder Companies Inc. | E30: United States | G30: 15608 | I30: =IFERROR(G30/$G$40,"") -> 0.082147368
B31: Coty Inc. | E31: United States | G31: 6118 | I31: =IFERROR(G32/$G$40,"") -> 0.058984211
B32: Ultra Beauty | E32: United States | G32: 11207 | I32: =IFERROR(G32/$G$40,"") -> 0.058984211
B33: Shiseido Company | E33: Japan | G33: 6545 | I33: =IFERROR(G33/$G$40,"") -> 0.034447368
B34: Natura &Co Holding S.A. | E34: Brazil | G34: 4487 | I34: =IFERROR(G34/$G$40,"") -> 0.023615789
G35: 0 | I35: =IFERROR(G35/$G$40,"") -> 0
G36: 0 | I36: =IFERROR(G36/$G$40,"") -> 0
B37: {=+_FV(Peers!#REF!,"Name")} -> #VALUE! | G37: 0 | I37: =IFERROR(G37/$G$40,"") -> 0
B38: {=+_FV(Peers!#REF!,"Name")} -> #VALUE! | G38: 0 | I38: =IFERROR(G38/$G$40,"") -> 0
B39: Others | E39: -- | I39: =IFERROR(G39/$G$40,"") -> 0
B40: Industry Size | E40: -- | G40: 190000 | I40: 1
B42: Porter's Five Forces Analysis | E42: Rating | H42: Graph
B44: Threat of New Entrants | E44: =IFERROR(AVERAGE(E45:E50),"") -> 2.6666667
B45: Economies of scale | E45: 3
B46: Product differentiation | E46: 3
B47: Capital requirements | E47: 2
B48: Access to distribution channels | E48: 3
B49: Regulations | E49: 3
B50: Switching costs | E50: 2
B51: Bargaining Power of Suppliers | E51: =IFERROR(AVERAGE(E52:E56),"") -> 2.6
B52: Number of suppliers | E52: 4
B53: Uniqueness | E53: 3
B54: Switching Costs | E54: 2
...

Sheet Peers
D3: Revenue Growth | F3: EBITDA Margin | H3: Profit Margin | J3: EV / Revenue | L3: EV / EBITDA | N3: Price / Earnings
B4: Peers | C4: Ticker | D4: =+Inputs!O4&"-"&Inputs!P4 -> 2022-2023 | E4: =+Inputs!P4&"-"&Inputs!Q4 -> 2023-2024 | F4: 2023 | G4: 2024 | H4: =+Inputs!O4&"-"&Inputs!P4 -> 2022-2023 | I4: =+Inputs!P4&"-"&Inputs!Q4 -> 2023-2024 | J4: 2023 | K4: 2024 | L4: 2023 | M4: 2024 | N4: 2023 | O4: 2024
A5: =+D85 -> #VALUE! | B5: {=IFERROR(_FV(A5,"Name"),"")} -> E.L.F. BEAUTY, INC. | C5: {=IFERROR(_FV(A5,"Ticker symbol",TRUE),"")} -> ELF | D5: =IFERROR(D88/D87-1,"") -> 0.47577766 | E5: =IFERROR(D91/D88-1,"") -> 0.76900484 | F5: =IFERROR(D89/D88,"") -> 0.11765722 | G5: =IFERROR(D94/D91,"") -> 0.14620568 | H5: =IFERROR(D90/D88,"") -> 0.10625432 | I5: =IFERROR(D99/D91,"") -> 0.12471921 | J5: {=IFERROR((_FV(A5,"Market cap",TRUE)/1000000+D$115-D$105)/D$88,"")} -> 13.46396 | K5: {=IFERROR((_FV(A5,"Market cap",TRUE)/1000000+D$115-D$105)/D$91,"")} -> 7.6110365 | L5: {=+IFERROR((_FV(A5,"Market cap",TRUE)/1000000+D$115-D$105)/D$89,"")} -> 114.43378 | M5: {=IFERROR((_FV(A5,"Market cap",TRUE)/1000000+D$115-D$105)/D$94,"")} -> 52.057049 | N5: {=IFERROR((_FV(A5,"Market cap",TRUE)/1000000)/D$90,"")} -> 125.37952 | O5: {=IFERROR((_FV(A5,"Market cap",TRUE)/1000000)/D$99,"")} -> 60.382461
A6: #VALUE! | B6: L'Oreal S.A. | C6: {=IFERROR(_FV(A6,"Ticker symbol",TRUE),"")} -> OR | D6: =+IFERROR(E88/E87-1,"") -> 0.07637219 | E6: =IFERROR(E91/E88-1,"") -> 0.055946773 | F6: =IFERROR(E89/E88,"") -> 0.21781361 | G6: =+IFERROR(E94/E91,"") -> 0.22172653 | H6: =IFERROR(E90/E88,"") -> 0.15016269 | I6: =+IFERROR(D99/D93,"") -> 0.17635686 | J6: {=+IFERROR((_FV(A6,"Market cap",TRUE)/1000000+E$115-E$105)/E$88,"")} -> 4.9528508 | K6: {=IFERROR(+(_FV(A6,"Market cap",TRUE)/1000000+E$115-E$105)/E$91,"")} -> 4.690436 | L6: {=IFERROR(+(_FV(A6,"Market cap",TRUE)/1000000+E$115-E$105)/E$89,"")} -> 22.738941 | M6: {=IFERROR(+(_FV(A6,"Market cap",TRUE)/1000000+E$115-E$105)/E$94,"")} -> 21.154149 | N6: {=IFERROR(+(_FV(A6,"Market cap",TRUE)/1000000)/E$90,"")} -> 32.264764 | O6: {=IFERROR(+(_FV(A6,"Market cap",TRUE)/1000000)/E$99,"")} -> 31.136907
A7: #VALUE! | B7: Estée Lauder Companies Inc. | C7: {=IFERROR(_FV(A7,"Ticker symbol",TRUE),"")} -> EL | D7: =IFERROR(F88/F87-1,"") -> -0.10300502 | E7: =IFERROR(+F91/F88-1,"") -> -0.018981772 | F7: =IFERROR(F89/F88,"") -> 0.18925204 | G7: =IFERROR(F94/F91,"") -> 0.18394413 | H7: =IFERROR(F90/F88,"") -> 0.078441232 | I7: =+IFERROR(F99/F91,"") -> 0.059905177 | J7: {=IFERROR(+(_FV(A7,"Market cap",TRUE)/1000000+F$115-F$106)/F$88,"")} -> 2.5199183 | K7: {=IFERROR(+(_FV(A7,"Market cap",TRUE)/1000000+F$115-F$106)/F$91,"")} -> 2.5686763 | L7: {=IFERROR(+(_FV(A7,"Market cap",TRUE)/1000000+F$115-F$106)/F$89,"")} -> 13.315144 | M7: {=IFERROR(+(_FV(A7,"Market cap",TRUE)/1000000+F$115-F$106)/F$94,"")} -> 13.964437 | N7: {=IFERROR(+(_FV(A7,"Market cap",TRUE)/1000000)/F$90,"")} -> 25.632131 | O7: {=IFERROR(+(_FV(A7,"Market cap",TRUE)/1000000)/F$99,"")} -> 34.212727
A8: #VALUE! | B8: Coty Inc. | C8: {=IFERROR(_FV(A8,"Ticker symbol",TRUE),"")} -> COTY | D8: =+IFERROR(G88/G87-1,"") -> 0.047134238 | E8: =IFERROR(G91/G88-1,"") -> 0.10154843 | F8: =IFERROR(G89/G88,"") -> 0.16168527 | G8: =IFERROR(G94/G91,"") -> 0.17325924 | H8: =IFERROR(G90/G88,"") -> 0.03474973 | I8: =+IFERROR(G99/G91,"") -> 0.016018307 | J8: {=IFERROR(+(_FV(A8,"Market cap",TRUE)/1000000+G$115-G$105)/G$88,"")} -> 1.3077059 | K8: {=IFERROR(+(_FV(A8,"Market cap",TRUE)/1000000+G$115-G$105)/G$91,"")} -> 1.1871524 | L8: {=IFERROR(+(_FV(A8,"Market cap",TRUE)/1000000+G$115-G$105)/G$89,"")} -> 8.0879717 | M8: {=IFERROR(+(_FV(A8,"Market cap",TRUE)/1000000+G$115-G$105)/G$94,"")} -> 6.8518854 | N8: {=IFERROR(+(_FV(A8,"Market cap",TRUE)/1000000)/G$90,"")} -> 17.839371 | O8: {=IFERROR(+(_FV(A8,"Market cap",TRUE)/1000000)/G$99,"")} -> 35.132638
A9: #VALUE! | B9: Ulta Beauty | C9: {=IFERROR(_FV(A9,"Ticker symbol",TRUE),"")} -> ULTA | D9: =IFERROR(H88/H87-1,"") -> 0.18282934 | E9: =IFERROR(H91/H88-1,"") -> 0.097756881 | F9: =IFERROR(H89/H88,"") -> 0.2161818 | G9: =IFERROR(H94/H91,"") -> 0.20308736 | H9: =IFERROR(H90/H88,"") -> 0.12224508 | I9: =+IFERROR(H99/H91,"") -> 0.11599893 | J9: {=IFERROR((_FV(A9,"Market cap",TRUE)/1000000+H$115-H$105)/H$88,"")} -> 2.562027 | K9: {=IFERROR(+(_FV(A9,"Market cap",TRUE)/1000000+H$115-H$105)/H$91,"")} -> 2.3338747 | L9: {=IFERROR(+(_FV(A9,"Market cap",TRUE)/1000000+H$115-H$105)/H$89,"")} -> 11.851261 | M9: {=IFERROR(+(_FV(A9,"Market cap",TRUE)/1000000+H$115-H$105)/H$94,"")} -> 11.491975 | N9: {=IFERROR(+(_FV(A9,"Market cap",TRUE)/1000000)/H$90,"")} -> 20.041454 | O9: {=IFERROR(+(_FV(A9,"Market cap",TRUE)/1000000)/H$99,"")} -> 19.239795
A10: #VALUE! | B10: Shiseido Company | C10: 4911 | D10: =+IFERROR(I88/I87-1,"") -> -0.15056923 | E10: =IFERROR(I91/I88-1,"") -> -0.056780516 | F10: =IFERROR(I89/I88,"") -> 0.11601095 | G10: =IFERROR(I94/I91,"") -> 0.11138273 | H10: =IFERROR(I90/I88,"") -> 0.02896671 | I10: =+IFERROR(I99/I91,"") -> 0.0079449962 | J10: {=IFERROR((_FV(A10,"Market cap",TRUE)/1000000+I$115-I$105)/I$88,"")} -> 1.1936757 | K10: {=IFERROR(+(_FV(A10,"Market cap",TRUE)/1000000+I$115-I$105)/I$91,"")} -> 1.2655334 | L10: {=IFERROR(+(_FV(A10,"Market cap",TRUE)/1000000+I$115-I$105)/I$89,"")} -> 10.289337 | M10: {=IFERROR(+(_FV(A10,"Market cap",TRUE)/1000000+I$115-I$105)/I$94,"")} -> 11.362025 | N10: {=IFERROR(+(_FV(A10,"Market cap",TRUE)/1000000)/I$90,"")} -> 33.611522 | O10: {=IFERROR(+(_FV(A10,"Market cap",TRUE)/1000000)/I$99,"")} -> 129.92146
A11: #VALUE! | B11: {=+_FV(A11,"Name")} -> Natura &Co Holding SA | C11: {=IFERROR(_FV(A11,"Ticker symbol",TRUE),"")} -> NTCO3Q | D11: =IFERROR(J88/J87-1,"") -> -0.29924176 | E11: =IFERROR(J91/J88-1,"") -> 0.12908908 | F11: =IFERROR(J89/J88,"") -> 0.19904378 | G11: =IFERROR(J94/J91,"") -> 0.15934923 | H11: =IFERROR(J90/J88,"") -> 0.056618017 | I11: =+IFERROR(J99/J91,"") -> 0.022955204 | J11: {=IFERROR(+(_FV(A11,"Market cap",TRUE)*Q11/1000000+J$115-J$105)/J$88,"")} -> 1.0653106 | K11: {=IFERROR(+(_FV(A11,"Market cap",TRUE)*Q11/1000000+J$115-J$105)/J$91,"")} -> 0.94351329 | L11: {=IFERROR(+(_FV(A11,"Market cap",TRUE)*Q11/1000000+J$115-J$105)/J$89,"")} -> 5.3521418 | M11: {=IFERROR(+(_FV(A11,"Market cap",TRUE)*Q11/1000000+J$115-J$105)/J$94,"")} -> 5.9210408 | N11: {=IFERROR(+(_FV(A11,"Market cap",TRUE)*Q11/1000000)/J$90,"")} -> 16.39353 | O11: {=IFERROR(+(_FV(A11,"Market cap",TRUE)*Q11/1000000)/J$99,"")} -> 35.811108 | P11: #VALUE! | Q11: {=+_FV(P11,"Previous close",TRUE)} -> 0.1873
B12: Average | D12: =IFERROR(AVERAGE(D5:D11),"") -> 0.032756776 | E12: =IFERROR(AVERAGE(E5:E11),"") -> 0.15394053 | F12: =IFERROR(AVERAGE(F5:F11),"") -> 0.17394924 | G12: =IFERROR(AVERAGE(G5:G11),"") -> 0.17127927 | H12: =IFERROR(AVERAGE(H5:H11),"") -> 0.082491111 | I12: =IFERROR(AVERAGE(I5:I11),"") -> 0.074842669 | J12: =IFERROR(AVERAGE(J5:J11),"") -> 3.8664927 | K12: =IFERROR(AVERAGE(K5:K11),"") -> 2.9428889 | ... O12: =IFERROR(AVERAGE(O5:O11),"") -> 49.4053
B13: Deviation from Average | D13: =IFERROR(+D12-D5,"") -> -0.44302089 | E13: =IFERROR(E12-E5,"") -> -0.61506431 | F13: =+IFERROR(F12-F5,"") -> 0.056292018 | G13: =IFERROR(G12-G5,"") -> 0.025073588 | H13: =IFERROR(+H5-H12,"") -> 0.023763208 | I13: =+IFERROR(I5-I12,"") -> 0.049876542 | J13: =+IFERROR(J5-J12,"") -> 9.5974677 | K13: =+IFERROR(K5-K12,"") -> 4.6681475 | L13: =IFERROR(+L5-L12,"") -> 87.852553 | M13: =IFERROR(M5-M12,"") -> 34.513826 | N13: =IFERROR(+N5-N12,"") -> 86.642047 | O13: =IFERROR(+O5-O12,"") -> 10.977161
D15: Trading Multiple | G15: Net | H15: Preferred | I15: Non-Controlling | J15: Equity Value | M15: Implied Upside (Downside)
B16: Implied Share Price | D16: Revenue | E16: EBITDA | F16: P/E | G16: Debt | H16: Stock | I16: Interest | J16: Revenue | K16: EBITDA | L16: P/E | M16: Revenue | N16: EBITDA | O16: P/E | P16: Current Price
B18: Second Minimum | D18: =IFERROR(SMALL(K5:K11,2),"") -> 1.1871524 | E18: =IFERROR(SMALL(M5:M11,2),"") -> 6.8518854 | F18: =IFERROR(SMALL(O5:O11,2),"") -> 31.136907 | G18: =-Inputs!$Q$98+Inputs!$Q$99 -> 82.1 | H18: =+Inputs!$Q$100 -> 0 | I18: =+Inputs!$Q$101 -> 0 | J18: =IFERROR(+D18*$D$91+G18+H18+I18,"") -> 1297.6254 | K18: =IFERROR(E18*$D$94+G18+H18+I18,"") -> 1107.8272 | L18: =IFERROR(F18*$D$99,"") -> 3976.183 | M18: {=IFERROR(+(J18/_FV($A$5,"Shares outstanding",TRUE)*1000000)/$P$18-1,"")} -> -0.83171414 | N18: {=IFERROR((+K18/_FV($A$5,"Shares outstanding",TRUE)*1000000)/$P$18-1,"")} -> -0.8563286 | O18: {=IFERROR(+(L18/_FV($A$5,"Shares outstanding",TRUE)*1000000)/$P$18-1,"")} -> -0.48433856 | P18: {=+_FV(A5,"Price")} -> 135.91
B19: Average | D19: =+IFERROR(AVERAGE(K5:K11),"") -> 2.9428889 | E19: =IFERROR(+AVERAGE(M5:M11),"") -> 17.543223 | F19: =IFERROR(+AVERAGE(O5:O11),"") -> 49.4053 | G19: =-Inputs!$Q$98+Inputs!$Q$99 -> 82.1 | H19: =+Inputs!$Q$100 -> 0 | I19: =+Inputs!$Q$101 -> 0 | J19: =IFERROR(+D19*$D$91+G19+H19+I19,"") -> 3095.324 | K19: =IFERROR(E19*$D$94+G19+H19+I19,"") -> 2708.3205 | L19: =IFERROR(+F19*$D$99,"") -> 6309.0568 | M19: {=IFERROR(+(J19/_FV($A$5,"Shares outstanding",TRUE)*1000000)/$P$18-1,"")} -> -0.59857501 | N19: {=IFERROR((+K19/_FV($A$5,"Shares outstanding",TRUE)*1000000)/$P$18-1,"")} -> -0.64876455 | O19: {=IFERROR(+(L19/_FV($A$5,"Shares outstanding",TRUE)*1000000)/$P$18-1,"")} -> -0.18179387
B20: Median | D20: =IFERROR(MEDIAN(K5:K11),"") -> 2.3338747 | E20: =IFERROR(MEDIAN(M5:M11),"") -> 11.491975 | F20: =IFERROR(MEDIAN(O5:O11),"") -> 35.132638 | G20: =-Inputs!$Q$98+Inputs!$Q$99 -> 82.1 | H20: =+Inputs!$Q$100 -> 0 | I20: =+Inputs!$Q$101 -> 0 | J20: =IFERROR(D20*$D$91+G20+H20+I20,"") -> 2471.7543 | K20: =IFERROR(E20*$D$94+G20+H20+I20,"") -> 1802.4486 | L20: =IFERROR(+F20*$D$99,"") -> 4486.4379 | M20: {=IFERROR(+(J20/_FV($A$5,"Shares outstanding",TRUE)*1000000)/$P$18-1,"")} -> -0.67944423 | N20: {=IFERROR((+K20/_FV($A$5,"Shares outstanding",TRUE)*1000000)/$P$18-1,"")} -> -0.76624485 | O20: {=+IFERROR((L20/_FV($A$5,"Shares outstanding",TRUE)*1000000)/$P$18-1,"")} -> -0.41816485
B21: Second Maximum | D21: =IFERROR(LARGE(K5:K11,2),"") -> 4.690436 | E21: =IFERROR(LARGE(M5:M11,2),"") -> 21.154149 | F21: =IFERROR(LARGE(O5:O11,2),"") -> 60.382461 | G21: =-Inputs!$Q$98+Inputs!$Q$99 -> 82.1 | H21: =+Inputs!$Q$100 -> 0 | I21: =+Inputs!$Q$101 -> 0 | J21: =IFERROR(+D21*$D$91+G21+H21+I21,"") -> 4884.6374 | K21: =IFERROR(E21*$D$94+G21+H21+I21,"") -> 3248.876 | L21: =IFERROR(+F21*$D$99,"") -> 7710.8403 | M21: {=IFERROR(+(J21/_FV($A$5,"Shares outstanding",TRUE)*1000000)/$P$18-1,"")} -> -0.36652333 | N21: {=IFERROR((+K21/_FV($A$5,"Shares outstanding",TRUE)*1000000)/$P$18-1,"")} -> -0.57866122 | O21: {=IFERROR(+(L21/_FV($A$5,"Shares outstanding",TRUE)*1000000)/$P$18-1,"")} -> 0
B23: Profitability | D23: =+LEFT(B5, FIND(" ", B5 & " ") - 1) -> E.L.F. | E23: =+LEFT(B6, FIND(" ", B6 & " ") - 1) -> L'Oreal | F23: =+_xlfn.TEXTBEFORE(B7, " ",2) -> Estée Lauder | G23: =+LEFT(B8, FIND(" ", B8 & " ") - 1) -> Coty | H23: =B9 -> Ulta Beauty | I23: =+LEFT(B10, FIND(" ", B10 & " ") - 1) -> Shiseido | J23: =+LEFT(B11, FIND(" ", B11 & " ") - 1) -> Natura | L23: =+LEFT(#REF!, FIND(" ",#REF! & " ") - 1) -> #REF! | M23: =+LEFT(#REF!, FIND(" ",#REF! & " ") - 1) -> #REF! | N23: =+LEFT(#REF!, FIND(" ",#REF! & " ") - 1) -> #REF! | O23: Average
B25: Operating Margin | D25: =IFERROR(D95/D91,"") -> 0.11114367 | E25: =IFERROR(E95/E91,"") -> 0.19951249 | F25: =IFERROR(F95/F91,"") -> 0.1017427 | G25: =IFERROR(G95/G91,"") -> 0.094965675 | H25: =IFERROR(H95/H91,"") -> 0.15070938 | I25: =IFERROR(I95/I91,"") -> 0.034988541 | J25: =IFERROR(J95/J91,"") -> 0.11901047 | K25: =IFERROR(K95/K91,"") | ... N25: =IFERROR(N95/N91,"") | O25: =IFERROR(+AVERAGE(D25:N25),"") -> 0.11601042
B26: Net Income Margin | D26: =IFERROR(D99/D91,"") -> 0.12471921 | E26: =IFERROR(E99/E91,"") -> 0.14735777 | F26: =IFERROR(F99/F91,"") -> 0.059905177 | G26: =IFERROR(G99/G91,"") -> 0.016018307 | H26: =IFERROR(H99/H91,"") -> 0.11599893 | I26: =IFERROR(I99/I91,"") -> 0.0079449962 | J26: =IFERROR(J99/J91,"") -> 0.022955204 | K26: =IFERROR(K99/K91,"") | ... N26: =IFERROR(N99/N91,"") | O26: =IFERROR(+AVERAGE(D26:N26),"") -> 0.070699942
B27: ROA (%) | D27: =IFERROR(D99/D111,"") -> 0.1130789 | E27: =IFERROR(E99/E111,"") -> 0.11371178 | F27: =IFERROR(F99/F111,"") -> 0.043133275 | G27: =IFERROR(G99/G111,"") -> 0.0081105686 | H27: =IFERROR(H99/H111,"") -> 0.22779043 | I27: =IFERROR(I99/I111,"") -> 0.0061443932 | J27: =IFERROR(J99/J111,"") -> 0.017115321 | K27: =IFERROR(K99/K111,"") | ... N27: =IFERROR(N99/N111,"") | O27: =IFERROR(+AVERAGE(D27:N27),"") -> 0.075583524
B28: Financial Cost of Debt | D28: =IFERROR(+(D96/D115)*(1-(D98/D97)),"") -> 0.032129149 | E28: =IFERROR(+(E96/E115)*(1-(E98/E97)),"") -> 0.019618509 | F28: =IFERROR(+(F96/F115)*(1-(F98/F97)),"") -> 0.014732027 | G28: =IFERROR(+(G96/G115)*(1-(G98/G97)),"") -> 0.033718338 | H28: =IFERROR(+(H96/H115)*(1-(H98/H97)),"") -> -0.0071733439 | I28: =IFERROR(+(I96/I115)*(1-(I98/I97)),"") -> -0.0032989753 | J28: =IFERROR(+(J96/J115)*(1-(J98/J97)),"") -> 0.0092334376 | K28: =IFERROR(+(K96/K115)*(1-(K98/K97)),"") | ... N28: =IFERROR(+(N96/N115)*(1-(N98/N97)),"") | O28: =IFERROR(+AVERAGE(D28:N28),"") -> 0.01413702
B29: Return on Equity (RoE) | D29: =IFERROR(+D99/D116,"") -> 0.19872393 | E29: =IFERROR(+E99/E116,"") -> 0.193379 | F29: =IFERROR(+F99/F116,"") -> 0.17595032 | G29: =IFERROR(+G99/G116,"") -> 0.02306968 | H29: =IFERROR(+H99/H116,"") -> 0.57042563 | I29: =IFERROR(+I99/I116,"") -> 0.0125 | J29: =IFERROR(+J99/J116,"") -> 0.040551181 | K29: =IFERROR(+K99/K116,"") | ... N29: =IFERROR(+N99/N116,"") | O29: =IFERROR(+AVERAGE(D29:N29),"") -> 0.17351425
B30: Return on Invested Capital (ROIC) | D30: =IFERROR(+D99/(D115+D116),"") -> 0.15331973 | E30: =IFERROR(+E99/(E115+E117),"") -> 0.75432607 | F30: =IFERROR(+F99/(F115+F116),"") -> 0.061740623 | G30: =IFERROR(+G99/(G115+G116),"") -> 0.011709882 | H30: =IFERROR(+H99/(H115+H116),"") -> 0.31026253 | I30: =IFERROR(+I99/(I115+I116),"") -> 0.0080395795 | J30: =IFERROR(+J99/(J115+J116),"") -> 0.027055424 | K30: =IFERROR(+K99/(K115+K116),"") | L30: =IFERROR(+L99/(L115+L116),"") | M30: =IFERROR(+M99/(M115+M116),"") | N30: =IFERROR(+N99/(N115+N116),"") | O30: =IFERROR(+AVERAGE(D30:N30),"") -> 0.18949341
B32: Solvency | D32: =+D23 -> E.L.F. | E32: =+E23 -> L'Oreal | F32: =+F23 -> Estée Lauder | G32: =+G23 -> Coty | H32: =+H23 -> Ulta Beauty | I32: =+I23 -> Shiseido | J32: =+J23 -> Natura | K32: =+K23 -> 0 | ... O32: =+O23 -> Average
B34: Debt/Assets | D34: =IFERROR(D115/D111,"") -> 0.16851147 | E34: =IFERROR(E115/E111,"") -> 0.15074619 | F34: =IFERROR(F115/F111,"") -> 0.45347603 | G34: =IFERROR(G115/G111,"") -> 0.34105768 | H34: =IFERROR(H115/H111,"") -> 0.33485194 | I34: =IFERROR(I115/I111,"") -> 0.27271653 | J34: =IFERROR(J115/J111,"") -> 0.21053506 | K34: =IFERROR(K115/K111,"") | ... N34: =IFERROR(N115/N111,"") | O34: =IFERROR(+AVERAGE(D34:N34),"") -> 0.27598499
B35: Net Debt/EBITDA | D35: =IFERROR(+(D115-D105)/D94,"") -> 0.54843019 | E35: =IFERROR(+(E115-E105)/E94,"") -> 0.46079652 | F35: =IFERROR(+(F115-F106)/F94,"") -> 2.8223615 | G35: =IFERROR(+(G115-G105)/G94,"") -> 3.6037736 | H35: =IFERROR(+(H115-H105)/H94,"") -> 0.5026362 | I35: =IFERROR(+(I115-I105)/I94,"") -> 2.0946502 | J35: =IFERROR(+(J115-J105)/J94,"") -> 0.76223776 | K35: =IFERROR(+(K115-K105)/K94,"") | L35: =IFERROR(+(L115-L105)/L94,"") | M35: =IFERROR(+(M115-M105)/M94,"") | N35: =IFERROR(+(N115-N105)/N94,"") | O35: =IFERROR(+AVERAGE(D35:N35),"") -> 1.5421266
B36: Interest Coverage Ratio | D36: =IFERROR(D95/D96,"") -> 16.257143 | E36: =IFERROR(E95/E96,"") -> 39.616438 | F36: =IFERROR(F95/F96,"") -> 7.5260664 | G36: =IFERROR(G95/G96,"") -> 2.3055556 | H36: =IFERROR(H95/F75,"") -> -84.45 | I36: =IFERROR(I95/I96,"") -> -10.904762 | J36: =IFERROR(J95/J96,"") -> 11.608696 | K36: =IFERROR(K95/K96,"") | L36: =IFERROR(L95/L96,"") | M36: =IFERROR(M95/M96,"") | N36: =IFERROR(N95/N96,"") | O36: =IFERROR(+AVERAGE(D36:N36),"") -> -2.5772662
B38: Liquidity | D38: =+D23 -> E.L.F. | E38: =+E23 -> L'Oreal | F38: =+F23 -> Estée Lauder | G38: =+G23 -> Coty | H38: =+H23 -> Ulta Beauty | I38: =+I23 -> Shiseido | J38: =+J23 -> Natura | K38: =+K23 -> 0 | ... O38: =+O23 -> Average
B40: Cash Ratio | D40: =IFERROR(D105/D113,"") -> 0.36175192 | E40: =IFERROR(E105/E113,"") -> 0.2768516 | F40: =IFERROR(F106/F113,"") -> 0.30287618 | G40: =IFERROR(G105/G113,"") -> 0.11568025 | H40: =IFERROR(H105/H113,"") -> 0.46260555 | I40: =IFERROR(I105/I113,"") -> 0.30833004 | J40: =IFERROR(J105/J113,"") -> 0.46371227 | K40: =IFERROR(K105/K113,"") | L40: =IFERROR(L105/L113,"") | M40: =IFERROR(M105/M113,"") | N40: =IFERROR(N105/N113,"") | O40: =IFERROR(+AVERAGE(D40:N40),"") -> 0.32740112
B41: Quick Ratio | D41: =IFERROR(+(D105+D106)/D113,"") -> 0.77566031 | E41: =IFERROR(+(E105+E106)/E113,"") -> 0.65953813 | F41: =IFERROR(+(F105+F106)/F113,"") -> 0.8982813 | G41: =IFERROR(+(G105+G106)/G113,"") -> 0.28554958 | H41: =IFERROR(+(H105+H106)/H113,"") -> 0.5880579 | I41: =IFERROR(+(I105+I106)/I113,"") -> 0.67666798 | J41: =IFERROR(+(J105+J106)/J113,"") -> 1.0134875 | K41: =IFERROR(+(K105+K106)/K113,"") | ... N41: =IFERROR(+(N105+N106)/N113,"") | O41: =IFERROR(+AVERAGE(D41:N41),"") -> 0.6996061
B42: Current Ratio | D42: =IFERROR(D109/D113,"") -> 1.5951187 | E42: =IFERROR(E109/E113,"") -> 1.1255124 | F42: =IFERROR(F109/F113,"") -> 1.3893371 | G42: =IFERROR(G109/G113,"") -> 0.754804 | H42: =IFERROR(H109/H113,"") -> 1.7110977 | I42: =IFERROR(I109/I113,"") -> 1.1985788 | J42: =IFERROR(J109/J113,"") -> 1.5754656 | K42: =IFERROR(K109/K113,"") | ... N42: =IFERROR(N109/N113,"") | O42: =IFERROR(+AVERAGE(D42:N42),"") -> 1.335702
B44: Activity | D44: =+D23 -> E.L.F. | E44: =+E23 -> L'Oreal | F44: =+F23 -> Estée Lauder | G44: =+G23 -> Coty | H44: =+H23 -> Ulta Beauty | I44: =+I23 -> Shiseido | J44: =+J23 -> Natura | K44: =+K23 -> 0 | ... O44: =+O23 -> Average
B46: Inventory Turnover | D46: =IFERROR(D92/(AVERAGE(D107:D108)),"") -> 2.1979472 | E46: =IFERROR(E92/(AVERAGE(E107:E108)),"") -> 2.464223 | F46: =IFERROR(F92/(AVERAGE(F107:F108)),"") -> 1.7163368 | G46: =IFERROR(G92/(AVERAGE(G107:G108)),"") -> 2.6493506 | H46: =IFERROR(H92/(AVERAGE(H107:H108)),"") -> 4.0813154 | I46: =IFERROR(I92/(AVERAGE(I107:I108)),"") -> 1.5055209 | J46: =IFERROR(J92/(AVERAGE(J107:J108)),"") -> 2.6373626 | K46: =IFERROR(K92/(AVERAGE(K107:K108)),"") | ... N46: =IFERROR(N92/(AVERAGE(N107:N108)),"") | O46: =IFERROR(+AVERAGE(D46:N46),"") -> 2.4645795
B47: Acc. Receivable Turnover | D47: =IFERROR(D91/D106,"") -> 8.2705977 | E47: =IFERROR(E91/E106,"") -> 7.7639707 | F47: =IFERROR(F91/F106,"") -> 9.0376375 | G47: =IFERROR(G91/G106,"") -> 13.841629 | H47: =IFERROR(H91/H106,"") -> 53.879808 | I47: =IFERROR(I91/I106,"") -> 7.0150054 | J47: =IFERROR(J91/J106,"") -> 5.2418224 | K47: =IFERROR(K91/K106,"") | ... N47: =IFERROR(N91/N106,"") | O47: =IFERROR(+AVERAGE(D47:N47),"") -> 15.00721
B48: Payables Turnover | D48: =IFERROR(D92/D112,"") -> 3.6966708 | E48: =IFERROR(E92/E112,"") -> 1.7357761 | F48: =IFERROR(F92/F112,"") -> 0.94629867 | G48: =IFERROR(G92/G112,"") -> 0.90839695 | H48: =IFERROR(H92/H112,"") -> 7.2771855 | I48: =IFERROR(I92/I112,"") -> 1.1304975 | J48: =IFERROR(J92/J112,"") -> 1.163311 | K48: =IFERROR(K92/K112,"") | ... N48: =IFERROR(N92/N112,"") | O48: =IFERROR(+AVERAGE(D48:N48),"") -> 2.4083052
B49: Fixed Asset Turnover | D49: =IFERROR(D91/D110,"") -> 24.731884 | E49: =IFERROR(E91/E110,"") -> 7.2901928 | F49: =IFERROR(F91/F110,"") -> 3.1410747 | G49: =IFERROR(G91/G110,"") -> 6.2813142 | H49: =IFERROR(H91/H110,"") -> 4.0649256 | I49: =IFERROR(I91/I110,"") -> 2.5798187 | J49: =IFERROR(J91/J110,"") -> 6.1047619 | K49: =IFERROR(K91/K110,"") | ... N49: =IFERROR(N91/N110,"") | O49: =IFERROR(+AVERAGE(D49:N49),"") -> 7.741996
B50: Total Asset Turnover | D50: =IFERROR(D91/D111,"") -> 0.90666785 | E50: =IFERROR(E91/E111,"") -> 0.77167143 | F50: =IFERROR(F91/F111,"") -> 0.72002583 | G50: =IFERROR(G91/G111,"") -> 0.50633121 | H50: =IFERROR(H91/H111,"") -> 1.9637288 | I50: =IFERROR(I91/I111,"") -> 0.77336642 | J50: =IFERROR(J91/J111,"") -> 0.74559654 | K50: =IFERROR(K91/K111,"") | ... N50: =IFERROR(N91/N111,"") | O50: =IFERROR(+AVERAGE(D50:N50),"") -> 0.91248401
B51: Cash Cycle (days) | D51: =IFERROR(365/D46+365/D47-365/D48,"") -> 111.45879 | E51: =IFERROR(365/E46+365/E47-365/E48,"") -> -15.148835 | F51: =IFERROR(365/F46+365/F47-365/F48,"") -> -132.66444 | G51: =IFERROR(365/G46+365/G47-365/G48,"") -> -237.66739 | H51: =IFERROR(365/H46+365/H47-365/H48,"") -> 46.049535 | I51: =IFERROR(365/I46+365/I47-365/I48,"") -> -28.39438 | J51: =IFERROR(365/J46+365/J47-365/J48,"") -> -105.73151 | K51: =IFERROR(365/K46+365/K47-365/K48,"") | ... N51: =IFERROR(365/N46+365/N47-365/N48,"") | O51: =IFERROR(+AVERAGE(D51:N51),"") -> -51.728318
B53: Cash Flow | D53: =+D32 -> E.L.F. | E53: =+E32 -> L'Oreal | F53: =+F32 -> Estée Lauder | G53: =+G32 -> Coty | H53: =+H32 -> Ulta Beauty | I53: =+I32 -> Shiseido | J53: =+J32 -> Natura | K53: =+K32 -> 0 | ... O53: =+O32 -> Average
...

Sheet Peers (2)
D3: EV / Revenue | F3: EV / EBITDA | H3: Price / Earnings | P3: Revenue Growth | R3: EBITDA Margin | T3: Profit Margin
B4: Peers | C4: Ticker | D4: 2023 | E4: 2024 | F4: 2023 | G4: 2024 | H4: 2023 | I4: 2024 | P4: =+Inputs!O4&"-"&Inputs!P4 -> 2022-2023 | Q4: =+Inputs!P4&"-"&Inputs!Q4 -> 2023-2024 | R4: 2023 | S4: 2024 | T4: =+Inputs!O4&"-"&Inputs!P4 -> 2022-2023 | U4: =+Inputs!P4&"-"&Inputs!Q4 -> 2023-2024
A5: =+P85 -> #VALUE! | B5: {=IFERROR(_FV(A5,"Name"),"")} -> E.L.F. BEAUTY, INC. | C5: {=IFERROR(_FV(A5,"Ticker symbol",TRUE),"")} -> ELF | D5: {=IFERROR((_FV(A5,"Market cap",TRUE)/1000000+P$115-P$105)/P$88,"")} -> 13.46396 | E5: {=IFERROR((_FV(A5,"Market cap",TRUE)/1000000+P$115-P$105)/P$91,"")} -> 7.6110365 | F5: {=+IFERROR((_FV(A5,"Market cap",TRUE)/1000000+P$115-P$105)/P$89,"")} -> 114.43378 | G5: {=IFERROR((_FV(A5,"Market cap",TRUE)/1000000+P$115-P$105)/P$94,"")} -> 52.057049 | H5: {=IFERROR((_FV(A5,"Market cap",TRUE)/1000000)/P$90,"")} -> 125.37952 | I5: {=IFERROR((_FV(A5,"Market cap",TRUE)/1000000)/P$99,"")} -> 60.382461 | P5: =IFERROR(P88/P87-1,"") -> 0.47577766 | Q5: =IFERROR(P91/P88-1,"") -> 0.76900484 | R5: =IFERROR(P89/P88,"") -> 0.11765722 | S5: =IFERROR(P94/P91,"") -> 0.14620568 | T5: =IFERROR(P90/P88,"") -> 0.10625432 | U5: =IFERROR(P99/P91,"") -> 0.12471921
A6: #VALUE! | B6: L'Oreal S.A. | C6: {=IFERROR(_FV(A6,"Ticker symbol",TRUE),"")} -> OR | D6: {=+IFERROR((_FV(A6,"Market cap",TRUE)/1000000+Q$115-Q$105)/Q$88,"")} -> 4.9528508 | E6: {=IFERROR(+(_FV(A6,"Market cap",TRUE)/1000000+Q$115-Q$105)/Q$91,"")} -> 4.690436 | F6: {=IFERROR(+(_FV(A6,"Market cap",TRUE)/1000000+Q$115-Q$105)/Q$89,"")} -> 22.738941 | G6: {=IFERROR(+(_FV(A6,"Market cap",TRUE)/1000000+Q$115-Q$105)/Q$94,"")} -> 21.154149 | H6: {=IFERROR(+(_FV(A6,"Market cap",TRUE)/1000000)/Q$90,"")} -> 32.264764 | I6: {=IFERROR(+(_FV(A6,"Market cap",TRUE)/1000000)/Q$99,"")} -> 31.136907 | P6: =+IFERROR(Q88/Q87-1,"") -> 0.07637219 | Q6: =IFERROR(Q91/Q88-1,"") -> 0.055946773 | R6: =IFERROR(Q89/Q88,"") -> 0.21781361 | S6: =+IFERROR(Q94/Q91,"") -> 0.22172653 | T6: =IFERROR(Q90/Q88,"") -> 0.15016269 | U6: =+IFERROR(P99/P93,"") -> 0.17635686
A7: #VALUE! | B7: Estée Lauder Companies Inc. | C7: {=IFERROR(_FV(A7,"Ticker symbol",TRUE),"")} -> EL | D7: {=IFERROR(+(_FV(A7,"Market cap",TRUE)/1000000+R$115-R$106)/R$88,"")} -> 2.5199183 | E7: {=IFERROR(+(_FV(A7,"Market cap",TRUE)/1000000+R$115-R$106)/R$91,"")} -> 2.5686763 | F7: {=IFERROR(+(_FV(A7,"Market cap",TRUE)/1000000+R$115-R$106)/R$89,"")} -> 13.315144 | G7: {=IFERROR(+(_FV(A7,"Market cap",TRUE)/1000000+R$115-R$106)/R$94,"")} -> 13.964437 | H7: {=IFERROR(+(_FV(A7,"Market cap",TRUE)/1000000)/R$90,"")} -> 25.632131 | I7: {=IFERROR(+(_FV(A7,"Market cap",TRUE)/1000000)/R$99,"")} -> 34.212727 | P7: =IFERROR(R88/R87-1,"") -> -0.10300502 | Q7: =IFERROR(+R91/R88-1,"") -> -0.018981772 | R7: =IFERROR(R89/R88,"") -> 0.18925204 | S7: =IFERROR(R94/R91,"") -> 0.18394413 | T7: =IFERROR(R90/R88,"") -> 0.078441232 | U7: =+IFERROR(R99/R91,"") -> 0.059905177
A8: #VALUE! | B8: Coty Inc. | C8: {=IFERROR(_FV(A8,"Ticker symbol",TRUE),"")} -> COTY | D8: {=IFERROR(+(_FV(A8,"Market cap",TRUE)/1000000+S$115-S$105)/S$88,"")} -> 1.3077059 | E8: {=IFERROR(+(_FV(A8,"Market cap",TRUE)/1000000+S$115-S$105)/S$91,"")} -> 1.1871524 | F8: {=IFERROR(+(_FV(A8,"Market cap",TRUE)/1000000+S$115-S$105)/S$89,"")} -> 8.0879717 | G8: {=IFERROR(+(_FV(A8,"Market cap",TRUE)/1000000+S$115-S$105)/S$94,"")} -> 6.8518854 | H8: {=IFERROR(+(_FV(A8,"Market cap",TRUE)/1000000)/S$90,"")} -> 17.839371 | I8: {=IFERROR(+(_FV(A8,"Market cap",TRUE)/1000000)/S$99,"")} -> 35.132638 | P8: =+IFERROR(S88/S87-1,"") -> 0.047134238 | Q8: =IFERROR(S91/S88-1,"") -> 0.10154843 | R8: =IFERROR(S89/S88,"") -> 0.16168527 | S8: =IFERROR(S94/S91,"") -> 0.17325924 | T8: =IFERROR(S90/S88,"") -> 0.03474973 | U8: =+IFERROR(S99/S91,"") -> 0.016018307
A9: #VALUE! | B9: Ulta Beauty | C9: {=IFERROR(_FV(A9,"Ticker symbol",TRUE),"")} -> ULTA | D9: {=IFERROR((_FV(A9,"Market cap",TRUE)/1000000+T$115-T$105)/T$88,"")} -> 2.562027 | E9: {=IFERROR(+(_FV(A9,"Market cap",TRUE)/1000000+T$115-T$105)/T$91,"")} -> 2.3338747 | F9: {=IFERROR(+(_FV(A9,"Market cap",TRUE)/1000000+T$115-T$105)/T$89,"")} -> 11.851261 | G9: {=IFERROR(+(_FV(A9,"Market cap",TRUE)/1000000+T$115-T$105)/T$94,"")} -> 11.491975 | H9: {=IFERROR(+(_FV(A9,"Market cap",TRUE)/1000000)/T$90,"")} -> 20.041454 | I9: {=IFERROR(+(_FV(A9,"Market cap",TRUE)/1000000)/T$99,"")} -> 19.239795 | P9: =IFERROR(T88/T87-1,"") -> 0.18282934 | Q9: =IFERROR(T91/T88-1,"") -> 0.097756881 | R9: =IFERROR(T89/T88,"") -> 0.2161818 | S9: =IFERROR(T94/T91,"") -> 0.20308736 | T9: =IFERROR(T90/T88,"") -> 0.12224508 | U9: =+IFERROR(T99/T91,"") -> 0.11599893
A10: #VALUE! | B10: Shiseido Company | C10: {=IFERROR(_FV(A10,"Ticker symbol",TRUE),"")} -> SSDOY | D10: {=IFERROR((_FV(A10,"Market cap",TRUE)/1000000+U$115-U$105)/U$88,"")} -> 1.1936757 | E10: {=IFERROR(+(_FV(A10,"Market cap",TRUE)/1000000+U$115-U$105)/U$91,"")} -> 1.2655334 | F10: {=IFERROR(+(_FV(A10,"Market cap",TRUE)/1000000+U$115-U$105)/U$89,"")} -> 10.289337 | G10: {=IFERROR(+(_FV(A10,"Market cap",TRUE)/1000000+U$115-U$105)/U$94,"")} -> 11.362025 | H10: {=IFERROR(+(_FV(A10,"Market cap",TRUE)/1000000)/U$90,"")} -> 33.611522 | I10: {=IFERROR(+(_FV(A10,"Market cap",TRUE)/1000000)/U$99,"")} -> 129.92146 | P10: =+IFERROR(U88/U87-1,"") -> -0.15056923 | Q10: =IFERROR(U91/U88-1,"") -> -0.056780516 | R10: =IFERROR(U89/U88,"") -> 0.11601095 | S10: =IFERROR(U94/U91,"") -> 0.11138273 | T10: =IFERROR(U90/U88,"") -> 0.02896671 | U10: =+IFERROR(U99/U91,"") -> 0.0079449962
A11: #VALUE! | B11: Natura &Co Holding S.A. | C11: {=IFERROR(_FV(A11,"Ticker symbol",TRUE),"")} -> NTCO3Q | D11: {=IFERROR(+(_FV(A11,"Market cap",TRUE)/1000000+D$115-D$105)/D$88,"")} -> 5.0926627 | E11: {=IFERROR(+(_FV(A11,"Market cap",TRUE)/1000000+D$115-D$105)/D$91,"")} -> 4.5104171 | F11: {=IFERROR(+(_FV(A11,"Market cap",TRUE)/1000000+D$115-D$105)/D$89,"")} -> 25.58564 | G11: {=IFERROR(+(_FV(A11,"Market cap",TRUE)/1000000+D$115-D$105)/D$94,"")} -> 28.305233 | H11: {=IFERROR(+(_FV(A11,"Market cap",TRUE)/1000000)/D$90,"")} -> 87.525518 | I11: {=IFERROR(+(_FV(A11,"Market cap",TRUE)/1000000)/D$99,"")} -> 191.19652 | P11: =IFERROR(D88/D87-1,"") -> -0.29924176 | Q11: =IFERROR(D91/D88-1,"") -> 0.12908908 | R11: =IFERROR(D89/D88,"") -> 0.19904378 | S11: =IFERROR(D94/D91,"") -> 0.15934923 | T11: =IFERROR(D90/D88,"") -> 0.056618017 | U11: =+IFERROR(D99/D91,"") -> 0.022955204
B12: Average | D12: =IFERROR(AVERAGE(D5:D11),"") -> 4.4418287 | E12: =IFERROR(AVERAGE(E5:E11),"") -> 3.4524466 | F12: =IFERROR(AVERAGE(F5:F11),"") -> 29.471725 | G12: =IFERROR(AVERAGE(G5:G11),"") -> 20.740965 | H12: =IFERROR(AVERAGE(H5:H11),"") -> 48.899182 | I12: =IFERROR(AVERAGE(I5:I11),"") -> 71.603216 | P12: =IFERROR(AVERAGE(P5:P11),"") -> 0.032756776 | Q12: =IFERROR(AVERAGE(Q5:Q11),"") -> 0.15394053 | R12: =IFERROR(AVERAGE(R5:R11),"") -> 0.17394924 | S12: =IFERROR(AVERAGE(S5:S11),"") -> 0.17127927 | T12: =IFERROR(AVERAGE(T5:T11),"") -> 0.082491111 | U12: =IFERROR(AVERAGE(U5:U11),"") -> 0.074842669
