Workbook
Name COOLFUCNTION: _xlfn.LAMBDA(_xldudf_BOARDFLARE_EXEC("workbook-settings:coolfucntion"))
Name COOLFUCNTION: _xlfn.LAMBDA(_xldudf_BOARDFLARE_EXEC("workbook-settings:coolfucntion"))
Name COOLFUCNTION: _xlfn.LAMBDA(_xldudf_BOARDFLARE_EXEC("workbook-settings:coolfucntion"))
Name COOLFUCNTION: _xlfn.LAMBDA(_xldudf_BOARDFLARE_EXEC("workbook-settings:coolfucntion"))
Name COOLFUCNTION: _xlfn.LAMBDA(_xldudf_BOARDFLARE_EXEC("workbook-settings:coolfucntion"))
Name COOLFUCNTION: _xlfn.LAMBDA(_xldudf_BOARDFLARE_EXEC("workbook-settings:coolfucntion"))
Name COOLFUCNTION: _xlfn.LAMBDA(_xldudf_BOARDFLARE_EXEC("workbook-settings:coolfucntion"))
Name COOLFUCNTION: _xlfn.LAMBDA(_xldudf_BOARDFLARE_EXEC("workbook-settings:coolfucntion"))
Name COOLFUCNTION: _xlfn.LAMBDA(_xldudf_BOARDFLARE_EXEC("workbook-settings:coolfucntion"))
Name COOLFUCNTION: _xlfn.LAMBDA(_xldudf_BOARDFLARE_EXEC("workbook-settings:coolfucntion"))
Name Sectors: #REF!
Name Sectors: #REF!
Name Sectors: #REF!

Sheet Summary
E2: | EQUITY RESEARCH | U2: Lisbon Investment Society Equity Research
U3: April 25th, 2025
D6: {=+_FV(DCF!R4,"Name")} -> INTERNATIONAL BUSINESS MACHINES CORPORATION | U6: Buy
D8: IBM is a global technology and consulting company known for its innovative enterprise solutions and legacy of technological leadership. The company provides a wide range of services, including hybrid cloud infrastructure, artificial intelligence (AI), data analytics, cybersecurity, and quantum computing. | U8: #VALUE!
U9: {=+"Price (7 Mar 25): $"&_FV(DCF!$R$4,"Price")} -> Price (7 Mar 25): $288.37
D10: Investment Thesis | U10: ="Price Target: $" & ROUND(IF(Summary!G25="FCFF",DCF!Q209,IF(Summary!G25="FCFE",DCF!Q252,IF(Summary!G25="Tax Shield",DCF!Q225,DCF!Q268))),2) &" "&IF(Summary!G25="FCFF","(FCFF)",IF(Summary!G25="FCFE","(FCFE)",IF(Summary!G25="Tax Shield","(APV)","(DDM)"))) -> Price Target: $257.51 (FCFF)
D11: IBM’s hybrid cloud and AI strategy, together with its software-driven portfolio, is expected to deliver mid-single-digit revenue growth, benefiting future free cash flow generation and providing upside potential. While the hybrid cloud market and the evolving AI industry bring competitive challenges, IBM as an enterprise solutions provider and its strong client base support its strategic positioning. As the stock is currently trading slightly below our base case scenario value of $268.83, the recommendation on IBM is BUY | U11: =+"Upside (Downside): "&ROUND((DCF!$Q$212*100),2)&"%" -> Upside (Downside): -10.7%
U14: United States, Information Technology
U15: =+ESG!C10 -> IT Services
D17: Operating Metrics | F17: 2023 | G17: =+F17+1 -> 2024 | H17: =+G17+1 -> 2025 | I17: =+H17+1 -> 2026 | K17: Valuation Multiples | N17: 2022 | O17: =+N17+1 -> 2023 | P17: =+O17+1 -> 2024 | Q17: =+P17+1 -> 2025 | R17: =+Q17+1 -> 2026 | U17: Haitao Yu
D18: Hybrid Platform & Solutions revenue | F18: =DCF!F17 -> 17396 | G18: =DCF!G17 -> 18808 | H18: =DCF!H17 -> 20594.76 | I18: =DCF!I17 -> 22654.236 | K18: EV / Sales | N18: =IFERROR(_xlfn.XLOOKUP($K18,Multiples!$B:$B,Multiples!N:N),"") -> 2.8652042 | O18: =IFERROR(_xlfn.XLOOKUP($K18,Multiples!$B:$B,Multiples!O:O),"") -> 3.1620182 | P18: =IFERROR(_xlfn.XLOOKUP($K18,Multiples!$B:$B,Multiples!P:P),"") -> 3.9284691 | Q18: =IFERROR(_xlfn.XLOOKUP($K18,Multiples!$B:$B,Multiples!Q:Q),"") -> 4.4795343 | R18: =IFERROR(_xlfn.XLOOKUP($K18,Multiples!$B:$B,Multiples!R:R),"") -> 4.4394652 | U18: haitaoyu@aln.iseg.ulisboa.pt
D19: Transaction revenue | F19: =DCF!F20 -> 7615 | G19: =DCF!G20 -> 8277 | H19: =DCF!H20 -> 8770.2562 | I19: =DCF!I20 -> 9292.9074 | K19: Price / Sales | N19: =IFERROR(_xlfn.XLOOKUP($K19,Multiples!$B:$B,Multiples!N:N),"") -> 2.1035819 | O19: =IFERROR(_xlfn.XLOOKUP($K19,Multiples!$B:$B,Multiples!O:O),"") -> 2.4091246 | P19: =IFERROR(_xlfn.XLOOKUP($K19,Multiples!$B:$B,Multiples!P:P),"") -> 3.2290444 | Q19: =IFERROR(_xlfn.XLOOKUP($K19,Multiples!$B:$B,Multiples!Q:Q),"") -> 3.8715384 | R19: =IFERROR(_xlfn.XLOOKUP($K19,Multiples!$B:$B,Multiples!R:R),"") -> 3.8841567 | U19: (+351) 938 305 543
D20: Consulting revenue | F20: =DCF!F25 -> 20884 | G20: =DCF!G25 -> 20692 | H20: =DCF!H25 -> 21105.84 | I20: =DCF!I25 -> 21739.015 | K20: EV / EBITDA | N20: =IFERROR(_xlfn.XLOOKUP($K20,Multiples!$B:$B,Multiples!N:N),"") -> 13.364476 | O20: =IFERROR(_xlfn.XLOOKUP($K20,Multiples!$B:$B,Multiples!O:O),"") -> 14.196723 | P20: =IFERROR(_xlfn.XLOOKUP($K20,Multiples!$B:$B,Multiples!P:P),"") -> 17.548635 | Q20: =IFERROR(_xlfn.XLOOKUP($K20,Multiples!$B:$B,Multiples!Q:Q),"") -> 21.831535 | R20: =IFERROR(_xlfn.XLOOKUP($K20,Multiples!$B:$B,Multiples!R:R),"") -> 21.677854 | U20: João Baiôa
D21: Infrastucture revenue | F21: =DCF!F26 -> 14593 | G21: =DCF!G26 -> 14020 | H21: =DCF!H26 -> 14648.096 | I21: =DCF!I26 -> 14500 | K21: EV / EBIT | N21: =IFERROR(_xlfn.XLOOKUP($K21,Multiples!$B:$B,Multiples!N:N),"") -> 21.214778 | O21: =IFERROR(_xlfn.XLOOKUP($K21,Multiples!$B:$B,Multiples!O:O),"") -> 20.848694 | P21: =IFERROR(_xlfn.XLOOKUP($K21,Multiples!$B:$B,Multiples!P:P),"") -> 26.278992 | Q21: =IFERROR(_xlfn.XLOOKUP($K21,Multiples!$B:$B,Multiples!Q:Q),"") -> 33.548656 | R21: =IFERROR(_xlfn.XLOOKUP($K21,Multiples!$B:$B,Multiples!R:R),"") -> 33.406955 | U21: l61773@aln.iseg.ulisboa.pt
K22: Price / Earnings | N22: =IFERROR(_xlfn.XLOOKUP($K22,Multiples!$B:$B,Multiples!N:N),"") -> 71.453317 | O22: =IFERROR(_xlfn.XLOOKUP($K22,Multiples!$B:$B,Multiples!O:O),"") -> 19.836077 | P22: =IFERROR(_xlfn.XLOOKUP($K22,Multiples!$B:$B,Multiples!P:P),"") -> 33.682218 | Q22: =IFERROR(_xlfn.XLOOKUP($K22,Multiples!$B:$B,Multiples!Q:Q),"") -> 37.601264 | R22: =IFERROR(_xlfn.XLOOKUP($K22,Multiples!$B:$B,Multiples!R:R),"") -> 32.215569 | U22: (+351) 963 849 143
K23: Price / Book | N23: =IFERROR(_xlfn.XLOOKUP($K23,Multiples!$B:$B,Multiples!N:N),"") -> 5.7819367 | O23: =IFERROR(_xlfn.XLOOKUP($K23,Multiples!$B:$B,Multiples!O:O),"") -> 6.5906796 | P23: =IFERROR(_xlfn.XLOOKUP($K23,Multiples!$B:$B,Multiples!P:P),"") -> 7.3974965 | Q23: =IFERROR(_xlfn.XLOOKUP($K23,Multiples!$B:$B,Multiples!Q:Q),"") -> 9.4071156 | R23: =IFERROR(_xlfn.XLOOKUP($K23,Multiples!$B:$B,Multiples!R:R),"") -> 9.4674731 | U23: João Garcia
U24: joaogarcia@aln.iseg.ulisboa.pt
D25: Year | E25: Net Sales | F25: EBIT Margin | G25: FCFF | H25: =+IF(Summary!$G$25="FCFF",DCF!AB6,IF(Summary!$G$25="FCFE",DCF!AC6,DCF!AD6)) -> NOPAT | I25: Net Capex | K25: Profitability Ratios | N25: 2022 | O25: =+N25+1 -> 2023 | P25: =+O25+1 -> 2024 | Q25: =+P25+1 -> 2025 | R25: =+Q25+1 -> 2026 | U25: (+351) 969 563 512
D26: 2022 | E26: =+DCF!E31 -> 60530 | F26: =+DCF!E61 -> 0.135057 | G26: =+INDEX(DCF!X7:AA7,MATCH(Summary!$G$25,{"FCFF","FCFE","Tax Shield","Total Payout"},0)) -> 11688.4 | H26: =+IF(Summary!$G$25="FCFF",DCF!AB7,IF(Summary!$G$25="FCFE",DCF!AC7,DCF!AD7)) -> 6932.4 | I26: =+DCF!E135 -> -1235 | K26: Return on Assets | N26: =IFERROR(_xlfn.XLOOKUP($K26,Multiples!$B:$B,Multiples!N:N),"") -> 0.01400459 | O26: =IFERROR(_xlfn.XLOOKUP($K26,Multiples!$B:$B,Multiples!O:O),"") -> 0.055553502 | P26: =IFERROR(_xlfn.XLOOKUP($K26,Multiples!$B:$B,Multiples!P:P),"") -> 0.043856388 | Q26: =IFERROR(_xlfn.XLOOKUP($K26,Multiples!$B:$B,Multiples!Q:Q),"") -> 0.047421906 | R26: =IFERROR(_xlfn.XLOOKUP($K26,Multiples!$B:$B,Multiples!R:R),"") -> 0.057999094 | U26: Lucas Alves
D27: =+D26+1 -> 2023 | E27: =+DCF!F31 -> 61860 | F27: =+DCF!F61 -> 0.15166505 | G27: =+INDEX(DCF!X8:AA8,MATCH(Summary!$G$25,{"FCFF","FCFE","Tax Shield","Total Payout"},0)) -> 14857.52 | H27: =+IF(Summary!$G$25="FCFF",DCF!AB8,IF(Summary!$G$25="FCFE",DCF!AC8,DCF!AD8)) -> 8068.52 | I27: =+DCF!F135 -> -924 | K27: Return on Equity | N27: =IFERROR(_xlfn.XLOOKUP($K27,Multiples!$B:$B,Multiples!N:N),"") -> 0.080919081 | O27: =IFERROR(_xlfn.XLOOKUP($K27,Multiples!$B:$B,Multiples!O:O),"") -> 0.33225721 | P27: =IFERROR(_xlfn.XLOOKUP($K27,Multiples!$B:$B,Multiples!P:P),"") -> 0.21962617 | Q27: =IFERROR(_xlfn.XLOOKUP($K27,Multiples!$B:$B,Multiples!Q:Q),"") -> 0.2256784 | R27: =IFERROR(_xlfn.XLOOKUP($K27,Multiples!$B:$B,Multiples!R:R),"") -> 0.27601469 | U27: lucas.alves@aln.iseg.ulisboa.pt
D28: =+D27+1 -> 2024 | E28: =+DCF!G31 -> 62753 | F28: =+DCF!G61 -> 0.14949086 | G28: =+INDEX(DCF!X9:AA9,MATCH(Summary!$G$25,{"FCFF","FCFE","Tax Shield","Total Payout"},0)) -> 14905.184 | H28: =+IF(Summary!$G$25="FCFF",DCF!AB9,IF(Summary!$G$25="FCFE",DCF!AC9,DCF!AD9)) -> 8105.184 | I28: =+DCF!G135 -> -491 | K28: Return on Total Capital | N28: =IFERROR(_xlfn.XLOOKUP($K28,Multiples!$B:$B,Multiples!N:N),"") -> 0.1218004 | O28: =IFERROR(_xlfn.XLOOKUP($K28,Multiples!$B:$B,Multiples!O:O),"") -> 0.075624696 | P28: =IFERROR(_xlfn.XLOOKUP($K28,Multiples!$B:$B,Multiples!P:P),"") -> 0.084372835 | Q28: =IFERROR(_xlfn.XLOOKUP($K28,Multiples!$B:$B,Multiples!Q:Q),"") -> 0.08214452 | R28: =IFERROR(_xlfn.XLOOKUP($K28,Multiples!$B:$B,Multiples!R:R),"") -> 0.083406235 | U28: (+351) 938 350 699
D29: =+D28+1 -> 2025 | E29: =+DCF!H31 -> 65932.415 | F29: =+DCF!H61 -> 0.13352351 | G29: =+INDEX(DCF!X10:AA10,MATCH(Summary!$G$25,{"FCFF","FCFE","Tax Shield","Total Payout"},0)) -> 11932.291 | H29: =+IF(Summary!$G$25="FCFF",DCF!AB10,IF(Summary!$G$25="FCFE",DCF!AC10,DCF!AD10)) -> 7547.5575 | I29: =+DCF!H135 -> -938.72157 | K29: EBITDA Margin | N29: =IFERROR(_xlfn.XLOOKUP($K29,Multiples!$B:$B,Multiples!N:N),"") -> 0.21438956 | O29: =IFERROR(_xlfn.XLOOKUP($K29,Multiples!$B:$B,Multiples!O:O),"") -> 0.22272874 | P29: =IFERROR(_xlfn.XLOOKUP($K29,Multiples!$B:$B,Multiples!P:P),"") -> 0.22386181 | Q29: =IFERROR(_xlfn.XLOOKUP($K29,Multiples!$B:$B,Multiples!Q:Q),"") -> 0.20518641 | R29: =IFERROR(_xlfn.XLOOKUP($K29,Multiples!$B:$B,Multiples!R:R),"") -> 0.20479265
D30: =+D29+1 -> 2026 | E30: =+DCF!I31 -> 68863.861 | F30: =+DCF!I61 -> 0.13289045 | G30: =+INDEX(DCF!X11:AA11,MATCH(Summary!$G$25,{"FCFF","FCFE","Tax Shield","Total Payout"},0)) -> 13978.955 | H30: =+IF(Summary!$G$25="FCFF",DCF!AB11,IF(Summary!$G$25="FCFE",DCF!AC11,DCF!AD11)) -> 7874.2278 | I30: =+DCF!I135 -> -770.11747 | K30: EBIT Margin | N30: =IFERROR(_xlfn.XLOOKUP($K30,Multiples!$B:$B,Multiples!N:N),"") -> 0.135057 | O30: =IFERROR(_xlfn.XLOOKUP($K30,Multiples!$B:$B,Multiples!O:O),"") -> 0.15166505 | P30: =IFERROR(_xlfn.XLOOKUP($K30,Multiples!$B:$B,Multiples!P:P),"") -> 0.14949086 | Q30: =IFERROR(_xlfn.XLOOKUP($K30,Multiples!$B:$B,Multiples!Q:Q),"") -> 0.13352351 | R30: =IFERROR(_xlfn.XLOOKUP($K30,Multiples!$B:$B,Multiples!R:R),"") -> 0.13289045 | U30: Statistics
D31: =+D30+1 -> 2027 | E31: =+DCF!J31 -> 72104.208 | F31: =+DCF!J61 -> 0.13351036 | G31: =+INDEX(DCF!X12:AA12,MATCH(Summary!$G$25,{"FCFF","FCFE","Tax Shield","Total Payout"},0)) -> 14199.951 | H31: =+IF(Summary!$G$25="FCFF",DCF!AB12,IF(Summary!$G$25="FCFE",DCF!AC12,DCF!AD12)) -> 8284.6312 | I31: =+DCF!J135 -> -683.21192 | K31: Gross Profit Margin | N31: =IFERROR(_xlfn.XLOOKUP($K31,Multiples!$B:$B,Multiples!N:N),"") -> 0.54002974 | O31: =IFERROR(_xlfn.XLOOKUP($K31,Multiples!$B:$B,Multiples!O:O),"") -> 0.55447785 | P31: =IFERROR(_xlfn.XLOOKUP($K31,Multiples!$B:$B,Multiples!P:P),"") -> 0.56653865 | Q31: =IFERROR(_xlfn.XLOOKUP($K31,Multiples!$B:$B,Multiples!Q:Q),"") -> 0.553881 | R31: =IFERROR(_xlfn.XLOOKUP($K31,Multiples!$B:$B,Multiples!R:R),"") -> 0.55278492 | U31: Beta | V31: =Peers!D74 -> 0.6925
D32: =+D31+1 -> 2028 | E32: =+DCF!K31 -> 77148.077 | F32: =+DCF!K61 -> 0.14306115 | G32: =+INDEX(DCF!X13:AA13,MATCH(Summary!$G$25,{"FCFF","FCFE","Tax Shield","Total Payout"},0)) -> 15830.407 | H32: =+IF(Summary!$G$25="FCFF",DCF!AB13,IF(Summary!$G$25="FCFE",DCF!AC13,DCF!AD13)) -> 9485.7321 | I32: =+DCF!K135 -> -729.75804 | K32: SG&A Margin | N32: =IFERROR(_xlfn.XLOOKUP($K32,Multiples!$B:$B,Multiples!N:N),"") -> 0.30743433 | O32: =IFERROR(_xlfn.XLOOKUP($K32,Multiples!$B:$B,Multiples!O:O),"") -> 0.30719366 | P32: =IFERROR(_xlfn.XLOOKUP($K32,Multiples!$B:$B,Multiples!P:P),"") -> 0.31373799 | Q32: =IFERROR(_xlfn.XLOOKUP($K32,Multiples!$B:$B,Multiples!Q:Q),"") -> 0.30945533 | R32: =IFERROR(_xlfn.XLOOKUP($K32,Multiples!$B:$B,Multiples!R:R),"") -> 0.31012899 | U32: % Float | V32: =+Peers!D73 -> 0.9979
D33: =+D32+1 -> 2029 | E33: =+DCF!L31 -> 81934.093 | F33: =+DCF!L61 -> 0.14060074 | G33: =+INDEX(DCF!X14:AA14,MATCH(Summary!$G$25,{"FCFF","FCFE","Tax Shield","Total Payout"},0)) -> 16724.743 | H33: =+IF(Summary!$G$25="FCFF",DCF!AB14,IF(Summary!$G$25="FCFE",DCF!AC14,DCF!AD14)) -> 9909.0909 | I33: =+DCF!L135 -> -665.94 | K33: Net Income Margin | N33: =IFERROR(_xlfn.XLOOKUP($K33,Multiples!$B:$B,Multiples!N:N),"") -> 0.029439947 | O33: =IFERROR(_xlfn.XLOOKUP($K33,Multiples!$B:$B,Multiples!O:O),"") -> 0.12145167 | P33: =IFERROR(_xlfn.XLOOKUP($K33,Multiples!$B:$B,Multiples!P:P),"") -> 0.095867927 | Q33: =IFERROR(_xlfn.XLOOKUP($K33,Multiples!$B:$B,Multiples!Q:Q),"") -> 0.10296299 | R33: =IFERROR(_xlfn.XLOOKUP($K33,Multiples!$B:$B,Multiples!R:R),"") -> 0.12056769 | U33: % Held by Insiders | V33: =+Peers!D76 -> 0.0012
U34: % Held by Institutions | V34: =+Peers!D77 -> 0.6406
D35: SWOT Analysis | K35: Liquidity Ratios | N35: 2022 | O35: =+N35+1 -> 2023 | P35: =+O35+1 -> 2024 | Q35: =+P35+1 -> 2025 | R35: =+Q35+1 -> 2026 | U35: Short % of Float | V35: =+Peers!D78 -> 0.0223
D36: Strengths | G36: Weaknesses | K36: Cash Ratio | N36: =IFERROR(_xlfn.XLOOKUP($K36,Multiples!$B:$B,Multiples!N:N),"") -> 0.25030947 | O36: =IFERROR(_xlfn.XLOOKUP($K36,Multiples!$B:$B,Multiples!O:O),"") -> 0.38297872 | P36: =IFERROR(_xlfn.XLOOKUP($K36,Multiples!$B:$B,Multiples!P:P),"") -> 0.42082554 | Q36: =IFERROR(_xlfn.XLOOKUP($K36,Multiples!$B:$B,Multiples!Q:Q),"") -> 0.51943532 | R36: =IFERROR(_xlfn.XLOOKUP($K36,Multiples!$B:$B,Multiples!R:R),"") -> 0.64176559 | W36: 120.87
D37: Leading in hybrid cloud, with strong client base. 93% of all fortune 500 companies leverage IBM’s hybrid cloud products and solutions. | G37: Growth of Consulting and Infrastructure is relatively slow, at low to mid single digit only. Further growth is limited due to high client penetration. IBM isn't perceived as a very innovative compay. | K37: Quick Ratio | N37: =IFERROR(_xlfn.XLOOKUP($K37,Multiples!$B:$B,Multiples!N:N),"") -> 0.48712903 | O37: =IFERROR(_xlfn.XLOOKUP($K37,Multiples!$B:$B,Multiples!O:O),"") -> 0.62408417 | P37: =IFERROR(_xlfn.XLOOKUP($K37,Multiples!$B:$B,Multiples!P:P),"") -> 0.6741295 | Q37: =IFERROR(_xlfn.XLOOKUP($K37,Multiples!$B:$B,Multiples!Q:Q),"") -> 0.77937201 | R37: =IFERROR(_xlfn.XLOOKUP($K37,Multiples!$B:$B,Multiples!R:R),"") -> 0.91415099 | U37: Major Holders | W37: 113.63
K38: Current Ratio | N38: =IFERROR(_xlfn.XLOOKUP($K38,Multiples!$B:$B,Multiples!N:N),"") -> 0.92423425 | O38: =IFERROR(_xlfn.XLOOKUP($K38,Multiples!$B:$B,Multiples!O:O),"") -> 0.96442178 | P38: =IFERROR(_xlfn.XLOOKUP($K38,Multiples!$B:$B,Multiples!P:P),"") -> 1.0404321 | Q38: =IFERROR(_xlfn.XLOOKUP($K38,Multiples!$B:$B,Multiples!Q:Q),"") -> 1.166993 | R38: =IFERROR(_xlfn.XLOOKUP($K38,Multiples!$B:$B,Multiples!R:R),"") -> 1.166993 | U38: The Vanguard Group, Inc. | V38: 0.1001
U39: BlackRock, Inc. | V39: 0.0851
D40: Opportunities | G40: Threats | K40: Cash Flow Ratios | N40: 2022 | O40: =+N40+1 -> 2023 | P40: =+O40+1 -> 2024 | Q40: =+P40+1 -> 2025 | R40: =+Q40+1 -> 2026 | U40: State Street Global Advisors, Inc. | V40: 0.0598
D41: A growing market. 73% of companies use hybrid cloud today. The Hybrid cloud market is expected to grow considerably in the next 10 years. | G41: The integration of GenAI into hybrid clould presents technological and operatinal challenges. IBM need to continuously innovate and enhance its offerings to address the complexity within the growing demand. Market is highly competitive with strong players like AWS and Azure. | K41: Cash Conversion Cycle | N41: =IFERROR(_xlfn.XLOOKUP($K41,Multiples!$B:$B,Multiples!N:N),"") -> 11.608122 | O41: =IFERROR(_xlfn.XLOOKUP($K41,Multiples!$B:$B,Multiples!O:O),"") -> 6.9944773 | P41: =IFERROR(_xlfn.XLOOKUP($K41,Multiples!$B:$B,Multiples!P:P),"") -> 8.2760561 | Q41: =IFERROR(_xlfn.XLOOKUP($K41,Multiples!$B:$B,Multiples!Q:Q),"") -> 8.9513139 | R41: =IFERROR(_xlfn.XLOOKUP($K41,Multiples!$B:$B,Multiples!R:R),"") -> 8.0657111 | U41: Geode Capital Management, LLC | V41: 0.0225
K42: Net Income / Op Cash Flow | N42: =IFERROR(_xlfn.XLOOKUP($K42,Multiples!$B:$B,Multiples!N:N),"") -> 0.17077144 | O42: =IFERROR(_xlfn.XLOOKUP($K42,Multiples!$B:$B,Multiples!O:O),"") -> 0.53930084 | P42: =IFERROR(_xlfn.XLOOKUP($K42,Multiples!$B:$B,Multiples!P:P),"") -> 0.44745258 | Q42: =IFERROR(_xlfn.XLOOKUP($K42,Multiples!$B:$B,Multiples!Q:Q),"") -> 0.53710929 | R42: =IFERROR(_xlfn.XLOOKUP($K42,Multiples!$B:$B,Multiples!R:R),"") -> 0.5550604 | U42: UBS Asset Management AG | V42: 0.0143
K43: Chg in Cash / Op Cash Flow | N43: =IFERROR(_xlfn.XLOOKUP($K43,Multiples!$B:$B,Multiples!N:N),"") -> 0.09889794 | O43: =IFERROR(_xlfn.XLOOKUP($K43,Multiples!$B:$B,Multiples!O:O),"") -> 0.3661618 | P43: =IFERROR(_xlfn.XLOOKUP($K43,Multiples!$B:$B,Multiples!P:P),"") -> 0.079657865 | Q43: =IFERROR(_xlfn.XLOOKUP($K43,Multiples!$B:$B,Multiples!Q:Q),"") -> 0.29226515 | R43: =IFERROR(_xlfn.XLOOKUP($K43,Multiples!$B:$B,Multiples!R:R),"") -> 0.27774298 | U43: Capital Research and Management Company | V43: 0.013
U44: Nothern Trust Global Investments | V44: 0.0117
D45: Revenue by Region | G45: Revenue by Segment | K45: Leverage Ratios | N45: 2022 | O45: =+N45+1 -> 2023 | P45: =+O45+1 -> 2024 | Q45: =+P45+1 -> 2025 | R45: =+Q45+1 -> 2026 | U45: Morgan Stanley | V45: 0.01
K46: Total Debt / Equity | N46: =IFERROR(_xlfn.XLOOKUP($K46,Multiples!$B:$B,Multiples!N:N),"") -> 2.4526837 | O46: =IFERROR(_xlfn.XLOOKUP($K46,Multiples!$B:$B,Multiples!O:O),"") -> 2.6505838 | P46: =IFERROR(_xlfn.XLOOKUP($K46,Multiples!$B:$B,Multiples!P:P),"") -> 2.1318633 | Q46: =IFERROR(_xlfn.XLOOKUP($K46,Multiples!$B:$B,Multiples!Q:Q),"") -> 1.9413015 | R46: =IFERROR(_xlfn.XLOOKUP($K46,Multiples!$B:$B,Multiples!R:R),"") -> 2.054483 | T46: . | U46: J.P. Morgan Asset Management | V46: 0.0099
K47: Total Debt / Capital | N47: =IFERROR(_xlfn.XLOOKUP($K47,Multiples!$B:$B,Multiples!N:N),"") -> 0.99959245 | O47: =IFERROR(_xlfn.XLOOKUP($K47,Multiples!$B:$B,Multiples!O:O),"") -> 0.99962287 | P47: =IFERROR(_xlfn.XLOOKUP($K47,Multiples!$B:$B,Multiples!P:P),"") -> 0.99953115 | Q47: =IFERROR(_xlfn.XLOOKUP($K47,Multiples!$B:$B,Multiples!Q:Q),"") -> 0.66001445 | R47: =IFERROR(_xlfn.XLOOKUP($K47,Multiples!$B:$B,Multiples!R:R),"") -> 0.67261236 | U47: Managed Account Advisors LLC | V47: 0.008
...

Sheet Segments
B2: Segments
B4: Regions | D4: Weight | E4: 2020 | F4: =+E4+1 -> 2021 | G4: =+F4+1 -> 2022 | H4: =+G4+1 -> 2023 | I4: =+H4+1 -> 2024 | J4: ="CAGR "&$G$4&" - "&$I$4 -> CAGR 2022 - 2024 | K4: 2021 | L4: =+K4+1 -> 2022 | M4: =+L4+1 -> 2023 | N4: =+M4+1 -> 2024
B6: United States of America | D6: =IFERROR(I6/SUM($I$6:$I$12),"") -> 0.41463737 | E6: 22258 | F6: 22893 | G6: 25098 | H6: 25309 | I6: 25098 | J6: =IFERROR((I6/G6)^(1/COUNT($G$4:$I$4))-1,"") -> 0 | K6: =IFERROR((F6-E6)/E6,"") -> 0.028529068 | L6: =IFERROR((G6-F6)/F6,"") -> 0.096317652 | M6: =IFERROR((H6-G6)/G6,"") -> 0.0084070444 | N6: =IFERROR((I6-H6)/H6,"") -> -0.0083369552
B7: Other countries | D7: =IFERROR(I7/SUM($I$6:$I$12),"") -> 0.58536263 | E7: =5680+27241 -> 32921 | F7: =5648+28810 -> 34458 | G7: 25432 | H7: 36551 | I7: 35432 | J7: =IFERROR((I7/G7)^(1/COUNT($G$4:$I$4))-1,"") -> 0.11687624 | K7: =IFERROR((F7-E7)/E7,"") -> 0.046687525 | L7: =IFERROR((G7-F7)/F7,"") -> -0.26194207 | M7: =IFERROR((H7-G7)/G7,"") -> 0.4372051 | N7: =IFERROR((I7-H7)/H7,"") -> -0.030614757
D8: =IFERROR(I8/SUM($I$6:$I$12),"") -> 0 | J8: =IFERROR((I8/E8)^(1/COUNT($E$4:$I$4))-1,"") | K8: =IFERROR((F8-E8)/E8,"") | L8: =IFERROR((G8-F8)/F8,"") | M8: =IFERROR(H8-G8/G8,"") | N8: =IFERROR((I8-H8)/H8,"")
D9: =IFERROR(I9/SUM($I$6:$I$12),"") -> 0 | J9: =IFERROR((I9/E9)^(1/COUNT($E$4:$I$4))-1,"") | K9: =IFERROR((F9-E9)/E9,"") | L9: =IFERROR((G9-F9)/F9,"") | M9: =IFERROR(H9-G9/G9,"") | N9: =IFERROR((I9-H9)/H9,"")
D10: =IFERROR(I10/SUM($I$6:$I$12),"") -> 0 | J10: =IFERROR((I10/E10)^(1/COUNT($E$4:$I$4))-1,"") | K10: =IFERROR((F10-E10)/E10,"") | L10: =IFERROR((G10-F10)/F10,"") | M10: =IFERROR(H10-G10/G10,"") | N10: =IFERROR((I10-H10)/H10,"")
D11: =IFERROR(I11/SUM($I$6:$I$12),"") -> 0 | K11: =IFERROR((F11-E11)/E11,"") | L11: =IFERROR((G11-F11)/F11,"")
D12: =IFERROR(I12/SUM($I$6:$I$12),"") -> 0 | K12: =IFERROR((F12-E12)/E12,"") | L12: =IFERROR((G12-F12)/F12,"")
B13: Total | D13: =SUM(D6:D12) -> 1 | E13: =SUM(E6:E10) -> 55179 | F13: =SUM(F6:F10) -> 57351 | G13: =SUM(G6:G10) -> 50530 | H13: =SUM(H6:H10) -> 61860 | I13: =SUM(I6:I10) -> 60530 | J13: =IFERROR((I13/G13)^(1/COUNT($G$4:$I$4))-1,"") -> 0.062038984 | K13: =IFERROR((F13-E13)/E13,"") -> 0.039362801 | L13: =IFERROR((G13-F13)/F13,"") -> -0.11893428 | M13: =IFERROR((H13-G13)/G13,"") -> 0.22422323 | N13: =IFERROR((I13-H13)/H13,"") -> -0.021500162
B15: Segments | D15: Weight | E15: 2020 | F15: =+E15+1 -> 2021 | G15: =+F15+1 -> 2022 | H15: =+G15+1 -> 2023 | I15: =+H15+1 -> 2024 | J15: ="CAGR "&$E$4&" - "&$I$4 -> CAGR 2020 - 2024 | K15: 2021 | L15: =+K15+1 -> 2022 | M15: =+L15+1 -> 2023 | N15: =+M15+1 -> 2024
B17: Software | D17: =IFERROR(I17/SUM($I$17:$I$21),"") -> 0.43329067 | E17: 22927 | F17: 24141 | G17: 23629 | H17: 25011 | I17: 27085 | J17: =IFERROR((I17/E17)^(1/COUNT($E$4:$I$4))-1,"") -> 0.03389473 | K17: =IFERROR((F17-E17)/E17,"") -> 0.05295067 | L17: =IFERROR((G17-F17)/F17,"") -> -0.021208732 | M17: =IFERROR((H17-G17)/G17,"") -> 0.058487452 | N17: =IFERROR((I17-H17)/H17,"") -> 0.082923514
B18: Consulting | D18: =IFERROR(I18/SUM($I$17:$I$21),"") -> 0.33101904 | E18: 16257 | F18: 17844 | G18: 20058 | H18: 20884 | I18: 20692 | J18: =IFERROR((I18/E18)^(1/COUNT($E$4:$I$4))-1,"") -> 0.049427433 | K18: =IFERROR((F18-E18)/E18,"") -> 0.097619487 | L18: =IFERROR((G18-F18)/F18,"") -> 0.12407532 | M18: =IFERROR((H18-G18)/G18,"") -> 0.041180576 | N18: =IFERROR((I18-H18)/H18,"") -> -0.0091936411
B19: Infraestructure | D19: =IFERROR(I19/SUM($I$17:$I$21),"") -> 0.22428411 | E19: 14533 | F19: 14188 | G19: 15288 | H19: 14593 | I19: 14020 | J19: =IFERROR((I19/E19)^(1/COUNT($E$4:$I$4))-1,"") -> -0.0071616412 | K19: =IFERROR((F19-E19)/E19,"") -> -0.023739077 | L19: =IFERROR((G19-F19)/F19,"") -> 0.077530307 | M19: =IFERROR((H19-G19)/G19,"") -> -0.045460492 | N19: =IFERROR((I19-H19)/H19,"") -> -0.039265401
B20: Financing | D20: =IFERROR(I20/SUM($I$17:$I$21),"") -> 0.011406175 | E20: 975 | F20: 774 | G20: 645 | H20: 741 | I20: 713 | J20: =IFERROR((I20/E20)^(1/COUNT($E$4:$I$4))-1,"") -> -0.060672617 | K20: =IFERROR((F20-E20)/E20,"") -> -0.20615385 | L20: =IFERROR((G20-F20)/F20,"") -> -0.16666667 | M20: =IFERROR((H20-G20)/G20,"") -> 0.14883721 | N20: =IFERROR((I20-H20)/H20,"") -> -0.037786775
D21: =IFERROR(I21/SUM($I$17:$I$21),"") -> 0 | J21: =IFERROR((I21/E21)^(1/COUNT($E$4:$I$4))-1,"") | K21: =IFERROR((F21-E21)/E21,"") | L21: =IFERROR((G21-F21)/F21,"") | M21: =IFERROR((H21-G21)/G21,"") | N21: =IFERROR((I21-H21)/H21,"")
B22: Total | D22: =SUM(D17:D21) -> 1 | E22: =SUM(E17:E21) -> 54692 | F22: =SUM(F17:F21) -> 56947 | G22: =SUM(G17:G21) -> 59620 | H22: =SUM(H17:H21) -> 61229 | I22: =SUM(I17:I21) -> 62510 | J22: =IFERROR((I22/E22)^(1/COUNT($E$4:$I$4))-1,"") -> 0.027082049 | K22: =IFERROR((F22-E22)/E22,"") -> 0.041230893 | L22: =IFERROR((G22-F22)/F22,"") -> 0.046938381 | M22: =IFERROR((H22-G22)/G22,"") -> 0.026987588 | N22: =IFERROR((I22-H22)/H22,"") -> 0.020921459
B24: Categories | D24: Description | J24: Graphs
B26: Software | D26: IBM Software segment englobes, the hybrid cloud, data and AI, automation, transaction processind and security.
B27: Consulting | D27: Many of the clients need expertise, not only in the software in wich are interested but also digital transformation and cloud modernization.
B28: Infraestructure | D28: IBM infrustructure revenue is based on high tech hardware capable of run all the cutting edge software.
B30: =IF(B21=0,"",B21)
B32: Products | D32: Weight | E32: 2020 | F32: =+E32+1 -> 2021 | G32: =+F32+1 -> 2022 | H32: =+G32+1 -> 2023 | I32: =+H32+1 -> 2024 | J32: =I32+1 -> 2025 | K32: =+J32+1 -> 2026 | L32: =+K32+1 -> 2027 | M32: =+L32+1 -> 2028 | N32: =+M32+1 -> 2029 | O32: =+N32+1 -> 2030 | P32: =+O32+1 -> 2031 | Q32: =+P32+1 -> 2032 | R32: =+Q32+1 -> 2033 | S32: =+R32+1 -> 2034
B34: =Sheet1!B60 -> Software | D34: =IFERROR(I34/$I$22,"") -> 0.43329067 | E34: =Sheet1!C62 -> 22124 | F34: =Sheet1!D62 -> 23426 | G34: =Sheet1!F62 -> 23629 | H34: =Sheet1!G62 -> 25011 | I34: =Sheet1!H62 -> 27085 | J34: =I34*(1+J35) -> 29362.139 | K34: =J34*(1+K35) -> 31928.673 | L34: =K34*(1+L35) -> 34846.981 | M34: =L34*(1+M35) -> 38151.446 | N34: =M34*(1+N35) -> 41900.013 | O34: =N34*(1+O35) -> 46131.77 | P34: =O34*(1+P35) -> 50474.729 | Q34: =P34*(1+Q35) -> 54880.587 | ... S34: =R34*(1+S35) -> 63657.805
B35: growth | F35: =(F34-E34)/E34 -> 0.058850118 | G35: =(G34-F34)/F34 -> 0.0086655852 | H35: =(H34-G34)/G34 -> 0.058487452 | I35: =(I34-H34)/H34 -> 0.082923514 | J35: =Sheet1!I61 -> 0.084073816 | K35: =Sheet1!J61 -> 0.087409629 | L35: =Sheet1!K61 -> 0.091400849 | M35: =Sheet1!L61 -> 0.094827881 | N35: =Sheet1!M61 -> 0.098254914 | O35: =Sheet1!N61 -> 0.10099654 | P35: =Sheet1!O61 -> 0.094142475 | Q35: =Sheet1!P61 -> 0.08728841 | ... S35: =Sheet1!R61 -> 0.07358028
B36: =" "&Sheet1!B5 -> Hybrid Platform & Solutions | D36: =IFERROR(I36/$I$34,"") -> 0.6944065 | E36: =Sheet1!R5 -> 15518 | F36: =Sheet1!O5 -> 17036 | G36: =Sheet1!I5 -> 16458 | H36: =Sheet1!F5 -> 17396 | I36: =Sheet1!C5 -> 18808 | J36: =I36*(1+J37) -> 20594.76 | K36: =J36*(1+K37) -> 22654.236 | L36: =K36*(1+L37) -> 25055.585 | M36: =L36*(1+M37) -> 27836.755 | N36: =M36*(1+N37) -> 31065.819 | O36: =N36*(1+O37) -> 34793.717 | P36: =O36*(1+P37) -> 38621.026 | Q36: =P36*(1+Q37) -> 42483.128 | ... S36: =R36*(1+S37) -> 50011.138
B37: growth | F37: =IFERROR((F36-E36)/E36,"") -> 0.097821884 | G37: =IFERROR((G36-F36)/F36,"") -> -0.033928152 | H37: =IFERROR((H36-G36)/G36,"") -> 0.056993559 | I37: =IFERROR((I36-H36)/H36,"") -> 0.081168085 | J37: =Sheet1!V4 -> 0.095 | K37: =Sheet1!W4 -> 0.1 | L37: =Sheet1!X4 -> 0.106 | M37: =Sheet1!Y4 -> 0.111 | N37: =Sheet1!Z4 -> 0.116 | O37: =Sheet1!AA4 -> 0.12 | P37: =Sheet1!AB4 -> 0.11 | Q37: =Sheet1!AC4 -> 0.1 | ... S37: =Sheet1!AE4 -> 0.08
B38: =" "&Sheet1!B6 -> Transaction Processing | D38: =IFERROR(I38/$I$34,"") -> 0.3055935 | E38: =Sheet1!R6 -> 6606 | F38: =Sheet1!O6 -> 6390 | G38: =Sheet1!I6 -> 7171 | H38: =Sheet1!F6 -> 7615 | I38: =Sheet1!C6 -> 8277 | J38: =I38*(1+J39) -> 8770.2562 | K38: =J38*(1+K39) -> 9292.9074 | L38: =K38*(1+L39) -> 9846.7052 | M38: =L38*(1+M39) -> 10433.506 | N38: =M38*(1+N39) -> 11055.276 | O38: =N38*(1+O39) -> 11714.1 | P38: =O38*(1+P39) -> 12412.185 | Q38: =P38*(1+Q39) -> 13151.872 | ... S38: =R38*(1+S39) -> 14766.114
B39: growth | F39: =IFERROR((F38-E38)/E38,"") -> -0.032697548 | G39: =IFERROR((G38-F38)/F38,"") -> 0.12222222 | H39: =IFERROR((H38-G38)/G38,"") -> 0.061916051 | I39: =IFERROR((I38-H38)/H38,"") -> 0.086933684 | J39: =Sheet1!$V$6 -> 0.059593602 | K39: =Sheet1!$V$6 -> 0.059593602 | L39: =Sheet1!$V$6 -> 0.059593602 | M39: =Sheet1!$V$6 -> 0.059593602 | N39: =Sheet1!$V$6 -> 0.059593602 | O39: =Sheet1!$V$6 -> 0.059593602 | P39: =Sheet1!$V$6 -> 0.059593602 | Q39: =Sheet1!$V$6 -> 0.059593602 | ... S39: =Sheet1!$V$6 -> 0.059593602
B40: =Sheet1!B54 -> Consulting | D40: =IFERROR(I40/$I$22,"") -> 0.33101904 | E40: =Sheet1!C56 -> 16257 | F40: =Sheet1!D56 -> 17844 | G40: =Sheet1!F56 -> 20058 | H40: =Sheet1!G56 -> 20884 | I40: =Sheet1!H56 -> 20692 | J40: =I40*(1+J41) -> 21105.84 | K40: =J40*(1+K41) -> 21739.015 | L40: =K40*(1+L41) -> 22608.576 | M40: =L40*(1+M41) -> 23739.005 | N40: =M40*(1+N41) -> 24925.955 | O40: =N40*(1+O41) -> 26172.253 | P40: =O40*(1+P41) -> 27480.865 | Q40: =P40*(1+Q41) -> 28854.908 | ... S40: =R40*(1+S41) -> 31812.537
B41: growth | F41: =IFERROR((F40-E40)/E40,"") -> 0.097619487 | G41: =IFERROR((G40-F40)/F40,"") -> 0.12407532 | H41: =IFERROR((H40-G40)/G40,"") -> 0.041180576 | I41: =IFERROR((I40-H40)/H40,"") -> -0.0091936411 | J41: =Sheet1!I55 -> 0.02 | K41: =Sheet1!J55 -> 0.03 | L41: =Sheet1!K55 -> 0.04 | M41: =Sheet1!L55 -> 0.05 | N41: =Sheet1!M55 -> 0.05 | O41: =Sheet1!N55 -> 0.05 | P41: =Sheet1!O55 -> 0.05 | Q41: =Sheet1!P55 -> 0.05 | ... S41: =Sheet1!R55 -> 0.05
B42: =Sheet1!B57 -> Infrastructure | D42: =IFERROR(I42/$I$22,"") -> 0.22428411 | E42: =Sheet1!C59 -> 14533 | F42: =Sheet1!D59 -> 14188 | G42: =Sheet1!E59 -> 15288 | H42: =Sheet1!G59 -> 14593 | I42: =Sheet1!H59 -> 14020 | J42: =I42*(1+J43) -> 14648.096 | K42: =J42*(1+K43) -> 14500 | L42: =K42*(1+L43) -> 14000 | M42: =L42*(1+M43) -> 14630 | N42: =M42*(1+N43) -> 14500 | O42: =N42*(1+O43) -> 14000 | P42: =O42*(1+P43) -> 14630 | Q42: =P42*(1+Q43) -> 14500 | ... S42: =R42*(1+S43) -> 14630
B43: growth | F43: =IFERROR((F42-E42)/E42,"") -> -0.023739077 | G43: =IFERROR((G42-F42)/F42,"") -> 0.077530307 | H43: =IFERROR((H42-G42)/G42,"") -> -0.045460492 | I43: =IFERROR((I42-H42)/H42,"") -> -0.039265401 | J43: =Sheet1!I58 -> 0.0448 | K43: =Sheet1!J58 -> -0.010110256 | L43: =Sheet1!K58 -> -0.034482759 | M43: =Sheet1!L58 -> 0.045 | N43: =Sheet1!M58 -> -0.008885851 | O43: =Sheet1!N58 -> -0.034482759 | P43: =Sheet1!O58 -> 0.045 | Q43: =Sheet1!P58 -> -0.008885851 | ... S43: =Sheet1!R58 -> 0.045
B44: =Sheet1!B63 -> Financing | D44: =IFERROR(I44/$I$22,"") -> 0.011406175 | E44: =Sheet1!C63 -> 975 | F44: =Sheet1!D63 -> 774 | G44: =Sheet1!E63 -> 645 | H44: =Sheet1!G63 -> 741 | I44: =Sheet1!H63 -> 713 | J44: =I44*(1+J45) -> 666.33948 | K44: =J44*(1+K45) -> 646.17293 | L44: =K44*(1+L45) -> 648.65152 | M44: =L44*(1+M45) -> 627.62578 | N44: =M44*(1+N45) -> 608.12451 | O44: =N44*(1+O45) -> 594.45465 | P44: =O44*(1+P45) -> 582.24916 | Q44: =P44*(1+Q45) -> 566.74722 | ... S44: =R44*(1+S45) -> 539.38303
B45: growth | J45: =Sheet1!I64 -> -0.06544252 | K45: =Sheet1!J64 -> -0.030264688 | L45: =Sheet1!K64 -> 0.0038358068 | M45: =Sheet1!L64 -> -0.032414544 | N45: =Sheet1!M64 -> -0.031071486 | O45: =Sheet1!N64 -> -0.022478728 | P45: =Sheet1!O64 -> -0.020532238 | Q45: =Sheet1!P64 -> -0.026624249 | ... S45: =Sheet1!R64 -> -0.023702972
B46: Total | D46: =SUM(D34+D40+D42+D44) -> 1 | E46: =E34+E40+E42+E44 -> 53889 | F46: =F34+F40+F42+F44 -> 56232 | G46: =G34+G40+G42+G44 -> 59620 | H46: =H34+H40+H42+H44 -> 61229 | I46: =I34+I40+I42+I44 -> 62510 | J46: =I46*(1+J47) -> 65677.103 | K46: =J46*(1+K47) -> 68597.198 | L46: =K46*(1+L47) -> 71824.997 | M46: =L46*(1+M47) -> 76849.334 | N46: =M46*(1+N47) -> 81616.817 | O46: =N46*(1+O47) -> 86561.978 | P46: =O46*(1+P47) -> 92807.067 | Q46: =P46*(1+Q47) -> 98419.649 | ... S46: =R46*(1+S47) -> 110211.29
J47: =Sheet1!I67 -> 0.050665542 | K47: =Sheet1!J67 -> 0.044461383 | L47: =Sheet1!K67 -> 0.047054391 | M47: =Sheet1!L67 -> 0.069952483 | N47: =Sheet1!M67 -> 0.062036751 | O47: =Sheet1!N67 -> 0.06058997 | P47: =Sheet1!O67 -> 0.072145869 | Q47: =Sheet1!P67 -> 0.060475803 | ... S47: =Sheet1!R67 -> 0.062362286
B48: Company's Strategy / Extra Notes
B50: Decline of revenue from Japan | D50: Eventhough the table does not show it, it must be noted that japanese clients, until 2021, represented at least 10% of the company revenue. Therefore being the second biggest country for IBM, just behind USA.
B51: Adapting AI to the clients needs | D51: IBM has, after consulting the feedback of their clients, developped AI tools "Apache 2.0" that was specially thougt to respond to their needs. By doing this they are offering cheaper specialized services that outperform the alternatives.
...

Sheet Industry
B2: Industry Overview
B4: Sales Growth Forecast | E4: Weight | F4: 2025 | G4: =+F4+1 -> 2026 | H4: =+G4+1 -> 2027 | I4: =+H4+1 -> 2028 | J4: =+I4+1 -> 2029 | K4: =+J4+1 -> 2030 | L4: =+K4+1 -> 2031 | M4: =+L4+1 -> 2032 | N4: =+M4+1 -> 2033 | ... P4: =+O4+1 -> 2035 | Q4: ="CAGR "&$F$4&" - "&$P$4 -> CAGR 2025 - 2035 | R4: Sources
B6: AI services | Q6: 0.266 | R6: Statista
B7: Hybrid Cloud | Q7: 0.174 | R7: Allied Market Research
B8: Weighted Average | E8: =SUM(E6:E7) -> 0 | F8: =SUMPRODUCT(F6:F7,$E$6:$E$7) -> 0 | G8: =SUMPRODUCT(G6:G7,$E$6:$E$7) -> 0 | H8: =SUMPRODUCT(H6:H7,$E$6:$E$7) -> 0 | I8: =SUMPRODUCT(I6:I7,$E$6:$E$7) -> 0 | J8: =SUMPRODUCT(J6:J7,$E$6:$E$7) -> 0 | K8: =SUMPRODUCT(K6:K7,$E$6:$E$7) -> 0 | L8: =SUMPRODUCT(L6:L7,$E$6:$E$7) -> 0 | M8: =SUMPRODUCT(M6:M7,$E$6:$E$7) -> 0 | ... P8: =SUMPRODUCT(P6:P7,$E$6:$E$7) -> 0 | Q8: =IFERROR(((1+F8)*(1+G8)*(1+H8)*(1+I8)*(1+J8)*(1+K8)*(1+L8)*(1+M8)*(1+N8)*(1+O8)*(1+P8))^(1/COUNT($F$4:$P$4))-1,"") -> 0
B10: Key Drivers | E10: Description
B12: Hybrid Cloud & AI Leadership | E12: IBM has articulated a clear strategy to dominate the hybrid cloud and AI market by integrating its Red Hat OpenShift platform with AI-driven services. This approach caters to enterprises seeking seamless on-premises and multicloud solutions, positioning IBM as a one-stop provider for complex, regulated industries.
B13: Leadership in Quantum & Emerging Technologies | E13: Quantum computing is the result of fisics applied to computing and allows machine learning not only cheapper but mainly faster. IBM Quantum Roadmap is the example of the company's lead in this area and plans to keep up with the high investment in R&D in order to keep this positioning.
B14: Shift to Recurring Revenue & Software Mix | E14: Switching form hardware to software provide greater revenue visibility and more stable free cash flow to fund innovation and strategic investments and increasing operating margin.
B17: Industry Trends | E17: Description
B19: Policies on AI development | E19: All around the world the Artificial intelifgence has been considered guilty of spreading misinformation and being a threat to the world. This resulted in governments applying strict regulations to the develpment of this type of technology (eg. European AI Office)
B20: Trade war threat | E20: With the applience of tariffs by USA and China on eachother products, it is not certain the outcome but the technology sector has so far been hit harshly. Therefore, the fear of the worstning of the situation might limit the short term development of companies like IBM.
B23: Market Share | E23: Headquarters | G23: Revenues | H23: (in MM of USD) | I23: Market Share
B25: {=+_FV(DCF!R4,"Name")} -> INTERNATIONAL BUSINESS MACHINES CORPORATION | E25: #VALUE! | G25: {=TRANSPOSE(Peers!D97:N97)} -> 62753 | I25: =IFERROR(G25/$G$37,"") -> 0.041835333
B26: =Peers!E$91 -> #VALUE! | E26: #VALUE! | G26: 64896.5 | I26: =IFERROR(G26/$G$37,"") -> 0.043264333
B27: =Peers!F91 -> #VALUE! | E27: #VALUE! | G27: 22096 | I27: =IFERROR(G27/$G$37,"") -> 0.014730667
B28: =Peers!G91 -> #VALUE! | E28: #VALUE! | G28: 245122 | I28: =IFERROR(G28/$G$37,"") -> 0.16341467
B29: =Peers!H91 -> #VALUE! | E29: #VALUE! | G29: 52961 | I29: =IFERROR(G29/$G$37,"") -> 0.035307333
B30: =Peers!I91 -> #VALUE! | E30: #VALUE! | G30: 30127 | I30: =IFERROR(G30/$G$37,"") -> 0.020084667
B31: =Peers!J91 -> #VALUE! | E31: #VALUE! | G31: 43073 | I31: =IFERROR(G31/$G$37,"") -> 0.028715333
B32: =Peers!K91 -> #VALUE! | E32: #VALUE! | G32: 10790 | I32: =IFERROR(G32/$G$37,"") -> 0.0071933333
B33: {=+_FV(Peers!A15,"Name")} -> #VALUE! | G33: 0 | I33: =IFERROR(G33/$G$37,"") -> 0
B34: {=+_FV(Peers!A16,"Name")} -> #VALUE! | G34: 0 | I34: =IFERROR(G34/$G$37,"") -> 0
B35: {=+_FV(Peers!A17,"Name")} -> #VALUE! | G35: 0 | I35: =IFERROR(G35/$G$37,"") -> 0
B36: Others | E36: -- | G36: =G37-SUM(G25:G35) -> 968181.5 | I36: =IFERROR(G36/$G$37,"") -> 0.64545433
B37: Industry Size | E37: -- | G37: 1500000 | I37: 1
B39: Porter's Five Forces Analysis | E39: Rating | H39: Graph
B41: Threat of New Entrants | E41: =IFERROR(AVERAGE(E42:E47),"") -> 2.8333333
B42: Economies of scale | E42: 4
B43: Product differentiation | E43: 3
B44: Capital requirements | E44: 3
B45: Access to distribution channels | E45: 2
B46: Regulations | E46: 2
B47: Switching costs | E47: 3
B48: Bargaining Power of Suppliers | E48: =IFERROR(AVERAGE(E49:E53),"") -> 4.4
B49: Number of suppliers | E49: 5
B50: Uniqueness | E50: 4
B51: Switching Costs | E51: 4
B52: Forward Integration | E52: 4
B53: Industry Importance | E53: 5
...

Sheet Peers
D3: Revenue Growth | F3: EBITDA Margin | H3: Profit Margin | J3: EV / Revenue | L3: EV / EBITDA | N3: Price / Earnings
B4: Peers | C4: Ticker | D4: =+Inputs!O4&"-"&Inputs!P4 -> 2022-2023 | E4: =+Inputs!P4&"-"&Inputs!Q4 -> 2023-2024 | F4: 2023 | G4: 2024 | H4: =+Inputs!O4&"-"&Inputs!P4 -> 2022-2023 | I4: =+Inputs!P4&"-"&Inputs!Q4 -> 2023-2024 | J4: 2023 | K4: 2024 | L4: 2023 | M4: 2024 | N4: 2023 | O4: 2024
A6: =+D91 -> #VALUE! | B6: {=IFERROR(_FV(A6,"Name"),"")} -> INTERNATIONAL BUSINESS MACHINES CORPORATION | C6: {=IFERROR(_FV(A6,"Ticker symbol",TRUE),"")} -> IBM | D6: =IFERROR(D94/D93-1,"") -> 0.021972576 | E6: =IFERROR(D97/D94-1,"") -> 0.014435823 | F6: =IFERROR(D95/D94,"") -> 0.22272874 | G6: =IFERROR(D100/D97,"") -> 0.22386181 | H6: =IFERROR(D96/D94,"") -> 0.12145167 | I6: =IFERROR(D105/D97,"") -> 0.095867927 | J6: {=IFERROR((_FV(A6,"Market cap",TRUE)/1000000+D$121-D$111)/D$94,"")} -> 5.5391003 | K6: {=IFERROR((_FV(A6,"Market cap",TRUE)/1000000+D$121-D$111)/D$97,"")} -> 5.4602767 | L6: {=+IFERROR((_FV(A6,"Market cap",TRUE)/1000000+D$121-D$111)/D$95,"")} -> 24.869266 | M6: {=IFERROR((_FV(A6,"Market cap",TRUE)/1000000+D$121-D$111)/D$100,"")} -> 24.391283 | N6: {=IFERROR((_FV(A6,"Market cap",TRUE)/1000000)/D$96,"")} -> 35.754319 | O6: {=IFERROR((_FV(A6,"Market cap",TRUE)/1000000)/D$105,"")} -> 44.651297
A8: =+E91 -> #VALUE! | B8: {=IFERROR(_FV(A8,"Nome"),"")} -> ACCENTURE PUBLIC LIMITED COMPANY | C8: {=+IFERROR(_FV(A8,"Símbolo do ticker",TRUE),"")} -> ACN | D8: =+IFERROR(E94/E93-1,"") -> 0.040870665 | E8: =IFERROR(E97/E94-1,"") -> 0.012241135 | F8: =IFERROR(E95/E94,"") -> 0.20285065 | G8: =+IFERROR(E100/E97,"") -> 0.19882582 | H8: =IFERROR(E96/E94,"") -> 0.10718168 | I8: =+IFERROR(D105/D99,"") -> 0.16921692 | J8: {=+IFERROR((_FV(A8,"Capitalização de mercado",TRUE)/1000000+E$121-E$111)/E$94,"")} -> 2.3695238 | K8: {=IFERROR(+(_FV(A8,"Capitalização de mercado",TRUE)/1000000+E$121-E$111)/E$97,"")} -> 2.3408689 | L8: {=IFERROR(+(_FV(A8,"Capitalização de mercado",TRUE)/1000000+E$121-E$111)/E$95,"")} -> 11.681125 | M8: {=IFERROR(+(_FV(A8,"Capitalização de mercado",TRUE)/1000000+E$121-E$111)/E$100,"")} -> 11.773465 | N8: {=IFERROR(+(_FV(A8,"Capitalização de mercado",TRUE)/1000000)/E$96,"")} -> 22.23619 | O8: {=IFERROR(+(_FV(A8,"Capitalização de mercado",TRUE)/1000000)/E$105,"")} -> 21.032678
A9: =+F91 -> #VALUE! | B9: {=IFERROR(_FV(A9,"Nome"),"")} -> Capgemini | C9: {=+IFERROR(_FV(A9,"Símbolo do ticker",TRUE),"")} -> CAPMF | D9: =IFERROR(F94/F93-1,"") -> 0.023959991 | E9: =IFERROR(+F97/F94-1,"") -> -0.018914839 | F9: =IFERROR(F95/F94,"") -> 0.14692301 | G9: =IFERROR(F100/F97,"") -> 0.14613505 | H9: =IFERROR(F96/F94,"") -> 0.073838913 | I9: =+IFERROR(F105/F97,"") -> 0.075624547 | J9: {=+IFERROR((_FV(A9,"Capitalização de mercado",TRUE)/1000000+E$121-E$111)/E$94,"")} -> 0.3198906 | K9: {=IFERROR(+(_FV(A9,"Capitalização de mercado",TRUE)/1000000+E$121-E$111)/E$97,"")} -> 0.31602213 | L9: {=IFERROR(+(_FV(A9,"Capitalização de mercado",TRUE)/1000000+E$121-E$111)/E$95,"")} -> 1.576976 | M9: {=IFERROR(+(_FV(A9,"Capitalização de mercado",TRUE)/1000000+E$121-E$111)/E$100,"")} -> 1.5894421 | N9: {=IFERROR(+(_FV(A9,"Capitalização de mercado",TRUE)/1000000)/E$96,"")} -> 3.1132094 | O9: {=IFERROR(+(_FV(A9,"Capitalização de mercado",TRUE)/1000000)/E$105,"")} -> 2.9447101
A10: =+G91 -> #VALUE! | B10: {=IFERROR(_FV(A10,"Nome"),"")} -> MICROSOFT CORPORATION | C10: {=+IFERROR(_FV(A10,"Símbolo do ticker",TRUE),"")} -> MSFT | D10: =+IFERROR(G94/G93-1,"") -> 0.068820296 | E10: =IFERROR(G97/G94-1,"") -> 0.15669962 | F10: =IFERROR(G95/G94,"") -> 0.50222967 | G10: =IFERROR(G100/G97,"") -> 0.55186805 | H10: =IFERROR(G96/G94,"") -> 0.34146238 | I10: =+IFERROR(G105/G97,"") -> 0.35955973 | J10: {=+IFERROR((_FV(A10,"Capitalização de mercado",TRUE)/1000000+E$121-E$111)/E$94,"")} -> 59.968227 | K10: {=IFERROR(+(_FV(A10,"Capitalização de mercado",TRUE)/1000000+E$121-E$111)/E$97,"")} -> 59.243025 | L10: {=IFERROR(+(_FV(A10,"Capitalização de mercado",TRUE)/1000000+E$121-E$111)/E$95,"")} -> 295.62748 | M10: {=IFERROR(+(_FV(A10,"Capitalização de mercado",TRUE)/1000000+E$121-E$111)/E$100,"")} -> 297.96444 | N10: {=IFERROR(+(_FV(A10,"Capitalização de mercado",TRUE)/1000000)/E$96,"")} -> 559.62934 | O10: {=IFERROR(+(_FV(A10,"Capitalização de mercado",TRUE)/1000000)/E$105,"")} -> 529.33997
A11: =+H91 -> #VALUE! | B11: {=IFERROR(_FV(A11,"Nome"),"")} -> ORACLE CORPORATION | C11: {=+IFERROR(_FV(A11,"Símbolo do ticker",TRUE),"")} -> ORCL | D11: =IFERROR(H94/H93-1,"") -> 0.17704995 | E11: =IFERROR(H97/H94-1,"") -> 0.06019538 | F11: =IFERROR(H95/H94,"") -> 0.41524202 | G11: =IFERROR(H100/H97,"") -> 0.44185344 | H11: =IFERROR(H96/H94,"") -> 0.1702166 | I11: =+IFERROR(H105/H102,"") -> 3.417238 | J11: {=+IFERROR((_FV(A11,"Capitalização de mercado",TRUE)/1000000+E$121-E$111)/E$94,"")} -> 12.709721 | K11: {=IFERROR(+(_FV(A11,"Capitalização de mercado",TRUE)/1000000+E$121-E$111)/E$97,"")} -> 12.556021 | L11: {=IFERROR(+(_FV(A11,"Capitalização de mercado",TRUE)/1000000+E$121-E$111)/E$95,"")} -> 62.655558 | M11: {=IFERROR(+(_FV(A11,"Capitalização de mercado",TRUE)/1000000+E$121-E$111)/E$100,"")} -> 63.150855 | N11: {=IFERROR(+(_FV(A11,"Capitalização de mercado",TRUE)/1000000)/E$96,"")} -> 118.70973 | O11: {=IFERROR(+(_FV(A11,"Capitalização de mercado",TRUE)/1000000)/E$105,"")} -> 112.28469
A12: =+I91 -> #VALUE! | B12: {=IFERROR(_FV(A12,"Nome"),"")} -> HEWLETT PACKARD ENTERPRISE COMPANY | C12: {=+IFERROR(_FV(A12,"Símbolo do ticker",TRUE),"")} -> HPE | D12: =+IFERROR(I94/I93-1,"") -> 0.0224242 | E12: =IFERROR(I97/I94-1,"") -> 0.034048395 | F12: =IFERROR(I95/I94,"") -> 0.18060752 | G12: =IFERROR(I100/I97,"") -> 0.17552362 | H12: =IFERROR(I96/I94,"") -> 0.069504033 | I12: =+IFERROR(I105/I97,"") -> 0.085604275 | J12: {=+IFERROR((_FV(A12,"Capitalização de mercado",TRUE)/1000000+E$121-E$111)/E$94,"")} -> 0.4889928 | K12: {=IFERROR(+(_FV(A12,"Capitalização de mercado",TRUE)/1000000+E$121-E$111)/E$97,"")} -> 0.48307936 | L12: {=IFERROR(+(_FV(A12,"Capitalização de mercado",TRUE)/1000000+E$121-E$111)/E$95,"")} -> 2.4106051 | M12: {=IFERROR(+(_FV(A12,"Capitalização de mercado",TRUE)/1000000+E$121-E$111)/E$100,"")} -> 2.4296611 | N12: {=IFERROR(+(_FV(A12,"Capitalização de mercado",TRUE)/1000000)/E$96,"")} -> 4.690925 | O12: {=IFERROR(+(_FV(A12,"Capitalização de mercado",TRUE)/1000000)/E$105,"")} -> 4.4370334
A13: =+J91 -> #VALUE! | B13: {=IFERROR(_FV(A13,"Nome"),"")} -> IONQ | C13: {=+IFERROR(_FV(A13,"Símbolo do ticker",TRUE),"")} -> IONQ | D13: =IFERROR(J94/J93-1,"") -> 0.98023538 | E13: =IFERROR(J97/J94-1,"") -> 0.95413302 | F13: =IFERROR(J95/J94,"") -> -6.6862807 | G13: =IFERROR(J100/J97,"") -> -4.9636896 | H13: =IFERROR(J96/J94,"") -> -7.1555688 | I13: =+IFERROR(J105/J97,"") -> -7.698281 | J13: {=+IFERROR((_FV(A13,"Capitalização de mercado",TRUE)/1000000+E$121-E$111)/E$94,"")} -> 0.3554646 | K13: {=IFERROR(+(_FV(A13,"Capitalização de mercado",TRUE)/1000000+E$121-E$111)/E$97,"")} -> 0.35116593 | L13: {=IFERROR(+(_FV(A13,"Capitalização de mercado",TRUE)/1000000+E$121-E$111)/E$95,"")} -> 1.7523464 | M13: {=IFERROR(+(_FV(A13,"Capitalização de mercado",TRUE)/1000000+E$121-E$111)/E$100,"")} -> 1.7661988 | N13: {=IFERROR(+(_FV(A13,"Capitalização de mercado",TRUE)/1000000)/E$96,"")} -> 3.4451132 | O13: {=IFERROR(+(_FV(A13,"Capitalização de mercado",TRUE)/1000000)/E$105,"")} -> 3.2586499
A14: =+K91 -> #VALUE! | B14: {=IFERROR(_FV(A14,"Nome"),"")} -> Rigetti | C14: {=+IFERROR(_FV(A14,"Símbolo do ticker",TRUE),"")} -> RGTI | D14: =IFERROR(K94/K93-1,"") -> -0.083498702 | E14: =IFERROR(K97/K94-1,"") -> -0.10143238 | F14: =+IFERROR(K95/K94,"") -> -5.1550633 | G14: =IFERROR(K100/K97,"") -> -6.3493976 | H14: =IFERROR(K96/K94,"") -> -6.2547468 | I14: =+IFERROR(K105/K97,"") -> -7.1616311 | J14: {=+IFERROR((_FV(A14,"Capitalização de mercado",TRUE)/1000000+E$121-E$111)/E$94,"")} -> 0.18876523 | K14: {=IFERROR(+(_FV(A14,"Capitalização de mercado",TRUE)/1000000+E$121-E$111)/E$97,"")} -> 0.18648248 | L14: {=IFERROR(+(_FV(A14,"Capitalização de mercado",TRUE)/1000000+E$121-E$111)/E$95,"")} -> 0.93056263 | M14: {=IFERROR(+(_FV(A14,"Capitalização de mercado",TRUE)/1000000+E$121-E$111)/E$100,"")} -> 0.93791879 | N14: {=IFERROR(+(_FV(A14,"Capitalização de mercado",TRUE)/1000000)/E$96,"")} -> 1.8898161 | O14: {=IFERROR(+(_FV(A14,"Capitalização de mercado",TRUE)/1000000)/E$105,"")} -> 1.7875317
A15: =+L91 -> PEER 8 | B15: {=IFERROR(_FV(A15,"Name"),"")} | C15: {=IFERROR(_FV(A15,"Ticker symbol",TRUE),"")} | D15: =+IFERROR(L94/L93,"") | E15: =IFERROR(L97/L94,"") | F15: =IFERROR(L95/L94,"") | G15: =IFERROR(L100/L97,"") | H15: =IFERROR(L96/L94,"") | I15: =+IFERROR(L105/L97,"") | J15: {=IFERROR(+(_FV(A15,"Market cap",TRUE)/1000000+L$121-L$111)/L$94,"")} | K15: {=IFERROR(+(_FV(A15,"Market cap",TRUE)/1000000+L$121-L$111)/L$97,"")} | L15: {=IFERROR(+(_FV(A15,"Market cap",TRUE)/1000000+L$121-L$111)/L$95,"")} | M15: {=IFERROR(+(_FV(A15,"Market cap",TRUE)/1000000+L$121-L$111)/L$100,"")} | N15: {=IFERROR(+(_FV(A15,"Market cap",TRUE)/1000000)/L$96,"")} | O15: {=IFERROR(+(_FV(A15,"Market cap",TRUE)/1000000)/L$105,"")}
A16: =+M91 -> PEER 9 | B16: {=IFERROR(_FV(A16,"Name"),"")} | C16: {=IFERROR(_FV(A16,"Ticker symbol",TRUE),"")} | D16: =IFERROR(M94/M93-1,"") | E16: =IFERROR(M97/M94-1,"") | F16: =IFERROR(M95/M94,"") | G16: =IFERROR(M100/M97,"") | H16: =IFERROR(M96/M94,"") | I16: =+IFERROR(M105/M97,"") | J16: {=IFERROR(+(_FV(A16,"Market cap",TRUE)/1000000+M$121-M$111)/M$94,"")} | K16: {=IFERROR(+(_FV(A16,"Market cap",TRUE)/1000000+M$121-M$111)/M$97,"")} | L16: {=IFERROR(+(_FV(A16,"Market cap",TRUE)/1000000+M$121-M$111)/M$95,"")} | M16: {=IFERROR(+(_FV(A16,"Market cap",TRUE)/1000000+M$121-M$111)/M$100,"")} | N16: {=IFERROR(+(_FV(A16,"Market cap",TRUE)/1000000)/M$96,"")} | O16: {=IFERROR(+(_FV(A16,"Market cap",TRUE)/1000000)/M$105,"")}
A17: =+N91 -> PEER 10 | B17: {=IFERROR(_FV(A17,"Name"),"")} | C17: {=+IFERROR(_FV(A17,"Ticker symbol",TRUE),"")} | D17: =IFERROR(N94/N93-1,"") | E17: =IFERROR(N97/N94-1,"") | F17: =IFERROR(N95/N94,"") | G17: =IFERROR(N100/N97,"") | H17: =IFERROR(N96/N94,"") | I17: =+IFERROR(N105/N97,"") | J17: {=IFERROR(+(_FV(A17,"Market cap",TRUE)/1000000+N$121-N$111)/N$94,"")} | K17: {=IFERROR(+(_FV(A17,"Market cap",TRUE)/1000000+N$121-N$111)/N$97,"")} | L17: {=IFERROR(+(_FV(A17,"Market cap",TRUE)/1000000+N$121-N$111)/N$95,"")} | M17: {=IFERROR(+(_FV(A17,"Market cap",TRUE)/1000000+N$121-N$111)/N$100,"")} | N17: {=IFERROR(+(_FV(A17,"Market cap",TRUE)/1000000)/N$96,"")} | O17: {=IFERROR(+(_FV(A17,"Market cap",TRUE)/1000000)/N$105,"")}
B18: Average | D18: =IFERROR(AVERAGE(D6:D17),"") -> 0.15647929 | E18: =IFERROR(AVERAGE(E6:E17),"") -> 0.13892577 | F18: =IFERROR(AVERAGE(F6:F17),"") -> -1.2713453 | G18: =IFERROR(AVERAGE(G6:G17),"") -> -1.1968774 | H18: =IFERROR(AVERAGE(H6:H17),"") -> -1.5658325 | I18: =IFERROR(AVERAGE(I6:I17),"") -> -1.3321001 | J18: =IFERROR(AVERAGE(J6:J17),"") -> 10.242461 | K18: =IFERROR(AVERAGE(K6:K17),"") -> 10.117118 | ... O18: =IFERROR(AVERAGE(O6:O17),"") -> 89.967069
B19: Deviation from Average | D19: =IFERROR(+D18-D6,"") -> 0.13450672 | E19: =IFERROR(E18-E6,"") -> 0.12448995 | F19: =+IFERROR(F18-F6,"") -> -1.494074 | G19: =IFERROR(G18-G6,"") -> -1.4207392 | H19: =IFERROR(+H6-H18,"") -> 1.6872842 | I19: =+IFERROR(I6-I18,"") -> 1.427968 | J19: =+IFERROR(J6-J18,"") -> -4.7033604 | K19: =+IFERROR(K6-K18,"") -> -4.656841 | L19: =IFERROR(+L6-L18,"") -> -25.318725 | M19: =IFERROR(M6-M18,"") -> -26.109125 | N19: =IFERROR(+N6-N18,"") -> -57.929262 | O19: =IFERROR(+O6-O18,"") -> -45.315773
D21: Trading Multiple | G21: Net | H21: Preferred | I21: Non-Controlling | J21: Equity Value | M21: Implied Upside (Downside)
B22: Implied Share Price | D22: Revenue | E22: EBITDA | F22: P/E | G22: Debt | H22: Stock | I22: Interest | J22: Revenue | K22: EBITDA | L22: P/E | M22: Revenue | N22: EBITDA | O22: P/E | P22: Current Price
B24: Second Minimum | D24: =IFERROR(SMALL(K6:K17,2),"") -> 0.31602213 | E24: =IFERROR(SMALL(M6:M17,2),"") -> 1.5894421 | F24: =IFERROR(SMALL(O6:O17,2),"") -> 2.9447101 | G24: =-Inputs!$Q$100+Inputs!$Q$101 -> 43805 | H24: =+Inputs!$Q$102 -> 0 | I24: =+Inputs!$Q$103 -> 86 | J24: =IFERROR(+D24*$D$97+G24+H24+I24,"") -> 63722.337 | K24: =IFERROR(E24*$D$100+G24+H24+I24,"") -> 66219.482 | L24: =IFERROR(F24*$D$105,"") -> 17715.376 | M24: {=IFERROR(+(J24/_FV($A$6,"Shares outstanding",TRUE)*1000000)/$P$24-1,"")} -> -0.76278082 | N24: {=IFERROR((+K24/_FV($A$6,"Shares outstanding",TRUE)*1000000)/$P$24-1,"")} -> -0.75348469 | O24: {=IFERROR(+(L24/_FV($A$6,"Shares outstanding",TRUE)*1000000)/$P$24-1,"")} -> -0.93405096 | P24: {=+_FV(A6,"Price")} -> 288.37
B25: Average | D25: =+IFERROR(AVERAGE(K6:K17),"") -> 10.117118 | E25: =IFERROR(+AVERAGE(M6:M17),"") -> 50.500408 | F25: =IFERROR(+AVERAGE(O6:O17),"") -> 89.967069 | G25: =-Inputs!$Q$100+Inputs!$Q$101 -> 43805 | H25: =+Inputs!$Q$102 -> 0 | I25: =+Inputs!$Q$103 -> 86 | J25: =IFERROR(+D25*$D$97+G25+H25+I25,"") -> 678770.49 | K25: =IFERROR(E25*$D$100+G25+H25+I25,"") -> 753320.74 | L25: =IFERROR(+F25*$D$105,"") -> 541241.89 | M25: {=IFERROR(+(J25/_FV($A$6,"Shares outstanding",TRUE)*1000000)/$P$24-1,"")} -> 1.5268593 | N25: {=IFERROR((+K25/_FV($A$6,"Shares outstanding",TRUE)*1000000)/$P$24-1,"")} -> 1.8043876 | O25: {=IFERROR(+(L25/_FV($A$6,"Shares outstanding",TRUE)*1000000)/$P$24-1,"")} -> 1.0148815
B26: Median | D26: =IFERROR(MEDIAN(K6:K17),"") -> 1.4119741 | E26: =IFERROR(MEDIAN(M6:M17),"") -> 7.1015632 | F26: =IFERROR(MEDIAN(O6:O17),"") -> 12.734856 | G26: =-Inputs!$Q$100+Inputs!$Q$101 -> 43805 | H26: =+Inputs!$Q$102 -> 0 | I26: =+Inputs!$Q$103 -> 86 | J26: =IFERROR(D26*$D$97+G26+H26+I26,"") -> 132496.61 | K26: =IFERROR(E26*$D$100+G26+H26+I26,"") -> 143653.76 | L26: =IFERROR(+F26*$D$105,"") -> 76612.892 | M26: {=IFERROR(+(J26/_FV($A$6,"Shares outstanding",TRUE)*1000000)/$P$24-1,"")} -> -0.50675477 | N26: {=IFERROR((+K26/_FV($A$6,"Shares outstanding",TRUE)*1000000)/$P$24-1,"")} -> -0.46522006 | O26: {=+IFERROR((L26/_FV($A$6,"Shares outstanding",TRUE)*1000000)/$P$24-1,"")} -> -0.71479314
B27: Second Maximum | D27: =IFERROR(LARGE(K6:K17,2),"") -> 12.556021 | E27: =IFERROR(LARGE(M6:M17,2),"") -> 63.150855 | F27: =IFERROR(LARGE(O6:O17,2),"") -> 112.28469 | G27: =-Inputs!$Q$100+Inputs!$Q$101 -> 43805 | H27: =+Inputs!$Q$102 -> 0 | I27: =+Inputs!$Q$103 -> 86 | J27: =IFERROR(+D27*$D$97+G27+H27+I27,"") -> 831818.97 | K27: =IFERROR(E27*$D$100+G27+H27+I27,"") -> 931034.21 | L27: =IFERROR(+F27*$D$105,"") -> 675504.68 | M27: {=IFERROR(+(J27/_FV($A$6,"Shares outstanding",TRUE)*1000000)/$P$24-1,"")} -> 2.096613 | N27: {=IFERROR((+K27/_FV($A$6,"Shares outstanding",TRUE)*1000000)/$P$24-1,"")} -> 2.4659616 | O27: {=IFERROR(+(L27/_FV($A$6,"Shares outstanding",TRUE)*1000000)/$P$24-1,"")} -> 1.5147017
B29: Profitability | D29: =+LEFT(B6, FIND(" ", B6 & " ") - 1) -> INTERNATIONAL | E29: =+LEFT(B8, FIND(" ", B8 & " ") - 1) -> ACCENTURE | F29: =+LEFT(B9, FIND(" ", B9 & " ") - 1) -> Capgemini | G29: =+LEFT(B10, FIND(" ", B10 & " ") - 1) -> MICROSOFT | H29: =+LEFT(B11, FIND(" ", B11 & " ") - 1) -> ORACLE | I29: =+LEFT(B12, FIND(" ", B12 & " ") - 1) -> HEWLETT | J29: =+LEFT(B13, FIND(" ", B13 & " ") - 1) -> IONQ | K29: =+LEFT(B14, FIND(" ", B14 & " ") - 1) -> Rigetti | L29: =+LEFT(B15, FIND(" ", B15 & " ") - 1) | M29: =+LEFT(B16, FIND(" ", B16 & " ") - 1) | N29: =+LEFT(B17, FIND(" ", B17 & " ") - 1) | O29: Average
B31: Operating Margin | D31: =IFERROR(D101/D97,"") -> 0.14949086 | E31: =IFERROR(E101/E97,"") -> 0.15462005 | F31: =IFERROR(F101/F97,"") -> 0.11522448 | G31: =IFERROR(G101/G97,"") -> 0.446443 | H31: =IFERROR(H101/H97,"") -> 0.30344971 | I31: =IFERROR(I101/I97,"") -> 0.082683307 | J31: =IFERROR(J101/J97,"") -> -5.3967683 | K31: =IFERROR(K101/K97,"") -> -6.9894347 | ... N31: =IFERROR(N101/N97,"") | O31: =IFERROR(+AVERAGE(D31:N31),"") -> -1.3917864
B32: Net Income Margin | D32: =IFERROR(D105/D97,"") -> 0.095867927 | E32: =IFERROR(E105/E97,"") -> 0.1119444 | F32: =IFERROR(F105/F97,"") -> 0.075624547 | G32: =IFERROR(G105/G97,"") -> 0.35955973 | H32: =IFERROR(H105/H97,"") -> 0.197636 | I32: =IFERROR(I105/I97,"") -> 0.085604275 | J32: =IFERROR(J105/J97,"") -> -7.698281 | K32: =IFERROR(K105/K97,"") -> -7.1616311 | ... N32: =IFERROR(N105/N97,"") | O32: =IFERROR(+AVERAGE(D32:N32),"") -> -1.7417094
B33: ROA (%) | D33: =IFERROR(D105/D117,"") -> 0.043856388 | E33: =IFERROR(E105/E117,"") -> 0.12988536 | F33: =IFERROR(F105/F117,"") -> 0.065120811 | G33: =IFERROR(G105/G117,"") -> 0.17208584 | H33: =IFERROR(H105/H117,"") -> 0.07424668 | I33: =IFERROR(I105/I117,"") -> 0.036190396 | J33: =IFERROR(J105/J117,"") -> -0.65223424 | K33: =IFERROR(K105/K117,"") -> -0.27133963 | ... N33: =IFERROR(N105/N117,"") | O33: =IFERROR(+AVERAGE(D33:N33),"") -> -0.050273549
B34: Financial Cost of Debt | D34: =IFERROR(+(D102/D121)*(1-(D104/D103)),"") -> 0.020192091 | E34: =IFERROR(+(E102/E121)*(1-(E104/E103)),"") -> -0.040122932 | F34: =IFERROR(+(F102/F121)*(1-(F104/F103)),"") -> -0.0032606173 | G34: =IFERROR(+(G102/G121)*(1-(G104/G103)),"") -> 0.024525922 | H34: =IFERROR(+(H102/H121)*(1-(H104/H103)),"") -> 0.028905123 | I34: =IFERROR(+(I102/I121)*(1-(I104/I103)),"") -> 0.0051565325 | J34: =IFERROR(+(J102/J121)*(1-(J104/J103)),"") -> -1.0295629 | K34: =IFERROR(+(K102/K121)*(1-(K104/K103)),"") -> 0.21113636 | ... N34: =IFERROR(+(N102/N121)*(1-(N104/N103)),"") | O34: =IFERROR(+AVERAGE(D34:N34),"") -> -0.097878808
B35: Return on Equity (RoE) | D35: =IFERROR(+D105/D122,"") -> 0.21962617 | E35: =IFERROR(+E105/E122,"") -> 0.24906576 | F35: =IFERROR(+F105/F122,"") -> 0.14164618 | G35: =IFERROR(+G105/G122,"") -> 0.32828138 | H35: =IFERROR(+H105/H122,"") -> 1.1329148 | I35: =IFERROR(+I105/I122,"") -> 0.10365756 | J35: =IFERROR(+J105/J122,"") -> -0.86382101 | K35: =IFERROR(+K105/K122,"") -> -0.61043219 | ... N35: =IFERROR(+N105/N122,"") | O35: =IFERROR(+AVERAGE(D35:N35),"") -> 0.087617334
B36: Return on Invested Capital (ROIC) | D36: =IFERROR(+D105/(D121+D122),"") -> 0.052147287 | E36: =IFERROR(+E105/(E121+E122),"") -> 0.21823622 | F36: =IFERROR(+F105/(F121+F122),"") -> 0.093487748 | G36: =IFERROR(+G105/(G121+G122),"") -> 0.24059247 | H36: =IFERROR(+H105/(H121+H122),"") -> 0.1009276 | I36: =IFERROR(+I105/(I121+I122),"") -> 0.057700913 | J36: =IFERROR(+J105/(J121+J122),"") -> -0.82569421 | K36: =IFERROR(+K105/(K121+K122),"") -> -0.57075538 | ... N36: =IFERROR(+N105/(N121+N122),"") | O36: =IFERROR(+AVERAGE(D36:N36),"") -> -0.079169668
B38: Solvency | D38: =+D29 -> INTERNATIONAL | E38: =+E29 -> ACCENTURE | F38: =+F29 -> Capgemini | G38: =+G29 -> MICROSOFT | H38: =+H29 -> ORACLE | I38: =+I29 -> HEWLETT | J38: =+J29 -> IONQ | K38: =+K29 -> Rigetti | ... O38: =+O29 -> Average
B40: Debt/Assets | D40: =IFERROR(D121/D117,"") -> 0.64132343 | E40: =IFERROR(E121/E117,"") -> 0.073669286 | F40: =IFERROR(F121/F117,"") -> 0.23682775 | G40: =IFERROR(G121/G117,"") -> 0.19105636 | H40: =IFERROR(H121/H117,"") -> 0.67010697 | I40: =IFERROR(I121/I117,"") -> 0.27807246 | J40: =IFERROR(J121/J117,"") -> 0.034865103 | K40: =IFERROR(K121/K117,"") -> 0.030900287 | ... N40: =IFERROR(N121/N117,"") | O40: =IFERROR(+AVERAGE(D40:N40),"") -> 0.26960271
B41: Net Debt/EBITDA | D41: =IFERROR(+(D121-D111)/D100,"") -> 5.2695431 | E41: =IFERROR(+(E121-E111)/E100,"") -> -0.068510668 | F41: =IFERROR(+(F121-F111)/F100,"") -> 1.0182719 | G41: =IFERROR(+(G121-G111)/G100,"") -> 0.58796526 | H41: =IFERROR(+(H121-H111)/H100,"") -> 3.6196744 | I41: =IFERROR(+(I121-I111)/I100,"") -> 0.93986384 | J41: =IFERROR(+(J121-J111)/J100,"") -> 0.17150528 | K41: =IFERROR(+(K121-K111)/K100,"") -> 0.859349 | ... N41: =IFERROR(+(N121-N111)/N100,"") | O41: =IFERROR(+AVERAGE(D41:N41),"") -> 1.5497078
B42: Interest Coverage Ratio | D42: =IFERROR(D101/D102,"") -> 5.4795561 | E42: =IFERROR(E101/E102,"") -> -47.043132 | F42: =IFERROR(F101/F102,"") -> -94.296296 | G42: =IFERROR(G101/G102,"") -> 37.28552 | H42: =IFERROR(H101/H102,"") -> 5.2468168 | I42: =IFERROR(I101/I102,"") -> 21.290598 | J42: =IFERROR(J101/J102,"") -> 12.737958 | K42: =IFERROR(K101/K102,"") -> -40.589882 | ... N42: =IFERROR(N101/N102,"") | O42: =IFERROR(+AVERAGE(D42:N42),"") -> -12.486108
B44: Liquidity | D44: =+D29 -> INTERNATIONAL | E44: =+E29 -> ACCENTURE | F44: =+F29 -> Capgemini | G44: =+G29 -> MICROSOFT | H44: =+H29 -> ORACLE | I44: =+I29 -> HEWLETT | J44: =+J29 -> IONQ | K44: =+K29 -> Rigetti | ... O44: =+O29 -> Average
B46: Cash Ratio | D46: =IFERROR(D111/D119,"") -> 0.42082554 | E46: =IFERROR(E111/E119,"") -> 0.26372648 | F46: =IFERROR(F111/F119,"") -> 0.36178493 | G46: =IFERROR(G111/G119,"") -> 0.14618553 | H46: =IFERROR(H111/H119,"") -> 0.30956759 | I46: =IFERROR(I111/I119,"") -> 0.57159358 | J46: =IFERROR(J111/J119,"") -> 1.5073576 | K46: =IFERROR(K111/K119,"") -> 5.702705 | ... N46: =IFERROR(N111/N119,"") | O46: =IFERROR(+AVERAGE(D46:N46),"") -> 1.1604683
B47: Quick Ratio | D47: =IFERROR(+(D111+D112)/D119,"") -> 0.65469797 | E47: =IFERROR(+(E111+E112)/E119,"") -> 0.88942933 | F47: =IFERROR(+(F111+F112)/F119,"") -> 0.78181346 | G47: =IFERROR(+(G111+G112)/G119,"") -> 0.60053797 | H47: =IFERROR(+(H111+H112)/H119,"") -> 0.52878519 | I47: =IFERROR(+(I111+I112)/I119,"") -> 0.6961845 | J47: =IFERROR(+(J111+J112)/J119,"") -> 1.6879313 | K47: =IFERROR(+(K111+K112)/K119,"") -> 5.9072217 | ... N47: =IFERROR(+(N111+N112)/N119,"") | O47: =IFERROR(+AVERAGE(D47:N47),"") -> 1.4683252
B48: Current Ratio | D48: =IFERROR(D115/D119,"") -> 1.0404321 | E48: =IFERROR(E115/E119,"") -> 1.0991616 | F48: =IFERROR(F115/F119,"") -> 1.2074199 | G48: =IFERROR(G115/G119,"") -> 1.2749549 | H48: =IFERROR(H115/H119,"") -> 0.71500127 | I48: =IFERROR(I115/I119,"") -> 1.2881454 | J48: =IFERROR(J115/J119,"") -> 10.497492 | K48: =IFERROR(K115/K119,"") -> 17.422938 | ... N48: =IFERROR(N115/N119,"") | O48: =IFERROR(+AVERAGE(D48:N48),"") -> 4.3181931
B50: Activity | D50: =+D29 -> INTERNATIONAL | E50: =+E29 -> ACCENTURE | F50: =+F29 -> Capgemini | G50: =+G29 -> MICROSOFT | H50: =+H29 -> ORACLE | I50: =+I29 -> HEWLETT | J50: =+J29 -> IONQ | K50: =+K29 -> Rigetti | ... O50: =+O29 -> Average
B52: Inventory Turnover | D52: =IFERROR(D98/(AVERAGE(D113:D114)),"") -> 22.204898 | E52: =IFERROR(E98/(AVERAGE(E113:E114)),"0") -> 0 | F52: =IFERROR(F98/(AVERAGE(F113:F114)),"0") -> 0 | G52: =IFERROR(G98/(AVERAGE(G113:G114)),"") -> 39.569674 | H52: =IFERROR(H98/(AVERAGE(H113:H114)),"") -> 47.920886 | I52: =IFERROR(I98/(AVERAGE(I113:I114)),"") -> 3.1817669 | J52: =IFERROR(J98/(AVERAGE(J113:J114)),"0") -> 0 | K52: =IFERROR(K98/(AVERAGE(K113:K114)),"0") -> 0 | L52: =IFERROR(L98/(AVERAGE(L113:L114)),"") | M52: =IFERROR(M98/(AVERAGE(M113:M114)),"") | N52: =IFERROR(N98/(AVERAGE(N113:N114)),"") | O52: =IFERROR(+AVERAGE(D52:N52),"") -> 28.219306
B53: Acc. Receivable Turnover | D53: =IFERROR(D97/D112,"") -> 8.0961166 | E53: =IFERROR(E97/E112,"") -> 5.4657049 | F53: =IFERROR(F97/F112,"") -> 6.8239654 | G53: =IFERROR(G97/G112,"") -> 4.3061275 | H53: =IFERROR(H97/H112,"") -> 7.6588576 | I53: =IFERROR(I97/I112,"") -> 9.3099506 | J53: =IFERROR(J97/J112,"") -> 6.6103438 | K53: =IFERROR(K97/K112,"") -> 4.4458179 | ... N53: =IFERROR(N97/N112,"") | O53: =IFERROR(+AVERAGE(D53:N53),"") -> 6.5896105
B54: Payables Turnover | D54: =IFERROR(D98/D118,"") -> 6.7462798 | E54: =IFERROR(E98/E118,"") -> 15.939245 | F54: =IFERROR(F98/F118,"") -> 9.771011 | G54: =IFERROR(G98/G118,"") -> 3.3694308 | H54: =IFERROR(H98/H118,"") -> 6.4246924 | I54: =IFERROR(I98/I118,"") -> 1.7854302 | J54: =IFERROR(J98/J118,"") -> 3.9382409 | K54: =IFERROR(K98/K118,"") -> 3.2031447 | ... N54: =IFERROR(N98/N118,"") | O54: =IFERROR(+AVERAGE(D54:N54),"") -> 6.3971843
...

Sheet ESG
B2: Environmental, Social and Governance Analysis
B4: Author: | C4: João Garcia | E4: Highlights | N4: Recent News
E5: AI Ethics | G5: An AI Ethics board that oversees AI workflows assuring transparency and responsability
B6: Overview | D6: .
B7: Last Update | C7: 45772 | D7: . | E7: New social paradigm | G7: IBM had a good track record in terms of DEI policies for the beginning of the decade, but a change in its approach might happen to avoid jumping to the eye of the new administration
B8: Latest year with data | C8: 2023
