Workbook
Name COOLFUCNTION: _xlfn.LAMBDA(_xldudf_BOARDFLARE_EXEC("workbook-settings:coolfucntion"))
Name COOLFUCNTION: _xlfn.LAMBDA(_xldudf_BOARDFLARE_EXEC("workbook-settings:coolfucntion"))
Name COOLFUCNTION: _xlfn.LAMBDA(_xldudf_BOARDFLARE_EXEC("workbook-settings:coolfucntion"))
Name COOLFUCNTION: _xlfn.LAMBDA(_xldudf_BOARDFLARE_EXEC("workbook-settings:coolfucntion"))
Name COOLFUCNTION: _xlfn.LAMBDA(_xldudf_BOARDFLARE_EXEC("workbook-settings:coolfucntion"))
Name COOLFUCNTION: _xlfn.LAMBDA(_xldudf_BOARDFLARE_EXEC("workbook-settings:coolfucntion"))
Name COOLFUCNTION: _xlfn.LAMBDA(_xldudf_BOARDFLARE_EXEC("workbook-settings:coolfucntion"))
Name COOLFUCNTION: _xlfn.LAMBDA(_xldudf_BOARDFLARE_EXEC("workbook-settings:coolfucntion"))
Name COOLFUCNTION: _xlfn.LAMBDA(_xldudf_BOARDFLARE_EXEC("workbook-settings:coolfucntion"))
Name COOLFUCNTION: _xlfn.LAMBDA(_xldudf_BOARDFLARE_EXEC("workbook-settings:coolfucntion"))
Name Sectors: #REF!
Name Sectors: #REF!
Name Sectors: #REF!

Sheet Summary
E2: | EQUITY RESEARCH | U2: Lisbon Investment Society Equity Research
U3: April 18, 2025
D6: {=+_FV(DCF!R4,"Name")} -> INTEL CORPORATION | U6: Hold
D8: Intel is a leading American technology company known for designing and manufacturing semiconductor chips and processors that power computers, data centers, and AI systems. Its products include high-performance CPUs, GPUs, and system-on-chip solutions used by major tech firms, enterprises, and consumers worldwide. | U8: EXCHANGE:(TICKER)
U9: {=+"Price (7 Mar 25): $"&_FV(DCF!$R$4,"Price")} -> Price (7 Mar 25): $31,515
D10: Investment Thesis | U10: ="Price Target: $" & ROUND(IF(Summary!G25="FCFF",DCF!Q211,IF(Summary!G25="FCFE",DCF!Q254,IF(Summary!G25="Tax Shield",DCF!Q227,DCF!Q270))),2) &" "&IF(Summary!G25="FCFF","(FCFF)",IF(Summary!G25="FCFE","(FCFE)",IF(Summary!G25="Tax Shield","(APV)","(DDM)"))) -> Price Target: $6,33 (FCFF)
D11: We issue a HOLD recommendation on Intel Corporation. While our Free Cash Flow to the Firm (FCFF) valuation indicates a downside potential, we believe the company's strong market presence and ongoing strategic investments justify a neutral stance. Despite Intel’s efforts to optimize its manufacturing processes, we do not foresee a significant turnaround in performance over the next decade. Its entrenched position in the semiconductor ecosystem provides a degree of stability and long-term optionality. We acknowledge the continued uncertainty regarding Intel’s ability to achieve and sustain a gross margin of 50% or higher, which is critical to regaining investor confidence and driving valuation multiples. | U11: =+"Upside (Downside): "&ROUND((DCF!$Q$214*100),2)&"%" -> Upside (Downside): -79,9%
U14: =+Industry!E28&", "&ESG!C9 -> USA, Information Technology
U15: =+ESG!C10 -> Semiconductors & Semiconductor Equipment
D17: Operating Metrics | F17: 2023 | G17: =+F17+1 -> 2024 | H17: =+G17+1 -> 2025 | I17: =+H17+1 -> 2026 | K17: Valuation Multiples | N17: 2022 | O17: =+N17+1 -> 2023 | P17: =+O17+1 -> 2024 | Q17: =+P17+1 -> 2025 | R17: =+Q17+1 -> 2026 | U17: Mafalda Bento
D18: =DCF!B17 -> CCD | F18: =DCF!F17 -> 29258 | G18: =DCF!G17 -> 30290 | H18: =DCF!H17 -> 31804.5 | I18: =DCF!I17 -> 34030.815 | K18: EV / Sales | N18: =IFERROR(_xlfn.XLOOKUP($K18,Multiples!$B:$B,Multiples!N:N),"") -> 1.9543991 | O18: =IFERROR(_xlfn.XLOOKUP($K18,Multiples!$B:$B,Multiples!O:O),"") -> 4.375922 | P18: =IFERROR(_xlfn.XLOOKUP($K18,Multiples!$B:$B,Multiples!P:P),"") -> 2.1893373 | Q18: =IFERROR(_xlfn.XLOOKUP($K18,Multiples!$B:$B,Multiples!Q:Q),"") -> 0.030084902 | R18: =IFERROR(_xlfn.XLOOKUP($K18,Multiples!$B:$B,Multiples!R:R),"") -> 0.028802171 | U18: mafaldajbento@aln.iseg.ulisboa.pt
D19: =DCF!B20 -> DCAI | F19: =DCF!F20 -> 12635 | G19: =DCF!G20 -> 12817 | H19: =DCF!H20 -> 11535.3 | I19: =DCF!I20 -> 10958.535 | K19: Price / Sales | N19: =IFERROR(_xlfn.XLOOKUP($K19,Multiples!$B:$B,Multiples!N:N),"") -> 1.7075948 | O19: =IFERROR(_xlfn.XLOOKUP($K19,Multiples!$B:$B,Multiples!O:O),"") -> 3.8826344 | P19: =IFERROR(_xlfn.XLOOKUP($K19,Multiples!$B:$B,Multiples!P:P),"") -> 1.6160524 | Q19: =IFERROR(_xlfn.XLOOKUP($K19,Multiples!$B:$B,Multiples!Q:Q),"") -> 0 | R19: =IFERROR(_xlfn.XLOOKUP($K19,Multiples!$B:$B,Multiples!R:R),"") -> 0 | U19: (+351) 913 761 691
D20: =DCF!B23 -> NEX | F20: =DCF!F23 -> 5774 | G20: =DCF!G23 -> 5842 | H20: =DCF!H23 -> 5900.42 | I20: =DCF!I23 -> 6018.4284 | K20: EV / EBITDA | N20: =IFERROR(_xlfn.XLOOKUP($K20,Multiples!$B:$B,Multiples!N:N),"") -> 8.5524797 | O20: =IFERROR(_xlfn.XLOOKUP($K20,Multiples!$B:$B,Multiples!O:O),"") -> 25.031382 | P20: =IFERROR(_xlfn.XLOOKUP($K20,Multiples!$B:$B,Multiples!P:P),"") -> 19.522418 | Q20: =IFERROR(_xlfn.XLOOKUP($K20,Multiples!$B:$B,Multiples!Q:Q),"") -> -0.26114947 | R20: =IFERROR(_xlfn.XLOOKUP($K20,Multiples!$B:$B,Multiples!R:R),"") -> -0.90451115 | U20: Deolize Neto
D21: =DCF!B26 -> Intel Foundry | F21: =DCF!F26 -> 18910 | G21: =DCF!G26 -> 17543 | H21: =DCF!H26 -> 18069.29 | I21: =DCF!I26 -> 19334.14 | K21: EV / EBIT | N21: =IFERROR(_xlfn.XLOOKUP($K21,Multiples!$B:$B,Multiples!N:N),"") -> 89.688996 | O21: =IFERROR(_xlfn.XLOOKUP($K21,Multiples!$B:$B,Multiples!O:O),"") -> -1945.0615 | P21: =IFERROR(_xlfn.XLOOKUP($K21,Multiples!$B:$B,Multiples!P:P),"") -> -21.433628 | Q21: =IFERROR(_xlfn.XLOOKUP($K21,Multiples!$B:$B,Multiples!Q:Q),"") -> -0.26114947 | R21: =IFERROR(_xlfn.XLOOKUP($K21,Multiples!$B:$B,Multiples!R:R),"") -> -0.90451115 | U21: l62144@aln.iseg.ulisboa.pt
K22: Price / Earnings | N22: =IFERROR(_xlfn.XLOOKUP($K22,Multiples!$B:$B,Multiples!N:N),"") -> 38.412658 | O22: =IFERROR(_xlfn.XLOOKUP($K22,Multiples!$B:$B,Multiples!O:O),"") -> 110.98972 | P22: =IFERROR(_xlfn.XLOOKUP($K22,Multiples!$B:$B,Multiples!P:P),"") -> -6.6081934 | Q22: =IFERROR(_xlfn.XLOOKUP($K22,Multiples!$B:$B,Multiples!Q:Q),"") -> 0 | R22: =IFERROR(_xlfn.XLOOKUP($K22,Multiples!$B:$B,Multiples!R:R),"") -> 0 | U22: (+351) 939 196 808
K23: Price / Book | N23: =IFERROR(_xlfn.XLOOKUP($K23,Multiples!$B:$B,Multiples!N:N),"") -> 1.0424518 | O23: =IFERROR(_xlfn.XLOOKUP($K23,Multiples!$B:$B,Multiples!O:O),"") -> 1.9146774 | P23: =IFERROR(_xlfn.XLOOKUP($K23,Multiples!$B:$B,Multiples!P:P),"") -> 0.81702719 | Q23: =IFERROR(_xlfn.XLOOKUP($K23,Multiples!$B:$B,Multiples!Q:Q),"") -> 0 | R23: =IFERROR(_xlfn.XLOOKUP($K23,Multiples!$B:$B,Multiples!R:R),"") -> 0 | U23: Guilherme Tomás
U24: l63853@aln.iseg.ulisboa.pt
D25: Year | E25: Net Sales | F25: EBIT Margin | G25: FCFF | H25: =+IF(Summary!$G$25="FCFF",DCF!AB6,IF(Summary!$G$25="FCFE",DCF!AC6,DCF!AD6)) -> NOPAT | I25: Net Capex | K25: Profitability Ratios | N25: 2022 | O25: =+N25+1 -> 2023 | P25: =+O25+1 -> 2024 | Q25: =+P25+1 -> 2025 | R25: =+Q25+1 -> 2026 | U25: (+351) 911 188 108
D26: 2022 | E26: =+DCF!E32 -> 63054 | F26: =+DCF!E62 -> 0.021790846 | G26: =+INDEX(DCF!X7:AA7,MATCH(Summary!$G$25,{"FCFF","FCFE","Tax Shield","Total Payout"},0)) -> -10609.043 | H26: =+IF(Summary!$G$25="FCFF",DCF!AB7,IF(Summary!$G$25="FCFE",DCF!AC7,DCF!AD7)) -> 1507.9569 | I26: =+DCF!E136 -> -25050 | K26: Return on Assets | N26: =IFERROR(_xlfn.XLOOKUP($K26,Multiples!$B:$B,Multiples!N:N),"") -> 0.015392388 | O26: =IFERROR(_xlfn.XLOOKUP($K26,Multiples!$B:$B,Multiples!O:O),"") -> 0.0099022822 | P26: =IFERROR(_xlfn.XLOOKUP($K26,Multiples!$B:$B,Multiples!P:P),"") -> -0.066091559 | Q26: =IFERROR(_xlfn.XLOOKUP($K26,Multiples!$B:$B,Multiples!Q:Q),"") -> -0.056875013 | R26: =IFERROR(_xlfn.XLOOKUP($K26,Multiples!$B:$B,Multiples!R:R),"") -> -0.014451172 | U26: Maria Ferreira
D27: =+D26+1 -> 2023 | E27: =+DCF!F32 -> 54228 | F27: =+DCF!F62 -> -0.0022497603 | G27: =+INDEX(DCF!X8:AA8,MATCH(Summary!$G$25,{"FCFF","FCFE","Tax Shield","Total Payout"},0)) -> -15272.197 | H27: =+IF(Summary!$G$25="FCFF",DCF!AB8,IF(Summary!$G$25="FCFE",DCF!AC8,DCF!AD8)) -> -235.19715 | I27: =+DCF!F136 -> -25750 | K27: Return on Equity | N27: =IFERROR(_xlfn.XLOOKUP($K27,Multiples!$B:$B,Multiples!N:N),"") -> 0.027138238 | O27: =IFERROR(_xlfn.XLOOKUP($K27,Multiples!$B:$B,Multiples!O:O),"") -> 0.017250943 | P27: =IFERROR(_xlfn.XLOOKUP($K27,Multiples!$B:$B,Multiples!P:P),"") -> -0.12363851 | Q27: =IFERROR(_xlfn.XLOOKUP($K27,Multiples!$B:$B,Multiples!Q:Q),"") -> 3.587293e-15 | R27: =IFERROR(_xlfn.XLOOKUP($K27,Multiples!$B:$B,Multiples!R:R),"") -> 9.1148267e-16 | U27: l61624@aln.iseg.ulisboa.pt
D28: =+D27+1 -> 2024 | E28: =+DCF!G32 -> 53101 | F28: =+DCF!G62 -> -0.10214497 | G28: =+INDEX(DCF!X9:AA9,MATCH(Summary!$G$25,{"FCFF","FCFE","Tax Shield","Total Payout"},0)) -> -24467.235 | H28: =+IF(Summary!$G$25="FCFF",DCF!AB9,IF(Summary!$G$25="FCFE",DCF!AC9,DCF!AD9)) -> -14192.235 | I28: =+DCF!G136 -> -23944 | K28: Return on Total Capital | N28: =IFERROR(_xlfn.XLOOKUP($K28,Multiples!$B:$B,Multiples!N:N),"") -> 0.010376588 | O28: =IFERROR(_xlfn.XLOOKUP($K28,Multiples!$B:$B,Multiples!O:O),"") -> -0.0014945109 | P28: =IFERROR(_xlfn.XLOOKUP($K28,Multiples!$B:$B,Multiples!P:P),"") -> -0.093509002 | Q28: =IFERROR(_xlfn.XLOOKUP($K28,Multiples!$B:$B,Multiples!Q:Q),"") -> 2.1696913e-15 | R28: =IFERROR(_xlfn.XLOOKUP($K28,Multiples!$B:$B,Multiples!R:R),"") -> 6.2674025e-16 | U28: (+351) 967 081 495
D29: =+D28+1 -> 2025 | E29: =+DCF!H32 -> 67309.51 | F29: =+DCF!H62 -> -0.11520185 | G29: =+INDEX(DCF!X10:AA10,MATCH(Summary!$G$25,{"FCFF","FCFE","Tax Shield","Total Payout"},0)) -> 10069.536 | H29: =+IF(Summary!$G$25="FCFF",DCF!AB10,IF(Summary!$G$25="FCFE",DCF!AC10,DCF!AD10)) -> -7754.1799 | I29: =+DCF!H136 -> -3112.72 | K29: EBITDA Margin | N29: =IFERROR(_xlfn.XLOOKUP($K29,Multiples!$B:$B,Multiples!N:N),"") -> 0.22851841 | O29: =IFERROR(_xlfn.XLOOKUP($K29,Multiples!$B:$B,Multiples!O:O),"") -> 0.17481744 | P29: =IFERROR(_xlfn.XLOOKUP($K29,Multiples!$B:$B,Multiples!P:P),"") -> 0.11214478 | Q29: =IFERROR(_xlfn.XLOOKUP($K29,Multiples!$B:$B,Multiples!Q:Q),"") -> -0.11520185 | R29: =IFERROR(_xlfn.XLOOKUP($K29,Multiples!$B:$B,Multiples!R:R),"") -> -0.031842804
D30: =+D29+1 -> 2026 | E30: =+DCF!I32 -> 70341.919 | F30: =+DCF!I62 -> -0.031842804 | G30: =+INDEX(DCF!X11:AA11,MATCH(Summary!$G$25,{"FCFF","FCFE","Tax Shield","Total Payout"},0)) -> 6728.3739 | H30: =+IF(Summary!$G$25="FCFF",DCF!AB11,IF(Summary!$G$25="FCFE",DCF!AC11,DCF!AD11)) -> -2239.8839 | I30: =+DCF!I136 -> -3423.992 | K30: EBIT Margin | N30: =IFERROR(_xlfn.XLOOKUP($K30,Multiples!$B:$B,Multiples!N:N),"") -> 0.021790846 | O30: =IFERROR(_xlfn.XLOOKUP($K30,Multiples!$B:$B,Multiples!O:O),"") -> -0.0022497603 | P30: =IFERROR(_xlfn.XLOOKUP($K30,Multiples!$B:$B,Multiples!P:P),"") -> -0.10214497 | Q30: =IFERROR(_xlfn.XLOOKUP($K30,Multiples!$B:$B,Multiples!Q:Q),"") -> -0.11520185 | R30: =IFERROR(_xlfn.XLOOKUP($K30,Multiples!$B:$B,Multiples!R:R),"") -> -0.031842804 | U30: Statistics
D31: =+D30+1 -> 2027 | E31: =+DCF!J32 -> 73263.225 | F31: =+DCF!J62 -> -0.01347868 | G31: =+INDEX(DCF!X12:AA12,MATCH(Summary!$G$25,{"FCFF","FCFE","Tax Shield","Total Payout"},0)) -> 12111.315 | H31: =+IF(Summary!$G$25="FCFF",DCF!AB12,IF(Summary!$G$25="FCFE",DCF!AC12,DCF!AD12)) -> -2185.2784 | I31: =+DCF!J136 -> -3595.1916 | K31: Gross Profit Margin | N31: =IFERROR(_xlfn.XLOOKUP($K31,Multiples!$B:$B,Multiples!N:N),"") -> 0.42607923 | O31: =IFERROR(_xlfn.XLOOKUP($K31,Multiples!$B:$B,Multiples!O:O),"") -> 0.40036513 | P31: =IFERROR(_xlfn.XLOOKUP($K31,Multiples!$B:$B,Multiples!P:P),"") -> 0.32664168 | Q31: =IFERROR(_xlfn.XLOOKUP($K31,Multiples!$B:$B,Multiples!Q:Q),"") -> 0.35 | R31: =IFERROR(_xlfn.XLOOKUP($K31,Multiples!$B:$B,Multiples!R:R),"") -> 0.38 | U31: Beta | V31: =Peers!D74 -> 1.266
D32: =+D31+1 -> 2028 | E32: =+DCF!K32 -> 76429.421 | F32: =+DCF!K62 -> -0.053088308 | G32: =+INDEX(DCF!X13:AA13,MATCH(Summary!$G$25,{"FCFF","FCFE","Tax Shield","Total Payout"},0)) -> 6742.719 | H32: =+IF(Summary!$G$25="FCFF",DCF!AB13,IF(Summary!$G$25="FCFE",DCF!AC13,DCF!AD13)) -> -8433.2258 | I32: =+DCF!K136 -> -3774.9512 | K32: SG&A Margin | N32: =IFERROR(_xlfn.XLOOKUP($K32,Multiples!$B:$B,Multiples!N:N),"") -> 0.11104767 | O32: =IFERROR(_xlfn.XLOOKUP($K32,Multiples!$B:$B,Multiples!O:O),"") -> 0.10389467 | P32: =IFERROR(_xlfn.XLOOKUP($K32,Multiples!$B:$B,Multiples!P:P),"") -> 0.10370803 | Q32: =IFERROR(_xlfn.XLOOKUP($K32,Multiples!$B:$B,Multiples!Q:Q),"") -> 0.10621679 | R32: =IFERROR(_xlfn.XLOOKUP($K32,Multiples!$B:$B,Multiples!R:R),"") -> 0.10460649 | U32: % Float | V32: =+Peers!D73 -> 0.99082569
D33: =+D32+1 -> 2029 | E33: =+DCF!L32 -> 79853.274 | F33: =+DCF!L62 -> -0.052452368 | G33: =+INDEX(DCF!X14:AA14,MATCH(Summary!$G$25,{"FCFF","FCFE","Tax Shield","Total Payout"},0)) -> 4999.6844 | H33: =+IF(Summary!$G$25="FCFF",DCF!AB14,IF(Summary!$G$25="FCFE",DCF!AC14,DCF!AD14)) -> -8981.6159 | I33: =+DCF!L136 -> -3963.6987 | K33: Net Income Margin | N33: =IFERROR(_xlfn.XLOOKUP($K33,Multiples!$B:$B,Multiples!N:N),"") -> 0.04445396 | O33: =IFERROR(_xlfn.XLOOKUP($K33,Multiples!$B:$B,Multiples!O:O),"") -> 0.034981928 | P33: =IFERROR(_xlfn.XLOOKUP($K33,Multiples!$B:$B,Multiples!P:P),"") -> -0.24455283 | Q33: =IFERROR(_xlfn.XLOOKUP($K33,Multiples!$B:$B,Multiples!Q:Q),"") -> -0.19047077 | R33: =IFERROR(_xlfn.XLOOKUP($K33,Multiples!$B:$B,Multiples!R:R),"") -> -0.046309718 | U33: % Held by Insiders | V33: =+Peers!D76 -> 0.0008
U34: % Held by Institutions | V34: =+Peers!D77 -> 0.6606
D35: SWOT Analysis | K35: Liquidity Ratios | N35: 2022 | O35: =+N35+1 -> 2023 | P35: =+O35+1 -> 2024 | Q35: =+P35+1 -> 2025 | R35: =+Q35+1 -> 2026 | U35: Short % of Float | V35: =+Peers!D78 -> 0.0261
D36: Strengths | G36: Weaknesses | K36: Cash Ratio | N36: =IFERROR(_xlfn.XLOOKUP($K36,Multiples!$B:$B,Multiples!N:N),"") -> 0.3465713 | O36: =IFERROR(_xlfn.XLOOKUP($K36,Multiples!$B:$B,Multiples!O:O),"") -> 0.25234378 | P36: =IFERROR(_xlfn.XLOOKUP($K36,Multiples!$B:$B,Multiples!P:P),"") -> 0.2312847 | Q36: =IFERROR(_xlfn.XLOOKUP($K36,Multiples!$B:$B,Multiples!Q:Q),"") -> 1.0419216 | R36: =IFERROR(_xlfn.XLOOKUP($K36,Multiples!$B:$B,Multiples!R:R),"") -> 1.6221183 | W36: 120.87
D37: Economies of scale; Strong recognition; Government Support; Advanced Manufacturing Capabilities | G37: A bad past scenario compared to the growth of the sector; Dependence on one market (not diverse); High capital intensity needed; | K37: Quick Ratio | N37: =IFERROR(_xlfn.XLOOKUP($K37,Multiples!$B:$B,Multiples!N:N),"") -> 1.0098274 | O37: =IFERROR(_xlfn.XLOOKUP($K37,Multiples!$B:$B,Multiples!O:O),"") -> 1.0136527 | P37: =IFERROR(_xlfn.XLOOKUP($K37,Multiples!$B:$B,Multiples!P:P),"") -> 0.71608815 | Q37: =IFERROR(_xlfn.XLOOKUP($K37,Multiples!$B:$B,Multiples!Q:Q),"") -> 1.4841004 | R37: =IFERROR(_xlfn.XLOOKUP($K37,Multiples!$B:$B,Multiples!R:R),"") -> 2.0674539 | U37: Major Holders | W37: 113.63
K38: Current Ratio | N38: =IFERROR(_xlfn.XLOOKUP($K38,Multiples!$B:$B,Multiples!N:N),"") -> 1.5676256 | O38: =IFERROR(_xlfn.XLOOKUP($K38,Multiples!$B:$B,Multiples!O:O),"") -> 1.5424019 | P38: =IFERROR(_xlfn.XLOOKUP($K38,Multiples!$B:$B,Multiples!P:P),"") -> 1.3268659 | Q38: =IFERROR(_xlfn.XLOOKUP($K38,Multiples!$B:$B,Multiples!Q:Q),"") -> 2.0178625 | R38: =IFERROR(_xlfn.XLOOKUP($K38,Multiples!$B:$B,Multiples!R:R),"") -> 2.0178625 | U38: Blackrock Inc. | V38: 0.0891
U39: Vanguard Group Inc | V39: 0.0846
D40: Opportunities | G40: Threats | K40: Cash Flow Ratios | N40: 2022 | O40: =+N40+1 -> 2023 | P40: =+O40+1 -> 2024 | Q40: =+P40+1 -> 2025 | R40: =+Q40+1 -> 2026 | U40: State Street Corporation | V40: 0.0457
D41: The era of technology; Custom chips and emerging markets(drones, automatic cars...); | G41: Intensifying Competition and Chinese products; The level of the product's prices which can benefit competitors with lower prices. | K41: Cash Conversion Cycle | N41: =IFERROR(_xlfn.XLOOKUP($K41,Multiples!$B:$B,Multiples!N:N),"") -> 101.76231 | O41: =IFERROR(_xlfn.XLOOKUP($K41,Multiples!$B:$B,Multiples!O:O),"") -> 90.060609 | P41: =IFERROR(_xlfn.XLOOKUP($K41,Multiples!$B:$B,Multiples!P:P),"") -> 62.118733 | Q41: =IFERROR(_xlfn.XLOOKUP($K41,Multiples!$B:$B,Multiples!Q:Q),"") -> 19.966555 | R41: =IFERROR(_xlfn.XLOOKUP($K41,Multiples!$B:$B,Multiples!R:R),"") -> 30.481231 | U41: Morgan Stanley | V41: 0.0242
K42: Net Income / Op Cash Flow | N42: =IFERROR(_xlfn.XLOOKUP($K42,Multiples!$B:$B,Multiples!N:N),"") -> 0.18162379 | O42: =IFERROR(_xlfn.XLOOKUP($K42,Multiples!$B:$B,Multiples!O:O),"") -> 0.16537355 | P42: =IFERROR(_xlfn.XLOOKUP($K42,Multiples!$B:$B,Multiples!P:P),"") -> -1.5668436 | Q42: =IFERROR(_xlfn.XLOOKUP($K42,Multiples!$B:$B,Multiples!Q:Q),"") -> -1.1959458 | R42: =IFERROR(_xlfn.XLOOKUP($K42,Multiples!$B:$B,Multiples!R:R),"") -> -0.26496173 | U42: Geode Capital Management, LLC | V42: 0.0219
K43: Chg in Cash / Op Cash Flow | N43: =IFERROR(_xlfn.XLOOKUP($K43,Multiples!$B:$B,Multiples!N:N),"") -> 0.4093177 | O43: =IFERROR(_xlfn.XLOOKUP($K43,Multiples!$B:$B,Multiples!O:O),"") -> -0.35437189 | P43: =IFERROR(_xlfn.XLOOKUP($K43,Multiples!$B:$B,Multiples!P:P),"") -> 0.14116795 | Q43: =IFERROR(_xlfn.XLOOKUP($K43,Multiples!$B:$B,Multiples!Q:Q),"") -> 3.2384187 | R43: =IFERROR(_xlfn.XLOOKUP($K43,Multiples!$B:$B,Multiples!R:R),"") -> 1.9460278 | U43: Primecap Management Company | V43: 0.0177
U44: UBS AM | V44: 0.0145
D45: Revenue by Region | G45: Revenue by Segment | K45: Leverage Ratios | N45: 2022 | O45: =+N45+1 -> 2023 | P45: =+O45+1 -> 2024 | Q45: =+P45+1 -> 2025 | R45: =+Q45+1 -> 2026 | U45: NORGES BANK | V45: 0.0143
K46: Total Debt / Equity | N46: =IFERROR(_xlfn.XLOOKUP($K46,Multiples!$B:$B,Multiples!N:N),"") -> 406.99611 | O46: =IFERROR(_xlfn.XLOOKUP($K46,Multiples!$B:$B,Multiples!O:O),"") -> 431.12809 | P46: =IFERROR(_xlfn.XLOOKUP($K46,Multiples!$B:$B,Multiples!P:P),"") -> 445.02628 | Q46: =IFERROR(_xlfn.XLOOKUP($K46,Multiples!$B:$B,Multiples!Q:Q),"") -> -1.3078844e-14 | R46: =IFERROR(_xlfn.XLOOKUP($K46,Multiples!$B:$B,Multiples!R:R),"") -> -1.8149291e-14 | U46: Northern Trust Corporation | V46: 0.0105
K47: Total Debt / Capital | N47: =IFERROR(_xlfn.XLOOKUP($K47,Multiples!$B:$B,Multiples!N:N),"") -> 0.997549 | O47: =IFERROR(_xlfn.XLOOKUP($K47,Multiples!$B:$B,Multiples!O:O),"") -> 0.99768587 | P47: =IFERROR(_xlfn.XLOOKUP($K47,Multiples!$B:$B,Multiples!P:P),"") -> 0.99775798 | Q47: =IFERROR(_xlfn.XLOOKUP($K47,Multiples!$B:$B,Multiples!Q:Q),"") -> -1.3078844e-14 | R47: =IFERROR(_xlfn.XLOOKUP($K47,Multiples!$B:$B,Multiples!R:R),"") -> -1.8149291e-14 | U47: Invesco Ltd. | V47: 0.0099
...

Sheet Segments
B2: Segments
B4: Regions | D4: Weight | E4: 2020 | F4: =+E4+1 -> 2021 | G4: =+F4+1 -> 2022 | H4: =+G4+1 -> 2023 | I4: =+H4+1 -> 2024 | J4: ="CAGR "&$G$4&" - "&$I$4 -> CAGR 2022 - 2024 | K4: 2021 | L4: =+K4+1 -> 2022 | M4: =+L4+1 -> 2023 | N4: =+M4+1 -> 2024
B6: China | D6: =IFERROR(I6/SUM($I$6:$I$10),"") -> 0.2924992 | E6: 20257 | F6: 22961 | G6: 17125 | H6: 14854 | I6: 15532 | J6: =IFERROR((I6/G6)^(1/COUNT($G$4:$I$4))-1,"") -> -0.032021747 | K6: =IFERROR((F6-E6)/E6,"") -> 0.13348472 | L6: =IFERROR((G6-F6)/F6,"") -> -0.25417011 | M6: =IFERROR((H6-G6)/G6,"") -> -0.13261314 | N6: =IFERROR((I6-H6)/H6,"") -> 0.045644271
B7: United States | D7: =IFERROR(I7/SUM($I$6:$I$10),"") -> 0.24470349 | E7: 17845 | F7: 18096 | G7: 16529 | H7: 13958 | I7: 12994 | J7: =IFERROR((I7/G7)^(1/COUNT($G$4:$I$4))-1,"") -> -0.077077088 | K7: =IFERROR((F7-E7)/E7,"") -> 0.014065565 | L7: =IFERROR((G7-F7)/F7,"") -> -0.086593722 | M7: =IFERROR((H7-G7)/G7,"") -> -0.1555448 | N7: =IFERROR((I7-H7)/H7,"") -> -0.069064336
B8: Singapore | D8: =IFERROR(I8/SUM($I$6:$I$10),"") -> 0.19184196 | E8: 16573 | F8: 14322 | G8: 9664 | H8: 8602 | I8: 10187 | J8: =IFERROR((I8/E8)^(1/COUNT($E$4:$I$4))-1,"") -> -0.0927457 | K8: =IFERROR((F8-E8)/E8,"") -> -0.13582333 | L8: =IFERROR((G8-F8)/F8,"") -> -0.32523391 | M8: =IFERROR((H8-G8)/G8,"") -> -0.10989238 | N8: =IFERROR((I8-H8)/H8,"") -> 0.18425947
B9: Taiwan | D9: =IFERROR(I9/SUM($I$6:$I$10),"") -> 0.14696522 | E9: 11605 | F9: 11418 | G9: 8287 | H9: 6867 | I9: 7804 | J9: =IFERROR((I9/E9)^(1/COUNT($E$4:$I$4))-1,"") -> -0.076292599 | K9: =IFERROR((F9-E9)/E9,"") -> -0.016113744 | L9: =IFERROR((G9-F9)/F9,"") -> -0.27421615 | M9: =IFERROR((H9-G9)/G9,"") -> -0.17135272 | N9: =IFERROR((I9-H9)/H9,"") -> 0.13644969
B10: Other Regions | D10: =IFERROR(I10/SUM($I$6:$I$10),"") -> 0.12399013 | E10: 11587 | F10: 12227 | G10: 11449 | H10: 9947 | I10: 6584 | J10: =IFERROR((I10/E10)^(1/COUNT($E$4:$I$4))-1,"") -> -0.10689245 | K10: =IFERROR((F10-E10)/E10,"") -> 0.055234314 | L10: =IFERROR((G10-F10)/F10,"") -> -0.063629672 | M10: =IFERROR((H10-G10)/G10,"") -> -0.1311905 | N10: =IFERROR((I10-H10)/H10,"") -> -0.33809189
B11: Total | D11: =SUM(D6:D10) -> 1 | E11: =SUM(E6:E10) -> 77867 | F11: =SUM(F6:F10) -> 79024 | G11: =SUM(G6:G10) -> 63054 | H11: =SUM(H6:H10) -> 54228 | I11: =SUM(I6:I10) -> 53101 | J11: =IFERROR((I11/G11)^(1/COUNT($G$4:$I$4))-1,"") -> -0.055656448 | K11: =IFERROR(F11-E11/E11,"") -> 79023 | L11: =IFERROR(G11-F11/F11,"") -> 63053 | M11: =IFERROR((H11-G11)/G11,"") -> -0.13997526 | N11: =IFERROR((I11-H11)/H11,"") -> -0.020782622
B13: Segments | D13: Weight | E13: 2020 | F13: =+E13+1 -> 2021 | G13: =+F13+1 -> 2022 | H13: =+G13+1 -> 2023 | I13: =+H13+1 -> 2024 | J13: ="CAGR "&$E$4&" - "&$I$4 -> CAGR 2020 - 2024 | K13: 2021 | L13: =+K13+1 -> 2022 | M13: =+L13+1 -> 2023 | N13: =+M13+1 -> 2024
B15: CCG | D15: =IFERROR(I15/I22,"") -> 0.5704224 | E15: 40535 | F15: 41067 | G15: 31773 | H15: 29258 | I15: 30290 | J15: =IFERROR((I15/E15)^(1/COUNT($E$4:$I$4))-1,"") -> -0.056604459 | K15: =IFERROR((F15-E15)/E15,"") -> 0.01312446 | L15: =IFERROR((G15-F15)/F15,"") -> -0.2263131 | M15: =IFERROR((H15-G15)/G15,"") -> -0.079155258 | N15: =IFERROR((I15-H15)/H15,"") -> 0.035272404
B16: DCAI | D16: =IFERROR(I16/I22,"") -> 0.24137022 | E16: 23413 | F16: 22691 | G16: 16856 | H16: 12635 | I16: 12817 | J16: =IFERROR((I16/E16)^(1/COUNT($E$4:$I$4))-1,"") -> -0.11352628 | K16: =IFERROR((F16-E16)/E16,"") -> -0.030837569 | L16: =IFERROR((G16-F16)/F16,"") -> -0.25715041 | M16: =IFERROR((H16-G16)/G16,"") -> -0.25041528 | N16: =IFERROR((I16-H16)/H16,"") -> 0.014404432
B17: NEX | D17: =IFERROR(I17/SUM($I$15:$I$21),"") -> 0.11001676 | E17: 7132 | F17: 7976 | G17: 8409 | H17: 5774 | I17: 5842 | J17: =IFERROR((I17/E17)^(1/COUNT($E$4:$I$4))-1,"") -> -0.039118032 | K17: =IFERROR((F17-E17)/E17,"") -> 0.11833988 | L17: =IFERROR((G17-F17)/F17,"") -> 0.054287864 | M17: =IFERROR((H17-G17)/G17,"") -> -0.31335474 | N17: =IFERROR((I17-H17)/H17,"") -> 0.011776931
B18: Intel Foundry | D18: =IFERROR(I18/SUM($I$15:$I$21),"") -> 0.33037043 | E18: 715 | F18: 786 | G18: 27491 | H18: 18910 | I18: 17543 | J18: =IFERROR((I18/E18)^(1/COUNT($E$4:$I$4))-1,"") -> 0.89652933 | K18: =IFERROR((F18-E18)/E18,"") -> 0.099300699 | L18: =IFERROR((G18-F18)/F18,"") -> 33.975827 | M18: =IFERROR((H18-G18)/G18,"") -> -0.31213852 | N18: =IFERROR((I18-H18)/H18,"") -> -0.072289794
B19: All Other | D19: =IFERROR(I19/SUM($I$15:$I$21),"") -> 0.07201371 | E19: 6709 | F19: 7179 | G19: 5530 | H19: 5608 | I19: 3824 | J19: =IFERROR((I19/E19)^(1/COUNT($E$4:$I$4))-1,"") -> -0.10634062 | K19: =IFERROR((F19-E19)/E19,"") -> 0.07005515 | L19: =IFERROR((G19-F19)/F19,"") -> -0.22969773 | M19: =IFERROR((H19-G19)/G19,"") -> 0.014104882 | N19: =IFERROR((I19-H19)/H19,"") -> -0.31811698
B20: Corporate Unallocated | E20: 0 | F20: 0 | G20: 0 | H20: 0 | I20: 0 | J20: =IFERROR((I20/E20)^(1/COUNT($E$4:$I$4))-1,"") | K20: =IFERROR((F20-E20)/E20,"") | L20: =IFERROR((G20-F20)/F20,"") | M20: =IFERROR((H20-G20)/G20,"") | N20: =IFERROR((I20-H20)/H20,"")
B21: Intersegment Eliminations | D21: =IFERROR(I21/SUM($I$15:$I$21),"") -> -0.32419352 | E21: -637 | F21: -675 | G21: -27005 | H21: -17957 | I21: -17215 | J21: =IFERROR((I21/E21)^(1/COUNT($E$4:$I$4))-1,"") -> 0.93354159 | K21: =IFERROR((F21-E21)/E21,"") -> 0.059654631 | L21: =IFERROR((G21-F21)/F21,"") -> 39.007407 | M21: =IFERROR((H21-G21)/G21,"") -> -0.33504906 | N21: =IFERROR((I21-H21)/H21,"") -> -0.041320933
B22: Total | D22: =SUM(D15:D21) -> 1 | E22: =SUM(E15:E21) -> 77867 | F22: =SUM(F15:F21) -> 79024 | G22: =SUM(G15:G21) -> 63054 | H22: =SUM(H15:H21) -> 54228 | I22: =SUM(I15:I21) -> 53101 | J22: =IFERROR((I22/E22)^(1/COUNT($E$4:$I$4))-1,"") -> -0.073703866 | K22: =IFERROR((F22-E22)/E22,"") -> 0.014858669 | L22: =IFERROR((G22-F22)/F22,"") -> -0.2020905 | M22: =IFERROR((H22-G22)/G22,"") -> -0.13997526 | N22: =IFERROR((I22-H22)/H22,"") -> -0.020782622
B24: Categories | D24: Description | J24: Graphs
B26: CCG | D26: Focuses on processors, chipsets, and other components for consumer and business PCs — laptops, desktops, and tablets. Core products include Intel® Core™ processors (i3, i5, i7, i9).
B27: DCAI | D27: Serves enterprise, cloud, and government markets with high-performance computing and AI solutions. Includes Intel® Xeon® CPUs and AI accelerators (e.g., Habana® Gaudi®).
B28: NEX | D28: Provides infrastructure for 5G networks, edge computing, and IoT. Supports telco and industrial customers with networking silicon and edge hardware/software.
B29: Intel Foundry | D29: Intel's internal and external wafer fabrication business. Manufactures chips for Intel and third-party customers under the IDM 2.0 strategy. Includes Intel Foundry Services (IFS).
B30: All Other | D30: Includes smaller businesses like Mobileye (autonomous driving), Altera (FPGAs), and early-stage ventures.
B31: Corporate Unallocated | D31: Overhead costs, R&D not tied to specific segments, and restructuring charges.
B32: Intersegment Eliminations | D32: Internal sales between Intel segments (e.g., Foundry services provided to CCG or DCAI).
B33: =IF(B18=0,"",B18) -> Intel Foundry
B34: =IF(B19=0,"",B19) -> All Other
B36: Products | D36: Weight | E36: 2020 | F36: =+E36+1 -> 2021 | G36: =+F36+1 -> 2022 | H36: =+G36+1 -> 2023 | I36: =+H36+1 -> 2024 | J36: =I36+1 -> 2025 | K36: =+J36+1 -> 2026 | L36: =+K36+1 -> 2027 | M36: =+L36+1 -> 2028 | N36: =+M36+1 -> 2029 | O36: =+N36+1 -> 2030 | P36: =+O36+1 -> 2031 | Q36: =+P36+1 -> 2032 | R36: =+Q36+1 -> 2033 | S36: =+R36+1 -> 2034
B38: =B15 -> CCG | D38: =IFERROR(I38/$I$11,"") -> 0.5704224 | E38: =E15 -> 40535 | F38: =F15 -> 41067 | G38: =G15 -> 31773 | H38: =H15 -> 29258 | I38: =I15 -> 30290 | J38: =DCF!H17 -> 31804.5 | K38: =DCF!I17 -> 34030.815 | L38: =DCF!J17 -> 36412.972 | M38: =DCF!K17 -> 38961.88 | N38: =DCF!L17 -> 41689.212 | O38: =DCF!M17 -> 44607.457 | P38: =DCF!N17 -> 46391.755 | Q38: =DCF!O17 -> 48247.425 | ... S38: =DCF!Q17 -> 52184.415
B39: =B16 -> DCAI | D39: =IFERROR(I39/$I$11,"") -> 0.24137022 | E39: =E16 -> 23413 | F39: =F16 -> 22691 | G39: =G16 -> 16856 | H39: =H16 -> 12635 | I39: =I16 -> 12817 | J39: =DCF!H20 -> 11535.3 | K39: =DCF!I20 -> 10958.535 | L39: =DCF!J20 -> 10410.608 | M39: =DCF!K20 -> 9890.0778 | N39: =DCF!L20 -> 9395.5739 | O39: =DCF!M20 -> 9583.4854 | P39: =DCF!N20 -> 9775.1551 | Q39: =DCF!O20 -> 9970.6582 | ... S39: =DCF!Q20 -> 10373.473
B41: NEX | D41: =IFERROR(I41/$I$11,"") -> 0.11001676 | E41: =E17 -> 7132 | F41: =F17 -> 7976 | G41: =G17 -> 8409 | H41: =H17 -> 5774 | I41: =I17 -> 5842 | J41: =DCF!H23 -> 5900.42 | K41: =DCF!I23 -> 6018.4284 | L41: =DCF!J23 -> 6138.797 | M41: =DCF!K23 -> 6261.5729 | N41: =DCF!L23 -> 6386.8044 | O41: =DCF!M23 -> 6514.5405 | P41: =DCF!N23 -> 6644.8313 | Q41: =DCF!O23 -> 6777.7279 | ... S41: =DCF!Q23 -> 7051.5481
F45: =IFERROR((F41-E41)/E41,"") -> 0.11833988 | G45: =IFERROR((G41-F41)/F41,"") -> 0.054287864 | H45: =IFERROR((H41-G41)/G41,"") -> -0.31335474 | I45: =IFERROR((I41-H41)/H41,"") -> 0.011776931
B46: Product 3 | D46: =IFERROR(I46/$I$11,"") -> 0 | J46: =I46*(1+J47) -> 0 | K46: =J46*(1+K47) -> 0 | L46: =K46*(1+L47) -> 0 | M46: =L46*(1+M47) -> 0 | N46: =M46*(1+N47) -> 0 | O46: =N46*(1+O47) -> 0 | P46: =O46*(1+P47) -> 0 | Q46: =P46*(1+Q47) -> 0 | ... S46: =R46*(1+S47) -> 0
F47: =IFERROR(F46-E46/E46,"") | G47: =IFERROR(G46-F46/F46,"") | H47: =IFERROR(H46-G46/G46,"") | I47: =IFERROR(I46-H46/H46,"")
B48: Product 4 | D48: =IFERROR(I48/$I$11,"") -> 0 | J48: =I48*(1+J49) -> 0 | K48: =J48*(1+K49) -> 0 | L48: =K48*(1+L49) -> 0 | M48: =L48*(1+M49) -> 0 | N48: =M48*(1+N49) -> 0 | O48: =N48*(1+O49) -> 0 | P48: =O48*(1+P49) -> 0 | Q48: =P48*(1+Q49) -> 0 | ... S48: =R48*(1+S49) -> 0
F49: =IFERROR(F48-E48/E48,"") | G49: =IFERROR(G48-F48/F48,"") | H49: =IFERROR(H48-G48/G48,"") | I49: =IFERROR(I48-H48/H48,"")
B50: Product 5 | D50: =IFERROR(I50/$I$11,"") -> 0 | J50: =I50*(1+J51) -> 0 | K50: =J50*(1+K51) -> 0 | L50: =K50*(1+L51) -> 0 | M50: =L50*(1+M51) -> 0 | N50: =M50*(1+N51) -> 0 | O50: =N50*(1+O51) -> 0 | P50: =O50*(1+P51) -> 0 | Q50: =P50*(1+Q51) -> 0 | ... S50: =R50*(1+S51) -> 0
F51: =IFERROR(F50-E50/E50,"") | G51: =IFERROR(G50-F50/F50,"") | H51: =IFERROR(H50-G50/G50,"") | I51: =IFERROR(I50-H50/H50,"")
B52: Total | D52: =SUM(D38:D50) -> 0.92180938 | E52: =SUM(E38:E50) -> 71080 | F52: =SUM(F38:F50) -> 71734.118 | G52: =SUM(G38:G50) -> 57038.054 | H52: =SUM(H38:H50) -> 47666.687 | I52: =SUM(I38:I50) -> 48949.012 | J52: =SUM(J38:J50) -> 49240.22 | K52: =SUM(K38:K50) -> 51007.778 | ... S52: =SUM(S38:S50) -> 69609.436
B54: Company's Strategy / Extra Notes
...

Sheet Industry
B2: Industry Overview
B4: Sales Growth Forecast | E4: Weight | F4: 2025 | G4: =+F4+1 -> 2026 | H4: =+G4+1 -> 2027 | I4: =+H4+1 -> 2028 | J4: =+I4+1 -> 2029 | K4: =+J4+1 -> 2030 | L4: =+K4+1 -> 2031 | M4: =+L4+1 -> 2032 | N4: =+M4+1 -> 2033 | ... P4: =+O4+1 -> 2035 | Q4: ="CAGR "&$F$4&" - "&$P$4 -> CAGR 2025 - 2035 | R4: Sources
B6: =Segments!B15 -> CCG | Q6: 0.045 | R6: Market Research Future | S6: https://www.marketresearchfuture.com/reports/client-computing-market-16110
B7: =Segments!B16 -> DCAI | Q7: 0.14 | R7: edge ai + vision | S7: https://www.edge-ai-vision.com/2025/04/ai-chips-for-data-centers-and-cloud-2025-2035-technologies-market-forecasts/
B8: =Segments!B17 -> NEX | Q8: 0.2363 | R8: =R6 -> Market Research Future | S8: https://www.marketresearchfuture.com/reports/us-intelligent-network-market-15455
B11: Weighted Average | E11: =SUM(E6:E10) -> 0 | F11: =SUMPRODUCT(F6:F10,$E$6:$E$10) -> 0 | G11: =SUMPRODUCT(G6:G10,$E$6:$E$10) -> 0 | H11: =SUMPRODUCT(H6:H10,$E$6:$E$10) -> 0 | I11: =SUMPRODUCT(I6:I10,$E$6:$E$10) -> 0 | J11: =SUMPRODUCT(J6:J10,$E$6:$E$10) -> 0 | K11: =SUMPRODUCT(K6:K10,$E$6:$E$10) -> 0 | L11: =SUMPRODUCT(L6:L10,$E$6:$E$10) -> 0 | M11: =SUMPRODUCT(M6:M10,$E$6:$E$10) -> 0 | ... P11: =SUMPRODUCT(P6:P10,$E$6:$E$10) -> 0 | Q11: =IFERROR(((1+F11)*(1+G11)*(1+H11)*(1+I11)*(1+J11)*(1+K11)*(1+L11)*(1+M11)*(1+N11)*(1+O11)*(1+P11))^(1/COUNT($F$4:$P$4))-1,"") -> 0
B13: Key Drivers | E13: Description
B15: Artificial Intelligence (AI) | E15: AI is rapidly reshaping the semiconductor landscape. From cloud-based training of large models to real-time inference in AI PCs and edge devices, demand is growing for chips optimized for AI workloads. This includes GPUs, NPUs, and accelerators, all driving innovation and investment across the industry.
B16: Cloud & Edge Computing | E16: As data volumes grow, processing is shifting to both large-scale cloud data centers and local edge environments. The cloud demands high-performance chips, while edge computing requires low-power, real-time processors. This dual trend is broadening the types of chips needed and driving architectural diversity.
B17: Advanced Manufacturing Technology | E17: With traditional scaling slowing, progress now depends on innovations in process nodes and packaging. Technologies like 3nm chips, chiplets, and 3D stacking are enabling better performance and power efficiency, helping the industry continue to advance despite physical limitations.
B18: Supply Chain & Geopolitical Realignment | E18: Semiconductors are now seen as strategic assets. Trade tensions and supply disruptions have led governments to invest in domestic production. Initiatives like the CHIPS Act are pushing for localized, secure, and diversified supply chains, reshaping global manufacturing dynamics.
B20: Industry Trends | E20: Description
B22: AI Integration Across Devices | E22: AI is rapidly expanding beyond cloud infrastructure into everyday hardware. This trend is evident in the rise of AI PCs, smartphones with on-device inference, and AI-enabled edge systems. Consumers and enterprises alike are expecting smarter, faster, and more context-aware devices. As a result, chipmakers are embedding AI accelerators into CPUs and SoCs, making AI a core feature rather than an add-on.
B23: Custom and Domain-Specific Chip Design | E23: There’s growing demand for chips optimized for specific tasks—like AI training, 5G networking, or autonomous driving. Major tech companies are increasingly designing custom silicon to gain performance advantages and efficiency. This trend is reshaping the competitive landscape, as traditional chipmakers now compete not only with each other but also with their largest customers.
B26: Market Share | E26: Headquarters | G26: Revenues | H26: (in MM of USD) | I26: Market Share
B28: {=+_FV(DCF!R4,"Name")} -> INTEL CORPORATION | E28: USA | G28: {=TRANSPOSE(Peers!D97:N97)} -> 53101 | I28: =IFERROR(G28/$G$40,"") -> 0.084708153
B29: {=+_FV(Peers!A8,"Name")} -> NVIDIA CORPORATION | E29: USA | G29: 130497 | I29: =IFERROR(G29/$G$40,"") -> 0.20817235
B30: {=+_FV(Peers!A9,"Name")} -> ADVANCED MICRO DEVICES, INC. | E30: USA | G30: 25785 | I30: =IFERROR(G30/$G$40,"") -> 0.04113293
B31: {=+_FV(Peers!A10,"Name")} -> BROADCOM INC. | E31: USA | G31: 51574 | I31: =IFERROR(G31/$G$40,"") -> 0.082272241
B32: {=+_FV(Peers!A11,"Name")} -> ASML Holding NV | E32: Netherlands | G32: 30574 | I32: =IFERROR(G32/$G$40,"") -> 0.048772473
G33: 0
G34: 0
G35: 0
G36: 0
G37: 0
G38: 0
B39: Others | E39: -- | G39: =G40-SUM(G28:G38) -> 335339 | I39: =IFERROR(G39/$G$40,"") -> 0.53494185
B40: Industry Size | E40: -- | G40: 626870 | H40: Source: Statista | I40: 1
B42: Porter's Five Forces Analysis | E42: Rating | H42: Graph
B44: Threat of New Entrants | E44: =IFERROR(AVERAGE(E45:E50),"") -> 2
B45: Economies of scale | E45: 1
B46: Product differentiation | E46: 2
B47: Capital requirements | E47: 1
B48: Access to distribution channels | E48: 2
B49: Regulations | E49: 4
B50: Switching costs | E50: 2
B51: Bargaining Power of Suppliers | E51: =IFERROR(AVERAGE(E52:E56),"") -> 2.8
B52: Number of suppliers | E52: 4
B53: Uniqueness | E53: 4
B54: Switching Costs | E54: 3
...

Sheet Peers
D3: Revenue Growth | F3: EBITDA Margin | H3: Profit Margin | J3: EV / Revenue | L3: EV / EBITDA | N3: Price / Earnings
B4: Peers | C4: Ticker | D4: =+Inputs!O4&"-"&Inputs!P4 -> 2022-2023 | E4: =+Inputs!P4&"-"&Inputs!Q4 -> 2023-2024 | F4: 2023 | G4: 2024 | H4: =+Inputs!O4&"-"&Inputs!P4 -> 2022-2023 | I4: =+Inputs!P4&"-"&Inputs!Q4 -> 2023-2024 | J4: 2023 | K4: 2024 | L4: 2023 | M4: 2024 | N4: 2023 | O4: 2024
A6: =+D91 -> #VALUE! | B6: {=IFERROR(_FV(A6,"Name"),"")} -> INTEL CORPORATION | C6: {=IFERROR(_FV(A6,"Ticker symbol",TRUE),"")} -> INTC | D6: =IFERROR(D94/D93-1,"") -> -0.13997526 | E6: =IFERROR(D97/D94-1,"") -> -0.020782622 | F6: =IFERROR(D95/D94,"") -> 0.17481744 | G6: =IFERROR(D100/D97,"") -> 0.11214478 | H6: =IFERROR(D96/D94,"") -> 0.034981928 | I6: =IFERROR(D105/D97,"") -> -0.24455283 | J6: {=IFERROR((_FV(A6,"Market cap",TRUE)/1000000+D$121-D$111)/D$94,"")} -> 3.4239933 | K6: {=IFERROR((_FV(A6,"Market cap",TRUE)/1000000+D$121-D$111)/D$97,"")} -> 3.4966631 | L6: {=+IFERROR((_FV(A6,"Market cap",TRUE)/1000000+D$121-D$111)/D$95,"")} -> 19.586108 | M6: {=IFERROR((_FV(A6,"Market cap",TRUE)/1000000+D$121-D$111)/D$100,"")} -> 31.1799 | N6: {=IFERROR((_FV(A6,"Market cap",TRUE)/1000000)/D$96,"")} -> 77.587405 | O6: {=IFERROR((_FV(A6,"Market cap",TRUE)/1000000)/D$105,"")} -> -11.333999
A8: =+E91 -> #VALUE! | B8: NVIDIA | C8: {=IFERROR(_FV(A8,"Ticker symbol",TRUE),"")} -> NVDA | D8: =+IFERROR(E94/E93-1,"") -> 1.2585453 | E8: =IFERROR(E97/E94-1,"") -> 1.1420341 | F8: =IFERROR(E95/E94,"") -> 0.83879387 | G8: =+IFERROR(E100/E97,"") -> 0.63846678 | H8: =IFERROR(E96/E94,"") -> 0.48849348 | I8: =+IFERROR(E105/E99,"") -> 0.7447526 | J8: {=+IFERROR((_FV(A8,"Market cap",TRUE)/1000000+E$121-E$111)/E$94,"")} -> 70.130372 | K8: {=IFERROR(+(_FV(A8,"Market cap",TRUE)/1000000+E$121-E$111)/E$97,"")} -> 32.740082 | L8: {=IFERROR(+(_FV(A8,"Market cap",TRUE)/1000000+E$121-E$111)/E$95,"")} -> 83.608589 | M8: {=IFERROR(+(_FV(A8,"Market cap",TRUE)/1000000+E$121-E$111)/E$100,"")} -> 51.279225 | N8: {=IFERROR(+(_FV(A8,"Market cap",TRUE)/1000000)/E$96,"")} -> 143.51779 | O8: {=IFERROR(+(_FV(A8,"Market cap",TRUE)/1000000)/E$105,"")} -> 58.604411
A9: =+F91 -> #VALUE! | B9: AMD | C9: {=IFERROR(_FV(A9,"Ticker symbol",TRUE),"")} -> AMD | D9: =IFERROR(F94/F93-1,"") -> -0.03902377 | E9: =IFERROR(+F97/F94-1,"") -> 0.13690476 | F9: =IFERROR(F95/F94,"") -> 0.21763668 | G9: =IFERROR(F100/F97,"") -> 0.19255381 | H9: =IFERROR(F96/F94,"") -> 0.037654321 | I9: =+IFERROR(F105/F97,"") -> 0.063641652 | J9: {=IFERROR(+(_FV(A9,"Market cap",TRUE)/1000000+F$121-F$111)/F$94,"")} -> 10.985103 | K9: {=IFERROR(+(_FV(A9,"Market cap",TRUE)/1000000+F$121-F$111)/F$97,"")} -> 9.6622896 | L9: {=IFERROR(+(_FV(A9,"Market cap",TRUE)/1000000+F$121-F$111)/F$95,"")} -> 50.474501 | M9: {=IFERROR(+(_FV(A9,"Market cap",TRUE)/1000000+F$121-F$111)/F$100,"")} -> 50.179685 | N9: {=IFERROR(+(_FV(A9,"Market cap",TRUE)/1000000)/F$96,"")} -> 294.15473 | O9: {=IFERROR(+(_FV(A9,"Market cap",TRUE)/1000000)/F$105,"")} -> 153.08235
A10: =+G91 -> #VALUE! | B10: Broadcom Inc. | C10: {=IFERROR(_FV(A10,"Ticker symbol",TRUE),"")} -> AVGO | D10: =+IFERROR(G94/G93-1,"") -> 0.078788061 | E10: =IFERROR(G97/G94-1,"") -> 0.43985036 | F10: =IFERROR(G95/G94,"") -> 0.50540216 | G10: =IFERROR(G100/G97,"") -> 0.38055997 | H10: =IFERROR(G96/G94,"") -> 0.3931433 | I10: =+IFERROR(G105/G97,"") -> 0.11430178 | J10: {=IFERROR(+(_FV(A10,"Market cap",TRUE)/1000000+G$121-G$111)/G$94,"")} -> 47.327012 | K10: {=IFERROR(+(_FV(A10,"Market cap",TRUE)/1000000+G$121-G$111)/G$97,"")} -> 32.869396 | L10: {=IFERROR(+(_FV(A10,"Market cap",TRUE)/1000000+G$121-G$111)/G$95,"")} -> 93.642283 | M10: {=IFERROR(+(_FV(A10,"Market cap",TRUE)/1000000+G$121-G$111)/G$100,"")} -> 86.371134 | N10: {=IFERROR(+(_FV(A10,"Market cap",TRUE)/1000000)/G$96,"")} -> 116.33712 | O10: {=IFERROR(+(_FV(A10,"Market cap",TRUE)/1000000)/G$105,"")} -> 277.90657
A11: =+H91 -> #VALUE! | B11: ASML | C11: {=IFERROR(_FV(A11,"Ticker symbol",TRUE),"")} -> ASML | D11: =IFERROR(H94/H93-1,"") -> 0.33648715 | E11: =IFERROR(H97/H94-1,"") -> 0.02580104 | F11: =IFERROR(H95/H94,"") -> 0.3845328 | G11: =IFERROR(H100/H97,"") -> 0.41888533 | H11: =IFERROR(H96/H94,"") -> 0.29448079 | I11: =+IFERROR(H105/H102,"") -> -430.09524 | J11: {=IFERROR((_FV(A11,"Market cap",TRUE)/1000000+H$121-H$111)/H$94,"")} -> 11.285617 | K11: {=IFERROR(+(_FV(A11,"Market cap",TRUE)/1000000+H$121-H$111)/H$97,"")} -> 11.00176 | L11: {=IFERROR(+(_FV(A11,"Market cap",TRUE)/1000000+H$121-H$111)/H$95,"")} -> 29.348905 | M11: {=IFERROR(+(_FV(A11,"Market cap",TRUE)/1000000+H$121-H$111)/H$100,"")} -> 26.264371 | N11: {=IFERROR(+(_FV(A11,"Market cap",TRUE)/1000000)/H$96,"")} -> 39.240754 | O11: {=IFERROR(+(_FV(A11,"Market cap",TRUE)/1000000)/H$105,"")} -> 38.132872
A12: =+I91 -> PEER 5 | B12: {=IFERROR(_FV(A12,"Name"),"")} | C12: {=IFERROR(_FV(A12,"Ticker symbol",TRUE),"")} | D12: =+IFERROR(I94/I93-1,"") | E12: =IFERROR(I97/I94-1,"") | F12: =IFERROR(I95/I94,"") | G12: =IFERROR(I100/I97,"") | H12: =IFERROR(I96/I94,"") | I12: =+IFERROR(I105/I97,"") | J12: {=IFERROR((_FV(A12,"Market cap",TRUE)/1000000+I$121-I$111)/I$94,"")} | K12: {=IFERROR(+(_FV(A12,"Market cap",TRUE)/1000000+I$121-I$111)/I$97,"")} | L12: {=IFERROR(+(_FV(A12,"Market cap",TRUE)/1000000+I$121-I$111)/I$95,"")} | M12: {=IFERROR(+(_FV(A12,"Market cap",TRUE)/1000000+I$121-I$111)/I$100,"")} | N12: {=IFERROR(+(_FV(A12,"Market cap",TRUE)/1000000)/I$96,"")} | O12: {=IFERROR(+(_FV(A12,"Market cap",TRUE)/1000000)/I$105,"")}
A13: =+J91 -> PEER 6 | B13: {=IFERROR(_FV(A13,"Name"),"")} | C13: {=IFERROR(_FV(A13,"Ticker symbol",TRUE),"")} | D13: =IFERROR(J94/J93-1,"") | E13: =IFERROR(J97/J94-1,"") | F13: =IFERROR(J95/J94,"") | G13: =IFERROR(J100/J97,"") | H13: =IFERROR(J96/J94,"") | I13: =+IFERROR(J105/J97,"") | J13: {=IFERROR(+(_FV(A13,"Market cap",TRUE)/1000000+J$121-J$111)/J$94,"")} | K13: {=IFERROR(+(_FV(A13,"Market cap",TRUE)/1000000+J$121-J$111)/J$97,"")} | L13: {=IFERROR(+(_FV(A13,"Market cap",TRUE)/1000000+J$121-J$111)/J$95,"")} | M13: {=IFERROR(+(_FV(A13,"Market cap",TRUE)/1000000+J$121-J$111)/J$100,"")} | N13: {=IFERROR(+(_FV(A13,"Market cap",TRUE)/1000000)/J$96,"")} | O13: {=IFERROR(+(_FV(A13,"Market cap",TRUE)/1000000)/J$105,"")}
A14: =+K91 -> PEER 7 | B14: {=IFERROR(_FV(A14,"Name"),"")} | C14: {=IFERROR(_FV(A14,"Ticker symbol",TRUE),"")} | D14: =IFERROR(K94/K93-1,"") | E14: =IFERROR(K97/K94-1,"") | F14: =+IFERROR(K95/K94,"") | G14: =IFERROR(K100/K97,"") | H14: =IFERROR(K96/K94,"") | I14: =+IFERROR(K105/K97,"") | J14: {=IFERROR((_FV(A14,"Market cap",TRUE)/1000000+D$121-K$111)/K$94,"")} | K14: {=IFERROR(+(_FV(A14,"Market cap",TRUE)/1000000+D$121-K$111)/K$97,"")} | L14: {=IFERROR(+(_FV(A14,"Market cap",TRUE)/1000000+D$121-K$111)/K$95,"")} | M14: {=IFERROR(+(_FV(A14,"Market cap",TRUE)/1000000+D$121-K$111)/K$100,"")} | N14: {=IFERROR(+(_FV(A14,"Market cap",TRUE)/1000000)/K$96,"")} | O14: {=IFERROR(+(_FV(A14,"Market cap",TRUE)/1000000)/K$105,"")}
A15: =+L91 -> PEER 8 | B15: {=IFERROR(_FV(A15,"Name"),"")} | C15: {=IFERROR(_FV(A15,"Ticker symbol",TRUE),"")} | D15: =+IFERROR(L94/L93,"") | E15: =IFERROR(L97/L94,"") | F15: =IFERROR(L95/L94,"") | G15: =IFERROR(L100/L97,"") | H15: =IFERROR(L96/L94,"") | I15: =+IFERROR(L105/L97,"") | J15: {=IFERROR(+(_FV(A15,"Market cap",TRUE)/1000000+L$121-L$111)/L$94,"")} | K15: {=IFERROR(+(_FV(A15,"Market cap",TRUE)/1000000+L$121-L$111)/L$97,"")} | L15: {=IFERROR(+(_FV(A15,"Market cap",TRUE)/1000000+L$121-L$111)/L$95,"")} | M15: {=IFERROR(+(_FV(A15,"Market cap",TRUE)/1000000+L$121-L$111)/L$100,"")} | N15: {=IFERROR(+(_FV(A15,"Market cap",TRUE)/1000000)/L$96,"")} | O15: {=IFERROR(+(_FV(A15,"Market cap",TRUE)/1000000)/L$105,"")}
A16: =+M91 -> PEER 9 | B16: {=IFERROR(_FV(A16,"Name"),"")} | C16: {=IFERROR(_FV(A16,"Ticker symbol",TRUE),"")} | D16: =IFERROR(M94/M93-1,"") | E16: =IFERROR(M97/M94-1,"") | F16: =IFERROR(M95/M94,"") | G16: =IFERROR(M100/M97,"") | H16: =IFERROR(M96/M94,"") | I16: =+IFERROR(M105/M97,"") | J16: {=IFERROR(+(_FV(A16,"Market cap",TRUE)/1000000+M$121-M$111)/M$94,"")} | K16: {=IFERROR(+(_FV(A16,"Market cap",TRUE)/1000000+M$121-M$111)/M$97,"")} | L16: {=IFERROR(+(_FV(A16,"Market cap",TRUE)/1000000+M$121-M$111)/M$95,"")} | M16: {=IFERROR(+(_FV(A16,"Market cap",TRUE)/1000000+M$121-M$111)/M$100,"")} | N16: {=IFERROR(+(_FV(A16,"Market cap",TRUE)/1000000)/M$96,"")} | O16: {=IFERROR(+(_FV(A16,"Market cap",TRUE)/1000000)/M$105,"")}
A17: =+N91 -> PEER 10 | B17: {=IFERROR(_FV(A17,"Name"),"")} | C17: {=+IFERROR(_FV(A17,"Ticker symbol",TRUE),"")} | D17: =IFERROR(N94/N93-1,"") | E17: =IFERROR(N97/N94-1,"") | F17: =IFERROR(N95/N94,"") | G17: =IFERROR(N100/N97,"") | H17: =IFERROR(N96/N94,"") | I17: =+IFERROR(N105/N97,"") | J17: {=IFERROR(+(_FV(A17,"Market cap",TRUE)/1000000+N$121-N$111)/N$94,"")} | K17: {=IFERROR(+(_FV(A17,"Market cap",TRUE)/1000000+N$121-N$111)/N$97,"")} | L17: {=IFERROR(+(_FV(A17,"Market cap",TRUE)/1000000+N$121-N$111)/N$95,"")} | M17: {=IFERROR(+(_FV(A17,"Market cap",TRUE)/1000000+N$121-N$111)/N$100,"")} | N17: {=IFERROR(+(_FV(A17,"Market cap",TRUE)/1000000)/N$96,"")} | O17: {=IFERROR(+(_FV(A17,"Market cap",TRUE)/1000000)/N$105,"")}
B18: Average | D18: =IFERROR(AVERAGE(D6:D17),"") -> 0.29896429 | E18: =IFERROR(AVERAGE(E6:E17),"") -> 0.34476152 | F18: =IFERROR(AVERAGE(F6:F17),"") -> 0.42423659 | G18: =IFERROR(AVERAGE(G6:G17),"") -> 0.34852214 | H18: =IFERROR(AVERAGE(H6:H17),"") -> 0.24975077 | I18: =IFERROR(AVERAGE(I6:I17),"") -> -85.883419 | J18: =IFERROR(AVERAGE(J6:J17),"") -> 28.630419 | K18: =IFERROR(AVERAGE(K6:K17),"") -> 17.954038 | ... O18: =IFERROR(AVERAGE(O6:O17),"") -> 103.27844
B19: Deviation from Average | D19: =IFERROR(+D18-D6,"") -> 0.43893955 | E19: =IFERROR(E18-E6,"") -> 0.36554414 | F19: =+IFERROR(F18-F6,"") -> 0.24941915 | G19: =IFERROR(G18-G6,"") -> 0.23637735 | H19: =IFERROR(+H6-H18,"") -> -0.21476884 | I19: =+IFERROR(I6-I18,"") -> 85.638866 | J19: =+IFERROR(J6-J18,"") -> -25.206426 | K19: =+IFERROR(K6-K18,"") -> -14.457375 | L19: =IFERROR(+L6-L18,"") -> -35.745969 | M19: =IFERROR(M6-M18,"") -> -17.874963 | N19: =IFERROR(+N6-N18,"") -> -56.580154 | O19: =IFERROR(+O6-O18,"") -> -114.61244
D21: Trading Multiple | G21: Net | H21: Preferred | I21: Non-Controlling | J21: Equity Value | M21: Implied Upside (Downside)
B22: Implied Share Price | D22: Revenue | E22: EBITDA | F22: P/E | G22: Debt | H22: Stock | I22: Interest | J22: Revenue | K22: EBITDA | L22: P/E | M22: Revenue | N22: EBITDA | O22: P/E | P22: Current Price
B24: Second Minimum | D24: =IFERROR(SMALL(K6:K17,2),"") -> 9.6622896 | E24: =IFERROR(SMALL(M6:M17,2),"") -> 31.1799 | F24: =IFERROR(SMALL(O6:O17,2),"") -> 38.132872 | G24: =-Inputs!$Q$99+Inputs!$Q$100 -> 24680 | H24: =+Inputs!$Q$101 -> 0 | I24: =+Inputs!$Q$102 -> 5762 | J24: =IFERROR(+D24*$D$97+G24+H24+I24,"") -> 543519.24 | K24: =IFERROR(E24*$D$100+G24+H24+I24,"") -> 216118.31 | L24: =IFERROR(F24*$D$105,"") -> -495193.48 | M24: {=IFERROR(+(J24/_FV($A$6,"Shares outstanding",TRUE)*1000000)/$P$24-1,"")} -> 2.6928049 | N24: {=IFERROR((+K24/_FV($A$6,"Shares outstanding",TRUE)*1000000)/$P$24-1,"")} -> 0.46836154 | O24: {=IFERROR(+(L24/_FV($A$6,"Shares outstanding",TRUE)*1000000)/$P$24-1,"")} -> -4.3644677 | P24: {=+_FV(A6,"Price")} -> 31.515
B25: Average | D25: =+IFERROR(AVERAGE(K6:K17),"") -> 17.954038 | E25: =IFERROR(+AVERAGE(M6:M17),"") -> 49.054863 | F25: =IFERROR(+AVERAGE(O6:O17),"") -> 103.27844 | G25: =-Inputs!$Q$99+Inputs!$Q$100 -> 24680 | H25: =+Inputs!$Q$101 -> 0 | I25: =+Inputs!$Q$102 -> 5762 | J25: =IFERROR(+D25*$D$97+G25+H25+I25,"") -> 983819.38 | K25: =IFERROR(E25*$D$100+G25+H25+I25,"") -> 322563.71 | L25: =IFERROR(+F25*$D$105,"") -> -1341173.8 | M25: {=IFERROR(+(J25/_FV($A$6,"Shares outstanding",TRUE)*1000000)/$P$24-1,"")} -> 5.6843136 | N25: {=IFERROR((+K25/_FV($A$6,"Shares outstanding",TRUE)*1000000)/$P$24-1,"")} -> 1.1915781 | O25: {=IFERROR(+(L25/_FV($A$6,"Shares outstanding",TRUE)*1000000)/$P$24-1,"")} -> -10.112269
B26: Median | D26: =IFERROR(MEDIAN(K6:K17),"") -> 11.00176 | E26: =IFERROR(MEDIAN(M6:M17),"") -> 50.179685 | F26: =IFERROR(MEDIAN(O6:O17),"") -> 58.604411 | G26: =-Inputs!$Q$99+Inputs!$Q$100 -> 24680 | H26: =+Inputs!$Q$101 -> 0 | I26: =+Inputs!$Q$102 -> 5762 | J26: =IFERROR(D26*$D$97+G26+H26+I26,"") -> 614646.44 | K26: =IFERROR(E26*$D$100+G26+H26+I26,"") -> 329262.03 | L26: =IFERROR(+F26*$D$105,"") -> -761036.89 | M26: {=IFERROR(+(J26/_FV($A$6,"Shares outstanding",TRUE)*1000000)/$P$24-1,"")} -> 3.1760608 | N26: {=IFERROR((+K26/_FV($A$6,"Shares outstanding",TRUE)*1000000)/$P$24-1,"")} -> 1.2370881 | O26: {=+IFERROR((L26/_FV($A$6,"Shares outstanding",TRUE)*1000000)/$P$24-1,"")} -> -6.1706739
B27: Second Maximum | D27: =IFERROR(LARGE(K6:K17,2),"") -> 32.740082 | E27: =IFERROR(LARGE(M6:M17,2),"") -> 51.279225 | F27: =IFERROR(LARGE(O6:O17,2),"") -> 153.08235 | G27: =-Inputs!$Q$99+Inputs!$Q$100 -> 24680 | H27: =+Inputs!$Q$101 -> 0 | I27: =+Inputs!$Q$102 -> 5762 | J27: =IFERROR(+D27*$D$97+G27+H27+I27,"") -> 1768973.1 | K27: =IFERROR(E27*$D$100+G27+H27+I27,"") -> 335809.79 | L27: =IFERROR(+F27*$D$105,"") -> -1987927.4 | M27: {=IFERROR(+(J27/_FV($A$6,"Shares outstanding",TRUE)*1000000)/$P$24-1,"")} -> 11.018843 | N27: {=IFERROR((+K27/_FV($A$6,"Shares outstanding",TRUE)*1000000)/$P$24-1,"")} -> 1.2815752 | O27: {=IFERROR(+(L27/_FV($A$6,"Shares outstanding",TRUE)*1000000)/$P$24-1,"")} -> -14.506473
B29: Profitability | D29: =+LEFT(B6, FIND(" ", B6 & " ") - 1) -> INTEL | E29: =+LEFT(B8, FIND(" ", B8 & " ") - 1) -> NVIDIA | F29: =+LEFT(B9, FIND(" ", B9 & " ") - 1) -> AMD | G29: =+LEFT(B10, FIND(" ", B10 & " ") - 1) -> Broadcom | H29: =+LEFT(B11, FIND(" ", B11 & " ") - 1) -> ASML | I29: =+LEFT(B12, FIND(" ", B12 & " ") - 1) | J29: =+LEFT(C12, FIND(" ", C12 & " ") - 1) | K29: =+LEFT(B14, FIND(" ", B14 & " ") - 1) | L29: =+LEFT(B15, FIND(" ", B15 & " ") - 1) | M29: =+LEFT(B16, FIND(" ", B16 & " ") - 1) | N29: =+LEFT(B17, FIND(" ", B17 & " ") - 1) | O29: Average
B31: Operating Margin | D31: =IFERROR(D101/D97,"") -> -0.10214497 | E31: =IFERROR(E101/E97,"") -> 0.62417527 | F31: =IFERROR(F101/F97,"") -> 0.073686252 | G31: =IFERROR(G101/G97,"") -> 0.30616202 | H31: =IFERROR(H101/H97,"") -> 0.35284883 | I31: =IFERROR(I101/I97,"") | J31: =IFERROR(J101/J97,"") | K31: =IFERROR(K101/K97,"") | ... N31: =IFERROR(N101/N97,"") | O31: =IFERROR(+AVERAGE(D31:N31),"") -> 0.25094548
B32: Net Income Margin | D32: =IFERROR(D105/D97,"") -> -0.24455283 | E32: =IFERROR(E105/E97,"") -> 0.55848027 | F32: =IFERROR(F105/F97,"") -> 0.063641652 | G32: =IFERROR(G105/G97,"") -> 0.11430178 | H32: =IFERROR(H105/H97,"") -> 0.2954144 | I32: =IFERROR(I105/I97,"") | J32: =IFERROR(J105/J97,"") | K32: =IFERROR(K105/K97,"") | ... N32: =IFERROR(N105/N97,"") | O32: =IFERROR(+AVERAGE(D32:N32),"") -> 0.15745705
B33: ROA (%) | D33: =IFERROR(D105/D117,"") -> -0.066091559 | E33: =IFERROR(E105/E117,"") -> 0.65304074 | F33: =IFERROR(F105/F117,"") -> 0.023704966 | G33: =IFERROR(G105/G117,"") -> 0.035588155 | H33: =IFERROR(H105/H117,"") -> 0.1858834 | I33: =IFERROR(I105/I117,"") | J33: =IFERROR(J105/J117,"") | K33: =IFERROR(K105/K117,"") | ... N33: =IFERROR(N105/N117,"") | O33: =IFERROR(+AVERAGE(D33:N33),"") -> 0.16642514
B34: Financial Cost of Debt | D34: =IFERROR(+(D102/D121)*(1-(D104/D103)),"") -> -0.011811534 | E34: =IFERROR(+(E102/E121)*(1-(E104/E103)),"") -> 0.22357173 | F34: =IFERROR(+(F102/F121)*(1-(F104/F103)),"") -> -0.043217358 | G34: =IFERROR(+(G102/G121)*(1-(G104/G103)),"") -> 0.037089748 | H34: =IFERROR(+(H102/H121)*(1-(H104/H103)),"") -> -0.0036622002 | I34: =IFERROR(+(I102/I121)*(1-(I104/I103)),"") | J34: =IFERROR(+(J102/J121)*(1-(J104/J103)),"") | K34: =IFERROR(+(K102/K121)*(1-(K104/K103)),"") | ... N34: =IFERROR(+(N102/N121)*(1-(N104/N103)),"") | O34: =IFERROR(+AVERAGE(D34:N34),"") -> 0.040394078
B35: Return on Equity (RoE) | D35: =IFERROR(+D105/D122,"") -> -0.12363851 | E35: =IFERROR(+E105/E122,"") -> 0.91872881 | F35: =IFERROR(+F105/F122,"") -> 0.02850542 | G35: =IFERROR(+G105/G122,"") -> 0.087103638 | H35: =IFERROR(+H105/H122,"") -> 0.1858834 | I35: =IFERROR(+I105/I122,"") | J35: =IFERROR(+J105/J122,"") | K35: =IFERROR(+K105/K122,"") | ... N35: =IFERROR(+N105/N122,"") | O35: =IFERROR(+AVERAGE(D35:N35),"") -> 0.21931655
B36: Return on Invested Capital (ROIC) | D36: =IFERROR(+D105/(D121+D122),"") -> -0.085561427 | E36: =IFERROR(+E105/(E121+E122),"") -> 0.81604318 | F36: =IFERROR(+F105/(F121+F122),"") -> 0.027677984 | G36: =IFERROR(+G105/(G121+G122),"") -> 0.044001403 | H36: =IFERROR(+H105/(H121+H122),"") -> 0.16952843 | I36: =IFERROR(+I105/(I121+I122),"") | J36: =IFERROR(+J105/(J121+J122),"") | K36: =IFERROR(+K105/(K121+K122),"") | ... N36: =IFERROR(+N105/(N121+N122),"") | O36: =IFERROR(+AVERAGE(D36:N36),"") -> 0.19433791
B38: Solvency | D38: =+D29 -> INTEL | E38: =+E29 -> NVIDIA | F38: =+F29 -> AMD | G38: =+G29 -> Broadcom | H38: =+H29 -> ASML | I38: =+I29 | J38: =+J29 | K38: =+K29 | ... O38: =+O29 -> Average
B40: Debt/Assets | D40: =IFERROR(D121/D117,"") -> 0.23789093 | E40: =IFERROR(E121/E117,"") -> 0.089443643 | F40: =IFERROR(F121/F117,"") -> 0.024860602 | G40: =IFERROR(G121/G117,"") -> 0.40022337 | H40: =IFERROR(H121/H117,"") -> 0.096473319 | I40: =IFERROR(I121/I117,"") | J40: =IFERROR(J121/J117,"") | K40: =IFERROR(K121/K117,"") | ... N40: =IFERROR(N121/N117,"") | O40: =IFERROR(+AVERAGE(D40:N40),"") -> 0.16977837
B41: Net Debt/EBITDA | D41: =IFERROR(+(D121-D111)/D100,"") -> 6.4639798 | E41: =IFERROR(+(E121-E111)/E100,"") -> 0.016719076 | F41: =IFERROR(+(F121-F111)/F100,"") -> -0.41611279 | G41: =IFERROR(+(G121-G111)/G100,"") -> 2.9014623 | H41: =IFERROR(+(H121-H111)/H100,"") -> -0.62842976 | I41: =IFERROR(+(I121-I111)/I100,"") | J41: =IFERROR(+(J121-J111)/J100,"") | K41: =IFERROR(+(K121-K111)/K100,"") | ... N41: =IFERROR(+(N121-N111)/N100,"") | O41: =IFERROR(+AVERAGE(D41:N41),"") -> 1.6675237
B42: Interest Coverage Ratio | D42: =IFERROR(D101/D102,"") -> 25.706161 | E42: =IFERROR(E101/E102,"") -> 31.656821 | F42: =IFERROR(F101/F102,"") -> -20.652174 | G42: =IFERROR(G101/G102,"") -> 3.9944346 | H42: =IFERROR(H101/H102,"") -> -513.71429 | I42: =IFERROR(I101/I102,"") | J42: =IFERROR(J101/J102,"") | K42: =IFERROR(K101/K102,"") | ... N42: =IFERROR(N101/N102,"") | O42: =IFERROR(+AVERAGE(D42:N42),"") -> -94.601809
B44: Liquidity | D44: =+D29 -> INTEL | E44: =+E29 -> NVIDIA | F44: =+F29 -> AMD | G44: =+G29 -> Broadcom | H44: =+H29 -> ASML | I44: =+I29 | J44: =+J29 | K44: =+K29 | ... O44: =+O29 -> Average
B46: Cash Ratio | D46: =IFERROR(D111/D119,"") -> 0.2312847 | E46: =IFERROR(E111/E119,"") -> 0.47592398 | F46: =IFERROR(F111/F119,"") -> 0.52012086 | G46: =IFERROR(G111/G119,"") -> 0.55986105 | H46: =IFERROR(H111/H119,"") -> 0.63516263 | I46: =IFERROR(I111/I119,"") | J46: =IFERROR(J111/J119,"") | K46: =IFERROR(K111/K119,"") | ... N46: =IFERROR(N111/N119,"") | O46: =IFERROR(+AVERAGE(D46:N46),"") -> 0.48447064
B47: Quick Ratio | D47: =IFERROR(+(D111+D112)/D119,"") -> 0.32880054 | E47: =IFERROR(+(E111+E112)/E119,"") -> 1.7539757 | F47: =IFERROR(+(F111+F112)/F119,"") -> 1.3705535 | G47: =IFERROR(+(G111+G112)/G119,"") -> 0.8243397 | H47: =IFERROR(+(H111+H112)/H119,"") -> 0.85846375 | I47: =IFERROR(+(I111+I112)/I119,"") | J47: =IFERROR(+(J111+J112)/J119,"") | K47: =IFERROR(+(K111+K112)/K119,"") | ... N47: =IFERROR(+(N111+N112)/N119,"") | O47: =IFERROR(+AVERAGE(D47:N47),"") -> 1.0272266
B48: Current Ratio | D48: =IFERROR(D115/D119,"") -> 1.3268659 | E48: =IFERROR(E115/E119,"") -> 4.4398515 | F48: =IFERROR(F115/F119,"") -> 2.6162615 | G48: =IFERROR(G115/G119,"") -> 1.1735641 | H48: =IFERROR(H115/H119,"") -> 1.5329304 | I48: =IFERROR(I115/I119,"") | J48: =IFERROR(J115/J119,"") | K48: =IFERROR(K115/K119,"") | ... N48: =IFERROR(N115/N119,"") | O48: =IFERROR(+AVERAGE(D48:N48),"") -> 2.2178947
B50: Activity | D50: =+D29 -> INTEL | E50: =+E29 -> NVIDIA | F50: =+F29 -> AMD | G50: =+G29 -> Broadcom | H50: =+H29 -> ASML | I50: =+I29 | J50: =+J29 | K50: =+K29 | ... O50: =+O29 -> Average
B52: Inventory Turnover | D52: =IFERROR(D98/(AVERAGE(D113:D114)),"") -> 3.065895 | E52: =IFERROR(E98/(AVERAGE(E113:E114)),"") -> 3.2510583 | F52: =IFERROR(F98/(AVERAGE(F113:F114)),"") -> 2.4023798 | G52: =IFERROR(G98/(AVERAGE(G113:G114)),"") -> 10.423729 | H52: =IFERROR(H98/(AVERAGE(H113:H114)),"") -> 1.5319468 | I52: =IFERROR(I98/(AVERAGE(I113:I114)),"") | J52: =IFERROR(J98/(AVERAGE(J113:J114)),"") | K52: =IFERROR(K98/(AVERAGE(K113:K114)),"") | ... N52: =IFERROR(N98/(AVERAGE(N113:N114)),"") | O52: =IFERROR(+AVERAGE(D52:N52),"") -> 4.1350017
B53: Acc. Receivable Turnover | D53: =IFERROR(D97/D112,"") -> 15.267683 | E53: =IFERROR(E97/E112,"") -> 5.6577932 | F53: =IFERROR(F97/F112,"") -> 4.1642442 | G53: =IFERROR(G97/G112,"") -> 11.678895 | H53: =IFERROR(H97/H112,"") -> 6.828364 | I53: =IFERROR(I97/I112,"") | J53: =IFERROR(J97/J112,"") | K53: =IFERROR(K97/K112,"") | ... N53: =IFERROR(N97/N112,"") | O53: =IFERROR(+AVERAGE(D53:N53),"") -> 8.7193958
B54: Payables Turnover | D54: =IFERROR(D98/D118,"") -> 2.8477222 | E54: =IFERROR(E98/E118,"") -> 5.1725832 | F54: =IFERROR(F98/F118,"") -> 6.0874372 | G54: =IFERROR(G98/G118,"") -> 11.471119 | H54: =IFERROR(H98/H118,"") -> 4.3200777 | I54: =IFERROR(I98/I118,"") | J54: =IFERROR(J98/J118,"") | K54: =IFERROR(K98/K118,"") | ... N54: =IFERROR(N98/N118,"") | O54: =IFERROR(+AVERAGE(D54:N54),"") -> 5.9797879
...

Sheet ESG
B2: Environmental, Social and Governance Analysis
B4: Author: | C4: Guilherme | E4: Highlights | N4: Recent News
B6: Overview | D6: .
B7: Last Update | C7: 45761 | D7: .
B8: Latest year with data | C8: 2024
B9: GICS Sector | C9: Information Technology
B10: GICS Industry Group | C10: Semiconductors & Semiconductor Equipment
B11: Final Review
B13: ESG Scores
B14: LSEG ESG Score | C14: 88
B15: E-Score | C15: 89
B16: S-Score | C16: 88 | E16: GHG Scope 1 and 2 Emissions: | N16: Water, Waste, Energy Management:
B17: G-Score | C17: 88
B18: S&P Global ESG Score | C18: 60
B19: Environmental | C19: 61
B20: Social | C20: 59
B21: Governance & Economic | C21: 60
B22: Sustainalytics | C22: 19.2
B23: ISS ESG Corporate Rating | C23: ?
B24: SDG Impact Rating | C24: ?
B25: Governance Quality Score | C25: ?
B26: MSCI ESG Ratings | C26: AA
B29: Industry ESG Overview:
E33: ENVIRONMENTAL
G35: Overview | H35: Targets | K35: Improvements | O35: Comments
E36: GHG (or CO2) Scope 1 Emissions | H36: Reduce Scope 1 (and 2 greenhouse) gas emissions by 10% between 2020 and 2030. Achieve net-zero emissions for these categories by 2040. | K36: In 2023, 100% renewable electricity in US, Europe, Israel, Malaysia, Vietnam, and China locations, was reached China locations | O36: N/A
E38: Water Consumption | H38: Save 60 billion gallons of water and support external projects that help restore water sources to achieve net positive water by 2030. | K38: In 2023, it was maintained the net positive water in the US and India and reached 2 additional countries (Costa Rica and México) | O38: Intel was the first semiconductor company in the US to achieve the Alliance for Water Stewardship (AWS) platinum certification (2023)
E40: Energy Consumption | H40: Transition to 100% renewable electricity and reduce electricity consumption by 4 billion kWh by 2030. | K40: In 2023 Intel had conserved a cumulative total of 1.6 billion kWh of electricity since the baseline date, which tends to raise every year (aimed at more 125 million in 2024) | O40: N/A
E42: Waste Management | H42: Achieve 0 waste to landfill. Adopt circular economy practices for at least 60% of the manufacturing waste streams by 2030 | K42: Intel continues to find ways to recover materials and regenerate resources to create circular economy solutions reducing costs and impact. | O42: 63% manufacturing waste upcycled in 2023
E44: Other
E46: SOCIAL
B48: Important Sources: | G48: Overview | H48: Targets | K48: Improvements | O48: Comments
B49: Annual Report | C49: https://d1io3yog0oux5.cloudfront.net/_7836e22efae1ffbd5e36f11a2d4b09f6/intel/db/888/9122/file/2024+ARS+Form+10-K+after+filing.pdf | E49: Employee Turnover % | H49: N/A | K49: N/A | O49: Its was 4% in 2020. In summer of 2024 due to a plan to reduce costs, Intel layed off roughly 15%.
B50: Sustainability Report | D50: .
B51: Proxy Statement | C51: https://d1io3yog0oux5.cloudfront.net/_7836e22efae1ffbd5e36f11a2d4b09f6/intel/db/888/9121/file/2025+Proxy+Statement+Final.pdf | D51: . | E51: Salaries & Compensation | H51: Intel is comitted to globay pay equity. | O51: To support employees during Covid19 more than $100 milion is being invested in employer benefits. Intel uses analysis to ensure fair pay. The median yearly total compensation reported at Intel is $174,771.
B53: Retiree Annual Enrollment Guide | C53: Retiree Benefits Enrollment Guide | E53: Reputation | H53: Commitment with lauching a new chip (Intel’s Panther Lake chipset) in the second half of 2025 | K53: (possible improvement) New CEO (18/3) strategy that consits in continuing to compound on what the company already does well can show relience and improve reputation | O53: Intel was named by Forbes as one of the 2019 World’s Most Reputable Companies. However, since then in January 2025 the company’s annual revenue presented a loss of about 33% in four years.
B55: Responsability Report | C55: https://csrreportbuilder.intel.com/pdfbuilder/pdfs/CSR-2023-24-Full-Report.pdf | E55: Discrimination Events | H55: N/A | K55: N/A | O55: (Sept. 2024) Processo por discriminação contra a Intel (“Intel failed to protect a talented Israeli employee from workplace discrimination, instead punishing him for raising concerns about his hostile anti-Israel manager.")
E57: Work Safety | H57: N/A | K57: In 2023 there was a reduction of 15% in office CTD(the most prevalent type of injury experienced at Intel in 2023) rates compared to 2022 | O57: In 2023 Intel had an OSHA(course that promotes workplace safety and improves compliance) recordable rate of 0.83 per 100 employees. (bigger than the industry average). Employees are required to complete EHS training.
