Workbook
Name COOLFUCNTION: _xlfn.LAMBDA(_xldudf_BOARDFLARE_EXEC("workbook-settings:coolfucntion"))
Name COOLFUCNTION: _xlfn.LAMBDA(_xldudf_BOARDFLARE_EXEC("workbook-settings:coolfucntion"))
Name COOLFUCNTION: _xlfn.LAMBDA(_xldudf_BOARDFLARE_EXEC("workbook-settings:coolfucntion"))
Name COOLFUCNTION: _xlfn.LAMBDA(_xldudf_BOARDFLARE_EXEC("workbook-settings:coolfucntion"))
Name COOLFUCNTION: _xlfn.LAMBDA(_xldudf_BOARDFLARE_EXEC("workbook-settings:coolfucntion"))
Name COOLFUCNTION: _xlfn.LAMBDA(_xldudf_BOARDFLARE_EXEC("workbook-settings:coolfucntion"))
Name COOLFUCNTION: _xlfn.LAMBDA(_xldudf_BOARDFLARE_EXEC("workbook-settings:coolfucntion"))
Name COOLFUCNTION: _xlfn.LAMBDA(_xldudf_BOARDFLARE_EXEC("workbook-settings:coolfucntion"))
Name COOLFUCNTION: _xlfn.LAMBDA(_xldudf_BOARDFLARE_EXEC("workbook-settings:coolfucntion"))
Name COOLFUCNTION: _xlfn.LAMBDA(_xldudf_BOARDFLARE_EXEC("workbook-settings:coolfucntion"))
Name Sectors: #REF!
Name Sectors: #REF!
Name Sectors: #REF!

Sheet Summary
E2: | EQUITY RESEARCH | U2: Lisbon Investment Society Equity Research
U3: April 21, 2025
D6: {=+_FV(DCF!AA4,"Name")} -> IONQ, INC. | U6: Sell
D8: IonQ is an American technology company focused on quantum computing. It is known for developing quantum computers based on trapped ions, one of the most promising approaches in the field. Its solutions allow businesses and researchers to explore quantum computing for applications like chemical simulations, optimization, and machine learning. | U8: XNYS⁩:(IONQ)
U9: {=+"Price (22 Apr 25): $"&_FV(DCF!$AA$4,"Price")} -> Price (22 Apr 25): $55.008
D10: Investment Thesis | U10: ="Price Target: $" & ROUND(IF(Summary!G25="FCFF",DCF!Z210,IF(Summary!G25="FCFE",DCF!AA253,IF(Summary!G25="Tax Shield",DCF!AA226,DCF!Q269))),2) &" "&IF(Summary!G25="FCFF","(FCFF)",IF(Summary!G25="FCFE","(FCFE)",IF(Summary!G25="Tax Shield","(APV)","(DDM)"))) -> Price Target: $13.35 (FCFF)
D11: IonQ offers compelling long-term potential driven by breakthroughs in quantum computing, with a particular focus on high-impact sectors such as healthcare—where quantum capabilities could revolutionize drug discovery, diagnostics, and genomics. Its partnerships with tech giants like Amazon and Microsoft offer distribution advantages and validation, but they also reflect the power imbalance in the ecosystem, where IonQ’s growth is partly dependent on these larger players’ platforms and roadmaps. While consumers wield influence over the broader tech landscape, IonQ remains largely insulated due to its B2B/government focus, although public perception and trust still impact long-term viability and investment flow. Despite strong growth relative to peers and a solid technology foundation, IonQ operates in a highly volatile market, with substantial risks tied to the availability of public and private funding—particularly in light of changing economic conditions. The company also faces the structural challenge of high operating costs and limited short- to mid-term monetization. Even over a 20-year horizon, stable and steady profitability remains uncertain, making the investment less appealing for those seeking near-term returns or sure long-term ones. | U11: =+"Upside (Downside): "&ROUND((DCF!$Z$213*100),2)&"%" -> Upside (Downside): -75.73%
U15: =+ESG!C10 -> 0
E17: j | K17: Valuation Multiples | N17: 2022 | O17: =+N17+1 -> 2023 | P17: =+O17+1 -> 2024 | Q17: =+P17+1 -> 2025 | R17: =+Q17+1 -> 2026 | U17: Cristina Lin
K18: EV / Sales | N18: =IFERROR(_xlfn.XLOOKUP($K18,Multiples!$B:$B,Multiples!N:N),"") -> 31.282787 | O18: =IFERROR(_xlfn.XLOOKUP($K18,Multiples!$B:$B,Multiples!O:O),"") -> 98.112097 | P18: =IFERROR(_xlfn.XLOOKUP($K18,Multiples!$B:$B,Multiples!P:P),"") -> 199.09628 | Q18: =IFERROR(_xlfn.XLOOKUP($K18,Multiples!$B:$B,Multiples!Q:Q),"") -> -27.061042 | R18: =IFERROR(_xlfn.XLOOKUP($K18,Multiples!$B:$B,Multiples!R:R),"") -> -17.209963 | U18: cristina.lin@aln.iseg.ulisboa.pt
K19: Price / Sales | N19: =IFERROR(_xlfn.XLOOKUP($K19,Multiples!$B:$B,Multiples!N:N),"") -> 62.883452 | O19: =IFERROR(_xlfn.XLOOKUP($K19,Multiples!$B:$B,Multiples!O:O),"") -> 113.87001 | P19: =IFERROR(_xlfn.XLOOKUP($K19,Multiples!$B:$B,Multiples!P:P),"") -> 206.58505 | Q19: =IFERROR(_xlfn.XLOOKUP($K19,Multiples!$B:$B,Multiples!Q:Q),"") -> -29.825629 | R19: =IFERROR(_xlfn.XLOOKUP($K19,Multiples!$B:$B,Multiples!R:R),"") -> -23.550357 | U19: (+351) 968185578
K20: EV / EBITDA | N20: =IFERROR(_xlfn.XLOOKUP($K20,Multiples!$B:$B,Multiples!N:N),"") -> -4.3448966 | O20: =IFERROR(_xlfn.XLOOKUP($K20,Multiples!$B:$B,Multiples!O:O),"") -> -14.673643 | P20: =IFERROR(_xlfn.XLOOKUP($K20,Multiples!$B:$B,Multiples!P:P),"") -> -40.110542 | Q20: =IFERROR(_xlfn.XLOOKUP($K20,Multiples!$B:$B,Multiples!Q:Q),"") -> 7.1044773 | R20: =IFERROR(_xlfn.XLOOKUP($K20,Multiples!$B:$B,Multiples!R:R),"") -> 5.984625 | U20: Madalena Oliveira da Silva
K21: EV / EBIT | N21: =IFERROR(_xlfn.XLOOKUP($K21,Multiples!$B:$B,Multiples!N:N),"") -> -4.0609323 | O21: =IFERROR(_xlfn.XLOOKUP($K21,Multiples!$B:$B,Multiples!O:O),"") -> -13.708602 | P21: =IFERROR(_xlfn.XLOOKUP($K21,Multiples!$B:$B,Multiples!P:P),"") -> -36.89176 | Q21: =IFERROR(_xlfn.XLOOKUP($K21,Multiples!$B:$B,Multiples!Q:Q),"") -> 6.5589154 | R21: =IFERROR(_xlfn.XLOOKUP($K21,Multiples!$B:$B,Multiples!R:R),"") -> 5.4442224 | U21: l.63835@aln.iseg.ulisboa.pt
K22: Price / Earnings | N22: =IFERROR(_xlfn.XLOOKUP($K22,Multiples!$B:$B,Multiples!N:N),"") -> -14.428804 | O22: =IFERROR(_xlfn.XLOOKUP($K22,Multiples!$B:$B,Multiples!O:O),"") -> -15.913482 | P22: =IFERROR(_xlfn.XLOOKUP($K22,Multiples!$B:$B,Multiples!P:P),"") -> -26.835219 | Q22: =IFERROR(_xlfn.XLOOKUP($K22,Multiples!$B:$B,Multiples!Q:Q),"") -> 7.3033356 | R22: =IFERROR(_xlfn.XLOOKUP($K22,Multiples!$B:$B,Multiples!R:R),"") -> 6.8596672 | U22: (+351) 937583978
K23: Price / Book | N23: =IFERROR(_xlfn.XLOOKUP($K23,Multiples!$B:$B,Multiples!N:N),"") -> 1.2318588 | O23: =IFERROR(_xlfn.XLOOKUP($K23,Multiples!$B:$B,Multiples!O:O),"") -> 5.1751627 | P23: =IFERROR(_xlfn.XLOOKUP($K23,Multiples!$B:$B,Multiples!P:P),"") -> 23.180825 | Q23: =IFERROR(_xlfn.XLOOKUP($K23,Multiples!$B:$B,Multiples!Q:Q),"") -> -20.069772 | R23: =IFERROR(_xlfn.XLOOKUP($K23,Multiples!$B:$B,Multiples!R:R),"") -> -490.16913 | U23: Gabriela de Almeida Rito Major
U24: l64181@aln.iseg.ulisboa.pt
D25: Year | E25: Net Sales | F25: EBIT Margin | G25: FCFF | H25: =+IF(Summary!$G$25="FCFF",DCF!AK6,IF(Summary!$G$25="FCFE",DCF!AL6,DCF!AM6)) -> NOPAT | I25: Net Capex | K25: Profitability Ratios | N25: 2022 | O25: =+N25+1 -> 2023 | P25: =+O25+1 -> 2024 | Q25: =+P25+1 -> 2025 | R25: =+Q25+1 -> 2026 | U25: (+351) 910247429
D26: 2022 | E26: =+DCF!E30 -> 11131 | F26: =+DCF!E61 -> -7.703351 | G26: =+INDEX(DCF!AG7:AJ7,MATCH(Summary!$G$25,{"FCFF","FCFE","Tax Shield","Total Payout"},0)) -> -64536 | H26: =+IF(Summary!$G$25="FCFF",DCF!AK7,IF(Summary!$G$25="FCFE",DCF!AL7,DCF!AM7)) -> -85746 | I26: =+DCF!E135 -> -12564 | K26: Return on Assets | N26: =IFERROR(_xlfn.XLOOKUP($K26,Multiples!$B:$B,Multiples!N:N),"") -> -0.081123159 | O26: =IFERROR(_xlfn.XLOOKUP($K26,Multiples!$B:$B,Multiples!O:O),"") -> -0.28491464 | P26: =IFERROR(_xlfn.XLOOKUP($K26,Multiples!$B:$B,Multiples!P:P),"") -> -0.65223424 | Q26: =IFERROR(_xlfn.XLOOKUP($K26,Multiples!$B:$B,Multiples!Q:Q),"") -> -0.95331909 | R26: =IFERROR(_xlfn.XLOOKUP($K26,Multiples!$B:$B,Multiples!R:R),"") -> -1.2822844 | U26: João de Sousa Eiró
D27: =+D26+1 -> 2023 | E27: =+DCF!F30 -> 22042 | F27: =+DCF!F61 -> -7.1569731 | G27: =+INDEX(DCF!AG8:AJ8,MATCH(Summary!$G$25,{"FCFF","FCFE","Tax Shield","Total Payout"},0)) -> -113850.05 | H27: =+IF(Summary!$G$25="FCFF",DCF!AK8,IF(Summary!$G$25="FCFE",DCF!AL8,DCF!AM8)) -> -157754.05 | I27: =+DCF!F135 -> -19549 | K27: Return on Equity | N27: =IFERROR(_xlfn.XLOOKUP($K27,Multiples!$B:$B,Multiples!N:N),"") -> -0.085374975 | O27: =IFERROR(_xlfn.XLOOKUP($K27,Multiples!$B:$B,Multiples!O:O),"") -> -0.32520618 | P27: =IFERROR(_xlfn.XLOOKUP($K27,Multiples!$B:$B,Multiples!P:P),"") -> -0.86382101 | Q27: =IFERROR(_xlfn.XLOOKUP($K27,Multiples!$B:$B,Multiples!Q:Q),"") -> 2.1736588 | R27: =IFERROR(_xlfn.XLOOKUP($K27,Multiples!$B:$B,Multiples!R:R),"") -> 2.9237313 | U27: joaodesousaeiro@aln.iseg.ulisboa.pt
D28: =+D27+1 -> 2024 | E28: =+DCF!G30 -> 43073 | F28: =+DCF!G61 -> -5.3967683 | G28: =+INDEX(DCF!AG9:AJ9,MATCH(Summary!$G$25,{"FCFF","FCFE","Tax Shield","Total Payout"},0)) -> -146246.04 | H28: =+IF(Summary!$G$25="FCFF",DCF!AK9,IF(Summary!$G$25="FCFE",DCF!AL9,DCF!AM9)) -> -232455.04 | I28: =+DCF!G135 -> -23569 | K28: Return on Total Capital | N28: =IFERROR(_xlfn.XLOOKUP($K28,Multiples!$B:$B,Multiples!N:N),"") -> -0.14983722 | O28: =IFERROR(_xlfn.XLOOKUP($K28,Multiples!$B:$B,Multiples!O:O),"") -> -0.31992368 | P28: =IFERROR(_xlfn.XLOOKUP($K28,Multiples!$B:$B,Multiples!P:P),"") -> -0.57884105 | Q28: =IFERROR(_xlfn.XLOOKUP($K28,Multiples!$B:$B,Multiples!Q:Q),"") -> -1.5801313 | R28: =IFERROR(_xlfn.XLOOKUP($K28,Multiples!$B:$B,Multiples!R:R),"") -> -1.7368601 | U28: (+351) 918446662
D29: =+D28+1 -> 2025 | E29: =+DCF!H30 -> 68916.8 | F29: =+DCF!H61 -> -4.1258411 | G29: =+INDEX(DCF!AG10:AJ10,MATCH(Summary!$G$25,{"FCFF","FCFE","Tax Shield","Total Payout"},0)) -> -112020.3 | H29: =+IF(Summary!$G$25="FCFF",DCF!AK10,IF(Summary!$G$25="FCFE",DCF!AL10,DCF!AM10)) -> -224628.41 | I29: =+DCF!H135 -> -34458.4 | K29: EBITDA Margin | N29: =IFERROR(_xlfn.XLOOKUP($K29,Multiples!$B:$B,Multiples!N:N),"") -> -7.1998922 | O29: =IFERROR(_xlfn.XLOOKUP($K29,Multiples!$B:$B,Multiples!O:O),"") -> -6.6862807 | P29: =IFERROR(_xlfn.XLOOKUP($K29,Multiples!$B:$B,Multiples!P:P),"") -> -4.9636896 | Q29: =IFERROR(_xlfn.XLOOKUP($K29,Multiples!$B:$B,Multiples!Q:Q),"") -> -3.8090125 | R29: =IFERROR(_xlfn.XLOOKUP($K29,Multiples!$B:$B,Multiples!R:R),"") -> -2.8756962
D30: =+D29+1 -> 2026 | E30: =+DCF!I30 -> 110266.88 | F30: =+DCF!I61 -> -3.1611426 | G30: =+INDEX(DCF!AG11:AJ11,MATCH(Summary!$G$25,{"FCFF","FCFE","Tax Shield","Total Payout"},0)) -> -188326.8 | H30: =+IF(Summary!$G$25="FCFF",DCF!AK11,IF(Summary!$G$25="FCFE",DCF!AL11,DCF!AM11)) -> -275369.77 | I30: =+DCF!I135 -> -55133.44 | K30: EBIT Margin | N30: =IFERROR(_xlfn.XLOOKUP($K30,Multiples!$B:$B,Multiples!N:N),"") -> -7.703351 | O30: =IFERROR(_xlfn.XLOOKUP($K30,Multiples!$B:$B,Multiples!O:O),"") -> -7.1569731 | P30: =IFERROR(_xlfn.XLOOKUP($K30,Multiples!$B:$B,Multiples!P:P),"") -> -5.3967683 | Q30: =IFERROR(_xlfn.XLOOKUP($K30,Multiples!$B:$B,Multiples!Q:Q),"") -> -4.1258411 | R30: =IFERROR(_xlfn.XLOOKUP($K30,Multiples!$B:$B,Multiples!R:R),"") -> -3.1611426 | U30: Statistics
D31: =+D30+1 -> 2027 | E31: =+DCF!J30 -> 165400.32 | F31: =+DCF!J61 -> -2.5476658 | G31: =+INDEX(DCF!AG12:AJ12,MATCH(Summary!$G$25,{"FCFF","FCFE","Tax Shield","Total Payout"},0)) -> -232576.45 | H31: =+IF(Summary!$G$25="FCFF",DCF!AK12,IF(Summary!$G$25="FCFE",DCF!AL12,DCF!AM12)) -> -332893.95 | I31: =+DCF!J135 -> -74430.144 | K31: Gross Profit Margin | N31: =IFERROR(_xlfn.XLOOKUP($K31,Multiples!$B:$B,Multiples!N:N),"") -> 0.73551343 | O31: =IFERROR(_xlfn.XLOOKUP($K31,Multiples!$B:$B,Multiples!O:O),"") -> 0.63215679 | P31: =IFERROR(_xlfn.XLOOKUP($K31,Multiples!$B:$B,Multiples!P:P),"") -> 0.52181181 | Q31: =IFERROR(_xlfn.XLOOKUP($K31,Multiples!$B:$B,Multiples!Q:Q),"") -> 0.52181181 | R31: =IFERROR(_xlfn.XLOOKUP($K31,Multiples!$B:$B,Multiples!R:R),"") -> 0.52181181 | U31: Beta | V31: =Peers!D74 -> 2.5362
D32: =+D31+1 -> 2028 | E32: =+DCF!K30 -> 248100.48 | F32: =+DCF!K61 -> -2.0417154 | G32: =+INDEX(DCF!AG13:AJ13,MATCH(Summary!$G$25,{"FCFF","FCFE","Tax Shield","Total Payout"},0)) -> -318961.71 | H32: =+IF(Summary!$G$25="FCFF",DCF!AK13,IF(Summary!$G$25="FCFE",DCF!AL13,DCF!AM13)) -> -400174.95 | I32: =+DCF!K135 -> -111645.22 | K32: SG&A Margin | N32: =IFERROR(_xlfn.XLOOKUP($K32,Multiples!$B:$B,Multiples!N:N),"") -> 3.9844578 | O32: =IFERROR(_xlfn.XLOOKUP($K32,Multiples!$B:$B,Multiples!O:O),"") -> 3.1300245 | P32: =IFERROR(_xlfn.XLOOKUP($K32,Multiples!$B:$B,Multiples!P:P),"") -> 2.308871 | Q32: =IFERROR(_xlfn.XLOOKUP($K32,Multiples!$B:$B,Multiples!Q:Q),"") | R32: =IFERROR(_xlfn.XLOOKUP($K32,Multiples!$B:$B,Multiples!R:R),"") | U32: % Float | V32: =+Peers!D73 -> 0.85310616
D33: =+D32+1 -> 2029 | E33: =+DCF!L30 -> 372150.72 | F33: =+DCF!L61 -> -1.5225164 | G33: =+INDEX(DCF!AG14:AJ14,MATCH(Summary!$G$25,{"FCFF","FCFE","Tax Shield","Total Payout"},0)) -> -376231.76 | H33: =+IF(Summary!$G$25="FCFF",DCF!AK14,IF(Summary!$G$25="FCFE",DCF!AL14,DCF!AM14)) -> -447618.39 | I33: =+DCF!L135 -> -148860.29 | K33: Net Income Margin | N33: =IFERROR(_xlfn.XLOOKUP($K33,Multiples!$B:$B,Multiples!N:N),"") -> -4.3581888 | O33: =IFERROR(_xlfn.XLOOKUP($K33,Multiples!$B:$B,Multiples!O:O),"") -> -7.1555688 | P33: =IFERROR(_xlfn.XLOOKUP($K33,Multiples!$B:$B,Multiples!P:P),"") -> -7.698281 | Q33: =IFERROR(_xlfn.XLOOKUP($K33,Multiples!$B:$B,Multiples!Q:Q),"") -> -4.0838366 | R33: =IFERROR(_xlfn.XLOOKUP($K33,Multiples!$B:$B,Multiples!R:R),"") -> -3.4331631 | U33: % Held by Insiders | V33: =+Peers!D76 -> 0.0854
U34: % Held by Institutions | V34: =+Peers!D77 -> 0.3738
D35: SWOT Analysis | K35: Liquidity Ratios | N35: 2022 | O35: =+N35+1 -> 2023 | P35: =+O35+1 -> 2024 | Q35: =+P35+1 -> 2025 | R35: =+Q35+1 -> 2026 | U35: Short % of Float | V35: =+Peers!D78 -> 0.1466
D36: Strengths | G36: Weaknesses | K36: Cash Ratio | N36: =IFERROR(_xlfn.XLOOKUP($K36,Multiples!$B:$B,Multiples!N:N),"") -> 2.200744 | O36: =IFERROR(_xlfn.XLOOKUP($K36,Multiples!$B:$B,Multiples!O:O),"") -> 0.95966527 | P36: =IFERROR(_xlfn.XLOOKUP($K36,Multiples!$B:$B,Multiples!P:P),"") -> 1.5073576 | Q36: =IFERROR(_xlfn.XLOOKUP($K36,Multiples!$B:$B,Multiples!Q:Q),"") -> -3.9720603 | R36: =IFERROR(_xlfn.XLOOKUP($K36,Multiples!$B:$B,Multiples!R:R),"") -> -12.715983 | W36: 120.87
D37: Technological Leadership: IonQ utilizes trapped-ion quantum technology, offering high fidelity and long coherence times, positioning them at the forefront of quantum computing advancements; Robust Intellectual Property Portfolio: As of February 1, 2024, IonQ holds or exclusively licenses 82 issued U.S. patents and 185 pending or allowed U.S. patent applications, along with international patents and trademarks; Strategic Partnerships: Collaborations with major cloud providers like Amazon Web Services and Microsoft Azure enhance accessibility to IonQ's quantum computing services. | G37: Financial Losses: In 2024, IonQ reported a net loss of $331.6 million and an Adjusted EBITDA loss of $107.2 million, indicating ongoing challenges in achieving profitability; High Operational Costs: Significant investments in research and development contribute to substantial operational expenses, impacting short-term financial performance. | K37: Quick Ratio | N37: =IFERROR(_xlfn.XLOOKUP($K37,Multiples!$B:$B,Multiples!N:N),"") -> 17.811954 | O37: =IFERROR(_xlfn.XLOOKUP($K37,Multiples!$B:$B,Multiples!O:O),"") -> 9.8726725 | P37: =IFERROR(_xlfn.XLOOKUP($K37,Multiples!$B:$B,Multiples!P:P),"") -> 9.6107801 | Q37: =IFERROR(_xlfn.XLOOKUP($K37,Multiples!$B:$B,Multiples!Q:Q),"") -> 1.1227435 | R37: =IFERROR(_xlfn.XLOOKUP($K37,Multiples!$B:$B,Multiples!R:R),"") -> -7.5133431 | U37: Major Holders | W37: 113.63
K38: Current Ratio | N38: =IFERROR(_xlfn.XLOOKUP($K38,Multiples!$B:$B,Multiples!N:N),"") -> 18.433929 | O38: =IFERROR(_xlfn.XLOOKUP($K38,Multiples!$B:$B,Multiples!O:O),"") -> 10.49373 | P38: =IFERROR(_xlfn.XLOOKUP($K38,Multiples!$B:$B,Multiples!P:P),"") -> 10.497492 | Q38: =IFERROR(_xlfn.XLOOKUP($K38,Multiples!$B:$B,Multiples!Q:Q),"") -> 1.7427224 | R38: =IFERROR(_xlfn.XLOOKUP($K38,Multiples!$B:$B,Multiples!R:R),"") -> 1.7427224 | U38: Vanguard Group Inc | V38: 0.0959
U39: Blackrock Inc. | V39: 0.0718
D40: Opportunities | G40: Threats | K40: Cash Flow Ratios | N40: 2022 | O40: =+N40+1 -> 2023 | P40: =+O40+1 -> 2024 | Q40: =+P40+1 -> 2025 | R40: =+Q40+1 -> 2026 | U40: Morgan Stanley | V40: 0.0281
D41: Growing Quantum Computing Market: The expanding demand for quantum computing solutions across various industries presents opportunities for IonQ to capture market share; Government and Defense Contracts: Engagements with governmental agencies, such as the U.S. Air Force Research Laboratory, open avenues for specialized applications and funding. | G41: Intense Competition: The quantum computing sector is highly competitive, with major players like IBM and Google investing heavily in similar technologies; Regulatory and Geopolitical Risks: Potential changes in regulations and international relations could affect IonQ's operations and collaborations. | K41: Cash Conversion Cycle | N41: =IFERROR(_xlfn.XLOOKUP($K41,Multiples!$B:$B,Multiples!N:N),"") -> 7.7715389 | O41: =IFERROR(_xlfn.XLOOKUP($K41,Multiples!$B:$B,Multiples!O:O),"") -> 97.169948 | P41: =IFERROR(_xlfn.XLOOKUP($K41,Multiples!$B:$B,Multiples!P:P),"") -> 10.897546 | Q41: =IFERROR(_xlfn.XLOOKUP($K41,Multiples!$B:$B,Multiples!Q:Q),"") -> -34.632229 | R41: =IFERROR(_xlfn.XLOOKUP($K41,Multiples!$B:$B,Multiples!R:R),"") -> -9.632229 | U41: State Street Corporation | V41: 0.0206
K42: Net Income / Op Cash Flow | N42: =IFERROR(_xlfn.XLOOKUP($K42,Multiples!$B:$B,Multiples!N:N),"") -> 1.0853058 | O42: =IFERROR(_xlfn.XLOOKUP($K42,Multiples!$B:$B,Multiples!O:O),"") -> 2.0012822 | P42: =IFERROR(_xlfn.XLOOKUP($K42,Multiples!$B:$B,Multiples!P:P),"") -> 3.1375724 | Q42: =IFERROR(_xlfn.XLOOKUP($K42,Multiples!$B:$B,Multiples!Q:Q),"") -> 3.5102349 | R42: =IFERROR(_xlfn.XLOOKUP($K42,Multiples!$B:$B,Multiples!R:R),"") -> 2.757168 | U42: Geode Capital Management, LLC | V42: 0.02
K43: Chg in Cash / Op Cash Flow | N43: =IFERROR(_xlfn.XLOOKUP($K43,Multiples!$B:$B,Multiples!N:N),"") -> 7.8897937 | O43: =IFERROR(_xlfn.XLOOKUP($K43,Multiples!$B:$B,Multiples!O:O),"") -> 0.10513761 | P43: =IFERROR(_xlfn.XLOOKUP($K43,Multiples!$B:$B,Multiples!P:P),"") -> -0.17750253 | Q43: =IFERROR(_xlfn.XLOOKUP($K43,Multiples!$B:$B,Multiples!Q:Q),"") -> 3.5600169 | R43: =IFERROR(_xlfn.XLOOKUP($K43,Multiples!$B:$B,Multiples!R:R),"") -> 3.7043132 | U43: UBS Group AG | V43: 0.0111
U44: JP Morgan Chase & Co | V44: 0.0111
D45: Revenue by Region | G45: Revenue by Segment | K45: Leverage Ratios | N45: 2022 | O45: =+N45+1 -> 2023 | P45: =+O45+1 -> 2024 | Q45: =+P45+1 -> 2025 | R45: =+Q45+1 -> 2026 | U45: Northern Trust Corporation | V45: 0.0087
K46: Total Debt / Equity | N46: =IFERROR(_xlfn.XLOOKUP($K46,Multiples!$B:$B,Multiples!N:N),"") -> 7.1276339 | O46: =IFERROR(_xlfn.XLOOKUP($K46,Multiples!$B:$B,Multiples!O:O),"") -> 16.711547 | P46: =IFERROR(_xlfn.XLOOKUP($K46,Multiples!$B:$B,Multiples!P:P),"") -> 46.175448 | Q46: =IFERROR(_xlfn.XLOOKUP($K46,Multiples!$B:$B,Multiples!Q:Q),"") -> -0.13689392 | R46: =IFERROR(_xlfn.XLOOKUP($K46,Multiples!$B:$B,Multiples!R:R),"") -> -2.0979168 | U46: Goldman Sachs Group Inc | V46: 0.0085
K47: Total Debt / Capital | N47: =IFERROR(_xlfn.XLOOKUP($K47,Multiples!$B:$B,Multiples!N:N),"") -> 0.87696296 | O47: =IFERROR(_xlfn.XLOOKUP($K47,Multiples!$B:$B,Multiples!O:O),"") -> 0.94353966 | P47: =IFERROR(_xlfn.XLOOKUP($K47,Multiples!$B:$B,Multiples!P:P),"") -> 0.97880253 | Q47: =IFERROR(_xlfn.XLOOKUP($K47,Multiples!$B:$B,Multiples!Q:Q),"") -> -0.15860614 | R47: =IFERROR(_xlfn.XLOOKUP($K47,Multiples!$B:$B,Multiples!R:R),"") -> 1.9108158 | U47: Charles Schwab Investment Management, Inc. | V47: 0.0074
K48: Total Liabilities / Total Assets | N48: =IFERROR(_xlfn.XLOOKUP($K48,Multiples!$B:$B,Multiples!N:N),"") -> 0.04980167 | O48: =IFERROR(_xlfn.XLOOKUP($K48,Multiples!$B:$B,Multiples!O:O),"") -> 0.12389537 | P48: =IFERROR(_xlfn.XLOOKUP($K48,Multiples!$B:$B,Multiples!P:P),"") -> 0.24494284 | Q48: =IFERROR(_xlfn.XLOOKUP($K48,Multiples!$B:$B,Multiples!Q:Q),"") -> 1.4385781 | R48: =IFERROR(_xlfn.XLOOKUP($K48,Multiples!$B:$B,Multiples!R:R),"") -> 1.4385781
...

Sheet Industry
B2: Industry Overview
B5: Key Drivers | E5: Description
B7: Limitations of Classical Computing | E7: Classical Computing is struggling with processing power, handling complex tasks with many variables and meeting the high energy requirements for AI systems, resulting in high costs and environmental concerns.
B8: Government and Private Sector Investment | E8: Governments and private companies are investing heavily in quantum computing, recognizing its potential to revolutionize industries like finance, healthcare, and cybersecurity. Notable examples include the U.S. government's $1.2 billion investment through the National Quantum Initiative Act and Microsoft's $1 billion commitment to R&D in Quantum Computing.
B9: Healthcare Personalizing | E9: A quantum computer can perform extremely fast DNA sequencing, which opens the possibility for personalized medicine. It can enable the development of new therapies and medicines through detailed modeling.
B10: Rapid Progression in Quantum Hardware | E10: Advancements in quantum hardware, such as improved qubit stability and error correction techniques, are enhancing the power and reliability of quantum computers. These developments are crucial for scaling quantum computing to address complex, industry specific challenges.
B12: Industry Trends | E12: Description
B14: Increasing Market Accessibility | E14: Cloud providers, such as Microsoft Azure and Google Cloud, are reshaping how businesses interact with quantum computing by lowering the barriers to access it and eliminating the need for expensive infrastructure. Greater accessibility allows for greater customer reach and, in turn, accelerated industry growth.
B15: Innovation Driven by Partnerships | E15: Companies, be it tech giants or startups, are increasingly forming strategic partnerships to tackle technical challenges and accelerate quantum technology. This shift from competitive rivalry to cooperation is aimed at solving shared problems and meet evolving market demands.
B16: Quantum Solutions as a Complement | E16: Faced with the limitations of classical computing systems and the early-stage challenges of quantum, businesses are integrating both technologies into a hybrid system, unlocking new ways to solve complex issues that neither could solve alone.
B19: Market Share | E19: Headquarters | G19: Revenues | H19: (in MM of USD) | I19: Market Share
B21: {=+_FV(DCF!AA4,"Name")} -> IONQ, INC. | E21: College Park, Maryland | G21: {=TRANSPOSE(Peers!D97:N97)} -> 43073 | I21: =IFERROR(G21/$G$33,"") -> 0.037128696
B22: {=+_FV(Peers!A8,"Name")} -> RIGETTI COMPUTING, INC | E22: Berkeley, California | G22: 10790 | I22: =IFERROR(G22/$G$33,"") -> 0.0093009223
B23: {=+_FV(Peers!A9,"Name")} -> D-WAVE QUANTUM INC. | E23: Burnaby, Canada | G23: 8827 | I23: =IFERROR(G23/$G$33,"") -> 0.0076088268
B24: {=+_FV(Peers!A10,"Name")} -> QUANTUM COMPUTING INC. | E24: Leesburg, Virginia | G24: 373 | I24: =IFERROR(G24/$G$33,"") -> 0.00032152401
G25: 0
G26: 0
G27: 0
G28: 0
G29: 0
G30: 0
G31: 0
B32: Others | E32: -- | G32: =G33-SUM(G21:G31) -> 1097037 | I32: =IFERROR(G32/$G$33,"") -> 0.94564003
B33: Industry Size | E33: -- | G33: =DCF!G21 -> 1160100 | I33: 1
B35: Porter's Five Forces Analysis | E35: Rating | H35: Graph
B37: Threat of New Entrants | E37: =IFERROR(AVERAGE(E38:E43),"") -> 2.1666667
B38: Economies of scale | E38: 2
B39: Product differentiation | E39: 2
B40: Capital requirements | E40: 1
B41: Access to distribution channels | E41: 2
B42: Regulations | E42: 2
B43: Switching costs | E43: 4
B44: Bargaining Power of Suppliers | E44: =IFERROR(AVERAGE(E45:E49),"") -> 3.4
B45: Number of suppliers | E45: 4
B46: Uniqueness | E46: 4
B47: Switching Costs | E47: 4
B48: Forward Integration | E48: 2
B49: Industry Importance | E49: 3
B50: Bargaining Power of Customers | E50: =IFERROR(AVERAGE(E51:E55),"") -> 4.2
B51: Number of buyers | E51: 3
...

Sheet Segments
B2: Segments
B4: Regions | D4: Weight | E4: 2020 | F4: =+E4+1 -> 2021 | G4: =+F4+1 -> 2022 | H4: =+G4+1 -> 2023 | I4: =+H4+1 -> 2024 | J4: ="CAGR "&$F$4&" - "&$I$4 -> CAGR 2021 - 2024 | K4: 2021 | L4: =+K4+1 -> 2022 | M4: =+L4+1 -> 2023 | N4: =+M4+1 -> 2024
B6: United States | D6: =IFERROR(I6/SUM($I$6:$I$7),"") -> 0.94523251 | E6: 0 | F6: 1889.1 | G6: 9175 | H6: 18703 | I6: 40714 | J6: =IFERROR((I6/F6)^(1/COUNT($G$4:$I$4))-1,"") -> 1.7828915 | K6: =IFERROR(F6-E6/E6,"") | L6: =IFERROR((G6-F6)/F6,"") -> 3.8568101 | M6: =IFERROR((H6-G6)/G6,"") -> 1.0384741 | N6: =IFERROR((I6-H6)/H6,"") -> 1.17687
B7: International | D7: =IFERROR(I7/SUM($I$6:$I$7),"") -> 0.054767488 | E7: 0 | F7: 209.9 | G7: 1956 | H7: 3339 | I7: 2359 | J7: =IFERROR((I7/F7)^(1/COUNT($G$4:$I$4))-1,"") -> 1.2399509 | K7: =IFERROR(F7-E7/E7,"") | L7: =IFERROR((G7-F7)/F7,"") -> 8.3187232 | M7: =IFERROR((H7-G7)/G7,"") -> 0.70705521 | N7: =IFERROR((I7-H7)/H7,"") -> -0.29350105
B8: Total | D8: =SUM(D6:D7) -> 1 | E8: =SUM(E6:E7) -> 0 | F8: =SUM(F6:F7) -> 2099 | G8: =SUM(G6:G7) -> 11131 | H8: =SUM(H6:H7) -> 22042 | I8: =SUM(I6:I7) -> 43073 | J8: =IFERROR((I8/F8)^(1/COUNT($G$4:$I$4))-1,"") -> 1.7377738 | K8: =IFERROR(F8-E8/E8,"") | L8: =IFERROR((G8-F8)/F8,"") -> 4.3030014 | M8: =IFERROR((H8-G8)/G8,"") -> 0.98023538 | N8: =IFERROR((I8-H8)/H8,"") -> 0.95413302
B10: Segments | D10: Weight | E10: 2020 | F10: =+E10+1 -> 2021 | G10: =+F10+1 -> 2022 | H10: =+G10+1 -> 2023 | I10: =+H10+1 -> 2024 | J10: ="CAGR "&$G$4&" - "&$I$4 -> CAGR 2022 - 2024 | K10: 2021 | L10: =+K10+1 -> 2022 | M10: =+L10+1 -> 2023 | N10: =+M10+1 -> 2024
B12: Specialized quantum computing hardware | D12: =IFERROR(I12/SUM($I$12:$I$13),"") -> 0.50133494 | E12: 0 | F12: 0 | G12: 239 | H12: 7083 | I12: 21594 | J12: =IFERROR((I12/G12)^(1/COUNT($H$4:$I$4))-1,"") -> 8.5053387 | K12: =IFERROR((F12-E12)/E12,"") | L12: =IFERROR((G12-F12)/F12,"") | M12: =IFERROR((H12-G12)/G12,"") -> 28.635983 | N12: =IFERROR((I12-H12)/H12,"") -> 2.0487082
B13: Platform, consulting and support services | D13: =IFERROR(I13/SUM($I$12:$I$13),"") -> 0.49866506 | E13: 0 | F13: 2099 | G13: 10892 | H13: 14959 | I13: 21479 | J13: =IFERROR((I13/G13)^(1/COUNT($H$4:$I$4))-1,"") -> 0.40427839 | K13: =IFERROR((F13-E13)/E13,"") | L13: =IFERROR((G13-F13)/F13,"") -> 4.1891377 | M13: =IFERROR((H13-G13)/G13,"") -> 0.37339332 | N13: =IFERROR((I13-H13)/H13,"") -> 0.43585801
B14: Total | D14: =SUM(D12:D13) -> 1 | E14: =SUM(E12:E13) -> 0 | F14: =SUM(F12:F13) -> 2099 | G14: =SUM(G12:G13) -> 11131 | H14: =SUM(H12:H13) -> 22042 | I14: =SUM(I12:I13) -> 43073 | J14: =IFERROR((I14/G14)^(1/COUNT($H$4:$I$4))-1,"") -> 0.9671409 | K14: =IFERROR((F14-E14)/E14,"") | L14: =IFERROR((G14-F14)/F14,"") -> 4.3030014 | M14: =IFERROR((H14-G14)/G14,"") -> 0.98023538 | N14: =IFERROR((I14-H14)/H14,"") -> 0.95413302
B16: Categories | D16: Description | J16: Graphs
B18: Specialized quantum computing hardware | D18: This segment focuses on building advanced quantum processors using trapped-ion technology. These processors deliver highly accurate and stable qubits, making them ideal for tackling complex problems. IonQ’s hardware powers its cloud services, allowing customers to access cutting-edge quantum computing for various applications.
B19: Platform, consulting and support services | D19: These services provide businesses and researchers with the tools, expertise, and support needed to effectively adopt and utilize quantum computing. They include cloud access, technical assistance, and specialized consulting.
B20: =IF(#REF!=0,"",#REF!) -> #REF!
B21: =IF(#REF!=0,"",#REF!) -> #REF!
B24: Company's Strategy / Extra Notes
B26: Tech Innovation | D26: This year marks the launch of the AQ 64 Tempo system, which is a substantial upgrade over the AQ36 Forte Enterprise. This system doubles the qubit count, improves qubit fidelity to over 99.9% and expands computational capacity by 536 million times, setting new standards in performance.
B27: Strategic Acquisitions | D27: In 2025, the company acquired Qubitekk and ID Quantique, gaining access to a more specialized team and increasing its patent portfolio to over 900 patents. These acquisitions also position the company for expansion into European and Asian markets, accelerating global growth.
B28: Major Partnerships | D28: Partnerships with major companies and entities such as AstraZeneca, Hyundai, U.S. Department of Defense and Airbus will help the company in the long-term, accelerating its growth and increasing its global credibility.
B29: Revenue Scaling | D29: Revenue has doubled in both 2023 and 2024, reflecting strong market demand and growth. Management expects this trend to continue with projections of $75-95 million in revenue for 2025.
B30: First Public Quantum Company | D30: In 2021, the company made history by becoming the first pure-play quantum computing company to go public. This was achieved through a merger with dMY Technology Group III, a special-purpose acquisition company (SPAC).

Sheet Peers
D3: Revenue Growth | F3: EBITDA Margin | H3: Profit Margin | J3: EV / Revenue | L3: EV / EBITDA | N3: Price / Earnings
B4: Peers | C4: Ticker | D4: =+Inputs!O4&"-"&Inputs!P4 -> 2022-2023 | E4: =+Inputs!P4&"-"&Inputs!Q4 -> 2023-2024 | F4: 2023 | G4: 2024 | H4: =+Inputs!O4&"-"&Inputs!P4 -> 2022-2023 | I4: =+Inputs!P4&"-"&Inputs!Q4 -> 2023-2024 | J4: 2023 | K4: 2024 | L4: 2023 | M4: 2024 | N4: 2023 | O4: 2024
A6: =+D91 -> #VALUE! | B6: {=IFERROR(_FV(A6,"Name"),"")} -> IONQ, INC. | C6: {=IFERROR(_FV(A6,"Ticker symbol",TRUE),"")} -> IONQ | D6: =IFERROR(D94/D93-1,"") -> 0.98023538 | E6: =IFERROR(D97/D94-1,"") -> 0.95413302 | F6: =IFERROR(D95/D94,"") -> -6.6862807 | G6: =IFERROR(D100/D97,"") -> -4.9636896 | H6: =IFERROR(D96/D94,"") -> -7.1555688 | I6: =IFERROR(D105/D97,"") -> -7.698281 | J6: {=IFERROR((_FV(A6,"Market cap",TRUE)/1000+D$121-D$111)/D$94,"")} -> 741.23244 | K6: {=IFERROR((_FV(A6,"Market cap",TRUE)/1000+D$121-D$111)/D$97,"")} -> 379.31524 | L6: {=+IFERROR((_FV(A6,"Market cap",TRUE)/1000+D$121-D$111)/D$95,"")} -> -110.85871 | M6: {=IFERROR((_FV(A6,"Market cap",TRUE)/1000+D$121-D$111)/D$100,"")} -> -76.418003 | N6: {=IFERROR((_FV(A6,"Market cap",TRUE)/1000)/D$96,"")} -> -103.82068 | O6: {=IFERROR((_FV(A6,"Market cap",TRUE)/1000)/D$105,"")} -> -49.383303
A8: =+E91 -> #VALUE! | B8: {=IFERROR(_FV(A8,"Name"),"")} -> RIGETTI COMPUTING, INC | C8: {=+IFERROR(_FV(A8,"Ticker symbol",TRUE),"")} -> RGTI | D8: =+IFERROR(E94/E93-1,"") -> -0.083498702 | E8: =IFERROR(E97/E94-1,"") -> -0.10143238 | F8: =IFERROR(E95/E94,"") -> -5.1550633 | G8: =+IFERROR(E100/E97,"") -> -6.3493976 | H8: =IFERROR(E96/E94,"") -> -6.2547468 | I8: =+IFERROR(E105/E99,"") -> -13.563981 | J8: {=+IFERROR((_FV(A8,"Market cap",TRUE)/1000+E$121-E$111)/E$94,"")} -> 517.0603 | K8: {=IFERROR(+(_FV(A8,"Market cap",TRUE)/1000+E$121-E$111)/E$97,"")} -> 575.42726 | L8: {=IFERROR(+(_FV(A8,"Market cap",TRUE)/1000+E$121-E$111)/E$95,"")} -> -100.30145 | M8: {=IFERROR(+(_FV(A8,"Market cap",TRUE)/1000+E$121-E$111)/E$100,"")} -> -90.627064 | N8: {=IFERROR(+(_FV(A8,"Market cap",TRUE)/1000)/E$96,"")} -> -83.450732 | O8: {=IFERROR(+(_FV(A8,"Market cap",TRUE)/1000)/E$105,"")} -> -81.110518
A9: =+F91 -> #VALUE! | B9: {=IFERROR(_FV(A9,"Name"),"")} -> D-WAVE QUANTUM INC. | C9: {=+IFERROR(_FV(A9,"Ticker symbol",TRUE),"")} -> QBTS | D9: =IFERROR(F94/F93-1,"") -> 0.22096752 | E9: =IFERROR(+F97/F94-1,"") -> 0.0078785111 | F9: =IFERROR(F95/F94,"") -> -8.6118977 | G9: =IFERROR(F100/F97,"") -> -8.7484989 | H9: =IFERROR(F96/F94,"") -> -9.4445079 | I9: =+IFERROR(F105/F97,"") -> -8.5258865 | J9: {=IFERROR(+(_FV(A9,"Market cap",TRUE)/1000+F$121-F$111)/F$94,"")} -> 679.96838 | K9: {=IFERROR(+(_FV(A9,"Market cap",TRUE)/1000+F$121-F$111)/F$97,"")} -> 674.65312 | L9: {=IFERROR(+(_FV(A9,"Market cap",TRUE)/1000+F$121-F$111)/F$95,"")} -> -78.956858 | M9: {=IFERROR(+(_FV(A9,"Market cap",TRUE)/1000+F$121-F$111)/F$100,"")} -> -77.116443 | N9: {=IFERROR(+(_FV(A9,"Market cap",TRUE)/1000)/F$96,"")} -> -73.683928 | O9: {=IFERROR(+(_FV(A9,"Market cap",TRUE)/1000)/F$105,"")} -> -80.98496
A10: =+G91 -> #VALUE! | B10: {=IFERROR(_FV(A10,"Name"),"")} -> QUANTUM COMPUTING INC. | C10: {=IFERROR(_FV(A10,"Ticker symbol",TRUE),"")} -> QUBT | D10: =+IFERROR(G94/G93-1,"") -> 1.6323529 | E10: =IFERROR(G97/G94-1,"") -> 0.041899441 | F10: =IFERROR(G95/G94,"") -> -61.768156 | G10: =IFERROR(G100/G97,"") -> -69.536193 | H10: =IFERROR(G96/G94,"") -> -75.480447 | I10: =+IFERROR(G105/G97,"") -> -74.160858 | J10: {=IFERROR(+(_FV(A10,"Market cap",TRUE)/1000+G$121-G$111)/G$94,"")} -> 7372.7681 | K10: {=IFERROR(+(_FV(A10,"Market cap",TRUE)/1000+G$121-G$111)/G$97,"")} -> 7076.2761 | L10: {=IFERROR(+(_FV(A10,"Market cap",TRUE)/1000+G$121-G$111)/G$95,"")} -> -119.36196 | M10: {=IFERROR(+(_FV(A10,"Market cap",TRUE)/1000+G$121-G$111)/G$100,"")} -> -101.76393 | N10: {=IFERROR(+(_FV(A10,"Market cap",TRUE)/1000)/G$96,"")} -> -100.55566 | O10: {=IFERROR(+(_FV(A10,"Market cap",TRUE)/1000)/G$105,"")} -> -98.229159
A11: =+H91 -> N/A | B11: {=IFERROR(_FV(A11,"Name"),"")} | C11: {=IFERROR(_FV(A11,"Ticker symbol",TRUE),"")} | D11: =IFERROR(H94/H93-1,"") | E11: =IFERROR(H97/H94-1,"") | F11: =IFERROR(H95/H94,"") | G11: =IFERROR(H100/H97,"") | H11: =IFERROR(H96/H94,"") | I11: =+IFERROR(H105/H102,"") | J11: {=IFERROR((_FV(A11,"Market cap",TRUE)/1000000+H$121-H$111)/H$94,"")} | K11: {=IFERROR(+(_FV(A11,"Market cap",TRUE)/1000000+H$121-H$111)/H$97,"")} | L11: {=IFERROR(+(_FV(A11,"Market cap",TRUE)/1000000+H$121-H$111)/H$95,"")} | M11: {=IFERROR(+(_FV(A11,"Market cap",TRUE)/1000000+H$121-H$111)/H$100,"")} | N11: {=IFERROR(+(_FV(A11,"Market cap",TRUE)/1000000)/H$96,"")} | O11: {=IFERROR(+(_FV(A11,"Market cap",TRUE)/1000000)/H$105,"")}
A12: =+I91 -> N/A | B12: {=IFERROR(_FV(A12,"Name"),"")} | C12: {=IFERROR(_FV(A12,"Ticker symbol",TRUE),"")} | D12: =+IFERROR(I94/I93-1,"") | E12: =IFERROR(I97/I94-1,"") | F12: =IFERROR(I95/I94,"") | G12: =IFERROR(I100/I97,"") | H12: =IFERROR(I96/I94,"") | I12: =+IFERROR(I105/I97,"") | J12: {=IFERROR((_FV(A12,"Market cap",TRUE)/1000000+I$121-I$111)/I$94,"")} | K12: {=IFERROR(+(_FV(A12,"Market cap",TRUE)/1000000+I$121-I$111)/I$97,"")} | L12: {=IFERROR(+(_FV(A12,"Market cap",TRUE)/1000000+I$121-I$111)/I$95,"")} | M12: {=IFERROR(+(_FV(A12,"Market cap",TRUE)/1000000+I$121-I$111)/I$100,"")} | N12: {=IFERROR(+(_FV(A12,"Market cap",TRUE)/1000000)/I$96,"")} | O12: {=IFERROR(+(_FV(A12,"Market cap",TRUE)/1000000)/I$105,"")}
A13: =+J91 -> N/A | B13: {=IFERROR(_FV(A13,"Name"),"")} | C13: {=IFERROR(_FV(A13,"Ticker symbol",TRUE),"")} | D13: =IFERROR(J94/J93-1,"") | E13: =IFERROR(J97/J94-1,"") | F13: =IFERROR(J95/J94,"") | G13: =IFERROR(J100/J97,"") | H13: =IFERROR(J96/J94,"") | I13: =+IFERROR(J105/J97,"") | J13: {=IFERROR(+(_FV(A13,"Market cap",TRUE)/1000000+J$121-J$111)/J$94,"")} | K13: {=IFERROR(+(_FV(A13,"Market cap",TRUE)/1000000+J$121-J$111)/J$97,"")} | L13: {=IFERROR(+(_FV(A13,"Market cap",TRUE)/1000000+J$121-J$111)/J$95,"")} | M13: {=IFERROR(+(_FV(A13,"Market cap",TRUE)/1000000+J$121-J$111)/J$100,"")} | N13: {=IFERROR(+(_FV(A13,"Market cap",TRUE)/1000000)/J$96,"")} | O13: {=IFERROR(+(_FV(A13,"Market cap",TRUE)/1000000)/J$105,"")}
A14: =+K91 -> N/A | B14: {=IFERROR(_FV(A14,"Name"),"")} | C14: {=IFERROR(_FV(A14,"Ticker symbol",TRUE),"")} | D14: =IFERROR(K94/K93-1,"") | E14: =IFERROR(K97/K94-1,"") | F14: =+IFERROR(K95/K94,"") | G14: =IFERROR(K100/K97,"") | H14: =IFERROR(K96/K94,"") | I14: =+IFERROR(K105/K97,"") | J14: {=IFERROR((_FV(A14,"Market cap",TRUE)/1000000+D$121-K$111)/K$94,"")} | K14: {=IFERROR(+(_FV(A14,"Market cap",TRUE)/1000000+D$121-K$111)/K$97,"")} | L14: {=IFERROR(+(_FV(A14,"Market cap",TRUE)/1000000+D$121-K$111)/K$95,"")} | M14: {=IFERROR(+(_FV(A14,"Market cap",TRUE)/1000000+D$121-K$111)/K$100,"")} | N14: {=IFERROR(+(_FV(A14,"Market cap",TRUE)/1000000)/K$96,"")} | O14: {=IFERROR(+(_FV(A14,"Market cap",TRUE)/1000000)/K$105,"")}
A15: =+L91 -> N/A | B15: {=IFERROR(_FV(A15,"Name"),"")} | C15: {=IFERROR(_FV(A15,"Ticker symbol",TRUE),"")} | D15: =+IFERROR(L94/L93,"") | E15: =IFERROR(L97/L94,"") | F15: =IFERROR(L95/L94,"") | G15: =IFERROR(L100/L97,"") | H15: =IFERROR(L96/L94,"") | I15: =+IFERROR(L105/L97,"") | J15: {=IFERROR(+(_FV(A15,"Market cap",TRUE)/1000000+L$121-L$111)/L$94,"")} | K15: {=IFERROR(+(_FV(A15,"Market cap",TRUE)/1000000+L$121-L$111)/L$97,"")} | L15: {=IFERROR(+(_FV(A15,"Market cap",TRUE)/1000000+L$121-L$111)/L$95,"")} | M15: {=IFERROR(+(_FV(A15,"Market cap",TRUE)/1000000+L$121-L$111)/L$100,"")} | N15: {=IFERROR(+(_FV(A15,"Market cap",TRUE)/1000000)/L$96,"")} | O15: {=IFERROR(+(_FV(A15,"Market cap",TRUE)/1000000)/L$105,"")}
A16: =+M91 -> N/A | B16: {=IFERROR(_FV(A16,"Name"),"")} | C16: {=IFERROR(_FV(A16,"Ticker symbol",TRUE),"")} | D16: =IFERROR(M94/M93-1,"") | E16: =IFERROR(M97/M94-1,"") | F16: =IFERROR(M95/M94,"") | G16: =IFERROR(M100/M97,"") | H16: =IFERROR(M96/M94,"") | I16: =+IFERROR(M105/M97,"") | J16: {=IFERROR(+(_FV(A16,"Market cap",TRUE)/1000000+M$121-M$111)/M$94,"")} | K16: {=IFERROR(+(_FV(A16,"Market cap",TRUE)/1000000+M$121-M$111)/M$97,"")} | L16: {=IFERROR(+(_FV(A16,"Market cap",TRUE)/1000000+M$121-M$111)/M$95,"")} | M16: {=IFERROR(+(_FV(A16,"Market cap",TRUE)/1000000+M$121-M$111)/M$100,"")} | N16: {=IFERROR(+(_FV(A16,"Market cap",TRUE)/1000000)/M$96,"")} | O16: {=IFERROR(+(_FV(A16,"Market cap",TRUE)/1000000)/M$105,"")}
A17: =+N91 -> N/A | B17: {=IFERROR(_FV(A17,"Name"),"")} | C17: {=+IFERROR(_FV(A17,"Ticker symbol",TRUE),"")} | D17: =IFERROR(N94/N93-1,"") | E17: =IFERROR(N97/N94-1,"") | F17: =IFERROR(N95/N94,"") | G17: =IFERROR(N100/N97,"") | H17: =IFERROR(N96/N94,"") | I17: =+IFERROR(N105/N97,"") | J17: {=IFERROR(+(_FV(A17,"Market cap",TRUE)/1000000+N$121-N$111)/N$94,"")} | K17: {=IFERROR(+(_FV(A17,"Market cap",TRUE)/1000000+N$121-N$111)/N$97,"")} | L17: {=IFERROR(+(_FV(A17,"Market cap",TRUE)/1000000+N$121-N$111)/N$95,"")} | M17: {=IFERROR(+(_FV(A17,"Market cap",TRUE)/1000000+N$121-N$111)/N$100,"")} | N17: {=IFERROR(+(_FV(A17,"Market cap",TRUE)/1000000)/N$96,"")} | O17: {=IFERROR(+(_FV(A17,"Market cap",TRUE)/1000000)/N$105,"")}
B18: Average | D18: =IFERROR(AVERAGE(D6:D17),"") -> 0.68751428 | E18: =IFERROR(AVERAGE(E6:E17),"") -> 0.22561965 | F18: =IFERROR(AVERAGE(F6:F17),"") -> -20.55535 | G18: =IFERROR(AVERAGE(G6:G17),"") -> -22.399445 | H18: =IFERROR(AVERAGE(H6:H17),"") -> -24.583818 | I18: =IFERROR(AVERAGE(I6:I17),"") -> -25.987252 | J18: =IFERROR(AVERAGE(J6:J17),"") -> 2327.7573 | K18: =IFERROR(AVERAGE(K6:K17),"") -> 2176.4179 | ... O18: =IFERROR(AVERAGE(O6:O17),"") -> -77.426985
B19: Deviation from Average | D19: =IFERROR(+D18-D6,"") -> -0.2927211 | E19: =IFERROR(E18-E6,"") -> -0.72851337 | F19: =+IFERROR(F18-F6,"") -> -13.869069 | G19: =IFERROR(G18-G6,"") -> -17.435755 | H19: =IFERROR(+H6-H18,"") -> 17.428249 | I19: =+IFERROR(I6-I18,"") -> 18.288971 | J19: =+IFERROR(J6-J18,"") -> -1586.5249 | K19: =+IFERROR(K6-K18,"") -> -1797.1027 | L19: =IFERROR(+L6-L18,"") -> -8.4889649 | M19: =IFERROR(M6-M18,"") -> 10.063356 | N19: =IFERROR(+N6-N18,"") -> -13.442927 | O19: =IFERROR(+O6-O18,"") -> 28.043682 | T19: {=_FV(A6,"Market cap",TRUE)} -> 16374913459
D21: Trading Multiple | G21: Net | H21: Preferred | I21: Non-Controlling | J21: Equity Value | M21: Implied Upside (Downside)
B22: Implied Share Price | D22: Revenue | E22: EBITDA | F22: P/E | G22: Debt | H22: Stock | I22: Interest | J22: Revenue | K22: EBITDA | L22: P/E | M22: Revenue | N22: EBITDA | O22: P/E | P22: Current Price
B24: Second Minimum | D24: =IFERROR(SMALL(K6:K17,2),"") -> 575.42726 | E24: =IFERROR(SMALL(M6:M17,2),"") -> -90.627064 | F24: =IFERROR(SMALL(O6:O17,2),"") -> -81.110518 | G24: =-Inputs!$Q$99+Inputs!$Q$100 -> -322564 | H24: =+Inputs!$Q$101 -> 0 | I24: =+Inputs!$Q$102 -> 0 | J24: =IFERROR(+D24*$D$97+G24+H24+I24,"") -> 24462814 | K24: =IFERROR(E24*$D$100+G24+H24+I24,"") -> 19053593 | L24: =IFERROR(F24*$D$105,"") -> 26895279 | M24: {=IFERROR(+(J24/_FV($A$6,"Shares outstanding",TRUE)*1000000)/$P$24-1,"")} -> 1492.9202 | N24: {=IFERROR((+K24/_FV($A$6,"Shares outstanding",TRUE)*1000000)/$P$24-1,"")} -> 1162.5843 | O24: {=IFERROR(+(L24/_FV($A$6,"Shares outstanding",TRUE)*1000000)/$P$24-1,"")} -> 1641.4685 | P24: {=+_FV(A6,"Price")} -> 55.008
B25: Average | D25: =+IFERROR(AVERAGE(K6:K17),"") -> 2176.4179 | E25: =IFERROR(+AVERAGE(M6:M17),"") -> -86.481359 | F25: =IFERROR(+AVERAGE(O6:O17),"") -> -77.426985 | G25: =-Inputs!$Q$99+Inputs!$Q$100 -> -322564 | H25: =+Inputs!$Q$101 -> 0 | I25: =+Inputs!$Q$102 -> 0 | J25: =IFERROR(+D25*$D$97+G25+H25+I25,"") -> 93422286 | K25: =IFERROR(E25*$D$100+G25+H25+I25,"") -> 18167237 | L25: =IFERROR(+F25*$D$105,"") -> 25673864 | M25: {=IFERROR(+(J25/_FV($A$6,"Shares outstanding",TRUE)*1000000)/$P$24-1,"")} -> 5704.2079 | N25: {=IFERROR((+K25/_FV($A$6,"Shares outstanding",TRUE)*1000000)/$P$24-1,"")} -> 1108.4555 | O25: {=IFERROR(+(L25/_FV($A$6,"Shares outstanding",TRUE)*1000000)/$P$24-1,"")} -> 1566.8778
B26: Median | D26: =IFERROR(MEDIAN(K6:K17),"") -> 625.04019 | E26: =IFERROR(MEDIAN(M6:M17),"") -> -83.871754 | F26: =IFERROR(MEDIAN(O6:O17),"") -> -81.047739 | G26: =-Inputs!$Q$99+Inputs!$Q$100 -> -322564 | H26: =+Inputs!$Q$101 -> 0 | I26: =+Inputs!$Q$102 -> 0 | J26: =IFERROR(D26*$D$97+G26+H26+I26,"") -> 26599792 | K26: =IFERROR(E26*$D$100+G26+H26+I26,"") -> 17609301 | L26: =IFERROR(+F26*$D$105,"") -> 26874462 | M26: {=IFERROR(+(J26/_FV($A$6,"Shares outstanding",TRUE)*1000000)/$P$24-1,"")} -> 1623.4234 | N26: {=IFERROR((+K26/_FV($A$6,"Shares outstanding",TRUE)*1000000)/$P$24-1,"")} -> 1074.3828 | O26: {=+IFERROR((L26/_FV($A$6,"Shares outstanding",TRUE)*1000000)/$P$24-1,"")} -> 1640.1972
B27: Second Maximum | D27: =IFERROR(LARGE(K6:K17,2),"") -> 674.65312 | E27: =IFERROR(LARGE(M6:M17,2),"") -> -77.116443 | F27: =IFERROR(LARGE(O6:O17,2),"") -> -80.98496 | G27: =-Inputs!$Q$99+Inputs!$Q$100 -> -322564 | H27: =+Inputs!$Q$101 -> 0 | I27: =+Inputs!$Q$102 -> 0 | J27: =IFERROR(+D27*$D$97+G27+H27+I27,"") -> 28736770 | K27: =IFERROR(E27*$D$100+G27+H27+I27,"") -> 16165009 | L27: =IFERROR(+F27*$D$105,"") -> 26853646 | M27: {=IFERROR(+(J27/_FV($A$6,"Shares outstanding",TRUE)*1000000)/$P$24-1,"")} -> 1753.9265 | N27: {=IFERROR((+K27/_FV($A$6,"Shares outstanding",TRUE)*1000000)/$P$24-1,"")} -> 986.18132 | O27: {=IFERROR(+(L27/_FV($A$6,"Shares outstanding",TRUE)*1000000)/$P$24-1,"")} -> 1638.926
B29: Profitability | D29: =+LEFT(B6, FIND(" ", B6 & " ") - 1) -> IONQ, | E29: =+LEFT(B8, FIND(" ", B8 & " ") - 1) -> RIGETTI | F29: =+LEFT(B9, FIND(" ", B9 & " ") - 1) -> D-WAVE | G29: =+LEFT(B10, FIND(" ", B10 & " ") - 1) -> QUANTUM | H29: =+LEFT(B11, FIND(" ", B11 & " ") - 1) | I29: =+LEFT(B12, FIND(" ", B12 & " ") - 1) | J29: =+LEFT(B13, FIND(" ", B13 & " ") - 1) | K29: =+LEFT(B14, FIND(" ", B14 & " ") - 1) | L29: =+LEFT(B15, FIND(" ", B15 & " ") - 1) | M29: =+LEFT(B16, FIND(" ", B16 & " ") - 1) | N29: =+LEFT(B17, FIND(" ", B17 & " ") - 1) | O29: Average
B31: Operating Margin | D31: =IFERROR(D101/D97,"") -> -5.3967683 | E31: =IFERROR(E101/E97,"") -> -6.9894347 | F31: =IFERROR(F101/F97,"") -> -8.9673728 | G31: =IFERROR(G101/G97,"") -> -79.718499 | H31: =IFERROR(H101/H97,"") | I31: =IFERROR(I101/I97,"") | J31: =IFERROR(J101/J97,"") | K31: =IFERROR(K101/K97,"") | ... N31: =IFERROR(N101/N97,"") | O31: =IFERROR(+AVERAGE(D31:N31),"") -> -25.268019
B32: Net Income Margin | D32: =IFERROR(D105/D97,"") -> -7.698281 | E32: =IFERROR(E105/E97,"") -> -7.1616311 | F32: =IFERROR(F105/F97,"") -> -8.5258865 | G32: =IFERROR(G105/G97,"") -> -74.160858 | H32: =IFERROR(H105/H97,"") | I32: =IFERROR(I105/I97,"") | J32: =IFERROR(J105/J97,"") | K32: =IFERROR(K105/K97,"") | ... N32: =IFERROR(N105/N97,"") | O32: =IFERROR(+AVERAGE(D32:N32),"") -> -24.386664
B33: ROA (%) | D33: =IFERROR(D105/D117,"") -> -0.65223424 | E33: =IFERROR(E105/E117,"") -> -0.27133963 | F33: =IFERROR(F105/F117,"") -> -0.37656678 | G33: =IFERROR(G105/G117,"") -> -0.18013923 | H33: =IFERROR(H105/H117,"") | I33: =IFERROR(I105/I117,"") | J33: =IFERROR(J105/J117,"") | K33: =IFERROR(K105/K117,"") | ... N33: =IFERROR(N105/N117,"") | O33: =IFERROR(+AVERAGE(D33:N33),"") -> -0.37006997
B34: Financial Cost of Debt | D34: =IFERROR(+(D102/D121)*(1-(D104/D103)),"") -> -1.0295629 | E34: =IFERROR(+(E102/E121)*(1-(E104/E103)),"") -> 0.21113636 | F34: =IFERROR(+(F102/F121)*(1-(F104/F103)),"") -> -0.1015452 | G34: =IFERROR(+(G102/G121)*(1-(G104/G103)),"") -> -1.7552921 | H34: =IFERROR(+(H102/H121)*(1-(H104/H103)),"") | I34: =IFERROR(+(I102/I121)*(1-(I104/I103)),"") | J34: =IFERROR(+(J102/J121)*(1-(J104/J103)),"") | K34: =IFERROR(+(K102/K121)*(1-(K104/K103)),"") | ... N34: =IFERROR(+(N102/N121)*(1-(N104/N103)),"") | O34: =IFERROR(+AVERAGE(D34:N34),"") -> -0.66881598
B35: Return on Equity (RoE) | D35: =IFERROR(+D105/D122,"") -> -0.86382101 | E35: =IFERROR(+E105/E122,"") -> -0.61043219 | F35: =IFERROR(+F105/F122,"") -> -1.2013217 | G35: =IFERROR(+G105/G122,"") -> -0.2578318 | H35: =IFERROR(+H105/H122,"") | I35: =IFERROR(+I105/I122,"") | J35: =IFERROR(+J105/J122,"") | K35: =IFERROR(+K105/K122,"") | ... N35: =IFERROR(+N105/N122,"") | O35: =IFERROR(+AVERAGE(D35:N35),"") -> -0.73335168
B36: Return on Invested Capital (ROIC) | D36: =IFERROR(+D105/(D121+D122),"") -> -0.82569421 | E36: =IFERROR(+E105/(E121+E122),"") -> -0.57075538 | F36: =IFERROR(+F105/(F121+F122),"") -> -0.74495907 | G36: =IFERROR(+G105/(G121+G122),"") -> -0.25502452 | H36: =IFERROR(+H105/(H121+H122),"") | I36: =IFERROR(+I105/(I121+I122),"") | J36: =IFERROR(+J105/(J121+J122),"") | K36: =IFERROR(+K105/(K121+K122),"") | ... N36: =IFERROR(+N105/(N121+N122),"") | O36: =IFERROR(+AVERAGE(D36:N36),"") -> -0.59910829
B38: Solvency | D38: =+D29 -> IONQ, | E38: =+E29 -> RIGETTI | F38: =+F29 -> D-WAVE | G38: =+G29 -> QUANTUM | H38: =+H29 | I38: =+I29 | J38: =+J29 | K38: =+K29 | ... O38: =+O29 -> Average
B40: Debt/Assets | D40: =IFERROR(D121/D117,"") -> 0.034865103 | E40: =IFERROR(E121/E117,"") -> 0.030900287 | F40: =IFERROR(F121/F117,"") -> 0.19202614 | G40: =IFERROR(G121/G117,"") -> 0.007690855 | H40: =IFERROR(H121/H117,"") | I40: =IFERROR(I121/I117,"") | J40: =IFERROR(J121/J117,"") | K40: =IFERROR(K121/K117,"") | ... N40: =IFERROR(N121/N117,"") | O40: =IFERROR(+AVERAGE(D40:N40),"") -> 0.066370596
B41: Net Debt/EBITDA | D41: =IFERROR(+(D121-D111)/D100,"") -> 0.17150528 | E41: =IFERROR(+(E121-E111)/E100,"") -> 0.859349 | F41: =IFERROR(+(F121-F111)/F100,"") -> 1.8077904 | G41: =IFERROR(+(G121-G111)/G100,"") -> 2.9981879 | H41: =IFERROR(+(H121-H111)/H100,"") | I41: =IFERROR(+(I121-I111)/I100,"") | J41: =IFERROR(+(J121-J111)/J100,"") | K41: =IFERROR(+(K121-K111)/K100,"") | ... N41: =IFERROR(+(N121-N111)/N100,"") | O41: =IFERROR(+AVERAGE(D41:N41),"") -> 1.4592082
B42: Interest Coverage Ratio | D42: =IFERROR(D101/D102,"") -> 12.737958 | E42: =IFERROR(E101/E102,"") -> -40.589882 | F42: =IFERROR(F101/F102,"") -> 20.311778 | G42: =IFERROR(G101/G102,"") -> 14.343946 | H42: =IFERROR(H101/H102,"") | I42: =IFERROR(I101/I102,"") | J42: =IFERROR(J101/J102,"") | K42: =IFERROR(K101/K102,"") | ... N42: =IFERROR(N101/N102,"") | O42: =IFERROR(+AVERAGE(D42:N42),"") -> 1.7009502
B44: Liquidity | D44: =+D29 -> IONQ, | E44: =+E29 -> RIGETTI | F44: =+F29 -> D-WAVE | G44: =+G29 -> QUANTUM | H44: =+H29 | I44: =+I29 | J44: =+J29 | K44: =+K29 | ... O44: =+O29 -> Average
B46: Cash Ratio | D46: =IFERROR(D111/D119,"") -> 1.5073576 | E46: =IFERROR(E111/E119,"") -> 5.702705 | F46: =IFERROR(F111/F119,"") -> 5.90413 | G46: =IFERROR(G111/G119,"") -> 17.316297 | H46: =IFERROR(H111/H119,"") | I46: =IFERROR(I111/I119,"") | J46: =IFERROR(J111/J119,"") | K46: =IFERROR(K111/K119,"") | ... N46: =IFERROR(N111/N119,"") | O46: =IFERROR(+AVERAGE(D46:N46),"") -> 7.6076225
B47: Quick Ratio | D47: =IFERROR(+(D111+D112)/D119,"") -> 1.6879313 | E47: =IFERROR(+(E111+E112)/E119,"") -> 5.9072217 | F47: =IFERROR(+(F111+F112)/F119,"") -> 5.9512357 | G47: =IFERROR(+(G111+G112)/G119,"") -> 17.32222 | H47: =IFERROR(+(H111+H112)/H119,"") | I47: =IFERROR(+(I111+I112)/I119,"") | J47: =IFERROR(+(J111+J112)/J119,"") | K47: =IFERROR(+(K111+K112)/K119,"") | ... N47: =IFERROR(+(N111+N112)/N119,"") | O47: =IFERROR(+AVERAGE(D47:N47),"") -> 7.7171521
B48: Current Ratio | D48: =IFERROR(D115/D119,"") -> 10.497492 | E48: =IFERROR(E115/E119,"") -> 17.422938 | F48: =IFERROR(F115/F119,"") -> 6.1383314 | G48: =IFERROR(G115/G119,"") -> 17.361483 | H48: =IFERROR(H115/H119,"") | I48: =IFERROR(I115/I119,"") | J48: =IFERROR(J115/J119,"") | K48: =IFERROR(K115/K119,"") | ... N48: =IFERROR(N115/N119,"") | O48: =IFERROR(+AVERAGE(D48:N48),"") -> 12.855061
B50: Activity | D50: =+D29 -> IONQ, | E50: =+E29 -> RIGETTI | F50: =+F29 -> D-WAVE | G50: =+G29 -> QUANTUM | H50: =+H29 | I50: =+I29 | J50: =+J29 | K50: =+K29 | ... O50: =+O29 -> Average
B52: Inventory Turnover | D52: =IFERROR(D98/(AVERAGE(D113:D114)),"") | E52: =IFERROR(E98/(AVERAGE(E113:E114)),"") | F52: =IFERROR(F98/(AVERAGE(F113:F114)),"") -> 1.7343252 | G52: =IFERROR(G98/(AVERAGE(G113:G114)),"") -> 5.7362637 | H52: =IFERROR(H98/(AVERAGE(H113:H114)),"") | I52: =IFERROR(I98/(AVERAGE(I113:I114)),"") | J52: =IFERROR(J98/(AVERAGE(J113:J114)),"") | K52: =IFERROR(K98/(AVERAGE(K113:K114)),"") | ... N52: =IFERROR(N98/(AVERAGE(N113:N114)),"") | O52: =IFERROR(+AVERAGE(D52:N52),"") -> 3.7352945
B53: Acc. Receivable Turnover | D53: =IFERROR(D97/D112,"") -> 6.6103438 | E53: =IFERROR(E97/E112,"") -> 4.4458179 | F53: =IFERROR(F97/F112,"") -> 6.2161972 | G53: =IFERROR(G97/G112,"") -> 13.814815 | H53: =IFERROR(H97/H112,"") | I53: =IFERROR(I97/I112,"") | J53: =IFERROR(J97/J112,"") | K53: =IFERROR(K97/K112,"") | ... N53: =IFERROR(N97/N112,"") | O53: =IFERROR(+AVERAGE(D53:N53),"") -> 7.7717934
B54: Payables Turnover | D54: =IFERROR(D98/D118,"") -> 3.9382409 | E54: =IFERROR(E98/E118,"") -> 3.2031447 | F54: =IFERROR(F98/F118,"") -> 4.004908 | G54: =IFERROR(G98/G118,"") -> 0.19023324 | H54: =IFERROR(H98/H118,"") | I54: =IFERROR(I98/I118,"") | J54: =IFERROR(J98/J118,"") | K54: =IFERROR(K98/K118,"") | ... N54: =IFERROR(N98/N118,"") | O54: =IFERROR(+AVERAGE(D54:N54),"") -> 2.8341317
...

Sheet ESG
B2: Environmental, Social and Governance Analysis
B4: Author: | C4: Cristina Lin | E4: Highlights
B6: Overview | E6: Educational Initiatives | G6: IonQ actively supports quantum education and workforce development. It collaborates with institutions like Sungkyunkwan University to provide quantum cloud resources for competitions and training programs
B7: Last Update | C7: 45768
B8: Latest year with data | C8: 2024 | E8: Weak environmental contribution | F8: It was not possible to assess the company's environmental commitment.
B9: GICS Sector
B10: GICS Industry Group
B11: Final Review | E11: High rotativity of directors | G11: IonQ divides its directors into three classes with overlapping three-year terms. This approach ensures that only a portion of the board is up for election each year, but at the same time, there is a high rotativity of the members of the board.
B13: ESG Scores
B14: LSEG ESG Score | C14: 32
B15: E-Score | C15: 0
B16: S-Score | C16: 26
B17: G-Score | C17: 47
B18: S&P Global ESG Score | C18: N/A
B19: Environmental | C19: N/A
B20: Social | C20: N/A
B21: Governance & Economic | C21: N/A
B22: Sustainalytics | C22: 20
B23: ISS ESG Corporate Rating | C23: D
B24: SDG Impact Rating | C24: -8.4
B25: Governance Quality Score | C25: 8
B26: MSCI ESG Ratings | C26: N/A
B29: Industry ESG Overview: | C29: Adequate
B30: Companies in the quantum computing industry often do not disclose ESG parameters due to their early-stage focus, lack of standard frameworks, and smaller market share at the moment. As the industry grows and attracts more institutional attention, ESG practices and transparency are expected to become more common and integrated into business strategies.
E33: ENVIRONMENTAL
E35: Comments
E36: The compay and its peers do not disclose any information regarding this matter as they are in early-growth stage (currently having a minimal footprint)
E46: SOCIAL
B48: Important Sources: | G48: Overview | H48: Targets | K48: Improvements | O48: Comments
B49: Annual Report | C49: https://www.sec.gov/ix?doc=/Archives/edgar/data/1824920/000095017025027722/ionq-20241231.htm | E49: Community Involvement | H49: N/A | K49: N/A | O49: IonQ actively supports quantum education and workforce development. It collaborates with Sungkyunkwan University in educational programs and with Hyundai Motors for years applying quantum computing to projects.
B50: Sustainability Report | C50: N/A
B51: Proxy Statement | C51: https://www.sec.gov/Archives/edgar/data/1824920/000119312524114115/d104516ddef14a.htm#toc | E51: Public Sector | H51: N/A | K51: N/A | O51: IonQ Announces Largest U.S. Quantum Contract Award of $54.5M with United States Air Force Research Lab in 2024.
E53: Litigation | H53: N/A | K53: N/A | O53: The company was invovled in a consolidated securities fraud class action. The plaintiffs alleged that IonQ and the special purpose acquisition company (SPAC) into which it merged, dMY Technology Group, misled investors about IonQ’s quantum computing technology, thereby inflating IonQ’s share price. On 8th April 2025, Cooley secured an appellate win on behalf of IonQ.
E55: GOVERNANCE
G57: Overview | H57: Targets | K57: Improvements | O57: Comments
E58: Diversity (Gender, Age, Industry, Region) | H58: N/A | K58: N/A | O58: 37.5% of board members are female (Gabrielle Toledano was appointed for the board in February 2025, so theproxy as of June 2024 only had 25% of female directors).
E60: % Independence | H60: N/A | K60: N/A | O60: 80% of the board members are independent (only CEO&President and Scientific Advisor Jungsang Kim were not).
E62: Average time as independent directors | H62: N/A | K62: N/A | O62: N/A
E64: Departures of C-level executives | H64: N/A | K64: N/A | O64: Harry You departed in February 2025 to lead a private AI-healthcare company. Craig Barratt chose not to stand for re-election at the June 2024 Annual Meeting, concluding his term as Chairman. Jungsang Kim also did not seek re-election in June 2024, ending his tenure as a director and co-founder.
E66: CEO/Chairman duality | H66: N/A | K66: N/A | O66: Peter Chapman is the Chairman (as of June 2024) while Niccolo de Masi is the CEO (Niccolo was the CEO of the predecessor, dMY Technology Group, Inc. III, a special purpose acquisition company). In the report for 2024, Peter was the CEO and Crag Barratt was the Chairman.
...

Sheet DCF
B2: DCF
A4: x | B4: Key Assumptions | AA4: #VALUE!
B6: Switches | E6: Bear Case | H6: Base Case | K6: Bull Case | AG6: FCFF | AH6: FCFE | AI6: Tax Shield | AJ6: Total Payout | AK6: NOPAT | AL6: Debt Borrowing | AM6: Cash Balance | AN6: Total Assets | AO6: Total Liabilities | AP6: Shareholder's Equity | AQ6: Current Liabilities | AR6: Current Assets
B7: Revenue | C7: 2 | E7: Revenue | F7: -0.02 | H7: Revenue | K7: Revenue | L7: 0.02 | AB7: Most Recent Fiscal Year | AC7: 2024 | AF7: 2022 | AG7: =+E194 -> -64536 | AH7: =+E246 -> -27301 | AI7: =+H218 -> 0 | AJ7: =+E259 -> -905 | AK7: =+E184 -> -85746 | AL7: =+E244 -> 0 | AM7: =+E89 -> 355797
B8: EBIT | C8: 2 | E8: EBIT | F8: -0.01 | H8: EBIT | K8: EBIT | L8: 0.01 | AB8: End of Fiscal Year | AC8: 45657 | AF8: =+AF7+1 -> 2023 | AG8: =+F194 -> -113850.05 | AH8: =+F246 -> -113819.05 | AI8: =+I218 -> 0 | AJ8: =+F259 -> 1954 | AK8: =+F184 -> -157754.05 | AL8: =+F244 -> 0 | AM8: =+F89 -> 355441
B9: WACC | C9: 2 | E9: WACC | F9: =IFERROR(+I9+0.5%,"") -> 0.13452675 | H9: WACC | I9: =WACC!G25 -> 0.12952675 | K9: WACC | L9: =IFERROR(I9-0.5%,"") -> 0.12452675 | AB9: Most Recent Quarter End Date | AC9: 45726 | AF9: =+AF8+1 -> 2024 | AG9: =+G194 -> -146246.04 | AH9: =+G246 -> -245379.06 | AI9: =+J218 -> 0 | AJ9: =+G259 -> 41449 | AK9: =+G184 -> -232455.04 | AL9: =+G244 -> 0 | AM9: =+G89 -> 340289 | AN9: =Inputs!Q48 -> 508388 | AO9: =+Inputs!Q60 -> 124526 | AP9: =+AN9-AO9 -> 383862 | AQ9: =+Inputs!Q54 -> 36085 | AR9: =+Inputs!Q38 -> 378802
B10: TGR | C10: 2 | E10: TGR | F10: =+I10-0.5% -> 0.015 | H10: TGR | I10: 0.02 | K10: TGR | L10: =+I10+0.5% -> 0.025 | AB10: Valuation Date | AC10: 45769 | AF10: =+AF9+1 -> 2025 | AG10: =+H194 -> -112020.3 | AH10: =+H246 -> 76542.223 | AI10: =+K218 -> 0 | AJ10: =+H259 -> 0 | AK10: =+H184 -> -224628.41 | AL10: =+H244 -> 245379.06 | AM10: =+H89 -> 54852.613 | AN10: =Inputs!Q48+DCF!H89+DCF!H91+DCF!H94+DCF!H97+DCF!H100+DCF!H106-DCF!G89-DCF!G91-DCF!G94-DCF!G97-DCF!G100-DCF!G106 -> 295226.38 | AO10: =+Inputs!Q60+(DCF!H111+DCF!H114+DCF!H117+DCF!H119*DCF!G111*DCF!G114*DCF!G117*DCF!G119) -> 424706.2 | AP10: =+AN10-AO10 -> -129479.82 | AQ10: =+AQ9+H111+H114-G111-G114 -> 58167.14 | AR10: =+H89+H91+H94+H97 -> 101369.18
AF11: =+AF10+1 -> 2026 | AG11: =+I194 -> -188326.8 | AH11: =+I246 -> -291521.22 | AI11: =+L218 -> 0 | AJ11: =+I259 -> 0 | AK11: =+I184 -> -275369.77 | AL11: =+I244 -> 0 | AM11: =+I89 -> -453756.34 | AN11: =AN10+DCF!I89+DCF!I91+DCF!I94+DCF!I97+DCF!I100+DCF!I106-DCF!H89-DCF!H91-DCF!H94-DCF!H97-DCF!H100-DCF!H106 -> -113659.55 | AO11: =AO10+(DCF!I111+DCF!I114+DCF!I117+DCF!I119*DCF!H111*DCF!H114*DCF!H117*DCF!H119) -> 1.0421837e+23 | AP11: =+AN11-AO11 -> -1.0421837e+23 | AQ11: =+AQ10+I111+I114-H111-H114 -> 72087.335 | AR11: =+I89+I91+I94+I97 -> -388421.46
B12: WACC | C12: =CHOOSE(C9,F9,I9,L9) -> 0.12952675 | AF12: =+AF11+1 -> 2027 | AG12: =+J194 -> -232576.45 | AH12: =+J246 -> -79751.71 | AI12: =+M218 -> 0 | AJ12: =+J259 -> 0 | AK12: =+J184 -> -332893.95 | AL12: =+J244 -> 291521.22 | AM12: =+J89 -> -703982.19
B13: TGR | C13: =CHOOSE(C10,F10,I10,L10) -> 0.02 | AF13: =+AF12+1 -> 2028 | AG13: =+K194 -> -318961.71 | AH13: =+K246 -> -388563.72 | AI13: =+N218 -> 0 | AJ13: =+K259 -> 0 | AK13: =+K184 -> -400174.95 | AL13: =+K244 -> 79751.71 | AM13: =+K89 -> -1467316.1
AF14: =+AF13+1 -> 2029 | AG14: =+L194 -> -376231.76 | AH14: =+L246 -> -183290.35 | AI14: =+O218 -> 0 | AJ14: =+L259 -> 0 | AK14: =+L184 -> -447618.39 | AL14: =+L244 -> 388563.72 | AM14: =+L89 -> -2031772.6
A15: x | B15: Market and Growth Assumptions | E15: 2022 | F15: =+E15+1 -> 2023 | G15: =+F15+1 -> 2024 | H15: =+G15+1 -> 2025 | I15: =+H15+1 -> 2026 | J15: =+I15+1 -> 2027 | K15: =+J15+1 -> 2028 | L15: =+K15+1 -> 2029 | M15: =+L15+1 -> 2030 | ... Z15: =+Y15+1 -> 2043
B17: Market Size (Fortune Business Insights) | E17: 695400 | F17: 885400 | G17: 1160100 | H17: =G17*(1+H18) -> 1508130 | I17: =H17*(1+I18) -> 1968109.6 | J17: =I17*(1+J18) -> 2568383.1 | K17: =J17*(1+K18) -> 3351739.9 | L17: =K17*(1+L18) -> 4374020.6 | M17: =L17*(1+M18) -> 5708096.9 | N17: =M17*(1+N18) -> 7449066.5 | O17: =N17*(1+O18) -> 9721031.7 | ... Z17: =Y17*(1+Z18) -> 1.8881471e+08
B18: Growth Rate | E18: - | F18: =F17/E17-1 -> 0.27322404 | G18: =G17/F17-1 -> 0.31025525 | H18: 0.3 | I18: 0.305 | J18: 0.305 | K18: 0.305 | L18: 0.305 | M18: 0.305 | N18: 0.305 | O18: 0.305 | P18: 0.305 | Q18: 0.31 | R18: 0.31 | S18: 0.31 | T18: 0.31 | U18: 0.31 | V18: 0.31 | W18: 0.31 | X18: 0.31 | Y18: 0.31 | Z18: 0.31
B19: Market Size (Statista) | E19: 695400 | F19: 885400 | G19: 1160100 | H19: =G19*(1+H20) -> 1498849.2 | I19: =H19*(1+I20) -> 1936513.2 | J19: =I19*(1+J20) -> 2501975 | K19: =J19*(1+K20) -> 3232551.7 | L19: =K19*(1+L20) -> 4266968.3 | M19: =L19*(1+M20) -> 5632398.1 | N19: =M19*(1+N20) -> 7434765.5 | O19: =N19*(1+O20) -> 9813890.5 | ... Z19: =Y19*(1+Z20) -> 2.2770062e+08
B20: Growth Rate | H20: 0.292 | I20: 0.292 | J20: 0.292 | K20: 0.292 | L20: 0.32 | M20: 0.32 | N20: 0.32 | O20: 0.32 | P20: 0.32 | Q20: 0.32 | R20: 0.32 | S20: 0.32 | T20: 0.33 | U20: 0.33 | V20: 0.34 | W20: 0.34 | X20: 0.34 | Y20: 0.34 | Z20: 0.34
B21: Average | E21: 695400 | F21: 885400 | G21: 1160100 | H21: =(H17+H19)/2 -> 1503489.6 | I21: =(I17+I19)/2 -> 1952311.4 | J21: =(J17+J19)/2 -> 2535179.1 | K21: =(K17+K19)/2 -> 3292145.8 | L21: =(L17+L19)/2 -> 4320494.4 | M21: =(M17+M19)/2 -> 5670247.5 | N21: =(N17+N19)/2 -> 7441916 | O21: =(O17+O19)/2 -> 9767461.1 | ... Z21: =(Z17+Z19)/2 -> 2.0825766e+08
B22: Average (%) | H22: =(H18+H20)/2 -> 0.296 | I22: =(I18+I20)/2 -> 0.2985 | J22: =(J18+J20)/2 -> 0.2985 | K22: =(K18+K20)/2 -> 0.2985 | L22: =(L18+L20)/2 -> 0.3125 | M22: =(M18+M20)/2 -> 0.3125 | N22: =(N18+N20)/2 -> 0.3125 | O22: =(O18+O20)/2 -> 0.3125 | ... Z22: =(Z18+Z20)/2 -> 0.325 | AX22: 0.6 | AY22: 0.6 | AZ22: 0.5 | BA22: 0.5 | BB22: 0.5 | BC22: 0.4 | BD22: 0.4 | BE22: 0.4 | BF22: 0.3 | BG22: 0.3 | BH22: 0.3 | BI22: 0.25 | BJ22: 0.25 | BK22: 0.25 | BL22: 0.25 | BM22: 0.25 | BN22: 0.2 | BO22: 0.2 | BP22: 0.2 | BQ22: =AVERAGE(AX22:BP22) -> 0.35
