Workbook
Name COOLFUCNTION: _xlfn.LAMBDA(_xldudf_BOARDFLARE_EXEC("workbook-settings:coolfucntion"))
Name COOLFUCNTION: _xlfn.LAMBDA(_xldudf_BOARDFLARE_EXEC("workbook-settings:coolfucntion"))
Name COOLFUCNTION: _xlfn.LAMBDA(_xldudf_BOARDFLARE_EXEC("workbook-settings:coolfucntion"))
Name COOLFUCNTION: _xlfn.LAMBDA(_xldudf_BOARDFLARE_EXEC("workbook-settings:coolfucntion"))
Name COOLFUCNTION: _xlfn.LAMBDA(_xldudf_BOARDFLARE_EXEC("workbook-settings:coolfucntion"))
Name COOLFUCNTION: _xlfn.LAMBDA(_xldudf_BOARDFLARE_EXEC("workbook-settings:coolfucntion"))
Name COOLFUCNTION: _xlfn.LAMBDA(_xldudf_BOARDFLARE_EXEC("workbook-settings:coolfucntion"))
Name COOLFUCNTION: _xlfn.LAMBDA(_xldudf_BOARDFLARE_EXEC("workbook-settings:coolfucntion"))
Name COOLFUCNTION: _xlfn.LAMBDA(_xldudf_BOARDFLARE_EXEC("workbook-settings:coolfucntion"))
Name COOLFUCNTION: _xlfn.LAMBDA(_xldudf_BOARDFLARE_EXEC("workbook-settings:coolfucntion"))
Name Sectors: #REF!
Name Sectors: #REF!
Name Sectors: #REF!

Sheet Summary
E2: | EQUITY RESEARCH | U2: Lisbon Investment Society Equity Research
U3: April 27th, 2025
D6: {=+_FV(#REF!,"Name")} -> #VALUE! | U6: Strong Sell
D8: Rocket Lab USA, Inc. is an end-to-end space company. The Company designs and manufactures small and medium-class rockets, spacecraft and spacecraft components, and related software and services to support the space economy. The Company delivers reliable launch services, satellite manufacture, spacecraft design services, spacecraft components, spacecraft manufacturing, and other spacecraft and on-orbit management solutions that make it easier to access space. Its Launch Services segment provides launch and launch-related services to customers on a dedicated mission or ride-share basis. Its Space Systems segment comprises the design and manufacture of spacecraft components and spacecraft program management services, space data applications, and mission operations. Its space systems solutions are the building blocks for spacecraft, which include composite structures, reaction wheels, star trackers, solar solutions, radios, separation systems, and command and control spacecraft software. | U8: #VALUE!
U9: {=+"Price (7 Mar 25): $"&_FV(#REF!,"Price")} -> #VALUE!
D10: Investment Thesis | U10: ="Price Target: $" & ROUND(IF(Summary!G25="FCFF",#REF!,IF(Summary!G25="FCFE",#REF!,IF(Summary!G25="Tax Shield",#REF!,#REF!))),2) &" "&IF(Summary!G25="FCFF","(FCFF)",IF(Summary!G25="FCFE","(FCFE)",IF(Summary!G25="Tax Shield","(APV)","(DDM)"))) -> #REF!
D11: The DCF implies a –130% downside to intrinsic value by 2034, well below current market levels, flagging deeply negative free-cash-flow projections and ongoing investment burn . Persistent sub-$100 M annual gross profit relative to over $400 M R&D and SG&A spend underscores structural unprofitability and likely dilution .With net operating losses persisting (–61% EBIT margin in 2029E) and no path to sustainable cash generation, a Strong Sell stance is warranted . | U11: =+"Upside (Downside): "&ROUND((#REF!*100),2)&"%" -> #REF!
U14: =+Industry!E28&", "&ESG!C9 -> , Industrials
U15: =+ESG!C10 -> Aerospace & Defense
D17: Operating Metrics | F17: 2023 | G17: =+F17+1 -> 2024 | H17: =+G17+1 -> 2025 | I17: =+H17+1 -> 2026 | K17: Valuation Multiples | N17: 2022 | O17: =+N17+1 -> 2023 | P17: =+O17+1 -> 2024 | Q17: =+P17+1 -> 2025 | R17: =+Q17+1 -> 2026 | U17: Jorge Daniel Vieira Freitas
K18: EV / Sales | N18: =IFERROR(_xlfn.XLOOKUP($K18,Multiples!$B:$B,Multiples!N:N),"") | O18: =IFERROR(_xlfn.XLOOKUP($K18,Multiples!$B:$B,Multiples!O:O),"") | P18: =IFERROR(_xlfn.XLOOKUP($K18,Multiples!$B:$B,Multiples!P:P),"") | Q18: =IFERROR(_xlfn.XLOOKUP($K18,Multiples!$B:$B,Multiples!Q:Q),"") | R18: =IFERROR(_xlfn.XLOOKUP($K18,Multiples!$B:$B,Multiples!R:R),"") | U18: vieirafreitasjorgedaniel@gmail.com
K19: Price / Sales | N19: =IFERROR(_xlfn.XLOOKUP($K19,Multiples!$B:$B,Multiples!N:N),"") | O19: =IFERROR(_xlfn.XLOOKUP($K19,Multiples!$B:$B,Multiples!O:O),"") | P19: =IFERROR(_xlfn.XLOOKUP($K19,Multiples!$B:$B,Multiples!P:P),"") | Q19: =IFERROR(_xlfn.XLOOKUP($K19,Multiples!$B:$B,Multiples!Q:Q),"") | R19: =IFERROR(_xlfn.XLOOKUP($K19,Multiples!$B:$B,Multiples!R:R),"") | U19: (+351) 935 907 954
K20: EV / EBITDA | N20: =IFERROR(_xlfn.XLOOKUP($K20,Multiples!$B:$B,Multiples!N:N),"") | O20: =IFERROR(_xlfn.XLOOKUP($K20,Multiples!$B:$B,Multiples!O:O),"") | P20: =IFERROR(_xlfn.XLOOKUP($K20,Multiples!$B:$B,Multiples!P:P),"") | Q20: =IFERROR(_xlfn.XLOOKUP($K20,Multiples!$B:$B,Multiples!Q:Q),"") | R20: =IFERROR(_xlfn.XLOOKUP($K20,Multiples!$B:$B,Multiples!R:R),"") | U20: Maria Pilar Fortunato
K21: EV / EBIT | N21: =IFERROR(_xlfn.XLOOKUP($K21,Multiples!$B:$B,Multiples!N:N),"") | O21: =IFERROR(_xlfn.XLOOKUP($K21,Multiples!$B:$B,Multiples!O:O),"") | P21: =IFERROR(_xlfn.XLOOKUP($K21,Multiples!$B:$B,Multiples!P:P),"") | Q21: =IFERROR(_xlfn.XLOOKUP($K21,Multiples!$B:$B,Multiples!Q:Q),"") | R21: =IFERROR(_xlfn.XLOOKUP($K21,Multiples!$B:$B,Multiples!R:R),"") | U21: pilarbarrocalfortunato@gmail.com
K22: Price / Earnings | N22: =IFERROR(_xlfn.XLOOKUP($K22,Multiples!$B:$B,Multiples!N:N),"") | O22: =IFERROR(_xlfn.XLOOKUP($K22,Multiples!$B:$B,Multiples!O:O),"") | P22: =IFERROR(_xlfn.XLOOKUP($K22,Multiples!$B:$B,Multiples!P:P),"") | Q22: =IFERROR(_xlfn.XLOOKUP($K22,Multiples!$B:$B,Multiples!Q:Q),"") | R22: =IFERROR(_xlfn.XLOOKUP($K22,Multiples!$B:$B,Multiples!R:R),"") | U22: (+351) 914 350 356
K23: Price / Book | N23: =IFERROR(_xlfn.XLOOKUP($K23,Multiples!$B:$B,Multiples!N:N),"") | O23: =IFERROR(_xlfn.XLOOKUP($K23,Multiples!$B:$B,Multiples!O:O),"") | P23: =IFERROR(_xlfn.XLOOKUP($K23,Multiples!$B:$B,Multiples!P:P),"") | Q23: =IFERROR(_xlfn.XLOOKUP($K23,Multiples!$B:$B,Multiples!Q:Q),"") | R23: =IFERROR(_xlfn.XLOOKUP($K23,Multiples!$B:$B,Multiples!R:R),"") | U23: Thor Cordeiro Alves Pinto
U24: thoropinto@gmail.com
D25: Year | E25: Net Sales | F25: EBIT Margin | G25: FCFF | H25: =+IF(Summary!$G$25="FCFF",#REF!,IF(Summary!$G$25="FCFE",#REF!,#REF!)) -> #REF! | I25: Net Capex | K25: Profitability Ratios | N25: 2022 | O25: =+N25+1 -> 2023 | P25: =+O25+1 -> 2024 | Q25: =+P25+1 -> 2025 | R25: =+Q25+1 -> 2026 | U25: (+351) 924 698 417
D26: 2022 | E26: =+#REF! -> #REF! | F26: =+#REF! -> #REF! | G26: =+INDEX(#REF!,MATCH(Summary!$G$25,{"FCFF","FCFE","Tax Shield","Total Payout"},0)) -> #REF! | H26: =+IF(Summary!$G$25="FCFF",#REF!,IF(Summary!$G$25="FCFE",#REF!,#REF!)) -> #REF! | I26: =+#REF! -> #REF! | K26: Return on Assets | N26: =IFERROR(_xlfn.XLOOKUP($K26,Multiples!$B:$B,Multiples!N:N),"") -> -0.10764331 | O26: =IFERROR(_xlfn.XLOOKUP($K26,Multiples!$B:$B,Multiples!O:O),"") -> -0.1638334 | P26: =IFERROR(_xlfn.XLOOKUP($K26,Multiples!$B:$B,Multiples!P:P),"") -> -0.12727349 | Q26: =IFERROR(_xlfn.XLOOKUP($K26,Multiples!$B:$B,Multiples!Q:Q),"") | R26: =IFERROR(_xlfn.XLOOKUP($K26,Multiples!$B:$B,Multiples!R:R),"") | U26: Maria Rita Baltazar Moura
D27: =+D26+1 -> 2023 | E27: =+#REF! -> #REF! | F27: =+#REF! -> #REF! | G27: =+INDEX(#REF!,MATCH(Summary!$G$25,{"FCFF","FCFE","Tax Shield","Total Payout"},0)) -> #REF! | H27: =+IF(Summary!$G$25="FCFF",#REF!,IF(Summary!$G$25="FCFE",#REF!,#REF!)) -> #REF! | I27: =+#REF! -> #REF! | K27: Return on Equity | N27: =IFERROR(_xlfn.XLOOKUP($K27,Multiples!$B:$B,Multiples!N:N),"") -> -0.15815508 | O27: =IFERROR(_xlfn.XLOOKUP($K27,Multiples!$B:$B,Multiples!O:O),"") -> -0.27808837 | P27: =IFERROR(_xlfn.XLOOKUP($K27,Multiples!$B:$B,Multiples!P:P),"") -> -0.39416841 | Q27: =IFERROR(_xlfn.XLOOKUP($K27,Multiples!$B:$B,Multiples!Q:Q),"") | R27: =IFERROR(_xlfn.XLOOKUP($K27,Multiples!$B:$B,Multiples!R:R),"") | U27: mariaritabaltazarmoura@gmail.com
D28: =+D27+1 -> 2024 | E28: =+#REF! -> #REF! | F28: =+#REF! -> #REF! | G28: =+INDEX(#REF!,MATCH(Summary!$G$25,{"FCFF","FCFE","Tax Shield","Total Payout"},0)) -> #REF! | H28: =+IF(Summary!$G$25="FCFF",#REF!,IF(Summary!$G$25="FCFE",#REF!,#REF!)) -> #REF! | I28: =+#REF! -> #REF! | K28: Return on Total Capital | N28: =IFERROR(_xlfn.XLOOKUP($K28,Multiples!$B:$B,Multiples!N:N),"") -> -0.13640392 | O28: =IFERROR(_xlfn.XLOOKUP($K28,Multiples!$B:$B,Multiples!O:O),"") -> -0.21705458 | P28: =IFERROR(_xlfn.XLOOKUP($K28,Multiples!$B:$B,Multiples!P:P),"") -> -0.17937245 | Q28: =IFERROR(_xlfn.XLOOKUP($K28,Multiples!$B:$B,Multiples!Q:Q),"") | R28: =IFERROR(_xlfn.XLOOKUP($K28,Multiples!$B:$B,Multiples!R:R),"") | U28: (+351) 925 922 810
D29: =+D28+1 -> 2025 | E29: =+#REF! -> #REF! | F29: =+#REF! -> #REF! | G29: =+INDEX(#REF!,MATCH(Summary!$G$25,{"FCFF","FCFE","Tax Shield","Total Payout"},0)) -> #REF! | H29: =+IF(Summary!$G$25="FCFF",#REF!,IF(Summary!$G$25="FCFE",#REF!,#REF!)) -> #REF! | I29: =+#REF! -> #REF! | K29: EBITDA Margin | N29: =IFERROR(_xlfn.XLOOKUP($K29,Multiples!$B:$B,Multiples!N:N),"") -> -0.64075829 | O29: =IFERROR(_xlfn.XLOOKUP($K29,Multiples!$B:$B,Multiples!O:O),"") -> -0.72771872 | P29: =IFERROR(_xlfn.XLOOKUP($K29,Multiples!$B:$B,Multiples!P:P),"") -> -0.41746905 | Q29: =IFERROR(_xlfn.XLOOKUP($K29,Multiples!$B:$B,Multiples!Q:Q),"") | R29: =IFERROR(_xlfn.XLOOKUP($K29,Multiples!$B:$B,Multiples!R:R),"")
D30: =+D29+1 -> 2026 | E30: =+#REF! -> #REF! | F30: =+#REF! -> #REF! | G30: =+INDEX(#REF!,MATCH(Summary!$G$25,{"FCFF","FCFE","Tax Shield","Total Payout"},0)) -> #REF! | H30: =+IF(Summary!$G$25="FCFF",#REF!,IF(Summary!$G$25="FCFE",#REF!,#REF!)) -> #REF! | I30: =+#REF! -> #REF! | K30: EBIT Margin | N30: =IFERROR(_xlfn.XLOOKUP($K30,Multiples!$B:$B,Multiples!N:N),"") -> -0.50127962 | O30: =IFERROR(_xlfn.XLOOKUP($K30,Multiples!$B:$B,Multiples!O:O),"") -> -0.61120196 | P30: =IFERROR(_xlfn.XLOOKUP($K30,Multiples!$B:$B,Multiples!P:P),"") -> -0.34440624 | Q30: =IFERROR(_xlfn.XLOOKUP($K30,Multiples!$B:$B,Multiples!Q:Q),"") | R30: =IFERROR(_xlfn.XLOOKUP($K30,Multiples!$B:$B,Multiples!R:R),"") | U30: Statistics
D31: =+D30+1 -> 2027 | E31: =+#REF! -> #REF! | F31: =+#REF! -> #REF! | G31: =+INDEX(#REF!,MATCH(Summary!$G$25,{"FCFF","FCFE","Tax Shield","Total Payout"},0)) -> #REF! | H31: =+IF(Summary!$G$25="FCFF",#REF!,IF(Summary!$G$25="FCFE",#REF!,#REF!)) -> #REF! | I31: =+#REF! -> #REF! | K31: Gross Profit Margin | N31: =IFERROR(_xlfn.XLOOKUP($K31,Multiples!$B:$B,Multiples!N:N),"") -> 0.090047393 | O31: =IFERROR(_xlfn.XLOOKUP($K31,Multiples!$B:$B,Multiples!O:O),"") -> 0.210139 | P31: =IFERROR(_xlfn.XLOOKUP($K31,Multiples!$B:$B,Multiples!P:P),"") -> 0.26616231 | Q31: =IFERROR(_xlfn.XLOOKUP($K31,Multiples!$B:$B,Multiples!Q:Q),"") | R31: =IFERROR(_xlfn.XLOOKUP($K31,Multiples!$B:$B,Multiples!R:R),"") | U31: Beta | V31: =Peers!D74
D32: =+D31+1 -> 2028 | E32: =+#REF! -> #REF! | F32: =+#REF! -> #REF! | G32: =+INDEX(#REF!,MATCH(Summary!$G$25,{"FCFF","FCFE","Tax Shield","Total Payout"},0)) -> #REF! | H32: =+IF(Summary!$G$25="FCFF",#REF!,IF(Summary!$G$25="FCFE",#REF!,#REF!)) -> #REF! | I32: =+#REF! -> #REF! | K32: SG&A Margin | N32: =IFERROR(_xlfn.XLOOKUP($K32,Multiples!$B:$B,Multiples!N:N),"") -> 0.42180095 | O32: =IFERROR(_xlfn.XLOOKUP($K32,Multiples!$B:$B,Multiples!O:O),"") -> 0.45094031 | P32: =IFERROR(_xlfn.XLOOKUP($K32,Multiples!$B:$B,Multiples!P:P),"") -> 0.28381476 | Q32: =IFERROR(_xlfn.XLOOKUP($K32,Multiples!$B:$B,Multiples!Q:Q),"") | R32: =IFERROR(_xlfn.XLOOKUP($K32,Multiples!$B:$B,Multiples!R:R),"") | U32: % Float | V32: =+Peers!D73 -> 0
D33: =+D32+1 -> 2029 | E33: =+#REF! -> #REF! | F33: =+#REF! -> #REF! | G33: =+INDEX(#REF!,MATCH(Summary!$G$25,{"FCFF","FCFE","Tax Shield","Total Payout"},0)) -> #REF! | H33: =+IF(Summary!$G$25="FCFF",#REF!,IF(Summary!$G$25="FCFE",#REF!,#REF!)) -> #REF! | I33: =+#REF! -> #REF! | K33: Net Income Margin | N33: =IFERROR(_xlfn.XLOOKUP($K33,Multiples!$B:$B,Multiples!N:N),"") -> -0.50459716 | O33: =IFERROR(_xlfn.XLOOKUP($K33,Multiples!$B:$B,Multiples!O:O),"") -> -0.63041701 | P33: =IFERROR(_xlfn.XLOOKUP($K33,Multiples!$B:$B,Multiples!P:P),"") -> -0.3455525 | Q33: =IFERROR(_xlfn.XLOOKUP($K33,Multiples!$B:$B,Multiples!Q:Q),"") | R33: =IFERROR(_xlfn.XLOOKUP($K33,Multiples!$B:$B,Multiples!R:R),"") | U33: % Held by Insiders | V33: =+Peers!D76 -> 0
U34: % Held by Institutions | V34: =+Peers!D77 -> 0
D35: SWOT Analysis | K35: Liquidity Ratios | N35: 2022 | O35: =+N35+1 -> 2023 | P35: =+O35+1 -> 2024 | Q35: =+P35+1 -> 2025 | R35: =+Q35+1 -> 2026 | U35: Short % of Float | V35: =+Peers!D78 -> 0
D36: Strengths | G36: Weaknesses | K36: Cash Ratio | N36: =IFERROR(_xlfn.XLOOKUP($K36,Multiples!$B:$B,Multiples!N:N),"") -> 1.4886433 | O36: =IFERROR(_xlfn.XLOOKUP($K36,Multiples!$B:$B,Multiples!O:O),"") -> 0.72739481 | P36: =IFERROR(_xlfn.XLOOKUP($K36,Multiples!$B:$B,Multiples!P:P),"") -> 0.7982327 | Q36: =IFERROR(_xlfn.XLOOKUP($K36,Multiples!$B:$B,Multiples!Q:Q),"") | R36: =IFERROR(_xlfn.XLOOKUP($K36,Multiples!$B:$B,Multiples!R:R),"") | W36: 120.87
D37: Global leader in dedicated small satellite launches, with a proven track record in a rapidly expanding market. Strong technological innovation and vertical integration, enabling cost reductions, faster production, and efficient mission delivery. Strategic global launch sites and key partnerships that strengthen international market reach and customer access. | G37: Reliance on Future Success of the Neutron Rocket. High capital expenditures required for developing cutting-edge technologies and expanding capabilities. Extreme operational complexity and inherent technical risks that could lead to launch delays or failures. | K37: Quick Ratio | N37: =IFERROR(_xlfn.XLOOKUP($K37,Multiples!$B:$B,Multiples!N:N),"") -> 3.1209331 | O37: =IFERROR(_xlfn.XLOOKUP($K37,Multiples!$B:$B,Multiples!O:O),"") -> 1.2533572 | P37: =IFERROR(_xlfn.XLOOKUP($K37,Multiples!$B:$B,Multiples!P:P),"") -> 1.3410898 | Q37: =IFERROR(_xlfn.XLOOKUP($K37,Multiples!$B:$B,Multiples!Q:Q),"") | R37: =IFERROR(_xlfn.XLOOKUP($K37,Multiples!$B:$B,Multiples!R:R),"") | U37: Major Holders | W37: 113.63
K38: Current Ratio | N38: =IFERROR(_xlfn.XLOOKUP($K38,Multiples!$B:$B,Multiples!N:N),"") -> 4.0656845 | O38: =IFERROR(_xlfn.XLOOKUP($K38,Multiples!$B:$B,Multiples!O:O),"") -> 2.1338406 | P38: =IFERROR(_xlfn.XLOOKUP($K38,Multiples!$B:$B,Multiples!P:P),"") -> 2.0400589 | Q38: =IFERROR(_xlfn.XLOOKUP($K38,Multiples!$B:$B,Multiples!Q:Q),"") | R38: =IFERROR(_xlfn.XLOOKUP($K38,Multiples!$B:$B,Multiples!R:R),"") | U38: Vanguard Group Inc | V38: 7.98%
U39: VK Services, LLC | V39: 7.24%
D40: Opportunities | G40: Threats | K40: Cash Flow Ratios | N40: 2022 | O40: =+N40+1 -> 2023 | P40: =+O40+1 -> 2024 | Q40: =+P40+1 -> 2025 | R40: =+Q40+1 -> 2026 | U40: Blackrock Inc. | V40: 6.95%
D41: Growing global demand for small satellites, fuelled by advancements in communication and Earth observation technologies. Potential expansion into larger payloads through the development of new vehicles like the Neutron rocket. Increasing opportunities to secure government and commercial contracts in a rapidly evolving space market. | G41: Intense competition from larger, well-established companies such as SpaceX and Blue Origin. Uncertainty in regulatory environments and geopolitical tensions that could impact international launches. Risks of technical issues, supply chain disruptions, and potential launch failures that may damage the company’s reputation. | K41: Cash Conversion Cycle | N41: =IFERROR(_xlfn.XLOOKUP($K41,Multiples!$B:$B,Multiples!N:N),"") -> 202.7979 | O41: =IFERROR(_xlfn.XLOOKUP($K41,Multiples!$B:$B,Multiples!O:O),"") -> 204.29601 | P41: =IFERROR(_xlfn.XLOOKUP($K41,Multiples!$B:$B,Multiples!P:P),"") -> 105.59852 | Q41: =IFERROR(_xlfn.XLOOKUP($K41,Multiples!$B:$B,Multiples!Q:Q),"") | R41: =IFERROR(_xlfn.XLOOKUP($K41,Multiples!$B:$B,Multiples!R:R),"") | U41: State Street Corporation | V41: 3.06%
K42: Net Income / Op Cash Flow | N42: =IFERROR(_xlfn.XLOOKUP($K42,Multiples!$B:$B,Multiples!N:N),"") -> 0.99971831 | O42: =IFERROR(_xlfn.XLOOKUP($K42,Multiples!$B:$B,Multiples!O:O),"") -> 1.5591507 | P42: =IFERROR(_xlfn.XLOOKUP($K42,Multiples!$B:$B,Multiples!P:P),"") -> 3.0824131 | Q42: =IFERROR(_xlfn.XLOOKUP($K42,Multiples!$B:$B,Multiples!Q:Q),"") | R42: =IFERROR(_xlfn.XLOOKUP($K42,Multiples!$B:$B,Multiples!R:R),"") | U42: Shaw D.E. & Co., Inc. | V42: 1.85%
K43: Chg in Cash / Op Cash Flow | N43: =IFERROR(_xlfn.XLOOKUP($K43,Multiples!$B:$B,Multiples!N:N),"") -> 4.1896714 | O43: =IFERROR(_xlfn.XLOOKUP($K43,Multiples!$B:$B,Multiples!O:O),"") -> 0.80283114 | P43: =IFERROR(_xlfn.XLOOKUP($K43,Multiples!$B:$B,Multiples!P:P),"") -> -2.2269939 | Q43: =IFERROR(_xlfn.XLOOKUP($K43,Multiples!$B:$B,Multiples!Q:Q),"") | R43: =IFERROR(_xlfn.XLOOKUP($K43,Multiples!$B:$B,Multiples!R:R),"") | U43: Geode Capital Management, LLC | V43: 1.83%
U44: Deer Management Co. LLC | V44: 1.80%
D45: Revenue by Region | G45: Revenue by Segment | K45: Leverage Ratios | N45: 2022 | O45: =+N45+1 -> 2023 | P45: =+O45+1 -> 2024 | Q45: =+P45+1 -> 2025 | R45: =+Q45+1 -> 2026 | U45: UBS Group AG | V45: 1.04%
K46: Total Debt / Equity | N46: =IFERROR(_xlfn.XLOOKUP($K46,Multiples!$B:$B,Multiples!N:N),"") -> 185.2347 | O46: =IFERROR(_xlfn.XLOOKUP($K46,Multiples!$B:$B,Multiples!O:O),"") -> 272.67809 | P46: =IFERROR(_xlfn.XLOOKUP($K46,Multiples!$B:$B,Multiples!P:P),"") -> 1201.8828 | Q46: =IFERROR(_xlfn.XLOOKUP($K46,Multiples!$B:$B,Multiples!Q:Q),"") | R46: =IFERROR(_xlfn.XLOOKUP($K46,Multiples!$B:$B,Multiples!R:R),"") | U46: Morgan Stanley | V46: 0.95%
K47: Total Debt / Capital | N47: =IFERROR(_xlfn.XLOOKUP($K47,Multiples!$B:$B,Multiples!N:N),"") -> 0.99463043 | O47: =IFERROR(_xlfn.XLOOKUP($K47,Multiples!$B:$B,Multiples!O:O),"") -> 0.99634607 | P47: =IFERROR(_xlfn.XLOOKUP($K47,Multiples!$B:$B,Multiples!P:P),"") -> 0.99916866 | Q47: =IFERROR(_xlfn.XLOOKUP($K47,Multiples!$B:$B,Multiples!Q:Q),"") | R47: =IFERROR(_xlfn.XLOOKUP($K47,Multiples!$B:$B,Multiples!R:R),"") | U47: Bank of America Corporation | V47: 0.84%
...

Sheet Regions
A1: In Millions of USD | E1: 2021 A (Rep) | F1: 2022 A (Rep) | G1: 2023 A (Rep) | H1: 2024 A (Rep) | I1: 2025 A (Fwd) | J1: 2026 A (Fwd)
A2: 12 Months Ending | B2: Field Expression | C2: Calcrt Field | D2: Segment Id | E2: 44561 | F2: 44926 | G2: 45291 | H2: 45657 | I2: 46022 | J2: 46387 | M2: =2 -> 2 | N2: =M2+1 -> 3 | O2: =N2+1 -> 4 | P2: =O2+1 -> 5
A3: Revenue | B3: SALES_REV_TURN | C3: IS010 | E3: 62.237 | F3: 210.996 | G3: 244.592 | H3: 436.214 | M3: 2021 | N3: =M3+1 -> 2022 | O3: =N3+1 -> 2023 | P3: =O3+1 -> 2024
A4: United States | B4: SALES_REV_TURN | C4: IS010 | D4: SEG0001085575 Segment | E4: 45.75 | F4: 164.593 | G4: 184.748 | H4: 268.326 | L4: United States | M4: =E4 -> 45.75 | N4: =F4 -> 164.593 | O4: =G4 -> 184.748 | P4: =H4 -> 268.326
A5: % of Total | B5: SALES_REV_TURN | C5: IS010 | D5: SEG0001085575 Segment | E5: 73.509327 | F5: 78.00764 | G5: 75.533133 | H5: 61.512469 | L5: Japan | M5: =E6 -> 0.769 | N5: =F6 -> 15.306 | O5: =G6 | P5: =H6 -> 30.684
A6: Japan | B6: SALES_REV_TURN | C6: IS010 | D6: SEG0001085569 Segment | E6: 0.769 | F6: 15.306 | H6: 30.684 | L6: Germany | M6: =E8 -> 9.77 | N6: =F8 -> 5.26 | O6: =G8 -> 5.503 | P6: =H8
A7: % of Total | B7: SALES_REV_TURN | C7: IS010 | D7: SEG0001085569 Segment | E7: 1.2355994 | F7: 7.254166 | H7: 7.0341621 | L7: Canada | M7: =E12 | N7: =F12 | O7: =G12 -> 36.116 | P7: =H12 -> 104.388
A8: Germany | B8: SALES_REV_TURN | C8: IS010 | D8: SEG0001085573 Segment | E8: 9.77 | F8: 5.26 | G8: 5.503 | L8: Rest Of World | M8: =E10 -> 5.948 | N8: =F10 -> 25.837 | O8: =G10 -> 18.225 | P8: =H10 -> 32.816
A9: % of Total | B9: SALES_REV_TURN | C9: IS010 | D9: SEG0001085573 Segment | E9: 15.698057 | F9: 2.4929383 | G9: 2.2498692
A10: Rest Of World | B10: SALES_REV_TURN | C10: IS010 | D10: SEG0001085570 Segment | E10: 5.948 | F10: 25.837 | G10: 18.225 | H10: 32.816
A11: % of Total | B11: SALES_REV_TURN | C11: IS010 | D11: SEG0001085570 Segment | E11: 9.5570159 | F11: 12.245256 | G11: 7.451184 | H11: 7.5229131
A12: Canada | B12: SALES_REV_TURN | C12: IS010 | D12: SEG0001085571 Segment | G12: 36.116 | H12: 104.388
A13: % of Total | B13: SALES_REV_TURN | C13: IS010 | D13: SEG0001085571 Segment | G13: 14.765814 | H13: 23.930456
A15: Percentage of Revenue | B15: IS_PERCENTAGE_OF_REVENUE | C15: IC214
A16: United States | B16: IS_PERCENTAGE_OF_REVENUE | C16: IC214 | D16: SEG0001085575 Segment | H16: 61
A17: % of Total | B17: IS_PERCENTAGE_OF_REVENUE | C17: IC214 | D17: SEG0001085575 Segment
A18: Japan | B18: IS_PERCENTAGE_OF_REVENUE | C18: IC214 | D18: SEG0001085569 Segment | H18: 7
A19: % of Total | B19: IS_PERCENTAGE_OF_REVENUE | C19: IC214 | D19: SEG0001085569 Segment
A20: Rest Of World | B20: IS_PERCENTAGE_OF_REVENUE | C20: IC214 | D20: SEG0001085570 Segment | H20: 8
A21: % of Total | B21: IS_PERCENTAGE_OF_REVENUE | C21: IC214 | D21: SEG0001085570 Segment
A22: Canada | B22: IS_PERCENTAGE_OF_REVENUE | C22: IC214 | D22: SEG0001085571 Segment | H22: 24
A23: % of Total | B23: IS_PERCENTAGE_OF_REVENUE | C23: IC214 | D23: SEG0001085571 Segment
A25: Total Non-Current Assets | B25: BS_TOTAL_NON_CURRENT_ASSETS | C25: BM321 | E25: 206.083 | F25: 326.829 | G25: 464.489 | H25: 491.721
A26: United States | B26: BS_TOTAL_NON_CURRENT_ASSETS | C26: BM321 | D26: SEG0001085575 Segment | H26: 346.383
A27: % of Total | B27: BS_TOTAL_NON_CURRENT_ASSETS | C27: BM321 | D27: SEG0001085575 Segment | H27: 70.442995
A28: Canada | B28: BS_TOTAL_NON_CURRENT_ASSETS | C28: BM321 | D28: SEG0001085571 Segment | H28: 4.082
A29: % of Total | B29: BS_TOTAL_NON_CURRENT_ASSETS | C29: BM321 | D29: SEG0001085571 Segment | H29: 0.83014555
A30: New Zealand | B30: BS_TOTAL_NON_CURRENT_ASSETS | C30: BM321 | D30: SEG0001085568 Segment | H30: 42.09
A31: % of Total | B31: BS_TOTAL_NON_CURRENT_ASSETS | C31: BM321 | D31: SEG0001085568 Segment | H31: 8.559732
A32: Source: Bloomberg

Sheet Segments
B2: Segments
B4: Regions | D4: Weight | E4: 2020 | F4: =+E4+1 -> 2021 | G4: =+F4+1 -> 2022 | H4: =+G4+1 -> 2023 | I4: =+H4+1 -> 2024 | J4: ="CAGR "&$G$4&" - "&$I$4 -> CAGR 2022 - 2024 | K4: 2021 | L4: =+K4+1 -> 2022 | M4: =+L4+1 -> 2023 | N4: =+M4+1 -> 2024
B6: United States | D6: =IFERROR(I6/SUM($I$6:$I$12),"") -> 0.61512469 | F6: =VLOOKUP($B6,Regions!$L$3:$P$8,Regions!M2,FALSE) -> 45.75 | G6: =VLOOKUP($B6,Regions!$L$3:$P$8,Regions!N2,FALSE) -> 164.593 | H6: =VLOOKUP($B6,Regions!$L$3:$P$8,Regions!O2,FALSE) -> 184.748 | I6: =VLOOKUP($B6,Regions!$L$3:$P$8,Regions!P2,FALSE) -> 268.326 | J6: =IFERROR((I6/G6)^(1/COUNT($G$4:$I$4))-1,"") -> 0.17692954 | K6: =IFERROR(F6-E6/E6,"") | L6: =IFERROR(G6-F6/F6,"") -> 163.593 | M6: =IFERROR((H6-G6)/G6,"") -> 0.12245357 | N6: =IFERROR((I6-H6)/H6,"") -> 0.4523892
B7: Japan | D7: =IFERROR(I7/SUM($I$6:$I$12),"") -> 0.070341621 | F7: =VLOOKUP($B7,Regions!$L$3:$P$8,Regions!M$2,FALSE) -> 0.769 | G7: =VLOOKUP($B7,Regions!$L$3:$P$8,Regions!N$2,FALSE) -> 15.306 | H7: =VLOOKUP($B7,Regions!$L$3:$P$8,Regions!O$2,FALSE) | I7: =VLOOKUP($B7,Regions!$L$3:$P$8,Regions!P$2,FALSE) -> 30.684 | J7: =IFERROR((I7/G7)^(1/COUNT($G$4:$I$4))-1,"") -> 0.26090806 | K7: =IFERROR(F7-E7/E7,"") | L7: =IFERROR(G7-F7/F7,"") -> 14.306 | M7: =IFERROR((H7-G7)/G7,"") | N7: =IFERROR((I7-H7)/H7,"")
B8: Germany | D8: =IFERROR(I8/SUM($I$6:$I$12),"") | F8: =VLOOKUP($B8,Regions!$L$3:$P$8,Regions!M$2,FALSE) -> 9.77 | G8: =VLOOKUP($B8,Regions!$L$3:$P$8,Regions!N$2,FALSE) -> 5.26 | H8: =VLOOKUP($B8,Regions!$L$3:$P$8,Regions!O$2,FALSE) -> 5.503 | I8: =VLOOKUP($B8,Regions!$L$3:$P$8,Regions!P$2,FALSE) | J8: =IFERROR((I8/E8)^(1/COUNT($E$4:$I$4))-1,"") | K8: =IFERROR(F8-E8/E8,"") | L8: =IFERROR(G8-F8/F8,"") -> 4.26 | M8: =IFERROR(H8-G8/G8,"") -> 4.503 | N8: =IFERROR((I8-H8)/H8,"")
B9: Canada | D9: =IFERROR(I9/SUM($I$6:$I$12),"") -> 0.23930456 | F9: =VLOOKUP($B9,Regions!$L$3:$P$8,Regions!M$2,FALSE) | G9: =VLOOKUP($B9,Regions!$L$3:$P$8,Regions!N$2,FALSE) | H9: =VLOOKUP($B9,Regions!$L$3:$P$8,Regions!O$2,FALSE) -> 36.116 | I9: =VLOOKUP($B9,Regions!$L$3:$P$8,Regions!P$2,FALSE) -> 104.388 | J9: =IFERROR((I9/E9)^(1/COUNT($E$4:$I$4))-1,"") | K9: =IFERROR(F9-E9/E9,"") | L9: =IFERROR(G9-F9/F9,"") | M9: =IFERROR(H9-G9/G9,"") | N9: =IFERROR((I9-H9)/H9,"") -> 1.8903533
B10: Rest Of World | D10: =IFERROR(I10/SUM($I$6:$I$12),"") -> 0.075229131 | F10: =VLOOKUP($B10,Regions!$L$3:$P$8,Regions!M$2,FALSE) -> 5.948 | G10: =VLOOKUP($B10,Regions!$L$3:$P$8,Regions!N$2,FALSE) -> 25.837 | H10: =VLOOKUP($B10,Regions!$L$3:$P$8,Regions!O$2,FALSE) -> 18.225 | I10: =VLOOKUP($B10,Regions!$L$3:$P$8,Regions!P$2,FALSE) -> 32.816 | J10: =IFERROR((I10/E10)^(1/COUNT($E$4:$I$4))-1,"") | K10: =IFERROR(F10-E10/E10,"") | L10: =IFERROR(G10-F10/F10,"") -> 24.837 | M10: =IFERROR(H10-G10/G10,"") -> 17.225 | N10: =IFERROR((I10-H10)/H10,"") -> 0.80060357
D11: =IFERROR(I11/SUM($I$6:$I$12),"") -> 0
D12: =IFERROR(I12/SUM($I$6:$I$12),"") -> 0
B13: Total | D13: =SUM(D6:D12) -> 1 | E13: =SUM(E6:E10) -> 0 | F13: =SUM(F6:F10) -> 62.237 | G13: =SUM(G6:G10) -> 210.996 | H13: =SUM(H6:H10) -> 244.592 | I13: =SUM(I6:I10) -> 436.214 | J13: =IFERROR((I13/G13)^(1/COUNT($G$4:$I$4))-1,"") -> 0.27391893 | K13: =IFERROR(F13-E13/E13,"") | L13: =IFERROR(G13-F13/F13,"") -> 209.996 | M13: =IFERROR((H13-G13)/G13,"") -> 0.15922577 | N13: =IFERROR((I13-H13)/H13,"") -> 0.78343527
B15: Segments | D15: Weight | E15: 2020 | F15: =+E15+1 -> 2021 | G15: =+F15+1 -> 2022 | H15: =+G15+1 -> 2023 | I15: =+H15+1 -> 2024 | J15: ="CAGR "&$E$4&" - "&$I$4 -> CAGR 2020 - 2024 | K15: 2021 | L15: =+K15+1 -> 2022 | M15: =+L15+1 -> 2023 | N15: =+M15+1 -> 2024
B17: Launch Service | D17: =IFERROR(I17/SUM($I$17:$I$21),"") -> 0.28741856 | F17: =VLOOKUP($B17,'Segments - Inputs'!$J$3:$N$5,'Segments - Inputs'!K$2,FALSE) -> 38.971 | G17: =VLOOKUP($B17,'Segments - Inputs'!$J$3:$N$5,'Segments - Inputs'!L$2,FALSE) -> 60.686 | H17: =VLOOKUP($B17,'Segments - Inputs'!$J$3:$N$5,'Segments - Inputs'!M$2,FALSE) -> 71.894 | I17: =VLOOKUP($B17,'Segments - Inputs'!$J$3:$N$5,'Segments - Inputs'!N$2,FALSE) -> 125.376 | J17: =IFERROR((I17/E17)^(1/COUNT($E$4:$I$4))-1,"") | K17: =IFERROR((F17-E17)/E17,"") | L17: =IFERROR((G17-F17)/F17,"") -> 0.55720921 | M17: =IFERROR((H17-G17)/G17,"") -> 0.1846884 | N17: =IFERROR((I17-H17)/H17,"") -> 0.74390074
B18: Space System | D18: =IFERROR(I18/SUM($I$17:$I$21),"") -> 0.71258144 | F18: =VLOOKUP($B18,'Segments - Inputs'!$J$3:$N$5,'Segments - Inputs'!K$2,FALSE) -> 23.266 | G18: =VLOOKUP($B18,'Segments - Inputs'!$J$3:$N$5,'Segments - Inputs'!L$2,FALSE) -> 150.31 | H18: =VLOOKUP($B18,'Segments - Inputs'!$J$3:$N$5,'Segments - Inputs'!M$2,FALSE) -> 172.698 | I18: =VLOOKUP($B18,'Segments - Inputs'!$J$3:$N$5,'Segments - Inputs'!N$2,FALSE) -> 310.838 | J18: =IFERROR((I18/E18)^(1/COUNT($E$4:$I$4))-1,"") | K18: =IFERROR((F18-E18)/E18,"") | L18: =IFERROR((G18-F18)/F18,"") -> 5.4605003 | M18: =IFERROR((H18-G18)/G18,"") -> 0.14894551 | N18: =IFERROR((I18-H18)/H18,"") -> 0.79989346
D19: =IFERROR(I19/SUM($I$17:$I$21),"") -> 0 | J19: =IFERROR((I19/E19)^(1/COUNT($E$4:$I$4))-1,"") | K19: =IFERROR((F19-E19)/E19,"") | L19: =IFERROR((G19-F19)/F19,"") | M19: =IFERROR((H19-G19)/G19,"") | N19: =IFERROR((I19-H19)/H19,"")
D20: =IFERROR(I20/SUM($I$17:$I$21),"") -> 0 | J20: =IFERROR((I20/E20)^(1/COUNT($E$4:$I$4))-1,"") | K20: =IFERROR((F20-E20)/E20,"") | L20: =IFERROR((G20-F20)/F20,"") | M20: =IFERROR((H20-G20)/G20,"") | N20: =IFERROR((I20-H20)/H20,"")
D21: =IFERROR(I21/SUM($I$17:$I$21),"") -> 0 | J21: =IFERROR((I21/E21)^(1/COUNT($E$4:$I$4))-1,"") | K21: =IFERROR((F21-E21)/E21,"") | L21: =IFERROR((G21-F21)/F21,"") | M21: =IFERROR((H21-G21)/G21,"") | N21: =IFERROR((I21-H21)/H21,"")
B22: Total | D22: =SUM(D17:D21) -> 1 | E22: =SUM(E17:E21) -> 0 | F22: =SUM(F17:F21) -> 62.237 | G22: =SUM(G17:G21) -> 210.996 | H22: =SUM(H17:H21) -> 244.592 | I22: =SUM(I17:I21) -> 436.214 | J22: =IFERROR((I22/E22)^(1/COUNT($E$4:$I$4))-1,"") | K22: =IFERROR((F22-E22)/E22,"") | L22: =IFERROR((G22-F22)/F22,"") -> 2.390202 | M22: =IFERROR((H22-G22)/G22,"") -> 0.15922577 | N22: =IFERROR((I22-H22)/H22,"") -> 0.78343527
B24: Categories | D24: Description | J24: Graphs
B26: Launch Service | D26: Rocket Lab provides small satellite launch solutions using its Electron rocket for payloads up to 300 kg, with a focus on flexibility and reusability, and is developing the Neutron rocket for larger payloads.
B27: Space System | D27: Rocket Lab offers integrated satellite solutions through its Photon platform, providing end-to-end services from satellite design and build to launch and operations, catering to both commercial and government clients.
B29: =IF(B20=0,"",B20)
B30: =IF(B21=0,"",B21)
B32: Products | D32: Weight | E32: 2020 | F32: =+E32+1 -> 2021 | G32: =+F32+1 -> 2022 | H32: =+G32+1 -> 2023 | I32: =+H32+1 -> 2024 | J32: =I32+1 -> 2025 | K32: =+J32+1 -> 2026 | L32: =+K32+1 -> 2027 | M32: =+L32+1 -> 2028 | N32: =+M32+1 -> 2029 | O32: =+N32+1 -> 2030 | P32: =+O32+1 -> 2031 | Q32: =+P32+1 -> 2032 | R32: =+Q32+1 -> 2033 | ... T32: =+S32+1 -> 2035
D34: =IFERROR(I34/$I$13,"") -> 0
D36: =IFERROR(I36/$I$13,"") -> 0
F37: =IFERROR((F36-E36)/E36,"") | G37: =IFERROR((G36-F36)/F36,"") | H37: =IFERROR((H36-G36)/G36,"") | I37: =IFERROR((I36-H36)/H36,"")
B38: Product 3 | D38: =IFERROR(I38/$I$13,"") -> 0 | J38: =I38*(1+J39) -> 0 | K38: =J38*(1+K39) -> 0 | L38: =K38*(1+L39) -> 0 | M38: =L38*(1+M39) -> 0 | N38: =M38*(1+N39) -> 0 | O38: =N38*(1+O39) -> 0 | P38: =O38*(1+P39) -> 0 | Q38: =P38*(1+Q39) -> 0 | ... T38: =S38*(1+T39) -> 0
F39: =IFERROR(F38-E38/E38,"") | G39: =IFERROR(G38-F38/F38,"") | H39: =IFERROR(H38-G38/G38,"") | I39: =IFERROR(I38-H38/H38,"")
B40: Product 4 | D40: =IFERROR(I40/$I$13,"") -> 0 | J40: =I40*(1+J41) -> 0 | K40: =J40*(1+K41) -> 0 | L40: =K40*(1+L41) -> 0 | M40: =L40*(1+M41) -> 0 | N40: =M40*(1+N41) -> 0 | O40: =N40*(1+O41) -> 0 | P40: =O40*(1+P41) -> 0 | Q40: =P40*(1+Q41) -> 0 | ... T40: =S40*(1+T41) -> 0
F41: =IFERROR(F40-E40/E40,"") | G41: =IFERROR(G40-F40/F40,"") | H41: =IFERROR(H40-G40/G40,"") | I41: =IFERROR(I40-H40/H40,"")
B42: Product 5 | D42: =IFERROR(I42/$I$13,"") -> 0 | J42: =I42*(1+J43) -> 0 | K42: =J42*(1+K43) -> 0 | L42: =K42*(1+L43) -> 0 | M42: =L42*(1+M43) -> 0 | N42: =M42*(1+N43) -> 0 | O42: =N42*(1+O43) -> 0 | P42: =O42*(1+P43) -> 0 | Q42: =P42*(1+Q43) -> 0 | ... T42: =S42*(1+T43) -> 0
F43: =IFERROR(F42-E42/E42,"") | G43: =IFERROR(G42-F42/F42,"") | H43: =IFERROR(H42-G42/G42,"") | I43: =IFERROR(I42-H42/H42,"")
B44: Total | D44: =SUM(D34:D42) -> 0 | E44: =SUM(E34:E42) -> 0 | F44: =SUM(F34:F42) -> 0 | G44: =SUM(G34:G42) -> 0 | H44: =SUM(H34:H42) -> 0 | I44: =SUM(I34:I42) -> 0 | J44: =SUM(J34:J42) -> 0 | K44: =SUM(K34:K42) -> 0 | ... T44: =SUM(T34:T42) -> 0
B46: Company's Strategy / Extra Notes

Sheet Industry
B2: Industry Overview
B4: Sales Growth Forecast | E4: Weight | F4: 2025 | G4: =+F4+1 -> 2026 | H4: =+G4+1 -> 2027 | I4: =+H4+1 -> 2028 | J4: =+I4+1 -> 2029 | K4: =+J4+1 -> 2030 | L4: =+K4+1 -> 2031 | M4: =+L4+1 -> 2032 | N4: =+M4+1 -> 2033 | ... P4: =+O4+1 -> 2035 | Q4: ="CAGR "&$F$4&" - "&$P$4 -> CAGR 2025 - 2035 | R4: Sources
B11: Weighted Average | E11: =SUM(E6:E10) -> 0 | F11: =SUMPRODUCT(F6:F10,$E$6:$E$10) -> 0 | G11: =SUMPRODUCT(G6:G10,$E$6:$E$10) -> 0 | H11: =SUMPRODUCT(H6:H10,$E$6:$E$10) -> 0 | I11: =SUMPRODUCT(I6:I10,$E$6:$E$10) -> 0 | J11: =SUMPRODUCT(J6:J10,$E$6:$E$10) -> 0 | K11: =SUMPRODUCT(K6:K10,$E$6:$E$10) -> 0 | L11: =SUMPRODUCT(L6:L10,$E$6:$E$10) -> 0 | M11: =SUMPRODUCT(M6:M10,$E$6:$E$10) -> 0 | ... P11: =SUMPRODUCT(P6:P10,$E$6:$E$10) -> 0 | Q11: =IFERROR(((1+F11)*(1+G11)*(1+H11)*(1+I11)*(1+J11)*(1+K11)*(1+L11)*(1+M11)*(1+N11)*(1+O11)*(1+P11))^(1/COUNT($F$4:$P$4))-1,"") -> 0
B13: Key Drivers | E13: Description
B20: Industry Trends | E20: Description
B26: Market Share | E26: Headquarters | G26: Revenues | H26: (in MM of USD) | I26: Market Share
B28: {=+_FV(#REF!,"Name")} -> #VALUE! | G28: {=TRANSPOSE(Peers!D97:N97)} -> 436.2 | I28: =IFERROR(G28/$G$40,"")
B29: {=+_FV(Peers!A8,"Name")} -> #VALUE! | G29: 0 | I29: =IFERROR(G29/$G$40,"")
B30: {=+_FV(Peers!A9,"Name")} -> #VALUE! | G30: 0 | I30: =IFERROR(G30/$G$40,"")
B31: {=+_FV(Peers!A10,"Name")} -> #VALUE! | G31: 0 | I31: =IFERROR(G31/$G$40,"")
B32: {=+_FV(Peers!A11,"Name")} -> #VALUE! | G32: 0 | I32: =IFERROR(G32/$G$40,"")
B33: {=+_FV(Peers!A12,"Name")} -> #VALUE! | G33: 0 | I33: =IFERROR(G33/$G$40,"")
B34: {=+_FV(Peers!A13,"Name")} -> #VALUE! | G34: 0 | I34: =IFERROR(G34/$G$40,"")
B35: {=+_FV(Peers!A14,"Name")} -> #VALUE! | G35: 0 | I35: =IFERROR(G35/$G$40,"")
B36: {=+_FV(Peers!A15,"Name")} -> #VALUE! | G36: 0 | I36: =IFERROR(G36/$G$40,"")
B37: {=+_FV(Peers!A16,"Name")} -> #VALUE! | G37: 0 | I37: =IFERROR(G37/$G$40,"")
B38: {=+_FV(Peers!A17,"Name")} -> #VALUE! | G38: 0 | I38: =IFERROR(G38/$G$40,"")
B39: Others | E39: -- | G39: =G40-SUM(G28:G38) -> -436.2 | I39: =IFERROR(G39/$G$40,"")
B40: Industry Size | E40: -- | I40: 1
B42: Porter's Five Forces Analysis | E42: Rating | H42: Graph
B44: Threat of New Entrants | E44: =IFERROR(AVERAGE(E45:E50),"")
B45: Economies of scale
B46: Product differentiation
B47: Capital requirements
B48: Access to distribution channels
B49: Regulations
B50: Switching costs
B51: Bargaining Power of Suppliers | E51: =IFERROR(AVERAGE(E52:E56),"")
B52: Number of suppliers
B53: Uniqueness
B54: Switching Costs
B55: Forward Integration
B56: Industry Importance
B57: Bargaining Power of Customers | E57: =IFERROR(AVERAGE(E58:E62),"")
B58: Number of buyers
B59: Purchase size
B60: Switching costs
B61: Price sensitivity
B62: Informed buyers
B63: Competitive Rivalry | E63: =IFERROR(AVERAGE(E64:E68),"")
...

Sheet Peers
D3: Revenue Growth | F3: EBITDA Margin | H3: Profit Margin | J3: EV / Revenue | L3: EV / EBITDA | N3: Price / Earnings
B4: Peers | C4: Ticker | D4: =+Inputs!O4&"-"&Inputs!P4 -> 2022-2023 | E4: =+Inputs!P4&"-"&Inputs!Q4 -> 2023-2024 | F4: 2023 | G4: 2024 | H4: =+Inputs!O4&"-"&Inputs!P4 -> 2022-2023 | I4: =+Inputs!P4&"-"&Inputs!Q4 -> 2023-2024 | J4: 2023 | K4: 2024 | L4: 2023 | M4: 2024 | N4: 2023 | O4: 2024
A6: =+D91 -> #REF! | B6: {=IFERROR(_FV(A6,"Name"),"")} | C6: {=IFERROR(_FV(A6,"Ticker symbol",TRUE),"")} | D6: =IFERROR(D94/D93-1,"") -> 0.15924171 | E6: =IFERROR(D97/D94-1,"") -> 0.78331971 | F6: =IFERROR(D95/D94,"") -> -0.72771872 | G6: =IFERROR(D100/D97,"") -> -0.41746905 | H6: =IFERROR(D96/D94,"") -> -0.63041701 | I6: =IFERROR(D105/D97,"") -> -0.3455525 | J6: {=IFERROR((_FV(A6,"Market cap",TRUE)/1000000+D$121-D$111)/D$94,"")} | K6: {=IFERROR((_FV(A6,"Market cap",TRUE)/1000000+D$121-D$111)/D$97,"")} | L6: {=+IFERROR((_FV(A6,"Market cap",TRUE)/1000000+D$121-D$111)/D$95,"")} | M6: {=IFERROR((_FV(A6,"Market cap",TRUE)/1000000+D$121-D$111)/D$100,"")} | N6: {=IFERROR((_FV(A6,"Market cap",TRUE)/1000000)/D$96,"")} | O6: {=IFERROR((_FV(A6,"Market cap",TRUE)/1000000)/D$105,"")}
A8: =+E91 -> PEER 1 | B8: {=IFERROR(_FV(A8,"Name"),"")} | C8: {=+IFERROR(_FV(A8,"Ticker symbol",TRUE),"")} | D8: =+IFERROR(E94/E93-1,"") | E8: =IFERROR(E97/E94-1,"") | F8: =IFERROR(E95/E94,"") | G8: =+IFERROR(E100/E97,"") | H8: =IFERROR(E96/E94,"") | I8: =+IFERROR(E105/E97,"") | J8: {=+IFERROR((_FV(A8,"Market cap",TRUE)/1000000+E$121-E$111)/E$94,"")} | K8: {=IFERROR(+(_FV(A8,"Market cap",TRUE)/1000000+E$121-E$111)/E$97,"")} | L8: {=IFERROR(+(_FV(A8,"Market cap",TRUE)/1000000+E$121-E$111)/E$95,"")} | M8: {=IFERROR(+(_FV(A8,"Market cap",TRUE)/1000000+E$121-E$111)/E$100,"")} | N8: {=IFERROR(+(_FV(A8,"Market cap",TRUE)/1000000)/E$96,"")} | O8: {=IFERROR(+(_FV(A8,"Market cap",TRUE)/1000000)/E$105,"")}
A9: =+F91 -> PEER 2 | B9: {=IFERROR(_FV(A9,"Name"),"")} | C9: {=+IFERROR(_FV(A9,"Ticker symbol",TRUE),"")} | D9: =IFERROR(F94/F93-1,"") | E9: =IFERROR(+F97/F94-1,"") | F9: =IFERROR(F95/F94,"") | G9: =IFERROR(F100/F97,"") | H9: =IFERROR(F96/F94,"") | I9: =+IFERROR(F105/F97,"") | J9: {=IFERROR(+(_FV(A9,"Market cap",TRUE)/1000000+F$121-F$111)/F$94,"")} | K9: {=IFERROR(+(_FV(A9,"Market cap",TRUE)/1000000+F$121-F$111)/F$97,"")} | L9: {=IFERROR(+(_FV(A9,"Market cap",TRUE)/1000000+F$121-F$111)/F$95,"")} | M9: {=IFERROR(+(_FV(A9,"Market cap",TRUE)/1000000+F$121-F$111)/F$100,"")} | N9: {=IFERROR(+(_FV(A9,"Market cap",TRUE)/1000000)/F$96,"")} | O9: {=IFERROR(+(_FV(A9,"Market cap",TRUE)/1000000)/F$105,"")}
A10: =+G91 -> PEER 3 | B10: {=IFERROR(_FV(A10,"Name"),"")} | C10: {=IFERROR(_FV(A10,"Ticker symbol",TRUE),"")} | D10: =+IFERROR(G94/G93-1,"") | E10: =IFERROR(G97/G94-1,"") | F10: =IFERROR(G95/G94,"") | G10: =IFERROR(G100/G97,"") | H10: =IFERROR(G96/G94,"") | I10: =+IFERROR(G105/G97,"") | J10: {=IFERROR(+(_FV(A10,"Market cap",TRUE)/1000000+G$121-G$111)/G$94,"")} | K10: {=IFERROR(+(_FV(A10,"Market cap",TRUE)/1000000+G$121-G$111)/G$97,"")} | L10: {=IFERROR(+(_FV(A10,"Market cap",TRUE)/1000000+G$121-G$111)/G$95,"")} | M10: {=IFERROR(+(_FV(A10,"Market cap",TRUE)/1000000+G$121-G$111)/G$100,"")} | N10: {=IFERROR(+(_FV(A10,"Market cap",TRUE)/1000000)/G$96,"")} | O10: {=IFERROR(+(_FV(A10,"Market cap",TRUE)/1000000)/G$105,"")}
A11: =+H91 -> PEER 4 | B11: {=IFERROR(_FV(A11,"Name"),"")} | C11: {=IFERROR(_FV(A11,"Ticker symbol",TRUE),"")} | D11: =IFERROR(H94/H93-1,"") | E11: =IFERROR(H97/H94-1,"") | F11: =IFERROR(H95/H94,"") | G11: =IFERROR(H100/H97,"") | H11: =IFERROR(H96/H94,"") | I11: =+IFERROR(H105/H102,"") | J11: {=IFERROR((_FV(A11,"Market cap",TRUE)/1000000+H$121-H$111)/H$94,"")} | K11: {=IFERROR(+(_FV(A11,"Market cap",TRUE)/1000000+H$121-H$111)/H$97,"")} | L11: {=IFERROR(+(_FV(A11,"Market cap",TRUE)/1000000+H$121-H$111)/H$95,"")} | M11: {=IFERROR(+(_FV(A11,"Market cap",TRUE)/1000000+H$121-H$111)/H$100,"")} | N11: {=IFERROR(+(_FV(A11,"Market cap",TRUE)/1000000)/H$96,"")} | O11: {=IFERROR(+(_FV(A11,"Market cap",TRUE)/1000000)/H$105,"")}
A12: =+I91 -> PEER 5 | B12: {=IFERROR(_FV(A12,"Name"),"")} | C12: {=IFERROR(_FV(A12,"Ticker symbol",TRUE),"")} | D12: =+IFERROR(I94/I93-1,"") | E12: =IFERROR(I97/I94-1,"") | F12: =IFERROR(I95/I94,"") | G12: =IFERROR(I100/I97,"") | H12: =IFERROR(I96/I94,"") | I12: =+IFERROR(I105/I97,"") | J12: {=IFERROR((_FV(A12,"Market cap",TRUE)/1000000+I$121-I$111)/I$94,"")} | K12: {=IFERROR(+(_FV(A12,"Market cap",TRUE)/1000000+I$121-I$111)/I$97,"")} | L12: {=IFERROR(+(_FV(A12,"Market cap",TRUE)/1000000+I$121-I$111)/I$95,"")} | M12: {=IFERROR(+(_FV(A12,"Market cap",TRUE)/1000000+I$121-I$111)/I$100,"")} | N12: {=IFERROR(+(_FV(A12,"Market cap",TRUE)/1000000)/I$96,"")} | O12: {=IFERROR(+(_FV(A12,"Market cap",TRUE)/1000000)/I$105,"")}
A13: =+J91 -> PEER 6 | B13: {=IFERROR(_FV(A13,"Name"),"")} | C13: {=IFERROR(_FV(A13,"Ticker symbol",TRUE),"")} | D13: =IFERROR(J94/J93-1,"") | E13: =IFERROR(J97/J94-1,"") | F13: =IFERROR(J95/J94,"") | G13: =IFERROR(J100/J97,"") | H13: =IFERROR(J96/J94,"") | I13: =+IFERROR(J105/J97,"") | J13: {=IFERROR(+(_FV(A13,"Market cap",TRUE)/1000000+J$121-J$111)/J$94,"")} | K13: {=IFERROR(+(_FV(A13,"Market cap",TRUE)/1000000+J$121-J$111)/J$97,"")} | L13: {=IFERROR(+(_FV(A13,"Market cap",TRUE)/1000000+J$121-J$111)/J$95,"")} | M13: {=IFERROR(+(_FV(A13,"Market cap",TRUE)/1000000+J$121-J$111)/J$100,"")} | N13: {=IFERROR(+(_FV(A13,"Market cap",TRUE)/1000000)/J$96,"")} | O13: {=IFERROR(+(_FV(A13,"Market cap",TRUE)/1000000)/J$105,"")}
A14: =+K91 -> PEER 7 | B14: {=IFERROR(_FV(A14,"Name"),"")} | C14: {=IFERROR(_FV(A14,"Ticker symbol",TRUE),"")} | D14: =IFERROR(K94/K93-1,"") | E14: =IFERROR(K97/K94-1,"") | F14: =+IFERROR(K95/K94,"") | G14: =IFERROR(K100/K97,"") | H14: =IFERROR(K96/K94,"") | I14: =+IFERROR(K105/K97,"") | J14: {=IFERROR((_FV(A14,"Market cap",TRUE)/1000000+D$121-K$111)/K$94,"")} | K14: {=IFERROR(+(_FV(A14,"Market cap",TRUE)/1000000+D$121-K$111)/K$97,"")} | L14: {=IFERROR(+(_FV(A14,"Market cap",TRUE)/1000000+D$121-K$111)/K$95,"")} | M14: {=IFERROR(+(_FV(A14,"Market cap",TRUE)/1000000+D$121-K$111)/K$100,"")} | N14: {=IFERROR(+(_FV(A14,"Market cap",TRUE)/1000000)/K$96,"")} | O14: {=IFERROR(+(_FV(A14,"Market cap",TRUE)/1000000)/K$105,"")}
A15: =+L91 -> PEER 8 | B15: {=IFERROR(_FV(A15,"Name"),"")} | C15: {=IFERROR(_FV(A15,"Ticker symbol",TRUE),"")} | D15: =+IFERROR(L94/L93,"") | E15: =IFERROR(L97/L94,"") | F15: =IFERROR(L95/L94,"") | G15: =IFERROR(L100/L97,"") | H15: =IFERROR(L96/L94,"") | I15: =+IFERROR(L105/L97,"") | J15: {=IFERROR(+(_FV(A15,"Market cap",TRUE)/1000000+L$121-L$111)/L$94,"")} | K15: {=IFERROR(+(_FV(A15,"Market cap",TRUE)/1000000+L$121-L$111)/L$97,"")} | L15: {=IFERROR(+(_FV(A15,"Market cap",TRUE)/1000000+L$121-L$111)/L$95,"")} | M15: {=IFERROR(+(_FV(A15,"Market cap",TRUE)/1000000+L$121-L$111)/L$100,"")} | N15: {=IFERROR(+(_FV(A15,"Market cap",TRUE)/1000000)/L$96,"")} | O15: {=IFERROR(+(_FV(A15,"Market cap",TRUE)/1000000)/L$105,"")}
A16: =+M91 -> PEER 9 | B16: {=IFERROR(_FV(A16,"Name"),"")} | C16: {=IFERROR(_FV(A16,"Ticker symbol",TRUE),"")} | D16: =IFERROR(M94/M93-1,"") | E16: =IFERROR(M97/M94-1,"") | F16: =IFERROR(M95/M94,"") | G16: =IFERROR(M100/M97,"") | H16: =IFERROR(M96/M94,"") | I16: =+IFERROR(M105/M97,"") | J16: {=IFERROR(+(_FV(A16,"Market cap",TRUE)/1000000+M$121-M$111)/M$94,"")} | K16: {=IFERROR(+(_FV(A16,"Market cap",TRUE)/1000000+M$121-M$111)/M$97,"")} | L16: {=IFERROR(+(_FV(A16,"Market cap",TRUE)/1000000+M$121-M$111)/M$95,"")} | M16: {=IFERROR(+(_FV(A16,"Market cap",TRUE)/1000000+M$121-M$111)/M$100,"")} | N16: {=IFERROR(+(_FV(A16,"Market cap",TRUE)/1000000)/M$96,"")} | O16: {=IFERROR(+(_FV(A16,"Market cap",TRUE)/1000000)/M$105,"")}
A17: =+N91 -> PEER 10 | B17: {=IFERROR(_FV(A17,"Name"),"")} | C17: {=+IFERROR(_FV(A17,"Ticker symbol",TRUE),"")} | D17: =IFERROR(N94/N93-1,"") | E17: =IFERROR(N97/N94-1,"") | F17: =IFERROR(N95/N94,"") | G17: =IFERROR(N100/N97,"") | H17: =IFERROR(N96/N94,"") | I17: =+IFERROR(N105/N97,"") | J17: {=IFERROR(+(_FV(A17,"Market cap",TRUE)/1000000+N$121-N$111)/N$94,"")} | K17: {=IFERROR(+(_FV(A17,"Market cap",TRUE)/1000000+N$121-N$111)/N$97,"")} | L17: {=IFERROR(+(_FV(A17,"Market cap",TRUE)/1000000+N$121-N$111)/N$95,"")} | M17: {=IFERROR(+(_FV(A17,"Market cap",TRUE)/1000000+N$121-N$111)/N$100,"")} | N17: {=IFERROR(+(_FV(A17,"Market cap",TRUE)/1000000)/N$96,"")} | O17: {=IFERROR(+(_FV(A17,"Market cap",TRUE)/1000000)/N$105,"")}
B18: Average | D18: =IFERROR(AVERAGE(D6:D17),"") -> 0.15924171 | E18: =IFERROR(AVERAGE(E6:E17),"") -> 0.78331971 | F18: =IFERROR(AVERAGE(F6:F17),"") -> -0.72771872 | G18: =IFERROR(AVERAGE(G6:G17),"") -> -0.41746905 | H18: =IFERROR(AVERAGE(H6:H17),"") -> -0.63041701 | I18: =IFERROR(AVERAGE(I6:I17),"") -> -0.3455525 | J18: =IFERROR(AVERAGE(J6:J17),"") | K18: =IFERROR(AVERAGE(K6:K17),"") | ... O18: =IFERROR(AVERAGE(O6:O17),"")
B19: Deviation from Average | D19: =IFERROR(+D18-D6,"") -> 0 | E19: =IFERROR(E18-E6,"") -> 0 | F19: =+IFERROR(F18-F6,"") -> 0 | G19: =IFERROR(G18-G6,"") -> 0 | H19: =IFERROR(+H6-H18,"") -> 0 | I19: =+IFERROR(I6-I18,"") -> 0 | J19: =+IFERROR(J6-J18,"") | K19: =+IFERROR(K6-K18,"") | L19: =IFERROR(+L6-L18,"") | M19: =IFERROR(M6-M18,"") | N19: =IFERROR(+N6-N18,"") | O19: =IFERROR(+O6-O18,"")
D21: Trading Multiple | G21: Net | H21: Preferred | I21: Non-Controlling | J21: Equity Value | M21: Implied Upside (Downside)
B22: Implied Share Price | D22: Revenue | E22: EBITDA | F22: P/E | G22: Debt | H22: Stock | I22: Interest | J22: Revenue | K22: EBITDA | L22: P/E | M22: Revenue | N22: EBITDA | O22: P/E | P22: Current Price
B24: Second Minimum | D24: =IFERROR(SMALL(K6:K17,2),"") | E24: =IFERROR(SMALL(M6:M17,2),"") | F24: =IFERROR(SMALL(O6:O17,2),"") | G24: =-Inputs!$Q$99+Inputs!$Q$100 -> 40.7 | H24: =+Inputs!$Q$101 -> 0 | I24: =+Inputs!$Q$102 -> 0 | J24: =IFERROR(+D24*$D$97+G24+H24+I24,"") | K24: =IFERROR(E24*$D$100+G24+H24+I24,"") | L24: =IFERROR(F24*$D$105,"") | M24: {=IFERROR(+(J24/_FV($A$6,"Shares outstanding",TRUE)*1000000)/$P$24-1,"")} | N24: {=IFERROR((+K24/_FV($A$6,"Shares outstanding",TRUE)*1000000)/$P$24-1,"")} | O24: {=IFERROR(+(L24/_FV($A$6,"Shares outstanding",TRUE)*1000000)/$P$24-1,"")} | P24: {=+_FV(A6,"Price")} -> #VALUE!
B25: Average | D25: =+IFERROR(AVERAGE(K6:K17),"") | E25: =IFERROR(+AVERAGE(M6:M17),"") | F25: =IFERROR(+AVERAGE(O6:O17),"") | G25: =-Inputs!$Q$99+Inputs!$Q$100 -> 40.7 | H25: =+Inputs!$Q$101 -> 0 | I25: =+Inputs!$Q$102 -> 0 | J25: =IFERROR(+D25*$D$97+G25+H25+I25,"") | K25: =IFERROR(E25*$D$100+G25+H25+I25,"") | L25: =IFERROR(+F25*$D$105,"") | M25: {=IFERROR(+(J25/_FV($A$6,"Shares outstanding",TRUE)*1000000)/$P$24-1,"")} | N25: {=IFERROR((+K25/_FV($A$6,"Shares outstanding",TRUE)*1000000)/$P$24-1,"")} | O25: {=IFERROR(+(L25/_FV($A$6,"Shares outstanding",TRUE)*1000000)/$P$24-1,"")}
B26: Median | D26: =IFERROR(MEDIAN(K6:K17),"") | E26: =IFERROR(MEDIAN(M6:M17),"") | F26: =IFERROR(MEDIAN(O6:O17),"") | G26: =-Inputs!$Q$99+Inputs!$Q$100 -> 40.7 | H26: =+Inputs!$Q$101 -> 0 | I26: =+Inputs!$Q$102 -> 0 | J26: =IFERROR(D26*$D$97+G26+H26+I26,"") | K26: =IFERROR(E26*$D$100+G26+H26+I26,"") | L26: =IFERROR(+F26*$D$105,"") | M26: {=IFERROR(+(J26/_FV($A$6,"Shares outstanding",TRUE)*1000000)/$P$24-1,"")} | N26: {=IFERROR((+K26/_FV($A$6,"Shares outstanding",TRUE)*1000000)/$P$24-1,"")} | O26: {=+IFERROR((L26/_FV($A$6,"Shares outstanding",TRUE)*1000000)/$P$24-1,"")}
B27: Second Maximum | D27: =IFERROR(LARGE(K6:K17,2),"") | E27: =IFERROR(LARGE(M6:M17,2),"") | F27: =IFERROR(LARGE(O6:O17,2),"") | G27: =-Inputs!$Q$99+Inputs!$Q$100 -> 40.7 | H27: =+Inputs!$Q$101 -> 0 | I27: =+Inputs!$Q$102 -> 0 | J27: =IFERROR(+D27*$D$97+G27+H27+I27,"") | K27: =IFERROR(E27*$D$100+G27+H27+I27,"") | L27: =IFERROR(+F27*$D$105,"") | M27: {=IFERROR(+(J27/_FV($A$6,"Shares outstanding",TRUE)*1000000)/$P$24-1,"")} | N27: {=IFERROR((+K27/_FV($A$6,"Shares outstanding",TRUE)*1000000)/$P$24-1,"")} | O27: {=IFERROR(+(L27/_FV($A$6,"Shares outstanding",TRUE)*1000000)/$P$24-1,"")}
B29: Profitability | D29: =+LEFT(B6, FIND(" ", B6 & " ") - 1) | E29: =+LEFT(B8, FIND(" ", B8 & " ") - 1) | F29: =+LEFT(B9, FIND(" ", B9 & " ") - 1) | G29: =+LEFT(B10, FIND(" ", B10 & " ") - 1) | H29: =+LEFT(B11, FIND(" ", B11 & " ") - 1) | I29: =+LEFT(B12, FIND(" ", B12 & " ") - 1) | J29: =+LEFT(C12, FIND(" ", C12 & " ") - 1) | K29: =+LEFT(B14, FIND(" ", B14 & " ") - 1) | L29: =+LEFT(B15, FIND(" ", B15 & " ") - 1) | M29: =+LEFT(B16, FIND(" ", B16 & " ") - 1) | N29: =+LEFT(B17, FIND(" ", B17 & " ") - 1) | O29: Average
B31: Operating Margin | D31: =IFERROR(D101/D97,"") -> -0.34440624 | E31: =IFERROR(E101/E97,"") | F31: =IFERROR(F101/F97,"") | G31: =IFERROR(G101/G97,"") | H31: =IFERROR(H101/H97,"") | I31: =IFERROR(I101/I97,"") | J31: =IFERROR(J101/J97,"") | K31: =IFERROR(K101/K97,"") | ... N31: =IFERROR(N101/N97,"") | O31: =IFERROR(+AVERAGE(D31:N31),"") -> -0.34440624
B32: Net Income Margin | D32: =IFERROR(D105/D97,"") -> -0.3455525 | E32: =IFERROR(E105/E97,"") | F32: =IFERROR(F105/F97,"") | G32: =IFERROR(G105/G97,"") | H32: =IFERROR(H105/H97,"") | I32: =IFERROR(I105/I97,"") | J32: =IFERROR(J105/J97,"") | K32: =IFERROR(K105/K97,"") | ... N32: =IFERROR(N105/N97,"") | O32: =IFERROR(+AVERAGE(D32:N32),"") -> -0.3455525
B33: ROA (%) | D33: =IFERROR(D105/D117,"") -> -0.12727349 | E33: =IFERROR(E105/E117,"") | F33: =IFERROR(F105/F117,"") | G33: =IFERROR(G105/G117,"") | H33: =IFERROR(H105/H117,"") | I33: =IFERROR(I105/I117,"") | J33: =IFERROR(J105/J117,"") | K33: =IFERROR(K105/K117,"") | ... N33: =IFERROR(N105/N117,"") | O33: =IFERROR(+AVERAGE(D33:N33),"") -> -0.12727349
B34: Financial Cost of Debt | D34: =IFERROR(+(D102/D121)*(1-(D104/D103)),"") -> 0.008749659 | E34: =IFERROR(+(E102/E121)*(1-(E104/E103)),"") | F34: =IFERROR(+(F102/F121)*(1-(F104/F103)),"") | G34: =IFERROR(+(G102/G121)*(1-(G104/G103)),"") | H34: =IFERROR(+(H102/H121)*(1-(H104/H103)),"") | I34: =IFERROR(+(I102/I121)*(1-(I104/I103)),"") | J34: =IFERROR(+(J102/J121)*(1-(J104/J103)),"") | K34: =IFERROR(+(K102/K121)*(1-(K104/K103)),"") | ... N34: =IFERROR(+(N102/N121)*(1-(N104/N103)),"") | O34: =IFERROR(+AVERAGE(D34:N34),"") -> 0.008749659
B35: Return on Equity (RoE) | D35: =IFERROR(+D105/D122,"") -> -0.39416841 | E35: =IFERROR(+E105/E122,"") | F35: =IFERROR(+F105/F122,"") | G35: =IFERROR(+G105/G122,"") | H35: =IFERROR(+H105/H122,"") | I35: =IFERROR(+I105/I122,"") | J35: =IFERROR(+J105/J122,"") | K35: =IFERROR(+K105/K122,"") | ... N35: =IFERROR(+N105/N122,"") | O35: =IFERROR(+AVERAGE(D35:N35),"") -> -0.39416841
B36: Return on Invested Capital (ROIC) | D36: =IFERROR(+D105/(D121+D122),"") -> -0.17901425 | E36: =IFERROR(+E105/(E121+E122),"") | F36: =IFERROR(+F105/(F121+F122),"") | G36: =IFERROR(+G105/(G121+G122),"") | H36: =IFERROR(+H105/(H121+H122),"") | I36: =IFERROR(+I105/(I121+I122),"") | J36: =IFERROR(+J105/(J121+J122),"") | K36: =IFERROR(+K105/(K121+K122),"") | ... N36: =IFERROR(+N105/(N121+N122),"") | O36: =IFERROR(+AVERAGE(D36:N36),"") -> -0.17901425
B38: Solvency | D38: =+D29 | E38: =+E29 | F38: =+F29 | G38: =+G29 | H38: =+H29 | I38: =+I29 | J38: =+J29 | K38: =+K29 | ... O38: =+O29 -> Average
B40: Debt/Assets | D40: =IFERROR(D121/D117,"") -> 0.38807735 | E40: =IFERROR(E121/E117,"") | F40: =IFERROR(F121/F117,"") | G40: =IFERROR(G121/G117,"") | H40: =IFERROR(H121/H117,"") | I40: =IFERROR(I121/I117,"") | J40: =IFERROR(J121/J117,"") | K40: =IFERROR(K121/K117,"") | ... N40: =IFERROR(N121/N117,"") | O40: =IFERROR(+AVERAGE(D40:N40),"") -> 0.38807735
B41: Net Debt/EBITDA | D41: =IFERROR(+(D121-D111)/D100,"") -> -1.0356947 | E41: =IFERROR(+(E121-E111)/E100,"") | F41: =IFERROR(+(F121-F111)/F100,"") | G41: =IFERROR(+(G121-G111)/G100,"") | H41: =IFERROR(+(H121-H111)/H100,"") | I41: =IFERROR(+(I121-I111)/I100,"") | J41: =IFERROR(+(J121-J111)/J100,"") | K41: =IFERROR(+(K121-K111)/K100,"") | ... N41: =IFERROR(+(N121-N111)/N100,"") | O41: =IFERROR(+AVERAGE(D41:N41),"") -> -1.0356947
B42: Interest Coverage Ratio | D42: =IFERROR(D101/D102,"") -> -37.5575 | E42: =IFERROR(E101/E102,"") | F42: =IFERROR(F101/F102,"") | G42: =IFERROR(G101/G102,"") | H42: =IFERROR(H101/H102,"") | I42: =IFERROR(I101/I102,"") | J42: =IFERROR(J101/J102,"") | K42: =IFERROR(K101/K102,"") | ... N42: =IFERROR(N101/N102,"") | O42: =IFERROR(+AVERAGE(D42:N42),"") -> -37.5575
B44: Liquidity | D44: =+D29 | E44: =+E29 | F44: =+F29 | G44: =+G29 | H44: =+H29 | I44: =+I29 | J44: =+J29 | K44: =+K29 | ... O44: =+O29 -> Average
B46: Cash Ratio | D46: =IFERROR(D111/D119,"") -> 0.7982327 | E46: =IFERROR(E111/E119,"") | F46: =IFERROR(F111/F119,"") | G46: =IFERROR(G111/G119,"") | H46: =IFERROR(H111/H119,"") | I46: =IFERROR(I111/I119,"") | J46: =IFERROR(J111/J119,"") | K46: =IFERROR(K111/K119,"") | ... N46: =IFERROR(N111/N119,"") | O46: =IFERROR(+AVERAGE(D46:N46),"") -> 0.7982327
B47: Quick Ratio | D47: =IFERROR(+(D111+D112)/D119,"") -> 0.90544919 | E47: =IFERROR(+(E111+E112)/E119,"") | F47: =IFERROR(+(F111+F112)/F119,"") | G47: =IFERROR(+(G111+G112)/G119,"") | H47: =IFERROR(+(H111+H112)/H119,"") | I47: =IFERROR(+(I111+I112)/I119,"") | J47: =IFERROR(+(J111+J112)/J119,"") | K47: =IFERROR(+(K111+K112)/K119,"") | ... N47: =IFERROR(+(N111+N112)/N119,"") | O47: =IFERROR(+AVERAGE(D47:N47),"") -> 0.90544919
B48: Current Ratio | D48: =IFERROR(D115/D119,"") -> 2.0400589 | E48: =IFERROR(E115/E119,"") | F48: =IFERROR(F115/F119,"") | G48: =IFERROR(G115/G119,"") | H48: =IFERROR(H115/H119,"") | I48: =IFERROR(I115/I119,"") | J48: =IFERROR(J115/J119,"") | K48: =IFERROR(K115/K119,"") | ... N48: =IFERROR(N115/N119,"") | O48: =IFERROR(+AVERAGE(D48:N48),"") -> 2.0400589
B50: Activity | D50: =+D29 | E50: =+E29 | F50: =+F29 | G50: =+G29 | H50: =+H29 | I50: =+I29 | J50: =+J29 | K50: =+K29 | ... O50: =+O29 -> Average
B52: Inventory Turnover | D52: =IFERROR(D98/(AVERAGE(D113:D114)),"") -> 2.8202643 | E52: =IFERROR(E98/(AVERAGE(E113:E114)),"") | F52: =IFERROR(F98/(AVERAGE(F113:F114)),"") | G52: =IFERROR(G98/(AVERAGE(G113:G114)),"") | H52: =IFERROR(H98/(AVERAGE(H113:H114)),"") | I52: =IFERROR(I98/(AVERAGE(I113:I114)),"") | J52: =IFERROR(J98/(AVERAGE(J113:J114)),"") | K52: =IFERROR(K98/(AVERAGE(K113:K114)),"") | ... N52: =IFERROR(N98/(AVERAGE(N113:N114)),"") | O52: =IFERROR(+AVERAGE(D52:N52),"") -> 2.8202643
B53: Acc. Receivable Turnover | D53: =IFERROR(D97/D112,"") -> 11.983516 | E53: =IFERROR(E97/E112,"") | F53: =IFERROR(F97/F112,"") | G53: =IFERROR(G97/G112,"") | H53: =IFERROR(H97/H112,"") | I53: =IFERROR(I97/I112,"") | J53: =IFERROR(J97/J112,"") | K53: =IFERROR(K97/K112,"") | ... N53: =IFERROR(N97/N112,"") | O53: =IFERROR(+AVERAGE(D53:N53),"") -> 11.983516
B54: Payables Turnover | D54: =IFERROR(D98/D118,"") -> 4.4151724 | E54: =IFERROR(E98/E118,"") | F54: =IFERROR(F98/F118,"") | G54: =IFERROR(G98/G118,"") | H54: =IFERROR(H98/H118,"") | I54: =IFERROR(I98/I118,"") | J54: =IFERROR(J98/J118,"") | K54: =IFERROR(K98/K118,"") | ... N54: =IFERROR(N98/N118,"") | O54: =IFERROR(+AVERAGE(D54:N54),"") -> 4.4151724
...

Sheet ESG
B2: Environmental, Social and Governance Analysis
B4: Author: | E4: Highlights | N4: Recent News
G5: Rocket Lab’s 2021 ESG report does not include any quantitative data on Scope 1 or Scope 2 greenhouse gas emissions. Furthermore, the report does not contain any stated commitment to monitor or disclose these emissions in future reports.
B6: Overview | D6: .
B7: Last Update | C7: 45727 | D7: . | G7: The 2021 ESG report by Rocket Lab does not provide any data or discussion related to water consumption. There is no mention of water usage, monitoring, or reduction efforts.
B8: Latest year with data
B9: GICS Sector | C9: Industrials | G9: Rocket Lab’s 2021 ESG report does not include any quantitative data on energy consumption. While the company mentions environmental considerations in general, there are no metrics, breakdowns, or targets related to energy use.
B10: GICS Industry Group | C10: Aerospace & Defense
B11: Final Review | G11: The 2021 ESG report mentions a general commitment to environmentally responsible operations and waste minimization, but does not include any quantitative data or specific strategies regarding waste management.
B13: ESG Scores
B14: LSEG ESG Score | C14: 22
B15: E-Score | C15: 0
B16: S-Score | C16: 13 | E16: GHG Scope 1 and 2 Emissions: | N16: Water, Waste, Energy Management:
B17: G-Score | C17: 50
B18: S&P Global ESG Score | C18: private
B19: Environmental | C19: private
B20: Social | C20: private
B21: Governance & Economic | C21: private
B22: Sustainalytics | C22: 39.9
B23: ISS ESG Corporate Rating | C23: D-
B24: SDG Impact Rating | C24: -7.8
B25: Governance Quality Score | C25: 8
B26: MSCI ESG Ratings | C26: N/A
B29: Industry ESG Overview:
E33: ENVIRONMENTAL
G35: Overview | H35: Targets | K35: Improvements | O35: Comments
E36: GHG (or CO2) Scope 1 Emissions
E38: Water Consumption
E40: Energy Consumption
E42: Waste Management
E44: Other
E46: SOCIAL
B48: Important Sources: | G48: Overview | H48: Targets | K48: Improvements | O48: Comments
B49: Annual Report | E49: Employee Turnover % | K49: ​Rocket Lab has initiated measures to enhance employee retention and address workplace culture concerns:Employee Relations Initiatives: Dedicated Management Role: The company has established positions such as the Employee Relations and Compliance Manager, responsible for developing and implementing employee recognition and engagement programs, aiming to improve workplace morale and retention. Policy Guidance and Support: Rocket Lab employs People & Culture Business Partners who work closely with management and staff to provide policy guidance, enhance work relationships, and boost productivity and retention. | O49: Rocket Lab does not publicly disclose official employee turnover statistics in its ESG or financial reports. However, various employee reviews and third-party platforms provide insights into the company's workforce dynamics. Short Tenure Reports: Some employees have noted a high turnover rate, with average tenures ranging from 1 to 2 years.
B50: Sustainability Report | D50: .
B51: Proxy Statement | D51: . | E51: Salaries & Compensation | K51: Rocket Lab's compensation practices have evolved positively, with noticeable increases in executive pay and competitive salaries for employees. | O51: While Rocket Lab's ESG disclosures, such as the 2021 ESG Impact Report, do not extensively cover compensation practices, the company demonstrates transparency in executive pay through its SEC filings. However, detailed information on company-wide compensation policies, pay equity initiatives, or benefits programs is limited. Rocket Lab's lower pay ratio reflects a more equitable compensation structure, aligning with its position as a growing company in the aerospace industry.​
E53: Reputation | O53: Rocket Lab is esteemed for its innovation and industry position, though it faces notable ESG risks that may impact its overall reputation.
E55: Discrimination Events | O55: Some of Rocket Lab's job postings, particularly for U.S.-based positions, specify that applicants must be U.S. citizens as defined by the International Traffic in Arms Regulations. This requirement could potentially exclude certain individuals, such as refugees or asylees, who are legally authorized to work in the U.S.
E57: Work Safety | K57: Rocket Lab has established formal health and safety policies, systems, and processes to ensure a safe working environment.
E59: Damage to consumer health | G59: N/A
...

Sheet ESG Inputs
B2: ESG Inputs
A4: x | B4: Total GHG Scope 1 Emissions | G4: 2014 | H4: =+G4+1 -> 2015 | I4: =+H4+1 -> 2016 | J4: =+I4+1 -> 2017 | K4: =+J4+1 -> 2018 | L4: =+K4+1 -> 2019 | M4: =+L4+1 -> 2020 | N4: =+M4+1 -> 2021 | O4: =+N4+1 -> 2022 | ... Q4: =+P4+1 -> 2024 | R4: ="CAGR "&$G$4&" - "&$Q$4 -> CAGR 2014 - 2024
B6: =+Peers!B6 | G6: x | R6: =IFERROR((Q6/G6)^(1/COUNT($G$4:$Q$4))-1,"")
B7: =+Peers!B8 | R7: =IFERROR((Q7/G7)^(1/COUNT($G$4:$Q$4))-1,"")
B8: =+Peers!B9 | R8: =IFERROR((Q8/G8)^(1/COUNT($G$4:$Q$4))-1,"")
B9: =+Peers!B10 | R9: =IFERROR((Q9/G9)^(1/COUNT($G$4:$Q$4))-1,"")
B10: =+Peers!B11 | R10: =IFERROR((Q10/G10)^(1/COUNT($G$4:$Q$4))-1,"")
B11: =+Peers!B12 | R11: =IFERROR((Q11/G11)^(1/COUNT($G$4:$Q$4))-1,"")
B12: =+Peers!B13 | R12: =IFERROR((Q12/G12)^(1/COUNT($G$4:$Q$4))-1,"")
B13: =+Peers!B14 | R13: =IFERROR((Q13/G13)^(1/COUNT($G$4:$Q$4))-1,"")
B14: =+Peers!B15 | R14: =IFERROR((Q14/G14)^(1/COUNT($G$4:$Q$4))-1,"")
B15: =+Peers!B16 | R15: =IFERROR((Q15/G15)^(1/COUNT($G$4:$Q$4))-1,"")
B16: =+Peers!B17 | R16: =IFERROR((Q16/G16)^(1/COUNT($G$4:$Q$4))-1,"")
A18: x | B18: Total GHG Scope 2 (Location-Based) Emissions | G18: 2014 | H18: =+G18+1 -> 2015 | I18: =+H18+1 -> 2016 | J18: =+I18+1 -> 2017 | K18: =+J18+1 -> 2018 | L18: =+K18+1 -> 2019 | M18: =+L18+1 -> 2020 | N18: =+M18+1 -> 2021 | O18: =+N18+1 -> 2022 | ... Q18: =+P18+1 -> 2024 | R18: ="CAGR "&$G$4&" - "&$Q$4 -> CAGR 2014 - 2024
B20: =+$B$6 | R20: =IFERROR((Q20/G20)^(1/COUNT($G$4:$Q$4))-1,"")
B21: =+$B$7 | R21: =IFERROR((Q21/G21)^(1/COUNT($G$4:$Q$4))-1,"")
B22: =+$B$8 | R22: =IFERROR((Q22/G22)^(1/COUNT($G$4:$Q$4))-1,"")
B23: =+$B$9 | R23: =IFERROR((Q23/G23)^(1/COUNT($G$4:$Q$4))-1,"")
B24: =+$B$10 | R24: =IFERROR((Q24/G24)^(1/COUNT($G$4:$Q$4))-1,"")
B25: =+$B$11 | R25: =IFERROR((Q25/G25)^(1/COUNT($G$4:$Q$4))-1,"")
B26: =+$B$12 | R26: =IFERROR((Q26/G26)^(1/COUNT($G$4:$Q$4))-1,"")
B27: =+$B$13 | R27: =IFERROR((Q27/G27)^(1/COUNT($G$4:$Q$4))-1,"")
B28: =+$B$14 | R28: =IFERROR((Q28/G28)^(1/COUNT($G$4:$Q$4))-1,"")
B29: =+$B$15 | R29: =IFERROR((Q29/G29)^(1/COUNT($G$4:$Q$4))-1,"")
B30: =+$B$16 | R30: =IFERROR((Q30/G30)^(1/COUNT($G$4:$Q$4))-1,"")
A32: x | B32: Total Energy Usage | G32: 2014 | H32: =+G32+1 -> 2015 | I32: =+H32+1 -> 2016 | J32: =+I32+1 -> 2017 | K32: =+J32+1 -> 2018 | L32: =+K32+1 -> 2019 | M32: =+L32+1 -> 2020 | N32: =+M32+1 -> 2021 | O32: =+N32+1 -> 2022 | ... Q32: =+P32+1 -> 2024 | R32: ="CAGR "&$G$4&" - "&$Q$4 -> CAGR 2014 - 2024
B34: =+$B$6 | R34: =IFERROR((Q34/G34)^(1/COUNT($G$4:$Q$4))-1,"")
B35: =+$B$7 | R35: =IFERROR((Q35/G35)^(1/COUNT($G$4:$Q$4))-1,"")
B36: =+$B$8 | R36: =IFERROR((Q36/G36)^(1/COUNT($G$4:$Q$4))-1,"")
B37: =+$B$9 | R37: =IFERROR((Q37/G37)^(1/COUNT($G$4:$Q$4))-1,"")
B38: =+$B$10 | R38: =IFERROR((Q38/G38)^(1/COUNT($G$4:$Q$4))-1,"")
B39: =+$B$11 | R39: =IFERROR((Q39/G39)^(1/COUNT($G$4:$Q$4))-1,"")
B40: =+$B$12 | R40: =IFERROR((Q40/G40)^(1/COUNT($G$4:$Q$4))-1,"")
B41: =+$B$13 | R41: =IFERROR((Q41/G41)^(1/COUNT($G$4:$Q$4))-1,"")
B42: =+$B$14 | R42: =IFERROR((Q42/G42)^(1/COUNT($G$4:$Q$4))-1,"")
B43: =+$B$15 | R43: =IFERROR((Q43/G43)^(1/COUNT($G$4:$Q$4))-1,"")
B44: =+$B$16 | R44: =IFERROR((Q44/G44)^(1/COUNT($G$4:$Q$4))-1,"")
A46: x | B46: Total Water Consumption | G46: 2014 | H46: =+G46+1 -> 2015 | I46: =+H46+1 -> 2016 | J46: =+I46+1 -> 2017 | K46: =+J46+1 -> 2018 | L46: =+K46+1 -> 2019 | M46: =+L46+1 -> 2020 | N46: =+M46+1 -> 2021 | O46: =+N46+1 -> 2022 | ... Q46: =+P46+1 -> 2024 | R46: ="CAGR "&$G$4&" - "&$Q$4 -> CAGR 2014 - 2024
B48: =+$B$6 | R48: =IFERROR((Q48/G48)^(1/COUNT($G$4:$Q$4))-1,"")
