Workbook
Name COOLFUCNTION: _xlfn.LAMBDA(_xldudf_BOARDFLARE_EXEC("workbook-settings:coolfucntion"))
Name COOLFUCNTION: _xlfn.LAMBDA(_xldudf_BOARDFLARE_EXEC("workbook-settings:coolfucntion"))
Name COOLFUCNTION: _xlfn.LAMBDA(_xldudf_BOARDFLARE_EXEC("workbook-settings:coolfucntion"))
Name COOLFUCNTION: _xlfn.LAMBDA(_xldudf_BOARDFLARE_EXEC("workbook-settings:coolfucntion"))
Name COOLFUCNTION: _xlfn.LAMBDA(_xldudf_BOARDFLARE_EXEC("workbook-settings:coolfucntion"))
Name COOLFUCNTION: _xlfn.LAMBDA(_xldudf_BOARDFLARE_EXEC("workbook-settings:coolfucntion"))
Name COOLFUCNTION: _xlfn.LAMBDA(_xldudf_BOARDFLARE_EXEC("workbook-settings:coolfucntion"))
Name COOLFUCNTION: _xlfn.LAMBDA(_xldudf_BOARDFLARE_EXEC("workbook-settings:coolfucntion"))
Name COOLFUCNTION: _xlfn.LAMBDA(_xldudf_BOARDFLARE_EXEC("workbook-settings:coolfucntion"))
Name COOLFUCNTION: _xlfn.LAMBDA(_xldudf_BOARDFLARE_EXEC("workbook-settings:coolfucntion"))
Name Sectors: #REF!
Name Sectors: #REF!
Name Sectors: #REF!

Sheet Summary
E2: | EQUITY RESEARCH | U2: Lisbon Investment Society Equity Research
U3: April 5, 2025
D6: {=+_FV(DCF!R4,"Name")} -> SK hynix Inc. | U6: Strong Buy
D8: {=_FV(U8,"Descrição")} -> SK Hynix Inc is a Korea-based company mainly engaged in the production and sale of semiconductor memories. The Company’s major products include dynamic random access memory (DRAM), NAND flashes, as well as multi-chip packages (MCP), among others. In addition, the Company manufactures and sells complementary metal oxide semiconductor image sensors (CISs). CISs is used in mobile phones, notebooks, tablets, medical devices, digital single lens reflex (DSLR) cameras, camcorders, automobiles, security equipments, game machines, and home appliances. The Company distributes its products within the domestic market and to overseas markets, including America, Germany, United Kingdom, Japan, Singapore, India, and China. | U8: #VALUE!
U9: {=+"Price (7 Mar 25): ₩"&_FV(DCF!$R$4,"Price")} -> Price (7 Mar 25): ₩184400
D10: Investment Thesis | U10: ="Price Target: ₩" & ROUND(IF(Summary!G25="FCFF",DCF!Q214,IF(Summary!G25="FCFE",DCF!Q257,IF(Summary!G25="Tax Shield",DCF!Q230,DCF!Q273))),2) &" "&IF(Summary!G25="FCFF","(FCFF)",IF(Summary!G25="FCFE","(FCFE)",IF(Summary!G25="Tax Shield","(APV)","(DDM)"))) -> Price Target: ₩257816.51 (FCFF)
D11: SK Hynix is uniquely positioned to benefit from the accelerating demand for advanced memory driven by the global AI boom. As the leading supplier of high-bandwidth memory (HBM) to NVIDIA, and with HBM4 production on track for late 2025, the company sits at the core of AI infrastructure buildout. Despite this strategic positioning, SK Hynix trades at a 72% TTM EV/EBITDA discount to the NASDAQ 100, far below the historical Korean average of 45%, reflecting an exaggerated valuation gap rather than fundamentals. With DRAM recovering, NAND bottoming, and HBM supply sold out for 2025, SK Hynix offers rare exposure to both cyclical recovery and structural growth, at a deeply mispriced entry point. | U11: =+"Upside (Downside): "&ROUND((DCF!$Q$217*100),2)&"%" -> Upside (Downside): 42.44%
U14: =+Industry!E29&", "&ESG!C9 -> South Korea, Informational Technology
U15: =+ESG!C10 -> Semiconductor Equipment
D17: Market Data | F17: 2023 | G17: =+F17+1 -> 2024 | H17: =+G17+1 -> 2025 | I17: =+H17+1 -> 2026 | K17: Valuation Multiples | N17: 2022 | O17: =+N17+1 -> 2023 | P17: =+O17+1 -> 2024 | Q17: =+P17+1 -> 2025 | R17: =+Q17+1 -> 2026 | U17: Raul Vasconcelos, Co-head of ER
D18: =+DCF!B17 -> DRAM Market | F18: =+DCF!F17 -> 79410.252 | G18: =+DCF!G17 -> 152948.38 | H18: =+DCF!H17 -> 183538.06 | I18: =+DCF!I17 -> 215069.9 | K18: EV / Sales | N18: =IFERROR(_xlfn.XLOOKUP($K18,Ratios!$B:$B,Ratios!N:N),"") -> 1.4951638 | O18: =IFERROR(_xlfn.XLOOKUP($K18,Ratios!$B:$B,Ratios!O:O),"") -> 3.5238512 | P18: =IFERROR(_xlfn.XLOOKUP($K18,Ratios!$B:$B,Ratios!P:P),"") -> 1.923657 | Q18: =IFERROR(_xlfn.XLOOKUP($K18,Ratios!$B:$B,Ratios!Q:Q),"") -> 2.7637354 | R18: =IFERROR(_xlfn.XLOOKUP($K18,Ratios!$B:$B,Ratios!R:R),"") -> 2.54297 | U18: raul.vasconcelos@aln.iseg.ulisboa.pt
D19: =+DCF!B18 -> Market growth | F19: =+DCF!F18 -> -0.36065483 | G19: =+DCF!G18 -> 0.92605338 | H19: =+DCF!H18 -> 0.2 | I19: =+DCF!I18 -> 0.1718 | K19: Price / Sales | N19: =IFERROR(_xlfn.XLOOKUP($K19,Ratios!$B:$B,Ratios!N:N),"") -> 1.1557183 | O19: =IFERROR(_xlfn.XLOOKUP($K19,Ratios!$B:$B,Ratios!O:O),"") -> 2.9715877 | P19: =IFERROR(_xlfn.XLOOKUP($K19,Ratios!$B:$B,Ratios!P:P),"") -> 1.8093292 | Q19: =IFERROR(_xlfn.XLOOKUP($K19,Ratios!$B:$B,Ratios!Q:Q),"") -> 2.5449301 | R19: =IFERROR(_xlfn.XLOOKUP($K19,Ratios!$B:$B,Ratios!R:R),"") -> 2.2047795 | U19: (+351) 960 242 437
D20: =+DCF!B19 -> SK Hynix Market Share | F20: =+DCF!F19 -> 0.26153628 | G20: =+DCF!G19 -> 0.29246248 | H20: =+DCF!H19 -> 0.30508108 | I20: =+DCF!I19 -> 0.31246248 | K20: EV / EBITDA | N20: =IFERROR(_xlfn.XLOOKUP($K20,Ratios!$B:$B,Ratios!N:N),"") -> 8.9088506 | O20: =IFERROR(_xlfn.XLOOKUP($K20,Ratios!$B:$B,Ratios!O:O),"") -> -16.163601 | P20: =IFERROR(_xlfn.XLOOKUP($K20,Ratios!$B:$B,Ratios!P:P),"") -> 5.2995642 | Q20: =IFERROR(_xlfn.XLOOKUP($K20,Ratios!$B:$B,Ratios!Q:Q),"") -> 11.452243 | R20: =IFERROR(_xlfn.XLOOKUP($K20,Ratios!$B:$B,Ratios!R:R),"") -> 9.9819784 | U20: Maria Ana Rocha, ER Analyst
D21: =+DCF!B24 -> Nand Market | F21: =+DCF!F24 -> 45721.938 | G21: =+DCF!G24 -> 71577.847 | H21: =+DCF!H24 -> 78735.632 | I21: =+DCF!I24 -> 85554.138 | K21: EV / EBIT | N21: =IFERROR(_xlfn.XLOOKUP($K21,Ratios!$B:$B,Ratios!N:N),"") -> 9.7977208 | O21: =IFERROR(_xlfn.XLOOKUP($K21,Ratios!$B:$B,Ratios!O:O),"") -> -14.936025 | P21: =IFERROR(_xlfn.XLOOKUP($K21,Ratios!$B:$B,Ratios!P:P),"") -> 5.4259368 | Q21: =IFERROR(_xlfn.XLOOKUP($K21,Ratios!$B:$B,Ratios!Q:Q),"") -> 11.868305 | R21: =IFERROR(_xlfn.XLOOKUP($K21,Ratios!$B:$B,Ratios!R:R),"") -> 10.324853 | U21: maria.ana.rocha@aln.iseg.ulisboa.pt
D22: =+DCF!B25 -> Market growth | F22: =+DCF!F25 -> -0.30124207 | G22: =+DCF!G25 -> 0.56550334 | H22: =+DCF!H25 -> 0.1 | I22: =+DCF!I25 -> 0.0866 | K22: Price / Earnings | N22: =IFERROR(_xlfn.XLOOKUP($K22,Ratios!$B:$B,Ratios!N:N),"") -> 23.004862 | O22: =IFERROR(_xlfn.XLOOKUP($K22,Ratios!$B:$B,Ratios!O:O),"") -> -10.65555 | P22: =IFERROR(_xlfn.XLOOKUP($K22,Ratios!$B:$B,Ratios!P:P),"") -> 6.0496199 | Q22: =IFERROR(_xlfn.XLOOKUP($K22,Ratios!$B:$B,Ratios!Q:Q),"") -> 16.665114 | R22: =IFERROR(_xlfn.XLOOKUP($K22,Ratios!$B:$B,Ratios!R:R),"") -> 12.147745 | U22: (+351) 935 474 506
D23: =+DCF!B26 -> SK Hynix Market Share | F23: =+DCF!F26 -> 0.21112534 | G23: =+DCF!G26 -> 0.26927479 | H23: =+DCF!H26 -> 0.26927479 | I23: =+DCF!I26 -> 0.26927479 | K23: Price / Book | N23: =IFERROR(_xlfn.XLOOKUP($K23,Ratios!$B:$B,Ratios!N:N),"") -> 0.81481423 | O23: =IFERROR(_xlfn.XLOOKUP($K23,Ratios!$B:$B,Ratios!O:O),"") -> 1.8197988 | P23: =IFERROR(_xlfn.XLOOKUP($K23,Ratios!$B:$B,Ratios!P:P),"") -> 1.6202908 | Q23: =IFERROR(_xlfn.XLOOKUP($K23,Ratios!$B:$B,Ratios!Q:Q),"") -> 2.3578344 | R23: =IFERROR(_xlfn.XLOOKUP($K23,Ratios!$B:$B,Ratios!R:R),"") -> 2.2618721 | U23: Rodrigo Ji, ER Analyst
U24: l63970@aln.iseg.ulisboa.pt
D25: Year | E25: Net Sales | F25: EBIT Margin | G25: FCFF | H25: =+IF(Summary!$G$25="FCFF",DCF!AB6,IF(Summary!$G$25="FCFE",DCF!AC6,DCF!AD6)) -> NOPAT | I25: Net Capex | K25: Profitability Ratios | N25: 2022 | O25: =+N25+1 -> 2023 | P25: =+O25+1 -> 2024 | Q25: =+P25+1 -> 2025 | R25: =+Q25+1 -> 2026 | U25: (+351) 963 757 458
D26: 2022 | E26: =+DCF!E36 -> 44621.6 | F26: =+DCF!E64 -> 0.15260322 | G26: {=TRANSPOSE(DCF!F198:M198)} -> -270.113 | H26: =+IF(Summary!$G$25="FCFF",DCF!AB7,IF(Summary!$G$25="FCFE",DCF!AC7,DCF!AD7)) -> 3813.4886 | I26: =+DCF!E138 -> -19424.2 | K26: Return on Assets | N26: =IFERROR(_xlfn.XLOOKUP($K26,Ratios!$B:$B,Ratios!N:N),"") -> 0.021581473 | O26: =IFERROR(_xlfn.XLOOKUP($K26,Ratios!$B:$B,Ratios!O:O),"") -> -0.091075269 | P26: =IFERROR(_xlfn.XLOOKUP($K26,Ratios!$B:$B,Ratios!P:P),"") -> 0.16517514 | Q26: =IFERROR(_xlfn.XLOOKUP($K26,Ratios!$B:$B,Ratios!Q:Q),"") -> 0.10158014 | R26: =IFERROR(_xlfn.XLOOKUP($K26,Ratios!$B:$B,Ratios!R:R),"") -> 0.14102809 | U26: Joao Branco, ER Analyst
D27: =+D26+1 -> 2023 | E27: =+DCF!F36 -> 32765.7 | F27: =+DCF!F64 -> -0.23592965 | G27: 10413.865 | H27: =+IF(Summary!$G$25="FCFF",DCF!AB8,IF(Summary!$G$25="FCFE",DCF!AC8,DCF!AD8)) -> -6059.179 | I27: =+DCF!F138 -> -7239.5 | K27: Return on Equity | N27: =IFERROR(_xlfn.XLOOKUP($K27,Ratios!$B:$B,Ratios!N:N),"") -> 0.035419218 | O27: =IFERROR(_xlfn.XLOOKUP($K27,Ratios!$B:$B,Ratios!O:O),"") -> -0.17078413 | P27: =IFERROR(_xlfn.XLOOKUP($K27,Ratios!$B:$B,Ratios!P:P),"") -> 0.26783349 | Q27: =IFERROR(_xlfn.XLOOKUP($K27,Ratios!$B:$B,Ratios!Q:Q),"") -> -1.0685163e-15 | R27: =IFERROR(_xlfn.XLOOKUP($K27,Ratios!$B:$B,Ratios!R:R),"") -> -1.4834672e-15 | U27: l61862@aln.iseg.ulisboa.pt
D28: =+D27+1 -> 2024 | E28: =+DCF!G36 -> 66193 | F28: =+DCF!G64 -> 0.35452994 | G28: -6051.9415 | H28: =+IF(Summary!$G$25="FCFF",DCF!AB9,IF(Summary!$G$25="FCFE",DCF!AC9,DCF!AD9)) -> 19450.565 | I28: =+DCF!G138 -> -16595.8 | K28: Return on Total Capital | N28: =IFERROR(_xlfn.XLOOKUP($K28,Ratios!$B:$B,Ratios!N:N),"") -> 0.045134155 | O28: =IFERROR(_xlfn.XLOOKUP($K28,Ratios!$B:$B,Ratios!O:O),"") -> -0.075465515 | P28: =IFERROR(_xlfn.XLOOKUP($K28,Ratios!$B:$B,Ratios!P:P),"") -> 0.20388625 | Q28: =IFERROR(_xlfn.XLOOKUP($K28,Ratios!$B:$B,Ratios!Q:Q),"") -> -1.1800366e-15 | R28: =IFERROR(_xlfn.XLOOKUP($K28,Ratios!$B:$B,Ratios!R:R),"") -> -1.5681202e-15 | U28: (+351) 924 355 215
D29: =+D28+1 -> 2025 | E29: =+DCF!H36 -> 79767.388 | F29: =+DCF!H64 -> 0.23286689 | G29: 4190.3822 | H29: =+IF(Summary!$G$25="FCFF",DCF!AB10,IF(Summary!$G$25="FCFE",DCF!AC10,DCF!AD10)) -> 13452.632 | I29: =+DCF!H138 -> -27178.341 | K29: EBITDA Margin | N29: =IFERROR(_xlfn.XLOOKUP($K29,Ratios!$B:$B,Ratios!N:N),"") -> 0.16782903 | O29: =IFERROR(_xlfn.XLOOKUP($K29,Ratios!$B:$B,Ratios!O:O),"") -> -0.21801152 | P29: =IFERROR(_xlfn.XLOOKUP($K29,Ratios!$B:$B,Ratios!P:P),"") -> 0.362984 | Q29: =IFERROR(_xlfn.XLOOKUP($K29,Ratios!$B:$B,Ratios!Q:Q),"") -> 0.241327 | R29: =IFERROR(_xlfn.XLOOKUP($K29,Ratios!$B:$B,Ratios!R:R),"") -> 0.25475611
D30: =+D29+1 -> 2026 | E30: =+DCF!I36 -> 93179.47 | F30: =+DCF!I64 -> 0.246296 | G30: 6770.2361 | H30: =+IF(Summary!$G$25="FCFF",DCF!AB11,IF(Summary!$G$25="FCFE",DCF!AC11,DCF!AD11)) -> 17876.856 | I30: =+DCF!I138 -> -31608.232 | K30: EBIT Margin | N30: =IFERROR(_xlfn.XLOOKUP($K30,Ratios!$B:$B,Ratios!N:N),"") -> 0.15260322 | O30: =IFERROR(_xlfn.XLOOKUP($K30,Ratios!$B:$B,Ratios!O:O),"") -> -0.23592965 | P30: =IFERROR(_xlfn.XLOOKUP($K30,Ratios!$B:$B,Ratios!P:P),"") -> 0.35452994 | Q30: =IFERROR(_xlfn.XLOOKUP($K30,Ratios!$B:$B,Ratios!Q:Q),"") -> 0.23286689 | R30: =IFERROR(_xlfn.XLOOKUP($K30,Ratios!$B:$B,Ratios!R:R),"") -> 0.246296 | U30: Statistics
D31: =+D30+1 -> 2027 | E31: =+DCF!J36 -> 106852.3 | F31: =+DCF!J64 -> 0.25310524 | G31: 6926.0222 | H31: =+IF(Summary!$G$25="FCFF",DCF!AB12,IF(Summary!$G$25="FCFE",DCF!AC12,DCF!AD12)) -> 21023.034 | I31: =+DCF!J138 -> -36638.734 | K31: Gross Profit Margin | N31: =IFERROR(_xlfn.XLOOKUP($K31,Ratios!$B:$B,Ratios!N:N),"") -> 0.35023173 | O31: =IFERROR(_xlfn.XLOOKUP($K31,Ratios!$B:$B,Ratios!O:O),"") -> -0.016282271 | P31: =IFERROR(_xlfn.XLOOKUP($K31,Ratios!$B:$B,Ratios!P:P),"") -> 0.48083936 | Q31: =IFERROR(_xlfn.XLOOKUP($K31,Ratios!$B:$B,Ratios!Q:Q),"") -> 0.35 | R31: =IFERROR(_xlfn.XLOOKUP($K31,Ratios!$B:$B,Ratios!R:R),"") -> 0.35 | U31: Beta | V31: =Peers!D74 -> 1.1446
D32: =+D31+1 -> 2028 | E32: =+DCF!K36 -> 120498.4 | F32: =+DCF!K64 -> 0.25913056 | G32: 10565.121 | H32: =+IF(Summary!$G$25="FCFF",DCF!AB13,IF(Summary!$G$25="FCFE",DCF!AC13,DCF!AD13)) -> 23736.295 | I32: =+DCF!K138 -> -41027.39 | K32: SG&A Margin | N32: =IFERROR(_xlfn.XLOOKUP($K32,Ratios!$B:$B,Ratios!N:N),"") -> 0.082123904 | O32: =IFERROR(_xlfn.XLOOKUP($K32,Ratios!$B:$B,Ratios!O:O),"") -> 0.087258932 | P32: =IFERROR(_xlfn.XLOOKUP($K32,Ratios!$B:$B,Ratios!P:P),"") -> 0.05083468 | Q32: =IFERROR(_xlfn.XLOOKUP($K32,Ratios!$B:$B,Ratios!Q:Q),"") -> 0.044911977 | R32: =IFERROR(_xlfn.XLOOKUP($K32,Ratios!$B:$B,Ratios!R:R),"") -> 0.039778236 | U32: % Float | V32: =+Peers!D73 -> 0.78296516
D33: =+D32+1 -> 2029 | E33: =+DCF!L36 -> 133714 | F33: =+DCF!L64 -> 0.26455899 | G33: 12992.71 | H33: =+IF(Summary!$G$25="FCFF",DCF!AB14,IF(Summary!$G$25="FCFE",DCF!AC14,DCF!AD14)) -> 27315.227 | I33: =+DCF!L138 -> -45482.143 | K33: Net Income Margin | N33: =IFERROR(_xlfn.XLOOKUP($K33,Ratios!$B:$B,Ratios!N:N),"") -> 0.050238001 | O33: =IFERROR(_xlfn.XLOOKUP($K33,Ratios!$B:$B,Ratios!O:O),"") -> -0.278877 | P33: =IFERROR(_xlfn.XLOOKUP($K33,Ratios!$B:$B,Ratios!P:P),"") -> 0.29908147 | Q33: =IFERROR(_xlfn.XLOOKUP($K33,Ratios!$B:$B,Ratios!Q:Q),"") -> 0.15271003 | R33: =IFERROR(_xlfn.XLOOKUP($K33,Ratios!$B:$B,Ratios!R:R),"") -> 0.18149702 | U33: % Held by Insiders | V33: =+Peers!D76 -> 0.2042
U34: % Held by Institutions | V34: =+Peers!D77 -> 0.439
D35: SWOT Analysis | K35: Liquidity Ratios | N35: 2022 | O35: =+N35+1 -> 2023 | P35: =+O35+1 -> 2024 | Q35: =+P35+1 -> 2025 | R35: =+Q35+1 -> 2026 | U35: Short % of Float | V35: =+Peers!D78 -> 0
D36: Strengths | G36: Weaknesses | K36: Cash Ratio | N36: =IFERROR(_xlfn.XLOOKUP($K36,Ratios!$B:$B,Ratios!N:N),"") -> 0.25081008 | O36: =IFERROR(_xlfn.XLOOKUP($K36,Ratios!$B:$B,Ratios!O:O),"") -> 0.36116585 | P36: =IFERROR(_xlfn.XLOOKUP($K36,Ratios!$B:$B,Ratios!P:P),"") -> 0.44882517 | Q36: =IFERROR(_xlfn.XLOOKUP($K36,Ratios!$B:$B,Ratios!Q:Q),"") -> -0.058287674 | R36: =IFERROR(_xlfn.XLOOKUP($K36,Ratios!$B:$B,Ratios!R:R),"") -> 0.22368549 | W36: 120.87
D37: HBM market leadership, supplying NVIDIA's Blackwell. Strong positioning in DRAM (36% market share). Vertical integration, reducing supplier dependency. | G37: Heavy exposure to China, with multiple manufacturing facilities located there. Volatile NAND margins. High dependence of geopolitical waivers. | K37: Quick Ratio | N37: =IFERROR(_xlfn.XLOOKUP($K37,Ratios!$B:$B,Ratios!N:N),"") -> 0.56771167 | O37: =IFERROR(_xlfn.XLOOKUP($K37,Ratios!$B:$B,Ratios!O:O),"") -> 0.72789155 | P37: =IFERROR(_xlfn.XLOOKUP($K37,Ratios!$B:$B,Ratios!P:P),"") -> 1.0793739 | Q37: =IFERROR(_xlfn.XLOOKUP($K37,Ratios!$B:$B,Ratios!Q:Q),"") -> 0.68400826 | R37: =IFERROR(_xlfn.XLOOKUP($K37,Ratios!$B:$B,Ratios!R:R),"") -> 1.0776456 | U37: Ownership Structure | W37: 113.63
K38: Current Ratio | N38: =IFERROR(_xlfn.XLOOKUP($K38,Ratios!$B:$B,Ratios!N:N),"") -> 1.447981 | O38: =IFERROR(_xlfn.XLOOKUP($K38,Ratios!$B:$B,Ratios!O:O),"") -> 1.4503232 | P38: =IFERROR(_xlfn.XLOOKUP($K38,Ratios!$B:$B,Ratios!P:P),"") -> 1.6934998 | Q38: =IFERROR(_xlfn.XLOOKUP($K38,Ratios!$B:$B,Ratios!Q:Q),"") -> 1.4587889 | R38: =IFERROR(_xlfn.XLOOKUP($K38,Ratios!$B:$B,Ratios!R:R),"") -> 1.4587889 | U38: Foreigner | V38: 0.539 | X38: The only foreign fund that owns more than 5% of stock is The Capital Group Companies, Inc. Totalling 6.7% of shares
U39: SK Square | V39: 0.201
D40: Opportunities | G40: Threats | K40: Cash Flow Ratios | N40: 2022 | O40: =+N40+1 -> 2023 | P40: =+O40+1 -> 2024 | Q40: =+P40+1 -> 2025 | R40: =+Q40+1 -> 2026 | U40: National Pension Service | V40: 0.074
D41: Mass production of HBM. Growing AI and HPC. Recovery in NAND pricing. Potential correction in Korean equities prices (current EV/EBITDA discount 72% vs usual 45%) | G41: Samsung's aggresive HBM4 roadmap and R&D. Micron's geopolitical advantage. U.S.-China trade tensions, disrupting Chinese production. KRW appreciation risk. Decreasing demand for conventional memory. | K41: Cash Conversion Cycle | N41: =IFERROR(_xlfn.XLOOKUP($K41,Ratios!$B:$B,Ratios!N:N),"") -> 221.74086 | O41: =IFERROR(_xlfn.XLOOKUP($K41,Ratios!$B:$B,Ratios!O:O),"") -> 200.73201 | P41: =IFERROR(_xlfn.XLOOKUP($K41,Ratios!$B:$B,Ratios!P:P),"") -> 200.64302 | Q41: =IFERROR(_xlfn.XLOOKUP($K41,Ratios!$B:$B,Ratios!Q:Q),"") -> 167.98406 | R41: =IFERROR(_xlfn.XLOOKUP($K41,Ratios!$B:$B,Ratios!R:R),"") -> 169.67067 | U41: Domestic Individual | V41: 0.073
K42: Net Income / Op Cash Flow | N42: =IFERROR(_xlfn.XLOOKUP($K42,Ratios!$B:$B,Ratios!N:N),"") -> 0.15166605 | O42: =IFERROR(_xlfn.XLOOKUP($K42,Ratios!$B:$B,Ratios!O:O),"") -> -2.1358515 | P42: =IFERROR(_xlfn.XLOOKUP($K42,Ratios!$B:$B,Ratios!P:P),"") -> 0.66442363 | Q42: =IFERROR(_xlfn.XLOOKUP($K42,Ratios!$B:$B,Ratios!Q:Q),"") -> 1.6033417 | R42: =IFERROR(_xlfn.XLOOKUP($K42,Ratios!$B:$B,Ratios!R:R),"") -> 1.0881717 | U42: Domestic Institutions | V42: 0.06
K43: Chg in Cash / Op Cash Flow | N43: =IFERROR(_xlfn.XLOOKUP($K43,Ratios!$B:$B,Ratios!N:N),"") -> -0.0054801935 | O43: =IFERROR(_xlfn.XLOOKUP($K43,Ratios!$B:$B,Ratios!O:O),"") -> 0.61013978 | P43: =IFERROR(_xlfn.XLOOKUP($K43,Ratios!$B:$B,Ratios!P:P),"") -> 0.12141939 | Q43: =IFERROR(_xlfn.XLOOKUP($K43,Ratios!$B:$B,Ratios!Q:Q),"") -> -1.6655929 | R43: =IFERROR(_xlfn.XLOOKUP($K43,Ratios!$B:$B,Ratios!R:R),"") -> 0.45107214 | U43: Others | V43: 0.027
U44: Treasury Stock | V44: 0.026
D45: Revenue by Region | G45: Revenue by Segment | K45: Leverage Ratios | N45: 2022 | O45: =+N45+1 -> 2023 | P45: =+O45+1 -> 2024 | Q45: =+P45+1 -> 2025 | R45: =+Q45+1 -> 2026
K46: Total Debt / Equity | N46: =IFERROR(_xlfn.XLOOKUP($K46,Ratios!$B:$B,Ratios!N:N),"") -> 0.33499182 | O46: =IFERROR(_xlfn.XLOOKUP($K46,Ratios!$B:$B,Ratios!O:O),"") -> 0.50065416 | P46: =IFERROR(_xlfn.XLOOKUP($K46,Ratios!$B:$B,Ratios!P:P),"") -> 0.29064732 | Q46: =IFERROR(_xlfn.XLOOKUP($K46,Ratios!$B:$B,Ratios!Q:Q),"") -> -1.8844787e-15 | R46: =IFERROR(_xlfn.XLOOKUP($K46,Ratios!$B:$B,Ratios!R:R),"") -> -2.0487953e-15 | U46: ESG Traffic Light
K47: Total Debt / Capital | N47: =IFERROR(_xlfn.XLOOKUP($K47,Ratios!$B:$B,Ratios!N:N),"") -> 0.25093174 | O47: =IFERROR(_xlfn.XLOOKUP($K47,Ratios!$B:$B,Ratios!O:O),"") -> 0.33362394 | P47: =IFERROR(_xlfn.XLOOKUP($K47,Ratios!$B:$B,Ratios!P:P),"") -> 0.225195 | Q47: =IFERROR(_xlfn.XLOOKUP($K47,Ratios!$B:$B,Ratios!Q:Q),"") -> -1.8844787e-15 | R47: =IFERROR(_xlfn.XLOOKUP($K47,Ratios!$B:$B,Ratios!R:R),"") -> -2.0487953e-15 | U47: LSEG ESG Score | V47: =ESG!C14 -> 70
...

Sheet Segments
B2: Segments
B4: Regions | D4: Weight | E4: 2020 | F4: =+E4+1 -> 2021 | G4: =+F4+1 -> 2022 | H4: =+G4+1 -> 2023 | I4: =+H4+1 -> 2024 | J4: ="CAGR "&$G$4&" - "&$I$4 -> CAGR 2022 - 2024 | K4: 2021 | L4: =+K4+1 -> 2022 | M4: =+L4+1 -> 2023 | N4: =+M4+1 -> 2024
B6: South Korea | D6: =IFERROR(I6/SUM($I$6:$I$12),"") -> 0.028766054 | E6: =SEG!I19 -> 1452.01 | F6: =SEG!J19 -> 1461.98 | G6: =SEG!K19 -> 1225.77 | H6: =SEG!L19 -> 2033.86 | I6: =SEG!M19 -> 1904.11 | J6: =IFERROR((I6/G6)^(1/COUNT($G$4:$I$4))-1,"") -> 0.15813988 | K6: =IFERROR((F6-E6)/E6,"") -> 0.0068663439 | L6: =IFERROR((G6-F6)/F6,"") -> -0.16156856 | M6: =IFERROR((H6-G6)/G6,"") -> 0.65925092 | N6: =IFERROR((I6-H6)/H6,"") -> -0.063794951
B7: China | D7: =IFERROR(I7/SUM($I$6:$I$12),"") -> 0.23467091 | E7: =SEG!I21 -> 12217.63 | F7: =SEG!J21 -> 15730.22 | G7: =SEG!K21 -> 12210.47 | H7: =SEG!L21 -> 10110.08 | I7: =SEG!M21 -> 15533.56 | J7: =IFERROR((I7/G7)^(1/COUNT($G$4:$I$4))-1,"") -> 0.083543138 | K7: =IFERROR((F7-E7)/E7,"") -> 0.28750175 | L7: =IFERROR((G7-F7)/F7,"") -> -0.2237572 | M7: =IFERROR((H7-G7)/G7,"") -> -0.17201549 | N7: =IFERROR((I7-H7)/H7,"") -> 0.53644284
B8: Asia (without China) | D8: =IFERROR(I8/SUM($I$6:$I$12),"") -> 0.081299292 | E8: =SEG!I23 | F8: =SEG!J23 -> 7022.93 | G8: =SEG!K23 -> 5615.38 | H8: =SEG!L23 -> 4296.94 | I8: =SEG!M23 -> 5381.44 | J8: =IFERROR((I8/E8)^(1/COUNT($E$4:$I$4))-1,"") | K8: =IFERROR((F8-E8)/E8,"") | L8: =IFERROR((G8-F8)/F8,"") -> -0.20042205 | M8: =IFERROR((H8-G8)/G8,"") -> -0.23479088 | N8: =IFERROR((I8-H8)/H8,"") -> 0.25238891
B9: United States | D9: =IFERROR(I9/SUM($I$6:$I$12),"") -> 0.63392053 | E9: =SEG!I25 -> 12686.11 | F9: =SEG!J25 -> 17144.32 | G9: =SEG!K25 -> 23960.98 | H9: =SEG!L25 -> 15390.23 | I9: =SEG!M25 -> 41961.07 | J9: =IFERROR((I9/E9)^(1/COUNT($E$4:$I$4))-1,"") -> 0.27029216 | K9: =IFERROR((F9-E9)/E9,"") -> 0.35142451 | L9: =IFERROR((G9-F9)/F9,"") -> 0.39760457 | M9: =IFERROR((H9-G9)/G9,"") -> -0.35769614 | N9: =IFERROR((I9-H9)/H9,"") -> 1.7264745
B10: Europe | D10: =IFERROR(I10/SUM($I$6:$I$12),"") -> 0.02134321 | E10: =SEG!I27 -> 1222.7 | F10: =SEG!J27 -> 1638.34 | G10: =SEG!K27 -> 1608.97 | H10: =SEG!L27 -> 934.61 | I10: =SEG!M27 -> 1412.77 | J10: =IFERROR((I10/E10)^(1/COUNT($E$4:$I$4))-1,"") -> 0.029319761 | K10: =IFERROR((F10-E10)/E10,"") -> 0.33993621 | L10: =IFERROR((G10-F10)/F10,"") -> -0.017926682 | M10: =IFERROR((H10-G10)/G10,"") -> -0.41912528 | N10: =IFERROR((I10-H10)/H10,"") -> 0.51161447
D11: =IFERROR(I11/SUM($I$6:$I$12),"") -> 0
D12: =IFERROR(I12/SUM($I$6:$I$12),"") -> 0
B13: Total | D13: =SUM(D6:D12) -> 1 | E13: =SUM(E6:E10) -> 27578.45 | F13: =SUM(F6:F10) -> 42997.79 | G13: =SUM(G6:G10) -> 44621.57 | H13: =SUM(H6:H10) -> 32765.72 | I13: =SUM(I6:I10) -> 66192.95 | J13: =IFERROR((I13/G13)^(1/COUNT($G$4:$I$4))-1,"") -> 0.14048339 | K13: =IFERROR((F13-E13)/E13,"") -> 0.55910829 | L13: =IFERROR((G13-F13)/F13,"") -> 0.037764266 | M13: =IFERROR((H13-G13)/G13,"") -> -0.26569773 | N13: =IFERROR((I13-H13)/H13,"") -> 1.0201891
B15: Segments | D15: Weight | E15: 2020 | F15: =+E15+1 -> 2021 | G15: =+F15+1 -> 2022 | H15: =+G15+1 -> 2023 | I15: =+H15+1 -> 2024 | J15: ="CAGR "&$E$4&" - "&$I$4 -> CAGR 2020 - 2024 | K15: 2021 | L15: =+K15+1 -> 2022 | M15: =+L15+1 -> 2023 | N15: =+M15+1 -> 2024
B17: DRAM | D17: =IFERROR(I17/SUM($I$17:$I$21),"") -> 0.6757768 | E17: =+SEG!I6 -> 22536.4 | F17: =+SEG!J6 -> 30599.71 | G17: =+SEG!K6 -> 28168.8 | H17: =+SEG!L6 -> 20768.66 | I17: =+SEG!M6 -> 44731.66 | J17: =IFERROR((I17/E17)^(1/COUNT($E$4:$I$4))-1,"") -> 0.14695425 | K17: =IFERROR((F17-E17)/E17,"") -> 0.35779051 | L17: =IFERROR((G17-F17)/F17,"") -> -0.079442256 | M17: =IFERROR((H17-G17)/G17,"") -> -0.26270697 | N17: =IFERROR((I17-H17)/H17,"") -> 1.1538058
B18: Nand | D18: =IFERROR(I18/SUM($I$17:$I$21),"") -> 0.29118071 | E18: =+SEG!I8 -> 7471.24 | F18: =+SEG!J8 -> 10529.45 | G18: =+SEG!K8 -> 14183.92 | H18: =+SEG!L8 -> 9653.06 | I18: =+SEG!M8 -> 19274.11 | J18: =IFERROR((I18/E18)^(1/COUNT($E$4:$I$4))-1,"") -> 0.2086939 | K18: =IFERROR((F18-E18)/E18,"") -> 0.40933098 | L18: =IFERROR((G18-F18)/F18,"") -> 0.34707131 | M18: =IFERROR((H18-G18)/G18,"") -> -0.31943638 | N18: =IFERROR((I18-H18)/H18,"") -> 0.99668395
B19: Other | D19: =IFERROR(I19/SUM($I$17:$I$21),"") -> 0.033042492 | E19: =+SEG!I10 -> 1892.77 | F19: =+SEG!J10 -> 1868.63 | G19: =+SEG!K10 -> 2268.84 | H19: =+SEG!L10 -> 2344 | I19: =+SEG!M10 -> 2187.18 | J19: =IFERROR((I19/E19)^(1/COUNT($E$4:$I$4))-1,"") -> 0.029336413 | K19: =IFERROR((F19-E19)/E19,"") -> -0.012753795 | L19: =IFERROR((G19-F19)/F19,"") -> 0.21417295 | M19: =IFERROR((H19-G19)/G19,"") -> 0.033127061 | N19: =IFERROR((I19-H19)/H19,"") -> -0.06690273
D20: =IFERROR(I20/SUM($I$17:$I$21),"") -> 0 | J20: =IFERROR((I20/E20)^(1/COUNT($E$4:$I$4))-1,"") | K20: =IFERROR((F20-E20)/E20,"") | L20: =IFERROR((G20-F20)/F20,"") | M20: =IFERROR((H20-G20)/G20,"") | N20: =IFERROR((I20-H20)/H20,"")
D21: =IFERROR(I21/SUM($I$17:$I$21),"") -> 0 | J21: =IFERROR((I21/E21)^(1/COUNT($E$4:$I$4))-1,"") | K21: =IFERROR((F21-E21)/E21,"") | L21: =IFERROR((G21-F21)/F21,"") | M21: =IFERROR((H21-G21)/G21,"") | N21: =IFERROR((I21-H21)/H21,"")
B22: Total | D22: =SUM(D17:D21) -> 1 | E22: =SUM(E17:E21) -> 31900.41 | F22: =SUM(F17:F21) -> 42997.79 | G22: =SUM(G17:G21) -> 44621.56 | H22: =SUM(H17:H21) -> 32765.72 | I22: =SUM(I17:I21) -> 66192.95 | J22: =IFERROR((I22/E22)^(1/COUNT($E$4:$I$4))-1,"") -> 0.1571858 | K22: =IFERROR((F22-E22)/E22,"") -> 0.34787578 | L22: =IFERROR((G22-F22)/F22,"") -> 0.037764034 | M22: =IFERROR((H22-G22)/G22,"") -> -0.26569757 | N22: =IFERROR((I22-H22)/H22,"") -> 1.0201891
B24: Categories | D24: Description | J24: Graphs
B26: DRAM (Dynamic Random-Access Memory) | D26: High-speed, volatile memory used for temporary data storage in computers and devices. Unlike permanent storage, DRAM loses data when powered off. It stores bits in tiny capacitors that require constant refreshing, enabling cost-effective, dense memory for system RAM. This makes DRAM essential for multitasking and performance in PCs, smartphones, and servers.
B27: Nand | D27: Non-volatile storage technology that retains data even when powered off. Unlike DRAM, it doesn't require constant refreshing, making it ideal for long-term data storage in devices like SSDs, USB drives, and smartphones. NAND stores data in memory cells organized in blocks, enabling high density and cost efficiency. While slower than DRAM, its persistence and endurance make it the backbone of modern storage solutions.
B29: =IF(B20=0,"",B20)
B30: =IF(B21=0,"",B21)
B32: Products | D32: Weight | E32: 2020 | F32: =+E32+1 -> 2021 | G32: =+F32+1 -> 2022 | H32: =+G32+1 -> 2023 | I32: =+H32+1 -> 2024 | J32: =I32+1 -> 2025 | K32: =+J32+1 -> 2026 | L32: =+K32+1 -> 2027 | M32: =+L32+1 -> 2028 | N32: =+M32+1 -> 2029 | O32: =+N32+1 -> 2030 | P32: =+O32+1 -> 2031 | Q32: =+P32+1 -> 2032 | R32: =+Q32+1 -> 2033 | S32: =+R32+1 -> 2034 | T32: CAGR
B34: DRAM | D34: =IFERROR(I34/$I$13,"") -> 0.6757768 | E34: =+E17 -> 22536.4 | F34: =+F17 -> 30599.71 | G34: =+G17 -> 28168.8 | H34: =+H17 -> 20768.66 | I34: =+I17 -> 44731.66 | J34: =+I34*(1+J35) -> 49459.796 | K34: =+J34*(1+K35) -> 54687.697 | L34: =+K34*(1+L35) -> 60468.187 | M34: =+L34*(1+M35) -> 66859.674 | N34: =+M34*(1+N35) -> 73926.741 | O34: =+N34*(1+O35) -> 81740.798 | P34: =+O34*(1+P35) -> 90380.8 | Q34: =+P34*(1+Q35) -> 99934.051 | ... S34: =+R34*(1+S35) -> 122176.62 | T34: Stellar
B35: % growth | F35: =+F34/E34-1 -> 0.35779051 | G35: =+G34/F34-1 -> -0.079442256 | H35: =+H34/G34-1 -> -0.26270697 | I35: =+I34/H34-1 -> 1.1538058 | J35: =+$T$35 -> 0.1057 | K35: =+$T$35 -> 0.1057 | L35: =+$T$35 -> 0.1057 | M35: =+$T$35 -> 0.1057 | N35: =+$T$35 -> 0.1057 | O35: =+$T$35 -> 0.1057 | P35: =+$T$35 -> 0.1057 | Q35: =+$T$35 -> 0.1057 | ... S35: =+$T$35 -> 0.1057 | T35: 0.1057
B36: Nand | D36: =IFERROR(I36/$I$13,"") -> 0.29118071 | E36: =+E18 -> 7471.24 | F36: =+F18 -> 10529.45 | G36: =+G18 -> 14183.92 | H36: =+H18 -> 9653.06 | I36: =+I18 -> 19274.11 | J36: =+I36*(1+J37) -> 20353.46 | K36: =+J36*(1+K37) -> 21493.254 | L36: =+K36*(1+L37) -> 22696.876 | M36: =+L36*(1+M37) -> 23967.901 | N36: =+M36*(1+N37) -> 25310.104 | O36: =+N36*(1+O37) -> 26727.469 | P36: =+O36*(1+P37) -> 28224.208 | Q36: =+P36*(1+Q37) -> 29804.763 | ... S36: =+R36*(1+S37) -> 33236.365 | T36: GMI
B37: % growth | F37: =+F36/E36-1 -> 0.40933098 | G37: =+G36/F36-1 -> 0.34707131 | H37: =+H36/G36-1 -> -0.31943638 | I37: =+I36/H36-1 -> 0.99668395 | J37: =+$T$37 -> 0.056 | K37: =+$T$37 -> 0.056 | L37: =+$T$37 -> 0.056 | M37: =+$T$37 -> 0.056 | N37: =+$T$37 -> 0.056 | O37: =+$T$37 -> 0.056 | P37: =+$T$37 -> 0.056 | Q37: =+$T$37 -> 0.056 | ... S37: =+$T$37 -> 0.056 | T37: 0.056
B38: Other | D38: =IFERROR(I38/$I$13,"") -> 0.033042492 | E38: =+E19 -> 1892.77 | F38: =+F19 -> 1868.63 | G38: =+G19 -> 2268.84 | H38: =+H19 -> 2344 | I38: =+I19 -> 2187.18 | J38: =+I38*(1+J46) -> 2364.0135 | K38: =+J38*(1+K46) -> 2555.144 | L38: =+K38*(1+L46) -> 2761.7274 | M38: =+L38*(1+M46) -> 2985.013 | N38: =+M38*(1+N46) -> 3226.3514 | O38: =+N38*(1+O46) -> 3487.2019 | P38: =+O38*(1+P46) -> 3769.1421 | Q38: =+P38*(1+Q46) -> 4073.8773 | ... S38: =+R38*(1+S46) -> 4759.253
F39: =IFERROR((F38-E38)/E38,"") -> -0.012753795 | G39: =IFERROR((G38-F38)/F38,"") -> 0.21417295 | H39: =IFERROR((H38-G38)/G38,"") -> 0.033127061 | I39: =IFERROR((I38-H38)/H38,"") -> -0.06690273
B40: Product 3 | D40: =IFERROR(I40/$I$13,"") -> 0 | J40: =I40*(1+J41) -> 0 | K40: =J40*(1+K41) -> 0 | L40: =K40*(1+L41) -> 0 | M40: =L40*(1+M41) -> 0 | N40: =M40*(1+N41) -> 0 | O40: =N40*(1+O41) -> 0 | P40: =O40*(1+P41) -> 0 | Q40: =P40*(1+Q41) -> 0 | ... S40: =R40*(1+S41) -> 0
F41: =IFERROR(F40-E40/E40,"") | G41: =IFERROR(G40-F40/F40,"") | H41: =IFERROR(H40-G40/G40,"") | I41: =IFERROR(I40-H40/H40,"")
B42: Product 4 | D42: =IFERROR(I42/$I$13,"") -> 0 | J42: =I42*(1+J43) -> 0 | K42: =J42*(1+K43) -> 0 | L42: =K42*(1+L43) -> 0 | M42: =L42*(1+M43) -> 0 | N42: =M42*(1+N43) -> 0 | O42: =N42*(1+O43) -> 0 | P42: =O42*(1+P43) -> 0 | Q42: =P42*(1+Q43) -> 0 | ... S42: =R42*(1+S43) -> 0
F43: =IFERROR(F42-E42/E42,"") | G43: =IFERROR(G42-F42/F42,"") | H43: =IFERROR(H42-G42/G42,"") | I43: =IFERROR(I42-H42/H42,"")
B44: Product 5 | D44: =IFERROR(I44/$I$13,"") -> 0 | J44: =I44*(1+J45) -> 0 | K44: =J44*(1+K45) -> 0 | L44: =K44*(1+L45) -> 0 | M44: =L44*(1+M45) -> 0 | N44: =M44*(1+N45) -> 0 | O44: =N44*(1+O45) -> 0 | P44: =O44*(1+P45) -> 0 | Q44: =P44*(1+Q45) -> 0 | ... S44: =R44*(1+S45) -> 0
F45: =IFERROR(F44-E44/E44,"") | G45: =IFERROR(G44-F44/F44,"") | H45: =IFERROR(H44-G44/G44,"") | I45: =IFERROR(I44-H44/H44,"")
B46: % growth | F46: =+F38/E38-1 -> -0.012753795 | G46: =+G38/F38-1 -> 0.21417295 | H46: =+H38/G38-1 -> 0.033127061 | I46: =+I38/H38-1 -> -0.06690273 | J46: =+AVERAGE(J37,J35) -> 0.08085 | K46: =+J46 -> 0.08085 | L46: =+K46 -> 0.08085 | M46: =+L46 -> 0.08085 | N46: =+M46 -> 0.08085 | O46: =+N46 -> 0.08085 | P46: =+O46 -> 0.08085 | Q46: =+P46 -> 0.08085 | R46: =+Q46 -> 0.08085 | S46: =+R46 -> 0.08085
B47: Total | D47: =SUM(D34:D44) -> 1 | E47: =SUM(E34:E44) -> 31900.41 | F47: =SUM(F34:F44) -> 42998.544 | G47: =SUM(G34:G44) -> 44622.042 | H47: =SUM(H34:H44) -> 32765.171 | I47: =SUM(I34:I44) -> 66195.034 | J47: =SUM(J34:J44) -> 72177.432 | K47: =SUM(K34:K44) -> 78736.257 | ... S47: =SUM(S34:S44) -> 160172.4
B49: Company's Strategy / Extra Notes

Sheet Industry
B2: Industry Overview
E3: 584.17 | F3: 627.76 | G3: 676.06 | H3: 729.63 | I3: 789.13 | J3: 855.3 | K3: 929 | L3: 997.69 | M3: 1067.63 | N3: 1137.57 | O3: 1207.51
B4: Sales Growth Forecast | E4: Weight | F4: 2025 | G4: =+F4+1 -> 2026 | H4: =+G4+1 -> 2027 | I4: =+H4+1 -> 2028 | J4: =+I4+1 -> 2029 | K4: =+J4+1 -> 2030 | L4: =+K4+1 -> 2031 | M4: =+L4+1 -> 2032 | N4: =+M4+1 -> 2033 | ... P4: =+O4+1 -> 2035 | Q4: ="CAGR "&$F$4&" - "&$P$4 -> CAGR 2025 - 2035 | R4: Sources
B6: Semiconductor Market | E6: 1 | F6: =(F3-E3)/E3 -> 0.07461869 | G6: =(G3-F3)/F3 -> 0.076940232 | H6: =(H3-G3)/G3 -> 0.079238529 | I6: =(I3-H3)/H3 -> 0.081548182 | J6: =(J3-I3)/I3 -> 0.083851837 | K6: =(K3-J3)/J3 -> 0.086168596 | L6: =(L3-K3)/K3 -> 0.07393972 | M6: =(M3-L3)/L3 -> 0.070101935 | ... O6: =(O3-N3)/N3 -> 0.061481931 | Q6: 6,8% | R6: Precendence Research
B11: Weighted Average | E11: =SUM(E6:E10) -> 1 | F11: =SUMPRODUCT(F6:F10,$E$6:$E$10) -> 0.07461869 | G11: =SUMPRODUCT(G6:G10,$E$6:$E$10) -> 0.076940232 | H11: =SUMPRODUCT(H6:H10,$E$6:$E$10) -> 0.079238529 | I11: =SUMPRODUCT(I6:I10,$E$6:$E$10) -> 0.081548182 | J11: =SUMPRODUCT(J6:J10,$E$6:$E$10) -> 0.083851837 | K11: =SUMPRODUCT(K6:K10,$E$6:$E$10) -> 0.086168596 | L11: =SUMPRODUCT(L6:L10,$E$6:$E$10) -> 0.07393972 | M11: =SUMPRODUCT(M6:M10,$E$6:$E$10) -> 0.070101935 | ... P11: =SUMPRODUCT(P6:P10,$E$6:$E$10) -> 0 | Q11: =IFERROR(((1+F11)*(1+G11)*(1+H11)*(1+I11)*(1+J11)*(1+K11)*(1+L11)*(1+M11)*(1+N11)*(1+O11)*(1+P11))^(1/COUNT($F$4:$P$4))-1,"") -> 0.068238723
B13: Key Drivers | E13: Description
B15: AI/HPC boom | E15: Explosive demand for AI accelarators (Nvidia Blackwell/Feynman GPUs, AMD MI400) is driving 8x growth in High-Bandwidth Memory (HBM) through 2030. SK Hynix's HBM3E/HBM4 products command 70% market shre due to (1) TSMC Logic Die Partnership that enables 16-layer stacking (HBM4) with 30% better power efficiency vs competitors; (2) MR-MUF packaging that achieves 85% yield rates vs industry average of 65% (thermal compression).
B16: Supply constraints | E16: HBM production requires 3x more wafers than standard DRAM, creating shortages (1) capacity lag, since only SK Hynix/Samsung can mass-produce 12Hi+ stacks until 2026; (2) geopolitical risks, since US export controls limit China's CXMT to legacy nodes (<18nm).
B17: Automotive/edge AI demand | E17: Next-gen vehicles and IoT devices will consume 22% of DRAM by 2030, fueled by (1) LPDDR6 adoption - 30% power savings for autonomous driving systems (2027 rollout); (2) MRAM Pilots - SK Hynix's embedded memory for Tesla Dojo 2.0 (sampling 2026)
B18: Geopolitical reshoring | E18: US/EU subsidies ($53B CHIPS Act) are accelerating kicak production (1) SK Hynix Indiana Fab, $3.9B facility exempt form US-China trade tariffs; (2) Samsung Taylor, TX, $17B fab ensures HBM supply for Nvidia/AWS.
B20: Industry Trends | E20: Description
B22: AI is changing memory chip designs | E22: The need for faster data processing in AI systems is pushing memory chip makers to develop new solutions. High-Bandwidth Memory (HBM) is now essential for AI chips, with companies like SK Hynix leading in advanced 3D-stacked designs. Their latest HBM3E technology is already used in top AI processors, and even more advanced versions are coming soon. This shift is making HBM a major revenue driver, expected to grow much faster than traditional memory chips.
B23: Global politics affects where chips are made | E23: Trade tensions and new laws are forcing chip companies to spread their factories across different countries. While many still operate in China, new plants are being built in the U.S. and South Korea to reduce risks. Governments are offering incentives to attract these factories, as having local chip production is now seen as vital for economic and national security.
B24: New types of memory for future tech | E24: Beyond standard memory chips, new varieties are being developed for specific uses. Cars, smart devices, and AI systems at the "edge" (like phones and sensors) need specialized memory that’s faster, more efficient, or more durable. Companies investing in these new memory types now could gain an advantage as demand grows in the coming years.
B25: Chip makers focus on sustainability | E25: The industry is working to reduce its environmental impact by cutting water and energy use in manufacturing. New factories are being designed to run on cleaner energy and recycle more resources. These efforts aren’t just about being eco-friendly—they’re becoming important for winning business from big tech companies with strict sustainability goals.
B26: HBM is becoming a high-profit oligopoly | E26: The market for HBM is controlled by just a few companies, allowing them to charge premium prices while other memory chips face price drops. This divide is pushing chip makers to focus more on high-end HBM development, where profits remain strong despite broader industry challenges.
B27: Market Share - Memory | E27: Headquarters | G27: Revenues | H27: (in Billions of KRW) | I27: Market Share
B29: {=+_FV(DCF!R4,"Name")} -> SK hynix Inc. | E29: South Korea | G29: =+Peers!D99 -> 66193 | I29: =IFERROR(G29/$G$41,"") -> 0.28516593
B30: {=+_FV(Peers!A8,"Name")} -> Samsung Electronics Co., Ltd. | E30: South Korea | G30: 84500 | I30: =IFERROR(G30/$G$41,"") -> 0.36403428
B31: {=+_FV(Peers!A9,"Name")} -> MICRON TECHNOLOGY, INC. | E31: United States | G31: 33767 | I31: =IFERROR(G31/$G$41,"") -> 0.14547154
B32: {=+_FV(Peers!A10,"Name")} -> Kioxia Holdings Corporation | E32: Japan | G32: 9842 | I32: =IFERROR(G32/$G$41,"") -> 0.0424003
B33: {=+_FV(Peers!A11,"Name")} -> WESTERN DIGITAL CORPORATION | E33: United States | G33: =+Peers!H99 -> 17344.6 | I33: =IFERROR(G33/$G$41,"") -> 0.074722235
I34: =IFERROR(G34/$G$41,"") -> 0
I35: =IFERROR(G35/$G$41,"") -> 0
I36: =IFERROR(G36/$G$41,"") -> 0
I37: =IFERROR(G37/$G$41,"") -> 0
I38: =IFERROR(G38/$G$41,"") -> 0
I39: =IFERROR(G39/$G$41,"") -> 0
B40: Others | E40: -- | G40: =+G41-SUM(G29:G39) -> 20474.4 | I40: =IFERROR(G40/$G$41,"") -> 0.08820572
B41: Industry Size | E41: -- | G41: 232121 | H41: Statista | I41: 1
B43: Porter's Five Forces Analysis | E43: Rating | H43: Graph
B45: Threat of New Entrants | E45: =IFERROR(AVERAGE(E46:E51),"") -> 1.5
B46: Economies of scale | E46: 1
B47: Product differentiation | E47: 2
B48: Capital requirements | E48: 1
B49: Access to distribution channels | E49: 2
B50: Regulations | E50: 2
B51: Switching costs | E51: 1
B52: Bargaining Power of Suppliers | E52: =IFERROR(AVERAGE(E53:E57),"") -> 4.25
B53: Number of suppliers | E53: 4
...

Sheet Peers
D3: Revenue Growth | F3: EBITDA Margin | H3: Profit Margin | J3: EV / Revenue | L3: EV / EBITDA | N3: Price / Earnings
B4: Peers | C4: Ticker | D4: =+Inputs!O4&"-"&Inputs!P4 -> 2022-2023 | E4: =+Inputs!P4&"-"&Inputs!Q4 -> 2023-2024 | F4: 2023 | G4: 2024 | H4: =+Inputs!O4&"-"&Inputs!P4 -> 2022-2023 | I4: =+Inputs!P4&"-"&Inputs!Q4 -> 2023-2024 | J4: 2023 | K4: 2024 | L4: 2023 | M4: 2024 | N4: 2023 | O4: 2024
A6: =+D93 -> #VALUE! | B6: {=IFERROR(_FV(A6,"Name"),"")} -> SK hynix Inc. | C6: {=IFERROR(_FV(A6,"Ticker symbol",TRUE),"")} -> 000660 | D6: =IFERROR(D96/D95-1,"") -> -0.26569868 | E6: =IFERROR(D99/D96-1,"") -> 1.0201918 | F6: =IFERROR(D97/D96,"") -> -0.21801152 | G6: =IFERROR(D102/D99,"") -> 0.362984 | H6: =IFERROR(D98/D96,"") -> -0.278877 | I6: =IFERROR(D107/D99,"") -> 0.29908147 | J6: {=IFERROR((_FV(A6,"Market cap",TRUE)/1000000000+D$123-D$113)/D$96,"")} -> 4.275236 | K6: {=IFERROR((_FV(A6,"Market cap",TRUE)/1000000000+D$123-D$113)/D$99,"")} -> 2.1162525 | L6: {=+IFERROR((_FV(A6,"Market cap",TRUE)/1000000000+D$123-D$113)/D$97,"")} -> -19.610138 | M6: {=IFERROR((_FV(A6,"Market cap",TRUE)/1000000000+D$123-D$113)/D$102,"")} -> 5.8301536 | N6: {=IFERROR((_FV(A6,"Market cap",TRUE)/1000000000)/D$98,"")} -> -14.205349 | O6: {=IFERROR((_FV(A6,"Market cap",TRUE)/1000000000)/D$107,"")} -> 6.5566573
A8: =+E93 -> #VALUE! | B8: {=IFERROR(_FV(A8,"Name"),"")} -> Samsung Electronics Co., Ltd. | C8: {=+IFERROR(_FV(A8,"Ticker symbol",TRUE),"")} -> 005930 | D8: =+IFERROR(E96/E95-1,"") -> -0.14325414 | E8: =IFERROR(E99/E96-1,"") -> 0.16195307 | F8: =IFERROR(E97/E96,"") -> 0.17469022 | G8: =+IFERROR(E102/E99,"") -> 0.25046224 | H8: =IFERROR(E98/E96,"") -> 0.055895773 | I8: =+IFERROR(E107/E101,"") -> 0.29412835 | J8: {=+IFERROR((_FV(A8,"Market cap",TRUE)/1000000000+E$123-E$113)/E$96,"")} -> 1.2860566 | K8: {=IFERROR(+(_FV(A8,"Market cap",TRUE)/1000000000+E$123-E$113)/E$99,"")} -> 1.1068059 | L8: {=IFERROR(+(_FV(A8,"Market cap",TRUE)/1000000000+E$123-E$113)/E$97,"")} -> 7.3619264 | M8: {=IFERROR(+(_FV(A8,"Market cap",TRUE)/1000000000+E$123-E$113)/E$102,"")} -> 4.4190531 | N8: {=IFERROR(+(_FV(A8,"Market cap",TRUE)/1000000000)/E$98,"")} -> 25.383193 | O8: {=IFERROR(+(_FV(A8,"Market cap",TRUE)/1000000000)/E$107,"")} -> 10.927002
A9: =+F93 -> #VALUE! | B9: {=IFERROR(_FV(A9,"Name"),"")} -> MICRON TECHNOLOGY, INC. | C9: {=+IFERROR(_FV(A9,"Ticker symbol",TRUE),"")} -> MU | D9: =IFERROR(F96/F95-1,"") -> -0.4574375 | E9: =IFERROR(+F99/F96-1,"") -> 0.64442248 | F9: =IFERROR(F97/F96,"") -> 0.15868648 | G9: =IFERROR(F102/F99,"") -> 0.35777048 | H9: =IFERROR(F98/F96,"") -> -0.37535429 | I9: =+IFERROR(F107/F99,"") -> 0.030983004 | J9: {=IFERROR(+(_FV(A9,"Market cap",TRUE)*Q9/1000000000+Q9+F$123-F$113)/F$96,"")} -> 6.5140537 | K9: {=IFERROR(+(_FV(A9,"Market cap",TRUE)*Q9/1000000000+F$123-F$113)/F$99,"")} -> 3.9187347 | L9: {=IFERROR(+(_FV(A9,"Market cap",TRUE)*Q9/1000000000+F$123-F$113)/F$97,"")} -> 40.608723 | M9: {=IFERROR(+(_FV(A9,"Market cap",TRUE)*Q9/1000000000+F$123-F$113)/F$102,"")} -> 10.953209 | N9: {=IFERROR(+(_FV(A9,"Market cap",TRUE)*Q9/1000000000)/F$98,"")} -> -16.13522 | O9: {=IFERROR(+(_FV(A9,"Market cap",TRUE)*Q9/1000000000)/F$107,"")} -> 118.87194 | P9: #VALUE! | Q9: {=+_FV(P9,"Price")} -> 1437.36 | R9: Market cap is in USD, convert to KRW
A10: =+G93 -> #VALUE! | B10: {=IFERROR(_FV(A10,"Name"),"")} -> Kioxia Holdings Corporation | C10: {=IFERROR(_FV(A10,"Ticker symbol",TRUE),"")} -> KI5 | D10: =+IFERROR(G96/G95-1,"") -> -0.21842907 | E10: =IFERROR(G99/G96-1,"") -> -0.20612719 | F10: =IFERROR(G97/G96,"") -> 0.25037105 | G10: =IFERROR(G102/G99,"") -> 0.074844033 | H10: =IFERROR(G98/G96,"") -> -0.10775014 | I10: =+IFERROR(G107/G99,"") -> -0.22639151 | J10: {=IFERROR(+(_FV(A10,"Market cap",TRUE)*Q10/1000000000+G$123-G$113)/G$96,"")} -> 1.8184336 | K10: {=IFERROR(+(_FV(A10,"Market cap",TRUE)*Q10/1000000000+G$123-G$113)/G$99,"")} -> 2.2905855 | L10: {=IFERROR(+(_FV(A10,"Market cap",TRUE)*Q10/1000000000+G$123-G$113)/G$97,"")} -> 7.2629546 | M10: {=IFERROR(+(_FV(A10,"Market cap",TRUE)*Q10/1000000000+G$123-G$113)/G$102,"")} -> 30.604785 | N10: {=IFERROR(+(_FV(A10,"Market cap",TRUE)*Q10/1000000000)/G$98,"")} -> -7.3211444 | O10: {=IFERROR(+(_FV(A10,"Market cap",TRUE)*Q10/1000000000)/G$107,"")} -> -4.3892036 | P10: #VALUE! | Q10: {=+_FV(P10,"Price")} -> 10.0011 | R10: Market cap is in JPY, convert to KRW
A11: =+H93 -> #VALUE! | B11: {=IFERROR(_FV(A11,"Name"),"")} -> WESTERN DIGITAL CORPORATION | C11: {=IFERROR(_FV(A11,"Ticker symbol",TRUE),"")} -> WDC | D11: =IFERROR(H96/H95-1,"") -> -0.27908376 | E11: =IFERROR(H99/H96-1,"") -> 0.064105474 | F11: =IFERROR(H97/H96,"") -> -0.012420842 | G11: =IFERROR(H102/H99,"") -> 0.073060203 | H11: =IFERROR(H98/H96,"") -> -0.13670804 | I11: =+IFERROR(H107/H104,"") -> -2.1110252 | J11: {=IFERROR((_FV(A11,"Market cap",TRUE)*Q11/1000000000+H$123-H$113)/H$96,"")} -> 1.7503565 | K11: {=IFERROR(+(_FV(A11,"Market cap",TRUE)*Q11/1000000000+H$123-H$113)/H$99,"")} -> 1.6449088 | L11: {=IFERROR(+(_FV(A11,"Market cap",TRUE)*Q11/1000000000+H$123-H$113)/H$97,"")} -> -140.92092 | M11: {=IFERROR(+(_FV(A11,"Market cap",TRUE)*Q11/1000000000+H$123-H$113)/H$102,"")} -> 22.51443 | N11: {=IFERROR(+(_FV(A11,"Market cap",TRUE)*Q11/1000000000)/H$98,"")} -> -9.1495248 | O11: {=IFERROR(+(_FV(A11,"Market cap",TRUE)*Q11/1000000000)/H$107,"")} -> -19.154346 | P11: #VALUE! | Q11: {=+_FV(P11,"Price")} -> 1437.36 | R11: Market cap is in USD, convert to KRW
A12: =+I93 -> PEER 5 | B12: {=IFERROR(_FV(A12,"Name"),"")} | C12: {=IFERROR(_FV(A12,"Ticker symbol",TRUE),"")} | D12: =+IFERROR(I96/I95-1,"") | E12: =IFERROR(I99/I96-1,"") | F12: =IFERROR(I97/I96,"") | G12: =IFERROR(I102/I99,"") | H12: =IFERROR(I98/I96,"") | I12: =+IFERROR(I107/I99,"") | J12: {=IFERROR((_FV(A12,"Market cap",TRUE)/1000000+I$123-I$113)/I$96,"")} | K12: {=IFERROR(+(_FV(A12,"Market cap",TRUE)/1000000+I$123-I$113)/I$99,"")} | L12: {=IFERROR(+(_FV(A12,"Market cap",TRUE)/1000000+I$123-I$113)/I$97,"")} | M12: {=IFERROR(+(_FV(A12,"Market cap",TRUE)/1000000+I$123-I$113)/I$102,"")} | N12: {=IFERROR(+(_FV(A12,"Market cap",TRUE)/1000000)/I$98,"")} | O12: {=IFERROR(+(_FV(A12,"Market cap",TRUE)/1000000)/I$107,"")} | S12: SANTANDER
A13: =+J93 -> PEER 6 | B13: {=IFERROR(_FV(A13,"Name"),"")} | C13: {=IFERROR(_FV(A13,"Ticker symbol",TRUE),"")} | D13: =IFERROR(J96/J95-1,"") | E13: =IFERROR(J99/J96-1,"") | F13: =IFERROR(J97/J96,"") | G13: =IFERROR(J102/J99,"") | H13: =IFERROR(J98/J96,"") | I13: =+IFERROR(J107/J99,"") | J13: {=IFERROR(+(_FV(A13,"Market cap",TRUE)/1000000+J$123-J$113)/J$96,"")} | K13: {=IFERROR(+(_FV(A13,"Market cap",TRUE)/1000000+J$123-J$113)/J$99,"")} | L13: {=IFERROR(+(_FV(A13,"Market cap",TRUE)/1000000+J$123-J$113)/J$97,"")} | M13: {=IFERROR(+(_FV(A13,"Market cap",TRUE)/1000000+J$123-J$113)/J$102,"")} | N13: {=IFERROR(+(_FV(A13,"Market cap",TRUE)/1000000)/J$98,"")} | O13: {=IFERROR(+(_FV(A13,"Market cap",TRUE)/1000000)/J$107,"")} | S13: HAITONG
A14: =+K93 -> PEER 7 | B14: {=IFERROR(_FV(A14,"Name"),"")} | C14: {=IFERROR(_FV(A14,"Ticker symbol",TRUE),"")} | D14: =IFERROR(K96/K95-1,"") | E14: =IFERROR(K99/K96-1,"") | F14: =+IFERROR(K97/K96,"") | G14: =IFERROR(K102/K99,"") | H14: =IFERROR(K98/K96,"") | I14: =+IFERROR(K107/K99,"") | J14: {=IFERROR((_FV(A14,"Market cap",TRUE)/1000000+D$123-K$113)/K$96,"")} | K14: {=IFERROR(+(_FV(A14,"Market cap",TRUE)/1000000+D$123-K$113)/K$99,"")} | L14: {=IFERROR(+(_FV(A14,"Market cap",TRUE)/1000000+D$123-K$113)/K$97,"")} | M14: {=IFERROR(+(_FV(A14,"Market cap",TRUE)/1000000+D$123-K$113)/K$102,"")} | N14: {=IFERROR(+(_FV(A14,"Market cap",TRUE)/1000000)/K$98,"")} | O14: {=IFERROR(+(_FV(A14,"Market cap",TRUE)/1000000)/K$107,"")} | S14: BNP
A15: =+L93 -> PEER 8 | B15: {=IFERROR(_FV(A15,"Name"),"")} | C15: {=IFERROR(_FV(A15,"Ticker symbol",TRUE),"")} | D15: =+IFERROR(L96/L95,"") | E15: =IFERROR(L99/L96,"") | F15: =IFERROR(L97/L96,"") | G15: =IFERROR(L102/L99,"") | H15: =IFERROR(L98/L96,"") | I15: =+IFERROR(L107/L99,"") | J15: {=IFERROR(+(_FV(A15,"Market cap",TRUE)/1000000+L$123-L$113)/L$96,"")} | K15: {=IFERROR(+(_FV(A15,"Market cap",TRUE)/1000000+L$123-L$113)/L$99,"")} | L15: {=IFERROR(+(_FV(A15,"Market cap",TRUE)/1000000+L$123-L$113)/L$97,"")} | M15: {=IFERROR(+(_FV(A15,"Market cap",TRUE)/1000000+L$123-L$113)/L$102,"")} | N15: {=IFERROR(+(_FV(A15,"Market cap",TRUE)/1000000)/L$98,"")} | O15: {=IFERROR(+(_FV(A15,"Market cap",TRUE)/1000000)/L$107,"")}
A16: =+M93 -> PEER 9 | B16: {=IFERROR(_FV(A16,"Name"),"")} | C16: {=IFERROR(_FV(A16,"Ticker symbol",TRUE),"")} | D16: =IFERROR(M96/M95-1,"") | E16: =IFERROR(M99/M96-1,"") | F16: =IFERROR(M97/M96,"") | G16: =IFERROR(M102/M99,"") | H16: =IFERROR(M98/M96,"") | I16: =+IFERROR(M107/M99,"") | J16: {=IFERROR(+(_FV(A16,"Market cap",TRUE)/1000000+M$123-M$113)/M$96,"")} | K16: {=IFERROR(+(_FV(A16,"Market cap",TRUE)/1000000+M$123-M$113)/M$99,"")} | L16: {=IFERROR(+(_FV(A16,"Market cap",TRUE)/1000000+M$123-M$113)/M$97,"")} | M16: {=IFERROR(+(_FV(A16,"Market cap",TRUE)/1000000+M$123-M$113)/M$102,"")} | N16: {=IFERROR(+(_FV(A16,"Market cap",TRUE)/1000000)/M$98,"")} | O16: {=IFERROR(+(_FV(A16,"Market cap",TRUE)/1000000)/M$107,"")}
A17: =+N93 -> PEER 10 | B17: {=IFERROR(_FV(A17,"Name"),"")} | C17: {=+IFERROR(_FV(A17,"Ticker symbol",TRUE),"")} | D17: =IFERROR(N96/N95-1,"") | E17: =IFERROR(N99/N96-1,"") | F17: =IFERROR(N97/N96,"") | G17: =IFERROR(N102/N99,"") | H17: =IFERROR(N98/N96,"") | I17: =+IFERROR(N107/N99,"") | J17: {=IFERROR(+(_FV(A17,"Market cap",TRUE)/1000000+N$123-N$113)/N$96,"")} | K17: {=IFERROR(+(_FV(A17,"Market cap",TRUE)/1000000+N$123-N$113)/N$99,"")} | L17: {=IFERROR(+(_FV(A17,"Market cap",TRUE)/1000000+N$123-N$113)/N$97,"")} | M17: {=IFERROR(+(_FV(A17,"Market cap",TRUE)/1000000+N$123-N$113)/N$102,"")} | N17: {=IFERROR(+(_FV(A17,"Market cap",TRUE)/1000000)/N$98,"")} | O17: {=IFERROR(+(_FV(A17,"Market cap",TRUE)/1000000)/N$107,"")}
B18: Average | D18: =IFERROR(AVERAGE(D6:D17),"") -> -0.27278063 | E18: =IFERROR(AVERAGE(E6:E17),"") -> 0.33690914 | F18: =IFERROR(AVERAGE(F6:F17),"") -> 0.070663079 | G18: =IFERROR(AVERAGE(G6:G17),"") -> 0.22382419 | H18: =IFERROR(AVERAGE(H6:H17),"") -> -0.16855874 | I18: =IFERROR(AVERAGE(I6:I17),"") -> -0.34264477 | J18: =IFERROR(AVERAGE(J6:J17),"") -> 3.1288273 | K18: =IFERROR(AVERAGE(K6:K17),"") -> 2.2154575 | ... O18: =IFERROR(AVERAGE(O6:O17),"") -> 22.56241
B19: Deviation from Average | D19: =IFERROR(+D18-D6,"") -> -0.0070819537 | E19: =IFERROR(E18-E6,"") -> -0.68328271 | F19: =+IFERROR(F18-F6,"") -> 0.2886746 | G19: =IFERROR(G18-G6,"") -> -0.13915981 | H19: =IFERROR(+H6-H18,"") -> -0.11031826 | I19: =+IFERROR(I6-I18,"") -> 0.64172624 | J19: =+IFERROR(J6-J18,"") -> 1.1464087 | K19: =+IFERROR(K6-K18,"") -> -0.099205023 | L19: =IFERROR(+L6-L18,"") -> 1.449353 | M19: =IFERROR(M6-M18,"") -> -9.0341725 | N19: =IFERROR(+N6-N18,"") -> -9.9197401 | O19: =IFERROR(+O6-O18,"") -> -16.005752
D21: Trading Multiple | G21: Net | H21: Preferred | I21: Non-Controlling | J21: Equity Value | M21: Implied Upside (Downside)
B22: Implied Share Price | D22: Revenue | E22: EBITDA | F22: P/E | G22: Debt | H22: Stock | I22: Interest | J22: Revenue | K22: EBITDA | L22: P/E | M22: Revenue | N22: EBITDA | O22: P/E | P22: Current Price
B24: Second Minimum | D24: =+MIN(K6:K11) -> 1.1068059 | E24: =MIN(M6:M11) -> 4.4190531 | F24: =MIN(O6:O11) -> -19.154346 | G24: =-Inputs!$Q$99+Inputs!$Q$100 -> 7555.4 | H24: =+Inputs!$Q$101 -> 0 | I24: =+Inputs!$Q$102 -> 12.3 | J24: =IFERROR(+D24*$D$99+G24+H24+I24,"") -> 80830.506 | K24: =IFERROR(E24*$D$102+G24+H24+I24,"") -> 113744.29 | L24: =IFERROR(F24*$D$107,"") -> -379200.51 | M24: {=IFERROR(+(J24/_FV($A$6,"Shares outstanding",TRUE)*1000000000)/$P$24-1,"")} -> -0.39788206 | N24: {=IFERROR((+K24/_FV($A$6,"Shares outstanding",TRUE)*1000000000)/$P$24-1,"")} -> -0.15270261 | O24: {=IFERROR(+(L24/_FV($A$6,"Shares outstanding",TRUE)*1000000000)/$P$24-1,"")} -> -3.8247185 | P24: {=+_FV(A6,"Price")} -> 184400
B25: Average | D25: =+IFERROR(AVERAGE(K6:K17),"") -> 2.2154575 | E25: =IFERROR(+AVERAGE(M6:M17),"") -> 14.864326 | F25: =IFERROR(+AVERAGE(O6:O17),"") -> 22.56241 | G25: =-Inputs!$Q$99+Inputs!$Q$100 -> 7555.4 | H25: =+Inputs!$Q$101 -> 0 | I25: =+Inputs!$Q$102 -> 12.3 | J25: =IFERROR(+D25*$D$99+G25+H25+I25,"") -> 154215.48 | K25: =IFERROR(E25*$D$102+G25+H25+I25,"") -> 364712.86 | L25: =IFERROR(+F25*$D$107,"") -> 446670.28 | M25: {=IFERROR(+(J25/_FV($A$6,"Shares outstanding",TRUE)*1000000000)/$P$24-1,"")} -> 0.14877305 | N25: {=IFERROR((+K25/_FV($A$6,"Shares outstanding",TRUE)*1000000000)/$P$24-1,"")} -> 1.716798 | O25: {=IFERROR(+(L25/_FV($A$6,"Shares outstanding",TRUE)*1000000000)/$P$24-1,"")} -> 2.3273105
B26: Median | D26: =IFERROR(MEDIAN(K6:K17),"") -> 2.1162525 | E26: =IFERROR(MEDIAN(M6:M17),"") -> 10.953209 | F26: =IFERROR(MEDIAN(O6:O17),"") -> 6.5566573 | G26: =-Inputs!$Q$99+Inputs!$Q$100 -> 7555.4 | H26: =+Inputs!$Q$101 -> 0 | I26: =+Inputs!$Q$102 -> 12.3 | J26: =IFERROR(D26*$D$99+G26+H26+I26,"") -> 147648.8 | K26: =IFERROR(E26*$D$102+G26+H26+I26,"") -> 270740.44 | L26: =IFERROR(+F26*$D$107,"") -> 129802.8 | M26: {=IFERROR(+(J26/_FV($A$6,"Shares outstanding",TRUE)*1000000000)/$P$24-1,"")} -> 0.099856926 | N26: {=IFERROR((+K26/_FV($A$6,"Shares outstanding",TRUE)*1000000000)/$P$24-1,"")} -> 1.0167841 | O26: {=+IFERROR((L26/_FV($A$6,"Shares outstanding",TRUE)*1000000000)/$P$24-1,"")} -> -0.033080468
B27: Second Maximum | D27: =+MAX(K6:K11) -> 3.9187347 | E27: =+MAX(M6:M11) -> 30.604785 | F27: =MAX(O6:O11) -> 118.87194 | G27: =-Inputs!$Q$99+Inputs!$Q$100 -> 7555.4 | H27: =+Inputs!$Q$101 -> 0 | I27: =+Inputs!$Q$102 -> 12.3 | J27: =IFERROR(+D27*$D$99+G27+H27+I27,"") -> 266960.51 | K27: =IFERROR(E27*$D$102+G27+H27+I27,"") -> 742908.87 | L27: =IFERROR(+F27*$D$107,"") -> 2353319.7 | M27: {=IFERROR(+(J27/_FV($A$6,"Shares outstanding",TRUE)*1000000000)/$P$24-1,"")} -> 0.9886268 | N27: {=IFERROR((+K27/_FV($A$6,"Shares outstanding",TRUE)*1000000000)/$P$24-1,"")} -> 4.5340339 | O27: {=+IFERROR((L27/_FV($A$6,"Shares outstanding",TRUE)*1000000000)/$P$24-1,"")} -> 16.530213
B29: Profitability | D29: =+LEFT(B6, FIND(" ", B6 & " ") - 1) -> SK | E29: =+LEFT(B8, FIND(" ", B8 & " ") - 1) -> Samsung | F29: =+LEFT(B9, FIND(" ", B9 & " ") - 1) -> MICRON | G29: =+LEFT(B10, FIND(" ", B10 & " ") - 1) -> Kioxia | H29: =+LEFT(B11, FIND(" ", B11 & " ") - 1) -> WESTERN | I29: =+LEFT(B12, FIND(" ", B12 & " ") - 1) | J29: =+LEFT(C12, FIND(" ", C12 & " ") - 1) | K29: =+LEFT(B14, FIND(" ", B14 & " ") - 1) | L29: =+LEFT(B15, FIND(" ", B15 & " ") - 1) | M29: =+LEFT(B16, FIND(" ", B16 & " ") - 1) | N29: =+LEFT(B17, FIND(" ", B17 & " ") - 1) | O29: Average
B31: Operating Margin | D31: =IFERROR(D103/D99,"") -> 0.35452994 | E31: =IFERROR(E103/E99,"") -> 0.1087709 | F31: =IFERROR(F103/F99,"") -> 0.042372856 | G31: =IFERROR(G103/G99,"") -> -0.24660123 | H31: =IFERROR(H103/H99,"") -> 0.024455854 | I31: =IFERROR(I103/I99,"") | J31: =IFERROR(J103/J99,"") | K31: =IFERROR(K103/K99,"") | ... N31: =IFERROR(N103/N99,"") | O31: =IFERROR(+AVERAGE(D31:N31),"") -> 0.056705664
B32: Net Income Margin | D32: =IFERROR(D107/D99,"") -> 0.29908147 | E32: =IFERROR(E107/E99,"") -> 0.11174693 | F32: =IFERROR(F107/F99,"") -> 0.030983004 | G32: =IFERROR(G107/G99,"") -> -0.22639151 | H32: =IFERROR(H107/H99,"") -> -0.061367803 | I32: =IFERROR(I107/I99,"") | J32: =IFERROR(J107/J99,"") | K32: =IFERROR(K107/K99,"") | ... N32: =IFERROR(N107/N99,"") | O32: =IFERROR(+AVERAGE(D32:N32),"") -> 0.030810419
B33: ROA (%) | D33: =IFERROR(D107/D119,"") -> 0.16517514 | E33: =IFERROR(E107/E119,"") -> 0.065343665 | F33: =IFERROR(F107/F119,"") -> 0.011307862 | G33: =IFERROR(G107/G119,"") -> -0.087428585 | H33: =IFERROR(H107/H119,"") -> -0.031907814 | I33: =IFERROR(I107/I119,"") | J33: =IFERROR(J107/J119,"") | K33: =IFERROR(K107/K119,"") | ... N33: =IFERROR(N107/N119,"") | O33: =IFERROR(+AVERAGE(D33:N33),"") -> 0.024498055
B34: Financial Cost of Debt | D34: =IFERROR(+(D104/D123)*(1-(D106/D105)),"") -> 0.03859561 | E34: =IFERROR(+(E104/E123)*(1-(E106/E105)),"") -> -0.18592942 | F34: =IFERROR(+(F104/F123)*(1-(F106/F105)),"") -> 0.0015055717 | G34: =IFERROR(+(G104/G123)*(1-(G106/G105)),"") -> 0.021636559 | H34: =IFERROR(+(H104/H123)*(1-(H106/H105)),"") -> 0.056709984 | I34: =IFERROR(+(I104/I123)*(1-(I106/I105)),"") | J34: =IFERROR(+(J104/J123)*(1-(J106/J105)),"") | K34: =IFERROR(+(K104/K123)*(1-(K106/K105)),"") | ... N34: =IFERROR(+(N104/N123)*(1-(N106/N105)),"") | O34: =IFERROR(+AVERAGE(D34:N34),"") -> -0.01349634
B35: Return on Equity (RoE) | D35: =IFERROR(+D107/D124,"") -> 0.26783349 | E35: =IFERROR(+E107/E124,"") -> 0.083595376 | F35: =IFERROR(+F107/F124,"") -> 0.017392605 | G35: =IFERROR(+G107/G124,"") -> -0.55691362 | H35: =IFERROR(+H107/H124,"") -> -0.069863607 | I35: =IFERROR(+I107/I124,"") | J35: =IFERROR(+J107/J124,"") | K35: =IFERROR(+K107/K124,"") | ... N35: =IFERROR(+N107/N124,"") | O35: =IFERROR(+AVERAGE(D35:N35),"") -> -0.05159115
B36: Return on Invested Capital (ROIC) | D36: =IFERROR(+D107/(D123+D124),"") -> 0.20751873 | E36: =IFERROR(+E107/(E123+E124),"") -> 0.079761854 | F36: =IFERROR(+F107/(F123+F124),"") -> 0.013257201 | G36: =IFERROR(+G107/(G123+G124),"") -> -0.12119646 | H36: =IFERROR(+H107/(H123+H124),"") -> -0.040987015 | I36: =IFERROR(+I107/(I123+I124),"") | J36: =IFERROR(+J107/(J123+J124),"") | K36: =IFERROR(+K107/(K123+K124),"") | ... N36: =IFERROR(+N107/(N123+N124),"") | O36: =IFERROR(+AVERAGE(D36:N36),"") -> 0.027670861
B38: Solvency | D38: =+D29 -> SK | E38: =+E29 -> Samsung | F38: =+F29 -> MICRON | G38: =+G29 -> Kioxia | H38: =+H29 -> WESTERN | I38: =+I29 | J38: =+J29 | K38: =+K29 | ... O38: =+O29 -> Average
B40: Debt/Assets | D40: =IFERROR(D123/D119,"") -> 0.17924462 | E40: =IFERROR(E123/E119,"") -> 0.037568516 | F40: =IFERROR(F123/F119,"") -> 0.20280654 | G40: =IFERROR(G123/G119,"") -> 0.56439132 | H40: =IFERROR(H123/H119,"") -> 0.3217701 | I40: =IFERROR(I123/I119,"") | J40: =IFERROR(J123/J119,"") | K40: =IFERROR(K123/K119,"") | ... N40: =IFERROR(N123/N119,"") | O40: =IFERROR(+AVERAGE(D40:N40),"") -> 0.26115622
B41: Net Debt/EBITDA | D41: =IFERROR(+(D123-D113)/D102,"") -> 0.42778125 | E41: =IFERROR(+(E123-E113)/E102,"") -> -0.45616852 | F41: =IFERROR(+(F123-F113)/F102,"") -> 0.65887193 | G41: =IFERROR(+(G123-G113)/G102,"") -> 17.328129 | H41: =IFERROR(+(H123-H113)/H102,"") -> 6.4255051 | I41: =IFERROR(+(I123-I113)/I102,"") | J41: =IFERROR(+(J123-J113)/J102,"") | K41: =IFERROR(+(K123-K113)/K102,"") | ... N41: =IFERROR(+(N123-N113)/N102,"") | O41: =IFERROR(+AVERAGE(D41:N41),"") -> 4.8768238
B42: Interest Coverage Ratio | D42: =IFERROR(D103/D104,"") -> 23.458017 | E42: =IFERROR(E103/E104,"") -> -8.3587045 | F42: =IFERROR(F103/F104,"") -> 32.225225 | G42: =IFERROR(G103/G104,"") -> -5.5360401 | H42: =IFERROR(H103/H104,"") -> 0.8412705 | I42: =IFERROR(I103/I104,"") | J42: =IFERROR(J103/J104,"") | K42: =IFERROR(K103/K104,"") | ... N42: =IFERROR(N103/N104,"") | O42: =IFERROR(+AVERAGE(D42:N42),"") -> 8.5259536
B44: Liquidity | D44: =+D29 -> SK | E44: =+E29 -> Samsung | F44: =+F29 -> MICRON | G44: =+G29 -> Kioxia | H44: =+H29 -> WESTERN | I44: =+I29 | J44: =+J29 | K44: =+K29 | ... O44: =+O29 -> Average
B46: Cash Ratio | D46: =IFERROR(D113/D121,"") -> 0.44882517 | E46: =IFERROR(E113/E121,"") -> 0.57546051 | F46: =IFERROR(F113/F121,"") -> 0.87651306 | G46: =IFERROR(G113/G121,"") -> 0.097560829 | H46: =IFERROR(H113/H121,"") -> 0.30869109 | I46: =IFERROR(I113/I121,"") | J46: =IFERROR(J113/J121,"") | K46: =IFERROR(K113/K121,"") | ... N46: =IFERROR(N113/N121,"") | O46: =IFERROR(+AVERAGE(D46:N46),"") -> 0.46141013
B47: Quick Ratio | D47: =IFERROR(+(D113+D114)/D121,"") -> 0.9703069 | E47: =IFERROR(+(E113+E114)/E121,"") -> 1.0428861 | F47: =IFERROR(+(F113+F114)/F121,"") -> 1.4624777 | G47: =IFERROR(+(G113+G114)/G121,"") -> 0.16598293 | H47: =IFERROR(+(H113+H114)/H121,"") -> 0.66453042 | I47: =IFERROR(+(I113+I114)/I121,"") | J47: =IFERROR(+(J113+J114)/J121,"") | K47: =IFERROR(+(K113+K114)/K121,"") | ... N47: =IFERROR(+(N113+N114)/N121,"") | O47: =IFERROR(+AVERAGE(D47:N47),"") -> 0.86123681
B48: Current Ratio | D48: =IFERROR(D117/D121,"") -> 1.6934998 | E48: =IFERROR(E117/E121,"") -> 2.4329937 | F48: =IFERROR(F117/F121,"") -> 2.6353805 | G48: =IFERROR(G117/G121,"") -> 0.3490503 | H48: =IFERROR(H117/H121,"") -> 1.3241411 | I48: =IFERROR(I117/I121,"") | J48: =IFERROR(J117/J121,"") | K48: =IFERROR(K117/K121,"") | ... N48: =IFERROR(N117/N121,"") | O48: =IFERROR(+AVERAGE(D48:N48),"") -> 1.6870131
B50: Activity | D50: =+D29 -> SK | E50: =+E29 -> Samsung | F50: =+F29 -> MICRON | G50: =+G29 -> Kioxia | H50: =+H29 -> WESTERN | I50: =+I29 | J50: =+J29 | K50: =+K29 | ... O50: =+O29 -> Average
B52: Inventory Turnover | D52: =IFERROR(D100/(AVERAGE(D115:D116)),"") -> 2.5650542 | E52: =IFERROR(E100/(AVERAGE(E115:E116)),"") -> 3.6092253 | F52: =IFERROR(F100/(AVERAGE(F115:F116)),"") -> 2.2871373 | G52: =IFERROR(G100/(AVERAGE(G115:G116)),"") -> 3.6791483 | H52: =IFERROR(H100/(AVERAGE(H115:H116)),"") -> 2.8295564 | I52: =IFERROR(I100/(AVERAGE(I115:I116)),"") | J52: =IFERROR(J100/(AVERAGE(J115:J116)),"") | K52: =IFERROR(K100/(AVERAGE(K115:K116)),"") | ... N52: =IFERROR(N100/(AVERAGE(N115:N116)),"") | O52: =IFERROR(+AVERAGE(D52:N52),"") -> 2.9940243
B53: Acc. Receivable Turnover | D53: =IFERROR(D99/D114,"") -> 5.0843383 | E53: =IFERROR(E99/E114,"") -> 6.8970545 | F53: =IFERROR(F99/F114,"") -> 4.6751724 | G53: =IFERROR(G99/G114,"") -> 8.6650819 | H53: =IFERROR(H99/H114,"") -> 5.8063069 | I53: =IFERROR(I99/I114,"") | J53: =IFERROR(J99/J114,"") | K53: =IFERROR(K99/K114,"") | ... N53: =IFERROR(N99/N114,"") | O53: =IFERROR(+AVERAGE(D53:N53),"") -> 6.2255908
B54: Payables Turnover | D54: =IFERROR(D100/D120,"") -> 15.090151 | E54: =IFERROR(E100/E120,"") -> 15.081591 | F54: =IFERROR(F100/F120,"") -> 7.2229929 | G54: =IFERROR(G100/G120,"") -> 10.976999 | H54: =IFERROR(H100/H120,"") -> 6.8942446 | I54: =IFERROR(I100/I120,"") | J54: =IFERROR(J100/J120,"") | K54: =IFERROR(K100/K120,"") | ... N54: =IFERROR(N100/N120,"") | O54: =IFERROR(+AVERAGE(D54:N54),"") -> 11.053196
...

Sheet ESG
B2: Environmental, Social and Governance Analysis
B4: Author: | C4: João Branco | E4: Highlights | N4: Recent News
B6: Overview | D6: .
B7: Last Update | C7: 45767 | D7: .
B8: Latest year with data | C8: 2024
B9: GICS Sector | C9: Informational Technology
B10: GICS Industry Group | C10: Semiconductor Equipment
B11: Final Review
B13: ESG Scores
B14: LSEG ESG Score | C14: 70
B15: E-Score | C15: 57
B16: S-Score | C16: 66 | E16: GHG Scope 1 and 2 Emissions: | N16: Water, Waste, Energy Management:
B17: G-Score | C17: 94
B18: S&P Global ESG Score | C18: 56
B19: Environmental | C19: 53
B20: Social | C20: 60
B21: Governance & Economic | C21: 56
B22: Sustainalytics | C22: 17.3
B23: ISS ESG Corporate Rating | C23: C+
B24: SDG Impact Rating | C24: 3.7
B25: Governance Quality Score | C25: 1
B26: MSCI ESG Ratings | C26: A
B29: Industry ESG Overview:
E33: ENVIRONMENTAL
G35: Overview | H35: Targets | K35: Improvements | O35: Comments
E36: GHG (or CO2) Scope 1 Emissions | H36: SK Hynix wants to reduce their GHG emissions by 40% until 2030 | K36: The company was able to reduce their GHG Scope 1 emissions by 25% between 2022 and 2023. | O36: The company has been able to keep reducing the GHG scope 1 emissions and keep values low when compared to their competitors.
E38: Water Consumption | H38: The company wants to conserve 600 million tons of water by 2030 | K38: The company was able to reduce their water consumption by 9% between 2022 and 2023. | O38: Although the company was able to reduce their water consumption they still maintain very high levels of consumption.
E40: Energy Consumption | H40: The company wants to create energy saving of 3000 GWh by 2030. | K40: The company increased the energy consumption by 36% | O40: The company keeps the 2nd highest energy consumption when compared to the other companies.
E42: Waste Management | K42: The company reduced their waste by 18%. | O42: Even though the company reduced their waste, they still are the 2nd company that produces more waste.
E44: Other
E46: SOCIAL
B48: Important Sources: | G48: Overview | H48: Targets | K48: Improvements | O48: Comments
B49: Annual Report | E49: Employee Turnover % | G49: Not Reported
B50: Sustainability Report | D50: .
