Workbook
Name COOLFUCNTION: _xlfn.LAMBDA(_xldudf_BOARDFLARE_EXEC("workbook-settings:coolfucntion"))
Name COOLFUCNTION: _xlfn.LAMBDA(_xldudf_BOARDFLARE_EXEC("workbook-settings:coolfucntion"))
Name COOLFUCNTION: _xlfn.LAMBDA(_xldudf_BOARDFLARE_EXEC("workbook-settings:coolfucntion"))
Name COOLFUCNTION: _xlfn.LAMBDA(_xldudf_BOARDFLARE_EXEC("workbook-settings:coolfucntion"))
Name COOLFUCNTION: _xlfn.LAMBDA(_xldudf_BOARDFLARE_EXEC("workbook-settings:coolfucntion"))
Name COOLFUCNTION: _xlfn.LAMBDA(_xldudf_BOARDFLARE_EXEC("workbook-settings:coolfucntion"))
Name COOLFUCNTION: _xlfn.LAMBDA(_xldudf_BOARDFLARE_EXEC("workbook-settings:coolfucntion"))
Name COOLFUCNTION: _xlfn.LAMBDA(_xldudf_BOARDFLARE_EXEC("workbook-settings:coolfucntion"))
Name COOLFUCNTION: _xlfn.LAMBDA(_xldudf_BOARDFLARE_EXEC("workbook-settings:coolfucntion"))
Name COOLFUCNTION: _xlfn.LAMBDA(_xldudf_BOARDFLARE_EXEC("workbook-settings:coolfucntion"))
Name Sectors: #REF!
Name Sectors: #REF!
Name Sectors: #REF!

Sheet Summary
E2: | EQUITY RESEARCH | U2: Lisbon Investment Society Equity Research | AB2: Iterations
U3: April 30, 2025
AA4: 1 | AB4: 95.991539
AA5: =+AA4+1 -> 2 | AB5: 100.38109
D6: {=+_FV(DCF!R4,"Name")} -> UBER TECHNOLOGIES, INC. | U6: Buy | AA6: =+AA5+1 -> 3 | AB6: 90.015784
AA7: =+AA6+1 -> 4 | AB7: 89.345851
D8: Uber is a ride-hailing company that allows passengers to find drivers through the mobile app. Beyond transportation, Uber offers food delivery services as well as freight services. Uber has a strong market position globally, among its peers, it has the best financial performance as well as the highest number of users. The company has gone through some major losses, however, it has shown significant growth in revenue, primarily driven by the mobility sector and its ability to maintain costs. | U8: UBER | AA8: =+AA7+1 -> 5 | AB8: 89.345851
U9: {=+"Price (7 Mar 25): $"&_FV(DCF!$R$4,"Price")} -> Price (7 Mar 25): $94,36 | AA9: =+AA8+1 -> 6 | AB9: 84.845899
D10: Investment Thesis | U10: ="Price Target: $" & ROUND(IF(Summary!G25="FCFF",DCF!Q204,IF(Summary!G25="FCFE",DCF!Q247,IF(Summary!G25="Tax Shield",DCF!Q220,DCF!Q263))),2) &" "&IF(Summary!G25="FCFF","(FCFF)",IF(Summary!G25="FCFE","(FCFE)",IF(Summary!G25="Tax Shield","(APV)","(DDM)"))) -> Price Target: $88.18 (FCFF) | AA10: =+AA9+1 -> 7 | AB10: 95.198437
D11: Up until 2022, Uber represented negative operting income, however, since then the company was able to generate high positive operating income and net income, primarly driven by the increase of revenue in the mobility sector and as well as its ability to mantain its cost of good solds and other expenses. This increase is both explained by the number of trips realized and montly active platform menbers. Thus despite its past losses, it is belived Uber will have an upside of 11,02% this it efforts in innovation shod by its recent partnerships such as with Nvidea and Weride and as well its effortsin expanding the autonomaus veichels in the US. Furthermore, comparing to its peers, Uber is the only one with positive profit margin , it has a signifcant leverage due to its diverse business model which offers mobility delivery and fright services. Despite that the comapany still has legal relatuon issues in the classification of itts drivers as legal employeed in some regions which could have an negative impact in its profitabiltiy. | U11: =+"Upside (Downside): "&ROUND((DCF!$Q$207*100),2)&"%" -> Upside (Downside): 11.02% | AA11: =+AA10+1 -> 8 | AB11: 101.96157
AA12: =+AA11+1 -> 9 | AB12: 90.015784
AA13: =+AA12+1 -> 10 | AB13: 84.845899
U14: =+Industry!E28&", "&ESG!C9 -> EUA, Industrials | AA14: =+AA13+1 -> 11 | AB14: 100.38109
U15: =+ESG!C10 -> Transportation | AA15: =+AA14+1 -> 12 | AB15: 100.38109
AA16: =+AA15+1 -> 13 | AB16: 95.991539
D17: Operating Metrics | F17: 2023 | G17: =+F17+1 -> 2024 | H17: =+G17+1 -> 2025 | I17: =+H17+1 -> 2026 | K17: Valuation Multiples | N17: 2022 | O17: =+N17+1 -> 2023 | P17: =+O17+1 -> 2024 | Q17: =+P17+1 -> 2025 | R17: =+Q17+1 -> 2026 | U17: Mariana Zhu | AA17: =+AA16+1 -> 14 | AB17: 89.345851
D18: =DCF!B17 -> Yearly Active Platform Consumers | F18: =DCF!F17 -> 2236 | G18: =DCF!G17 -> 2548 | H18: =DCF!H17 -> 2751.84 | I18: =DCF!I17 -> 2971.9872 | K18: EV / Sales | N18: =IFERROR(_xlfn.XLOOKUP($K18,Multiples!$B:$B,Multiples!N:N),"") -> 1.7812847 | O18: =IFERROR(_xlfn.XLOOKUP($K18,Multiples!$B:$B,Multiples!O:O),"") -> 3.5686019 | P18: =IFERROR(_xlfn.XLOOKUP($K18,Multiples!$B:$B,Multiples!P:P),"") -> 2.9318812 | Q18: =IFERROR(_xlfn.XLOOKUP($K18,Multiples!$B:$B,Multiples!Q:Q),"") -> 3.1162152 | R18: =IFERROR(_xlfn.XLOOKUP($K18,Multiples!$B:$B,Multiples!R:R),"") -> 2.8733681 | U18: l63113@aln.iseg.ulisboa.pt | AA18: =+AA17+1 -> 15 | AB18: 89.345851
D19: =DCF!B19 -> Trip | F19: =DCF!F19 -> 9448 | G19: =DCF!G19 -> 11273 | H19: =DCF!H19 -> 12373.583 | I19: =DCF!I19 -> 13023.38 | K19: Price / Sales | N19: =IFERROR(_xlfn.XLOOKUP($K19,Multiples!$B:$B,Multiples!N:N),"") -> 1.5410801 | O19: =IFERROR(_xlfn.XLOOKUP($K19,Multiples!$B:$B,Multiples!O:O),"") -> 3.3619819 | P19: =IFERROR(_xlfn.XLOOKUP($K19,Multiples!$B:$B,Multiples!P:P),"") -> 2.8729427 | Q19: =IFERROR(_xlfn.XLOOKUP($K19,Multiples!$B:$B,Multiples!Q:Q),"") -> 2.9410175 | R19: =IFERROR(_xlfn.XLOOKUP($K19,Multiples!$B:$B,Multiples!R:R),"") -> 2.7937255 | U19: (+351) 926 820 308 | AA19: =+AA18+1 -> 16 | AB19: 90.015784
D20: =DCF!B20 -> Average Revenue per Trip | F20: =DCF!F20 -> 3.9459145 | G20: =DCF!G20 -> 3.9011798 | H20: =DCF!H20 -> 4.126312 | I20: =DCF!I20 -> 4.2501014 | K20: EV / EBITDA | N20: =IFERROR(_xlfn.XLOOKUP($K20,Multiples!$B:$B,Multiples!N:N),"") -> -64.160464 | O20: =IFERROR(_xlfn.XLOOKUP($K20,Multiples!$B:$B,Multiples!O:O),"") -> 68.826202 | P20: =IFERROR(_xlfn.XLOOKUP($K20,Multiples!$B:$B,Multiples!P:P),"") -> 36.73455 | Q20: =IFERROR(_xlfn.XLOOKUP($K20,Multiples!$B:$B,Multiples!Q:Q),"") -> 44.656863 | R20: =IFERROR(_xlfn.XLOOKUP($K20,Multiples!$B:$B,Multiples!R:R),"") -> 35.445728 | U20: João Ferreira | AA20: =+AA19+1 -> 17 | AB20: 95.198437
D21: =DCF!B21 -> Average Trip per MAPC | F21: =DCF!F21 -> 4.2254025 | G21: =DCF!G21 -> 4.4242543 | H21: =DCF!H21 -> 4.4964763 | I21: =DCF!I21 -> 4.3820444 | K21: EV / EBIT | N21: =IFERROR(_xlfn.XLOOKUP($K21,Multiples!$B:$B,Multiples!N:N),"") -> -30.994547 | O21: =IFERROR(_xlfn.XLOOKUP($K21,Multiples!$B:$B,Multiples!O:O),"") -> 119.8568 | P21: =IFERROR(_xlfn.XLOOKUP($K21,Multiples!$B:$B,Multiples!P:P),"") -> 46.065835 | Q21: =IFERROR(_xlfn.XLOOKUP($K21,Multiples!$B:$B,Multiples!Q:Q),"") -> 57.428454 | R21: =IFERROR(_xlfn.XLOOKUP($K21,Multiples!$B:$B,Multiples!R:R),"") -> 43.17702 | U21: joao@aln.iseg.ulisboa.pt | AA21: =+AA20+1 -> 18 | AB21: 100.38109
D22: =DCF!B22 -> Revenue for Mobility and Delivery | F22: =DCF!F22 -> 37281 | G22: =DCF!G22 -> 43978 | H22: =DCF!H22 -> 51057.265 | I22: =DCF!I22 -> 55350.684 | K22: Price / Earnings | N22: =IFERROR(_xlfn.XLOOKUP($K22,Multiples!$B:$B,Multiples!N:N),"") -> -5.3136843 | O22: =IFERROR(_xlfn.XLOOKUP($K22,Multiples!$B:$B,Multiples!O:O),"") -> 59.458278 | P22: =IFERROR(_xlfn.XLOOKUP($K22,Multiples!$B:$B,Multiples!P:P),"") -> 12.784202 | Q22: =IFERROR(_xlfn.XLOOKUP($K22,Multiples!$B:$B,Multiples!Q:Q),"") -> 93.432868 | R22: =IFERROR(_xlfn.XLOOKUP($K22,Multiples!$B:$B,Multiples!R:R),"") -> 39.866388 | U22: (+351) 968 210 598 | AA22: =+AA21+1 -> 19 | AB22: 101.96157
D23: =DCF!B23 -> Freight Revenue | G23: =DCF!G23 -> 5141 | H23: =DCF!H23 -> 5000 | I23: =DCF!I23 -> 5750 | K23: Price / Book | N23: =IFERROR(_xlfn.XLOOKUP($K23,Multiples!$B:$B,Multiples!N:N),"") -> 5.7766946 | O23: =IFERROR(_xlfn.XLOOKUP($K23,Multiples!$B:$B,Multiples!O:O),"") -> 9.8831453 | P23: =IFERROR(_xlfn.XLOOKUP($K23,Multiples!$B:$B,Multiples!P:P),"") -> 5.621386 | Q23: =IFERROR(_xlfn.XLOOKUP($K23,Multiples!$B:$B,Multiples!Q:Q),"") -> 6.5977806 | R23: =IFERROR(_xlfn.XLOOKUP($K23,Multiples!$B:$B,Multiples!R:R),"") -> 6.5164074 | U23: José Gonçalves | AA23: =+AA22+1 -> 20 | AB23: 84.845899
U24: l64272@aln.iseg.ulisboa.pt | AA24: =+AA23+1 -> 21 | AB24: 93.845803
D25: Year | E25: Net Sales | F25: EBIT Margin | G25: FCFF | H25: =+IF(Summary!$G$25="FCFF",DCF!AB6,IF(Summary!$G$25="FCFE",DCF!AC6,DCF!AD6)) -> NOPAT | I25: Net Capex | K25: Profitability Ratios | N25: 2022 | O25: =+N25+1 -> 2023 | P25: =+O25+1 -> 2024 | Q25: =+P25+1 -> 2025 | R25: =+Q25+1 -> 2026 | U25: (+351) 927 598 576 | AA25: =+AA24+1 -> 22 | AB25: 95.991539
D26: 2022 | E26: =+DCF!E26 -> 31877 | F26: =+DCF!E56 -> -0.057470904 | G26: =+INDEX(DCF!X7:AA7,MATCH(Summary!$G$25,{"FCFF","FCFE","Tax Shield","Total Payout"},0)) -> 556.17844 | H26: =+IF(Summary!$G$25="FCFF",DCF!AB7,IF(Summary!$G$25="FCFE",DCF!AC7,DCF!AD7)) -> -1796.8216 | I26: =+DCF!E130 -> -252 | K26: Return on Assets | N26: =IFERROR(_xlfn.XLOOKUP($K26,Multiples!$B:$B,Multiples!N:N),"") -> -0.2879255 | O26: =IFERROR(_xlfn.XLOOKUP($K26,Multiples!$B:$B,Multiples!O:O),"") -> 0.054471692 | P26: =IFERROR(_xlfn.XLOOKUP($K26,Multiples!$B:$B,Multiples!P:P),"") -> 0.1928616 | Q26: =IFERROR(_xlfn.XLOOKUP($K26,Multiples!$B:$B,Multiples!Q:Q),"") -> 0.029093078 | R26: =IFERROR(_xlfn.XLOOKUP($K26,Multiples!$B:$B,Multiples!R:R),"") -> 0.083634594 | U26: Marta Ferreiro | AA26: =+AA25+1 -> 23 | AB26: 89.345851
D27: =+D26+1 -> 2023 | E27: =+DCF!F26 -> 37281 | F27: =+DCF!F56 -> 0.029773879 | G27: =+INDEX(DCF!X8:AA8,MATCH(Summary!$G$25,{"FCFF","FCFE","Tax Shield","Total Payout"},0)) -> 3402.1344 | H27: =+IF(Summary!$G$25="FCFF",DCF!AB8,IF(Summary!$G$25="FCFE",DCF!AC8,DCF!AD8)) -> 1008.1344 | I27: =+DCF!F130 -> -223 | K27: Return on Equity | N27: =IFERROR(_xlfn.XLOOKUP($K27,Multiples!$B:$B,Multiples!N:N),"") -> -1.0871355 | O27: =IFERROR(_xlfn.XLOOKUP($K27,Multiples!$B:$B,Multiples!O:O),"") -> 0.16621984 | P27: =IFERROR(_xlfn.XLOOKUP($K27,Multiples!$B:$B,Multiples!P:P),"") -> 0.43971347 | Q27: =IFERROR(_xlfn.XLOOKUP($K27,Multiples!$B:$B,Multiples!Q:Q),"") -> 0.06919639 | R27: =IFERROR(_xlfn.XLOOKUP($K27,Multiples!$B:$B,Multiples!R:R),"") -> 0.19261473 | U27: marta.remuinan@aln.iseg.ulisboa.pt | AA27: =+AA26+1 -> 24 | AB27: 89.345851
D28: =+D27+1 -> 2024 | E28: =+DCF!G26 -> 43978 | F28: =+DCF!G56 -> 0.063645459 | G28: =+INDEX(DCF!X9:AA9,MATCH(Summary!$G$25,{"FCFF","FCFE","Tax Shield","Total Payout"},0)) -> 11040.065 | H28: =+IF(Summary!$G$25="FCFF",DCF!AB9,IF(Summary!$G$25="FCFE",DCF!AC9,DCF!AD9)) -> 6706.0647 | I28: =+DCF!G130 -> -242 | K28: Return on Total Capital | N28: =IFERROR(_xlfn.XLOOKUP($K28,Multiples!$B:$B,Multiples!N:N),"") -> -0.089652807 | O28: =IFERROR(_xlfn.XLOOKUP($K28,Multiples!$B:$B,Multiples!O:O),"") -> 0.041386528 | P28: =IFERROR(_xlfn.XLOOKUP($K28,Multiples!$B:$B,Multiples!P:P),"") -> 0.21544205 | Q28: =IFERROR(_xlfn.XLOOKUP($K28,Multiples!$B:$B,Multiples!Q:Q),"") -> 0.068078497 | R28: =IFERROR(_xlfn.XLOOKUP($K28,Multiples!$B:$B,Multiples!R:R),"") -> 0.11984609 | U28: (+34) 698 138 312 | AA28: =+AA27+1 -> 25 | AB28: 95.198437
D29: =+D28+1 -> 2025 | E29: =+DCF!H26 -> 56057.265 | F29: =+DCF!H56 -> 0.055215463 | G29: =+INDEX(DCF!X10:AA10,MATCH(Summary!$G$25,{"FCFF","FCFE","Tax Shield","Total Payout"},0)) -> 4175.9664 | H29: =+IF(Summary!$G$25="FCFF",DCF!AB10,IF(Summary!$G$25="FCFE",DCF!AC10,DCF!AD10)) -> 2204.012 | I29: =+DCF!H130 -> -300 | K29: EBITDA Margin | N29: =IFERROR(_xlfn.XLOOKUP($K29,Multiples!$B:$B,Multiples!N:N),"") -> -0.027762964 | O29: =IFERROR(_xlfn.XLOOKUP($K29,Multiples!$B:$B,Multiples!O:O),"") -> 0.051849468 | P29: =IFERROR(_xlfn.XLOOKUP($K29,Multiples!$B:$B,Multiples!P:P),"") -> 0.079812634 | Q29: =IFERROR(_xlfn.XLOOKUP($K29,Multiples!$B:$B,Multiples!Q:Q),"") -> 0.070234737 | R29: =IFERROR(_xlfn.XLOOKUP($K29,Multiples!$B:$B,Multiples!R:R),"") -> 0.083041581 | AA29: =+AA28+1 -> 26 | AB29: 100.38109
D30: =+D29+1 -> 2026 | E30: =+DCF!I26 -> 61100.684 | F30: =+DCF!I56 -> 0.068219208 | G30: =+INDEX(DCF!X11:AA11,MATCH(Summary!$G$25,{"FCFF","FCFE","Tax Shield","Total Payout"},0)) -> 6797.9969 | H30: =+IF(Summary!$G$25="FCFF",DCF!AB11,IF(Summary!$G$25="FCFE",DCF!AC11,DCF!AD11)) -> 4009.5308 | I30: =+DCF!I130 -> -330 | K30: EBIT Margin | N30: =IFERROR(_xlfn.XLOOKUP($K30,Multiples!$B:$B,Multiples!N:N),"") -> -0.057470904 | O30: =IFERROR(_xlfn.XLOOKUP($K30,Multiples!$B:$B,Multiples!O:O),"") -> 0.029773879 | P30: =IFERROR(_xlfn.XLOOKUP($K30,Multiples!$B:$B,Multiples!P:P),"") -> 0.063645459 | Q30: =IFERROR(_xlfn.XLOOKUP($K30,Multiples!$B:$B,Multiples!Q:Q),"") -> 0.055215463 | R30: =IFERROR(_xlfn.XLOOKUP($K30,Multiples!$B:$B,Multiples!R:R),"") -> 0.068219208 | U30: Statistics | AA30: =+AA29+1 -> 27 | AB30: 84.845899
D31: =+D30+1 -> 2027 | E31: =+DCF!J26 -> 68918.259 | F31: =+DCF!J56 -> 0.071762543 | G31: =+INDEX(DCF!X12:AA12,MATCH(Summary!$G$25,{"FCFF","FCFE","Tax Shield","Total Payout"},0)) -> 9152.6815 | H31: =+IF(Summary!$G$25="FCFF",DCF!AB12,IF(Summary!$G$25="FCFE",DCF!AC12,DCF!AD12)) -> 4729.4643 | I31: =+DCF!J130 -> -363 | K31: Gross Profit Margin | N31: =IFERROR(_xlfn.XLOOKUP($K31,Multiples!$B:$B,Multiples!N:N),"") -> 0.38328575 | O31: =IFERROR(_xlfn.XLOOKUP($K31,Multiples!$B:$B,Multiples!O:O),"") -> 0.39762882 | P31: =IFERROR(_xlfn.XLOOKUP($K31,Multiples!$B:$B,Multiples!P:P),"") -> 0.39399245 | Q31: =IFERROR(_xlfn.XLOOKUP($K31,Multiples!$B:$B,Multiples!Q:Q),"") -> 0.39163567 | R31: =IFERROR(_xlfn.XLOOKUP($K31,Multiples!$B:$B,Multiples!R:R),"") -> 0.39441898 | U31: Beta | V31: =Peers!D74 -> 1.482 | AA31: =+AA30+1 -> 28 | AB31: 95.991539
D32: =+D31+1 -> 2028 | E32: =+DCF!K26 -> 76965.424 | F32: =+DCF!K56 -> 0.072003797 | G32: =+INDEX(DCF!X13:AA13,MATCH(Summary!$G$25,{"FCFF","FCFE","Tax Shield","Total Payout"},0)) -> 8099.7704 | H32: =+IF(Summary!$G$25="FCFF",DCF!AB13,IF(Summary!$G$25="FCFE",DCF!AC13,DCF!AD13)) -> 4360.534 | I32: =+DCF!K130 -> -399.3 | K32: SG&A Margin | N32: =IFERROR(_xlfn.XLOOKUP($K32,Multiples!$B:$B,Multiples!N:N),"") -> 0.24757662 | O32: =IFERROR(_xlfn.XLOOKUP($K32,Multiples!$B:$B,Multiples!O:O),"") -> 0.18878249 | P32: =IFERROR(_xlfn.XLOOKUP($K32,Multiples!$B:$B,Multiples!P:P),"") -> 0.18136341 | Q32: =IFERROR(_xlfn.XLOOKUP($K32,Multiples!$B:$B,Multiples!Q:Q),"") -> 0.18091 | R32: =IFERROR(_xlfn.XLOOKUP($K32,Multiples!$B:$B,Multiples!R:R),"") -> 0.18045773 | U32: % Float | V32: =+Peers!D73 -> 0.9634 | AA32: =+AA31+1 -> 29 | AB32: 100.38109
D33: =+D32+1 -> 2029 | E33: =+DCF!L26 -> 85560.99 | F33: =+DCF!L56 -> 0.077418287 | G33: =+INDEX(DCF!X14:AA14,MATCH(Summary!$G$25,{"FCFF","FCFE","Tax Shield","Total Payout"},0)) -> 9622.6828 | H33: =+IF(Summary!$G$25="FCFF",DCF!AB14,IF(Summary!$G$25="FCFE",DCF!AC14,DCF!AD14)) -> 5232.9484 | I33: =+DCF!L130 -> -439.23 | K33: Net Income Margin | N33: =IFERROR(_xlfn.XLOOKUP($K33,Multiples!$B:$B,Multiples!N:N),"") -> -0.29002102 | O33: =IFERROR(_xlfn.XLOOKUP($K33,Multiples!$B:$B,Multiples!O:O),"") -> 0.056543548 | P33: =IFERROR(_xlfn.XLOOKUP($K33,Multiples!$B:$B,Multiples!P:P),"") -> 0.224726 | Q33: =IFERROR(_xlfn.XLOOKUP($K33,Multiples!$B:$B,Multiples!Q:Q),"") -> 0.027044967 | R33: =IFERROR(_xlfn.XLOOKUP($K33,Multiples!$B:$B,Multiples!R:R),"") -> 0.072384671 | U33: % Held by Insiders | V33: =+Peers!D76 -> 0.0167 | AA33: =+AA32+1 -> 30 | AB33: 89.345851
U34: % Held by Institutions | V34: =+Peers!D77 -> 0.8116 | AA34: =+AA33+1 -> 31 | AB34: 89.345851
D35: SWOT Analysis | K35: Liquidity Ratios | N35: 2022 | O35: =+N35+1 -> 2023 | P35: =+O35+1 -> 2024 | Q35: =+P35+1 -> 2025 | R35: =+Q35+1 -> 2026 | U35: Short % of Float | V35: =+Peers!D78 -> 0.031 | AA35: =+AA34+1 -> 32 | AB35: 93.845803
D36: Strengths | G36: Weaknesses | K36: Cash Ratio | N36: =IFERROR(_xlfn.XLOOKUP($K36,Multiples!$B:$B,Multiples!N:N),"") -> 0.4753191 | O36: =IFERROR(_xlfn.XLOOKUP($K36,Multiples!$B:$B,Multiples!O:O),"") -> 0.49502856 | P36: =IFERROR(_xlfn.XLOOKUP($K36,Multiples!$B:$B,Multiples!P:P),"") -> 0.51350645 | Q36: =IFERROR(_xlfn.XLOOKUP($K36,Multiples!$B:$B,Multiples!Q:Q),"") -> 0.28314325 | R36: =IFERROR(_xlfn.XLOOKUP($K36,Multiples!$B:$B,Multiples!R:R),"") -> 0.3377768 | W36: 120.87 | AA36: =+AA35+1 -> 33 | AB36: 107.93161
D37: Brand Recognition Variety of Services | G37: Driver classification lawsuits Reputation Concerns | K37: Quick Ratio | N37: =IFERROR(_xlfn.XLOOKUP($K37,Multiples!$B:$B,Multiples!N:N),"") -> 0.80085847 | O37: =IFERROR(_xlfn.XLOOKUP($K37,Multiples!$B:$B,Multiples!O:O),"") -> 0.93198646 | P37: =IFERROR(_xlfn.XLOOKUP($K37,Multiples!$B:$B,Multiples!P:P),"") -> 0.89839665 | Q37: =IFERROR(_xlfn.XLOOKUP($K37,Multiples!$B:$B,Multiples!Q:Q),"") -> 0.74182436 | R37: =IFERROR(_xlfn.XLOOKUP($K37,Multiples!$B:$B,Multiples!R:R),"") -> 0.82630139 | U37: Major Holders | W37: 113.63 | AA37: =+AA36+1 -> 34 | AB37: 95.198437
K38: Current Ratio | N38: =IFERROR(_xlfn.XLOOKUP($K38,Multiples!$B:$B,Multiples!N:N),"") -> 1.0447306 | O38: =IFERROR(_xlfn.XLOOKUP($K38,Multiples!$B:$B,Multiples!O:O),"") -> 1.1949439 | P38: =IFERROR(_xlfn.XLOOKUP($K38,Multiples!$B:$B,Multiples!P:P),"") -> 1.0670094 | Q38: =IFERROR(_xlfn.XLOOKUP($K38,Multiples!$B:$B,Multiples!Q:Q),"") -> 0.96143881 | R38: =IFERROR(_xlfn.XLOOKUP($K38,Multiples!$B:$B,Multiples!R:R),"") -> 0.96143881 | U38: Vanguard Group Inc. | V38: 0.0864 | AA38: =+AA37+1 -> 35 | AB38: 100.38109
U39: BlackRock Inc. | V39: 0.0741 | AA39: =+AA38+1 -> 36 | AB39: 93.845803
D40: Opportunities | G40: Threats | K40: Cash Flow Ratios | N40: 2022 | O40: =+N40+1 -> 2023 | P40: =+O40+1 -> 2024 | Q40: =+P40+1 -> 2025 | R40: =+Q40+1 -> 2026 | U40: Capital Research Global Investors | V40: 0.0565 | AA40: =+AA39+1 -> 37 | AB40: 89.345851
D41: Expansion to AVs Strategic Partnerships | G41: Intensive Competition Regulatory Issues | K41: Cash Conversion Cycle | N41: =IFERROR(_xlfn.XLOOKUP($K41,Multiples!$B:$B,Multiples!N:N),"") -> 23.484487 | O41: =IFERROR(_xlfn.XLOOKUP($K41,Multiples!$B:$B,Multiples!O:O),"") -> 25.592393 | P41: =IFERROR(_xlfn.XLOOKUP($K41,Multiples!$B:$B,Multiples!P:P),"") -> 20.541521 | Q41: =IFERROR(_xlfn.XLOOKUP($K41,Multiples!$B:$B,Multiples!Q:Q),"") -> 18.248673 | R41: =IFERROR(_xlfn.XLOOKUP($K41,Multiples!$B:$B,Multiples!R:R),"") -> 18.23029 | U41: State Street Corporation | V41: 0.0408 | AA41: =+AA40+1 -> 38 | AB41: 95.198437
...

Sheet Segments
B2: Segments
B4: Regions | D4: Weight | E4: 2020 | F4: =+E4+1 -> 2021 | G4: =+F4+1 -> 2022 | H4: =+G4+1 -> 2023 | I4: =+H4+1 -> 2024 | J4: ="CAGR "&$G$4&" - "&$I$4 -> CAGR 2022 - 2024 | K4: 2021 | L4: =+K4+1 -> 2022 | M4: =+L4+1 -> 2023 | N4: =+M4+1 -> 2024
B6: United States and Canada | D6: =IFERROR(I6/SUM($I$6:$I$12),"") -> 0.50274597 | E6: 6611 | F6: 10094 | G6: 19474 | H6: 20436 | I6: 23618 | J6: =IFERROR((I6/G6)^(1/COUNT($G$4:$I$4))-1,"") -> 0.066422544 | K6: =IFERROR((F6-E6)/E6,"") -> 0.52684919 | L6: =IFERROR((G6-F6)/F6,"") -> 0.92926491 | M6: =IFERROR((H6-G6)/G6,"") -> 0.049399199 | N6: =IFERROR((I6-H6)/H6,"") -> 0.15570562
B7: Europe, Middle East & Africa | D7: =IFERROR(I7/SUM($I$6:$I$12),"") -> 0.26669931 | E7: 2086 | F7: 3213 | G7: 6944 | H7: 9904 | I7: 12529 | J7: =IFERROR((I7/E7)^(1/COUNT($E$4:$I$4))-1,"") -> 0.43126622 | K7: =IFERROR((F7-E7)/E7,"") -> 0.54026846 | L7: =IFERROR((G7-F7)/F7,"") -> 1.16122 | M7: =IFERROR((H7-G7)/G7,"") -> 0.42626728 | N7: =IFERROR((I7-H7)/H7,"") -> 0.26504443
B8: Asia Pacific | D8: =IFERROR(I8/SUM($I$6:$I$12),"") -> 0.17105879 | E8: 1147 | F8: 2731 | G8: 3481 | H8: 4429 | I8: 8036 | J8: =IFERROR((I8/E8)^(1/COUNT($E$4:$I$4))-1,"") -> 0.4760304 | K8: =IFERROR((F8-E8)/E8,"") -> 1.3809939 | L8: =IFERROR((G8-F8)/F8,"") -> 0.27462468 | M8: =IFERROR((H8-G8)/G8,"") -> 0.27233554 | N8: =IFERROR((I8-H8)/H8,"") -> 0.81440506
B9: Latin America | D9: =IFERROR(I9/SUM($I$6:$I$12),"") -> 0.059495934 | E9: 1295 | F9: 1417 | G9: 1978 | H9: 2512 | I9: 2795 | J9: =IFERROR((I9/G9)^(1/COUNT($G$4:$I$4))-1,"") -> 0.1221524 | K9: =IFERROR((F9-E9)/E9,"") -> 0.094208494 | L9: =IFERROR((G9-F9)/F9,"") -> 0.39590685 | M9: =IFERROR((H9-G9)/G9,"") -> 0.26996967 | N9: =IFERROR((I9-H9)/H9,"") -> 0.11265924
D10: =IFERROR(I10/SUM($I$6:$I$12),"") -> 0 | J10: =IFERROR((I10/E10)^(1/COUNT($E$4:$I$4))-1,"") | K10: =IFERROR(F10-E10/E10,"") | L10: =IFERROR(G10-F10/F10,"") | M10: =IFERROR(H10-G10/G10,"") | N10: =IFERROR((I10-H10)/H10,"")
D11: =IFERROR(I11/SUM($I$6:$I$12),"") -> 0
D12: =IFERROR(I12/SUM($I$6:$I$12),"") -> 0
B13: Total | D13: =SUM(D6:D12) -> 1 | E13: =SUM(E6:E10) -> 11139 | F13: =SUM(F6:F10) -> 17455 | G13: =SUM(G6:G10) -> 31877 | H13: =SUM(H6:H10) -> 37281 | I13: =SUM(I6:I10) -> 46978 | J13: =IFERROR((I13/G13)^(1/COUNT($G$4:$I$4))-1,"") -> 0.13799152 | K13: =IFERROR((F13-E13)/E13,"") -> 0.56701679 | L13: =IFERROR((G13-F13)/F13,"") -> 0.8262389 | M13: =IFERROR((H13-G13)/G13,"") -> 0.16952662 | N13: =IFERROR((I13-H13)/H13,"") -> 0.26010568
B15: Segments | D15: Weight | E15: 2020 | F15: =+E15+1 -> 2021 | G15: =+F15+1 -> 2022 | H15: =+G15+1 -> 2023 | I15: =+H15+1 -> 2024 | J15: ="CAGR "&$E$4&" - "&$I$4 -> CAGR 2020 - 2024 | K15: 2021 | L15: =+K15+1 -> 2022 | M15: =+L15+1 -> 2023 | N15: =+M15+1 -> 2024
B17: Mobility | D17: =IFERROR(I17/SUM($I$17:$I$21),"") -> 0.57044431 | E17: 6089 | F17: 6953 | G17: 14029 | H17: 19832 | I17: 25087 | J17: =IFERROR((I17/E17)^(1/COUNT($E$4:$I$4))-1,"") -> 0.32733501 | K17: =IFERROR((F17-E17)/E17,"") -> 0.14189522 | L17: =IFERROR((G17-F17)/F17,"") -> 1.0176902 | M17: =IFERROR((H17-G17)/G17,"") -> 0.41364317 | N17: =IFERROR((I17-H17)/H17,"") -> 0.2649758
B18: Delivery | D18: =IFERROR(I18/SUM($I$17:$I$21),"") -> 0.31265633 | E18: 3904 | F18: 8362 | G18: 10901 | H18: 12204 | I18: 13750 | J18: =IFERROR((I18/E18)^(1/COUNT($E$4:$I$4))-1,"") -> 0.2863483 | K18: =IFERROR((F18-E18)/E18,"") -> 1.1419057 | L18: =IFERROR((G18-F18)/F18,"") -> 0.30363549 | M18: =IFERROR((H18-G18)/G18,"") -> 0.11953032 | N18: =IFERROR((I18-H18)/H18,"") -> 0.12667978
B19: Freight | D19: =IFERROR(I19/SUM($I$17:$I$21),"") -> 0.11689936 | E19: 1011 | F19: 2132 | G19: 6947 | H19: 5245 | I19: 5141 | J19: =IFERROR((I19/E19)^(1/COUNT($E$4:$I$4))-1,"") -> 0.38439267 | K19: =IFERROR((F19-E19)/E19,"") -> 1.1088032 | L19: =IFERROR((G19-F19)/F19,"") -> 2.2584428 | M19: =IFERROR((H19-G19)/G19,"") -> -0.24499784 | N19: =IFERROR((I19-H19)/H19,"") -> -0.019828408
B20: All Other | D20: =IFERROR(I20/SUM($I$17:$I$21),"") -> 0 | E20: 135 | F20: 8 | J20: =IFERROR((I20/E20)^(1/COUNT($E$4:$I$4))-1,"") -> -1 | K20: =IFERROR((F20-E20)/E20,"") -> -0.94074074 | L20: =IFERROR((G20-F20)/F20,"") -> -1 | M20: =IFERROR((H20-G20)/G20,"") | N20: =IFERROR((I20-H20)/H20,"")
D21: =IFERROR(I21/SUM($I$17:$I$21),"") -> 0 | J21: =IFERROR((I21/E21)^(1/COUNT($E$4:$I$4))-1,"") | K21: =IFERROR((F21-E21)/E21,"") | L21: =IFERROR((G21-F21)/F21,"") | M21: =IFERROR((H21-G21)/G21,"") | N21: =IFERROR((I21-H21)/H21,"")
B22: Total | D22: =SUM(D17:D21) -> 1 | E22: =SUM(E17:E21) -> 11139 | F22: =SUM(F17:F21) -> 17455 | G22: =SUM(G17:G21) -> 31877 | H22: =SUM(H17:H21) -> 37281 | I22: =SUM(I17:I21) -> 43978 | J22: =IFERROR((I22/E22)^(1/COUNT($E$4:$I$4))-1,"") -> 0.31606656 | K22: =IFERROR((F22-E22)/E22,"") -> 0.56701679 | L22: =IFERROR((G22-F22)/F22,"") -> 0.8262389 | M22: =IFERROR((H22-G22)/G22,"") -> 0.16952662 | N22: =IFERROR((I22-H22)/H22,"") -> 0.17963574
B24: Categories | D24: Description | J24: Graphs
B26: Mobility | D26: The Mobility segment's offering connects consumers with a wide range of transportation modalities, such as ridesharing, carsharing, micromobility, rentals, public transit, taxis, and more
B27: Delivery | D27: The Delivery segment's offering allows consumers to search for and discover local restaurants, order a meal, and either pick-up at the restaurant or have the meal delivered
B28: Freight | D28: The Freight segment leverages its proprietary technology, brand awareness, and experience revolutionizing industries to connect carriers with shippers on its platform, and gives carriers upfront, transparent pricing and the ability to book a shipment
B29: All Other | C29: All Other
B30: =IF(B21=0,"",B21)
B32: Products | D32: Weight | E32: 2020 | F32: =+E32+1 -> 2021 | G32: =+F32+1 -> 2022 | H32: =+G32+1 -> 2023 | I32: =+H32+1 -> 2024 | J32: =I32+1 -> 2025 | K32: =+J32+1 -> 2026 | L32: =+K32+1 -> 2027 | M32: =+L32+1 -> 2028 | N32: =+M32+1 -> 2029 | O32: =+N32+1 -> 2030 | P32: =+O32+1 -> 2031 | Q32: =+P32+1 -> 2032 | R32: =+Q32+1 -> 2033 | ... T32: =+S32+1 -> 2035
B34: UBER ONE | D34: =IFERROR(I34/$I$13,"") -> 0.056036797 | F34: 0 | G34: =+W52 -> 1052.9987 | H34: =+X52 -> 1667.2479 | I34: =+Y52 -> 2632.4966 | J34: =+I34*(1+DCF!H18) -> 2843.0964 | K34: =+J34*(1+DCF!I18) -> 3070.5441 | L34: =+K34*(1+DCF!J18) -> 3316.1876 | M34: =+L34*(1+DCF!K18) -> 3581.4826 | N34: =+M34*(1+DCF!L18) -> 3868.0012 | O34: =+N34*(1+DCF!M18) -> 4177.4413 | P34: =+O34*(1+DCF!N18) -> 4511.6366 | Q34: =+P34*(1+DCF!O18) -> 4872.5675 | ... S34: =+R34*(1+DCF!Q18) -> 5683.3628 | T34: =+S34*(1+0.08) -> 6138.0318
D36: =IFERROR(I36/$I$13,"") -> 0 | J36: =+J34/I34-1 -> 0.08 | K36: =+K34/J34-1 -> 0.08 | L36: =+L34/K34-1 -> 0.08 | M36: =+M34/L34-1 -> 0.08 | N36: =+N34/M34-1 -> 0.08 | O36: =+O34/N34-1 -> 0.08 | P36: =+P34/O34-1 -> 0.08 | Q36: =+Q34/P34-1 -> 0.08 | ... T36: =+T34/S34-1 -> 0.08
F37: =IFERROR((F36-E36)/E36,"") | G37: =IFERROR((G36-F36)/F36,"") | H37: =IFERROR((H36-G36)/G36,"") | I37: =IFERROR((I36-H36)/H36,"")
B38: Product 3 | D38: =IFERROR(I38/$I$13,"") -> 0 | J38: =I38*(1+J39) -> 0 | K38: =J38*(1+K39) -> 0 | L38: =K38*(1+L39) -> 0 | M38: =L38*(1+M39) -> 0 | N38: =M38*(1+N39) -> 0 | O38: =N38*(1+O39) -> 0 | P38: =O38*(1+P39) -> 0 | Q38: =P38*(1+Q39) -> 0 | ... T38: =S38*(1+T39) -> 0
F39: =IFERROR(F38-E38/E38,"") | G39: =IFERROR(G38-F38/F38,"") | H39: =IFERROR(H38-G38/G38,"") | I39: =IFERROR(I38-H38/H38,"")
B40: Product 4 | D40: =IFERROR(I40/$I$13,"") -> 0 | J40: =I40*(1+J41) -> 0 | K40: =J40*(1+K41) -> 0 | L40: =K40*(1+L41) -> 0 | M40: =L40*(1+M41) -> 0 | N40: =M40*(1+N41) -> 0 | O40: =N40*(1+O41) -> 0 | P40: =O40*(1+P41) -> 0 | Q40: =P40*(1+Q41) -> 0 | ... T40: =S40*(1+T41) -> 0
F41: =IFERROR(F40-E40/E40,"") | G41: =IFERROR(G40-F40/F40,"") | H41: =IFERROR(H40-G40/G40,"") | I41: =IFERROR(I40-H40/H40,"")
B42: Product 5 | D42: =IFERROR(I42/$I$13,"") -> 0 | J42: =I42*(1+J43) -> 0 | K42: =J42*(1+K43) -> 0 | L42: =K42*(1+L43) -> 0 | M42: =L42*(1+M43) -> 0 | N42: =M42*(1+N43) -> 0 | O42: =N42*(1+O43) -> 0 | P42: =O42*(1+P43) -> 0 | Q42: =P42*(1+Q43) -> 0 | ... T42: =S42*(1+T43) -> 0
F43: =IFERROR(F42-E42/E42,"") | G43: =IFERROR(G42-F42/F42,"") | H43: =IFERROR(H42-G42/G42,"") | I43: =IFERROR(I42-H42/H42,"")
B44: Total | D44: =SUM(D34:D42) -> 0.056036797 | E44: =SUM(E34:E42) -> 0 | F44: =SUM(F34:F42) -> 0 | G44: =SUM(G34:G42) -> 1052.9987 | H44: =SUM(H34:H42) -> 1667.2479 | I44: =SUM(I34:I42) -> 2632.4966 | J44: =SUM(J34:J42) -> 2843.1764 | K44: =SUM(K34:K42) -> 3070.6241 | ... T44: =SUM(T34:T42) -> 6138.1118
B46: Company's Strategy / Extra Notes
D49: Suppliers | F49: % Quantity of Supplies Origin | G49: Tarrif (19/4/25) | I49: Ride Option | J49: Description | K49: Price Category / Description | M49: Region | N49: Country | O49: Local Price (Monthly) | P49: Approx USD Price | Q49: Total GDP 2024 (USD Trillions) | R49: GDP % of Total | S49: Weighted Price (USD) | U49: UBER ONE | V49: 2021 | W49: =+V49+1 -> 2022 | X49: =+W49+1 -> 2023 | Y49: =+X49+1 -> 2024
D50: US | F50: 0.4759 | G50: 0 | I50: UberX Share | J50: Share the ride (and cost) with another passenger. | K50: Economy (Cheapest option) | M50: North America | N50: USA | O50: USD 9,99 | P50: 9.99 | Q50: 28.78 | R50: =+Q50/$Q$69 -> 0.46383445 | S50: =+R50*P50 -> 4.6337062 | U50: Users (millions) | V50: 0 | W50: 12 | X50: 19 | Y50: 30
D51: China | F51: 0.1074 | G51: 145% (245%) | I51: UberX Saver | J51: Lower-cost option if you're willing to wait longer. | K51: Economy (Cheaper than UberX) | M51: North America | N51: Canada | O51: CAD 9,99 | P51: 7.21 | Q51: 2.24 | R51: =+Q51/$Q$69 -> 0.036101083 | S51: =+R51*P51 -> 0.26028881 | U51: Growth % | V51: - | W51: - | X51: =+X50/W50-1 -> 0.58333333 | Y51: =+Y50/X50-1 -> 0.57894737
D52: Brazil | F52: 0.062 | G52: 0.1 | I52: UberX | J52: Standard, affordable ride for up to 4 passengers. | K52: Economy (Base price) | M52: North America | N52: Mexico | O52: MXN 70,00 | P52: 3.57 | Q52: 1.99 | R52: =+Q52/$Q$69 -> 0.032071944 | S52: =+R52*P52 -> 0.11449684 | U52: Expected Revenue | V52: 0 | W52: =+W50*$S$69*12 -> 1052.9987 | X52: =+X50*$S$69*12 -> 1667.2479 | Y52: =+Y50*$S$69*12 -> 2632.4966
D53: Canada | F53: 0.0481 | G53: 0.1 | I53: Uber Green | J53: Ride in an electric or hybrid vehicle (up to 4 passengers). | K53: Economy (Often similar to UberX) | M53: Europe | N53: Portugal | O53: EUR 4,99 | P53: 5.69 | Q53: 0.309 | R53: =+Q53/$Q$69 -> 0.0049800155 | S53: =+R53*P53 -> 0.028336288
...

Sheet Industry
B2: Industry Overview
B4: Sales Growth Forecast | E4: Weight | F4: 2025 | G4: =+F4+1 -> 2026 | H4: =+G4+1 -> 2027 | I4: =+H4+1 -> 2028 | J4: =+I4+1 -> 2029 | K4: =+J4+1 -> 2030 | L4: =+K4+1 -> 2031 | M4: =+L4+1 -> 2032 | N4: =+M4+1 -> 2033 | ... P4: =+O4+1 -> 2035 | Q4: ="CAGR "&$F$4&" - "&$P$4 -> CAGR 2025 - 2035 | R4: Sources
B6: Mobility | E6: 0.57 | F6: =25087*(1+0.171) -> 29376.877 | G6: =F6*(1+0.171) -> 34400.323 | H6: =G6*(1+0.171) -> 40282.778 | I6: =H6*(1+0.171) -> 47171.133 | J6: =I6*(1+0.171) -> 55237.397 | K6: =J6*(1+0.171) -> 64682.992 | L6: =K6*(1+0.171) -> 75743.784 | M6: =L6*(1+0.171) -> 88695.971 | N6: =M6*(1+0.171) -> 103862.98 | O6: =N6*(1+0.171) -> 121623.55 | Q6: 0.39 | R6: Precedence Research
B7: Delivery | E7: 31.3% | F7: =13750*(1+0.09) -> 14987.5 | G7: =F7*(1+0.09) -> 16336.375 | H7: =G7*(1+0.09) -> 17806.649 | I7: =H7*(1+0.09) -> 19409.247 | J7: =I7*(1+0.09) -> 21156.079 | K7: =J7*(1+0.09) -> 23060.127 | Q7: 0.09 | R7: Grand Review Research
B8: Freight | E8: 17.1% | F8: =5141*(1+0.1131) -> 5722.4471 | G8: =F8*(1+0.1131) -> 6369.6559 | H8: =G8*(1+0.1131) -> 7090.0639 | I8: =H8*(1+0.1131) -> 7891.9502 | J8: =I8*(1+0.1131) -> 8784.5297 | K8: =J8*(1+0.1131) -> 9778.0601 | Q8: 4,99% | R8: Precedence Research
B11: Weighted Average | E11: =SUM(E6:E10) -> 0.57 | F11: =SUMPRODUCT(F6:F10,$E$6:$E$10) -> 16744.82 | G11: =SUMPRODUCT(G6:G10,$E$6:$E$10) -> 19608.184 | H11: =SUMPRODUCT(H6:H10,$E$6:$E$10) -> 22961.184 | I11: =SUMPRODUCT(I6:I10,$E$6:$E$10) -> 26887.546 | J11: =SUMPRODUCT(J6:J10,$E$6:$E$10) -> 31485.316 | K11: =SUMPRODUCT(K6:K10,$E$6:$E$10) -> 36869.305 | L11: =SUMPRODUCT(L6:L10,$E$6:$E$10) -> 43173.957 | M11: =SUMPRODUCT(M6:M10,$E$6:$E$10) -> 50556.703 | ... O11: =SUMPRODUCT(O6:O10,$E$6:$E$10) -> 69325.424
B13: Key Drivers | E13: Description
B15: Platform Expansion and User Growth | E15: Uber's ability to acquire and retain both drivers and riders directly increases the number of transactions on the platform.
B16: Diversification of Services | E16: Investing in other forms of mobility (bikes, scooters), delivery (Uber Eats) and freight services, creates more income streams and reduces dependence on single segments.
B17: Geographic Expansion | E17: The growth in internacional markets and the expansion to different geographic locations increases Uber's total adressable market allowing long-term scalability.
B18: Technology and Operational Efficiency | E18: Investment in arificial intelligence, automation and possible future technologies like autonomous vehicles can lead to changes that could help improving user experience, reduce costs and provide competitive advantages.
B20: Industry Trends | E20: Description
B22: Increasing Customer Demand for Sustainability | E22: Consumers and governments are prioritizing lower carbon emissions and other and eco-friendly practices, calling for corporate responsability. Uber has commited to becoming a zero-emissions platform in key markets by 2040.
B23: Integration of AI in the Industry | E23: Companies from all industries are using artificial intelligence to personalize user experience and improve operational efficiency. Uber relies on AI in many aspects such as route optimization, pricing and matching riders to drivers. As this technology evolves, Uber can make the platform smarter and more efficient.
B26: Market Share | E26: Headquarters | G26: Revenues | H26: (in MM of USD) | I26: Global Market Share | K26: US Market Share
B28: {=+_FV(DCF!R4,"Name")} -> UBER TECHNOLOGIES, INC. | E28: EUA | G28: 43978 | I28: =G28/$G$40 -> 0.26581643
B29: =Peers!B8 -> LYFT INC. | E29: EUA | G29: 5786 | I29: =G29/$G$40 -> 0.034972347
B30: =Peers!B9 -> DOORDASH INC. | E30: EUA | G30: 10722 | I30: =G30/$G$40 -> 0.064807036
B31: =Peers!B10 -> GRAB HOLDINGS LIMITED | E31: SG | G31: 2797 | I31: =G31/$G$40 -> 0.01690592
B32: =Peers!B11 -> DELIVERY HERO SE | E32: GER | G32: 12082 | I32: =G32/$G$40 -> 0.07302729
B33: =Peers!B12 -> DiDi GLOBAL INC. | E33: CN | G33: 28379 | I33: =G33/$G$40 -> 0.17153132
B34: =Peers!B13 -> MEITUAN | E34: CN | G34: 46328 | I34: =G34/$G$40 -> 0.28002055
B35: =Peers!B14 -> DELIVEROO PLC | E35: UK | G35: 2760 | I35: =G35/$G$40 -> 0.016682281
B36: =Peers!B15 -> JUST EAT TAKEAWAY | E36: NLD | G36: 3564 | I36: =G36/$G$40 -> 0.021541902
B37: =Peers!B16 -> HERTZ GLOBAL HOLDINGS INC. | E37: EUA | G37: 9049 | I37: =G37/$G$40 -> 0.054694914
B38: Others | I38: =G38/$G$40 -> 0
E39: -- | G39: =G40-SUM(G28:G38) -> 0 | I39: =G39/$G$40 -> 0
B40: Industry Size | E40: -- | G40: =SUM(G28:G37) -> 165445 | I40: 1
B42: Porter's Five Forces Analysis | E42: Rating | H42: Graph
B44: Threat of New Entrants | E44: =IFERROR(AVERAGE(E45:E50),"") -> 4.1666667
B45: Economies of scale | E45: 5
B46: Product differentiation | E46: 3
B47: Capital requirements | E47: 5
B48: Access to distribution channels | E48: 5
B49: Regulations | E49: 5
B50: Switching costs | E50: 2
B51: Bargaining Power of Suppliers | E51: =IFERROR(AVERAGE(E52:E56),"") -> 3.2
B52: Number of suppliers | E52: 4
B53: Uniqueness | E53: 3
B54: Switching Costs | E54: 2
...

Sheet Peers
D3: Revenue Growth | F3: EBITDA Margin | H3: Profit Margin | J3: EV / Revenue | L3: EV / EBITDA | N3: Price / Earnings
B4: Peers | C4: Ticker | D4: =+Inputs!O4&"-"&Inputs!P4 -> 2022-2023 | E4: =+Inputs!P4&"-"&Inputs!Q4 -> 2023-2024 | F4: 2023 | G4: 2024 | H4: =+Inputs!O4&"-"&Inputs!P4 -> 2022-2023 | I4: =+Inputs!P4&"-"&Inputs!Q4 -> 2023-2024 | J4: 2023 | K4: 2024 | L4: 2023 | M4: 2024 | N4: 2023 | O4: 2024
A6: =+D91 -> #VALUE! | B6: {=IFERROR(_FV(A6,"Name"),"")} -> UBER TECHNOLOGIES, INC. | C6: {=IFERROR(_FV(A6,"Ticker symbol",TRUE),"")} -> UBER | D6: =IFERROR(D94/D93-1,"") -> 0.16952662 | E6: =IFERROR(D97/D94-1,"") -> 0.17963574 | F6: =IFERROR(D95/D94,"") -> 0.051849468 | G6: =IFERROR(D100/D97,"") -> 0.079812634 | H6: =IFERROR(D96/D94,"") -> 0.056543548 | I6: =IFERROR(D105/D97,"") -> 0.224726 | J6: {=IFERROR((_FV(A6,"Market cap",TRUE)/1000000+D$121-D$111)/D$94,"")} -> 5.3522743 | K6: {=IFERROR((_FV(A6,"Market cap",TRUE)/1000000+D$121-D$111)/D$97,"")} -> 4.5372263 | L6: {=+IFERROR((_FV(A6,"Market cap",TRUE)/1000000+D$121-D$111)/D$95,"")} -> 103.22718 | M6: {=IFERROR((_FV(A6,"Market cap",TRUE)/1000000+D$121-D$111)/D$100,"")} -> 56.848472 | N6: {=IFERROR((_FV(A6,"Market cap",TRUE)/1000000)/D$96,"")} -> 93.349211 | O6: {=IFERROR((_FV(A6,"Market cap",TRUE)/1000000)/D$105,"")} -> 19.910972
A8: =+E91 -> #VALUE! | B8: {=IFERROR(_FV(A8,"Name"),"LYFT INC.")} -> LYFT INC. | C8: {=+IFERROR(_FV(A8,"Ticker symbol",TRUE),"LYFT")} -> LYFT | D8: =+IFERROR(E94/E93-1,"") -> 0.075457875 | E8: =IFERROR(E97/E94-1,"") -> 0.31380563 | F8: =IFERROR(E95/E94,"") -> -0.057674841 | G8: =+IFERROR(E100/E97,"") -> 0.012616661 | H8: =IFERROR(E96/E94,"") -> -0.077202543 | I8: =+IFERROR(E105/E97,"") -> 0.0039751123 | J8: {=(_FV(A8,"Capitalização de mercado",TRUE)/1000000+$E$121-$E$111)/$E$94} -> 1.7266301 | K8: {=(_FV(A8,"Capitalização de mercado",TRUE)/1000000+$E$121-$E$111)/$E$97} -> 1.3142204 | L8: {=(_FV(A8,"Capitalização de mercado",TRUE)/1000000+$E$121-E$111)/E$95} -> -29.937319 | M8: {=(_FV(A8,"Capitalização de mercado",TRUE)/1000000+E$121-E$111)/E$100} -> 104.16547 | N8: {=(_FV(A8,"Capitalização de mercado",TRUE)/1000000)/E$96} -> -21.17082 | O8: {=(_FV(A8,"Capitalização de mercado",TRUE)/1000000)/E$105} -> 312.95995
A9: =+F91 -> #VALUE! | B9: {=IFERROR(_FV(A9,"Name"),"DOORDASH INC.")} -> DOORDASH INC. | C9: {=+IFERROR(_FV(A9,"Ticker symbol",TRUE),"DASH")} -> DASH | D9: =IFERROR(F94/F93-1,"") -> 0.31171199 | E9: =IFERROR(+F97/F94-1,"") -> 0.24169079 | F9: =IFERROR(F95/F94,"") -> 0.02327736 | G9: =IFERROR(F100/F97,"") -> 0.083379966 | H9: =IFERROR(F96/F94,"") -> -0.06462073 | I9: =+IFERROR(F105/F97,"") -> 0.01147174 | J9: {=(_FV($A$9,"Capitalização de mercado",TRUE)/1000000+$F$121-$F$111)/$F$94} -> 11.994443 | K9: {=(_FV($A$9,"Capitalização de mercado",TRUE)/1000000+$F$121-$F$111)/$F$94} -> 11.994443 | L9: {=(_FV(A9,"Capitalização de mercado",TRUE)/1000000+F$121-F$111)/F$95} -> 515.28367 | M9: {=(_FV(A9,"Capitalização de mercado",TRUE)/1000000+F$121-F$111)/F$100} -> 115.85237 | N9: {=(_FV(A9,"Capitalização de mercado",TRUE)/1000000)/F$96} -> -191.85487 | O9: {=(_FV(A9,"Capitalização de mercado",TRUE)/1000000)/F$105} -> 870.36599
A10: =+G91 -> #VALUE! | B10: {=IFERROR(_FV(A10,"Name"),"GRAB HOLDINGS LIMITED")} -> GRAB HOLDINGS LIMITED | C10: {=IFERROR(_FV(A10,"Ticker symbol",TRUE),"GRAB")} -> GRAB | D10: =+IFERROR(G94/G93-1,"") -> 0.64619679 | E10: =IFERROR(G97/G94-1,"") -> 0.18567189 | F10: =IFERROR(G95/G94,"") -> -0.14963968 | G10: =IFERROR(G100/G97,"") -> -0.030747229 | H10: =IFERROR(G96/G94,"") -> -0.18397626 | I10: =+IFERROR(G105/G97,"") -> -0.037540222 | J10: {=(_FV(A10,"Capitalização de mercado",TRUE)/1000000+$G$121-$G$111)/$G$94} -> 7.8653836 | K10: {=(_FV(A10,"Capitalização de mercado",TRUE)/1000000+$G$121-$G$111)/$G$97} -> 6.6336932 | L10: {=(_FV(A10,"Capitalização de mercado",TRUE)/1000000+G$121-G$111)/G$95} -> -52.562153 | M10: {=(_FV(A10,"Capitalização de mercado",TRUE)/1000000+G$121-G$111)/G$100} -> -215.7493 | N10: {=(_FV(A10,"Capitalização de mercado",TRUE)/1000000)/G$96} -> -48.742949 | O10: {=(_FV(A10,"Capitalização de mercado",TRUE)/1000000)/G$105} -> -201.47086
A11: =+H91 -> #VALUE! | B11: {=IFERROR(_FV(A11,"Name"),"DELIVERY HERO SE")} -> DELIVERY HERO SE | C11: DHER | D11: =IFERROR(H94/H93-1,"") -> 0.15914655 | E11: =IFERROR(H97/H94-1,"") -> 0.21524844 | F11: =IFERROR(H95/H94,"") -> -0.015590424 | G11: =IFERROR(H100/H97,"") -> 0.060503228 | H11: =IFERROR(H96/H94,"") -> -0.23114062 | I11: =+IFERROR(H105/H97,"") -> -0.069442145 | J11: {=(_FV(A11,"Capitalização de mercado",TRUE)/1000000+$H$121-$H$111)/$H$94} -> 1.1943149 | K11: {=(_FV(A11,"Capitalização de mercado",TRUE)/1000000+$H$121-$H$111)/$H$97} -> 0.98277429 | L11: {=(_FV(A11,"Capitalização de mercado",TRUE)/1000000+H$121-H$111)/H$95} -> -76.605671 | M11: {=(_FV(A11,"Capitalização de mercado",TRUE)/1000000+H$121-H$111)/H$100} -> 16.243337 | N11: {=(_FV(A11,"Capitalização de mercado",TRUE)/1000000)/H$96} -> -3.4681806 | O11: {=(_FV(A11,"Capitalização de mercado",TRUE)/1000000)/H$105} -> -9.4992598
A12: =+I91 -> #VALUE! | B12: {=IFERROR(_FV(A12,"Name"),"DiDi GLOBAL INC.")} -> DiDi GLOBAL INC. | C12: {=IFERROR(_FV(A12,"Ticker symbol",TRUE),"DIDIY")} -> DIDIY | D12: =+IFERROR(I94/I93-1,"") -> 0.29763565 | E12: =IFERROR(I97/I94-1,"") -> 0.0572821 | F12: =IFERROR(I95/I94,"") -> 0.024050973 | G12: =IFERROR(I100/I97,"") -> 0.0045955402 | H12: =IFERROR(I96/I94,"") -> -0.024915984 | I12: =+IFERROR(I105/I97,"") -> 0.0060856093 | J12: {=(_FV(A12,"Capitalização de mercado",TRUE)/1000000+$I$121-$I$111)/$I$94} -> 0.86837312 | K12: {=(_FV(A12,"Capitalização de mercado",TRUE)/1000000+$I$121-$I$111)/$I$97} -> 0.82132585 | L12: {=(_FV(A12,"Capitalização de mercado",TRUE)/1000000+I$121-I$111)/I$95} -> 36.10553 | M12: {=(_FV(A12,"Capitalização de mercado",TRUE)/1000000+I$121-I$111)/I$100} -> 178.72237 | N12: {=(_FV(A12,"Capitalização de mercado",TRUE)/1000000)/I$96} -> -44.713182 | O12: {=(_FV(A12,"Capitalização de mercado",TRUE)/1000000)/I$105} -> 173.14847
A13: =+J91 -> #VALUE! | B13: {=IFERROR(_FV(A13,"Name"),"MEITUAN")} -> MEITUAN | C13: {=IFERROR(_FV(A13,"Ticker symbol",TRUE),"3690")} -> 3690 | D13: =IFERROR(J94/J93-1,"") -> 0.19481607 | E13: =IFERROR(J97/J94-1,"") -> 0.19981833 | F13: =IFERROR(J95/J94,"") -> 0.080993322 | G13: =IFERROR(J100/J97,"") -> 0.14769216 | H13: =IFERROR(J96/J94,"") -> 0.050067808 | I13: =+IFERROR(J105/J97,"") -> 0.10606717 | J13: {=(_FV(A13,"Capitalização de mercado",TRUE)/1000000+$J$121-$J$111)/$J$94} -> 15.575584 | K13: {=(_FV(A13,"Capitalização de mercado",TRUE)/1000000+$J$121-$J$111)/$J$97} -> 12.981619 | L13: {=(_FV(A13,"Capitalização de mercado",TRUE)/1000000+J$121-J$111)/J$95} -> 192.30702 | M13: {=(_FV(A13,"Capitalização de mercado",TRUE)/1000000+J$121-J$111)/J$100} -> 87.896467 | N13: {=(_FV(A13,"Capitalização de mercado",TRUE)/1000000)/J$96} -> 318.56268 | O13: {=(_FV(A13,"Capitalização de mercado",TRUE)/1000000)/J$105} -> 125.33057
A14: =+K91 -> #VALUE! | B14: {=IFERROR(_FV(A14,"Name"),"DELIVEROO PLC")} -> DELIVEROO PLC | C14: ROO | D14: =IFERROR(K94/K93-1,"") -> 0.027848101 | E14: =IFERROR(K97/K94-1,"") -> 0.020689655 | F14: =+IFERROR(K95/K94,"") -> 0.0098522167 | G14: =IFERROR(K100/K97,"") -> 0.042471042 | H14: =IFERROR(K96/K94,"") -> 0.0014778325 | I14: =+IFERROR(K105/K97,"") -> 0.0014478764 | J14: {=(_FV(A14,"Capitalização de mercado",TRUE)/1000000+$K$121-$K$111)/$K$94} -> 1.1179236 | K14: {=(_FV(A14,"Capitalização de mercado",TRUE)/1000000+$K$121-$K$111)/$K$97} -> 1.095263 | L14: {=(_FV(A14,"Capitalização de mercado",TRUE)/1000000+D$121-K$111)/K$95} -> 543.51925 | M14: {=(_FV(A14,"Capitalização de mercado",TRUE)/1000000+D$121-K$111)/K$100} -> 123.5271 | N14: {=(_FV(A14,"Capitalização de mercado",TRUE)/1000000)/K$96} -> 893.46167 | O14: {=(_FV(A14,"Capitalização de mercado",TRUE)/1000000)/K$105} -> 893.46167
A15: =+L91 -> #VALUE! | B15: {=IFERROR(_FV(A15,"Name"),"JUST EAT TAKEAWAY")} -> JUST EAT TAKEAWAY | C15: {=IFERROR(_FV(A15,"Ticker symbol",TRUE),"TKWY")} -> TKWY | D15: =+IFERROR(L94/L93-1,"") -> -0.36450279 | E15: =IFERROR(L97/L94-1,"") -> 0.0084889643 | F15: =IFERROR(L95/L94,"") -> 0.11544992 | G15: =IFERROR(L100/L97,"") -> 0.10549944 | H15: =IFERROR(L96/L94,"") -> -0.52235427 | I15: =+IFERROR(L105/L97,"") -> -0.46156004 | J15: {=(_FV(A15,"Capitalização de mercado",TRUE)/1000000+$L$121-$L$111)/$L$94} -> 1.3060291 | K15: {=(_FV(A15,"Capitalização de mercado",TRUE)/1000000+$L$121-$L$111)/$L$97} -> 1.2950356 | L15: {=(_FV(A15,"Capitalização de mercado",TRUE)/1000000+L$121-L$111)/L$95} -> 11.312517 | M15: {=(_FV(A15,"Capitalização de mercado",TRUE)/1000000+L$121-L$111)/L$100} -> 12.275285 | N15: {=(_FV(A15,"Capitalização de mercado",TRUE)/1000000)/L$96} -> -2.2911739 | O15: {=(_FV(A15,"Capitalização de mercado",TRUE)/1000000)/L$105} -> -2.5711289
A16: =+M91 -> #VALUE! | B16: {=IFERROR(_FV(A16,"Name"),"HERTZ GLOBAL HOLDINGS INC.")} -> HERTZ GLOBAL HOLDINGS INC. | C16: {=IFERROR(_FV(A16,"Ticker symbol",TRUE),"HTZ")} -> HTZ | D16: =IFERROR(M94/M93-1,"") -> 0.078986759 | E16: =IFERROR(M97/M94-1,"") -> -0.034361327 | F16: =IFERROR(M95/M94,"") -> 0.42044606 | G16: =IFERROR(M100/M97,"") -> 0.40137032 | H16: =IFERROR(M96/M94,"") -> 0.065734713 | I16: =+IFERROR(M105/M97,"") -> -0.31627804 | J16: {=(_FV(A16,"Capitalização de mercado",TRUE)/1000000+$M$121-$M$111)/$M$94} -> 2.0995093 | K16: {=(_FV(A16,"Capitalização de mercado",TRUE)/1000000+$M$121-$M$111)/$M$97} -> 2.1742183 | L16: {=(_FV(A16,"Capitalização de mercado",TRUE)/1000000+M$121-M$111)/M$95} -> 4.9935283 | M16: {=(_FV(A16,"Capitalização de mercado",TRUE)/1000000+M$121-M$111)/M$100} -> 5.4169883 | N16: {=(_FV(A16,"Capitalização de mercado",TRUE)/1000000)/M$96} -> 3.0170479 | O16: {=(_FV(A16,"Capitalização de mercado",TRUE)/1000000)/M$105} -> -0.64937158
A17: =+N91 -> 0 | C17: {=+IFERROR(_FV(A17,"Ticker symbol",TRUE),"")} | D17: =IFERROR(N94/N93-1,"") | E17: =IFERROR(N97/N94-1,"") | F17: =IFERROR(N95/N94,"") | G17: =IFERROR(N100/N97,"") | H17: =IFERROR(N96/N94,"") | I17: =+IFERROR(N105/N97,"") | J17: {=IFERROR(+(_FV(A17,"Market cap",TRUE)/1000000+N$121-N$111)/N$94,"")} | K17: {=IFERROR(+(_FV(A17,"Market cap",TRUE)/1000000+N$121-N$111)/N$97,"")} | L17: {=IFERROR(+(_FV(A17,"Market cap",TRUE)/1000000+N$121-N$111)/N$95,"")} | M17: {=IFERROR(+(_FV(A17,"Market cap",TRUE)/1000000+N$121-N$111)/N$100,"")} | N17: {=IFERROR(+(_FV(A17,"Market cap",TRUE)/1000000)/N$96,"")} | O17: {=IFERROR(+(_FV(A17,"Market cap",TRUE)/1000000)/N$105,"")}
B18: Average | D18: =IFERROR(AVERAGE(D6:D17),"") -> 0.15968236 | E18: =IFERROR(AVERAGE(E6:E17),"") -> 0.13879702 | F18: =IFERROR(AVERAGE(F6:F17),"") -> 0.050301437 | G18: =IFERROR(AVERAGE(G6:G17),"") -> 0.090719376 | H18: =IFERROR(AVERAGE(H6:H17),"") -> -0.09303865 | I18: =IFERROR(AVERAGE(I6:I17),"") -> -0.053104695 | J18: =IFERROR(AVERAGE(J6:J17),"") -> 4.9100465 | K18: =IFERROR(AVERAGE(K6:K17),"") -> 4.3829819 | ... O18: =IFERROR(AVERAGE(O6:O17),"") -> 218.0987
B19: Deviation from Average | D19: =IFERROR(+D18-D6,"") -> -0.0098442558 | E19: =IFERROR(E18-E6,"") -> -0.040838718 | F19: =+IFERROR(F18-F6,"") -> -0.0015480308 | G19: =IFERROR(G18-G6,"") -> 0.010906742 | H19: =IFERROR(+H6-H18,"") -> 0.1495822 | I19: =+IFERROR(I6-I18,"") -> 0.27783069 | J19: =+IFERROR(J6-J18,"") -> 0.44222773 | K19: =+IFERROR(K6-K18,"") -> 0.15424438 | L19: =IFERROR(+L6-L18,"") -> -21.537175 | M19: =IFERROR(M6-M18,"") -> 8.3286168 | N19: =IFERROR(+N6-N18,"") -> -6.2657322 | O19: =IFERROR(+O6-O18,"") -> -198.18773
D21: Trading Multiple | G21: Net | H21: Preferred | I21: Non-Controlling | J21: Equity Value | M21: Implied Upside (Downside)
B22: Implied Share Price | D22: Revenue | E22: EBITDA | F22: P/E | G22: Debt | H22: Stock | I22: Interest | J22: Revenue | K22: EBITDA | L22: P/E | M22: Revenue | N22: EBITDA | O22: P/E | P22: Current Price
B24: Second Minimum | D24: =IFERROR(SMALL(K6:K17,2),"") -> 0.98277429 | E24: =IFERROR(SMALL(M6:M17,2),"") -> 5.4169883 | F24: =IFERROR(SMALL(O6:O17,2),"") -> -9.4992598 | G24: =-Inputs!$Q$100+Inputs!$Q$101 -> 1674 | H24: =+Inputs!$Q$102 -> 0 | I24: =+Inputs!$Q$103 -> 918 | J24: =IFERROR(+D24*$D$97+G24+H24+I24,"") -> 45812.448 | K24: =IFERROR(E24*$D$100+G24+H24+I24,"") -> 21605.629 | L24: =IFERROR(F24*$D$105,"") -> -93881.185 | M24: {=IFERROR(+(J24/_FV($A$6,"Shares outstanding",TRUE)*1000000)/$P$24-1,"")} -> -0.76718967 | N24: {=IFERROR((+K24/_FV($A$6,"Shares outstanding",TRUE)*1000000)/$P$24-1,"")} -> -0.89020422 | O24: {=IFERROR(+(L24/_FV($A$6,"Shares outstanding",TRUE)*1000000)/$P$24-1,"")} -> -1.4770867 | P24: {=+_FV(A6,"Price")} -> 94.36
B25: Average | D25: =+IFERROR(AVERAGE(K6:K17),"") -> 4.3829819 | E25: =IFERROR(+AVERAGE(M6:M17),"") -> 48.519855 | F25: =IFERROR(+AVERAGE(O6:O17),"") -> 218.0987 | G25: =-Inputs!$Q$100+Inputs!$Q$101 -> 1674 | H25: =+Inputs!$Q$102 -> 0 | I25: =+Inputs!$Q$103 -> 918 | J25: =IFERROR(+D25*$D$97+G25+H25+I25,"") -> 195346.78 | K25: =IFERROR(E25*$D$100+G25+H25+I25,"") -> 172896.69 | L25: =IFERROR(+F25*$D$105,"") -> 2155469.5 | M25: {=IFERROR(+(J25/_FV($A$6,"Shares outstanding",TRUE)*1000000)/$P$24-1,"")} -> -0.0072840653 | N25: {=IFERROR((+K25/_FV($A$6,"Shares outstanding",TRUE)*1000000)/$P$24-1,"")} -> -0.12137122 | O25: {=IFERROR(+(L25/_FV($A$6,"Shares outstanding",TRUE)*1000000)/$P$24-1,"")} -> 9.9536943
B26: Median | D26: =IFERROR(MEDIAN(K6:K17),"") -> 1.7442193 | E26: =IFERROR(MEDIAN(M6:M17),"") -> 72.372469 | F26: =IFERROR(MEDIAN(O6:O17),"") -> 72.620772 | G26: =-Inputs!$Q$100+Inputs!$Q$101 -> 1674 | H26: =+Inputs!$Q$102 -> 0 | I26: =+Inputs!$Q$103 -> 918 | J26: =IFERROR(D26*$D$97+G26+H26+I26,"") -> 79299.278 | K26: =IFERROR(E26*$D$100+G26+H26+I26,"") -> 256619.37 | L26: =IFERROR(+F26*$D$105,"") -> 717711.09 | M26: {=IFERROR(+(J26/_FV($A$6,"Shares outstanding",TRUE)*1000000)/$P$24-1,"")} -> -0.59701584 | N26: {=IFERROR((+K26/_FV($A$6,"Shares outstanding",TRUE)*1000000)/$P$24-1,"")} -> 0.30409182 | O26: {=+IFERROR((L26/_FV($A$6,"Shares outstanding",TRUE)*1000000)/$P$24-1,"")} -> 2.6472741
B27: Second Maximum | D27: =IFERROR(LARGE(K6:K17,2),"") -> 11.994443 | E27: =IFERROR(LARGE(M6:M17,2),"") -> 123.5271 | F27: =IFERROR(LARGE(O6:O17,2),"") -> 870.36599 | G27: =-Inputs!$Q$100+Inputs!$Q$101 -> 1674 | H27: =+Inputs!$Q$102 -> 0 | I27: =+Inputs!$Q$103 -> 918 | J27: =IFERROR(+D27*$D$97+G27+H27+I27,"") -> 530083.62 | K27: =IFERROR(E27*$D$100+G27+H27+I27,"") -> 436172.13 | L27: =IFERROR(+F27*$D$105,"") -> 8601827.1 | M27: {=IFERROR(+(J27/_FV($A$6,"Shares outstanding",TRUE)*1000000)/$P$24-1,"")} -> 1.6937862 | N27: {=IFERROR((+K27/_FV($A$6,"Shares outstanding",TRUE)*1000000)/$P$24-1,"")} -> 1.2165455 | O27: {=IFERROR(+(L27/_FV($A$6,"Shares outstanding",TRUE)*1000000)/$P$24-1,"")} -> 42.712883
B29: Profitability | D29: =+LEFT(B6, FIND(" ", B6 & " ") - 1) -> UBER | E29: =+LEFT(B8, FIND(" ", B8 & " ") - 1) -> LYFT | F29: =+LEFT(B9, FIND(" ", B9 & " ") - 1) -> DOORDASH | G29: =+LEFT(B10, FIND(" ", B10 & " ") - 1) -> GRAB | H29: DELIVERY HERO | I29: =+LEFT(B12, FIND(" ", B12 & " ") - 1) -> DiDi | J29: =+LEFT(C12, FIND(" ", C12 & " ") - 1) -> DIDIY | K29: =+LEFT(B14, FIND(" ", B14 & " ") - 1) -> DELIVEROO | L29: JUST EAT TAKEAWAY | M29: =+LEFT(B16, FIND(" ", B16 & " ") - 1) -> HERTZ | N29: =+LEFT(B17, FIND(" ", B17 & " ") - 1) | O29: Average
B31: Operating Margin | D31: =IFERROR(D101/D97,"") -> 0.063645459 | E31: =IFERROR(E101/E97,"") -> -0.019702731 | F31: =IFERROR(F101/F97,"") -> 0.021637754 | G31: =IFERROR(G101/G97,"") -> -0.08330354 | H31: =IFERROR(H101/H97,"") -> 0.015808641 | I31: =IFERROR(I101/I97,"") -> -0.010642853 | J31: =IFERROR(J101/J97,"") -> 0.12274659 | K31: =IFERROR(K101/K97,"") -> 0.0014478764 | ... N31: =IFERROR(N101/N97,"") | O31: =IFERROR(+AVERAGE(D31:N31),"") -> -0.0054630033
B32: Net Income Margin | D32: =IFERROR(D105/D97,"") -> 0.224726 | E32: =IFERROR(E105/E97,"") -> 0.0039751123 | F32: =IFERROR(F105/F97,"") -> 0.01147174 | G32: =IFERROR(G105/G97,"") -> -0.037540222 | H32: =IFERROR(H105/H97,"") -> -0.069442145 | I32: =IFERROR(I105/I97,"") -> 0.0060856093 | J32: =IFERROR(J105/J97,"") -> 0.10606717 | K32: =IFERROR(K105/K97,"") -> 0.0014478764 | ... N32: =IFERROR(N105/N97,"") | O32: =IFERROR(+AVERAGE(D32:N32),"") -> -0.053104695
B33: ROA (%) | D33: =IFERROR(D105/D117,"") -> 0.1928616 | E33: =IFERROR(E105/E117,"") -> 0.0042318307 | F33: =IFERROR(F105/F117,"") -> 0.0095757104 | G33: =IFERROR(G105/G117,"") -> -0.011296396 | H33: =IFERROR(H105/H117,"") -> -0.079996186 | I33: =IFERROR(I105/I117,"") -> 0.008867245 | J33: =IFERROR(J105/J117,"") -> 0.11192552 | K33: =IFERROR(K105/K117,"") -> 0.0031678986 | ... N33: =IFERROR(N105/N117,"") | O33: =IFERROR(+AVERAGE(D33:N33),"") -> -0.0094321946
B34: Financial Cost of Debt | D34: =IFERROR(+(D102/D121)*(1-(D104/D103)),"") -> -0.054835742 | E34: =IFERROR(+(E102/E121)*(1-(E104/E103)),"") -> -0.10348498 | F34: =IFERROR(+(F102/F121)*(1-(F104/F103)),"") -> -0.27845149 | G34: =IFERROR(+(G102/G121)*(1-(G104/G103)),"") -> -0.3335454 | H34: =IFERROR(+(H102/H121)*(1-(H104/H103)),"") | I34: =IFERROR(+(I102/I121)*(1-(I104/I103)),"") -> -3.2136468 | J34: =IFERROR(+(J102/J121)*(1-(J104/J103)),"") -> 0.00070477272 | K34: =IFERROR(+(K102/K121)*(1-(K104/K103)),"") -> 0 | ... N34: =IFERROR(+(N102/N121)*(1-(N104/N103)),"") | O34: =IFERROR(+AVERAGE(D34:N34),"") -> -0.45077974
B35: Return on Equity (RoE) | D35: =IFERROR(+D105/D122,"") -> 0.43971347 | E35: =IFERROR(+E105/E122,"") -> 0.029986962 | F35: =IFERROR(+F105/F122,"") -> 0.01574904 | G35: =IFERROR(+G105/G122,"") -> -0.016532829 | H35: =IFERROR(+H105/H122,"") -> -0.50879321 | I35: =IFERROR(+I105/I122,"") -> 0.012927082 | J35: =IFERROR(+J105/J122,"") -> 0.21032889 | K35: =IFERROR(+K105/K122,"") -> 0.006833713 | ... N35: =IFERROR(+N105/N122,"") | O35: =IFERROR(+AVERAGE(D35:N35),"") -> -1.8885998
B36: Return on Invested Capital (ROIC) | D36: =IFERROR(+D105/(D121+D122),"") -> 0.3175057 | E36: =IFERROR(+E105/(E121+E122),"") -> 0.011904762 | F36: =IFERROR(+F105/(F121+F122),"") -> 0.014737599 | G36: =IFERROR(+G105/(G121+G122),"") -> -0.015636634 | H36: =IFERROR(+H105/(H121+H122),"") -> -0.11633389 | I36: =IFERROR(+I105/(I121+I122),"") -> 0.012742475 | J36: =IFERROR(+J105/(J121+J122),"") -> 0.15506813 | K36: =IFERROR(+K105/(K121+K122),"") -> 0.0061349693 | ... N36: =IFERROR(+N105/(N121+N122),"") | O36: =IFERROR(+AVERAGE(D36:N36),"") -> -0.0042009552
B38: Solvency | D38: =+D29 -> UBER | E38: =+E29 -> LYFT | F38: =+F29 -> DOORDASH | G38: =+G29 -> GRAB | H38: =+H29 -> DELIVERY HERO | I38: =+I29 -> DiDi | J38: =+J29 -> DIDIY | K38: =+K29 -> DELIVEROO | ... O38: =+O29 -> Average
B40: Debt/Assets | D40: =IFERROR(D121/D117,"") -> 0.16881976 | E40: =IFERROR(E121/E117,"") -> 0.21435143 | F40: =IFERROR(F121/F117,"") -> 0.041728299 | G40: =IFERROR(G121/G117,"") -> 0.039160839 | H40: =IFERROR(H121/H117,"") -> 0.53041571 | I40: =IFERROR(I121/I117,"") -> 0.0099376046 | J40: =IFERROR(J121/J117,"") -> 0.18963763 | K40: =IFERROR(K121/K117,"") -> 0.05279831 | ... N40: =IFERROR(N121/N117,"") | O40: =IFERROR(+AVERAGE(D40:N40),"") -> 0.2283474
B41: Net Debt/EBITDA | D41: =IFERROR(+(D121-D111)/D100,"") -> 0.78575499 | E41: =IFERROR(+(E121-E111)/E100,"") -> 5.5616438 | F41: =IFERROR(+(F121-F111)/F100,"") -> -3.8959732 | G41: =IFERROR(+(G121-G111)/G100,"") -> 30.232558 | H41: =IFERROR(+(H121-H111)/H100,"") -> 5.3406293 | I41: =IFERROR(+(I121-I111)/I100,"") -> -50.568182 | J41: =IFERROR(+(J121-J111)/J100,"") -> -2.1114176 | K41: =IFERROR(+(K121-K111)/K100,"") -> -4.6704545 | ... N41: =IFERROR(+(N121-N111)/N100,"") | O41: =IFERROR(+AVERAGE(D41:N41),"") -> -1.3393559
B42: Interest Coverage Ratio | D42: =IFERROR(D101/D102,"") -> -14.136364 | E42: =IFERROR(E101/E102,"") -> 0.83211679 | F42: =IFERROR(F101/F102,"") -> -1.1658291 | G42: =IFERROR(G101/G102,"") -> 3.1917808 | H42: =IFERROR(H101/H102,"") | I42: =IFERROR(I101/I102,"") -> 0.49338283 | J42: =IFERROR(J101/J102,"") -> 913.5873 | K42: =IFERROR(K101/K102,"") -> -0.12 | ... N42: =IFERROR(N101/N102,"") | O42: =IFERROR(+AVERAGE(D42:N42),"") -> 100.8201
B44: Liquidity | D44: =+D29 -> UBER | E44: =+E29 -> LYFT | F44: =+F29 -> DOORDASH | G44: =+G29 -> GRAB | H44: =+H29 -> DELIVERY HERO | I44: =+I29 -> DiDi | J44: =+J29 -> DIDIY | K44: =+K29 -> DELIVEROO | ... O44: =+O29 -> Average
B46: Cash Ratio | D46: =IFERROR(D111/D119,"") -> 0.51350645 | E46: =IFERROR(E111/E119,"") -> 0.19556815 | F46: =IFERROR(F111/F119,"") -> 0.9055881 | G46: =IFERROR(G111/G119,"") -> 1.1435185 | H46: =IFERROR(H111/H119,"") -> 0.56351902 | I46: =IFERROR(I111/I119,"") -> 1.1545791 | J46: =IFERROR(J111/J119,"") -> 1.5587378 | K46: =IFERROR(K111/K119,"") -> 0.9978355 | ... N46: =IFERROR(N111/N119,"") | O46: =IFERROR(+AVERAGE(D46:N46),"") -> 0.78336024
B47: Quick Ratio | D47: =IFERROR(+(D111+D112)/D119,"") -> 0.80393865 | E47: =IFERROR(+(E111+E112)/E119,"") -> 0.19556815 | F47: =IFERROR(+(F111+F112)/F119,"") -> 1.0705273 | G47: =IFERROR(+(G111+G112)/G119,"") -> 1.2229938 | H47: =IFERROR(+(H111+H112)/H119,"") -> 0.77309783 | I47: =IFERROR(+(I111+I112)/I119,"") -> 1.2349857 | J47: =IFERROR(+(J111+J112)/J119,"") -> 1.5833204 | K47: =IFERROR(+(K111+K112)/K119,"") -> 1.1298701 | ... N47: =IFERROR(+(N111+N112)/N119,"") | O47: =IFERROR(+AVERAGE(D47:N47),"") -> 0.94978278
B48: Current Ratio | D48: =IFERROR(D115/D119,"") -> 1.0670094 | E48: =IFERROR(E115/E119,"") -> 0.76037104 | F48: =IFERROR(F115/F119,"") -> 1.6642632 | G48: =IFERROR(G115/G119,"") -> 2.533179 | H48: =IFERROR(H115/H119,"") -> 0.96297554 | I48: =IFERROR(I115/I119,"") -> 11.747437 | J48: =IFERROR(J115/J119,"") -> 1.9431524 | K48: =IFERROR(K115/K119,"") -> 1.7121212 | ... N48: =IFERROR(N115/N119,"") | O48: =IFERROR(+AVERAGE(D48:N48),"") -> 2.5135879
B50: Activity | D50: =+D29 -> UBER | E50: =+E29 -> LYFT | F50: =+F29 -> DOORDASH | G50: =+G29 -> GRAB | H50: =+H29 -> DELIVERY HERO | I50: =+I29 -> DiDi | J50: =+J29 -> DIDIY | K50: =+K29 -> DELIVEROO | ... O50: =+O29 -> Average
B52: Inventory Turnover | D52: =IFERROR(D98/(AVERAGE(D113:D114)),"") | E52: =IFERROR(E98/(AVERAGE(E113:E114)),"") | F52: =IFERROR(F98/(AVERAGE(F113:F114)),"") | G52: =IFERROR(G98/(AVERAGE(G113:G114)),"") -> 30.055556 | H52: =IFERROR(H98/(AVERAGE(H113:H114)),"") -> 58.385965 | I52: =IFERROR(I98/(AVERAGE(I113:I114)),"") | J52: =IFERROR(J98/(AVERAGE(J113:J114)),"") -> 274.10826 | K52: =IFERROR(K98/(AVERAGE(K113:K114)),"") -> 93.214286 | ... N52: =IFERROR(N98/(AVERAGE(N113:N114)),"") | O52: =IFERROR(+AVERAGE(D52:N52),"") -> 118.17504
B53: Acc. Receivable Turnover | D53: =IFERROR(D97/D112,"") -> 13.194719 | E53: =IFERROR(E97/E112,"") | F53: =IFERROR(F97/F112,"") -> 14.647541 | G53: =IFERROR(G97/G112,"") -> 13.57767 | H53: =IFERROR(H97/H112,"") -> 19.581848 | I53: =IFERROR(I97/I112,"") -> 60.028213 | J53: =IFERROR(J97/J112,"") -> 128.99615 | K53: =IFERROR(K97/K112,"") -> 33.967213 | ... N53: =IFERROR(N97/N112,"") | O53: =IFERROR(+AVERAGE(D53:N53),"") -> 34.718622
B54: Payables Turnover | D54: =IFERROR(D98/D118,"") -> 31.061772 | E54: =IFERROR(E98/E118,"") -> 34.061224 | F54: =IFERROR(F98/F118,"") -> 17.155763 | G54: =IFERROR(G98/G118,"") -> 1.3883661 | H54: =IFERROR(H98/H118,"") -> 28.29932 | I54: =IFERROR(I98/I118,"") -> 5.318944 | J54: =IFERROR(J98/J118,"") -> 4.5054321 | K54: =IFERROR(K98/K118,"") -> 37.285714 | ... N54: =IFERROR(N98/N118,"") | O54: =IFERROR(+AVERAGE(D54:N54),"") -> 21.035651
...

Sheet ESG
B2: Environmental, Social and Governance Analysis
B4: Author: | C4: Bloomberg | E4: Highlights | N4: Recent News
G5: EV Integration: Uber has expanded its electric vehicle offerings, now with over 182,000 EVs available globally. The "Uber Green" option is accessible in over 200 cities, allowing users to choose electric or hybrid vehicles easily and promoting deliveries by bike, foot, or EVs. | N5: Climate-Focused Initiatives: At its "Go-Get Zero" event in October 2024, Uber unveiled several climate-focused features, including the ability for users to choose electric vehicles at the same price as standard rides and to track emissions savings. These initiatives align with Uber's goal to become an emissions-free mobility platform by 2040. | R5: Investor Call for Transparency: In December 2024, a group of Uber investors proposed a resolution demanding more detailed disclosures on driver compensation. They argue that the current lack of transparency hinders the assessment of the company's financial health and its commitment to fair labor practices.
B6: Overview | D6: . | E6: Leadership in Sustainability: In August 2024, Uber appointed former Tesla executive Rebecca Tinucci as its Global Head of Sustainability, underscoring its commitment to accelerating the transition to electric vehicles and enhancing sustainability efforts.
B7: Last Update | C7: 45748 | D7: . | G7: Uber aims to have net-zero emissions across its platform by 2040, including Uber Eats deliveries.
B8: Latest year with data | C8: 2024 | E8: The platform now enables users to track emissions savings when opting for sustainable transport options. Uber also introduced a sustainable packaging marketplace for restaurants and provided financial incentives to encourage eco-friendly packaging .​
B9: GICS Sector | C9: Industrials
B10: GICS Industry Group | C10: Transportation
B11: Final Review
B13: ESG Scores
B14: LSEG ESG Score | C14: 78
B15: E-Score | C15: 67 | O15: https://www.esgdive.com/news/uber-rolls-out-climate-focused-features-updates-drives-sustainability-goals/729509/? | S15: https://www.bloomberg.com/news/articles/2024-12-20/uber-investors-are-calling-for-more-transparency-into-driver-pay
B16: S-Score | C16: 67 | E16: GHG Scope 1 and 2 Emissions: | N16: Water, Waste, Energy Management:
B17: G-Score | C17: 90
B18: S&P Global ESG Score | C18: 39
B19: Environmental | C19: 55
B20: Social | C20: 27
B21: Governance & Economic | C21: 42
B22: Sustainalytics | C22: 21.8
B23: ISS ESG Corporate Rating | C23: C+
B24: SDG Impact Rating | C24: -5.5
B25: Governance Quality Score | C25: 9
B26: MSCI ESG Ratings | C26: A
B29: Industry ESG Overview:
B30: Concerning environmental impact, particularly carbon emissions and waste management, companies in the mobility and delivery sector like Uber are pivotal in transitioning to sustainable practices. This includes adopting electric vehicles (EVs), reducing packaging waste, and enhancing supply chain sustainability. Socially, there's a growing emphasis on worker rights, diversity, and community engagement. Governance-wise, transparency in operations and aligning executive compensation with ESG goals are becoming industry standards.
E33: ENVIRONMENTAL
G35: Overview | H35: Targets | K35: Improvements | O35: Comments
