Workbook
Name COOLFUCNTION: _xlfn.LAMBDA(_xldudf_BOARDFLARE_EXEC("workbook-settings:coolfucntion"))
Name COOLFUCNTION: _xlfn.LAMBDA(_xldudf_BOARDFLARE_EXEC("workbook-settings:coolfucntion"))
Name COOLFUCNTION: _xlfn.LAMBDA(_xldudf_BOARDFLARE_EXEC("workbook-settings:coolfucntion"))
Name COOLFUCNTION: _xlfn.LAMBDA(_xldudf_BOARDFLARE_EXEC("workbook-settings:coolfucntion"))
Name COOLFUCNTION: _xlfn.LAMBDA(_xldudf_BOARDFLARE_EXEC("workbook-settings:coolfucntion"))
Name COOLFUCNTION: _xlfn.LAMBDA(_xldudf_BOARDFLARE_EXEC("workbook-settings:coolfucntion"))
Name COOLFUCNTION: _xlfn.LAMBDA(_xldudf_BOARDFLARE_EXEC("workbook-settings:coolfucntion"))
Name COOLFUCNTION: _xlfn.LAMBDA(_xldudf_BOARDFLARE_EXEC("workbook-settings:coolfucntion"))
Name COOLFUCNTION: _xlfn.LAMBDA(_xldudf_BOARDFLARE_EXEC("workbook-settings:coolfucntion"))
Name COOLFUCNTION: _xlfn.LAMBDA(_xldudf_BOARDFLARE_EXEC("workbook-settings:coolfucntion"))
Name COOLFUCNTION: _xlfn.LAMBDA(_xldudf_BOARDFLARE_EXEC("workbook-settings:coolfucntion"))
Name Sectors: #REF!
Name Sectors: #REF!
Name Sectors: #REF!
Name Sectors: #REF!
Name Sectors: #REF!
Name Sectors: #REF!
Name Sectors: #REF!
Name Sectors: #REF!

Sheet Dashboard
C154: =+C155+1 -> 45984
C155: =+C156+1 -> 45983
C156: =+C157+1 -> 45982
C157: =+C158+1 -> 45981
C158: =+C159+1 -> 45980
C159: =+C160+1 -> 45979
C160: =+C161+1 -> 45978 | L160: =IF(FCFF!$R$157="Revenue Exit",FCFF!$AF$169,IF(FCFF!$R$157="EBITDA Exit",FCFF!Z169,FCFF!AL169)) -> 46.167588
C161: =+C162+1 -> 45977
C162: =+C163+1 -> 45976 | E162: =IF(FCFF!$R$157="Revenue Exit",FCFF!$AF$169,IF(FCFF!$R$157="EBITDA Exit",FCFF!Z169,FCFF!AL169)) -> 46.167588
C163: =+C164+1 -> 45975 | E163: =E164+($E$162-$E$193)/COUNTA($C$162:$C$192) -> 48.762827
C164: =+C165+1 -> 45974 | E164: =E165+($E$162-$E$193)/COUNTA($C$162:$C$192) -> 51.358066
C165: =+C166+1 -> 45973 | E165: =E166+($E$162-$E$193)/COUNTA($C$162:$C$192) -> 53.953306
C166: =+C167+1 -> 45972 | E166: =E167+($E$162-$E$193)/COUNTA($C$162:$C$192) -> 56.548545
C167: =+C168+1 -> 45971 | E167: =E168+($E$162-$E$193)/COUNTA($C$162:$C$192) -> 59.143784
C168: =+C169+1 -> 45970 | E168: =E169+($E$162-$E$193)/COUNTA($C$162:$C$192) -> 61.739023
C169: =+C170+1 -> 45969 | E169: =E170+($E$162-$E$193)/COUNTA($C$162:$C$192) -> 64.334262
C170: =+C171+1 -> 45968 | E170: =E171+($E$162-$E$193)/COUNTA($C$162:$C$192) -> 66.929501
C171: =+C172+1 -> 45967 | E171: =E172+($E$162-$E$193)/COUNTA($C$162:$C$192) -> 69.52474
C172: =+C173+1 -> 45966 | E172: =E173+($E$162-$E$193)/COUNTA($C$162:$C$192) -> 72.119979
C173: =+C174+1 -> 45965 | E173: =E174+($E$162-$E$193)/COUNTA($C$162:$C$192) -> 74.715218
C174: =+C175+1 -> 45964 | E174: =E175+($E$162-$E$193)/COUNTA($C$162:$C$192) -> 77.310457
... C192: =+C193+1 -> 45946 | E192: =E193+($E$162-$E$193)/COUNTA($C$162:$C$192) -> 124.02476
B193: TODAY | C193: =+'Stock Data'!AM4 -> 45945 | D193: =_xlfn.XLOOKUP(C193,'Stock Data'!$AM$4:$AM$1051,'Stock Data'!$AN$4:$AN$1051) -> 126.62 | E193: =D193 -> 126.62
C194: =+'Stock Data'!AM5 -> 45944 | D194: =_xlfn.XLOOKUP(C194,'Stock Data'!$AM$4:$AM$1051,'Stock Data'!$AN$4:$AN$1051) -> 126.62
C195: =+'Stock Data'!AM6 -> 45943 | D195: =_xlfn.XLOOKUP(C195,'Stock Data'!$AM$4:$AM$1051,'Stock Data'!$AN$4:$AN$1051) -> 126.62
C196: =+'Stock Data'!AM7 -> 45942 | D196: =_xlfn.XLOOKUP(C196,'Stock Data'!$AM$4:$AM$1051,'Stock Data'!$AN$4:$AN$1051) -> 126.62
C197: =+'Stock Data'!AM8 -> 45941 | D197: =_xlfn.XLOOKUP(C197,'Stock Data'!$AM$4:$AM$1051,'Stock Data'!$AN$4:$AN$1051) -> 125.94
C198: =+'Stock Data'!AM9 -> 45940 | D198: =_xlfn.XLOOKUP(C198,'Stock Data'!$AM$4:$AM$1051,'Stock Data'!$AN$4:$AN$1051) -> 124.08
C199: =+'Stock Data'!AM10 -> 45939 | D199: =_xlfn.XLOOKUP(C199,'Stock Data'!$AM$4:$AM$1051,'Stock Data'!$AN$4:$AN$1051) -> 124.94
C200: =+'Stock Data'!AM11 -> 45938 | D200: =_xlfn.XLOOKUP(C200,'Stock Data'!$AM$4:$AM$1051,'Stock Data'!$AN$4:$AN$1051) -> 124.89
C201: =+'Stock Data'!AM12 -> 45937 | D201: =_xlfn.XLOOKUP(C201,'Stock Data'!$AM$4:$AM$1051,'Stock Data'!$AN$4:$AN$1051) -> 124.89
C202: =+'Stock Data'!AM13 -> 45936 | D202: =_xlfn.XLOOKUP(C202,'Stock Data'!$AM$4:$AM$1051,'Stock Data'!$AN$4:$AN$1051) -> 124.89
C203: =+'Stock Data'!AM14 -> 45935 | D203: =_xlfn.XLOOKUP(C203,'Stock Data'!$AM$4:$AM$1051,'Stock Data'!$AN$4:$AN$1051) -> 124.89
C204: =+'Stock Data'!AM15 -> 45934 | D204: =_xlfn.XLOOKUP(C204,'Stock Data'!$AM$4:$AM$1051,'Stock Data'!$AN$4:$AN$1051) -> 125.74
C205: =+'Stock Data'!AM16 -> 45933 | D205: =_xlfn.XLOOKUP(C205,'Stock Data'!$AM$4:$AM$1051,'Stock Data'!$AN$4:$AN$1051) -> 125.64
... C558: =+'Stock Data'!AM369 -> 45580 | D558: =_xlfn.XLOOKUP(C558,'Stock Data'!$AM$4:$AM$1051,'Stock Data'!$AN$4:$AN$1051) -> 94.05

Sheet Key Info
B7: Analysts | F7: LIS – Equity Research | J7: Stock Performance
B12: Mariana Zhu, Co-Head of Equity Research | F12: Recommendation: | H12: Strong Buy
B13: MSc in Mathematical Finance, ISEG – Ulisboa | E13: #VALUE! | F13: Target Price (FCFF):
B14: l63113@aln.iseg.ulisboa.pt | F14: Upside:
B15: Maria Ana Rocha, Analyst
B16: BSc in Applied Mathematics, ISEG – Ulisboa | F16: Ticker | H16: {=_FV(E13,"Nome")} -> ACM Rsrch
B17: maria.ana.rocha@aln.iseg.ulisboa.pt | F17: Stock Exchange | H17: {=_FV(E13,"Bolsa")} -> Nasdaq Stock Market
B18: Rodrigo Ji, Analyst
B19: BSc in Economics, ISEG – Ulisboa | F19: Current Price | H19: 38.12
B20: l63970@aln.iseg.ulisboa.pt | F20: ="Market Cap (in "&IF(Inputs!$D$14="BLN","billions",IF(Inputs!$D$14="MLN","millions","thousands"))&")" -> Market Cap (in millions) | H20: 2443.7
B21: Maria Gonçalves, Analyst | F21: Beta | H21: 1.52
B22: BSc in Applied Mathematics, ISEG – Ulisboa | F22: % of 52-Week High | H22: 0.4512
B23: l63847@aln.iseg.ulisboa.pt | F23: 100-Day Moving Average | H23: 29.42
B25: Reviewed by: | F25: Avg Vol (1 month) | H25: 156927
B26: José Lima, Vice President | F26: Shares Outstanding (millions) | H26: 59.2
B27: BSc in Management, ISEG – Ulisboa | F27: % Float | H27: =50.2/59.2 -> 0.84797297
B28: l60456@aln.iseg.ulisboa.pt | F28: Short % of Float | H28: 0.0959
B30: LISBON INVESTMENT SOCIETY | F30: % Held by Insiders | H30: 0.1526
B31: ISEG – Rua do Quelhas, 6 | F31: % Held by Institutions | H31: 0.7036
B32: lis@iseg.ulisboa.pt
B34: Disclaimer: This report was prepared by members of the Lisbon Investment Society (LIS), an independent, student-led, non-profit organization based at ISEG – Lisbon School of Economics & Management, and is intended solely for academic and educational purposes. All analyses, forecasts, and opinions expressed in this report reflect the independent judgment of the authors as of the date of publication and are subject to change without notice. The views presented herein do not represent those of ISEG, its faculty, or any affiliated entity. This document does not constitute, and should not be interpreted as, investment advice, an offer, or a solicitation to buy or sell any security or financial instrument. Nothing in this report should be construed as a recommendation to make or refrain from making any investment decision. The content is intended for informational purposes only, and readers are strongly encouraged to conduct their own research and seek advice from a qualified financial professional before making any financial decisions. The information contained in this report has been obtained from publicly available sources believed to be reliable; however, no representation or warranty is made regarding the accuracy, completeness, or timeliness of such information. LIS and its members accept no liability whatsoever for any direct or indirect loss arising from the use of this report or its contents. This report incorporates terminology, financial metrics, and methodologies commonly used in professional equity research, including but not limited to Discounted Cash Flow (DCF), trading multiples, Monte Carlo simulations, and strategic analysis tools such as Porter’s Five Forces. Definitions and assumptions used in these models are disclosed within the report and reflect a hypothetical investment thesis designed solely for academic discussion. All valuations, projections, and target prices presented herein are based on publicly available data and subject to the limitations of modeling assumptions. These are not guarantees of future performance and should not be relied upon as such, as past performance is not indicative of future results. Any company names, logos, trademarks, or brand references mentioned in this report are the property of their respective owners and are used strictly for identification and academic purposes. This document may not be reproduced, redistributed, or quoted in whole or in part without the prior written consent of the Lisbon Investment Society. About LIS – Lisbon Investment Society: The Lisbon Investment Society (LIS) is a non-profit academic association headquartered at ISEG – Lisbon School of Economics & Management. Founded in 2016, LIS is committed to fostering student interest in finance and investment through applied research, skill development, and institutional engagement. The Society operates independently and autonomously from any political, religious, or commercial affiliation, and is composed of selected students and collaborators who are invited through a rigorous recruitment process and share a commitment to excellence, analytical rigor, and ethical standards. Its activities include equity research, portfolio management, macroeconomic analysis, and investment education. This report was prepared by the Equity Research team at the Lisbon Investment Society, whose analysts combine rigorous financial modeling, critical thinking, and collaborative research to deliver high-quality, student-led investment analysis. We welcome your feedback, discussion, and questions regarding this report or our research process, and invite you to reach out to our team as we are always open to engagement.

Sheet Industry
D6: 584.17 | E6: 627.76 | F6: 676.06 | G6: 729.63 | H6: 789.13 | I6: 855.3 | J6: 929 | K6: 997.69 | L6: 1067.63 | M6: 1137.57
A7: x | B7: Industry Growth Forecast | O7: Industry Index
D9: 2022 | E9: =+D9+1 -> 2023 | F9: =+E9+1 -> 2024 | G9: =+F9+1 -> 2025 | H9: =+G9+1 -> 2026 | I9: =+H9+1 -> 2027 | J9: =+I9+1 -> 2028 | K9: =+J9+1 -> 2029 | M9: ="CAGR "&$G$9&" - "&$K$9 -> CAGR 2025 - 2029
B12: Market Size | D12: 608180 | E12: 549420 | F12: 659100 | G12: 789270 | H12: 891000 | I12: 969010 | J12: 1036450 | K12: 1148020 | M12: =(K12/G12)^(1/5)-1 -> 0.077816361
B13: Market Share | D13: =+IS!T18/D12 -> 0.00063933704 | E13: =+IS!Z18/Industry!E12 -> 0.0010151123 | F13: =IS!AF18/Industry!F12 -> 0.0011866454 | G13: =+IS!AK18/Industry!G12 -> 0.00038624451 | H13: =+IS!AR18/Industry!H12 -> 0.0012748995 | I13: =IS!AT18/Industry!I12 -> 0.001387179 | J13: =+IS!AV18/Industry!J12 -> 0.0015130706 | K13: =+IS!AX18/Industry!K12 -> 0.0015709267 | M13: =((K13*K12)/(G13*G12))^(1/5)-1 -> 0.42693271
A23: x
B25: Industry Driver | D25: Description | O25: Porter's Five Forces
B27: Subsidies | D27: Governments encouraging domestic semiconductor fabs with subsidies
B28: Growth tied to China | D28: China is the largest consumer of semiconductors. Adittionally, the Chinese government could intervene in ACM Shanghai’s operations, impose restrictions on foreign listings, or change audit and access requirements
B29: Market Expansion | D29: The semiconductor industry is currently in a massive expansion phase, due to the rising demand in chips fueled by AI, data centres, and high-performance computing.
B30: Rising Complexity of chips | D30: As chips move toward smaller nodes, manufacturing steps become more complex, requiring more advanced cleaning.
B31: Sustainability & ESG Pressures | D31: Push for greener manufacturing processes in semiconductors (reducing water, energy, and chemical usage) and increases demand for advanced, efficient equipment.
O32: Rivalry Among Existing Competitors | R32: 3.5
O33: Threat of New Entrants | R33: 2
O34: Threat of Substitutes | R34: 3
O35: Bargaining Power of Customers | R35: 4
O36: Bargaining Power of Suppliers | R36: 5

Sheet ESG
A7: x | B7: ESG Analysis
B12: ESG Scores | G12: GHG Scope 1 Emissions, Water Consumption, Energy Consumption and Waste Production per Sales
B15: LSEG ESG Score | D15: 52
B16: E-Score | D16: 34
B17: S-Score | D17: 46
B18: G-Score | D18: 85
B19: S&P Global ESG Score | D19: 32
B20: Environmental | D20: -
B21: Social | D21: -
B22: Governance & Economic | D22: -
B23: Sustainalytics | D23: 20.5
B24: ISS ESG Corporate Rating | D24: D
B25: SDG Impact Rating | D25: -7
B26: Governance Quality Score | D26: 9
B27: MSCI ESG Ratings | D27: -
B30: Key Info | G30: Environmental
H32: Overview | I32: Targets | J32: Improvements | K32: Comments
B33: GICS Sector | C33: Information Technology | G33: GHG Scope 1 Emissions | I33: Annual greenhouse gas emissions accounting is conducted across all facilities, with full coverage to be achieved in 2025. | J33: In 2024, ACM Research iniciated measures to reduce potencial climate risks associated with GHG emissions by procuring energy-efficient equipment and promoting energy conservation awareness among employess. | K33: Annual emissions surveys ensure timely compliance with regulatory requirements.
B34: GICS Industry Group | C34: Semiconductors & Semiconductor Equipment
B35: GICS Industry | C35: Semiconductor Equipment & Materials | G35: Water Consumption | I35: Long-term water resource management goals include achieving a 75% purification rate of the water system by 2030. | J35: In 2024, water management practices were enhanced through conservation signage and strengthened maintenance of water-related equipment, improving utilization efficiency. | K35: Improper water management or shortages have been identified as potencial operation risks, ongoing assessments are conducted to evaluate likelihood and impact.
B36: GICS Sub-Industry | C36: Semiconductor Equipment & Materials
G37: Energy Consumption | I37: Annual upgrades to production processes and equipment are implemented to reduce energy consmption and environmental pollution. | J37: In 2024, energy-saving measures such as awareness signage and optimized office air conditioning were introduced, contributing to reductions in consumption. | K37: Energy management strategies are in place to anticipate and address risks, impacts and opportunities associated with energy use.
B38: Headquarters | C38: Fremont, CA 94539 United States
B39: Numer of Employees | C39: 2023 | G39: Waste Management | I39: Strict compliance with hazardous and non-hazardous waste seperation requirements in maintained, with a zero-tolerance target to non-compliance incidents. | J39: A dedicated hazardous waste storage facility has been constructed in compliance with all appicable regulations and standards. | K39: N/A
B41: Annual Report | C41: 2024 | G41: Other
B42: Sustainability Report | C42: 2024
B44: Recent Headlines | G44: Social
H46: Overview | I46: Targets | J46: Improvements | K46: Comments
G47: Employee Turnover % | I47: Maintain a fair and supportive work environment by upholding employee rights and benefits, with the goal of improving employee retention and attractiong top talent. | J47: Extensive training programmes covering about 91.9% of employees, along with share-ownership incentives involving 4.4% of the workforce, serve as key retention mechanisms and provide a baseline for monitoring future improvements. | K47: The ESG Report highlights workplace practices and notes that over 75% of employees report being "Satisfeid" or "Very Satisfied". However, it doesn't look into the reasons behind staff turnover or set any goals for reducing it.
B48: ACM Research, Inc. (ACMR) Suffers a Larger Drop Than the General Market: Key Insights --Yahoo Finance -- 7/10/2025
G49: Salaries & Compensation | I49: Ensure competitive and fair salaries with comprehensive compensation benefits to attract and retain top talent. | J49: A performance-driven culture is promoted through ongoing feedback and quaterly assessments, culminating in an annual review that guides salary adjustments, position changes and year-end bonuses for all employees. | K49: Year-on-year salary increases and target salary levels are not included in the ESG or Annual Report.
B50: ACM Research (NASDAQ:ACMR) Receives Hold (C+) Rating from Weiss Ratings -- MarketBeat.com -- 8/10/25
G51: Reputation | I51: Maintain and communicate an externally verified reputation score. | J51: The report documents multiple awards and customer recognitions and outlines active stakeholder communication channels. | K51: N/A
B52: ACM Research’s Operating Subsidiary ACM Research (Shanghai) Provides Backlog Data -- Yahoo Finance -- 29/09/2025
G53: Discrimination Events | I53: Maintain a zero-tolerance policy toward any form of discrimination, ensuring an inclusive and equitable work environment for all employees. | J53: Discrimination or biased actions based on race, color, religion, gender, nationality or any other characteristic protected by local laws and regulations are strictly prohibited. | K53: The report provides gender breakdowns (total workforce: male 1,706; female 296) and indicates female representation in senior management (40%).
B54: ACM Research (NASDAQ:ACMR) Trading Down 3.8% - What's Next? -- MarketBeat.com -- 3/10/2025
G55: Work Safety | I55: Clear occupational health and safety targets are set, including maintaining ISO 45001 certification and achieving certification for newer facilities within 2 years. | J55: In 2024, safety management systems were further enhanced, with strengthened safety drills and awareness training to achieve occupational health and safety targets. | K55: N/A
G57: Damage to consumer health | I57: Maintain 100% third-party safety assessment before shipment for all product models. | J57: The report records zero major liability incidents related to product safety in 2024. | K57: N/A
G59: Pension Plan | I59: N/A | J59: Insurance coverage is detailed, showing 100% coverage for work injury and work safety liability insurance, along with the amounts invested. | K59: The company offers statutory and contribution-based pension plans only. No defined benefit or formal enhancement targets reported.
G61: Supply chain | I61: Implement regular audits to ensure compliance and foster long-term partnerships that align with ACM Research's sustainability goals. | J61: In 2024, the supllier base expanded to 1.154 in total (1.069 in Mainland China; 85 overseas), including 451 new suppliers. Supply-chain governance was stregthened by introducing transparent procurement, regular conferences and dedicated due-diligence channels. | K61: Supllier management and supply-chain security are highlighted, but the report lacks dislosure of supplier ESG KPIs or identification of major suppliers.
...

Sheet Segments
A7: x | B7: Segments | D7: =F7 -> 2020 | E7: =F7 -> 2020 | F7: 2020 | G7: =F7 -> 2020 | H7: =F7 -> 2020 | J7: =L7 -> 2021 | K7: =L7 -> 2021 | L7: 2021 | M7: =L7 -> 2021 | N7: =L7 -> 2021 | P7: =R7 -> 2022 | Q7: =R7 -> 2022 | R7: 2022 | S7: =R7 -> 2022 | T7: =R7 -> 2022 | V7: =X7 -> 2023 | W7: =X7 -> 2023 | X7: 2023 | Y7: =X7 -> 2023 | Z7: =X7 -> 2023 | AB7: =AD7 -> 2024 | AC7: =AD7 -> 2024 | AD7: 2024 | AE7: =AD7 -> 2024 | AF7: =AD7 -> 2024 | AH7: =AJ7 -> 2025 | AI7: =AJ7 -> 2025 | AJ7: 2025 | AK7: =AJ7 -> 2025 | AL7: =AJ7 -> 2025 | AN7: =AP7 -> 2025 | AO7: =AP7 -> 2025 | AP7: 2025 | AQ7: =AP7 -> 2025 | AR7: =AP7 -> 2025 | AZ7: Products
D8: 2020 | J8: =D8+1 -> 2021 | P8: =J8+1 -> 2022 | V8: =P8+1 -> 2023 | AB8: =V8+1 -> 2024 | AH8: =AB8+1 -> 2025 | AN8: =AH8+1 -> 2026 | AT8: =AN8+1 -> 2027 | AV8: =+AT8+1 -> 2028 | AX8: =+AV8+1 -> 2029
D9: Q1 | E9: Q2 | F9: Q3 | G9: Q4 | H9: FY | J9: Q1 | K9: Q2 | L9: Q3 | M9: Q4 | N9: FY | P9: Q1 | Q9: Q2 | R9: Q3 | S9: Q4 | T9: FY | V9: Q1 | W9: Q2 | X9: Q3 | Y9: Q4 | Z9: FY | AB9: Q1 | AC9: Q2 | AD9: Q3 | AE9: Q4 | AF9: FY | AH9: Q1 | AI9: Q2 | AJ9: Q3 | AK9: Q4 | AL9: FY | AN9: Q1 | AO9: Q2 | AP9: Q3 | AQ9: Q4 | AR9: FY | AT9: FY | AV9: FY | AX9: FY
B12: Revenue by segment:
B13: Single Wafer Cleaning,Tahoe and Semi- Critical Cleaning Equipment | H13: 131.248 | N13: 189.208 | T13: 272.939 | Z13: 403.851 | AF13: 578.887 | AL13: =FCFF!Z10 -> 681.09169 | AR13: =FCFF!AF10 -> 817.31002 | AT13: =FCFF!AH10 -> 967.15019 | AV13: =FCFF!AJ10 -> 1128.3419 | AX13: =FCFF!AL10 -> 1297.5932
B14: Electro-chemical plating (ECP) (front-end and packaging), Furnace and Other Technologies | H14: 13.343 | N14: 33.21 | T14: 77.482 | Z14: 103.356 | AF14: 151.057 | AL14: =FCFF!Z11 -> 211.00001 | AR14: =FCFF!AF11 -> 253.20001 | AT14: =FCFF!AH11 -> 299.62002 | AV14: =FCFF!AJ11 -> 349.55668 | AX14: =FCFF!AL11 -> 401.99019
B15: Advanced Packaging, Services & Spares | H15: 12.033 | N15: 37.333 | T15: 38.411 | Z15: 50.516 | AF15: 52.174 | AL15: =FCFF!Z12 -> 54.524902 | AR15: =FCFF!AF12 -> 65.429882 | AT15: =FCFF!AH12 -> 77.425361 | AV15: =FCFF!AJ12 -> 90.329587 | AX15: =FCFF!AL12 -> 103.87903
B18: Total revenue | D18: =IS!D18 -> 24.348 | E18: =IS!E18 -> 39.049 | F18: =IS!F18 -> 47.665 | G18: =IS!G18 -> 45.562 | H18: =IS!H18 -> 156.624 | J18: =IS!J18 -> 43.732 | K18: =IS!K18 -> 53.864 | L18: =IS!L18 -> 67.013 | M18: =IS!M18 -> 95.142 | N18: =IS!N18 -> 259.751 | P18: =IS!P18 -> 42.186 | Q18: =IS!Q18 -> 104.395 | R18: =IS!R18 -> 133.709 | S18: =IS!S18 -> 108.542 | T18: =IS!T18 -> 388.832 | V18: =IS!V18 -> 74.256 | W18: =IS!W18 -> 144.577 | X18: =IS!X18 -> 168.569 | Y18: =IS!Y18 -> 170.321 | Z18: =IS!Z18 -> 557.723 | AB18: =IS!AB18 -> 152.191 | AC18: =IS!AC18 -> 202.48 | AD18: =IS!AD18 -> 203.976 | AE18: =IS!AE18 -> 223.471 | AF18: =IS!AF18 -> 782.118 | AH18: =IS!AH18 -> 172.347 | AI18: =IS!AI18 -> 215.372 | AJ18: =IS!AJ18 -> 254.04267 | AK18: =IS!AK18 -> 304.85121 | AL18: =FCFF!Z31 -> 946.61288 | AN18: =IS!AN18 -> 206.8164 | AO18: =IS!AO18 -> 258.4464 | AP18: =IS!AP18 -> 304.85121 | AQ18: =IS!AQ18 -> 365.82145 | AR18: =FCFF!AF31 -> 1135.9355 | AT18: =FCFF!AH31 -> 1344.1903 | AV18: =FCFF!AJ31 -> 1568.222 | AX18: =FCFF!AL31 -> 1803.4553
B20: Revenue by region:
B21: Mainland China | H21: 154.359 | N21: 258.615 | T21: 377.752 | Z21: 540.969 | AF21: 775.752 | AL21: =AL26*98% -> 927.68062 | AN21: =AN26*98% -> 202.68007 | AO21: =AO26*98% -> 253.27747 | AP21: =AP26*98% -> 298.75418 | AQ21: =AQ26*98% -> 358.50502 | AR21: =AR26*98% -> 1113.2167 | AT21: =AT26*98% -> 1317.3065 | AV21: =AV26*98% -> 1536.8576 | AX21: =AX26*98% -> 1767.3862
B22: Other Regions | H22: 2.265 | N22: 1.136 | T22: 11.08 | Z22: 16.754 | AF22: 6.366 | AL22: =2%*AL26 -> 18.932258 | AN22: =2%*AN26 -> 4.136328 | AO22: =2%*AO26 -> 5.168928 | AP22: =2%*AP26 -> 6.0970241 | AQ22: =2%*AQ26 -> 7.316429 | AR22: =2%*AR26 -> 22.718709 | AT22: =2%*AT26 -> 26.883806 | AV22: =2%*AV26 -> 31.36444 | AX22: =2%*AX26 -> 36.069106
B26: Total revenue | D26: =IS!D18 -> 24.348 | E26: =IS!E18 -> 39.049 | F26: =IS!F18 -> 47.665 | G26: =IS!G18 -> 45.562 | H26: =IS!H18 -> 156.624 | J26: =IS!J18 -> 43.732 | K26: =IS!K18 -> 53.864 | L26: =IS!L18 -> 67.013 | M26: =IS!M18 -> 95.142 | N26: =IS!N18 -> 259.751 | P26: =IS!P18 -> 42.186 | Q26: =IS!Q18 -> 104.395 | R26: =IS!R18 -> 133.709 | S26: =IS!S18 -> 108.542 | T26: =IS!T18 -> 388.832 | V26: =IS!V18 -> 74.256 | W26: =IS!W18 -> 144.577 | X26: =IS!X18 -> 168.569 | Y26: =IS!Y18 -> 170.321 | Z26: =IS!Z18 -> 557.723 | AB26: =IS!AB18 -> 152.191 | AC26: =IS!AC18 -> 202.48 | AD26: =IS!AD18 -> 203.976 | AE26: =IS!AE18 -> 223.471 | AF26: =IS!AF18 -> 782.118 | AH26: =IS!AH18 -> 172.347 | AI26: =IS!AI18 -> 215.372 | AJ26: =IS!AJ18 -> 254.04267 | AK26: =IS!AK18 -> 304.85121 | AL26: =FCFF!Z31 -> 946.61288 | AN26: =IS!AN18 -> 206.8164 | AO26: =IS!AO18 -> 258.4464 | AP26: =IS!AP18 -> 304.85121 | AQ26: =IS!AQ18 -> 365.82145 | AR26: =FCFF!AF31 -> 1135.9355 | AT26: =FCFF!AH31 -> 1344.1903 | AV26: =FCFF!AJ31 -> 1568.222 | AX26: =FCFF!AL31 -> 1803.4553
B28: Products:
B29: Product 1
B30: Product 2
B31: Product 3
B32: Product 4
B33: Product 5
A35: x | B35: Notes & Forecasts
B40: Shift toward advanced wafer cleaning | H40: Growing microchip complexity and shrinking node sizes are increasing the need for advanced single-wafer cleaning systems. New processes like plasma and cryogenic cleaning are gaining traction as they reduce chemical waste and improve precision. This trend supports long-term growth in high-end cleaning equipment demand.
B41: China's expanding semiconductor self-sufficiency | H41: Mainland China remains one of the biggest investors in semiconductor manufacturing equipment, helped by strong government support and expanding local factories. Despite export restrictions from other countries, China continues to invest heavily in older but reliable chip technologies.
B42: Diversification beyond cleaning tools | H42: ACM Research is gradually expanding beyond its core cleaning business into electro-chemical planting (ECP), furnace, and advanced packaging equipment. These new segments are gaining traction, supported by growing demand for advanced interconnect and packaging technologies. The shift should help reduce dependence on traditional cleaning tools and provide higher-margin growth opportunities over the next few years.
B43: Expansion into other regions | H43: Although currently small, ACM's non-China revenue is expected to increase gradually as the company qualifies tools with international customers and builds service capabilities abroad. Successful expansion into overseas markets would help mitigate geographic concentration risk and improve long-term valuation potencial.

Sheet Peers
N6: on
B7: Peers
D11: TIER I | I11: TIER II | N11: TIER III
A12: x | B12: Growth | C12: ACM RESEARCH-A | D12: NAURA TECH GR -A | E12: LAM RESEARCH | F12: TOKYO ELECTRON | G12: APPLIED MATERIAL | H12: KINGSEMI CO LT-A | I12: SCREEN HOLDINGS | J12: SAMSUNG ELECTRON | K12: HIMAX TECHNO-ADR | L12: ENTEGRIS INC | M12: ONTO INNOVATION | N12: SK HYNIX INC | O12: TAIWAN SEMIC-ADR | P12: NVIDIA CORP | Q12: QUALCOMM INC | R12: ADV MICRO DEVICE
B14: Revenue (LTM) | C14: 0.17533425 | D14: 0.28825718 | E14: 0.2368409 | F14: 0.21678189 | G14: 0.065502346 | H14: 0.031571713 | I14: 0.16200785 | J14: 0.097540541 | K14: -0.02606187 | L14: -0.02606187 | M14: -0.018596879 | N14: 0.56855116 | O14: 0.39483946 | P14: 0.7155347 | Q14: 0.7155347 | R14: 0.15821463
B15: Revenue (3-yr CAGR) | C15: 0.38214284 | D15: 0.42944736 | E15: 0.022858305 | F15: 0.062015613 | G15: 0.043814535 | H15: 0.21677968 | I15: 0.13313386 | J15: 0.0033317187 | K15: -0.17742233 | L15: 0.080252437 | M15: 0.039031412 | N15: 0.15471249 | O15: 0.21891361 | P15: 0.77112223 | Q15: 0.0087507094 | R15: 0.11115231
B16: Gross profit (LTM) | C16: 0.17224414 | D16: 0.25586403 | E16: 0.25323779 | F16: 0.21916612 | G16: 0.088848808 | H16: 0.066816319 | I16: 0.16116396 | J16: 0.14164459 | K16: -0.034606507 | L16: -0.034606507 | M16: 0.020992182 | N16: 1.8546024 | O16: 0.53145785 | P16: 0.57690056 | Q16: 0.57690056 | R16: 0.15376509
B17: EBIT (LTM) | C17: 0.22008511 | D17: 0.20877056 | E17: 0.34093105 | F17: 0.25338468 | G17: 0.09764181 | H17: -0.22141708 | I17: 0.21920674 | J17: 0.2119973 | K17: -0.045584729 | L17: -0.045584729 | M17: 0.019486393 | N17: 3.5980277 | O17: 0.61840034 | P17: 0.60461058 | Q17: 0.60461058 | R17: 0.26977937
B18: EBITDA (LTM) | C18: 0.22068057 | D18: 0.22022173 | E18: 0.32088681 | F18: 0.24893117 | G18: 0.082874251 | H18: -0.084102483 | I18: 0.21153302 | J18: 0.17073199 | K18: -0.031391968 | L18: -0.031391968 | M18: 0.01832896 | N18: 1.2593119 | O18: 0.43307613 | P18: 0.59879178 | Q18: 0.59879178 | R18: 0.22398466
B19: FCF (LTM) | E19: 0.27222466 | F19: 0.3338495 | G19: -0.014090071 | I19: -0.14964746 | K19: -0.10535829 | L19: 0.83026952 | M19: 0.43087684 | O19: 1.7873594 | P19: 1.2520632 | Q19: 0.13321149 | R19: 1.1454059
A21: x | B21: Margins | C21: =C12 -> ACM RESEARCH-A | D21: =D12 -> NAURA TECH GR -A | E21: =E12 -> LAM RESEARCH | F21: =F12 -> TOKYO ELECTRON | G21: =G12 -> APPLIED MATERIAL | H21: =H12 -> KINGSEMI CO LT-A | I21: =I12 -> SCREEN HOLDINGS | J21: =J12 -> SAMSUNG ELECTRON | ... R21: =R12 -> ADV MICRO DEVICE
B23: Gross margin | C23: 0.5006329 | D23: 0.42854289 | E23: 0.48705024 | F23: 0.47141927 | G23: 0.47457315 | H23: 0.37674125 | I23: 0.37631483 | J23: 0.37992585 | K23: 0.30458799 | L23: 0.45869287 | M23: 0.52192549 | N23: 0.48083884 | O23: 0.56122352 | P23: 0.74988697 | Q23: 0.56213747 | R23: 0.49350398
B24: EBIT margin | C24: 0.19306294 | D24: 0.22063906 | E24: 0.32008564 | F24: 0.2867775 | G24: 0.28948337 | H24: 0.12628751 | I24: 0.2169994 | J24: 0.10877077 | K24: 0.07523252 | L24: 0.16472932 | M24: 0.18950574 | N24: 0.35452893 | O24: 0.4567667 | P24: 0.62417527 | Q24: 0.25848262 | R24: 0.073686252
B25: EBITDA margin | C25: 0.19772046 | D25: =1052.9/4114.4 -> 0.25590609 | E25: 0.34103843 | F25: 0.30608269 | G25: 0.31642959 | H25: =39.8/243.6 -> 0.16338259 | I25: 0.23210659 | J25: 0.23484276 | K25: 0.099470413 | L25: 0.27791021 | M25: 0.24012475 | N25: 0.58050798 | O25: 0.69350797 | P25: 0.59728964 | Q25: 0.31643433 | R25: 0.17827703
B26: Net margin | C26: 0.13249535 | D26: 0.18838984 | E26: 0.29064525 | F26: 0.22377865 | G26: 0.26409332 | H26: 0.11565426 | I26: 0.15907873 | J26: 0.09821447 | K26: 0.087951945 | L26: 0.090332678 | M26: 0.20425981 | N26: 0.29895336 | O26: 0.40537076 | P26: 0.55848027 | Q26: 0.26030491 | R26: 0.063641652
B27: SG&A margin | C27: 0.17271435 | D27: 0.099535053 | E27: 0.053250476 | F27: 0.081819632 | G27: 0.066124522 | H27: 0.1814637 | I27: 0.10860606 | J27: 0.14683642 | K27: 0.052548406 | L27: 0.13777795 | M27: 0.16408139 | N27: 0.050834077 | O27: 0.033475533 | P27: 0.026751573 | Q27: 0.070812587 | R27: 0.10793097
B28: R&D margin | C28: 0.14341496 | E28: 0.11371412 | F28: 0.10664186 | G28: 0.12270646 | H28: 0.17619823 | I28: 0.052763318 | J28: 0.12059922 | K28: 0.17648368 | L28: 0.10283479 | M28: 0.12205397 | N28: 0.073727014 | O28: 0.066988849 | P28: 0.093113341 | Q28: 0.20745775 | R28: 0.23547297
A30: x | B30: Returns | C30: =+C21 -> ACM RESEARCH-A | D30: =D21 -> NAURA TECH GR -A | E30: =E21 -> LAM RESEARCH | F30: =F21 -> TOKYO ELECTRON | G30: =G21 -> APPLIED MATERIAL | H30: =H21 -> KINGSEMI CO LT-A | I30: =I21 -> SCREEN HOLDINGS | J30: =J21 -> SAMSUNG ELECTRON | K30: =K21 -> HIMAX TECHNO-ADR | ... R30: =R21 -> ADV MICRO DEVICE
B32: ROIC | C32: 0.093969143 | D32: 0.13661976 | E32: 0.36742097 | G32: 0.25026919 | H32: 0.037240064 | I32: 0.23305939 | J32: 0.063682368 | K32: 0.04677638 | L32: 0.059044886 | M32: 0.090878512 | N32: 0.2672146 | O32: 0.25841889 | P32: 1.0268123 | Q32: 0.28951275 | R32: 0.04324939
B33: CROIC | C33: 0.053793367 | D33: -0.014716985 | E33: 0.35698561 | F33: 0.22111462 | G33: 0.31050929 | H33: 0.044838495 | I33: 0.11130795 | J33: 0.052296567 | K33: 0.08096272 | L33: 0.04001478 | M33: 0.11246363 | N33: 0.13869852 | O33: 0.17068653 | P33: 0.75701934 | Q33: 0.29568696 | R33: 0.040362507
B34: ROCE | C34: 0.11770327 | D34: 0.16396785 | E34: 0.55333883 | F34: 0.45359657 | G34: 0.47742444 | H34: 0.062094108 | I34: 0.39663998 | J34: 0.098340047 | K34: 0.12317328 | L34: 0.18223216 | M34: 0.12608359 | N34: 0.27066855 | O34: 0.24860964 | P34: 0.91328333 | Q34: 0.46605581 | R34: 0.11306832
B35: RONA | C35: 0.13778372 | D35: 0.20429491 | E35: 0.5983772 | F35: 0.37587086 | G35: 0.41403084 | H35: 0.07853762 | I35: 0.32252183 | J35: 0.081368986 | K35: 0.076111732 | L35: 0.14463536 | M35: 0.09715185 | N35: 0.31748759 | O35: 0.30577083 | P35: 1.0268005 | Q35: 0.38330669 | R35: 0.033004447
B36: ROE | C36: 0.12323899 | D36: 0.19888032 | E36: 0.58238093 | F36: 0.29389652 | G36: 0.35635301 | H36: 0.055096325 | I36: 0.24658314 | J36: 0.069935052 | K36: 0.086130426 | L36: 0.080838516 | M36: 0.10533705 | N36: 0.39267559 | O36: 0.34870793 | P36: 1.0941701 | Q36: 0.44634631 | R36: 0.04877671
B37: ROA | C37: 0.060488389 | D37: 0.08379492 | E37: 0.26730948 | F37: 0.21408956 | G37: 0.20136167 | H37: 0.027273066 | I37: 0.15409814 | J37: 0.061213637 | K37: 0.043843926 | L37: 0.03521071 | M37: 0.096425148 | N37: 0.24586254 | O37: 0.22477584 | P37: 0.76645705 | Q37: 0.21519846 | R37: 0.039718022
A39: x | B39: Efficiency | C39: ACM RESEARCH-A | D39: =D30 -> NAURA TECH GR -A | E39: =E30 -> LAM RESEARCH | F39: =F30 -> TOKYO ELECTRON | G39: =G30 -> APPLIED MATERIAL | H39: =H30 -> KINGSEMI CO LT-A | I39: =I30 -> SCREEN HOLDINGS | J39: =J30 -> SAMSUNG ELECTRON | K39: =K30 -> HIMAX TECHNO-ADR | ... R39: =R30 -> ADV MICRO DEVICE
B41: Asset turnover | C41: 0.43976382 | D41: 0.46610335 | E41: 0.91971048 | F41: 0.96948931 | G41: 0.84331987 | H41: 0.33836023 | I41: 0.98627122 | J41: 0.62302357 | K41: 0.52590068 | L41: 0.38402413 | M41: 0.49996744 | N41: 0.65792251 | O41: 0.52371605 | P41: 1.4623197 | Q41: 0.80401104 | R41: 0.4148389
B42: Net operating asset turnover | C42: 0.63958987 | D42: 0.66141513 | E42: 1.8077572 | F42: 1.1533071 | G42: 1.4823542 | H42: 0.70870011 | I42: 1.3408352 | J42: 0.78648784 | K42: 1.0376817 | L42: 0.81063639 | M42: 0.79010711 | N42: 0.82252709 | O42: 0.89799023 | P42: 2.2452642 | Q42: 1.4750511 | R42: 0.41765201
B43: Fixed asset turnover | C43: 2.9565154 | D43: 4.3901527 | E43: 7.5707084 | F43: 5.8148561 | G43: 7.0666831 | H43: 1.5648719 | I43: 5.7420797 | J43: 1.5449951 | K43: 7.1986097 | L43: 1.9414066 | M43: 7.4820449 | N43: 1.2599335 | O43: 1.0345164 | P43: 18.70463 | Q43: 9.362987 | R43: 13.366448
B44: Revenue per employee thsnd of USD | C44: 402.94909 | D44: 285.04789 | E44: 970.29426 | F44: 829.20078 | G44: 801.48459 | H44: 179.44499 | I44: 653.68633 | J44: #VALUE! | K44: 408.61782 | L44: 393.06476 | M44: 668.18375 | N44: #VALUE! | O44: 1266.3073 | P44: 4589.3889 | Q44: 882.79592 | R44: 1057.1429
B45: EBIT per employee thsnd of USD | C45: 71.994068 | D45: 57.307325 | E45: 312.82016 | F45: 231.14292 | G45: 241.20448 | H45: 17.231958 | I45: 137.96785 | J45: #VALUE! | K45: 29.237023 | L45: 63.087683 | M45: 159.55706 | N45: #VALUE! | O45: 616.90416 | P45: 2681.75 | Q45: 252.53061 | R45: 95.25
A47: x | B47: Working Capital | C47: ACM RESEARCH-A | D47: =D39 -> NAURA TECH GR -A | E47: =E39 -> LAM RESEARCH | F47: =F39 -> TOKYO ELECTRON | G47: =G39 -> APPLIED MATERIAL | H47: =H39 -> KINGSEMI CO LT-A | I47: =I39 -> SCREEN HOLDINGS | J47: =J39 -> SAMSUNG ELECTRON | K47: =K39 -> HIMAX TECHNO-ADR | ... R47: =R39 -> ADV MICRO DEVICE
B49: DSO | C49: 162.79737 | D49: 82.436898 | E49: 58.219583 | F49: 56.541621 | G49: 68.327124 | H49: 100.79116 | I49: 50.221513 | J49: 51.576144 | K49: 94.66187 | L49: 53.711647 | M49: 91.875006 | N49: 55.188518 | O49: 23.925655 | P49: 46.200051 | Q49: 27.265159 | R49: 66.798919
B50: DIO | C50: 553.55537 | D50: 485.1318 | E50: 164.08939 | F50: 215.34159 | G50: 140.49881 | H50: 636.6938 | I50: 167.01704 | J50: 99.037351 | K50: 99.870869 | L50: 137.6333 | M50: 213.78951 | N50: 137.24236 | O50: 74.710076 | P50: 79.046409 | Q50: 119.57691 | R50: 136.96956
B51: DPO | C51: 131.15285 | D51: 143.06845 | E51: 27.989828 | F51: 25.434942 | G51: 39.368105 | H51: 96.771231 | I51: 48.820485 | J51: 24.524046 | K51: 96.948928 | L51: 29.882593 | M51: 35.874324 | N51: 20.254174 | O51: 18.842625 | P51: 39.917529 | Q51: 46.858048 | R51: 50.597906
B52: CCC | C52: 565.09836 | D52: 387.87773 | E52: 194.31914 | F52: 251.72768 | G52: 172.01492 | H52: 595.8599 | I52: 154.91905 | J52: 127.00841 | K52: 133.95945 | L52: 150.07985 | M52: 290.80926 | N52: 174.86502 | O52: 89.204707 | P52: 87.976881 | Q52: 124.64536 | R52: 171.22044
B53: Working capital intensity | C53: 1.0621352 | D53: 0.77161558 | E53: 0.44732366 | F53: 0.428873 | G53: 0.44172229 | H53: 1.26046 | I53: 0.3499921 | J53: 0.42330918 | K53: 0.49321857 | L53: 0.36070951 | M53: 1.2425385 | N53: 0.20857268 | O53: 0.50428477 | P53: 0.37412994 | Q53: 0.35483274 | R53: 0.43827703
B54: Cash conversion ratio | C54: 1.009616 | D54: 0.22101468 | E54: 1.0461443 | F54: 0.83487471 | G54: 1.1029617 | H54: 1.9169258 | I54: 0.52500313 | J54: 2.2301139 | K54: 1.7000044 | L54: 1.183171 | M54: 1.3130522 | N54: 1.2696757 | O54: 1.427635 | P54: 0.78682185 | Q54: 1.2115977 | R54: 1.6005263
B55: CFO margin | C55: 0.19491944 | D55: 0.04876447 | E55: 0.33485577 | F55: 0.23942329 | G55: 0.31928908 | H55: 0.24208379 | I55: 0.11392537 | J55: 0.24257122 | K55: 0.12789562 | L55: 0.19490295 | M55: 0.24883093 | N55: 0.45013677 | O55: 0.65209615 | P55: 0.49111474 | Q55: 0.31317694 | R55: 0.11793678
A57: x | B57: Leverage & Coverage | C57: ACM RESEARCH-A | D57: =D47 -> NAURA TECH GR -A | E57: =E47 -> LAM RESEARCH | F57: =F47 -> TOKYO ELECTRON | G57: =G47 -> APPLIED MATERIAL | H57: =H47 -> KINGSEMI CO LT-A | I57: =I47 -> SCREEN HOLDINGS | J57: =J47 -> SAMSUNG ELECTRON | K57: =K47 -> HIMAX TECHNO-ADR | ... R57: =R47 -> ADV MICRO DEVICE
B59: Net debt / EBITDA | C59: -1.2833814 | D59: ='Trading Comps'!T15 -> -0.53024979 | E59: -0.2599078 | F59: ='Trading Comps'!T17 -> -0.86142492 | G59: -0.027833002 | H59: ='Trading Comps'!T19 -> 0.33248082 | I59: -1.1344257 | J59: -1.1963192 | K59: 2.3392665 | L59: 4.1076606 | M59: -3.5423461 | N59: 0.16525226 | O59: -0.6882496 | P59: -0.46809481 | Q59: 0.34899182 | R59: -0.37540269
...

Sheet Trading Comps
D7: Current | E7: % of | I7: Enterprise Value / | S7: LTM | T7: Net | V7: Price / | Z7: LT
D8: Share | E8: 52-week | F8: Equity | G8: Enterprise | I8: LTM | J8: 2025 | K8: 2026 | L8: LTM | M8: 2025E | N8: 2026E | O8: LTM | P8: 2025E | Q8: 2026E | S8: EBITDA | T8: Debt / | V8: LTM | W8: 2025E | X8: 2026E | Z8: EPS
B9: Company | C9: Ticker | D9: Price | E9: High | F9: Value | G9: Value | I9: Sales | J9: Sales | K9: Sales | L9: EBITDA | M9: EBITDA | N9: EBITDA | O9: EBIT | P9: EBIT | Q9: EBIT | S9: Margin | T9: EBITDA | V9: EPS | W9: EPS | X9: EPS | Z9: Growth
B11: ACM RESEARCH-A | C11: ACMR US | D11: USD 41,07 | E11: 0.91023936 | F11: 2411.3302 | G11: 1659.0665 | I11: 2.0352498 | J11: 1.8196506 | K11: 1.5585406 | L11: 10.293572 | M11: 9.4695574 | N11: 7.3605433 | O11: 11.391245 | P11: 9.986856 | Q11: 7.9906873 | S11: 0.19772046 | T11: 1.7829874 | V11: 22.304965 | W11: 18.033452 | X11: 15.237474 | Z11: 0.12620777
B12: Tier I: Wafer Cleaning, Electroplanting and PECVD equipment and Track system
B15: NAURA TECH GR -A | C15: 002371 CH | D15: CNY 458,05 | E15: 0.96704387 | F15: 317078.43 | G15: 246241.31 | I15: 7.318872 | J15: 6.3666721 | K15: 5.028357 | L15: 31.177 | M15: 26.536197 | N15: 20.194639 | O15: 36.404229 | P15: 30.166943 | Q15: 22.686216 | S15: 0.23475229 | T15: =+-558.3/1052.9 -> -0.53024979 | V15: 52.353312 | W15: 42.88882 | X15: 32.903184 | Z15: 0.23977321
B16: LAM RESEARCH | C16: LRCX US | D16: USD 141 | E16: 0.91740135 | F16: 169243.14 | G16: 121687.42 | I16: 6.6006793 | J16: 6.6634109 | K16: 6.0554512 | L16: 19.224347 | M16: 19.499719 | N16: 17.452231 | O16: 20.473749 | P16: 20.771272 | Q16: 18.76951 | S16: 0.34334999 | T16: 0.75654042 | V16: 31.838035 | W16: 32.665485 | X16: 29.848879 | Z16: 0.11251985
B17: TOKYO ELECTRON | C17: 8035 JT | D17: JPY 29700 | E17: 0.94225888 | F17: 13809406 | G17: 17860479 | I17: 7.361858 | J17: 7.3885397 | K17: 7.4411087 | L17: 24.05186 | M17: 23.573634 | N17: 25.557035 | O17: 26.409887 | P17: 25.834296 | Q17: 29.047342 | S17: 0.30608269 | T17: =+-3034.8/3523 -> -0.86142492 | V17: 25.718894 | W17: 25.948484 | X17: 28.886836 | Z17: 0.051737427
B18: APPLIED MATERIAL | C18: AMAT US | D18: USD 220,3 | E18: 0.97266988 | F18: 170075.19 | G18: 147742.93 | I18: 5.1634897 | J18: 5.2298901 | K18: 5.0800179 | L18: 16.33963 | M18: 16.502926 | N18: 16.277124 | O18: 17.157465 | P18: 17.325197 | Q18: 17.22501 | S18: 0.31601021 | T18: 0.74685222 | V18: 22.058298 | W18: 22.470919 | X18: 22.584847 | Z18: 0.040295709
B19: KINGSEMI CO LT-A | C19: 688037 CH | D19: CNY 150,1 | E19: 0.94473817 | F19: 29945.686 | G19: 22227.609 | I19: 12.564227 | J19: 10.670494 | K19: 8.1705498 | L19: 90.537005 | M19: 112.54486 | N19: 79.384319 | O19: 130.83757 | P19: 82.446622 | Q19: 51.860965 | S19: 0.13877449 | T19: =13/39.1 -> 0.33248082 | V19: 245.2583 | W19: 118.83209 | X19: 75.735169 | Z19: -0.6931
B21: Mean | I21: =AVERAGE(I15:I19) -> 7.8018252 | K21: =AVERAGE(K15:K19) -> 6.3550969 | L21: =AVERAGE(L15:L19) -> 36.265968 | M21: =AVERAGE(M15:M19) -> 39.731467 | N21: =AVERAGE(N15:N19) -> 31.77307 | O21: =AVERAGE(O15:O19) -> 46.25658 | P21: =AVERAGE(P15:P19) -> 35.308866 | Q21: =AVERAGE(Q15:Q19) -> 27.917808 | S21: =AVERAGE(S15:S19) -> 0.26779393 | T21: =AVERAGE(T15:T19) -> 0.088839751 | V21: =AVERAGE(V15:V19) -> 75.445369 | W21: =AVERAGE(W15:W19) -> 48.561159 | X21: =AVERAGE(X15:X19) -> 37.991783 | Z21: =AVERAGE(Z15:Z19) -> -0.049754761
B22: Median | I22: =MEDIAN(I15:I19) -> 7.318872 | J22: =MEDIAN(J15:J19) -> 6.6634109 | K22: =MEDIAN(K15:K19) -> 6.0554512 | L22: =MEDIAN(L15:L19) -> 24.05186 | M22: =MEDIAN(M15:M19) -> 23.573634 | N22: =MEDIAN(N15:N19) -> 20.194639 | O22: =MEDIAN(O15:O19) -> 26.409887 | P22: =MEDIAN(P15:P19) -> 25.834296 | Q22: =MEDIAN(Q15:Q19) -> 22.686216 | S22: =MEDIAN(S15:S19) -> 0.30608269 | T22: =MEDIAN(T15:T19) -> 0.33248082 | V22: =MEDIAN(V15:V19) -> 31.838035 | W22: =MEDIAN(W15:W19) -> 32.665485 | X22: =MEDIAN(X15:X19) -> 29.848879 | Z22: =MEDIAN(Z15:Z19) -> 0.051737427
B24: Tier II: Related to Wafer
B27: SCREEN HOLDINGS | C27: 7735 JT | D27: JPY 14295 | E27: 0.92106959 | F27: 1318628.3 | G27: 945983.95 | I27: 1.5091387 | J27: 1.5312018 | K27: 1.5030303 | L27: 6.5019207 | M27: 6.7231961 | N27: 6.8134051 | O27: 7.1502403 | P27: 7.3664877 | Q27: 7.6722613 | S27: 0.23210659 | T27: 0.030943069 | V27: 13.510964 | W27: 14.289076 | X27: 14.51873 | Z27: 0.052579814
B28: SAMSUNG ELECTRON | C28: 005930 KS | D28: KRW 89000 | E28: 0.94179894 | F28: 5.5881382e+08 | G28: 2.7571821e+08 | I28: 0.89346641 | J28: 0.89346641 | K28: 0.78169168 | L28: 3.8045303 | M28: 3.5398446 | N28: 2.7590312 | O28: 10.197659 | P28: 8.7103889 | Q28: 5.1807098 | S28: 0.23484276 | T28: 0.1935901 | V28: 20.964264 | W28: 17.61825 | X28: 12.133603 | Z28: 0.20293984
B29: HIMAX TECHNO-ADR | C29: HIMX US | D29: USD 8,94 | E29: 0.64270309 | F29: 1471.0218 | G29: 1775.5605 | I29: 1.9959964 | J29: 2.1580802 | K29: 1.905619 | L29: 20.819386 | M29: 23.099226 | N29: 16.734783 | O29: 27.896126 | P29: 32.489671 | Q29: 18.939312 | S29: 0.095872009 | T29: 6.0600554 | V29: 20.905307 | W29: 29.34219 | X29: 15.649168 | Z29: 0.3989
B30: ENTEGRIS INC | C30: ENTG US | D30: USD 94,23 | E30: 0.83864365 | F30: 13363.54 | G30: 16151.732 | I30: 5.0111932 | J30: 5.0433448 | K30: 4.654566 | L30: 17.97761 | M30: 18.061304 | N30: 15.887423 | O30: 31.221996 | P30: 23.374431 | Q30: 19.811446 | S30: 0.27874635 | T30: 4.5283179 | V30: 44.427918 | W30: 31.423459 | X30: 24.94467 | Z30: 0.19185015
B31: ONTO INNOVATION | C31: ONTO US | D31: USD 136,6 | E31: 0.59802119 | F31: 6244.5252 | G31: 3957.3636 | I31: 3.8185479 | J31: 3.9682763 | K31: 3.5849743 | L31: 12.957374 | M31: 13.369471 | N31: 11.27454 | O31: 15.991092 | P31: 15.748462 | Q31: 13.337287 | S31: 0.29470074 | T31: 0.053883 | V31: 26.874971 | W31: 25.821607 | X31: 22.026544 | Z31: 0.24970818
B33: Mean | I33: =AVERAGE(I27:I31) -> 2.6456685 | J33: =AVERAGE(J27:J31) -> 2.7188739 | K33: =AVERAGE(K27:K31) -> 2.4859763 | L33: =AVERAGE(L27:L31) -> 12.412164 | M33: =AVERAGE(M27:M31) -> 12.958609 | N33: =AVERAGE(N27:N31) -> 10.693837 | O33: =AVERAGE(O27:O31) -> 18.491423 | P33: =AVERAGE(P27:P31) -> 17.537888 | Q33: =AVERAGE(Q27:Q31) -> 12.988203 | S33: =AVERAGE(S27:S31) -> 0.22725369 | T33: =AVERAGE(T27:T31) -> 2.1733579 | V33: =AVERAGE(V27:V31) -> 25.336685 | W33: =AVERAGE(W27:W31) -> 23.698916 | X33: =AVERAGE(X27:X31) -> 17.854543 | Z33: =AVERAGE(Z27:Z31) -> 0.2191956
B34: Median | I34: =MEDIAN(I27:I31) -> 1.9959964 | J34: =MEDIAN(J27:J31) -> 2.1580802 | K34: =MEDIAN(K27:K31) -> 1.905619 | L34: =MEDIAN(L27:L31) -> 12.957374 | M34: =MEDIAN(M27:M31) -> 13.369471 | N34: =MEDIAN(N27:N31) -> 11.27454 | O34: =MEDIAN(O27:O31) -> 15.991092 | P34: =MEDIAN(P27:P31) -> 15.748462 | Q34: =MEDIAN(Q27:Q31) -> 13.337287 | S34: =MEDIAN(S27:S31) -> 0.23484276 | T34: =MEDIAN(T27:T31) -> 0.1935901 | V34: =MEDIAN(V27:V31) -> 20.964264 | W34: =MEDIAN(W27:W31) -> 25.821607 | X34: =MEDIAN(X27:X31) -> 15.649168 | Z34: =MEDIAN(Z27:Z31) -> 0.20293984
B36: Tier III: Semiconductors Industry
B39: SK HYNIX INC | C39: 000660 KS | D39: KRW 395500 | E39: 0.97775031 | F39: 2.8792494e+14 | G39: 2.0902255e+08 | I39: 2.7071534 | J39: 2.3402536 | K39: 1.8978659 | L39: 4.6634215 | M39: 3.9082272 | N39: 3.0506407 | O39: 6.580049 | P39: 5.3375498 | Q39: 4.0600281 | S39: 0.58050798 | T39: 0.54369117 | V39: 11.811781 | W39: 9.6664487 | X39: 7.6743818 | Z39: 0.40193663
B40: TAIWAN SEMIC-ADR | C40: TSM US | D40: USD 292,19 | E40: 0.95082981 | F40: 1.5793553e+12 | G40: 25900715 | I40: 7.6151723 | J40: 6.9958919 | K40: 5.9399039 | L40: 10.980656 | M40: 10.252473 | N40: 8.8403122 | O40: 15.631517 | P40: 14.549916 | Q40: 12.491881 | S40: 0.69350797 | T40: 0.42787285 | V40: 1.0614112 | W40: 0.99627027 | X40: 0.85305053 | Z40: 0.1545171
B41: NVIDIA CORP | C41: NVDA US | D41: USD 187,62 | E41: 0.98204658 | F41: 4513239000000 | G41: 4178011.5 | I41: 25.287871 | J41: 32.235625 | K41: 20.243348 | L41: 42.097955 | M41: 47.634476 | N41: 32.215379 | O41: 43.276172 | P41: 48.649495 | Q41: 32.18802 | S41: 0.60069121 | T41: 0.10739438 | V41: 55.520693 | W41: 63.940457 | X41: 42.379469 | Z41: 0.35454655
B42: QUALCOMM INC | C42: QCOM US | D42: USD 169,18 | E42: 0.92904997 | F42: 182761020000 | G42: 176634.36 | I42: 4.0833706 | J42: 4.0456996 | K42: 3.9613941 | L42: 12.577212 | M42: 10.4571 | N42: 11.112651 | O42: 14.274637 | P42: 11.596364 | Q42: 11.897032 | S42: 0.32466422 | T42: 1.0803624 | V42: 16.275368 | W42: 13.578253 | X42: 13.677148 | Z42: 0.024015069
B43: ADV MICRO DEVICE | C43: AMD US | D43: USD 164,67 | E43: 0.72634964 | F43: 3.372756e+11 | G43: 231278.82 | I43: 7.8134736 | J43: 7.0102586 | K43: 5.5877151 | L43: 40.73962 | M43: 31.849628 | N43: 20.377826 | O43: 86.718718 | P43: 32.337077 | Q43: 20.95217 | S43: 0.19179054 | T43: 0.73640326 | V43: 126.54692 | W43: 59.018161 | X43: 37.26666 | Z43: 0.35890074
B45: Mean | I45: =AVERAGE(I39:I43) -> 9.5014082 | J45: =AVERAGE(J39:J43) -> 10.525546 | K45: =AVERAGE(K39:K43) -> 7.5260455 | L45: =AVERAGE(L39:L43) -> 22.211773 | M45: =AVERAGE(M39:M43) -> 20.820381 | N45: =AVERAGE(N39:N43) -> 15.119362 | O45: =AVERAGE(O39:O43) -> 33.296219 | P45: =AVERAGE(P39:P43) -> 22.49408 | Q45: =AVERAGE(Q39:Q43) -> 16.317826 | S45: =AVERAGE(S39:S43) -> 0.47823238 | T45: =AVERAGE(T39:T43) -> 0.5791448 | V45: =AVERAGE(V39:V43) -> 42.243234 | W45: =AVERAGE(W39:W43) -> 29.439918 | X45: =AVERAGE(X39:X43) -> 20.370142 | Z45: =AVERAGE(Z39:Z43) -> 0.25878322
B46: Median | I46: =MEDIAN(I39:I43) -> 7.6151723 | J46: =MEDIAN(J39:J43) -> 6.9958919 | K46: =MEDIAN(K39:K43) -> 5.5877151 | L46: =MEDIAN(L39:L43) -> 12.577212 | M46: =MEDIAN(M39:M43) -> 10.4571 | N46: =MEDIAN(N39:N43) -> 11.112651 | O46: =MEDIAN(O39:O43) -> 15.631517 | P46: =MEDIAN(P39:P43) -> 14.549916 | Q46: =MEDIAN(Q39:Q43) -> 12.491881 | S46: =MEDIAN(S39:S43) -> 0.58050798 | T46: =MEDIAN(T39:T43) -> 0.54369117 | V46: =MEDIAN(V39:V43) -> 16.275368 | W46: =MEDIAN(W39:W43) -> 13.578253 | X46: =MEDIAN(X39:X43) -> 13.677148 | Z46: =MEDIAN(Z39:Z43) -> 0.35454655
B48: Overall
B51: Mean | I51: =AVERAGE(I39:I43,I27:I32,I15:I19) -> 6.649634 | J51: =AVERAGE(J39:J43,J27:J32,J15:J19) -> 6.8360737 | K51: =AVERAGE(K39:K43,K27:K32,K15:K19) -> 5.4557062 | L51: =AVERAGE(L39:L43,L27:L32,L15:L19) -> 23.629968 | M51: =AVERAGE(M39:M43,M27:M32,M15:M19) -> 24.503485 | N51: =AVERAGE(N39:N43,N27:N32,N15:N19) -> 19.195423 | O51: =AVERAGE(O39:O43,O27:O32,O15:O19) -> 32.681407 | P51: =AVERAGE(P39:P43,P27:P32,P15:P19) -> 25.113612 | Q51: =AVERAGE(Q39:Q43,Q27:Q32,Q15:Q19) -> 19.074613 | S51: =AVERAGE(S39:S43,S27:S32,S15:S19) -> 0.32442667 | T51: =AVERAGE(T39:T43,T27:T32,T15:T19) -> 0.94711415 | V51: =AVERAGE(V39:V43,V27:V32,V15:V19) -> 47.675096 | W51: =AVERAGE(W39:W43,W27:W32,W15:W19) -> 33.899998 | X51: =AVERAGE(X39:X43,X27:X32,X15:X19) -> 25.405489 | Z51: =AVERAGE(Z39:Z43,Z27:Z32,Z15:Z19) -> 0.14274135
B52: Median | I52: =MEDIAN(I39:I43,I27:I31,I15:I19) -> 5.1634897 | J52: =MEDIAN(J39:J43,J27:J31,J15:J19) -> 5.2298901 | K52: =MEDIAN(K39:K43,K27:K31,K15:K19) -> 5.028357 | L52: =MEDIAN(L39:L43,L27:L31,L15:L19) -> 17.97761 | M52: =MEDIAN(M39:M43,M27:M31,M15:M19) -> 18.061304 | N52: =MEDIAN(N39:N43,N27:N31,N15:N19) -> 16.277124 | O52: =MEDIAN(O39:O43,O27:O31,O15:O19) -> 20.473749 | P52: =MEDIAN(P39:P43,P27:P31,P15:P19) -> 20.771272 | Q52: =MEDIAN(Q39:Q43,Q27:Q31,Q15:Q19) -> 18.76951 | S52: =MEDIAN(S39:S43,S27:S31,S15:S19) -> 0.29470074 | T52: =MEDIAN(T39:T43,T27:T31,T15:T19) -> 0.42787285 | V52: =MEDIAN(V39:V43,V27:V31,V15:V19) -> 25.718894 | W52: =MEDIAN(W39:W43,W27:W31,W15:W19) -> 25.948484 | X52: =MEDIAN(X39:X43,X27:X31,X15:X19) -> 22.584847 | Z52: =MEDIAN(Z39:Z43,Z27:Z31,Z15:Z19) -> 0.19185015
B54: High | I54: =MAX(I39:I43,I27:I31,I15:I19) -> 25.287871 | J54: =MAX(J39:J43,J27:J31,J15:J19) -> 32.235625 | K54: =MAX(K39:K43,K27:K31,K15:K19) -> 20.243348 | L54: =MAX(L39:L43,L27:L31,L15:L19) -> 90.537005 | M54: =MAX(M39:M43,M27:M31,M15:M19) -> 112.54486 | N54: =MAX(N39:N43,N27:N31,N15:N19) -> 79.384319 | O54: =MAX(O39:O43,O27:O31,O15:O19) -> 130.83757 | P54: =MAX(P39:P43,P27:P31,P15:P19) -> 82.446622 | ... T54: =MAX(T39:T43,T27:T31,T15:T19) -> 6.0600554 | V54: =MAX(V39:V43,V27:V31,V15:V19) -> 245.2583 | W54: =MAX(W39:W43,W27:W31,W15:W19) -> 118.83209 | X54: =MAX(X39:X43,X27:X31,X15:X19) -> 75.735169 | Z54: =MAX(Z39:Z43,Z27:Z31,Z15:Z19) -> 0.40193663
B55: Low | I55: =MIN(I39:I43,I27:I31,I15:I19) -> 0.89346641 | J55: =MIN(J39:J43,J27:J31,J15:J19) -> 0.89346641 | K55: =MIN(K39:K43,K27:K31,K15:K19) -> 0.78169168 | L55: =MIN(L39:L43,L27:L31,L15:L19) -> 3.8045303 | M55: =MIN(M39:M43,M27:M31,M15:M19) -> 3.5398446 | N55: =MIN(N39:N43,N27:N31,N15:N19) -> 2.7590312 | O55: =MIN(O39:O43,O27:O31,O15:O19) -> 6.580049 | P55: =MIN(P39:P43,P27:P31,P15:P19) -> 5.3375498 | ... T55: =MIN(T39:T43,T27:T31,T15:T19) -> -0.86142492 | V55: =MIN(V39:V43,V27:V31,V15:V19) -> 1.0614112 | W55: =MIN(W39:W43,W27:W31,W15:W19) -> 0.99627027 | X55: =MIN(X39:X43,X27:X31,X15:X19) -> 0.85305053 | Z55: =MIN(Z39:Z43,Z27:Z31,Z15:Z19) -> -0.6931

Sheet WACC
A7: x | B7: Rolling WACC | K7: Equity Risk Premium
P8: Weights
D9: 2025 | E9: =+D9+1 -> 2026 | F9: =+E9+1 -> 2027 | G9: =+F9+1 -> 2028 | H9: =+G9+1 -> 2029 | M9: ERP | N9: 2025 | O9: =+N9+1 -> 2026 | P9: =+O9+1 -> 2027 | Q9: =+P9+1 -> 2028 | R9: =+Q9+1 -> 2029
B12: Equity: | K12: =+Segments!B21 -> Mainland China | M12: 0.0527 | N12: =+Segments!AL21/Segments!AL$26 -> 0.98 | O12: =+Segments!AN21/Segments!AN$26 -> 0.98 | P12: =+Segments!AP21/Segments!AP$26 -> 0.98 | Q12: =+Segments!AR21/Segments!AR$26 -> 0.98 | R12: =+Segments!AT21/Segments!AT$26 -> 0.98
B13: Market Cap (in billions) | D13: =+Inputs!J13 -> 16770.325 | E13: =+FCFF!AF99*FCFF!AF31 -> 4543.7418 | F13: =+FCFF!AH99*FCFF!AH31 -> 4704.666 | G13: =+FCFF!AJ99*FCFF!AJ31 -> 5488.777 | H13: =+FCFF!AL99*FCFF!AL31 -> 6312.0936 | K13: Korea and United States | M13: =(0.0433+0.0499)/2 -> 0.0466 | N13: =+Segments!AL22/Segments!AL$26 -> 0.02 | O13: =+Segments!AN22/Segments!AN$26 -> 0.02 | P13: =+Segments!AP22/Segments!AP$26 -> 0.02 | Q13: =+Segments!AR22/Segments!AR$26 -> 0.02 | R13: =+Segments!AT22/Segments!AT$26 -> 0.02
B14: % of Equity | D14: =IFERROR(D13/D35,"") -> 0.98315289 | E14: =IFERROR(E13/E35,"") -> 0.94051621 | F14: =IFERROR(E13/F35,"") -> 0.91019758 | G14: =IFERROR(F13/G35,"") -> 0.81449858 | H14: =IFERROR(G13/H35,"") -> 0.8317001 | N14: =+Segments!AL23/Segments!AL$26 -> 0 | O14: =+Segments!AN23/Segments!AN$26 -> 0 | P14: =+Segments!AP23/Segments!AP$26 -> 0 | Q14: =+Segments!AR23/Segments!AR$26 -> 0 | R14: =+Segments!AT23/Segments!AT$26 -> 0
B15: Risk-Free Rate | D15: 0.0159 | E15: 0.0159 | F15: 0.0159 | G15: 0.0159 | H15: 0.0159
B16: Beta | D16: =+Inputs!M18 -> 1.42 | E16: =+D17*(1+(E28/E13)*(1-E32)) -> 1.4753542 | F16: =+E17*(1+(F28/F13)*(1-F32)) -> 1.4727797 | G16: =+F17*(1+(G28/G13)*(1-G32)) -> 1.462395 | H16: =+G17*(1+(H28/H13)*(1-H32)) -> 1.4542679
B17: Unlevered Beta | D17: =+D16/(1+(D28/D13)*(1-D32)) -> 1.400087 | E17: =+E16/(1+(E28/E13)*(1-E32)) -> 1.400087 | F17: =+F16/(1+(F28/F13)*(1-F32)) -> 1.400087 | G17: =+G16/(1+(G28/G13)*(1-G32)) -> 1.400087 | H17: =+H16/(1+(H28/H13)*(1-H32)) -> 1.400087
B18: Equity Risk Premium | D18: =+N18 -> 0.052578 | E18: =+O18 -> 0.052578 | F18: =+P18 -> 0.052578 | G18: =+Q18 -> 0.052578 | H18: =+R18 -> 0.052578 | K18: ERP | N18: =+SUMPRODUCT($M12:$M16,N12:N16) -> 0.052578 | O18: =+SUMPRODUCT($M12:$M16,O12:O16) -> 0.052578 | P18: =+SUMPRODUCT($M12:$M16,P12:P16) -> 0.052578 | Q18: =+SUMPRODUCT($M12:$M16,Q12:Q16) -> 0.052578 | R18: =+SUMPRODUCT($M12:$M16,R12:R16) -> 0.052578
B19: Ke (Cost of Equity) | D19: =IFERROR(+D15+D16*D18,"") -> 0.09056076 | E19: =IFERROR(+E15+E16*E18,"") -> 0.093471175 | F19: =IFERROR(+F15+F16*F18,"") -> 0.093335812 | G19: =IFERROR(+G15+G16*G18,"") -> 0.092789806 | H19: =IFERROR(+H15+H16*H18,"") -> 0.092362497
B21: Preferred Equity: | K21: ROIC vs WACC
B22: Market Capitalization | D22: =IFERROR(Inputs!J14,0) -> 0 | E22: =+D22*(E13/D13) -> 0 | F22: =+E22*(F13/E13) -> 0 | G22: =+F22*(G13/F13) -> 0 | H22: =+G22*(H13/G13) -> 0
B23: % of Preferred Equity | D23: =+D22/D35 -> 0 | E23: =+E22/E35 -> 0 | F23: =+F22/F35 -> 0 | G23: =+G22/G35 -> 0 | H23: =+H22/H35 -> 0
B24: Preferred Dividends | D24: =+IS!AF50 -> 0 | E24: =D24 -> 0 | F24: =E24 -> 0 | G24: =F24 -> 0 | H24: =G24 -> 0
B25: Kp (Cost of Preferred Equity) | D25: =IFERROR(D24/D22,0) -> 0 | E25: =IFERROR(E24/E22,0) -> 0 | F25: =IFERROR(F24/F22,0) -> 0 | G25: =IFERROR(G24/G22,0) -> 0 | H25: =IFERROR(H24/H22,0) -> 0
B27: Debt:
B28: Debt (in millions) | C28: =+BS!AF38+BS!AF39+BS!AF44+BS!AF45 -> 188.783 | D28: =+BS!AI38+BS!AI39+BS!AI44+BS!AI45 -> 287.373 | E28: 287.373 | F28: 287.373 | G28: 287.373 | H28: 287.373
B29: % of Debt | D29: =IFERROR(D28/D35,"") -> 0.016847115 | E29: =IFERROR(E28/E35,"") -> 0.059483786 | F29: =IFERROR(F28/F35,"") -> 0.057566257 | G29: =IFERROR(G28/G35,"") -> 0.049751651 | H29: =IFERROR(H28/H35,"") -> 0.043544883
B30: Debt Spread | D30: =+D31-D15 -> -0.0159 | E30: =E31-E15 -> 0.0111 | F30: =F31-F15 -> 0.0111 | G30: =G31-G15 -> 0.0111 | H30: =H31-H15 -> 0.0111
B31: Cost of Debt | D31: =+IS!AI39/WACC!D28 -> 0 | E31: 0.027 | F31: 0.027 | G31: 0.027 | H31: 0.027
B32: Tax Rate | D32: =+FCFF!Z124 -> 0.17 | E32: =+FCFF!AF124 -> 0.15 | F32: =+FCFF!AH124 -> 0.15 | G32: =+FCFF!AJ124 -> 0.15 | H32: =+FCFF!AL124 -> 0.15
B33: Kd (After-Tax Cost of Debt) | D33: =+D31*(1-D32) -> 0 | E33: =+E31*(1-E32) -> 0.02295 | F33: =+F31*(1-F32) -> 0.02295 | G33: =+G31*(1-G32) -> 0.02295 | H33: =+H31*(1-H32) -> 0.02295
B35: Total | D35: =+D13+D24+D28 -> 17057.698 | E35: =+E13+E24+E28 -> 4831.1148 | F35: =+F13+F24+F28 -> 4992.039 | G35: =+G13+G24+G28 -> 5776.15 | H35: =+H13+H24+H28 -> 6599.4666
B37: Country/Conglomerate/... Risk Premium
A39: x | B39: WACC | D39: =+D19*D14+D25*D23+D33*D29+D37 -> 0.089035072 | E39: =+E19*E14+E25*E23+E33*E29+E37 -> 0.089276309 | F39: =+F19*F14+F25*F23+F33*F29+F37 -> 0.086275175 | G39: =+G19*G14+G25*G23+G33*G29+G37 -> 0.076718966 | H39: =+H19*H14+H25*H23+H33*H29+H37 -> 0.077817253
B41: NOPAT | D41: =+FCFF!Z126 -> 139.29388 | E41: =+FCFF!AF126 -> 164.14267 | F41: =+FCFF!AH126 -> 194.2355 | G41: =+FCFF!AJ126 -> 226.60808 | H41: =+FCFF!AL126 -> 260.59929
B42: Total Payout | D42: =+FCFF!Z112+FCFF!Z115 -> 20.757556 | E42: =+FCFF!AF112+FCFF!AF115 -> 14.202622 | F42: =+FCFF!AH112+FCFF!AH115 -> 0.93317134 | G42: =+FCFF!AJ112+FCFF!AJ115 -> -3.487198 | H42: =+FCFF!AL112+FCFF!AL115 -> 2.096516
B43: Book Value of Equity | C43: =+BS!AF54 -> 1095.906 | D43: =+C43+D41+D42 -> 1255.9574 | E43: =+D43+E41+E42 -> 1434.3027 | F43: =+E43+F41+F42 -> 1629.4714 | G43: =+F43+G41+G42 -> 1852.5923 | H43: =+G43+H41+H42 -> 2115.2881
B44: Invested Capital | C44: =+C43+C28 -> 1284.689 | D44: =+D43+D28 -> 1543.3304 | E44: =+E43+E28 -> 1721.6757 | F44: =+F43+F28 -> 1916.8444 | G44: =+G43+G28 -> 2139.9653 | H44: =+H43+H28 -> 2402.6611
A45: x | B45: ROIC | D45: =+D41/((D44+C44)/2) -> 0.098509846 | E45: =+E41/((E44+D44)/2) -> 0.10054662 | F45: =+F41/((F44+E44)/2) -> 0.10676621 | G45: =+G41/((G44+F44)/2) -> 0.11171738 | H45: =+H41/((H44+G44)/2) -> 0.11473508
W49: ,

Sheet FCFF
A7: x | B7: Market Assumptions
D8: 2022 | J8: =D8+1 -> 2023 | P8: =J8+1 -> 2024 | V8: =P8+1 -> 2025 | AB8: =V8+1 -> 2026 | AH8: =AB8+1 -> 2027 | AJ8: =+AH8+1 -> 2028 | AL8: =+AJ8+1 -> 2029
D9: Q1 | E9: Q2 | F9: Q3 | G9: Q4 | H9: FY | J9: Q1 | K9: Q2 | L9: Q3 | M9: Q4 | N9: FY | P9: Q1 | Q9: Q2 | R9: Q3 | S9: Q4 | T9: FY | V9: Q1 | W9: Q2 | X9: Q3 | Y9: Q4 | Z9: FY | AB9: Q1 | AC9: Q2 | AD9: Q3 | AE9: Q4 | AF9: FY | AH9: FY | AJ9: FY | AL9: FY
B10: Single Wafer Cleaning,Tahoe and Semi- Critical Cleaning Equipment | D10: 26.033 | E10: 72.583 | F10: 99.72 | G10: 74.603 | H10: =Segments!T13 -> 272.939 | J10: 36.614 | K10: 112.528 | L10: 132.417 | M10: 122.292 | N10: =Segments!Z13 -> 403.851 | P10: 109.47 | Q10: 153.221 | R10: 160.985 | S10: 155.211 | T10: =Segments!AF13 -> 578.887 | V10: 129.569 | W10: 154.961 | Z10: =Z31*W13 -> 681.09169 | AF10: =AF$31*W13 -> 817.31002 | AH10: =AH$31*W13 -> 967.15019 | AJ10: =AJ$31*W13 -> 1128.3419 | AL10: =AL$31*W13 -> 1297.5932
B11: ECP, Furnace & Other Technologies | D11: 12.248 | E11: 20.5 | F11: 24.521 | G11: 20.213 | H11: =Segments!T14 -> 77.482 | J11: 26.598 | K11: 19.117 | L11: 25.508 | M11: 32.133 | N11: =Segments!Z14 -> 103.356 | P11: 25.8 | Q11: 38.962 | R11: 34.6 | S11: 51.695 | T11: =Segments!AF14 -> 151.057 | V11: 27.63 | W11: 48.016 | Z11: =Z$31*W14 -> 211.00001 | AF11: =AF$31*W14 -> 253.20001 | AH11: =AH$31*W14 -> 299.62002 | AJ11: =AJ$31*W14 -> 349.55668 | AL11: =AL$31*W14 -> 401.99019
B12: Advanced Packaging, Services & Spares | D12: 3.905 | E12: 11.312 | F12: 9.468 | G12: 13.726 | H12: =Segments!T15 -> 38.411 | J12: 11.044 | K12: 12.932 | L12: 10.644 | M12: 15.896 | N12: =Segments!Z15 -> 50.516 | P12: 16.921 | Q12: 10.297 | R12: 8.391 | S12: 16.565 | T12: =Segments!AF15 -> 52.174 | V12: 15.148 | W12: 12.395 | Z12: =Z$31*W15 -> 54.524902 | AF12: =AF$31*W15 -> 65.429882 | AH12: =AH$31*W15 -> 77.425361 | AJ12: =AJ$31*W15 -> 90.329587 | AL12: =AL$31*W15 -> 103.87903
W13: =W10/W31 -> 0.71950393
B14: Single Wafer Cleaning,Tahoe and Semi- Critical Cleaning Equipment % | W14: 0.2229
B15: ECP, Furnace & Other Technologies % | W15: 0.0576 | AS15: 2022 | AT15: =+AS15+1 -> 2023 | AU15: =+AT15+1 -> 2024 | AV15: =+AU15+1 -> 2025 | AW15: =+AV15+1 -> 2026 | AX15: =+AW15+1 -> 2027 | AY15: =+AX15+1 -> 2028 | AZ15: =+AY15+1 -> 2029
B16: Advanced Packaging, Services & Spares % | AR16: EBITDA | AS16: =H61+H128 -> 64.389 | AT16: =N61+N128 -> 103.929 | AU16: =T61+T128 -> 160.02 | AV16: =Z61+Z128 -> 165.56257 | AW16: =AF61+AF128 -> 206.44413 | AX16: =AH61+AH128 -> 241.01171 | AY16: =AJ61+AJ128 -> 279.74863 | AZ16: =AL61+AL128 -> 319.85059
AR17: FCFF | AS17: =H136 -> -171.72758 | AT17: =N136 -> -137.49706 | AU17: =T136 -> 16.513302 | AV17: =Z136 -> -112.51087 | AW17: =AF136 -> 99.49381 | AX17: =AH136 -> 142.71882 | AY17: =AJ136 -> 157.47185 | AZ17: =AL136 -> 194.58486
AR18: Revenue Growth | AS18: =H32 -> 0.4969413 | AT18: =N32 -> 0.43435468 | AU18: =T32 -> 0.40234131 | AV18: =Z32 -> 0.21031977 | AW18: =AF32 -> 0.2 | AX18: =AH32 -> 0.18333333 | AY18: =+AJ32 -> 0.16666667 | AZ18: =+AL32 -> 0.15
Z21: =SUM(Z10:Z12) -> 946.6166 | AF21: =SUM(AF10:AF12) -> 1135.9399 | AH21: =SUM(AH10:AH12) -> 1344.1956 | AJ21: =SUM(AJ10:AJ12) -> 1568.2282 | AL21: =SUM(AL10:AL12) -> 1803.4624
A23: x
D24: =D$8 -> 2022 | E24: =F24 -> 0 | F24: =F$8 -> 0 | G24: =F24 -> 0 | H24: =F24 -> 0 | J24: =J$8 -> 2023 | K24: =L24 -> 0 | L24: =L$8 -> 0 | M24: =L24 -> 0 | N24: =L24 -> 0 | P24: =P$8 -> 2024 | Q24: =R24 -> 0 | R24: =R$8 -> 0 | S24: =R24 -> 0 | T24: =R24 -> 0 | V24: =V$8 -> 2025 | W24: =X24 -> 0 | X24: =X$8 -> 0 | Y24: =X24 -> 0 | Z24: =X24 -> 0 | AB24: =AB$8 -> 2026 | AC24: =AD24 -> 0 | AD24: =AD$8 -> 0 | AE24: =AD24 -> 0 | AF24: =AD24 -> 0 | AH24: =AH$8 -> 2027 | AJ24: =AJ$8 -> 2028 | AL24: =AL$8 -> 2029
