Workbook
Name COOLFUCNTION: _xlfn.LAMBDA(_xldudf_BOARDFLARE_EXEC("workbook-settings:coolfucntion"))
Name COOLFUCNTION: _xlfn.LAMBDA(_xldudf_BOARDFLARE_EXEC("workbook-settings:coolfucntion"))
Name COOLFUCNTION: _xlfn.LAMBDA(_xldudf_BOARDFLARE_EXEC("workbook-settings:coolfucntion"))
Name COOLFUCNTION: _xlfn.LAMBDA(_xldudf_BOARDFLARE_EXEC("workbook-settings:coolfucntion"))
Name COOLFUCNTION: _xlfn.LAMBDA(_xldudf_BOARDFLARE_EXEC("workbook-settings:coolfucntion"))
Name COOLFUCNTION: _xlfn.LAMBDA(_xldudf_BOARDFLARE_EXEC("workbook-settings:coolfucntion"))
Name COOLFUCNTION: _xlfn.LAMBDA(_xldudf_BOARDFLARE_EXEC("workbook-settings:coolfucntion"))
Name COOLFUCNTION: _xlfn.LAMBDA(_xldudf_BOARDFLARE_EXEC("workbook-settings:coolfucntion"))
Name COOLFUCNTION: _xlfn.LAMBDA(_xldudf_BOARDFLARE_EXEC("workbook-settings:coolfucntion"))
Name COOLFUCNTION: _xlfn.LAMBDA(_xldudf_BOARDFLARE_EXEC("workbook-settings:coolfucntion"))
Name COOLFUCNTION: _xlfn.LAMBDA(_xldudf_BOARDFLARE_EXEC("workbook-settings:coolfucntion"))
Name Sectors: #REF!
Name Sectors: #REF!
Name Sectors: #REF!
Name Sectors: #REF!
Name Sectors: #REF!
Name Sectors: #REF!
Name Sectors: #REF!
Name Sectors: #REF!

Sheet Dashboard
C154: =+C155+1 -> 45993
C155: =+C156+1 -> 45992
C156: =+C157+1 -> 45991
C157: =+C158+1 -> 45990
C158: =+C159+1 -> 45989
C159: =+C160+1 -> 45988
C160: =+C161+1 -> 45987 | L160: =IF(FCFF!$R$155="Revenue Exit",FCFF!$AF$167,IF(FCFF!$R$155="EBITDA Exit",FCFF!Z167,FCFF!AL167)) -> 24.343911
C161: =+C162+1 -> 45986
C162: =+C163+1 -> 45985 | E162: =IF(FCFF!$R$155="Revenue Exit",FCFF!$AF$167,IF(FCFF!$R$155="EBITDA Exit",FCFF!Z167,FCFF!AL167)) -> 24.343911
C163: =+C164+1 -> 45984 | E163: =E164+($E$162-$E$193)/COUNTA($C$162:$C$192) -> 24.598301
C164: =+C165+1 -> 45983 | E164: =E165+($E$162-$E$193)/COUNTA($C$162:$C$192) -> 24.852691
C165: =+C166+1 -> 45982 | E165: =E166+($E$162-$E$193)/COUNTA($C$162:$C$192) -> 25.107081
C166: =+C167+1 -> 45981 | E166: =E167+($E$162-$E$193)/COUNTA($C$162:$C$192) -> 25.361471
C167: =+C168+1 -> 45980 | E167: =E168+($E$162-$E$193)/COUNTA($C$162:$C$192) -> 25.615861
C168: =+C169+1 -> 45979 | E168: =E169+($E$162-$E$193)/COUNTA($C$162:$C$192) -> 25.870251
C169: =+C170+1 -> 45978 | E169: =E170+($E$162-$E$193)/COUNTA($C$162:$C$192) -> 26.124641
C170: =+C171+1 -> 45977 | E170: =E171+($E$162-$E$193)/COUNTA($C$162:$C$192) -> 26.379031
C171: =+C172+1 -> 45976 | E171: =E172+($E$162-$E$193)/COUNTA($C$162:$C$192) -> 26.633421
C172: =+C173+1 -> 45975 | E172: =E173+($E$162-$E$193)/COUNTA($C$162:$C$192) -> 26.887811
C173: =+C174+1 -> 45974 | E173: =E174+($E$162-$E$193)/COUNTA($C$162:$C$192) -> 27.142201
C174: =+C175+1 -> 45973 | E174: =E175+($E$162-$E$193)/COUNTA($C$162:$C$192) -> 27.396591
... C192: =+C193+1 -> 45955 | E192: =E193+($E$162-$E$193)/COUNTA($C$162:$C$192) -> 31.97561
B193: TODAY | C193: =+'Stock Data'!AM4 -> 45954 | D193: =_xlfn.XLOOKUP(C193,'Stock Data'!$AM$4:$AM$1051,'Stock Data'!$AN$4:$AN$1051) -> 32.23 | E193: =D193 -> 32.23
C194: =+'Stock Data'!AM5 -> 45953 | D194: =_xlfn.XLOOKUP(C194,'Stock Data'!$AM$4:$AM$1051,'Stock Data'!$AN$4:$AN$1051) -> 32.23
C195: =+'Stock Data'!AM6 -> 45952 | D195: =_xlfn.XLOOKUP(C195,'Stock Data'!$AM$4:$AM$1051,'Stock Data'!$AN$4:$AN$1051) -> 32.87
C196: =+'Stock Data'!AM7 -> 45951 | D196: =_xlfn.XLOOKUP(C196,'Stock Data'!$AM$4:$AM$1051,'Stock Data'!$AN$4:$AN$1051) -> 32.87
C197: =+'Stock Data'!AM8 -> 45950 | D197: =_xlfn.XLOOKUP(C197,'Stock Data'!$AM$4:$AM$1051,'Stock Data'!$AN$4:$AN$1051) -> 32.87
C198: =+'Stock Data'!AM9 -> 45949 | D198: =_xlfn.XLOOKUP(C198,'Stock Data'!$AM$4:$AM$1051,'Stock Data'!$AN$4:$AN$1051) -> 33.24
C199: =+'Stock Data'!AM10 -> 45948 | D199: =_xlfn.XLOOKUP(C199,'Stock Data'!$AM$4:$AM$1051,'Stock Data'!$AN$4:$AN$1051) -> 33.53
C200: =+'Stock Data'!AM11 -> 45947 | D200: =_xlfn.XLOOKUP(C200,'Stock Data'!$AM$4:$AM$1051,'Stock Data'!$AN$4:$AN$1051) -> 33.775
C201: =+'Stock Data'!AM12 -> 45946 | D201: =_xlfn.XLOOKUP(C201,'Stock Data'!$AM$4:$AM$1051,'Stock Data'!$AN$4:$AN$1051) -> 34.695
C202: =+'Stock Data'!AM13 -> 45945 | D202: =_xlfn.XLOOKUP(C202,'Stock Data'!$AM$4:$AM$1051,'Stock Data'!$AN$4:$AN$1051) -> 34.905
C203: =+'Stock Data'!AM14 -> 45944 | D203: =_xlfn.XLOOKUP(C203,'Stock Data'!$AM$4:$AM$1051,'Stock Data'!$AN$4:$AN$1051) -> 34.905
C204: =+'Stock Data'!AM15 -> 45943 | D204: =_xlfn.XLOOKUP(C204,'Stock Data'!$AM$4:$AM$1051,'Stock Data'!$AN$4:$AN$1051) -> 34.905
C205: =+'Stock Data'!AM16 -> 45942 | D205: =_xlfn.XLOOKUP(C205,'Stock Data'!$AM$4:$AM$1051,'Stock Data'!$AN$4:$AN$1051) -> 34.905
... C558: =+'Stock Data'!AM369 -> 45589 | D558: =_xlfn.XLOOKUP(C558,'Stock Data'!$AM$4:$AM$1051,'Stock Data'!$AN$4:$AN$1051) -> 46.505

Sheet Key Info
B7: Analysts | F7: LIS – Equity Research | J7: Stock Performance
B12: Thor Pinto, Analyst | F12: Recommendation: | H12: Buy
B13: Bsc in Economics, ISEG – Ulisboa | F13: Target Price (FCFF):
B14: l62767@aln.iseg.ulisboa.pt | F14: Upside:
B15: Patrícia Franco, Analyst
B16: Bsc in Mathematics Applied to Economics and Management, ISEG – Ulisboa | F16: Ticker | H16: =Inputs!D15 -> AZZA3 BZ Equity
B17: l61831@aln.iseg.ulisboa.pt | F17: Stock Exchange
B18: Arnaud Hees, Analyst
B19: Bsc in XXX, ISEG – Ulisboa | F19: Current Price | H19: ='Stock Data'!AN4 -> 32.23
B20: email@aln.iseg.ulisboa.pt | F20: ="Market Cap (in "&IF(Inputs!$D$14="BLN","billions",IF(Inputs!$D$14="MLN","millions","thousands"))&")" -> Market Cap (in millions) | H20: ='Stock Data'!AQ4 -> 6655.1666
F21: Beta | H21: 0.41
F22: % of 52-Week High | H22: ='Stock Data'!E165 -> 0.1642097
F23: 100-Day Moving Average | H23: ='Stock Data'!E166 -> 36.1415
B25: Reviewed by: | F25: Avg Vol (1 month) | H25: ='Stock Data'!E168 -> 2277173
B26: Madalena Silva, Co-Head of Equity Research | F26: Shares Outstanding (millions) | H26: ='Stock Data'!E169 -> 206.4898
B27: Bsc in Applied Mathematics in Economics and Managment, ISEG – Ulisboa | F27: % Float | H27: ='Stock Data'!E170 -> 0.6086
B28: l63835@aln.iseg.ulisboa.pt | F28: Short % of Float | H28: =IFERROR('Stock Data'!E171,0) -> 0
B30: LISBON INVESTMENT SOCIETY | F30: % Held by Insiders | H30: ='Stock Data'!E173 -> 0.15760001
B31: ISEG – Rua do Quelhas, 6 | F31: % Held by Institutions | H31: ='Stock Data'!E174 -> 0.7931779
B32: lis@iseg.ulisboa.pt
B34: Disclaimer: This report was prepared by members of the Lisbon Investment Society (LIS), an independent, student-led, non-profit organization based at ISEG – Lisbon School of Economics & Management, and is intended solely for academic and educational purposes. All analyses, forecasts, and opinions expressed in this report reflect the independent judgment of the authors as of the date of publication and are subject to change without notice. The views presented herein do not represent those of ISEG, its faculty, or any affiliated entity. This document does not constitute, and should not be interpreted as, investment advice, an offer, or a solicitation to buy or sell any security or financial instrument. Nothing in this report should be construed as a recommendation to make or refrain from making any investment decision. The content is intended for informational purposes only, and readers are strongly encouraged to conduct their own research and seek advice from a qualified financial professional before making any financial decisions. The information contained in this report has been obtained from publicly available sources believed to be reliable; however, no representation or warranty is made regarding the accuracy, completeness, or timeliness of such information. LIS and its members accept no liability whatsoever for any direct or indirect loss arising from the use of this report or its contents. This report incorporates terminology, financial metrics, and methodologies commonly used in professional equity research, including but not limited to Discounted Cash Flow (DCF), trading multiples, Monte Carlo simulations, and strategic analysis tools such as Porter’s Five Forces. Definitions and assumptions used in these models are disclosed within the report and reflect a hypothetical investment thesis designed solely for academic discussion. All valuations, projections, and target prices presented herein are based on publicly available data and subject to the limitations of modeling assumptions. These are not guarantees of future performance and should not be relied upon as such, as past performance is not indicative of future results. Any company names, logos, trademarks, or brand references mentioned in this report are the property of their respective owners and are used strictly for identification and academic purposes. This document may not be reproduced, redistributed, or quoted in whole or in part without the prior written consent of the Lisbon Investment Society. About LIS – Lisbon Investment Society: The Lisbon Investment Society (LIS) is a non-profit academic association headquartered at ISEG – Lisbon School of Economics & Management. Founded in 2016, LIS is committed to fostering student interest in finance and investment through applied research, skill development, and institutional engagement. The Society operates independently and autonomously from any political, religious, or commercial affiliation, and is composed of selected students and collaborators who are invited through a rigorous recruitment process and share a commitment to excellence, analytical rigor, and ethical standards. Its activities include equity research, portfolio management, macroeconomic analysis, and investment education. This report was prepared by the Equity Research team at the Lisbon Investment Society, whose analysts combine rigorous financial modeling, critical thinking, and collaborative research to deliver high-quality, student-led investment analysis. We welcome your feedback, discussion, and questions regarding this report or our research process, and invite you to reach out to our team as we are always open to engagement.

Sheet Industry
D6: 584.17 | E6: 627.76 | F6: 676.06 | G6: 729.63 | H6: 789.13 | I6: 855.3 | J6: 929 | K6: 997.69 | L6: 1067.63 | M6: 1137.57
A7: x | B7: Industry Growth Forecast | O7: Industry Index
B9: in Billion | D9: 2022 | E9: =+D9+1 -> 2023 | F9: =+E9+1 -> 2024 | G9: =+F9+1 -> 2025 | H9: =+G9+1 -> 2026 | I9: =+H9+1 -> 2027 | J9: =+I9+1 -> 2028 | K9: =+J9+1 -> 2029 | M9: ="CAGR "&$G$9&" - "&$K$9 -> CAGR 2025 - 2029
B12: Market Size (Footwear) | D12: 578.74 | E12: 616.09 | F12: 649.06 | G12: 679.65 | H12: 710.18 | I12: 739.15 | J12: 773.72 | K12: 789.71 | M12: =(K12/G12)^(1/5)-1 -> 0.030472635
B13: Market Share | D13: 0.0019145039 | E13: 0.0019721145 | F13: 0.001945891 | G13: 0.002 | H13: 0.002 | I13: 0.0022 | J13: 0.0024 | K13: 0.0025 | M13: =((K13*K12)/(G13*G12))^(1/5)-1 -> 0.077502945
B14: Market Size (Bags) | D14: 1570 | E14: 1730 | F14: 1790 | G14: 1840 | H14: 1890 | I14: 1940 | J14: 2000 | K14: 2060 | M14: =(K14/G14)^(1/5)-1 -> 0.022845125
B15: Market Share | D15: 0.0013471338 | E15: 0.0013520231 | F15: 0.0015804469 | G15: 0.0017 | H15: 0.0018 | I15: 0.002 | J15: 0.0022 | K15: 0.0024 | M15: =((K15*K14)/(G15*G14))^(1/5)-1 -> 0.095878341
B16: Market Size (Apparel) | M16: =(K16/G16)^(1/5)-1 -> #DIV/0!
B17: Market Share | M17: =((K17*K16)/(G15*G14))^(1/5)-1 -> -1
B18: Market Size | M18: =(K18/G18)^(1/5)-1 -> #DIV/0!
B19: Market Share | M19: =((K19*K18)/(G19*G18))^(1/5)-1 -> #DIV/0!
B20: Market Size | M20: =(K20/G20)^(1/5)-1 -> #DIV/0!
B21: Market Share | M21: =((K21*K20)/(G21*G20))^(1/5)-1 -> #DIV/0!
A23: x
B25: Industry Driver | D25: Description | O25: Porter's Five Forces
B27: Digitalization & E-Commerce | D27: Online sales are growing rapidly, especially in emerging markets
B28: Sustainability & Circular Economy | D28: Consumers demand eco-friendly materials and recycling models
B29: Artificial Intelligence & Personalization | D29: AI supports product recommendations, inventory optimization, and design
B30: Demographic Shift & “Silver Generation” | D30: Older consumers with high purchasing power influence design and marketing
B31: Resale & Second-Hand Trend | D31: Resale platforms are booming, especially among younger demographics
O32: Rivalry Among Existing Competitors | R32: 5
O33: Threat of New Entrants | R33: 3
O34: Threat of Substitutes | R34: 4
O35: Bargaining Power of Customers | R35: 4
O36: Bargaining Power of Suppliers | R36: 2

Sheet ESG
A7: x | B7: ESG Analysis
B12: ESG Scores | G12: GHG Scope 1 Emissions, Water Consumption, Energy Consumption and Waste Production per Sales
B15: LSEG ESG Score
B16: E-Score
B17: S-Score
B18: G-Score
B19: S&P Global ESG Score | D19: 50
B20: Environmental
B21: Social
B22: Governance & Economic
B23: Sustainalytics
B24: ISS ESG Corporate Rating
B25: SDG Impact Rating
B26: Governance Quality Score
B27: MSCI ESG Ratings
B30: Key Info | G30: Environmental
H32: Overview | I32: Targets | J32: Improvements | K32: Comments
B33: GICS Sector | C33: Consumer Discrecionary | G33: GHG Scope 1 Emissions | I33: Carbon neutrality by 2040 | J33: SBTi-validated climate targets | K33: Exact emission values not disclosed
B34: GICS Industry Group | C34: Consumer Durables & Apparel
B35: GICS Industry | C35: Textiles, Apparel & Luxury Goods | G35: Water Consumption | I35: Eco-efficiency in processes | J35: Circular production model | K35: No specific consumption data available
B36: GICS Sub-Industry | C36: Apparel, Accessories & Luxury Goods
G37: Energy Consumption | I37: Reduce energy intensity | J37: LED lighting, solar integration | K37: No quantitative data disclosed
B38: Headquarters | C38: Belo Horizonte, Minas Gerais, Brazil
B39: Numer of Employees | C39: 6000 | G39: Waste Management | I39: Circular economy | J39: Leather traceability | K39: Prioritizes sustainable materials
B41: Annual Report | C41: https://ri.azzas2154.com.br/ | G41: Other
B42: Sustainability Report | C42: https://ri.azzas2154.com.br/en/sustaintability-report/
B44: Recent Headlines | G44: Social
H46: Overview | I46: Targets | J46: Improvements | K46: Comments
G47: Employee Turnover %
G49: Salaries & Compensation
G51: Reputation | I51: Brand strengthening | J51: B Corp, ISE B3
G53: Discrimination Events | I53: DEI policy | J53: Racial Equity Pact
G55: Work Safety
G57: Damage to consumer health | I57: Sustainable materials | J57: No harmful substances
G59: Pension Plan
G61: Supply chain | I61: Transparency & compliance | J61: Supplier code of conduct | K61: ESG-aligned supplier policy
G63: Community involvement | I63: Social programs | J63: 1P=5P, Fundação Hering | K63: High social impact
G65: Public Sector
G67: Litigation
B70: Board of Directors | G70: Governance
...

Sheet Segments
A7: x | B7: Segments | D7: =F7 -> 2020 | E7: =F7 -> 2020 | F7: 2020 | G7: =F7 -> 2020 | H7: =F7 -> 2020 | J7: =L7 -> 2021 | K7: =L7 -> 2021 | L7: 2021 | M7: =L7 -> 2021 | N7: =L7 -> 2021 | P7: =R7 -> 2022 | Q7: =R7 -> 2022 | R7: 2022 | S7: =R7 -> 2022 | T7: =R7 -> 2022 | V7: =X7 -> 2023 | W7: =X7 -> 2023 | X7: 2023 | Y7: =X7 -> 2023 | Z7: =X7 -> 2023 | AB7: =AD7 -> 2024 | AC7: =AD7 -> 2024 | AD7: 2024 | AE7: =AD7 -> 2024 | AF7: =AD7 -> 2024 | AH7: =AJ7 -> 2025 | AI7: =AJ7 -> 2025 | AJ7: 2025 | AK7: =AJ7 -> 2025 | AL7: =AJ7 -> 2025 | AN7: =AP7 -> 2025 | AO7: =AP7 -> 2025 | AP7: 2025 | AQ7: =AP7 -> 2025 | AR7: =AP7 -> 2025 | AZ7: Products
D8: 2020 | J8: =D8+1 -> 2021 | P8: =J8+1 -> 2022 | V8: =P8+1 -> 2023 | AB8: =V8+1 -> 2024 | AH8: =AB8+1 -> 2025 | AN8: =AH8+1 -> 2026 | AT8: =AN8+1 -> 2027 | AV8: =+AT8+1 -> 2028 | AX8: =+AV8+1 -> 2029
D9: Q1 | E9: Q2 | F9: Q3 | G9: Q4 | H9: FY | J9: Q1 | K9: Q2 | L9: Q3 | M9: Q4 | N9: FY | P9: Q1 | Q9: Q2 | R9: Q3 | S9: Q4 | T9: FY | V9: Q1 | W9: Q2 | X9: Q3 | Y9: Q4 | Z9: FY | AB9: Q1 | AC9: Q2 | AD9: Q3 | AE9: Q4 | AF9: FY | AH9: Q1 | AI9: Q2 | AJ9: Q3 | AK9: Q4 | AL9: FY | AN9: Q1 | AO9: Q2 | AP9: Q3 | AQ9: Q4 | AR9: FY | AT9: FY | AV9: FY | AX9: FY
B12: Revenue by segment:
B13: Shoes & Bags | H13: =295.969+152.38+83.8+78.4+24.5+76.78 -> 711.829 | N13: =6.7+1065+607+292+391+520 -> 2881.7 | T13: =1381+804.7+368.964+275 -> 2829.664 | Z13: =SUM(Z14:Z24) -> 4565.8 | AF13: =SUM(AF14:AF24) -> 4785.2 | AL13: =AL14+AL16+AL20+AL22+AL24 -> 4258.697 | AR13: =AR14+AR16+AR20+AR22+AR24 -> 4575.1898 | AT13: =AT14+AT16+AT20+AT22+AT24 -> 4859.887 | AV13: =AV14+AV16+AV20+AV22+AV24 -> 5107.1826 | AX13: =AX14+AX16+AX20+AX22+AX24 -> 5308.4232
B14: Franchises | Z14: 1193 | AF14: 1199.8 | AL14: =AF14*(1+AL15) -> 1343.776 | AR14: =AL14*(1+AR15) -> 1478.1536 | AT14: =AR14*(1+AT15) -> 1596.4059 | AV14: =AT14*(1+AV15) -> 1692.1902 | AX14: =AV14*(1+AX15) -> 1759.8779
B15: % of growth | AL15: 0.12 | AR15: =AL15-($AL$15-$AX$15)/4 -> 0.1 | AT15: =AR15-($AL$15-$AX$15)/4 -> 0.08 | AV15: =AT15-($AL$15-$AX$15)/4 -> 0.06 | AX15: 0.04
B16: Multi-brand | Z16: 1278.9 | AF16: 1255.4 | AL16: =AF16*(1+AL17) -> 1318.17 | AR16: =AL16*(1+AR17) -> 1410.4419 | AT16: =AR16*(1+AT17) -> 1490.3669 | AV16: =AT16*(1+AV17) -> 1554.9495 | AX16: =AV16*(1+AX17) -> 1601.598
B17: % of growth | AL17: 0.05 | AR17: 0.07 | AT17: =AR17-($AR$17-$AX$17)/3 -> 0.056666667 | AV17: =AT17-($AR$17-$AX$17)/3 -> 0.043333333 | AX17: 0.03
B18: Owned Stores | Z18: 716.5 | AF18: 821.4 | AL18: =AF18*(1+AL19) -> 878.898 | AR18: =AL18*(1+AR19) -> 936.02637 | AT18: =AR18*(1+AT19) -> 992.18795 | AV18: =AT18*(1+AV19) -> 1046.7583 | AX18: =AV18*(1+AX19) -> 1099.0962
B19: % of growth | AL19: 0.07 | AR19: =AL19-($AL$19-$AX$19)/4 -> 0.065 | AT19: =AR19-($AL$19-$AX$19)/4 -> 0.06 | AV19: =AT19-($AL$19-$AX$19)/4 -> 0.055 | AX19: 0.05
B20: Web Commerce | Z20: 902.4 | AF20: 1028.5 | AL20: =AF20*(1+AL21) -> 1110.78 | AR20: =AL20*(1+AR21) -> 1177.4268 | AT20: =AR20*(1+AT21) -> 1244.1477 | AV20: =AT20*(1+AV21) -> 1310.5022 | AX20: =AV20*(1+AX21) -> 1376.0273
B21: % of growth | AL21: 0.08 | AR21: 0.06 | AT21: =AR21-($AR$21-$AX$21)/3 -> 0.056666667 | AV21: =AT21-($AR$21-$AX$21)/3 -> 0.053333333 | AX21: 0.05
B22: International | Z22: 430.4 | AF22: 426.6 | AL22: =AF22*(1+AL23) -> 430.866 | AR22: =AL22*(1+AR23) -> 452.4093 | AT22: =AR22*(1+AT23) -> 470.50567 | AV22: =AT22*(1+AV23) -> 489.3259 | AX22: =AV22*(1+AX23) -> 508.89893
B23: % of growth | AL23: 0.01 | AR23: 0.05 | AT23: 0.04 | AV23: 0.04 | AX23: 0.04
B24: Others | Z24: 44.6 | AF24: 53.5 | AL24: =AF24*(1+AL25) -> 55.105 | AR24: =AL24*(1+AR25) -> 56.75815 | AT24: =AR24*(1+AT25) -> 58.460895 | AV24: =AT24*(1+AV25) -> 60.214721 | AX24: =AV24*(1+AX25) -> 62.021163
B25: % of growth | AL25: 0.03 | AR25: 0.03 | AT25: 0.03 | AV25: 0.03 | AX25: 0.03
B27: Fashion & Lifestyle Women | H27: =26.3+398+75+46.9+614.4+95.2+90.7+75.1 -> 1421.6 | N27: =540.6+87.4+72.6+898.4+271.7+173.5+243.8+72.8 -> 2360.8 | T27: =463+275+670.1+1191.7+490.9+193.4+381.4+120.4+62.1+104.6+463 -> 4415.6 | Z27: =SUM(Z28:Z38) -> 4103.9 | AF27: =SUM(AF28:AF38) -> 4782.1 | AL27: =AL28+AL30+AL32+AL34+AL36+AL38 -> 5634.651 | AR27: =AR28+AR30+AR32+AR34+AR36+AR38 -> 6530.2666 | AT27: =AT28+AT30+AT32+AT34+AT36+AT38 -> 7437.1189 | AV27: =AV28+AV30+AV32+AV34+AV36+AV38 -> 8316.3496 | AX27: =AX28+AX30+AX32+AX34+AX36+AX38 -> 9124.7281
B28: Franchises | Z28: 15.2 | AF28: 9.9 | AL28: =AF28*(1+AL29) -> 10.098 | AR28: =AL28*(1+AR29) -> 10.29996 | AT28: =AR28*(1+AT29) -> 10.505959 | AV28: =AT28*(1+AV29) -> 10.716078 | AX28: =AV28*(1+AX29) -> 10.9304
B29: % of growth | AL29: 0.02 | AR29: 0.02 | AT29: 0.02 | AV29: 0.02 | AX29: 0.02
B30: Multi-brand | Z30: 810.6 | AF30: 856.6 | AL30: =AF30*(1+AL31) -> 1070.75 | AR30: =AL30*(1+AR31) -> 1298.2844 | AT30: =AR30*(1+AT31) -> 1525.4841 | AV30: =AT30*(1+AV31) -> 1735.2382 | AX30: =AV30*(1+AX31) -> 1908.762
B31: % of growth | AL31: 0.25 | AR31: =AL31-($AL$31-$AX$31)/4 -> 0.2125 | AT31: =AR31-($AL$31-$AX$31)/4 -> 0.175 | AV31: =AT31-($AL$31-$AX$31)/4 -> 0.1375 | AX31: 0.1
B32: Owned Stores | Z32: 1765.3 | AF32: 2090.8 | AL32: =AF32*(1+AL33) -> 2404.42 | AR32: =AL32*(1+AR33) -> 2716.9946 | AT32: =AR32*(1+AT33) -> 3015.864 | AV32: =AT32*(1+AV33) -> 3287.2918 | AX32: =AV32*(1+AX33) -> 3517.4022
B33: % of growth | AL33: 0.15 | AR33: =AL33-($AL$33-$AX$33)/4 -> 0.13 | AT33: =AR33-($AL$33-$AX$33)/4 -> 0.11 | AV33: =AT33-($AL$33-$AX$33)/4 -> 0.09 | AX33: 0.07
B34: Web Commerce | Z34: 719.2 | AF34: 789.9 | AL34: =AF34*(1+AL35) -> 884.688 | AR34: =AL34*(1+AR35) -> 982.00368 | AT34: =AR34*(1+AT35) -> 1080.204 | AV34: =AT34*(1+AV35) -> 1177.4224 | AX34: =AV34*(1+AX35) -> 1271.6162
B35: % of growth | AL35: 0.12 | AR35: =AL35-($AL$35-$AX$35)/4 -> 0.11 | AT35: =AR35-($AL$35-$AX$35)/4 -> 0.1 | AV35: =AT35-($AL$35-$AX$35)/4 -> 0.09 | AX35: 0.08
B36: International | Z36: 775.3 | AF36: 995.7 | AL36: =AF36*(1+AL37) -> 1224.711 | AR36: =AL36*(1+AR37) -> 1481.9003 | AT36: =AR36*(1+AT37) -> 1763.4614 | AV36: =AT36*(1+AV37) -> 2063.2498 | AX36: =AV36*(1+AX37) -> 2372.7373
B37: % of growth | AL37: 0.23 | AR37: =AL37-($AL$37-$AX$37)/4 -> 0.21 | AT37: =AR37-($AL$37-$AX$37)/4 -> 0.19 | AV37: =AT37-($AL$37-$AX$37)/4 -> 0.17 | AX37: 0.15
B38: Others | Z38: 18.3 | AF38: 39.2 | AL38: =AF38*(1+AL39) -> 39.984 | AR38: =AL38*(1+AR39) -> 40.78368 | AT38: =AR38*(1+AT39) -> 41.599354 | AV38: =AT38*(1+AV39) -> 42.431341 | AX38: =AV38*(1+AX39) -> 43.279967
B39: % of growth | AL39: 0.02 | AR39: 0.02 | AT39: 0.02 | AV39: 0.02 | AX39: 0.02
B41: Basic | H41: 8.5 | N41: 1849.4 | T41: 2330.4 | Z41: =SUM(Z42:Z52) -> 2587.7 | AF41: =SUM(AF42:AF52) -> 2794 | AL41: =AL42+AL44+AL46+AL48+AL50+AL52 -> 3047.724 | AR41: =AR42+AR44+AR46+AR48+AR50+AR52 -> 3335.3089 | AT41: =AT42+AT44+AT46+AT48+AT50+AT52 -> 3623.619 | AV41: =AV42+AV44+AV46+AV48+AV50+AV52 -> 3906.7965 | AX41: =AX42+AX44+AX46+AX48+AX50+AX52 -> 4178.4062
B42: Franchises | Z42: 787.5 | AF42: 823.5 | AL42: =AF42*(1+AL43) -> 856.44 | AR42: =AL42*(1+AR43) -> 916.3908 | AT42: =AR42*(1+AT43) -> 974.42888 | AV42: =AT42*(1+AV43) -> 1029.6465 | AX42: =AV42*(1+AX43) -> 1081.1288
AL43: 0.04 | AR43: 0.07 | AT43: =AR43-($AR$43-$AX$43)/3 -> 0.063333333 | AV43: =AT43-($AR$43-$AX$43)/3 -> 0.056666667 | AX43: 0.05
B44: Multi-brand | Z44: 881.8 | AF44: 856.4 | AL44: =AF44*(1+AL45) -> 924.912 | AR44: =AL44*(1+AR45) -> 994.2804 | AT44: =AR44*(1+AT45) -> 1063.88 | AV44: =AT44*(1+AV45) -> 1133.0322 | AX44: =AV44*(1+AX45) -> 1201.0142
AL45: 0.08 | AR45: =AL45-($AL$45-$AX$45)/4 -> 0.075 | AT45: =AR45-($AL$45-$AX$45)/4 -> 0.07 | AV45: =AT45-($AL$45-$AX$45)/4 -> 0.065 | AX45: 0.06
B46: Owned Stores | Z46: 566.3 | AF46: 610.6 | AL46: =AF46*(1+AL47) -> 714.402 | AR46: =AL46*(1+AR47) -> 823.3483 | AT46: =AR46*(1+AT47) -> 934.50033 | AV46: =AT46*(1+AV47) -> 1044.3041 | AX46: =AV46*(1+AX47) -> 1148.7345
AL47: 0.17 | AR47: =AL47-($AL$47-$AX$47)/4 -> 0.1525 | AT47: =AR47-($AL$47-$AX$47)/4 -> 0.135 | AV47: =AT47-($AL$47-$AX$47)/4 -> 0.1175 | AX47: 0.1
B48: Web Commerce | Z48: 332.3 | AF48: 480 | AL48: =AF48*(1+AL49) -> 528 | AR48: =AL48*(1+AR49) -> 576.84 | AT48: =AR48*(1+AT49) -> 625.8714 | AV48: =AT48*(1+AV49) -> 674.37643 | AX48: =AV48*(1+AX49) -> 721.58278
AL49: 0.1 | AR49: =AL49-($AL$49-$AX$49)/4 -> 0.0925 | AT49: =AR49-($AL$49-$AX$49)/4 -> 0.085 | AV49: =AT49-($AL$49-$AX$49)/4 -> 0.0775 | AX49: 0.07
B50: International | AL50: =AF50*(1+AL51) -> 0 | AR50: =AL50*(1+AR51) -> 0 | AT50: =AR50*(1+AT51) -> 0 | AV50: =AT50*(1+AV51) -> 0 | AX50: =AV50*(1+AX51) -> 0
...

Sheet Peers
B7: Peers
A12: x | B12: Growth | C12: AZZAS 2154 SA | D12: GUARARAPES | E12: LOJAS RENNER SA | F12: C&A MODAS LTDA | G12: MARISA LOJAS SA | H12: VESTE SA ESTILO | I12: VULCABRAS SA | J12: GRENDENE SA | K12: ALPARGATAS-PREF | L12: GRUPO SBF SA | M12: TRACK & FIELD CO | N12: REDTAPE LTD/INDI | O12: LI NING CO LTD | P12: TOPSPORTS INTERN | Q12: CHINA LILANG LTD | R12: DAZZLE FASHION-A
B14: Revenue (LTM) | C14: 1.2556565 | D14: 0.11258158 | E14: 0.11855769 | F14: 0.12668832 | G14: 0.15093568 | H14: 0.05878629 | I14: 0.14072007 | J14: 0.10465911 | K14: 0.12981686 | L14: 0.12981686 | M14: 0.025524777 | N14: 0.025524777 | O14: 0.025524777 | P14: 0.025524777 | Q14: 0.025524777 | R14: 0.025524777
B15: Revenue (3-yr CAGR) | C15: 0.46735652 | D15: 0.074483354 | E15: 0.065973345 | F15: 0.099914554 | G15: -0.1879159 | H15: 0.045729191 | I15: 0.1278818 | J15: 0.030018488 | K15: 0.024792939 | L15: 0.069313482 | M15: 0.21460678 | N15: 0 | O15: 0.055534968 | P15: -0.053689788 | Q15: 0.033368996 | R15: -0.065916061
B16: Gross profit (LTM) | C16: 1.3232691 | D16: 0.14565826 | E16: 0.13090249 | F16: 0.15852495 | G16: 0.32239037 | H16: 0.035551934 | I16: 0.12152993 | J16: 0.15297977 | K16: 0.24266392 | L16: 0.24266392 | M16: 0.056092437 | N16: 0.056092437 | O16: 0.056092437 | P16: 0.056092437 | Q16: 0.056092437 | R16: 0.056092437
B17: EBIT (LTM) | C17: 0.74828656 | D17: 0.45272413 | E17: 0.4363497 | F17: -0.456377 | G17: -1.5516545 | H17: 0.40695062 | I17: 0.26944998 | J17: -0.0072534124 | K17: -1.2785196 | L17: -1.2785196 | M17: -0.13783918 | N17: -0.13783918 | O17: -0.13783918 | P17: -0.13783918 | Q17: -0.13783918 | R17: -0.13783918
B18: EBITDA (LTM) | C18: 1.0020522 | D18: 0.25926503 | E18: 0.26076944 | F18: -0.26252502 | G18: -3.2686743 | H18: 0.053443644 | I18: 0.23964658 | J18: 0.1005505 | K18: -1.6211 | L18: -1.6211 | M18: -0.059208487 | N18: -0.059208487 | O18: -0.059208487 | P18: -0.059208487 | Q18: -0.059208487 | R18: -0.059208487
B19: FCF (LTM) | C19: =-(55/177.4)-1 -> -1.3100338 | D19: 0.12284517 | E19: 0.021083572 | F19: 0.63279099 | G19: =(-88.2/279.4)-1 -> -1.3156764 | H19: 0.80945236 | I19: -0.045196394 | J19: -0.16044988 | K19: 16.335793 | L19: 0.86648428 | M19: 0.24876016 | N19: -2.8232662 | O19: 0.45966728 | P19: -0.029005954 | Q19: -0.56520088 | R19: -0.45922865
A21: x | B21: Margins | C21: AZZAS 2154 SA | D21: GUARARAPES | E21: LOJAS RENNER SA | F21: C&A MODAS LTDA | G21: MARISA LOJAS SA | H21: VESTE SA ESTILO | I21: VULCABRAS SA | J21: GRENDENE SA | K21: ALPARGATAS-PREF | L21: GRUPO SBF SA | M21: TRACK & FIELD CO | N21: REDTAPE LTD/INDI | O21: LI NING CO LTD | P21: TOPSPORTS INTERN | Q21: CHINA LILANG LTD | R21: DAZZLE FASHION-A
B23: Gross margin | C23: 0.53283921 | D23: 0.58975139 | E23: 0.60555052 | F23: 0.5469191 | G23: 0.49099499 | H23: 0.63268754 | I23: 0.4193401 | J23: 0.47214618 | K23: 0.43149022 | L23: 0.4912284 | M23: 0.56584059 | N23: =2508.1/20209.1 -> 0.12410746 | O23: 0.49366297 | P23: 0.38438672 | Q23: 0.4765214 | R23: 0.74840407
B24: EBIT margin | C24: 0.04578166 | D24: 0.079076046 | E24: 0.087234073 | F24: 0.10597013 | G24: -0.031269192 | H24: 0.039080387 | I24: 0.18839931 | J24: 0.19444034 | K24: 0.0072864493 | L24: 0.085515025 | M24: 0.19742017 | N24: 0.12461713 | O24: 0.12826935 | P24: 0.058960719 | Q24: 0.15136701 | R24: 0.16262923
B25: EBITDA margin | C25: 0.12207758 | D25: 0.15388595 | E25: 0.19028459 | F25: 0.2109477 | G25: 0.23217044 | H25: 0.19796399 | I25: 0.25010125 | J25: 0.20331435 | K25: 0.11284125 | L25: 0.1400035 | M25: 0.24680886 | N25: 0.16590051 | O25: 0.182683 | P25: 0.11302378 | Q25: 0.18864833 | R25: 0.217
B26: Net margin | C26: 0.04078008 | D26: 0.024406575 | E26: 0.082892606 | F26: 0.05925158 | G26: -0.22682878 | H26: 0.00059826099 | I26: 0.18693076 | J26: 0.27970844 | K26: 0.026283064 | L26: 0.074982864 | M26: 0.14157106 | N26: 0.08412052 | O26: 0.10506889 | P26: 0.047606884 | Q26: 0.12633429 | R26: 0.13678793
B27: SG&A margin | C27: =(5548.7/11548.4) -> 0.48047349 | D27: 0.43787537 | E27: 0.35119912 | F27: 0.33611784 | G27: 0.44772007 | H27: 0.5950034 | I27: 0.23384148 | J27: 0.27222911 | K27: 0.37046635 | L27: 0.35267042 | M27: 0.37291451 | O27: 0.37058677 | P27: 0.33092708 | Q27: 0.34168077 | R27: 0.47491698
B28: R&D margin | O28: 0.024136005 | Q28: 0.037294207 | R28: 0.035670317
A30: x | B30: Returns | C30: AZZAS 2154 SA | D30: GUARARAPES | E30: LOJAS RENNER SA | F30: C&A MODAS LTDA | G30: MARISA LOJAS SA | H30: VESTE SA ESTILO | I30: VULCABRAS SA | J30: GRENDENE SA | K30: ALPARGATAS-PREF | L30: GRUPO SBF SA | M30: TRACK & FIELD CO | N30: REDTAPE LTD/INDI | O30: LI NING CO LTD | P30: TOPSPORTS INTERN | Q30: CHINA LILANG LTD | R30: DAZZLE FASHION-A
B32: ROIC | C32: 0.16918018 | D32: 0.069005171 | E32: 0.097664511 | F32: 0.14464212 | G32: 0.11062665 | H32: 0.041986884 | I32: 0.24773206 | J32: 0.099680305 | K32: 0.049972688 | L32: 0.10286241 | M32: 0.24942472 | N32: 0.13886843 | O32: 0.086845471 | P32: 0.10023206 | Q32: 0.06732947 | R32: 0.055541628
B33: CROIC | C33: -0.0051281769 | D33: 0.15597084 | E33: 0.12040782 | F33: 0.18381891 | G33: -0.085671997 | H33: 0.17803777 | I33: 0.14329723 | J33: 0.12380824 | K33: 0.12433083 | L33: 0.15469667 | M33: 0.084197026 | N33: -0.12402523 | O33: 0.15398744 | P33: 0.25743589 | Q33: 0.075427382 | R33: 0.092778969
B34: ROCE | C34: 0.080544041 | D34: 0.14595231 | E34: 0.13188882 | F34: 0.22077174 | G34: -0.53597636 | H34: 0.092869726 | I34: 0.27617269 | J34: 0.16736201 | K34: 0.0092236426 | L34: 0.20200546 | M34: 0.27095314 | N34: 0.22679298 | O34: 0.17848211 | P34: 0.17996203 | Q34: 0.15399648 | R34: 0.10169918
B35: RONA | C35: 0.049684421 | D35: 0.14098604 | E35: 0.11689861 | F35: 0.24459663 | G35: -0.15295424 | H35: 0.041637752 | I35: 0.27216007 | J35: 0.12648078 | K35: 0.0074163006 | L35: 0.20302429 | M35: 0.3472988 | N35: 0.31925359 | O35: 0.14090752 | P35: 0.17581411 | Q35: 0.13624141 | R35: 0.09829913
B36: ROE | C36: 0.139305 | D36: 0.077408803 | E36: 0.13269836 | F36: 0.15221259 | G36: -2.2154 | H36: 0.00050451406 | I36: 0.36040769 | J36: 0.21160091 | K36: 0.06471241 | L36: 0.13232501 | M36: 0.27925058 | N36: 0.23655959 | O36: 0.10544833 | P36: 0.13602924 | Q36: 0.10359023 | R36: 0.070283704
B37: ROA | C37: 0.073857084 | D37: 0.030591115 | E37: 0.072035651 | F37: 0.057445468 | G37: -0.029876775 | H37: 0.00031506099 | I37: 0.25766966 | J37: 0.19165889 | K37: 0.040760494 | L37: 0.045710792 | M37: 0.1751245 | N37: 0.089178457 | O37: 0.077390538 | P37: 0.087344846 | Q37: 0.064491798 | R37: 0.05479408
A39: x | B39: Efficiency | C39: AZZAS 2154 SA | D39: GUARARAPES | E39: LOJAS RENNER SA | F39: C&A MODAS LTDA | G39: MARISA LOJAS SA | H39: VESTE SA ESTILO | I39: VULCABRAS SA | J39: GRENDENE SA | K39: ALPARGATAS-PREF | L39: GRUPO SBF SA | M39: TRACK & FIELD CO | N39: REDTAPE LTD/INDI | O39: LI NING CO LTD | P39: TOPSPORTS INTERN | Q39: CHINA LILANG LTD | R39: DAZZLE FASHION-A
B41: Asset turnover | C41: 1.0732879 | D41: 0.75544775 | E41: 0.81268039 | F41: 0.91776054 | G41: 0.74016266 | H41: 0.69291238 | I41: 1.0574968 | J41: 0.64482474 | K41: 0.68295093 | L41: 0.8726369 | M41: 1.2196158 | N41: 1.0601273 | O41: 0.80609823 | P41: 1.8347104 | Q41: 0.57519467 | R41: 0.47045338
B42: Net operating asset turnover | C42: 0.76537203 | D42: 1.0571958 | E42: 1.0299645 | F42: 1.4809611 | G42: 1.186773 | H42: 0.88661466 | I42: 1.3148879 | J42: 0.80942694 | K42: 1.0990872 | L42: 1.4212626 | M42: 1.2787007 | N42: 1.3592346 | O42: 1.0928419 | P42: 3.2742115 | Q42: 0.77533427 | R42: 1.7637767
B43: Fixed asset turnover | C43: 7.6145874 | D43: 4.1347389 | E43: 3.0796469 | F43: 3.6836739 | G43: 2.9318356 | H43: 3.6846039 | I43: 6.2570456 | J43: 5.027273 | K43: 2.7867584 | L43: 3.6671263 | M43: 4.7902592 | N43: 2.8675559 | O43: 4.6145698 | P43: 11.208672 | Q43: 2.7054077 | R43: 3.2506133
B44: Revenue per employee thsnd of USD | D44: 59.252105 | E44: 107.49758 | J44: 27.460398 | N44: 291.92391 | O44: 804.16277 | P44: 137.22917 | Q44: 105.15313 | R44: 431.72673
B45: EBIT per employee thsnd of USD | D45: 5.2598321 | E45: 12.531122 | J45: 4.5698511 | N45: 36.229934 | O45: 117.78982 | P45: 8.708367 | Q45: 14.012604 | R45: 49.015191
A47: x | B47: Working Capital | C47: AZZAS 2154 SA | D47: GUARARAPES | E47: LOJAS RENNER SA | F47: C&A MODAS LTDA | G47: MARISA LOJAS SA | H47: VESTE SA ESTILO | I47: VULCABRAS SA | J47: GRENDENE SA | K47: ALPARGATAS-PREF | L47: GRUPO SBF SA | M47: TRACK & FIELD CO | N47: REDTAPE LTD/INDI | O47: LI NING CO LTD | P47: TOPSPORTS INTERN | Q47: CHINA LILANG LTD | R47: DAZZLE FASHION-A
B49: DSO | C49: 56.262752 | D49: 167.0841 | E49: 147.53405 | F49: 66.590651 | G49: 14.804321 | H49: 55.977601 | I49: 101.73184 | J49: 106.48929 | K49: 75.7619 | L49: 68.88003 | M49: 64.498913 | N49: 18.346537 | O49: 16.046924 | P49: 14.062679 | Q49: 36.482074 | R49: 11.852138
B50: DIO | C50: 120.16759 | D50: 142.5043 | E50: 116.87241 | F50: 113.89348 | G50: 128.22888 | H50: 237.63833 | I50: 138.42486 | J50: 118.45076 | K50: 142.66171 | L50: 181.96172 | M50: 275.4845 | N50: 236.03189 | O50: 58.416455 | P50: 134.85213 | Q50: 177.3857 | R50: 289.71089
B51: DPO | C51: 61.492327 | D51: 96.515938 | E51: 81.425603 | F51: 137.71892 | G51: 135.37904 | H51: 112.05468 | I51: 22.233345 | J51: 17.631387 | K51: 76.188175 | L51: 102.96857 | M51: 55.496537 | N51: 71.681798 | O51: 43.74594 | P51: 8.1540487 | Q51: 76.218277 | R51: 39.798343
B52: CCC | C52: 137.04225 | D52: 213.08118 | E52: 178.16437 | F52: -7.40285 | G52: -64.488004 | H52: 189.8718 | I52: 218.721 | J52: 261.38094 | K52: 141.51727 | L52: 134.35789 | M52: 299.48737 | N52: 182.69663 | O52: 35.543633 | P52: 140.76076 | Q52: 133.67995 | R52: 233.72701
B53: Working capital intensity | C53: 0.14941759 | D53: 0.28904962 | E53: 0.29533558 | F53: 0.15100754 | G53: -0.39784517 | H53: 0.1551868 | I53: 0.45772679 | J53: 0.87837737 | K53: 0.44408789 | L53: 0.20022791 | M53: 0.3922293 | N53: 0.16145202 | O53: 0.41972076 | P53: 0.25363623 | Q53: 0.46271307 | R53: 1.336881
B54: Cash conversion ratio | C54: 0.94869135 | D54: 1.9766761 | E54: 1.9748448 | F54: 1.8351019 | G54: 1.8544749 | H54: 5.4776703 | I54: 0.98286063 | J54: 1.3749467 | K54: 28.228863 | L54: 1.7494633 | M54: 0.61132967 | N54: -0.067701715 | O54: 1.5946657 | P54: 2.3947385 | Q54: 0.97288081 | R54: 1.1237422
B55: CFO margin | C55: 0.043432664 | D55: 0.15630773 | E55: 0.17227376 | F55: 0.19446597 | G55: -0.057987931 | H55: 0.21406948 | I55: 0.18517027 | J55: 0.26734511 | K55: 0.20568818 | L55: 0.1496054 | M55: 0.12068881 | N55: -0.0084367933 | O55: 0.20454673 | P55: 0.1411955 | Q55: 0.14726206 | R55: 0.18275334
A57: x | B57: Leverage & Coverage | C57: AZZAS 2154 SA | D57: GUARARAPES | E57: LOJAS RENNER SA | F57: C&A MODAS LTDA | G57: MARISA LOJAS SA | H57: VESTE SA ESTILO | I57: VULCABRAS SA | J57: GRENDENE SA | K57: ALPARGATAS-PREF | L57: GRUPO SBF SA | M57: TRACK & FIELD CO | N57: REDTAPE LTD/INDI | O57: LI NING CO LTD | P57: TOPSPORTS INTERN | Q57: CHINA LILANG LTD | R57: DAZZLE FASHION-A
B59: Net debt / EBITDA | C59: 2.1403824 | D59: 1.2498803 | E59: 0.44633096 | F59: 1.1909165 | G59: 1.8877603 | H59: 1.3590474 | I59: 0.22024404 | J59: -3.1855785 | K59: -0.033263111 | L59: 2.1254795 | M59: 0.53290463 | N59: 2.1177857 | O59: -1.8691265 | P59: 0.48393436 | Q59: -1.0014637 | R59: -5.3
B60: Net debt / FCF | C60: -50.081462 | D60: 1.1756966 | E60: 0.44562525 | F60: 1.4686036 | G60: -6.1895206 | H60: 1.4633759 | I60: 0.14351818 | J60: -2.9384931 | K60: 0.1626787 | L60: 2.0623351 | M60: 2.3189105 | N60: -3.7769562 | O60: -1.2361179 | P60: 0.42934356 | Q60: 1.1585352 | R60: -7.8585605
B61: Interest coverage | C61: 1.6132164 | D61: 1.6112239 | E61: 3.9661848 | F61: 1.8003907 | G61: -0.31242464 | H61: 0.77774197 | I61: 11.96762 | J61: 51.279422 | K61: 0.16796562 | L61: 3.8319246 | M61: 13.396916 | N61: 5.2488537 | O61: 23.498109 | P61: 8.1012208 | Q61: 17.731217 | R61: 44.534924
...

Sheet Trading Comps
B7: in millions of BRL | D7: Current | E7: % of | I7: Enterprise Value / | S7: LTM | T7: Net | V7: Price / | Z7: LT
D8: Share | E8: 52-week | F8: Equity | G8: Enterprise | I8: LTM | J8: 2025 | K8: 2026 | L8: LTM | M8: 2025E | N8: 2026E | O8: LTM | P8: 2025E | Q8: 2026E | S8: EBITDA | T8: Debt / | V8: LTM | W8: 2025E | X8: 2026E | Z8: EPS
B9: Company | C9: Ticker | D9: Price | E9: High | F9: Value | G9: Value | I9: Sales | J9: Sales | K9: Sales | L9: EBITDA | M9: EBITDA | N9: EBITDA | O9: EBIT | P9: EBIT | Q9: EBIT | S9: Margin | T9: EBITDA | V9: EPS | W9: EPS | X9: EPS | Z9: Growth
B12: Tier I: DRAM and NAND
B15: GUARARAPES | C15: GUAR3 BZ | D15: BRL 9,53 | E15: 0.9172281 | F15: 4592.64 | G15: 6223.5221 | I15: 0.61216933 | J15: 0.58551496 | K15: 0.5466697 | L15: 3.8709538 | M15: 3.7199774 | N15: 3.3519008 | O15: 6.8960986 | P15: 6.5797696 | Q15: 5.7579507 | S15: 0.15814431 | T15: 2.0169797 | V15: 10.452433 | W15: 10.547402 | X15: 8.2453142 | Z15: 0.16472618
B16: LOJAS RENNER SA | C16: LREN3 BZ | D16: BRL 15,15 | E16: 0.76245596 | F16: 15611.398 | G16: 21000.847 | I16: 1.3607871 | J16: 1.2925478 | K16: 1.2058897 | L16: 6.8265623 | M16: 6.8668196 | N16: 6.3695351 | O16: 11.673441 | P16: 10.718504 | Q16: 9.5699318 | S16: 0.19933709 | T16: 1.0561394 | V16: 10.691501 | W16: 10.461066 | X16: 9.2632332 | Z16: 0.11225041
B17: C&A MODAS LTDA | C17: CEAB3 BZ | D17: BRL 16,3 | E17: 0.76525822 | F17: 4864.1072 | G17: 7970.7108 | I17: 0.99354859 | J17: 0.95887097 | K17: 0.87920656 | L17: 6.7791815 | M17: 4.7395337 | N17: 4.3434157 | O17: 16.983784 | P17: 7.5587585 | Q17: 7.4571028 | S17: 0.14655878 | T17: 1.7841119 | V17: 30.17011 | W17: 9.7109504 | X17: 8.7501428 | Z17: 0.1270052
B18: MARISA LOJAS SA | C18: AMAR3 BZ | D18: BRL 1,21 | E18: 0.69142857 | F18: 1248.5127 | G18: 1370.5621 | I18: 0.90734995 | J18: #VALUE! | K18: #VALUE! | L18: 3.9192734 | M18: #VALUE! | N18: #VALUE! | O18: 7.5028991 | P18: #VALUE! | Q18: #VALUE! | S18: 0.23150973 | T18: 1.918656 | V18: -29.764279 | W18: #VALUE! | X18: #VALUE! | Z18: #VALUE!
B19: VESTE SA ESTILO | C19: VSTE3 BZ | D19: BRL 5,24 | E19: 0.4192 | F19: 597.36267 | G19: 1003.5478 | I19: 0.86585215 | J19: 0.83489829 | K19: 0.78771409 | L19: 4.3447952 | M19: 3.9665919 | N19: 3.3340457 | O19: 17.419982 | P19: #VALUE! | Q19: #VALUE! | S19: 0.19928492 | T19: 1.505121 | V19: 388.53868 | W19: 12.709844 | X19: 5.5828287 | Z19: #VALUE!
B21: Mean | I21: =AVERAGE(I15:I19) -> 0.94794142 | J21: =AVERAGE(J15:J19) -> #VALUE! | K21: =AVERAGE(K15:K19) -> #VALUE! | L21: =AVERAGE(L15:L19) -> 5.1481532 | M21: =AVERAGE(M15:M19) -> #VALUE! | N21: =AVERAGE(N15:N19) -> #VALUE! | O21: =AVERAGE(O15:O19) -> 12.095241 | P21: =AVERAGE(P15:P19) -> #VALUE! | Q21: =AVERAGE(Q15:Q19) -> #VALUE! | S21: =AVERAGE(S15:S19) -> 0.18696697 | T21: =AVERAGE(T15:T19) -> 1.6562016 | V21: =AVERAGE(V15:V19) -> 82.017688 | W21: =AVERAGE(W15:W19) -> #VALUE! | X21: =AVERAGE(X15:X19) -> #VALUE! | Z21: =AVERAGE(Z15:Z19) -> #VALUE!
B22: Median | I22: =MEDIAN(I15:I19) -> 0.90734995 | J22: =MEDIAN(J15:J19) -> #VALUE! | K22: =MEDIAN(K15:K19) -> #VALUE! | L22: =MEDIAN(L15:L19) -> 4.3447952 | M22: =MEDIAN(M15:M19) -> #VALUE! | N22: =MEDIAN(N15:N19) -> #VALUE! | O22: =MEDIAN(O15:O19) -> 11.673441 | P22: =MEDIAN(P15:P19) -> #VALUE! | Q22: =MEDIAN(Q15:Q19) -> #VALUE! | S22: =MEDIAN(S15:S19) -> 0.19928492 | T22: =MEDIAN(T15:T19) -> 1.7841119 | V22: =MEDIAN(V15:V19) -> 10.691501 | W22: =MEDIAN(W15:W19) -> #VALUE! | X22: =MEDIAN(X15:X19) -> #VALUE! | Z22: =MEDIAN(Z15:Z19) -> #VALUE!
B24: Tier II: Chips
B27: VULCABRAS SA | C27: VULC3 BZ | D27: BRL 19,93 | E27: 0.88577778 | F27: 5366.783 | G27: 5910.787 | I27: 1.7986074 | J27: 1.6645415 | K27: 1.5192222 | L27: 7.1128005 | M27: 7.6137231 | N27: 7.0646857 | O27: 8.2957483 | P27: 9.0563642 | Q27: 8.4560616 | S27: 0.2528691 | T27: 0.48247073 | V27: 6.6523796 | W27: 9.237148 | X27: 8.4872689 | Z27: #VALUE!
B28: GRENDENE SA | C28: GRND3 BZ | D28: BRL 5,19 | E28: 0.86789298 | F28: 4619.0592 | G28: 3195.018 | I28: 1.1711891 | J28: 1.1711891 | K28: #VALUE! | L28: 5.3147813 | M28: #VALUE! | N28: #VALUE! | O28: 7.0377171 | P28: #VALUE! | Q28: #VALUE! | S28: 0.2203645 | T28: 0.15578822 | V28: 5.3805186 | W28: #VALUE! | X28: #VALUE! | Z28: #VALUE!
B29: ALPARGATAS-PREF | C29: ALPA4 BZ | D29: BRL 9,57 | E29: 0.90625 | F29: 6509.3405 | G29: 6253.2617 | I29: 1.436257 | J29: 1.3926643 | K29: 1.2875498 | L29: 10.576198 | M29: 8.8698747 | N29: 7.3654437 | O29: 18.913457 | P29: 13.927086 | Q29: 10.301914 | S29: 0.13580088 | T29: 1.7550067 | V29: 19.97793 | W29: 15.647453 | X29: 11.674451 | Z29: 0.17178978
B30: GRUPO SBF SA | C30: SBFG3 BZ | D30: BRL 13,23 | E30: 0.80474453 | F30: 3056.9416 | G30: 5010.0952 | I30: 0.68494293 | J30: 0.65948337 | K30: 0.59755778 | L30: 5.0015725 | M30: 4.8681087 | N30: 4.4398869 | O30: 8.9738406 | P30: 7.7475699 | Q30: 6.9419371 | S30: 0.13694552 | T30: 2.5444266 | V30: 8.304191 | W30: 7.7028767 | X30: 6.288155 | Z30: 0.13873099
B31: TRACK & FIELD CO | C31: TFCO4 BZ | D31: BRL 17,13 | E31: 0.97718197 | F31: 2560.2728 | G31: 14182.693 | I31: 15.209273 | J31: 13.659095 | K31: 11.480863 | L31: 58.93249 | M31: 59.926873 | N31: 48.962117 | O31: 69.552327 | P31: 64.761156 | Q31: 52.078433 | S31: 0.2580796 | T31: 0.63576798 | V31: 18.179288 | W31: 15.330975 | X31: 12.865692 | Z31: 0.19781149
B33: Mean | I33: =AVERAGE(I27:I31) -> 4.060054 | J33: =AVERAGE(J27:J31) -> 3.7093946 | K33: =AVERAGE(K27:K31) -> #VALUE! | L33: =AVERAGE(L27:L31) -> 17.387569 | M33: =AVERAGE(M27:M31) -> #VALUE! | N33: =AVERAGE(N27:N31) -> #VALUE! | O33: =AVERAGE(O27:O31) -> 22.554618 | P33: =AVERAGE(P27:P31) -> #VALUE! | Q33: =AVERAGE(Q27:Q31) -> #VALUE! | S33: =AVERAGE(S27:S31) -> 0.20081192 | T33: =AVERAGE(T27:T31) -> 1.114692 | V33: =AVERAGE(V27:V31) -> 11.698861 | W33: =AVERAGE(W27:W31) -> #VALUE! | X33: =AVERAGE(X27:X31) -> #VALUE! | Z33: =AVERAGE(Z27:Z31) -> #VALUE!
B34: Median | I34: =MEDIAN(I27:I31) -> 1.436257 | J34: =MEDIAN(J27:J31) -> 1.3926643 | K34: =MEDIAN(K27:K31) -> #VALUE! | L34: =MEDIAN(L27:L31) -> 7.1128005 | M34: =MEDIAN(M27:M31) -> #VALUE! | N34: =MEDIAN(N27:N31) -> #VALUE! | O34: =MEDIAN(O27:O31) -> 8.9738406 | P34: =MEDIAN(P27:P31) -> #VALUE! | Q34: =MEDIAN(Q27:Q31) -> #VALUE! | S34: =MEDIAN(S27:S31) -> 0.2203645 | T34: =MEDIAN(T27:T31) -> 0.63576798 | V34: =MEDIAN(V27:V31) -> 8.304191 | W34: =MEDIAN(W27:W31) -> #VALUE! | X34: =MEDIAN(X27:X31) -> #VALUE! | Z34: =MEDIAN(Z27:Z31) -> #VALUE!
B36: Tier III: Semiconductors
B39: REDTAPE LTD/INDI | C39: REDTAPE IN | D39: INR 146,2 | E39: 0.59564066 | F39: 80820.471 | G39: 87788.097 | I39: 4.3439885 | J39: #VALUE! | K39: #VALUE! | L39: 26.264988 | M39: #VALUE! | N39: #VALUE! | O39: 35.001833 | P39: #VALUE! | Q39: #VALUE! | S39: 0.16539084 | T39: 2.1586184 | V39: 47.743944 | W39: #VALUE! | X39: #VALUE! | Z39: #VALUE!
B40: LI NING CO LTD | C40: 2331 HK | D40: HKD 17,64 | E40: 0.84 | F40: 45337.585 | G40: 29959.457 | I40: 1.0278703 | J40: 1.0300053 | K40: 0.98325924 | L40: 5.095827 | M40: 5.9159212 | N40: 5.455026 | O40: 7.0173724 | P40: 9.2830378 | Q40: 8.4683203 | S40: 0.20170824 | T40: 0.34660035 | V40: 14.079602 | W40: 17.531757 | X40: 15.566047 | Z40: 0.15737721
B41: TOPSPORTS INTERN | C41: 6110 HK | D41: HKD 3,16 | E41: 0.79777834 | F41: 19719.886 | G41: 21028.02 | I41: 0.77844363 | J41: 0.78705569 | K41: 0.8028853 | L41: 6.6238329 | M41: 6.8461728 | N41: 6.9388836 | O41: 12.266958 | P41: 11.857809 | Q41: 12.630334 | S41: 0.11752163 | T41: 1.3314009 | V41: 14.213017 | W41: 14.075965 | X41: 14.905432 | Z41: 0.071019808
B42: CHINA LILANG LTD | C42: 1234 HK | D42: HKD 3,56 | E42: 0.75648109 | F42: 4131.323 | G42: 3498.5362 | I42: 0.92623582 | J42: 0.86661785 | K42: 0.79530263 | L42: 4.8785517 | M42: #VALUE! | N42: #VALUE! | O42: 6.9506422 | P42: 5.8601947 | Q42: 5.1223078 | S42: 0.18985877 | T42: 1.6165385 | V42: 9.6766867 | W42: 8.2958293 | X42: 7.3120761 | Z42: 0.09898232
B43: DAZZLE FASHION-A | C43: 603587 CH | D43: CNY 12,35 | E43: 0.78562341 | F43: 5855.0459 | G43: 3316.4703 | I43: 1.5381055 | J43: 1.485541 | K43: 1.3789897 | L43: 9.1793236 | M43: 6.2990889 | N43: 5.8183689 | O43: 13.547663 | P43: 8.4388557 | Q43: 7.2018899 | S43: 0.16756197 | T43: #N/A N/A | V43: 25.009604 | W43: 19.419721 | X43: 16.946587 | Z43: 0.26270081
B45: Mean | I45: 1.7229287 | J45: #VALUE! | K45: #VALUE! | L45: 10.408505 | M45: #VALUE! | N45: #VALUE! | O45: 14.956894 | P45: #VALUE! | Q45: #VALUE! | S45: 0.16840829 | T45: 1.3632895 | V45: 22.144571 | W45: #VALUE! | X45: #VALUE! | Z45: #VALUE!
B46: Median | I46: 1.0278703 | J46: #VALUE! | K46: #VALUE! | L46: 6.6238329 | M46: #VALUE! | N46: #VALUE! | O46: 12.266958 | P46: #VALUE! | Q46: #VALUE! | S46: 0.16756197 | T46: 1.4739697 | V46: 14.213017 | W46: #VALUE! | X46: #VALUE! | Z46: #VALUE!
B48: Overall
B51: Mean | I51: 2.2436414 | J51: #VALUE! | K51: #VALUE! | L51: 10.981409 | M51: #VALUE! | N51: #VALUE! | O51: 16.535584 | P51: #VALUE! | Q51: #VALUE! | S51: 0.18539572 | T51: 1.3791162 | V51: 38.620373 | W51: #VALUE! | X51: #VALUE! | Z51: #VALUE!
B52: Median | I52: 1.0278703 | J52: #VALUE! | K52: #VALUE! | L52: 6.6238329 | M52: #VALUE! | N52: #VALUE! | O52: 11.673441 | P52: #VALUE! | Q52: #VALUE! | S52: 0.18985877 | T52: 1.5608298 | V52: 14.079602 | W52: #VALUE! | X52: #VALUE! | Z52: #VALUE!
B54: High | I54: 15.209273 | J54: #VALUE! | K54: #VALUE! | L54: 58.93249 | M54: #VALUE! | N54: #VALUE! | O54: 69.552327 | P54: #VALUE! | Q54: #VALUE! | R54: 0 | S54: 0.2580796 | T54: 2.5444266 | V54: 388.53868 | W54: #VALUE! | X54: #VALUE! | Z54: #VALUE!
B55: Low | I55: 0.61216933 | J55: #VALUE! | K55: #VALUE! | L55: 3.8709538 | M55: #VALUE! | N55: #VALUE! | O55: 6.8960986 | P55: #VALUE! | Q55: #VALUE! | R55: 0 | S55: 0.11752163 | T55: 0.15578822 | V55: -29.764279 | W55: #VALUE! | X55: #VALUE! | Z55: #VALUE!

Sheet WACC
A7: x | B7: Rolling WACC | K7: Equity Risk Premium
P8: Weights
D9: 2025 | E9: =+D9+1 -> 2026 | F9: =+E9+1 -> 2027 | G9: =+F9+1 -> 2028 | H9: =+G9+1 -> 2029 | M9: ERP | N9: 2025 | O9: =+N9+1 -> 2026 | P9: =+O9+1 -> 2027 | Q9: =+P9+1 -> 2028 | R9: =+Q9+1 -> 2029
B12: Equity: | K12: =+Segments!B73 -> Brazil | M12: 0.0767 | N12: =+Segments!AL73/Segments!AL$78 -> 0.90189679 | O12: =+Segments!AR73/Segments!AR$78 -> 0.90189679 | P12: =+Segments!AT73/Segments!AT$78 -> 0.90189679 | Q12: =+Segments!AR73/Segments!AR$78 -> 0.90189679 | R12: =+Segments!AT73/Segments!AT$78 -> 0.90189679
B13: Market Cap (in billions) | D13: =+Inputs!J13 -> 6655.1666 | E13: =+FCFF!AF96*FCFF!AF26 -> 9949.7514 | F13: =+FCFF!AH96*FCFF!AH26 -> 12747.935 | G13: =+FCFF!AJ96*FCFF!AJ26 -> 15810.109 | H13: =+FCFF!AL96*FCFF!AL26 -> 14822.077 | K13: =+Segments!B74 -> Rest of the World | M13: 0.05 | N13: =+Segments!AL74/Segments!AL$78 -> 0.098103214 | O13: =+Segments!AR74/Segments!AR$78 -> 0.098103214 | P13: =+Segments!AT74/Segments!AT$78 -> 0.098103214 | Q13: =+Segments!AR74/Segments!AR$78 -> 0.098103214 | R13: =+Segments!AT74/Segments!AT$78 -> 0.098103214
B14: % of Equity | D14: =IFERROR(D13/D35,"") -> 0.63400982 | E14: =IFERROR(E13/E35,"") -> 0.73977214 | F14: =IFERROR(E13/F35,"") -> 0.62388964 | G14: =IFERROR(F13/G35,"") -> 0.67771721 | H14: =IFERROR(G13/H35,"") -> 0.8971763 | K14: =+Segments!B75 -> 0 | N14: =+Segments!AL75/Segments!AL$78 -> 0 | O14: =+Segments!AR75/Segments!AR$78 -> 0 | P14: =+Segments!AT75/Segments!AT$78 -> 0 | Q14: =+Segments!AR75/Segments!AR$78 -> 0 | R14: =+Segments!AT75/Segments!AT$78 -> 0
B15: Risk-Free Rate | D15: 0.1351 | E15: 0.1351 | F15: 0.1351 | G15: 0.1351 | H15: 0.1351 | K15: =+Segments!B76 -> 0 | N15: =+Segments!AL76/Segments!AL$78 -> 0 | O15: =+Segments!AR76/Segments!AR$78 -> 0 | P15: =+Segments!AT76/Segments!AT$78 -> 0 | Q15: =+Segments!AR76/Segments!AR$78 -> 0 | R15: =+Segments!AT76/Segments!AT$78 -> 0
B16: Beta | D16: =+Inputs!M18 -> 1.166738 | E16: =+D17*(1+(E28/E13)*(1-E32)) -> 0.85634402 | F16: =+E17*(1+(F28/F13)*(1-F32)) -> 0.80650589 | G16: =+F17*(1+(G28/G13)*(1-G32)) -> 0.77619681 | H16: =+G17*(1+(H28/H13)*(1-H32)) -> 0.77577899 | K16: =+Segments!B77 -> 0 | N16: =+Segments!AL77/Segments!AL$78 -> 0 | O16: =+Segments!AR77/Segments!AR$78 -> 0 | P16: =+Segments!AT77/Segments!AT$78 -> 0 | Q16: =+Segments!AR77/Segments!AR$78 -> 0 | R16: =+Segments!AT77/Segments!AT$78 -> 0
B17: Unlevered Beta | D17: =+D16/(1+(D28/D13)*(1-D32)) -> 0.68232871 | E17: =+E16/(1+(E28/E13)*(1-E32)) -> 0.68232871 | F17: =+F16/(1+(F28/F13)*(1-F32)) -> 0.68232871 | G17: =+G16/(1+(G28/G13)*(1-G32)) -> 0.68232871 | H17: =+H16/(1+(H28/H13)*(1-H32)) -> 0.68232871
B18: Equity Risk Premium | D18: =+N18 -> 0.074080644 | E18: =+O18 -> 0.074080644 | F18: =+P18 -> 0.074080644 | G18: =+Q18 -> 0.074080644 | H18: =+R18 -> 0.074080644 | K18: ERP | N18: =+SUMPRODUCT($M12:$M16,N12:N16) -> 0.074080644 | O18: =+SUMPRODUCT($M12:$M16,O12:O16) -> 0.074080644 | P18: =+SUMPRODUCT($M12:$M16,P12:P16) -> 0.074080644 | Q18: =+SUMPRODUCT($M12:$M16,Q12:Q16) -> 0.074080644 | R18: =+SUMPRODUCT($M12:$M16,R12:R16) -> 0.074080644
B19: Ke (Cost of Equity) | D19: =IFERROR(+D15+D16*D18,"") -> 0.2215327 | E19: =IFERROR(+E15+E16*E18,"") -> 0.19853852 | F19: =IFERROR(+F15+F16*F18,"") -> 0.19484648 | G19: =IFERROR(+G15+G16*G18,"") -> 0.19260116 | H19: =IFERROR(+H15+H16*H18,"") -> 0.19257021
B21: Preferred Equity: | K21: ROIC vs WACC
B22: Market Capitalization | D22: =IFERROR(Inputs!J14,0) -> 0 | E22: =+D22*(E13/D13) -> 0 | F22: =+E22*(F13/E13) -> 0 | G22: =+F22*(G13/F13) -> 0 | H22: =+G22*(H13/G13) -> 0
B23: % of Preferred Equity | D23: =+D22/D35 -> 0 | E23: =+E22/E35 -> 0 | F23: =+F22/F35 -> 0 | G23: =+G22/G35 -> 0 | H23: =+H22/H35 -> 0
B24: Preferred Dividends | D24: =+IS!AF50 -> 0 | E24: =D24 -> 0 | F24: =E24 -> 0 | G24: =F24 -> 0 | H24: =G24 -> 0
B25: Kp (Cost of Preferred Equity) | D25: =IFERROR(D24/D22,0) -> 0 | E25: =IFERROR(E24/E22,0) -> 0 | F25: =IFERROR(F24/F22,0) -> 0 | G25: =IFERROR(G24/G22,0) -> 0 | H25: =IFERROR(H24/H22,0) -> 0
B27: Debt:
B28: Debt (in millions) | C28: =+BS!AF38+BS!AF39+BS!AF44+BS!AF45 -> 3530.401 | D28: =+BS!AI38+BS!AI39+BS!AI44+BS!AI45 -> 3841.779 | E28: 3500 | F28: 3200 | G28: 3000 | H28: 2800
B29: % of Debt | D29: =IFERROR(D28/D35,"") -> 0.36599018 | E29: =IFERROR(E28/E35,"") -> 0.26022786 | F29: =IFERROR(F28/F35,"") -> 0.20065294 | G29: =IFERROR(G28/G35,"") -> 0.1594887 | H29: =IFERROR(H28/H35,"") -> 0.1588916
B30: Debt Spread | D30: =+D31-D15 -> -0.07319899 | E30: 0.1 | F30: 0.1 | G30: 0.1 | H30: 0.1
B31: Cost of Debt | D31: =+IS!AF36/WACC!D28 -> 0.06190101 | E31: =+E30+E15 -> 0.2351 | F31: =+F30+F15 -> 0.2351 | G31: =+G30+G15 -> 0.2351 | H31: =+H30+H15 -> 0.2351
B32: Tax Rate | D32: =+FCFF!Z121 -> -0.22983083 | E32: =+FCFF!AF121 -> 0.275 | F32: =+FCFF!AH121 -> 0.275 | G32: =+FCFF!AJ121 -> 0.275 | H32: =+FCFF!AL121 -> 0.275
B33: Kd (After-Tax Cost of Debt) | D33: =+D31*(1-D32) -> 0.07612777 | E33: =+E31*(1-E32) -> 0.1704475 | F33: =+F31*(1-F32) -> 0.1704475 | G33: =+G31*(1-G32) -> 0.1704475 | H33: =+H31*(1-H32) -> 0.1704475
B35: Total | D35: =+D13+D24+D28 -> 10496.946 | E35: =+E13+E24+E28 -> 13449.751 | F35: =+F13+F24+F28 -> 15947.935 | G35: =+G13+G24+G28 -> 18810.109 | H35: =+H13+H24+H28 -> 17622.077
B37: Country/Conglomerate/... Risk Premium | D37: 0.0075 | E37: 0.0075 | F37: 0.0075 | G37: 0.0075 | H37: 0.0075
A39: x | B39: WACC | D39: =+D19*D14+D25*D23+D33*D29+D37+Sensitivity!$U$41 -> 0.17581593 | E39: =+E19*E14+E25*E23+E33*E29+E37+Sensitivity!$U$41 -> 0.19872845 | F39: =+F19*F14+F25*F23+F33*F29+F37+Sensitivity!$U$41 -> 0.16326349 | G39: =+G19*G14+G25*G23+G33*G29+G37+Sensitivity!$U$41 -> 0.16521357 | H39: =+H19*H14+H25*H23+H33*H29+H37+Sensitivity!$U$41 -> 0.2073521
B41: NOPAT | D41: =+FCFF!Z123 -> 2435.8221 | E41: =+FCFF!AF123 -> 1679.0775 | F41: =+FCFF!AH123 -> 2370.2417 | G41: =+FCFF!AJ123 -> 2948.6842 | H41: =+FCFF!AL123 -> 3371.1755
B42: Total Payout | D42: =+FCFF!Z109+FCFF!Z112 -> 793.01717 | E42: =+FCFF!AF109+FCFF!AF112 -> -18 | F42: =+FCFF!AH109+FCFF!AH112 -> -610.56044 | G42: =+FCFF!AJ110+FCFF!AJ112 -> -17.7 | H42: =+FCFF!AL110+FCFF!AL112 -> -17.7
B43: Book Value of Equity | C43: =+BS!AF54 -> 7721.515 | D43: =+C43+D41+D42 -> 10950.354 | E43: =+D43+E41+E42 -> 12611.432 | F43: =+E43+F41+F42 -> 14371.113 | G43: =+F43+G41+G42 -> 17302.097 | H43: =+G43+H41+H42 -> 20655.573
B44: Invested Capital | C44: =+C43+C28 -> 11251.916 | D44: =+D43+D28 -> 14792.133 | E44: =+E43+E28 -> 16111.432 | F44: =+F43+F28 -> 17571.113 | G44: =+G43+G28 -> 20302.097 | H44: =+H43+H28 -> 23455.573
A45: x | B45: ROIC | D45: =+D41/((D44+C44)/2) -> 0.18705402 | E45: =+E41/((E44+D44)/2) -> 0.10866562 | F45: =+F41/((F44+E44)/2) -> 0.14074006 | G45: =+G41/((G44+F44)/2) -> 0.15571346 | H45: =+H41/((H44+G44)/2) -> 0.15408387
W49: ,

Sheet FCFF
A7: x | B7: Market Assumptions
D8: 2022 | J8: =D8+1 -> 2023 | P8: =J8+1 -> 2024 | V8: =P8+1 -> 2025 | AB8: =V8+1 -> 2026 | AH8: =AB8+1 -> 2027 | AJ8: =+AH8+1 -> 2028 | AL8: =+AJ8+1 -> 2029
D9: Q1 | E9: Q2 | F9: Q3 | G9: Q4 | H9: FY | J9: Q1 | K9: Q2 | L9: Q3 | M9: Q4 | N9: FY | P9: Q1 | Q9: Q2 | R9: Q3 | S9: Q4 | T9: FY | V9: Q1 | W9: Q2 | X9: Q3 | Y9: Q4 | Z9: FY | AB9: Q1 | AC9: Q2 | AD9: Q3 | AE9: Q4 | AF9: FY | AH9: FY | AJ9: FY | AL9: FY
B11: Shoes & Bags | D11: =$H$11*0.25 -> 707.416 | E11: =$H$11*0.25 -> 707.416 | F11: =$H$11*0.25 -> 707.416 | G11: =$H$11*0.25 -> 707.416 | H11: =Segments!T13 -> 2829.664 | J11: =$N$11*0.25 -> 1141.45 | K11: =$N$11*0.25 -> 1141.45 | L11: =$N$11*0.25 -> 1141.45 | M11: =$N$11*0.25 -> 1141.45 | N11: =Segments!Z13 -> 4565.8 | P11: =$T$11*0.25 -> 1196.3 | Q11: =$T$11*0.25 -> 1196.3 | R11: =$T$11*0.25 -> 1196.3 | S11: =$T$11*0.25 -> 1196.3 | T11: =Segments!AF13 -> 4785.2 | V11: =$Z$11*0.25 -> 1064.6742 | W11: =$Z$11*0.25 -> 1064.6742 | X11: =$Z$11*0.25 -> 1064.6742 | Y11: =$Z$11*0.25 -> 1064.6742 | Z11: =Segments!AL13 -> 4258.697 | AB11: =$AF$11*0.25 -> 1143.7974 | AC11: =$AF$11*0.25 -> 1143.7974 | AD11: =$AF$11*0.25 -> 1143.7974 | AE11: =$AF$11*0.25 -> 1143.7974 | AF11: =Segments!AR13 -> 4575.1898 | AH11: =Segments!AT13 -> 4859.887 | AJ11: =Segments!AV13 -> 5107.1826 | AL11: =Segments!AX13 -> 5308.4232 | AS11: 2022 | AT11: =+AS11+1 -> 2023 | AU11: =+AT11+1 -> 2024 | AV11: =+AU11+1 -> 2025 | AW11: =+AV11+1 -> 2026 | AX11: =+AW11+1 -> 2027 | AY11: =+AX11+1 -> 2028 | AZ11: =+AY11+1 -> 2029
B12: Fashion & Lifestyle Women | D12: =$H$12*0.227 -> 1002.3412 | E12: =$H$12*0.227 -> 1002.3412 | F12: =H12*0.26 -> 1148.056 | G12: =H12*0.286 -> 1262.8616 | H12: =Segments!T27 -> 4415.6 | J12: =$N$12*0.227 -> 931.5853 | K12: =$N$12*0.227 -> 931.5853 | L12: =N12*0.26 -> 1067.014 | M12: =N12*0.286 -> 1173.7154 | N12: =Segments!Z27 -> 4103.9 | P12: =T12*0.228 -> 1090.3188 | Q12: =T12*0.228 -> 1090.3188 | R12: 1241.6 | S12: 1362.9 | T12: =Segments!AF27 -> 4782.1 | V12: =$Z$12*0.227 -> 1279.0658 | W12: =$Z$12*0.227 -> 1279.0658 | X12: =Z12*0.26 -> 1465.0093 | Y12: =Z12*0.286 -> 1611.5102 | Z12: =Segments!AL27 -> 5634.651 | AB12: =AF12*0.227 -> 1482.3705 | AC12: =AF12*0.227 -> 1482.3705 | AD12: =AF12*0.26 -> 1697.8693 | AE12: =AF12*0.286 -> 1867.6562 | AF12: =Segments!AR27 -> 6530.2666 | AH12: =Segments!AT27 -> 7437.1189 | AJ12: =Segments!AV27 -> 8316.3496 | AL12: =Segments!AX27 -> 9124.7281 | AR12: EBITDA | AS12: =H58+H125 -> 735.73 | AT12: =N58+N125 -> 810.844 | AU12: =T58+T125 -> 1045.455 | AV12: =Z58+Z125 -> 2439.1925 | AW12: =AF58+AF125 -> 2870.0478 | AX12: =AH58+AH125 -> 3949.6079 | AY12: =AJ58+AJ125 -> 4776.7937 | AZ12: =AL58+AL125 -> 5387.0327
B13: Basic | D13: =H13*0.24 -> 559.296 | E13: =H13*0.24 -> 559.296 | F13: =H13*0.26 -> 605.904 | G13: =H13*0.27 -> 629.208 | H13: =Segments!T41 -> 2330.4 | J13: =$N$13*0.24 -> 621.048 | K13: =$N$13*0.24 -> 621.048 | L13: =N13*0.26 -> 672.802 | M13: =N13*0.27 -> 698.679 | N13: =Segments!Z41 -> 2587.7 | P13: =T13*0.24 -> 670.56 | Q13: =T13*0.24 -> 670.56 | R13: 713 | S13: 757 | T13: =Segments!AF41 -> 2794 | V13: =$Z$13*0.24 -> 731.45376 | W13: =$Z$13*0.24 -> 731.45376 | X13: =Z13*0.26 -> 792.40824 | Y13: =Z13*0.27 -> 822.88548 | Z13: =Segments!AL41 -> 3047.724 | AB13: =AF13*0.24 -> 800.47414 | AC13: =AF13*0.24 -> 800.47414 | AD13: =AF13*0.26 -> 867.18032 | AE13: =AF13*0.27 -> 900.5334 | AF13: =Segments!AR41 -> 3335.3089 | AH13: =Segments!AT41 -> 3623.619 | AJ13: =Segments!AV41 -> 3906.7965 | AL13: =Segments!AX41 -> 4178.4062 | AR13: FCFF | AS13: =H133 -> 122.33043 | AT13: =N133 -> 516.80594 | AU13: =T133 -> 842.61658 | AV13: =Z133 -> 228.89892 | AW13: =AF133 -> 1780.1075 | AX13: =AH133 -> 2450.9435 | AY13: =AJ133 -> 3604.217 | AZ13: =AL133 -> 3584.1406
B14: Fashion & Lifestyle Men | D14: =$H$14*0.223 -> 290.9258 | E14: =$H$14*0.223 -> 290.9258 | F14: =H14*0.26 -> 339.196 | G14: =H14*0.3 -> 391.38 | H14: =Segments!T55 -> 1304.6 | J14: =$N$14*0.223 -> 338.1126 | K14: =$N$14*0.223 -> 338.1126 | L14: =N14*0.26 -> 394.212 | M14: =N14*0.3 -> 454.86 | N14: =Segments!Z55 -> 1516.2 | P14: =$T$14*0.223 -> 400.2627 | Q14: =$T$14*0.223 -> 400.2627 | R14: 467.9 | S14: 525.3 | T14: =Segments!AF55 -> 1794.9 | V14: =Z14*0.223 -> 443.92521 | W14: =Z14*0.223 -> 443.92521 | X14: =Z14*0.26 -> 517.58096 | Y14: =Z14*0.3 -> 597.2088 | Z14: =Segments!AL55 -> 1990.696 | AB14: =AF14*0.223 -> 477.7003 | AC14: =AF14*0.223 -> 477.7003 | AD14: =AF14*0.26 -> 556.95999 | AE14: =AF14*0.3 -> 642.64615 | AF14: =Segments!AR55 -> 2142.1538 | AH14: =Segments!AT55 -> 2290.7106 | AJ14: =Segments!AV55 -> 2432.3082 | AL14: =Segments!AX55 -> 2562.8377 | AR14: Revenue Growth | AS14: =H27 -> 0.37093191 | AT14: =N27 -> 0.17401563 | AU14: =T27 -> 0.10823887 | AV14: =Z27 -> 0.054786454 | AW14: =AF27 -> 0.11057974 | AX14: =AH27 -> 0.098198423 | AY14: =+AJ27 -> 0.085183277 | AZ14: =+AL27 -> 0.071435728
B16: Revenue | D16: =SUM(D11:D15) -> 2559.979 | E16: =SUM(E11:E15) -> 2559.979 | F16: =SUM(F11:F15) -> 2800.572 | G16: =SUM(G11:G15) -> 2990.8656 | H16: =SUM(H11:H15) -> 10880.264 | I16: =SUM(I11:I15) -> 0 | J16: =SUM(J11:J15) -> 3032.1959 | K16: =SUM(K11:K15) -> 3032.1959 | ... AL16: =SUM(AL11:AL15) -> 21174.395
A18: x | B18: Operating Assumptions
D19: =D$8 -> 2022 | E19: =F19 -> 0 | F19: =F$8 -> 0 | G19: =F19 -> 0 | H19: =F19 -> 0 | J19: =J$8 -> 2023 | K19: =L19 -> 0 | L19: =L$8 -> 0 | M19: =L19 -> 0 | N19: =L19 -> 0 | P19: =P$8 -> 2024 | Q19: =R19 -> 0 | R19: =R$8 -> 0 | S19: =R19 -> 0 | T19: =R19 -> 0 | V19: =V$8 -> 2025 | W19: =X19 -> 0 | X19: =X$8 -> 0 | Y19: =X19 -> 0 | Z19: =X19 -> 0 | AB19: =AB$8 -> 2026 | AC19: =AD19 -> 0 | AD19: =AD$8 -> 0 | AE19: =AD19 -> 0 | AF19: =AD19 -> 0 | AH19: =AH$8 -> 2027 | AJ19: =AJ$8 -> 2028 | AL19: =AL$8 -> 2029 | AM19: =AN19 -> 0
D20: Q1 | E20: Q2 | F20: Q3 | G20: Q4 | H20: FY | J20: Q1 | K20: Q2 | L20: Q3 | M20: Q4 | N20: FY | P20: Q1 | Q20: Q2 | R20: Q3 | S20: Q4 | T20: FY | V20: Q1 | W20: Q2 | X20: Q3 | Y20: Q4 | Z20: FY | AB20: Q1 | AC20: Q2 | AD20: Q3 | AE20: Q4 | AF20: FY | AH20: FY | AJ20: FY | AL20: FY
B23: Income Statement
B26: Gross Sales | D26: =D16 -> 2559.979 | E26: =E16 -> 2559.979 | F26: =F16 -> 2800.572 | G26: =G16 -> 2990.8656 | H26: =H16 -> 10880.264 | J26: =J16 -> 3032.1959 | K26: =K16 -> 3032.1959 | L26: =L16 -> 3275.478 | M26: =M16 -> 3468.7044 | N26: =N16 -> 12773.6 | P26: =P16 -> 3357.4415 | Q26: =Q16 -> 3357.4415 | R26: =R16 -> 3618.8 | S26: =S16 -> 3841.5 | T26: =T16 -> 14156.2 | V26: =V16 -> 3519.119 | W26: =W16 -> 3519.119 | X26: =X16 -> 3839.6727 | Y26: =Y16 -> 4096.2787 | Z26: =Z16 -> 14931.768 | AA26: =AA16 -> 0 | AB26: =AB16 -> 3904.3424 | AC26: =AC16 -> 3904.3424 | ... AL26: =AL16 -> 21174.395
B27: % of growth | H27: =H26/Segments!N70-1 -> 0.37093191 | J27: =J26/D26-1 -> 0.18446124 | K27: =K26/E26-1 -> 0.18446124 | L27: =L26/F26-1 -> 0.16957464 | M27: =M26/G26-1 -> 0.15976606 | N27: =N26/H26-1 -> 0.17401563 | P27: =P26/J26-1 -> 0.10726405 | Q27: =Q26/K26-1 -> 0.10726405 | R27: =R26/L26-1 -> 0.10481585 | S27: =S26/M26-1 -> 0.10747402 | T27: =T26/N26-1 -> 0.10823887 | V27: =V26/P26-1 -> 0.04815497 | W27: =W26/Q26-1 -> 0.04815497 | X27: =X26/R26-1 -> 0.061034793 | Y27: =Y26/S26-1 -> 0.066322717 | Z27: =Z26/T26-1 -> 0.054786454 | AB27: =AB26/V26-1 -> 0.10946586 | AC27: =AC26/W26-1 -> 0.10946586 | AD27: =AD26/X26-1 -> 0.11098195 | AE27: =AE26/Y26-1 -> 0.11189535 | AF27: =AF26/Z26-1 -> 0.11057974 | AH27: =AH26/AF26-1 -> 0.098198423 | AJ27: =AJ26/AH26-1 -> 0.085183277 | AL27: =AL26/AJ26-1 -> 0.071435728
B28: Net Sales | H28: 4233.7 | N28: 4846.8 | T28: 8379.8 | Z28: =Z26*Z29 -> 9556.3315 | AF28: =AF26*AF29 -> 10944.727 | AH28: =AH26*AH29 -> 12383.708 | AJ28: =AJ26*AJ29 -> 13833.846 | AL28: =AL26*AL29 -> 15245.565
B29: % of gross sales | H29: =H28/H26 -> 0.3891174 | N29: =N28/N26 -> 0.37943884 | T29: =T28/T26 -> 0.59195264 | Z29: 0.64 | AF29: 0.66 | AH29: 0.68 | AJ29: 0.7 | AL29: 0.72
