Workbook
Name COOLFUCNTION: _xlfn.LAMBDA(_xldudf_BOARDFLARE_EXEC("workbook-settings:coolfucntion"))
Name COOLFUCNTION: _xlfn.LAMBDA(_xldudf_BOARDFLARE_EXEC("workbook-settings:coolfucntion"))
Name COOLFUCNTION: _xlfn.LAMBDA(_xldudf_BOARDFLARE_EXEC("workbook-settings:coolfucntion"))
Name COOLFUCNTION: _xlfn.LAMBDA(_xldudf_BOARDFLARE_EXEC("workbook-settings:coolfucntion"))
Name COOLFUCNTION: _xlfn.LAMBDA(_xldudf_BOARDFLARE_EXEC("workbook-settings:coolfucntion"))
Name COOLFUCNTION: _xlfn.LAMBDA(_xldudf_BOARDFLARE_EXEC("workbook-settings:coolfucntion"))
Name COOLFUCNTION: _xlfn.LAMBDA(_xldudf_BOARDFLARE_EXEC("workbook-settings:coolfucntion"))
Name COOLFUCNTION: _xlfn.LAMBDA(_xldudf_BOARDFLARE_EXEC("workbook-settings:coolfucntion"))
Name COOLFUCNTION: _xlfn.LAMBDA(_xldudf_BOARDFLARE_EXEC("workbook-settings:coolfucntion"))
Name COOLFUCNTION: _xlfn.LAMBDA(_xldudf_BOARDFLARE_EXEC("workbook-settings:coolfucntion"))
Name COOLFUCNTION: _xlfn.LAMBDA(_xldudf_BOARDFLARE_EXEC("workbook-settings:coolfucntion"))
Name Sectors: #REF!
Name Sectors: #REF!
Name Sectors: #REF!
Name Sectors: #REF!
Name Sectors: #REF!
Name Sectors: #REF!
Name Sectors: #REF!
Name Sectors: #REF!

Sheet Dashboard
C154: =+C155+1 -> 45979
C155: =+C156+1 -> 45978
C156: =+C157+1 -> 45977
C157: =+C158+1 -> 45976
C158: =+C159+1 -> 45975
C159: =+C160+1 -> 45974
C160: =+C161+1 -> 45973 | L160: =IF(FCFF!$R$157="Revenue Exit",FCFF!$AF$169,IF(FCFF!$R$157="EBITDA Exit",FCFF!Z169,FCFF!AL169)) -> #VALUE!
C161: =+C162+1 -> 45972
C162: =+C163+1 -> 45971 | E162: =IF(FCFF!$R$157="Revenue Exit",FCFF!$AF$169,IF(FCFF!$R$157="EBITDA Exit",FCFF!Z169,FCFF!AL169)) -> #VALUE!
C163: =+C164+1 -> 45970 | E163: =E164+($E$162-$E$193)/COUNTA($C$162:$C$192) -> #VALUE!
C164: =+C165+1 -> 45969 | E164: =E165+($E$162-$E$193)/COUNTA($C$162:$C$192) -> #VALUE!
C165: =+C166+1 -> 45968 | E165: =E166+($E$162-$E$193)/COUNTA($C$162:$C$192) -> #VALUE!
C166: =+C167+1 -> 45967 | E166: =E167+($E$162-$E$193)/COUNTA($C$162:$C$192) -> #VALUE!
C167: =+C168+1 -> 45966 | E167: =E168+($E$162-$E$193)/COUNTA($C$162:$C$192) -> #VALUE!
C168: =+C169+1 -> 45965 | E168: =E169+($E$162-$E$193)/COUNTA($C$162:$C$192) -> #VALUE!
C169: =+C170+1 -> 45964 | E169: =E170+($E$162-$E$193)/COUNTA($C$162:$C$192) -> #VALUE!
C170: =+C171+1 -> 45963 | E170: =E171+($E$162-$E$193)/COUNTA($C$162:$C$192) -> #VALUE!
C171: =+C172+1 -> 45962 | E171: =E172+($E$162-$E$193)/COUNTA($C$162:$C$192) -> #VALUE!
C172: =+C173+1 -> 45961 | E172: =E173+($E$162-$E$193)/COUNTA($C$162:$C$192) -> #VALUE!
C173: =+C174+1 -> 45960 | E173: =E174+($E$162-$E$193)/COUNTA($C$162:$C$192) -> #VALUE!
C174: =+C175+1 -> 45959 | E174: =E175+($E$162-$E$193)/COUNTA($C$162:$C$192) -> #VALUE!
... C192: =+C193+1 -> 45941 | E192: =E193+($E$162-$E$193)/COUNTA($C$162:$C$192) -> #VALUE!
B193: TODAY | C193: =+'Stock Data'!AM4 -> 45940 | D193: =_xlfn.XLOOKUP(C193,'Stock Data'!$AM$4:$AM$1051,'Stock Data'!$AN$4:$AN$1051) -> 111.54 | E193: =D193 -> 111.54
C194: =+'Stock Data'!AM5 -> 45939 | D194: =_xlfn.XLOOKUP(C194,'Stock Data'!$AM$4:$AM$1051,'Stock Data'!$AN$4:$AN$1051) -> 111.54
C195: =+'Stock Data'!AM6 -> 45938 | D195: =_xlfn.XLOOKUP(C195,'Stock Data'!$AM$4:$AM$1051,'Stock Data'!$AN$4:$AN$1051) -> 113.83
C196: =+'Stock Data'!AM7 -> 45937 | D196: =_xlfn.XLOOKUP(C196,'Stock Data'!$AM$4:$AM$1051,'Stock Data'!$AN$4:$AN$1051) -> 113.83
C197: =+'Stock Data'!AM8 -> 45936 | D197: =_xlfn.XLOOKUP(C197,'Stock Data'!$AM$4:$AM$1051,'Stock Data'!$AN$4:$AN$1051) -> 113.83
C198: =+'Stock Data'!AM9 -> 45935 | D198: =_xlfn.XLOOKUP(C198,'Stock Data'!$AM$4:$AM$1051,'Stock Data'!$AN$4:$AN$1051) -> 113.07
C199: =+'Stock Data'!AM10 -> 45934 | D199: =_xlfn.XLOOKUP(C199,'Stock Data'!$AM$4:$AM$1051,'Stock Data'!$AN$4:$AN$1051) -> 110.6
C200: =+'Stock Data'!AM11 -> 45933 | D200: =_xlfn.XLOOKUP(C200,'Stock Data'!$AM$4:$AM$1051,'Stock Data'!$AN$4:$AN$1051) -> 116.01
C201: =+'Stock Data'!AM12 -> 45932 | D201: =_xlfn.XLOOKUP(C201,'Stock Data'!$AM$4:$AM$1051,'Stock Data'!$AN$4:$AN$1051) -> 115.64
C202: =+'Stock Data'!AM13 -> 45931 | D202: =_xlfn.XLOOKUP(C202,'Stock Data'!$AM$4:$AM$1051,'Stock Data'!$AN$4:$AN$1051) -> 115.64
C203: =+'Stock Data'!AM14 -> 45930 | D203: =_xlfn.XLOOKUP(C203,'Stock Data'!$AM$4:$AM$1051,'Stock Data'!$AN$4:$AN$1051) -> 115.64
C204: =+'Stock Data'!AM15 -> 45929 | D204: =_xlfn.XLOOKUP(C204,'Stock Data'!$AM$4:$AM$1051,'Stock Data'!$AN$4:$AN$1051) -> 115.64
C205: =+'Stock Data'!AM16 -> 45928 | D205: =_xlfn.XLOOKUP(C205,'Stock Data'!$AM$4:$AM$1051,'Stock Data'!$AN$4:$AN$1051) -> 115.4
... C558: =+'Stock Data'!AM369 -> 45575 | D558: =_xlfn.XLOOKUP(C558,'Stock Data'!$AM$4:$AM$1051,'Stock Data'!$AN$4:$AN$1051) -> 68.45

Sheet Key Info
B7: Analysts | F7: LIS – Equity Research | J7: Stock Performance
B12: NAME, Co-Head of Equity Research | F12: Recommendation: | H12: Hold
B13: Bsc in XXX, ISEG – Ulisboa | F13: Target Price (FCFF):
B14: email@aln.iseg.ulisboa.pt | F14: Upside:
B15: Martim de Sousa Patinho, Analyst
B16: Bsc in Economics, ISEG – Ulisboa | F16: Ticker
B17: l61952@aln.iseg.ulisboa.pt | F17: Stock Exchange
B18: NAME, Analyst
B19: Bsc in XXX, ISEG – Ulisboa | F19: Current Price | H19: ='Stock Data'!AN4 -> 111.54
B20: email@aln.iseg.ulisboa.pt | F20: ="Market Cap (in "&IF(Inputs!$D$14="BLN","billions",IF(Inputs!$D$14="MLN","millions","thousands"))&")" -> Market Cap (in thousands) | H20: ='Stock Data'!AQ4 -> 5409408.6
B21: NAME, Analyst | F21: Beta | H21: ='Stock Data'!E164 -> 0.70151639
B22: Bsc in XXX, ISEG – Ulisboa | F22: % of 52-Week High | H22: ='Stock Data'!E165 -> 0.73278931
B23: email@aln.iseg.ulisboa.pt | F23: 100-Day Moving Average | H23: ='Stock Data'!E166 -> 102.31285
B25: Reviewed by: | F25: Avg Vol (1 month) | H25: ='Stock Data'!E168 -> 724438.06
B26: NAME, Analyst | F26: Shares Outstanding (millions) | H26: ='Stock Data'!E169 -> 48.49748
B27: Bsc in XXX, ISEG – Ulisboa | F27: % Float | H27: ='Stock Data'!E170 -> 0.868456
B28: email@aln.iseg.ulisboa.pt | F28: Short % of Float | H28: =IFERROR('Stock Data'!E171,0) -> 0.1161959
B30: LISBON INVESTMENT SOCIETY | F30: % Held by Insiders | H30: ='Stock Data'!E173 -> 0.035214593
B31: ISEG – Rua do Quelhas, 6 | F31: % Held by Institutions | H31: ='Stock Data'!E174 -> 1.1210906
B32: lis@iseg.ulisboa.pt
B34: Disclaimer: This report was prepared by members of the Lisbon Investment Society (LIS), an independent, student-led, non-profit organization based at ISEG – Lisbon School of Economics & Management, and is intended solely for academic and educational purposes. All analyses, forecasts, and opinions expressed in this report reflect the independent judgment of the authors as of the date of publication and are subject to change without notice. The views presented herein do not represent those of ISEG, its faculty, or any affiliated entity. This document does not constitute, and should not be interpreted as, investment advice, an offer, or a solicitation to buy or sell any security or financial instrument. Nothing in this report should be construed as a recommendation to make or refrain from making any investment decision. The content is intended for informational purposes only, and readers are strongly encouraged to conduct their own research and seek advice from a qualified financial professional before making any financial decisions. The information contained in this report has been obtained from publicly available sources believed to be reliable; however, no representation or warranty is made regarding the accuracy, completeness, or timeliness of such information. LIS and its members accept no liability whatsoever for any direct or indirect loss arising from the use of this report or its contents. This report incorporates terminology, financial metrics, and methodologies commonly used in professional equity research, including but not limited to Discounted Cash Flow (DCF), trading multiples, Monte Carlo simulations, and strategic analysis tools such as Porter’s Five Forces. Definitions and assumptions used in these models are disclosed within the report and reflect a hypothetical investment thesis designed solely for academic discussion. All valuations, projections, and target prices presented herein are based on publicly available data and subject to the limitations of modeling assumptions. These are not guarantees of future performance and should not be relied upon as such, as past performance is not indicative of future results. Any company names, logos, trademarks, or brand references mentioned in this report are the property of their respective owners and are used strictly for identification and academic purposes. This document may not be reproduced, redistributed, or quoted in whole or in part without the prior written consent of the Lisbon Investment Society. About LIS – Lisbon Investment Society: The Lisbon Investment Society (LIS) is a non-profit academic association headquartered at ISEG – Lisbon School of Economics & Management. Founded in 2016, LIS is committed to fostering student interest in finance and investment through applied research, skill development, and institutional engagement. The Society operates independently and autonomously from any political, religious, or commercial affiliation, and is composed of selected students and collaborators who are invited through a rigorous recruitment process and share a commitment to excellence, analytical rigor, and ethical standards. Its activities include equity research, portfolio management, macroeconomic analysis, and investment education. This report was prepared by the Equity Research team at the Lisbon Investment Society, whose analysts combine rigorous financial modeling, critical thinking, and collaborative research to deliver high-quality, student-led investment analysis. We welcome your feedback, discussion, and questions regarding this report or our research process, and invite you to reach out to our team as we are always open to engagement.

Sheet Industry
D6: 584.17 | E6: 627.76 | F6: 676.06 | G6: 729.63 | H6: 789.13 | I6: 855.3 | J6: 929 | K6: 997.69 | L6: 1067.63 | M6: 1137.57
A7: x | B7: Industry Growth Forecast | O7: Industry Index
D9: 2022 | E9: =+D9+1 -> 2023 | F9: =+E9+1 -> 2024 | G9: =+F9+1 -> 2025 | H9: =+G9+1 -> 2026 | I9: =+H9+1 -> 2027 | J9: =+I9+1 -> 2028 | K9: =+J9+1 -> 2029 | M9: ="CAGR "&$G$9&" - "&$K$9 -> CAGR 2025 - 2029
B12: Market Size | M12: =(K12/G12)^(1/5)-1 -> #DIV/0!
B13: Market Share | M13: =((K13*K12)/(G13*G12))^(1/5)-1 -> #DIV/0!
B14: Market Size | M14: =(K14/G14)^(1/5)-1 -> #DIV/0!
B15: Market Share | M15: =((K15*K14)/(G15*G14))^(1/5)-1 -> #DIV/0!
B16: Market Size | M16: =(K16/G16)^(1/5)-1 -> #DIV/0!
B17: Market Share | M17: =((K17*K16)/(G17*G16))^(1/5)-1 -> #DIV/0!
B18: Market Size | M18: =(K18/G18)^(1/5)-1 -> #DIV/0!
B19: Market Share | M19: =((K19*K18)/(G19*G18))^(1/5)-1 -> #DIV/0!
B20: Market Size | M20: =(K20/G20)^(1/5)-1 -> #DIV/0!
B21: Market Share | M21: =((K21*K20)/(G21*G20))^(1/5)-1 -> #DIV/0!
A23: x
B25: Industry Driver | D25: Description | O25: Porter's Five Forces
O32: Rivalry Among Existing Competitors | R32: 2
O33: Threat of New Entrants | R33: 4
O34: Threat of Substitutes | R34: 3
O35: Bargaining Power of Customers | R35: 5
O36: Bargaining Power of Suppliers | R36: 5

Sheet ESG
A7: x | B7: ESG Analysis
B12: ESG Scores | G12: GHG Scope 1 Emissions, Water Consumption, Energy Consumption and Waste Production per Sales
B15: LSEG ESG Score | D15: 55
B16: E-Score | D16: 23
B17: S-Score | D17: 67
B18: G-Score | D18: 68
B19: S&P Global ESG Score | D19: 33
B20: Environmental | D20: 48
B21: Social | D21: 67
B22: Governance & Economic | D22: 67
B23: Sustainalytics | D23: 37.2
B24: ISS ESG Corporate Rating | D24: D-
B25: SDG Impact Rating | D25: -6.5
B26: Governance Quality Score | D26: 70
B27: MSCI ESG Ratings | D27: BBB
B30: Key Info | G30: Environmental
H32: Overview | I32: Targets | J32: Improvements | K32: Comments
B33: GICS Sector | C33: Consumer Staples | G33: GHG Scope 1 Emissions | I33: Reduce by 10% from 2023 baseline by 2030 | J33: Implemented methane capture pilots at farms; 5% reduction in FY2024 | K33: Strong start, but Scope 1 data not fully disclosed; aligns with UN SDG 13 (Climate Action).
B34: GICS Industry Group | C34: Food, Beverage & Staples Retailing
B35: GICS Industry | C35: Packaged Foods & Meats | G35: Water Consumption | I35: Achieve 95% water recycling in operations by 2027 | J35: Upgraded recycling systems at 80% of facilities; saved 15% water in FY2024 | K35: N/A
B36: GICS Sub-Industry | C36: Packaged Foods & Meats
G37: Energy Consumption | I37: Shift 20% to renewables (solar/wind) by 2028 | J37: Installed solar panels at 3 farms; 8% renewable mix in FY2024 | K37: N/A
B38: Headquarters | C38: Ridgeland, Mississippi
B39: Numer of Employees | C39: 3,067 | G39: Waste Management | I39: 90% waste diversion from landfills by 2026 | J39: Expanded composting for manure; 75% diversion rate in FY2024 | K39: N/A
B41: Annual Report | C41: https://www.calmainefoods.com/annual-reports | G41: Other | I41: N/A | J41: Converted 40% of flocks to cage-free; enhanced biosecurity | K41: Includes animal welfare (key for sector); FY2024 progress ties to consumer demand.
B42: Sustainability Report | C42: https://www.calmainefoods.com/reports
B44: Recent Headlines | G44: Social
B46: US Egg Giant Cal-Maine Under DOJ Probe for Price-Fixing Amid Soaring Profits (CNN Business, April 9, 2025) | H46: Overview | I46: Targets | J46: Improvements | K46: Comments
B47: Background: The DOJ launched an antitrust probe in March 2025 into Cal-Maine Foods for potential price-fixing during the HPAI outbreak, which reduced supply and drove egg prices to $5.90/dozen by February 2025. Critics allege collusion, echoing a 2023 $53 million damages case. Key Developments: Cal-Maine received a subpoena on April 8, 2025, requesting pricing data and is cooperating. Q3 FY2025 sales hit $1.42 billion (up 82%), with profits soaring 245%, though shares dropped 5% post-news. Implications: Scrutiny highlights food industry consolidation (top four firms control 60% of U.S. egg market), risking fines or lawsuits if collusion is proven, amid election-year inflation debates. | G47: Employee Turnover % | I47: Reduce to <15% by 2026 | J47: Implement retention incentives | K47: No specific turnover rate reported in 2024/2025 filings or sustainability report; employee count stable at 3,067. Reviews on Indeed and Glassdoor (205+ reviews) indicate moderate satisfaction with job security but some stress from operations, aligning with industry averages for agriculture (20-30% turnover).
G49: Salaries & Compensation | I49: Maintain competitive wages | J49: Annual wage review and benefit enhancements | K49: Average salary ~$74,361 (2025 data), competitive for sector per Salary.com; Glassdoor rates compensation 3/5 stars, with positive notes on benefits but gaps in executive pay ratios (2024 proxy). No major complaints in recent reviews.
G51: Reputation | I51: Improve to neutral by 2025 | J51: N/A | K51: Mixed perception: Strong operational performance praised in earnings (e.g., Q2 FY2025 sales up 82%), but scrutiny over HPAI profiteering and antitrust probes (Reuters, 2025) harms public view; Wikipedia notes 2025 watchdog complaints on collusion.
G53: Discrimination Events | I53: N/A | J53: N/A | K53: No reported discrimination incidents or lawsuits in 2024/2025; sustainability report emphasizes ethical practices, but general employee reviews on Fairygodboss rate equality low (1/5 for women). Proactive training implied but unverified.
B55: Cal-Maine Accused of Profiteering from Bird Flu: $1 Billion Windfall (Food & Water Watch Report, April 28, 2025) | G55: Work Safety | I55: Maintain OSHA compliance | J55: N/A | K55: No OSHA citations or incidents found in 2024/2025 releases; sustainability report highlights OSHA compliance and safety audits. Employee reviews note good safety records, aligning with "zero lost-time incidents" targets.
G57: Damage to consumer health | I57: Reduce incidents to 0 by 2027 | J57: N/A | K57: No salmonella outbreaks linked to Cal-Maine in 2024/2025 (CDC/FDA reports focus on other sources like raw milk); rigorous food safety processes noted in reports, but past concerns (pre-2024) and HPAI depopulation raise minor risks.
B58: Background: Food & Water Watch’s April 28 report claims Cal-Maine earned $1 billion in excess profits in FY2025’s first three quarters, hiking prices beyond cost increases (e.g., $1.14 profit/dozen vs. $0.15 pre-outbreak) during HPAI. Key Developments: The report cites SEC filings showing tripled margins despite minimal cost rises, plus $44.8 million in USDA indemnity payments, prompting watchdog complaints for antitrust action. Implications: Highlights risks of factory farming density and consumer cost burdens ($5.90/dozen), fueling calls for monopoly breakup and stricter regulations as profits tripled since 2022.
G59: Pension Plan | I59: N/A | J59: N/A | K59: Benefits include standard retirement plans per 2024 proxy, but no specific pension metrics; Glassdoor/Indeed reviews rate overall benefits 3/5, moderate compared to peers. No controversies noted.
G61: Supply chain | I61: 90% sustainable suppliers by 2026 | J61: N/A | K61: 2024 Sustainability Report details audits for ethical labor and 90% sustainable suppliers target; progress on transparency via SASB framework, with no major violations reported.
G63: Community involvement | I63: Increase donations by 10% by 2026 | J63: N/A | K63: Strong 60+ years of initiatives per sustainability report (e.g., donations, partnerships); 2024/2025 expansions (e.g., Dexter facility creating 96 jobs) boost local support.
G65: Public Sector | I65: N/A | J65: Engage with regulators | K65: Tense relations: DOJ antitrust probe on egg prices (2025 filing) and regulatory scrutiny over HPAI indemnity ($44.8M USDA payments); cooperating but ongoing concerns per Reuters.
G67: Litigation | I67: Reduce cases to 0 by 2026 | J67: Legal risk mitigation strategies | K67: Multiple 2024/2025 cases: Class-action antitrust suit with Tyson (Missouri farmers, June 2024); DOJ price-fixing probe (April 2025); ongoing egg price-fixing liability from 2023 verdict ($17.7M damages, potentially tripled).
...

Sheet Segments
A7: x | B7: Segments | D7: =F7 -> 2020 | E7: =F7 -> 2020 | F7: 2020 | G7: =F7 -> 2020 | H7: =F7 -> 2020 | J7: =L7 -> 2021 | K7: =L7 -> 2021 | L7: 2021 | M7: =L7 -> 2021 | N7: =L7 -> 2021 | P7: =R7 -> 2022 | Q7: =R7 -> 2022 | R7: 2022 | S7: =R7 -> 2022 | T7: =R7 -> 2022 | V7: =X7 -> 2023 | W7: =X7 -> 2023 | X7: 2023 | Y7: =X7 -> 2023 | Z7: =X7 -> 2023 | AB7: =AD7 -> 2024 | AC7: =AD7 -> 2024 | AD7: 2024 | AE7: =AD7 -> 2024 | AF7: =AD7 -> 2024 | AH7: =AJ7 -> 2025 | AI7: =AJ7 -> 2025 | AJ7: 2025 | AK7: =AJ7 -> 2025 | AL7: =AJ7 -> 2025 | AN7: =AP7 -> 2025 | AO7: =AP7 -> 2025 | AP7: 2025 | AQ7: =AP7 -> 2025 | AR7: =AP7 -> 2025 | AZ7: Products
D8: 2020 | J8: =D8+1 -> 2021 | P8: =J8+1 -> 2022 | V8: =P8+1 -> 2023 | AB8: =V8+1 -> 2024 | AH8: =AB8+1 -> 2025 | AN8: =AH8+1 -> 2026 | AT8: =AN8+1 -> 2027 | AV8: =+AT8+1 -> 2028 | AX8: =+AV8+1 -> 2029
D9: Q1 | E9: Q2 | F9: Q3 | G9: Q4 | H9: FY | J9: Q1 | K9: Q2 | L9: Q3 | M9: Q4 | N9: FY | P9: Q1 | Q9: Q2 | R9: Q3 | S9: Q4 | T9: FY | V9: Q1 | W9: Q2 | X9: Q3 | Y9: Q4 | Z9: FY | AB9: Q1 | AC9: Q2 | AD9: Q3 | AE9: Q4 | AF9: FY | AH9: Q1 | AI9: Q2 | AJ9: Q3 | AK9: Q4 | AL9: FY | AN9: Q1 | AO9: Q2 | AP9: Q3 | AQ9: Q4 | AR9: FY | AT9: FY | AV9: FY | AX9: FY
B12: Revenue by segment:
B13: Conventional shell egg sales | H13: 827727 | N13: 766284 | T13: 1061995 | Z13: 2051961 | AF13: 1291743 | AL13: 2835423
B14: Specialty shell egg sales | H14: 483881 | N14: 539780 | T14: 648838 | Z14: 956993 | AF14: 925665 | AL14: 1184487
B15: Egg products and prepared foods | H15: 48655 | N15: 36733 | T15: 60004 | Z15: 122270 | AF15: 89009 | AL15: 198833
B16: Other | H16: 6145 | N16: 6190 | T16: 6322 | Z16: 14993 | AF16: 20026 | AL16: 43142
B17: Total revenue | D17: =IS!D18 -> 241166 | E17: =IS!E18 -> 311522 | F17: =IS!F18 -> 345588 | G17: =IS!G18 -> 453333 | H17: =H13+H14+H15+H16 -> 1366408 | J17: =IS!J18 -> 292782 | K17: =IS!K18 -> 347328 | L17: =IS!L18 -> 359080 | M17: =IS!M18 -> 349798 | N17: =IS!N18 -> 1348987 | P17: =IS!P18 -> 331704 | Q17: =IS!Q18 -> 381723 | R17: =IS!R18 -> 477485 | S17: =IS!S18 -> 592964 | T17: =IS!T18 -> 1777159 | V17: =IS!V18 -> 658344 | W17: =IS!W18 -> 801700 | X17: =IS!X18 -> 997493 | Y17: =IS!Y18 -> 688680 | Z17: =IS!Z18 -> 3146217 | AB17: =IS!AB18 -> 459344 | AC17: =IS!AC18 -> 523234 | AD17: =IS!AD18 -> 703076 | AE17: =IS!AE18 -> 640789 | AF17: 2326443 | AH17: =IS!AH18 -> 785871 | AI17: =IS!AI18 -> 954671 | AJ17: =IS!AJ18 -> 25000 | AK17: =IS!AK18 -> 25000 | AL17: 4261885 | AN17: =IS!AN18 -> 22000 | AO17: =IS!AO18 -> 22000 | AP17: =IS!AP18 -> 22000 | AQ17: =IS!AQ18 -> 22000 | AR17: =IS!AR18 -> 88000 | AT17: =IS!AT18 -> 90000 | AV17: =IS!AV18 -> 87000 | AX17: =IS!AX18 -> 105000
B19: Revenue by region:
B20: USA | H20: =H21 -> 1351609 | J20: =J21 -> 292782 | K20: =K21 -> 347328 | L20: =L21 -> 359080 | M20: =M21 -> 349798 | N20: =N21 -> 1348987 | P20: =P21 -> 331704 | Q20: =Q21 -> 381723 | R20: =R21 -> 477485 | S20: =S21 -> 592964 | T20: =T21 -> 1777159 | V20: =V21 -> 658344 | W20: =W21 -> 801700 | X20: =X21 -> 997493 | Y20: =Y21 -> 688680 | Z20: =Z21 -> 3146217 | AB20: =AB21 -> 459344 | AC20: =AC21 -> 523234 | AD20: =AD21 -> 703076 | AE20: =AE21 -> 640789 | AF20: =AF21 -> 2326443
B21: Total revenue | D21: =IS!D18 -> 241166 | E21: =IS!E18 -> 311522 | F21: =IS!F18 -> 345588 | G21: =IS!G18 -> 453333 | H21: =IS!H18 -> 1351609 | J21: =IS!J18 -> 292782 | K21: =IS!K18 -> 347328 | L21: =IS!L18 -> 359080 | M21: =IS!M18 -> 349798 | N21: =IS!N18 -> 1348987 | P21: =IS!P18 -> 331704 | Q21: =IS!Q18 -> 381723 | R21: =IS!R18 -> 477485 | S21: =IS!S18 -> 592964 | T21: =IS!T18 -> 1777159 | V21: =IS!V18 -> 658344 | W21: =IS!W18 -> 801700 | X21: =IS!X18 -> 997493 | Y21: =IS!Y18 -> 688680 | Z21: =IS!Z18 -> 3146217 | AB21: =IS!AB18 -> 459344 | AC21: =IS!AC18 -> 523234 | AD21: =IS!AD18 -> 703076 | AE21: =IS!AE18 -> 640789 | AF21: =IS!AF18 -> 2326443 | AH21: =IS!AH18 -> 785871 | AI21: =IS!AI18 -> 954671 | AJ21: =IS!AJ18 -> 25000 | AK21: =IS!AK18 -> 25000 | AL21: =IS!AL18 -> 1790542 | AN21: =IS!AN18 -> 22000 | AO21: =IS!AO18 -> 22000 | AP21: =IS!AP18 -> 22000 | AQ21: =IS!AQ18 -> 22000 | AR21: =IS!AR18 -> 88000 | AT21: =IS!AT18 -> 90000 | AV21: =IS!AV18 -> 87000 | AX21: =IS!AX18 -> 105000
B23: Products:
B24: Product 1
B25: Product 2
B26: Product 3
B27: Product 4
B28: Product 5
A30: x | B30: Notes & Forecasts

Sheet Peers
B7: Peers
A12: x | B12: Growth | C12: =Inputs!S7 -> CAL-MAINE FOODS | D12: {=TRANSPOSE(Inputs!B21:B25)} -> VITAL FARMS INC | E12: POST HOLDINGS IN | F12: TYSON FOODS-A | G12: LAMB WESTON | H12: HORMEL FOODS CRP | I12: {=TRANSPOSE(Inputs!H21:H25)} -> GENERAL MILLS IN | J12: CONAGRA BRANDS I | K12: PILGRIM'S PRIDE | L12: NESTLE SA-REG | M12: UNILEVER PLC | N12: {=TRANSPOSE(Inputs!N21:N25)} -> PEPSICO INC | O12: PROCTER & GAMBLE | P12: COCA-COLA CO/THE | Q12: KIMBERLY-CLARK | R12: COLGATE-PALMOLIV
B14: Revenue (LTM) | C14: 0.83193184 | D14: =_xll.BQL( Inputs!$E$21, "(sales_rev_turn(fpt=ltm,fa_adjusted=y) / sales_rev_turn(fpt=ltm,fa_adjusted=y,fa_period_offset=-1)) - 1" ) -> 0.21491736 | E14: =_xll.BQL( Inputs!$E$22, "(sales_rev_turn(fpt=ltm,fa_adjusted=y) / sales_rev_turn(fpt=ltm,fa_adjusted=y,fa_period_offset=-1)) - 1" ) -> 0.008042759 | F14: =_xll.BQL( Inputs!$E$23, "(sales_rev_turn(fpt=ltm,fa_adjusted=y) / sales_rev_turn(fpt=ltm,fa_adjusted=y,fa_period_offset=-1)) - 1" ) -> 0.019852332 | G14: =_xll.BQL( Inputs!$E$24, "(sales_rev_turn(fpt=ltm,fa_adjusted=y) / sales_rev_turn(fpt=ltm,fa_adjusted=y,fa_period_offset=-1)) - 1" ) -> 1.5488508e-05 | H14: =_xll.BQL( Inputs!$E$25, "(sales_rev_turn(fpt=ltm,fa_adjusted=y) / sales_rev_turn(fpt=ltm,fa_adjusted=y,fa_period_offset=-1)) - 1" ) -> 0.0064941488 | I14: =_xll.BQL( Inputs!$K$21, "(sales_rev_turn(fpt=ltm,fa_adjusted=y) / sales_rev_turn(fpt=ltm,fa_adjusted=y,fa_period_offset=-1)) - 1" ) -> -0.032554569 | J14: =_xll.BQL( Inputs!$K$22, "(sales_rev_turn(fpt=ltm,fa_adjusted=y) / sales_rev_turn(fpt=ltm,fa_adjusted=y,fa_period_offset=-1)) - 1" ) -> -0.041141201 | K14: =_xll.BQL( Inputs!$K$23, "(sales_rev_turn(fpt=ltm,fa_adjusted=y) / sales_rev_turn(fpt=ltm,fa_adjusted=y,fa_period_offset=-1)) - 1" ) -> 0.020644371 | L14: =_xll.BQL( Inputs!$K$23, "(sales_rev_turn(fpt=ltm,fa_adjusted=y) / sales_rev_turn(fpt=ltm,fa_adjusted=y,fa_period_offset=-1)) - 1" ) -> 0.020644371 | M14: =_xll.BQL( Inputs!$K$24, "(sales_rev_turn(fpt=ltm,fa_adjusted=y) / sales_rev_turn(fpt=ltm,fa_adjusted=y,fa_period_offset=-1)) - 1" ) -> -0.013104467 | N14: =_xll.BQL( Inputs!$K$24, "(sales_rev_turn(fpt=ltm,fa_adjusted=y) / sales_rev_turn(fpt=ltm,fa_adjusted=y,fa_period_offset=-1)) - 1" ) -> -0.013104467 | O14: =_xll.BQL( Inputs!$K$24, "(sales_rev_turn(fpt=ltm,fa_adjusted=y) / sales_rev_turn(fpt=ltm,fa_adjusted=y,fa_period_offset=-1)) - 1" ) -> -0.013104467 | P14: =_xll.BQL( Inputs!$K$24, "(sales_rev_turn(fpt=ltm,fa_adjusted=y) / sales_rev_turn(fpt=ltm,fa_adjusted=y,fa_period_offset=-1)) - 1" ) -> -0.013104467 | Q14: =_xll.BQL( Inputs!$K$24, "(sales_rev_turn(fpt=ltm,fa_adjusted=y) / sales_rev_turn(fpt=ltm,fa_adjusted=y,fa_period_offset=-1)) - 1" ) -> -0.013104467 | R14: =_xll.BQL( Inputs!$K$24, "(sales_rev_turn(fpt=ltm,fa_adjusted=y) / sales_rev_turn(fpt=ltm,fa_adjusted=y,fa_period_offset=-1)) - 1" ) -> -0.013104467
B15: Revenue (3-yr CAGR) | C15: 0.33852087 | D15: =_xll.BQL( Inputs!$E$21, "(sales_rev_turn(fpt=ltm,fa_adjusted=y) / sales_rev_turn(fpt=ltm,fa_adjusted=y,fa_period_offset=-3))^(1/3) - 1" ) -> 0.29642431 | E15: =_xll.BQL( Inputs!$E$22, "(sales_rev_turn(fpt=ltm,fa_adjusted=y) / sales_rev_turn(fpt=ltm,fa_adjusted=y,fa_period_offset=-3))^(1/3) - 1" ) -> 0.080814416 | F15: =_xll.BQL( Inputs!$E$23, "(sales_rev_turn(fpt=ltm,fa_adjusted=y) / sales_rev_turn(fpt=ltm,fa_adjusted=y,fa_period_offset=-3))^(1/3) - 1" ) -> 0.011268873 | G15: =_xll.BQL( Inputs!$E$24, "(sales_rev_turn(fpt=ltm,fa_adjusted=y) / sales_rev_turn(fpt=ltm,fa_adjusted=y,fa_period_offset=-3))^(1/3) - 1" ) -> 0.15044764 | H15: =_xll.BQL( Inputs!$E$25, "(sales_rev_turn(fpt=ltm,fa_adjusted=y) / sales_rev_turn(fpt=ltm,fa_adjusted=y,fa_period_offset=-3))^(1/3) - 1" ) -> -0.015316215 | I15: =_xll.BQL( Inputs!$K$21, "(sales_rev_turn(fpt=ltm,fa_adjusted=y) / sales_rev_turn(fpt=ltm,fa_adjusted=y,fa_period_offset=-3))^(1/3) - 1" ) -> -0.00025218708 | J15: =_xll.BQL( Inputs!$K$22, "(sales_rev_turn(fpt=ltm,fa_adjusted=y) / sales_rev_turn(fpt=ltm,fa_adjusted=y,fa_period_offset=-3))^(1/3) - 1" ) -> -0.0096053537 | K15: =_xll.BQL( Inputs!$K$23, "(sales_rev_turn(fpt=ltm,fa_adjusted=y) / sales_rev_turn(fpt=ltm,fa_adjusted=y,fa_period_offset=-3))^(1/3) - 1" ) -> 0.027873335 | L15: =_xll.BQL( Inputs!$K$24, "(sales_rev_turn(fpt=ltm,fa_adjusted=y) / sales_rev_turn(fpt=ltm,fa_adjusted=y,fa_period_offset=-3))^(1/3) - 1" ) -> -0.0014734777 | M15: =_xll.BQL( Inputs!$K$25, "(sales_rev_turn(fpt=ltm,fa_adjusted=y) / sales_rev_turn(fpt=ltm,fa_adjusted=y,fa_period_offset=-3))^(1/3) - 1" ) -> 0.021282953 | N15: =_xll.BQL( Inputs!$Q$21, "(sales_rev_turn(fpt=ltm,fa_adjusted=y) / sales_rev_turn(fpt=ltm,fa_adjusted=y,fa_period_offset=-3))^(1/3) - 1" ) -> 0.038734967 | O15: =_xll.BQL( Inputs!$Q$22, "(sales_rev_turn(fpt=ltm,fa_adjusted=y) / sales_rev_turn(fpt=ltm,fa_adjusted=y,fa_period_offset=-3))^(1/3) - 1" ) -> 0.01674893 | P15: =_xll.BQL( Inputs!$Q$23, "(sales_rev_turn(fpt=ltm,fa_adjusted=y) / sales_rev_turn(fpt=ltm,fa_adjusted=y,fa_period_offset=-3))^(1/3) - 1" ) -> 0.045260705 | Q15: =_xll.BQL( Inputs!$Q$24, "(sales_rev_turn(fpt=ltm,fa_adjusted=y) / sales_rev_turn(fpt=ltm,fa_adjusted=y,fa_period_offset=-3))^(1/3) - 1" ) -> -0.021139434 | R15: =_xll.BQL( Inputs!$Q$25, "(sales_rev_turn(fpt=ltm,fa_adjusted=y) / sales_rev_turn(fpt=ltm,fa_adjusted=y,fa_period_offset=-3))^(1/3) - 1" ) -> 0.041528358
B16: Gross profit (LTM) | C16: 2.4176221 | D16: =_xll.BQL( Inputs!$E$21, "(gross_profit(fpt=ltm,fa_adjusted=y) / gross_profit(fpt=ltm,fa_adjusted=y,fa_period_offset=-1)) - 1" ) -> 0.24800689 | E16: =_xll.BQL( Inputs!$E$22, "(gross_profit(fpt=ltm,fa_adjusted=y) / gross_profit(fpt=ltm,fa_adjusted=y,fa_period_offset=-1)) - 1" ) -> 0.013941865 | F16: =_xll.BQL( Inputs!$E$23, "(gross_profit(fpt=ltm,fa_adjusted=y) / gross_profit(fpt=ltm,fa_adjusted=y,fa_period_offset=-1)) - 1" ) -> 0.22858056 | G16: =_xll.BQL( Inputs!$E$24, "(gross_profit(fpt=ltm,fa_adjusted=y) / gross_profit(fpt=ltm,fa_adjusted=y,fa_period_offset=-1)) - 1" ) -> -0.16225065 | H16: =_xll.BQL( Inputs!$E$25, "(gross_profit(fpt=ltm,fa_adjusted=y) / gross_profit(fpt=ltm,fa_adjusted=y,fa_period_offset=-1)) - 1" ) -> -0.0099699837 | I16: =_xll.BQL( Inputs!$K$21, "(gross_profit(fpt=ltm,fa_adjusted=y) / gross_profit(fpt=ltm,fa_adjusted=y,fa_period_offset=-1)) - 1" ) -> -0.045457185 | J16: =_xll.BQL( Inputs!$K$22, "(gross_profit(fpt=ltm,fa_adjusted=y) / gross_profit(fpt=ltm,fa_adjusted=y,fa_period_offset=-1)) - 1" ) -> -0.10840158 | K16: =_xll.BQL( Inputs!$K$23, "(gross_profit(fpt=ltm,fa_adjusted=y) / gross_profit(fpt=ltm,fa_adjusted=y,fa_period_offset=-1)) - 1" ) -> 0.43899673 | L16: =_xll.BQL( Inputs!$K$23, "(gross_profit(fpt=ltm,fa_adjusted=y) / gross_profit(fpt=ltm,fa_adjusted=y,fa_period_offset=-1)) - 1" ) -> 0.43899673 | M16: =_xll.BQL( Inputs!$K$24, "(gross_profit(fpt=ltm,fa_adjusted=y) / gross_profit(fpt=ltm,fa_adjusted=y,fa_period_offset=-1)) - 1" ) -> -0.017377201 | N16: =_xll.BQL( Inputs!$K$24, "(gross_profit(fpt=ltm,fa_adjusted=y) / gross_profit(fpt=ltm,fa_adjusted=y,fa_period_offset=-1)) - 1" ) -> -0.017377201 | O16: =_xll.BQL( Inputs!$K$24, "(gross_profit(fpt=ltm,fa_adjusted=y) / gross_profit(fpt=ltm,fa_adjusted=y,fa_period_offset=-1)) - 1" ) -> -0.017377201 | P16: =_xll.BQL( Inputs!$K$24, "(gross_profit(fpt=ltm,fa_adjusted=y) / gross_profit(fpt=ltm,fa_adjusted=y,fa_period_offset=-1)) - 1" ) -> -0.017377201 | Q16: =_xll.BQL( Inputs!$K$24, "(gross_profit(fpt=ltm,fa_adjusted=y) / gross_profit(fpt=ltm,fa_adjusted=y,fa_period_offset=-1)) - 1" ) -> -0.017377201 | R16: =_xll.BQL( Inputs!$K$24, "(gross_profit(fpt=ltm,fa_adjusted=y) / gross_profit(fpt=ltm,fa_adjusted=y,fa_period_offset=-1)) - 1" ) -> -0.017377201
B17: EBIT (LTM) | C17: 4.3173811 | D17: =_xll.BQL( Inputs!$E$21, "(is_oper_inc(fpt=ltm,fa_adjusted=y) / is_oper_inc(fpt=ltm,fa_adjusted=y,fa_period_offset=-1)) - 1" ) -> 0.22001286 | E17: =_xll.BQL( Inputs!$E$22, "(is_oper_inc(fpt=ltm,fa_adjusted=y) / is_oper_inc(fpt=ltm,fa_adjusted=y,fa_period_offset=-1)) - 1" ) -> 0.017761159 | F17: =_xll.BQL( Inputs!$E$23, "(is_oper_inc(fpt=ltm,fa_adjusted=y) / is_oper_inc(fpt=ltm,fa_adjusted=y,fa_period_offset=-1)) - 1" ) -> 0.46462585 | G17: =_xll.BQL( Inputs!$E$24, "(is_oper_inc(fpt=ltm,fa_adjusted=y) / is_oper_inc(fpt=ltm,fa_adjusted=y,fa_period_offset=-1)) - 1" ) -> -0.23688275 | H17: =_xll.BQL( Inputs!$E$25, "(is_oper_inc(fpt=ltm,fa_adjusted=y) / is_oper_inc(fpt=ltm,fa_adjusted=y,fa_period_offset=-1)) - 1" ) -> 0.0013903233 | I17: =_xll.BQL( Inputs!$K$21, "(is_oper_inc(fpt=ltm,fa_adjusted=y) / is_oper_inc(fpt=ltm,fa_adjusted=y,fa_period_offset=-1)) - 1" ) -> -0.091486029 | J17: =_xll.BQL( Inputs!$K$22, "(is_oper_inc(fpt=ltm,fa_adjusted=y) / is_oper_inc(fpt=ltm,fa_adjusted=y,fa_period_offset=-1)) - 1" ) -> -0.029727941 | K17: =_xll.BQL( Inputs!$K$23, "(is_oper_inc(fpt=ltm,fa_adjusted=y) / is_oper_inc(fpt=ltm,fa_adjusted=y,fa_period_offset=-1)) - 1" ) -> 0.59581 | L17: =_xll.BQL( Inputs!$K$23, "(is_oper_inc(fpt=ltm,fa_adjusted=y) / is_oper_inc(fpt=ltm,fa_adjusted=y,fa_period_offset=-1)) - 1" ) -> 0.59581 | M17: =_xll.BQL( Inputs!$K$24, "(is_oper_inc(fpt=ltm,fa_adjusted=y) / is_oper_inc(fpt=ltm,fa_adjusted=y,fa_period_offset=-1)) - 1" ) -> -0.047780074 | N17: =_xll.BQL( Inputs!$K$24, "(is_oper_inc(fpt=ltm,fa_adjusted=y) / is_oper_inc(fpt=ltm,fa_adjusted=y,fa_period_offset=-1)) - 1" ) -> -0.047780074 | O17: =_xll.BQL( Inputs!$K$24, "(is_oper_inc(fpt=ltm,fa_adjusted=y) / is_oper_inc(fpt=ltm,fa_adjusted=y,fa_period_offset=-1)) - 1" ) -> -0.047780074 | P17: =_xll.BQL( Inputs!$K$24, "(is_oper_inc(fpt=ltm,fa_adjusted=y) / is_oper_inc(fpt=ltm,fa_adjusted=y,fa_period_offset=-1)) - 1" ) -> -0.047780074 | Q17: =_xll.BQL( Inputs!$K$24, "(is_oper_inc(fpt=ltm,fa_adjusted=y) / is_oper_inc(fpt=ltm,fa_adjusted=y,fa_period_offset=-1)) - 1" ) -> -0.047780074 | R17: =_xll.BQL( Inputs!$K$24, "(is_oper_inc(fpt=ltm,fa_adjusted=y) / is_oper_inc(fpt=ltm,fa_adjusted=y,fa_period_offset=-1)) - 1" ) -> -0.047780074
B18: EBITDA (LTM) | C18: 3.4163446 | D18: =_xll.BQL( Inputs!$E$21, "(ebitda(fpt=ltm,fa_adjusted=y) / ebitda(fpt=ltm,fa_adjusted=y,fa_period_offset=-1)) - 1" ) -> 0.31492032 | E18: =_xll.BQL( Inputs!$E$22, "(ebitda(fpt=ltm,fa_adjusted=y) / ebitda(fpt=ltm,fa_adjusted=y,fa_period_offset=-1)) - 1" ) -> 0.03856916 | F18: =_xll.BQL( Inputs!$E$23, "(ebitda(fpt=ltm,fa_adjusted=y) / ebitda(fpt=ltm,fa_adjusted=y,fa_period_offset=-1)) - 1" ) -> 0.18724559 | G18: =_xll.BQL( Inputs!$E$24, "(ebitda(fpt=ltm,fa_adjusted=y) / ebitda(fpt=ltm,fa_adjusted=y,fa_period_offset=-1)) - 1" ) -> -0.11100528 | H18: =_xll.BQL( Inputs!$E$25, "(ebitda(fpt=ltm,fa_adjusted=y) / ebitda(fpt=ltm,fa_adjusted=y,fa_period_offset=-1)) - 1" ) -> 0.026147734 | I18: =_xll.BQL( Inputs!$K$21, "(ebitda(fpt=ltm,fa_adjusted=y) / ebitda(fpt=ltm,fa_adjusted=y,fa_period_offset=-1)) - 1" ) -> -0.083294405 | J18: =_xll.BQL( Inputs!$K$22, "(ebitda(fpt=ltm,fa_adjusted=y) / ebitda(fpt=ltm,fa_adjusted=y,fa_period_offset=-1)) - 1" ) -> -0.032209482 | K18: =_xll.BQL( Inputs!$K$23, "(ebitda(fpt=ltm,fa_adjusted=y) / ebitda(fpt=ltm,fa_adjusted=y,fa_period_offset=-1)) - 1" ) -> 0.45113872 | L18: =_xll.BQL( Inputs!$K$23, "(ebitda(fpt=ltm,fa_adjusted=y) / ebitda(fpt=ltm,fa_adjusted=y,fa_period_offset=-1)) - 1" ) -> 0.45113872 | M18: =_xll.BQL( Inputs!$K$24, "(ebitda(fpt=ltm,fa_adjusted=y) / ebitda(fpt=ltm,fa_adjusted=y,fa_period_offset=-1)) - 1" ) -> -0.033281972 | N18: =_xll.BQL( Inputs!$K$24, "(ebitda(fpt=ltm,fa_adjusted=y) / ebitda(fpt=ltm,fa_adjusted=y,fa_period_offset=-1)) - 1" ) -> -0.033281972 | O18: =_xll.BQL( Inputs!$K$24, "(ebitda(fpt=ltm,fa_adjusted=y) / ebitda(fpt=ltm,fa_adjusted=y,fa_period_offset=-1)) - 1" ) -> -0.033281972 | P18: =_xll.BQL( Inputs!$K$24, "(ebitda(fpt=ltm,fa_adjusted=y) / ebitda(fpt=ltm,fa_adjusted=y,fa_period_offset=-1)) - 1" ) -> -0.033281972 | Q18: =_xll.BQL( Inputs!$K$24, "(ebitda(fpt=ltm,fa_adjusted=y) / ebitda(fpt=ltm,fa_adjusted=y,fa_period_offset=-1)) - 1" ) -> -0.033281972 | R18: =_xll.BQL( Inputs!$K$24, "(ebitda(fpt=ltm,fa_adjusted=y) / ebitda(fpt=ltm,fa_adjusted=y,fa_period_offset=-1)) - 1" ) -> -0.033281972
B19: FCF (LTM) | C19: 2.4950441 | D19: {=_xll.BDP(Inputs!$E$21,"FREE_CASH_FLOW_1_YEAR_GROWTH")/100} -> -0.081030278 | E19: {=_xll.BDP(Inputs!$E$22,"FREE_CASH_FLOW_1_YEAR_GROWTH")/100} -> 0.12273642 | F19: {=_xll.BDP(Inputs!$E$23,"FREE_CASH_FLOW_1_YEAR_GROWTH")/100} -> #VALUE! | G19: {=_xll.BDP(Inputs!$E$24,"FREE_CASH_FLOW_1_YEAR_GROWTH")/100} -> #VALUE! | H19: {=_xll.BDP(Inputs!$E$25,"FREE_CASH_FLOW_1_YEAR_GROWTH")/100} -> 0.29919011 | I19: {=_xll.BDP(Inputs!$K$21,"FREE_CASH_FLOW_1_YEAR_GROWTH")/100} -> -0.093177773 | J19: {=_xll.BDP(Inputs!$K$22,"FREE_CASH_FLOW_1_YEAR_GROWTH")/100} -> -0.19963134 | K19: {=_xll.BDP(Inputs!$K$23,"FREE_CASH_FLOW_1_YEAR_GROWTH")/100} -> 10.293173 | L19: {=_xll.BDP(Inputs!$K$24,"FREE_CASH_FLOW_1_YEAR_GROWTH")/100} -> 0.079202112 | M19: {=_xll.BDP(Inputs!$K$25,"FREE_CASH_FLOW_1_YEAR_GROWTH")/100} -> -0.018855398 | N19: {=_xll.BDP(Inputs!$Q$21,"FREE_CASH_FLOW_1_YEAR_GROWTH")/100} -> -0.092756184 | O19: {=_xll.BDP(Inputs!$Q$22,"FREE_CASH_FLOW_1_YEAR_GROWTH")/100} -> -0.15003329 | P19: {=_xll.BDP(Inputs!$Q$23,"FREE_CASH_FLOW_1_YEAR_GROWTH")/100} -> -0.51359393 | Q19: {=_xll.BDP(Inputs!$Q$24,"FREE_CASH_FLOW_1_YEAR_GROWTH")/100} -> -0.094740634 | R19: {=_xll.BDP(Inputs!$Q$25,"FREE_CASH_FLOW_1_YEAR_GROWTH")/100} -> 0.16644737
A21: x | B21: Margins | C21: CAL-MAINE FOODS | D21: =D12 -> VITAL FARMS INC | E21: =E12 -> POST HOLDINGS IN | F21: =F12 -> TYSON FOODS-A | G21: =G12 -> LAMB WESTON | H21: =H12 -> HORMEL FOODS CRP | I21: =I12 -> GENERAL MILLS IN | J21: =J12 -> CONAGRA BRANDS I | K21: =K12 -> PILGRIM'S PRIDE | ... R21: =R12 -> COLGATE-PALMOLIV
B23: Gross margin | C23: 0.43428788 | D23: {=_xll.BDP(Inputs!$E$21,"GROSS_MARGIN")/100} -> 0.37922373 | E23: {=_xll.BDP(Inputs!$E$22,"GROSS_MARGIN")/100} -> 0.29092355 | F23: {=_xll.BDP(Inputs!$E$23,"GROSS_MARGIN")/100} -> 0.068037292 | G23: {=_xll.BDP(Inputs!$E$24,"GROSS_MARGIN")/100} -> 0.21679351 | H23: {=_xll.BDP(Inputs!$E$25,"GROSS_MARGIN")/100} -> 0.16963111 | I23: {=_xll.BDP(Inputs!$K$21,"GROSS_MARGIN")/100} -> 0.34551949 | J23: {=_xll.BDP(Inputs!$K$22,"GROSS_MARGIN")/100} -> 0.25863702 | K23: {=_xll.BDP(Inputs!$K$23,"GROSS_MARGIN")/100} -> 0.12936175 | L23: {=_xll.BDP(Inputs!$K$24,"GROSS_MARGIN")/100} -> 0.46936328 | M23: {=_xll.BDP(Inputs!$K$25,"GROSS_MARGIN")/100} -> 0.45045342 | N23: {=_xll.BDP(Inputs!$Q$21,"GROSS_MARGIN")/100} -> 0.54553966 | O23: {=_xll.BDP(Inputs!$Q$22,"GROSS_MARGIN")/100} -> 0.51160363 | P23: {=_xll.BDP(Inputs!$Q$23,"GROSS_MARGIN")/100} -> 0.61063301 | Q23: {=_xll.BDP(Inputs!$Q$24,"GROSS_MARGIN")/100} -> 0.35796191 | R23: {=_xll.BDP(Inputs!$Q$25,"GROSS_MARGIN")/100} -> 0.60499478
B24: EBIT margin | C24: 0.36053038 | D24: {=_xll.BDP(Inputs!$E$21,"OPER_MARGIN")/100} -> 0.10481819 | E24: {=_xll.BDP(Inputs!$E$22,"OPER_MARGIN")/100} -> 0.10015525 | F24: {=_xll.BDP(Inputs!$E$23,"OPER_MARGIN")/100} -> 0.026430809 | G24: {=_xll.BDP(Inputs!$E$24,"OPER_MARGIN")/100} -> 0.1030955 | H24: {=_xll.BDP(Inputs!$E$25,"OPER_MARGIN")/100} -> 0.089585621 | I24: {=_xll.BDP(Inputs!$K$21,"OPER_MARGIN")/100} -> 0.16959346 | J24: {=_xll.BDP(Inputs!$K$22,"OPER_MARGIN")/100} -> 0.11750827 | K24: {=_xll.BDP(Inputs!$K$23,"OPER_MARGIN")/100} -> 0.084240099 | L24: {=_xll.BDP(Inputs!$K$24,"OPER_MARGIN")/100} -> 0.16053205 | M24: {=_xll.BDP(Inputs!$K$25,"OPER_MARGIN")/100} -> 0.1547045 | N24: {=_xll.BDP(Inputs!$Q$21,"OPER_MARGIN")/100} -> 0.14029873 | O24: {=_xll.BDP(Inputs!$Q$22,"OPER_MARGIN")/100} -> 0.24264392 | P24: {=_xll.BDP(Inputs!$Q$23,"OPER_MARGIN")/100} -> 0.21232018 | Q24: {=_xll.BDP(Inputs!$Q$24,"OPER_MARGIN")/100} -> 0.1600359 | R24: {=_xll.BDP(Inputs!$Q$25,"OPER_MARGIN")/100} -> 0.21232774
B25: EBITDA margin | C25: 0.38259127 | D25: {=_xll.BDP(Inputs!$E$21,"EBITDA_MARGIN")/100} -> 0.13396672 | E25: {=_xll.BDP(Inputs!$E$22,"EBITDA_MARGIN")/100} -> 0.16715902 | F25: {=_xll.BDP(Inputs!$E$23,"EBITDA_MARGIN")/100} -> 0.051933661 | G25: {=_xll.BDP(Inputs!$E$24,"EBITDA_MARGIN")/100} -> 0.15825912 | H25: {=_xll.BDP(Inputs!$E$25,"EBITDA_MARGIN")/100} -> 0.1054717 | I25: {=_xll.BDP(Inputs!$K$21,"EBITDA_MARGIN")/100} -> 0.24729589 | J25: {=_xll.BDP(Inputs!$K$22,"EBITDA_MARGIN")/100} -> 0.14818567 | K25: {=_xll.BDP(Inputs!$K$23,"EBITDA_MARGIN")/100} -> 0.11949839 | L25: {=_xll.BDP(Inputs!$K$24,"EBITDA_MARGIN")/100} -> 0.19486463 | M25: {=_xll.BDP(Inputs!$K$25,"EBITDA_MARGIN")/100} -> #VALUE! | N25: {=_xll.BDP(Inputs!$Q$21,"EBITDA_MARGIN")/100} -> 0.15004142 | O25: {=_xll.BDP(Inputs!$Q$22,"EBITDA_MARGIN")/100} -> 0.27642257 | P25: {=_xll.BDP(Inputs!$Q$23,"EBITDA_MARGIN")/100} -> 0.30274956 | Q25: {=_xll.BDP(Inputs!$Q$24,"EBITDA_MARGIN")/100} -> 0.20711751 | R25: {=_xll.BDP(Inputs!$Q$25,"EBITDA_MARGIN")/100} -> 0.24412441
B26: Net margin | C26: 0.28626957 | D26: {=_xll.BDP(Inputs!$E$21,"NET_INCOME_TO_COMMON_MARGIN")/100} -> 0.088054401 | E26: {=_xll.BDP(Inputs!$E$22,"NET_INCOME_TO_COMMON_MARGIN")/100} -> 0.046284726 | F26: {=_xll.BDP(Inputs!$E$23,"NET_INCOME_TO_COMMON_MARGIN")/100} -> 0.015006847 | G26: {=_xll.BDP(Inputs!$E$24,"NET_INCOME_TO_COMMON_MARGIN")/100} -> 0.055368685 | H26: {=_xll.BDP(Inputs!$E$25,"NET_INCOME_TO_COMMON_MARGIN")/100} -> 0.06753223 | I26: {=_xll.BDP(Inputs!$K$21,"NET_INCOME_TO_COMMON_MARGIN")/100} -> 0.1177835 | J26: {=_xll.BDP(Inputs!$K$22,"NET_INCOME_TO_COMMON_MARGIN")/100} -> 0.099235327 | K26: {=_xll.BDP(Inputs!$K$23,"NET_INCOME_TO_COMMON_MARGIN")/100} -> 0.06076856 | L26: {=_xll.BDP(Inputs!$K$24,"NET_INCOME_TO_COMMON_MARGIN")/100} -> 0.1186655 | M26: {=_xll.BDP(Inputs!$K$25,"NET_INCOME_TO_COMMON_MARGIN")/100} -> 0.094534323 | N26: {=_xll.BDP(Inputs!$Q$21,"NET_INCOME_TO_COMMON_MARGIN")/100} -> 0.10427417 | O26: {=_xll.BDP(Inputs!$Q$22,"NET_INCOME_TO_COMMON_MARGIN")/100} -> 0.18607328 | P26: {=_xll.BDP(Inputs!$Q$23,"NET_INCOME_TO_COMMON_MARGIN")/100} -> 0.2258983 | Q26: {=_xll.BDP(Inputs!$Q$24,"NET_INCOME_TO_COMMON_MARGIN")/100} -> 0.12688204 | R26: {=_xll.BDP(Inputs!$Q$25,"NET_INCOME_TO_COMMON_MARGIN")/100} -> 0.14372419
B27: SG&A margin | C27: #VALUE! | D27: {=_xll.BDP(Inputs!$E$21,"SG&A_AS_%_TOTAL_SALES")/100} -> 0.27440554 | E27: {=_xll.BDP(Inputs!$E$22,"SG&A_AS_%_TOTAL_SALES")/100} -> 0.16792255 | F27: {=_xll.BDP(Inputs!$E$23,"SG&A_AS_%_TOTAL_SALES")/100} -> 0.039618076 | G27: {=_xll.BDP(Inputs!$E$24,"SG&A_AS_%_TOTAL_SALES")/100} -> 0.087594748 | H27: {=_xll.BDP(Inputs!$E$25,"SG&A_AS_%_TOTAL_SALES")/100} -> 0.084331106 | I27: {=_xll.BDP(Inputs!$K$21,"SG&A_AS_%_TOTAL_SALES")/100} -> 0.17682921 | J27: {=_xll.BDP(Inputs!$K$22,"SG&A_AS_%_TOTAL_SALES")/100} -> 0.13237979 | K27: {=_xll.BDP(Inputs!$K$23,"SG&A_AS_%_TOTAL_SALES")/100} -> 0.039898109 | L27: {=_xll.BDP(Inputs!$K$24,"SG&A_AS_%_TOTAL_SALES")/100} -> 0.27997165 | M27: {=_xll.BDP(Inputs!$K$25,"SG&A_AS_%_TOTAL_SALES")/100} -> 0.61705699 | N27: {=_xll.BDP(Inputs!$Q$21,"SG&A_AS_%_TOTAL_SALES")/100} -> 0.39603066 | O27: {=_xll.BDP(Inputs!$Q$22,"SG&A_AS_%_TOTAL_SALES")/100} -> 0.24404395 | P27: {=_xll.BDP(Inputs!$Q$23,"SG&A_AS_%_TOTAL_SALES")/100} -> 0.30985317 | Q27: {=_xll.BDP(Inputs!$Q$24,"SG&A_AS_%_TOTAL_SALES")/100} -> 0.21492671 | R27: {=_xll.BDP(Inputs!$Q$25,"SG&A_AS_%_TOTAL_SALES")/100} -> 0.36684742
B28: R&D margin | C28: #VALUE! | D28: {=_xll.BDP(Inputs!$E$21,"TRAILING_12M_R&D_%_SALES")/100} -> #VALUE! | E28: {=_xll.BDP(Inputs!$E$22,"TRAILING_12M_R&D_%_SALES")/100} -> #VALUE! | F28: {=_xll.BDP(Inputs!$E$23,"TRAILING_12M_R&D_%_SALES")/100} -> #VALUE! | G28: {=_xll.BDP(Inputs!$E$24,"TRAILING_12M_R&D_%_SALES")/100} -> #VALUE! | H28: {=_xll.BDP(Inputs!$E$25,"TRAILING_12M_R&D_%_SALES")/100} -> #VALUE! | I28: {=_xll.BDP(Inputs!$K$21,"TRAILING_12M_R&D_%_SALES")/100} -> #VALUE! | J28: {=_xll.BDP(Inputs!$K$22,"TRAILING_12M_R&D_%_SALES")/100} -> #VALUE! | K28: {=_xll.BDP(Inputs!$K$23,"TRAILING_12M_R&D_%_SALES")/100} -> #VALUE! | L28: {=_xll.BDP(Inputs!$K$24,"TRAILING_12M_R&D_%_SALES")/100} -> 0.017854982 | M28: {=_xll.BDP(Inputs!$K$25,"TRAILING_12M_R&D_%_SALES")/100} -> #VALUE! | N28: {=_xll.BDP(Inputs!$Q$21,"TRAILING_12M_R&D_%_SALES")/100} -> #VALUE! | O28: {=_xll.BDP(Inputs!$Q$22,"TRAILING_12M_R&D_%_SALES")/100} -> #VALUE! | P28: {=_xll.BDP(Inputs!$Q$23,"TRAILING_12M_R&D_%_SALES")/100} -> #VALUE! | Q28: {=_xll.BDP(Inputs!$Q$24,"TRAILING_12M_R&D_%_SALES")/100} -> #VALUE! | R28: {=_xll.BDP(Inputs!$Q$25,"TRAILING_12M_R&D_%_SALES")/100} -> #VALUE!
A30: x | B30: Returns | C30: CAL-MAINE FOODS | D30: =D21 -> VITAL FARMS INC | E30: =E21 -> POST HOLDINGS IN | F30: =F21 -> TYSON FOODS-A | G30: =G21 -> LAMB WESTON | H30: =H21 -> HORMEL FOODS CRP | I30: =I21 -> GENERAL MILLS IN | J30: =J21 -> CONAGRA BRANDS I | K30: =K21 -> PILGRIM'S PRIDE | ... R30: =R21 -> COLGATE-PALMOLIV
B32: ROIC | C32: 0.49631534 | D32: {=_xll.BDP(Inputs!$E$21,"RETURN_ON_INV_CAPITAL")/100} -> 0.16569803 | E32: {=_xll.BDP(Inputs!$E$22,"RETURN_ON_INV_CAPITAL")/100} -> 0.058291058 | F32: {=_xll.BDP(Inputs!$E$23,"RETURN_ON_INV_CAPITAL")/100} -> 0.03344423 | G32: {=_xll.BDP(Inputs!$E$24,"RETURN_ON_INV_CAPITAL")/100} -> 0.071946428 | H32: {=_xll.BDP(Inputs!$E$25,"RETURN_ON_INV_CAPITAL")/100} -> 0.072628488 | I32: {=_xll.BDP(Inputs!$K$21,"RETURN_ON_INV_CAPITAL")/100} -> 0.14140226 | J32: {=_xll.BDP(Inputs!$K$22,"RETURN_ON_INV_CAPITAL")/100} -> 0.056191781 | K32: {=_xll.BDP(Inputs!$K$23,"RETURN_ON_INV_CAPITAL")/100} -> 0.17544146 | L32: {=_xll.BDP(Inputs!$K$24,"RETURN_ON_INV_CAPITAL")/100} -> 0.11479441 | M32: {=_xll.BDP(Inputs!$K$25,"RETURN_ON_INV_CAPITAL")/100} -> #VALUE! | N32: {=_xll.BDP(Inputs!$Q$21,"RETURN_ON_INV_CAPITAL")/100} -> 0.1270013 | O32: {=_xll.BDP(Inputs!$Q$22,"RETURN_ON_INV_CAPITAL")/100} -> 0.18861607 | P32: {=_xll.BDP(Inputs!$Q$23,"RETURN_ON_INV_CAPITAL")/100} -> 0.13661659 | Q32: {=_xll.BDP(Inputs!$Q$24,"RETURN_ON_INV_CAPITAL")/100} -> 0.29099642 | R32: {=_xll.BDP(Inputs!$Q$25,"RETURN_ON_INV_CAPITAL")/100} -> 0.33781178
B33: CROIC | C33: 0.39078221 | D33: {=_xll.BDP(Inputs!$E$21,"CF_FREE_CASH_FLOW")/_xll.BDP(Inputs!$E$21,"TOTAL_INVESTED_CAPITAL")} -> 0.1252484 | E33: {=_xll.BDP(Inputs!$E$22,"CF_FREE_CASH_FLOW")/_xll.BDP(Inputs!$E$22,"TOTAL_INVESTED_CAPITAL")} -> 0.042492702 | F33: {=_xll.BDP(Inputs!$E$23,"CF_FREE_CASH_FLOW")/_xll.BDP(Inputs!$E$23,"TOTAL_INVESTED_CAPITAL")} -> 0.050218717 | G33: {=_xll.BDP(Inputs!$E$24,"CF_FREE_CASH_FLOW")/_xll.BDP(Inputs!$E$24,"TOTAL_INVESTED_CAPITAL")} -> 0.038396075 | H33: {=_xll.BDP(Inputs!$E$25,"CF_FREE_CASH_FLOW")/_xll.BDP(Inputs!$E$25,"TOTAL_INVESTED_CAPITAL")} -> 0.086889315 | I33: {=_xll.BDP(Inputs!$K$21,"CF_FREE_CASH_FLOW")/_xll.BDP(Inputs!$K$21,"TOTAL_INVESTED_CAPITAL")} -> 0.086669086 | J33: {=_xll.BDP(Inputs!$K$22,"CF_FREE_CASH_FLOW")/_xll.BDP(Inputs!$K$22,"TOTAL_INVESTED_CAPITAL")} -> 0.075526616 | K33: {=_xll.BDP(Inputs!$K$23,"CF_FREE_CASH_FLOW")/_xll.BDP(Inputs!$K$23,"TOTAL_INVESTED_CAPITAL")} -> 0.1817282 | L33: {=_xll.BDP(Inputs!$K$24,"CF_FREE_CASH_FLOW")/_xll.BDP(Inputs!$K$24,"TOTAL_INVESTED_CAPITAL")} -> 0.10351522 | M33: {=_xll.BDP(Inputs!$K$25,"CF_FREE_CASH_FLOW")/_xll.BDP(Inputs!$K$25,"TOTAL_INVESTED_CAPITAL")} -> 0.12538605 | N33: {=_xll.BDP(Inputs!$Q$21,"CF_FREE_CASH_FLOW")/_xll.BDP(Inputs!$Q$21,"TOTAL_INVESTED_CAPITAL")} -> 0.10992355 | O33: {=_xll.BDP(Inputs!$Q$22,"CF_FREE_CASH_FLOW")/_xll.BDP(Inputs!$Q$22,"TOTAL_INVESTED_CAPITAL")} -> 0.15792906 | P33: {=_xll.BDP(Inputs!$Q$23,"CF_FREE_CASH_FLOW")/_xll.BDP(Inputs!$Q$23,"TOTAL_INVESTED_CAPITAL")} -> 0.063087159 | Q33: {=_xll.BDP(Inputs!$Q$24,"CF_FREE_CASH_FLOW")/_xll.BDP(Inputs!$Q$24,"TOTAL_INVESTED_CAPITAL")} -> 0.28369835 | R33: {=_xll.BDP(Inputs!$Q$25,"CF_FREE_CASH_FLOW")/_xll.BDP(Inputs!$Q$25,"TOTAL_INVESTED_CAPITAL")} -> 0.36586876
B34: ROCE | C34: 0.57196465 | D34: {=_xll.BDP(Inputs!$E$21,"IS_OPER_INC")/_xll.BDP(Inputs!$E$21,"CAPITAL_EMPLOYED")} -> 0.2072055 | E34: {=_xll.BDP(Inputs!$E$22,"IS_OPER_INC")/_xll.BDP(Inputs!$E$22,"CAPITAL_EMPLOYED")} -> 0.19516454 | F34: {=_xll.BDP(Inputs!$E$23,"IS_OPER_INC")/_xll.BDP(Inputs!$E$23,"CAPITAL_EMPLOYED")} -> 0.10633962 | G34: {=_xll.BDP(Inputs!$E$24,"IS_OPER_INC")/_xll.BDP(Inputs!$E$24,"CAPITAL_EMPLOYED")} -> 0.15048533 | H34: {=_xll.BDP(Inputs!$E$25,"IS_OPER_INC")/_xll.BDP(Inputs!$E$25,"CAPITAL_EMPLOYED")} -> 0.25489657 | I34: {=_xll.BDP(Inputs!$K$21,"IS_OPER_INC")/_xll.BDP(Inputs!$K$21,"CAPITAL_EMPLOYED")} -> 3.8276581 | J34: {=_xll.BDP(Inputs!$K$22,"IS_OPER_INC")/_xll.BDP(Inputs!$K$22,"CAPITAL_EMPLOYED")} -> 0.45091366 | K34: {=_xll.BDP(Inputs!$K$23,"IS_OPER_INC")/_xll.BDP(Inputs!$K$23,"CAPITAL_EMPLOYED")} -> 0.29082136 | L34: {=_xll.BDP(Inputs!$K$24,"IS_OPER_INC")/_xll.BDP(Inputs!$K$24,"CAPITAL_EMPLOYED")} -> 0.79895816 | M34: {=_xll.BDP(Inputs!$K$25,"IS_OPER_INC")/_xll.BDP(Inputs!$K$25,"CAPITAL_EMPLOYED")} -> 1.8684158 | N34: {=_xll.BDP(Inputs!$Q$21,"IS_OPER_INC")/_xll.BDP(Inputs!$Q$21,"CAPITAL_EMPLOYED")} -> 0.62524865 | O34: {=_xll.BDP(Inputs!$Q$22,"IS_OPER_INC")/_xll.BDP(Inputs!$Q$22,"CAPITAL_EMPLOYED")} -> 1.4446878 | P34: {=_xll.BDP(Inputs!$Q$23,"IS_OPER_INC")/_xll.BDP(Inputs!$Q$23,"CAPITAL_EMPLOYED")} -> 0.64677325 | Q34: {=_xll.BDP(Inputs!$Q$24,"IS_OPER_INC")/_xll.BDP(Inputs!$Q$24,"CAPITAL_EMPLOYED")} -> 0.68254306 | R34: {=_xll.BDP(Inputs!$Q$25,"IS_OPER_INC")/_xll.BDP(Inputs!$Q$25,"CAPITAL_EMPLOYED")} -> 1.1381333
B35: RONA | C35: 0.59880359 | D35: {=_xll.BDP(Inputs!$E$21,"IS_OPER_INC")/_xll.BDP(Inputs!$E$21,"NET_ASSETS")} -> 0.23598785 | E35: {=_xll.BDP(Inputs!$E$22,"IS_OPER_INC")/_xll.BDP(Inputs!$E$22,"NET_ASSETS")} -> 0.19347524 | F35: {=_xll.BDP(Inputs!$E$23,"IS_OPER_INC")/_xll.BDP(Inputs!$E$23,"NET_ASSETS")} -> 0.07610457 | G35: {=_xll.BDP(Inputs!$E$24,"IS_OPER_INC")/_xll.BDP(Inputs!$E$24,"NET_ASSETS")} -> 0.38274731 | H35: {=_xll.BDP(Inputs!$E$25,"IS_OPER_INC")/_xll.BDP(Inputs!$E$25,"NET_ASSETS")} -> 0.13342462 | I35: {=_xll.BDP(Inputs!$K$21,"IS_OPER_INC")/_xll.BDP(Inputs!$K$21,"NET_ASSETS")} -> 0.35878061 | J35: {=_xll.BDP(Inputs!$K$22,"IS_OPER_INC")/_xll.BDP(Inputs!$K$22,"NET_ASSETS")} -> 0.15276456 | K35: {=_xll.BDP(Inputs!$K$23,"IS_OPER_INC")/_xll.BDP(Inputs!$K$23,"NET_ASSETS")} -> 0.35408624 | L35: {=_xll.BDP(Inputs!$K$24,"IS_OPER_INC")/_xll.BDP(Inputs!$K$24,"NET_ASSETS")} -> 0.40127545 | M35: {=_xll.BDP(Inputs!$K$25,"IS_OPER_INC")/_xll.BDP(Inputs!$K$25,"NET_ASSETS")} -> 0.41675903 | N35: {=_xll.BDP(Inputs!$Q$21,"IS_OPER_INC")/_xll.BDP(Inputs!$Q$21,"NET_ASSETS")} -> 0.70920698 | O35: {=_xll.BDP(Inputs!$Q$22,"IS_OPER_INC")/_xll.BDP(Inputs!$Q$22,"NET_ASSETS")} -> 0.39114469 | P35: {=_xll.BDP(Inputs!$Q$23,"IS_OPER_INC")/_xll.BDP(Inputs!$Q$23,"NET_ASSETS")} -> 0.3788867 | Q35: {=_xll.BDP(Inputs!$Q$24,"IS_OPER_INC")/_xll.BDP(Inputs!$Q$24,"NET_ASSETS")} -> 3.1719368 | R35: {=_xll.BDP(Inputs!$Q$25,"IS_OPER_INC")/_xll.BDP(Inputs!$Q$25,"NET_ASSETS")} -> 7.8455882
B36: ROE | C36: 0.5595561 | D36: {=_xll.BDP(Inputs!$E$21,"RETURN_COM_EQY")/100} -> 0.18813241 | E36: {=_xll.BDP(Inputs!$E$22,"RETURN_COM_EQY")/100} -> 0.092251898 | F36: {=_xll.BDP(Inputs!$E$23,"RETURN_COM_EQY")/100} -> 0.043060361 | G36: {=_xll.BDP(Inputs!$E$24,"RETURN_COM_EQY")/100} -> 0.16219495 | H36: {=_xll.BDP(Inputs!$E$25,"RETURN_COM_EQY")/100} -> 0.094609617 | I36: {=_xll.BDP(Inputs!$K$21,"RETURN_COM_EQY")/100} -> 0.31087945 | J36: {=_xll.BDP(Inputs!$K$22,"RETURN_COM_EQY")/100} -> 0.096539741 | K36: {=_xll.BDP(Inputs!$K$23,"RETURN_COM_EQY")/100} -> 0.33129458 | L36: {=_xll.BDP(Inputs!$K$24,"RETURN_COM_EQY")/100} -> 0.33413313 | M36: {=_xll.BDP(Inputs!$K$25,"RETURN_COM_EQY")/100} -> #VALUE! | N36: {=_xll.BDP(Inputs!$Q$21,"RETURN_COM_EQY")/100} -> 0.39879569 | O36: {=_xll.BDP(Inputs!$Q$22,"RETURN_COM_EQY")/100} -> 0.31220751 | P36: {=_xll.BDP(Inputs!$Q$23,"RETURN_COM_EQY")/100} -> 0.44759176 | Q36: {=_xll.BDP(Inputs!$Q$24,"RETURN_COM_EQY")/100} -> 1.9676113 | R36: {=_xll.BDP(Inputs!$Q$25,"RETURN_COM_EQY")/100} -> 7.0521212
B37: ROA | C37: 0.4630708 | D37: {=_xll.BDP(Inputs!$E$21,"RETURN_ON_ASSET")/100} -> 0.13728484 | E37: {=_xll.BDP(Inputs!$E$22,"RETURN_ON_ASSET")/100} -> 0.028731553 | F37: {=_xll.BDP(Inputs!$E$23,"RETURN_ON_ASSET")/100} -> 0.021133215 | G37: {=_xll.BDP(Inputs!$E$24,"RETURN_ON_ASSET")/100} -> 0.039880129 | H37: {=_xll.BDP(Inputs!$E$25,"RETURN_ON_ASSET")/100} -> 0.056709179 | I37: {=_xll.BDP(Inputs!$K$21,"RETURN_ON_ASSET")/100} -> 0.090129166 | J37: {=_xll.BDP(Inputs!$K$22,"RETURN_ON_ASSET")/100} -> 0.040079584 | K37: {=_xll.BDP(Inputs!$K$23,"RETURN_ON_ASSET")/100} -> 0.12251913 | L37: {=_xll.BDP(Inputs!$K$24,"RETURN_ON_ASSET")/100} -> 0.077560805 | M37: {=_xll.BDP(Inputs!$K$25,"RETURN_ON_ASSET")/100} -> #VALUE! | N37: {=_xll.BDP(Inputs!$Q$21,"RETURN_ON_ASSET")/100} -> 0.073702399 | O37: {=_xll.BDP(Inputs!$Q$22,"RETURN_ON_ASSET")/100} -> 0.1290221 | P37: {=_xll.BDP(Inputs!$Q$23,"RETURN_ON_ASSET")/100} -> 0.11854915 | Q37: {=_xll.BDP(Inputs!$Q$24,"RETURN_ON_ASSET")/100} -> 0.14272709 | R37: {=_xll.BDP(Inputs!$Q$25,"RETURN_ON_ASSET")/100} -> 0.17136966
A39: x | B39: Efficiency | C39: CAL-MAINE FOODS | D39: =D30 -> VITAL FARMS INC | E39: =E30 -> POST HOLDINGS IN | F39: =F30 -> TYSON FOODS-A | G39: =G30 -> LAMB WESTON | H39: =H30 -> HORMEL FOODS CRP | I39: =I30 -> GENERAL MILLS IN | J39: =J30 -> CONAGRA BRANDS I | K39: =K30 -> PILGRIM'S PRIDE | ... R39: =R30 -> COLGATE-PALMOLIV
B41: Asset turnover | C41: 1.617604 | D41: {=_xll.BDP(Inputs!$E$21,"ASSET_TURNOVER")} -> 1.751627 | E41: {=_xll.BDP(Inputs!$E$22,"ASSET_TURNOVER")} -> 0.62131688 | F41: {=_xll.BDP(Inputs!$E$23,"ASSET_TURNOVER")} -> 1.4595396 | G41: {=_xll.BDP(Inputs!$E$24,"ASSET_TURNOVER")} -> 0.87550511 | H41: {=_xll.BDP(Inputs!$E$25,"ASSET_TURNOVER")} -> 0.90630291 | I41: {=_xll.BDP(Inputs!$K$21,"ASSET_TURNOVER")} -> 0.59137329 | J41: {=_xll.BDP(Inputs!$K$22,"ASSET_TURNOVER")} -> 0.53985564 | K41: {=_xll.BDP(Inputs!$K$23,"ASSET_TURNOVER")} -> 1.8000006 | L41: {=_xll.BDP(Inputs!$K$24,"ASSET_TURNOVER")} -> 0.68415329 | M41: {=_xll.BDP(Inputs!$K$25,"ASSET_TURNOVER")} -> 0.76787032 | N41: {=_xll.BDP(Inputs!$Q$21,"ASSET_TURNOVER")} -> 0.89563545 | O41: {=_xll.BDP(Inputs!$Q$22,"ASSET_TURNOVER")} -> 0.680805 | P41: {=_xll.BDP(Inputs!$Q$23,"ASSET_TURNOVER")} -> 0.45794634 | Q41: {=_xll.BDP(Inputs!$Q$24,"ASSET_TURNOVER")} -> 1.1091011 | R41: {=_xll.BDP(Inputs!$Q$25,"ASSET_TURNOVER")} -> 1.1780854
B42: Net operating asset turnover | C42: 2.5180722 | D42: {=_xll.BDP(Inputs!$E$21,"SALES_REV_TURN")/(_xll.BDP(Inputs!$E$21,"BS_TOT_ASSET")-_xll.BDP(Inputs!$E$21,"BS_CASH_CASH_EQUIVALENTS_AND_STI")-_xll.BDP(Inputs!$E$21,"SHORT_AND_LONG_TERM_DEBT"))} -> 3.3622268 | E42: {=_xll.BDP(Inputs!$E$22,"SALES_REV_TURN")/(_xll.BDP(Inputs!$E$22,"BS_TOT_ASSET")-_xll.BDP(Inputs!$E$22,"BS_CASH_CASH_EQUIVALENTS_AND_STI")-_xll.BDP(Inputs!$E$22,"SHORT_AND_LONG_TERM_DEBT"))} -> 1.5827673 | F42: {=_xll.BDP(Inputs!$E$23,"SALES_REV_TURN")/(_xll.BDP(Inputs!$E$23,"BS_TOT_ASSET")-_xll.BDP(Inputs!$E$23,"BS_CASH_CASH_EQUIVALENTS_AND_STI")-_xll.BDP(Inputs!$E$23,"SHORT_AND_LONG_TERM_DEBT"))} -> 2.1407517 | G42: {=_xll.BDP(Inputs!$E$24,"SALES_REV_TURN")/(_xll.BDP(Inputs!$E$24,"BS_TOT_ASSET")-_xll.BDP(Inputs!$E$24,"BS_CASH_CASH_EQUIVALENTS_AND_STI")-_xll.BDP(Inputs!$E$24,"SHORT_AND_LONG_TERM_DEBT"))} -> 2.1029762 | H42: {=_xll.BDP(Inputs!$E$25,"SALES_REV_TURN")/(_xll.BDP(Inputs!$E$25,"BS_TOT_ASSET")-_xll.BDP(Inputs!$E$25,"BS_CASH_CASH_EQUIVALENTS_AND_STI")-_xll.BDP(Inputs!$E$25,"SHORT_AND_LONG_TERM_DEBT"))} -> 1.2345488 | I42: {=_xll.BDP(Inputs!$K$21,"SALES_REV_TURN")/(_xll.BDP(Inputs!$K$21,"BS_TOT_ASSET")-_xll.BDP(Inputs!$K$21,"BS_CASH_CASH_EQUIVALENTS_AND_STI")-_xll.BDP(Inputs!$K$21,"SHORT_AND_LONG_TERM_DEBT"))} -> 1.1192441 | J42: {=_xll.BDP(Inputs!$K$22,"SALES_REV_TURN")/(_xll.BDP(Inputs!$K$22,"BS_TOT_ASSET")-_xll.BDP(Inputs!$K$22,"BS_CASH_CASH_EQUIVALENTS_AND_STI")-_xll.BDP(Inputs!$K$22,"SHORT_AND_LONG_TERM_DEBT"))} -> 0.9249321 | K42: {=_xll.BDP(Inputs!$K$23,"SALES_REV_TURN")/(_xll.BDP(Inputs!$K$23,"BS_TOT_ASSET")-_xll.BDP(Inputs!$K$23,"BS_CASH_CASH_EQUIVALENTS_AND_STI")-_xll.BDP(Inputs!$K$23,"SHORT_AND_LONG_TERM_DEBT"))} -> 3.5542361 | L42: {=_xll.BDP(Inputs!$K$24,"SALES_REV_TURN")/(_xll.BDP(Inputs!$K$24,"BS_TOT_ASSET")-_xll.BDP(Inputs!$K$24,"BS_CASH_CASH_EQUIVALENTS_AND_STI")-_xll.BDP(Inputs!$K$24,"SHORT_AND_LONG_TERM_DEBT"))} -> 1.3360135 | M42: {=_xll.BDP(Inputs!$K$25,"SALES_REV_TURN")/(_xll.BDP(Inputs!$K$25,"BS_TOT_ASSET")-_xll.BDP(Inputs!$K$25,"BS_CASH_CASH_EQUIVALENTS_AND_STI")-_xll.BDP(Inputs!$K$25,"SHORT_AND_LONG_TERM_DEBT"))} -> 1.4990871 | N42: {=_xll.BDP(Inputs!$Q$21,"SALES_REV_TURN")/(_xll.BDP(Inputs!$Q$21,"BS_TOT_ASSET")-_xll.BDP(Inputs!$Q$21,"BS_CASH_CASH_EQUIVALENTS_AND_STI")-_xll.BDP(Inputs!$Q$21,"SHORT_AND_LONG_TERM_DEBT"))} -> 2.1638163 | O42: {=_xll.BDP(Inputs!$Q$22,"SALES_REV_TURN")/(_xll.BDP(Inputs!$Q$22,"BS_TOT_ASSET")-_xll.BDP(Inputs!$Q$22,"BS_CASH_CASH_EQUIVALENTS_AND_STI")-_xll.BDP(Inputs!$Q$22,"SHORT_AND_LONG_TERM_DEBT"))} -> 1.0507786 | P42: {=_xll.BDP(Inputs!$Q$23,"SALES_REV_TURN")/(_xll.BDP(Inputs!$Q$23,"BS_TOT_ASSET")-_xll.BDP(Inputs!$Q$23,"BS_CASH_CASH_EQUIVALENTS_AND_STI")-_xll.BDP(Inputs!$Q$23,"SHORT_AND_LONG_TERM_DEBT"))} -> 1.1694208 | Q42: {=_xll.BDP(Inputs!$Q$24,"SALES_REV_TURN")/(_xll.BDP(Inputs!$Q$24,"BS_TOT_ASSET")-_xll.BDP(Inputs!$Q$24,"BS_CASH_CASH_EQUIVALENTS_AND_STI")-_xll.BDP(Inputs!$Q$24,"SHORT_AND_LONG_TERM_DEBT"))} -> 2.6233325 | R42: {=_xll.BDP(Inputs!$Q$25,"SALES_REV_TURN")/(_xll.BDP(Inputs!$Q$25,"BS_TOT_ASSET")-_xll.BDP(Inputs!$Q$25,"BS_CASH_CASH_EQUIVALENTS_AND_STI")-_xll.BDP(Inputs!$Q$25,"SHORT_AND_LONG_TERM_DEBT"))} -> 3.2018159
B43: Fixed asset turnover | C43: 4.524491 | D43: {=_xll.BDP(Inputs!$E$21,"NET_FIX_ASSET_TURN")} -> 5.8967449 | E43: {=_xll.BDP(Inputs!$E$22,"NET_FIX_ASSET_TURN")} -> 3.4224978 | F43: {=_xll.BDP(Inputs!$E$23,"NET_FIX_ASSET_TURN")} -> 5.8698032 | G43: {=_xll.BDP(Inputs!$E$24,"NET_FIX_ASSET_TURN")} -> 1.6938414 | H43: {=_xll.BDP(Inputs!$E$25,"NET_FIX_ASSET_TURN")} -> 5.5046471 | I43: {=_xll.BDP(Inputs!$K$21,"NET_FIX_ASSET_TURN")} -> 5.2057884 | J43: {=_xll.BDP(Inputs!$K$22,"NET_FIX_ASSET_TURN")} -> 4.0228007 | K43: {=_xll.BDP(Inputs!$K$23,"NET_FIX_ASSET_TURN")} -> 5.2424206 | L43: {=_xll.BDP(Inputs!$K$24,"NET_FIX_ASSET_TURN")} -> 2.8380661 | M43: {=_xll.BDP(Inputs!$K$25,"NET_FIX_ASSET_TURN")} -> 5.4296216 | N43: {=_xll.BDP(Inputs!$Q$21,"NET_FIX_ASSET_TURN")} -> 3.286162 | O43: {=_xll.BDP(Inputs!$Q$22,"NET_FIX_ASSET_TURN")} -> 3.5229158 | P43: {=_xll.BDP(Inputs!$Q$23,"NET_FIX_ASSET_TURN")} -> 4.6384782 | Q43: {=_xll.BDP(Inputs!$Q$24,"NET_FIX_ASSET_TURN")} -> 2.7097654 | R43: {=_xll.BDP(Inputs!$Q$25,"NET_FIX_ASSET_TURN")} -> 4.4833539
