Workbook
Name COOLFUCNTION: _xlfn.LAMBDA(_xldudf_BOARDFLARE_EXEC("workbook-settings:coolfucntion"))
Name COOLFUCNTION: _xlfn.LAMBDA(_xldudf_BOARDFLARE_EXEC("workbook-settings:coolfucntion"))
Name COOLFUCNTION: _xlfn.LAMBDA(_xldudf_BOARDFLARE_EXEC("workbook-settings:coolfucntion"))
Name COOLFUCNTION: _xlfn.LAMBDA(_xldudf_BOARDFLARE_EXEC("workbook-settings:coolfucntion"))
Name COOLFUCNTION: _xlfn.LAMBDA(_xldudf_BOARDFLARE_EXEC("workbook-settings:coolfucntion"))
Name COOLFUCNTION: _xlfn.LAMBDA(_xldudf_BOARDFLARE_EXEC("workbook-settings:coolfucntion"))
Name COOLFUCNTION: _xlfn.LAMBDA(_xldudf_BOARDFLARE_EXEC("workbook-settings:coolfucntion"))
Name COOLFUCNTION: _xlfn.LAMBDA(_xldudf_BOARDFLARE_EXEC("workbook-settings:coolfucntion"))
Name COOLFUCNTION: _xlfn.LAMBDA(_xldudf_BOARDFLARE_EXEC("workbook-settings:coolfucntion"))
Name COOLFUCNTION: _xlfn.LAMBDA(_xldudf_BOARDFLARE_EXEC("workbook-settings:coolfucntion"))
Name COOLFUCNTION: _xlfn.LAMBDA(_xldudf_BOARDFLARE_EXEC("workbook-settings:coolfucntion"))
Name Sectors: #REF!
Name Sectors: #REF!
Name Sectors: #REF!
Name Sectors: #REF!
Name Sectors: #REF!
Name Sectors: #REF!
Name Sectors: #REF!
Name Sectors: #REF!

Sheet Dashboard
C154: =+C155+1 -> 45957
C155: =+C156+1 -> 45956
C156: =+C157+1 -> 45955
C157: =+C158+1 -> 45954
C158: =+C159+1 -> 45953
C159: =+C160+1 -> 45952
C160: =+C161+1 -> 45951 | L160: =IF(FCFF!$R$157="Revenue Exit",FCFF!$AF$169,IF(FCFF!$R$157="EBITDA Exit",FCFF!Z169,FCFF!AL169)) -> 393.57378
C161: =+C162+1 -> 45950
C162: =+C163+1 -> 45949 | E162: =IF(FCFF!$R$157="Revenue Exit",FCFF!$AF$169,IF(FCFF!$R$157="EBITDA Exit",FCFF!Z169,FCFF!AL169)) -> 393.57378
C163: =+C164+1 -> 45948 | E163: =E164+($E$162-$E$193)/COUNTA($C$162:$C$192) -> 396.41043
C164: =+C165+1 -> 45947 | E164: =E165+($E$162-$E$193)/COUNTA($C$162:$C$192) -> 399.24708
C165: =+C166+1 -> 45946 | E165: =E166+($E$162-$E$193)/COUNTA($C$162:$C$192) -> 402.08373
C166: =+C167+1 -> 45945 | E166: =E167+($E$162-$E$193)/COUNTA($C$162:$C$192) -> 404.92039
C167: =+C168+1 -> 45944 | E167: =E168+($E$162-$E$193)/COUNTA($C$162:$C$192) -> 407.75704
C168: =+C169+1 -> 45943 | E168: =E169+($E$162-$E$193)/COUNTA($C$162:$C$192) -> 410.59369
C169: =+C170+1 -> 45942 | E169: =E170+($E$162-$E$193)/COUNTA($C$162:$C$192) -> 413.43034
C170: =+C171+1 -> 45941 | E170: =E171+($E$162-$E$193)/COUNTA($C$162:$C$192) -> 416.26699
C171: =+C172+1 -> 45940 | E171: =E172+($E$162-$E$193)/COUNTA($C$162:$C$192) -> 419.10365
C172: =+C173+1 -> 45939 | E172: =E173+($E$162-$E$193)/COUNTA($C$162:$C$192) -> 421.9403
C173: =+C174+1 -> 45938 | E173: =E174+($E$162-$E$193)/COUNTA($C$162:$C$192) -> 424.77695
C174: =+C175+1 -> 45937 | E174: =E175+($E$162-$E$193)/COUNTA($C$162:$C$192) -> 427.6136
... C192: =+C193+1 -> 45919 | E192: =E193+($E$162-$E$193)/COUNTA($C$162:$C$192) -> 478.67335
B193: TODAY | C193: =+'Stock Data'!AM4 -> 45918 | D193: =_xlfn.XLOOKUP(C193,'Stock Data'!$AM$4:$AM$1051,'Stock Data'!$AN$4:$AN$1051) -> 481.51 | E193: =D193 -> 481.51
C194: =+'Stock Data'!AM5 -> 45917 | D194: =_xlfn.XLOOKUP(C194,'Stock Data'!$AM$4:$AM$1051,'Stock Data'!$AN$4:$AN$1051) -> 481.51
C195: =+'Stock Data'!AM6 -> 45916 | D195: =_xlfn.XLOOKUP(C195,'Stock Data'!$AM$4:$AM$1051,'Stock Data'!$AN$4:$AN$1051) -> 473.26
C196: =+'Stock Data'!AM7 -> 45915 | D196: =_xlfn.XLOOKUP(C196,'Stock Data'!$AM$4:$AM$1051,'Stock Data'!$AN$4:$AN$1051) -> 473.26
C197: =+'Stock Data'!AM8 -> 45914 | D197: =_xlfn.XLOOKUP(C197,'Stock Data'!$AM$4:$AM$1051,'Stock Data'!$AN$4:$AN$1051) -> 473.26
C198: =+'Stock Data'!AM9 -> 45913 | D198: =_xlfn.XLOOKUP(C198,'Stock Data'!$AM$4:$AM$1051,'Stock Data'!$AN$4:$AN$1051) -> 474.9
C199: =+'Stock Data'!AM10 -> 45912 | D199: =_xlfn.XLOOKUP(C199,'Stock Data'!$AM$4:$AM$1051,'Stock Data'!$AN$4:$AN$1051) -> 469.52
C200: =+'Stock Data'!AM11 -> 45911 | D200: =_xlfn.XLOOKUP(C200,'Stock Data'!$AM$4:$AM$1051,'Stock Data'!$AN$4:$AN$1051) -> 476.78
C201: =+'Stock Data'!AM12 -> 45910 | D201: =_xlfn.XLOOKUP(C201,'Stock Data'!$AM$4:$AM$1051,'Stock Data'!$AN$4:$AN$1051) -> 478.64
C202: =+'Stock Data'!AM13 -> 45909 | D202: =_xlfn.XLOOKUP(C202,'Stock Data'!$AM$4:$AM$1051,'Stock Data'!$AN$4:$AN$1051) -> 478.64
C203: =+'Stock Data'!AM14 -> 45908 | D203: =_xlfn.XLOOKUP(C203,'Stock Data'!$AM$4:$AM$1051,'Stock Data'!$AN$4:$AN$1051) -> 478.64
C204: =+'Stock Data'!AM15 -> 45907 | D204: =_xlfn.XLOOKUP(C204,'Stock Data'!$AM$4:$AM$1051,'Stock Data'!$AN$4:$AN$1051) -> 478.64
C205: =+'Stock Data'!AM16 -> 45906 | D205: =_xlfn.XLOOKUP(C205,'Stock Data'!$AM$4:$AM$1051,'Stock Data'!$AN$4:$AN$1051) -> 491.44
... C558: =+'Stock Data'!AM369 -> 45553 | D558: =_xlfn.XLOOKUP(C558,'Stock Data'!$AM$4:$AM$1051,'Stock Data'!$AN$4:$AN$1051) -> 387.23

Sheet Key Info
B7: Analysts | F7: LIS – Equity Research | J7: Stock Performance
B12: Daniel Cruz, Team Leader and Analyst | F12: Recommendation: | H12: Hold
B13: Bsc in Applied Mathematics, ISEG – Ulisboa | F13: Target Price (FCFF): | H13: =FCFF!AF169 -> 393.57378
B14: danielfccruz@aln.iseg.ulisboa.pt | F14: Upside: | H14: =FCFF!AF171 -> -0.18262596
B15: Daan Bootsma, Analyst
B16: Bsc in Management, ISEG – Ulisboa | F16: Ticker | H16: =Inputs!D15 -> DE US Equity
B17: d.bootsma@aln.iseg.ulisboa.pt | F17: Stock Exchange | H17: NYSE
B18: Nicole Sequeira, Analyst
B19: Bsc in Applied Mathematics, ISEG – Ulisboa | F19: Current Price | H19: ='Stock Data'!AN4 -> 481.51
B20: l63823@aln.iseg.ulisboa.pt | F20: ="Market Cap (in "&IF(Inputs!$D$14="BLN","billions",IF(Inputs!$D$14="MLN","millions","thousands"))&")" -> Market Cap (in millions) | H20: ='Stock Data'!AQ4 -> 130166.3
F21: Beta | H21: ='Stock Data'!E164 -> 0.89700514
F22: % of 52-Week High | H22: ='Stock Data'!E165 -> 0.55938667
F23: 100-Day Moving Average | H23: ='Stock Data'!E166 -> 500.28311
B25: Reviewed by: | F25: Avg Vol (1 month) | H25: ='Stock Data'!E168 -> 1490618.5
B26: Tomás Reis, Analyst | F26: Shares Outstanding (millions) | H26: ='Stock Data'!E169 -> 270.3294
B27: Bsc in XXX, ISEG – Ulisboa | F27: % Float | H27: ='Stock Data'!E170 -> 0.9248926
B28: email@aln.iseg.ulisboa.pt | F28: Short % of Float | H28: =IFERROR('Stock Data'!E171,0) -> 0.017152
B30: LISBON INVESTMENT SOCIETY | F30: % Held by Insiders | H30: ='Stock Data'!E173 -> 0.0019671067
B31: ISEG – Rua do Quelhas, 6 | F31: % Held by Institutions | H31: ='Stock Data'!E174 -> 0.8491587
B32: lis@iseg.ulisboa.pt
B34: Disclaimer: This report was prepared by members of the Lisbon Investment Society (LIS), an independent, student-led, non-profit organization based at ISEG – Lisbon School of Economics & Management, and is intended solely for academic and educational purposes. All analyses, forecasts, and opinions expressed in this report reflect the independent judgment of the authors as of the date of publication and are subject to change without notice. The views presented herein do not represent those of ISEG, its faculty, or any affiliated entity. This document does not constitute, and should not be interpreted as, investment advice, an offer, or a solicitation to buy or sell any security or financial instrument. Nothing in this report should be construed as a recommendation to make or refrain from making any investment decision. The content is intended for informational purposes only, and readers are strongly encouraged to conduct their own research and seek advice from a qualified financial professional before making any financial decisions. The information contained in this report has been obtained from publicly available sources believed to be reliable; however, no representation or warranty is made regarding the accuracy, completeness, or timeliness of such information. LIS and its members accept no liability whatsoever for any direct or indirect loss arising from the use of this report or its contents. This report incorporates terminology, financial metrics, and methodologies commonly used in professional equity research, including but not limited to Discounted Cash Flow (DCF), trading multiples, Monte Carlo simulations, and strategic analysis tools such as Porter’s Five Forces. Definitions and assumptions used in these models are disclosed within the report and reflect a hypothetical investment thesis designed solely for academic discussion. All valuations, projections, and target prices presented herein are based on publicly available data and subject to the limitations of modeling assumptions. These are not guarantees of future performance and should not be relied upon as such, as past performance is not indicative of future results. Any company names, logos, trademarks, or brand references mentioned in this report are the property of their respective owners and are used strictly for identification and academic purposes. This document may not be reproduced, redistributed, or quoted in whole or in part without the prior written consent of the Lisbon Investment Society. About LIS – Lisbon Investment Society: The Lisbon Investment Society (LIS) is a non-profit academic association headquartered at ISEG – Lisbon School of Economics & Management. Founded in 2016, LIS is committed to fostering student interest in finance and investment through applied research, skill development, and institutional engagement. The Society operates independently and autonomously from any political, religious, or commercial affiliation, and is composed of selected students and collaborators who are invited through a rigorous recruitment process and share a commitment to excellence, analytical rigor, and ethical standards. Its activities include equity research, portfolio management, macroeconomic analysis, and investment education. This report was prepared by the Equity Research team at the Lisbon Investment Society, whose analysts combine rigorous financial modeling, critical thinking, and collaborative research to deliver high-quality, student-led investment analysis. We welcome your feedback, discussion, and questions regarding this report or our research process, and invite you to reach out to our team as we are always open to engagement.

Sheet Industry
D6: 584.17 | E6: 627.76 | F6: 676.06 | G6: 729.63 | H6: 789.13 | I6: 855.3 | J6: 929 | K6: 997.69 | L6: 1067.63 | M6: 1137.57
A7: x | B7: Industry Growth Forecast | O7: Industry Index
D9: 2022 | E9: =+D9+1 -> 2023 | F9: =+E9+1 -> 2024 | G9: =+F9+1 -> 2025 | H9: =+G9+1 -> 2026 | I9: =+H9+1 -> 2027 | J9: =+I9+1 -> 2028 | K9: =+J9+1 -> 2029 | M9: ="CAGR "&$G$9&" - "&$K$9 -> CAGR 2025 - 2029
B12: Market Size Agricultural Machinery Manufacturing | D12: =D44 -> 97000 | E12: =E44 -> 98240 | F12: =F44 -> 100150 | G12: =G44 -> 142623.33 | H12: =H44 -> 149425.68 | I12: =I44 -> 156862.05 | J12: =J44 -> 164388.05 | K12: =K44 -> 172600.88 | M12: =(K12/G12)^(1/5)-1 -> 0.038892203
B13: Market Share | D13: =SUM(Segments!T12:T13)/D12 -> 0.3647732 | E13: =SUM(Segments!N12:N13)/E12 -> 0.28877239 | F13: =SUM(Segments!AF12:AF13)/F12 -> 0.31755367 | G13: =SUM(Segments!AL12:AL13)/G12 -> 0.19011637 | H13: =SUM(Segments!AR12:AR13)/H12 -> 0.1925837 | I13: =SUM(Segments!AT12:AT13)/I12 -> 0.20662448 | J13: =SUM(Segments!AV12:AV13)/J12 -> 0.22792253 | K13: =SUM(Segments!AX12:AX13)/K12 -> 0.22554335 | M13: =((K13*K12)/(G13*G12))^(1/5)-1 -> 0.075010215
B14: Market Size Construction Equipment | D14: 198500 | E14: 208425 | F14: 196478.75 | G14: 201113.39 | H14: 212109.52 | I14: 223721.77 | J14: 235985.5 | K14: 248938.15 | M14: =(K14/G14)^(1/5)-1 -> 0.043590444
B15: Market Share | D15: =SUM(Segments!T32:T34)/D14 -> 0.055274559 | E15: =SUM(Segments!Z32:Z34)/E14 -> 0.062789972 | F15: =SUM(Segments!AF32:AF34)/F14 -> 0.059156525 | G15: =SUM(Segments!AL32:AL34)/G14 -> 0.04968117 | H15: =SUM(Segments!AR32:AR34)/H14 -> 0.050826992 | I15: =SUM(Segments!AT32:AT34)/I14 -> 0.052647065 | J15: =SUM(Segments!AV32:AV34)/J14 -> 0.055960787 | K15: =SUM(Segments!AX32:AX34)/K14 -> 0.05527712 | M15: =((K15*K14)/(G15*G14))^(1/5)-1 -> 0.066107044
B16: Market Size Forestry Machinery | G16: 12000 | H16: =G16*1.046 -> 12552 | I16: =H16*1.046 -> 13129.392 | J16: =I16*1.046 -> 13733.344 | K16: =J16*1.046 -> 14365.078 | M16: =(K16/G16)^(1/5)-1 -> 0.036633758
B17: Market Share | G17: =Segments!AL35/G16 -> 0.098943465 | H17: =Segments!AR35/H16 -> 0.10206509 | I17: =Segments!AT35/I16 -> 0.10660397 | J17: =Segments!AV35/J16 -> 0.11426899 | K17: =Segments!AX35/K16 -> 0.11383202 | M17: =((K17*K16)/(G17*G16))^(1/5)-1 -> 0.066107044
B18: Market Size | M18: =(K18/G18)^(1/5)-1 -> #DIV/0!
B19: Market Share | M19: =((K19*K18)/(G19*G18))^(1/5)-1 -> #DIV/0!
B20: Market Size | M20: =(K20/G20)^(1/5)-1 -> #DIV/0!
B21: Market Share | M21: =((K21*K20)/(G21*G20))^(1/5)-1 -> #DIV/0!
A23: x
B25: Industry Driver | D25: Description | O25: Porter's Five Forces
B27: AGRICULTURAL MACHINERY
B28: Labor Shortage Crisis & Automation Demand | D28: Agricultural labor shortages are intensifying globally, with the US immigration restrictions are reducing farm labor availability, creating urgent demand for autonomous tractors, precision agriculture technology, and smart machinery to compensate for workforce gaps.
B29: Precision Agriculture & Technology Integration | D29: The industry is experiencing a rush toward autonomous field operations, with connected machinery using IoT, AI, and data analytics to optimize crop yields and resource management. Farmers need GPS-guided equipment, variable rate technology, and data-driven decision systems to maximize productivity while reducing input costs amid challenging farm economics.
B30: Government Support & Infrastructure Investment | D30: Government farm mechanization subsidies and climate-linked incentives are reinforcing equipment demand Industry. Farm aid resuming in 2026 will improve purchasing power. Additionally, sustainability regulations are pushing adoption of low-emission, electric, and precision equipment that reduces environmental impact.
B31: CONSTRUCTION EQUIPMENT
B32: Massive Infrastructure Spending & Urbanization | D32: Government infrastructure investments are driving sustained demand, with the US Infrastructure Investment and Jobs Act providing multi-year disbursements for roads, bridges, and broadband, while data center construction creates additional specialized equipment needs. Rapid urbanization with over 80% of the US population in urban areas is fueling residential and commercial construction projects requiring earthmoving and material handling equipment. | O32: Rivalry Among Existing Competitors | R32: =R58 -> 3.8
O33: Threat of New Entrants | R33: =R39 -> 2.5
B34: FORESTRY EQUIPMENT | O34: Threat of Substitutes | R34: =R64 -> 3
B35: Sustainable Forest Management & Bioenergy Demand | D35: Growing emphasis on sustainable forestry practices and renewable energy is driving adoption of advanced, eco-friendly machinery, with wood and biomass increasingly used for bioenergy production. Electric and hybrid forestry equipment featuring telematics, GPS systems, and autonomous capabilities is gaining market share as operators seek to minimize ecological impact while improving operational efficiency and meeting stricter environmental regulations | O35: Bargaining Power of Customers | R35: =R52 -> 3.2
O36: Bargaining Power of Suppliers | R36: =R46 -> 2.6
O39: Threat of New Entrants | R39: =AVERAGE(R40:R45) -> 2.5
B40: Market Size Agricultural Machinery Manufacturing | D40: 2022 | E40: 2023 | F40: 2024 | G40: 2025 | H40: 2026 | I40: 2027 | J40: 2028 | K40: 2029 | O40: Economies of scale | R40: 2 | T40: Are relevant for this industry
B41: Statista | D41: 97000 | E41: 98240 | F41: 100150 | G41: 100300 | H41: 100730 | I41: 101830 | J41: 101890 | K41: 102620 | O41: Product differentiation | R41: 3 | T41: Research by Farm Equipment find that 63% farmers were brand loyal in 2024
B42: Grand View Research | G42: =176.02*1000 -> 176020 | H42: =G42*1.067 -> 187813.34 | I42: =H42*1.067 -> 200396.83 | J42: =I42*1.067 -> 213823.42 | K42: =J42*1.067 -> 228149.59 | O42: Capital requirements | R42: 2 | T42: Complicated, highly fractured supply, and large numbers required
B43: Mordor Intelligence | G43: =151.55*1000 -> 151550 | H43: =G43*1.054 -> 159733.7 | I43: =H43*1.054 -> 168359.32 | J43: =I43*1.054 -> 177450.72 | K43: =J43*1.054 -> 187033.06 | O43: Access to distribution channels | R43: 2 | T43: DE has a vast expansioning dealer network
B44: Average | D44: =AVERAGE(D41:D43) -> 97000 | E44: =AVERAGE(E41:E43) -> 98240 | F44: =AVERAGE(F41:F43) -> 100150 | G44: =AVERAGE(G41:G43) -> 142623.33 | H44: =AVERAGE(H41:H43) -> 149425.68 | I44: =AVERAGE(I41:I43) -> 156862.05 | J44: =AVERAGE(J41:J43) -> 164388.05 | K44: =AVERAGE(K41:K43) -> 172600.88 | M44: =(K44/G44)^(1/5)-1 -> 0.038892203 | O44: Regulations | R44: 3 | T44: Depending on region, various safety and now environmental regulations exist
O45: Switching costs | R45: 3 | T45: Ecosystems are getting more and more integrated in developed countries
O46: Bargaining Power of Suppliers | R46: =AVERAGE(R47:R51) -> 2.6 | T46: ALAMO GROUP | U46: TEREX CORP | V46: AGCO CORP | W46: KOMATSU LTD-ADR | X46: KUBOTA CORP-ADR | Y46: CNH INDUSTRIAL N | Z46: DEERE & CO | AA46: CATTERPILLAR INC
O47: Number of suppliers | R47: 3 | T47: 16 | U47: 52 | V47: 101 | W47: 132 | X47: 150 | Y47: 164 | Z47: 245 | AA47: 372
O48: Uniqueness | R48: 3 | T48: Suppliers per firm differ vastly
O49: Switching Costs | R49: 3 | T49: Honestly not sure
O50: Forward Integration | R50: 2 | T50: Suppliers deliver specific parts, not whole sale products
B51: Construction Equipment Market (in Millions) | D51: 2022 | E51: 2023 | F51: 2024 | G51: 2025 | H51: 2026 | I51: 2027 | J51: 2028 | K51: 2029 | L51: 2030 | M51: CAGR | O51: Industry Importance | R51: 2 | T51: Suppliers are mostly not restricted to this industry
B52: Mordor Intelligence | G52: =192.59*1000 -> 192590 | H52: =G52*1.0673 -> 205551.31 | I52: =H52*1.0673 -> 219384.91 | J52: =I52*1.0673 -> 234149.51 | K52: =J52*1.0673 -> 249907.78 | L52: =K52*1.0673 -> 266726.57 | O52: Bargaining Power of Customers | R52: =AVERAGE(R53:R57) -> 3.2
B53: Econ Market Research | D53: =198.5*1000 -> 198500 | E53: =D53*1.05 -> 208425 | F53: =E53*1.05 -> 218846.25 | G53: =F53*1.05 -> 229788.56 | H53: =G53*1.05 -> 241277.99 | I53: =H53*1.05 -> 253341.89 | J53: =I53*1.05 -> 266008.98 | K53: =J53*1.05 -> 279309.43 | L53: =K53*1.05 -> 293274.91 | O53: Number of buyers | R53: 3 | T53: I expect the number of buyers to decrease over time
...

Sheet Segments
B7: Segments | D7: 2020 | J7: =D7+1 -> 2021 | P7: =J7+1 -> 2022 | V7: =P7+1 -> 2023 | AB7: =V7+1 -> 2024 | AH7: =AB7+1 -> 2025 | AN7: =AH7+1 -> 2026 | AT7: =AN7+1 -> 2027 | AV7: =+AT7+1 -> 2028 | AX7: =+AV7+1 -> 2029
D8: Q1 | E8: Q2 | F8: Q3 | G8: Q4 | H8: FY | I8: % | J8: Q1 | K8: Q2 | L8: Q3 | M8: Q4 | N8: FY | P8: Q1 | Q8: Q2 | R8: Q3 | S8: Q4 | T8: FY | V8: Q1 | W8: Q2 | X8: Q3 | Y8: Q4 | Z8: FY | AB8: Q1 | AC8: Q2 | AD8: Q3 | AE8: Q4 | AF8: FY | AH8: Q1 | AI8: Q2 | AJ8: Q3 | AK8: Q4 | AL8: FY | AM8: DE | AN8: Q1 | AO8: Q2 | AP8: Q3 | AQ8: DE | AR8: FY | AS8: DE | AT8: FY | AV8: FY | AX8: FY
B11: Revenue by segment: | AZ11: Production agriculture
B12: Production and Precision Agriculture (PPA) | H12: 12962 | I12: =H12/H$17 -> 0.36471581 | N12: 16509 | O12: =N12/N$17 -> 0.375 | T12: 22002 | U12: =T12/T$17 -> 0.41847196 | Z12: 26790 | AA12: =Z12/Z$17 -> 0.43738061 | AF12: 20834 | AG12: =AF12/AF$17 -> 0.40285405 | AL12: 17210.74 | AM12: =AL12/AL$17 -> 0.38132623 | AR12: 18108 | AS12: =AR12/AR$17 -> 0.37793871 | AT12: 20688.61 | AU12: =AT12/AT$17 -> 0.38970224 | AV12: 24245.9 | AW12: =AV12/AV$17 -> 0.40260079 | AX12: =AV12*1.039 -> 25191.49 | AY12: =AX12/AX$17 -> 0.39939592 | AZ12: Small agriculture
B13: Small Agriculture and Turf (SAT) | H13: 9363 | I13: =H13/H$17 -> 0.26344963 | N13: 11860 | O13: =N13/N$17 -> 0.26939851 | T13: 13381 | U13: =T13/T$17 -> 0.25450292 | Z13: 13980 | AA13: =Z13/Z$17 -> 0.22824117 | AF13: 10969 | AG13: =AF13/AF$17 -> 0.2121007 | AL13: 9904.29 | AM13: =AL13/AL$17 -> 0.21944237 | AR13: 10668.95 | AS13: =AR13/AR$17 -> 0.22267557 | AT13: 11722.93 | AU13: =AT13/AT$17 -> 0.22081967 | AV13: 13221.84 | AW13: =AV13/AV$17 -> 0.21954736 | AX13: =AV13*1.039 -> 13737.492 | AY13: =AX13/AX$17 -> 0.21779967 | AZ13: Turf
B14: Construction and Forestry (CF) | H14: 9181 | I14: =H14/H$17 -> 0.25832864 | N14: 11613 | O14: =N14/N$17 -> 0.26378793 | T14: 13065 | U14: =T14/T$17 -> 0.24849269 | Z14: 15020 | AA14: =Z14/Z$17 -> 0.24522049 | AF14: 13254 | AG14: =AF14/AF$17 -> 0.25628432 | AL14: 11178.87 | AM14: =AL14/AL$17 -> 0.24768234 | AR14: 12062.01 | AS14: =AR14/AR$17 -> 0.25175064 | AT14: 13177.94 | AU14: =AT14/AT$17 -> 0.24822706 | AV14: 14775.23 | AW14: =AV14/AV$17 -> 0.24534125 | AX14: =AV14*1.042 -> 15395.79 | AY14: =AX14/AX$17 -> 0.24409098 | AZ14: Construction
B15: Financial Services (FS) | H15: 3589 | I15: =H15/H$17 -> 0.10098481 | N15: 3548 | O15: =N15/N$17 -> 0.080592404 | T15: 3625 | U15: =T15/T$17 -> 0.068946498 | Z15: 4721 | AA15: =Z15/Z$17 -> 0.077076293 | AF15: 5782 | AG15: =AF15/AF$17 -> 0.11180292 | AL15: 5833.24 | AM15: =AL15/AL$17 -> 0.12924299 | AR15: 6018.81 | AS15: =AR15/AR$17 -> 0.12562079 | AT15: 6364.38 | AU15: =AT15/AT$17 -> 0.11988302 | AV15: 6794.07 | AW15: =AV15/AV$17 -> 0.11281487 | AX15: =(AT15/AL15)*AV15 -> 7412.6974 | AY15: =AX15/AX$17 -> 0.11752386 | AZ15: Compact Construction
B16: Other | H16: 679 | I16: =H16/H$17 -> 0.019105234 | N16: 739 | O16: =N16/N$17 -> 0.016786298 | T16: 1035 | U16: =T16/T$17 -> 0.019685414 | Z16: 965 | AA16: =Z16/Z$17 -> 0.015754845 | AF16: 1175 | AG16: =AF16/AF$17 -> 0.022720241 | AL16: 1006.76 | AM16: =AL16/AL$17 -> 0.022306071 | AR16: 1054.76 | AS16: =AR16/AR$17 -> 0.022014283 | AT16: 1134.39 | AU16: =AT16/AT$17 -> 0.021368005 | AV16: 1186.14 | AW16: =AV16/AV$17 -> 0.019695738 | AX16: =(AT16/AL16)*AV16 -> 1336.5105 | AY16: =AX16/AX$17 -> 0.021189571 | AZ16: Roadbuilding
B17: Total revenue | D17: =IS!D18 -> 7631 | E17: =IS!E18 -> 9253 | F17: =IS!F18 -> 8925 | G17: =IS!G18 -> 9731 | H17: =IS!H18 -> 35540 | J17: =IS!J18 -> 9112 | K17: =IS!K18 -> 12058 | L17: =IS!L18 -> 11527 | M17: =IS!M18 -> 11327 | N17: =IS!N18 -> 44024 | P17: =IS!P18 -> 9569 | Q17: =IS!Q18 -> 13370 | R17: =IS!R18 -> 14102 | S17: =IS!S18 -> 15536 | T17: =IS!T18 -> 52577 | V17: =IS!V18 -> 12652 | W17: =IS!W18 -> 17387 | X17: =IS!X18 -> 15801 | Y17: =IS!Y18 -> 15412 | Z17: =IS!Z18 -> 61251 | AB17: =IS!AB18 -> 12185 | AC17: =IS!AC18 -> 15235 | AD17: =IS!AD18 -> 13152 | AE17: =IS!AE18 -> 11143 | AF17: =IS!AF18 -> 51716 | AH17: =IS!AH18 -> 8508 | AI17: =IS!AI18 -> 12763 | AJ17: =IS!AJ18 -> 0 | AK17: =IS!AK18 -> 0 | AL17: =SUM(AL12:AL16) -> 45133.9 | AN17: =SUM(AN12:AN16) -> 0 | AO17: =SUM(AO12:AO16) -> 0 | AP17: =SUM(AP12:AP16) -> 0 | AQ17: =SUM(AQ12:AQ16) -> 0 | AR17: =SUM(AR12:AR16) -> 47912.53 | AT17: =SUM(AT12:AT16) -> 53088.25 | AV17: =SUM(AV12:AV16) -> 60223.18 | AX17: =SUM(AX12:AX16) -> 63073.98 | AZ17: Forestry
AZ18: Financial products
B19: Revenue by region: | AZ19: Other
B20: United States (US) | H20: 18996 | I20: =H20/H$26 -> 0.53449634 | N20: 22814 | O20: =N20/N$26 -> 0.51821734 | T20: 28238 | U20: =T20/T$26 -> 0.53707895 | Z20: 34105 | AA20: =Z20/Z$26 -> 0.55680724 | AF20: 30242 | AG20: =AF20/AF$26 -> 0.58477067 | AL20: =AM20*$AL$17 -> 26392.981 | AM20: 0.58477067 | AR20: =AS20*AR$17 -> 28747.518 | AS20: 0.6 | AT20: =AU20*AT$17 -> 31852.95 | AU20: 0.6 | AV20: =AW20*AV$17 -> 36133.908 | AW20: 0.6 | AX20: =AY20*AX$17 -> 37213.648 | AY20: 0.59
B21: Canada (CAN) | H21: 2390 | I21: =H21/H$26 -> 0.067248171 | N21: 3015 | O21: =N21/N$26 -> 0.068485372 | T21: 3902 | U21: =T21/T$26 -> 0.074214961 | Z21: 4287 | AA21: =Z21/Z$26 -> 0.069990694 | AF21: 3900 | AG21: =AF21/AF$26 -> 0.075411865 | AL21: =AM21*$AL$17 -> 3403.6316 | AM21: 0.075411865 | AR21: =AS21*AR$17 -> 3353.8771 | AS21: 0.07 | AT21: =AU21*AT$17 -> 3716.1775 | AU21: 0.07 | AV21: =AW21*AV$17 -> 4215.6226 | AW21: 0.07 | AX21: =AY21*AX$17 -> 4415.1786 | AY21: 0.07
B22: Western Europe (WE) | H22: 5333 | I22: =H22/H$26 -> 0.15005627 | N22: 6429 | O22: =N22/N$26 -> 0.14603398 | T22: 6344 | U22: =T22/T$26 -> 0.12066113 | Z22: 7321 | AA22: =Z22/Z$26 -> 0.11952458 | AF22: 6189 | AG22: =AF22/AF$26 -> 0.11967283 | AL22: =AM22*$AL$17 -> 5401.3015 | AM22: 0.11967283 | AR22: =AS22*AR$17 -> 4312.1277 | AS22: 0.09 | AT22: =AU22*AT$17 -> 4777.9425 | AU22: 0.09 | AV22: =AW22*AV$17 -> 5420.0862 | AW22: 0.09 | AX22: =AY22*AX$17 -> 5676.6582 | AY22: 0.09
B23: Central Europe and CIS (CECIS) | H23: 2072 | I23: =H23/H$26 -> 0.058300506 | N23: 2664 | O23: =N23/N$26 -> 0.060512448 | T23: 2289 | U23: =T23/T$26 -> 0.043536147 | Z23: 2137 | AA23: =Z23/Z$26 -> 0.034889226 | AF23: 1488 | AG23: =AF23/AF$26 -> 0.028772527 | AL23: =AM23*$AL$17 -> 1298.6164 | AM23: 0.028772527 | AR23: =AS23*AR$17 -> 958.2506 | AS23: 0.02 | AT23: =AU23*AT$17 -> 1061.765 | AU23: 0.02 | AV23: =AW23*AV$17 -> 1204.4636 | AW23: 0.02 | AX23: =AY23*AX$17 -> 1261.4796 | AY23: 0.02
B24: Latin America (LA) | H24: 3023 | I24: =H24/H$26 -> 0.085059088 | N24: 4522 | O24: =N24/N$26 -> 0.1027167 | T24: 7339 | U24: =T24/T$26 -> 0.13958575 | Z24: 8197 | AA24: =Z24/Z$26 -> 0.13382639 | AF24: 5538 | AG24: =AF24/AF$26 -> 0.10708485 | AL24: =AM24*$AL$17 -> 4833.1568 | AM24: 0.10708485 | AR24: =AS24*AR$17 -> 6707.7542 | AS24: 0.14 | AT24: =AU24*AT$17 -> 8494.12 | AU24: 0.16 | AV24: =AW24*AV$17 -> 9635.7088 | AW24: 0.16 | AX24: =AY24*AX$17 -> 10091.837 | AY24: 0.16
B25: Asia, Africa, Australia, New Zealand, and Middle East (AAANM) | H25: 3726 | I25: =H25/H$26 -> 0.10483962 | N25: 4580 | O25: =N25/N$26 -> 0.10403416 | T25: 4465 | U25: =T25/T$26 -> 0.084923065 | Z25: 5204 | AA25: =Z25/Z$26 -> 0.084961878 | AF25: 4359 | AG25: =AF25/AF$26 -> 0.084287261 | AL25: =AM25*$AL$17 -> 3804.2128 | AM25: 0.084287261 | AR25: =AS25*AR$17 -> 4038.4159 | AS25: 0.084287261 | AT25: =AU25*AT$17 -> 3185.295 | AU25: 0.06 | AV25: =AW25*AV$17 -> 3613.3908 | AW25: 0.06 | AX25: =AY25*AX$17 -> 4415.1786 | AY25: 0.07
B26: Total revenue | D26: =IS!D18 -> 7631 | E26: =IS!E18 -> 9253 | F26: =IS!F18 -> 8925 | G26: =IS!G18 -> 9731 | H26: =IS!H18 -> 35540 | J26: =IS!J18 -> 9112 | K26: =IS!K18 -> 12058 | L26: =IS!L18 -> 11527 | M26: =IS!M18 -> 11327 | N26: =IS!N18 -> 44024 | P26: =IS!P18 -> 9569 | Q26: =IS!Q18 -> 13370 | R26: =IS!R18 -> 14102 | S26: =IS!S18 -> 15536 | T26: =IS!T18 -> 52577 | V26: =IS!V18 -> 12652 | W26: =IS!W18 -> 17387 | X26: =IS!X18 -> 15801 | Y26: =IS!Y18 -> 15412 | Z26: =IS!Z18 -> 61251 | AB26: =IS!AB18 -> 12185 | AC26: =IS!AC18 -> 15235 | AD26: =IS!AD18 -> 13152 | AE26: =IS!AE18 -> 11143 | AF26: =IS!AF18 -> 51716 | AH26: =IS!AH18 -> 8508 | AI26: =IS!AI18 -> 12763 | AJ26: =IS!AJ18 -> 0 | AK26: =IS!AK18 -> 0 | AL26: =SUM(AL20:AL25) -> 45133.9 | AM26: =SUM(AM20:AM25) -> 1 | AN26: =SUM(AN20:AN25) -> 0 | AO26: =SUM(AO20:AO25) -> 0 | AP26: =SUM(AP20:AP25) -> 0 | AQ26: =SUM(AQ20:AQ25) -> 0 | AR26: =SUM(AR20:AR25) -> 48117.944 | AS26: =SUM(AS20:AS25) -> 1.0042873 | ... AY26: =SUM(AY20:AY25) -> 1
B28: Products:
B29: Production agriculture | H29: 12662 | I29: =H29/H12 -> 0.97685542 | J29: 3726 | K29: 3726 | L29: 3726 | M29: 3726 | N29: 16248 | O29: =N29/N12 -> 0.98419044 | T29: 21685 | U29: =T29/T12 -> 0.98559222 | Z29: 26450 | AA29: =Z29/Z12 -> 0.9873087 | AF29: 20574 | AG29: =AF29/AF12 -> 0.9875204 | AL29: =$AG$29*AL12 -> 16995.957 | AR29: =$AG$29*AR12 -> 17882.019 | AT29: =$AG$29*AT12 -> 20430.424 | AV29: =$AG$29*AV12 -> 23943.321 | AX29: =$AG$29*AX12 -> 24877.11
B30: Small agriculture | H30: 6827 | I30: =H30/H13 -> 0.72914664 | N30: 8619 | O30: =N30/N13 -> 0.7267285 | T30: 10027 | U30: =T30/T13 -> 0.74934609 | Z30: 10122 | AA30: =Z30/Z13 -> 0.72403433 | AF30: 7693 | AG30: =AF30/AF13 -> 0.70134014 | AL30: =$AG$30*AL13 -> 6946.2761 | AR30: =$AG$30*AR13 -> 7482.5629 | AT30: =$AG$30*AT13 -> 8221.7614 | AV30: =$AG$30*AV13 -> 9273.0071 | AX30: =$AG$30*AX13 -> 9634.6544
B31: Turf | H31: 2390 | I31: =H31/H13 -> 0.25526007 | N31: 2853 | O31: =N31/N13 -> 0.24055649 | T31: 3027 | U31: =T31/T13 -> 0.22621628 | Z31: 3505 | AA31: =Z31/Z13 -> 0.25071531 | AF31: 3023 | AG31: =AF31/AF13 -> 0.27559486 | AL31: =$AG$31*AL13 -> 2729.5714 | AR31: =$AG$31*AR13 -> 2940.3078 | AT31: =$AG$31*AT13 -> 3230.7792 | AV31: =$AG$31*AV13 -> 3643.8711 | AX31: =$AG$31*AX13 -> 3785.9821
B32: Construction | C32: =AVERAGE(I32,O32,U32,AA32,AG32) -> 0.44006141 | H32: 3521 | I32: =H32/SUM(H$32:H$35) -> 0.3994781 | N32: 4684 | O32: =N32/SUM(N$32:N$35) -> 0.41813962 | T32: 5864 | U32: =T32/SUM(T$32:T$35) -> 0.47752443 | Z32: 6842 | AA32: =Z32/SUM(Z$32:Z$35) -> 0.47134197 | AF32: 5523 | AG32: =AF32/SUM(AF$32:AF$35) -> 0.43382295 | AL32: =AL$14*$C32 -> 4919.3893 | AR32: =AR$14*$C32 -> 5308.0252 | AT32: =AT$14*$C32 -> 5799.1029 | AV32: =AV$14*$C32 -> 6502.0086 | AX32: =AX$14*$C32 -> 6775.093
B33: Compact Construction | C33: =AVERAGE(I33,O33,U33,AA33,AG33) -> 0.15492922 | H33: 1269 | I33: =H33/SUM(H$32:H$35) -> 0.14397549 | N33: 1489 | O33: =N33/SUM(N$32:N$35) -> 0.13292269 | T33: 1667 | U33: =T33/SUM(T$32:T$35) -> 0.13574919 | Z33: 2451 | AA33: =Z33/SUM(Z$32:Z$35) -> 0.16884817 | AF33: 2459 | AG33: =AF33/SUM(AF$32:AF$35) -> 0.19315058 | AL33: =AL$14*$C33 -> 1731.9336 | AR33: =AR$14*$C33 -> 1868.7578 | AT33: =AT$14*$C33 -> 2041.648 | AV33: =AV$14*$C33 -> 2289.1149 | AX33: =AX$14*$C33 -> 2385.2577
B34: Roadbuilding | C34: =AVERAGE(I34,O34,U34,AA34,AG34) -> 0.29879813 | H34: 2924 | I34: =H34/SUM(H$32:H$35) -> 0.33174495 | N34: 3749 | O34: =N34/SUM(N$32:N$35) -> 0.33467238 | T34: 3441 | U34: =T34/SUM(T$32:T$35) -> 0.28021173 | Z34: 3794 | AA34: =Z34/SUM(Z$32:Z$35) -> 0.26136677 | AF34: 3641 | AG34: =AF34/SUM(AF$32:AF$35) -> 0.28599482 | AL34: =AL$14*$C34 -> 3340.2254 | AR34: =AR$14*$C34 -> 3604.106 | AT34: =AT$14*$C34 -> 3937.5438 | AV34: =AV$14*$C34 -> 4414.8111 | AX34: =AX$14*$C34 -> 4600.2331 | BA34: https://www.mordorintelligence.com/industry-reports/global-precision-farming-market-industry
B35: Forestry | C35: =AVERAGE(I35,O35,U35,AA35,AG35) -> 0.10621123 | H35: 1100 | I35: =H35/SUM(H$32:H$35) -> 0.12480145 | N35: 1280 | O35: =N35/SUM(N$32:N$35) -> 0.11426531 | T35: 1308 | U35: =T35/SUM(T$32:T$35) -> 0.10651466 | Z35: 1429 | AA35: =Z35/SUM(Z$32:Z$35) -> 0.098443097 | AF35: 1108 | AG35: =AF35/SUM(AF$32:AF$35) -> 0.087031655 | AL35: =AL$14*$C35 -> 1187.3216 | AR35: =AR$14*$C35 -> 1281.121 | AT35: =AT$14*$C35 -> 1399.6453 | AV35: =AV$14*$C35 -> 1569.2954 | AX35: =AX$14*$C35 -> 1635.2058 | BA35: https://www.grandviewresearch.com/industry-analysis/precision-farming-market
B36: Financial products | H36: 3720 | N36: 3669 | T36: 3769 | Z36: 5094 | AF36: 6220 | AL36: =SUM(AL12:AL14)-SUM(AL29:AL35)+AL15 -> 6276.4656 | AR36: =SUM(AR12:AR14)-SUM(AR29:AR35)+AR15 -> 6490.87 | AT36: =SUM(AT12:AT14)-SUM(AT29:AT35)+AT15 -> 6892.955 | AV36: =SUM(AV12:AV14)-SUM(AV29:AV35)+AV15 -> 7401.6109 | AX36: =SUM(AX12:AX14)-SUM(AX29:AX35)+AX15 -> 8043.9324 | BA36: https://www.alliedmarketresearch.com/precision-agriculture-market
B37: Other | H37: 1127 | N37: 1433 | T37: 1789 | Z37: 1564 | AF37: 1475 | AL37: =AL16 -> 1006.76 | AR37: =AR16 -> 1054.76 | AT37: =AT16 -> 1134.39 | AV37: =AV16 -> 1186.14 | AX37: =AX16 -> 1336.5105 | BA37: https://investor.deere.com/home/
A39: x | B39: Notes & Forecasts
B44: PPA\
B45: Regional Forecast | H45: Over the next years I expect US and Latin America´s share of total Rev to grow, mainly due to the second effect of tarrifs. The Brazillian and Argentine market are positioned to capatalize, with US trading partners opting to shift their business to these countries. In terms of precision farming and advanced agricultural machinery, developed countries seem more likely to invest, and Deere invests into these technologies. I´m expecting US and WE markets to continue to grow a bit in share due to these technologies, however I expect WE to decrease in share due to trade agreements
B46: PPA & SAT | H46: Expect a drop this year and potentially next year due to the trade wars as well as less gov aid, however when that will settle down, larger farms will be needing better equipment to deal witht the ramifications, thus in the years after I expect sales to go back up and having to catch up with demand
B51: 2025/2026/2027 PPA/SAT/CF Forecast | H51: Mean consensus from following firms: Oppenheimer,Truist Securities,Melius Research LLC,JP Morgan,Evercore ISI,Raymond James,D.A. Davidson,Baird,Bernstein,HSBC,Morningstar,Barclays,BMO Capital Markets,Daiwa Securities,Wolfe Research
B52: 2025/2026/2027 FS/Other Forecast | H52: Mean consensus from following firms: Oppenheimer,JP Morgan,D.A. Davidson,BMO Capital Markets,Daiwa Securities,Wolfe Research
B53: 2028 PPA/SAT/CF Forecast | H53: Mean consensus from following firms: Melius Research LLC,Bernstein,HSBC,Morningstar,BMO Capital Markets, D.A. Davidson
B54: 2028 FS/Other Forecast | H54: Mean consensus: BMA Capital Markets, D.A. Davidson
B55: 2029 Forecast
B71: Notes from Grand Review | N71: Key factors that are driving the agriculture equipment market growth include rising mechanization in farm practices and government support in form of subsidies, especially in developing economies.
B72: Agricultural Machinery Manufacturing | N72: Investing in precision agriculture systems
B73: US Segment | N73: Held biggest share in global revenue - 37~%
...

Sheet Trading Comps
B7: ="in "&IF(Inputs!$R$18="k","thousands",IF(Inputs!$R$18="MLN","millions","billions")&" of "&Inputs!$R$17) -> in millions of USD | D7: Current | E7: % of | I7: Enterprise Value / | S7: LTM | T7: Net | V7: Price / | Z7: LTM
D8: Share | E8: 52-week | F8: Equity | G8: Enterprise | I8: LTM | J8: 2025 | K8: 2026 | L8: LTM | M8: 2025E | N8: 2026E | O8: LTM | P8: 2025E | Q8: 2026E | S8: EBITDA | T8: Debt / | V8: LTM | W8: 2025E | X8: 2026E | Z8: EPS
B9: Company | C9: Ticker | D9: Price (USD) | E9: High | F9: Value | G9: Value | I9: Sales | J9: Sales | K9: Sales | L9: EBITDA | M9: EBITDA | N9: EBITDA | O9: EBIT | P9: EBIT | Q9: EBIT | S9: Margin | T9: EBITDA | V9: EPS | W9: EPS | X9: EPS | Z9: Growth
B15: =+Inputs!B21 -> AGCO CORP | C15: AGCO US | D15: 109.3 | E15: 0.90211291 | F15: 8.1559908e+09 | G15: 10295.065 | I15: 1.0120885 | J15: 1.0447979 | K15: 1.0004437 | L15: 9.8297452 | M15: 10.243846 | N15: 8.5935437 | O15: 14.032896 | P15: 14.63123 | Q15: 11.990311 | S15: 0.10296182 | T15: 8.3017958 | V15: 0.34780008 | W15: 0.30563562 | X15: 0.23289625 | Z15: =(_xll.BQL(Inputs!$E21, "EARN_FOR_COMMON(fpr = 2028, fpt = a, ae = e, fa_adjusted = y, fs = mr)")/_xll.BQL(Inputs!$E21, "EARN_FOR_COMMON(fpr = 2025, fpt = a, ae = e, fa_adjusted = y, fs = mr)"))^(1/3)-1 -> 0.19927279
B16: =+Inputs!B22 -> CATTERPILLAR INC | C16: CAT US | D16: 450.66 | E16: 0.99628598 | F16: 2.1112471e+11 | G16: 188322.2 | I16: 2.9826605 | J16: 3.0582475 | K16: 2.8637984 | L16: 13.55031 | M16: 14.65853 | N16: 12.953988 | O16: 16.087665 | P16: 17.428865 | Q16: 15.076511 | S16: 0.22011752 | T16: 2.9738724 | V16: 0.048693679 | W16: 0.052890642 | X16: 0.046017595 | Z16: =(_xll.BQL(Inputs!$E22, "EARN_FOR_COMMON(fpr = 2028, fpt = a, ae = e, fa_adjusted = y, fs = mr)")/_xll.BQL(Inputs!$E22, "EARN_FOR_COMMON(fpr = 2025, fpt = a, ae = e, fa_adjusted = y, fs = mr)"))^(1/3)-1 -> 0.15486087
B17: =+Inputs!B23 -> CNH INDUSTRIAL N | C17: CNH US | D17: 10.85 | E17: 0.76033637 | F17: 1.3571398e+10 | G17: 19214.628 | I17: 1.0634029 | J17: 1.2771895 | K17: 1.2025504 | L17: 4.8181113 | M17: 15.285425 | N17: 11.840984 | O17: 5.8922502 | P17: 21.320323 | Q17: 15.608213 | S17: 0.2207095 | T17: 6.9758186 | V17: 0.01289211 | W17: 0.014203636 | X17: 0.010833465 | Z17: =(_xll.BQL(Inputs!$E23, "EARN_FOR_COMMON(fpr = 2028, fpt = a, ae = e, fa_adjusted = y, fs = mr)")/_xll.BQL(Inputs!$E23, "EARN_FOR_COMMON(fpr = 2025, fpt = a, ae = e, fa_adjusted = y, fs = mr)"))^(1/3)-1 -> 0.31805284
B18: =+Inputs!B24 -> TEREX CORP | C18: TEX US | D18: 52.6 | E18: 0.89669281 | F18: 3450560000 | G18: 5249.181 | I18: 1.0155119 | J18: 0.96305609 | K18: 0.92277805 | L18: 8.3056661 | M18: 7.7650607 | N18: 7.1886894 | O18: 10.477407 | P18: 9.5145568 | Q18: 8.4732542 | S18: 0.12226736 | T18: 5.1448413 | V18: 0.17872588 | W18: 0.1648433 | X18: 0.14454159 | Z18: =(_xll.BQL(Inputs!$E24, "EARN_FOR_COMMON(fpr = 2028, fpt = a, ae = e, fa_adjusted = y, fs = mr)")/_xll.BQL(Inputs!$E24, "EARN_FOR_COMMON(fpr = 2025, fpt = a, ae = e, fa_adjusted = y, fs = mr)"))^(1/3)-1 -> #VALUE!
B19: =+Inputs!B25 -> ALAMO GROUP | C19: ALG US | D19: 201.74 | E19: 0.8647606 | F19: 2.443255e+09 | G19: 2645.0214 | I19: 1.65661 | J19: 1.6262044 | K19: 1.5329014 | L19: 11.479081 | M19: 11.148668 | N19: 10.114805 | O19: 16.016358 | P19: 14.355611 | Q19: 12.777881 | S19: 0.14431556 | T19: 0.98141017 | V19: 1.7144681 | W19: 1.563876 | X19: 1.3330837 | Z19: =(_xll.BQL(Inputs!$E25, "EARN_FOR_COMMON(fpr = 2028, fpt = a, ae = e, fa_adjusted = y, fs = mr)")/_xll.BQL(Inputs!$E25, "EARN_FOR_COMMON(fpr = 2025, fpt = a, ae = e, fa_adjusted = y, fs = mr)"))^(1/3)-1 -> #VALUE!
B20: =+Inputs!H21 -> KUBOTA CORP-ADR | C20: KUBTY US | D20: 62.415 | E20: 0.83275517 | F20: 1.4366645e+10 | G20: 3979719.1 | I20: 1.3762963 | J20: 1.3434723 | K20: 1.2848063 | L20: 10.298947 | M20: 10.89237 | N20: 10.001498 | O20: 15.206367 | P20: 16.349267 | Q20: 14.730084 | S20: 0.13363466 | T20: 5.5416301 | V20: 0.00034805382 | W20: 0.00036982861 | X20: 0.00032669536 | Z20: =(_xll.BQL(Inputs!$K21, "EARN_FOR_COMMON(fpr = 2028, fpt = a, ae = e, fa_adjusted = y, fs = mr)")/_xll.BQL(Inputs!$K21, "EARN_FOR_COMMON(fpr = 2025, fpt = a, ae = e, fa_adjusted = y, fs = mr)"))^(1/3)-1 -> 0.10901522
B21: =+Inputs!H22 -> KOMATSU LTD-ADR | C21: KMTUY US | D21: 35.59 | E21: 0.95492353 | F21: 3.3844422e+10 | G21: 5483123.8 | I21: 1.3524945 | J21: 1.3524945 | K21: 1.3864023 | L21: 6.7888758 | M21: 7.0411057 | N21: 7.4923966 | O21: 8.4835003 | P21: 8.9817617 | Q21: 9.8017535 | S21: 0.19922217 | T21: 1.7801182 | V21: 8.3667242e-05 | W21: 8.9560783e-05 | X21: 9.6090087e-05 | Z21: =(_xll.BQL(Inputs!$K22, "EARN_FOR_COMMON(fpr = 2028, fpt = a, ae = e, fa_adjusted = y, fs = mr)")/_xll.BQL(Inputs!$K22, "EARN_FOR_COMMON(fpr = 2025, fpt = a, ae = e, fa_adjusted = y, fs = mr)"))^(1/3)-1 -> 0.032789428
B23: Mean | I23: =AVERAGE(I15:I21) -> 1.4941521 | J23: =AVERAGE(J15:J21) -> 1.5236375 | K23: =AVERAGE(K15:K21) -> 1.4562401 | L23: =AVERAGE(L15:L21) -> 9.2958195 | M23: =AVERAGE(M15:M21) -> 11.005001 | N23: =AVERAGE(N15:N21) -> 9.7408435 | O23: =AVERAGE(O15:O21) -> 12.313778 | P23: =AVERAGE(P15:P21) -> 14.654516 | ... Y23: =AVERAGE(Y15:Y21) -> #DIV/0! | Z23: =AVERAGE(Z15:Z17,Z20:Z21) -> 0.16279823
B24: Median | I24: =MEDIAN(I15:I21) -> 1.3524945 | J24: =MEDIAN(J15:J21) -> 1.3434723 | K24: =MEDIAN(K15:K21) -> 1.2848063 | L24: =MEDIAN(L15:L21) -> 9.8297452 | M24: =MEDIAN(M15:M21) -> 10.89237 | N24: =MEDIAN(N15:N21) -> 10.001498 | O24: =MEDIAN(O15:O21) -> 14.032896 | P24: =MEDIAN(P15:P21) -> 14.63123 | ... Y24: =MEDIAN(Y15:Y21) -> #NUM! | Z24: =MEDIAN(Z15:Z17,Z20:Z21) -> 0.15486087
B35: Mean
B36: Median
B47: Mean
B48: Median
B50: Overall
B53: Mean | I53: =AVERAGE(I41:I45,I20:I34,I15:I19) -> 1.4784124 | J53: =AVERAGE(J41:J45,J20:J34,J15:J19) -> 1.5036191 | K53: =AVERAGE(K41:K45,K20:K34,K15:K19) -> 1.4371919 | L53: =AVERAGE(L41:L45,L20:L34,L15:L19) -> 9.3551446 | M53: =AVERAGE(M41:M45,M20:M34,M15:M19) -> 10.992486 | N53: =AVERAGE(N41:N45,N20:N34,N15:N19) -> 9.7698052 | O53: =AVERAGE(O41:O45,O20:O34,O15:O19) -> 12.504791 | P53: =AVERAGE(P41:P45,P20:P34,P15:P19) -> 14.651929 | Q53: =AVERAGE(Q41:Q45,Q20:Q34,Q15:Q19) -> 12.652527 | S53: =AVERAGE(S41:S45,S20:S34,S15:S19) -> 0.16120695 | T53: =AVERAGE(T41:T45,T20:T34,T15:T19) -> 4.5969807 | V53: =AVERAGE(V41:V45,V20:V34,V15:V19) -> 0.29785632 | W53: =AVERAGE(W41:W45,W20:W34,W15:W19) -> 0.27278576 | X53: =AVERAGE(X41:X45,X20:X34,X15:X19) -> 0.22959502 | Z53: =AVERAGE(Z41:Z45,Z27:Z34,Z15:Z17) -> 0.22406217
B54: Median | I54: =MEDIAN(I41:I45,I20:I33,I15:I19) -> 1.3524945 | J54: =MEDIAN(J41:J45,J20:J33,J15:J19) -> 1.3434723 | K54: =MEDIAN(K41:K45,K20:K33,K15:K19) -> 1.2848063 | L54: =MEDIAN(L41:L45,L20:L33,L15:L19) -> 9.8297452 | M54: =MEDIAN(M41:M45,M20:M33,M15:M19) -> 10.89237 | N54: =MEDIAN(N41:N45,N20:N33,N15:N19) -> 10.001498 | O54: =MEDIAN(O41:O45,O20:O33,O15:O19) -> 14.032896 | P54: =MEDIAN(P41:P45,P20:P33,P15:P19) -> 14.63123 | Q54: =MEDIAN(Q41:Q45,Q20:Q33,Q15:Q19) -> 12.777881 | S54: =MEDIAN(S41:S45,S20:S33,S15:S19) -> 0.14431556 | T54: =MEDIAN(T41:T45,T20:T33,T15:T19) -> 5.1448413 | V54: =MEDIAN(V41:V45,V20:V33,V15:V19) -> 0.048693679 | W54: =MEDIAN(W41:W45,W20:W33,W15:W19) -> 0.052890642 | X54: =MEDIAN(X41:X45,X20:X33,X15:X19) -> 0.046017595 | Z54: =MEDIAN(Z41:Z45,Z27:Z33,Z15:Z17) -> 0.19927279
B56: High | I56: =MAX(I41:I45,I20:I33,I15:I19) -> 2.9826605 | J56: =MAX(J41:J45,J20:J33,J15:J19) -> 3.0582475 | K56: =MAX(K41:K45,K20:K33,K15:K19) -> 2.8637984 | L56: =MAX(L41:L45,L20:L33,L15:L19) -> 13.55031 | M56: =MAX(M41:M45,M20:M33,M15:M19) -> 15.285425 | N56: =MAX(N41:N45,N20:N33,N15:N19) -> 12.953988 | O56: =MAX(O41:O45,O20:O33,O15:O19) -> 16.087665 | P56: =MAX(P41:P45,P20:P33,P15:P19) -> 21.320323 | ... T56: =MAX(T41:T45,T20:T33,T15:T19) -> 8.3017958 | V56: =MAX(V41:V45,V20:V33,V15:V19) -> 1.7144681 | W56: =MAX(W41:W45,W20:W33,W15:W19) -> 1.563876 | X56: =MAX(X41:X45,X20:X33,X15:X19) -> 1.3330837 | Z56: =MAX(Z41:Z45,Z27:Z33,Z15:Z17) -> 0.31805284
B57: Low | I57: =MIN(I41:I45,I20:I33,I15:I19) -> 1.0120885 | J57: =MIN(J41:J45,J20:J33,J15:J19) -> 0.96305609 | K57: =MIN(K41:K45,K20:K33,K15:K19) -> 0.92277805 | L57: =MIN(L41:L45,L20:L33,L15:L19) -> 4.8181113 | M57: =MIN(M41:M45,M20:M33,M15:M19) -> 7.0411057 | N57: =MIN(N41:N45,N20:N33,N15:N19) -> 7.1886894 | O57: =MIN(O41:O45,O20:O33,O15:O19) -> 5.8922502 | P57: =MIN(P41:P45,P20:P33,P15:P19) -> 8.9817617 | ... T57: =MIN(T41:T45,T20:T33,T15:T19) -> 0.98141017 | V57: =MIN(V41:V45,V20:V33,V15:V19) -> 8.3667242e-05 | W57: =MIN(W41:W45,W20:W33,W15:W19) -> 8.9560783e-05 | X57: =MIN(X41:X45,X20:X33,X15:X19) -> 9.6090087e-05 | Z57: =MIN(Z41:Z45,Z27:Z33,Z15:Z17) -> 0.15486087

Sheet Peers
B7: Peers
A12: x | B12: Growth | C12: =C21 -> DEERE & CO | D12: {=TRANSPOSE(Inputs!B21:B25)} -> AGCO CORP | E12: CATTERPILLAR INC | F12: CNH INDUSTRIAL N | G12: TEREX CORP | H12: ALAMO GROUP | I12: {=TRANSPOSE(Inputs!H21:H22)} -> KUBOTA CORP-ADR | J12: KOMATSU LTD-ADR
B14: Revenue (LTM) | C14: -0.2097 | D14: -0.2427 | E14: -0.0487 | F14: -0.2172 | G14: -0.0035 | H14: -0.049 | I14: -0.0612 | J14: X
B15: Revenue (3-yr CAGR) | C15: =(51716/52577)^(1/3)-1 -> -0.0054887317 | D15: =(11661900/12651400)^(1/3)-1 -> -0.026781755 | E15: =(64809/59427)^(1/3)-1 -> 0.029320221 | F15: =(19836000/23551000)^(1/3)-1 -> -0.055616808 | G15: =(5127/4418)^(1/3)-1 -> 0.050862437 | H15: =(1628513/1513616)^(1/3)-1 -> 0.024688448 | I15: =(20291160/18008610)^(1/3)-1 -> 0.040580207 | J15: X
B16: Gross profit (LTM) | C16: -0.184 | D16: -0.2988 | E16: -0.0786 | F16: -0.2112 | G16: -0.1846 | H16: -0.0881 | I16: -0.0475 | J16: X
B17: EBIT (LTM) | C17: -0.2743 | D17: -0.93 | E17: -0.1527 | F17: -0.2727 | G17: -0.4079 | H17: -0.1018 | I17: -0.2852 | J17: X
B18: EBITDA (LTM) | C18: -0.2574 | D18: -0.6991 | E18: -0.1277 | F18: -0.2539 | G18: -0.2707 | H18: -0.0637 | I18: -0.1284 | J18: X
B19: FCF (LTM) | C19: 0.074739141 | D19: -0.49299145 | E19: -0.099356683 | F19: #VALUE! | G19: -0.43089431 | H19: 0.9782355 | I19: #VALUE! | J19: 0.34284026
A21: x | B21: Margins | C21: DEERE & CO | D21: =D12 -> AGCO CORP | E21: =E12 -> CATTERPILLAR INC | F21: =F12 -> CNH INDUSTRIAL N | G21: =G12 -> TEREX CORP | H21: =H12 -> ALAMO GROUP | I21: =I12 -> KUBOTA CORP-ADR | J21: =J12 -> KOMATSU LTD-ADR
B23: Gross margin | C23: 0.40492304 | D23: 0.24859585 | E23: 0.35988829 | F23: 0.32698125 | G23: 0.20830895 | H23: 0.25329119 | I23: 0.30765701 | J23: 0.32218707
B24: EBIT margin | C24: 0.24274886 | D24: -0.010469992 | E24: 0.20170038 | F24: 0.18814277 | G24: 0.10259411 | H24: 0.10120153 | I24: 0.1046441 | J24: 0.16010277
B25: EBITDA margin | C25: 0.26591196 | D25: 0.036678759 | E25: 0.21701326 | F25: 0.21971332 | G25: 0.097504353 | H25: 0.14488863 | I25: 0.13004013 | J25: 0.19779028
B26: Net margin | C26: 0.13728827 | D26: -0.036426311 | E26: 0.16652008 | F26: 0.062815084 | G26: 0.065340355 | H26: 0.071187642 | I26: 0.076397723 | J26: 0.10702089
B27: SG&A margin | C27: #VALUE! | D27: 0.11985183 | E27: 0.10287151 | F27: 0.086307723 | G27: 0.10571484 | H27: 0.14212536 | I27: 0.16086266 | J27: 0.13360897
B28: R&D margin | C28: 0.050796723 | D28: 0.045034949 | E28: 0.032990703 | F28: 0.047650672 | G28: #VALUE! | H28: #VALUE! | I28: #VALUE! | J28: #VALUE!
A30: x | B30: Returns | C30: DEERE & CO | D30: =D21 -> AGCO CORP | E30: =E21 -> CATTERPILLAR INC | F30: =F21 -> CNH INDUSTRIAL N | G30: =G21 -> TEREX CORP | H30: =H21 -> ALAMO GROUP | I30: =I21 -> KUBOTA CORP-ADR | J30: =J21 -> KOMATSU LTD-ADR
B32: ROIC | C32: 0.0838383 | D32: 0.037641709 | E32: 0.15931688 | F32: 0.06848172 | G32: 0.088644543 | H32: 0.096869642 | I32: 0.040713577 | J32: 0.10192899
B33: CROIC | C33: 0.050127327 | D33: 0.044171085 | E33: 0.15075635 | F33: 0.022368421 | G33: 0.04145646 | H33: 0.14434625 | I33: 0.019935633 | J33: 0.068127943
B34: ROCE | C34: 2.0733278 | D34: -0.030751794 | E34: 0.5083019 | F34: 0.11082405 | G34: 0.24660103 | H34: 0.18039286 | I34: 0.158497 | J34: 0.24881909
B35: RONA | C35: 0.54761178 | D35: -0.030201093 | E35: 0.6705653 | F35: 0.48043254 | G35: 0.2871179 | H35: 0.16185353 | I35: 0.11520546 | J35: 0.19645856
B36: ROE | C36: 0.21589236 | D36: 0.024226798 | E36: 0.52733928 | F36: 0.10792735 | G36: 0.094486526 | H36: 0.11301735 | I36: 0.069996936 | J36: 0.13444477
B37: ROA | C37: 0.048289421 | D37: 0.0076838215 | E37: 0.10868301 | F37: 0.018780093 | G37: 0.036046921 | H37: 0.077288984 | I37: 0.029304755 | J37: 0.070862918
A39: x | B39: Efficiency | C39: DEERE & CO | D39: =D30 -> AGCO CORP | E39: =E30 -> CATTERPILLAR INC | F39: =F30 -> CNH INDUSTRIAL N | G39: =G30 -> TEREX CORP | H39: =H30 -> ALAMO GROUP | I39: =I30 -> KUBOTA CORP-ADR | J39: =J30 -> KOMATSU LTD-ADR
B41: Asset turnover | C41: 0.41205984 | D41: 0.78474499 | E41: 0.72715233 | F41: 0.41231773 | G41: 1.0409304 | H41: 1.0423274 | I41: 0.4923426 | J41: 0.68226992
B42: Net operating asset turnover | C42: 1.5493574 | D42: 1.5045089 | E42: 1.5480843 | F42: 1.5770393 | G42: 1.9538872 | H42: 1.6056375 | I42: 0.89219734 | J42: 0.98491644
B43: Fixed asset turnover | C43: 3.018991 | D43: 4.9424712 | E43: 4.7691669 | F43: 4.7947459 | G43: 7.8526396 | H43: 8.937691 | I43: 3.4911776 | J43: 4.0704799
B44: Revenue per employee thsnd of USD | C44: =51716000/75800 -> 682.26913 | D44: =11661900/24000 -> 485.9125 | E44: =64800000/112900 -> 573.95926 | F44: =19836000/35850 -> 553.30544 | G44: =5127000/11400 -> 449.73684 | H44: =1628513/3750 -> 434.27013 | I44: =20291160/52094 -> 389.5105 | J44: =27611130/65738 -> 420.0178
B45: EBIT per employee thsnd of USD | C45: =9039000/75800 -> 119.24802 | D45: =122100/24000 -> 5.0875 | E45: =13072000/112900 -> 115.78388 | F45: =3068000/35850 -> 85.578801 | G45: =526000/11400 -> 46.140351 | H45: =164808/3750 -> 43.9488 | I45: =2255610/52094 -> 43.298844 | J45: =4420620/65738 -> 67.246037
A47: x | B47: Working Capital | C47: DEERE & CO | D47: =D39 -> AGCO CORP | E47: =E39 -> CATTERPILLAR INC | F47: =F39 -> CNH INDUSTRIAL N | G47: =G39 -> TEREX CORP | H47: =H39 -> ALAMO GROUP | I47: =I39 -> KUBOTA CORP-ADR | J47: =J39 -> KOMATSU LTD-ADR
B49: DSO | C49: 55.592906 | D49: 47.931794 | E49: 112.1147 | F49: 481.79838 | G49: 57.316792 | H49: 85.126211 | I49: 207.55354 | J49: 112.17662
B50: DIO | C50: 104.69399 | D50: 156.3067 | E50: 156.91174 | F50: 166.85586 | G50: 107.94662 | H50: 115.85036 | I50: 126.42069 | J50: 205.55986
B51: DPO | C51: 38.608118 | D51: 53.4064 | E51: 68.479934 | F51: 84.707727 | G51: 63.436037 | H51: 33.222361 | I51: 52.350077 | J51: 43.855528
B52: CCC | C52: 96.227493 | D52: 128.06526 | E52: 185.35945 | F52: 494.6825 | G52: 89.299968 | H52: 154.97829 | I52: 259.05175 | J52: 256.01051
B53: Working capital intensity | C53: -0.22493923 | D53: 0.20153164 | E53: 0.16909517 | F53: 1.6497593 | G53: 0.26162701 | H53: 0.44956963 | I53: 0.41403627 | J53: 0.42374316
B54: Cash conversion ratio | C54: 0.73530349 | D54: -5.6502867 | E54: 0.92067013 | F54: 0.52733119 | G54: 0.61977186 | H54: 1.272863 | I54: 0.89370034 | J54: 0.78701465
B55: CFO margin | C55: 0.17849408 | D55: 0.059158456 | E55: 0.18569952 | F55: 0.099213551 | G55: 0.063584942 | H55: 0.12881567 | I55: 0.093520464 | J55: 0.12600322
A57: x | B57: Leverage & Coverage | C57: DEERE & CO | D57: =D47 -> AGCO CORP | E57: =E47 -> CATTERPILLAR INC | F57: =F47 -> CNH INDUSTRIAL N | G57: =G47 -> TEREX CORP | H57: =H47 -> ALAMO GROUP | I57: =I47 -> KUBOTA CORP-ADR | J57: =J47 -> KOMATSU LTD-ADR
B59: Net debt / EBITDA | C59: 0.20050783 | D59: 6.2007505 | E59: 0.47088016 | F59: 0.72619647 | G59: 4.4027778 | H59: 0.12266563 | I59: 5.0074676 | J59: 1.2203046
B60: Net debt / FCF | C60: 0.40099345 | D60: 7.4642616 | E60: 0.27721088 | F60: 2.1879795 | G60: 12.328042 | H60: 0.22449874 | I60: 20.291459 | J60: 2.6826239
B61: Interest coverage | C61: 3.7497013 | D61: -0.76647834 | E61: 25.53125 | F61: 2.3165736 | G61: 5.9101124 | H61: 8.0206346 | I61: 55.815385 | J61: 11.409609
...

Sheet ESG
A7: x | B7: ESG Analysis
B12: ESG Scores | G12: GHG Scope 1 Emissions, Water Consumption, Energy Consumption and Waste Production per Sales
B15: LSEG ESG Score | D15: 71
B16: E-Score | D16: 84
B17: S-Score | D17: 72
B18: G-Score | D18: 54
B19: S&P Global ESG Score | D19: 47
B20: Environmental
B21: Social
B22: Governance & Economic
B23: Sustainalytics | D23: 16.1
B24: ISS ESG Corporate Rating | D24: B-
B25: SDG Impact Rating | D25: 1.9
B26: Governance Quality Score | D26: 7
B27: MSCI ESG Ratings | D27: AA
B30: Key Info | G30: Environmental
H32: Overview | I32: Targets | J32: Improvements | K32: Comments
B33: GICS Sector | C33: Industrials | G33: GHG Scope 1 Emissions | I33: Reduce 50% operational CO2 emissions (Scope 1 & 2) by 2030 | J33: A 29% reduction in Scope 1and 2 emissions by 2024 | K33: Progress is ahead of schedule towards an ambitious, SBTi-validated goal. A portion of the reduction is attributed to lower production volumes.
B34: GICS Industry Group | C34: Machinery
B35: GICS Industry | C35: Industrial Machinery & Equipment | G35: Water Consumption | I35: Reduce 10% of freshwater consumption intensity at water stressed manufacturing locations by 2030 | J35: N/A | K35: Performance is consistently moving in the opposite direction of the time-bound goal, indicating a significant operational challenge.
B36: GICS Sub-Industry | C36: Construction & Farm Machinery
G37: Energy Consumption | I37: Implicit in GHG reduction goals, not a standalone target | J37: Renewable electricity accounts for 65% of total eletctricity in 2024, up from 59% in 2022 | K37: Demonstrates strong, consistent progress in transitioning to renewable sources. Strategic investments and acquisitions underpin this progress.
B38: Headquarters | C38: Moline, Illinois, United States
B39: Number of Employees | C39: 75800 | G39: Waste Management | I39: Reduce 15% waste intensity by 2030 | J39: A 6% increase in waste intensity by 2024. But, it's showing a consistent year-over-year decrease | K39: While not yet vellow the 2021 baseline, the company is on a postive trajectory. Execution has not yet matched the stated ambition.
B41: Annual Report | C41: January 10 2025 | G41: Other | I41: Reduce 30% Scope 3 emissions; Reduce 15% customer CO2 emissons; Grow remanufacturing revenuy by 50%; Achieve 95% recycable content | J41: A 19% reduction in Scope 3 emissions; A 5% reduction in costumer emissons; A 2% growth in remanufacturing revenue; A 92% recycable product content | K41: The strategy adresses the most significant part of the footprint. Progress is strong but inconsistent, with remanufacturing lagging significantly.
B42: Sustainability Report | C42: January 16 2025
B44: Recent Headlines | G44: Social
H46: Overview | I46: Targets | J46: Improvements | K46: Comments
B47: Product Safety Recall and Lawsuit in September and October 2024 | G47: Employee Turnover % | I47: N/A | J47: Increased to 14.2% in 2024, up from 13.2% in 2023. | K47: This rate, while increasing, remains significantly lower than the manufacturing industry average of 28.6%. The company saw a reduction of 7,200 employees in 2024.
B48: Racial and Age Discrimination Claims in June and July 2024
B49: John Deere Employees Raise Over $200K for Flood Relief | G49: Salaries & Compensation | I49: The Compensation Committee aims to align compensation with the company's strategic priorities and performance. | J49: Executive compensation increased in 2024 . | K49: The CEO's total compensation was $27.80M in 2024, up 4.04% from 2023. This contrasts with ongoing layoffs and a lawsuit alleging that older, more expensive employees were targeted for job cuts.
B50: Brock Purdy and "Tractor Kid" Team Up with Deere to Fight Hunger
B51: Federal Judge Rules Deere Must Face "Right to Repair" Antitrust Lawsuit | G51: Reputation | I51: N/A | J51: N/A | K51: The company's reputation is under pressure from layoffs product recalls and high-profile lawsuits, including an antitrust case over its "Right to Repair" policies. Customer loyalty, as measured by NPS, ranks below key competitors.
B52: Shareholder Vote down on DEI and Sustainability, February 2025
B53: Layoffs and Declining Sales | G53: Discrimination Events | I53: N/A | J53: N/A | K53: The company settled for $1.1M with the Department of Labor over allegations of racial discrimination against 277 Black and Hispanic job applicants.
B54: John Deere Launches Enhanced Digital Self-Repair Tool
B55: John Deere Reman Announces $13.5M Expansion | G55: Work Safety | I55: Reduce the Total Recordable Incident Rate (TRIR) by 20% by 2026 | J55: Improved to 1.69 in 2024 from 2.08 in 2023. Representing a 15% decrease from the 2021 baseline. | K55: This rate is better than the national average for the goods-producing sector of 2.7, indicating an effective internal safety management system. The company's fatality rate was 0.000 in 2024.
B56: John Deere Launches Enhanced Digital Self-Repair Tool
G57: Damage to consumer health | I57: N/A | J57: N/A | K57: A class-action lawsuit was filed in October 2024 over a brake system defect in certain tractors that caused a recall and led to injuries, including a hospitalization. The suit alleges the recall is "repeatedly ineffective."
G59: Pension Plan | I59: N/A | J59: N/A | K59: Deere offers both a defined contribution (401k) and a two-tiered pension plan for wage employees. The two-tiered system was a key point of contention during the 2021 UAW strike.
...

Sheet WACC
A7: x | B7: Rolling WACC | K7: Equity Risk Premium
P8: Weights
D9: 2025 | E9: =+D9+1 -> 2026 | F9: =+E9+1 -> 2027 | G9: =+F9+1 -> 2028 | H9: =+G9+1 -> 2029 | M9: ERP | N9: 2025 | O9: =+N9+1 -> 2026 | P9: =+O9+1 -> 2027 | Q9: =+P9+1 -> 2028 | R9: =+Q9+1 -> 2029
B12: Equity: | K12: =+Segments!B20 -> United States (US) | M12: 0.0433 | N12: =+Segments!AL20/Segments!AL$26 -> 0.58477067 | O12: =Segments!$AR$20/Segments!$AR$26 -> 0.59743862 | P12: =Segments!AT20/Segments!AT26 -> 0.6 | Q12: =Segments!AV20/Segments!$AV$26 -> 0.6 | R12: =Segments!AX20/Segments!$AX$26 -> 0.59
B13: Market Cap (in billions) | D13: =+Inputs!J13 -> 130166.3 | E13: =+FCFF!AF99*FCFF!AF31 -> 119781.32 | F13: =+FCFF!AH99*FCFF!AH31 -> 132720.62 | G13: =+FCFF!AJ99*FCFF!AJ31 -> 150557.95 | H13: =+FCFF!AL99*FCFF!AL31 -> 157684.95 | K13: =+Segments!B21 -> Canada (CAN) | M13: 0.0433 | N13: =+Segments!AL21/Segments!AL$26 -> 0.075411865 | O13: =Segments!AR21/Segments!AR26 -> 0.069701173 | P13: =Segments!AT21/Segments!AT26 -> 0.07 | Q13: =Segments!AV21/Segments!$AV$26 -> 0.07 | R13: =Segments!AX21/Segments!$AX$26 -> 0.07
B14: % of Equity | D14: =IFERROR(D13/D35,"") -> 0.66246674 | E14: =IFERROR(E13/E35,"") -> 0.64129176 | F14: =IFERROR(E13/F35,"") -> 0.5952736 | G14: =IFERROR(F13/G35,"") -> 0.60174945 | H14: =IFERROR(G13/H35,"") -> 0.65265615 | K14: =+Segments!B22 -> Western Europe (WE) | M14: 0.0457 | N14: =+Segments!AL22/Segments!AL$26 -> 0.11967283 | O14: =Segments!AR22/Segments!AR26 -> 0.089615794 | P14: =Segments!AT22/Segments!AT26 -> 0.09 | Q14: =Segments!AV22/Segments!$AV$26 -> 0.09 | R14: =Segments!AX22/Segments!$AX$26 -> 0.09
B15: Risk-Free Rate | D15: 0.0417 | E15: 0.041 | F15: 0.041 | G15: 0.041 | H15: 0.041 | K15: =+Segments!B23 -> Central Europe and CIS (CECIS) | M15: 0.0927 | N15: =+Segments!AL23/Segments!AL$26 -> 0.028772527 | O15: =Segments!AR23/Segments!AR26 -> 0.019914621 | P15: =Segments!AT23/Segments!AT26 -> 0.02 | Q15: =Segments!AV23/Segments!$AV$26 -> 0.02 | R15: =Segments!AX23/Segments!$AX$26 -> 0.02
B16: Beta | D16: =+Inputs!M18 -> 0.89700514 | E16: =+D17*(1+(E28/E13)*(1-E32)) -> 0.91480089 | F16: =+E17*(1+(F28/F13)*(1-F32)) -> 0.89332398 | G16: =+F17*(1+(G28/G13)*(1-G32)) -> 0.86789577 | H16: =+G17*(1+(H28/H13)*(1-H32)) -> 0.86690773 | K16: =+Segments!B24 -> Latin America (LA) | M16: 0.1154 | N16: =+Segments!AL25/Segments!AL$26 -> 0.084287261 | O16: =Segments!AR24/Segments!AR26 -> 0.13940235 | P16: =Segments!AT24/Segments!AT26 -> 0.16 | Q16: =Segments!AV24/Segments!$AV$26 -> 0.16 | R16: =Segments!AX24/Segments!$AX$26 -> 0.16
B17: Unlevered Beta | D17: =+D16/(1+(D28/D13)*(1-D32)) -> 0.63691711 | E17: =+E16/(1+(E28/E13)*(1-E32)) -> 0.63691711 | F17: =+F16/(1+(F28/F13)*(1-F32)) -> 0.63691711 | G17: =+G16/(1+(G28/G13)*(1-G32)) -> 0.63691711 | H17: =+H16/(1+(H28/H13)*(1-H32)) -> 0.63691711 | K17: =+Segments!B25 -> Asia, Africa, Australia, New Zealand, and Middle East (AAANM) | M17: 0.1071 | N17: =Segments!AL25/Segments!AL26 -> 0.084287261 | O17: =Segments!AR25/Segments!AR26 -> 0.083927442 | P17: =Segments!AT25/Segments!AT26 -> 0.06 | Q17: =Segments!AV25/Segments!$AV$26 -> 0.06 | R17: =Segments!AX25/Segments!$AX$26 -> 0.07
B18: Equity Risk Premium | D18: =+N18 -> 0.055476081 | E18: =+O18 -> 0.05990434 | F18: =+P18 -> 0.059868 | G18: =+Q18 -> 0.059868 | H18: =+R18 -> 0.060506 | K18: ERP | N18: =+SUMPRODUCT($M12:$M17,N12:N17) -> 0.055476081 | O18: =+SUMPRODUCT($M12:$M17,O12:O17) -> 0.05990434 | P18: =+SUMPRODUCT($M12:$M17,P12:P17) -> 0.059868 | Q18: =+SUMPRODUCT($M12:$M17,Q12:Q17) -> 0.059868 | R18: =+SUMPRODUCT($M12:$M17,R12:R17) -> 0.060506
B19: Ke (Cost of Equity) | D19: =IFERROR(+D15+D16*D18,"") -> 0.09146233 | E19: =IFERROR(+E15+E16*E18,"") -> 0.095800544 | F19: =IFERROR(+F15+F16*F18,"") -> 0.09448152 | G19: =IFERROR(+G15+G16*G18,"") -> 0.092959184 | H19: =IFERROR(+H15+H16*H18,"") -> 0.093453119
B21: Preferred Equity: | K21: ROIC vs WACC
B22: Market Capitalization | D22: =IFERROR(Inputs!J14,0) -> 126816.92 | E22: =+D22*(E13/D13) -> 116699.17 | F22: =+E22*(F13/E13) -> 129305.52 | G22: =+F22*(G13/F13) -> 146683.86 | H22: =+G22*(H13/G13) -> 153627.47
B23: % of Preferred Equity | D23: =+D22/D35 -> 0.64542044 | E23: =+E22/E35 -> 0.62479033 | F23: =+F22/F35 -> 0.64260568 | G23: =+G22/G35 -> 0.66505814 | H23: =+H22/H35 -> 0.66596226
B24: Preferred Dividends | D24: =+IS!AF50 -> 0 | E24: =D24 -> 0 | F24: =E24 -> 0 | G24: =F24 -> 0 | H24: =G24 -> 0
B25: Kp (Cost of Preferred Equity) | D25: =IFERROR(D24/D22,0) -> 0 | E25: =IFERROR(E24/E22,0) -> 0 | F25: =IFERROR(F24/F22,0) -> 0 | G25: =IFERROR(G24/G22,0) -> 0 | H25: =IFERROR(H24/H22,0) -> 0
B27: Debt:
B28: Debt (in millions) | C28: =+BS!AF38+BS!AF39+BS!AF44+BS!AF45 -> 65463 | D28: =+BS!AI38+BS!AI39+BS!AI44+BS!AI45 -> 66321 | E28: 67000 | F28: 68500 | G28: 70000 | H28: 73000
B29: % of Debt | D29: =IFERROR(D28/D35,"") -> 0.33753326 | E29: =IFERROR(E28/E35,"") -> 0.35870824 | F29: =IFERROR(F28/F35,"") -> 0.34042236 | G29: =IFERROR(G28/G35,"") -> 0.31737691 | H29: =IFERROR(H28/H35,"") -> 0.31644891
B30: Debt Spread | D30: =+D31-D15 -> 0.0084047934 | E30: 0.007 | F30: 0.007 | G30: 0.008 | H30: 0.008
B31: Cost of Debt | D31: =+(IS!AI36+IS!AH36+IS!AE36+IS!AD36)/WACC!D28 -> 0.050104793 | E31: =+E30+E15 -> 0.048 | F31: =+F30+F15 -> 0.048 | G31: =+G30+G15 -> 0.049 | H31: =+H30+H15 -> 0.049
B32: Tax Rate | D32: =+FCFF!Z124 -> 0.19853425 | E32: =+FCFF!AF124 -> 0.22 | F32: =+FCFF!AH124 -> 0.22 | G32: =+FCFF!AJ124 -> 0.22 | H32: =+FCFF!AL124 -> 0.22
B33: Kd (After-Tax Cost of Debt) | D33: =+D31*(1-D32) -> 0.040157276 | E33: =+E31*(1-E32) -> 0.03744 | F33: =+F31*(1-F32) -> 0.03744 | G33: =+G31*(1-G32) -> 0.03822 | H33: =+H31*(1-H32) -> 0.03822
