Workbook
Name COOLFUCNTION: _xlfn.LAMBDA(_xldudf_BOARDFLARE_EXEC("workbook-settings:coolfucntion"))
Name COOLFUCNTION: _xlfn.LAMBDA(_xldudf_BOARDFLARE_EXEC("workbook-settings:coolfucntion"))
Name COOLFUCNTION: _xlfn.LAMBDA(_xldudf_BOARDFLARE_EXEC("workbook-settings:coolfucntion"))
Name COOLFUCNTION: _xlfn.LAMBDA(_xldudf_BOARDFLARE_EXEC("workbook-settings:coolfucntion"))
Name COOLFUCNTION: _xlfn.LAMBDA(_xldudf_BOARDFLARE_EXEC("workbook-settings:coolfucntion"))
Name COOLFUCNTION: _xlfn.LAMBDA(_xldudf_BOARDFLARE_EXEC("workbook-settings:coolfucntion"))
Name COOLFUCNTION: _xlfn.LAMBDA(_xldudf_BOARDFLARE_EXEC("workbook-settings:coolfucntion"))
Name COOLFUCNTION: _xlfn.LAMBDA(_xldudf_BOARDFLARE_EXEC("workbook-settings:coolfucntion"))
Name COOLFUCNTION: _xlfn.LAMBDA(_xldudf_BOARDFLARE_EXEC("workbook-settings:coolfucntion"))
Name COOLFUCNTION: _xlfn.LAMBDA(_xldudf_BOARDFLARE_EXEC("workbook-settings:coolfucntion"))
Name Sectors: #REF!
Name Sectors: #REF!
Name Sectors: #REF!
Name Sectors: #REF!
Name Sectors: #REF!
Name Sectors: #REF!
Name Sectors: #REF!
Name Sectors: #REF!

Sheet Dashboard
C154: =+C155+1 -> 45977
C155: =+C156+1 -> 45976
C156: =+C157+1 -> 45975
C157: =+C158+1 -> 45974
C158: =+C159+1 -> 45973
C159: =+C160+1 -> 45972
C160: =+C161+1 -> 45971 | L160: =IF(FCFF!$R$199="Revenue Exit",FCFF!$AF$211,IF(FCFF!$R$199="EBITDA Exit",FCFF!Z211,FCFF!AL211)) -> 271.50078
C161: =+C162+1 -> 45970
C162: =+C163+1 -> 45969 | E162: =IF(FCFF!$R$199="Revenue Exit",FCFF!$AF$211,IF(FCFF!$R$199="EBITDA Exit",FCFF!Z211,FCFF!AL211)) -> 271.50078
C163: =+C164+1 -> 45968 | E163: =E164+($E$162-$E$193)/COUNTA($C$162:$C$192) -> 270.00076
C164: =+C165+1 -> 45967 | E164: =E165+($E$162-$E$193)/COUNTA($C$162:$C$192) -> 268.50073
C165: =+C166+1 -> 45966 | E165: =E166+($E$162-$E$193)/COUNTA($C$162:$C$192) -> 267.00071
C166: =+C167+1 -> 45965 | E166: =E167+($E$162-$E$193)/COUNTA($C$162:$C$192) -> 265.50068
C167: =+C168+1 -> 45964 | E167: =E168+($E$162-$E$193)/COUNTA($C$162:$C$192) -> 264.00066
C168: =+C169+1 -> 45963 | E168: =E169+($E$162-$E$193)/COUNTA($C$162:$C$192) -> 262.50063
C169: =+C170+1 -> 45962 | E169: =E170+($E$162-$E$193)/COUNTA($C$162:$C$192) -> 261.00061
C170: =+C171+1 -> 45961 | E170: =E171+($E$162-$E$193)/COUNTA($C$162:$C$192) -> 259.50058
C171: =+C172+1 -> 45960 | E171: =E172+($E$162-$E$193)/COUNTA($C$162:$C$192) -> 258.00056
C172: =+C173+1 -> 45959 | E172: =E173+($E$162-$E$193)/COUNTA($C$162:$C$192) -> 256.50053
C173: =+C174+1 -> 45958 | E173: =E174+($E$162-$E$193)/COUNTA($C$162:$C$192) -> 255.0005
C174: =+C175+1 -> 45957 | E174: =E175+($E$162-$E$193)/COUNTA($C$162:$C$192) -> 253.50048
... C192: =+C193+1 -> 45939 | E192: =E193+($E$162-$E$193)/COUNTA($C$162:$C$192) -> 226.50003
B193: TODAY | C193: =+'Stock Data'!AM4 -> 45938 | D193: =_xlfn.XLOOKUP(C193,'Stock Data'!$AM$4:$AM$1051,'Stock Data'!$AN$4:$AN$1051) -> 225 | E193: =D193 -> 225
C194: =+'Stock Data'!AM5 -> 45937 | D194: =_xlfn.XLOOKUP(C194,'Stock Data'!$AM$4:$AM$1051,'Stock Data'!$AN$4:$AN$1051) -> 225
C195: =+'Stock Data'!AM6 -> 45936 | D195: =_xlfn.XLOOKUP(C195,'Stock Data'!$AM$4:$AM$1051,'Stock Data'!$AN$4:$AN$1051) -> 227.72
C196: =+'Stock Data'!AM7 -> 45935 | D196: =_xlfn.XLOOKUP(C196,'Stock Data'!$AM$4:$AM$1051,'Stock Data'!$AN$4:$AN$1051) -> 227.72
C197: =+'Stock Data'!AM8 -> 45934 | D197: =_xlfn.XLOOKUP(C197,'Stock Data'!$AM$4:$AM$1051,'Stock Data'!$AN$4:$AN$1051) -> 227.72
C198: =+'Stock Data'!AM9 -> 45933 | D198: =_xlfn.XLOOKUP(C198,'Stock Data'!$AM$4:$AM$1051,'Stock Data'!$AN$4:$AN$1051) -> 225.28
C199: =+'Stock Data'!AM10 -> 45932 | D199: =_xlfn.XLOOKUP(C199,'Stock Data'!$AM$4:$AM$1051,'Stock Data'!$AN$4:$AN$1051) -> 225.34
C200: =+'Stock Data'!AM11 -> 45931 | D200: =_xlfn.XLOOKUP(C200,'Stock Data'!$AM$4:$AM$1051,'Stock Data'!$AN$4:$AN$1051) -> 224.18
C201: =+'Stock Data'!AM12 -> 45930 | D201: =_xlfn.XLOOKUP(C201,'Stock Data'!$AM$4:$AM$1051,'Stock Data'!$AN$4:$AN$1051) -> 231.07
C202: =+'Stock Data'!AM13 -> 45929 | D202: =_xlfn.XLOOKUP(C202,'Stock Data'!$AM$4:$AM$1051,'Stock Data'!$AN$4:$AN$1051) -> 231.07
C203: =+'Stock Data'!AM14 -> 45928 | D203: =_xlfn.XLOOKUP(C203,'Stock Data'!$AM$4:$AM$1051,'Stock Data'!$AN$4:$AN$1051) -> 231.07
C204: =+'Stock Data'!AM15 -> 45927 | D204: =_xlfn.XLOOKUP(C204,'Stock Data'!$AM$4:$AM$1051,'Stock Data'!$AN$4:$AN$1051) -> 231.07
C205: =+'Stock Data'!AM16 -> 45926 | D205: =_xlfn.XLOOKUP(C205,'Stock Data'!$AM$4:$AM$1051,'Stock Data'!$AN$4:$AN$1051) -> 231.27
... C558: =+'Stock Data'!AM369 -> 45573 | D558: =_xlfn.XLOOKUP(C558,'Stock Data'!$AM$4:$AM$1051,'Stock Data'!$AN$4:$AN$1051) -> 283.3

Sheet Key Info
B7: Analysts | F7: LIS – Equity Research | J7: Stock Performance
B12: José Ricardo Godinho, Team Leader | F12: Recommendation: | H12: Hold
B13: Bsc in Economia, ISEG – Ulisboa | F13: Target Price (FCFF): | H13: =FCFF!AL211 -> 354.9833
B14: ze.ricardo.godinho@aln.iseg.ulisboa.pt | F14: Upside: | H14: =FCFF!AL213 -> 0.57770354
B15: Lucas Alves, Analyst
B16: Bsc in Gestão, ISEG – Ulisboa | F16: Ticker | H16: =Inputs!D15 -> FDX US Equity
B17: lucas.alves@aln.iseg.ulisboa.pt | F17: Stock Exchange | H17: NYSE
B18: Mariana Gomes, Analyst
B19: Bsc in MAEG, ISEG – Ulisboa | F19: Current Price | H19: ='Stock Data'!AN4 -> 225
B20: l63852@aln.iseg.ulisboa.pt | F20: ="Market Cap (in "&IF(Inputs!$D$14="BLN","billions",IF(Inputs!$D$14="MLN","millions","thousands"))&")" -> Market Cap (in millions) | H20: ='Stock Data'!AQ4 -> 53088.327
F21: Beta | H21: ='Stock Data'!E164 -> 0.96032262
F22: % of 52-Week High | H22: ='Stock Data'!E165 -> 0.42049286
F23: 100-Day Moving Average | H23: ='Stock Data'!E166 -> 228.79581
B25: Reviewed by: | F25: Avg Vol (1 month) | H25: ='Stock Data'!E168 -> 2225232.2
B26: Damião, Analyst | F26: Shares Outstanding (millions) | H26: ='Stock Data'!E169 -> 235.9555
B27: Bsc in Economia, ISEG – Ulisboa | F27: % Float | H27: ='Stock Data'!E170 -> 0.914445
B28: email@aln.iseg.ulisboa.pt | F28: Short % of Float | H28: =IFERROR('Stock Data'!E171,0) -> 0.02028042
B30: LISBON INVESTMENT SOCIETY | F30: % Held by Insiders | H30: ='Stock Data'!E173 -> 0.085517532
B31: ISEG – Rua do Quelhas, 6 | F31: % Held by Institutions | H31: ='Stock Data'!E174 -> 0.8870004
B32: lis@iseg.ulisboa.pt
B34: Disclaimer: This report was prepared by members of the Lisbon Investment Society (LIS), an independent, student-led, non-profit organization based at ISEG – Lisbon School of Economics & Management, and is intended solely for academic and educational purposes. All analyses, forecasts, and opinions expressed in this report reflect the independent judgment of the authors as of the date of publication and are subject to change without notice. The views presented herein do not represent those of ISEG, its faculty, or any affiliated entity. This document does not constitute, and should not be interpreted as, investment advice, an offer, or a solicitation to buy or sell any security or financial instrument. Nothing in this report should be construed as a recommendation to make or refrain from making any investment decision. The content is intended for informational purposes only, and readers are strongly encouraged to conduct their own research and seek advice from a qualified financial professional before making any financial decisions. The information contained in this report has been obtained from publicly available sources believed to be reliable; however, no representation or warranty is made regarding the accuracy, completeness, or timeliness of such information. LIS and its members accept no liability whatsoever for any direct or indirect loss arising from the use of this report or its contents. This report incorporates terminology, financial metrics, and methodologies commonly used in professional equity research, including but not limited to Discounted Cash Flow (DCF), trading multiples, Monte Carlo simulations, and strategic analysis tools such as Porter’s Five Forces. Definitions and assumptions used in these models are disclosed within the report and reflect a hypothetical investment thesis designed solely for academic discussion. All valuations, projections, and target prices presented herein are based on publicly available data and subject to the limitations of modeling assumptions. These are not guarantees of future performance and should not be relied upon as such, as past performance is not indicative of future results. Any company names, logos, trademarks, or brand references mentioned in this report are the property of their respective owners and are used strictly for identification and academic purposes. This document may not be reproduced, redistributed, or quoted in whole or in part without the prior written consent of the Lisbon Investment Society. About LIS – Lisbon Investment Society: The Lisbon Investment Society (LIS) is a non-profit academic association headquartered at ISEG – Lisbon School of Economics & Management. Founded in 2016, LIS is committed to fostering student interest in finance and investment through applied research, skill development, and institutional engagement. The Society operates independently and autonomously from any political, religious, or commercial affiliation, and is composed of selected students and collaborators who are invited through a rigorous recruitment process and share a commitment to excellence, analytical rigor, and ethical standards. Its activities include equity research, portfolio management, macroeconomic analysis, and investment education. This report was prepared by the Equity Research team at the Lisbon Investment Society, whose analysts combine rigorous financial modeling, critical thinking, and collaborative research to deliver high-quality, student-led investment analysis. We welcome your feedback, discussion, and questions regarding this report or our research process, and invite you to reach out to our team as we are always open to engagement.

Sheet Industry
D6: 584.17 | E6: 627.76 | F6: 676.06 | G6: 729.63 | H6: 789.13 | I6: 855.3 | J6: 929 | K6: 997.69 | L6: 1067.63 | M6: 1137.57
A7: x | B7: Industry Growth Forecast | O7: Industry Index
D9: 2022 | E9: =+D9+1 -> 2023 | F9: =+E9+1 -> 2024 | G9: =+F9+1 -> 2025 | H9: =+G9+1 -> 2026 | I9: =+H9+1 -> 2027 | J9: =+I9+1 -> 2028 | K9: =+J9+1 -> 2029 | M9: ="CAGR "&$G$9&" - "&$K$9 -> CAGR 2025 - 2029
B12: Global transportation and Logistics Market Size | D12: =C44 -> 1272945.2 | E12: =D44 -> 1337992.7 | F12: =E44 -> 1406364.1 | G12: =F44 -> 1478229.3 | H12: =G44 -> 1553766.8 | I12: =H44 -> 1633164.3 | J12: =I44 -> 1716619 | K12: =J44 -> 1804338.2 | M12: =(K12/G12)^(1/5)-1 -> 0.040675257
B13: FedEx Market Share | D13: =FCFF!D13 -> 0.069585087 | E13: =FCFF!E13 -> 0.064187198 | F13: =FCFF!F13 -> 0.059867143 | G13: =FCFF!G13 -> 0.057974468 | H13: =FCFF!H13 -> 0.056684884 | I13: =FCFF!J13 -> 0.055640595 | J13: =FCFF!K13 -> 0.054732614 | K13: =FCFF!L13 -> 0.05174646 | M13: =((K13*K12)/(G13*G12))^(1/5)-1 -> 0.017288193
B14: E-commerce Market Size | D14: 30830770 | E14: =D14*(1+0.189) -> 36657786 | F14: =E14*(1+0.189) -> 43586107 | G14: =F14*(1+0.189) -> 51823881 | H14: =G14*(1+0.189) -> 61618595 | I14: =H14*(1+0.189) -> 73264509 | J14: =I14*(1+0.189) -> 87111501 | K14: 83260000 | M14: =(K14/G14)^(1/5)-1 -> 0.09946471
B15: FedEx Market Share | D15: =FCFF!D15 -> 0.0025638672 | E15: =FCFF!E15 -> 0.0020800493 | F15: =FCFF!F15 -> 0.0017233244 | G15: =FCFF!G15 -> 0.0014801945 | H15: =FCFF!H15 -> 0.001282501 | I15: =FCFF!J15 -> 0.0011152217 | J15: =FCFF!K15 -> 0.00097147653 | K15: =FCFF!L15 -> 0.0010158129 | M15: =((K15*K14)/(G15*G14))^(1/5)-1 -> 0.019718461
B16: E-commerce in the U.S. Market Size | D16: =E16/(1+0.1071) -> 921190.52 | E16: =F16/(1+0.1071) -> 1019850 | F16: =G16/(1+0.1071) -> 1129076 | G16: 1250000 | H16: =G16*(1+0.1071) -> 1383875 | I16: =H16*(1.1071) -> 1532088 | J16: =I16*(1.1071) -> 1696174.6 | K16: 2080000 | M16: =(K16/G16)^(1/5)-1 -> 0.10721169
B17: FedEx Market Share | D17: =FCFF!D17 -> 0.057127162 | E17: =FCFF!E17 -> 0.05128205 | F17: =FCFF!F17 -> 0.046035875 | G17: =FCFF!G17 -> 0.042099852 | H17: =FCFF!H17 -> 0.038920613 | I17: =FCFF!J17 -> 0.036122108 | J17: =FCFF!K17 -> 0.033572922 | K17: =FCFF!L17 -> 0.027083178 | M17: =((K17*K16)/(G17*G16))^(1/5)-1 -> 0.013711737
B18: Global Express Delivery Service | D18: =E18/1.06 -> 227260.59 | E18: =F18/1.06 -> 240896.23 | F18: 255350 | G18: =F18*1.06 -> 270671 | H18: =G18*1.06 -> 286911.26 | I18: =H18*1.06 -> 304125.94 | J18: =I18*1.06 -> 322373.49 | K18: =J18*1.06 -> 341715.9 | M18: =(K18/G18)^(1/5)-1 -> 0.047718692
B19: FedEx Market Share | D19: =FCFF!D19 -> 0.20159236 | E19: =FCFF!E19 -> 0.17743325 | F19: =FCFF!F19 -> 0.16000392 | G19: =FCFF!G19 -> 0.15690974 | H19: =FCFF!H19 -> 0.154321 | I19: =FCFF!J19 -> 0.15213618 | J19: =FCFF!K19 -> 0.14995716 | K19: =FCFF!L19 -> 0.14477194 | M19: =((K19*K18)/(G19*G18))^(1/5)-1 -> 0.030983204
B20: US Express Delivery Service | D20: =E20/1.0501 -> 87330.304 | E20: =F20/1.0501 -> 91705.552 | F20: 96300 | G20: =F20*1.0501 -> 101124.63 | H20: =G20*1.0501 -> 106190.97 | I20: =H20*1.0501 -> 111511.14 | J20: =I20*1.0501 -> 117097.85 | K20: =J20*1.0501 -> 122964.45 | M20: =(K20/G20)^(1/5)-1 -> 0.039883116
B21: FedEx Market Share | D21: =FCFF!D21 -> 0.23187827 | E21: =FCFF!E21 -> 0.21430545 | F21: =FCFF!F21 -> 0.19279335 | G21: =FCFF!G21 -> 0.19023468 | H21: =FCFF!H21 -> 0.18818775 | I21: =FCFF!J21 -> 0.1865502 | J21: =FCFF!K21 -> 0.1843668 | K21: =FCFF!L21 -> 0.18 | M21: =((K21*K20)/(G21*G20))^(1/5)-1 -> 0.02844504
B22: US freight and logistics market | F22: 1405500 | G22: 1450500 | H22: =G22*1.042 -> 1511421 | I22: =H22*1.042 -> 1574900.7 | J22: =I22*1.042 -> 1641046.5 | K22: =J22*1.042 -> 1709970.5 | M22: =(K22/G22)^(1/5)-1 -> 0.033461197
B23: FedEx Market Share | F23: =FCFF!F23 -> 0.030834578 | G23: =FCFF!G23 -> 0.029802579 | H23: =FCFF!H23 -> 0.028978465 | I23: =FCFF!J23 -> 0.02832031 | J23: =FCFF!K23 -> 0.027794966 | K23: =FCFF!L23 -> 0.025671346 | M23: =((K23*K22)/(G23*G22))^(1/5)-1 -> 0.0030743649
B24: Rest of World freight and logistics market | D24: =E24/1.0415 -> 4363400.2 | E24: =F24/1.0415 -> 4544481.3 | F24: =G24/1.0415 -> 4733077.3 | G24: =6380000-G22 -> 4929500 | H24: =(G24+G22)*1.0499-H22 -> 5186941 | I24: =(H24+H22)*1.0499-I22 -> 5457709.6 | J24: =(I24+I22)*1.0499-J22 -> 5742491 | K24: =(J24+J22)*1.0499-K22 -> 6042005.6 | M24: =(K24/G24)^(1/5)-1 -> 0.041539272
B25: FedEx Market Share | D25: =FCFF!D25 -> 0.00025026354 | E25: =FCFF!E25 -> 0.00024733296 | F25: =FCFF!F25 -> 0.00023325205 | G25: =FCFF!G25 -> 0.00022460164 | H25: =FCFF!H25 -> 0.00021768131 | I25: =FCFF!J25 -> 0.00021214505 | J25: =FCFF!K25 -> 0.00020771604 | K25: =FCFF!L25 -> 0.00019 | M25: =((K25*K24)/(G25*G24))^(1/5)-1 -> 0.0072650949
A27: x
B29: Industry Driver | D29: Description | O29: Porter's Five Forces
B31: E-commerce expansion is transforming logistics | D31: As online shopping continues to grow, costumers changed their buying behavior: they demand faster deliveries and more flexible services. This shift means the companies in the industry need to expand its operations and integrate with retail networks. They can then benefit from increased parcel volume and faster and innovative services. Companies can also gain from partnerships in the last-mile delivery.
B32: Sustainability regulations are reshaping fleet strategies | D32: In a world where sustainability is a highly discussed issue, growing pressure from governments and stakeholders is leading to a cut in logistics firms' emissions. Efforts such as transitioning to electric vehicles and sustainable aviation fuel and investing in renewable energy will not only meet regulatory targets but also enhance the company's appeal to clients with ESG goals.
B33: Automation and AI are boosting supply chain efficiency | D33: Adopting automation and AI to simplify package sorting, routing and delivery can help managing labor shortages, improve operational efficiency and reduce costs. Companies such as FedEx Corporation are implementing technologies like robotic package sorting and autonomous delivery vehicles.
B34: Rising fuel and labor costs affect profitability | D34: Transport firm's margins are considerably affected by volatile fuel prices and rising labor costs, impacting operating costs. This represents a structural pressure in the industry, compelling companies to invest in fleet efficiency and route optimization to protect their profit margins.
B35: Geopolitical shifts are disrupting trade routes | D35: Big conflitcs such as wars and difficult relationships between countries are affecting global freight flows. As this means tensions, tariffs and supply chain disruptions, companies are exposed to higher risks, meaning they have to constantly adjust routes and strategies to stregthen service reliability.
O36: Rivalry Among Existing Competitors | R36: 5
O37: Threat of New Entrants | R37: 2
O38: Threat of Substitutes | R38: 3
O39: Bargaining Power of Customers | R39: 4
O40: Bargaining Power of Suppliers | R40: 3
B43: Global transportation and Logistics Market Size - 2021 | C43: 22 | D43: 2023
B44: 1211060 | C44: =B44*1.0511 -> 1272945.2 | D44: =C44*1.0511 -> 1337992.7 | E44: =D44*1.0511 -> 1406364.1 | F44: =E44*1.0511 -> 1478229.3 | G44: =F44*1.0511 -> 1553766.8 | H44: =G44*1.0511 -> 1633164.3 | I44: =H44*1.0511 -> 1716619 | J44: =I44*1.0511 -> 1804338.2 | K44: =J44*1.0511 -> 1896539.9
B47: US Express Delivery Service | C47: 22 | D47: 2023 | E47: 2024
B48: FedEx Express Segment - Total U.S. Domestic package revenue | C48: 16385 | D48: 16024 | E48: 15471

Sheet ESG
A7: x | B7: ESG Analysis
B12: ESG Scores | G12: GHG Scope 1 Emissions, Water Consumption, Energy Consumption and Waste Production per Sales
B15: LSEG ESG Score | D15: 70
B16: E-Score | D16: 71
B17: S-Score | D17: 64
B18: G-Score | D18: 78
B19: S&P Global ESG Score | D19: 31
B20: Environmental
B21: Social
B22: Governance & Economic
B23: Sustainalytics | D23: 19.4
B24: ISS ESG Corporate Rating | D24: D+
B25: SDG Impact Rating | D25: -0.7
B26: Governance Quality Score | D26: 5
B27: MSCI ESG Ratings
B30: Key Info | G30: Environmental
H32: Overview | I32: Targets | J32: Improvements | K32: Comments
B33: GICS Sector | C33: Industrials | G33: GHG Scope 1 Emissions | I33: FedEx Corporation set a goal of becoming carbon-neutral across their operations by 2040. Reducing in 40% aviation emissions intensity by 2034, considering the same 2005 baseline. By 2040, transform the entire PUD fleet to all electric vehichles. | J33: In 2006, the company launched the Fuel Sense program, resulting in over 9.6 million metric tons of avoided CO2 emissions. In 2011, met the goal of 20% reduction in aircraft CO2 emissions. Reduction of aviation emissions intensity by 30% from 2005 baseline. From FY23 to FY24, there was a 6.1% reduction in scope 1 emissions, being 4.9% of those just from jet fuel consiumption. From FY24 to FY25 scope 1 emissions reduced 4.9%. In 2024, the company prevented over 1.2 milion metric tons of CO2 emission through aircraft modernization initiatives. In FY24, the company continued adding EVs across international markets, also adding e-cargo bicycles and tricycles in Canada, Taiwan and UK. | K33: In 2022, FedEx launched FedEx Sustainability Insights for costumers and suppliers to calculate their estimated Co2 transportation emissions. In 2025, the company began using SAF (sustainable aviation fuel). However, in 2024, less than 1% of all jet fuel produced was SAF. FedEx is first focusing on decarbonizing their operations by using proven technologies that reduce emissions. The future change of new equipment will reduce their emissions per package-mile. Costumers can also forecast future emissions trough predictive modeling capabilities.
B34: GICS Industry Group | C34: Transportation
B35: GICS Industry | C35: Air Freight & Logistics | G35: Water Consumption
B36: GICS Sub-Industry | C36: Air Freight & Logistics
G37: Energy Consumption | I37: By 2040, the company aim to source 100% of their facility industry from renewable sources. By 2028, FedEx aims to source 500 gigawatt-hours (GWh) of energy from renewable sources and 1,300 GWh by 2033. In 2025, the company still plans to install an additional natural gas generator at their Lehigh Valley, Pennsylvania facility in 2025. | J37: In 2010, the company completed their first non-US on-site solar energy installation in Cologne, Germany. In 2011, FedEx opened one of the most energy efficient data centers in the US. Since FY17, the company reduced the energy consumption at participating FedEx Office stores by 47% through the implementation of energy management systems and LED lighting. In FY24, the company completed contracts to produce aproximately 8 additional Ws of renewable energy across the U.S. They also generated over 31 GWh of on- and off-site solar energy at 34 locations around the world. | K37: As part of the Fuel Sense program, the company is flying their fleet at higher altitudes where low air density requires aircraft to expend less energy to propel forward. With the transition to one FedEx and to accomodate the increasing volume of packages transported, PUD EVs will need to be larger, which means larger capacity batteries and higher energy usage to charge. FedEx manages energy usage and waste globally through ISO standards, energy systems, and employee-driven innovations to improve performance and savings.
B38: Headquarters | C38: Memphis, Tennessee, United States
B39: Numer of Employees | C39: 510.000 | G39: Waste Management | I39: The company aims to minimize their operational waste footprint. | J39: In 2021, the company introduced FedEx Reusable Pak, allowing customers to return items or prepare their own shipments without additional packaging. In FY23, FedEx Freight recycled over 1,700 tons of metal, 2,700 tons of paper, and 2,100 tons of wood-related waste. Meanwhile, FedEx Express recycled 42.5 million pounds of cardboard, wood pallets, paper, and metal waste, FedEx Office maintained its toner recycling program, preventing over 62,000 cartridges from being disposed of in landfills. Lastly, FedEx Ground facilities achieved a waste diversion rate of nearly 80% from recycling. In FY24, FedEx piloted a project that introduced mesh reusable bags into the small package sort systems, preventing 50 million plastic bags from entering landfills. | K39: FedEx earned the ISO 9001 global certification for 30 consecutive years, for their effective quality management system, by streamlining processes to improve resource management and reduce waste. Through the Supply Exchange Program, FedEx freight reduces waste via office and operations supplies reuse and sharing excess supplies across various locations and departments.
B41: Annual Report | C41: 2024 | G41: Other
B42: Sustainability Report | C42: 2024
B44: Recent Headlines | G44: Social
H46: Overview | I46: Targets | J46: Improvements | K46: Comments
B47: Concern over jobs as FedEx confirms closure plan - BBC News - 14/05/2025 | G47: Employee Turnover % | I47: The company is committed to compensating our employees fairly and respect the rights of team members to unionize. | J47: In FY24, they implemented a cohesive listening platform to analyze employee feedback across the enterprise. | K47: In FY24, the global turnover rate for all employees was 95%. Turnover for part-time team members, primarily package handlers at our sorting locations, was 195%, while full-time team member turnover was 26%. This number is so high due to many reasons: FedEx relies heavily on seasonal and part-time staff at hubs, the reoles are physically intense and low paid and hiring highly increases in peak season meaning inflating annual turnover stats when workers leave afterward.
B49: FedEx announces leadership for company split - 19/05/2025 | G49: Salaries & Compensation | I49: Maintain the comprehensive compensation package. | J49: As in January 2024, in the U.S., the company covered approximately 70% of the total eligible health, wellness and disability costs at the plan level for 215,000 participating team members. In 2024, they also launched a new plan option ("Your Choice"), designed for flexibility, simplicity, cost transparency, and increased access to quality providers. | K49: In FedEx's compensation plan, each executive officer has individual performance objectives established at the beginning of each fiscal year. "Our comprehensive benefits include health care coverage, well-being programs, basic and supplemental life and accidental death and dismemberment insurance, paid sick leave, paid time off, and parental leave for all eligible full- and part-time employees.(...)These health benefits include flexible medical, behavioral, dental, vision, and pharmacy coverage, in addition to mental health services. " - 2025 corporate responsability report. To help ensure the benefits and compensation packages remain competitive, they routinely conduct peer benchmarking and internal pay equity analyses. Workers often report burnout, feeling undervalued and unpredictable scheduling.
B50: FedEx closes 100 stations through Network 2.0 overhaul - Supply Chain Dive - 25/06/2025
B51: FedEx to implement single pricing structure for express, standard pickups. - Freight Waves - 03/07/2025 | G51: Reputation | I51: FedEx aims to be seen as a trusted, innovative and responsible global logistics leader, developing mutually rewarding relationships, valuing its people and communities and comitting to a sustainable, technology-drivn future. | J51: FedEx has been ranked among "World's Most Admired Companies" for 25 consecutive years. It remains the highest-ranked delivery company in that ranking. | K51: In 2024, FedEx was named among the World's Most Ethical Companies by Ethisphere. However, workers continue expressing frustration around workload and lack of recognition.
B52: FedEx executive Sriram Krishnasamy stepping down, company anounces - Action News 5 - 17/07/2025.
G53: Discrimination Events | I53: Fedex plans to align policies more closely with ADA (Americans with disabilities) standards. The company also suggests an ongoing focus in workforce diversity and inclusion in their goals. | J53: After the 2007's class action, FedEx eliminated the BST. After the sex discrimination case in 2012, FedEx comitted to provide anti-discrimination training, revice their policies and issue regret letters. The company also agreed to invest in ASL interpreters, acessible orientation and captioned training | K53: In 2007,there was a class action by African American and Latino employees alledging discrimination in promotions, pay, evaluations and discipline. They also revealed that the "Basic Skills Test" contruibuted to minorities being stuck in lower-paying roles, screening them out from promotions. In 2012, FedEx Freight allegedly hired a man over more qualified women for an HR position. The company faced accusations regarding failure in providing accommodations to deaf and hard-on-hearing workers. In 2024, EEOC accused FedEx of placing disabled transport workers on unpaid leave or firing them if they were not "100% healed". In 2025, EEOC also sued FedEx for disability discrimination, meaning it violated federal law by failing to accomodate several dispatchers' requests to continue working from home and demanded their immediate return to the office. It also forced one dispatcher into retirement.
G55: Work Safety | I55: FedEx Corporations plans to pilot AI capabilities within vehicles that can alert and validate operational safety in FY25. | J55: In 2020, FedEx Express launched an interactive program that encourages employee safety engagement and recognizes team members for working safely.From 2021 to 2024, FedEx reported a 74% improvement in distracted driving events since the implementation of the VEDR (video event data recorder) program. From 2023 to 2024, there was a 2.7% improvement in PUD preventable vehicle accident rate. | K55: Employees and managers use safety observations to reinforce proper lifting techniques to reduce injuries. FedEx also provides mandatory safety trainings for all new hires during onboarding. They aim to equip employees with the tools necessary to address their work- and responsibility-specific safety hazards. The Leading with Safety program teaches managers proper safety procedure execution, hazard recognition and reporting. We also provide a program to reduce risk of injury and discomfort as well as trainings to improve workplace efficiencies, reduce injury, and enhance employee morale.
G57: Damage to consumer health | I57: Continue to ensure timely delivery of medical products. | J57: In the past years, FedEx added additional facilities to their network in Asia to help supporting cold chain logistics in the region. Throughout the pandemic, the company came up with a monitoring and intervention solution to monitor vaccine transportation. | K57: Although there's no direct damage to consumer health, when it comes to delivering critical medical supplies and healthcare products, some incidents, such as late deliveris when the medicine expired and the costumer was charged can happen, which may lead to impacts on the costumer's health.
G59: Pension Plan | I59: In FY26, the company anticipates making up to 400 million dollars in voluntary contributions to its U.S. pension plan. FedEx is also commiting to ensure that healthcare and pension plans remain adequately funded and sustainable despite any volatility in the market. | J59: The Company sponsors defined benefit pension plans that provide retirement benefits to certain U.S. employees.
G61: Supply chain | I61: FedEx Corporation is in the process of making supply chains smarter and more efficient through AI and robotics technologies. | J61: In FY24, 74% of packaging materials were from third-party certified sources. With Pyxera Global, the company launched the Circular Supply Chain Coalition to transform supply chains and upcycle rare earth minerals from consumer electronic waste. Branded packaging is now 100% recyclable and 40% made from recycled content. | K61: "FedEx is consistently recognized as one of the most ethical companies in the world" - 2025 corporate responsability report. The company currently relies in 100000 direct suppliers to maintain their global operations. In 2025, FedEx established a partnership with Amazon for residential deliveries of select large packages, which means the companies renewed their relationship.
G63: Community involvement | I63: Continue ecouraging members to participate in community service programs (such as "Purple Toats" and "Community Engagement Fund") to maintain a high community involvement. | J63: FedEx has the FedEx Alert Line call center and web portal for reporting concerns accessible for team members and community members as well in which they received more than 18700 reports in FY2024. From FY2024 to FY2025, employee participation in community programs increased 20% in the Asia Pacific region. | K63: FedEx is involved with the community also through FedEx Cares, a global community engagement program that aims to connect people and possibilities. It includes volunteerism, charitable giving and strategic investments. Although the company shows a big community involvement, this varies by region.
G65: Public Sector | I65: Continue expand logistics for federal, state and local agencies and protect operational flexibility and costumer interests. | J65: The comapny provides shipping and logistics to multiple federal and state agencies. During the pandemic, it partnered with the U.S. Department of Health and Human Services to ship medical supplies. | K65: FedEx Corporation is a fully private company, publicly traded on the NYSE. There is no government ownership.
...

Sheet Segments
A7: x | B7: Segments | D7: =F7 -> 2020 | E7: =F7 -> 2020 | F7: 2020 | G7: =F7 -> 2020 | H7: =F7 -> 2020 | J7: =L7 -> 2021 | K7: =L7 -> 2021 | L7: 2021 | M7: =L7 -> 2021 | N7: =L7 -> 2021 | P7: =R7 -> 2022 | Q7: =R7 -> 2022 | R7: 2022 | S7: =R7 -> 2022 | T7: =R7 -> 2022 | V7: =X7 -> 2023 | W7: =X7 -> 2023 | X7: 2023 | Y7: =X7 -> 2023 | Z7: =X7 -> 2023 | AB7: =AD7 -> 2024 | AC7: =AD7 -> 2024 | AD7: 2024 | AE7: =AD7 -> 2024 | AF7: =AD7 -> 2024 | AH7: =AJ7 -> 2025 | AI7: =AJ7 -> 2025 | AJ7: 2025 | AK7: =AJ7 -> 2025 | AL7: =AJ7 -> 2025 | AN7: =AP7 -> 2025 | AO7: =AP7 -> 2025 | AP7: 2025 | AQ7: =AP7 -> 2025 | AR7: =AP7 -> 2025 | AZ7: Products
D8: 2020 | J8: =D8+1 -> 2021 | P8: =J8+1 -> 2022 | V8: =P8+1 -> 2023 | AB8: =V8+1 -> 2024 | AH8: =AB8+1 -> 2025 | AN8: =AH8+1 -> 2026 | AT8: =AN8+1 -> 2027 | AV8: =+AT8+1 -> 2028 | AX8: =+AV8+1 -> 2029
D9: Q1 | E9: Q2 | F9: Q3 | G9: Q4 | H9: FY | J9: Q1 | K9: Q2 | L9: Q3 | M9: Q4 | N9: FY | P9: Q1 | Q9: Q2 | R9: Q3 | S9: Q4 | T9: FY | V9: Q1 | W9: Q2 | X9: Q3 | Y9: Q4 | Z9: FY | AB9: Q1 | AC9: Q2 | AD9: Q3 | AE9: Q4 | AF9: FY | AH9: Q1 | AI9: Q2 | AJ9: Q3 | AK9: Q4 | AL9: FY | AN9: Q1 | AO9: Q2 | AP9: Q3 | AQ9: Q4 | AR9: FY | AT9: FY | AV9: FY | AX9: FY
B12: Revenue by segment:
B13: FedEx Express | D13: =soma( | H13: 35513 | N13: 42078 | T13: 45814 | Z13: 42743 | AF13: 40857 | AL13: =FCFF!G29 -> 42470.916 | AR13: =FCFF!H29 -> 44276.432 | AT13: =FCFF!J29 -> 46268.558 | AV13: =FCFF!K29 -> 48342.212 | AX13: =FCFF!L29 -> 49470.874
B14: FedEx Ground | H14: 22733 | N14: 30496 | T14: 33232 | Z14: 33507 | AF14: 34256 | AL14: =FCFF!G30 -> 34238.509 | AR14: =FCFF!H30 -> 34749.475 | AT14: =FCFF!J30 -> 35437.614 | AV14: =FCFF!K30 -> 36284.567 | AX14: =FCFF!L30 -> 35105.71
B15: FedEx Freight | H15: 7102 | N15: 7833 | T15: 9532 | Z15: 9632 | AF15: 9082 | AL15: =FCFF!G31 -> 8990.1317 | AR15: =FCFF!H31 -> 9049.1849 | AT15: =FCFF!J31 -> 9164.0608 | AV15: =FCFF!K31 -> 9328.2652 | AX15: =FCFF!L31 -> 8791.5325
B16: FedEx Services | H16: 22 | N16: 32 | T16: 253 | Z16: 301 | AF16: 260 | AL16: =FCFF!G32 -> 267.8 | AR16: =FCFF!H32 -> 275.834 | AT16: =FCFF!J32 -> 284.10902 | AV16: =FCFF!K32 -> 292.63229 | AX16: =FCFF!L32 -> 301.41126
B17: Corporate, other and eliminations | H17: 3847 | N17: 3520 | T17: 4681 | Z17: 3972 | AF17: 3238 | AL17: =FCFF!G33 -> 3909.3207 | AR17: =FCFF!H33 -> 3823.6974 | AT17: =FCFF!J33 -> 3860.4761 | AV17: =FCFF!K33 -> 4122.2675 | AX17: =FCFF!L33 -> 4039.5437
B18: Total revenue | D18: =IS!D18 -> 17048 | E18: =IS!E18 -> 17324 | F18: =IS!F18 -> 17487 | G18: =IS!G18 -> 17358 | H18: =IS!H18 -> 69217 | J18: =IS!J18 -> 19321 | K18: =IS!K18 -> 20563 | L18: =IS!L18 -> 21510 | M18: =IS!M18 -> 22565 | N18: =IS!N18 -> 83959 | P18: =IS!P18 -> 22003 | Q18: =IS!Q18 -> 23474 | R18: =IS!R18 -> 23641 | S18: =IS!S18 -> 24394 | T18: =IS!T18 -> 93512 | V18: =IS!V18 -> 23242 | W18: =IS!W18 -> 22814 | X18: =IS!X18 -> 22169 | Y18: =IS!Y18 -> 21930 | Z18: =IS!Z18 -> 90155 | AB18: =IS!AB18 -> 21681 | AC18: =IS!AC18 -> 22165 | AD18: =IS!AD18 -> 21738 | AE18: =IS!AE18 -> 22109 | AF18: =IS!AF18 -> 87693 | AH18: =IS!AH18 -> 21579 | AI18: =IS!AI18 -> 21967 | AJ18: =IS!AJ18 -> 0 | AK18: =IS!AK18 -> 0 | AL18: =SUM(AL13:AL17) -> 89876.678 | AN18: =IS!AN18 -> 0 | AO18: =IS!AO18 -> 0 | AP18: =IS!AP18 -> 0 | AQ18: =IS!AQ18 -> 0 | AR18: =SUM(AR13:AR17) -> 92174.623 | AT18: =SUM(AT13:AT17) -> 95014.818 | AV18: =SUM(AV13:AV17) -> 98369.944 | AX18: =SUM(AX13:AX17) -> 97709.071
B20: Revenue by region:
B21: U.S. | H21: 48404 | N21: 58792 | T21: 64941 | Z21: 64890 | AF21: 63531 | AL21: =FCFF!G48 -> 64274.068 | AR21: =FCFF!H48 -> 65667.985 | AT21: =FCFF!J48 -> 67261.051 | AV21: =FCFF!K48 -> 69148.065 | AX21: =FCFF!L48 -> 67982.179
B22: International | H22: 20813 | N22: 25167 | T22: 28571 | Z22: 25265 | AF22: 24162 | AL22: =FCFF!G59 -> 24340.678 | AR22: =FCFF!H59 -> 25421.692 | AT22: =FCFF!J59 -> 26623.959 | AV22: =FCFF!K59 -> 27946.064 | AX22: =FCFF!L59 -> 28485.253
B26: Total revenue | D26: =IS!D18 -> 17048 | E26: =IS!E18 -> 17324 | F26: =IS!F18 -> 17487 | G26: =IS!G18 -> 17358 | H26: =IS!H18 -> 69217 | J26: =IS!J18 -> 19321 | K26: =IS!K18 -> 20563 | L26: =IS!L18 -> 21510 | M26: =IS!M18 -> 22565 | N26: =IS!N18 -> 83959 | P26: =IS!P18 -> 22003 | Q26: =IS!Q18 -> 23474 | R26: =IS!R18 -> 23641 | S26: =IS!S18 -> 24394 | T26: =IS!T18 -> 93512 | V26: =IS!V18 -> 23242 | W26: =IS!W18 -> 22814 | X26: =IS!X18 -> 22169 | Y26: =IS!Y18 -> 21930 | Z26: =IS!Z18 -> 90155 | AB26: =IS!AB18 -> 21681 | AC26: =IS!AC18 -> 22165 | AD26: =IS!AD18 -> 21738 | AE26: =IS!AE18 -> 22109 | AF26: =IS!AF18 -> 87693 | AH26: =IS!AH18 -> 21579 | AI26: =IS!AI18 -> 21967 | AJ26: =IS!AJ18 -> 0 | AK26: =IS!AK18 -> 0 | AL26: =SUM(AL21:AL22) -> 88614.746 | AN26: =IS!AN18 -> 0 | AO26: =IS!AO18 -> 0 | AP26: =IS!AP18 -> 0 | AQ26: =IS!AQ18 -> 0 | AR26: =SUM(AR21:AR22) -> 91089.677 | AT26: =SUM(AT21:AT22) -> 93885.01 | AV26: =SUM(AV21:AV22) -> 97094.129 | AX26: =SUM(AX21:AX22) -> 96467.432
B28: Products:
B29: Product 1
B30: Product 2
B31: Product 3
B32: Product 4
B33: Product 5
A35: x | B35: Notes & Forecasts
B40: Separating FedEx Freight from FedEx Corporation | H40: The dynamics, cost structures and investment needs within LTL market are different from parcel delivery. To compete more effectively in the market, FedEx believes to be crucial separating FedEx Freight, creating two independent industry-leading companies. This is intended to be tax-efficient for share-holders and allows better capital allocation as well as more operational agility and accountability. Although cooperation between the two is ensured, this change can lead to a range of different investor bases.
B41: Remotion of de minimis exemption | H41: The recent end of the de minimis exemption means parcels now face tariffs, increasing costs for costumers. As FedEx focused heavily on direct shippments from China to U.S. by air, the air freight demand fell sharply and is expected to continue weak, meaning an incertain future for global logistics providers. Although all this resulted in a reduction of demand for these shipments, product mix is possibly shifting from low-value cheap parcels toward high-value shipment, more lucrative than the first ones.
B42: Introduction of the "Easy Returns" program | H42: The continuous rapid growth of online shopping also came with an increase in returns. However, handling these is expensive and complex. To improve costumer experience and reduce costs to better compete in the industry, FedEx Corporation introduced a new "Easy Returns" program, with boxless returns for items under 10 pounds, QR-code based tracking and an expansion of the drop-off network. This ended up stretching FedEx's domestic retail logistics footprint and positions it to capture higher-margin services.
B43: Transforming FedEx's operating companies into a unified structure (One FedEx) | H43: FedEx always operated multiple entities, meaning redundancies in operation, overlapping networks and inefficiencies in some management and logistics. As peers operate more integrated, to remain competitive in the industry, FedEx rannounced, in 2023, the One FedEx consolidation plan, integrating all operating companies into a single organization. This will have a positive impact in financial gains, costumer experience and workforce structure.

Sheet Trading Comps
B7: in millions of USD | D7: Current | E7: % of | I7: Enterprise Value / | S7: LTM | T7: Net | V7: Price / | Z7: LT
D8: Share | E8: 52-week | F8: Equity | G8: Enterprise | I8: LTM | J8: 2025 | K8: 2026 | L8: LTM | M8: 2025E | N8: 2026E | O8: LTM | P8: 2025E | Q8: 2026E | S8: EBITDA | T8: Debt / | V8: LTM | W8: 2025E | X8: 2026E | Z8: EPS
B9: Company | C9: Ticker | D9: Price | E9: High | F9: Value | G9: Value | I9: Sales | J9: Sales | K9: Sales | L9: EBITDA | M9: EBITDA | N9: EBITDA | O9: EBIT | P9: EBIT | Q9: EBIT | S9: Margin | T9: EBITDA | V9: EPS | W9: EPS | X9: EPS | Z9: Growth
B12: Tier I: US Distribution Sector
B15: UNITED PARCEL-B | C15: UPS US | D15: USD 82,58 | E15: 0.56947797 | F15: 69992.301 | G15: 108237.03 | I15: 1.1984656 | J15: 1.2360011 | K15: 1.2331078 | L15: 7.6611711 | M15: 9.4897375 | N15: 8.9021693 | O15: 11.342034 | P15: 13.921531 | Q15: 12.673715 | S15: 0.15643374 | T15: 2.2265096 | V15: 10.593658 | W15: 12.795748 | X15: 11.741773 | Z15: 0.083500503
B16: DHL GROUP | C16: DHL GR | D16: EUR 37,85 | E16: 0.85440181 | F16: 45648 | G16: 69272 | I16: 0.82534463 | J16: 0.82475082 | K16: 0.80447903 | L16: 6.2177542 | M16: 6.4065946 | N16: 6.1294025 | O16: 10.941715 | P16: 11.553119 | Q16: 10.853427 | S16: 0.13273999 | T16: 2.3182551 | V16: 13.297212 | W16: 13.231479 | X16: 12.348581 | Z16: 0.083904073
B17: OLD DOMINION FRT | C17: ODFL UW | D17: USD 140,6 | E17: 0.6028384 | F17: 30157.026 | G17: 34325.628 | I17: 6.0875916 | J17: 6.1681776 | K17: 5.8103826 | L17: 19.200109 | M17: 19.957288 | N17: 18.144253 | O17: 23.96196 | P17: 25.291842 | Q17: 22.578599 | S17: 0.31706027 | T17: 0.095121227 | V17: 27.527026 | W17: 29.527552 | X17: 26.4314 | Z17: 0.13447901
B18: XPO INC | C18: XPO US | D18: USD 126,84 | E18: 0.78782609 | F18: 15316.725 | G18: 18844.22 | I18: 2.3531743 | J18: 2.332446 | K18: 2.2411806 | L18: 15.799631 | M18: 14.853385 | N18: 13.331174 | O18: 27.401803 | P18: 23.899986 | Q18: 21.015258 | S18: 0.14893856 | T18: 3.5373514 | V18: 42.251059 | W18: 35.914434 | X18: 28.930334 | Z18: 0.21415028
B19: HUNT (JB) TRANS | C19: JBHT US | D19: USD 134,2 | E19: 0.66966068 | F19: 13427.028 | G19: 15568.836 | I19: 1.2905104 | J19: 1.2990692 | K19: 1.2391452 | L19: 9.8336031 | M19: 10.158834 | N19: 9.2032527 | O19: 18.683664 | P19: 19.367235 | Q19: 16.6571 | S19: 0.13123474 | T19: 1.104247 | V19: 23.368823 | W19: 24.739918 | X19: 20.92771 | Z19: 0.17269073
F20: =SUM(F15:F19) -> 174541.08
B21: Mean | I21: 3.2437588 | J21: 3.2665643 | K21: 3.0969028 | L21: 14.944448 | M21: 14.989836 | N21: 13.55956 | O21: 23.349142 | P21: 22.853021 | Q21: 20.083652 | R21: #DIV/0! | S21: 0.19907786 | T21: 1.5789065 | U21: #DIV/0! | V21: 31.048969 | W21: 30.060635 | X21: 25.429815 | Y21: #DIV/0! | Z21: 0.17377334
B22: Median | I22: 1.2905104 | J22: 1.2990692 | K22: 1.2391452 | L22: 9.8336031 | M22: 10.158834 | N22: 9.2032527 | O22: 18.683664 | P22: 19.367235 | Q22: 16.6571 | S22: 0.14893856 | T22: 2.2265096 | V22: 23.368823 | W22: 24.739918 | X22: 20.92771 | Z22: 0.13447901
B24: Tier II: E-commerce
B27: AMAZON.COM INC | C27: AMZN US | D27: USD 218,15 | E27: 0.89951344 | F27: 2326550.6 | G27: 2397434.4 | I27: 3.5780574 | J27: 3.382659 | K27: 3.0640144 | L27: 16.23959 | M27: 14.407115 | N27: 12.172073 | O27: 31.466523 | P27: 29.960901 | Q27: 24.53865 | S27: 0.22032929 | T27: 1.0290458 | V27: 32.89614 | W27: 26.243134 | X27: 22.666832 | Z27: 0.18305782
B28: FSN E-COMMERCE V | C28: NYKAA IN | D28: INR 239,81 | E28: 0.96154771 | F28: 686163.34 | G28: #N/A N/A | S28: 0.062027959 | T28: #N/A N/A | V28: 860.28502 | W28: 809.15488 | X28: 298.78939 | Z28: 1.0278293
B29: SHOPIFY INC - A | C29: SHOP US | D29: USD 151,3 | E29: 0.93887682 | F29: 209195.07 | G29: 145090.54 | I29: 14.48877 | J29: 12.870042 | K29: 10.487759 | L29: 111.01036 | M29: 76.221855 | N29: 57.728971 | O29: 113.7965 | P29: 77.726775 | Q29: 58.619867 | S29: 0.13051728 | T29: 0.89403454 | V29: 144.43786 | W29: 109.16336 | X29: 85.482302 | Z29: 0.26643244
B30: ALIBABA GRP-ADR | C30: BABA US | D30: USD 189,34 | E30: 0.98271656 | F30: 451330.22 | G30: 1467142.5 | I30: 1.4660239 | J30: 1.4672228 | K30: 1.4104008 | L30: 8.9965692 | M30: 7.1966846 | N30: 8.5241546 | O30: 12.126748 | P30: 10.721424 | Q30: 12.372651 | S30: 0.16295367 | T30: 1.2752778 | V30: 3.9466945 | W30: 2.8871075 | X30: 3.5768905 | Z30: 0.077852734
B31: JD.COM INC-ADR | C31: JD US | D31: USD 35,98 | E31: 0.75240485 | F31: 51894.675 | G31: 227251.84 | I31: 0.17962939 | J31: 0.17157703 | K31: 0.16139142 | L31: 5.0577961 | M31: 8.8068453 | N31: 5.2489523 | O31: 6.339317 | P31: 23.065164 | Q31: 8.4645988 | S31: 0.035515348 | T31: 2.5652041 | V31: 1.2626419 | W31: 1.8579805 | X31: 1.337682 | Z31: 0.25958147
B33: Mean | I33: 4.9281202 | J33: 4.4728752 | K33: 3.7808915 | L33: 35.326079 | M33: 26.658125 | N33: 20.918538 | O33: 40.932273 | P33: 35.368566 | Q33: 25.998942 | S33: 0.12226871 | T33: 1.4408905 | V33: 208.56567 | W33: 189.86129 | X33: 82.370619 | Z33: 0.36295076
B34: Median | I34: 2.5220406 | J34: 2.4249409 | K34: 2.2372076 | L34: 12.618079 | M34: 11.60698 | N34: 10.348114 | O34: 21.796636 | P34: 26.513033 | Q34: 18.45565 | S34: 0.13051728 | T34: 1.1521618 | V34: 32.89614 | W34: 26.243134 | X34: 22.666832 | Z34: 0.25958147
B36: Tier III: Logistics International Sector
B39: AP MOLLER-B | C39: MAERSKB DC | D39: DKK 12610 | E39: 0.85260311 | F39: 201179.37 | G39: 27199.015 | I39: 0.47879689 | J39: 0.52026157 | K39: 0.55220043 | L39: 2.006863 | M39: 3.0128881 | N39: 4.5997519 | O39: 3.8346278 | P39: 9.5032335 | Q39: -72.882095 | S39: 0.23857975 | T39: 1.3079482 | V39: 29.140214 | W39: 77.979524 | X39: -247.77311 | Z39: -1.5484448
B40: KUEHNE & NAGEL-R | C40: KNIN SW | D40: CHF 152,6 | E40: 0.67283951 | F40: 18596.083 | G40: 23224.963 | I40: 0.90274665 | J40: 0.92618847 | K40: 0.91627693 | L40: 9.3535896 | M40: 10.023505 | N40: 9.7915062 | O40: 14.362995 | P40: 16.018321 | Q40: 15.54393 | S40: 0.096513391 | T40: 1.3700724 | V40: 16.148358 | W40: 18.053418 | X40: 17.797298 | Z40: 0.051829791
B41: DB SCHENKER | C41: 3001735Z GR | D41: EUR #N/A N/A | E41: #VALUE! | F41: #N/A N/A | G41: #N/A Field Not Applicable
B42: NIPPON EXPRESS H | C42: 9147 JT | D42: JPY 3290 | E42: 0.93732194 | F42: 855297 | G42: 1414876.5 | I42: 0.54423789 | J42: 0.54166504 | K42: 0.52807791 | L42: 5.5340814 | M42: 5.8111895 | N42: 5.1401502 | O42: 21.063486 | P42: 23.243393 | Q42: 15.829514 | S42: 0.098342949 | T42: 3.5195988 | V42: 24.278412 | W42: 24.771961 | X42: 15.034344 | Z42: 0.25512163
B43: EXPEDITORS INTL | C43: EXPD US | D43: USD 123,06 | E43: 0.95284553 | F43: 16953.958 | G43: 14871.376 | I43: 1.3191867 | J43: 1.3877502 | K43: 1.3848492 | L43: 12.649784 | M43: 14.20719 | N43: 14.446996 | O43: 13.322956 | P43: 15.050208 | Q43: 15.426739 | S43: 0.10428532 | T43: 0.49892695 | V43: 19.879855 | W43: 22.566339 | X43: 22.955346 | Z43: 0.024269636
B45: Mean | I45: 0.81124203 | J45: 0.84396633 | K45: 0.84535113 | L45: 7.3860794 | M45: 8.2636933 | N45: 8.4946011 | O45: 13.146016 | P45: 15.953789 | Q45: -6.520478 | S45: 0.13443035 | T45: 1.6741366 | V45: 22.36171 | W45: 35.842811 | X45: -47.99653 | Z45: -0.30430593
B46: Median | I46: 0.72349227 | J46: 0.73392675 | K46: 0.73423868 | L46: 7.4438355 | M46: 7.9173474 | N46: 7.4658282 | O46: 13.842976 | P46: 15.534265 | Q46: 15.485335 | S46: 0.10131413 | T46: 1.3390103 | V46: 22.079133 | W46: 23.66915 | X46: 16.415821 | Z46: 0.038049714
W47: 4
B48: Overall
B51: Mean | I51: 2.670195 | J51: 2.5482931 | K51: 2.2948666 | L51: 17.658531 | M51: 15.427163 | N51: 13.335601 | O51: 23.741872 | P51: 23.024856 | Q51: 12.437843 | S51: 0.14539088 | T51: 1.6724302 | V51: 89.236641 | W51: 86.349059 | X51: 22.874769 | Z51: 0.091875332
B52: Median | I52: 1.2905104 | J52: 1.2990692 | K52: 1.2391452 | L52: 9.3535896 | M52: 10.023505 | N52: 9.2032527 | O52: 14.362995 | P52: 19.367235 | Q52: 15.54393 | S52: 0.13198737 | T52: 1.3079482 | V52: 23.823617 | W52: 24.75594 | X52: 19.362504 | Z52: 0.15358487
B54: High | I54: 14.48877 | J54: 12.870042 | K54: 10.487759 | L54: 111.01036 | M54: 76.221855 | N54: 57.728971 | O54: 113.7965 | P54: 77.726775 | Q54: 58.619867 | R54: 0 | S54: 0.31706027 | T54: 3.5373514 | V54: 860.28502 | W54: 809.15488 | X54: 298.78939 | Z54: 1.0278293
B55: Low | I55: 0.17962939 | J55: 0.17157703 | K55: 0.16139142 | L55: 2.006863 | M55: 3.0128881 | N55: 4.5997519 | O55: 3.8346278 | P55: 9.5032335 | Q55: -72.882095 | R55: 0 | S55: 0.035515348 | T55: 0.095121227 | V55: 1.2626419 | W55: 1.8579805 | X55: -247.77311 | Z55: -1.5484448

Sheet Peers
B7: Peers
A12: x | B12: Growth | C12: FEDEX CORP | D12: UNITED PARCEL-B | E12: DHL GROUP | F12: OLD DOMINION FRT | G12: XPO INC | H12: HUNT (JB) TRANS | I12: AMAZON.COM INC | J12: FSN E-COMMERCE V | K12: SHOPIFY INC - A | L12: ALIBABA GRP-ADR | M12: JD.COM INC-ADR | N12: AP MOLLER-B | O12: KUEHNE & NAGEL-R | P12: DB SCHENKER | Q12: NIPPON EXPRESS H | R12: EXPEDITORS INTL
B14: Revenue (LTM) | C14: 0.0026569966 | D14: 0.00906125 | E14: 0.028112597 | F14: -0.055443441 | G14: -0.0011226144 | H14: -0.022369924 | I14: 0.10872134 | J14: 0.24571678 | K14: 0.28979907 | L14: 0.28979907 | M14: 0.053159807 | N14: 0.053159807 | O14: 0.053159807 | P14: 0.053159807 | Q14: 0.053159807 | R14: 0.053159807
B15: Revenue (3-yr CAGR) | C15: -0.020322072 | D15: -0.033711428 | E15: -0.023133083 | F15: -0.019136684 | G15: 0.020140491 | H15: -0.047669245 | I15: 0.11305575 | J15: 0.26744208 | K15: 0.26030292 | L15: 0.054746952 | M15: 0.080868358 | N15: -0.092705013 | O15: -0.13794412 | P15: #N/A | Q15: 0.024461922 | R15: -0.15946
B16: Gross profit (LTM) | C16: 0.0022688898 | D16: 0.064459035 | E16: 0.03322679 | F16: -0.10359638 | G16: 0.16045304 | H16: -0.022302274 | I16: 0.14480215 | J16: #N/A | K16: 0.24615385 | L16: 0.24615385 | M16: 0.14434733 | N16: 0.14434733 | O16: 0.14434733 | P16: 0.14434733 | Q16: 0.14434733 | R16: 0.14434733
B17: EBIT (LTM) | C17: -0.019387919 | D17: 0.16109016 | E17: 0.11480895 | F17: -0.13609541 | G17: 0.015805022 | H17: -0.048546306 | I17: 0.38822586 | J17: 0.72972616 | K17: 0.56826568 | L17: 0.56826568 | M17: -0.18767793 | N17: -0.18767793 | O17: -0.18767793 | P17: -0.18767793 | Q17: -0.18767793 | R17: -0.18767793
B18: EBITDA (LTM) | C18: -0.0035368847 | D18: 0.074536051 | E18: 0.082912131 | F18: -0.10431085 | G18: 0.04622807 | H18: -0.026082228 | I18: 0.27556681 | J18: 0.40581066 | K18: 0.52508751 | L18: 0.52508751 | M18: -0.10278883 | N18: -0.10278883 | O18: -0.10278883 | P18: -0.10278883 | Q18: -0.10278883 | R18: -0.10278883
B19: FCF (LTM) | C19: -0.04942602 | D19: 0.2230315 | E19: -0.055166052 | F19: 0.093787339 | G19: #VALUE! | H19: #VALUE! | I19: 0.020517118 | J19: #VALUE! | K19: 0.76464088 | L19: -0.48482453 | M19: 0.12074115 | N19: 0.16142558 | O19: -0.17241379 | P19: #VALUE! | Q19: 0.27967096 | R19: -0.32645183
A21: x | B21: Margins | C21: FEDEX CORP | D21: UNITED PARCEL-B | E21: DHL GROUP | F21: OLD DOMINION FRT | G21: XPO INC | H21: HUNT (JB) TRANS | I21: AMAZON.COM INC | J21: FSN E-COMMERCE V | K21: SHOPIFY INC - A | L21: ALIBABA GRP-ADR | M21: JD.COM INC-ADR | N21: AP MOLLER-B | O21: KUEHNE & NAGEL-R | P21: DB SCHENKER | Q21: NIPPON EXPRESS H | R21: EXPEDITORS INTL
B23: Gross margin | C23: 0.21603394 | D23: 0.20284397 | E23: 0.4920058 | F23: 0.34786915 | G23: 0.31020813 | H23: 0.12970601 | I23: 0.48854393 | J23: #VALUE! | K23: 0.5036036 | L23: 0.39952145 | M23: 0.15866844 | N23: #VALUE! | O23: 0.34956858 | P23: #VALUE! | Q23: 0.086005704 | R23: 0.32204067
B24: EBIT margin | C24: 0.059333985 | D24: 0.092983419 | E24: 0.073990925 | F24: 0.26552854 | G24: 0.081764123 | H24: 0.068769006 | I24: 0.10751945 | J24: 0.026102478 | K24: 0.12105856 | L24: 0.14142161 | M24: 0.033427136 | N24: 0.11171191 | O24: 0.06668817 | P24: #VALUE! | Q24: 0.018226729 | R24: 0.098233246
B25: EBITDA margin | C25: 0.10782931 | D25: 0.14376668 | E25: 0.13301402 | F25: 0.31694073 | G25: 0.1471029 | H25: 0.12906425 | I25: 0.22032929 | J25: 0.062027959 | K25: 0.12722189 | L25: 0.18185924 | M25: 0.031058046 | N25: 0.23808686 | O25: 0.09663 | P25: #VALUE! | Q25: 0.094991843 | R25: 0.10428532
B26: Net margin | C26: 0.046539135 | D26: 0.063489623 | E26: 0.039579027 | F26: 0.20397451 | G26: 0.047943508 | H26: 0.047230609 | I26: 0.092871172 | J26: 0.0083121379 | K26: 0.22736486 | L26: 0.12994469 | M26: 0.035690647 | N26: 0.11010778 | O26: 0.047617128 | P26: #VALUE! | Q26: 0.012310859 | R26: 0.076418268
B27: SG&A margin | C27: #VALUE! | D27: #VALUE! | E27: #VALUE! | F27: 0.036294565 | G27: #VALUE! | H27: 0.025345398 | I27: 0.086629392 | J27: #VALUE! | K27: 0.2018018 | L27: 0.18895024 | M27: 0.049050801 | N27: #VALUE! | O27: 0.054148859 | P27: #VALUE! | Q27: 0.054003211 | R27: 0.0031442812
B28: R&D margin | C28: #VALUE! | D28: 0 | E28: #VALUE! | F28: #VALUE! | G28: #VALUE! | H28: 0 | I28: 0.14323964 | J28: #VALUE! | K28: 0.14519672 | L28: 0.058734186 | M28: 0.014781265 | N28: #VALUE! | O28: 0 | P28: #VALUE! | Q28: 0 | R28: #VALUE!
A30: x | B30: Returns | C30: FEDEX CORP | D30: UNITED PARCEL-B | E30: DHL GROUP | F30: OLD DOMINION FRT | G30: XPO INC | H30: HUNT (JB) TRANS | I30: AMAZON.COM INC | J30: FSN E-COMMERCE V | K30: SHOPIFY INC - A | L30: ALIBABA GRP-ADR | M30: JD.COM INC-ADR | N30: AP MOLLER-B | O30: KUEHNE & NAGEL-R | P30: DB SCHENKER | Q30: NIPPON EXPRESS H | R30: EXPEDITORS INTL
B32: ROIC | C32: 0.054291712 | D32: 0.14724174 | E32: 0.09356161 | F32: 0.25371291 | G32: 0.086361161 | H32: 0.096352609 | I32: 0.14833321 | J32: #VALUE! | K32: 0.099553003 | L32: 0.088374937 | M32: 0.067412897 | N32: 0.090772011 | O32: 0.22803951 | P32: #VALUE! | Q32: 0.018477262 | R32: 0.29457345
B33: CROIC | C33: 0.04298362 | D33: 0.13502412 | E33: 0.10374797 | F33: 0.18483571 | G33: 0.0032934651 | H33: 0.087234765 | I33: 0.072775487 | J33: 0.10059969 | K33: 0.12555031 | L33: 0.055977452 | M33: 0.10500503 | N33: 0.10966099 | O33: 0.17655007 | P33: #VALUE! | Q33: 0.10055517 | R33: 0.24741963
B34: ROCE | C34: 0.08542656 | D34: 0.18289417 | E34: 0.21490426 | F34: 0.32289622 | G34: 0.14911884 | H34: 0.15101762 | I34: 0.17851603 | J34: 0.18507188 | K34: 0.17721728 | L34: 0.32520616 | M34: 0.20824127 | N34: 0.10794336 | O34: 0.72195548 | P34: #VALUE! | Q34: 0.040445484 | R34: 0.40512367
B35: RONA | C35: 0.18583031 | D35: 0.5057636 | E35: 0.25729038 | F35: 0.36375686 | G35: 0.41198502 | H35: 0.20705542 | I35: 0.23986082 | J35: 0.15455141 | K35: 0.093009171 | L35: 0.12925807 | M35: 0.12363987 | N35: 0.10695981 | O35: 0.50658499 | P35: #VALUE! | Q35: 0.053813765 | R35: 0.46784549
B36: ROE | C36: 0.14704614 | D36: 0.34960342 | E36: 0.16151163 | F36: 0.26251269 | G36: 0.21097561 | H36: 0.14328305 | I36: 0.24770353 | J36: #VALUE! | K36: 0.22022915 | L36: 0.15198773 | M36: 0.17258731 | N36: 0.12737132 | O36: 0.51315203 | P36: #VALUE! | Q36: 0.035152489 | R36: 0.39014862
B37: ROA | C37: 0.046863726 | D37: 0.081658247 | E37: 0.051111062 | F37: 0.20102638 | G37: 0.043626277 | H37: 0.066504597 | I37: 0.11418542 | J37: #VALUE! | K37: 0.18103215 | L37: 0.080596034 | M37: 0.056902269 | N37: 0.08163459 | O37: 0.10055915 | P37: #VALUE! | Q37: 0.012835159 | R37: 0.17813825
A39: x | B39: Efficiency | C39: FEDEX CORP | D39: UNITED PARCEL-B | E39: DHL GROUP | F39: OLD DOMINION FRT | G39: XPO INC | H39: HUNT (JB) TRANS | I39: AMAZON.COM INC | J39: FSN E-COMMERCE V | K39: SHOPIFY INC - A | L39: ALIBABA GRP-ADR | M39: JD.COM INC-ADR | N39: AP MOLLER-B | O39: KUEHNE & NAGEL-R | P39: DB SCHENKER | Q39: NIPPON EXPRESS H | R39: EXPEDITORS INTL
B41: Asset turnover | C41: 1.0069746 | D41: 1.2870508 | E41: 1.2437815 | F41: 1.0351611 | G41: 1.0097087 | H41: 1.44853 | I41: 1.0833379 | J41: #N/A N/A | K41: 0.77307291 | L41: 0.55105986 | M41: 1.8624147 | N41: 0.67384716 | O41: 2.2476848 | P41: #N/A Field Not Applicable | Q41: 1.1546841 | R41: 2.3547466
B42: Net operating asset turnover | C42: 1.9666286 | D42: 2.3902887 | E42: 2.0364296 | F42: 1.1151378 | G42: 2.4102717 | H42: 1.9793086 | I42: 1.6973585 | J42: 3.2557345 | K42: 1.2132805 | L42: 0.88326755 | M42: 3.0945494 | N42: 0.87975898 | O42: 3.0147077 | P42: #VALUE! | Q42: 2.0623124 | R42: 3.490225
B43: Fixed asset turnover | C43: 1.5068594 | D43: 2.178658 | E43: 2.7734783 | F43: 1.2716417 | G43: 1.8956089 | H43: 2.0828845 | I43: 1.9852007 | J43: #N/A N/A | K43: 69.783972 | L43: 4.8222919 | M43: 11.726025 | N43: 1.444809 | O43: 8.4907591 | P43: #N/A Field Not Applicable | Q43: 2.7234204 | R43: 11.086395
B44: Revenue per employee thsnd of USD | C44: 370.99578 | D44: 287.62102 | E44: 163.34833 | F44: 257.53012 | G44: 145.6 | H44: 358.55947 | I44: 430.61568 | J44: 495.79457 | K44: 1236.2963 | L44: 1115.3606 | M44: 307.04273 | N44: 315.31417 | O44: 394.80218 | P44: #VALUE! | Q44: 227.67239 | R44: 612.67065
B45: EBIT per employee thsnd of USD | C45: 25.822785 | D45: 30.39172 | E45: 12.321529 | F45: 65.426125 | G45: 12.503636 | H45: 24.766272 | I45: 48.965296 | J45: 13.997782 | K45: 157.40741 | L45: 134.8379 | M45: 8.7002903 | N45: 39.37056 | O45: 24.814208 | P45: #VALUE! | Q45: 5.8825943 | R45: 60.664239
A47: x | B47: Working Capital | C47: FEDEX CORP | D47: UNITED PARCEL-B | E47: DHL GROUP | F47: OLD DOMINION FRT | G47: XPO INC | H47: HUNT (JB) TRANS | I47: AMAZON.COM INC | J47: FSN E-COMMERCE V | K47: SHOPIFY INC - A | L47: ALIBABA GRP-ADR | M47: JD.COM INC-ADR | N47: AP MOLLER-B | O47: KUEHNE & NAGEL-R | P47: DB SCHENKER | Q47: NIPPON EXPRESS H | R47: EXPEDITORS INTL
B49: DSO | C49: 44.532192 | D49: 39.36017 | E49: 46.673607 | F49: 35.87995 | G49: 50.593157 | H49: 36.818005 | I49: 29.285776 | J49: #N/A N/A | K49: 47.966846 | L49: #N/A N/A | M49: 9.1784107 | N49: #N/A N/A | O49: 59.076457 | P49: #N/A Field Not Applicable | Q49: 68.722009 | R49: 62.310972
B50: DIO | C50: 3.2194513 | D50: #N/A N/A | E50: 9.3300538 | F50: #N/A N/A | G50: #N/A N/A | H50: #N/A N/A | I50: 40.501266 | J50: #N/A N/A | K50: #N/A N/A | L50: #N/A N/A | M50: 29.919077 | N50: #N/A N/A | O50: 2.9254407 | P50: #N/A Field Not Applicable | Q50: 1.876783 | R50: #N/A N/A
B51: DPO | C51: 18.221136 | D51: 28.873955 | E51: 67.002928 | F51: 9.6934484 | G51: 32.066589 | H51: #N/A N/A | I51: 95.445363 | J51: #N/A N/A | K51: #N/A N/A | L51: #N/A N/A | M51: 65.638087 | N51: #N/A N/A | O51: 45.803276 | P51: #N/A Field Not Applicable | Q51: 36.25702 | R51: 52.327678
B52: CCC | C52: 29.530507 | D52: #N/A N/A | E52: -16.396649 | F52: #N/A N/A | G52: #N/A N/A | H52: 16.137597 | I52: -31.539636 | J52: 74.810317 | K52: #N/A N/A | L52: #N/A N/A | M52: -29.161868 | N52: -890.84324 | O52: #N/A N/A | P52: #N/A Field Not Applicable | Q52: 34.446161 | R52: #N/A N/A
B53: Working capital intensity | C53: 0.044509019 | D53: 0.046217045 | E53: -0.019373056 | F53: 0.039516659 | G53: 0.0019355644 | H53: 0.0035592401 | I53: 0.014651408 | J53: #N/A N/A | K53: 0.57174955 | L53: 0.20146828 | M53: 0.044808179 | N53: 0.28927773 | O53: -0.035682357 | P53: #N/A Field Not Applicable | Q53: 0.067613133 | R53: 0.13621484
B54: Cash conversion ratio | C54: 1.3486678 | D54: 1.1953236 | E54: 1.293466 | F54: 1.0746665 | G54: 1.2242424 | H54: 1.7843015 | I54: 1.6893415 | J54: 1.7860826 | K54: 1.5032558 | L54: 1.1604201 | M54: 1.4997677 | N54: 2.0185544 | O54: 0.8923821 | P54: #VALUE! | Q54: 4.850049 | R54: 0.69465574
B55: CFO margin | C55: 0.080021837 | D55: 0.11114527 | E55: 0.095704749 | F55: 0.28535464 | G55: 0.10009911 | H55: 0.12270464 | I55: 0.18163706 | J55: 0.046621181 | K55: 0.18198198 | L55: 0.16410849 | M55: 0.050132937 | N55: 0.22549656 | O55: 0.05951133 | P55: #VALUE! | Q55: 0.088400527 | R55: 0.068238288
A57: x | B57: Leverage & Coverage | C57: FEDEX CORP | D57: UNITED PARCEL-B | E57: DHL GROUP | F57: OLD DOMINION FRT | G57: XPO INC | H57: HUNT (JB) TRANS | I57: AMAZON.COM INC | J57: FSN E-COMMERCE V | K57: SHOPIFY INC - A | L57: ALIBABA GRP-ADR | M57: JD.COM INC-ADR | N57: AP MOLLER-B | O57: KUEHNE & NAGEL-R | P57: DB SCHENKER | Q57: NIPPON EXPRESS H | R57: EXPEDITORS INTL
B59: Net debt / EBITDA | C59: 3.3661006 | D59: 1.7423752 | E59: 1.958617 | F59: 0.08165982 | G59: 3.3463497 | H59: 1.0715561 | I59: 0.39786898 | J59: #N/A N/A | K59: -3.6742543 | L59: -3.0196376 | M59: -4.4396569 | N59: -0.15977819 | O59: 1.1363636 | P59: #N/A Field Not Applicable | Q59: 2.7351572 | R59: -0.48451927
B60: Net debt / FCF | C60: 10.705803 | D60: 3.1118622 | E60: 3.8599883 | F60: 0.06713215 | G60: 203.73684 | H60: 3.417904 | I60: 1.4184561 | J60: 4.5332566 | K60: -2.7257358 | L60: -6.9231593 | M60: -4.5983603 | N60: 0.95824308 | O60: 1.0153061 | P60: #VALUE! | Q60: 3.1999577 | R60: -0.84842179
B61: Interest coverage | C61: 6.6121673 | D61: 9.778291 | E61: 7.0384181 | F61: 7283.0094 | G61: 2.9596413 | H61: 10.519172 | I61: 28.509144 | J61: 1.9734665 | K61: #DIV/0! | L61: 14.683722 | M61: 13.375691 | N61: 6.4227979 | O61: 44.702703 | P61: #VALUE! | Q61: 5.1919549 | R61: #DIV/0!
...

Sheet WACC
A7: x | B7: Rolling WACC | K7: Equity Risk Premium
P8: Weights
