Workbook
Name COOLFUCNTION: _xlfn.LAMBDA(_xldudf_BOARDFLARE_EXEC("workbook-settings:coolfucntion"))
Name COOLFUCNTION: _xlfn.LAMBDA(_xldudf_BOARDFLARE_EXEC("workbook-settings:coolfucntion"))
Name COOLFUCNTION: _xlfn.LAMBDA(_xldudf_BOARDFLARE_EXEC("workbook-settings:coolfucntion"))
Name COOLFUCNTION: _xlfn.LAMBDA(_xldudf_BOARDFLARE_EXEC("workbook-settings:coolfucntion"))
Name COOLFUCNTION: _xlfn.LAMBDA(_xldudf_BOARDFLARE_EXEC("workbook-settings:coolfucntion"))
Name COOLFUCNTION: _xlfn.LAMBDA(_xldudf_BOARDFLARE_EXEC("workbook-settings:coolfucntion"))
Name COOLFUCNTION: _xlfn.LAMBDA(_xldudf_BOARDFLARE_EXEC("workbook-settings:coolfucntion"))
Name COOLFUCNTION: _xlfn.LAMBDA(_xldudf_BOARDFLARE_EXEC("workbook-settings:coolfucntion"))
Name COOLFUCNTION: _xlfn.LAMBDA(_xldudf_BOARDFLARE_EXEC("workbook-settings:coolfucntion"))
Name COOLFUCNTION: _xlfn.LAMBDA(_xldudf_BOARDFLARE_EXEC("workbook-settings:coolfucntion"))
Name COOLFUCNTION: _xlfn.LAMBDA(_xldudf_BOARDFLARE_EXEC("workbook-settings:coolfucntion"))
Name Sectors: #REF!
Name Sectors: #REF!
Name Sectors: #REF!
Name Sectors: #REF!
Name Sectors: #REF!
Name Sectors: #REF!
Name Sectors: #REF!
Name Sectors: #REF!

Sheet Dashboard
C154: =+C155+1 -> 45972
C155: =+C156+1 -> 45971
C156: =+C157+1 -> 45970
C157: =+C158+1 -> 45969
C158: =+C159+1 -> 45968
C159: =+C160+1 -> 45967
C160: =+C161+1 -> 45966 | L160: =IF(FCFF!$R$157="Revenue Exit",FCFF!$AF$169,IF(FCFF!$R$157="EBITDA Exit",FCFF!Z169,FCFF!AL169)) -> 2.9943439
C161: =+C162+1 -> 45965
C162: =+C163+1 -> 45964 | E162: =IF(FCFF!$R$157="Revenue Exit",FCFF!$AF$169,IF(FCFF!$R$157="EBITDA Exit",FCFF!Z169,FCFF!AL169)) -> 2.9943439
C163: =+C164+1 -> 45963 | E163: =E164+($E$162-$E$193)/COUNTA($C$162:$C$192) -> 3.0367844
C164: =+C165+1 -> 45962 | E164: =E165+($E$162-$E$193)/COUNTA($C$162:$C$192) -> 3.079225
C165: =+C166+1 -> 45961 | E165: =E166+($E$162-$E$193)/COUNTA($C$162:$C$192) -> 3.1216655
C166: =+C167+1 -> 45960 | E166: =E167+($E$162-$E$193)/COUNTA($C$162:$C$192) -> 3.164106
C167: =+C168+1 -> 45959 | E167: =E168+($E$162-$E$193)/COUNTA($C$162:$C$192) -> 3.2065465
C168: =+C169+1 -> 45958 | E168: =E169+($E$162-$E$193)/COUNTA($C$162:$C$192) -> 3.248987
C169: =+C170+1 -> 45957 | E169: =E170+($E$162-$E$193)/COUNTA($C$162:$C$192) -> 3.2914276
C170: =+C171+1 -> 45956 | E170: =E171+($E$162-$E$193)/COUNTA($C$162:$C$192) -> 3.3338681
C171: =+C172+1 -> 45955 | E171: =E172+($E$162-$E$193)/COUNTA($C$162:$C$192) -> 3.3763086
C172: =+C173+1 -> 45954 | E172: =E173+($E$162-$E$193)/COUNTA($C$162:$C$192) -> 3.4187491
C173: =+C174+1 -> 45953 | E173: =E174+($E$162-$E$193)/COUNTA($C$162:$C$192) -> 3.4611896
C174: =+C175+1 -> 45952 | E174: =E175+($E$162-$E$193)/COUNTA($C$162:$C$192) -> 3.5036301
... C192: =+C193+1 -> 45934 | E192: =E193+($E$162-$E$193)/COUNTA($C$162:$C$192) -> 4.2675595
B193: TODAY | C193: =+'Stock Data'!AM4 -> 45933 | D193: =_xlfn.XLOOKUP(C193,'Stock Data'!$AM$4:$AM$1051,'Stock Data'!$AN$4:$AN$1051) -> 4.31 | E193: =D193 -> 4.31
C194: =+'Stock Data'!AM5 -> 45932 | D194: =_xlfn.XLOOKUP(C194,'Stock Data'!$AM$4:$AM$1051,'Stock Data'!$AN$4:$AN$1051) -> 4.31
C195: =+'Stock Data'!AM6 -> 45931 | D195: =_xlfn.XLOOKUP(C195,'Stock Data'!$AM$4:$AM$1051,'Stock Data'!$AN$4:$AN$1051) -> 4.4
C196: =+'Stock Data'!AM7 -> 45930 | D196: =_xlfn.XLOOKUP(C196,'Stock Data'!$AM$4:$AM$1051,'Stock Data'!$AN$4:$AN$1051) -> 4.4
C197: =+'Stock Data'!AM8 -> 45929 | D197: =_xlfn.XLOOKUP(C197,'Stock Data'!$AM$4:$AM$1051,'Stock Data'!$AN$4:$AN$1051) -> 4.4
C198: =+'Stock Data'!AM9 -> 45928 | D198: =_xlfn.XLOOKUP(C198,'Stock Data'!$AM$4:$AM$1051,'Stock Data'!$AN$4:$AN$1051) -> 4.45
C199: =+'Stock Data'!AM10 -> 45927 | D199: =_xlfn.XLOOKUP(C199,'Stock Data'!$AM$4:$AM$1051,'Stock Data'!$AN$4:$AN$1051) -> 4.38
C200: =+'Stock Data'!AM11 -> 45926 | D200: =_xlfn.XLOOKUP(C200,'Stock Data'!$AM$4:$AM$1051,'Stock Data'!$AN$4:$AN$1051) -> 4.375
C201: =+'Stock Data'!AM12 -> 45925 | D201: =_xlfn.XLOOKUP(C201,'Stock Data'!$AM$4:$AM$1051,'Stock Data'!$AN$4:$AN$1051) -> 4.405
C202: =+'Stock Data'!AM13 -> 45924 | D202: =_xlfn.XLOOKUP(C202,'Stock Data'!$AM$4:$AM$1051,'Stock Data'!$AN$4:$AN$1051) -> 4.51
C203: =+'Stock Data'!AM14 -> 45923 | D203: =_xlfn.XLOOKUP(C203,'Stock Data'!$AM$4:$AM$1051,'Stock Data'!$AN$4:$AN$1051) -> 4.51
C204: =+'Stock Data'!AM15 -> 45922 | D204: =_xlfn.XLOOKUP(C204,'Stock Data'!$AM$4:$AM$1051,'Stock Data'!$AN$4:$AN$1051) -> 4.51
C205: =+'Stock Data'!AM16 -> 45921 | D205: =_xlfn.XLOOKUP(C205,'Stock Data'!$AM$4:$AM$1051,'Stock Data'!$AN$4:$AN$1051) -> 4.585
... C558: =+'Stock Data'!AM369 -> 45568 | D558: =_xlfn.XLOOKUP(C558,'Stock Data'!$AM$4:$AM$1051,'Stock Data'!$AN$4:$AN$1051) -> 5.055

Sheet Key Info
B7: Analysts | F7: LIS – Equity Research | J7: Stock Performance
B12: João Pedro Ferreira, Quantitative Research Head | F12: Recommendation: | H12: Strong Sell
B13: Bsc in Finance, ISEG – Ulisboa | F13: Target Price (FCFF): | H13: =+FCFF!AL169 -> -15.041035
B14: joao@aln.iseg.ulisboa.pt | F14: Downside: | H14: =+FCFF!$AL$171 -> -4.4897992
B15: José Gonçalves, Analyst
B16: Bsc in Management, ISEG – Ulisboa | F16: Ticker | H16: HBRE3
B17: l64272@aln.iseg.ulisboa.pt | F17: Stock Exchange | H17: BRL
B18: João Baiôa, Analyst
B19: Bsc in MAEG, ISEG – Ulisboa | F19: Current Price | H19: ='Stock Data'!AN4 -> 4.31
B20: l61773@aln.iseg.ulisboa.pt | F20: ="Market Cap (in "&IF(Inputs!$D$14="BLN","billions",IF(Inputs!$D$14="MLN","millions","thousands"))&")" -> Market Cap (in thousands) | H20: ='Stock Data'!AQ4 -> 444.7445
F21: Beta | H21: ='Stock Data'!E164 -> 1.475767
F22: % of 52-Week High | H22: ='Stock Data'!E165 -> 0.717687
F23: 100-Day Moving Average | H23: 3.79
B25: Reviewed by: | F25: Avg Vol (1 month) | H25: ='Stock Data'!E168 -> 576723.3
B26: Madalena Silva, Co-Head of Equity Research | F26: Shares Outstanding (millions) | H26: ='Stock Data'!E169 -> 103.189
B27: Bsc in Applied Mathematics in Economic and Management, ISEG – Ulisboa | F27: % Float | H27: ='Stock Data'!E170 -> 0.473
B28: l63835@aln.iseg.ulisboa.pt | F28: Short % of Float | H28: =IFERROR('Stock Data'!E171,0) -> 0
B30: LISBON INVESTMENT SOCIETY | F30: % Held by Insiders | H30: ='Stock Data'!E173 -> 0.034599994
B31: ISEG – Rua do Quelhas, 6 | F31: % Held by Institutions | H31: ='Stock Data'!E174 -> 0.4350661
B32: lis@iseg.ulisboa.pt
B34: Disclaimer: This report was prepared by members of the Lisbon Investment Society (LIS), an independent, student-led, non-profit organization based at ISEG – Lisbon School of Economics & Management, and is intended solely for academic and educational purposes. All analyses, forecasts, and opinions expressed in this report reflect the independent judgment of the authors as of the date of publication and are subject to change without notice. The views presented herein do not represent those of ISEG, its faculty, or any affiliated entity. This document does not constitute, and should not be interpreted as, investment advice, an offer, or a solicitation to buy or sell any security or financial instrument. Nothing in this report should be construed as a recommendation to make or refrain from making any investment decision. The content is intended for informational purposes only, and readers are strongly encouraged to conduct their own research and seek advice from a qualified financial professional before making any financial decisions. The information contained in this report has been obtained from publicly available sources believed to be reliable; however, no representation or warranty is made regarding the accuracy, completeness, or timeliness of such information. LIS and its members accept no liability whatsoever for any direct or indirect loss arising from the use of this report or its contents. This report incorporates terminology, financial metrics, and methodologies commonly used in professional equity research, including but not limited to Discounted Cash Flow (DCF), trading multiples, Monte Carlo simulations, and strategic analysis tools such as Porter’s Five Forces. Definitions and assumptions used in these models are disclosed within the report and reflect a hypothetical investment thesis designed solely for academic discussion. All valuations, projections, and target prices presented herein are based on publicly available data and subject to the limitations of modeling assumptions. These are not guarantees of future performance and should not be relied upon as such, as past performance is not indicative of future results. Any company names, logos, trademarks, or brand references mentioned in this report are the property of their respective owners and are used strictly for identification and academic purposes. This document may not be reproduced, redistributed, or quoted in whole or in part without the prior written consent of the Lisbon Investment Society. About LIS – Lisbon Investment Society: The Lisbon Investment Society (LIS) is a non-profit academic association headquartered at ISEG – Lisbon School of Economics & Management. Founded in 2016, LIS is committed to fostering student interest in finance and investment through applied research, skill development, and institutional engagement. The Society operates independently and autonomously from any political, religious, or commercial affiliation, and is composed of selected students and collaborators who are invited through a rigorous recruitment process and share a commitment to excellence, analytical rigor, and ethical standards. Its activities include equity research, portfolio management, macroeconomic analysis, and investment education. This report was prepared by the Equity Research team at the Lisbon Investment Society, whose analysts combine rigorous financial modeling, critical thinking, and collaborative research to deliver high-quality, student-led investment analysis. We welcome your feedback, discussion, and questions regarding this report or our research process, and invite you to reach out to our team as we are always open to engagement.

Sheet Industry
D6: 584.17 | E6: 627.76 | F6: 676.06 | G6: 729.63 | H6: 789.13 | I6: 855.3 | J6: 929 | K6: 997.69 | L6: 1067.63 | M6: 1137.57
A7: x | B7: Industry Growth Forecast | O7: Industry Index
B9: Brazilian Commercial Real Estate | D9: 2022 | E9: =+D9+1 -> 2023 | F9: =+E9+1 -> 2024 | G9: =+F9+1 -> 2025 | H9: =+G9+1 -> 2026 | I9: =+H9+1 -> 2027 | J9: =+I9+1 -> 2028 | K9: =+J9+1 -> 2029 | M9: ="CAGR "&$G$9&" - "&$K$9 -> CAGR 2025 - 2029
B12: Market Size - Mordor Intelligence | D12: 227.2 | E12: 292.6 | F12: 343.4 | G12: 380.7 | H12: 413.8 | I12: 449.8 | J12: 488.9 | K12: 531.4 | M12: =(K12/G12)^(1/5)-1 -> 0.068975458
B13: Market Share | D13: =+D21/(D12*1000) -> 0.0020484155 | E13: =+E21/(E12*1000) -> 0.0021408066 | F13: =+F21/(F12*1000) -> 0.00089545719 | G13: =+G21/(G12*1000) -> 0.0011688994 | H13: =+H21/(H12*1000) -> 0.00073350787 | I13: =+I21/(I12*1000) -> 0.00075568267 | J13: =+J21/(J12*1000) -> 0.00070464846 | K13: =+K21/(K12*1000) -> 0.00063907476 | M13: =((K13*K12)/(G13*G12))^(1/5)-1 -> -0.052623426
B14: Market Size - Growth Market Reports | D14: 194.7 | E14: 195.9 | F14: 220 | G14: 233.3 | H14: 242.7 | I14: 252.4 | J14: 262.4 | K14: 272.9 | M14: =(K14/G14)^(1/5)-1 -> 0.031852829
B15: Market Share | D15: =+D21/(D16*1000) -> 0.00037065945 | E15: =+E21/(E16*1000) -> 0.00050164171 | F15: =+F21/(F16*1000) -> 0.00022182946 | G15: =+G21/(G16*1000) -> 0.00030624183 | H15: =+H21/(H16*1000) -> 0.00020319022 | I15: =+I21/(I16*1000) -> 0.00022132183 | J15: =+J21/(J16*1000) -> 0.00021700953 | K15: =+K21/(K16*1000) -> 0.00020930929 | M15: =((K15*K14)/(G15*G14))^(1/5)-1 -> -0.043769569
B16: Market Size - IMARC Group | D16: 1255.6 | E16: 1248.7 | F16: 1386.2 | G16: 1453.1 | H16: 1493.8 | I16: 1535.8 | J16: 1587.5 | K16: 1622.5 | M16: =(K16/G16)^(1/5)-1 -> 0.022298775
B17: Market Share | D17: =+D21/(D16*1000) -> 0.00037065945 | E17: =+E21/(E16*1000) -> 0.00050164171 | F17: =+F21/(F16*1000) -> 0.00022182946 | G17: =+G21/(G16*1000) -> 0.00030624183 | H17: =+H21/(H16*1000) -> 0.00020319022 | I17: =+I21/(I16*1000) -> 0.00022132183 | J17: =+J21/(J16*1000) -> 0.00021700953 | K17: =+K21/(K16*1000) -> 0.00020930929 | M17: =((K17*K16)/(G17*G16))^(1/5)-1 -> -0.052623426
B19: Average | D19: =+AVERAGE(D13,D15,D17) -> 0.00092991146 | E19: =+AVERAGE(E13,E15,E17) -> 0.00104803 | F19: =+AVERAGE(F13,F15,F17) -> 0.00044637204 | G19: =+AVERAGE(G13,G15,G17) -> 0.00059379435 | H19: =+AVERAGE(H13,H15,H17) -> 0.00037996277 | I19: =+AVERAGE(I13,I15,I17) -> 0.00039944211 | J19: =+AVERAGE(J13,J15,J17) -> 0.00037955584 | K19: =+AVERAGE(K13,K15,K17) -> 0.00035256445
B20: Median | D20: =+MEDIAN(D17,D15,D13) -> 0.00037065945 | E20: =+MEDIAN(E17,E15,E13) -> 0.00050164171 | F20: =+MEDIAN(F17,F15,F13) -> 0.00022182946 | G20: =+MEDIAN(G17,G15,G13) -> 0.00030624183 | H20: =+MEDIAN(H17,H15,H13) -> 0.00020319022 | I20: =+MEDIAN(I17,I15,I13) -> 0.00022132183 | J20: =+MEDIAN(J17,J15,J13) -> 0.00021700953 | K20: =+MEDIAN(K17,K15,K13) -> 0.00020930929
D21: 465.4 | E21: 626.4 | F21: 307.5 | G21: 445 | H21: 303.52556 | I21: 339.90607 | J21: 344.50263 | K21: 339.60433
A23: x
B25: Industry Driver | D25: Description | O25: Porter's Five Forces
B27: Interest Rate Sensitivity | D27: Its business depends heavily on financing, mortgage credit and investment in construction; Interest rates are a key input for discounting future cash flows; Demand depends on buyers or tenants obtaining loans or financing; High interest rates make fixed-income investments relatively more attractive; If interest rates rise, their capital structure becomes heavier, increasing financial (solvency) risk and limiting their ability to expand.
B28: Economic growth and consumer purchasing power in Brazil | D28: It is forecasted a slower growth in GDP of 1.5-2% (worst in 6 years). Inflation is 5-5.5% (above target), so interest rates are high. This affects mostly low-middle class individuals which make up the biggest proportion of its business (convenience stores and shopping malls). The unemployment rate is the lowest of the last 12 years. The 'trade war' between Brazil and the United States remains intense and aggressive. As a consequence, it's expected to rise inflation, and delay the decrease of interest rates.
B29: Labour and Construction Material Cost | D29: Rising labour and construction-material costs materially worsen project economics for commercial real-estate developers: they raise CAPEX, compress margins, reducing returns and making marginal projects infeasible or likely to be delayed. For highly leveraged firms, coverage ratios deteriorate, and delays mean increase interest costs.
O32: Rivalry Among Existing Competitors | R32: 4.5
O33: Threat of New Entrants | R33: 2
O34: Threat of Substitutes | R34: 3
O35: Bargaining Power of Customers | R35: 2
O36: Bargaining Power of Suppliers | R36: 3.8

Sheet ESG
A7: x | B7: ESG Analysis
B12: ESG Scores | G12: GHG Scope 1 Emissions, Water Consumption, Energy Consumption and Waste Production per Sales
B15: ESG Score
B16: E-Score
B17: S-Score
B18: G-Score
B20: S&P Global ESG Score | D20: 29
B30: Key Info | G30: Environmental
H32: Overview | I32: Targets | J32: Improvements | K32: Comments
B33: GICS Sector | C33: Real Estate | G33: GHG Scope 1 Emissions | I33: Reduce Ethanol Emissions | J33: None | K33: The company released its first GHG inventory in 2024 but set no target for the future, only for ethanol veichles which represent .1% of their total emissions
B34: GICS Industry Group | C34: Real Estate Management and Development
B35: GICS Industry | C35: Real Estate Management and Development | G35: Water Consumption | I35: Transition from Artesian well to municipal | J35: 6% YoY reduction | K35: The 6% decrease is shown but not contextualized
B36: GICS Sub-Industry | C36: Real Estate Operating Companies
G37: Energy Consumption | I37: 100% Renewable sources across all operations by 2026 | J37: Solar initiative launched at ConVem Santana 2024. Ethanol over Gasoline | K37: Clear 2026 Target but massive increase in recent years, no clear efficiency targets,14.5% consumption increase in Suzano Shopping with no clear explanation
B38: Headquarters | C38: Mogi das Cruzes, São Paulo, Brazil
B39: Numer of Employees | G39: Waste Management | I39: 100% Waste diversion goal | J39: Composting and CDRU for non Recyclables introduced | K39: Still 63% to landfill despite the 0% goal with a 22% YoY increase, only 4/48 projects are reported in the data. The recycling rate as been stagnant (13%) from 2023-2024
B41: Annual Report
B42: Sustainability Report
B44: Recent Headlines | G44: Social
B46: since june | H46: Overview | I46: Targets | J46: Improvements | K46: Comments
B47: 30/9 / Sold Building in Sao Paulo for 319.5M | G47: Employee Turnover % | I47: None | J47: First GPTW Climate Survey, 87% participation, 69% favorability | K47: 40% Turnover in for an 80 person company is problematic, under 30 employees have 58% turnover and women have 45% to mens 32%
B48: 23/9 - Asset Recycling May reduce Net Debt by 40% says CEO
B49: 11/9 - HBR Realty announced the sale of 91% of the HBR Corporate Tower for R$477.2mn As HBR Realty holds 66.6% of the asset, the expected proceeds should total ~R$318mn. This sale represents 67.0% of the company's market cap and 16.7% of its EV | G49: Salaries & Compensation | I49: No Clear Target | J49: CEO comp increased 7.5% to average employee 10% increase | K49: Highest paid employee earns 21x average salary
G51: Reputation | I51: No Target | J51: Master Imobiliario and Abrasce 2024 awards | K51: Aqards given for honors in real estate but externally judged, but still strong presence as familly has been involved in real estate for 61 years
G53: Discrimination Events | I53: To maintain | J53: No discrimination cases in 2024 | K53: 0 cases don’t mean 0 occurences, 100% white male board, management 92% white and 58% male
G55: Work Safety | I55: No Target | J55: 0 workplace accidents, zero disceases, 100% covered by health insurance | K55: Doesn-t compare to industry performance, no data on previous year. Construction partners are not covered, likely for mall operations staff among other third parties
G57: Damage to consumer health | I57: No Target | J57: None | K57: No occurances related to consumer health were reported but HBR doesn’t report Indoor air quality, fire safety, food safety among other safety protocols. With 30 million mall visitiors 0 incidents are unlikely
G59: Pension Plan | I59: No Target | J59: None | K59: No private pension plan, or not disclosed, only Governament pension. HBR offers annual life insurance, PPR (profit sharing), gym membership, 95-100% meal vouchers, 40%-80% of scholarships
G61: Supply chain | I61: To have suppliers which provide livable conditions to employees | J61: None | K61: Clauses prohibiting child labor, forced labor, slavery-like conditions, 100% of suppliers going through renewal. Very general approach for supply chain analysis. No environmental data on supply chain partners
G63: Community involvement | I63: Expansion of charitable spaces within its properties and others | J63: Charitable donations to food banks, clothing and hygiene item, creation of autism support spaces | K63: The company is really involved in eachs mall community using its own spaces for the better of the community which demonstrate real activity and not just PR stunts
G65: Public Sector | I65: No Target | J65: None | K65: No comment
G67: Litigation | I67: To maintain no litigation issues | J67: None | K67: The company was involved in 0 corruption-related legal proceedings, but doesn’t mention third parties (construction) related incidents despite having joint liability risk
B70: Board of Directors | G70: Governance
B72: Name | C72: Position | E72: M/F – Age | H72: Overview | I72: Targets | J72: Improvements | K72: Comments
B73: Henrique Borenstein | C73: Chairman / Founder | E73: M - 89 | G73: Diversity (Gender, Age, Industry, Region) | I73: No Target | J73: Get more diversity in all aspects, age, gender and race | K73: All members of the board are middle aged to older white males. In management 92% white and 58% male, workforce 52% males
B74: Henry Borenstein | C74: Vice Chair | E74: M - 52
B75: Mario Mello Freire Neto | C75: Director | E75: M - 59 | G75: % Independence | I75: To move to a more independent board | J75: None | K75: 60% of all board members are independent, besides chair and vice-chair
B76: Jose Luis Acar Pedro | C76: Director | E76: M - 72
B77: Rodolpho Amboss | C77: Director | E77: M - 62 | G77: Average time as independent directors | I77: - | J77: - | K77: =+AVERAGE(5.2, 1.5, 5.2, 5.2, 5.2) -> 4.46
B79: Major Holders | G79: Departures of C-level executives | I79: None | J79: None | K79: CFO and CEO left after 2 and 12 years, respectively
...

Sheet Segments
A7: x | B7: Segments | D7: =F7 -> 2020 | E7: =F7 -> 2020 | F7: 2020 | G7: =F7 -> 2020 | H7: =F7 -> 2020 | J7: =L7 -> 2021 | K7: =L7 -> 2021 | L7: 2021 | M7: =L7 -> 2021 | N7: =L7 -> 2021 | P7: =R7 -> 2022 | Q7: =R7 -> 2022 | R7: 2022 | S7: =R7 -> 2022 | T7: =R7 -> 2022 | V7: =X7 -> 2023 | W7: =X7 -> 2023 | X7: 2023 | Y7: =X7 -> 2023 | Z7: =X7 -> 2023 | AB7: =AD7 -> 2024 | AC7: =AD7 -> 2024 | AD7: 2024 | AE7: =AD7 -> 2024 | AF7: =AD7 -> 2024 | AH7: =AJ7 -> 2025 | AI7: =AJ7 -> 2025 | AJ7: 2025 | AK7: =AJ7 -> 2025 | AL7: =AJ7 -> 2025 | AN7: =AP7 -> 2025 | AO7: =AP7 -> 2025 | AP7: 2025 | AQ7: =AP7 -> 2025 | AR7: =AP7 -> 2025
D8: 2020 | J8: =D8+1 -> 2021 | P8: =J8+1 -> 2022 | V8: =P8+1 -> 2023 | AB8: =V8+1 -> 2024 | AH8: =AB8+1 -> 2025 | AN8: =AH8+1 -> 2026 | AT8: =AN8+1 -> 2027 | AV8: =+AT8+1 -> 2028 | AX8: =+AV8+1 -> 2029 | AZ8: CAGR
D9: Q1 | E9: Q2 | F9: Q3 | G9: Q4 | H9: FY | J9: Q1 | K9: Q2 | L9: Q3 | M9: Q4 | N9: FY | P9: Q1 | Q9: Q2 | R9: Q3 | S9: Q4 | T9: FY | V9: Q1 | W9: Q2 | X9: Q3 | Y9: Q4 | Z9: FY | AB9: Q1 | AC9: Q2 | AD9: Q3 | AE9: Q4 | AF9: FY | AH9: Q1 | AI9: Q2 | AJ9: Q3 | AK9: Q4 | AL9: FY | AN9: Q1 | AO9: Q2 | AP9: Q3 | AQ9: Q4 | AR9: FY | AT9: FY | AV9: FY | AX9: FY | AZ9: 2025-2029
B12: Revenue by segment:
B13: ComVem | H13: =IS!H13 -> 12513 | J13: =IS!J13 -> 0 | K13: =IS!K13 -> 0 | L13: =IS!L13 -> 0 | M13: =IS!M13 -> 0 | N13: =IS!N13 -> 11799 | P13: =IS!P13 -> 3799 | Q13: =IS!Q13 -> 4345 | R13: =IS!R13 -> 4263 | S13: =IS!S13 -> 4845 | T13: =IS!T13 -> 17252 | V13: =IS!V13 -> 5383 | W13: =IS!W13 -> 6445 | X13: =IS!X13 -> 4847 | Y13: =IS!Y13 -> 5228 | Z13: =IS!Z13 -> 21903 | AB13: =IS!AB13 -> 5301 | AC13: =IS!AC13 -> 5429 | AD13: =IS!AD13 -> 6314 | AE13: =IS!AE13 -> 6552 | AF13: =IS!AF13 -> 23596 | AL13: =IS!AL13 -> 34497.742 | AR13: =IS!AR13 -> 43401.727 | AT13: =IS!AT13 -> 53812.75 | AV13: =IS!AV13 -> 62636.8 | AX13: =IS!AX13 -> 71316.84 | AZ13: =+_xlfn.RRI(5, AL13,AX13) -> 0.15632598
B14: HBR 3A | H14: =IS!H14 -> 24451 | J14: =IS!J14 -> 0 | K14: =IS!K14 -> 0 | L14: =IS!L14 -> 0 | M14: =IS!M14 -> 0 | N14: =IS!N14 -> 8417 | P14: =IS!P14 -> 7737 | Q14: =IS!Q14 -> 7647 | R14: =IS!R14 -> 7466 | S14: =IS!S14 -> 7646 | T14: =IS!T14 -> 30496 | V14: =IS!V14 -> 7690 | W14: =IS!W14 -> 7832 | X14: =IS!X14 -> 7788 | Y14: =IS!Y14 -> 7804 | Z14: =IS!Z14 -> 31114 | AB14: =IS!AB14 -> 7785 | AC14: =IS!AC14 -> 7733 | AD14: =IS!AD14 -> 8071 | AE14: =IS!AE14 -> 8466 | AF14: =IS!AF14 -> 32055 | AL14: =IS!AL14 -> 48450.166 | AR14: =IS!AR14 -> 57549.104 | AT14: =IS!AT14 -> 69390.125 | AV14: =IS!AV14 -> 78296 | AX14: =IS!AX14 -> 86599.02 | AZ14: =+_xlfn.RRI(5, AL14,AX14) -> 0.12316495
B15: HBR Malls | H15: =IS!H15 -> 31749 | J15: =IS!J15 -> 0 | K15: =IS!K15 -> 0 | L15: =IS!L15 -> 0 | M15: =IS!M15 -> 0 | N15: =IS!N15 -> 37328 | P15: =IS!P15 -> 15286 | Q15: =IS!Q15 -> 12965 | R15: =IS!R15 -> 13301 | S15: =IS!S15 -> 14842 | T15: =IS!T15 -> 56394 | V15: =IS!V15 -> 12871 | W15: =IS!W15 -> 12671 | X15: =IS!X15 -> 14359 | Y15: =IS!Y15 -> 15805 | Z15: =IS!Z15 -> 55706 | AB15: =IS!AB15 -> 14831 | AC15: =IS!AC15 -> 14262 | AD15: =IS!AD15 -> 14908 | AE15: =IS!AE15 -> 17113 | AF15: =IS!AF15 -> 61114 | AL15: =IS!AL15 -> 88525.716 | AR15: =IS!AR15 -> 86818.453 | AT15: =IS!AT15 -> 92048.125 | AV15: =IS!AV15 -> 100218.88 | AX15: =IS!AX15 -> 106975.26 | AZ15: =+_xlfn.RRI(5, AL15,AX15) -> 0.038586757
B16: HBR Opportunities | H16: =IS!H16 -> 8620 | J16: =IS!J16 -> 0 | K16: =IS!K16 -> 0 | L16: =IS!L16 -> 0 | M16: =IS!M16 -> 0 | N16: =IS!N16 -> 30358 | P16: =IS!P16 -> 9452 | Q16: =IS!Q16 -> 10696 | R16: =IS!R16 -> 10820 | S16: =IS!S16 -> 11947 | T16: =IS!T16 -> 42915 | V16: =IS!V16 -> 11741 | W16: =IS!W16 -> 12755 | X16: =IS!X16 -> 13022 | Y16: =IS!Y16 -> 12095 | Z16: =IS!Z16 -> 49613 | AB16: =IS!AB16 -> 11281 | AC16: =IS!AC16 -> 13239 | AD16: =IS!AD16 -> 13432 | AE16: =IS!AE16 -> 13363 | AF16: =IS!AF16 -> 51315 | AL16: =IS!AL16 -> 71918.279 | AR16: =IS!AR16 -> 65918.918 | AT16: =IS!AT16 -> 65141.75 | AV16: =IS!AV16 -> 68900.48 | AX16: =IS!AX16 -> 71316.84 | AZ16: =+_xlfn.RRI(5, AL16,AX16) -> -0.0016781863
B17: Other & Holding | H17: =IS!H17 -> 0 | J17: =IS!J17 -> 0 | K17: =IS!K17 -> 0 | L17: =IS!L17 -> 0 | M17: =IS!M17 -> 0 | N17: =IS!N17 -> 0 | P17: =IS!P17 -> 1139 | Q17: =IS!Q17 -> 1164 | R17: =IS!R17 -> 1034 | S17: =IS!S17 -> 1046 | T17: =IS!T17 -> 4383 | V17: =IS!V17 -> 1037 | W17: =IS!W17 -> 980 | X17: =IS!X17 -> 995 | Y17: =IS!Y17 -> 997 | Z17: =IS!Z17 -> 4009 | AB17: =IS!AB17 -> 809 | AC17: =IS!AC17 -> 1187 | AD17: =IS!AD17 -> 1001 | AE17: =IS!AE17 -> 1099 | AF17: =IS!AF17 -> 4096 | AL17: =IS!AL17 -> 5113.5516 | AR17: =IS!AR17 -> 5144.5009 | AT17: =IS!AT17 -> 5381.275 | AV17: =IS!AV17 -> 5950.496 | AX17: =IS!AX17 -> 6452.476 | AZ17: =+_xlfn.RRI(5, AL17,AX17) -> 0.047612691
B18: Total revenue | D18: =IS!D18 -> 19810 | E18: =IS!E18 -> 18309 | F18: =IS!F18 -> 20789 | G18: =IS!G18 -> 21861 | H18: =IS!H18 -> 77333 | J18: =IS!J18 -> 19127 | K18: =IS!K18 -> 17498 | L18: =IS!L18 -> 22105 | M18: =IS!M18 -> 47678 | N18: =IS!N18 -> 87902 | P18: =IS!P18 -> 34134 | Q18: =IS!Q18 -> 34302 | R18: =IS!R18 -> 34378 | S18: =IS!S18 -> 38052 | T18: =IS!T18 -> 140866 | V18: =IS!V18 -> 52729 | W18: =IS!W18 -> 39112 | X18: =IS!X18 -> 38430 | Y18: =IS!Y18 -> 23111 | Z18: =IS!Z18 -> 153382 | AB18: =IS!AB18 -> 37691 | AC18: =IS!AC18 -> 39774 | AD18: =IS!AD18 -> 41539 | AE18: =IS!AE18 -> 43978 | AF18: =IS!AF18 -> 162982 | AH18: =IS!AH18 -> 45846 | AI18: =IS!AI18 -> 63997 | AJ18: =IS!AJ18 -> 58154.6 | AK18: =IS!AK18 -> 81089.4 | AL18: =IS!AL18 -> 249087 | AN18: =IS!AN18 -> 64306.262 | AO18: =IS!AO18 -> 64306.262 | AP18: =IS!AP18 -> 65306.262 | AQ18: =IS!AQ18 -> 63306.262 | AR18: =IS!AR18 -> 257225 | AT18: =IS!AT18 -> 283225 | AV18: =IS!AV18 -> 313184 | AX18: =IS!AX18 -> 339604
B20: Notes & Forecasts
C25: Considerable growth, with minimal impact from the partial sale of the Faria Lima "trophy" asset.
B26: HBR 3A | C26: Occupancy rate of 100% in operating projects.
C27: The second segment with the most assets under development with a total of 40.
C30: Slight reduction in share over time, even with occupancy improvements, as other segments grow faster.
B31: HBR Malls | C31: Global shopping center market is expected to grow at a CAGR of 7% until 2029. (Source: Research and Markets- Shopping Centers Market Report 2025)
C32: The two malls Mogi and Patteo Olinda are increasing their occupancy rates to the segment average of 92%.
C35: Consistent growth quarter by quarter, reflecting the expansion of essential projects and revenue increase.
B36: ComVem | C36: The segment includes resilient assets as they are positioned within the essential retail dynamics.
C37: The assets under development are located in prime areas of São Paulo, and revenue is expected to improve.
C38: One of the company’s main future focuses, with 54 assets under development.
C41: Gradual decline, despite strong seasonality in Q3 and Q4:
B42: HBR Opportunities | C42: In the hospitality segment, the 3rd and 4th quarters are typically stronger. Revenue from the W Hotel, the segment’s most notable asset, is expected to increase.
C43: No new project deliveries expected until 2030.

Sheet Peers
B7: Peers
A12: x | B12: Growth | C12: HBR REALTY EMPRE | D12: ALLOS SA | E12: JHSF PART | F12: MULTIPLAN | G12: IGUATEMI SA - UN | H12: WERELDHAVE NV | I12: CTO REALTY GROWT | J12: FOUR CORNERS PRO | K12: SUNWAY REAL ESTA | L12: TERA YATIRIM TEK
B14: Revenue (LTM) | C14: 0.3487 | D14: 0.0444 | E14: 0.164 | F14: 0.0685 | G14: 0.077 | H14: 0.043 | I14: 0.141 | J14: 0.07 | K14: 0.072 | L14: 0.604
B15: Revenue (3-yr CAGR) | C15: 0.2285 | D15: 0.716 | E15: 0.235 | F15: 0.083 | G15: 0.164 | H15: 0.0103 | I15: 0.21 | J15: N/A | K15: N/A | L15: 0.39
B16: Gross profit (LTM) | C16: 0.0745 | D16: 0.0447 | E16: 0.15 | F16: 0.0714 | G16: N/A | H16: 0.095 | I16: N/A | J16: 0.081 | K16: 0.081 | L16: 0.841
B17: EBIT (LTM) | C17: =((IS!AI33+IS!AH33+IS!AE33+IS!AD33)/(IS!AI18+IS!AH18+IS!AE18+IS!AD18))/((IS!AC33+IS!AB33-IS!Y33+IS!X33)/(IS!AC18+IS!AB18+IS!Y18+IS!X18))-1 -> 0.051218417 | D17: 0.0721 | E17: 0.201 | F17: 0.0902 | G17: N/A | H17: 0.422 | I17: 0.1271 | J17: 0.089 | K17: N/A | L17: 0.045
B18: EBITDA (LTM) | C18: 13,55% | D18: 0.082 | E18: 0.187 | F18: 0.0967 | G18: 0.154 | H18: 0.416 | I18: 0.169 | J18: 0.085 | K18: N/A | L18: 0.046
B19: FCF (LTM) | C19: 0.02909853 | D19: 0.125 | E19: 0.35 | F19: 0.0523 | G19: 0.232 | H19: 3.397 | I19: 0.179 | J19: 0.094 | K19: N/A | L19: N/A
A21: x | B21: Margins | C21: HBR REALTY EMPRE | D21: ALLOS SA | E21: JHSF PART | F21: MULTIPLAN | G21: IGUATEMI SA - UN | H21: WERELDHAVE NV | I21: CTO REALTY GROWT | J21: FOUR CORNERS PRO | K21: SUNWAY REAL ESTA | L21: TERA YATIRIM TEK
B23: Gross margin | C23: 68,54% | D23: 0.744 | E23: 0.589 | F23: 0.8335 | G23: N/A | H23: 0.7205 | I23: N/A | J23: 0.8485 | K23: 0.7427 | L23: 0.2886
B24: EBIT margin | C24: 48,2% | D24: 0.72 | E24: 0.72502018 | F24: 0.67180855 | G24: N/A | H24: 0.92166395 | I24: 0.14143223 | J24: 0.55645664 | K24: 0.67485981 | L24: N/A
B25: EBITDA margin | C25: =IS!AF34/IS!AF18 -> 0.58648808 | D25: 0.748 | E25: 0.77848615 | F25: 0.71390297 | G25: 0.775 | H25: 0.72239559 | I25: 0.46156629 | J25: 0.7598 | K25: N/A | L25: 0.28653702
B26: Net margin | C26: 0.2692949 | D26: 0.378 | E26: 0.51233745 | F26: 0.52688612 | G26: 0.376 | H26: 0.7276 | I26: -0.070503297 | J26: 0.37479716 | K26: 0.68403146 | L26: N/A
B27: SG&A margin | C27: =IS!AF27/IS!AF18 -> 0.29067627 | D27: 0.03 | E27: 0.08 | F27: 0.0995 | G27: N/A | H27: 0.0738 | I27: N/A | J27: 0.0887 | K27: N/A | L27: N/A
B29: Returns | C29: HBR REALTY EMPRE | D29: ALLOS SA | E29: JHSF PART | F29: MULTIPLAN | G29: IGUATEMI SA - UN | H29: WERELDHAVE NV | I29: CTO REALTY GROWT | J29: FOUR CORNERS PRO | K29: SUNWAY REAL ESTA | L29: TERA YATIRIM TEK
A30: x
B31: ROIC | C31: 0.055446469 | D31: 0.118 | E31: 0.039 | F31: 0.14442572 | G31: N/A | H31: N/A | I31: N/A | J31: N/A | K31: 0.056177833 | L31: N/A
B32: CROIC | C32: -0,46% | D32: 0.136 | E32: 0.032 | F32: N/A | G32: N/A | H32: N/A | I32: N/A | J32: N/A | K32: N/A | L32: N/A
B33: ROCE | C33: 4,1% | D33: 0.145 | E33: 0.145 | F33: N/A | G33: N/A | H33: 0.08 | I33: N/A | J33: N/A | K33: N/A | L33: 0.3745
B34: RONA | C34: 0.095972888 | D34: 0.092 | E34: 0.092 | F34: N/A | G34: N/A | H34: N/A | I34: N/A | J34: N/A | K34: N/A | L34: N/A
B35: ROE | C35: 0.04 | D35: 0.094 | E35: 0.19 | F35: 0.19747396 | G35: 0.2 | H35: 0.1166 | I35: -0.0164 | J35: 0.0742 | K35: 0.0977 | L35: 0.2381
B36: ROA | C36: 2,3% | D36: 0.057 | E36: 0.074 | F36: 0.10749069 | G36: N/A | H36: 0.0603 | I36: -0.0018 | J36: 0.0394 | K36: 0.0486 | L36: 0.1838
B38: Efficiency | C38: HBR REALTY EMPRE | D38: ALLOS SA | E38: JHSF PART | F38: MULTIPLAN | G38: IGUATEMI SA - UN | H38: WERELDHAVE NV | I38: CTO REALTY GROWT | J38: FOUR CORNERS PRO | K38: SUNWAY REAL ESTA | L38: TERA YATIRIM TEK
A39: x
B40: Asset turnover | C40: 0,077 | D40: 0.14 | E40: 0.12 | F40: 0.22500014 | G40: N/A | H40: 0.08336662 | I40: 0.11 | J40: 0.10642623 | K40: 0.079963514 | L40: 0.0145
B41: Net operating asset turnover | C41: 0,079 | D41: 0.16 | E41: 0.13 | F41: N/A | G41: N/A | H41: N/A | I41: N/A | J41: N/A | K41: N/A | L41: N/A
B42: Fixed asset turnover | C42: 0,087 | D42: 0.16 | E42: 0.1 | F42: 0.29 | G42: N/A | H42: 0.09 | I42: 0.15 | J42: 0.11 | K42: N/A | L42: 0.018
B44: Working Capital | C44: HBR REALTY EMPRE | D44: ALLOS SA | E44: JHSF PART | F44: MULTIPLAN | G44: IGUATEMI SA - UN | H44: WERELDHAVE NV | I44: CTO REALTY GROWT | J44: FOUR CORNERS PRO | K44: SUNWAY REAL ESTA | L44: TERA YATIRIM TEK
B46: DSO | C46: 25 | D46: 23 | E46: 25 | F46: 107 | G46: N/A | H46: N/A | I46: N/A | J46: N/A | K46: N/A | L46: 235
A47: x | B47: DIO | C47: 0 | D47: 0 | E47: 0 | F47: N/A | G47: N/A | H47: N/A | I47: N/A | J47: N/A | K47: N/A | L47: N/A
B48: DPO | C48: 45 | D48: 47 | E48: 50 | F48: N/A | G48: N/A | H48: N/A | I48: N/A | J48: N/A | K48: N/A | L48: 1672
B49: CCC | C49: 20 | D49: N/A | E49: N/A | F49: N/A | G49: N/A | H49: N/A | I49: N/A | J49: N/A | K49: N/A | L49: -1104.5403
B50: Working capital intensity | C50: 0.068 | D50: 0.075 | E50: N/A | F50: N/A | G50: N/A | H50: N/A | I50: N/A | J50: N/A | K50: N/A | L50: -1.63
B51: Cash conversion ratio | C51: 0.927 | D51: 0.923 | E51: 0.27292975 | F51: N/A | G51: N/A | H51: N/A | I51: N/A | J51: N/A | K51: N/A | L51: 0.26
B52: CFO margin | C52: 0.447 | D52: 0.66 | E52: 0.19787958 | F52: 0.538447 | G52: 0.525 | H52: 0.48071268 | I52: N/A | J52: N/A | K52: N/A | L52: 5.86
B54: Leverage & Coverage | C54: HBR REALTY EMPRE | D54: ALLOS SA | E54: JHSF PART | F54: MULTIPLAN | G54: IGUATEMI SA - UN | H54: WERELDHAVE NV | I54: CTO REALTY GROWT | J54: FOUR CORNERS PRO | K54: SUNWAY REAL ESTA | L54: TERA YATIRIM TEK
B56: Net debt / EBITDA | C56: 5.467815 | D56: 3.45 | E56: 1.86 | F56: 2.31 | G56: 1.84 | H56: 5.25 | I56: 6.07 | J56: 5.2620324 | K56: 8.09 | L56: 0.29
A57: x | B57: Net debt / FCF | C57: 9.1 | D57: 5.17 | E57: 7.6 | F57: 6.25 | G57: 2.71 | H57: 17.597718 | I57: 9.87 | J57: 7.01 | K57: N/A | L57: 8.26
B58: Interest coverage | C58: 0.5 | D58: 3 | E58: 3 | F58: 4.6 | G58: N/A | H58: 4.1 | I58: 2.8 | J58: 4.5 | K58: 3.1071847 | L58: 11.2
B59: Debt / capital | C59: 0.57 | D59: 0.394 | E59: 0.39 | F59: 0.49191878 | G59: N/A | H59: 0.42980635 | I59: 0.0046 | J59: 0.33 | K59: 0.43203985 | L59: 0.11030314
...

Sheet Trading Comps
B7: ="in "&IF(Inputs!$R$18="k","thousands",IF(Inputs!$R$18="MLN","millions","billions")&" of "&Inputs!$R$17) -> in thousands | D7: Current | E7: % of | I7: Enterprise Value / | S7: LTM | T7: Net | V7: Price / | Z7: LT
D8: Share | E8: 52-week | F8: Equity | G8: Enterprise | I8: LTM | J8: 2025 | K8: 2026 | L8: LTM | M8: 2025E | N8: 2026E | O8: LTM | P8: 2025E | Q8: 2026E | S8: EBITDA | T8: Debt / | V8: LTM | W8: 2025E | X8: 2026E | Z8: EPS
B9: Company | C9: Ticker | D9: Price | E9: High | F9: Value | G9: Value | I9: Sales | J9: Sales | K9: Sales | L9: EBITDA | M9: EBITDA | N9: EBITDA | O9: EBIT | P9: EBIT | Q9: EBIT | S9: Margin | T9: EBITDA | V9: EPS | W9: EPS | X9: EPS | Z9: Growth
B14: HBR REALTY EMPRE | C14: HBRE3 BZ | D14: BRL 4.78 | E14: 0.87067395 | F14: 4.9014766e+08 | G14: 3.04 B | I14: 14.42 | J14: 5.9 | K14: 7.35 | L14: 30.2 | M14: 12.31 | N14: 15.48 | O14: =+Inputs!J18/SUM(IS!AH34:AI34,IS!AD34:AE34) -> 30.19932 | P14: =+Inputs!J18/FCFF!Z61 -> 28.560331 | Q14: =+Inputs!J18/FCFF!AF61 -> 26.88288 | S14: 0.49275452 | T14: =+FCFF!Z164/(FCFF!Z128+FCFF!Z122) -> 14.857587 | V14: =4.64/0.21 -> 22.095238 | W14: -32 | X14: -15 | Z14: =+AVERAGE(W15:X15) -> -1.4897629
W15: =+W14/V14-1 -> -2.4482759 | X15: =+X14/W14-1 -> -0.53125
B16: Tier I: Real Estate Operating Companies
B19: =+Inputs!B21 -> ALLOS SA | C19: ALOS3 BZ | D19: BRL 24.4 | E19: 0.98307816 | F19: 13247661 | G19: 17958489 | I19: 6.1609046 | J19: 6.3937654 | K19: 6.0977863 | L19: 9.2889904 | M19: 8.6004343 | N19: 8.2636844 | O19: 13.577432 | P19: 11.861617 | Q19: 11.511852 | S19: 0.66324804 | T19: 2.9370158 | V19: 22.777528 | W19: 16.909291 | X19: 16.195844 | Z19: 0.14099033
B20: =+Inputs!B22 -> JHSF PART | C20: JHSF3 BZ | D20: BRL 5.51 | E20: 0.95826087 | F20: 3754088.4 | G20: 7874342.7 | I20: 3.5189841 | J20: 3.7134368 | K20: 3.3365859 | L20: 8.738405 | M20: 9.0770522 | N20: 8.076249 | O20: 9.4580678 | P20: 10.669841 | Q20: 9.7094238 | S20: 0.40270325 | T20: 3.2069134 | V20: 12.430592 | W20: 6.7337908 | X20: 7.5081768
B21: =+Inputs!B23 -> LOG COMMERCIAL P | C21: LOGG3 BZ | D21: BRL 21.77 | E21: 0.91701769 | F21: 1912693.8 | G21: 3850355.1 | I21: 16.792292 | J21: 15.667772 | K21: 13.052051 | L21: -11.140912 | M21: 14.584678 | N21: 16.961917 | O21: -10.937173 | P21: 13.353833 | Q21: 17.448739 | S21: -1.5072636 | T21: 4.7939948 | V21: -3.752985 | W21: 7.3096578 | X21: 8.9896308 | Z21: -0.16929348
B22: =+Inputs!B24 -> MULTIPLAN | C22: MULT3 BZ | D22: BRL 28.4 | E22: 0.98611111 | F22: 14573849 | G22: 18280671 | I22: 6.7676311 | J22: 7.5756484 | K22: 7.2420207 | L22: 9.4797631 | M22: 10.12032 | N22: 9.3714991 | O22: 10.23563 | P22: 11.071874 | Q22: 10.25642 | S22: 0.71390297 | T22: 2.6573663 | V22: 11.293557 | W22: 14.510968 | X22: 13.179065 | Z22: 0.13662818
B23: =+Inputs!B25 -> IGUATEMI SA - UN | C23: IGTI11 BZ | D23: BRL 23.75 | E23: 0.98547718 | F23: 6772056.6 | G23: 5795567.8 | I23: 4.2476794 | J23: 3.7592872 | K23: 3.5032648 | L23: 6.2618096 | M23: 5.2306568 | N23: 4.8451173 | O23: 7.5130903 | P23: 5.6377118 | Q23: 5.632233 | S23: 0.67834695 | T23: 3.4942432 | V23: 17.070442 | W23: 12.64033 | X23: 11.870388 | Z23: 0.091667043
B25: Mean | I25: =AVERAGE(I19:I23) -> 7.4974983 | J25: =AVERAGE(J19:J23) -> 7.421982 | K25: =AVERAGE(K19:K23) -> 6.6463418 | L25: =AVERAGE(L19:L23) -> 4.5256111 | M25: =AVERAGE(M19:M23) -> 9.5226282 | N25: =AVERAGE(N19:N23) -> 9.5036932 | O25: =AVERAGE(O19:O23) -> 5.9694094 | P25: =AVERAGE(P19:P23) -> 10.518975 | Q25: =AVERAGE(Q19:Q23) -> 10.911734 | S25: =AVERAGE(S19:S23) -> 0.19018752 | T25: =AVERAGE(T19:T23) -> 3.4179067 | V25: =AVERAGE(V19:V23) -> 11.963826 | W25: =AVERAGE(W19:W23) -> 11.620807 | X25: =AVERAGE(X19:X23) -> 11.548621 | Z25: =AVERAGE(Z19:Z23) -> 0.049998017
B26: Median | I26: =MEDIAN(I19:I23) -> 6.1609046 | J26: =MEDIAN(J19:J23) -> 6.3937654 | K26: =MEDIAN(K19:K23) -> 6.0977863 | L26: =MEDIAN(L19:L23) -> 8.738405 | M26: =MEDIAN(M19:M23) -> 9.0770522 | N26: =MEDIAN(N19:N23) -> 8.2636844 | O26: =MEDIAN(O19:O23) -> 9.4580678 | P26: =MEDIAN(P19:P23) -> 11.071874 | Q26: =MEDIAN(Q19:Q23) -> 10.25642 | S26: =MEDIAN(S19:S23) -> 0.66324804 | T26: =MEDIAN(T19:T23) -> 3.2069134 | V26: =MEDIAN(V19:V23) -> 12.430592 | W26: =MEDIAN(W19:W23) -> 12.64033 | X26: =MEDIAN(X19:X23) -> 11.870388 | Z26: =MEDIAN(Z19:Z23) -> 0.11414761
B28: Tier II: Real Estate Management and Development
B31: =+Inputs!H21 -> PTA LOG IMO RESP | C31: No Data Avaliable
B32: =+Inputs!H22 -> KINEA-RENDA IMOB
B33: =+Inputs!H23 -> XP LOG FII
B34: =+Inputs!H24 -> FII REC REND
B35: =+Inputs!H25 -> FII BTG PACTUAL
B37: Mean
B38: Median
B40: Tier III: Real Estate
B41: dddddd
B43: WERELDHAVE NV | C43: WHA NA | D43: EUR 18.84 | E43: 0.98022893 | F43: 877824.94 | G43: 2078457.4 | I43: 10.214001 | J43: 11.33704 | K43: 11.016558 | L43: 15.629614 | M43: 11.775962 | N43: 11.676727 | O43: 15.775887 | P43: 11.775962 | Q43: 11.676727 | S43: 0.6535031 | T43: 7.3687662 | V43: 12.088082 | W43: 12.277272 | X43: 11.975784 | Z43: #N/A
B44: CTO REALTY GROWT | C44: CTO US | D44: USD 16.53 | E44: 0.79166667 | F44: 544491.75 | G44: 1283363.9 | I44: 9.10213 | J44: 8.5700429 | K44: 7.9097931 | L44: 14.92301 | M44: 15.027681 | N44: 12.340038 | O44: 93.18646 | P44: 69.296108 | Q44: 34.437315 | S44: 0.60993929 | T44: 9.306151 | V44: -36.450111 | W44: -21.18645 | X44: 128.19413 | Z44: #N/A
B45: FOUR CORNERS PRO | C45: FCPT US | D45: USD 25.45 | E45: 0.82282574 | F45: 2658616.7 | G45: 3955699.4 | I45: 14.155556 | J45: 14.48311 | K45: 13.324461 | L45: 17.309398 | M45: 17.580886 | N45: 15.835466 | O45: 25.407537 | P45: 23.973936 | Q45: 21.576542 | S45: 0.81779599 | T45: 5.2882041 | V45: 25.119918 | W45: 23.398167 | X45: 20.954615 | Z45: 0.063048107
B46: SUNWAY REAL ESTA | C46: SREIT MK | D46: MYR 2.06 | E46: 0.88793103 | F46: 7055103.9 | G46: 11327202 | I46: 13.432776 | J46: 13.323508 | K46: 13.243424 | L46: #N/A | M46: 19.690921 | N46: 19.001388 | O46: 19.963697 | P46: 19.358012 | Q46: 18.856222 | S46: #N/A | T46: #N/A N/A | V46: 16.831208 | W46: 17.716853 | X46: 17.091444 | Z46: 0.030941096
B47: TERA YATIRIM TEK | C47: TEHOL TI | D47: TRY 33.2 | E47: 0.97704532 | F47: 33669821 | G47: #N/A N/A | I47: #VALUE! | J47: #VALUE! | K47: #VALUE! | L47: #VALUE! | M47: #VALUE! | N47: #VALUE! | O47: #VALUE! | P47: #VALUE! | Q47: #VALUE! | S47: -26.401705 | T47: #N/A N/A | V47: -121.76453 | W47: #N/A | X47: #N/A | Z47: #N/A
B49: Mean | I49: =+AVERAGE(I43:I46) -> 11.726116 | J49: =+AVERAGE(J43:J46) -> 11.928425 | K49: =+AVERAGE(K43:K46) -> 11.373559 | L49: =+AVERAGE(L43:L45) -> 15.954007 | M49: =+AVERAGE(M43:M46) -> 16.018862 | N49: =+AVERAGE(N43:N46) -> 14.713405 | O49: =+AVERAGE(O43:O46) -> 38.583395 | P49: =+AVERAGE(P43:P46) -> 31.101004 | Q49: =+AVERAGE(Q43:Q46) -> 21.636701 | S49: =+AVERAGE(S43:S45) -> 0.69374613 | T49: =+AVERAGE(T43:T45) -> 7.3210404 | V49: =AVERAGE(V43:V47) -> -20.835086 | W49: =+AVERAGE(W43:W46) -> 8.0514606 | X49: =+AVERAGE(X43:X46) -> 44.553993 | Z49: =AVERAGE(Z43:Z47) -> #N/A
B50: Median | I50: =+MEDIAN(I43:I46) -> 11.823389 | J50: =+MEDIAN(J43:J46) -> 12.330274 | K50: =+MEDIAN(K43:K46) -> 12.129991 | L50: =+MEDIAN(L43:L45) -> 15.629614 | M50: =+MEDIAN(M43:M46) -> 16.304283 | N50: =+MEDIAN(N43:N46) -> 14.087752 | O50: =+MEDIAN(O43:O46) -> 22.685617 | P50: =+MEDIAN(P43:P46) -> 21.665974 | Q50: =+MEDIAN(Q43:Q46) -> 20.216382 | S50: =+MEDIAN(S43:S45) -> 0.6535031 | T50: =MEDIAN(T43:T47) -> 7.3687662 | V50: =MEDIAN(V43:V47) -> 12.088082 | W50: =+MEDIAN(W43:W46) -> 14.997062 | X50: =+MEDIAN(X43:X46) -> 19.023029 | Z50: =MEDIAN(Z43:Z47) -> #N/A
B52: Overall
B55: Mean | I55: =+AVERAGE(I43:I46,I19:I23) -> 9.3768839 | J55: =+AVERAGE(J43:J46,J19:J23) -> 9.4248457 | K55: =+AVERAGE(K43:K46,K19:K23) -> 8.7473272 | L55: =+AVERAGE(L43:L45,L19:L23) -> 8.8112597 | M55: =+AVERAGE(M43:M46,M19:M23) -> 12.409843 | N55: =+AVERAGE(N43:N46,N19:N23) -> 11.81912 | O55: =+AVERAGE(O43:O46,O19:O23) -> 20.464514 | P55: =+AVERAGE(P43:P46,P19:P23) -> 19.666544 | Q55: =+AVERAGE(Q43:Q46,Q19:Q23) -> 15.678386 | S55: =+AVERAGE(S43:S45,S19:S23) -> 0.37902199 | T55: =+AVERAGE(T19:T23,T43:T45) -> 4.8815819 | V55: =+AVERAGE(V43:V47,V35,V19:V23) -> -4.4356297 | W55: =+AVERAGE(W43:W46,W19:W23) -> 10.034431 | X55: =+AVERAGE(X43:X46,X19:X23) -> 26.217675 | Z55: =+AVERAGE(Z19,Z21,Z22,Z45,Z46) -> 0.040462845
B56: Median | I56: =+MEDIAN(I43:I46,I19:I23) -> 9.10213 | J56: =+MEDIAN(J43:J46,J19:J23) -> 8.5700429 | K56: =+MEDIAN(K43:K46,K19:K23) -> 7.9097931 | L56: =+MEDIAN(L43:L45,L19:L23) -> 9.3843767 | M56: =+MEDIAN(M43:M46,M19:M23) -> 11.775962 | N56: =+MEDIAN(N43:N46,N19:N23) -> 11.676727 | O56: =+MEDIAN(O43:O46,O19:O23) -> 13.577432 | P56: =+MEDIAN(P43:P46,P19:P23) -> 11.861617 | Q56: =+MEDIAN(Q43:Q46,Q19:Q23) -> 11.676727 | R56: =+MEDIAN(R43:R46,R19:R23) -> #NUM! | S56: =+MEDIAN(S43:S45,S19:S23) -> 0.65837557 | T56: =+MEDIAN(T43:T45,T19:T23) -> 4.144119 | V56: =+MEDIAN(V43:V47,V19:V23) -> 12.259337 | W56: =+MEDIAN(W43:W46,W19:W23) -> 12.64033 | X56: =+MEDIAN(X43:X46,X19:X23) -> 13.179065 | Z56: =+MEDIAN(Z46,Z45,Z23,Z22,Z21,Z19) -> 0.077357575
B58: High | I58: =+MAX(I19:I23,I43:I46) -> 16.792292 | J58: =+MAX(J19:J23,J43:J46) -> 15.667772 | K58: =+MAX(K19:K23,K43:K46) -> 13.324461 | L58: =+MAX(L19:L23,L43:L45) -> 17.309398 | M58: =+MAX(M19:M23,M43:M46) -> 19.690921 | N58: =+MAX(N19:N23,N43:N46) -> 19.001388 | O58: =+MAX(O19:O23,O43:O46) -> 93.18646 | P58: =+MAX(P19:P23,P43:P46) -> 69.296108 | Q58: =+MAX(Q19:Q23,Q43:Q46) -> 34.437315 | S58: =+MAX(S43:S45,S19:S23) -> 0.81779599 | T58: =MAX(T43:T47,T31:T35,T19:T23) -> 9.306151 | V58: =+MAX(V43:V47,V35,V19:V23) -> 25.119918 | W58: =+MAX(W43:W46,W19:W23) -> 23.398167 | X58: =+MAX(X43:X46,X19:X23) -> 128.19413 | Z58: =MAX(Z43:Z47,Z31:Z35,Z19:Z23) -> #N/A
B59: Low | I59: =+MIN(I43:I46,I19:I23) -> 3.5189841 | J59: =+MIN(J43:J46,J19:J23) -> 3.7134368 | K59: =+MIN(K43:K46,K19:K23) -> 3.3365859 | L59: =+MIN(L43:L45,L19:L23) -> -11.140912 | M59: =+MIN(M43:M46,M19:M23) -> 5.2306568 | N59: =+MIN(N43:N46,N19:N23) -> 4.8451173 | O59: =+MIN(O43:O46,O19:O23) -> -10.937173 | P59: =+MIN(P43:P46,P19:P23) -> 5.6377118 | Q59: =+MIN(Q43:Q46,Q19:Q23) -> 5.632233 | S59: =+MIN(S43:S45,S19:S23) -> -1.5072636 | T59: =+MIN(T43:T45,T19:T23) -> 2.6573663 | V59: =+MIN(V43:V47,V19:V23,V35) -> -121.76453 | W59: =+MIN(W43:W46,W19:W23) -> -21.18645 | X59: =+MIN(X43:X46,X19:X23) -> 7.5081768 | Z59: =MIN(Z43:Z47,Z31:Z35,Z19:Z23) -> #N/A
C61: Price/Book | F61: NAV
B62: HBR REALTY EMPRE | C62: 0.24 | F62: =3397-1433-76.519-(705/2)+(319.5*0.7) -> 1758.631
B63: ALLOS | C63: 0.94
B64: JHSF | C64: 0.71
B65: LOG COM | C65: 0.53 | D65: jscs
...

Sheet Assumptions
B3: Revenue
B6: Main Driver
B7: Gross Leasable Area (GLA)
J8: Forecast
C9: 2020 | D9: =+C9+1 -> 2021 | E9: 2022 | F9: =+E9+1 -> 2023 | G9: =+F9+1 -> 2024 | H9: 2025 | I9: Average | J9: 2026 | K9: =+J9+1 -> 2027 | L9: =+K9+1 -> 2028 | M9: =+L9+1 -> 2029 | N9: CAGR
B10: Total Revenue | C10: 77333 | D10: 105657 | E10: 140866 | F10: 153382 | G10: 176925 | H10: =+FCFF!Z31 -> 249087 | J10: =+J12*($I$22*(1+$I$23))/1000 -> 306468.31 | K10: =+K12*($I$22*(1+$I$23))/1000 -> 347931.27 | L10: =+L12*($I$22*(1+$I$23))/1000 -> 384532.92 | M10: =+M12*($I$22*(1+$I$23))/1000 -> 416843.22 | N10: =+_xlfn.RRI(COUNT(J9:M9), J10,M10) -> 0.079932954
B11: growth % | D11: =+D10/C10-1 -> 0.3662602 | E11: =+E10/D10-1 -> 0.33323869 | F11: =+F10/E10-1 -> 0.088850397 | G11: =+G10/F10-1 -> 0.15349259 | H11: =+H10/G10-1 -> 0.40786774
B12: Total GLA | C12: 209822 | D12: 225228 | E12: 224479 | F12: 227138 | G12: 240674 | H12: 265268 | J12: =+H12+H20*B35 -> 313282.25 | K12: =+J12+J20*$B$35 -> 355667.09 | L12: =+K12+K20*$B$35 -> 393082.53 | M12: =+L12+L20*$B$35 -> 426111.22
B13: GLA Owned | C13: 138511 | D13: 147176 | E13: 148983 | F13: 152367 | G13: 161435 | H13: 176620
B14: % Total GLA | C14: 0.61 | D14: 0.66 | E14: 0.67 | F14: 0.66 | G14: 0.67 | H14: 0.68 | I14: =+AVERAGE(C14:H14) -> 0.65833333
B15: growth % | D15: =+D12/C12-1 -> 0.07342414 | E15: =+E12/D12-1 -> -0.003325519 | F15: =+F12/E12-1 -> 0.011845206 | G15: =+G12/F12-1 -> 0.059593727 | H15: =+H12/G12-1 -> 0.10218802
B17: Revenue Lease | C17: =+C14*C10 -> 47173.13 | D17: =+D14*D10 -> 69733.62 | E17: =+E14*E10 -> 94380.22 | F17: =+F14*F10 -> 101232.12 | G17: =+G14*G10 -> 118539.75 | H17: =+H14*H10 -> 169379.16
B18: Revenue Sale | C18: =+C10-C17 -> 30159.87 | D18: =+D10-D17 -> 35923.38 | E18: =+E10-E17 -> 46485.78 | F18: =+F10-F17 -> 52149.88 | G18: =+G10-G17 -> 58385.25 | H18: =+H10-H17 -> 79707.84
B20: Asset under Development | C20: 274376 | D20: 295187 | E20: 223124 | F20: 198440 | G20: 172116 | H20: 142054 | J20: =+H20*(1+I21) -> 125398.93 | K20: =+J20*(1+$I$21) -> 110696.58 | L20: =+K20*(1+$I$21) -> 97717.998 | M20: =+L20*(1+$I$21) -> 86261.087
D21: =+D20/C20-1 -> 0.075848471 | E21: =+E20/D20-1 -> -0.2441266 | F21: =+F20/E20-1 -> -0.11062907 | G21: =+G20/F20-1 -> -0.13265471 | H21: =+H20/G20-1 -> -0.17466127 | I21: =+AVERAGE(C21:H21) -> -0.11724464
B22: Revenue Per Square Meter (RSM) | C22: =+C10*1000/C12 -> 368.56478 | D22: =+D10*1000/D12 -> 469.1113 | E22: =+E10*1000/E12 -> 627.52418 | F22: =+F10*1000/F12 -> 675.28111 | G22: =+G10*1000/G12 -> 735.12303 | H22: =+H10*1000/H12 -> 939.00131 | I22: =+AVERAGE(G22:H22) -> 837.06217
B23: growth % | D23: =+D22/C22-1 -> 0.27280555 | E23: =+E22/D22-1 -> 0.33768719 | F23: =+F22/E22-1 -> 0.076103727 | G23: =+G22/F22-1 -> 0.088617795 | H23: =+H22/G22-1 -> 0.277339 | I23: =+_xlfn.RRI(COUNT(C22:H22), C22,H22) -> 0.16867044
B26: R*2 Between Revenue & GLA | C26: =+CORREL(C10:H10,C12:H12) -> 0.96834789
B27: Year 1 | C27: Projected GLA * RSM
B28: Year 2 | C28: (Projected GLA + Development) * RSM*(1+RSM Growth Rate)
B29: Year n | C29: Etc
B33: On Average HBR finished 5.5% of Under Development Assets
B34: =6.5%*4 -> 0.26 | C34: multiply by 4 quarters
B35: =+B34*(1+30%) -> 0.338 | C35: Apply 30% expected growth construction sector
B36: 34% Expected Under Development Assets Build Rate
C39: 2026 | D39: =+C39+1 -> 2027 | E39: =+D39+1 -> 2028 | F39: =+E39+1 -> 2029
B40: Revenue | C40: =+J10 -> 306468.31 | D40: =+K10 -> 347931.27 | E40: =+L10 -> 384532.92 | F40: =+M10 -> 416843.22
B41: Revenue Applied | C41: =+C40*0.99 -> 303403.62 | D41: =+FCFF!AH31 -> 349576.11 | E41: =+E40*0.96 -> 369151.6 | F41: =+F40*0.96 -> 400169.49
B43: Revenue will decrease x%, by the sensitivity analysis with a selic rate y% and -4% spread
B44: First graphshown, others arent relevant
B46: Other Calculations
B48: Debt
C50: 2022 | D50: =+C50+1 -> 2023 | E50: =+D50+1 -> 2024 | F50: 2025 | G50: =+F50+1 -> 2026 | H50: =+G50+1 -> 2027 | I50: =+H50+1 -> 2028 | J50: =+I50+1 -> 2029
B51: EBIT | C51: 84728 | D51: 19586 | E51: 93922 | F51: =+FCFF!Z61 -> 106547.59 | G51: =+FCFF!AF61 -> 113196 | H51: =+FCFF!AH61 -> 147035.96 | I51: =+FCFF!AJ61 -> 155870.63 | J51: =+FCFF!AL122 -> 169854.3
B52: DA | C52: 915 | D52: 1977 | E52: 1119 | F52: =+FCFF!Z49 -> 6918.4059 | G52: =+FCFF!AF49 -> 8165.4487 | H52: =+FCFF!AH49 -> 10273.293 | I52: 9495 | J52: 10231
B53: EBITDA | D53: =+D52+D51 -> 21563 | E53: =+E52+E51 -> 95041 | F53: =+F52+F51 -> 113466 | G53: =+G52+G51 -> 121361.45 | H53: =+H52+H51 -> 157309.25 | I53: =+I52+I51 -> 165365.63 | J53: =+J52+J51 -> 180085.3
B54: DEBT | C54: =+BS!T38+BS!V44 -> 1269184 | D54: =+BS!Z38+BS!Z44 -> 1339215 | E54: =+BS!AF38+BS!AF44 -> 1568184 | F54: =+BS!AI38+BS!AI44 -> 1709387 | G54: =+$F$55*G53 -> 1828333.5 | H54: =+$F$55*H53 -> 2369894 | I54: =+$F$55*I53 -> 2491264.8 | J54: =+$F$55*J53 -> 2713019.5
B55: ratio | C55: =+C54/C53 -> #DIV/0! | D55: =+D54/D53 -> 62.107082 | E55: =+E54/E53 -> 16.500079 | F55: =+F54/F53 -> 15.065191
B56: Predicted Debt | G56: =+G54/1000 -> 1828.3335 | H56: =+H54/1000 -> 2369.894 | I56: =+I54/1000 -> 2491.2648 | J56: =+J54/1000 -> 2713.0195
B59: ESG
...

Sheet WACC
A7: x | B7: Rolling WACC | K7: Equity Risk Premium
P8: Weights
D9: 2025 | E9: =+D9+1 -> 2026 | F9: =+E9+1 -> 2027 | G9: =+F9+1 -> 2028 | H9: =+G9+1 -> 2029 | M9: ERP | N9: 2025 | O9: =+N9+1 -> 2026 | P9: =+O9+1 -> 2027 | Q9: =+P9+1 -> 2028 | R9: =+Q9+1 -> 2029
B12: Equity: | K12: Brazil | M12: 0.0767 | N12: 1 | O12: 1 | P12: 1 | Q12: 1 | R12: 1
B13: Market Cap (in billions) | D13: =+Inputs!J13/1000 -> 444.7445 | E13: =+FCFF!AF99*FCFF!AF31/1000 -> 358.01628 | F13: =+FCFF!AH99*FCFF!AH31/1000 -> 454.44894 | G13: =+FCFF!AJ99*FCFF!AJ31/1000 -> 516.81224 | H13: =+FCFF!AL99*FCFF!AL31/1000 -> 600.25424
B14: % of Equity | D14: =IFERROR(D13/D35,"") -> 0.20646117 | E14: =IFERROR(E13/E35,"") -> 0.16375069 | F14: =IFERROR(E13/F35,"") -> 0.12676091 | G14: =IFERROR(F13/G35,"") -> 0.15107623 | H14: =IFERROR(G13/H35,"") -> 0.15598236
B15: Risk-Free Rate | D15: 0.0425 | E15: 0.0425 | F15: 0.0425 | G15: 0.0425 | H15: 0.0425
B16: Beta | D16: =+Inputs!M18 -> 1.535918 | E16: 1.535918 | F16: 1.535918 | G16: 1.535918 | H16: 1.535918
B17: Unlevered Beta | D17: =+D16/(1+(D28/D13)*(1-D32)) -> 0.31710742 | E17: =+E16/(1+(E28/E13)*(1-E32)) -> 0.25150763 | F17: =+F16/(1+(F28/F13)*(1-F32)) -> 0.24713583 | G17: =+G16/(1+(G28/G13)*(1-G32)) -> 0.26388328 | H17: =+H16/(1+(H28/H13)*(1-H32)) -> 0.2782569
B18: Equity Risk Premium | D18: =+N18 -> 0.0767 | E18: =+D18*0.98 -> 0.075166 | F18: =+E18*0.98 -> 0.07366268 | G18: =+F18*0.98 -> 0.072189426 | H18: =+G18*0.98 -> 0.070745638 | K18: ERP | N18: 0.0767 | O18: 0.075166 | P18: 0.07366268 | Q18: 0.072189426 | R18: 0.070745638
B19: Ke (Cost of Equity) | D19: =IFERROR(+D15+D16*D18,"") -> 0.16030491 | E19: =IFERROR(+E15+E16*E18,"") -> 0.15794881 | F19: =IFERROR(+F15+F16*F18,"") -> 0.15563984 | G19: =IFERROR(+G15+G16*G18,"") -> 0.15337704 | H19: =IFERROR(+H15+H16*H18,"") -> 0.1511595
B21: Preferred Equity: | K21: ROIC vs WACC
B22: Market Capitalization | D22: =IFERROR(Inputs!J14,0) -> 0 | E22: 0 | F22: 0 | G22: 0 | H22: 0
B23: % of Preferred Equity | D23: =+D22/D35 -> 0 | E23: 0 | F23: 0 | G23: 0 | H23: 0
B24: Preferred Dividends | D24: =+IS!AF50 -> 0 | E24: =D24 -> 0 | F24: =E24 -> 0 | G24: =F24 -> 0 | H24: =G24 -> 0
B25: Kp (Cost of Preferred Equity) | D25: =IFERROR(D24/D22,0) -> 0 | E25: =IFERROR(E24/E22,0) -> 0 | F25: =IFERROR(F24/F22,0) -> 0 | G25: =IFERROR(G24/G22,0) -> 0 | H25: =IFERROR(H24/H22,0) -> 0
B27: Debt:
B28: Debt (in millions) | C28: =+BS!AF38+BS!AF39+BS!AF44+BS!AF45 -> 1568184 | D28: =(+BS!AI38+BS!AI39+BS!AI44+BS!AI45)/1000 -> 1709.387 | E28: =+Assumptions!G56 -> 1828.3335 | F28: =+Assumptions!H56 -> 2369.894 | G28: =+Assumptions!I56 -> 2491.2648 | H28: =+Assumptions!J56 -> 2713.0195
B29: % of Debt | D29: =IFERROR(D28/D35,"") -> 0.79353883 | E29: =IFERROR(E28/E35,"") -> 0.83624931 | F29: =IFERROR(F28/F35,"") -> 0.83909569 | G29: =IFERROR(G28/G35,"") -> 0.82819182 | H29: =IFERROR(H28/H35,"") -> 0.81883349
B30: Debt Spread | D30: =+D31-D15 -> 0.056477002 | E30: =+D30 -> 0.056477002 | F30: =+E30 -> 0.056477002 | G30: =+F30 -> 0.056477002 | H30: =+G30 -> 0.056477002
B31: Cost of Debt | D31: =+(IS!AI36+IS!AH36+IS!AE36+IS!AD36)/(WACC!D28*1000) -> 0.098977002 | E31: =+E15+E30 -> 0.098977002 | F31: =+F15+F30 -> 0.098977002 | G31: =+G15+G30 -> 0.098977002 | H31: =+H15+H30 -> 0.098977002
B32: Tax Rate | D32: 0 | E32: 0 | F32: 0 | G32: 0 | H32: 0
B33: Kd (After-Tax Cost of Debt) | D33: =+D31*(1-D32) -> 0.098977002 | E33: =+E31*(1-E32) -> 0.098977002 | F33: =+F31*(1-F32) -> 0.098977002 | G33: =+G31*(1-G32) -> 0.098977002 | H33: =+H31*(1-H32) -> 0.098977002
B35: Total | D35: =+D13+D24+D28 -> 2154.1315 | E35: =+E13+E24+E28 -> 2186.3497 | F35: =+F13+F24+F28 -> 2824.3429 | G35: =+G13+G24+G28 -> 3008.077 | H35: =+H13+H24+H28 -> 3313.2737
B37: Country/Conglomerate/... Risk Premium
A39: x | B39: WACC | D39: =+D19*D14+D25*D23+D33*D29+D37 -> 0.11163883 | E39: =+D39*0.9 -> 0.10047495 | F39: =+F19*F14+F25*F23+F33*F29+F37 -> 0.10278022 | G39: =+G19*G14+G25*G23+G33*G29+G37 -> 0.10514357 | H39: =+H19*H14+H25*H23+H33*H29+H37 -> 0.1046239
D40: =+AVERAGE(D39:H39) -> 0.10493229
B41: NOPAT | D41: =+FCFF!Z126 -> 115418.67 | E41: =+FCFF!AF126 -> 121119.72 | F41: =+FCFF!AH126 -> 154387.76 | G41: =+FCFF!AJ126 -> 162105.45 | H41: =+FCFF!AL126 -> 174949.93
B42: Total Payout | C42: 0 | D42: =+FCFF!Z112+FCFF!Z115 -> 0 | E42: =+FCFF!AF112+FCFF!AF115 -> 0 | F42: =+FCFF!AH112+FCFF!AH115 -> 0 | G42: =+FCFF!AJ112+FCFF!AJ115 -> 0 | H42: =+FCFF!AL112+FCFF!AL115 -> 0
B43: Book Value of Equity | C43: =+BS!AF54 -> 2949583 | D43: =+C43+D41+D42 -> 3065001.7 | E43: =+D43+E41+E42 -> 3186121.4 | F43: =+E43+F41+F42 -> 3340509.1 | G43: =+F43+G41+G42 -> 3502614.6 | H43: =+G43+H41+H42 -> 3677564.5
B44: Invested Capital | C44: =+C43+C28 -> 4517767 | D44: =+D43+D28 -> 3066711.1 | E44: =+E43+E28 -> 3187949.7 | F44: =+F43+F28 -> 3342879 | G44: =+G43+G28 -> 3505105.9 | H44: =+H43+H28 -> 3680277.5
A45: x | B45: ROIC | D45: =+D41/((D44+C44)/2) -> 0.030435494 | E45: =+E41/((E44+D44)/2) -> 0.038729429 | F45: =+F41/((F44+E44)/2) -> 0.047279683 | G45: =+G41/((G44+F44)/2) -> 0.047343986 | H45: =+H41/((H44+G44)/2) -> 0.048696059
B48: Bloomberg Metrics>
B49: WACC 17% | W49: ,
B50: ROIC 2.04%

Sheet FCFF
A7: x | B7: Market Assumptions
D8: 2022 | J8: =D8+1 -> 2023 | P8: =J8+1 -> 2024 | V8: =P8+1 -> 2025 | AB8: =V8+1 -> 2026 | AH8: =AB8+1 -> 2027 | AJ8: =+AH8+1 -> 2028 | AL8: =+AJ8+1 -> 2029
D9: Q1 | E9: Q2 | F9: Q3 | G9: Q4 | H9: FY | J9: Q1 | K9: Q2 | L9: Q3 | M9: Q4 | N9: FY | P9: Q1 | Q9: Q2 | R9: Q3 | S9: Q4 | T9: FY | V9: Q1 | W9: Q2 | X9: Q3 | Y9: Q4 | Z9: FY | AB9: Q1 | AC9: Q2 | AD9: Q3 | AE9: Q4 | AF9: FY | AH9: FY | AJ9: FY | AL9: FY
B21: Revenue
A23: x | B23: Operating Assumptions
D24: =D$8 -> 2022 | E24: =F24 -> 0 | F24: =F$8 -> 0 | G24: =F24 -> 0 | H24: =F24 -> 0 | J24: =J$8 -> 2023 | K24: =L24 -> 0 | L24: =L$8 -> 0 | M24: =L24 -> 0 | N24: =L24 -> 0 | P24: =P$8 -> 2024 | Q24: =R24 -> 0 | R24: =R$8 -> 0 | S24: =R24 -> 0 | T24: =R24 -> 0 | V24: =V$8 -> 2025 | W24: =X24 -> 0 | X24: =X$8 -> 0 | Y24: =X24 -> 0 | Z24: =X24 -> 0 | AB24: =AB$8 -> 2026 | AC24: =AD24 -> 0 | AD24: =AD$8 -> 0 | AE24: =AD24 -> 0 | AF24: =AD24 -> 0 | AH24: =AH$8 -> 2027 | AJ24: =AJ$8 -> 2028 | AL24: =AL$8 -> 2029
D25: Q1 | E25: Q2 | F25: Q3 | G25: Q4 | H25: FY | J25: Q1 | K25: Q2 | L25: Q3 | M25: Q4 | N25: FY | P25: Q1 | Q25: Q2 | R25: Q3 | S25: Q4 | T25: FY | V25: Q1 | W25: Q2 | X25: Q3 | Y25: Q4 | Z25: FY | AB25: Q1 | AC25: Q2 | AD25: Q3 | AE25: Q4 | AF25: FY | AH25: FY | AJ25: FY | AL25: FY
B28: Income Statement
B31: Revenue | D31: =IS!P18 -> 34134 | E31: =IS!Q18 -> 34302 | F31: =IS!R18 -> 34378 | G31: =IS!S18 -> 38052 | H31: =IS!T18 -> 140866 | J31: 52729 | K31: 39112 | L31: 38430 | M31: 23111 | N31: =+SUM(J31:M31) -> 153382 | P31: 37950 | Q31: 39774 | R31: 41539 | S31: 57921 | T31: =+SUM(P31:S31) -> 177184 | V31: =IS!AH18 -> 45846 | W31: =IS!AI18 -> 63997 | X31: =+R31*1.4 -> 58154.6 | Y31: =+S31*1.4 -> 81089.4 | Z31: 249087 | AB31: =+$AF$31/4 -> 75850.906 | AC31: =+$AF$31/4 -> 75850.906 | AD31: =+$AF$31/4 -> 75850.906 | AE31: =+$AF$31/4 -> 75850.906 | AF31: =+Assumptions!C41 -> 303403.62 | AH31: 349576.11 | AJ31: =+Assumptions!E41 -> 369151.6 | AL31: =+Assumptions!F41 -> 400169.49
B32: % of growth | D32: =D31/IS!J18-1 -> 0.78459769 | E32: =E31/IS!K18-1 -> 0.96033832 | F32: =F31/IS!L18-1 -> 0.55521375 | G32: =G31/IS!M18-1 -> -0.20189605 | H32: =H31/IS!N18-1 -> 0.60253464 | J32: =J31/IS!P18-1 -> 0.54476475 | K32: =K31/IS!Q18-1 -> 0.14022506 | L32: =L31/IS!R18-1 -> 0.11786608 | M32: =M31/IS!S18-1 -> -0.3926469 | N32: =N31/H31-1 -> 0.088850397 | P32: =P31/IS!V18-1 -> -0.2802822 | Q32: =Q31/IS!W18-1 -> 0.016925752 | R32: =R31/IS!X18-1 -> 0.080900338 | S32: =S31/IS!Y18-1 -> 1.5062092 | T32: =T31/N31-1 -> 0.15518118 | V32: =V31/IS!AB18-1 -> 0.21636465 | W32: =W31/IS!AC18-1 -> 0.60901594 | X32: =X31/IS!AD18-1 -> 0.4 | Y32: 0.4 | Z32: =Z31/T31-1 -> 0.40580978 | AB32: =AB31/IS!AH18-1 -> 0.65447162 | AC32: =AC31/IS!AI18-1 -> 0.18522596 | AD32: =AD31/IS!AJ18-1 -> 0.30429761 | AE32: =AE31/IS!AK18-1 -> -0.064601468 | AF32: =AF31/Z31-1 -> 0.21806286 | AH32: =AH31/AF31-1 -> 0.15218173 | AJ32: =AJ31/AH31-1 -> 0.055997789 | AL32: =AL31/AJ31-1 -> 0.084024805 | AR32: 2022 | AS32: =+AR32+1 -> 2023 | AT32: =+AS32+1 -> 2024 | AU32: =+AT32+1 -> 2025 | AV32: =+AU32+1 -> 2026 | AW32: =+AV32+1 -> 2027 | AX32: =+AW32+1 -> 2028 | AY32: =+AX32+1 -> 2029
AQ33: EBITDA | AR33: =H61+H128 -> 85643 | AS33: =N61+N128 -> 65966 | AT33: =T61+T128 -> 97957 | AU33: =Z61+Z128 -> 113466 | AV33: =AF61+AF128 -> 121361.45 | AW33: =AH61+AH128 -> 157309.25 | AX33: =AJ61+AJ128 -> 166118.22 | AY33: =AL61+AL128 -> 180076.27
B34: Cost of Goods & Services | D34: =IS!P21 -> 7004 | E34: =IS!Q21 -> 4944 | F34: =IS!R21 -> 4459 | G34: =IS!S21 -> 5892 | H34: =IS!T21 -> 22299 | J34: =IS!V21 -> 5907 | K34: =IS!W21 -> 6864 | L34: =IS!X21 -> 8319 | M34: =IS!Y21 -> 8013 | N34: =IS!Z21 -> 29103 | P34: =IS!AB21 -> 7197 | Q34: =IS!AC21 -> 8176 | R34: =IS!AD21 -> 8130 | S34: =IS!AE21 -> 9500 | T34: =IS!AF21 -> 33003 | V34: =IS!AH21 -> 15902 | W34: =IS!AI21 -> 27846 | X34: =(X35+Sensitivity!$U$39)*X$31 -> 5815.46 | Y34: =(Y35+Sensitivity!$U$39)*Y$31 -> 8108.94 | Z34: =SUM(V34:Y34) -> 57672.4 | AB34: =(AB35+Sensitivity!$U$39)*AB$31 -> 15170.181 | AC34: =(AC35+Sensitivity!$U$39)*AC$31 -> 15170.181 | AD34: =(AD35+Sensitivity!$U$39)*AD$31 -> 15170.181 | AE34: =(AE35+Sensitivity!$U$39)*AE$31 -> 15170.181 | AF34: =SUM(AB34:AE34) -> 60680.725 | AH34: =(AH35+Sensitivity!$U$39)*AH$31 -> 52436.417 | AJ34: =(AJ35+Sensitivity!$U$39)*AJ$31 -> 55372.74 | AL34: =(AL35+Sensitivity!$U$39)*AL$31 -> 60025.424 | AQ34: FCFF | AR34: =H136 -> 340577.16 | AS34: =N136 -> -61634.368 | AT34: =T136 -> 175059.24 | AU34: =Z136 -> 47148.377 | AV34: =AF136 -> 161535.98 | AW34: =AH136 -> 111726.85 | AX34: =AJ136 -> 186503.01 | AY34: =AL136 -> 172823.37
