Workbook
Name COOLFUCNTION: _xlfn.LAMBDA(_xldudf_BOARDFLARE_EXEC("workbook-settings:coolfucntion"))
Name COOLFUCNTION: _xlfn.LAMBDA(_xldudf_BOARDFLARE_EXEC("workbook-settings:coolfucntion"))
Name COOLFUCNTION: _xlfn.LAMBDA(_xldudf_BOARDFLARE_EXEC("workbook-settings:coolfucntion"))
Name COOLFUCNTION: _xlfn.LAMBDA(_xldudf_BOARDFLARE_EXEC("workbook-settings:coolfucntion"))
Name COOLFUCNTION: _xlfn.LAMBDA(_xldudf_BOARDFLARE_EXEC("workbook-settings:coolfucntion"))
Name COOLFUCNTION: _xlfn.LAMBDA(_xldudf_BOARDFLARE_EXEC("workbook-settings:coolfucntion"))
Name COOLFUCNTION: _xlfn.LAMBDA(_xldudf_BOARDFLARE_EXEC("workbook-settings:coolfucntion"))
Name COOLFUCNTION: _xlfn.LAMBDA(_xldudf_BOARDFLARE_EXEC("workbook-settings:coolfucntion"))
Name COOLFUCNTION: _xlfn.LAMBDA(_xldudf_BOARDFLARE_EXEC("workbook-settings:coolfucntion"))
Name COOLFUCNTION: _xlfn.LAMBDA(_xldudf_BOARDFLARE_EXEC("workbook-settings:coolfucntion"))
Name COOLFUCNTION: _xlfn.LAMBDA(_xldudf_BOARDFLARE_EXEC("workbook-settings:coolfucntion"))
Name Sectors: #REF!
Name Sectors: #REF!
Name Sectors: #REF!
Name Sectors: #REF!
Name Sectors: #REF!
Name Sectors: #REF!
Name Sectors: #REF!
Name Sectors: #REF!

Sheet Dashboard
C154: =+C155+1 -> 45984
C155: =+C156+1 -> 45983
C156: =+C157+1 -> 45982
C157: =+C158+1 -> 45981
C158: =+C159+1 -> 45980
C159: =+C160+1 -> 45979
C160: =+C161+1 -> 45978 | L160: =IF(FCFF!$R$165="Revenue Exit",FCFF!$AF$177,IF(FCFF!$R$165="EBITDA Exit",FCFF!Z177,FCFF!AL177)) -> #NAME?
C161: =+C162+1 -> 45977
C162: =+C163+1 -> 45976 | E162: =IF(FCFF!$R$165="Revenue Exit",FCFF!$AF$177,IF(FCFF!$R$165="EBITDA Exit",FCFF!Z177,FCFF!AL177)) -> #NAME?
C163: =+C164+1 -> 45975 | E163: =E164+($E$162-$E$193)/COUNTA($C$162:$C$192) -> #NAME?
C164: =+C165+1 -> 45974 | E164: =E165+($E$162-$E$193)/COUNTA($C$162:$C$192) -> #NAME?
C165: =+C166+1 -> 45973 | E165: =E166+($E$162-$E$193)/COUNTA($C$162:$C$192) -> #NAME?
C166: =+C167+1 -> 45972 | E166: =E167+($E$162-$E$193)/COUNTA($C$162:$C$192) -> #NAME?
C167: =+C168+1 -> 45971 | E167: =E168+($E$162-$E$193)/COUNTA($C$162:$C$192) -> #NAME?
C168: =+C169+1 -> 45970 | E168: =E169+($E$162-$E$193)/COUNTA($C$162:$C$192) -> #NAME?
C169: =+C170+1 -> 45969 | E169: =E170+($E$162-$E$193)/COUNTA($C$162:$C$192) -> #NAME?
C170: =+C171+1 -> 45968 | E170: =E171+($E$162-$E$193)/COUNTA($C$162:$C$192) -> #NAME?
C171: =+C172+1 -> 45967 | E171: =E172+($E$162-$E$193)/COUNTA($C$162:$C$192) -> #NAME?
C172: =+C173+1 -> 45966 | E172: =E173+($E$162-$E$193)/COUNTA($C$162:$C$192) -> #NAME?
C173: =+C174+1 -> 45965 | E173: =E174+($E$162-$E$193)/COUNTA($C$162:$C$192) -> #NAME?
C174: =+C175+1 -> 45964 | E174: =E175+($E$162-$E$193)/COUNTA($C$162:$C$192) -> #NAME?
... C192: =+C193+1 -> 45946 | E192: =E193+($E$162-$E$193)/COUNTA($C$162:$C$192) -> #NAME?
B193: TODAY | C193: =+'Stock Data'!AM4 -> 45945 | D193: =_xlfn.XLOOKUP(C193,'Stock Data'!$AM$4:$AM$1051,'Stock Data'!$AN$4:$AN$1051) -> 141.83 | E193: =D193 -> 141.83
C194: =+'Stock Data'!AM5 -> 45944 | D194: =_xlfn.XLOOKUP(C194,'Stock Data'!$AM$4:$AM$1051,'Stock Data'!$AN$4:$AN$1051) -> 141.83
C195: =+'Stock Data'!AM6 -> 45943 | D195: =_xlfn.XLOOKUP(C195,'Stock Data'!$AM$4:$AM$1051,'Stock Data'!$AN$4:$AN$1051) -> 144.43
C196: =+'Stock Data'!AM7 -> 45942 | D196: =_xlfn.XLOOKUP(C196,'Stock Data'!$AM$4:$AM$1051,'Stock Data'!$AN$4:$AN$1051) -> 144.43
C197: =+'Stock Data'!AM8 -> 45941 | D197: =_xlfn.XLOOKUP(C197,'Stock Data'!$AM$4:$AM$1051,'Stock Data'!$AN$4:$AN$1051) -> 144.43
C198: =+'Stock Data'!AM9 -> 45940 | D198: =_xlfn.XLOOKUP(C198,'Stock Data'!$AM$4:$AM$1051,'Stock Data'!$AN$4:$AN$1051) -> 141.81
C199: =+'Stock Data'!AM10 -> 45939 | D199: =_xlfn.XLOOKUP(C199,'Stock Data'!$AM$4:$AM$1051,'Stock Data'!$AN$4:$AN$1051) -> 135.64
C200: =+'Stock Data'!AM11 -> 45938 | D200: =_xlfn.XLOOKUP(C200,'Stock Data'!$AM$4:$AM$1051,'Stock Data'!$AN$4:$AN$1051) -> 137.37
C201: =+'Stock Data'!AM12 -> 45937 | D201: =_xlfn.XLOOKUP(C201,'Stock Data'!$AM$4:$AM$1051,'Stock Data'!$AN$4:$AN$1051) -> 136.85
C202: =+'Stock Data'!AM13 -> 45936 | D202: =_xlfn.XLOOKUP(C202,'Stock Data'!$AM$4:$AM$1051,'Stock Data'!$AN$4:$AN$1051) -> 136.85
C203: =+'Stock Data'!AM14 -> 45935 | D203: =_xlfn.XLOOKUP(C203,'Stock Data'!$AM$4:$AM$1051,'Stock Data'!$AN$4:$AN$1051) -> 136.85
C204: =+'Stock Data'!AM15 -> 45934 | D204: =_xlfn.XLOOKUP(C204,'Stock Data'!$AM$4:$AM$1051,'Stock Data'!$AN$4:$AN$1051) -> 136.85
C205: =+'Stock Data'!AM16 -> 45933 | D205: =_xlfn.XLOOKUP(C205,'Stock Data'!$AM$4:$AM$1051,'Stock Data'!$AN$4:$AN$1051) -> 136.84
... C558: =+'Stock Data'!AM369 -> 45580 | D558: =_xlfn.XLOOKUP(C558,'Stock Data'!$AM$4:$AM$1051,'Stock Data'!$AN$4:$AN$1051) -> 131.81

Sheet Key Info
B7: Analysts | F7: LIS – Equity Research | J7: Stock Performance
B12: Ana Luiza Costa, Team Leader | F12: Recommendation: | H12: Hold
B13: Bsc in Economics, ISEG – Ulisboa | F13: Target Price (FCFF): | H13: =FCFF!AL177 -> #NAME?
B14: analuiza@aln.iseg.ulisboa.pt | F14: Upside(Downside): | H14: =FCFF!AL179 -> #NAME?
B15: John Stavale, Analyst
B16: Bsc in Economics, ISEG – Ulisboa | F16: Ticker | H16: MIDD
B17: johnstavale@aln.iseg.ulisboa.pt | F17: Stock Exchange | H17: NASDAQ
B18: Manuel Jáco, Analyst
B19: Bsc in MAEG, ISEG – Ulisboa | F19: Current Price | H19: ='Stock Data'!AN4 -> 141.83
B20: manueljaco@aln.iseg.ulisboa.pt | F20: ="Market Cap (in "&IF(Inputs!$D$14="BLN","billions",IF(Inputs!$D$14="MLN","millions","thousands"))&")" -> Market Cap (in thousands) | H20: ='Stock Data'!AQ4 -> 7188282.8
F21: Beta | H21: ='Stock Data'!E164 -> 0.98372155
F22: % of 52-Week High | H22: ='Stock Data'!E165 -> 0.24535887
F23: 100-Day Moving Average | H23: ='Stock Data'!E166 -> 141.4245
B25: Reviewed by: | F25: Avg Vol (1 month) | H25: ='Stock Data'!E168 -> 1068818.6
B26: NAME, Analyst | F26: Shares Outstanding (millions) | H26: ='Stock Data'!E169 -> 50.68239
B27: Bsc in XXX, ISEG – Ulisboa | F27: % Float | H27: ='Stock Data'!E170 -> 0.9198911
B28: email@aln.iseg.ulisboa.pt | F28: Short % of Float | H28: =IFERROR('Stock Data'!E171,0) -> 0.06098394
B30: LISBON INVESTMENT SOCIETY | F30: % Held by Insiders | H30: ='Stock Data'!E173 -> 0.015432757
B31: ISEG – Rua do Quelhas, 6 | F31: % Held by Institutions | H31: ='Stock Data'!E174 -> 1.2342792
B32: lis@iseg.ulisboa.pt
B34: Disclaimer: This report was prepared by members of the Lisbon Investment Society (LIS), an independent, student-led, non-profit organization based at ISEG – Lisbon School of Economics & Management, and is intended solely for academic and educational purposes. All analyses, forecasts, and opinions expressed in this report reflect the independent judgment of the authors as of the date of publication and are subject to change without notice. The views presented herein do not represent those of ISEG, its faculty, or any affiliated entity. This document does not constitute, and should not be interpreted as, investment advice, an offer, or a solicitation to buy or sell any security or financial instrument. Nothing in this report should be construed as a recommendation to make or refrain from making any investment decision. The content is intended for informational purposes only, and readers are strongly encouraged to conduct their own research and seek advice from a qualified financial professional before making any financial decisions. The information contained in this report has been obtained from publicly available sources believed to be reliable; however, no representation or warranty is made regarding the accuracy, completeness, or timeliness of such information. LIS and its members accept no liability whatsoever for any direct or indirect loss arising from the use of this report or its contents. This report incorporates terminology, financial metrics, and methodologies commonly used in professional equity research, including but not limited to Discounted Cash Flow (DCF), trading multiples, Monte Carlo simulations, and strategic analysis tools such as Porter’s Five Forces. Definitions and assumptions used in these models are disclosed within the report and reflect a hypothetical investment thesis designed solely for academic discussion. All valuations, projections, and target prices presented herein are based on publicly available data and subject to the limitations of modeling assumptions. These are not guarantees of future performance and should not be relied upon as such, as past performance is not indicative of future results. Any company names, logos, trademarks, or brand references mentioned in this report are the property of their respective owners and are used strictly for identification and academic purposes. This document may not be reproduced, redistributed, or quoted in whole or in part without the prior written consent of the Lisbon Investment Society. About LIS – Lisbon Investment Society: The Lisbon Investment Society (LIS) is a non-profit academic association headquartered at ISEG – Lisbon School of Economics & Management. Founded in 2016, LIS is committed to fostering student interest in finance and investment through applied research, skill development, and institutional engagement. The Society operates independently and autonomously from any political, religious, or commercial affiliation, and is composed of selected students and collaborators who are invited through a rigorous recruitment process and share a commitment to excellence, analytical rigor, and ethical standards. Its activities include equity research, portfolio management, macroeconomic analysis, and investment education. This report was prepared by the Equity Research team at the Lisbon Investment Society, whose analysts combine rigorous financial modeling, critical thinking, and collaborative research to deliver high-quality, student-led investment analysis. We welcome your feedback, discussion, and questions regarding this report or our research process, and invite you to reach out to our team as we are always open to engagement.

Sheet Industry
D6: 584.17 | E6: 627.76 | F6: 676.06 | G6: 729.63 | H6: 789.13 | I6: 855.3 | J6: 929 | K6: 997.69 | L6: 1067.63 | M6: 1137.57
A7: x | B7: Industry Growth Forecast | O7: Industry Index
D9: 2022 | E9: =+D9+1 -> 2023 | F9: =+E9+1 -> 2024 | G9: =+F9+1 -> 2025 | H9: =+G9+1 -> 2026 | I9: =+H9+1 -> 2027 | J9: =+I9+1 -> 2028 | K9: =+J9+1 -> 2029 | M9: ="CAGR "&$G$9&" - "&$K$9 -> CAGR 2025 - 2029
B12: Market Size (Commercial Foodservice Machinery) | F12: 39071 | G12: =F12*(1+0.07) -> 41805.97 | H12: =G12*(1+0.07) -> 44732.388 | I12: =H12*(1+0.07) -> 47863.655 | J12: =I12*(1+0.07) -> 51214.111 | K12: =J12*(1+0.07) -> 54799.099 | M12: =(K12/G12)^(1/5)-1 -> 0.055618571 | X12: Global | Y12: North America
B13: Market Share | M13: =((K13*K12)/(G13*G12))^(1/5)-1 -> #DIV/0! | W13: Commercial Foodservice Machinery | X13: =M12 -> 0.055618571 | Y13: =M18 -> 0.02551911
B14: Market Size (Food Processing Machinery) | E14: 52690 | F14: =E14*(1+0.04) -> 54797.6 | G14: =F14*(1+0.04) -> 56989.504 | H14: =G14*(1+0.04) -> 59269.084 | I14: =H14*(1+0.04) -> 61639.848 | J14: =I14*(1+0.04) -> 64105.441 | K14: =J14*(1+0.04) -> 66669.659 | M14: =(K14/G14)^(1/5)-1 -> 0.031874004 | W14: Food Processing Machinery | X14: =M14 -> 0.031874004 | Y14: =M20 -> 0.02631401
B15: Market Share | M15: =((K15*K14)/(G15*G14))^(1/5)-1 -> #DIV/0! | W15: Household Kitchen Appliances | X15: =M16 -> 0.033461197 | Y15: =M22 -> 0.021542301
B16: Market Size (Household Kitchen Appliances) | F16: 269270 | G16: =F16*(1+0.042) -> 280579.34 | H16: =G16*(1+0.042) -> 292363.67 | I16: =H16*(1+0.042) -> 304642.95 | J16: =I16*(1+0.042) -> 317437.95 | K16: =J16*(1+0.042) -> 330770.34 | M16: =(K16/G16)^(1/5)-1 -> 0.033461197
B17: Market Share | M17: =((K17*K16)/(G17*G16))^(1/5)-1 -> #DIV/0!
B18: Market Size (NA Commercial Foodservice Machinery) | F18: 10738 | G18: =F18*(1+0.032) -> 11081.616 | H18: =G18*(1+0.032) -> 11436.228 | I18: =H18*(1+0.032) -> 11802.187 | J18: =I18*(1+0.032) -> 12179.857 | K18: =J18*(1+0.032) -> 12569.612 | M18: =(K18/G18)^(1/5)-1 -> 0.02551911
B19: Market Share | M19: =((K19*K18)/(G19*G18))^(1/5)-1 -> #DIV/0!
B20: Market Size (NA Food Processing Equipment) | D20: 9609 | E20: =D20*(1+0.033) -> 9926.097 | F20: =E20*(1+0.033) -> 10253.658 | G20: =F20*(1+0.033) -> 10592.029 | H20: =G20*(1+0.033) -> 10941.566 | I20: =H20*(1+0.033) -> 11302.638 | J20: =I20*(1+0.033) -> 11675.625 | K20: =J20*(1+0.033) -> 12060.92 | M20: =(K20/G20)^(1/5)-1 -> 0.02631401
B21: Market Share | M21: =((K21*K20)/(G21*G20))^(1/5)-1 -> #DIV/0!
B22: Market Size (NA Household Kitchen Appliances) | F22: 68120 | G22: =F22*(1+0.027) -> 69959.24 | H22: =G22*(1+0.027) -> 71848.139 | I22: =H22*(1+0.027) -> 73788.039 | J22: =I22*(1+0.027) -> 75780.316 | K22: =J22*(1+0.027) -> 77826.385 | M22: =(K22/G22)^(1/5)-1 -> 0.021542301
B23: Market Share | M23: =((K23*K22)/(G23*G22))^(1/5)-1 -> #DIV/0!
A25: x
B27: Industry Driver | D27: Description | O27: Porter's Five Forces
B29: Commercial Foodservice Machinery - net openings and equipments cycle | D29: Highly dependant on commercial foodservices openings (full and quick service restaurants) and equipments renewal, the industry benefits from decreasing interest rates and increasing consumer confidence and discretionary spending.
B30: Food Processing Machinery - demand for processed food | D30: Increasing demand for processed and ultra-processed food all over the world increases confidence on the industry growth, as more machinery and equipments will be required. APAC demand increase might be the highest, so a strong position would be highly rewarded. Supply chain optimizations may also be a competitive advantage, due to risks of distruption and dependance on commodities.
B31: Residential Kitchen Machinery - house constructions and renewals | D31: As long as there's a demand for house constructions and renewals, householders will need kitchen equipments. Therefore, lower interest rates, as well as higher GDP growth and employment rates and wages increase the demand for refurbished and new houses.
O34: Rivalry Among Existing Competitors | R34: 5
O35: Threat of New Entrants | R35: 2
O36: Threat of Substitutes | R36: 3
O37: Bargaining Power of Customers | R37: 3
O38: Bargaining Power of Suppliers | R38: 4

Sheet ESG
A7: x | B7: ESG Analysis
B12: ESG Scores | G12: GHG Scope 1 Emissions, Water Consumption, Energy Consumption and Waste Production per Sales
B15: LSEG ESG Score | D15: 55
B16: E-Score | D16: 37
B17: S-Score | D17: 46
B18: G-Score | D18: 88
B19: S&P Global ESG Score | D19: 26
B20: Sustainalytics | D20: 31.62
B21: ISS ESG Corporate Rating | D21: D+
B22: SDG Impact Rating | D22: -6.5
B23: Governance Quality Score | D23: 1
B24: MSCI ESG Ratings | D24: BBB
B30: Key Info | G30: Environmental
H32: Overview | I32: Targets | J32: Improvements | K32: Comments
B33: GICS Sector | C33: Industrials | G33: GHG Scope 1 Emissions | I33: Net-zero CO₂ emissions by 2050. | K33: Increase in Scope 1 and Scope 2 emissions from 2022 to 2023 due to business growth and the impact of additional Middleby locations reporting metrics.
B34: GICS Industry Group | C34: Capital Goods
B35: GICS Industry | C35: Machinery | G35: Water Consumption | J35: Slight decrease in Water Intensity (total water withdrawal per 1,000-square feet of facility) | K35: Reported water withdrawals in fiscal year 2023 increased slightly from the previous reporting year as a result of the acquisition of additional businesses and facilities.
B36: GICS Sub-Industry | C36: Special Industrial Machinery
G37: Energy Consumption | J37: Energy usage and GJ-intensity decreased in 2023 versus the previous year. | K37: Energy sources include Indirect Purchased Energy (Electrical Grid), Fuel Combustion, and Self-Generated Renewables (solar, wind, geothermal, bioenergy, hydro and tidal energy). Energy 1,
B38: Headquarters | C38: Elgin, Illinois, USA
B39: Numer of Employees | C39: 10616 | G39: Waste Management | J39: Available waste metrics point to a 16.2% decrease in hazardous waste in 2023 compared to 2022. | K39: Non-hazardous waste increased in 2023 compared to 2022, primarily as a result of acquisitions made of additional businesses and facilities while Waste Intensity decreased.
B41: Annual Report | C41: Form 10K 2024 | G41: Other
B42: Sustainability Report | C42: 2024 Sustainability Report Update
C43: 2023 Sustainability Report
B44: Recent Headlines | G44: Social
H46: Overview | I46: Targets | J46: Improvements | K46: Comments
G47: Employee Turnover % | K47: After a period of growth, Middleby's total number of employees decreased by 4.85% from 2022 to 2023, and by a further 0.99% from 2023 to 2024, ending at 10,616 in December 2024. The company does not disclose Employee Turnover rates.
G49: Salaries & Compensation | K49: Middleby employees attributed a compensation and benefits rating of 3.2/5 stars to their company on Glassdoor.
G51: Reputation
G53: Discrimination Events | K53: No reported discrimination events; standard EEO policies in place.
G55: Work Safety | K55: No recent confirmation of any major safety incidents involving worker injuries at Middleby in the last years from credible news or regulatory sources.
G57: Damage to consumer health | K57: 2017 Viking recall handled proactively as it strengthened product safety program in place with no major incidents since.
G59: Pension Plan | K59: The company does not offer a traditional defined benefit pension plan but instead provides a defined contribution plan,the Middleby Corporation Profit Sharing Plan, which functions as a 401(k) and a savings plan for eligible employees.
G61: Supply chain | K61: Middleby recognizes supply-chain risks and has a Supplier Code of Conduct.
G63: Community involvement | K63: Middleby engages communities via ‘Middleby Cares,’ donations, volunteering, and nonprofit partnerships.
G65: Public Sector | K65: Limited reliance on government contracts; primary exposure is compliance with food safety and labor standards.
G67: Litigation | K67: Routine product-liability claims, mostly insured and not material to financials.
B70: Board of Directors | G70: Governance
B72: Name | C72: Position | E72: M/F – Age | H72: Overview | I72: Targets | J72: Improvements | K72: Comments
B73: Gordon O'Brien | C73: Chairman | E73: M - 59 | G73: Diversity (Gender, Age, Industry, Region) | K73: Women account for 30% of the board.
...

Sheet Segments
A7: x | B7: Segments | D7: =F7 -> 2020 | E7: =F7 -> 2020 | F7: 2020 | G7: =F7 -> 2020 | H7: =F7 -> 2020 | J7: =L7 -> 2021 | K7: =L7 -> 2021 | L7: 2021 | M7: =L7 -> 2021 | N7: =L7 -> 2021 | P7: =R7 -> 2022 | Q7: =R7 -> 2022 | R7: 2022 | S7: =R7 -> 2022 | T7: =R7 -> 2022 | V7: =X7 -> 2023 | W7: =X7 -> 2023 | X7: 2023 | Y7: =X7 -> 2023 | Z7: =X7 -> 2023 | AB7: =AD7 -> 2024 | AC7: =AD7 -> 2024 | AD7: 2024 | AE7: =AD7 -> 2024 | AF7: =AD7 -> 2024 | AH7: =AJ7 -> 2025 | AI7: =AJ7 -> 2025 | AJ7: 2025 | AK7: =AJ7 -> 2025 | AL7: =AJ7 -> 2025 | AN7: =AP7 -> 2025 | AO7: =AP7 -> 2025 | AP7: 2025 | AQ7: =AP7 -> 2025 | AR7: =AP7 -> 2025 | AZ7: Products
D8: 2020 | J8: =D8+1 -> 2021 | P8: =J8+1 -> 2022 | V8: =P8+1 -> 2023 | AB8: =V8+1 -> 2024 | AH8: =AB8+1 -> 2025 | AN8: =AH8+1 -> 2026 | AT8: =AN8+1 -> 2027 | AV8: =+AT8+1 -> 2028 | AX8: =+AV8+1 -> 2029
D9: Q1 | E9: Q2 | F9: Q3 | G9: Q4 | H9: FY | J9: Q1 | K9: Q2 | L9: Q3 | M9: Q4 | N9: FY | P9: Q1 | Q9: Q2 | R9: Q3 | S9: Q4 | T9: FY | V9: Q1 | W9: Q2 | X9: Q3 | Y9: Q4 | Z9: FY | AB9: Q1 | AC9: Q2 | AD9: Q3 | AE9: Q4 | AF9: FY | AH9: Q1 | AI9: Q2 | AJ9: Q3 | AK9: Q4 | AL9: FY | AN9: Q1 | AO9: Q2 | AP9: Q3 | AQ9: Q4 | AR9: FY | AT9: FY | AV9: FY | AX9: FY
B12: Revenue by segment:
B13: Commercial Foodservice Equipment Group | H13: 1510279 | N13: 2032761 | T13: 2394762 | Z13: 2521471 | AF13: 2419236 | AL13: =FCFF!Z11 -> 2368431.2 | AR13: =FCFF!AF11 -> 2434945.4 | AT13: =FCFF!AH11 -> 2530368 | AV13: =FCFF!AJ11 -> 2622378.5 | AX13: =FCFF!AL11 -> 2720762.4
B14: Food Processing Equipment Group | H14: 437272 | N14: 480746 | T14: 589969 | Z14: 720618 | AF14: 794516 | AL14: =FCFF!Z17 -> 796982.56 | AR14: =FCFF!AF17 -> 865326.67 | AT14: =FCFF!AH17 -> 924724.45 | AV14: =FCFF!AJ17 -> 980517.65 | AX14: =FCFF!AL17 -> 1032242.1
B15: Residential Kitchen Equipment Group. | H15: 565706 | N15: 737285 | T15: 1048122 | Z15: 794516 | AF15: 724923 | AL15: =FCFF!Z23 -> 713547.48 | AR15: =FCFF!AF23 -> 726878.53 | AT15: =FCFF!AH23 -> 746028.25 | AV15: =FCFF!AJ23 -> 769238.05 | AX15: =FCFF!AL23 -> 793226.3
B18: Total revenue | D18: =IS!D18 -> 677459 | E18: =IS!E18 -> 471977 | F18: =IS!F18 -> 634525 | G18: =IS!G18 -> 729296 | H18: =IS!H18 -> 2513257 | J18: =IS!J18 -> 758058 | K18: =IS!K18 -> 808773 | L18: =IS!L18 -> 817545 | M18: =IS!M18 -> 866416 | N18: =IS!N18 -> 3250792 | P18: =IS!P18 -> 994676 | Q18: =IS!Q18 -> 1013601 | R18: =IS!R18 -> 992871 | S18: =IS!S18 -> 1031705 | T18: =IS!T18 -> 4032853 | V18: =IS!V18 -> 1007396 | W18: =IS!W18 -> 1039982 | X18: =IS!X18 -> 980651 | Y18: =IS!Y18 -> 1008576 | Z18: =IS!Z18 -> 4036605 | AB18: =IS!AB18 -> 926926 | AC18: =IS!AC18 -> 991546 | AD18: =IS!AD18 -> 942809 | AE18: =IS!AE18 -> 1013881 | AF18: =IS!AF18 -> 3875162 | AH18: =IS!AH18 -> 906627 | AI18: =IS!AI18 -> 977859 | AJ18: =IS!AJ18 -> 0 | AK18: =IS!AK18 -> 0 | AL18: =SUM(AL13:AL15) -> 3878961.2 | AN18: =IS!AN18 -> 0 | AO18: =IS!AO18 -> 0 | AP18: =IS!AP18 -> 0 | AQ18: =IS!AQ18 -> 0 | AR18: =SUM(AR13:AR15) -> 4027150.6 | AT18: =SUM(AT13:AT15) -> 4201120.7 | AV18: =SUM(AV13:AV15) -> 4372134.2 | AX18: =SUM(AX13:AX15) -> 4546230.8
B20: Revenue by region:
B21: United States and Canada | H21: 1752778 | N21: 2236775 | T21: 2879019 | Z21: 2821061 | AF21: 2614872 | AL21: =FCFF!Z12+FCFF!Z18+FCFF!Z24 -> 2560457.1 | AR21: =FCFF!AF12+FCFF!AF24+FCFF!AF18 -> 2621789.5 | AT21: =FCFF!AH12+FCFF!AH18+FCFF!AH24 -> 2716262.5 | AV21: =FCFF!AJ12+FCFF!AJ18+FCFF!AJ24 -> 2810723.6 | AX21: =FCFF!AL12+FCFF!AL18+FCFF!AL24 -> 2908939.5
B22: Asia | H22: 189231 | N22: 233227 | T22: 264609 | Z22: 285858 | AF22: 262705 | AL22: =FCFF!Z13+FCFF!Z19+FCFF!Z25 -> 257988.88 | AR22: =FCFF!AF13+FCFF!AF19+FCFF!AF25 -> 268396.75 | AT22: =FCFF!AH13+FCFF!AH19+FCFF!AH25 -> 278429.41 | AV22: =FCFF!AJ13+FCFF!AJ19+FCFF!AJ25 -> 289808.54 | AX22: =FCFF!AL13+FCFF!AL19+FCFF!AL25 -> 302462.65
B23: Europe and Middle East | H23: 508454 | N23: 687452 | T23: 768199 | Z23: 773317 | AF23: 826913 | AL23: =FCFF!Z14+FCFF!Z20+FCFF!Z26 -> 876487.64 | AR23: =FCFF!AF14+FCFF!AF20+FCFF!AF26 -> 934158.97 | AT23: =FCFF!AH14+FCFF!AH20+FCFF!AH26 -> 989078.49 | AV23: =FCFF!AJ14+FCFF!AJ20+FCFF!AJ26 -> 1041087.5 | AX23: =FCFF!AL14+FCFF!AL20+FCFF!AL26 -> 1092720.5
B24: Latin America | H24: 62794 | N24: 93338 | T24: 121026 | Z24: 156369 | AF24: 170672 | AL24: =FCFF!Z15+FCFF!Z21+FCFF!Z27 -> 184027.54 | AR24: =FCFF!AF15+FCFF!AF21+FCFF!AF27 -> 202805.39 | AT24: =FCFF!AH15+FCFF!AH21+FCFF!AH27 -> 217350.24 | AV24: =FCFF!AJ15+FCFF!AJ21+FCFF!AJ27 -> 230514.49 | AX24: =FCFF!AL15+FCFF!AL21+FCFF!AL27 -> 242108.19
B26: Total revenue | D26: =IS!D18 -> 677459 | E26: =IS!E18 -> 471977 | F26: =IS!F18 -> 634525 | G26: =IS!G18 -> 729296 | H26: =IS!H18 -> 2513257 | J26: =IS!J18 -> 758058 | K26: =IS!K18 -> 808773 | L26: =IS!L18 -> 817545 | M26: =IS!M18 -> 866416 | N26: =IS!N18 -> 3250792 | P26: =IS!P18 -> 994676 | Q26: =IS!Q18 -> 1013601 | R26: =IS!R18 -> 992871 | S26: =IS!S18 -> 1031705 | T26: =IS!T18 -> 4032853 | V26: =IS!V18 -> 1007396 | W26: =IS!W18 -> 1039982 | X26: =IS!X18 -> 980651 | Y26: =IS!Y18 -> 1008576 | Z26: =IS!Z18 -> 4036605 | AB26: =IS!AB18 -> 926926 | AC26: =IS!AC18 -> 991546 | AD26: =IS!AD18 -> 942809 | AE26: =IS!AE18 -> 1013881 | AF26: =IS!AF18 -> 3875162 | AH26: =IS!AH18 -> 906627 | AI26: =IS!AI18 -> 977859 | AJ26: =IS!AJ18 -> 0 | AK26: =IS!AK18 -> 0 | AL26: =SUM(AL21:AL24) -> 3878961.2 | AN26: =IS!AN18 -> 0 | AO26: =IS!AO18 -> 0 | AP26: =IS!AP18 -> 0 | AQ26: =IS!AQ18 -> 0 | AR26: =IFERROR(SUM(AR21:AR24), " ") -> 4027150.6 | AS26: =IFERROR(SUM(AS21:AS24), " ") -> 0 | AT26: =IFERROR(SUM(AT21:AT24), " ") -> 4201120.7 | AV26: =IFERROR(SUM(AV21:AV24), " ") -> 4372134.2 | AX26: =IFERROR(SUM(AX21:AX24), " ") -> 4546230.8
B28: Products:
B29: Product 1
B30: Product 2
B31: Product 3
B32: Product 4
B33: Product 5
A35: x | B35: Notes & Forecasts
B40: Dividends | H40: The company’s Board of Directors currently intends to retain any future earnings to support its operations and to finance the growth and development of the company’s business and does not intend to declare or pay cash dividends on its common stock for the foreseeable future.
B41: Announced Separation of Food Processing Business for 2026 | H41: Middleby Board of Directors unanimously approved a plan to separate our Food Processing segment into a standalone public company This action will create two independent and innovative leaders: The Middleby Corporation and Middleby Food Processing. The separation will be executed through a tax-free spin-off and is expected to be completed in early 2026.
B42: Expectations for 2025 revenue | H42: For 2025, Middleby corp is expecting a: • Total revenue of $3.81-3.87 billion; • Adjusted EBITDA of $770-800 million; and • Adjusted Earnings Per Share of $8.65-9.05

Sheet Peers
B7: Peers
A12: x | B12: Growth | C12: MIDDLEBY CORP | D12: NORDSON CORP | E12: STANLEY BLACK & | F12: HILLENBRAND INC | G12: TENNANT CO | H12: KADANT INC | I12: JBT MAREL CORP | J12: MSA SAFETY INC | K12: ENERPAC TOOL GRO | L12: SNAP-ON INC | M12: THERMON GROUP HO | N12: FED SIGNAL CORP | O12: DOUGLAS DYNAMICS | P12: ESAB CORP | Q12: FORTUNE BRANDS I | R12: GEA GROUP AG
B14: Revenue (LTM) | C14: -0.017023573 | D14: 0.0448811 | E14: -0.027123451 | F14: -0.080019305 | G14: -0.003815277 | H14: 0.017405109 | I14: 0.64980521 | J14: 0.0054899989 | K14: 0.028227695 | L14: 0.028227695 | M14: -0.0076128224 | N14: -0.0076128224 | O14: -0.0076128224 | P14: -0.0076128224 | Q14: -0.0076128224 | R14: =_xll.BQL( Inputs!$Q$24, "(sales_rev_turn(fpt=ltm,fa_adjusted=y) / sales_rev_turn(fpt=ltm,fa_adjusted=y,fa_period_offset=-1)) - 1" ) -> #NAME?
B15: Revenue (3-yr CAGR) | C15: 0.013269195 | D15: 0.035740049 | E15: -0.031488222 | F15: -0.0098965482 | G15: 0.048693214 | H15: 0.057317114 | I15: 0.1381728 | J15: 0.079385688 | K15: 0.024913716 | L15: 0.023562645 | M15: 0.089939808 | N15: 0.1505117 | O15: 0.0067282557 | P15: 0.029262877 | Q15: -0.10847821 | R15: =_xll.BQL( Inputs!$Q$25, "(sales_rev_turn(fpt=ltm,fa_adjusted=y) / sales_rev_turn(fpt=ltm,fa_adjusted=y,fa_period_offset=-3))^(1/3) - 1" ) -> #NAME?
B16: Gross profit (LTM) | C16: -0.017806707 | D16: 0.035261735 | E16: 0.0054829186 | F16: -0.070683662 | G16: -0.036417142 | H16: 0.045651093 | I16: 0.64607028 | J16: -0.022288876 | K16: 0.0094937127 | L16: 0.0094937127 | M16: 0.003503961 | N16: 0.003503961 | O16: 0.003503961 | P16: 0.003503961 | Q16: 0.003503961 | R16: =_xll.BQL( Inputs!$Q$24, "(gross_profit(fpt=ltm,fa_adjusted=y) / gross_profit(fpt=ltm,fa_adjusted=y,fa_period_offset=-1)) - 1" ) -> #NAME?
B17: EBIT (LTM) | C17: 0.020717435 | D17: 0.045871902 | E17: 0.014782516 | F17: -0.13530443 | G17: -0.10562414 | H17: -0.058583492 | I17: 0.47714604 | J17: -0.010764279 | K17: -0.0098607551 | L17: -0.0098607551 | M17: -0.016612304 | N17: -0.016612304 | O17: -0.016612304 | P17: -0.016612304 | Q17: -0.016612304 | R17: =_xll.BQL( Inputs!$Q$24, "(is_oper_inc(fpt=ltm,fa_adjusted=y) / is_oper_inc(fpt=ltm,fa_adjusted=y,fa_period_offset=-1)) - 1" ) -> #NAME?
B18: EBITDA (LTM) | C18: 0.013216806 | D18: 0.060447768 | E18: -0.018241042 | F18: -0.039993045 | G18: -0.063157895 | H18: -0.0025983024 | I18: 0.6860119 | J18: -9.4824773e-05 | K18: -0.0071547076 | L18: -0.0071547076 | M18: -0.01644319 | N18: -0.01644319 | O18: -0.01644319 | P18: -0.01644319 | Q18: -0.01644319 | R18: =_xll.BQL( Inputs!$Q$24, "(ebitda(fpt=ltm,fa_adjusted=y) / ebitda(fpt=ltm,fa_adjusted=y,fa_period_offset=-1)) - 1" ) -> #NAME?
B19: FCF (LTM) | C19: 0.17272461 | D19: -0.18941188 | E19: -0.11681914 | F19: -0.0043572985 | G19: -0.58454106 | H19: 0.0042260369 | I19: =(282.9-195.7)/195.7 -> 0.44557997 | J19: 3.8351067 | K19: 0.0044426198 | L19: 0.070619335 | M19: -0.037678152 | N19: 0.16209628 | O19: 16.105236 | P19: -0.43123296 | Q19: -0.40635556 | R19: {=_xll.BDP(Inputs!$Q$25,"FREE_CASH_FLOW_1_YEAR_GROWTH")/100} -> #NAME?
A21: x | B21: Margins | C21: MIDDLEBY CORP | D21: NORDSON CORP | E21: STANLEY BLACK & | F21: HILLENBRAND INC | G21: TENNANT CO | H21: KADANT INC | I21: JBT MAREL CORP | J21: MSA SAFETY INC | K21: ENERPAC TOOL GRO | L21: SNAP-ON INC | M21: THERMON GROUP HO | N21: FED SIGNAL CORP | O21: DOUGLAS DYNAMICS | P21: ESAB CORP | Q21: FORTUNE BRANDS I | R21: =R12 -> GEA GROUP AG
B23: Gross margin | C23: 0.3794342 | D23: 0.55248054 | E23: 0.29379722 | F23: 0.33194043 | G23: 0.42745007 | H23: 0.44252428 | I23: 0.36509324 | J23: 0.475873 | K23: 0.5106122 | L23: 0.51969305 | M23: 0.44739636 | N23: 0.28632823 | O23: 0.25828666 | P23: 0.37852228 | Q23: 0.44831851 | R23: {=_xll.BDP(Inputs!$Q$25,"GROSS_MARGIN")/100} -> #NAME?
B24: EBIT margin | C24: 0.16933176 | D24: 0.25056535 | E24: 0.036483857 | F24: -0.0056239789 | G24: 0.088831896 | H24: 0.16257319 | I24: 0.068997669 | J24: 0.21724811 | K24: 0.20625095 | L24: 0.26342886 | M24: 0.16008808 | N24: 0.15116841 | O24: 0.15603936 | P24: 0.16325508 | Q24: 0.1600998 | R24: {=_xll.BDP(Inputs!$Q$25,"OPER_MARGIN")/100} -> #NAME?
B25: EBITDA margin | C25: 0.19962376 | D25: 0.29642082 | E25: 0.081297488 | F25: 0.12681426 | G25: 0.11561478 | H25: 0.20586044 | I25: 0.098033428 | J25: 0.24003587 | K25: 0.23173036 | L25: 0.27490189 | M25: 0.20363877 | N25: 0.19340626 | O25: 0.21771093 | P25: 0.1852217 | Q25: 0.18819787 | R25: {=_xll.BDP(Inputs!$Q$25,"EBITDA_MARGIN")/100} -> #NAME?
B26: Net margin | C26: 0.11055873 | D26: 0.17371663 | E26: 0.019153049 | F26: -0.066293829 | G26: 0.065050128 | H26: 0.10594237 | I26: 0.0497669 | J26: 0.15756634 | K26: 0.14545809 | L26: 0.2043497 | M26: 0.10741519 | N26: 0.11619662 | O26: 0.096864754 | P26: 0.096629345 | Q26: 0.10238663 | R26: {=_xll.BDP(Inputs!$Q$25,"NET_INCOME_TO_COMMON_MARGIN")/100} -> #NAME?
B27: SG&A margin | C27: =754.3/3841.2 -> 0.19637093 | D27: 0.30191519 | E27: 0.19404908 | F27: =603.5/2859.3 -> 0.21106565 | G27: 0.3045776 | H27: 0.26573405 | I27: 0.29527972 | J27: 0.21829449 | K27: 0.28594087 | L27: =1368.2/5070.9 -> 0.26981404 | M27: 0.25954473 | N27: 0.11904378 | O27: 0.16126887 | P27: 0.21153582 | Q27: 0.26884357 | R27: {=_xll.BDP(Inputs!$Q$25,"TRAILING_12_MONTH_SG&A_EXPENSE")/_xll.BDP(Inputs!$Q$25,"TRAIL_12M_NET_SALES")} -> #NAME?
B28: R&D margin | C28: #VALUE! | D28: #VALUE! | G28: 0.03351153 | H28: 0.014014945 | J28: 0.036219432 | R28: {=_xll.BDP(Inputs!$Q$25,"TRAILING_12M_R&D_%_SALES")/100} -> #NAME? | T28: {=_xll.BDP(Inputs!$Q$25,"TRAILING_12M_R&D_%_SALES")/100} -> #NAME?
A30: x | B30: Returns | C30: MIDDLEBY CORP | D30: NORDSON CORP | E30: STANLEY BLACK & | F30: HILLENBRAND INC | G30: TENNANT CO | H30: KADANT INC | I30: JBT MAREL CORP | J30: MSA SAFETY INC | K30: ENERPAC TOOL GRO | L30: SNAP-ON INC | M30: THERMON GROUP HO | N30: FED SIGNAL CORP | O30: DOUGLAS DYNAMICS | P30: ESAB CORP | Q30: FORTUNE BRANDS I | R30: =R21 -> GEA GROUP AG
B32: ROIC | C32: 0.075913294 | D32: 0.10707024 | E32: 0.01785057 | F32: 0.0098943027 | G32: 0.077376435 | H32: 0.1004689 | I32: 0.044793926 | J32: 0.13465844 | K32: 0.16106336 | L32: 0.14832808 | M32: 0.088298512 | N32: 0.15936523 | O32: 0.14343477 | P32: 0.11254756 | Q32: 0.092949498 | R32: {=_xll.BDP(Inputs!$Q$25,"RETURN_ON_INV_CAPITAL")/100} -> #NAME?
B33: CROIC | C33: 0.098830754 | D33: 0.089585189 | E33: 0.048898009 | F33: 0.03887046 | G33: 0.07673433 | H33: 0.11316121 | I33: 0.024325641 | J33: 0.13442093 | K33: 0.10665185 | L33: 0.16815196 | M33: 0.079964365 | N33: 0.12801235 | O33: 0.068402685 | P33: 0.051996055 | Q33: 0.088195387 | R33: {=_xll.BDP(Inputs!$Q$25,"CF_FREE_CASH_FLOW")/_xll.BDP(Inputs!$Q$25,"TOTAL_INVESTED_CAPITAL")} -> #NAME?
B34: ROCE | C34: 0.33664098 | D34: 0.58653972 | E34: 0.20313802 | F34: -0.029576999 | G34: 0.20926401 | H34: 0.38087909 | I34: 0.17184325 | J34: 0.41817568 | K34: 0.40065047 | L34: 0.34276617 | M34: 0.32352893 | N34: 0.41122315 | O34: 0.31658833 | P34: 0.42003869 | Q34: 0.3368176 | R34: {=_xll.BDP(Inputs!$Q$25,"IS_OPER_INC")/_xll.BDP(Inputs!$Q$25,"CAPITAL_EMPLOYED")} -> #NAME?
B35: RONA | C35: 0.18034917 | D35: 0.22986251 | E35: 0.064289728 | F35: -0.012282146 | G35: 0.18373252 | H35: 0.19956463 | I35: 0.076674006 | J35: 0.34357428 | K35: 0.31018754 | L35: 0.24842164 | M35: 0.16102278 | N35: 0.23724812 | O35: 0.33574551 | P35: 0.24744933 | Q35: 0.30466557 | R35: {=_xll.BDP(Inputs!$Q$25,"IS_OPER_INC")/_xll.BDP(Inputs!$Q$25,"NET_ASSETS")} -> #NAME?
B36: ROE | C36: 0.12059906 | D36: 0.1559437 | E36: 0.053787202 | F36: -0.013206163 | G36: 0.095103799 | H36: 0.12209507 | I36: -0.046727862 | J36: 0.24300715 | K36: 0.22160309 | L36: 0.18178843 | M36: 0.10877001 | N36: 0.18765348 | O36: 0.25758892 | P36: 0.13565749 | Q36: 0.1684508 | R36: {=_xll.BDP(Inputs!$Q$25,"RETURN_COM_EQY")/100} -> #NAME?
B37: ROA | C37: 0.059154418 | D37: 0.08114939 | E37: 0.021282939 | F37: -0.0036188179 | G37: 0.050394355 | H37: 0.071986631 | I37: -0.025167463 | J37: 0.11555469 | K37: 0.1129384 | L37: 0.12529994 | M37: 0.0704007 | N37: 0.12285516 | O37: 0.10286409 | P37: 0.061010963 | Q37: 0.059293423 | R37: {=_xll.BDP(Inputs!$Q$25,"RETURN_ON_ASSET")/100} -> #NAME?
A39: x | B39: Efficiency | C39: MIDDLEBY CORP | D39: NORDSON CORP | E39: STANLEY BLACK & | F39: HILLENBRAND INC | G39: TENNANT CO | H39: KADANT INC | I39: JBT MAREL CORP | J39: MSA SAFETY INC | K39: ENERPAC TOOL GRO | L39: SNAP-ON INC | M39: THERMON GROUP HO | N39: FED SIGNAL CORP | O39: DOUGLAS DYNAMICS | P39: ESAB CORP | Q39: FORTUNE BRANDS I | R39: =R30 -> GEA GROUP AG
B41: Asset turnover | C41: 0.53492067 | D41: 0.49658077 | E41: 0.67464647 | F41: 0.57484922 | G41: 1.0405147 | H41: 0.69655159 | I41: 0.4953622 | J41: 0.76258411 | K41: 0.77093222 | L41: 0.63538345 | M41: 0.64636868 | N41: 1.0947193 | O41: 0.90394881 | P41: 0.6518813 | Q41: 0.67760897 | R41: {=_xll.BDP(Inputs!$Q$25,"ASSET_TURNOVER")} -> #NAME?
B42: Net operating asset turnover | C42: 0.95152718 | D42: 0.75460738 | E42: 1.0268719 | F42: 1.0668723 | G42: 1.5391148 | H42: 1.041133 | I42: 1.9073024 | J42: 1.2157794 | K42: 1.5468116 | L42: 0.97451354 | M42: 0.88299036 | N42: 1.309348 | O42: 1.5532642 | P42: 1.0117853 | Q42: 1.3740572 | R42: {=_xll.BDP(Inputs!$Q$25,"SALES_REV_TURN")/(_xll.BDP(Inputs!$Q$25,"BS_TOT_ASSET")-_xll.BDP(Inputs!$Q$25,"BS_CASH_CASH_EQUIVALENTS_AND_STI")-_xll.BDP(Inputs!$Q$25,"SHORT_AND_LONG_TERM_DEBT"))} -> #NAME?
B43: Fixed asset turnover | C43: 7.1458754 | D43: 5.0467619 | E43: 6.0011479 | F43: 7.2469902 | G43: 5.3331915 | H43: 5.8704694 | I43: 5.1837047 | J43: 6.0267371 | K43: 13.642154 | L43: 8.0394768 | M43: 5.8225123 | N43: 7.9878641 | O43: 6.1923173 | P43: 6.9100918 | Q43: 3.8419074 | R43: {=_xll.BDP(Inputs!$Q$25,"NET_FIX_ASSET_TURN")} -> #NAME?
B44: Revenue per employee thsnd of USD | C44: 361.82894 | D44: 348.04363 | E44: 312.61031 | F44: 273.61722 | G44: 278.51111 | H44: 292.606 | I44: 222.15574 | J44: 351.50596 | K44: 304.0495 | L44: 390.06923 | M44: 313.76212 | N44: 420.12766 | O44: 348.08189 | P44: #VALUE! | Q44: 408.70909 | R44: =_xll.BQL( Inputs!$Q$25, "sales_rev_turn(fpt=ltm,fa_adjusted=y,fs=mr)/1k", "currency=USD" )/IFERROR(VALUE(_xll.BDP(Inputs!$Q$25,"NUM_OF_EMPLOYEES")),_xll.BDP(Inputs!$Q$25,"NUM_OF_EMPLOYEES_CSR")) -> #NAME?
B45: EBIT per employee thsnd of USD | C45: 66.143086 | D45: 91.15375 | E45: 19.674227 | F45: 33.023923 | G45: 28.977778 | H45: 46.602 | I45: 21.721311 | J45: 74.2975 | K45: 67.979 | L45: 99.723077 | M45: 49.382653 | N45: 67.962295 | O45: 35.285117 | P45: #VALUE! | Q45: 66.581818 | R45: =_xll.BQL( Inputs!$Q$25, "is_oper_inc(fpt=ltm,fa_adjusted=y,fs=mr)/1k", "currency=USD" )/IFERROR(VALUE(_xll.BDP(Inputs!$Q$25,"NUM_OF_EMPLOYEES")),_xll.BDP(Inputs!$Q$25,"NUM_OF_EMPLOYEES_CSR")) -> #NAME?
A47: x | B47: Working Capital | C47: MIDDLEBY CORP | D47: NORDSON CORP | E47: STANLEY BLACK & | F47: HILLENBRAND INC | G47: TENNANT CO | H47: KADANT INC | I47: JBT MAREL CORP | J47: MSA SAFETY INC | K47: ENERPAC TOOL GRO | L47: SNAP-ON INC | M47: THERMON GROUP HO | N47: FED SIGNAL CORP | O47: DOUGLAS DYNAMICS | P47: ESAB CORP | Q47: FORTUNE BRANDS I | R47: =R39 -> GEA GROUP AG
B49: DSO | C49: 61.143465 | D49: 73.9014 | E49: 33.438371 | F49: 40.300248 | G49: 77.773279 | H49: 53.716178 | I49: 43.236265 | J49: 63.182689 | K49: 66.27633 | L49: 103.11503 | M49: 73.966846 | N49: 41.766307 | O49: 88.177052 | P49: 60.121953 | Q49: 48.607011 | R49: {=_xll.BDP(Inputs!$Q$25,"ACCT_RCV_DAYS")} -> #NAME?
B50: DIO | C50: 138.34164 | D50: 129.44811 | E50: 156.3695 | F50: 92.332358 | G50: 96.354195 | H50: 110.50205 | I50: 96.440021 | J50: 124.83803 | K50: 100.37075 | L50: 146.63249 | M50: 130.98696 | N50: 89.009777 | O50: 135.24814 | P50: 98.021133 | Q50: 148.18013 | R50: {=_xll.BDP(Inputs!$Q$25,"INVENT_DAYS")} -> #NAME?
B51: DPO | C51: 36.775726 | D51: 32.323259 | E51: 83.452523 | F51: 88.826772 | G51: 62.314651 | H51: 34.852499 | I51: 36.15084 | J51: 47.365705 | K51: 51.270962 | L51: 39.875162 | M51: 40.705335 | N51: 24.209184 | O51: 26.866385 | P51: 76.197769 | Q51: 78.588576 | R51: {=_xll.BDP(Inputs!$Q$25,"ACCOUNTS_PAYABLE_TURNOVER_DAYS")} -> #NAME?
B52: CCC | C52: 160.66554 | D52: 186.76316 | E52: 99.978206 | F52: 59.591557 | G52: 102.84946 | H52: 111.14823 | I52: 82.856363 | J52: 129.59446 | K52: 96.438209 | L52: 206.39789 | M52: 154.66168 | N52: 105.33915 | O52: 149.75598 | P52: 69.293602 | Q52: 102.3307 | R52: {=_xll.BDP(Inputs!$Q$25,"CASH_CONVERSION_CYCLE")} -> #NAME?
B53: Working capital intensity | C53: 0.34693594 | D53: 0.22439913 | E53: 0.056982772 | F53: 0.11885776 | G53: 0.24391606 | H53: 0.25790556 | I53: 0.10474855 | J53: 0.30410115 | K53: 0.39168622 | L53: 0.60996076 | M53: 0.32977627 | N53: 0.20794085 | O53: 0.27548636 | P53: 0.22121758 | Q53: 0.16952489 | R53: {=_xll.BDP(Inputs!$Q$25,"WORKING_CAPITAL_TO_SALES")} -> #NAME?
B54: Cash conversion ratio | C54: 1.0466756 | D54: 0.82521094 | E54: 1.9744916 | F54: -10.687151 | G54: 0.7847769 | H54: 0.90664635 | I54: 1.964527 | J54: 0.75462495 | K54: 0.66881328 | L54: 0.9047336 | M54: 0.79137881 | N54: 0.82196162 | O54: 0.46366209 | P54: 0.79427646 | Q54: 0.90500068 | R54: {=_xll.BDP(Inputs!$Q$25,"CF_CASH_FROM_OPER")/_xll.BDP(Inputs!$Q$25,"IS_OPER_INC")} -> #NAME?
B55: CFO margin | C55: 0.17723543 | D55: 0.20676927 | E55: 0.07203707 | F55: 0.060104311 | G55: 0.06971322 | H55: 0.14739639 | I55: 0.13554779 | J55: 0.16394085 | K55: 0.13794338 | L55: 0.23833294 | M55: 0.12669031 | N55: 0.12425463 | O55: 0.072349535 | P55: 0.12966966 | Q55: 0.14489043 | R55: {=_xll.BDP(Inputs!$Q$25,"CF_CASH_FROM_OPER")/_xll.BDP(Inputs!$Q$25,"SALES_REV_TURN")} -> #NAME?
A57: x | B57: Leverage & Coverage | C57: MIDDLEBY CORP | D57: NORDSON CORP | E57: STANLEY BLACK & | F57: HILLENBRAND INC | G57: TENNANT CO | H57: KADANT INC | I57: JBT MAREL CORP | J57: MSA SAFETY INC | K57: ENERPAC TOOL GRO | L57: SNAP-ON INC | M57: THERMON GROUP HO | N57: FED SIGNAL CORP | O57: DOUGLAS DYNAMICS | P57: ESAB CORP | Q57: FORTUNE BRANDS I | R57: =R47 -> GEA GROUP AG
B59: Net debt / EBITDA | C59: 2.4668918 | D59: 2.5118248 | E59: 5.5423495 | F59: 4.4426365 | G59: 1.15804 | H59: 0.72857238 | I59: 6.8110651 | J59: 1.3195478 | K59: 0.36584498 | L59: -0.11319943 | M59: 1.1470465 | N59: 0.60617963 | O59: 1.9587875 | P59: 1.6217217 | Q59: 3.2630895 | R59: {=_xll.BDP(Inputs!$Q$25,"NET_DEBT_TO_EBITDA")} -> #NAME?
B60: Net debt / FCF | C60: 2.8729361 | D60: 4.4824628 | E60: 8.3722444 | F60: 13.543399 | G60: 2.2456395 | H60: 1.7075674 | I60: 0.29429892 | J60: 1.6078818 | K60: 0.90542434 | L60: -0.058377425 | M60: 2.1212998 | N60: 0.84583115 | O60: 6.4145434 | P60: 5.5108232 | Q60: 5.1534247 | R60: {=_xll.BDP(Inputs!$Q$25,"NET_DEBT")/_xll.BDP(Inputs!$Q$25,"CF_FREE_CASH_FLOW")} -> #NAME?
B61: Interest coverage | C61: =695/79.6 -> 8.7311558 | D61: 7.5795173 | E61: 1.1243482 | F61: -0.1473251 | G61: 12.56044 | H61: 8.5506291 | I61: 6.1030928 | J61: 10.648567 | K61: =135.8/9.4 -> 14.446809 | L61: 27.131048 | M61: 7.7246489 | N61: 22.512 | O61: 5.8131717 | P61: =452.9/72.4 -> 6.2555249 | Q61: 6.1236515 | R61: {=_xll.BDP(Inputs!$Q$25,"IS_OPER_INC")/_xll.BDP(Inputs!$Q$25,"IS_INT_EXPENSE")} -> #NAME?
...

Sheet Trading Comps
B7: ="in "&IF(Inputs!$R$18="k","thousands",IF(Inputs!$R$18="MLN","millions","billions")&" of "&Inputs!$R$17) -> in thousands | D7: Current | E7: % of | I7: Enterprise Value / | S7: LTM | T7: Net | V7: Price / | Z7: LT
D8: Share | E8: 52-week | F8: Equity | G8: Enterprise | I8: LTM | J8: 2025 | K8: 2026 | L8: LTM | M8: 2025E | N8: 2026E | O8: LTM | P8: 2025E | Q8: 2026E | S8: EBITDA | T8: Debt / | V8: LTM | W8: 2025E | X8: 2026E | Z8: EPS
B9: Company | C9: Ticker | D9: Price | E9: High | F9: Value | G9: Value | I9: Sales | J9: Sales | K9: Sales | L9: EBITDA | M9: EBITDA | N9: EBITDA | O9: EBIT | P9: EBIT | Q9: EBIT | S9: Margin | T9: EBITDA | V9: EPS | W9: EPS | X9: EPS | Z9: Growth
B12: Tier I
B15: =+Inputs!B21 -> NORDSON CORP | C15: =+_xll.BDP(Inputs!E21,"TICKER_AND_EXCH_CODE") -> NDSN US | D15: =CONCATENATE(_xll.BDP(Inputs!E21,"CRNCY")," ",_xll.BDP(Inputs!E21,"PX_YEST_CLOSE")) -> USD 227 | E15: =_xll.BDP(Inputs!E21,"PX_YEST_CLOSE")/_xll.BDP(Inputs!E21,"HIGH_52WEEK") -> 0.85063329 | F15: =_xll.BDP(Inputs!$E21, "CUR_MKT_CAP", "SCALING_FORMAT=" & Inputs!$R$18) -> 12743054 | G15: =_xll.BDP(Inputs!$E21, "ENTERPRISE_VALUE", "SCALING_FORMAT=" & Inputs!$R$18) -> 14162691 | I15: {=G15/_xll.BQL(Inputs!$E21, "sales_rev_turn(fpt = ltm, fa_adjusted = y, fs = mr)/1"&IF(Inputs!$R$18="BLN","b",IF(Inputs!$R$18="MLN","m","k")))} -> 5.0865358 | J15: {=G15/_xll.BQL(Inputs!$E21, "sales_rev_turn(fpr = 2025, fpt = a, ae = e, fa_adjusted = y, fs = mr)/1"&IF(Inputs!$R$18="BLN","b",IF(Inputs!$R$18="MLN","m","k")))} -> 5.0503971 | K15: =G15/_xll.BQL(Inputs!$E21, "sales_rev_turn(fpr = 2026, fpt = a, ae = e, fa_adjusted = y, fs = mr)/1"&IF(Inputs!$R$18="BLN","b",IF(Inputs!$R$18="MLN","m","k"))) -> 4.8326333 | L15: =G15/_xll.BQL(Inputs!$E21, "ebitda(fpt = ltm, fa_adjusted = y, fs = mr)/1"&IF(Inputs!$R$18="BLN","b",IF(Inputs!$R$18="MLN","m","k"))) -> 16.126715 | M15: =G15/_xll.BQL(Inputs!$E21, "ebitda(fpr = 2025, fpt = a, ae = e, fa_adjusted = y, fs = mr)/1"&IF(Inputs!$R$18="BLN","b",IF(Inputs!$R$18="MLN","m","k"))) -> 15.808339 | N15: {=G15/_xll.BQL(Inputs!$E21,"EBITDA(fpr = 2026, fpt = a, ae = e, fa_adjusted = y, fs = mr)/1"&IF(Inputs!$R$18="BLN","b",IF(Inputs!$R$18="MLN","m","k")))} -> 15.042688 | O15: =G15/_xll.BQL(Inputs!$E21, "is_oper_inc(fpt = ltm, fa_adjusted = y, fs = mr)/1"&IF(Inputs!$R$18="BLN","b",IF(Inputs!$R$18="MLN","m","k"))) -> 19.421432 | P15: =G15/_xll.BQL(Inputs!$E21, "is_oper_inc(fpr = 2025, fpt = a, ae = e, fa_adjusted = y, fs = mr)/1"&IF(Inputs!$R$18="BLN","b",IF(Inputs!$R$18="MLN","m","k"))) -> 19.149122 | Q15: =G15/_xll.BQL(Inputs!$E21, "is_oper_inc(fpr = 2026, fpt = a, ae = e, fa_adjusted = y, fs = mr)/1"&IF(Inputs!$R$18="BLN","b",IF(Inputs!$R$18="MLN","m","k"))) -> 17.74369 | S15: =_xll.BQL(Inputs!$E21, "ebitda(fpt = ltm, fa_adjusted = y, fs = mr)/1"&IF(Inputs!$R$18="BLN","b",IF(Inputs!$R$18="MLN","m","k")))/_xll.BQL(Inputs!$E21, "sales_rev_turn(fpt = ltm, fa_adjusted = y, fs = mr)/1"&IF(Inputs!$R$18="BLN","b",IF(Inputs!$R$18="MLN","m","k"))) -> 0.31541053 | T15: =_xll.BDP(Inputs!$E21,"TOT_DEBT_TO_EBITDA") -> 2.6908882 | V15: =F15/_xll.BQL(Inputs!$E21, "earn_for_common(fpt = ltm, fa_adjusted = y, fs = mr)/1"&IF(Inputs!$R$18="BLN","b",IF(Inputs!$R$18="MLN","m","k"))) -> 25.632215 | W15: =F15/_xll.BQL(Inputs!$E21, "EARN_FOR_COMMON(fpr = 2025, fpt = a, ae = e, fa_adjusted = y, fs = mr)/1"&IF(Inputs!$R$18="BLN","b",IF(Inputs!$R$18="MLN","m","k"))) -> 22.385689 | X15: =F15/_xll.BQL(Inputs!$E21, "EARN_FOR_COMMON(fpr = 2026, fpt = a, ae = e, fa_adjusted = y, fs = mr)/1"&IF(Inputs!$R$18="BLN","b",IF(Inputs!$R$18="MLN","m","k"))) -> 20.628172 | Z15: =(_xll.BQL(Inputs!$E21, "EARN_FOR_COMMON(fpr = 2028, fpt = a, ae = e, fa_adjusted = y, fs = mr)")/_xll.BQL(Inputs!$E21, "EARN_FOR_COMMON(fpr = 2025, fpt = a, ae = e, fa_adjusted = y, fs = mr)"))^(1/3)-1 -> 0.084951831
B16: =+Inputs!B22 -> STANLEY BLACK & | C16: SWK US | D16: USD 76,67 | E16: 0.69146825 | F16: =_xll.BDP(Inputs!$E22, "CUR_MKT_CAP", "SCALING_FORMAT=" & Inputs!$R$18) -> 11361751 | G16: =_xll.BDP(Inputs!$E22, "ENTERPRISE_VALUE", "SCALING_FORMAT=" & Inputs!$R$18) -> 17300578 | I16: {=G16/_xll.BQL(Inputs!$E22, "sales_rev_turn(fpt = ltm, fa_adjusted = y, fs = mr)/1"&IF(Inputs!$R$18="BLN","b",IF(Inputs!$R$18="MLN","m","k")))} -> 1.1410786 | J16: =G16/_xll.BQL(Inputs!$E22, "sales_rev_turn(fpr = 2025, fpt = a, ae = e, fa_adjusted = y, fs = mr)/1"&IF(Inputs!$R$18="BLN","b",IF(Inputs!$R$18="MLN","m","k"))) -> 1.1330178 | K16: =G16/_xll.BQL(Inputs!$E22, "sales_rev_turn(fpr = 2026, fpt = a, ae = e, fa_adjusted = y, fs = mr)/1"&IF(Inputs!$R$18="BLN","b",IF(Inputs!$R$18="MLN","m","k"))) -> 1.0890227 | L16: =G16/_xll.BQL(Inputs!$E22, "ebitda(fpt = ltm, fa_adjusted = y, fs = mr)/1"&IF(Inputs!$R$18="BLN","b",IF(Inputs!$R$18="MLN","m","k"))) -> 11.480144 | M16: {=G16/_xll.BQL(Inputs!$E22, "ebitda(fpr = 2025, fpt = a, ae = e, fa_adjusted = y, fs = mr)/1"&IF(Inputs!$R$18="BLN","b",IF(Inputs!$R$18="MLN","m","k")))} -> 10.344761 | N16: =G16/_xll.BQL(Inputs!$E22, "ebitda(fpr = 2026, fpt = a, ae = e, fa_adjusted = y, fs = mr)/1"&IF(Inputs!$R$18="BLN","b",IF(Inputs!$R$18="MLN","m","k"))) -> 9.0514626 | O16: =G16/_xll.BQL(Inputs!$E22, "is_oper_inc(fpt = ltm, fa_adjusted = y, fs = mr)/1"&IF(Inputs!$R$18="BLN","b",IF(Inputs!$R$18="MLN","m","k"))) -> 18.130976 | P16: =G16/_xll.BQL(Inputs!$E22, "is_oper_inc(fpr = 2025, fpt = a, ae = e, fa_adjusted = y, fs = mr)/1"&IF(Inputs!$R$18="BLN","b",IF(Inputs!$R$18="MLN","m","k"))) -> 12.179217 | Q16: =G16/_xll.BQL(Inputs!$E22, "is_oper_inc(fpr = 2026, fpt = a, ae = e, fa_adjusted = y, fs = mr)/1"&IF(Inputs!$R$18="BLN","b",IF(Inputs!$R$18="MLN","m","k"))) -> 10.404276 | S16: =_xll.BQL(Inputs!$E22, "ebitda(fpt = ltm, fa_adjusted = y, fs = mr)/1"&IF(Inputs!$R$18="BLN","b",IF(Inputs!$R$18="MLN","m","k")))/_xll.BQL(Inputs!$E22, "sales_rev_turn(fpt = ltm, fa_adjusted = y, fs = mr)/1"&IF(Inputs!$R$18="BLN","b",IF(Inputs!$R$18="MLN","m","k"))) -> 0.099395842 | T16: =_xll.BDP(Inputs!$E22,"TOT_DEBT_TO_EBITDA") -> 5.7953107 | V16: =F16/_xll.BQL(Inputs!$E22, "earn_for_common(fpt = ltm, fa_adjusted = y, fs = mr)/1"&IF(Inputs!$R$18="BLN","b",IF(Inputs!$R$18="MLN","m","k"))) -> 15.4204 | W16: =F16/_xll.BQL(Inputs!$E22, "EARN_FOR_COMMON(fpr = 2025, fpt = a, ae = e, fa_adjusted = y, fs = mr)/1"&IF(Inputs!$R$18="BLN","b",IF(Inputs!$R$18="MLN","m","k"))) -> 16.189772 | X16: =F16/_xll.BQL(Inputs!$E22, "EARN_FOR_COMMON(fpr = 2026, fpt = a, ae = e, fa_adjusted = y, fs = mr)/1"&IF(Inputs!$R$18="BLN","b",IF(Inputs!$R$18="MLN","m","k"))) -> 12.83717 | Z16: =(_xll.BQL(Inputs!$E22, "EARN_FOR_COMMON(fpr = 2028, fpt = a, ae = e, fa_adjusted = y, fs = mr)")/_xll.BQL(Inputs!$E22, "EARN_FOR_COMMON(fpr = 2025, fpt = a, ae = e, fa_adjusted = y, fs = mr)"))^(1/3)-1 -> 0.14970242
B17: =+Inputs!B23 -> HILLENBRAND INC | C17: HI US | D17: USD 24,62 | E17: 0.69176735 | F17: =_xll.BDP(Inputs!$E23, "CUR_MKT_CAP", "SCALING_FORMAT=" & Inputs!$R$18) -> 1848744.1 | G17: =_xll.BDP(Inputs!$E23, "ENTERPRISE_VALUE", "SCALING_FORMAT=" & Inputs!$R$18) -> 3059528 | I17: {=G17/_xll.BQL(Inputs!$E23, "sales_rev_turn(fpt = ltm, fa_adjusted = y, fs = mr)/1"&IF(Inputs!$R$18="BLN","b",IF(Inputs!$R$18="MLN","m","k")))} -> 1.0700269 | J17: =G17/_xll.BQL(Inputs!$E23, "sales_rev_turn(fpr = 2025, fpt = a, ae = e, fa_adjusted = y, fs = mr)/1"&IF(Inputs!$R$18="BLN","b",IF(Inputs!$R$18="MLN","m","k"))) -> 1.1705511 | K17: =G17/_xll.BQL(Inputs!$E23, "sales_rev_turn(fpr = 2026, fpt = a, ae = e, fa_adjusted = y, fs = mr)/1"&IF(Inputs!$R$18="BLN","b",IF(Inputs!$R$18="MLN","m","k"))) -> 1.2758666 | L17: =G17/_xll.BQL(Inputs!$E23, "ebitda(fpt = ltm, fa_adjusted = y, fs = mr)/1"&IF(Inputs!$R$18="BLN","b",IF(Inputs!$R$18="MLN","m","k"))) -> 5.5416193 | M17: =G17/_xll.BQL(Inputs!$E23, "ebitda(fpr = 2025, fpt = a, ae = e, fa_adjusted = y, fs = mr)/1"&IF(Inputs!$R$18="BLN","b",IF(Inputs!$R$18="MLN","m","k"))) -> 8.1316359 | N17: =G17/_xll.BQL(Inputs!$E23, "ebitda(fpr = 2026, fpt = a, ae = e, fa_adjusted = y, fs = mr)/1"&IF(Inputs!$R$18="BLN","b",IF(Inputs!$R$18="MLN","m","k"))) -> 8.1641841 | O17: =G17/_xll.BQL(Inputs!$E23, "is_oper_inc(fpt = ltm, fa_adjusted = y, fs = mr)/1"&IF(Inputs!$R$18="BLN","b",IF(Inputs!$R$18="MLN","m","k"))) -> 8.8656274 | P17: =G17/_xll.BQL(Inputs!$E23, "is_oper_inc(fpr = 2025, fpt = a, ae = e, fa_adjusted = y, fs = mr)/1"&IF(Inputs!$R$18="BLN","b",IF(Inputs!$R$18="MLN","m","k"))) -> 8.9722229 | Q17: =G17/_xll.BQL(Inputs!$E23, "is_oper_inc(fpr = 2026, fpt = a, ae = e, fa_adjusted = y, fs = mr)/1"&IF(Inputs!$R$18="BLN","b",IF(Inputs!$R$18="MLN","m","k"))) -> 10.130887 | S17: =_xll.BQL(Inputs!$E23, "ebitda(fpt = ltm, fa_adjusted = y, fs = mr)/1"&IF(Inputs!$R$18="BLN","b",IF(Inputs!$R$18="MLN","m","k")))/_xll.BQL(Inputs!$E23, "sales_rev_turn(fpt = ltm, fa_adjusted = y, fs = mr)/1"&IF(Inputs!$R$18="BLN","b",IF(Inputs!$R$18="MLN","m","k"))) -> 0.19308922 | T17: =_xll.BDP(Inputs!$E23,"TOT_DEBT_TO_EBITDA") -> 4.8916161 | V17: =F17/_xll.BQL(Inputs!$E23, "earn_for_common(fpt = ltm, fa_adjusted = y, fs = mr)/1"&IF(Inputs!$R$18="BLN","b",IF(Inputs!$R$18="MLN","m","k"))) -> 14.313848 | W17: =F17/_xll.BQL(Inputs!$E23, "EARN_FOR_COMMON(fpr = 2025, fpt = a, ae = e, fa_adjusted = y, fs = mr)/1"&IF(Inputs!$R$18="BLN","b",IF(Inputs!$R$18="MLN","m","k"))) -> 11.590872 | X17: =F17/_xll.BQL(Inputs!$E23, "EARN_FOR_COMMON(fpr = 2026, fpt = a, ae = e, fa_adjusted = y, fs = mr)/1"&IF(Inputs!$R$18="BLN","b",IF(Inputs!$R$18="MLN","m","k"))) -> 11.590872 | Z17: =(_xll.BQL(Inputs!$E23, "EARN_FOR_COMMON(fpr = 2028, fpt = a, ae = e, fa_adjusted = y, fs = mr)")/_xll.BQL(Inputs!$E23, "EARN_FOR_COMMON(fpr = 2025, fpt = a, ae = e, fa_adjusted = y, fs = mr)"))^(1/3)-1 -> #VALUE!
B18: =+Inputs!B24 -> TENNANT CO | C18: TNC US | D18: USD 80,66 | E18: 0.81871701 | F18: =_xll.BDP(Inputs!$E24, "CUR_MKT_CAP", "SCALING_FORMAT=" & Inputs!$R$18) -> 1475960.4 | G18: =_xll.BDP(Inputs!$E24, "ENTERPRISE_VALUE", "SCALING_FORMAT=" & Inputs!$R$18) -> 1605484.6 | I18: {=G18/_xll.BQL(Inputs!$E24, "sales_rev_turn(fpt = ltm, fa_adjusted = y, fs = mr)/1"&IF(Inputs!$R$18="BLN","b",IF(Inputs!$R$18="MLN","m","k")))} -> 1.2810058 | J18: =G18/_xll.BQL(Inputs!$E24, "sales_rev_turn(fpr = 2025, fpt = a, ae = e, fa_adjusted = y, fs = mr)/1"&IF(Inputs!$R$18="BLN","b",IF(Inputs!$R$18="MLN","m","k"))) -> 1.3003385 | K18: =G18/_xll.BQL(Inputs!$E24, "sales_rev_turn(fpr = 2026, fpt = a, ae = e, fa_adjusted = y, fs = mr)/1"&IF(Inputs!$R$18="BLN","b",IF(Inputs!$R$18="MLN","m","k"))) -> 1.2286872 | L18: =G18/_xll.BQL(Inputs!$E24, "ebitda(fpt = ltm, fa_adjusted = y, fs = mr)/1"&IF(Inputs!$R$18="BLN","b",IF(Inputs!$R$18="MLN","m","k"))) -> 8.5900729 | M18: =G18/_xll.BQL(Inputs!$E24, "ebitda(fpr = 2025, fpt = a, ae = e, fa_adjusted = y, fs = mr)/1"&IF(Inputs!$R$18="BLN","b",IF(Inputs!$R$18="MLN","m","k"))) -> 8.1496681 | N18: =G18/_xll.BQL(Inputs!$E24, "ebitda(fpr = 2026, fpt = a, ae = e, fa_adjusted = y, fs = mr)/1"&IF(Inputs!$R$18="BLN","b",IF(Inputs!$R$18="MLN","m","k"))) -> 7.4673703 | O18: =G18/_xll.BQL(Inputs!$E24, "is_oper_inc(fpt = ltm, fa_adjusted = y, fs = mr)/1"&IF(Inputs!$R$18="BLN","b",IF(Inputs!$R$18="MLN","m","k"))) -> 12.311999 | P18: =G18/_xll.BQL(Inputs!$E24, "is_oper_inc(fpr = 2025, fpt = a, ae = e, fa_adjusted = y, fs = mr)/1"&IF(Inputs!$R$18="BLN","b",IF(Inputs!$R$18="MLN","m","k"))) -> 14.207828 | Q18: =G18/_xll.BQL(Inputs!$E24, "is_oper_inc(fpr = 2026, fpt = a, ae = e, fa_adjusted = y, fs = mr)/1"&IF(Inputs!$R$18="BLN","b",IF(Inputs!$R$18="MLN","m","k"))) -> 11.495117 | S18: =_xll.BQL(Inputs!$E24, "ebitda(fpt = ltm, fa_adjusted = y, fs = mr)/1"&IF(Inputs!$R$18="BLN","b",IF(Inputs!$R$18="MLN","m","k")))/_xll.BQL(Inputs!$E24, "sales_rev_turn(fpt = ltm, fa_adjusted = y, fs = mr)/1"&IF(Inputs!$R$18="BLN","b",IF(Inputs!$R$18="MLN","m","k"))) -> 0.14912631 | T18: =_xll.BDP(Inputs!$E24,"TOT_DEBT_TO_EBITDA") -> 1.7108351 | V18: =F18/_xll.BQL(Inputs!$E24, "earn_for_common(fpt = ltm, fa_adjusted = y, fs = mr)/1"&IF(Inputs!$R$18="BLN","b",IF(Inputs!$R$18="MLN","m","k"))) -> 15.979077 | W18: =F18/_xll.BQL(Inputs!$E24, "EARN_FOR_COMMON(fpr = 2025, fpt = a, ae = e, fa_adjusted = y, fs = mr)/1"&IF(Inputs!$R$18="BLN","b",IF(Inputs!$R$18="MLN","m","k"))) -> 14.908691 | X18: =F18/_xll.BQL(Inputs!$E24, "EARN_FOR_COMMON(fpr = 2026, fpt = a, ae = e, fa_adjusted = y, fs = mr)/1"&IF(Inputs!$R$18="BLN","b",IF(Inputs!$R$18="MLN","m","k"))) -> 13.02318 | Z18: =(_xll.BQL(Inputs!$E24, "EARN_FOR_COMMON(fpr = 2028, fpt = a, ae = e, fa_adjusted = y, fs = mr)")/_xll.BQL(Inputs!$E24, "EARN_FOR_COMMON(fpr = 2025, fpt = a, ae = e, fa_adjusted = y, fs = mr)"))^(1/3)-1 -> 0.14342805
B19: =+Inputs!B25 -> KADANT INC | C19: KAI US | D19: USD 305,45 | E19: 0.71043145 | F19: =_xll.BDP(Inputs!$E25, "CUR_MKT_CAP", "SCALING_FORMAT=" & Inputs!$R$18) -> 3514513.9 | G19: =_xll.BDP(Inputs!$E25, "ENTERPRISE_VALUE", "SCALING_FORMAT=" & Inputs!$R$18) -> 3857415.9 | I19: {=G19/_xll.BQL(Inputs!$E25, "sales_rev_turn(fpt = ltm, fa_adjusted = y, fs = mr)/1"&IF(Inputs!$R$18="BLN","b",IF(Inputs!$R$18="MLN","m","k")))} -> 3.7665627 | J19: =G19/_xll.BQL(Inputs!$E25, "sales_rev_turn(fpr = 2025, fpt = a, ae = e, fa_adjusted = y, fs = mr)/1"&IF(Inputs!$R$18="BLN","b",IF(Inputs!$R$18="MLN","m","k"))) -> 3.747793 | K19: =G19/_xll.BQL(Inputs!$E25, "sales_rev_turn(fpr = 2026, fpt = a, ae = e, fa_adjusted = y, fs = mr)/1"&IF(Inputs!$R$18="BLN","b",IF(Inputs!$R$18="MLN","m","k"))) -> 3.5675523 | L19: =G19/_xll.BQL(Inputs!$E25, "ebitda(fpt = ltm, fa_adjusted = y, fs = mr)/1"&IF(Inputs!$R$18="BLN","b",IF(Inputs!$R$18="MLN","m","k"))) -> 18.106024 | M19: =G19/_xll.BQL(Inputs!$E25, "ebitda(fpr = 2025, fpt = a, ae = e, fa_adjusted = y, fs = mr)/1"&IF(Inputs!$R$18="BLN","b",IF(Inputs!$R$18="MLN","m","k"))) -> 18.567586 | N19: =G19/_xll.BQL(Inputs!$E25, "ebitda(fpr = 2026, fpt = a, ae = e, fa_adjusted = y, fs = mr)/1"&IF(Inputs!$R$18="BLN","b",IF(Inputs!$R$18="MLN","m","k"))) -> 16.955674 | O19: =G19/_xll.BQL(Inputs!$E25, "is_oper_inc(fpt = ltm, fa_adjusted = y, fs = mr)/1"&IF(Inputs!$R$18="BLN","b",IF(Inputs!$R$18="MLN","m","k"))) -> 23.649604 | P19: =G19/_xll.BQL(Inputs!$E25, "is_oper_inc(fpr = 2025, fpt = a, ae = e, fa_adjusted = y, fs = mr)/1"&IF(Inputs!$R$18="BLN","b",IF(Inputs!$R$18="MLN","m","k"))) -> 24.298683 | Q19: =G19/_xll.BQL(Inputs!$E25, "is_oper_inc(fpr = 2026, fpt = a, ae = e, fa_adjusted = y, fs = mr)/1"&IF(Inputs!$R$18="BLN","b",IF(Inputs!$R$18="MLN","m","k"))) -> 21.701356 | S19: =_xll.BQL(Inputs!$E25, "ebitda(fpt = ltm, fa_adjusted = y, fs = mr)/1"&IF(Inputs!$R$18="BLN","b",IF(Inputs!$R$18="MLN","m","k")))/_xll.BQL(Inputs!$E25, "sales_rev_turn(fpt = ltm, fa_adjusted = y, fs = mr)/1"&IF(Inputs!$R$18="BLN","b",IF(Inputs!$R$18="MLN","m","k"))) -> 0.20802815 | T19: =_xll.BDP(Inputs!$E25,"TOT_DEBT_TO_EBITDA") -> 1.1807035 | V19: =F19/_xll.BQL(Inputs!$E25, "earn_for_common(fpt = ltm, fa_adjusted = y, fs = mr)/1"&IF(Inputs!$R$18="BLN","b",IF(Inputs!$R$18="MLN","m","k"))) -> 32.64512 | W19: =F19/_xll.BQL(Inputs!$E25, "EARN_FOR_COMMON(fpr = 2025, fpt = a, ae = e, fa_adjusted = y, fs = mr)/1"&IF(Inputs!$R$18="BLN","b",IF(Inputs!$R$18="MLN","m","k"))) -> 32.617299 | X19: =F19/_xll.BQL(Inputs!$E25, "EARN_FOR_COMMON(fpr = 2026, fpt = a, ae = e, fa_adjusted = y, fs = mr)/1"&IF(Inputs!$R$18="BLN","b",IF(Inputs!$R$18="MLN","m","k"))) -> 28.515326 | Z19: =(_xll.BQL(Inputs!$E25, "EARN_FOR_COMMON(fpr = 2028, fpt = a, ae = e, fa_adjusted = y, fs = mr)")/_xll.BQL(Inputs!$E25, "EARN_FOR_COMMON(fpr = 2025, fpt = a, ae = e, fa_adjusted = y, fs = mr)"))^(1/3)-1 -> #VALUE!
B21: Mean | I21: =AVERAGE(I15:I19) -> 2.469042 | J21: =AVERAGE(J15:J19) -> 2.4804195 | K21: =AVERAGE(K15:K19) -> 2.3987524 | L21: =AVERAGE(L15:L19) -> 11.968915 | M21: =AVERAGE(M15:M19) -> 12.200398 | N21: =AVERAGE(N15:N19) -> 11.336276 | O21: =AVERAGE(O15:O19) -> 16.475928 | P21: =AVERAGE(P15:P19) -> 15.761415 | Q21: =AVERAGE(Q15:Q19) -> 14.295065 | S21: =AVERAGE(S15:S19) -> 0.19301001 | T21: =AVERAGE(T15:T19) -> 3.2538707 | V21: =AVERAGE(V15:V19) -> 20.798132 | W21: =AVERAGE(W15:W19) -> 19.538465 | X21: =AVERAGE(X15:X19) -> 17.318944 | Z21: =AVERAGE(Z15:Z19) -> #VALUE!
B22: Median | I22: =MEDIAN(I15:I19) -> 1.2810058 | J22: =MEDIAN(J15:J19) -> 1.3003385 | K22: =MEDIAN(K15:K19) -> 1.2758666 | L22: =MEDIAN(L15:L19) -> 11.480144 | M22: =MEDIAN(M15:M19) -> 10.344761 | N22: =MEDIAN(N15:N19) -> 9.0514626 | O22: =MEDIAN(O15:O19) -> 18.130976 | P22: =MEDIAN(P15:P19) -> 14.207828 | Q22: =MEDIAN(Q15:Q19) -> 11.495117 | S22: =MEDIAN(S15:S19) -> 0.19308922 | T22: =MEDIAN(T15:T19) -> 2.6908882 | V22: =MEDIAN(V15:V19) -> 15.979077 | W22: =MEDIAN(W15:W19) -> 16.189772 | X22: =MEDIAN(X15:X19) -> 13.02318 | Z22: =MEDIAN(Z15:Z19) -> #VALUE!
B24: Tier II
B27: =+Inputs!H21 -> JBT MAREL CORP | C27: =+_xll.BDP(Inputs!K21,"TICKER_AND_EXCH_CODE") -> JBTM US | D27: =CONCATENATE(_xll.BDP(Inputs!K21,"CRNCY")," ",_xll.BDP(Inputs!K21,"PX_YEST_CLOSE")) -> USD 137,35 | E27: =_xll.BDP(Inputs!K21,"PX_YEST_CLOSE")/_xll.BDP(Inputs!K21,"HIGH_52WEEK") -> 0.92326824 | F27: =_xll.BDP(Inputs!$K21, "CUR_MKT_CAP", "SCALING_FORMAT=" & Inputs!$R$18) -> 7123062.3 | G27: =_xll.BDP(Inputs!$K21, "ENTERPRISE_VALUE", "SCALING_FORMAT=" & Inputs!$R$18) -> 8059605.3 | I27: =G27/_xll.BQL(Inputs!$K21, "sales_rev_turn(fpt = ltm, fa_adjusted = y, fs = mr)/1"&IF(Inputs!$R$18="BLN","b",IF(Inputs!$R$18="MLN","m","k"))) -> 2.9736949 | J27: =G27/_xll.BQL(Inputs!$K21, "sales_rev_turn(fpr = 2025, fpt = a, ae = e, fa_adjusted = y, fs = mr)/1"&IF(Inputs!$R$18="BLN","b",IF(Inputs!$R$18="MLN","m","k"))) -> 2.1753321 | K27: =G27/_xll.BQL(Inputs!$K21, "sales_rev_turn(fpr = 2026, fpt = a, ae = e, fa_adjusted = y, fs = mr)/1"&IF(Inputs!$R$18="BLN","b",IF(Inputs!$R$18="MLN","m","k"))) -> 2.0757199 | L27: =G27/_xll.BQL(Inputs!$K21, "ebitda(fpt = ltm, fa_adjusted = y, fs = mr)/1"&IF(Inputs!$R$18="BLN","b",IF(Inputs!$R$18="MLN","m","k"))) -> 17.783772 | M27: =G27/_xll.BQL(Inputs!$K21, "ebitda(fpr = 2025, fpt = a, ae = e, fa_adjusted = y, fs = mr)/1"&IF(Inputs!$R$18="BLN","b",IF(Inputs!$R$18="MLN","m","k"))) -> 13.67967 | N27: =G27/_xll.BQL(Inputs!$K21, "ebitda(fpr = 2026, fpt = a, ae = e, fa_adjusted = y, fs = mr)/1"&IF(Inputs!$R$18="BLN","b",IF(Inputs!$R$18="MLN","m","k"))) -> 12.211523 | O27: =G27/_xll.BQL(Inputs!$K21, "is_oper_inc(fpt = ltm, fa_adjusted = y, fs = mr)/1"&IF(Inputs!$R$18="BLN","b",IF(Inputs!$R$18="MLN","m","k"))) -> 30.413605 | P27: =G27/_xll.BQL(Inputs!$K21, "is_oper_inc(fpr = 2025, fpt = a, ae = e, fa_adjusted = y, fs = mr)/1"&IF(Inputs!$R$18="BLN","b",IF(Inputs!$R$18="MLN","m","k"))) -> 17.752435 | Q27: =G27/_xll.BQL(Inputs!$K21, "is_oper_inc(fpr = 2026, fpt = a, ae = e, fa_adjusted = y, fs = mr)/1"&IF(Inputs!$R$18="BLN","b",IF(Inputs!$R$18="MLN","m","k"))) -> 14.795053 | S27: =_xll.BQL(Inputs!$K21, "ebitda(fpt = ltm, fa_adjusted = y, fs = mr)/1"&IF(Inputs!$R$18="BLN","b",IF(Inputs!$R$18="MLN","m","k")))/_xll.BQL(Inputs!$K21, "sales_rev_turn(fpt = ltm, fa_adjusted = y, fs = mr)/1"&IF(Inputs!$R$18="BLN","b",IF(Inputs!$R$18="MLN","m","k"))) -> 0.16721396 | T27: =_xll.BDP(Inputs!$K21,"TOT_DEBT_TO_EBITDA") -> 7.2318404 | V27: =F27/_xll.BQL(Inputs!$K21, "earn_for_common(fpt = ltm, fa_adjusted = y, fs = mr)/1"&IF(Inputs!$R$18="BLN","b",IF(Inputs!$R$18="MLN","m","k"))) -> -556.53321 | W27: =F27/_xll.BQL(Inputs!$K21, "EARN_FOR_COMMON(fpr = 2025, fpt = a, ae = e, fa_adjusted = y, fs = mr)/1"&IF(Inputs!$R$18="BLN","b",IF(Inputs!$R$18="MLN","m","k"))) -> 23.258979 | X27: =F27/_xll.BQL(Inputs!$K21, "EARN_FOR_COMMON(fpr = 2026, fpt = a, ae = e, fa_adjusted = y, fs = mr)/1"&IF(Inputs!$R$18="BLN","b",IF(Inputs!$R$18="MLN","m","k"))) -> 19.986146 | Z27: =(_xll.BQL(Inputs!$K21, "EARN_FOR_COMMON(fpr = 2028, fpt = a, ae = e, fa_adjusted = y, fs = mr)")/_xll.BQL(Inputs!$K21, "EARN_FOR_COMMON(fpr = 2025, fpt = a, ae = e, fa_adjusted = y, fs = mr)"))^(1/3)-1 -> #VALUE!
