Workbook
Name COOLFUCNTION: _xlfn.LAMBDA(_xldudf_BOARDFLARE_EXEC("workbook-settings:coolfucntion"))
Name COOLFUCNTION: _xlfn.LAMBDA(_xldudf_BOARDFLARE_EXEC("workbook-settings:coolfucntion"))
Name COOLFUCNTION: _xlfn.LAMBDA(_xldudf_BOARDFLARE_EXEC("workbook-settings:coolfucntion"))
Name COOLFUCNTION: _xlfn.LAMBDA(_xldudf_BOARDFLARE_EXEC("workbook-settings:coolfucntion"))
Name COOLFUCNTION: _xlfn.LAMBDA(_xldudf_BOARDFLARE_EXEC("workbook-settings:coolfucntion"))
Name COOLFUCNTION: _xlfn.LAMBDA(_xldudf_BOARDFLARE_EXEC("workbook-settings:coolfucntion"))
Name COOLFUCNTION: _xlfn.LAMBDA(_xldudf_BOARDFLARE_EXEC("workbook-settings:coolfucntion"))
Name COOLFUCNTION: _xlfn.LAMBDA(_xldudf_BOARDFLARE_EXEC("workbook-settings:coolfucntion"))
Name COOLFUCNTION: _xlfn.LAMBDA(_xldudf_BOARDFLARE_EXEC("workbook-settings:coolfucntion"))
Name COOLFUCNTION: _xlfn.LAMBDA(_xldudf_BOARDFLARE_EXEC("workbook-settings:coolfucntion"))
Name COOLFUCNTION: _xlfn.LAMBDA(_xldudf_BOARDFLARE_EXEC("workbook-settings:coolfucntion"))
Name Sectors: #REF!
Name Sectors: #REF!
Name Sectors: #REF!
Name Sectors: #REF!
Name Sectors: #REF!
Name Sectors: #REF!
Name Sectors: #REF!
Name Sectors: #REF!

Sheet Dashboard
C154: =+C155+1 -> 45947
C155: =+C156+1 -> 45946
C156: =+C157+1 -> 45945
C157: =+C158+1 -> 45944
C158: =+C159+1 -> 45943
C159: =+C160+1 -> 45942
C160: =+C161+1 -> 45941 | L160: =IF(FCFF!$R$157="Revenue Exit",FCFF!$AF$169,IF(FCFF!$R$157="EBITDA Exit",FCFF!Z169,FCFF!AL169)) -> 20.277514
C161: =+C162+1 -> 45940
C162: =+C163+1 -> 45939 | E162: =IF(FCFF!$R$157="Revenue Exit",FCFF!$AF$169,IF(FCFF!$R$157="EBITDA Exit",FCFF!Z169,FCFF!AL169)) -> 20.277514
C163: =+C164+1 -> 45938 | E163: =E164+($E$162-$E$193)/COUNTA($C$162:$C$192) -> 19.95711
C164: =+C165+1 -> 45937 | E164: =E165+($E$162-$E$193)/COUNTA($C$162:$C$192) -> 19.636707
C165: =+C166+1 -> 45936 | E165: =E166+($E$162-$E$193)/COUNTA($C$162:$C$192) -> 19.316303
C166: =+C167+1 -> 45935 | E166: =E167+($E$162-$E$193)/COUNTA($C$162:$C$192) -> 18.995899
C167: =+C168+1 -> 45934 | E167: =E168+($E$162-$E$193)/COUNTA($C$162:$C$192) -> 18.675496
C168: =+C169+1 -> 45933 | E168: =E169+($E$162-$E$193)/COUNTA($C$162:$C$192) -> 18.355092
C169: =+C170+1 -> 45932 | E169: =E170+($E$162-$E$193)/COUNTA($C$162:$C$192) -> 18.034688
C170: =+C171+1 -> 45931 | E170: =E171+($E$162-$E$193)/COUNTA($C$162:$C$192) -> 17.714285
C171: =+C172+1 -> 45930 | E171: =E172+($E$162-$E$193)/COUNTA($C$162:$C$192) -> 17.393881
C172: =+C173+1 -> 45929 | E172: =E173+($E$162-$E$193)/COUNTA($C$162:$C$192) -> 17.073477
C173: =+C174+1 -> 45928 | E173: =E174+($E$162-$E$193)/COUNTA($C$162:$C$192) -> 16.753073
C174: =+C175+1 -> 45927 | E174: =E175+($E$162-$E$193)/COUNTA($C$162:$C$192) -> 16.43267
... C192: =+C193+1 -> 45909 | E192: =E193+($E$162-$E$193)/COUNTA($C$162:$C$192) -> 10.665404
B193: TODAY | C193: =+'Stock Data'!AM4 -> 45908 | D193: =_xlfn.XLOOKUP(C193,'Stock Data'!$AM$4:$AM$1051,'Stock Data'!$AN$4:$AN$1051) -> 10.345 | E193: =D193 -> 10.345
C194: =+'Stock Data'!AM5 -> 45907 | D194: =_xlfn.XLOOKUP(C194,'Stock Data'!$AM$4:$AM$1051,'Stock Data'!$AN$4:$AN$1051) -> 10.46
C195: =+'Stock Data'!AM6 -> 45906 | D195: =_xlfn.XLOOKUP(C195,'Stock Data'!$AM$4:$AM$1051,'Stock Data'!$AN$4:$AN$1051) -> 10.46
C196: =+'Stock Data'!AM7 -> 45905 | D196: =_xlfn.XLOOKUP(C196,'Stock Data'!$AM$4:$AM$1051,'Stock Data'!$AN$4:$AN$1051) -> 10.46
C197: =+'Stock Data'!AM8 -> 45904 | D197: =_xlfn.XLOOKUP(C197,'Stock Data'!$AM$4:$AM$1051,'Stock Data'!$AN$4:$AN$1051) -> 10.45
C198: =+'Stock Data'!AM9 -> 45903 | D198: =_xlfn.XLOOKUP(C198,'Stock Data'!$AM$4:$AM$1051,'Stock Data'!$AN$4:$AN$1051) -> 10.11
C199: =+'Stock Data'!AM10 -> 45902 | D199: =_xlfn.XLOOKUP(C199,'Stock Data'!$AM$4:$AM$1051,'Stock Data'!$AN$4:$AN$1051) -> 10.29
C200: =+'Stock Data'!AM11 -> 45901 | D200: =_xlfn.XLOOKUP(C200,'Stock Data'!$AM$4:$AM$1051,'Stock Data'!$AN$4:$AN$1051) -> 10.21
C201: =+'Stock Data'!AM12 -> 45900 | D201: =_xlfn.XLOOKUP(C201,'Stock Data'!$AM$4:$AM$1051,'Stock Data'!$AN$4:$AN$1051) -> 10.21
C202: =+'Stock Data'!AM13 -> 45899 | D202: =_xlfn.XLOOKUP(C202,'Stock Data'!$AM$4:$AM$1051,'Stock Data'!$AN$4:$AN$1051) -> 10.21
C203: =+'Stock Data'!AM14 -> 45898 | D203: =_xlfn.XLOOKUP(C203,'Stock Data'!$AM$4:$AM$1051,'Stock Data'!$AN$4:$AN$1051) -> 10.21
C204: =+'Stock Data'!AM15 -> 45897 | D204: =_xlfn.XLOOKUP(C204,'Stock Data'!$AM$4:$AM$1051,'Stock Data'!$AN$4:$AN$1051) -> 10.16
C205: =+'Stock Data'!AM16 -> 45896 | D205: =_xlfn.XLOOKUP(C205,'Stock Data'!$AM$4:$AM$1051,'Stock Data'!$AN$4:$AN$1051) -> 10.15
... C558: =+'Stock Data'!AM369 -> 45543 | D558: =_xlfn.XLOOKUP(C558,'Stock Data'!$AM$4:$AM$1051,'Stock Data'!$AN$4:$AN$1051) -> 4.07

Sheet Key Info
B7: Analysts | F7: LIS – Equity Research | J7: Stock Performance
B12: Mariana Zhu, Co-Head of Equity Research | F12: Recommendation: | H12: Strong Buy
B13: MSc in Mathematical Finance, ISEG – Ulisboa | F13: Target Price (FCFF):
B14: 63113l@aln.iseg.ulisboa.pt | F14: Upside:
B15: João Garcia, Analyst
B16: BSc in MAEG, ISEG – Ulisboa | F16: Ticker | H16: 005930
B17: joaogarcia@aln.iseg.ulisboa.pt | F17: Stock Exchange | H17: KRX
B18: Maria Inês Ferreira, Analyst
B19: BSc in Management, ISEG – Ulisboa | F19: Current Price | H19: 10.345
B20: 61624@aln.iseg.ulisboa.pt | F20: Market Cap (in millions) | H20: -296.62353
B21: Name, Analyst | F21: Beta | H21: 1.2550896
B22: BSc in XXX, ISEG – Ulisboa | F22: % of 52-Week High | H22: 0.49721275
B23: email@aln.iseg.ulisboa.pt | F23: 100-Day Moving Average | H23: 11.4455
B25: Reviewed by: | F25: Avg Vol (1 month) | H25: 1152697
B26: Name, Co-Head of Equity Research | F26: Shares Outstanding (millions) | H26: 28.35789
B27: BSc in XXX, ISEG – Ulisboa | F27: % Float | H27: 0.9377795
B28: email@aln.iseg.ulisboa.pt | F28: Short % of Float | H28: 0.1964122
B30: LISBON INVESTMENT SOCIETY | F30: % Held by Insiders | H30: 0.062220497
B31: ISEG – Rua do Quelhas, 6 | F31: % Held by Institutions | H31: 0.71446345
B32: lis@iseg.ulisboa.pt
B34: Disclaimer: This report was prepared by members of the Lisbon Investment Society (LIS), an independent, student-led, non-profit organization based at ISEG – Lisbon School of Economics & Management, and is intended solely for academic and educational purposes. All analyses, forecasts, and opinions expressed in this report reflect the independent judgment of the authors as of the date of publication and are subject to change without notice. The views presented herein do not represent those of ISEG, its faculty, or any affiliated entity. This document does not constitute, and should not be interpreted as, investment advice, an offer, or a solicitation to buy or sell any security or financial instrument. Nothing in this report should be construed as a recommendation to make or refrain from making any investment decision. The content is intended for informational purposes only, and readers are strongly encouraged to conduct their own research and seek advice from a qualified financial professional before making any financial decisions. The information contained in this report has been obtained from publicly available sources believed to be reliable; however, no representation or warranty is made regarding the accuracy, completeness, or timeliness of such information. LIS and its members accept no liability whatsoever for any direct or indirect loss arising from the use of this report or its contents. This report incorporates terminology, financial metrics, and methodologies commonly used in professional equity research, including but not limited to Discounted Cash Flow (DCF), trading multiples, Monte Carlo simulations, and strategic analysis tools such as Porter’s Five Forces. Definitions and assumptions used in these models are disclosed within the report and reflect a hypothetical investment thesis designed solely for academic discussion. All valuations, projections, and target prices presented herein are based on publicly available data and subject to the limitations of modeling assumptions. These are not guarantees of future performance and should not be relied upon as such, as past performance is not indicative of future results. Any company names, logos, trademarks, or brand references mentioned in this report are the property of their respective owners and are used strictly for identification and academic purposes. This document may not be reproduced, redistributed, or quoted in whole or in part without the prior written consent of the Lisbon Investment Society. About LIS – Lisbon Investment Society: The Lisbon Investment Society (LIS) is a non-profit academic association headquartered at ISEG – Lisbon School of Economics & Management. Founded in 2016, LIS is committed to fostering student interest in finance and investment through applied research, skill development, and institutional engagement. The Society operates independently and autonomously from any political, religious, or commercial affiliation, and is composed of selected students and collaborators who are invited through a rigorous recruitment process and share a commitment to excellence, analytical rigor, and ethical standards. Its activities include equity research, portfolio management, macroeconomic analysis, and investment education. This report was prepared by the Equity Research team at the Lisbon Investment Society, whose analysts combine rigorous financial modeling, critical thinking, and collaborative research to deliver high-quality, student-led investment analysis. We welcome your feedback, discussion, and questions regarding this report or our research process, and invite you to reach out to our team as we are always open to engagement.

Sheet Industry
D6: 584.17 | E6: 627.76 | F6: 676.06 | G6: 729.63 | H6: 789.13 | I6: 855.3 | J6: 929 | K6: 997.69 | L6: 1067.63 | M6: 1137.57
A7: x | B7: Industry Growth Forecast | O7: Industry Index
B9: (in trillions) | D9: 2022 | E9: =+D9+1 -> 2023 | F9: =+E9+1 -> 2024 | G9: =+F9+1 -> 2025 | H9: =+G9+1 -> 2026 | I9: =+H9+1 -> 2027 | J9: =+I9+1 -> 2028 | K9: =+J9+1 -> 2029 | M9: ="CAGR "&$G$9&" - "&$K$9 -> CAGR 2025 - 2029
B12: Market Size (FinTech Market Industry) | F12: 0.34 | G12: 0.39 | H12: =G12*(1+L12)^1 -> 0.45318 | I12: =G12*(1+L12)^2 -> 0.52659516 | J12: =G12*(1+L12)^3 -> 0.61190358 | K12: =G12*(1+L12)^4 -> 0.71103196 | L12: 0.162 | M12: =(K12/G12)^(1/5)-1 -> 0.12762554
B13: Market Share | F13: =Segments!AF14/(F12*10^6) -> 0.00154695 | G13: =Segments!AL14/(G12*10^6) -> 0.0018552644 | H13: =Segments!AR14/(H12*10^6) -> 0.0018767786 | I13: =Segments!AT14/(I12*10^6) -> 0.0019184593 | J13: =Segments!AV14/(J12*10^6) -> 0.0021224791 | K13: =Segments!AX14/(K12*10^6) -> 0.0023296484 | M13: =((K13*K12)/(G13*G12))^(1/5)-1 -> 0.18016251
B14: Market Size (Financial Services Industry) | E14: 30.9 | F14: 33.77 | G14: 36.13 | H14: =G14*(1+L14)^1 -> 38.69523 | I14: =G14*(1+L14)^2 -> 41.442591 | J14: =G14*(1+L14)^3 -> 44.385015 | K14: 47.55 | L14: 0.071 | M14: =(K14/G14)^(1/5)-1 -> 0.056468401
B15: Market Share | E15: =Segments!Z14/(Industry!E14*10^6) -> 1.6470841e-05 | F15: =Segments!AF14/(Industry!F14*10^6) -> 1.5574859e-05 | G15: =Segments!AL14/(Industry!G14*10^6) -> 2.002638e-05 | H15: =Segments!AR14/(Industry!H14*10^6) -> 2.1979932e-05 | I15: =Segments!AN14/(Industry!I14*10^6) -> 3.9208101e-06 | J15: =Segments!AV14/(Industry!J14*10^6) -> 2.9261059e-05 | K15: =Segments!AX14/(Industry!K14*10^6) -> 3.4836055e-05 | M15: =((K15*K14)/(G15*G14))^(1/5)-1 -> 0.18016251
B16: Market Size (Micro Lending Market) | F16: 0.1 | G16: 0.11 | H16: =G16*(1+L16)^1 -> 0.12166 | I16: =G16*(1+L16)^2 -> 0.13455596 | J16: =G16*(1+L16)^3 -> 0.14881889 | K16: =G16*(1+L16)^4 -> 0.16459369 | L16: 0.106 | M16: =(K16/G16)^(1/5)-1 -> 0.083937151
B17: Market Share | F17: =Segments!AF14/(F16*10^6) -> 0.00525963 | G17: =Segments!AL14/(G16*(10^6)) -> 0.0065777556 | H17: =Segments!AR14/(H16*10^6) -> 0.0069909464 | I17: =Segments!AT14/(I16*10^6) -> 0.007508039 | J17: =Segments!AV14/(J16*10^6) -> 0.0087270678 | K17: =Segments!AX14/(K16*10^6) -> 0.0100639 | M17: =((K17*K16)/(G17*G16))^(1/5)-1 -> 0.18016251
A19: x
B21: Industry Driver | D21: Description | O21: Porter's Five Forces
B23: Government Policy | D23: OppFi’s model is highly sensitive to regulation. Interest rate caps and oversight of bank partnerships directly shape how it can lend and what margins it earns.
B24: Macroeconomic Trends | D24: Economic stress drives more customers to OppFi but also raises default risk, making growth closely tied to broader financial cycles.
B25: Consumer Behavior | D25: Borrowers increasingly expect fast, online credit. This shift supports OppFi’s digital installment loan model and helps it reach underbanked customers.
B26: Access to capital | D26: Dependence on bank partners and investors makes OppFi vulnerable to funding costs. Cheap capital fuels growth, but tighter markets compress margins.
B27: Technology | D27: Digital platforms and algorithms allow OppFi to approve and deliver loans quickly, giving it an edge in serving non-prime borrowers banks often overlook.
O28: Rivalry Among Existing Competitors | R28: 4
O29: Threat of New Entrants | R29: 4
O30: Threat of Substitutes | R30: 5
O31: Bargaining Power of Customers | R31: 4
O32: Bargaining Power of Suppliers | R32: 3

Sheet ESG
A7: x | B7: ESG Analysis
B12: ESG Scores | G12: GHG Scope 1 Emissions, Water Consumption, Energy Consumption and Waste Production per Sales | M12: ISS ESG Corporate Rating
B15: LSEG ESG Score | D15: 28
B16: E-Score | D16: 2
B17: S-Score | D17: 27
B18: G-Score | D18: 38
B19: S&P Global ESG Score | D19: N/A
B20: Environmental | D20: N/A
B21: Social | D21: N/A
B22: Governance & Economic | D22: N/A
B23: Sustainalytics | D23: Low/Average
B24: ISS ESG Corporate Rating | D24: D+
B25: SDG Impact Rating | D25: 2.8
B26: Governance Quality Score | D26: 9
B27: MSCI ESG Ratings | D27: N/A
B30: Key Info | G30: Environmental
H32: Overview | I32: Targets | J32: Improvements | K32: Comments
B33: GICS Sector | C33: Financials | G33: GHG Scope 1 Emissions | I33: - | J33: - | K33: -
B34: GICS Industry Group | C34: Financial Services
B35: GICS Industry | C35: Consumer Finance | G35: Water Consumption | I35: - | J35: - | K35: -
B36: GICS Sub-Industry | C36: Consumer Finance
G37: Energy Consumption | I37: - | J37: - | K37: -
B38: Headquarters | C38: Chicago
B39: Number of Employees | C39: 450 | G39: Waste Management | I39: - | J39: - | K39: -
B41: Annual Report | C41: 45727 | G41: Other | I41: - | J41: - | K41: -
B42: Sustainability Report | C42: N/A
B44: Recent Headlines | G44: Social
H46: Overview | I46: Targets | J46: Improvements | K46: Comments
G47: Employee Turnover % | I47: - | J47: - | K47: -
G49: Salaries & Compensation | I49: - | J49: - | K49: Good pay for high-end, engineering, data analyst jobs (~81k - ~160k). Lower level jobs pay way worse, at 16,5$/hour, such as entry level, remote jobs and customer service roles.
G51: Reputation | I51: - | J51: - | K51: Although their mission is to supposedly include people marginalized from the traditional credit system to give them na opportunity, OppFi is most of the times regarded as a predatory company whose goal is to take advantage of their customers to have very high interest on their loans.
G53: Discrimination Events | I53: - | J53: - | K53: -
G55: Work Safety | I55: - | J55: - | K55: -
G57: Damage to consumer health | I57: - | J57: - | K57: -
G59: Pension Plan | I59: - | J59: - | K59: Typical 401k pension plans that is competitive in the job market.
G61: Supply chain | I61: - | J61: - | K61: -
G63: Community involvement | I63: - | J63: - | K63: Just the nature of the business model is very predatory IMO.
G65: Public Sector | I65: - | J65: Not much room for improvement with the current business model, maybe try to get better at lobying. | K65: Because the company functions as a nonbank fintech lender, it bypasses bank regulations. This makes the relationship with the public sector more complicated, as they aren't well regarded by law-makers and public entities, having minimal chance for public partnerships and low trust.
G67: Litigation | I67: - | J67: See above | K67: Many ongoing litigation tied to lending practices regarding high interest rates and regulatory evasion.
B70: Board of Directors | G70: Governance
...

Sheet Segments
A7: x | B7: Segments | D7: =F7 -> 2020 | E7: =F7 -> 2020 | F7: 2020 | G7: =F7 -> 2020 | H7: =F7 -> 2020 | J7: =L7 -> 2021 | K7: =L7 -> 2021 | L7: 2021 | M7: =L7 -> 2021 | N7: =L7 -> 2021 | P7: =R7 -> 2022 | Q7: =R7 -> 2022 | R7: 2022 | S7: =R7 -> 2022 | T7: =R7 -> 2022 | V7: =X7 -> 2023 | W7: =X7 -> 2023 | X7: 2023 | Y7: =X7 -> 2023 | Z7: =X7 -> 2023 | AB7: =AD7 -> 2024 | AC7: =AD7 -> 2024 | AD7: 2024 | AE7: =AD7 -> 2024 | AF7: =AD7 -> 2024 | AH7: =AJ7 -> 2025 | AI7: =AJ7 -> 2025 | AJ7: 2025 | AK7: =AJ7 -> 2025 | AL7: =AJ7 -> 2025 | AN7: =AP7 -> 2025 | AO7: =AP7 -> 2025 | AP7: 2025 | AQ7: =AP7 -> 2025 | AR7: =AP7 -> 2025 | AZ7: Products
D8: 2020 | J8: =D8+1 -> 2021 | P8: =J8+1 -> 2022 | V8: =P8+1 -> 2023 | AB8: =V8+1 -> 2024 | AH8: =AB8+1 -> 2025 | AN8: =AH8+1 -> 2026 | AT8: =AN8+1 -> 2027 | AV8: =+AT8+1 -> 2028 | AX8: =+AV8+1 -> 2029
D9: Q1 | E9: Q2 | F9: Q3 | G9: Q4 | H9: FY | J9: Q1 | K9: Q2 | L9: Q3 | M9: Q4 | N9: FY | P9: Q1 | Q9: Q2 | R9: Q3 | S9: Q4 | T9: FY | V9: Q1 | W9: Q2 | X9: Q3 | Y9: Q4 | Z9: FY | AB9: Q1 | AC9: Q2 | AD9: Q3 | AE9: Q4 | AF9: FY | AH9: Q1 | AI9: Q2 | AJ9: Q3 | AK9: Q4 | AL9: FY | AN9: Q1 | AO9: Q2 | AP9: Q3 | AQ9: Q4 | AR9: FY | AT9: FY | AV9: FY | AX9: FY
B12: Revenue by segment:
B13: Financial services
B14: Total revenue | D14: =IS!D18 -> 0 | E14: =IS!E18 -> 0 | F14: =IS!F18 -> 0 | G14: =IS!G18 -> 0 | H14: =IS!H18 -> 0 | J14: =IS!J18 -> 0 | K14: =IS!K18 -> 0 | L14: =IS!L18 -> 91.448 | M14: =IS!M18 -> 95.958 | N14: =IS!N18 -> 349.029 | P14: =IS!P18 -> 100.336 | Q14: =IS!Q18 -> 107.873 | R14: =IS!R18 -> 123.605 | S14: =IS!S18 -> 120.03 | T14: =IS!T18 -> 452.859 | V14: =IS!V18 -> 120.374 | W14: =IS!W18 -> 122.486 | X14: =IS!X18 -> 133.165 | Y14: =IS!Y18 -> 132.924 | Z14: =IS!Z18 -> 508.949 | AB14: =IS!AB18 -> 127.343 | AC14: =IS!AC18 -> 126.304 | AD14: =IS!AD18 -> 136.593 | AE14: =IS!AE18 -> 135.723 | AF14: =IS!AF18 -> 525.963 | AH14: =IS!AH18 -> 140.268 | AI14: =IS!AI18 -> 142.443 | AJ14: =IS!AJ18 -> 150.10346 | AK14: =IS!AK18 -> 156.13393 | AL14: =IS!AL18 -> 723.55312 | AN14: =IS!AN18 -> 162.48853 | AO14: =IS!AO18 -> 168.79837 | AP14: =IS!AP18 -> 176.86832 | AQ14: =IS!AQ18 -> 186.71815 | AR14: =IS!AR18 -> 850.51853 | AT14: =IS!AT18 -> 1010.2514 | AV14: =IS!AV18 -> 1298.7526 | AX14: =IS!AX18 -> 1656.4544
B16: Revenue by region:
B17: USA | H17: =H18 -> 0 | J17: =J18 -> 0 | K17: =K18 -> 0 | L17: =L18 -> 91.448 | M17: =M18 -> 95.958 | N17: =N18 -> 349.029 | P17: =P18 -> 100.336 | Q17: =Q18 -> 107.873 | R17: =R18 -> 123.605 | S17: =S18 -> 120.03 | T17: =T18 -> 452.859 | V17: =V18 -> 120.374 | W17: =W18 -> 122.486 | X17: =X18 -> 133.165 | Y17: =Y18 -> 132.924 | Z17: =Z18 -> 508.949 | AB17: =AB18 -> 127.343 | AC17: =AC18 -> 126.304 | AD17: =AD18 -> 136.593 | AE17: =AE18 -> 135.723 | AF17: =AF18 -> 525.963 | AL17: =AL18 -> 723.55312 | AN17: =AN18 -> 162.48853 | AO17: =AO18 -> 168.79837 | AP17: =AP18 -> 176.86832 | AQ17: =AQ18 -> 186.71815 | AR17: =AR18 -> 850.51853 | AT17: =AT18 -> 1010.2514 | AV17: =AV18 -> 1298.7526 | AX17: =AX18 -> 1656.4544
B18: Total revenue | D18: =IS!D18 -> 0 | E18: =IS!E18 -> 0 | F18: =IS!F18 -> 0 | G18: =IS!G18 -> 0 | H18: =IS!H18 -> 0 | J18: =IS!J18 -> 0 | K18: =IS!K18 -> 0 | L18: =IS!L18 -> 91.448 | M18: =IS!M18 -> 95.958 | N18: =IS!N18 -> 349.029 | P18: =IS!P18 -> 100.336 | Q18: =IS!Q18 -> 107.873 | R18: =IS!R18 -> 123.605 | S18: =IS!S18 -> 120.03 | T18: =IS!T18 -> 452.859 | V18: =IS!V18 -> 120.374 | W18: =IS!W18 -> 122.486 | X18: =IS!X18 -> 133.165 | Y18: =IS!Y18 -> 132.924 | Z18: =IS!Z18 -> 508.949 | AB18: =IS!AB18 -> 127.343 | AC18: =IS!AC18 -> 126.304 | AD18: =IS!AD18 -> 136.593 | AE18: =IS!AE18 -> 135.723 | AF18: =IS!AF18 -> 525.963 | AH18: =IS!AH18 -> 140.268 | AI18: =IS!AI18 -> 142.443 | AJ18: =IS!AJ18 -> 150.10346 | AK18: =IS!AK18 -> 156.13393 | AL18: =IS!AL18 -> 723.55312 | AN18: =IS!AN18 -> 162.48853 | AO18: =IS!AO18 -> 168.79837 | AP18: =IS!AP18 -> 176.86832 | AQ18: =IS!AQ18 -> 186.71815 | AR18: =IS!AR18 -> 850.51853 | AT18: =IS!AT18 -> 1010.2514 | AV18: =IS!AV18 -> 1298.7526 | AX18: =IS!AX18 -> 1656.4544
B20: Products:
B21: Opploans
B22: SalaryTap
B23: Oppfi Card
A25: x | B25: Notes & Forecasts
B30: Revenue | H30: Revenue is fully generated from financial services in the U.S., with OppLoans as the main product and other offerings like SalaryTap and the OppFi Card still immaterial.
B31: Growth | H31: Growth is primarily driven by higher loan originations, larger receivables, and stable yields, although charge-offs remain elevated.Forecasts reflect strong near-term expansion supported by management guidance, followed by more moderate growth as the business matures and credit risk stabilizes.
B32: Financial Inclusion | H32: OppFi places financial inclusion at the core of its mission. The company provides credit products through its OppLoans platform to consumers who are often underserved by traditional banking systems.
B33: Financial Health Surveys | H33: OppFi conducts semi-annual Financial Health Surveys to assess the well-being of its customers. The Spring 2025 survey indicated modest gains in financial health among respondents, despite ongoing economic challenges such as inflation and increased living costs.
B34: SalaryTap | H34: A payroll-deductible loan that allows consumers to access funds securely, with automatic repayments from their paycheck. Provides a safe, short-term cash solution between pay periods.
B35: OppCard | H35: A credit card for consumers with limited or poor credit history, designed to help responsibly build or improve credit while expanding access to revolving credit.
B36: Bitty Holdings | H36: OppFi holds a 35% stake in Bitty Holdings, a company that provides small businesses with revenue-based financing and other working capital solutions. This segment allows OppFi to expand beyond consumer lending, targeting small businesses that often struggle to access traditional credit.

Sheet Peers
B7: Peers
A12: x | B12: Growth | C12: OPPFI INC | D12: ENOVA INTERNATIO | E12: REGIONAL MANAGEM | F12: WORLD ACCEPTANCE | G12: EZCORP INC-A | H12: ONEMAIN HOLDINGS | I12: LENDINGCLUB CORP | J12: UPSTART HOLDINGS | K12: SOFI TECHNOLOGIE | L12: OPORTUN FINANCIA | M12: GREEN DOT CORP-A | N12: SYNCHRONY FINANC | O12: DISCOVER FINANCI | P12: CAPITAL ONE FINA | Q12: ALLY FINANCIAL I | R12: AFFIRM HOLDINGS
B14: Revenue (LTM) | C14: 0.067901781 | D14: 0.23418337 | E14: 0.073190377 | F14: 0.0077193326 | G14: 0.083064183 | H14: 0.09321879 | I14: 0.15904538 | J14: 0.60621769 | K14: 0.22595016 | L14: 0.22595016 | M14: 0.21783936 | N14: 0.21783936 | O14: -0.014687101 | P14: 0.088791107 | Q14: 0.096750129 | R14: -0.051558315
B15: Revenue (3-yr CAGR) | C15: 0.11947342 | D15: 0.25622651 | E15: 0.08815074 | F15: -0.023977107 | G15: 0.13381423 | H15: 0.06089953 | I15: 0.017755776 | J15: -0.073675667 | K15: 0.45917291 | L15: -0.044159498 | M15: 0.10373992 | N15: 0.11684866 | O15: 0.2100027 | P15: 0.18934416 | Q15: 0.12706483 | R15: 0.33694906
B16: Gross profit (LTM) | C16: #N/A | D16: 0.23541343 | E16: #N/A | F16: #N/A | G16: 0.084966065 | H16: #N/A | I16: #N/A | J16: #N/A | K16: #N/A | L16: #N/A | M16: #N/A | N16: #N/A | O16: #N/A | P16: #N/A | Q16: #N/A | R16: #N/A
B17: EBIT (LTM) | C17: 0.96601966 | D17: 0.33535563 | E17: 0.37996088 | F17: 0.0082506089 | G17: 0.2913342 | H17: 0.12823674 | I17: 0.70427297 | J17: -1.3924433 | K17: 3.1551344 | L17: 3.1551344 | M17: -1.2303798 | N17: -1.2303798 | O17: 0.4854641 | P17: 1.1523713 | Q17: -0.98610387 | R17: 0.42587421
B18: EBITDA (LTM) | C18: 0.758944 | D18: 0.31151631 | E18: 0.19649027 | F18: 0.051861299 | G18: 0.13305368 | H18: 0.11369863 | I18: 0.21994808 | J18: -1.667427 | K18: 0.2796766 | L18: 0.2796766 | M18: 0.76592956 | N18: 0.76592956 | O18: 0.1538255 | P18: 0.39953811 | Q18: -0.22781958 | R18: -0.0092804919
B19: FCF (LTM) | C19: 0.082328359 | D19: 0.33302129 | E19: 0.079349951 | F19: -0.036062258 | G19: 0.25230466 | H19: 0.071456927 | I19: -1.2476848 | J19: #VALUE! | K19: 0.82638636 | L19: 0.0033552845 | M19: -0.6711313 | N19: 0.14604911 | O19: -0.012469734 | P19: -0.13556643 | Q19: -0.40600667 | R19: 1.0688896
A21: x | B21: Margins | C21: OPPFI INC | D21: ENOVA INTERNATIO | E21: REGIONAL MANAGEM | F21: WORLD ACCEPTANCE | G21: EZCORP INC-A | H21: ONEMAIN HOLDINGS | I21: LENDINGCLUB CORP | J21: UPSTART HOLDINGS | K21: SOFI TECHNOLOGIE | L21: OPORTUN FINANCIA | M21: GREEN DOT CORP-A | N21: SYNCHRONY FINANC | O21: DISCOVER FINANCI | P21: CAPITAL ONE FINA | Q21: ALLY FINANCIAL I | R21: AFFIRM HOLDINGS
B23: Gross margin | C23: #VALUE! | D23: 0.57545677 | E23: #VALUE! | F23: #VALUE! | G23: 0.58735522 | H23: #VALUE! | I23: #VALUE! | J23: #VALUE! | K23: #VALUE! | L23: #VALUE! | M23: #VALUE! | N23: #VALUE! | O23: #VALUE! | P23: #VALUE! | Q23: #VALUE! | R23: #VALUE!
B24: EBIT margin | C24: 0.26474106 | D24: 0.2200158 | E24: 0.10520981 | F24: 0.21447719 | G24: 0.096874833 | H24: 0.14701345 | I24: 0.082674829 | J24: -0.27156072 | K24: 0.087236374 | L24: -0.3901607 | M24: -0.000967587 | N24: 0.28235659 | O24: 0.33914015 | P24: 0.15110452 | Q24: 0.093753505 | R24: -0.02706633
B25: EBITDA margin | C25: 0.30645356 | D25: 0.24088419 | E25: 0.22827795 | F25: 0.33684815 | G25: 0.20170403 | H25: 0.39859555 | I25: 0.42870633 | J25: -0.032314039 | K25: 0.39361319 | L25: 0.47388362 | M25: 0.088878249 | N25: 0.55709657 | O25: 0.5155911 | P25: 0.30627692 | Q25: 0.56113215 | R25: 0.033732972
B26: Net margin | C26: 0.01379945 | D26: 0.078805027 | E26: 0.080212385 | F26: 0.17187496 | G26: 0.071534829 | H26: 0.11218867 | I26: 0.065221452 | J26: -0.20200368 | K26: 0.18642665 | L26: -0.26653433 | M26: -0.015489513 | N26: 0.21252713 | O26: 0.24824121 | P26: 0.11364799 | Q26: 0.0625771 | R26: 0.016184656
B27: SG&A margin | C27: 0.12993062 | D27: 0.25069451 | E27: #VALUE! | F27: #VALUE! | G27: 0.065564789 | H27: #VALUE! | I27: #VALUE! | J27: 0.55907256 | K27: #VALUE! | L27: #VALUE! | M27: 0.27340666 | N27: #VALUE! | O27: #VALUE! | P27: #VALUE! | Q27: #VALUE! | R27: 0.30390037
B28: R&D margin | C28: 0.03181647 | D28: 0 | E28: #VALUE! | F28: #VALUE! | G28: 0 | H28: #VALUE! | I28: #VALUE! | J28: 0.30380644 | K28: #VALUE! | L28: #VALUE! | M28: #VALUE! | N28: #VALUE! | O28: #VALUE! | P28: #VALUE! | Q28: #VALUE! | R28: 0.18289319
A30: x | B30: Returns | C30: OPPFI INC | D30: ENOVA INTERNATIO | E30: REGIONAL MANAGEM | F30: WORLD ACCEPTANCE | G30: EZCORP INC-A | H30: ONEMAIN HOLDINGS | I30: LENDINGCLUB CORP | J30: UPSTART HOLDINGS | K30: SOFI TECHNOLOGIE | L30: OPORTUN FINANCIA | M30: GREEN DOT CORP-A | N30: SYNCHRONY FINANC | O30: DISCOVER FINANCI | P30: CAPITAL ONE FINA | Q30: ALLY FINANCIAL I | R30: AFFIRM HOLDINGS
B32: ROIC | C32: 0.27863713 | D32: 0.10934619 | E32: 0.13157101 | F32: 0.2396028 | G32: 0.06373359 | H32: 0.097710315 | I32: 0.17398179 | J32: -0.021888272 | K32: 0.058716681 | L32: -0.0027901529 | M32: 0.073094913 | N32: 0.21198824 | O32: 0.21951616 | P32: 0.12212293 | Q32: 0.063865048 | R32: 0.090657329
B33: CROIC | C33: 0.54885257 | D33: 0.31174745 | E33: 0.12810184 | F33: 0.241935 | G33: 0.060353901 | H33: 0.098088385 | I33: -1.8600427 | J33: 0.084549093 | K33: -0.13051477 | L33: 0.20602886 | M33: 0.0075504141 | N33: 0.24195966 | O33: 0.2043132 | P33: 0.12856385 | Q33: 0.030717018 | R33: 0.10206325
B34: ROCE | C34: 1.796604 | D34: 0.11344948 | E34: #VALUE! | F34: #VALUE! | G34: 0.092322839 | H34: #VALUE! | I34: #VALUE! | J34: -0.10103474 | K34: #VALUE! | L34: #VALUE! | M34: 0.0013573158 | N34: #VALUE! | O34: #VALUE! | P34: #VALUE! | Q34: #VALUE! | R34: -0.0089245239
B35: RONA | C35: 0.59451866 | D35: 0.48855046 | E35: 0.1514375 | F35: 0.25481309 | G35: 0.13986336 | H35: 0.20902538 | I35: 0.048494072 | J35: -0.27298024 | K35: 0.035760951 | L35: -0.3255344 | M35: -0.0019093734 | N35: 0.27460796 | O35: 0.33883744 | P35: 0.097229534 | Q35: 0.060130907 | R35: -0.028436867
B36: ROE | C36: -2.0949373 | D36: 0.21564244 | E36: 0.098110627 | F36: 0.19081034 | G36: 0.10952195 | H36: 0.20466121 | I36: 0.054956607 | J36: -0.0096497357 | K36: 0.088010303 | L36: -0.012633799 | M36: -0.026790884 | N36: 0.21359029 | O36: 0.2978683 | P36: -0.0037936793 | Q36: 0.040589474 | R36: 0.017992077
B37: ROA | C37: -0.053747068 | D37: 0.048606866 | E37: 0.018488982 | F37: 0.078300427 | G37: 0.057823944 | H37: 0.025641521 | I37: 0.0072712153 | J37: -0.0029561954 | K37: 0.015228892 | L37: -0.0014297568 | M37: -0.0043220238 | N37: 0.027278687 | O37: 0.03185597 | P37: 0 | Q37: 0.003099444 | R37: 0.0050483329
A39: x | B39: Efficiency | C39: OPPFI INC | D39: ENOVA INTERNATIO | E39: REGIONAL MANAGEM | F39: WORLD ACCEPTANCE | G39: EZCORP INC-A | H39: ONEMAIN HOLDINGS | I39: LENDINGCLUB CORP | J39: UPSTART HOLDINGS | K39: SOFI TECHNOLOGIE | L39: OPORTUN FINANCIA | M39: GREEN DOT CORP-A | N39: SYNCHRONY FINANC | O39: DISCOVER FINANCI | P39: CAPITAL ONE FINA | Q39: ALLY FINANCIAL I | R39: AFFIRM HOLDINGS
B41: Asset turnover | C41: 0.89055957 | D41: 0.55570145 | E41: 0.32563855 | F41: 0.54790663 | G41: 0.72616217 | H41: 0.23131514 | I41: 0.12263666 | J41: 0.3963461 | K41: 0.11290849 | L41: 0.19032164 | M41: 0.34732882 | N41: 0.19207947 | O41: 0.15639897 | P41: 0.10068078 | Q41: 0.081575062 | R41: 0.31192092
B42: Net operating asset turnover | C42: 2.1227444 | D42: 1.6683165 | E42: #VALUE! | F42: #VALUE! | G42: 1.5369538 | H42: #VALUE! | I42: #VALUE! | J42: 5.0482037 | K42: #VALUE! | L42: #VALUE! | M42: 0.45870262 | N42: #VALUE! | O42: #VALUE! | P42: #VALUE! | Q42: #VALUE! | R42: 0.52675299
B43: Fixed asset turnover | C43: 22.097223 | D43: 21.402802 | E43: 11.699487 | F43: 5.7707081 | G43: 4.1173013 | H43: #N/A N/A | I43: 5.5164573 | J43: 9.9952592 | K43: 10.934092 | L43: 45.782841 | M43: 9.9721808 | N43: #N/A N/A | O43: 21.497028 | P43: 11.373004 | Q43: 1.6388115 | R43: 6.4467481
B44: Revenue per employee thsnd of USD | C44: 1247.2517 | D44: 1639.0929 | E44: 286.99155 | F44: 200.05855 | G44: 164.26907 | H44: 664.55556 | I44: 1246.0339 | J44: 713.96982 | K44: 832.747 | L44: 265.53849 | M44: 1676.3626 | N44: 1157.25 | O44: 1119.381 | P44: 1090.057 | Q44: 1456.1682 | R44: 1461.6555
B45: EBIT per employee thsnd of USD | C45: 359.62697 | D45: 372.0873 | E45: 21.521821 | F45: 35.545235 | G45: 18.3856 | H45: 101.66667 | I45: 98.597804 | J45: 46.274099 | K45: 62.9694 | L45: 9.2902249 | M45: 86.307826 | N45: 212.05 | O45: 304.71429 | P45: 1.5209125 | Q45: 151.61363 | R45: 750.13146
A47: x | B47: Working Capital | C47: OPPFI INC | D47: ENOVA INTERNATIO | E47: REGIONAL MANAGEM | F47: WORLD ACCEPTANCE | G47: EZCORP INC-A | H47: ONEMAIN HOLDINGS | I47: LENDINGCLUB CORP | J47: UPSTART HOLDINGS | K47: SOFI TECHNOLOGIE | L47: OPORTUN FINANCIA | M47: GREEN DOT CORP-A | N47: SYNCHRONY FINANC | O47: DISCOVER FINANCI | P47: CAPITAL ONE FINA | Q47: ALLY FINANCIAL I | R47: AFFIRM HOLDINGS
B49: DSO | C49: #N/A N/A | D49: #N/A N/A | E49: #N/A N/A | F49: #N/A N/A | G49: 81.968855 | H49: #N/A N/A | I49: #N/A N/A | J49: #N/A N/A | K49: #N/A N/A | L49: #N/A N/A | M49: 7.6650649 | N49: #N/A N/A | O49: #N/A N/A | P49: #N/A N/A | Q49: #N/A N/A | R49: 44.102588
B50: DIO | C50: #N/A N/A | D50: #N/A N/A | E50: #N/A N/A | F50: #N/A N/A | G50: 142.45583 | H50: #N/A N/A | I50: #N/A N/A | J50: #N/A N/A | K50: #N/A N/A | L50: #N/A N/A | M50: #N/A N/A | N50: #N/A N/A | O50: #N/A N/A | P50: #N/A N/A | Q50: #N/A N/A | R50: #N/A N/A
B51: DPO | C51: #N/A N/A | D51: 86.492746 | E51: #N/A N/A | F51: #N/A N/A | G51: 12.070037 | H51: #N/A N/A | I51: #N/A N/A | J51: #N/A N/A | K51: #N/A N/A | L51: #N/A N/A | M51: #N/A N/A | N51: #N/A N/A | O51: #N/A N/A | P51: #N/A N/A | Q51: #N/A N/A | R51: #N/A N/A
B52: CCC | C52: #N/A N/A | D52: #N/A N/A | E52: #N/A N/A | F52: #N/A N/A | G52: 202.82374 | H52: #N/A N/A | I52: #N/A N/A | J52: #N/A N/A | K52: #N/A N/A | L52: #N/A N/A | M52: #N/A N/A | N52: #N/A N/A | O52: #N/A N/A | P52: #N/A N/A | Q52: #N/A N/A | R52: #N/A N/A
B53: Working capital intensity | C53: 0.091221688 | D53: 1.5406443 | E53: #N/A N/A | F53: #N/A N/A | G53: 0.55650973 | H53: #N/A N/A | I53: #N/A N/A | J53: 1.7243862 | K53: #N/A N/A | L53: #N/A N/A | M53: -0.94821448 | N53: #N/A N/A | O53: #N/A N/A | P53: #N/A N/A | Q53: #N/A N/A | R53: 2.6322636
B54: Cash conversion ratio | C54: 2.3254575 | D54: 2.6311329 | E54: 4.9732224 | F54: 2.2696142 | G54: 1.0409224 | H54: 4.0464768 | I54: -40.484646 | J54: -1.0779551 | K54: -4.7989329 | L54: -3.4166717 | M54: -48.790767 | N54: 2.1629695 | O54: 1.3870596 | P54: 3.0725888 | Q54: 5.4162679 | R54: -9.0968455
B55: CFO margin | C55: 0.61564407 | D55: 0.57889081 | E55: 0.45696793 | F55: 0.44997334 | G55: 0.10083919 | H55: 0.47168822 | I55: -2.2690244 | J55: 0.29273025 | K55: -0.29733113 | L55: 0.73781409 | M55: 0.047209312 | N55: 0.40751469 | O55: 0.35647796 | P55: 0.33666432 | Q55: 0.27628287 | R55: 0.24621823
A57: x | B57: Leverage & Coverage | C57: OPPFI INC | D57: ENOVA INTERNATIO | E57: REGIONAL MANAGEM | F57: WORLD ACCEPTANCE | G57: EZCORP INC-A | H57: ONEMAIN HOLDINGS | I57: LENDINGCLUB CORP | J57: UPSTART HOLDINGS | K57: SOFI TECHNOLOGIE | L57: OPORTUN FINANCIA | M57: GREEN DOT CORP-A | N57: SYNCHRONY FINANC | O57: DISCOVER FINANCI | P57: CAPITAL ONE FINA | Q57: ALLY FINANCIAL I | R57: AFFIRM HOLDINGS
B59: Net debt / EBITDA | C59: 1.6053442 | D59: 5.5850469 | E59: 11.050548 | F59: 2.8271658 | G59: 1.1669517 | H59: 8.9278523 | I59: -2.1390077 | J59: #N/A N/A | K59: 1.1663719 | L59: 2.9805829 | M59: 0.42831546 | N59: -0.2674112 | O59: 0.22054455 | P59: -0.36689255 | Q59: 1.0454078 | R59: 5.3496033
B60: Net debt / FCF | C60: 0.87101507 | D60: 2.3577558 | E60: 5.7172428 | F60: 2.059364 | G60: 4.8718708 | H60: 7.8332716 | I60: 0.52243576 | J60: 3.5316461 | K60: -0.51157862 | L60: 4.0097979 | M60: 4.9930947 | N60: 0.076259139 | O60: 0.95365943 | P60: 0.15075199 | Q60: 8.2659176 | R60: 0.9670129
B61: Interest coverage | C61: 3.1145209 | D61: 2.0133383 | E61: #VALUE! | F61: #VALUE! | G61: 8.2834008 | H61: #VALUE! | I61: #VALUE! | J61: -4.2751218 | K61: #VALUE! | L61: #VALUE! | M61: -0.30294224 | N61: #VALUE! | O61: #VALUE! | P61: #VALUE! | Q61: #VALUE! | R61: #VALUE!
...

Sheet Trading Comps
B7: ="in "&IF(Inputs!$R$18="k","thousands",IF(Inputs!$R$18="MLN","millions","billions")&" of "&Inputs!$R$17) -> in millions of usd | D7: Current | E7: % of | I7: Enterprise Value / | S7: LTM | T7: Net | V7: Price / | Z7: LT
D8: Share | E8: 52-week | F8: Equity | G8: Enterprise | I8: LTM | J8: 2025 | K8: 2026 | L8: LTM | M8: 2025E | N8: 2026E | O8: LTM | P8: 2025E | Q8: 2026E | S8: EBITDA | T8: Debt / | V8: LTM | W8: 2025E | X8: 2026E | Z8: EPS
B9: Company | C9: Ticker | D9: Price | E9: High | F9: Value | G9: Value | I9: Sales | J9: Sales | K9: Sales | L9: EBITDA | M9: EBITDA | N9: EBITDA | O9: EBIT | P9: EBIT | Q9: EBIT | S9: Margin | T9: EBITDA | V9: EPS | W9: EPS | X9: EPS | Z9: Growth
B12: Tier I: Fintech
N14: =G14/_xll.BQL(Inputs!$E20, "ebitda(fpr = 2026, fpt = a, ae = e, fa_adjusted = y, fs = mr)/1"&IF(Inputs!$R$18="BLN","b",IF(Inputs!$R$18="MLN","m","k"))) -> #NAME? | Q14: =G14/_xll.BQL(Inputs!$E20, "is_oper_inc(fpr = 2026, fpt = a, ae = e, fa_adjusted = y, fs = mr)/1"&IF(Inputs!$R$18="BLN","b",IF(Inputs!$R$18="MLN","m","k"))) -> #NAME?
B15: =+Inputs!B21 -> ENOVA INTERNATIO | C15: =+_xll.BDP(Inputs!E21,"TICKER_AND_EXCH_CODE") -> ENVA US | D15: =CONCATENATE(_xll.BDP(Inputs!E21,"CRNCY")," ",_xll.BDP(Inputs!E21,"PX_YEST_CLOSE")) -> USD 125,34 | E15: =_xll.BDP(Inputs!E21,"PX_YEST_CLOSE")/_xll.BDP(Inputs!E21,"HIGH_52WEEK") -> 0.96166461 | F15: =_xll.BDP(Inputs!$E21, "CUR_MKT_CAP", "SCALING_FORMAT=" & Inputs!$R$18) -> 3119.9483 | G15: =_xll.BDP(Inputs!$E21, "ENTERPRISE_VALUE", "SCALING_FORMAT=" & Inputs!$R$18) -> 6736.4175 | I15: =G15/_xll.BQL(Inputs!$E21, "sales_rev_turn(fpt = ltm, fa_adjusted = y, fs = mr)/1"&IF(Inputs!$R$18="BLN","b",IF(Inputs!$R$18="MLN","m","k"))) -> #NAME? | J15: =G15/_xll.BQL(Inputs!$E21, "sales_rev_turn(fpr = 2025, fpt = a, ae = e, fa_adjusted = y, fs = mr)/1"&IF(Inputs!$R$18="BLN","b",IF(Inputs!$R$18="MLN","m","k"))) -> #NAME? | K15: =G15/_xll.BQL(Inputs!$E21, "sales_rev_turn(fpr = 2026, fpt = a, ae = e, fa_adjusted = y, fs = mr)/1"&IF(Inputs!$R$18="BLN","b",IF(Inputs!$R$18="MLN","m","k"))) -> #NAME? | L15: =G15/_xll.BQL(Inputs!$E21, "ebitda(fpt = ltm, fa_adjusted = y, fs = mr)/1"&IF(Inputs!$R$18="BLN","b",IF(Inputs!$R$18="MLN","m","k"))) -> #NAME? | M15: =G15/_xll.BQL(Inputs!$E21, "ebitda(fpr = 2025, fpt = a, ae = e, fa_adjusted = y, fs = mr)/1"&IF(Inputs!$R$18="BLN","b",IF(Inputs!$R$18="MLN","m","k"))) -> #NAME? | N15: =G15/_xll.BQL(Inputs!$E21, "ebitda(fpr = 2026, fpt = a, ae = e, fa_adjusted = y, fs = mr)/1"&IF(Inputs!$R$18="BLN","b",IF(Inputs!$R$18="MLN","m","k"))) -> #NAME? | O15: =G15/_xll.BQL(Inputs!$E21, "is_oper_inc(fpt = ltm, fa_adjusted = y, fs = mr)/1"&IF(Inputs!$R$18="BLN","b",IF(Inputs!$R$18="MLN","m","k"))) -> #NAME? | P15: =G15/_xll.BQL(Inputs!$E21, "is_oper_inc(fpr = 2025, fpt = a, ae = e, fa_adjusted = y, fs = mr)/1"&IF(Inputs!$R$18="BLN","b",IF(Inputs!$R$18="MLN","m","k"))) -> #NAME? | Q15: =G15/_xll.BQL(Inputs!$E21, "is_oper_inc(fpr = 2026, fpt = a, ae = e, fa_adjusted = y, fs = mr)/1"&IF(Inputs!$R$18="BLN","b",IF(Inputs!$R$18="MLN","m","k"))) -> #NAME? | R15: is_oper_inc(fpr=2026,fpt=a,ae=e,fa_adjusted=y,fs=mr)/1m | S15: =_xll.BQL(Inputs!$E21, "ebitda(fpt = ltm, fa_adjusted = y, fs = mr)/1"&IF(Inputs!$R$18="BLN","b",IF(Inputs!$R$18="MLN","m","k")))/_xll.BQL(Inputs!$E21, "sales_rev_turn(fpt = ltm, fa_adjusted = y, fs = mr)/1"&IF(Inputs!$R$18="BLN","b",IF(Inputs!$R$18="MLN","m","k"))) -> #NAME? | T15: =_xll.BDP(Inputs!$E21,"TOT_DEBT_TO_EBITDA") -> #NAME? | V15: =F15/_xll.BQL(Inputs!$E21, "earn_for_common(fpt = ltm, fa_adjusted = y, fs = mr)/1"&IF(Inputs!$R$18="BLN","b",IF(Inputs!$R$18="MLN","m","k"))) -> #NAME? | W15: =F15/_xll.BQL(Inputs!$E21, "EARN_FOR_COMMON(fpr = 2025, fpt = a, ae = e, fa_adjusted = y, fs = mr)/1"&IF(Inputs!$R$18="BLN","b",IF(Inputs!$R$18="MLN","m","k"))) -> #NAME? | X15: =F15/_xll.BQL(Inputs!$E21, "EARN_FOR_COMMON(fpr = 2026, fpt = a, ae = e, fa_adjusted = y, fs = mr)/1"&IF(Inputs!$R$18="BLN","b",IF(Inputs!$R$18="MLN","m","k"))) -> #NAME? | Y15: EARN_FOR_COMMON(fpr=2026,fpt=a,ae=e,fa_adjusted=y,fs=mr)/1m | Z15: =(_xll.BQL(Inputs!$E21, "EARN_FOR_COMMON(fpr = 2028, fpt = a, ae = e, fa_adjusted = y, fs = mr)")/_xll.BQL(Inputs!$E21, "EARN_FOR_COMMON(fpr = 2025, fpt = a, ae = e, fa_adjusted = y, fs = mr)"))^(1/3)-1 -> #NAME? | AA15: EARN_FOR_COMMON(fpr=2028,fpt=a,ae=e,fa_adjusted=y,fs=mr)
B16: =+Inputs!B22 -> REGIONAL MANAGEM | C16: =+_xll.BDP(Inputs!E22,"TICKER_AND_EXCH_CODE") -> RM US | D16: =CONCATENATE(_xll.BDP(Inputs!E22,"CRNCY")," ",_xll.BDP(Inputs!E22,"PX_YEST_CLOSE")) -> USD 43,46 | E16: =_xll.BDP(Inputs!E22,"PX_YEST_CLOSE")/_xll.BDP(Inputs!E22,"HIGH_52WEEK") -> 0.94478261 | F16: =_xll.BDP(Inputs!$E22, "CUR_MKT_CAP", "SCALING_FORMAT=" & Inputs!$R$18) -> 422.92769 | G16: =_xll.BDP(Inputs!$E22, "ENTERPRISE_VALUE", "SCALING_FORMAT=" & Inputs!$R$18) -> 1833.757 | I16: =G16/_xll.BQL(Inputs!$E22, "sales_rev_turn(fpt = ltm, fa_adjusted = y, fs = mr)/1"&IF(Inputs!$R$18="BLN","b",IF(Inputs!$R$18="MLN","m","k"))) -> #NAME? | J16: =G16/_xll.BQL(Inputs!$E22, "sales_rev_turn(fpr = 2025, fpt = a, ae = e, fa_adjusted = y, fs = mr)/1"&IF(Inputs!$R$18="BLN","b",IF(Inputs!$R$18="MLN","m","k"))) -> #NAME? | K16: =G16/_xll.BQL(Inputs!$E22, "sales_rev_turn(fpr = 2026, fpt = a, ae = e, fa_adjusted = y, fs = mr)/1"&IF(Inputs!$R$18="BLN","b",IF(Inputs!$R$18="MLN","m","k"))) -> #NAME? | L16: =G16/_xll.BQL(Inputs!$E22, "ebitda(fpt = ltm, fa_adjusted = y, fs = mr)/1"&IF(Inputs!$R$18="BLN","b",IF(Inputs!$R$18="MLN","m","k"))) -> #NAME? | M16: =G16/_xll.BQL(Inputs!$E22, "ebitda(fpr = 2025, fpt = a, ae = e, fa_adjusted = y, fs = mr)/1"&IF(Inputs!$R$18="BLN","b",IF(Inputs!$R$18="MLN","m","k"))) -> #NAME? | N16: =G16/_xll.BQL(Inputs!$E22, "ebitda(fpr = 2026, fpt = a, ae = e, fa_adjusted = y, fs = mr)/1"&IF(Inputs!$R$18="BLN","b",IF(Inputs!$R$18="MLN","m","k"))) -> #NAME? | O16: =G16/_xll.BQL(Inputs!$E22, "is_oper_inc(fpt = ltm, fa_adjusted = y, fs = mr)/1"&IF(Inputs!$R$18="BLN","b",IF(Inputs!$R$18="MLN","m","k"))) -> #NAME? | P16: =G16/_xll.BQL(Inputs!$E22, "is_oper_inc(fpr = 2025, fpt = a, ae = e, fa_adjusted = y, fs = mr)/1"&IF(Inputs!$R$18="BLN","b",IF(Inputs!$R$18="MLN","m","k"))) -> #NAME? | Q16: =G16/_xll.BQL(Inputs!$E22, "is_oper_inc(fpr = 2026, fpt = a, ae = e, fa_adjusted = y, fs = mr)/1"&IF(Inputs!$R$18="BLN","b",IF(Inputs!$R$18="MLN","m","k"))) -> #NAME? | R16: #N/A | S16: =_xll.BQL(Inputs!$E22, "ebitda(fpt = ltm, fa_adjusted = y, fs = mr)/1"&IF(Inputs!$R$18="BLN","b",IF(Inputs!$R$18="MLN","m","k")))/_xll.BQL(Inputs!$E22, "sales_rev_turn(fpt = ltm, fa_adjusted = y, fs = mr)/1"&IF(Inputs!$R$18="BLN","b",IF(Inputs!$R$18="MLN","m","k"))) -> #NAME? | T16: =_xll.BDP(Inputs!$E22,"TOT_DEBT_TO_EBITDA") -> #NAME? | V16: =F16/_xll.BQL(Inputs!$E22, "earn_for_common(fpt = ltm, fa_adjusted = y, fs = mr)/1"&IF(Inputs!$R$18="BLN","b",IF(Inputs!$R$18="MLN","m","k"))) -> #NAME? | W16: =F16/_xll.BQL(Inputs!$E22, "EARN_FOR_COMMON(fpr = 2025, fpt = a, ae = e, fa_adjusted = y, fs = mr)/1"&IF(Inputs!$R$18="BLN","b",IF(Inputs!$R$18="MLN","m","k"))) -> #NAME? | X16: =F16/_xll.BQL(Inputs!$E22, "EARN_FOR_COMMON(fpr = 2026, fpt = a, ae = e, fa_adjusted = y, fs = mr)/1"&IF(Inputs!$R$18="BLN","b",IF(Inputs!$R$18="MLN","m","k"))) -> #NAME? | Y16: #N/A | Z16: =(_xll.BQL(Inputs!$E22, "EARN_FOR_COMMON(fpr = 2028, fpt = a, ae = e, fa_adjusted = y, fs = mr)")/_xll.BQL(Inputs!$E22, "EARN_FOR_COMMON(fpr = 2025, fpt = a, ae = e, fa_adjusted = y, fs = mr)"))^(1/3)-1 -> #NAME? | AA16: #N/A
B17: =+Inputs!B23 -> WORLD ACCEPTANCE | C17: =+_xll.BDP(Inputs!E23,"TICKER_AND_EXCH_CODE") -> WRLD US | D17: =CONCATENATE(_xll.BDP(Inputs!E23,"CRNCY")," ",_xll.BDP(Inputs!E23,"PX_YEST_CLOSE")) -> USD 175,41 | E17: =_xll.BDP(Inputs!E23,"PX_YEST_CLOSE")/_xll.BDP(Inputs!E23,"HIGH_52WEEK") -> 0.9831848 | F17: =_xll.BDP(Inputs!$E23, "CUR_MKT_CAP", "SCALING_FORMAT=" & Inputs!$R$18) -> 964.12231 | G17: =_xll.BDP(Inputs!$E23, "ENTERPRISE_VALUE", "SCALING_FORMAT=" & Inputs!$R$18) -> 1439.4902 | I17: =G17/_xll.BQL(Inputs!$E23, "sales_rev_turn(fpt = ltm, fa_adjusted = y, fs = mr)/1"&IF(Inputs!$R$18="BLN","b",IF(Inputs!$R$18="MLN","m","k"))) -> #NAME? | J17: =G17/_xll.BQL(Inputs!$E23, "sales_rev_turn(fpr = 2025, fpt = a, ae = e, fa_adjusted = y, fs = mr)/1"&IF(Inputs!$R$18="BLN","b",IF(Inputs!$R$18="MLN","m","k"))) -> #NAME? | K17: =G17/_xll.BQL(Inputs!$E23, "sales_rev_turn(fpr = 2026, fpt = a, ae = e, fa_adjusted = y, fs = mr)/1"&IF(Inputs!$R$18="BLN","b",IF(Inputs!$R$18="MLN","m","k"))) -> #NAME? | L17: =G17/_xll.BQL(Inputs!$E23, "ebitda(fpt = ltm, fa_adjusted = y, fs = mr)/1"&IF(Inputs!$R$18="BLN","b",IF(Inputs!$R$18="MLN","m","k"))) -> #NAME? | M17: =G17/_xll.BQL(Inputs!$E23, "ebitda(fpr = 2025, fpt = a, ae = e, fa_adjusted = y, fs = mr)/1"&IF(Inputs!$R$18="BLN","b",IF(Inputs!$R$18="MLN","m","k"))) -> #NAME? | N17: =G17/_xll.BQL(Inputs!$E23, "ebitda(fpr = 2026, fpt = a, ae = e, fa_adjusted = y, fs = mr)/1"&IF(Inputs!$R$18="BLN","b",IF(Inputs!$R$18="MLN","m","k"))) -> #NAME? | O17: =G17/_xll.BQL(Inputs!$E23, "is_oper_inc(fpt = ltm, fa_adjusted = y, fs = mr)/1"&IF(Inputs!$R$18="BLN","b",IF(Inputs!$R$18="MLN","m","k"))) -> #NAME? | P17: =G17/_xll.BQL(Inputs!$E23, "is_oper_inc(fpr = 2025, fpt = a, ae = e, fa_adjusted = y, fs = mr)/1"&IF(Inputs!$R$18="BLN","b",IF(Inputs!$R$18="MLN","m","k"))) -> #NAME? | Q17: =G17/_xll.BQL(Inputs!$E23, "is_oper_inc(fpr = 2026, fpt = a, ae = e, fa_adjusted = y, fs = mr)/1"&IF(Inputs!$R$18="BLN","b",IF(Inputs!$R$18="MLN","m","k"))) -> #NAME? | R17: #N/A | S17: =_xll.BQL(Inputs!$E23, "ebitda(fpt = ltm, fa_adjusted = y, fs = mr)/1"&IF(Inputs!$R$18="BLN","b",IF(Inputs!$R$18="MLN","m","k")))/_xll.BQL(Inputs!$E23, "sales_rev_turn(fpt = ltm, fa_adjusted = y, fs = mr)/1"&IF(Inputs!$R$18="BLN","b",IF(Inputs!$R$18="MLN","m","k"))) -> #NAME? | T17: =_xll.BDP(Inputs!$E23,"TOT_DEBT_TO_EBITDA") -> #NAME? | V17: =F17/_xll.BQL(Inputs!$E23, "earn_for_common(fpt = ltm, fa_adjusted = y, fs = mr)/1"&IF(Inputs!$R$18="BLN","b",IF(Inputs!$R$18="MLN","m","k"))) -> #NAME? | W17: =F17/_xll.BQL(Inputs!$E23, "EARN_FOR_COMMON(fpr = 2025, fpt = a, ae = e, fa_adjusted = y, fs = mr)/1"&IF(Inputs!$R$18="BLN","b",IF(Inputs!$R$18="MLN","m","k"))) -> #NAME? | X17: =F17/_xll.BQL(Inputs!$E23, "EARN_FOR_COMMON(fpr = 2026, fpt = a, ae = e, fa_adjusted = y, fs = mr)/1"&IF(Inputs!$R$18="BLN","b",IF(Inputs!$R$18="MLN","m","k"))) -> #NAME? | Y17: #N/A | Z17: =(_xll.BQL(Inputs!$E23, "EARN_FOR_COMMON(fpr = 2028, fpt = a, ae = e, fa_adjusted = y, fs = mr)")/_xll.BQL(Inputs!$E23, "EARN_FOR_COMMON(fpr = 2025, fpt = a, ae = e, fa_adjusted = y, fs = mr)"))^(1/3)-1 -> #NAME? | AA17: #N/A
B18: =+Inputs!B24 -> EZCORP INC-A | C18: =+_xll.BDP(Inputs!E24,"TICKER_AND_EXCH_CODE") -> EZPW US | D18: =CONCATENATE(_xll.BDP(Inputs!E24,"CRNCY")," ",_xll.BDP(Inputs!E24,"PX_YEST_CLOSE")) -> USD 17,96 | E18: =_xll.BDP(Inputs!E24,"PX_YEST_CLOSE")/_xll.BDP(Inputs!E24,"HIGH_52WEEK") -> 0.97874659 | F18: =_xll.BDP(Inputs!$E24, "CUR_MKT_CAP", "SCALING_FORMAT=" & Inputs!$R$18) -> 1107.0918 | G18: =_xll.BDP(Inputs!$E24, "ENTERPRISE_VALUE", "SCALING_FORMAT=" & Inputs!$R$18) -> 1136.1593 | I18: =G18/_xll.BQL(Inputs!$E24, "sales_rev_turn(fpt = ltm, fa_adjusted = y, fs = mr)/1"&IF(Inputs!$R$18="BLN","b",IF(Inputs!$R$18="MLN","m","k"))) -> 0.92219377 | J18: =G18/_xll.BQL(Inputs!$E24, "sales_rev_turn(fpr = 2025, fpt = a, ae = e, fa_adjusted = y, fs = mr)/1"&IF(Inputs!$R$18="BLN","b",IF(Inputs!$R$18="MLN","m","k"))) -> 0.90762049 | K18: =G18/_xll.BQL(Inputs!$E24, "sales_rev_turn(fpr = 2026, fpt = a, ae = e, fa_adjusted = y, fs = mr)/1"&IF(Inputs!$R$18="BLN","b",IF(Inputs!$R$18="MLN","m","k"))) -> 0.85361332 | L18: =G18/_xll.BQL(Inputs!$E24, "ebitda(fpt = ltm, fa_adjusted = y, fs = mr)/1"&IF(Inputs!$R$18="BLN","b",IF(Inputs!$R$18="MLN","m","k"))) -> 4.5775222 | M18: =G18/_xll.BQL(Inputs!$E24, "ebitda(fpr = 2025, fpt = a, ae = e, fa_adjusted = y, fs = mr)/1"&IF(Inputs!$R$18="BLN","b",IF(Inputs!$R$18="MLN","m","k"))) -> 6.1248481 | N18: =G18/_xll.BQL(Inputs!$E24, "ebitda(fpr = 2026, fpt = a, ae = e, fa_adjusted = y, fs = mr)/1"&IF(Inputs!$R$18="BLN","b",IF(Inputs!$R$18="MLN","m","k"))) -> 5.4940006 | O18: =G18/_xll.BQL(Inputs!$E24, "is_oper_inc(fpt = ltm, fa_adjusted = y, fs = mr)/1"&IF(Inputs!$R$18="BLN","b",IF(Inputs!$R$18="MLN","m","k"))) -> 8.2394869 | P18: =G18/_xll.BQL(Inputs!$E24, "is_oper_inc(fpr = 2025, fpt = a, ae = e, fa_adjusted = y, fs = mr)/1"&IF(Inputs!$R$18="BLN","b",IF(Inputs!$R$18="MLN","m","k"))) -> 7.7080009 | Q18: =G18/_xll.BQL(Inputs!$E24, "is_oper_inc(fpr = 2026, fpt = a, ae = e, fa_adjusted = y, fs = mr)/1"&IF(Inputs!$R$18="BLN","b",IF(Inputs!$R$18="MLN","m","k"))) -> 6.6911621 | S18: =_xll.BQL(Inputs!$E24, "ebitda(fpt = ltm, fa_adjusted = y, fs = mr)/1"&IF(Inputs!$R$18="BLN","b",IF(Inputs!$R$18="MLN","m","k")))/_xll.BQL(Inputs!$E24, "sales_rev_turn(fpt = ltm, fa_adjusted = y, fs = mr)/1"&IF(Inputs!$R$18="BLN","b",IF(Inputs!$R$18="MLN","m","k"))) -> 0.20146134 | T18: =_xll.BDP(Inputs!$E24,"TOT_DEBT_TO_EBITDA") -> 3.0666793 | V18: =F18/_xll.BQL(Inputs!$E24, "earn_for_common(fpt = ltm, fa_adjusted = y, fs = mr)/1"&IF(Inputs!$R$18="BLN","b",IF(Inputs!$R$18="MLN","m","k"))) -> 11.30888 | W18: =F18/_xll.BQL(Inputs!$E24, "EARN_FOR_COMMON(fpr = 2025, fpt = a, ae = e, fa_adjusted = y, fs = mr)/1"&IF(Inputs!$R$18="BLN","b",IF(Inputs!$R$18="MLN","m","k"))) -> 10.330561 | X18: =F18/_xll.BQL(Inputs!$E24, "EARN_FOR_COMMON(fpr = 2026, fpt = a, ae = e, fa_adjusted = y, fs = mr)/1"&IF(Inputs!$R$18="BLN","b",IF(Inputs!$R$18="MLN","m","k"))) -> 9.8262582 | Z18: =(_xll.BQL(Inputs!$E24, "EARN_FOR_COMMON(fpr = 2028, fpt = a, ae = e, fa_adjusted = y, fs = mr)")/_xll.BQL(Inputs!$E24, "EARN_FOR_COMMON(fpr = 2025, fpt = a, ae = e, fa_adjusted = y, fs = mr)"))^(1/3)-1 -> 0.093174362
B19: =+Inputs!B25 -> ONEMAIN HOLDINGS | C19: =+_xll.BDP(Inputs!E25,"TICKER_AND_EXCH_CODE") -> OMF US | D19: =CONCATENATE(_xll.BDP(Inputs!E25,"CRNCY")," ",_xll.BDP(Inputs!E25,"PX_YEST_CLOSE")) -> USD 60,41 | E19: =_xll.BDP(Inputs!E25,"PX_YEST_CLOSE")/_xll.BDP(Inputs!E25,"HIGH_52WEEK") -> 0.95517432 | F19: =_xll.BDP(Inputs!$E25, "CUR_MKT_CAP", "SCALING_FORMAT=" & Inputs!$R$18) -> 7198.9738 | G19: =_xll.BDP(Inputs!$E25, "ENTERPRISE_VALUE", "SCALING_FORMAT=" & Inputs!$R$18) -> 28058.848 | I19: =G19/_xll.BQL(Inputs!$E25, "sales_rev_turn(fpt = ltm, fa_adjusted = y, fs = mr)/1"&IF(Inputs!$R$18="BLN","b",IF(Inputs!$R$18="MLN","m","k"))) -> 4.6913306 | J19: =G19/_xll.BQL(Inputs!$E25, "sales_rev_turn(fpr = 2025, fpt = a, ae = e, fa_adjusted = y, fs = mr)/1"&IF(Inputs!$R$18="BLN","b",IF(Inputs!$R$18="MLN","m","k"))) -> 5.6728951 | K19: =G19/_xll.BQL(Inputs!$E25, "sales_rev_turn(fpr = 2026, fpt = a, ae = e, fa_adjusted = y, fs = mr)/1"&IF(Inputs!$R$18="BLN","b",IF(Inputs!$R$18="MLN","m","k"))) -> 5.354888 | L19: =G19/_xll.BQL(Inputs!$E25, "ebitda(fpt = ltm, fa_adjusted = y, fs = mr)/1"&IF(Inputs!$R$18="BLN","b",IF(Inputs!$R$18="MLN","m","k"))) -> 11.504243 | M19: =G19/_xll.BQL(Inputs!$E25, "ebitda(fpr = 2025, fpt = a, ae = e, fa_adjusted = y, fs = mr)/1"&IF(Inputs!$R$18="BLN","b",IF(Inputs!$R$18="MLN","m","k"))) -> 11.39677 | N19: =G19/_xll.BQL(Inputs!$E25, "ebitda(fpr = 2026, fpt = a, ae = e, fa_adjusted = y, fs = mr)/1"&IF(Inputs!$R$18="BLN","b",IF(Inputs!$R$18="MLN","m","k"))) -> 10.181004 | O19: =G19/_xll.BQL(Inputs!$E25, "is_oper_inc(fpt = ltm, fa_adjusted = y, fs = mr)/1"&IF(Inputs!$R$18="BLN","b",IF(Inputs!$R$18="MLN","m","k"))) -> 30.665408 | P19: =G19/_xll.BQL(Inputs!$E25, "is_oper_inc(fpr = 2025, fpt = a, ae = e, fa_adjusted = y, fs = mr)/1"&IF(Inputs!$R$18="BLN","b",IF(Inputs!$R$18="MLN","m","k"))) -> 35.528773 | Q19: =G19/_xll.BQL(Inputs!$E25, "is_oper_inc(fpr = 2026, fpt = a, ae = e, fa_adjusted = y, fs = mr)/1"&IF(Inputs!$R$18="BLN","b",IF(Inputs!$R$18="MLN","m","k"))) -> 31.464927 | S19: =_xll.BQL(Inputs!$E25, "ebitda(fpt = ltm, fa_adjusted = y, fs = mr)/1"&IF(Inputs!$R$18="BLN","b",IF(Inputs!$R$18="MLN","m","k")))/_xll.BQL(Inputs!$E25, "sales_rev_turn(fpt = ltm, fa_adjusted = y, fs = mr)/1"&IF(Inputs!$R$18="BLN","b",IF(Inputs!$R$18="MLN","m","k"))) -> 0.40779134 | T19: =_xll.BDP(Inputs!$E25,"TOT_DEBT_TO_EBITDA") -> 9.2504195 | V19: =F19/_xll.BQL(Inputs!$E25, "earn_for_common(fpt = ltm, fa_adjusted = y, fs = mr)/1"&IF(Inputs!$R$18="BLN","b",IF(Inputs!$R$18="MLN","m","k"))) -> 10.190352 | W19: =F19/_xll.BQL(Inputs!$E25, "EARN_FOR_COMMON(fpr = 2025, fpt = a, ae = e, fa_adjusted = y, fs = mr)/1"&IF(Inputs!$R$18="BLN","b",IF(Inputs!$R$18="MLN","m","k"))) -> 9.4516068 | X19: =F19/_xll.BQL(Inputs!$E25, "EARN_FOR_COMMON(fpr = 2026, fpt = a, ae = e, fa_adjusted = y, fs = mr)/1"&IF(Inputs!$R$18="BLN","b",IF(Inputs!$R$18="MLN","m","k"))) -> 7.5842539 | Z19: =(_xll.BQL(Inputs!$E25, "EARN_FOR_COMMON(fpr = 2028, fpt = a, ae = e, fa_adjusted = y, fs = mr)")/_xll.BQL(Inputs!$E25, "EARN_FOR_COMMON(fpr = 2025, fpt = a, ae = e, fa_adjusted = y, fs = mr)"))^(1/3)-1 -> 0.19812496
B21: Mean | I21: =AVERAGE(I15:I19) -> #NAME? | J21: =AVERAGE(J15:J19) -> #NAME? | K21: =AVERAGE(K15:K19) -> #NAME? | L21: =AVERAGE(L15:L19) -> #NAME? | M21: =AVERAGE(M15:M19) -> #NAME? | N21: =AVERAGE(N15:N19) -> #NAME? | O21: =AVERAGE(O15:O19) -> #NAME? | P21: =AVERAGE(P15:P19) -> #NAME? | Q21: =AVERAGE(Q15:Q19) -> #NAME? | S21: =AVERAGE(S15:S19) -> #NAME? | T21: =AVERAGE(T15:T19) -> #NAME? | V21: =AVERAGE(V15:V19) -> #NAME? | W21: =AVERAGE(W15:W19) -> #NAME? | X21: =AVERAGE(X15:X19) -> #NAME? | Z21: =AVERAGE(Z15:Z19) -> #NAME?
B22: Median | I22: =MEDIAN(I15:I19) -> #NAME? | J22: =MEDIAN(J15:J19) -> #NAME? | K22: =MEDIAN(K15:K19) -> #NAME? | L22: =MEDIAN(L15:L19) -> #NAME? | M22: =MEDIAN(M15:M19) -> #NAME? | N22: =MEDIAN(N15:N19) -> #NAME? | O22: =MEDIAN(O15:O19) -> #NAME? | P22: =MEDIAN(P15:P19) -> #NAME? | Q22: =MEDIAN(Q15:Q19) -> #NAME? | S22: =MEDIAN(S15:S19) -> #NAME? | T22: =MEDIAN(T15:T19) -> #NAME? | V22: =MEDIAN(V15:V19) -> #NAME? | W22: =MEDIAN(W15:W19) -> #NAME? | X22: =MEDIAN(X15:X19) -> #NAME? | Z22: =MEDIAN(Z15:Z19) -> #NAME?
B24: Tier II: Other Fintech and Credit
B27: =+Inputs!H21 -> LENDINGCLUB CORP | C27: =+_xll.BDP(Inputs!K21,"TICKER_AND_EXCH_CODE") -> LC US | D27: =CONCATENATE(_xll.BDP(Inputs!K21,"CRNCY")," ",_xll.BDP(Inputs!K21,"PX_YEST_CLOSE")) -> USD 17,13 | E27: =_xll.BDP(Inputs!K21,"PX_YEST_CLOSE")/_xll.BDP(Inputs!K21,"HIGH_52WEEK") -> 0.9136 | F27: =_xll.BDP(Inputs!$K21, "CUR_MKT_CAP", "SCALING_FORMAT=" & Inputs!$R$18) -> 1951.1562 | G27: =_xll.BDP(Inputs!$K21, "ENTERPRISE_VALUE", "SCALING_FORMAT=" & Inputs!$R$18) -> 235.41797 | I27: =G27/_xll.BQL(Inputs!$K21, "sales_rev_turn(fpt = ltm, fa_adjusted = y, fs = mr)/1"&IF(Inputs!$R$18="BLN","b",IF(Inputs!$R$18="MLN","m","k"))) -> 0.18855672 | J27: =G27/_xll.BQL(Inputs!$K21, "sales_rev_turn(fpr = 2025, fpt = a, ae = e, fa_adjusted = y, fs = mr)/1"&IF(Inputs!$R$18="BLN","b",IF(Inputs!$R$18="MLN","m","k"))) -> 0.23988862 | K27: =G27/_xll.BQL(Inputs!$K21, "sales_rev_turn(fpr = 2026, fpt = a, ae = e, fa_adjusted = y, fs = mr)/1"&IF(Inputs!$R$18="BLN","b",IF(Inputs!$R$18="MLN","m","k"))) -> 0.2075497 | L27: =G27/_xll.BQL(Inputs!$K21, "ebitda(fpt = ltm, fa_adjusted = y, fs = mr)/1"&IF(Inputs!$R$18="BLN","b",IF(Inputs!$R$18="MLN","m","k"))) -> 0.43982724 | M27: =G27/_xll.BQL(Inputs!$K21, "ebitda(fpr = 2025, fpt = a, ae = e, fa_adjusted = y, fs = mr)/1"&IF(Inputs!$R$18="BLN","b",IF(Inputs!$R$18="MLN","m","k"))) -> 0.79265309 | N27: =G27/_xll.BQL(Inputs!$K21, "ebitda(fpr = 2026, fpt = a, ae = e, fa_adjusted = y, fs = mr)/1"&IF(Inputs!$R$18="BLN","b",IF(Inputs!$R$18="MLN","m","k"))) -> 0.4940566 | O27: =G27/_xll.BQL(Inputs!$K21, "is_oper_inc(fpt = ltm, fa_adjusted = y, fs = mr)/1"&IF(Inputs!$R$18="BLN","b",IF(Inputs!$R$18="MLN","m","k"))) -> 2.3828936 | P27: =G27/_xll.BQL(Inputs!$K21, "is_oper_inc(fpr = 2025, fpt = a, ae = e, fa_adjusted = y, fs = mr)/1"&IF(Inputs!$R$18="BLN","b",IF(Inputs!$R$18="MLN","m","k"))) -> 1.6936544 | Q27: =G27/_xll.BQL(Inputs!$K21, "is_oper_inc(fpr = 2026, fpt = a, ae = e, fa_adjusted = y, fs = mr)/1"&IF(Inputs!$R$18="BLN","b",IF(Inputs!$R$18="MLN","m","k"))) -> 1.4354754 | S27: =_xll.BQL(Inputs!$K21, "ebitda(fpt = ltm, fa_adjusted = y, fs = mr)/1"&IF(Inputs!$R$18="BLN","b",IF(Inputs!$R$18="MLN","m","k")))/_xll.BQL(Inputs!$K21, "sales_rev_turn(fpt = ltm, fa_adjusted = y, fs = mr)/1"&IF(Inputs!$R$18="BLN","b",IF(Inputs!$R$18="MLN","m","k"))) -> 0.42870633 | T27: =_xll.BDP(Inputs!$K21,"TOT_DEBT_TO_EBITDA") -> 0.06717596 | V27: =F27/_xll.BQL(Inputs!$K21, "earn_for_common(fpt = ltm, fa_adjusted = y, fs = mr)/1"&IF(Inputs!$R$18="BLN","b",IF(Inputs!$R$18="MLN","m","k"))) -> 26.357715 | W27: =F27/_xll.BQL(Inputs!$K21, "EARN_FOR_COMMON(fpr = 2025, fpt = a, ae = e, fa_adjusted = y, fs = mr)/1"&IF(Inputs!$R$18="BLN","b",IF(Inputs!$R$18="MLN","m","k"))) -> 16.244594 | X27: =F27/_xll.BQL(Inputs!$K21, "EARN_FOR_COMMON(fpr = 2026, fpt = a, ae = e, fa_adjusted = y, fs = mr)/1"&IF(Inputs!$R$18="BLN","b",IF(Inputs!$R$18="MLN","m","k"))) -> 11.746091 | Z27: =(_xll.BQL(Inputs!$K21, "EARN_FOR_COMMON(fpr = 2028, fpt = a, ae = e, fa_adjusted = y, fs = mr)")/_xll.BQL(Inputs!$K21, "EARN_FOR_COMMON(fpr = 2025, fpt = a, ae = e, fa_adjusted = y, fs = mr)"))^(1/3)-1 -> #VALUE!
B28: =+Inputs!H22 -> UPSTART HOLDINGS | C28: =+_xll.BDP(Inputs!K22,"TICKER_AND_EXCH_CODE") -> UPST US | D28: =CONCATENATE(_xll.BDP(Inputs!K22,"CRNCY")," ",_xll.BDP(Inputs!K22,"PX_YEST_CLOSE")) -> USD 62,38 | E28: =_xll.BDP(Inputs!K22,"PX_YEST_CLOSE")/_xll.BDP(Inputs!K22,"HIGH_52WEEK") -> 0.64689815 | F28: =_xll.BDP(Inputs!$K22, "CUR_MKT_CAP", "SCALING_FORMAT=" & Inputs!$R$18) -> 6074.2261 | G28: =_xll.BDP(Inputs!$K22, "ENTERPRISE_VALUE", "SCALING_FORMAT=" & Inputs!$R$18) -> 7250.3101 | I28: =G28/_xll.BQL(Inputs!$K22, "sales_rev_turn(fpt = ltm, fa_adjusted = y, fs = mr)/1"&IF(Inputs!$R$18="BLN","b",IF(Inputs!$R$18="MLN","m","k"))) -> 8.5120914 | J28: =G28/_xll.BQL(Inputs!$K22, "sales_rev_turn(fpt = ltm, fa_adjusted = y, fs = mr)/1"&IF(Inputs!$R$18="BLN","b",IF(Inputs!$R$18="MLN","m","k"))) -> 8.5120914 | K28: =G28/_xll.BQL(Inputs!$K22, "sales_rev_turn(fpr = 2026, fpt = a, ae = e, fa_adjusted = y, fs = mr)/1"&IF(Inputs!$R$18="BLN","b",IF(Inputs!$R$18="MLN","m","k"))) -> 5.3914241 | L28: =G28/_xll.BQL(Inputs!$K22, "ebitda(fpt = ltm, fa_adjusted = y, fs = mr)/1"&IF(Inputs!$R$18="BLN","b",IF(Inputs!$R$18="MLN","m","k"))) -> 93.507746 | M28: =G28/_xll.BQL(Inputs!$K22, "ebitda(fpr = 2025, fpt = a, ae = e, fa_adjusted = y, fs = mr)/1"&IF(Inputs!$R$18="BLN","b",IF(Inputs!$R$18="MLN","m","k"))) -> 32.683592 | N28: =G28/_xll.BQL(Inputs!$K22, "ebitda(fpr = 2026, fpt = a, ae = e, fa_adjusted = y, fs = mr)/1"&IF(Inputs!$R$18="BLN","b",IF(Inputs!$R$18="MLN","m","k"))) -> 22.215877 | O28: =G28/_xll.BQL(Inputs!$K22, "is_oper_inc(fpt = ltm, fa_adjusted = y, fs = mr)/1"&IF(Inputs!$R$18="BLN","b",IF(Inputs!$R$18="MLN","m","k"))) -> 131.3343 | P28: =G28/_xll.BQL(Inputs!$K22, "is_oper_inc(fpr = 2025, fpt = a, ae = e, fa_adjusted = y, fs = mr)/1"&IF(Inputs!$R$18="BLN","b",IF(Inputs!$R$18="MLN","m","k"))) -> 228.13348 | Q28: =G28/_xll.BQL(Inputs!$K22, "is_oper_inc(fpr = 2026, fpt = a, ae = e, fa_adjusted = y, fs = mr)/1"&IF(Inputs!$R$18="BLN","b",IF(Inputs!$R$18="MLN","m","k"))) -> 48.381436 | S28: =_xll.BQL(Inputs!$K22, "ebitda(fpt = ltm, fa_adjusted = y, fs = mr)/1"&IF(Inputs!$R$18="BLN","b",IF(Inputs!$R$18="MLN","m","k")))/_xll.BQL(Inputs!$K22, "sales_rev_turn(fpt = ltm, fa_adjusted = y, fs = mr)/1"&IF(Inputs!$R$18="BLN","b",IF(Inputs!$R$18="MLN","m","k"))) -> 0.09103087 | T28: =_xll.BDP(Inputs!$K22,"TOT_DEBT_TO_EBITDA") -> #N/A N/A | V28: =F28/_xll.BQL(Inputs!$K22, "earn_for_common(fpt = ltm, fa_adjusted = y, fs = mr)/1"&IF(Inputs!$R$18="BLN","b",IF(Inputs!$R$18="MLN","m","k"))) -> 252.44649 | W28: =F28/_xll.BQL(Inputs!$K22, "EARN_FOR_COMMON(fpr = 2025, fpt = a, ae = e, fa_adjusted = y, fs = mr)/1"&IF(Inputs!$R$18="BLN","b",IF(Inputs!$R$18="MLN","m","k"))) -> 34.194722 | X28: =F28/_xll.BQL(Inputs!$K22, "EARN_FOR_COMMON(fpr = 2026, fpt = a, ae = e, fa_adjusted = y, fs = mr)/1"&IF(Inputs!$R$18="BLN","b",IF(Inputs!$R$18="MLN","m","k"))) -> 23.798957 | Z28: =(_xll.BQL(Inputs!$K22, "EARN_FOR_COMMON(fpr = 2028, fpt = a, ae = e, fa_adjusted = y, fs = mr)")/_xll.BQL(Inputs!$K22, "EARN_FOR_COMMON(fpr = 2025, fpt = a, ae = e, fa_adjusted = y, fs = mr)"))^(1/3)-1 -> 0.23302189
