Workbook
Name COOLFUCNTION: _xlfn.LAMBDA(_xldudf_BOARDFLARE_EXEC("workbook-settings:coolfucntion"))
Name COOLFUCNTION: _xlfn.LAMBDA(_xldudf_BOARDFLARE_EXEC("workbook-settings:coolfucntion"))
Name COOLFUCNTION: _xlfn.LAMBDA(_xldudf_BOARDFLARE_EXEC("workbook-settings:coolfucntion"))
Name COOLFUCNTION: _xlfn.LAMBDA(_xldudf_BOARDFLARE_EXEC("workbook-settings:coolfucntion"))
Name COOLFUCNTION: _xlfn.LAMBDA(_xldudf_BOARDFLARE_EXEC("workbook-settings:coolfucntion"))
Name COOLFUCNTION: _xlfn.LAMBDA(_xldudf_BOARDFLARE_EXEC("workbook-settings:coolfucntion"))
Name COOLFUCNTION: _xlfn.LAMBDA(_xldudf_BOARDFLARE_EXEC("workbook-settings:coolfucntion"))
Name COOLFUCNTION: _xlfn.LAMBDA(_xldudf_BOARDFLARE_EXEC("workbook-settings:coolfucntion"))
Name COOLFUCNTION: _xlfn.LAMBDA(_xldudf_BOARDFLARE_EXEC("workbook-settings:coolfucntion"))
Name COOLFUCNTION: _xlfn.LAMBDA(_xldudf_BOARDFLARE_EXEC("workbook-settings:coolfucntion"))
Name COOLFUCNTION: _xlfn.LAMBDA(_xldudf_BOARDFLARE_EXEC("workbook-settings:coolfucntion"))
Name Sectors: #REF!
Name Sectors: #REF!
Name Sectors: #REF!
Name Sectors: #REF!
Name Sectors: #REF!
Name Sectors: #REF!
Name Sectors: #REF!
Name Sectors: #REF!

Sheet Dashboard
C154: =+C155+1 -> 45990
C155: =+C156+1 -> 45989
C156: =+C157+1 -> 45988
C157: =+C158+1 -> 45987
C158: =+C159+1 -> 45986
C159: =+C160+1 -> 45985
C160: =+C161+1 -> 45984 | L160: =IF(FCFF!$R$157="Revenue Exit",FCFF!$AF$169,IF(FCFF!$R$157="EBITDA Exit",FCFF!Z169,FCFF!AL169)) -> 188.76742
C161: =+C162+1 -> 45983
C162: =+C163+1 -> 45982 | E162: =IF(FCFF!$R$157="Revenue Exit",FCFF!$AF$169,IF(FCFF!$R$157="EBITDA Exit",FCFF!Z169,FCFF!AL169)) -> 188.76742
C163: =+C164+1 -> 45981 | E163: =E164+($E$162-$E$193)/COUNTA($C$162:$C$192) -> 189.64718
C164: =+C165+1 -> 45980 | E164: =E165+($E$162-$E$193)/COUNTA($C$162:$C$192) -> 190.52694
C165: =+C166+1 -> 45979 | E165: =E166+($E$162-$E$193)/COUNTA($C$162:$C$192) -> 191.4067
C166: =+C167+1 -> 45978 | E166: =E167+($E$162-$E$193)/COUNTA($C$162:$C$192) -> 192.28646
C167: =+C168+1 -> 45977 | E167: =E168+($E$162-$E$193)/COUNTA($C$162:$C$192) -> 193.16622
C168: =+C169+1 -> 45976 | E168: =E169+($E$162-$E$193)/COUNTA($C$162:$C$192) -> 194.04599
C169: =+C170+1 -> 45975 | E169: =E170+($E$162-$E$193)/COUNTA($C$162:$C$192) -> 194.92575
C170: =+C171+1 -> 45974 | E170: =E171+($E$162-$E$193)/COUNTA($C$162:$C$192) -> 195.80551
C171: =+C172+1 -> 45973 | E171: =E172+($E$162-$E$193)/COUNTA($C$162:$C$192) -> 196.68527
C172: =+C173+1 -> 45972 | E172: =E173+($E$162-$E$193)/COUNTA($C$162:$C$192) -> 197.56503
C173: =+C174+1 -> 45971 | E173: =E174+($E$162-$E$193)/COUNTA($C$162:$C$192) -> 198.44479
C174: =+C175+1 -> 45970 | E174: =E175+($E$162-$E$193)/COUNTA($C$162:$C$192) -> 199.32455
... C192: =+C193+1 -> 45952 | E192: =E193+($E$162-$E$193)/COUNTA($C$162:$C$192) -> 215.16024
B193: TODAY | C193: =+'Stock Data'!AM4 -> 45951 | D193: =_xlfn.XLOOKUP(C193,'Stock Data'!$AM$4:$AM$1051,'Stock Data'!$AN$4:$AN$1051) -> 216.04 | E193: =D193 -> 216.04
C194: =+'Stock Data'!AM5 -> 45950 | D194: =_xlfn.XLOOKUP(C194,'Stock Data'!$AM$4:$AM$1051,'Stock Data'!$AN$4:$AN$1051) -> 216.04
C195: =+'Stock Data'!AM6 -> 45949 | D195: =_xlfn.XLOOKUP(C195,'Stock Data'!$AM$4:$AM$1051,'Stock Data'!$AN$4:$AN$1051) -> 215.19
C196: =+'Stock Data'!AM7 -> 45948 | D196: =_xlfn.XLOOKUP(C196,'Stock Data'!$AM$4:$AM$1051,'Stock Data'!$AN$4:$AN$1051) -> 216.05
C197: =+'Stock Data'!AM8 -> 45947 | D197: =_xlfn.XLOOKUP(C197,'Stock Data'!$AM$4:$AM$1051,'Stock Data'!$AN$4:$AN$1051) -> 217.26
C198: =+'Stock Data'!AM9 -> 45946 | D198: =_xlfn.XLOOKUP(C198,'Stock Data'!$AM$4:$AM$1051,'Stock Data'!$AN$4:$AN$1051) -> 220.31
C199: =+'Stock Data'!AM10 -> 45945 | D199: =_xlfn.XLOOKUP(C199,'Stock Data'!$AM$4:$AM$1051,'Stock Data'!$AN$4:$AN$1051) -> 220.31
C200: =+'Stock Data'!AM11 -> 45944 | D200: =_xlfn.XLOOKUP(C200,'Stock Data'!$AM$4:$AM$1051,'Stock Data'!$AN$4:$AN$1051) -> 220.31
C201: =+'Stock Data'!AM12 -> 45943 | D201: =_xlfn.XLOOKUP(C201,'Stock Data'!$AM$4:$AM$1051,'Stock Data'!$AN$4:$AN$1051) -> 223.06
C202: =+'Stock Data'!AM13 -> 45942 | D202: =_xlfn.XLOOKUP(C202,'Stock Data'!$AM$4:$AM$1051,'Stock Data'!$AN$4:$AN$1051) -> 221.76
C203: =+'Stock Data'!AM14 -> 45941 | D203: =_xlfn.XLOOKUP(C203,'Stock Data'!$AM$4:$AM$1051,'Stock Data'!$AN$4:$AN$1051) -> 221.99
C204: =+'Stock Data'!AM15 -> 45940 | D204: =_xlfn.XLOOKUP(C204,'Stock Data'!$AM$4:$AM$1051,'Stock Data'!$AN$4:$AN$1051) -> 223.57
C205: =+'Stock Data'!AM16 -> 45939 | D205: =_xlfn.XLOOKUP(C205,'Stock Data'!$AM$4:$AM$1051,'Stock Data'!$AN$4:$AN$1051) -> 223.57
... C558: =+'Stock Data'!AM369 -> 45586 | D558: =_xlfn.XLOOKUP(C558,'Stock Data'!$AM$4:$AM$1051,'Stock Data'!$AN$4:$AN$1051) -> 248.89

Sheet Key Info
B7: Analysts | F7: LIS – Equity Research | J7: Stock Performance
B12: Mafalda Joana Bento, Co-Head of Equity Research | F12: Recommendation: | H12: Hold
B13: Bsc in Economics, ISEG – Ulisboa | F13: Target Price (FCFF): | H13: 187.91713
B14: mafaldajbento@aln.iseg.ulisboa.pt | F14: Downside: | H14: -0.13017434
B15: Deolize Neto, Analyst
B16: Bsc in Finance, ISEG – Ulisboa | F16: Ticker | H16: UNP
B17: l62144@aln.iseg.ulisboa.pt | F17: Stock Exchange | H17: NYS
B18: Guilherme Tomás, Analyst
B19: Bsc in Applied Mathematics, ISEG – Ulisboa | F19: Current Price | H19: ='Stock Data'!AN4 -> 216.04
B20: l63853@aln.iseg.ulisboa.pt | F20: ="Market Cap (in "&IF(Inputs!$D$14="BLN","billions",IF(Inputs!$D$14="MLN","millions","thousands"))&")" -> Market Cap (in millions) | H20: ='Stock Data'!AQ4 -> 128121.15
F21: Beta | H21: ='Stock Data'!E164 -> 0,81448
F22: % of 52-Week High | H22: ='Stock Data'!E165 -> 0,615945
F23: 100-Day Moving Average | H23: ='Stock Data'!E166 -> 2255855
B25: Reviewed by: | F25: Avg Vol (1 month) | H25: ='Stock Data'!E168 -> 4889126
B26: NAME, Analyst | F26: Shares Outstanding (millions) | H26: ='Stock Data'!E169 -> 5930437
B27: Bsc in XXX, ISEG – Ulisboa | F27: % Float | H27: ='Stock Data'!E170 -> 0.99
B28: email@aln.iseg.ulisboa.pt | F28: Short % of Float | H28: =IFERROR('Stock Data'!E171,0) -> 0.02
B30: LISBON INVESTMENT SOCIETY | F30: % Held by Insiders | H30: ='Stock Data'!E173 -> 0
B31: ISEG – Rua do Quelhas, 6 | F31: % Held by Institutions | H31: ='Stock Data'!E174 -> 0.85
B32: lis@iseg.ulisboa.pt
B34: Disclaimer: This report was prepared by members of the Lisbon Investment Society (LIS), an independent, student-led, non-profit organization based at ISEG – Lisbon School of Economics & Management, and is intended solely for academic and educational purposes. All analyses, forecasts, and opinions expressed in this report reflect the independent judgment of the authors as of the date of publication and are subject to change without notice. The views presented herein do not represent those of ISEG, its faculty, or any affiliated entity. This document does not constitute, and should not be interpreted as, investment advice, an offer, or a solicitation to buy or sell any security or financial instrument. Nothing in this report should be construed as a recommendation to make or refrain from making any investment decision. The content is intended for informational purposes only, and readers are strongly encouraged to conduct their own research and seek advice from a qualified financial professional before making any financial decisions. The information contained in this report has been obtained from publicly available sources believed to be reliable; however, no representation or warranty is made regarding the accuracy, completeness, or timeliness of such information. LIS and its members accept no liability whatsoever for any direct or indirect loss arising from the use of this report or its contents. This report incorporates terminology, financial metrics, and methodologies commonly used in professional equity research, including but not limited to Discounted Cash Flow (DCF), trading multiples, Monte Carlo simulations, and strategic analysis tools such as Porter’s Five Forces. Definitions and assumptions used in these models are disclosed within the report and reflect a hypothetical investment thesis designed solely for academic discussion. All valuations, projections, and target prices presented herein are based on publicly available data and subject to the limitations of modeling assumptions. These are not guarantees of future performance and should not be relied upon as such, as past performance is not indicative of future results. Any company names, logos, trademarks, or brand references mentioned in this report are the property of their respective owners and are used strictly for identification and academic purposes. This document may not be reproduced, redistributed, or quoted in whole or in part without the prior written consent of the Lisbon Investment Society. About LIS – Lisbon Investment Society: The Lisbon Investment Society (LIS) is a non-profit academic association headquartered at ISEG – Lisbon School of Economics & Management. Founded in 2016, LIS is committed to fostering student interest in finance and investment through applied research, skill development, and institutional engagement. The Society operates independently and autonomously from any political, religious, or commercial affiliation, and is composed of selected students and collaborators who are invited through a rigorous recruitment process and share a commitment to excellence, analytical rigor, and ethical standards. Its activities include equity research, portfolio management, macroeconomic analysis, and investment education. This report was prepared by the Equity Research team at the Lisbon Investment Society, whose analysts combine rigorous financial modeling, critical thinking, and collaborative research to deliver high-quality, student-led investment analysis. We welcome your feedback, discussion, and questions regarding this report or our research process, and invite you to reach out to our team as we are always open to engagement.

Sheet ESG
A7: x | B7: ESG Analysis
B12: ESG Scores | G12: GHG Scope 1 Emissions, Water Consumption, Energy Consumption and Waste Production per Sales
B15: LSEG ESG Score | D15: 71
B16: E-Score | D16: 53
B17: S-Score | D17: 93
B18: G-Score | D18: 64
B19: S&P Global ESG Score | D19: 60
B20: Environmental | D20: N/A
B21: Social | D21: N/A
B22: Governance & Economic | D22: N/A
B23: Sustainalytics | D23: 24.8
B24: ISS ESG Corporate Rating | D24: C+
B25: SDG Impact Rating | D25: 3.2
B26: Governance Quality Score | D26: 1
B27: MSCI ESG Ratings
B30: Key Info | G30: Environmental
H32: Overview | I32: Targets | J32: Improvements | K32: Comments
B33: GICS Sector | C33: Industrials | G33: GHG Scope 1 Emissions | I33: Reduce aboslute Scope 1,2,3 by 50.4% until 2030 | J33: Managed to achieve 37% of their set target as of 2024
B34: GICS Industry Group | C34: Transportation
B35: GICS Industry | C35: Road & Rail | G35: Water Consumption | I35: N/A | J35: The company implements policies and has commitments to reduce water consumption volume as mentioned in their 2024 CDP Questionnaire | K35: While the company recognize the importance of water conservation and responsible water management, it is not a significant part of their day-to-day operations. The commitment to sustainability and environmental responsibility is primarily addressed through various initiatives related to energy efficiency, emissions reduction, and resource conservation.
B36: GICS Sub-Industry | C36: Railroads
G37: Energy Consumption | I37: According to the Investor Pitchbook in May 2024, increase low-carbon fuel share (goal: 20% low-carbon fuels by 2030); reduce absolute Scope 1/2 as above. Conserving energy and investing in developing energy alternatives. Achieve full implementation of EMS (Energy Management System) by 2026 on locomotive fleet. | J37: Fuel-efficiency programs (Energy Management System on locomotives) reduced fuel intensity; biofuel % climbed to >6% (progress toward 20% goal).
B38: Headquarters | C38: Union Pacific Center, Omaha, Nebraska, United States
B39: Numer of Employees | C39: 32439 | G39: Waste Management | I39: N/A | J39: Year-on-year volumes fluctuate; sustainability metrics now disclose disposal tonnages and some diversion measures. However, in average, there was a decrease in waste generated in 2024 from to 2023
B41: Annual Report | C41: 45695 | G41: Other
B42: Sustainability Report | C42: 45411
B44: Recent Headlines | G44: Social
H46: Overview | I46: Targets | J46: Improvements | K46: Comments
B47: https://www.businesswire.com/news/home/20250922776661/en/SMART-TD-and-Union-Pacific-Announce-Landmark-Agreement-Securing-Jobs-and-the-Future-of-Railroading | G47: Employee Turnover % | I47: N/A | J47: There was a decline of ~ 1.62% from 2023 to 2024. (-534 employees)
B49: https://investor.unionpacific.com/news-releases/news-release-details/union-pacific-railroad-announces-pay-raises-and-labor-agreements | G49: Salaries & Compensation | I49: Continue competitive compensation/pay equity | J49: Railroad craft workers got a 24% raise, boosting their average salary to $110,000 in 2024. Overall, the median annual compensation reported in sustainability metrics shows increases over time; althought there was a slight decrease of 4.67% from 2023 to 2024
B51: Largest US rail union endorses Union Pacific, Norfolk Southern merger | Reuters | G51: Reputation | I51: The target revolves in improving safety culture and mantain inclusion scores. | J51: Ranked 4th of 940 companies included in the JUST 100 Index in 2025; 2025 Industry Leader in JUST; Inclusion metrics strong (HRC score 100%) in 2022; Honored by the Women’s Choice Awards as a top workplace for women, diversity, and millennials in 2022; safety/regulatory attention is a material reputational risk and UP is responding with safety initiatives.
B53: https://www.wsj.com/articles/union-pacific-ordered-to-pay-damages-for-retaliating-against-worker-264ee9f0? | G53: Discrimination Events | I53: The company demonstrate its will to minimize incidents | J53: Company documents policies, pay-equity audits, and DEI programs; still some litigation and EEOC/ADA cases reported in past years. | K53: Some litigations are reported such as U.S. Equal Employment Opportunity Commission v. Union Pacific Railroad Company;
B55: https://www.theguardian.com/us-news/2025/aug/25/union-pacific-norfolk-southern-railroad-merger? | G55: Work Safety | I55: The company strives for continuos reduction and making safety a core pillar. | J55: Based on its the most recent sustainability report - Building America Report - released in april 2024 for the year of 2023, the railroad reduced year-over-year serious injuries by 15% from 2022. The reportable derailment rate declined 6% compared with 2022, and over the past 10 years, track-related derailments declined 28%. Also there was 23% reduction in personal injury rates and a 20% decrease in derailment incidents compared to 2023. | K55: FRA review / audit concerns surfaced (safety culture issues flagged) when in July 2024 U.S. railroad Union Pacific interfered in a federal safety audit after employees were coached to provide specific response to FRA questions if they were approached for a safety cullture interview, prompting the federal rail agency to end the review. Cantwell, the Senator, said she was "deeply concerned about these FRA findings and the chilling effect the Union Pacific actions have on employee reporting of safety issues." She added she is concerned this indicates a weak safety culture and cited Union Pacific’s derailment rate that is 30% higher than the next-highest major railroad.
G57: Damage to consumer health | I57: N/A | J57: N/A | K57: Taking in account some comments from the "work safety" , the freight incidents that may affect communities (derailments) still is something that the company needs to work more deligent on it to improve with better system and technology, despite small improvements the company presents on its recent sustainability report.
G59: Pension Plan | I59: N/A | J59: N/A | K59: The Company provides retirement benefits through a tax-qualified defined benefit Pension Plan for eligible employees and a non-qualified Supplemental Pension Plan for executives (including the NEOs). The Pension Plan offers competitive retirement benefits to employees based on years of service, salary, bonus, and age. The Supplemental Pension Plan enhances retirement benefits for executives by covering compensation and deferred pay that exceed government limits.
G61: Supply chain | I61: N/A | J61: N/A | K61: Union Pacific Corporation conducts supplier category risk assessments, which include human rights and safety topics, and in-person supplier audits on topics such as safety. We also ask our critical and strategic Tier 1 suppliers to complete a self-assessment annually on various sustainability topics.
G63: Community involvement | I63: The 2024 Sustainability metrics reports that Union Pacific Corp aims to provide care for the community they served in many aspects. | J63: Regular community grant programs and volunteer hours reported in sustainability docs. | K63: The company disclosed on the report the amount spent on the Community Ties Giving Program registering 19.9 Millions of US Dollars in 2024
G65: Public Sector | I65: Maintain regulatory compliance; improve safety culture & transparency. | J65: Regulatory scrutiny increased after safety audit issues; UP publicly responded to inquiries and is providing documentation per requests.
G67: Litigation | I67: Reduce litigation through improved compliance & remediation | J67: To address these challenges, Union Pacific is streamlining management, enhancing safety at crossings, strengthening maintenance protocols, and working closely with regulators to ensure compliance with labor, safety, and environmental standards. | K67: Union Pacific currently faces active litigation involving employment discrimination, privacy violations, and environmental liability. Key cases include the James Hess employment suit, the Clay privacy case, and the Rowena Fire lawsuit, all of which remain in progress.
B70: Board of Directors | G70: Governance
...

Sheet Industry
D6: 584.17 | E6: 627.76 | F6: 676.06 | G6: 729.63 | H6: 789.13 | I6: 855.3 | J6: 929 | K6: 997.69 | L6: 1067.63 | M6: 1137.57
A7: x | B7: Industry Growth Forecast | O7: Industry Index
D9: 2022 | E9: =+D9+1 -> 2023 | F9: =+E9+1 -> 2024 | G9: =+F9+1 -> 2025 | H9: =+G9+1 -> 2026 | I9: =+H9+1 -> 2027 | J9: =+I9+1 -> 2028 | K9: =+J9+1 -> 2029 | M9: ="CAGR "&$G$9&" - "&$K$9 -> CAGR 2025 - 2029
B12: Market Size (Railroad) - www.futuremarketinsights.com/reports/railroad-market? ; www.thebusinessresearchcompany.com/market-insights/rail-freight-market-insights-2025? ; www.prnewswire.com/news-releases/rail-freight-industry-overview-2023-2027-estimated-market-size-competitive-landscape-and-major-trend--by-the-business-research-company-301944301.html? | D12: 258.77 | E12: 273.23 | F12: 296.8 | G12: 330.2 | H12: 348.68 | I12: 367.99 | J12: 388.5 | K12: 410.23 | M12: =(K12/G12)^(1/5)-1 -> 0.044359615
B13: Market Share | D13: 0.233 | E13: 0.245 | F13: 0.244 | M13: =((K13*K12)/(G13*G12))^(1/5)-1 -> #DIV/0!
B14: Market Size | M14: =(K14/G14)^(1/5)-1 -> #DIV/0!
B15: Market Share | M15: =((K15*K14)/(G15*G14))^(1/5)-1 -> #DIV/0!
B16: Market Size | M16: =(K16/G16)^(1/5)-1 -> #DIV/0!
B17: Market Share | M17: =((K17*K16)/(G17*G16))^(1/5)-1 -> #DIV/0!
B18: Market Size | M18: =(K18/G18)^(1/5)-1 -> #DIV/0!
B19: Market Share | M19: =((K19*K18)/(G19*G18))^(1/5)-1 -> #DIV/0!
B20: Market Size | M20: =(K20/G20)^(1/5)-1 -> #DIV/0!
B21: Market Share | M21: =((K21*K20)/(G21*G20))^(1/5)-1 -> #DIV/0!
A23: x
B25: Industry Driver | D25: Description | O25: Porter's Five Forces
B27: Industrial Production and Economic Growth | D27: Demand for freight rail services is closely tied to industrial output, construction, agriculture, and overall economic health. Higher production volumes result in increased shipments of commodities like coal, grain, metals, and chemicals—key freight categories for Union Pacific.
B28: Environmental and Sustainability Regulations | D28: Rising demand for lower-emission transport and regulatory pressure are encouraging shifts from trucking to rail, which is more fuel-efficient per ton-mile. Union Pacific is targeting emissions reduction and investing in cleaner technologies to align with ESG goals.
B29: Urbanization and Infrastructure Development | D29: Urban expansion increases demand for construction materials, energy, and consumer goods—all of which rely on freight transport. Union Pacific benefits from hauling such freight into rapidly growing metro areas, supported by federal infrastructure investment.
B30: Shift in Modal Preferences (Rail vs. Trucking) | D30: Trucking faces headwinds like driver shortages, fuel volatility, and stricter regulations. These challenges make rail a more appealing option for shippers—especially for long-haul and bulk cargo. Union Pacific’s efficiency gives it a competitive edge.
O32: Rivalry Among Existing Competitors | R32: 3
O33: Threat of New Entrants | R33: 1
O34: Threat of Substitutes | R34: 3
O35: Bargaining Power of Customers | R35: 4
O36: Bargaining Power of Suppliers | R36: 5

Sheet Segments
A7: x | B7: Segments | D7: =F7 -> 2020 | E7: =F7 -> 2020 | F7: 2020 | G7: =F7 -> 2020 | H7: =F7 -> 2020 | J7: =L7 -> 2021 | K7: =L7 -> 2021 | L7: 2021 | M7: =L7 -> 2021 | N7: =L7 -> 2021 | P7: =R7 -> 2022 | Q7: =R7 -> 2022 | R7: 2022 | S7: =R7 -> 2022 | T7: =R7 -> 2022 | V7: =X7 -> 2023 | W7: =X7 -> 2023 | X7: 2023 | Y7: =X7 -> 2023 | Z7: =X7 -> 2023 | AB7: =AD7 -> 2024 | AC7: =AD7 -> 2024 | AD7: 2024 | AE7: =AD7 -> 2024 | AF7: =AD7 -> 2024 | AH7: =AJ7 -> 2025 | AI7: =AJ7 -> 2025 | AJ7: 2025 | AK7: =AJ7 -> 2025 | AL7: =AJ7 -> 2025 | AN7: =AP7 -> 2025 | AO7: =AP7 -> 2025 | AP7: 2025 | AQ7: =AP7 -> 2025 | AR7: =AP7 -> 2025 | AZ7: Products
D8: 2020 | J8: =D8+1 -> 2021 | P8: =J8+1 -> 2022 | V8: =P8+1 -> 2023 | AB8: =V8+1 -> 2024 | AH8: =AB8+1 -> 2025 | AN8: =AH8+1 -> 2026 | AT8: =AN8+1 -> 2027 | AV8: =+AT8+1 -> 2028 | AX8: =+AV8+1 -> 2029
D9: Q1 | E9: Q2 | F9: Q3 | G9: Q4 | H9: FY | J9: Q1 | K9: Q2 | L9: Q3 | M9: Q4 | N9: FY | P9: Q1 | Q9: Q2 | R9: Q3 | S9: Q4 | T9: FY | V9: Q1 | W9: Q2 | X9: Q3 | Y9: Q4 | Z9: FY | AB9: Q1 | AC9: Q2 | AD9: Q3 | AE9: Q4 | AF9: FY | AH9: Q1 | AI9: Q2 | AJ9: Q3 | AK9: Q4 | AL9: FY | AN9: Q1 | AO9: Q2 | AP9: Q3 | AQ9: Q4 | AR9: FY | AT9: FY | AV9: FY | AX9: FY
B12: Revenue by segment:
B18: Total revenue | D18: =IS!D18 -> 5229 | E18: =IS!E18 -> 4244 | F18: =IS!F18 -> 4919 | G18: =IS!G18 -> 5141 | H18: =IS!H18 -> 19533 | J18: =IS!J18 -> 5001 | K18: =IS!K18 -> 5504 | L18: =IS!L18 -> 5566 | M18: =IS!M18 -> 5733 | N18: =IS!N18 -> 21804 | P18: =IS!P18 -> 5860 | Q18: =IS!Q18 -> 6269 | R18: =IS!R18 -> 6566 | S18: =IS!S18 -> 6180 | T18: =IS!T18 -> 24875 | V18: =IS!V18 -> 6056 | W18: =IS!W18 -> 5963 | X18: =IS!X18 -> 5941 | Y18: =IS!Y18 -> 6159 | Z18: =IS!Z18 -> 24119 | AB18: =IS!AB18 -> 6031 | AC18: =IS!AC18 -> 6007 | AD18: =IS!AD18 -> 6091 | AE18: =IS!AE18 -> 6121 | AF18: =IS!AF18 -> 24250 | AH18: =IS!AH18 -> 6027 | AI18: =IS!AI18 -> 6154 | AJ18: =IS!AJ18 -> 0 | AK18: =IS!AK18 -> 0 | AL18: =IS!AL18 -> 0 | AN18: =IS!AN18 -> 0 | AO18: =IS!AO18 -> 0 | AP18: =IS!AP18 -> 0 | AQ18: =IS!AQ18 -> 0 | AR18: =IS!AR18 -> 0 | AT18: =IS!AT18 -> 0 | AV18: =IS!AV18 -> 0 | AX18: =IS!AX18 -> 0
B20: Operations
B21: Bulk | D21: 1534 | E21: 1386 | F21: 1478 | G21: =H21-F21-E21-D21 -> 1562 | H21: 5960 | J21: 1512 | K21: 1648 | L21: 1687 | M21: =N21-L21-K21-J21 -> 1809 | N21: 6656 | P21: 1832 | Q21: 1813 | R21: 1959 | S21: =T21-R21-Q21-P21 -> 1933 | T21: 7537 | V21: 1897 | W21: 1757 | X21: 1766 | Y21: =Z21-X21-W21-V21 -> 1938 | Z21: 7358 | AB21: 1817 | AC21: 1721 | AD21: 1805 | AE21: =AF21-AD21-AC21-AB21 -> 1864 | AF21: 7207 | AH21: 1836 | AI21: 1901 | AL21: =Anexo_projections!AA60 -> 7502.4757 | AR21: =Anexo_projections!AG60 -> 7727.1069 | AT21: =Anexo_projections!AI60 -> 7927.8107 | AV21: =Anexo_projections!AK60 -> 8179.4589 | AX21: =Anexo_projections!AM60 -> 8453.6025
B22: Industrial | D22: 1894 | E22: 1500 | F22: 1567 | G22: =H22-F22-E22-D22 -> 1661 | H22: 6622 | J22: 1656 | K22: 1859 | L22: 1911 | M22: =N22-L22-K22-J22 -> 1897 | N22: 7323 | P22: 1921 | Q22: 2091 | R22: 2194 | S22: =T22-R22-Q22-P22 -> 1999 | T22: 8205 | V22: 2017 | W22: 2086 | X22: 2057 | Y22: =Z22-X22-W22-V22 -> 2078 | Z22: 8238 | AB22: 2104 | AC22: 2123 | AD22: 2121 | AE22: =AF22-AD22-AC22-AB22 -> 2092 | AF22: 8440 | AH22: 2082 | AI22: 2212 | AL22: =Anexo_projections!AA69 -> 8434.437 | AR22: =Anexo_projections!AG69 -> 8683.6106 | AT22: =Anexo_projections!AI69 -> 8963.96 | AV22: =Anexo_projections!AK69 -> 9222.7948 | AX22: =Anexo_projections!AM69 -> 9476.3775
B23: Premium | D23: 1452 | E23: 1086 | F23: 1551 | G23: =H23-F23-E23-D23 -> 1580 | H23: 5669 | J23: 1481 | K23: 1625 | L23: 1568 | M23: =N23-L23-K23-J23 -> 1591 | N23: 6265 | P23: 1687 | Q23: 1938 | R23: 1956 | S23: =T23-R23-Q23-P23 -> 1836 | T23: 7417 | V23: 1742 | W23: 1726 | X23: 1722 | Y23: =Z23-X23-W23-V23 -> 1785 | Z23: 6975 | AB23: 1695 | AC23: 1794 | AD23: 1842 | AE23: =AF23-AD23-AC23-AB23 -> 1833 | AF23: 7164 | AH23: 1773 | AI23: 1730 | AL23: =Anexo_projections!AA74 -> 8043.9583 | AR23: =Anexo_projections!AG74 -> 8278.1383 | AT23: =Anexo_projections!AI74 -> 8436.0022 | AV23: =Anexo_projections!AK74 -> 8757.9669 | AX23: =Anexo_projections!AM74 -> 8904.1805
B24: Other revenues | D24: =214+11+18 -> 243 | E24: =150+103+19 -> 272 | F24: =193+114+16 -> 323 | G24: =H24-F24-E24-D24 -> 444 | H24: =743+473+66 -> 1282 | J24: =177+161+14 -> 352 | K24: =180+176+16 -> 372 | L24: =182+198+20 -> 400 | M24: =N24-L24-K24-J24 -> 436 | N24: =741+752+67 -> 1560 | P24: =205+151+14 -> 370 | Q24: =233+183+11 -> 427 | R24: =231+212+14 -> 457 | S24: =T24-R24-Q24-P24 -> 462 | T24: =884+779+53 -> 1716 | V24: =235+151+14 -> 400 | W24: =220+149+25 -> 394 | X24: =226+142+28 -> 396 | Y24: =Z24-X24-W24-V24 -> 358 | Z24: =872+584+92 -> 1548 | AB24: =217+174+24 -> 415 | AC24: =212+131+26 -> 369 | AD24: =179+122+22 -> 323 | AE24: =AF24-AD24-AC24-AB24 -> 332 | AF24: =788+554+97 -> 1439 | AH24: =194+118+24 -> 336 | AI24: =181+107+23 -> 311 | AL24: =Anexo_projections!AA77 -> 1500 | AR24: =Anexo_projections!AG77 -> 1500 | AT24: =Anexo_projections!AI77 -> 1500 | AV24: =Anexo_projections!AK77 -> 1500 | AX24: =Anexo_projections!AM77 -> 1500
B26: Total revenue | D26: =IS!D18 -> 5229 | E26: =IS!E18 -> 4244 | F26: =IS!F18 -> 4919 | G26: =IS!G18 -> 5141 | H26: =IS!H18 -> 19533 | J26: =IS!J18 -> 5001 | K26: =IS!K18 -> 5504 | L26: =IS!L18 -> 5566 | M26: =IS!M18 -> 5733 | N26: =IS!N18 -> 21804 | P26: =IS!P18 -> 5860 | Q26: =IS!Q18 -> 6269 | R26: =IS!R18 -> 6566 | S26: =IS!S18 -> 6180 | T26: =IS!T18 -> 24875 | V26: =IS!V18 -> 6056 | W26: =IS!W18 -> 5963 | X26: =IS!X18 -> 5941 | Y26: =IS!Y18 -> 6159 | Z26: =IS!Z18 -> 24119 | AB26: =IS!AB18 -> 6031 | AC26: =IS!AC18 -> 6007 | AD26: =IS!AD18 -> 6091 | AE26: =IS!AE18 -> 6121 | AF26: =IS!AF18 -> 24250 | AH26: =IS!AH18 -> 6027 | AI26: =IS!AI18 -> 6154 | AJ26: =IS!AJ18 -> 0 | AK26: =IS!AK18 -> 0 | AL26: =SUM(AL21:AL24) -> 25480.871 | AN26: =IS!AN18 -> 0 | AO26: =IS!AO18 -> 0 | AP26: =IS!AP18 -> 0 | AQ26: =IS!AQ18 -> 0 | AR26: =IS!AR18 -> 0 | AT26: =IS!AT18 -> 0 | AV26: =IS!AV18 -> 0 | AX26: =IS!AX18 -> 0
B28: Operations:
B29: Bulk
B30: Industrial
B31: Premium
A35: x | B35: Notes & Forecasts
B40: Operations | D40: Company only has one segment, railroad, but discloses data in terms of operations and other revenues. Although, they disclose data in their railroad network, by commodity group, Bulk, Industrial and Premium.
B41: Freight revenues | D41: Bulk: This shipments consist of grain products, fertilizer, food and refrigerated, and coal and renewables. The company connects the large grain markets, from the Midwest and Western US, producing areas to export terminals in the Pacififc Northwest and Gulf Coast port as well as Mexico. Industrial: network facilitates movement of different commodities throughout North America. This group includes several categories, including construction, industrial chemicals, plastics, forest products, specialized products, metals and ores, petroleum, liquide petroleum gases, soda ash, and sand. Premium:This group includes finished automobiles, automotive parts, and merchandise in intermodal containers, both domestic and international. International business consists of import and export traffic moving in 20 or 40-foot shipping containers, that mainly pass through West Coast ports, destined for one of the Company's many inland intermodal terminals. Domestic business includes container and trailer traffic picked up and delivered within North America for intermodal marketing companies as well as truckload carriers.

Sheet Peers
B7: Peers
A12: x | B12: Growth | C12: Union Pacific Corp | D12: CAN NATL RAILWAY | E12: CSX CORP | F12: CANADIAN PACIFIC | G12: NORFOLK SOUTHERN | H12: BNSF RAILWAY CO | I12: {=TRANSPOSE(Inputs!H21:H25)} -> BOEING CO/THE | J12: LOCKHEED MARTIN | K12: NORTHROP GRUMMAN | L12: GENERAL DYNAMICS | M12: 3M CO | N12: {=TRANSPOSE(Inputs!N21:N25)} -> DEERE & CO | O12: ILLINOIS TOOL WO | P12: HONEYWELL INTL | Q12: AUTOMATIC DATA | R12: WASTE MANAGEMENT
B14: Revenue (LTM) | C14: 0.01 | D14: 0.01 | E14: -0.03 | F14: 0.05 | G14: 0.01 | H14: 0.01 | I14: 0.02 | J14: 0.01 | K14: -0.01 | L14: -0.01 | M14: 0.12 | N14: 0.12 | O14: 0.12 | P14: 0.12 | Q14: 0.12 | R14: 0.12
B15: Revenue (3-yr CAGR) | C15: 0.01 | D15: 0.04 | E15: 0 | F15: 0.14 | G15: 0.01 | H15: -0.01 | I15: 0.07 | J15: 0.04 | K15: 0.05 | L15: 0.09 | M15: -0.11 | N15: -0.03 | O15: 0.01 | P15: 0.05 | Q15: 0.08 | R15: 0.08
B16: Gross profit (LTM) | C16: - | D16: - | E16: - | F16: - | G16: - | H16: - | I16: -1.04 | J16: -0.31 | K16: 0.14 | L16: 0.14 | M16: 0.1 | N16: 0.1 | O16: 0.1 | P16: 0.1 | Q16: 0.1 | R16: 0.1
B17: EBIT (LTM) | C17: 0.05 | D17: -0.02 | E17: -0.09 | F17: 0.1 | G17: 0.55 | H17: 0.07 | I17: 2.76 | J17: -0.16 | K17: 0.43 | L17: 0.43 | M17: 0.14 | N17: 0.14 | O17: 0.14 | P17: 0.14 | Q17: 0.14 | R17: 0.14
B18: EBITDA (LTM) | C18: 0.05 | D18: 0 | E18: -0.06 | F18: 0.09 | G18: 0.39 | H18: 0.05 | I18: 8.41 | J18: -0.12 | K18: 0.31 | L18: 0.31 | M18: 0.13 | N18: 0.13 | O18: 0.13 | P18: 0.13 | Q18: 0.13 | R18: 0.13
B19: FCF (LTM) | C19: 0.23 | D19: -0.17 | E19: -0.17 | F19: 0.49 | G19: 1.01 | H19: 0.12 | I19: - | J19: -0.15 | K19: 0.25 | L19: -0.16 | M19: -0.87 | N19: 0.07 | O19: -0.08 | P19: 0.15 | Q19: 0.21 | R19: 0.18
A21: x | B21: Margins | C21: =C12 -> Union Pacific Corp | D21: =D12 -> CAN NATL RAILWAY | E21: =E12 -> CSX CORP | F21: =F12 -> CANADIAN PACIFIC | G21: =G12 -> NORFOLK SOUTHERN | H21: =H12 -> BNSF RAILWAY CO | I21: =I12 -> BOEING CO/THE | J21: =J12 -> LOCKHEED MARTIN | ... R21: =R12 -> WASTE MANAGEMENT
G22: -
B23: Gross margin | C23: - | D23: - | E23: - | F23: - | G23: - | H23: 0.66 | I23: -0.03 | J23: 0.1 | K23: 0.2 | L23: 0.15 | M23: 0.41 | N23: 0.4 | O23: 0.44 | P23: 0.38 | Q23: 0.46 | R23: 0.39
B24: EBIT margin | C24: 0.4 | D24: 0.37 | E24: 0.36 | F24: 0.36 | G24: 0.34 | H24: 0.32 | I24: -0.16 | J24: 0.1 | K24: 0.11 | L24: 0.1 | M24: 0.2 | N24: 0.24 | O24: 0.27 | P24: 0.19 | Q24: 0.26 | R24: 0.18
B25: EBITDA margin | C25: 0.5 | D25: 0.49 | E25: 0.46 | F25: 0.49 | G25: 0.53 | H25: 0.45 | I25: -0.1 | J25: 0.11 | K25: 0.14 | L25: 0.12 | M25: 0.24 | N25: 0.27 | O25: 0.29 | P25: 0.23 | Q25: 0.3 | R25: 0.28
B26: Net margin | C26: 0.28 | D26: 0.26 | E26: 0.24 | F26: 0.26 | G26: 0.22 | H26: 0.31 | I26: -0.18 | J26: 0.08 | K26: 0.1 | L26: 0.08 | M26: 0.17 | N26: 0.14 | O26: 0.22 | P26: 0.15 | Q26: 0.2 | R26: 0.12
B27: SG&A margin | C27: - | D27: - | E27: - | F27: - | G27: - | H27: - | I27: 0.07 | J27: - | K27: 0.1 | L27: 0.04 | M27: 0.17 | N27: 0.1 | O27: 0.17 | P27: 0.14 | Q27: 0.2 | R27: 0.11
B28: R&D margin | C28: 0 | D28: - | E28: - | F28: - | G28: - | H28: - | I28: 0.05 | J28: - | K28: - | L28: 0.01 | M28: 0.05 | N28: 0.05 | O28: - | P28: 0.05 | Q28: 0 | R28: -
A30: x | B30: Returns | C30: =C21 -> Union Pacific Corp | D30: =D21 -> CAN NATL RAILWAY | E30: =E21 -> CSX CORP | F30: =F21 -> CANADIAN PACIFIC | G30: =G21 -> NORFOLK SOUTHERN | H30: =H21 -> BNSF RAILWAY CO | I30: =I21 -> BOEING CO/THE | J30: =J21 -> LOCKHEED MARTIN | ... R30: =R21 -> WASTE MANAGEMENT
B32: ROIC | C32: 0.12 | D32: 0.08 | E32: 0.11 | F32: 0.05 | G32: 0.12 | H32: 0.08 | I32: -0.23 | J32: 0.19 | K32: 0.08 | L32: 0.13 | M32: 0.22 | N32: 0.08 | O32: 0.27 | P32: 0.11 | Q32: 0.43 | R32: 0.12
B33: CROIC | C33: 0.09 | D33: 0.06 | E33: 0.07 | F33: 0.03 | G33: 0.04 | H33: 0.07 | I33: -0.28 | J33: 0.17 | K33: 0.07 | L33: 0.1 | M33: 0.05 | N33: 0.05 | O33: 0.25 | P33: 0.09 | Q33: 0.44 | R33: 0.06
B34: ROCE | C34: 0.17 | D34: 0.13 | E34: 0.15 | F34: 0.1 | G34: 0.12 | H34: 0.11 | I34: -0.3 | J34: 0.84 | K34: 0.34 | L34: 0.36 | M34: 0.35 | N34: 2.07 | O34: 0.95 | P34: 0.54 | Q34: 1.8 | R34: 0.21
B35: RONA | C35: 0.58 | D35: 0.3 | E35: 0.42 | F35: 0.11 | G35: 0.28 | H35: 0.1 | I35: 2.74 | J35: 1.11 | K35: 0.29 | L35: 0.22 | M35: 1.24 | N35: 0.55 | O35: 1.29 | P35: 0.39 | Q35: 0.87 | R35: 0.49
B36: ROE | C36: 0.42 | D36: 0.22 | E36: 0.25 | F36: 0.09 | G36: 0.24 | H36: 0.1 | I36: - | J36: 0.73 | K36: 0.27 | L36: 0.18 | M36: 0.96 | N36: 0.22 | O36: 1.09 | P36: 0.35 | Q36: 0.76 | R36: 0.33
B37: ROA | C37: 0.1 | D37: 0.08 | E37: 0.07 | F37: 0.05 | G37: 0.08 | H37: 0.08 | I37: -0.07 | J37: 0.07 | K37: 0.08 | L37: 0.07 | M37: 0.1 | N37: 0.05 | O37: 0.21 | P37: 0.08 | Q37: 0.08 | R37: 0.07
A39: x | B39: Efficiency | C39: =C30 -> Union Pacific Corp | D39: =D30 -> CAN NATL RAILWAY | E39: =E30 -> CSX CORP | F39: =F30 -> CANADIAN PACIFIC | G39: =G30 -> NORFOLK SOUTHERN | H39: =H30 -> BNSF RAILWAY CO | I39: =I30 -> BOEING CO/THE | J39: =J30 -> LOCKHEED MARTIN | ... R39: =R30 -> WASTE MANAGEMENT
B41: Asset turnover | C41: 0,4x | D41: 0,3x | E41: 0,3x | F41: 0,2x | G41: 0,3x | H41: 0,2x | I41: 0,5x | J41: 1,3x | K41: 0,8x | L41: 0,9x | M41: 0,6x | N41: 0,4x | O41: 1,0x | P41: 0,5x | Q41: 0,4x | R41: 0,6x
B42: Net operating asset turnover | C42: 0,7x | D42: 0,5x | E42: 0,6x | F42: 0,2x | G42: 0,5x | H42: 0,3x | I42: 0,9x | J42: 2,2x | K42: 1,5x | L42: 1,1x | M42: 1,3x | N42: 1,5x | O42: 2,6x | P42: 1,2x | Q42: 0,5x | R42: 1,2x
B43: Fixed asset turnover | C43: 0,4x | D43: 0,4x | E43: 0,4x | F43: 0,3x | G43: 0,3x | H43: 0,3x | I43: 6,7x | J43: 8,4x | K43: 3,4x | L43: 7,8x | M43: 3,1x | N43: 3,0x | O43: 7,5x | P43: 5,6x | Q43: 19,7x | R43: 1,3x
B44: Revenue per employee thsnd of USD | C44: 804 | D44: 498 | E44: 601 | F44: 540 | G44: 621 | H44: - | I44: 438 | J44: 594 | K44: 418 | L44: 430 | M44: 400 | N44: 1 262 | O44: 359 | P44: 392 | Q44: 307 | R44: 388
B45: EBIT per employee thsnd of USD | C45: 324 | D45: 186 | E45: 208 | F45: 213 | G45: 234 | H45: - | I45: -59 | J45: 62 | K45: 41 | L45: 44 | M45: 97 | N45: 276 | O45: 93 | P45: 80 | Q45: 81 | R45: 71
A47: x | B47: Working Capital | C47: =C39 -> Union Pacific Corp | D47: =D39 -> CAN NATL RAILWAY | E47: =E39 -> CSX CORP | F47: =F39 -> CANADIAN PACIFIC | G47: =G39 -> NORFOLK SOUTHERN | H47: =H39 -> BNSF RAILWAY CO | I47: =I39 -> BOEING CO/THE | J47: =J39 -> LOCKHEED MARTIN | ... R47: =R39 -> WASTE MANAGEMENT
B49: DSO | C49: 30 | D49: 25 | E49: 37 | F49: 48 | G49: 73 | H49: 32 | I49: 16 | J49: 16 | K49: 18 | L49: 24 | M49: 54 | N49: 56 | O49: 76 | P49: 76 | Q49: 62 | R49: 47
B50: DIO | C50: - | D50: - | E50: - | F50: - | G50: - | H50: - | I50: 414 | J50: 19 | K50: 17 | L50: 84 | M50: 102 | N50: 105 | O50: 73 | P50: 98 | Q50: - | R50: 5
B51: DPO | C51: - | D51: - | E51: - | F51: - | G51: - | H51: - | I51: 54 | J51: 19 | K51: 28 | L51: 26 | M51: 71 | N51: 39 | O51: 25 | P51: 97 | Q51: 4 | R51: 48
B52: CCC | C52: - | D52: - | E52: - | F52: - | G52: - | H52: 53 | I52: 400 | J52: 18 | K52: 0 | L52: 78 | M52: 86 | N52: 96 | O52: 116 | P52: 66 | Q52: - | R52: 3
B53: Working capital intensity | C53: -0.04 | D53: -0.07 | E53: -0.01 | F53: -0.11 | G53: -0.09 | H53: -0.03 | I53: 0.28 | J53: 0.03 | K53: 0.02 | L53: 0.13 | M53: 0.22 | N53: -0.22 | O53: 0.12 | P53: 0.13 | Q53: 0.06 | R53: -0.01
B54: Cash conversion ratio | C54: 1,0x | D54: 1,1x | E54: 1,0x | F54: 1,0x | G54: 1,0x | H54: 1,3x | I54: 1,1x | J54: 1,0x | K54: 1,0x | L54: 0,9x | M54: 0,4x | N54: 0,7x | O54: 0,8x | P54: 0,8x | Q54: 0,9x | R54: 1,3x
B55: CFO margin | C55: 0.39 | D55: 0.39 | E55: 0.36 | F55: 0.36 | G55: 0.33 | H55: 0.41 | I55: -0.18 | J55: 0.1 | K55: 0.11 | L55: 0.09 | M55: 0.07 | N55: 0.18 | O55: 0.21 | P55: 0.16 | Q55: 0.24 | R55: 0.24
A57: x | B57: Leverage & Coverage | C57: =C47 -> Union Pacific Corp | D57: =D47 -> CAN NATL RAILWAY | E57: =E47 -> CSX CORP | F57: =F47 -> CANADIAN PACIFIC | G57: =G47 -> NORFOLK SOUTHERN | H57: =H47 -> BNSF RAILWAY CO | I57: =I47 -> BOEING CO/THE | J57: =J47 -> LOCKHEED MARTIN | ... R57: =R47 -> WASTE MANAGEMENT
B59: Net debt / EBITDA | C59: 2,7x | D59: 2,5x | E59: 3,0x | F59: 2,9x | G59: 2,5x | H59: 0,1x | I59: - | J59: 2,7x | K59: 2,8x | L59: 1,5x | M59: 1,6x | N59: 0,2x | O59: 1,8x | P59: 2,9x | Q59: -0,6x | R59: 3,5x
B60: Net debt / FCF | C60: 5,3x | D60: 6,7x | E60: 6,6x | F60: 9,1x | G60: 9,5x | H60: 0,2x | I60: -2,1x | J60: 3,6x | K60: 5,4x | L60: 2,8x | M60: 9,2x | N60: 0,4x | O60: 2,5x | P60: 4,3x | Q60: -0,7x | R60: 11,4x
...

Sheet Trading Comps
D7: Current | E7: % of | I7: Enterprise Value / | S7: LTM | T7: Net | V7: Price / | Z7: LT
D8: Share | E8: 52-week | F8: Equity | G8: Enterprise | I8: LTM | J8: 2025 | K8: 2026 | L8: LTM | M8: 2025E | N8: 2026E | O8: LTM | P8: 2025E | Q8: 2026E | S8: EBITDA | T8: Debt / | V8: LTM | W8: 2025E | X8: 2026E | Z8: EPS | AB8: S
B9: Company | C9: Ticker | D9: Price | E9: High | F9: Value | G9: Value | I9: Sales | J9: Sales | K9: Sales | L9: EBITDA | M9: EBITDA | N9: EBITDA | O9: EBIT | P9: EBIT | Q9: EBIT | S9: Margin | T9: EBITDA | V9: EPS | W9: EPS | X9: EPS | Z9: Growth
B12: UNION PAC CORP | C12: UNP US | D12: USD 227,98 | E12: 88,8% | F12: 135 202 | G12: 169 336 | I12: 6,9x | J12: 6,9x | K12: 6,6x | L12: 13,8x | M12: 13,4x | N12: 12,7x | O12: 17,2x | P12: 16,8x | Q12: 15,7x | S12: 0.5 | T12: 2,8x | V12: 19,5x | W12: 19,3x | X12: 18,0x | Z12: 0.1
B17: =+Inputs!B21 -> CAN NATL RAILWAY | C17: CNR CN | D17: CAD 127,52 | E17: 79,3% | F17: 79 609 | G17: 109 390 | I17: 6,4x | J17: 6,3x | K17: 6,0x | L17: 13,1x | M17: 12,6x | N17: 11,8x | O17: 17,1x | P17: 16,5x | Q17: 15,3x | S17: 0.49 | T17: 2,5x | V17: 17,4x | W17: 16,8x | X17: 15,7x | Z17: 0.07
B18: =+Inputs!B22 -> CSX CORP | C18: CSX US | D18: USD 34,07 | E18: 91,5% | F18: 63 516 | G18: 80 093 | I18: 5,7x | J18: 5,6x | K18: 5,4x | L18: 12,2x | M18: 12,2x | N18: 11,2x | O18: 16,4x | P18: 16,5x | Q18: 15,0x | S18: 0.46 | T18: 3,0x | V18: 20,1x | W18: 20,4x | X18: 18,2x | Z18: 0.09
B19: =+Inputs!B23 -> CANADIAN PACIFIC | C19: CP CN | D19: CAD 102,63 | E19: 86,4% | F19: 93 765 | G19: 122 100 | I19: 8,2x | J19: 8,0x | K19: 7,5x | L19: 15,6x | M19: 15,4x | N19: 14,1x | O19: 20,8x | P19: 20,1x | Q19: 18,0x | S19: 0.52 | T19: 3,0x | V19: 22,0x | W19: 21,5x | X19: 19,4x | Z19: 0.09
B20: =+Inputs!B24 -> NORFOLK SOUTHERN | C20: NSC US | D20: USD 292,08 | E20: 99,1% | F20: 65 606 | G20: 73 559 | I20: 6,0x | J20: 6,0x | K20: 5,7x | L20: 12,4x | M20: 12,7x | N20: 11,9x | O20: 16,1x | P20: 16,8x | Q20: 15,5x | S20: 0.49 | T20: 2,7x | V20: 21,9x | W20: 22,9x | X20: 20,9x | Z20: 0.09
B21: =+Inputs!B25 -> BNSF RAILWAY CO | C21: BNI1 US | D21: USD #N/A N/A | E21: - | F21: #N/A N/A | G21: #N/A N/A | I21: - | J21: - | K21: - | L21: - | M21: - | N21: - | O21: - | P21: - | Q21: - | S21: 0.45 | T21: 0,1x | V21: - | W21: - | X21: - | Z21: -
Z22: -
B23: Mean | I23: 6,6x | J23: 6,5x | K23: 6,2x | L23: 13,3x | M23: 13,2x | N23: 12,2x | O23: 17,6x | P23: 17,5x | Q23: 16,0x | S23: 48,2% | T23: 2,3x | V23: 20,4x | W23: 20,4x | X23: 18,6x | Z23: 8,6%
B24: Median | I24: 6,2x | J24: 6,1x | K24: 5,9x | L24: 12,7x | M24: 12,7x | N24: 11,8x | O24: 16,7x | P24: 16,7x | Q24: 15,4x | S24: 48,6% | T24: 2,7x | V24: 21,0x | W24: 21,0x | X24: 18,8x | Z24: 9,0%
B29: =+Inputs!H21 -> BOEING CO/THE | C29: BA US | D29: USD 215,1 | E29: 88,6% | F29: 162 650 | G29: 194 431 | I29: 2,6x | J29: 2,3x | K29: 2,0x | L29: -23,3x | M29: 66,7x | N29: 25,4x | O29: -19,0x | P29: 249,7x | Q29: 37,0x | S29: -0.11 | T29: #N/A N/A | V29: -13,6x | W29: -109,2x | X29: 60,9x | Z29: -2.75
B30: =+Inputs!H22 -> LOCKHEED MARTIN | C30: LMT US | D30: USD 486,25 | E30: 78,6% | F30: 113 522 | G30: 126 738 | I30: 1,8x | J30: 1,8x | K30: 1,6x | L30: 13,8x | M30: 13,7x | N30: 11,6x | O30: 16,8x | P30: 16,7x | Q30: 13,7x | S30: 0.13 | T30: 2,8x | V30: 20,8x | W30: 22,2x | X30: 17,1x | Z30: 0.12
B31: =+Inputs!H23 -> NORTHROP GRUMMAN | C31: NOC US | D31: USD 586,27 | E31: 97,6% | F31: 83 944 | G31: 87 252 | I31: 2,2x | J31: 2,1x | K31: 2,0x | L31: 16,1x | M31: 14,9x | N31: 13,7x | O31: 21,9x | P31: 19,6x | Q31: 17,9x | S31: 0.13 | T31: 3,1x | V31: 24,5x | W31: 23,0x | X31: 20,7x | Z31: 0.08
B32: =+Inputs!H24 -> GENERAL DYNAMICS | C32: GD US | D32: USD 323,62 | E32: 98,0% | F32: 87 052 | G32: 87 303 | I32: 1,7x | J32: 1,7x | K32: 1,6x | L32: 14,4x | M32: 14,1x | N32: 13,0x | O32: 16,9x | P32: 16,6x | Q32: 15,1x | S32: 0.12 | T32: 1,7x | V32: 21,3x | W32: 21,1x | X32: 19,1x | Z32: 0.08
B33: =+Inputs!H25 -> 3M CO | C33: MMM US | D33: USD 154,6 | E33: 94,2% | F33: 82 345 | G33: 90 661 | I33: 3,7x | J33: 3,8x | K33: 3,6x | L33: 12,6x | M33: 13,4x | N33: 12,6x | O33: 15,1x | P33: 16,1x | Q33: 15,2x | S33: 0.29 | T33: 2,3x | V33: 17,4x | W33: 19,3x | X33: 18,1x | Z33: 0.07
B35: Mean | I35: 2,4x | J35: 2,3x | K35: 2,2x | L35: 6,7x | M35: 24,5x | N35: 15,3x | O35: 10,4x | P35: 63,7x | Q35: 19,8x | S35: 11,3% | T35: 2,5x | V35: 14,1x | W35: -4,7x | X35: 27,2x | Z35: -48,0%
B36: Median | I36: 2,2x | J36: 2,1x | K36: 2,0x | L36: 13,8x | M36: 14,1x | N36: 13,0x | O36: 16,8x | P36: 16,7x | Q36: 15,2x | S36: 12,8% | T36: 2,6x | V36: 20,8x | W36: 21,1x | X36: 19,1x | Z36: 7,6%
B41: =+Inputs!N21 -> DEERE & CO | C41: DE US | D41: USD 468,94 | E41: 87,9% | F41: 126 768 | G41: 142 321 | I41: 3,2x | J41: 3,7x | K41: 3,5x | L41: 12,0x | M41: 20,1x | N41: 17,7x | O41: 14,7x | P41: 24,8x | Q41: 21,3x | S41: 0.27 | T41: 5,6x | V41: 24,0x | W41: 25,2x | X41: 22,9x | Z41: 0.18
B42: =+Inputs!N22 -> ILLINOIS TOOL WO | C42: ITW US | D42: USD 259,56 | E42: 93,0% | F42: 75 662 | G42: 80 223 | I42: 5,1x | J42: 5,0x | K42: 4,8x | L42: 17,8x | M42: 17,3x | N42: 16,4x | O42: 19,6x | P42: 18,9x | Q42: 17,9x | S42: 0.29 | T42: 2,0x | V42: 22,6x | W42: 24,9x | X42: 23,5x | Z42: 0.06
B43: =+Inputs!N23 -> HONEYWELL INTL | C43: HON US | D43: USD 208,6 | E43: 85,9% | F43: 132 439 | G43: 175 386 | I43: 4,4x | J43: 4,3x | K43: 4,1x | L43: 18,2x | M43: 16,6x | N43: 15,6x | O43: 21,6x | P43: 18,5x | Q43: 17,3x | S43: 0.24 | T43: 4,1x | V43: 21,1x | W43: 19,5x | X43: 18,4x | Z43: 0.07
B44: =+Inputs!N24 -> AUTOMATIC DATA | C44: ADP US | D44: USD 291,5 | E44: 88,4% | F44: 118 070 | G44: 121 583 | I44: 5,9x | J44: 5,9x | K44: 5,6x | L44: 19,9x | M44: 20,6x | N44: 19,1x | O44: 22,5x | P44: 22,7x | Q44: 20,9x | S44: 0.3 | T44: 0,7x | V44: 29,0x | W44: 29,0x | X44: 26,7x | Z44: 0.08
B45: =+Inputs!N25 -> WASTE MANAGEMENT | C45: WM US | D45: USD 219,42 | E45: 90,5% | F45: 88 389 | G45: 115 704 | I45: 4,8x | J45: 4,6x | K45: 4,3x | L45: 16,6x | M45: 15,4x | N45: 14,2x | O45: 26,3x | P45: 24,2x | Q45: 21,6x | S45: 0.29 | T45: 3,5x | V45: 30,6x | W45: 29,0x | X45: 25,6x | Z45: 0.12
B47: Mean | I47: 4,7x | J47: 4.7x | K47: 4,5x | L47: 16,9x | M47: 18,0x | N47: 16,6x | O47: 20,9x | P47: 21,8x | Q47: 19,8x | S47: 27,6% | T47: 3,2x | V47: 25,5x | W47: 25,5x | X47: 23,4x | Z47: 0.1
B48: Median | I48: 4,8x | J48: 4,6x | K48: 4,3x | L48: 17,8x | M48: 17,3x | N48: 16,4x | O48: 21,6x | P48: 22,7x | Q48: 20,9x | S48: 28,5% | T48: 3,5x | V48: 24,0x | W48: 25,2x | X48: 23,5x | Z48: 0.08
B50: Overall
B53: Mean | I53: 4,4x | J53: 4,4x | K53: 4,1x | L53: 12,2x | M53: 19,2x | N53: 14,9x | O53: 16,2x | P53: 38,0x | Q53: 18,7x | S53: 29,0% | T53: 2,7x | V53: 19,9x | W53: 14,8x | X53: 23,5x | Z53: -0.1
B54: Median | I54: 4,6x | J54: 4,4x | K54: 4,2x | L54: 14,1x | M54: 15,1x | N54: 13,9x | O54: 17,0x | P54: 18,7x | Q54: 17,6x | S54: 29,1% | T54: 2,8x | V54: 21,8x | W54: 21,9x | X54: 20,2x | Z54: 0.08
B56: High | I56: 8,2x | J56: 8,0x | K56: 7,5x | L56: 19,9x | M56: 70,5x | N56: 25,3x | O56: 26,3x | P56: 283,9x | Q56: 37,6x | S56: 52,5% | T56: 5,6x | V56: 30,5x | W56: 29,0x | X56: 62,9x | Z56: 0.18
B57: Low | I57: 1,7x | J57: 1,7x | K57: 1,6x | L57: -23,3x | M57: 12,2x | N57: 11,2x | O57: -19,0x | P57: 16,1x | Q57: 13,7x | S57: -11,1% | T57: 0,1x | V57: -14,0x | W57: -87,7x | X57: 15,7x | Z57: -2.57

Sheet WACC
A7: x | B7: Rolling WACC | K7: Equity Risk Premium
P8: Weights
D9: 2025 | E9: =+D9+1 -> 2026 | F9: =+E9+1 -> 2027 | G9: =+F9+1 -> 2028 | H9: =+G9+1 -> 2029 | M9: ERP | N9: 2025 | O9: =+N9+1 -> 2026 | P9: =+O9+1 -> 2027 | Q9: =+P9+1 -> 2028 | R9: =+Q9+1 -> 2029
B12: Equity: | K12: United States | M12: 0.0433 | N12: 0.6 | O12: 0.6 | P12: 0.6 | Q12: 0.6 | R12: 0.6
B13: Market Cap (in billions) | D13: =+Inputs!J13 -> 128121.15 | E13: =FCFF!AF99*FCFF!AF31 -> 133563.16 | F13: =FCFF!AH99*FCFF!AH31 -> 134138.86 | G13: =FCFF!AJ99*FCFF!AJ31 -> 138301.1 | H13: =FCFF!AL99*FCFF!AL31 -> 141670.8 | K13: Outside of US | M13: =((0.0687+0.0433)/2) -> 0.056 | N13: 0.4 | O13: 0.4 | P13: 0.4 | Q13: 0.4 | R13: 0.4
B14: % of Equity | D14: =IFERROR(D13/D35,"") -> 0.79049484 | E14: =IFERROR(E13/E35,"") -> 0.79408161 | F14: =IFERROR(E13/F35,"") -> 0.78813817 | G14: =IFERROR(F13/G35,"") -> 0.76942951 | H14: =IFERROR(G13/H35,"") -> 0.775118 | N14: - | O14: - | P14: - | Q14: - | R14: -
B15: Risk-Free Rate | D15: 0.0416 | E15: 0.0362 | F15: 0.0355 | G15: 0.0356 | H15: 0.0368 | N15: - | O15: - | P15: - | Q15: - | R15: -
B16: Beta | D16: =+Inputs!M18 -> 0.82 | E16: =+D17*(1+(E28/E13)*(1-E32)) -> 0.81700366 | F16: =+E17*(1+(F28/F13)*(1-F32)) -> 0.81912802 | G16: =+F17*(1+(G28/G13)*(1-G32)) -> 0.81765064 | H16: =+G17*(1+(H28/H13)*(1-H32)) -> 0.81706845 | N16: - | O16: - | P16: - | Q16: - | R16: -
B17: Unlevered Beta | D17: =+D16/(1+(D28/D13)*(1-D32)) -> 0.6810216 | E17: =+E16/(1+(E28/E13)*(1-E32)) -> 0.6810216 | F17: =+F16/(1+(F28/F13)*(1-F32)) -> 0.6810216 | G17: =+G16/(1+(G28/G13)*(1-G32)) -> 0.6810216 | H17: =+H16/(1+(H28/H13)*(1-H32)) -> 0.6810216
B18: Equity Risk Premium | D18: =+N18 -> 0.04838 | E18: =+O18 -> 0.04838 | F18: =+P18 -> 0.04838 | G18: =+Q18 -> 0.04838 | H18: =+R18 -> 0.04838 | K18: ERP | N18: =+SUMPRODUCT($M12:$M16,N12:N16) -> 0.04838 | O18: =+SUMPRODUCT($M12:$M16,O12:O16) -> 0.04838 | P18: =+SUMPRODUCT($M12:$M16,P12:P16) -> 0.04838 | Q18: =+SUMPRODUCT($M12:$M16,Q12:Q16) -> 0.04838 | R18: =+SUMPRODUCT($M12:$M16,R12:R16) -> 0.04838
B19: Ke (Cost of Equity) | D19: =IFERROR(+D15+D16*D18,"") -> 0.0812716 | E19: =IFERROR(+E15+E16*E18,"") -> 0.075726637 | F19: =IFERROR(+F15+F16*F18,"") -> 0.075129414 | G19: =IFERROR(+G15+G16*G18,"") -> 0.075157938 | H19: =IFERROR(+H15+H16*H18,"") -> 0.076329772
B21: Preferred Equity: | K21: ROIC vs WACC
B22: Market Capitalization | D22: =IFERROR(Inputs!J14,0) -> 0 | E22: =+D22*(E13/D13) -> 0 | F22: =+E22*(F13/E13) -> 0 | G22: =+F22*(G13/F13) -> 0 | H22: =+G22*(H13/G13) -> 0
B23: % of Preferred Equity | D23: =+D22/D35 -> 0 | E23: =+E22/E35 -> 0 | F23: =+F22/F35 -> 0 | G23: =+G22/G35 -> 0 | H23: =+H22/H35 -> 0
B24: Preferred Dividends | D24: =+IS!AF50 -> 0 | E24: =D24 -> 0 | F24: =E24 -> 0 | G24: =F24 -> 0 | H24: =G24 -> 0
B25: Kp (Cost of Preferred Equity) | D25: =IFERROR(D24/D22,0) -> 0 | E25: =IFERROR(E24/E22,0) -> 0 | F25: =IFERROR(F24/F22,0) -> 0 | G25: =IFERROR(G24/G22,0) -> 0 | H25: =IFERROR(H24/H22,0) -> 0
B27: Debt:
B28: Debt (in millions) | C28: =+BS!AF38+BS!AF39+BS!AF44+BS!AF45 -> 32463 | D28: =+BS!AI38+BS!AI39+BS!AI44+BS!AI45 -> 33956 | E28: =D28*1.02 -> 34635.12 | F28: =E28*1.02 -> 35327.822 | G28: =F28*1.02 -> 36034.379 | H28: =G28*1.02 -> 36755.066
B29: % of Debt | D29: =IFERROR(D28/D35,"") -> 0.20950516 | E29: =IFERROR(E28/E35,"") -> 0.20591839 | F29: =IFERROR(F28/F35,"") -> 0.2084647 | G29: =IFERROR(G28/G35,"") -> 0.20669561 | H29: =IFERROR(H28/H35,"") -> 0.20599629
B30: Debt Spread | D30: =+D31-D15 -> -0.0038158087 | E30: 0.005 | F30: 0.005 | G30: 0.005 | H30: 0.005
B31: Cost of Debt | D31: =+(IS!AI36+IS!AH36+IS!AE36+IS!AD36)/WACC!D28 -> 0.037784191 | E31: =+E30+E15 -> 0.0412 | F31: =+F30+F15 -> 0.0405 | G31: =+G30+G15 -> 0.0406 | H31: =+H30+H15 -> 0.0418
B32: Tax Rate | D32: =+FCFF!Z124 -> 0.23 | E32: =+FCFF!AF124 -> 0.23 | F32: =+FCFF!AH124 -> 0.23 | G32: =+FCFF!AJ124 -> 0.23 | H32: =+FCFF!AL124 -> 0.23
B33: Kd (After-Tax Cost of Debt) | D33: =+D31*(1-D32) -> 0.029093827 | E33: =+E31*(1-E32) -> 0.031724 | F33: =+F31*(1-F32) -> 0.031185 | G33: =+G31*(1-G32) -> 0.031262 | H33: =+H31*(1-H32) -> 0.032186
B35: Total | D35: =+D13+D24+D28 -> 162077.15 | E35: =+E13+E24+E28 -> 168198.28 | F35: =+F13+F24+F28 -> 169466.69 | G35: =+G13+G24+G28 -> 174335.48 | H35: =+H13+H24+H28 -> 178425.87
B37: Country/Conglomerate/... Risk Premium | D37: 0 | E37: 0 | F37: 0 | G37: 0 | H37: 0
A39: x | B39: WACC | D39: =+D19*D14+D25*D23+D33*D29+D37 -> 0.070340087 | E39: =+E19*E14+E25*E23+E33*E29+E37 -> 0.066665685 | F39: =+F19*F14+F25*F23+F33*F29+F37 -> 0.06571333 | G39: =+G19*G14+G25*G23+G33*G29+G37 -> 0.064290454 | H39: =+H19*H14+H25*H23+H33*H29+H37 -> 0.065794777
B41: NOPAT | D41: =+FCFF!Z126 -> 8401.4117 | E41: =+FCFF!AF126 -> 8620.0282 | F41: =+FCFF!AH126 -> 9149.7741 | G41: =+FCFF!AJ126 -> 9662.704 | H41: =+FCFF!AL126 -> 10204.503
B42: Total Payout | D42: =+FCFF!Z112+FCFF!Z115 -> -8091.607 | E42: =+FCFF!AF112+FCFF!AF115 -> -7906.6121 | F42: =+FCFF!AH112+FCFF!AH115 -> -8184.4029 | G42: =+FCFF!AJ112+FCFF!AJ115 -> -4058.3357 | H42: =+FCFF!AL112+FCFF!AL115 -> -4183.8464
B43: Book Value of Equity | C43: =+BS!AF54 -> 16890 | D43: =+C43+D41+D42 -> 17199.805 | E43: =+D43+E41+E42 -> 17913.221 | F43: =+E43+F41+F42 -> 18878.592 | G43: =+F43+G41+G42 -> 24482.96 | H43: =+G43+H41+H42 -> 30503.617
B44: Invested Capital | C44: =+C43+C28 -> 49353 | D44: =+D43+D28 -> 51155.805 | E44: =+E43+E28 -> 52548.341 | F44: =+F43+F28 -> 54206.414 | G44: =+G43+G28 -> 60517.339 | H44: =+H43+H28 -> 67258.684
A45: x | B45: ROIC | D45: =+D41/((D44+C44)/2) -> 0.16717763 | E45: =+E41/((E44+D44)/2) -> 0.16624269 | F45: =+F41/((F44+E44)/2) -> 0.1714167 | G45: =+G41/((G44+F44)/2) -> 0.16845167 | H45: =+H41/((H44+G44)/2) -> 0.15972486
W49: ,

Sheet FCFF
A7: x | B7: Market Assumptions
D8: 2022 | J8: =D8+1 -> 2023 | P8: =J8+1 -> 2024 | V8: =P8+1 -> 2025 | AB8: =V8+1 -> 2026 | AH8: =AB8+1 -> 2027 | AJ8: =+AH8+1 -> 2028 | AL8: =+AJ8+1 -> 2029
D9: Q1 | E9: Q2 | F9: Q3 | G9: Q4 | H9: FY | J9: Q1 | K9: Q2 | L9: Q3 | M9: Q4 | N9: FY | P9: Q1 | Q9: Q2 | R9: Q3 | S9: Q4 | T9: FY | V9: Q1 | W9: Q2 | X9: Q3 | Y9: Q4 | Z9: FY | AB9: Q1 | AC9: Q2 | AD9: Q3 | AE9: Q4 | AF9: FY | AH9: FY | AJ9: FY | AL9: FY
B11: Bulk | H11: =Segments!T21 -> 7537 | N11: =Segments!Z21 -> 7358 | T11: =Segments!AF21 -> 7207 | Z11: =Anexo_projections!AA60 -> 7502.4757 | AF11: =Anexo_projections!AG60 -> 7727.1069 | AH11: =Anexo_projections!AI60 -> 7927.8107 | AJ11: =Anexo_projections!AK60 -> 8179.4589 | AL11: =Anexo_projections!AM60 -> 8453.6025
B12: Industrials | H12: =Segments!T22 -> 8205 | N12: =Segments!Z22 -> 8238 | T12: =Segments!AF22 -> 8440 | Z12: =Anexo_projections!AA69 -> 8434.437 | AF12: =Anexo_projections!AG69 -> 8683.6106 | AH12: =Anexo_projections!AI69 -> 8963.96 | AJ12: =Anexo_projections!AK69 -> 9222.7948 | AL12: =Anexo_projections!AM69 -> 9476.3775
B13: Premium | H13: =Segments!T23 -> 7417 | N13: =Segments!Z23 -> 6975 | T13: =Segments!AF23 -> 7164 | Z13: =Anexo_projections!AA74 -> 8043.9583 | AF13: =Anexo_projections!AG74 -> 8278.1383 | AH13: =Anexo_projections!AI74 -> 8436.0022 | AJ13: =Anexo_projections!AK74 -> 8757.9669 | AL13: =Anexo_projections!AM74 -> 8904.1805
B14: Other revenues | H14: =Segments!T24 -> 1716 | N14: =Segments!Z24 -> 1548 | T14: =Segments!AF24 -> 1439 | Z14: =Anexo_projections!AA77 -> 1500 | AF14: =Anexo_projections!AG77 -> 1500 | AH14: =Anexo_projections!AI77 -> 1500 | AJ14: =Anexo_projections!AK77 -> 1500 | AL14: =Anexo_projections!AM77 -> 1500
B21: Revenue | H21: =SUM(H11:H19) -> 24875 | N21: =SUM(N11:N19) -> 24119 | T21: =SUM(T11:T19) -> 24250 | Z21: =SUM(Z11:Z19) -> 25480.871 | AA21: =SUM(AA11:AA19) -> 0 | AF21: =SUM(AF11:AF19) -> 26188.856 | AG21: =SUM(AG11:AG19) -> 0 | AH21: =SUM(AH11:AH19) -> 26827.773 | AI21: =SUM(AI11:AI19) -> 0 | AJ21: =SUM(AJ11:AJ19) -> 27660.221 | AK21: =SUM(AK11:AK19) -> 0 | AL21: =SUM(AL11:AL19) -> 28334.16
A23: x | B23: Operating Assumptions
D24: =D$8 -> 2022 | E24: =F24 -> 0 | F24: =F$8 -> 0 | G24: =F24 -> 0 | H24: =F24 -> 0 | J24: =J$8 -> 2023 | K24: =L24 -> 0 | L24: =L$8 -> 0 | M24: =L24 -> 0 | N24: =L24 -> 0 | P24: =P$8 -> 2024 | Q24: =R24 -> 0 | R24: =R$8 -> 0 | S24: =R24 -> 0 | T24: =R24 -> 0 | V24: =V$8 -> 2025 | W24: =X24 -> 0 | X24: =X$8 -> 0 | Y24: =X24 -> 0 | Z24: =X24 -> 0 | AB24: =AB$8 -> 2026 | AC24: =AD24 -> 0 | AD24: =AD$8 -> 0 | AE24: =AD24 -> 0 | AF24: =AD24 -> 0 | AH24: =AH$8 -> 2027 | AJ24: =AJ$8 -> 2028 | AL24: =AL$8 -> 2029 | AM24: =AN24 -> 0
D25: Q1 | E25: Q2 | F25: Q3 | G25: Q4 | H25: FY | J25: Q1 | K25: Q2 | L25: Q3 | M25: Q4 | N25: FY | P25: Q1 | Q25: Q2 | R25: Q3 | S25: Q4 | T25: FY | V25: Q1 | W25: Q2 | X25: Q3 | Y25: Q4 | Z25: FY | AB25: Q1 | AC25: Q2 | AD25: Q3 | AE25: Q4 | AF25: FY | AH25: FY | AJ25: FY | AL25: FY
B28: Income Statement
B31: Revenue | D31: =IS!P18 -> 5860 | E31: =IS!Q18 -> 6269 | F31: =IS!R18 -> 6566 | G31: =IS!S18 -> 6180 | H31: =IS!T18 -> 24875 | J31: =IS!V18 -> 6056 | K31: =IS!W18 -> 5963 | L31: =IS!X18 -> 5941 | M31: =IS!Y18 -> 6159 | N31: =IS!Z18 -> 24119 | P31: =IS!AB18 -> 6031 | Q31: =IS!AC18 -> 6007 | R31: =IS!AD18 -> 6091 | S31: =IS!AE18 -> 6121 | T31: =IS!AF18 -> 24250 | V31: =IS!AH18 -> 6027 | W31: =IS!AI18 -> 6154 | Z31: =Z21 -> 25480.871 | AF31: =AF21 -> 26188.856 | AH31: =AH21 -> 26827.773 | AI31: =AI21 -> 0 | AJ31: =AJ21 -> 27660.221 | AK31: =AK21 -> 0 | AL31: =AL21 -> 28334.16
B32: % of growth | D32: =D31/IS!J18-1 -> 0.17176565 | E32: =E31/IS!K18-1 -> 0.13898983 | F32: =F31/IS!L18-1 -> 0.17966223 | G32: =G31/IS!M18-1 -> 0.077969649 | H32: =H31/IS!N18-1 -> 0.14084572 | J32: =J31/IS!P18-1 -> 0.033447099 | K32: =K31/IS!Q18-1 -> -0.048811613 | L32: =L31/IS!R18-1 -> -0.095187329 | M32: =M31/IS!S18-1 -> -0.0033980583 | N32: =N31/H31-1 -> -0.03039196 | P32: =P31/IS!V18-1 -> -0.0041281374 | Q32: =Q31/IS!W18-1 -> 0.0073788362 | R32: =R31/IS!X18-1 -> 0.025248275 | S32: =S31/IS!Y18-1 -> -0.0061698328 | T32: =T31/N31-1 -> 0.0054314026 | V32: =V31/IS!AB18-1 -> -0.00066323993 | W32: =W31/IS!AC18-1 -> 0.02447145 | X32: =X31/IS!AD18-1 -> -1 | Y32: =Y31/IS!AE18-1 -> -1 | Z32: =Z31/T31-1 -> 0.050757567 | AB32: =AB31/IS!AH18-1 -> -1 | AC32: =AC31/IS!AI18-1 -> -1 | AD32: =AD31/X31-1 -> #DIV/0! | AE32: =AE31/Y31-1 -> #DIV/0! | AF32: =AF31/Z31-1 -> 0.027784954 | AH32: =AH31/AF31-1 -> 0.024396527 | AJ32: =AJ31/AH31-1 -> 0.031029324 | AL32: =AL31/AJ31-1 -> 0.024364949
B34: Cost of Goods & Services | D34: =IS!P21 -> 0 | E34: =IS!Q21 -> 0 | F34: =IS!R21 -> 0 | G34: =IS!S21 -> 0 | H34: =IS!T21 -> 0 | J34: =IS!V21 -> 0 | K34: =IS!W21 -> 0 | L34: =IS!X21 -> 0 | M34: =IS!Y21 -> 0 | N34: =IS!Z21 -> 0 | P34: =IS!AB21 -> 0 | Q34: =IS!AC21 -> 0 | R34: =IS!AD21 -> 0 | S34: =IS!AE21 -> 0 | T34: =IS!AF21 -> 0 | V34: =IS!AH21 -> 0 | W34: =IS!AI21 -> 0 | X34: =(X35+Sensitivity!$U$39)*X$31 -> 0 | Y34: =(Y35+Sensitivity!$U$39)*Y$31 -> 0 | Z34: =(Z35+Sensitivity!$U$39)*Z$31 -> 0 | AB34: =(AB35+Sensitivity!$U$39)*AB$31 -> 0 | AC34: =(AC35+Sensitivity!$U$39)*AC$31 -> 0 | AD34: =(AD35+Sensitivity!$U$39)*AD$31 -> 0 | AE34: =(AE35+Sensitivity!$U$39)*AE$31 -> 0 | AF34: =(AF35+Sensitivity!$U$39)*AF$31 -> 0 | AH34: =(AH35+Sensitivity!$U$39)*AH$31 -> 0 | AJ34: =(AJ35+Sensitivity!$U$39)*AJ$31 -> 0 | AL34: =(AL35+Sensitivity!$U$39)*AL$31 -> 0
B35: % of sales | D35: =D34/D31 -> 0 | E35: =E34/E31 -> 0 | F35: =F34/F31 -> 0 | G35: =G34/G31 -> 0 | H35: =H34/H31 -> 0 | J35: =J34/J31 -> 0 | K35: =K34/K31 -> 0 | L35: =L34/L31 -> 0 | M35: =M34/M31 -> 0 | N35: =N34/N31 -> 0 | P35: =P34/P31 -> 0 | Q35: =Q34/Q31 -> 0 | R35: =R34/R31 -> 0 | S35: =S34/S31 -> 0 | T35: =T34/T31 -> 0 | V35: =V34/V31 -> 0 | W35: =W34/W31 -> 0 | Z35: =AVERAGE(T35,N35,H35) -> 0 | AF35: 0 | AH35: 0 | AJ35: 0 | AL35: 0
B37: COGS Depreciation & Amortization | D37: =IS!P22 -> 0 | E37: =IS!Q22 -> 0 | F37: =IS!R22 -> 0 | G37: =IS!S22 -> 0 | H37: =IS!T22 -> 0 | J37: =IS!V22 -> 0 | K37: =IS!W22 -> 0 | L37: =IS!X22 -> 0 | M37: =IS!Y22 -> 0 | N37: =IS!Z22 -> 0 | P37: =IS!AB22 -> 0 | Q37: =IS!AC22 -> 0 | R37: =IS!AD22 -> 0 | S37: =IS!AE22 -> 0 | T37: =IS!AF22 -> 0 | V37: =IS!AH22 -> 0 | W37: =IS!AI22 -> 0 | X37: =X38*X34 -> 0 | Y37: =Y38*Y34 -> 0 | Z37: =SUM(V37:Y37) -> 0 | AB37: =AB38*AB34 -> 0 | AC37: =AC38*AC34 -> 0 | AD37: =AD38*AD34 -> 0 | AE37: =AE38*AE34 -> 0 | AF37: =SUM(AB37:AE37) -> 0 | AH37: =AH38*AH34 -> 0 | AJ37: =AJ38*AJ34 -> 0 | AL37: =AL38*AL34 -> 0
B38: % of cost of goods & services | D38: =D37/D34 -> #DIV/0! | E38: =E37/E34 -> #DIV/0! | F38: =F37/F34 -> #DIV/0! | G38: =G37/G34 -> #DIV/0! | H38: =H37/H34 -> #DIV/0! | J38: =J37/J34 -> #DIV/0! | K38: =K37/K34 -> #DIV/0! | L38: =L37/L34 -> #DIV/0! | M38: =M37/M34 -> #DIV/0! | N38: =N37/N34 -> #DIV/0! | P38: =P37/P34 -> #DIV/0! | Q38: =Q37/Q34 -> #DIV/0! | R38: =R37/R34 -> #DIV/0! | S38: =S37/S34 -> #DIV/0! | T38: =T37/T34 -> #DIV/0! | V38: =V37/V34 -> #DIV/0! | W38: =W37/W34 -> #DIV/0! | Z38: 0 | AF38: 0 | AH38: 0 | AJ38: 0 | AL38: 0
B40: Gross Profit | D40: =IS!P24 -> 5860 | E40: =IS!Q24 -> 6269 | F40: =IS!R24 -> 6566 | G40: =IS!S24 -> 6180 | H40: =IS!T24 -> 24875 | J40: =IS!V24 -> 6056 | K40: =IS!W24 -> 5963 | L40: =IS!X24 -> 5941 | M40: =IS!Y24 -> 6159 | N40: =IS!Z24 -> 24119 | P40: =IS!AB24 -> 6031 | Q40: =IS!AC24 -> 6007 | R40: =IS!AD24 -> 6091 | S40: =IS!AE24 -> 6121 | T40: =IS!AF24 -> 24250 | V40: =IS!AH24 -> 6027 | W40: =IS!AI24 -> 6154 | X40: =X31-X34-X37 -> 0 | Y40: =Y31-Y34-Y37 -> 0 | Z40: =Z31 -> 25480.871 | AB40: =AB31-AB34-AB37 -> 0 | AC40: =AC31-AC34-AC37 -> 0 | AD40: =AD31-AD34-AD37 -> 0 | AE40: =AE31-AE34-AE37 -> 0 | AF40: =AF31 -> 26188.856 | AH40: =AH31-AH34-AH37 -> 26827.773 | AJ40: =AJ31-AJ34-AJ37 -> 27660.221 | AL40: =AL31-AL34-AL37 -> 28334.16
B41: % of sales | D41: =D40/D31 -> 1 | E41: =E40/E31 -> 1 | F41: =F40/F31 -> 1 | G41: =G40/G31 -> 1 | H41: =H40/H31 -> 1 | J41: =J40/J31 -> 1 | K41: =K40/K31 -> 1 | L41: =L40/L31 -> 1 | M41: =M40/M31 -> 1 | N41: =N40/N31 -> 1 | P41: =P40/P31 -> 1 | Q41: =Q40/Q31 -> 1 | R41: =R40/R31 -> 1 | S41: =S40/S31 -> 1 | T41: =T40/T31 -> 1 | V41: =V40/V31 -> 1 | W41: =W40/W31 -> 1 | X41: =X40/X31 -> #DIV/0! | Y41: =Y40/Y31 -> #DIV/0! | Z41: =Z40/Z$31 -> 1 | AB41: =AB40/AB31 -> #DIV/0! | AC41: =AC40/AC31 -> #DIV/0! | AD41: =AD40/AD31 -> #DIV/0! | AE41: =AE40/AE31 -> #DIV/0! | AF41: =AF40/AF$31 -> 1 | AH41: =AH40/AH31 -> 1 | AJ41: =AJ40/AJ31 -> 1 | AL41: =AL40/AL31 -> 1
B43: SG&A (Selling, General & Administrative) | D43: =IS!P27 -> 0 | E43: =IS!Q27 -> 0 | F43: =IS!R27 -> 0 | G43: =IS!S27 -> 0 | H43: =IS!T27 -> 0 | J43: =IS!V27 -> 0 | K43: =IS!W27 -> 0 | L43: =IS!X27 -> 0 | M43: =IS!Y27 -> 0 | N43: =IS!Z27 -> 0 | P43: =IS!AB27 -> 0 | Q43: =IS!AC27 -> 0 | R43: =IS!AD27 -> 0 | S43: =IS!AE27 -> 0 | T43: =IS!AF27 -> 0 | V43: =IS!AH27 -> 0 | W43: =IS!AI27 -> 0 | X43: =(X44+Sensitivity!$U$40)*X$31 -> 0 | Y43: =(Y44+Sensitivity!$U$40)*Y$31 -> 0 | Z43: =SUM(V43:Y43) -> 0 | AB43: =(AB44+Sensitivity!$U$40)*AB$31 -> 0 | AC43: =(AC44+Sensitivity!$U$40)*AC$31 -> 0 | AD43: =(AD44+Sensitivity!$U$40)*AD$31 -> 0 | AE43: =(AE44+Sensitivity!$U$40)*AE$31 -> 0 | AF43: =SUM(AB43:AE43) -> 0 | AH43: =(AH44+Sensitivity!$U$40)*AH$31 -> 0 | AJ43: =(AJ44+Sensitivity!$U$40)*AJ$31 -> 0 | AL43: =(AL44+Sensitivity!$U$40)*AL$31 -> 0
