Workbook

Sheet OP
A1: Team | B1: Date | C1: Company
A2: Depriciated Land | B2: 45400 | C2: #VALUE!
G3: {=_FV(C2,"Description")} -> Airbus SE, formerly Airbus Group SE, is a company based in the Netherlands that is active in the aerospace and defense industry. The Company operates through three segments: Airbus, Airbus Helicopters and Airbus Defence and Space. The Airbus segment focuses on the development, manufacturing, marketing and sale of commercial jet aircraft and aircraft components, as well as on aircraft conversion and related services. The Airbus Helicopters segment specializes in the development, manufacturing, marketing and sale of civil and military helicopters, as well as on the provision of helicopter related services. The Airbus Defence and Space segment produces military combat aircraft and training aircraft, provides defense electronics and global security market solutions, and manufacturers and markets missiles.
A5: Beta | B5: {=_FV(C2,"Beta")} -> 1.6933
H8: Objetivos | I8: Completion Marker
A9: Share Holders | H9: Descrição da Empresa
H10: Data | I10: Feito
H11: Nome da Equipa
H12: Beta | I12: Feito
H13: Financial Performance last 5 years**
H14: Shareholders
H15: Extra Sector Performance Data

Sheet KPI
A2: CORES A USAR | C2: Titulos ou Cabeçalhos
C3: Subtítulos
C4: Se precisarem de mais cores utilizem as cores da Airbus !

Sheet Sector Specifics

Sheet Segments
B1: 2023 | C1: 2022 | D1: 2021 | E1: 2020 | F1: 2019 | G1: 2018 | H1: 2017 | I1: 2016 | J1: 2015 | K1: 2014 | L1: 2013 | M1: 2012
A2: New Aircraft Orders | Q2: Objetivos | R2: Completion Marker
A3: Aircraft Delivered | Q3: Aircraft Performance
A4: Efficiency Measurement | Q4: Segments
A5: Aircraft Backlog | Q5: Revenue per Segment
A7: Segment
A8: Europe
A9: North America
A10: Latin America
A11: Asia Pacific
A12: Middle East
A13: Other
A16: Civil Aviation
A17: A220
A18: A320
A19: A330
A20: A350
... A34: Revenues per segment

Sheet Peers
A1: #VALUE! | B1: {=_FV(A1,"Ticker symbol",TRUE)} -> AIR | C1: {=_FV(A1,"Currency")} -> EUR | D1: {=_FV(A1,"Exchange")} -> Deutsche Boerse AG | E1: {=_FV(A1,"Industry")} -> Aerospace & Defense | F1: {=_FV(A1,"Shares outstanding",TRUE)} -> 792283700 | G1: {=_FV(A1,"Employees")} -> 156569 | H1: {=_FV(A1,"Market cap",TRUE)} -> 115261400000 | I1: {=_FV(A1,"Year incorporated",TRUE)} -> 1998
A2: Peers | B2: Ticker | K2: Objetivos | L2: Completion Marker
A3: #VALUE! | B3: {=_FV(A3,"Ticker symbol",TRUE)} -> BA | C3: {=_FV(A3,"Currency")} -> USD | D3: {=_FV(A3,"Exchange")} -> New York Stock Exchange | E3: {=_FV(A3,"Industry")} -> Aerospace & Defense | F3: {=_FV(A3,"Shares outstanding",TRUE)} -> 747170800 | G3: {=_FV(A3,"Employees")} -> 171000 | H3: {=_FV(A3,"Market cap",TRUE)} -> 108743238232 | I3: {=_FV(A3,"Year incorporated",TRUE)} -> 1934 | K3: Picture of the Peers
A4: #VALUE! | B4: {=_FV(A4,"Ticker symbol",TRUE)} -> LMT | C4: {=_FV(A4,"Currency")} -> USD | D4: {=_FV(A4,"Exchange")} -> New York Stock Exchange | E4: {=_FV(A4,"Industry")} -> Aerospace & Defense | F4: {=_FV(A4,"Shares outstanding",TRUE)} -> 237035300 | G4: {=_FV(A4,"Employees")} -> 122000 | H4: {=_FV(A4,"Market cap",TRUE)} -> 134526421573 | I4: {=_FV(A4,"Year incorporated",TRUE)} -> 1994 | K4: Financial of the Peers
A5: #VALUE! | B5: {=_FV(A5,"Ticker symbol",TRUE)} -> NOC | C5: {=_FV(A5,"Currency")} -> USD | D5: {=_FV(A5,"Exchange")} -> New York Stock Exchange | E5: {=_FV(A5,"Industry")} -> Aerospace & Defense | F5: {=_FV(A5,"Shares outstanding",TRUE)} -> 145695300 | G5: {=_FV(A5,"Employees")} -> 101000 | H5: {=_FV(A5,"Market cap",TRUE)} -> 77489502258 | I5: {=_FV(A5,"Year incorporated",TRUE)} -> 2010 | K5: Comparison Metrics
A6: #VALUE! | B6: {=_FV(A6,"Ticker symbol",TRUE)} -> BA. | C6: {=_FV(A6,"Currency")} -> GBp | D6: {=_FV(A6,"Exchange")} -> London Stock Exchange | E6: {=_FV(A6,"Industry")} -> Aerospace & Defense | F6: {=_FV(A6,"Shares outstanding",TRUE)} -> 3020740000 | G6: {=_FV(A6,"Employees")} -> 100000 | H6: {=_FV(A6,"Market cap",TRUE)} -> 42094020000 | I6: {=_FV(A6,"Year incorporated",TRUE)} -> 1979 | K6: Retrive the same graphics from below with the description from Airbus themselves

Sheet Forecast

Sheet Assumptions
B1: 2023 | C1: 2022 | D1: 2021 | E1: 2020 | F1: 2019 | G1: 2018 | H1: 2017 | I1: 2016 | J1: 2015 | K1: 2014 | L1: 2013 | M1: 2012
A2: Liquidity Ratios
A3: Current Ratio (%)
A4: Quick Ratio (%)
A5: Cash Ratio (%)
A6: Efficiency Ratios
A7: Total Assets Turnover (x)
A8: Trade Receivables Turnover (x)
A9: DSO (days)
A10: Other Receivables Turnover (x)
A11: DSO - Other (days)
A12: Inventory Turnover (x)
A13: DIO (days)
... A37: Interest Coverage Ratio (x)

Sheet Financial Data
A1: Year | B1: (in millions) | C1: 2023 | D1: 2022 | E1: 2021 | F1: 2020 | G1: 2019 | H1: 2018 | I1: 2017 | J1: 2016 | K1: 2015 | L1: 2014 | M1: 2013 | N1: 2012
A2: Net Sales | C2: =Inputs!B65 -> 65446 | D2: =Inputs!C65 -> 58763 | E2: =Inputs!D65 -> 52149 | F2: =Inputs!E65 -> 49912 | G2: =Inputs!F65 -> 70478 | H2: =Inputs!G65 -> 63707 | I2: =Inputs!H65 -> 59022 | J2: =Inputs!I65 -> 66581 | ... N2: =Inputs!M65 -> 56480
A3: Growth YoY | C3: =IFERROR(C2/D2-1,"-") -> 0.11372803 | D3: =IFERROR(D2/E2-1,"-") -> 0.12682889 | E3: =IFERROR(E2/F2-1,"-") -> 0.044818881 | F3: =IFERROR(F2/G2-1,"-") -> -0.29180737 | G3: =IFERROR(G2/H2-1,"-") -> 0.10628345 | H3: =IFERROR(H2/I2-1,"-") -> 0.079377181 | I3: =IFERROR(I2/J2-1,"-") -> -0.11353089 | J3: =IFERROR(J2/K2-1,"-") -> 0.033064391 | ... N3: =IFERROR(N2/O2-1,"-") -> -
A4: Gross Profit | C4: =Inputs!B69 -> 10044 | D4: =Inputs!C69 -> 10571 | E4: =Inputs!D69 -> 9631 | F4: =Inputs!E69 -> 5662 | G4: =Inputs!F69 -> 10505 | H4: =Inputs!G69 -> 8787 | I4: =Inputs!H69 -> 6873 | J4: =Inputs!I69 -> 5264 | ... N4: =Inputs!M69 -> 7898
A5: % over sales | C5: =IFERROR(C4/D4-1,"-") -> -0.049853372 | D5: =IFERROR(D4/E4-1,"-") -> 0.097601495 | E5: =IFERROR(E4/F4-1,"-") -> 0.70098905 | F5: =IFERROR(F4/G4-1,"-") -> -0.46101856 | G5: =IFERROR(G4/H4-1,"-") -> 0.1955161 | H5: =IFERROR(H4/I4-1,"-") -> 0.27848101 | I5: =IFERROR(I4/J4-1,"-") -> 0.30566109 | J5: =IFERROR(J4/K4-1,"-") -> -0.40526494 | ... N5: =IFERROR(N4/O4-1,"-") -> -
A6: Operating expenses | C6: =Inputs!B71 -> 2521 | D6: =Inputs!C71 -> 2240 | E6: =Inputs!D71 -> 2052 | F6: =Inputs!E71 -> 2140 | G6: =Inputs!F71 -> 6125 | H6: =Inputs!G71 -> 2435 | I6: =Inputs!H71 -> 2439 | J6: =Inputs!I71 -> 2723 | ... N6: =Inputs!M71 -> 2869
A7: % over sales | C7: =IFERROR(C6/D6-1,"-") -> 0.12544643 | D7: =IFERROR(D6/E6-1,"-") -> 0.091617934 | E7: =IFERROR(E6/F6-1,"-") -> -0.041121495 | F7: =IFERROR(F6/G6-1,"-") -> -0.65061224 | G7: =IFERROR(G6/H6-1,"-") -> 1.5154004 | H7: =IFERROR(H6/I6-1,"-") -> -0.0016400164 | I7: =IFERROR(I6/J6-1,"-") -> -0.10429673 | J7: =IFERROR(J6/K6-1,"-") -> 0.027159562 | ... N7: =IFERROR(N6/O6-1,"-") -> -
A8: Operating Income | C8: =Inputs!B88 -> 4600
A9: Operating Margin
A10: Growth vs. Previous year | C10: =IFERROR(C9/D9-1,"-") -> - | D10: =IFERROR(D9/E9-1,"-") -> - | E10: =IFERROR(E9/F9-1,"-") -> - | F10: =IFERROR(F9/G9-1,"-") -> - | G10: =IFERROR(G9/H9-1,"-") -> - | H10: =IFERROR(H9/I9-1,"-") -> - | I10: =IFERROR(I9/J9-1,"-") -> - | J10: =IFERROR(J9/K9-1,"-") -> - | ... N10: =IFERROR(N9/O9-1,"-") -> -
A11: Research and Development | C11: =Inputs!B73 -> 3257
A12: Growth YoY | C12: =IFERROR(C11/D11-1,"-") -> - | D12: =IFERROR(D11/E11-1,"-") -> - | E12: =IFERROR(E11/F11-1,"-") -> - | F12: =IFERROR(F11/G11-1,"-") -> - | G12: =IFERROR(G11/H11-1,"-") -> - | H12: =IFERROR(H11/I11-1,"-") -> - | I12: =IFERROR(I11/J11-1,"-") -> - | J12: =IFERROR(J11/K11-1,"-") -> - | ... N12: =IFERROR(N11/O11-1,"-") -> -
A13: EBIT | C13: =Inputs!B148 -> 4573
A14: Depreciation & Amortization
A15: Changes Net Working Capital | C15: =Inputs!B14 -> 745
A16: EBITDA | C16: =Inputs!B149 -> 6800
A17: EBITDA Margin
A18: Taxes | C18: =Inputs!B155 -> 1156
A19: % Tax
A20: Net Income
A21: Net Income Margin
A22: Growth vs. Previous year
A23: Cash Generated
A24: Dividends
A25: Share buyback
A26: Net Cash Flow
A29: Net Capex
A30: Investments & Acquisitions
A31: Capex + Investments
A32: Dividends + Share Buyback
... A35: Assets
A36: Cash & Eq. | C36: =Inputs!B185 -> 13419 | D36: =Inputs!C185 -> 12136 | E36: =Inputs!D185 -> 12608 | F36: =Inputs!E185 -> 10266 | G36: =Inputs!F185 -> 7665 | H36: =Inputs!G185 -> 7551 | I36: =Inputs!H185 -> 8344 | J36: =Inputs!I185 -> 10143 | ... N36: =Inputs!M185 -> 8756
A37: Accounts Receivable | C37: =Inputs!B187 -> 6548 | D37: =Inputs!C187 -> 6454 | E37: =Inputs!D187 -> 6334 | F37: =Inputs!E187 -> 6206 | G37: =Inputs!F187 -> 6841 | H37: =Inputs!G187 -> 6867 | I37: =Inputs!H187 -> 5983 | J37: =Inputs!I187 -> 8101 | ... N37: =Inputs!M187 -> 6788
A38: Inventory | C38: =Inputs!B193 -> 33741 | D38: =Inputs!C193 -> 32202 | E38: =Inputs!D193 -> 28538 | F38: =Inputs!E193 -> 30401 | G38: =Inputs!F193 -> 31550 | H38: =Inputs!G193 -> 31891 | I38: =Inputs!H193 -> 29737 | J38: =Inputs!I193 -> 29688 | ... N38: =Inputs!M193 -> 23216
A39: Property, Plant and Equipment | C39: =Inputs!B210 -> 17201 | D39: =Inputs!C210 -> 16505 | E39: =Inputs!D210 -> 16536 | F39: =Inputs!E210 -> 16674 | G39: =Inputs!F210 -> 17294 | H39: =Inputs!G210 -> 16773 | I39: =Inputs!H210 -> 16610 | J39: =Inputs!I210 -> 16913 | ... N39: =Inputs!M210 -> 15196
A40: Other Assets | C40: =C41-(SUM(C36:C39)) -> 47962 | D40: =D41-(SUM(D36:D39)) -> 48647 | E40: =E41-(SUM(E36:E39)) -> 43031 | F40: =F41-(SUM(F36:F39)) -> 46548 | G40: =G41-(SUM(G36:G39)) -> 51059 | H40: =H41-(SUM(H36:H39)) -> 52116 | I40: =I41-(SUM(I36:I39)) -> 48775 | J40: =J41-(SUM(J36:J39)) -> 46288 | ... N40: =N41-(SUM(N36:N39)) -> 38165
A41: Total Assets | C41: =Inputs!B227 -> 118871 | D41: =Inputs!C227 -> 115944 | E41: =Inputs!D227 -> 107047 | F41: =Inputs!E227 -> 110095 | G41: =Inputs!F227 -> 114409 | H41: =Inputs!G227 -> 115198 | I41: =Inputs!H227 -> 109449 | J41: =Inputs!I227 -> 111133 | ... N41: =Inputs!M227 -> 92121
A44: Liabilities
A45: Current Liabilities
A46: Short-Term Debt
...

Sheet Inputs
B1: 2023 | C1: 2022 | D1: 2021 | E1: 2020 | F1: 2019 | G1: 2018 | H1: 2017 | I1: 2016 | J1: 2015 | K1: 2014 | L1: 2013 | M1: 2012
A2: Cash Flow
A3: Industry - Annual Standardised in Millions of Euros
A4: Statement Date | B4: 31-Dec-2023 | C4: 31-Dec-2022 | D4: 31-Dec-2021 | E4: 31-Dec-2020 | F4: 31-Dec-2019 | G4: 31-Dec-2018 | H4: 31-Dec-2018 | I4: 31-Dec-2016 | J4: 31-Dec-2016 | K4: 31-Dec-2014 | L4: 31-Dec-2014 | M4: 31-Dec-2013
A5: Reporting Unit | B5: Millions | C5: Millions | D5: Millions | E5: Millions | F5: Millions | G5: Millions | H5: Millions | I5: Millions | J5: Millions | K5: Millions | L5: Millions | M5: Millions
A6: Cash Flow-Operating Activities (€ Millions)
A7: Net Income/Starting Line | B7: 3789 | C7: 4247 | D7: 4213 | E7: -1133 | F7: -1362 | G7: 3054 | H7: 2361 | I7: 995 | J7: 2696 | K7: 2343 | L7: 1473 | M7: 1197
A8: Depreciation/Depletion | B8: 2242 | C8: 2716 | D8: 2325 | E8: 2831 | F8: 2927 | G8: 2444 | H8: 2298 | I8: 2294 | J8: 2466 | K8: 2150 | L8: 1927 | M8: 2053
A9: Depreciation | B9: 2242 | C9: 2716 | D9: 2325 | E9: 2831 | F9: 2927 | G9: 2444 | H9: 2298 | I9: 2294 | J9: 2466 | K9: 2150 | L9: 1927 | M9: 2053
A10: Non-Cash Items | B10: -521 | C10: -1234 | D10: -2426 | E10: 1163 | F10: 1484 | G10: -1544 | H10: -72 | I10: 633 | J10: 13 | K10: 772 | L10: 968 | M10: 1038
A11: Unusual Items | B11: -477 | C11: -544 | D11: -979 | E11: 104 | F11: 523 | G11: -2110 | H11: -2114 | I11: -738 | J11: 253 | K11: 469 | L11: -10 | M11: 297
A12: Equity in Net Earnings (Loss) | B12: -267 | C12: -133 | D12: -40 | E12: -39 | F12: -299 | G12: -330 | H12: -311 | I12: -231 | J12: -1016 | K12: -840 | L12: -434 | M12: -241
A13: Other Non-Cash Items | B13: 223 | C13: -557 | D13: -1407 | E13: 1098 | F13: 1260 | G13: 896 | H13: 2353 | I13: 1602 | J13: 776 | K13: 1143 | L13: 1412 | M13: 982
A14: Changes in Working Capital | B14: 745 | C14: 559 | D14: 527 | E14: -8281 | F14: 704 | G14: -1636 | H14: -143 | I14: 447 | J14: -2284 | K14: -2705 | L14: -2539 | M14: -448
A15: Accounts Receivable | B15: 258 | C15: -115 | D15: 379 | E15: 351 | F15: 29 | G15: -881 | H15: -47 | I15: -1215 | J15: -1378 | K15: -700 | L15: -83 | M15: -260
A16: Inventories | B16: -1854 | C16: -3218 | D16: 2405 | E16: 152 | F16: 117 | G16: -671 | H16: -2112 | I16: -3477 | J16: -4133 | K16: -3252 | L16: -3102 | M16: -1526
A17: Other Assets | B17: -- | C17: -- | D17: -- | E17: -- | F17: -- | G17: -- | H17: -- | I17: -202 | J17: -193 | K17: 124 | L17: -327 | M17: 30
A18: Accounts Payable | B18: 1421 | C18: 3309 | D18: 194 | E18: -5523 | F18: -1625 | G18: 2294 | H18: 829 | I18: 2398 | J18: 894 | K18: 130 | L18: 522 | M18: 754
A19: Accrued Expenses | B19: -- | C19: -- | D19: -- | E19: -- | F19: -- | G19: -- | H19: -- | I19: -- | J19: -- | K19: -- | L19: -- | M19: --
A20: Other Liabilities | B20: -- | C20: -- | D20: -- | E20: -- | F20: -- | G20: -- | H20: -- | I20: 4578 | J20: 3795 | K20: 1699 | L20: 588 | M20: 1067
A21: Other Assets & Liabilities, Net | B21: 1380 | C21: 1445 | D21: -1911 | E21: -3217 | F21: 3695 | G21: -1375 | H21: 1691 | I21: -837 | J21: -417 | K21: -387 | L21: 311 | M21: -141
A22: Other Operating Cash Flow | B22: -460 | C22: -862 | D22: -540 | E22: -44 | F22: -1512 | G22: -1003 | H22: -504 | I22: -798 | J22: -852 | K22: -319 | L22: -448 | M22: -372
A23: Cash from Operating Activities | B23: 6255 | C23: 6288 | D23: 4639 | E23: -5420 | F23: 3753 | G23: 2318 | H23: 4444 | I23: 4369 | J23: 2891 | K23: 2560 | L23: 1829 | M23: 3840
A25: Cash Flow-Investing Activities (€ Millions)
A26: Capital Expenditures | B26: -3051 | C26: -2464 | D26: -1928 | E26: -1759 | F26: -2340 | G26: -2285 | H26: -2558 | I26: -3060 | J26: -2924 | K26: -2548 | L26: -2918 | M26: -3270
A27: Purchase of Fixed Assets | B27: -3051 | C27: -2464 | D27: -1928 | E27: -1759 | F27: -2340 | G27: -2285 | H27: -2558 | I27: -3060 | J27: -2924 | K27: -2548 | L27: -2918 | M27: -3270
A28: Other Investing Cash Flow Items, Total | B28: -1077 | C28: -649 | D28: -791 | E28: 5885 | F28: -524 | G28: 650 | H28: 28 | I28: 2230 | J28: -535 | K28: -675 | L28: 1306 | M28: 3244
A29: Acquisition of Business | B29: -65 | C29: -188 | D29: -25 | E29: -481 | F29: -- | G29: -- | H29: -23 | I29: -120 | J29: -13 | K29: -81 | L29: -16 | M29: -201
A30: Sale of Business | B30: -- | C30: -- | D30: -- | E30: -- | F30: 8 | G30: 129 | H30: 377 | I30: 731 | J30: 127 | K30: -- | L30: 0 | M30: 0
A31: Sale of Fixed Assets | B31: 75 | C31: 101 | D31: 522 | E31: 228 | F31: 249 | G31: 533 | H31: 1070 | I31: 1599 | J31: 205 | K31: 232 | L31: 48 | M31: 73
A32: Sale/Maturity of Investment | B32: 2423 | C32: 1966 | D32: 2259 | E32: 7048 | F32: 2822 | G32: 2514 | H32: 3066 | I32: 2799 | J32: 6521 | K32: 4593 | L32: 2819 | M32: 6891
A33: Investment, Net | B33: -- | C33: -- | D33: -- | E33: -- | F33: -- | G33: -- | H33: -- | I33: -- | J33: -- | K33: -- | L33: -- | M33: --
A34: Purchase of Investments | B34: -3660 | C34: -2628 | D34: -3626 | E34: -902 | F34: -3813 | G34: -2717 | H34: -4680 | I34: -2971 | J34: -7409 | K34: -5562 | L34: -1691 | M34: -3565
A35: Other Investing Cash Flow | B35: 150 | C35: 100 | D35: 79 | E35: -8 | F35: 210 | G35: 191 | H35: 218 | I35: 192 | J35: 34 | K35: 143 | L35: 146 | M35: 46
A36: Cash from Investing Activities | B36: -4128 | C36: -3113 | D36: -2719 | E36: 4126 | F36: -2864 | G36: -1635 | H36: -2530 | I36: -830 | J36: -3459 | K36: -3223 | L36: -1612 | M36: -26
A38: Cash Flow-Financing Activities (€ Millions)
A39: Financing Cash Flow Items | B39: 138 | C39: 134 | D39: 0 | E39: 91 | F39: 319 | G39: 179 | H39: -3 | I39: -4 | J39: -3 | K39: -2 | L39: -2 | M39: -10
A40: Other Financing Cash Flow | B40: 138 | C40: 134 | D40: 0 | E40: 91 | F40: 319 | G40: 179 | H40: -3 | I40: -4 | J40: -3 | K40: -2 | L40: -2 | M40: -10
A41: Total Cash Dividends Paid | B41: -1421 | C41: -1181 | D41: 0 | E41: 0 | F41: -1280 | G41: -1161 | H41: -1043 | I41: -1008 | J41: -945 | K41: -587 | L41: -467 | M41: -369
A42: Cash Dividends Paid - Common | B42: -1421 | C42: -1181 | D42: 0 | E42: 0 | F42: -1280 | G42: -1161 | H42: -1043 | I42: -1008 | J42: -945 | K42: -587 | L42: -467 | M42: -369
...
