Workbook
Name businessresearchinsights: Segments!$D$38,Segments!$B$38
Name Sectors: 'Sector Impact'!$K$4:$K$16

Sheet OP
B2: 45039 | C2: Team 4 | E2: =Inputs!H3 -> #VALUE! | L2: NASDAQ | M2: SIC:
D3: COMPANY DESCRIPTION | H3: CEO & BOARD OF DIRECTORS
D4: {=_FV(Inputs!H3,"Description")} -> Comcast Corporation is a global media and technology company. It delivers broadband, wireless, and video through Xfinity, Comcast Business, and Sky; produce, distribute, and stream entertainment, sports, and news through brands, including NBC, Telemundo, Universal, Peacock, and Sky; and brings theme parks and attractions to life through Universal Destinations and Experiences. It operates through two primary businesses: Connectivity & Platforms and Content & Experiences. The Connectivity & Platforms segment contains its broadband, wireless, video and wireline voice businesses in the United States, United Kingdom and Italy. It also includes the operations of its Sky-branded entertainment television networks in the United Kingdom, and Italy. The Content & Experiences segment contains media and entertainment businesses that produce and distribute entertainment, sports, news and other content for audiences and that own and operate theme parks and attractions in the United States and Asia. | H4: Name | I4: Gender | J4: Age | K4: Tenure | L4: Executive? | M4: Other roles
H5: Brian L. Roberts | I5: M | J5: 64 | K5: 37 | L5: YES | M5: CEO of Comcast Corporation
H6: Thomas J. Baltimore, Jr. | I6: M | J6: 58 | K6: 0 | L6: NO | M6: Chairman, President and CEO of Park Hotels & Resorts, Inc.
H7: Madeline S. Bell | I7: F | J7: 61 | K7: 7 | L7: NO | M7: President and CEO of Children’s Hospital of Philadelphia
H8: Edward D. Breen | I8: M | J8: 67 | K8: 9 | L8: NO | M8: Executive Chairman and CEO of DuPont de Nemours, Inc.
H9: Gerald L. Hassell | I9: M | J9: 71 | K9: 15 | L9: NO | M9: CEO of The Bank of New York Mellon
H10: Jeffrey A. Honickman | I10: M | J10: 66 | K10: 18 | L10: NO | M10: CEO of Pepsi-Cola & National Brand Beverages, Ltd.
H11: Maritza G. Montiel | I11: F | J11: 71 | K11: 5 | L11: NO | M11: Deputy CEO of Deloitte LLP
H12: Asuka Nakahara | I12: M | J12: 67 | K12: 6 | L12: NO | M12: Co-founder Incompass Labs, Inc.
H13: David C. Novak | I13: M | J13: 70 | K13: 7 | L13: NO | M13: Founder of David Novak Leadership, Inc.
H14: Kenneth J. Bacon | I14: M | J14: 68 | K14: 21 | L14: NO | M14: Partner at RailField Partners
B16: USD MILLIONS
B17: COMPANY OVERVIEW
B18: Stock | D18: Liquidity and Solvency | F18: Segments | I18: Profitability (2022) | L18: Multiples
B19: Last Price | C19: {=_FV(E2,"Price")} -> 40.545 | D19: Total Assets | E19: =_xlfn.XLOOKUP(D19,'Fin. Data'!A:A,'Fin. Data'!B:B,,0) -> 257275 | F19: Regions | H19: % Sales | I19: Reporting Year | J19: 2022 | L19: Float | M19: 0.99
B20: Outstanding Shares | C20: {=_FV(E2,"Shares outstanding",TRUE)} -> 3872502000 | D20: Total Liabilities | E20: =_xlfn.XLOOKUP(D20,'Fin. Data'!A:A,'Fin. Data'!B:B,,0) -> 176332 | F20: =Segments!C5 -> United Kingdom | H20: =Segments!B5 -> 0.11018966 | I20: End of Year | J20: 1 October 2022 | L20: Insiders Own | M20: 0.0074
B21: Market Cap. | C21: =C19*C20/1000000 -> 157010.59 | D21: Cash/Share | E21: =_xlfn.XLOOKUP("Cash & Eq.",'Fin. Data'!A:A,'Fin. Data'!B:B,,0)*1000000/C20 -> 1.2263389 | F21: =Segments!C6 -> United States | H21: =Segments!B6 -> 0.79423028 | I21: EBITDA | K21: =_xlfn.XLOOKUP(I21,'Fin. Data'!A:A,'Fin. Data'!B:B,,0) -> 28723 | L21: b (Yahoo) | M21: 1.05
B22: +Total Debt | C22: ='Fin. Data'!B58 -> 105022 | D22: EBIDTA/Net Financial Cost (NFC) | E22: ='Fin. Data (Common Size)'!B19/(-'Fin. Data (Common Size)'!B14) -> 7.3724333 | F22: Other | H22: =Segments!B8 -> 0.09558006 | I22: Depreciation & Amortization | K22: =_xlfn.XLOOKUP(I22,'Fin. Data'!A:A,'Fin. Data'!B:B,,0) -> 13821 | L22: Score (S&P) | M22: A-
B23: -Cash | C23: ='Fin. Data'!B39 -> 4749 | D23: Debt/EBITDA | E23: =_xlfn.XLOOKUP("Total Debt",'Fin. Data'!A:A,'Fin. Data'!B:B,,0)/_xlfn.XLOOKUP("EBITDA",'Fin. Data'!A:A,'Fin. Data'!B:B,,0) -> 3.6563729 | I23: EBIT | K23: =_xlfn.XLOOKUP(I23,'Fin. Data'!A:A,'Fin. Data'!B:B,,0) -> 14902 | L23: Price/Book Value | M23: =IFERROR((C19*C20/(E19-E20))/1000000,"") -> 1.9397674
B24: =Enterprise Value | C24: =C21+C22-C23 -> 257283.59 | D24: "Others Assets"/Asset | E24: =_xlfn.XLOOKUP("Other Assets",'Fin. Data'!A:A,'Fin. Data'!B:B,,0)/_xlfn.XLOOKUP("Total Assets",'Fin. Data'!A:A,'Fin. Data'!B:B,,0) -> 0.67224565 | I24: Net Income | K24: =_xlfn.XLOOKUP(I24,'Fin. Data'!A:A,'Fin. Data'!B:B,,0) -> 4925 | L24: NCF(3y avg)/Asset | M24: =IFERROR(K30/E19,"") -> 0.038167978
B25: Holdings (nac/int'l) | C25: - | D25: Debt/Assets | E25: =_xlfn.XLOOKUP(D25,'Fin. Data'!A:A,'Fin. Data'!B:B,,0) -> 0.40820911 | F25: Categories | H25: % Sales | I25: EPS | K25: =1000000*K24/C20 -> 1.2717876 | L25: Price/Net Inc. (3y avg) | M25: =IFERROR(C21/K29,"") -> 15.989402
B26: t liq. (Holdings/Vol.) | C26: - | D26: EBITDA Margin (average) | E26: =AVERAGE(_xlfn.XLOOKUP("EBITDA Margin",'Fin. Data'!A:A,'Fin. Data'!B:D,,0)) -> 0.26541817 | F26: =Segments!C14 -> Cable Communications | H26: =Segments!B14 -> 0.52 | I26: ROA | K26: =K24/E19 -> 0.01914294 | L26: EV/Asset | M26: =IFERROR(C24/E19,"") -> 1.0000334
B27: % Short | C27: 0.0095 | D27: Operating Margin (average) | E27: =AVERAGE(_xlfn.XLOOKUP("Operating Margin",'Fin. Data'!A:A,'Fin. Data'!B:D,,0)) -> 0.15446885 | F27: =Segments!C15 -> Media | H27: =Segments!B15 -> 0.19 | I27: ROIC | K27: =K24/(E19-(E20-C22)) -> 0.026483478 | L27: EV/Ebidta (3y average) | M27: =IFERROR(C24/K28,"") -> 8.5551122
B28: Traffic ESG | D28: Net Income Margin (average) | E28: =AVERAGE(_xlfn.XLOOKUP("Net Income Margin",'Fin. Data'!A:A,'Fin. Data'!B:D,,0)) -> 0.087580761 | F28: =Segments!C16 -> Studios | H28: =Segments!B16 -> 0.09 | I28: EBITDA (3y average) | K28: =AVERAGE(_xlfn.XLOOKUP("EBITDA",'Fin. Data'!A:A,'Fin. Data'!B:D,,0)) -> 30073.667 | L28: Price/NCF (3y average) | M28: =IFERROR(C21/K30,"") -> 15.989402
B29: E | F29: =Segments!C17 -> Theme Parks | H29: =Segments!B17 -> 0.06 | I29: Net Income (3y average) | K29: =AVERAGE(_xlfn.XLOOKUP("Net Income",'Fin. Data'!A:A,'Fin. Data'!B:D,,0)) -> 9819.6667 | L29: Bonds 1,3,5a (USD) | M29: -
B30: S | D30: Net Financial Cost/Avg Net Debt | E30: =-_xlfn.XLOOKUP("Net Financial Cost",'Fin. Data'!A:A,'Fin. Data'!B:B,,0)/AVERAGE(_xlfn.XLOOKUP("Net Debt",'Fin. Data'!A:A,'Fin. Data'!B:D,,0)) -> 0.039594971 | F30: =Segments!C18 -> Sky | H30: =Segments!B18 -> 0.14 | I30: NCF (3y average) | K30: =AVERAGE(_xlfn.XLOOKUP("Net Income",'Fin. Data'!A:A,'Fin. Data'!B:D,,0)) -> 9819.6667 | L30: Div+Rep.(3y avg)/Price | M30: =-IFERROR(SUM(E51:E53)/(3*C21),"") -> 0.067823449
B31: G | L31: Div. Yield | M31: =-IFERROR(L52/C21,"") -> 0.030195415
B32: INVESTMENT THESIS
B33: Pillars of Recommendation | H33: Recommendation | I33: Valuation Assumptions
B34: Pillar | C34: Explanation | H34: BUY | I34: Check DCF
B35: Strong Market Position and Diversified Service Portfolio | C35: Comcast holds a dominant position in the telecommunications and media industry, making it a reliable and stable investment option. With a diversified service portfolio, Comcast has multiple revenue streams. This diversification reduces the company's reliance on any single business segment, making it better positioned to face market fluctuations and changes in consumer preferences.
B36: Robust Infrastructure and Technological Advancements | C36: Comcast has made significant investments in building and maintaining a state-of-the-art network infrastructure, allowing it to deliver high-quality services to millions of customers. The company's focus on technological advancements ensures it stays competitive and relevant in the rapidly evolving telecommunications landscape. Comcast's infrastructure investments provide a competitive edge and support future growth opportunities.
B37: Expansion into the Streaming and On-Demand Market | C37: Comcast's ownership of NBCUniversal gives it a strong position in the content creation and distribution space. The company's streaming platform, Peacock, has the potential for significant growth as the trend of online content consumption continues to rise. With a vast library of content from NBCUniversal's properties and original programming, Comcast can capitalize on the growing popularity of streaming services and attract new subscribers. This expansion into the streaming market allows Comcast to tap into a broader audience and diversify its revenue sources beyond traditional cable TV offerings.
B38: Risks of Investment | H38: Price Target | I38: Valuation
B39: Risk | C39: Explanation | H39: =DCF!D75 -> 56.095131 | I39: Discount Rate | J39: =DCF!F50 -> 0.0925 | L39: Upside | M39: =DCF!D74 -> 0.3835277
B40: Intense Competition and Market Disruptions | C40: The telecommunications and media industry is highly competitive, with various players vying for market share. Comcast faces competition not only from traditional cable providers but also from emerging streaming services and digital content platforms. As consumer preferences shift towards on-demand content consumption and cord-cutting becomes more prevalent, Comcast's traditional cable TV business could face challenges.
B41: Customer Service Issues and Reputation | C41: Comcast has faced criticism in the past for its customer service practices, including complaints about long wait times, service outages, and billing problems. Poor customer service experiences can lead to customer dissatisfaction, higher churn rates, and damage to the company's reputation.
B42: Regulatory and Legal Challenges | C42: The telecommunications industry is subject to extensive regulatory oversight, and changes in regulations can significantly affect Comcast's operations and profitability. Additionally, the company may face legal challenges related to antitrust, data privacy, or content distribution issues.
...

Sheet Segments
B2: ="Regions "&"("&OP!$J$19&")" -> Regions (2022) | Q2: Products
D3: Nominal value | K3: YoY Growth
B4: Weight | C4: Region | D4: =OP!J19 -> 2022 | E4: =D4-1 -> 2021 | F4: =E4-1 -> 2020 | G4: =F4-1 -> 2019 | H4: =G4-1 -> 2018 | I4: =H4-1 -> 2017 | K4: =OP!J19 -> 2022 | L4: =K4-1 -> 2021 | M4: =L4-1 -> 2020 | N4: =M4-1 -> 2019 | O4: =N4-1 -> 2018 | P4: =O4-1 -> 2017
B5: =IFERROR(D5/$D$9,"") -> 0.11018966 | C5: United Kingdom | D5: 13380 | E5: 13999 | F5: 20460 | G5: 21553 | K5: =(D5-E5)/E5 -> -0.044217444 | L5: =(E5-F5)/F5 -> -0.3157869 | M5: =(F5-G5)/G5 -> -0.050712198 | N5: =(G5-H5)/H5 -> #DIV/0! | O5: =(H5-I5)/I5 -> #DIV/0!
B6: =IFERROR(D6/$D$9,"") -> 0.79423028 | C6: United States | D6: 96441 | E6: 90926 | F6: 80327 | G6: 82952 | H6: 82233 | I6: 77246 | K6: =(D6-E6)/E6 -> 0.060653718 | L6: =(E6-F6)/F6 -> 0.13194816 | M6: =(F6-G6)/G6 -> -0.031644807 | N6: =(G6-H6)/H6 -> 0.0087434485 | O6: =(H6-I6)/I6 -> 0.064559977
B7: =IFERROR(D7/$D$9,"") -> 0
B8: =IFERROR(D8/$D$9,"") -> 0.09558006 | C8: Other | D8: 11606 | E8: 11460 | F8: 2777 | G8: 4437 | H8: 12274 | I8: 7783 | K8: =(D8-E8)/E8 -> 0.012739965 | L8: =(E8-F8)/F8 -> 3.1267555 | M8: =(F8-G8)/G8 -> -0.37412666 | N8: =(G8-H8)/H8 -> -0.63850416 | O8: =K14=(H8-I8)/I8 -> FALSE
B9: =SUM(B5:B8) -> 1 | C9: TOTAL | D9: =SUM(D5:D8) -> 121427 | E9: =SUM(E5:E8) -> 116385 | F9: =SUM(F5:F8) -> 103564 | G9: =SUM(G5:G8) -> 108942 | H9: =SUM(H5:H8) -> 94507 | I9: =SUM(I5:I8) -> 85029 | K9: =(D9-E9)/E9 -> 0.043321734 | L9: =(E9-F9)/F9 -> 0.12379784 | M9: =(F9-G9)/G9 -> -0.049365718 | N9: =(G9-H9)/H9 -> 0.15274001 | O9: =(H9-I9)/I9 -> 0.11146785 | P9: 0.037
B11: ="Categories "&"("&OP!$J$19&")" -> Categories (2022)
D12: Nominal value | K12: YoY Growth
B13: Weight | C13: Category | D13: =OP!J19 -> 2022 | E13: =D13-1 -> 2021 | F13: =E13-1 -> 2020 | G13: =F13-1 -> 2019 | H13: =G13-1 -> 2018 | I13: =H13-1 -> 2017 | K13: =OP!J19 -> 2022 | L13: =K13-1 -> 2021 | M13: =L13-1 -> 2020 | N13: =M13-1 -> 2019 | O13: =N13-1 -> 2018 | P13: =O13-1 -> 2017 | Q13: TV and streaming
B14: 0.52 | C14: Cable Communications | D14: 66318 | E14: 64328 | F14: 60051 | G14: 58082 | K14: =(D14-E14)/E14 -> 0.030935207 | L14: =(E14-F14)/F14 -> 0.071222794 | M14: =(F14-G14)/G14 -> 0.033900348 | N14: =(G14-H14)/H14 -> #DIV/0! | O14: =(H14-I14)/I14 -> #DIV/0!
B15: 0.19 | C15: Media | D15: 23406 | E15: 22780 | F15: 18936 | G15: 19947 | K15: =(D15-E15)/E15 -> 0.027480246 | L15: =(E15-F15)/F15 -> 0.20299958 | M15: =(F15-G15)/G15 -> -0.050684313 | N15: =(G15-H15)/H15 -> #DIV/0! | O15: =(H15-I15)/I15 -> #DIV/0!
B16: 0.09 | C16: Studios | D16: 11622 | E16: 9449 | F16: 8134 | G16: 9352 | K16: =(D16-E16)/E16 -> 0.22997143 | L16: =(E16-F16)/F16 -> 0.16166708 | M16: =(F16-G16)/G16 -> -0.13023952 | N16: =(G16-H16)/H16 -> #DIV/0! | O16: =(H16-I16)/I16 -> #DIV/0!
B17: 0.06 | C17: Theme Parks | D17: 7541 | E17: 5051 | F17: 2094 | G17: 6213 | K17: =(D17-E17)/E17 -> 0.49297169 | L17: =(E17-F17)/F17 -> 1.4121299 | M17: =(F17-G17)/G17 -> -0.66296475 | N17: =(G17-H17)/H17 -> #DIV/0! | O17: =(H17-I17)/I17 -> #DIV/0!
B18: 0.14 | C18: Sky | D18: 17946 | E18: 20285 | F18: 18594 | G18: 19219 | K18: =(D18-E18)/E18 -> -0.11530688 | L18: =(E18-F18)/F18 -> 0.090943315 | M18: =(F18-G18)/G18 -> -0.032519902 | N18: =(G18-H18)/H18 -> #DIV/0! | O18: =(H18-I18)/I18 -> #DIV/0!
B19: =SUM(B14:B18) -> 1 | C19: TOTAL | D19: =SUM(D14:D18) -> 126833 | E19: =SUM(E14:E18) -> 121893 | F19: =SUM(F14:F18) -> 107809 | G19: =SUM(G14:G18) -> 112813 | H19: =SUM(H14:H18) -> 0 | I19: =SUM(I14:I18) -> 0 | K19: =(D19-E19)/E19 -> 0.040527348 | L19: =(E19-F19)/F19 -> 0.13063844 | M19: =(F19-G19)/G19 -> -0.04435659 | N19: =(G19-H19)/H19 -> #DIV/0! | O19: =(H19-I19)/I19 -> #DIV/0! | P19: 0.037
B21: Categories | D21: Description | I21: Graphs
B22: Cable Communications | D22: Consists of the operations of Comcast Cable, which is a provider of broadband, video, voice, wireless, and other services. These services are provided to residencial customers in the United States under the Xfinity brand and are also provided to business costumers. Also selling of advertising. | X22: studios
B23: Media | D23: Consists primerily of NBCUniversal's(acquired between 2011 and 2013) television and streaming platforms, including nacional, regional and internacional cable networks
B24: Studios | D24: Consists primarily of NBCUniversal's film and television studio production and distribution operations
B25: Theme Parks | D25: Consists primarily of Universal theme parks in Orlando, Florida, Hollywood, California, Osaka, Japan and China
B26: Sky | D26: Consists primarily of the operations of sky (acquired in 2018), an intertainment company, wich includes a direct-to-consumer business, providing video, broadband, voice and wireless phone services, and a content business, operating entertainment network, the sky News broadcast network and Sky Sports networks | Q26: theme parks
B29: Industry | J29: Graphs (Industry Forecasts)
B30: Drivers | D30: Description
B31: Consumption Patterns | D31: Consumers are incrisingly turning to streaming services, decreasing their consumption of cable communications and television networks
B32: Personalized user experience | D32: The sucesse of media and entertainment content depends on consumer tastes and preferences that usually chages in unpredictable ways, making harder to be consistent in creating personalized content.
B33: Tecnological developments | D33: Tecnological developments are rapidly changing the way streaming services are produced and distributed and the quality and speed of this services are increasing almost by the day, which is making harder for the companies to catch up
B34: Digital safety | D34: Technology brings along with all the developments,a bunch of concerns regarding the safety of confidencial information and the security needed to prevent cyber attacks and tecnhology disruptions
B36: Source | D36: Market Growth CGAR | G36: Period
B37: Research and Markets | D37: 0.2082 | G37: 2021-2027
B38: Business Research Insights | D38: 0.059 | G38: 2022-2028
B39: Vault | D39: 0.13 | G39: 2021-2026
B40: Statista | D40: 0.105 | G40: 2022-2027
B41: Company's Strategy / Extra Notes
B44: "PHILADELPH"IA--(BUSINESS WIRE)--Jul. 27, 2023-- Comcast Corporation (Nasdaq: CMCSA) announced that its Board of Directors declared a quarterly dividend of $0.29 a share on the company’s common stock. The quarterly dividend is payable on October 25, 2023, to shareholders of record as of the close of business on October 4, 2023."

Sheet Acuerdo
A1: Invertir
A2: NO invertir
A3: Mantener sin elevar posición
A4: Mantener (y seguir comprando)
A5: Liquidar
A6: PENDIENTE

Sheet Peers
B1: Peer Logo | C1: Peer Name | D1: Description
C2: =D8 -> #VALUE! | D2: {=_FV(D8,"description")} -> AT&T Inc. is a holding company. The Company is a provider of telecommunications and technology services globally. The Company operates through two segments: Communications and Latin America. The Communications segment provides wireless and wireline telecom and broadband services to consumers located in the United States and businesses globally. The business units of the Communication segment include Mobility, Business Wireline and Consumer Wireline. Mobility provides nationwide wireless service and equipment. Business Wireline provides advanced ethernet-based fiber services, IP Voice and managed professional services, as well as traditional voice and data services and related equipment to business customers. Consumer Wireline provides broadband services, including fiber connections. Consumer Wireline provides legacy telephony voice communication services. The Latin America segment provides wireless services and equipment in Mexico.
C3: =E8 -> #VALUE! | D3: {=_FV(E8,"description")} -> Paramount Global is a media, streaming and entertainment company. The Company has three segments. TV Media segment consists of its broadcast operations: CBS Television Network, CBS Stations and its international free-to-air networks; domestic premium and basic cable networks, including Paramount+ with Showtime, MTV, Comedy Central, Paramount Network, The Smithsonian Channel, Nickelodeon, BET Media Group, CBS Sports Network and international extensions of certain of these brands, and domestic and international television studio operations. Direct-to-Consumer segment includes its portfolio of domestic and international pay and free streaming services, including Paramount+, Pluto TV, BET+ and Noggin. Filmed Entertainment segment consists of Paramount Pictures, Paramount Players, Paramount Animation, Nickelodeon Studio, Awesomeness and Miramax. Filmed Entertainment segment consists of Paramount Pictures, Paramount Players, Paramount Animation, Nickelodeon Studio, Awesomeness and Miramax.
C4: =F8 -> #VALUE! | D4: {=_FV(F8,"description")} -> Lumen Technologies, Inc. is a facilities-based technology and communications company. The Company provides a range of integrated products and services to its domestic and global business customers and its domestic mass markets customers. It operates through two segments: Business segment and Mass Markets segment. Its Business segment provides its products and services under four sales channels to meet the needs of its enterprise and commercial customers. Its products and services in this segment include Dark Fiber, Edge Cloud Services, Internet Protocol (IP), Managed Security Services, Software-Defined Wide Area Networks (SD WAN), Secure Access Service Edge (SASE), Optical Services, Ethernet, VPN Data Networks, Voice Services, IT Solutions and Other Legacy Services. Its Mass Markets segment provides products and services to residential and small business customers. Its products and services in this segment include Fiber Broadband, Other Broadband and Voice and Other.
C5: =G8 -> #VALUE! | D5: {=_FV(G8,"description")} -> Verizon Communications Inc. is a holding company. The Company, through its subsidiaries, provides communications, information and entertainment products and services to consumers, businesses and governmental agencies. Its reportable segments are Verizon Consumer Group and Verizon Business Group. Its Consumer segment provides wireless and wireline communications services. Its wireless services are provided across wireless networks in the United States (U.S.) under the Verizon brands. Its wireline services are provided in nine states in the Mid-Atlantic and Northeastern U.S., as well as Washington D.C., over its fiber-optic network under the Fios brand and over a traditional copper-based network. Its Business segment provides wireless and wireline communications services and products, including data, video and conferencing services, security and managed network services, local and long-distance voice services and network access to deliver various Internet of Things services and products.
C6: =H8 -> #VALUE! | D6: {=_FV(H8,"Description")} -> T-Mobile US, Inc. is a provider of mobile communications services, including voice, messaging and data, under its flagship brands, T-Mobile and Metro by T-Mobile in the United States, Puerto Rico and the United States Virgin Islands. The Company provides mobile communications services primarily using its 4G Long Term Evolution (LTE) network and its 5G technology network. It also offers a selection of wireless devices, including handsets, tablets and other mobile communication devices, and accessories for sale, as well as financing through equipment installment plans (EIP). The Company’s primary service plan offering is Go5G Plus, which includes unlimited talk, text and data on its network, 5G access at no extra cost, scam protection features and more. In addition to its mobile wireless communications services, the Company also offers high speed Internet, which includes a fixed wireless product that utilizes the excess capacity of its nationwide 5G network.
B8: In Millions USD (exc Market Cap) | C8: =OP!E2 -> #VALUE! | D8: #VALUE! | E8: #VALUE! | F8: #VALUE! | G8: #VALUE! | H8: #VALUE! | I8: AVERAGE
B9: Company Info | I9: =IFERROR(AVERAGE(C9:H9),"")
B10: Market Cap | C10: {=_FV(C8,"Market cap",TRUE)} -> 155326000000 | D10: {=_FV(D8,"Market cap",TRUE)} -> 154447000000 | E10: {=_FV(E8,"Market cap",TRUE)} -> 7396970000 | F10: {=_FV(F8,"Market cap",TRUE)} -> 7015989000 | G10: {=_FV(G8,"Market cap",TRUE)} -> 185408308400 | H10: {=_FV(H8,"Market cap",TRUE)} -> 235071972480 | I10: =IFERROR(AVERAGE(C10:H10),"") -> 124111039980
B11: Net Sales (current) | C11: =C53 -> 121427 | D11: =D53 -> 120741 | E11: =E53 -> 30154 | F11: =F53 -> 17478 | G11: =G53 -> 136835 | H11: =H53 -> 79571 | I11: =IFERROR(AVERAGE(C11:H11),"") -> 84367.667
B12: Profitability | I12: =IFERROR(AVERAGE(C12:H12),"")
B13: Sales Growth (ttm) | C13: =C53/C52-1 -> 0.043321734 | D13: =D53/D52-1 -> -0.099203211 | E13: =E53/E52-1 -> 0.054852025 | F13: =F53/F52-1 -> -0.11220602 | G13: =G53/G52-1 -> 0.02411442 | H13: =H53/H52-1 -> -0.0068274295 | I13: =IFERROR(AVERAGE(C13:H13),"") -> -0.015991414
B14: Sales Growth (36m) | C14: =C53/C51-1 -> 0.11460227 | D14: =D53/D51-1 -> -0.3336332 | E14: =E53/E51-1 -> 0.11689755 | F14: =F53/F51-1 -> -0.21976697 | G14: =G53/G51-1 -> 0.037666454 | H14: =H53/H51-1 -> 0.76832304 | I14: =IFERROR(AVERAGE(C14:H14),"") -> 0.080681522
B15: Operating Margin | C15: =C56/C53 -> 0.11563326 | D15: =D56/D53 -> 0.18975327 | E15: =E56/E53 -> 0.0736884 | F15: =F56/F53 -> 0.18840828 | G15: =G56/G53 -> 0.22265502 | H15: =H56/H53 -> 0.10188385 | I15: =IFERROR(AVERAGE(C15:H15),"") -> 0.14867035
B16: Net Income Margin | C16: =C59/C53 -> 0.040559348 | D16: =D59/D53 -> -0.058430856 | E16: =E59/E53 -> 0.036612058 | F16: =F59/F53 -> -0.088568486 | G16: =G59/G53 -> 0.15534037 | H16: =H59/H53 -> 0.032549547 | I16: =IFERROR(AVERAGE(C16:H16),"") -> 0.019676997
B17: Return on Equity (RoE) | C17: =C59/C70 -> 0.061679691 | D17: =D59/D70 -> -0.066270889 | E17: =E59/E70 -> 0.047697226 | F17: =F59/F70 -> -0.14831848 | G17: =G59/G70 -> 0.22988655 | H17: =H59/H70 -> 0.037182727 | I17: =IFERROR(AVERAGE(C17:H17),"") -> 0.026976137
B18: Return on Invested Capital (ROIC) | C18: =(C59+C58)/(C69+C70) -> 0.0030616109 | D18: =(D59+D58)/(D69+D70) -> -0.012541358 | E18: =(E59+E58)/(E69+E70) -> 0.02154156 | F18: =(F59+F58)/(F69+F70) -> -0.046181523 | G18: =(G59+G58)/(G69+G70) -> 0.038803729 | H18: =(H59+H58)/(H69+H70) -> 0.0096243932 | I18: =IFERROR(AVERAGE(C18:H18),"") -> 0.0023847355
B19: Solvency | I19: =IFERROR(AVERAGE(C19:H19),"")
B20: Debt/Assets | C20: =C69/C66 -> 0.40820911 | D20: =D69/D66 -> 0.38395891 | E20: =E69/E66 -> 0.30082373 | F20: =F69/F66 -> 0.77102301 | G20: =G69/G66 -> 0.75647124 | H20: =H69/H66 -> 0.67040475 | I20: =IFERROR(AVERAGE(C20:H20),"") -> 0.54848179
B21: Net Debt/EBITDA | C21: =(C69-C61)/C55 -> 3.4910351 | D21: =(D69-D61)/D55 -> 7.1774661 | E21: =(E69-E61)/E56 -> 6.6071107 | F21: =(F69-F61)/F55 -> 9.4673184 | G21: =(G69-G61)/G55 -> 5.810424 | H21: =(H69-H61)/H55 -> 6.803978 | I21: =IFERROR(AVERAGE(C21:H21),"") -> 6.5595554 | S21: 1000000 | T21: 1000000 | U21: 1000000 | V21: 1000000 | W21: 1000000 | X21: 1000000
B22: Interest Coverage Ratio | C22: =-C55/C57 -> 7.3724333 | D22: =-D55/D57 -> -3.4438441 | E22: =-E56/E57 -> 2.6998785 | F22: =-F55/F57 -> 2.6876877 | G22: =-G55/G57 -> 14.128353 | H22: =-H55/H57 -> 5.9931629 | I22: =IFERROR(AVERAGE(C22:H22),"") -> 4.9062785 | S22: 1000000 | T22: 1000000 | U22: 1000000 | V22: 1000000 | W22: 1000000 | X22: 1000000
B23: Liquidity | S23: 1000000 | T23: 1000000 | U23: 1000000 | V23: 1000000 | W23: 1000000 | X23: 1000000
B24: Current Ratio | C24: =C64/C68 -> 0.78265859 | D24: =D64/D68 -> 0.58939348 | E24: =E64/E68 -> 1.2272362 | F24: =F64/F68 -> 1.1284614 | G24: =G64/G68 -> 0.75455941 | H24: =H64/H68 -> 0.77063293 | I24: =IFERROR(AVERAGE(C24:H24),"") -> 0.87549033
B25: Quick Ratio | C25: =(C61+C62)/C68 -> 0.62466382 | D25: =(D61+D62)/D68 -> 0.27000516 | E25: =(E61+E62)/E68 -> 0.92011438 | F25: =(F61+F62)/F68 -> 0.56797835 | G25: =(G61+G62)/G68 -> 0.54037193 | H25: =(H61+H62)/H68 -> 0.36181392 | I25: =IFERROR(AVERAGE(C25:H25),"") -> 0.54749126
B26: Activity | I26: =IFERROR(AVERAGE(C26:H26),"")
B27: Inventory Turnover | C27: =C54/C63 -> #DIV/0! | D27: =D54/D63 -> 34.385207 | E27: =E54/E63 -> 14.78763 | F27: =F54/F63 -> 46.381356 | G27: =G54/G63 -> 37.382328 | H27: =H54/H63 -> 19.217622 | I27: =IFERROR(AVERAGE(C27:H27),"")
B28: Acc. Receivable Turnover | C28: =C53/C62 -> 9.5830637 | D28: =D53/D62 -> 10.530351 | E28: =E53/E62 -> 4.0682677 | F28: =F53/F62 -> 11.833446 | G28: =G53/G62 -> 5.5837346 | H28: =H53/H62 -> 17.901237 | I28: =IFERROR(AVERAGE(C28:H28),"") -> 9.9166833
A29: Price/Sales | B29: Payables Turnover | C29: =C54/C67 -> 6.774713 | D29: =D54/D67 -> 2.5181737 | E29: =E54/E67 -> 14.14469 | F29: =F54/F67 -> 11.522105 | G29: =G54/G67 -> 10.202171 | H29: =H54/H67 -> 5.019548 | I29: =IFERROR(AVERAGE(C29:H29),"") -> 8.3635669
B30: Fixed Asset Turnover | C30: =C53/C65 -> 2.1884654 | D30: =D53/D65 -> 0.94739692 | E30: =E53/E65 -> 17.113507 | F30: =F53/F65 -> 0.91192737 | G30: =G53/G65 -> 1.2736657 | H30: =H53/H65 -> 1075.2838 | I30: =IFERROR(AVERAGE(C30:H30),"") -> 182.95312
B31: Total Asset Turnover | C31: =C53/C66 -> 0.47197357 | D31: =D53/D66 -> 0.29971478 | E31: =E53/E66 -> 0.51639751 | F31: =F53/F66 -> 0.38344924 | G31: =G53/G66 -> 0.3603956 | H31: =H53/H66 -> 0.37651061 | I31: =IFERROR(AVERAGE(C31:H31),"") -> 0.40140689
B32: Valuation | I32: =IFERROR(AVERAGE(C32:H32),"")
B33: Price/Earnings | C33: =C10/C59/S21 -> 31.538274 | D33: =D10/D59/T21 -> -21.89185 | E33: =E10/E59/U21 -> 6.700154 | F33: =F10/F59/V21 -> -4.5322926 | G33: =G10/G59/W21 -> 8.722634 | H33: =H10/H59/X21 -> 90.761379 | I33: =IFERROR(AVERAGE(C33:H33),"") -> 18.549717
B34: Price/Sales | C34: =C10/C53/S22 -> 1.2791718 | D34: =D10/D53/T22 -> 1.2791595 | E34: =E10/E53/U22 -> 0.24530643 | F34: =F10/F53/V22 -> 0.4014183 | G34: =G10/G53/W22 -> 1.3549772 | H34: =H10/H53/X22 -> 2.9542418 | I34: =IFERROR(AVERAGE(C34:H34),"") -> 1.2523792
B35: Price/Book | C35: =C10/C70/S23 -> 1.945271 | D35: =D10/D70/T23 -> 1.4507923 | E35: =E10/E70/U23 -> 0.31957876 | F35: =F10/F70/V23 -> 0.67222277 | G35: =G10/G70/W23 -> 2.0052162 | H35: =H10/H70/X23 -> 3.3747555 | I35: =IFERROR(AVERAGE(C35:H35),"") -> 1.6279728
B36: EV/Sales | C36: =(C69+(C10/1000000)-C61)/C53 -> 2.1049602 | D36: =(D69+(D10/1000000)-D61)/D53 -> 2.5295881 | E36: =(E69+(E10/1000000)-E61)/E53 -> 0.73217384 | F36: =(F69+(F10/1000000)-F61)/F53 -> 2.340599 | G36: =(G69+(G10/1000000)-G61)/G53 -> 3.4349421 | H36: =(H69+(H10/1000000)-H61)/H53 -> 4.6781739 | I36: =IFERROR(AVERAGE(C36:H36),"") -> 2.6367395
B37: EV/EBITDA | C37: =(C69+(C10/1000000)-C61)/C55 -> 8.8987571 | D37: =(D69+(D10/1000000)-D61)/D55 -> 14.519848 | E37: =(E69+(E10/1000000)-E61)/E55 -> 8.1921967 | F37: =(F69+(F10/1000000)-F61)/F55 -> 11.427092 | G37: =(G69+(G10/1000000)-G61)/G55 -> 9.5955803 | H37: =(H69+(H10/1000000)-H61)/H55 -> 18.463716 | I37: =IFERROR(AVERAGE(C37:H37),"") -> 11.849532
B38: Stock Info | I38: =IFERROR(AVERAGE(C38:H38),"")
B39: Float | C39: =OP!M19 -> 0.99 | D39: 0.991 | E39: 0.1734 | F39: 0.5269 | G39: 0.9949 | H39: 0.9964 | I39: =IFERROR(AVERAGE(C39:H39),"") -> 0.77876667
B40: b (Yahoo) | C40: =OP!M21 -> 1.05 | D40: 0.66 | E40: 0.99 | F40: 0.17 | G40: 0.55 | H40: 0.79 | I40: =IFERROR(AVERAGE(C40:H40),"") -> 0.70166667
B41: Dividend Yield (yahoo finance) | C41: =OP!M31 -> 0.030195415 | D41: 0.0252 | E41: 0 | F41: 0.0262 | G41: 0 | H41: 0.0197 | I41: =IFERROR(AVERAGE(C41:H41),"") -> 0.016882569
...

Sheet ESG
B1: Company GICS Sector: | T1: Yes
B2: Communication Services | C2: <- Select Industry | I2: 9+ | T2: No
B3: ESG Analysis | K3: Relative ESG Analysis
B4: Parameters | C4: Impact | D4: Do they report? | E4: Ranking | F4: Mitigation Plan | G4: Traffic Lights | H4: Improvement over time? | I4: Targets / Goals? | J4: Comments | K4: Parameters | L4: Comcast Corporation | M4: AT&T Inc. | N4: Paramount Global | O4: Lumen Technologies, Inc. | P4: Verizon Communications Inc. | Q4: T-Mobile US, Inc.
B5: Environmental | K5: Ratios
A6: 1 | B6: CO2 Direct Emissions | C6: low | D6: Yes | E6: Medium | J6: Goal to become carbon neutral by 2035 for Scope 1 and 2 emissions across our global operations. | K6: CO2 Emissions/$M Sales | L6: =L12/L$11 -> 0.15500021 | M6: =M12/M$11 -> 0.15193879 | N6: =N12/N$11 -> 0.071383334 | O6: =O12/O$11 -> 0.090473409 | P6: =P12/P$11 -> 0.11426427 | Q6: =Q12/Q$11 -> 0.091541114
A7: 2 | B7: Total Water Consumption | C7: =VLOOKUP($B$2,'Sector Impact'!$K$4:$AA$16,A7+1,FALSE) -> Low | K7: Water Consumption/$M Sales | L7: =L13/L$11 -> 0 | M7: =M13/M$11 -> 7.5724794e-05 | N7: =N13/N$11 -> 0 | O7: =O13/O$11 -> 0.021893653 | P7: =P13/P$11 -> 1.5118289e-05 | Q7: =Q13/Q$11 -> 0.013162872
A8: 3 | B8: Total Energy Consumption | C8: =VLOOKUP($B$2,'Sector Impact'!$K$4:$AA$16,A8+1,FALSE) -> Medium | D8: Yes | E8: Medium | F8: Yes | J8: Utilizing the latest clean technologies to green our operations and network. This means investing in clean and renewable energy, piloting electric and hybrid vehicles, and building for the future. | K8: Energy Consumption/$M Sales | L8: =L14/L$11 -> 0.18862853 | M8: =M14/M$11 -> 0.12682971 | N8: =N14/N$11 -> 0.22978206 | O8: =O14/O$11 -> 0.26529827 | P8: =P14/P$11 -> 0.04916101 | Q8: =Q14/Q$11 -> 0.10020714
A9: 4 | B9: Waste Management | C9: =VLOOKUP($B$2,'Sector Impact'!$K$4:$AA$16,A9+1,FALSE) -> Low | K9: Waste Production/$M Sales | L9: =L15/L$11 -> 0 | M9: =M15/M$11 -> 0.0014191722 | N9: =N15/N$11 -> 0 | O9: =O15/O$11 -> 0.0019890283 | P9: =P15/P$11 -> 0.00032481869 | Q9: =Q15/Q$11 -> 0.00014478644
A10: 5 | B10: Land Degradation/Deforestation/Biodiversity loss/Animal sufering/… | C10: =VLOOKUP($B$2,'Sector Impact'!$K$4:$AA$16,A10+1,FALSE) -> Low | K10: Inputs
B11: Social | K11: Net Sales ($M) | L11: =Peers!C52 -> 116385 | M11: =Peers!D52 -> 134038 | N11: =Peers!E52 -> 28586 | O11: =Peers!F52 -> 19687 | P11: =Peers!G52 -> 133613 | Q11: =Peers!H52 -> 80118
A12: 6 | B12: Employee Turnover % | C12: =VLOOKUP($B$2,'Sector Impact'!$K$4:$AA$16,A12+1,FALSE) -> Medium | D12: No | E12: Medium High | F12: No | K12: CO2 Emissions Total (Tonnes) | L12: 18039.7 | M12: 20365.571 | N12: 2040.564 | O12: 1781.15 | P12: 15267.192 | Q12: 7334.091
A13: 7 | B13: Salaries & Compensation | C13: =VLOOKUP($B$2,'Sector Impact'!$K$4:$AA$16,A13+1,FALSE) -> Medium | D13: No | E13: Medium High | F13: No | K13: Water Consumption Total (Cubic Meters) | L13: 0 | M13: 10.15 | N13: 0 | O13: 431.02034 | P13: 2.02 | Q13: 1054.583
A14: 8 | B14: Reputation | C14: =VLOOKUP($B$2,'Sector Impact'!$K$4:$AA$16,A14+1,FALSE) -> Low | K14: Energy Consumption Total (Gigajoules) | L14: 21953.532 | M14: 17000 | N14: 6568.55 | O14: 5222.927 | P14: 6568.55 | Q14: 8028.396
A15: 9 | B15: Discrimination Events | C15: =VLOOKUP($B$2,'Sector Impact'!$K$4:$AA$16,A15+1,FALSE) -> Low | F15: Yes | K15: Waste Production Total (Tonnes) | L15: 0 | M15: 190.223 | N15: 0 | O15: 39.158 | P15: 43.4 | Q15: 11.6
A16: 10 | B16: Work Safety | C16: =VLOOKUP($B$2,'Sector Impact'!$K$4:$AA$16,A16+1,FALSE) -> High | D16: Yes | E16: Medium High | F16: Yes | I16: None | J16: Robust Employee Assistance Program and generous portfolio of mental and behavioral health resources | K16: ESG Scores
A17: 11 | B17: Damage to consumer health | C17: =VLOOKUP($B$2,'Sector Impact'!$K$4:$AA$16,A17+1,FALSE) -> Low | I17: None | K17: Refinitiv | L17: 66/100 | M17: 76/100 | N17: 69/100 | P17: 72/100 | Q17: 64/100
A18: 12 | B18: PXP? | C18: =VLOOKUP($B$2,'Sector Impact'!$K$4:$AA$16,A18+1,FALSE) -> Low | K18: Sustainalytics | L18: 23,1 (Medium risk) | M18: 23,9 (Medium Risk) | N18: 15,0 (Low Risk) | O18: 26,1 (Medium Risk) | P18: 18,6 (Low Risk) | Q18: 24,7 (Medium Risk)
A19: 13 | B19: Supply chain | C19: =VLOOKUP($B$2,'Sector Impact'!$K$4:$AA$16,A19+1,FALSE) -> Low | I19: None | K19: ISS
A20: 14 | B20: Community involvement | C20: =VLOOKUP($B$2,'Sector Impact'!$K$4:$AA$16,A20+1,FALSE) -> Low | K20: CDP | L20: B | M20: A | N20: B | O20: B | P20: B | Q20: A-
A21: 15 | B21: Public Sector | C21: =VLOOKUP($B$2,'Sector Impact'!$K$4:$AA$16,A21+1,FALSE) -> Low | I21: None
A22: 16 | B22: Litigation | C22: =VLOOKUP($B$2,'Sector Impact'!$K$4:$AA$16,A22+1,FALSE) -> Medium | D22: Yes | E22: Medium | F22: No | H22: Yes | I22: None | J22: No major law-suits in the last 5 years
B23: Corporate Governance | K23: PARAMETERS
A24: 17 | B24: Diversity (Gender, Age, Industry, Region) | E24: Medium | F24: Yes | I24: Aspiration to have 50% women and 33% people of color at every level of our workforce. | J24: Board of Directors is 50% diverse by people of color and gender | K24: IMPACT | L24: RANKING | M24: MITIGATION PLAN
A25: 18 | B25: % Independence | E25: Medium High | F25: No | I25: None | J25: 89% of Board membersand are independent (1 out of 9 is non-independent) | K25: Low | L25: "Best in class" | M25: Evidence / plan?
A26: 19 | B26: average time as independent directors | E26: Medium High | F26: No | I26: None | J26: Independence director tenure has an average of10 years | K26: Medium | L26: Medium High
A27: 20 | B27: Recent departures of directors / C-level executives? | E27: Medium High | F27: No | I27: None | J27: Maritza G. Montiel has been a director since 2018, being the most recent change to the board | K27: High | L27: Medium
A28: 21 | B28: CEO/Chairman duality | E28: Medium | F28: No | I28: None | J28: Brian L. Roberts is the Chairman, President and Chief Executive Officer of Comcast | K28: Very high | L28: "Villain"
A29: 22 | B29: Transparency (ESG, segments, acquisitions, other) | E29: Medium High | F29: No | I29: None | J29: The information of the board about their public profile is available and accurately disclosed
A30: 23 | B30: Time taken to report after the end of the quarter / year | E30: Medium High | F30: No | I30: None | J30: On Jan. 26, 2023, Comcast Corporation reported results for the quarter and year ended December 31, 2022.
A31: 24 | B31: Additional participation of the CEO in other boards or excessive participation of Ch. | E31: Medium | F31: No | I31: None | J31: The Ceo and Chairman, Brian L. Roberts is not present in any other committee
A32: 25 | B32: Audit / Consulting | D32: Yes | E32: Medium | F32: No | J32: In 2021 they paid 27,4 millions for the services of Deloitte
A33: 26 | B33: ESG-compensation related | D33: No | E33: Medium | F33: No | I33: None | J33: None
A34: 27 | B34: Management compensation schemes | D34: Yes | E34: Medium High | F34: No | I34: None | J34: Base salary, Annueal Cash Bonus, Annueal PSU Grants and Annual Stock Option Grants

Sheet DCF
A1: VALUATION MODEL
G3: Short Term | K3: Long Term
A4: Section | B4: Line # | C4: ITEM | D4: 2020 (Real) | E4: 2021 (Real) | F4: 2022 (Real) | G4: 2023 | H4: =G4+1 -> 2024 | I4: =H4+1 -> 2025 | J4: =I4+1 -> 2026 | K4: =J4+1 -> 2027 | L4: =K4+1 -> 2028 | M4: =L4+1 -> 2029 | N4: =M4+1 -> 2030 | O4: =N4+1 -> 2031 | ... AF4: =AE4+1 -> 2048
A5: INCOME STATEMENT | B5: 1 | C5: Growth | D5: ='Fin. Data'!D6 -> -0.049365718 | E5: =+E6/D6-1 -> 0.12379784 | F5: =+F6/E6-1 -> 0.043321734 | G5: =+G6/F6-1 -> 0.035 | H5: =+H6/G6-1 -> 0.036428571 | I5: =+I6/H6-1 -> 0.038095238 | J5: =+J6/I6-1 -> 0.039761905 | K5: =+K6/J6-1 -> 0.041428571 | L5: =+L6/K6-1 -> 0.043095238 | ... AF5: =+AF6/AE6-1 -> 0.02
B6: 2 | C6: Revenues/Sales | D6: 103564 | E6: 116385 | F6: 121427 | G6: =Assum.!I8 -> 125676.94 | H6: =Assum.!J8 -> 130255.18 | I6: =Assum.!K8 -> 135217.28 | J6: =Assum.!L8 -> 140593.78 | K6: =Assum.!M8 -> 146418.37 | L6: =Assum.!N8 -> 152728.31 | M6: =Assum.!O8 -> 159564.72 | N6: =Assum.!P8 -> 166745.13 | ... AF6: =Assum.!AH8 -> 250028.98
B7: 3 | C7: EBIT/Operating Margin | D7: =D8/D6 -> 0.16891005 | E7: =E8/E6 -> 0.17886326 | F7: =F8/F6 -> 0.11563326 | G7: =0.126 -> 0.126 | H7: =+G7*(1+H5) -> 0.13059 | I7: =+$G$7*(1+I5) -> 0.1308 | J7: =+$G$7*(1+J5) -> 0.13101 | K7: =+$G$7*(1+K5) -> 0.13122 | L7: =+$G$7*(1+L5) -> 0.13143 | M7: =+$G$7*(1+M5) -> 0.13164 | N7: =+$G$7*(1+N5) -> 0.13167 | O7: =+$G$7*(1+O5) -> 0.13104 | P7: =+$G$7*(1+P5) -> 0.13041 | ... AF7: =+$G$7*(1+AF5) -> 0.12852
B8: 4 | C8: EBIT | D8: ='Fin. Data'!D11 -> 17493 | E8: ='Fin. Data'!C11 -> 20817 | F8: ='Fin. Data'!B11 -> 14041 | G8: =G7*G6 -> 15835.295 | H8: =H7*H6 -> 17010.024 | I8: =I7*I6 -> 17686.42 | J8: =J7*J6 -> 18419.19 | K8: =K7*K6 -> 19213.019 | L8: =L7*L6 -> 20073.082 | M8: =M7*M6 -> 21005.1 | N8: =N7*N6 -> 21955.331 | ... AF8: =AF7*AF6 -> 32133.724
B9: 5a | C9: (Dep) | D9: -8320 | E9: -8628 | F9: -8724 | G9: =$D$53*DCF!F40 -> -8886.892 | H9: =$D$53*DCF!G40 -> -10520.905 | I9: =$D$53*DCF!H40 -> -12214.442 | J9: =$D$53*DCF!I40 -> -13972.495 | K9: =$E$53*DCF!J40 -> -15303.671 | L9: =$E$53*DCF!K40 -> -17147.504 | M9: =$E$53*DCF!L40 -> -19070.797 | N9: =$E$53*DCF!M40 -> -21080.18 | O9: =$E$53*DCF!N40 -> -23179.986 | P9: =$E$53*DCF!O40 -> -25363.783 | Q9: =$E$53*DCF!P40 -> -27624.014 | R9: =$E$53*DCF!Q40 -> -29952.052 | ... AF9: =$E$53*DCF!AE40 -> -68069.679 | AG9: =SUM(D9:AF9) -> -942949.43
B10: 5b | C10: Amort | D10: -4780 | E10: -5176 | F10: -5097 | G10: =F38*$D$54 -> -4833.5105 | H10: =G38*$D$54 -> -5097.1993 | I10: =H38*$D$54 -> -5375.2734 | J10: =I38*$D$54 -> -5668.5177 | K10: =J38*$E$54 -> -4382.98 | L10: =K38*$E$54 -> -4558.2992 | M10: =L38*$E$54 -> -4740.6312 | N10: =M38*$E$54 -> -4930.2565 | O10: =N38*$E$54 -> -5127.4667 | P10: =O38*$E$54 -> -5332.5654 | Q10: =P38*$E$54 -> -5545.868 | R10: =Q38*$E$54 -> -5767.7027 | ... AF10: =AE38*$E$54 -> -9987.795
B11: 5c | C11: (Stock based compensation) | D11: =D20 -> -1193 | E11: =E20 -> -1315 | F11: =F20 -> -1336 | G11: =G6*$D$55 -> -1305.3487 | H11: =H6*$D$55 -> -1352.9006 | I11: =I6*$D$55 -> -1404.4397 | J11: =J6*$D$55 -> -1460.2829 | K11: =K6*$D$55 -> -1520.7804 | L11: =L6*$D$55 -> -1586.3187 | M11: =M6*$D$55 -> -1657.3254 | N11: =N6*$D$55 -> -1731.905 | ... AF11: =AF6*$D$55 -> -2596.9361
B12: 6 | C12: EBIDTA | D12: =D8-D9-D10 -> 30593 | E12: =E8-E9-E10 -> 34621 | F12: =F8-F9-F10 -> 27862 | G12: =G8-G9-G10 -> 29555.698 | H12: =H8-H9-H10 -> 32628.127 | I12: =I8-I9-I10 -> 35276.135 | J12: =J8-J9-J10 -> 38060.203 | K12: =K8-K9-K10 -> 38899.67 | ... AF12: =AF8-AF9-AF10 -> 110191.2
B13: 7 | C13: (Net financing cost) | D13: ='Fin. Data'!D14 -> -4588 | E13: ='Fin. Data'!C14 -> -4281 | F13: ='Fin. Data'!B14 -> -3896 | G13: =F43*$D$58-F44*$D$57 -> -3897.3799 | H13: =G43*$D$58-G44*$D$57 -> -3807.0092 | I13: =H43*$D$58-H44*$D$57 -> -3628.1916 | J13: =I43*$D$58-I44*$D$57 -> -3389.5502 | K13: =J43*$E$58-J44*$E$57 -> -4007.1143 | L13: =K43*$E$58-K44*$E$57 -> -3704.5513 | M13: =L43*$E$58-L44*$E$57 -> -3575.0124 | N13: =M43*$E$58-M44*$E$57 -> -3521.5208 | O13: =N43*$E$58-N44*$E$57 -> -3426.3004 | P13: =O43*$E$58-O44*$E$57 -> -3275.9099 | Q13: =P43*$E$58-P44*$E$57 -> -3070.7374 | R13: =Q43*$E$58-Q44*$E$57 -> -2806.3797 | ... AF13: =AE43*$E$58-AE44*$E$57 -> 7288.3211
B14: 8 | C14: Other income/(cost) | D14: ='Fin. Data'!D15 -> 1160 | E14: ='Fin. Data'!C15 -> 2556 | F14: ='Fin. Data'!B15 -> -861 | G14: =AVERAGE(D14:F14)*(1+G5) -> 984.975 | H14: =AVERAGE(E14:G14)*(1+H5) -> 925.86755 | I14: =AVERAGE(F14:H14)*(1+I5) -> 363.27885 | J14: =AVERAGE(G14:I14)*(1+J5) -> 788.1816 | K14: =AVERAGE(H14:J14)*(1+K5) -> 721.12958 | L14: =AVERAGE(I14:K14)*(1+L5) -> 651.09658 | M14: =AVERAGE(J14:L14)*(1+M5) -> 752.37058 | N14: =AVERAGE(K14:M14)*(1+N5) -> 740.06786 | ... AF14: =AVERAGE(AC14:AE14)*(1+AF5) -> 899.18941
B15: 9 | C15: Earnings before taxes | D15: =D8+D13+D14 -> 14065 | E15: =E8+E13+E14 -> 19092 | F15: =F8+F13+F14 -> 9284 | G15: =G8+G13+G14 -> 12922.89 | H15: =H8+H13+H14 -> 14128.882 | I15: =I8+I13+I14 -> 14421.507 | J15: =J8+J13+J14 -> 15817.822 | K15: =K8+K13+K14 -> 15927.034 | ... AF15: =AF8+AF13+AF14 -> 40321.235
B16: 10 | C16: (Income tax) | D16: ='Fin. Data'!D21 -> -3364 | E16: ='Fin. Data'!C21 -> -5259 | F16: ='Fin. Data'!B21 -> -4359 | G16: =-(1*$D$56)*G15 -> -3077.6863 | H16: =-(1*$D$56)*H15 -> -3364.9025 | I16: =-(1*$D$56)*I15 -> -3434.5935 | J16: =-(1*$D$56)*J15 -> -3767.1367 | K16: =-(1*$E$56)*K15 -> -4300.2993 | L16: =-(1*$E$56)*L15 -> -4595.2993 | M16: =-(1*$E$56)*M15 -> -4909.2636 | N16: =-(1*$E$56)*N15 -> -5176.9472 | O16: =-(1*$E$56)*O15 -> -5411.093 | P16: =-(1*$E$56)*P15 -> -5643.5174 | Q16: =-(1*$E$56)*Q15 -> -5857.8059 | R16: =-(1*$E$56)*R15 -> -6061.0154 | ... AF16: =-(1*$E$56)*AF15 -> -10886.733
B17: 11 | C17: Net income | D17: ='Fin. Data'!D23 -> 10701 | E17: ='Fin. Data'!C23 -> 13833 | F17: ='Fin. Data'!B23 -> 4925 | G17: =G16+G15 -> 9845.2039 | H17: =H16+H15 -> 10763.979 | I17: =I16+I15 -> 10986.914 | J17: =J16+J15 -> 12050.685 | K17: =K16+K15 -> 11626.735 | L17: =L16+L15 -> 12424.328 | M17: =M16+M15 -> 13273.194 | N17: =N16+N15 -> 13996.931 | ... AF17: =AF16+AF15 -> 29434.501
A19: CASH FLOW STATEMENT | B19: 12 | C19: Operating cash flows before WK | D19: =D17-D9-D10-550-D11+24737-23073 -> 26108 | E19: =E17-E9-E10+1892-E11+29146-28030 -> 31960 | F19: =F17-F9-F10-F11+8583+2090 -> 30755 | G19: =G17-G10-G9-G11 -> 24870.955 | H19: =H17-H10-H9-H11 -> 27734.984 | I19: =I17-I10-I9-I11 -> 29981.069 | J19: =J17-J10-J9-J11 -> 33151.981 | K19: =K17-K10-K9-K11 -> 32834.167 | L19: =L17-L10-L9-L11 -> 35716.449 | M19: =M17-M10-M9-M11 -> 38741.948 | N19: =N17-N10-N9-N11 -> 41739.273 | ... AF19: =AF17-AF10-AF9-AF11 -> 110088.91
B20: 13 | C20: (Stock-based compensation) | D20: -1193 | E20: -1315 | F20: -1336 | G20: =G11 -> -1305.3487 | H20: =H11 -> -1352.9006 | I20: =I11 -> -1404.4397 | J20: =J11 -> -1460.2829 | K20: =K11 -> -1520.7804 | L20: =L11 -> -1586.3187 | M20: =M11 -> -1657.3254 | N20: =N11 -> -1731.905 | ... AF20: =AF11 -> -2596.9361
B21: 14 | C21: (Working Capital Flows) | D21: =Inputs!D62 -> -178 | E21: =Inputs!C62 -> -1499 | F21: =Inputs!B62 -> -3006 | G21: =$D$60*(G6-F6) -> -573.28206 | H21: =$D$60*(H6-G6) -> -617.56518 | I21: =$D$60*(I6-H6) -> -669.34608 | J21: =$D$60*(J6-I6) -> -725.24445 | K21: =$E$60*(K6-J6) -> -785.68976 | L21: =$E$60*(L6-K6) -> -851.15746 | M21: =$E$60*(M6-L6) -> -922.17458 | N21: =$E$60*(N6-M6) -> -968.57762 | O21: =$E$60*(O6-N6) -> -899.70099 | P21: =$E$60*(P6-O6) -> -818.7279 | Q21: =$E$60*(Q6-P6) -> -726.32861 | R21: =$E$60*(R6-Q6) -> -623.43205 | ... AF21: =$E$60*(AF6-AE6) -> -661.31019
B22: 15 | C22: -Total Operating Cash Flow | D22: =D19+D20+D21 -> 24737 | E22: =E19+E20+E21 -> 29146 | F22: =F19+F20+F21 -> 26413 | G22: =G19+G20+G21 -> 22992.324 | H22: =H19+H20+H21 -> 25764.518 | I22: =I19+I20+I21 -> 27907.283 | J22: =J19+J20+J21 -> 30966.454 | K22: =K19+K20+K21 -> 30527.696 | ... AF22: =AF19+AF20+AF21 -> 106830.66
B23: 16 | C23: (CAPEX) | D23: ='Fin. Data'!D32 -> -9179 | E23: ='Fin. Data'!C32 -> -9174 | F23: ='Fin. Data'!B32 -> -10626 | G23: =G6*$D$62 -> -11304.556 | H23: =H6*$D$62 -> -11716.364 | I23: =I6*$D$62 -> -12162.702 | J23: =J6*$D$62 -> -12646.314 | K23: =K6*$E$62 -> -13170.233 | L23: =L6*$E$62 -> -13737.807 | M23: =M6*$E$62 -> -14352.738 | N23: =N6*$E$62 -> -14998.611 | O23: =O6*$E$62 -> -15598.555 | P23: =P6*$E$62 -> -16144.505 | Q23: =Q6*$E$62 -> -16628.84 | R23: =R6*$E$62 -> -17044.561 | ... AF23: =AF6*$E$62 -> -22489.936 | AG23: =SUM(D23:AF23) -> -476198.93
B24: 17 | C24: Adq | D24: =Inputs!D66 -> -233 | E24: ='Fin. Data'!C33 -> -1374 | F24: ='Fin. Data'!B33 -> -12 | G24: =G6*$D$63 -> -555.09983 | H24: =H6*$D$63 -> -575.32132 | I24: =I6*$D$63 -> -597.23832 | J24: =J6*$D$63 -> -620.98566 | K24: =K6*$E$63 -> -6895.7318 | L24: =L6*$E$63 -> -7192.905 | M24: =M6*$E$63 -> -7514.8731 | N24: =N6*$E$63 -> -7853.0424 | O24: =O6*$E$63 -> -8167.1641 | P24: =P6*$E$63 -> -8453.0149 | Q24: =Q6*$E$63 -> -8706.6053 | R24: =R6*$E$63 -> -8924.2705 | ... AF24: =AF6*$E$63 -> -11775.385 | AH24: =AG9-AG23 -> -466750.51
B25: 18 | C25: (Other investing flows) | D25: =Inputs!D67 -> -2635 | E25: =Inputs!C67 -> -2898 | F25: =Inputs!B67 -> -3502 | G25: =(1+G5)*AVERAGE(D25:F25) -> -3117.075 | H25: =(1+H5)*AVERAGE(E25:G25) -> -3287.9228 | I25: =(1+I5)*AVERAGE(F25:H25) -> -3428.1358 | J25: =(1+J5)*AVERAGE(G25:I25) -> -3408.0392 | K25: =(1+K5)*AVERAGE(H25:J25) -> -3514.5082 | L25: =(1+L5)*AVERAGE(I25:K25) -> -3598.9161 | M25: =(1+M5)*AVERAGE(J25:L25) -> -3664.1414 | N25: =(1+N5)*AVERAGE(K25:M25) -> -3754.1854 | ... AF25: =(1+AF5)*AVERAGE(AC25:AE25) -> -4560.2077
B26: 19 | C26: -Total Investing Flows | D26: =D23+D24+D25 -> -12047 | E26: =E23+E24+E25 -> -13446 | F26: =F23+F24+F25 -> -14140 | G26: =G23+G24+G25 -> -14976.73 | H26: =H23+H24+H25 -> -15579.609 | I26: =I23+I24+I25 -> -16188.076 | J26: =J23+J24+J25 -> -16675.339 | K26: =K23+K24+K25 -> -23580.473 | ... AF26: =AF23+AF24+AF25 -> -38825.529
B27: 20 | C27: (Flows related to leases) | D27: =Inputs!D71+Inputs!D72 -> 0 | E27: =Inputs!C71+Inputs!C72 -> 0 | F27: =Inputs!B71+Inputs!B72 -> 0 | G27: 0 | H27: 0 | I27: 0 | J27: 0 | K27: 0 | L27: 0 | M27: 0 | N27: 0 | O27: 0 | P27: 0 | Q27: 0 | R27: 0 | S27: 0 | T27: 0 | U27: 0 | V27: 0 | W27: 0 | X27: 0 | Y27: 0 | Z27: 0 | AA27: 0 | AB27: 0 | AC27: 0 | AD27: 0 | AE27: 0 | AF27: 0
B28: 21 | C28: Flows related to debt | D28: =+SUM(Inputs!D69:D70) -> -133 | E28: =+SUM(Inputs!C69:C70) -> -8870 | F28: =+SUM(Inputs!B69:B70) -> 438 | G28: =G44-F44 -> -4532.6282 | H28: =H44-G44 -> -2604.9896 | I28: =I44-H44 -> -9694.0437 | J28: =J44-I44 -> -4457.8915 | K28: =K44-J44 -> -9823.0737 | L28: =L44-K44 -> -2885.2696 | M28: =M44-L44 -> 682.34028 | N28: =N44-M44 -> 242.20781 | ... AF28: =AF44-AE44 -> 410.1073
B29: 22 | C29: (Respurchases)/Issuance of stock | D29: ='Fin. Data'!D28 -> -534 | E29: ='Fin. Data'!C28 -> -4672 | F29: ='Fin. Data'!B28 -> -13328 | G29: =-G17*$D$65 -> -2151.0915 | H29: =-H17*$D$65 -> -2351.836 | I29: =-I17*$D$65 -> -2400.5452 | J29: =-J17*$D$65 -> -2632.9701 | K29: =-K17*$E$65 -> -2540.3406 | L29: =-L17*$E$65 -> -2714.6077 | M29: =-M17*$E$65 -> -2900.0776 | N29: =-N17*$E$65 -> -3058.2079 | O29: =-O17*$E$65 -> -3196.5262 | P29: =-P17*$E$65 -> -3333.8276 | Q29: =-Q17*$E$65 -> -3460.4155 | R29: =-R17*$E$65 -> -3580.4586 | ... AF29: =-AF17*$E$65 -> -6431.1829
B30: 23 | C30: (Dividends) | D30: ='Fin. Data'!D27 -> -4140 | E30: ='Fin. Data'!C27 -> -4532 | F30: ='Fin. Data'!B27 -> -4741 | G30: =-$D$64*G17 -> -3212.6855 | H30: =-$D$64*H17 -> -3512.5002 | I30: =-$D$64*I17 -> -3585.2481 | J30: =-$D$64*J17 -> -3932.3779 | K30: =-$E$64*K17 -> -3794.0345 | L30: =-$E$64*L17 -> -4054.3048 | M30: =-$E$64*M17 -> -4331.3068 | N30: =-$E$64*N17 -> -4567.4766 | O30: =-$E$64*O17 -> -4774.0569 | P30: =-$E$64*P17 -> -4979.1186 | Q30: =-$E$64*Q17 -> -5168.1793 | R30: =-$E$64*R17 -> -5347.4655 | ... AF30: =-$E$64*AF17 -> -9605.0623
B31: 24 | C31: Other financing flows | D31: =Inputs!D75 -> -1706 | E31: =Inputs!C75 -> -544 | F31: =Inputs!B75 -> 1447 | G31: =(1+G5)*AVERAGE(D31:F31) -> -277.035 | H31: =(1+H5)*AVERAGE(E31:G31) -> 216.256 | I31: =(1+I5)*AVERAGE(F31:H31) -> 479.67647 | J31: =(1+J5)*AVERAGE(G31:I31) -> 145.18455 | K31: =(1+K5)*AVERAGE(H31:J31) -> 291.98777 | L31: =(1+L5)*AVERAGE(I31:K31) -> 318.78687 | M31: =(1+M5)*AVERAGE(J31:L31) -> 263.26578 | N31: =(1+N5)*AVERAGE(K31:M31) -> 304.45741 | ... AF31: =(1+AF5)*AVERAGE(AC31:AE31) -> 361.46152
B32: 25 | C32: -Total Financing flows | D32: =D27+D28+D29+D30+D31 -> -6513 | E32: =E27+E28+E29+E30+E31 -> -18618 | F32: =F27+F28+F29+F30+F31 -> -16184 | G32: =G27+G28+G29+G30+G31 -> -10173.44 | H32: =H27+H28+H29+H30+H31 -> -8253.0697 | I32: =I27+I28+I29+I30+I31 -> -15200.161 | J32: =J27+J28+J29+J30+J31 -> -10878.055 | K32: =K27+K28+K29+K30+K31 -> -15865.461 | ... AF32: =AF27+AF28+AF29+AF30+AF31 -> -15264.676
A34: SUMMARY | B34: 26 | C34: Cash before shareholder returns | D34: =D22+D26+D27+D28+D31 -> 10851 | E34: =E22+E26+E27+E28+E31 -> 6286 | F34: =F22+F26+F27+F28+F31 -> 14158 | G34: =G22+G26+G27+G28+G31 -> 3205.9308 | H34: =H22+H26+H27+H28+H31 -> 7796.176 | I34: =I22+I26+I27+I28+I31 -> 2504.8397 | J34: =J22+J26+J27+J28+J31 -> 9978.4074 | K34: =K22+K26+K27+K28+K31 -> -2583.8626 | ... AF34: =AF22+AF26+AF27+AF28+AF31 -> 68776.704
B35: 27 | C35: Returns to shareholders | D35: =-1*(D29+D30) -> 4674 | E35: =-1*(E29+E30) -> 9204 | F35: =-1*(F29+F30) -> 18069 | G35: =-1*(G29+G30) -> 5363.7771 | H35: =-1*(H29+H30) -> 5864.3362 | I35: =-1*(I29+I30) -> 5985.7934 | J35: =-1*(J29+J30) -> 6565.348 | K35: =-1*(K29+K30) -> 6334.3751 | ... AF35: =-1*(AF29+AF30) -> 16036.245
B36: 28 | C36: Excess cash acumulation | D36: =D34-D35 -> 6177 | E36: =E34-E35 -> -2918 | F36: =F34-F35 -> -3911 | G36: =G34-G35 -> -2157.8463 | H36: =H34-H35 -> 1931.8398 | I36: =I34-I35 -> -3480.9536 | J36: =J34-J35 -> 3413.0595 | K36: =K34-K35 -> -8918.2377 | ... AF36: =AF34-AF35 -> 52740.459
A38: BALANCE SHEET | B38: 29 | C38: Intangible assets | D38: =114579-19825 -> 94754 | E38: =116491-23545 -> 92946 | F38: =114500-25900 -> 88600 | G38: =+F38+(-G10) -> 93433.511 | H38: =+G38+(-H10) -> 98530.71 | I38: =+H38+(-I10) -> 103905.98 | J38: =+I38+(-J10) -> 109574.5 | K38: =+J38+(-K10) -> 113957.48 | L38: =+K38+(-L10) -> 118515.78 | M38: =+L38+(-M10) -> 123256.41 | N38: =+M38+(-N10) -> 128186.67 | ... AF38: =+AE38+(-AF10) -> 259682.67 | AG38: =SUM(G38:AF38) -> 4308257.1
B39: 30 | C39: Accumulated amorization | D39: 19825 | E39: 23545 | F39: 25900 | G39: =F39-G10 -> 30733.511 | H39: =G39-H10 -> 35830.71 | I39: =H39-I10 -> 41205.983 | J39: =I39-J10 -> 46874.501 | K39: =J39-K10 -> 51257.481 | L39: =K39-L10 -> 55815.78 | M39: =L39-M10 -> 60556.411 | N39: =M39-N10 -> 65486.668 | ... AF39: =AE39-AF10 -> 196982.67 | AG39: =SUM(G39:AF39) -> 2678057.1
B40: 31 | C40: PPE+Right of use Assets | D40: =+Inputs!D33+Inputs!D34 -> 55779 | E40: =+Inputs!C33+Inputs!C34 -> 60514 | F40: =+Inputs!B33+Inputs!B34 -> 61482 | G40: =F40+(-G23) -> 72786.556 | H40: =G40+(-H23) -> 84502.92 | I40: =H40+(-I23) -> 96665.622 | J40: =I40+(-J23) -> 109311.94 | K40: =J40+(-K23) -> 122482.17 | L40: =K40+(-L23) -> 136219.98 | M40: =L40+(-M23) -> 150572.71 | N40: =M40+(-N23) -> 165571.33 | ... AF40: =AE40+(-AF23) -> 508701.93 | AG40: =SUM(G40:AF40) -> 6988962
B41: 32 | C41: Accumulated depreciation | D41: 54388 | E41: 55611 | F41: 56900 | G41: =F41-G9 -> 65786.892 | H41: =G41-H9 -> 76307.797 | I41: =H41-I9 -> 88522.239 | J41: =I41-J9 -> 102494.73 | K41: =J41-K9 -> 117798.4 | L41: =K41-L9 -> 134945.91 | M41: =L41-M9 -> 154016.71 | N41: =M41-N9 -> 175096.89 | ... AF41: =AE41-AF9 -> 974177.43 | AG41: =SUM(G41:AF41) -> 10378847
A43: CASH & DEBT & DISCOUNTING | B43: 33 | C43: Ending cash balance | D43: ='Fin. Data'!D39 -> 11740 | E43: =E36+D43 -> 8822 | F43: =F36+E43 -> 4911 | G43: =G36+F43 -> 2753.1537 | H43: =H36+G43 -> 4684.9935 | I43: =I36+H43 -> 1204.0399 | J43: =J36+I43 -> 4617.0993 | K43: =K36+J43 -> -4301.1384 | L43: =L36+K43 -> -4887.1889 | ... AF43: =AF36+AE43 -> 443126.84
B44: 34 | C44: Total Debt | D44: ='Fin. Data'!D58 -> 110240 | E44: ='Fin. Data'!C58 -> 105127 | F44: ='Fin. Data'!B58 -> 105022 | G44: =G12*3.4 -> 100489.37 | H44: =H12*3 -> 97884.382 | I44: =I12*2.5 -> 88190.339 | J44: =J12*2.2 -> 83732.447 | K44: =K12*1.9 -> 73909.373 | L44: =L12*Assum.!L22 -> 71024.104 | M44: =M12*Assum.!M22 -> 71706.444 | N44: =N12*Assum.!N22 -> 71948.652 | O44: =O12*Assum.!O22 -> 71444.444 | P44: =P12*Assum.!P22 -> 70333.792 | Q44: =Q12*Assum.!Q22 -> 68594.616 | R44: =R12*Assum.!R22 -> 66211.729 | S44: =S12*Assum.!S22 -> 63177.115 | ... AF44: =AF12*Assum.!AF22 -> 11019.12
B45: 35 | C45: Discount factor | F45: =1/((1+$F$50)^G50) -> 1 | G45: =1/((1+$F$50)^G49) -> 0.91533181 | H45: =1/((1+$F$50)^H49) -> 0.83783232 | I45: =1/((1+$F$50)^I49) -> 0.76689457 | J45: =1/((1+$F$50)^J49) -> 0.70196299 | K45: =1/((1+$F$50)^K49) -> 0.64252906 | L45: =1/((1+$F$50)^L49) -> 0.58812728 | M45: =1/((1+$F$50)^M49) -> 0.53833161 | N45: =1/((1+$F$50)^N49) -> 0.49275204 | ... AF45: =1/((1+$F$50)^AF49) -> 0.10024031
...

Sheet Fin. Data (Common Size)
A1: =Inputs!H3 -> #VALUE!
A2: =Inputs!G2 -> Figures in Millions of USD
A3: Results
B4: =OP!J19 -> 2022 | C4: =B4-1 -> 2021 | D4: =C4-1 -> 2020 | E4: =D4-1 -> 2019 | F4: =E4-1 -> 2018 | G4: =F4-1 -> 2017 | H4: =G4-1 -> 2016 | I4: =H4-1 -> 2015 | J4: =I4-1 -> 2014 | ... M4: =L4-1 -> 2011
A5: Net Sales | B5: =_xlfn.XLOOKUP($A5,Inputs!$A:$A,Inputs!B:B,,0) -> 121427 | C5: =_xlfn.XLOOKUP($A5,Inputs!$A:$A,Inputs!C:C,,0) -> 116385 | D5: =_xlfn.XLOOKUP($A5,Inputs!$A:$A,Inputs!D:D,,0) -> 103564 | E5: =_xlfn.XLOOKUP($A5,Inputs!$A:$A,Inputs!E:E,,0) -> 108942 | F5: =_xlfn.XLOOKUP($A5,Inputs!$A:$A,Inputs!F:F,,0) -> 94507 | G5: =_xlfn.XLOOKUP($A5,Inputs!$A:$A,Inputs!G:G,,0) -> 85029 | H5: =_xlfn.XLOOKUP($A5,Inputs!$A:$A,Inputs!H:H,,0) -> 80736 | I5: =_xlfn.XLOOKUP($A5,Inputs!$A:$A,Inputs!I:I,,0) -> 74510 | J5: =_xlfn.XLOOKUP($A5,Inputs!$A:$A,Inputs!J:J,,0) -> 68775 | K5: =_xlfn.XLOOKUP($A5,Inputs!$A:$A,Inputs!K:K,,0) -> 64657 | L5: =_xlfn.XLOOKUP($A5,Inputs!$A:$A,Inputs!L:L,,0) -> 62570 | M5: =_xlfn.XLOOKUP($A5,Inputs!$A:$A,Inputs!M:M,,0) -> 55842
A6: Growth vs. Previous year | B6: =IFERROR(B5/C5-1,"-") -> 0.043321734 | C6: =IFERROR(C5/D5-1,"-") -> 0.12379784 | D6: =IFERROR(D5/E5-1,"-") -> -0.049365718 | E6: =IFERROR(E5/F5-1,"-") -> 0.15274001 | F6: =IFERROR(F5/G5-1,"-") -> 0.11146785 | G6: =IFERROR(G5/H5-1,"-") -> 0.053173306 | H6: =IFERROR(H5/I5-1,"-") -> 0.083559254 | I6: =IFERROR(I5/J5-1,"-") -> 0.083387859 | ... M6: =IFERROR(M5/N5-1,"-") -> -
A7: Gross Profit | B7: =_xlfn.XLOOKUP($A7,Inputs!$A:$A,Inputs!B:B,,0) -> 36445 | C7: =_xlfn.XLOOKUP($A7,Inputs!$A:$A,Inputs!C:C,,0) -> 34621 | D7: =_xlfn.XLOOKUP($A7,Inputs!$A:$A,Inputs!D:D,,0) -> 30593 | E7: =_xlfn.XLOOKUP($A7,Inputs!$A:$A,Inputs!E:E,,0) -> 34078 | F7: =_xlfn.XLOOKUP($A7,Inputs!$A:$A,Inputs!F:F,,0) -> 29685 | G7: =_xlfn.XLOOKUP($A7,Inputs!$A:$A,Inputs!G:G,,0) -> 27706 | H7: =_xlfn.XLOOKUP($A7,Inputs!$A:$A,Inputs!H:H,,0) -> 26257 | I7: =_xlfn.XLOOKUP($A7,Inputs!$A:$A,Inputs!I:I,,0) -> 24678 | J7: =_xlfn.XLOOKUP($A7,Inputs!$A:$A,Inputs!J:J,,0) -> 22923 | K7: =_xlfn.XLOOKUP($A7,Inputs!$A:$A,Inputs!K:K,,0) -> 21434 | L7: =_xlfn.XLOOKUP($A7,Inputs!$A:$A,Inputs!L:L,,0) -> 19977 | M7: =_xlfn.XLOOKUP($A7,Inputs!$A:$A,Inputs!M:M,,0) -> 24440
A8: % over sales | B8: =IFERROR(B7/B$5,"-") -> 0.30013918 | C8: =IFERROR(C7/C$5,"-") -> 0.29746961 | D8: =IFERROR(D7/D$5,"-") -> 0.29540188 | E8: =IFERROR(E7/E$5,"-") -> 0.31280865 | F8: =IFERROR(F7/F$5,"-") -> 0.31410372 | G8: =IFERROR(G7/G$5,"-") -> 0.32584177 | H8: =IFERROR(H7/H$5,"-") -> 0.32522047 | I8: =IFERROR(I7/I$5,"-") -> 0.33120387 | ... M8: =IFERROR(M7/M$5,"-") -> 0.43766341
A9: Operating expenses | B9: =B5-B11 -> 107386 | C9: =C5-C11 -> 95568 | D9: =D5-D11 -> 86071 | E9: =E5-E11 -> 87817 | F9: =F5-F11 -> 75498 | G9: =G5-G11 -> 67011 | H9: =H5-H11 -> 63905 | I9: =I5-I11 -> 58512 | ... M9: =M5-M11 -> 45121
A10: % over sales | B10: =IFERROR(B9/B$5,"-") -> 0.88436674 | C10: =IFERROR(C9/C$5,"-") -> 0.82113674 | D10: =IFERROR(D9/D$5,"-") -> 0.83108995 | E10: =IFERROR(E9/E$5,"-") -> 0.80608948 | F10: =IFERROR(F9/F$5,"-") -> 0.79886146 | G10: =IFERROR(G9/G$5,"-") -> 0.78809583 | H10: =IFERROR(H9/H$5,"-") -> 0.79153042 | I10: =IFERROR(I9/I$5,"-") -> 0.78529057 | ... M10: =IFERROR(M9/M$5,"-") -> 0.80801189
A11: Operating Income | B11: =_xlfn.XLOOKUP($A11,Inputs!$A:$A,Inputs!B:B,,0) -> 14041 | C11: =_xlfn.XLOOKUP($A11,Inputs!$A:$A,Inputs!C:C,,0) -> 20817 | D11: =_xlfn.XLOOKUP($A11,Inputs!$A:$A,Inputs!D:D,,0) -> 17493 | E11: =_xlfn.XLOOKUP($A11,Inputs!$A:$A,Inputs!E:E,,0) -> 21125 | F11: =_xlfn.XLOOKUP($A11,Inputs!$A:$A,Inputs!F:F,,0) -> 19009 | G11: =_xlfn.XLOOKUP($A11,Inputs!$A:$A,Inputs!G:G,,0) -> 18018 | H11: =_xlfn.XLOOKUP($A11,Inputs!$A:$A,Inputs!H:H,,0) -> 16831 | I11: =_xlfn.XLOOKUP($A11,Inputs!$A:$A,Inputs!I:I,,0) -> 15998 | J11: =_xlfn.XLOOKUP($A11,Inputs!$A:$A,Inputs!J:J,,0) -> 14904 | K11: =_xlfn.XLOOKUP($A11,Inputs!$A:$A,Inputs!K:K,,0) -> 13563 | L11: =_xlfn.XLOOKUP($A11,Inputs!$A:$A,Inputs!L:L,,0) -> 12179 | M11: =_xlfn.XLOOKUP($A11,Inputs!$A:$A,Inputs!M:M,,0) -> 10721
A12: % over sales | B12: =IFERROR(B11/B$5,"-") -> 0.11563326 | C12: =IFERROR(C11/C$5,"-") -> 0.17886326 | D12: =IFERROR(D11/D$5,"-") -> 0.16891005 | E12: =IFERROR(E11/E$5,"-") -> 0.19391052 | F12: =IFERROR(F11/F$5,"-") -> 0.20113854 | G12: =IFERROR(G11/G$5,"-") -> 0.21190417 | H12: =IFERROR(H11/H$5,"-") -> 0.20846958 | I12: =IFERROR(I11/I$5,"-") -> 0.21470943 | ... M12: =IFERROR(M11/M$5,"-") -> 0.19198811
A13: Growth vs. Previous year | B13: =IFERROR(B12/C12-1,"-") -> -0.35351025 | C13: =IFERROR(C12/D12-1,"-") -> 0.058926096 | D13: =IFERROR(D12/E12-1,"-") -> -0.12892789 | E13: =IFERROR(E12/F12-1,"-") -> -0.035935524 | F13: =IFERROR(F12/G12-1,"-") -> -0.050804256 | G13: =IFERROR(G12/H12-1,"-") -> 0.016475277 | H13: =IFERROR(H12/I12-1,"-") -> -0.029061858 | I13: =IFERROR(I12/J12-1,"-") -> -0.0092162245 | ... M13: =IFERROR(M12/N12-1,"-") -> -
A14: Net Financial Cost | B14: =_xlfn.XLOOKUP($A14,Inputs!$A:$A,Inputs!B:B,,0) -> -3896 | C14: =_xlfn.XLOOKUP($A14,Inputs!$A:$A,Inputs!C:C,,0) -> -4281 | D14: =_xlfn.XLOOKUP($A14,Inputs!$A:$A,Inputs!D:D,,0) -> -4588 | E14: =_xlfn.XLOOKUP($A14,Inputs!$A:$A,Inputs!E:E,,0) -> -4567 | F14: =_xlfn.XLOOKUP($A14,Inputs!$A:$A,Inputs!F:F,,0) -> -3542 | G14: =_xlfn.XLOOKUP($A14,Inputs!$A:$A,Inputs!G:G,,0) -> -3086 | H14: =_xlfn.XLOOKUP($A14,Inputs!$A:$A,Inputs!H:H,,0) -> -2942 | I14: =_xlfn.XLOOKUP($A14,Inputs!$A:$A,Inputs!I:I,,0) -> -2702 | J14: =_xlfn.XLOOKUP($A14,Inputs!$A:$A,Inputs!J:J,,0) -> -2617 | K14: =_xlfn.XLOOKUP($A14,Inputs!$A:$A,Inputs!K:K,,0) -> -2574 | L14: =_xlfn.XLOOKUP($A14,Inputs!$A:$A,Inputs!L:L,,0) -> -2521 | M14: =_xlfn.XLOOKUP($A14,Inputs!$A:$A,Inputs!M:M,,0) -> -2505
A15: Other Expenses (Revenues) | B15: =_xlfn.XLOOKUP($A15,Inputs!$A:$A,Inputs!B:B,,0) -> -861 | C15: =_xlfn.XLOOKUP($A15,Inputs!$A:$A,Inputs!C:C,,0) -> 2556 | D15: =_xlfn.XLOOKUP($A15,Inputs!$A:$A,Inputs!D:D,,0) -> 1160 | E15: =_xlfn.XLOOKUP($A15,Inputs!$A:$A,Inputs!E:E,,0) -> 438 | F15: =_xlfn.XLOOKUP($A15,Inputs!$A:$A,Inputs!F:F,,0) -> -225 | G15: =_xlfn.XLOOKUP($A15,Inputs!$A:$A,Inputs!G:G,,0) -> 421 | H15: =_xlfn.XLOOKUP($A15,Inputs!$A:$A,Inputs!H:H,,0) -> 437 | I15: =_xlfn.XLOOKUP($A15,Inputs!$A:$A,Inputs!I:I,,0) -> 76 | J15: =_xlfn.XLOOKUP($A15,Inputs!$A:$A,Inputs!J:J,,0) -> 178 | K15: =_xlfn.XLOOKUP($A15,Inputs!$A:$A,Inputs!K:K,,0) -> 126 | L15: =_xlfn.XLOOKUP($A15,Inputs!$A:$A,Inputs!L:L,,0) -> 1951 | M15: =_xlfn.XLOOKUP($A15,Inputs!$A:$A,Inputs!M:M,,0) -> -9
