Workbook
Name Sectors: '[1]Sector Impact'!$K$4:$K$16
Name Sectors: 'Sector Impact'!$K$4:$K$16

Sheet OP
B2: 45138 | C2: Team 2 | D2: 8th August | E2: =Inputs!H3 -> Daikin Industries,Ltd. (6367.T) | L2: TSE | M2: SIC:
D3: COMPANY DESCRIPTION | H3: CEO & BOARD OF DIRECTORS
D4: Daikin is a leading Japanese company specializing in HVAC (Heating, Ventilation, and Air Conditioning) systems and refrigerants. Established in 1924, Daikin has become a global industry leader known for its innovative technologies and commitment to environmental sustainability. With a strong focus on research and development, Daikin continues to provide cutting-edge cooling solutions and maintain a prominent presence in the international market. | H4: Name | I4: Gender | J4: Age | K4: Tenure | L4: Executive? | M4: Other roles
H5: Noriyuki Inoue | I5: M | J5: 88 | K5: 9 | L5: Y- Chairman of the Board | M5: Chairman Daikin Foundation for Contemporary Arts and Kansai Philharmonic Orchestra
H6: Masanori Togawa | I6: M | J6: 74 | K6: 9 | L6: Y- President and CEO | M6: N/A
H7: Tatsuo Kawada | I7: M | J7: 83 | K7: 7 | L7: N | M7: Chairman and CEO of Seiren Co., Ltd.; External Director of Hokuriku Electric Power Company
H8: Akiji Makino | I8: M | J8: 82 | K8: 7 | L8: N | M8: Chairman and CEO of Iwatani Corporation; Chairman of the Board of Iwatani Industrial Gases Corp
H9: Shingo Torii | I9: M | J9: 70 | K9: 3 | L9: N | M9: Director and Vice Chairman of the Board of Suntory Holdings Limited
H10: Yuko Arai | I10: F | J10: 62 | K10: 2 | L10: N | M10: Senior Advisor of ANA Akindo Co., Ltd.; Outside Director of Aichi Steel Corp
H11: Ken Tayano | I11: M | J11: 76 | K11: 9 | L11: Y | M11: Chairman of the Board and President of Daikin (China) Investment Co., Ltd.
H12: Masatsugu Minaka | I12: M | J12: 70 | K12: 12 | L12: Y | M12: Chairman of the Board of Daikin Europe N.V
H13: Takashi Matsuzaki | I13: M | J13: 65 | K13: 3 | L13: Y | M13: N/A
B14: JPY MILLIONS | H14: Kanwal Jeet Jawa | I14: M | J14: 64 | K14: 4 | L14: Y | M14: Managing Director and CEO of Daikin Airconditioning India Pvt. Ltd
B15: COMPANY OVERVIEW
B16: Stock | D16: Liquidity and Solvency | F16: Segments | I16: Profitability (2022) | L16: Multiples
B17: Last Price | C17: 25025 | D17: Total Assets | E17: =_xlfn.XLOOKUP(D17,'Fin. Data'!A:A,'Fin. Data'!B:B,,0) -> 4303682 | F17: Regions | H17: % Sales | I17: Reporting Year | J17: 2022 | L17: Float | M17: =2.68/2.93 -> 0.91467577
B18: Outstanding Shares | C18: 292680000 | D18: Total Liabilities | E18: =_xlfn.XLOOKUP(D18,'Fin. Data'!A:A,'Fin. Data'!B:B,,0) -> 2065534 | F18: =Segments!C5 -> Japan | H18: =Segments!B5 -> 0.17182367 | I18: End of Year | J18: 31 March 2023 | L18: Insiders Own | M18: 0
B19: Market Cap. | C19: =C17*C18/1000000 -> 7324317 | D19: Cash/Share | E19: =_xlfn.XLOOKUP("Cash & Eq.",'Fin. Data'!A:A,'Fin. Data'!B:B,,0)*1000000/C18 -> 2110.3697 | F19: =Segments!C6 -> U.S. | H19: =Segments!B6 -> 0.32022948 | I19: EBITDA | K19: =_xlfn.XLOOKUP(I19,'Fin. Data'!A:A,'Fin. Data'!B:B,,0) -> 537584 | L19: b (Yahoo) | M19: 0.9
B20: +Total Debt | C20: ='Fin. Data'!B58 -> 813766 | D20: EBIDTA/Net Financial Cost (NFC) | E20: ='Fin. Data (Common Size)'!B19/(-'Fin. Data (Common Size)'!B14) -> 61.578923 | F20: =Segments!C9 -> Europe | H20: =Segments!B9 -> 0.17800765 | I20: Depreciation & Amortization | K20: =_xlfn.XLOOKUP(I20,'Fin. Data'!A:A,'Fin. Data'!B:B,,0) -> 182224 | L20: Score (Moodys) | M20: A2
B21: -Cash | C21: ='Fin. Data'!B39 -> 617663 | D21: Debt/EBITDA | E21: =_xlfn.XLOOKUP("Total Debt",'Fin. Data'!A:A,'Fin. Data'!B:B,,0)/_xlfn.XLOOKUP("EBITDA",'Fin. Data'!A:A,'Fin. Data'!B:B,,0) -> 1.5137467 | F21: =Segments!C10 -> Asian and Oceania | H21: =Segments!B10 -> 0.14577092 | I21: EBIT | K21: =_xlfn.XLOOKUP(I21,'Fin. Data'!A:A,'Fin. Data'!B:B,,0) -> 355360 | L21: Price/Book Value | M21: =IFERROR((C17*C18/(E17-E18))/1000000,"") -> 3.27249
B22: =Enterprise Value | C22: =C19+C20-C21 -> 7520420 | D22: "Others Assets"/Asset | E22: =_xlfn.XLOOKUP("Other Assets",'Fin. Data'!A:A,'Fin. Data'!B:B,,0)/_xlfn.XLOOKUP("Total Assets",'Fin. Data'!A:A,'Fin. Data'!B:B,,0) -> 0.21323509 | F22: =Segments!C11 -> China | H22: =Segments!B11 -> 0.12269915 | I22: Net Income | K22: =_xlfn.XLOOKUP(I22,'Fin. Data'!A:A,'Fin. Data'!B:B,,0) -> 257755 | L22: NCF(3y avg)/Asset | M22: =IFERROR(K28/E17,"") -> -0.00051088037
B23: Holdings (nac/int'l) | C23: - | D23: Debt/Assets | E23: =_xlfn.XLOOKUP(D23,'Fin. Data'!A:A,'Fin. Data'!B:B,,0) -> 0.189086 | F23: =Segments!C12 -> Other | H23: =Segments!B12 -> 0.061469127 | I23: EPS | K23: =1000000*K22/C18 -> 880.67172 | L23: Price/Net Inc. (3y avg) | M23: =IFERROR(C19/K27,"") -> 34.783013
B24: t liq. (Holdings/Vol.) | C24: - | D24: EBITDA Margin (average) | E24: =AVERAGE(_xlfn.XLOOKUP("EBITDA Margin",'Fin. Data'!A:A,'Fin. Data'!B:D,,0)) -> 0.14402521 | F24: Categories | H24: % Sales | I24: ROA | K24: =K22/E17 -> 0.059891739 | L24: EV/Asset | M24: =IFERROR(C22/E17,"") -> 1.7474386
B25: % Short | C25: N/A | D25: Operating Margin (average) | E25: =AVERAGE(_xlfn.XLOOKUP("Operating Margin",'Fin. Data'!A:A,'Fin. Data'!B:D,,0)) -> 0.095731488 | F25: =Segments!C18 -> Air Conditioning | H25: =Segments!B18 -> 0.91218284 | I25: ROIC | K25: =K22/(E17-(E18-C20)) -> 0.084456836 | L25: EV/Ebidta (3y average) | M25: =IFERROR(C22/K26,"") -> 16.500737
B26: Traffic ESG | D26: Net Income Margin (average) | E26: =AVERAGE(_xlfn.XLOOKUP("Net Income Margin",'Fin. Data'!A:A,'Fin. Data'!B:D,,0)) -> 0.065808676 | F26: =Segments!C19 -> Chemicals | H26: =Segments!B19 -> 0.071565775 | I26: EBITDA (3y average) | K26: =AVERAGE(_xlfn.XLOOKUP("EBITDA",'Fin. Data'!A:A,'Fin. Data'!B:D,,0)) -> 455762.67 | L26: Price/NCF (3y average) | M26: =IFERROR(C19/K28,"") -> -3331.2539
B27: E | F27: =Segments!C20 -> Others | H27: =Segments!B20 -> 0.022603155 | I27: Net Income (3y average) | K27: =AVERAGE(_xlfn.XLOOKUP("Net Income",'Fin. Data'!A:A,'Fin. Data'!B:D,,0)) -> 210571.67 | L27: Bonds 1,3,5a (USD) | M27: -
B28: S | D28: Net Financial Cost/Avg Net Debt | E28: =-_xlfn.XLOOKUP("Net Financial Cost",'Fin. Data'!A:A,'Fin. Data'!B:B,,0)/AVERAGE(_xlfn.XLOOKUP("Net Debt",'Fin. Data'!A:A,'Fin. Data'!B:D,,0)) -> -0.11778727 | F28: =Segments!C21 -> Eliminations and Corporate | H28: =Segments!B21 -> -0.006351769 | I28: NFC (3y average) | K28: =AVERAGE(_xlfn.XLOOKUP("Net Financial Cost",'Fin. Data'!A:A,'Fin. Data'!B:D,,0)) -> -2198.6667 | L28: Div+Rep.(3y avg)/Price | M28: =-IFERROR(SUM(E51:E53)/(3*C19),"") -> 0.0071877009
B29: G | L29: Div. Yield | M29: =-IFERROR(L52/C19,"") -> 0.0083923184
B30: INVESTMENT THESIS
B31: Pillars of Recommendation | H31: Recommendation | I31: Valuation Assumptions
B32: Pillar | C32: Explanation | H32: HOLD | I32: CHECK DCF
B33: Market Leadership | C33: Daikin is the world's biggest AC manufacturer (segment represents 91% of revenue FY 2022) and has a very consolidated position with an envious 12% global market share
B34: Energy transition | C34: Daikin is specially well positioned to seize the added value generated by switching from higher polluting items to more eco-friendly ones. Specially in the HC segment (Within AC) which is forecasted to grow by a considerable amount in the near future
B35: AI and Machine Learning | C35: Daikin is already developing several AI and machine learning solutions to some problems reported by consumer and in-house feedback and since it has better and with more value added products and spends a bigger percentage of revenue in R&D than the average of it's peers, it's well positioned to take advantage of the current and following AI booms
B36: Fusion 25 | C36: Daikin's Fusion 25 company strategy is showing incredible results surpassing every forecast and strenghtenning Daikin's reputation for delivering results. Plus it has more objectives that we feel have a very good impact on the companies' outlook
B37: Risks of Investment | H37: Price Target | I37: Valuation
B38: Risk | C38: Explanation | H38: =DCF!D75 -> 13800.241 | I38: Discount Rate | J38: =DCF!F50 -> 0.0948598 | L38: Upside | M38: =DCF!D74 -> -0.4485418
B39: Low brand recognition | C39: Daikin's low brand recognition means that they lose customers run to peers that are more focused on marketing on the long
B40: Higher cost products compared to peers | C40: Daikin's higher prices reflect their superior products. However, because the AC market is not commonly known as a "premium items" market, people have a hard time justifying choosing a Daikin product over, say, a Carrier one.
B41: Hard time penetrating in new markets | C41: Because of the previous two risks of investment, Daikin has had a hard time penetrating new markets. Most notably the North American one. They solved this problem through several acquisitions and extensive Capex and now the US market is one of their biggest growth drivers. However the difficulty Daikin has in entering new markets should be noted. Especially when they plan to do so, for example in India.
...

Sheet Segments
B2: ="Regions "&"("&OP!$J$17&")" -> Regions (2022) | Q2: Products
D3: Nominal value | K3: YoY Growth
B4: Weight | C4: Region | D4: =OP!J17 -> 2022 | E4: =D4-1 -> 2021 | F4: =E4-1 -> 2020 | G4: =F4-1 -> 2019 | H4: =G4-1 -> 2018 | I4: =H4-1 -> 2017 | K4: =OP!J17 -> 2022 | L4: =K4-1 -> 2021 | M4: =L4-1 -> 2020 | N4: =M4-1 -> 2019 | O4: =N4-1 -> 2018 | P4: =O4-1 -> 2017
B5: =IFERROR(D5/$D$13,"") -> 0.17182367 | C5: Japan | D5: 684129 | E5: 638447 | F5: 585573 | G5: 596978 | H5: 585106 | I5: 542725 | K5: =(D5-E5)/E5 -> 0.07155175 | L5: =(E5-F5)/F5 -> 0.090294464 | M5: =(F5-G5)/G5 -> -0.019104557 | N5: =(G5-H5)/H5 -> 0.020290341 | O5: =(H5-I5)/I5 -> 0.078089272 | P5: =(I5-518453)/518453 -> 0.046816201
B6: =IFERROR(D6/$D$13,"") -> 0.32022948 | C6: U.S. | D6: 1275018 | E6: 840455 | F6: 641295 | G6: 666305 | H6: 625041 | I6: 551819 | K6: =(D6-E6)/E6 -> 0.51705683 | L6: =(E6-F6)/F6 -> 0.3105591 | M6: =(F6-G6)/G6 -> -0.037535363 | N6: =(G6-H6)/H6 -> 0.066018069 | O6: =(H6-I6)/I6 -> 0.13269206 | P6: =(I6-503489)/503489 -> 0.095990181
B7: =IFERROR(D7/$D$13,"") -> 0 | K7: =(D7-E7)/E7 -> #DIV/0! | L7: =(E7-F7)/F7 -> #DIV/0! | M7: =(F7-G7)/G7 -> #DIV/0! | N7: =(G7-H7)/H7 -> #DIV/0! | O7: =(H7-I7)/I7 -> #DIV/0!
B8: =IFERROR(D8/$D$13,"") -> 0 | K8: =(D8-E8)/E8 -> #DIV/0! | L8: =(E8-F8)/F8 -> #DIV/0! | M8: =(F8-G8)/G8 -> #DIV/0! | N8: =(G8-H8)/H8 -> #DIV/0! | O8: =(H8-I8)/I8 -> #DIV/0!
B9: =IFERROR(D9/$D$13,"") -> 0.17800765 | C9: Europe | D9: 708751 | E9: 553214 | F9: 417225 | G9: 405610 | H9: 366670 | I9: 332955 | K9: =(D9-E9)/E9 -> 0.2811516 | L9: =(E9-F9)/F9 -> 0.32593684 | M9: =(F9-G9)/G9 -> 0.028635882 | N9: =(G9-H9)/H9 -> 0.10619903 | O9: =(H9-I9)/I9 -> 0.10125993 | P9: =(I9-274054)/274054 -> 0.2149248
B10: =IFERROR(D10/$D$13,"") -> 0.14577092 | C10: Asian and Oceania | D10: 580398 | E10: 426107 | F10: 351044 | G10: 395461 | H10: 387092 | I10: 349189 | K10: =(D10-E10)/E10 -> 0.3620945 | L10: =(E10-F10)/F10 -> 0.2138279 | M10: =(F10-G10)/G10 -> -0.11231702 | N10: =(G10-H10)/H10 -> 0.021620183 | O10: =(H10-I10)/I10 -> 0.1085458 | P10: =(I10-303416)/303416 -> 0.15085889
B11: =IFERROR(D11/$D$13,"") -> 0.12269915 | C11: China | D11: 488536 | E11: 478121 | F11: 369818 | G11: 341284 | H11: 379628 | I11: 381665 | K11: =(D11-E11)/E11 -> 0.021783189 | L11: =(E11-F11)/F11 -> 0.29285486 | M11: =(F11-G11)/G11 -> 0.083607787 | N11: =(G11-H11)/H11 -> -0.10100414 | O11: =(H11-I11)/I11 -> -0.0053371412 | P11: =(I11-329247)/329247 -> 0.1592057
B12: =IFERROR(D12/$D$13,"") -> 0.061469127 | C12: Other | D12: 244744 | E12: 172758 | F12: 128429 | G12: 144665 | H12: 137570 | I12: 132204 | K12: =(D12-E12)/E12 -> 0.41668693 | L12: =(E12-F12)/F12 -> 0.34516348 | M12: =(F12-G12)/G12 -> -0.11223171 | N12: =(G12-H12)/H12 -> 0.051573744 | O12: =(H12-I12)/I12 -> 0.040588787 | P12: =(I12-115307)/115307 -> 0.14653924
B13: =SUM(B5:B12) -> 1 | C13: TOTAL | D13: =SUM(D5:D12) -> 3981576 | E13: =SUM(E5:E12) -> 3109102 | F13: =SUM(F5:F12) -> 2493384 | G13: =SUM(G5:G12) -> 2550303 | H13: =SUM(H5:H12) -> 2481107 | I13: =SUM(I5:I12) -> 2290557 | K13: =(D13-E13)/E13 -> 0.28061929 | L13: =(E13-F13)/F13 -> 0.2469407 | M13: =(F13-G13)/G13 -> -0.022318525 | N13: =(G13-H13)/H13 -> 0.027889164 | O13: =(H13-I13)/I13 -> 0.083189373 | P13: 0.037
B15: ="Categories "&"("&OP!$J$17&")" -> Categories (2022)
D16: Nominal value | K16: YoY Growth
B17: Weight | C17: Category | D17: =OP!J17 -> 2022 | E17: =D17-1 -> 2021 | F17: =E17-1 -> 2020 | G17: =F17-1 -> 2019 | H17: =G17-1 -> 2018 | I17: =H17-1 -> 2017 | K17: =OP!J17 -> 2022 | L17: =K17-1 -> 2021 | M17: =L17-1 -> 2020 | N17: =M17-1 -> 2019 | O17: =N17-1 -> 2018 | P17: =O17-1 -> 2017
B18: =IFERROR(D18/$D$22,"") -> 0.91218284 | C18: Air Conditioning | D18: 3631918 | E18: 2830662 | F18: 2275497 | G18: 2309986 | H18: 2222886 | I18: 2053469 | K18: =(D18-E18)/E18 -> 0.28306311 | L18: =(E18-F18)/F18 -> 0.24397527 | M18: =(F18-G18)/G18 -> -0.014930394 | N18: =(G18-H18)/H18 -> 0.039183296 | O18: =(H18-I18)/I18 -> 0.082502828 | P18: =(I18-1835764)/1835764 -> 0.11859095
B19: =IFERROR(D19/$D$22,"") -> 0.071565775 | C19: Chemicals | D19: 284944 | E19: 224643 | F19: 173782 | G19: 193733 | H19: 218913 | I19: 198535 | K19: =(D19-E19)/E19 -> 0.26843035 | L19: =(E19-F19)/F19 -> 0.29267128 | M19: =(F19-G19)/G19 -> -0.10298194 | N19: =(G19-H19)/H19 -> -0.11502286 | O19: =(H19-I19)/I19 -> 0.10264185 | P19: =(I19-169019)/169019 -> 0.17463125
B20: =IFERROR(D20/$D$22,"") -> 0.022603155 | C20: Others | D20: 89996 | E20: 69357 | F20: 56281 | G20: 62002 | H20: 58791 | I20: 54957 | K20: =(D20-E20)/E20 -> 0.29757631 | L20: =(E20-F20)/F20 -> 0.23233418 | M20: =(F20-G20)/G20 -> -0.092271217 | N20: =(G20-H20)/H20 -> 0.054617203 | O20: =(H20-I20)/I20 -> 0.069763633 | P20: =(I20-52357)/52357 -> 0.049659071
B21: =IFERROR(D21/$D$22,"") -> -0.006351769 | C21: Eliminations and Corporate | D21: -25290 | E21: -15566 | F21: -12175 | G21: -15418 | H21: -19483 | I21: -16401 | K21: =(D21-E21)/E21 -> 0.62469485 | L21: =(E21-F21)/F21 -> 0.27852156 | M21: =(F21-G21)/G21 -> -0.21033857 | N21: =(G21-H21)/H21 -> -0.20864343 | O21: =(H21-I21)/I21 -> 0.18791537 | P21: =(I21--13173)/-13173 -> 0.24504669
B22: =SUM(B18:B21) -> 1 | C22: TOTAL | D22: =SUM(D18:D21) -> 3981568 | E22: =SUM(E18:E21) -> 3109096 | F22: =SUM(F18:F21) -> 2493385 | G22: =SUM(G18:G21) -> 2550303 | H22: =SUM(H18:H21) -> 2481107 | I22: =SUM(I18:I21) -> 2290560 | K22: =(D22-E22)/E22 -> 0.28061919 | L22: =(E22-F22)/F22 -> 0.2469378 | M22: =(F22-G22)/G22 -> -0.022318132 | N22: =(G22-H22)/H22 -> 0.027889164 | O22: =(H22-I22)/I22 -> 0.083187954 | P22: 0.037
B24: Categories | D24: Description | I24: Graphs
B25: Air Conditioning | D25: Engaged in the manufacture (including installation work) and sale of air-conditioning and refrigeration equipment
B26: Chemicals | D26: Engaged in the manufacture and sale of chemicals
B28: Others | D28: “Others” segment is a business segment not included in reported segments. It includes the oil hydraulic equipment business, the defense systems business, and the electronics business
B29: Eliminations and Corporate | D29: Intersegment revenue
B32: Industry | J32: Graphs (Industry Forecasts)
B33: Drivers | D33: Description | J33: Forecast of the global heating & cooling market revenue from 2018 to 2028(in billion U.S. dollars)
B34: Weather and climate patterns- Global Warming | D34: Long-term shifts in temperatures and weather patterns leads to higher demand in HVAC
B35: Population growth and urbanization | D35: Population growth lead to higher demand for housing and infrastructure. With more people living and working in urban areas, there is a greater need for HVAC installations in various buildings, such as apartments, offices, schools, hospitals, and shopping malls
B36: Energy transition- Government policies and regulations | D36: Sustainable heating, cooling and refrigeration solutions. Ex. Carbon pricing mechanisms or carbon taxes to put a cost on carbon emissions. This encourages businesses and consumers to choose energy-efficient HVAC options to minimize their carbon footprint and reduce their tax burden.
B37: Sales forecast
B38: Source | D38: Market Growth CGAR | G38: Period
B39: Statista | D39: 0.0308 | G39: 2023-2028
B40: Grand View Research | D40: 0.062 | G40: 2021-2028
B41: Mordor Intelligence | D41: 0.0608 | G41: 2023-2028
B42: GlobeNewswire | D42: 0.06 | G42: 2022-2032
B43: Company's Strategy / Extra Notes
B44: FUSION 25
S48: B2B or B2C ?
T49: Japan | U49: U.S. | V49: Europe | W49: Asia and Oceania | X49: China | Y49: Total
...

Sheet Acuerdo
A1: Invertir
A2: NO invertir
A3: Mantener sin elevar posición
A4: Mantener (y seguir comprando)
A5: Liquidar
A6: PENDIENTE

Sheet Peers
B1: Peer Logo | C1: Peer Name | D1: Description
C2: =D7 -> #VALUE! | D2: {=_FV(C2,"Description")} -> Johnson Controls International plc offers smart, healthy and sustainable buildings, serving a range of customers. It operates through four segments: Building Solutions North America, Building Solutions EMEA/LA, Building Solutions Asia Pacific, and Global Products. Its Building Solutions North America, Building Solutions EMEA/LA, and Building Solutions Asia Pacific segments design, sell, install, and services heating, ventilation and air conditioning (HVAC), controls, building management, refrigeration, integrated electronic security, integrated fire detection and suppression systems, and provides technical services. Its Global Products segment designs, manufactures and sells HVAC equipment, controls software and software services for residential and commercial applications to commercial, industrial, retail, residential, small business, institutional and governmental customers worldwide. Global Products segment also designs, manufactures and sells refrigeration equipment and controls.
C3: =E7 -> #VALUE! | D3: {=_FV(C3,"Description")} -> Carrier Global Corporation is engaged in offering intelligent climate and energy solutions with a focus on providing differentiated, digitally enabled lifecycle solutions. The Company operates through three segments: HVAC, Refrigeration, and Fire & Security. Its HVAC segment provides products, controls, services and solutions to meet the heating, cooling and ventilation needs of residential and commercial customers. Its Refrigeration segment includes transport refrigeration and monitoring products, services and digital solutions for trucks, trailers, shipping containers, and intermodal and rail. Its Fire & Security segment provides a range of residential, commercial and industrial technologies designed to help protect people and property. This segment offers products, such as fire, flame, gas, smoke and carbon monoxide detection, portable fire extinguishers, and others. The Company's portfolio includes brands, such as Carrier, Carrier Transicold, Viessmann, and others.
C4: =F7 -> #VALUE! | D4: {=_FV(C4,"Description")} -> Trane Technologies PLC is a global climate innovator. Through its brands, such as Trane and Thermo King, and its portfolio of products and services, it brings climate solutions to buildings, homes, and transportation. Its segments include the Americas, EMEA and Asia Pacific. Its Americas segment serves customers in North America and Latin America and includes commercial heating and cooling systems, building controls, and energy services and solutions; residential heating and cooling; and transport refrigeration systems and solutions. Its EMEA segment serves customers in the Europe, Middle East and Africa region and includes heating and cooling systems, services and solutions for commercial buildings, and transport refrigeration systems and solutions. Its Asia Pacific segment serves customers throughout the Asia Pacific region and includes heating and cooling systems and solutions. It also offers cloud-based connected workplace and enterprise asset management products and solutions.
C5: =G7 -> #VALUE! | D5: {=_FV(C5,"Description")} -> Lennox International Inc. is a provider of climate control solutions. The Company designs, manufactures and markets a range of products for the heating, ventilation, air conditioning and refrigeration (HVACR) markets. It operates through three segments: Home Comfort Solutions, Building Climate Solutions, and Corporate and Other. Home Comfort Solutions segment manufacture and market a broad range of furnaces, air conditioners, heat pumps, packaged heating and cooling systems, indoor air quality equipment, comfort control products, replacement parts and supplies and related products. Building Climate Solutions segment manufacture and sell unitary heating and air conditioning equipment, applied systems, controls, installation and service of commercial heating and cooling equipment, variable refrigerant flow commercial products, curb, curb adapters, drop box diffusers, HVAC recycling and salvage service, condensing units, unit coolers, fluid coolers, air cooled condensers, and others.
B7: In Millions JPY | C7: =OP!E2 -> Daikin Industries,Ltd. (6367.T) | D7: #VALUE! | E7: #VALUE! | F7: #VALUE! | G7: #VALUE! | H7: AVERAGE
B8: Company Info | H8: =IFERROR(AVERAGE(C8:G8),"")
B9: Market Cap | C9: =OP!C19 -> 7324317 | D9: 6697803.4 | E9: 6971591.5 | F9: 6388924.2 | G9: 1978040 | H9: =IFERROR(AVERAGE(C9:G9),"") -> 5872135.2
B10: Net Sales (current) | C10: =C54 -> 3981578 | D10: =D54 -> 3464289.3 | E10: =E54 -> 3148268.4 | F10: =F54 -> 2164367.6 | G10: =G54 -> 692443 | H10: =IFERROR(AVERAGE(C10:G10),"") -> 2690189.3
B11: Profitability | H11: =IFERROR(AVERAGE(C11:G11),"")
B12: Sales Growth (ttm) | C12: =C54/C53-1 -> 0.28061829 | D12: =D54/D53-1 -> -0.053866832 | E12: =E54/E53-1 -> 0.17451626 | F12: =F54/F53-1 -> 0.031099766 | G12: =G54/G53-1 -> 0.11803191 | H12: =IFERROR(AVERAGE(C12:G12),"") -> 0.11007988
B13: Sales Growth (36m) | C13: =C54/C52-1 -> 0.5612164 | D13: =D54/D52-1 -> 0.47156481 | E13: =E54/E52-1 -> 0.74663967 | F13: =F54/F52-1 -> 0.68296099 | G13: =G54/G52-1 -> 0.84528939 | H13: =IFERROR(AVERAGE(C13:G13),"") -> 0.66153425
B14: Operating Margin | C14: =C57/C54 -> 0.091645323 | D14: =D57/D54 -> 0.096424337 | E14: =E57/E54 -> 0.097383247 | F14: =F57/F54 -> 0.15012884 | G14: =G57/G54 -> 0.15147731 | H14: =IFERROR(AVERAGE(C14:G14),"") -> 0.11741181 | K14: Best value
B15: Net Income Margin | C15: =C60/C54 -> 0.064736896 | D15: =D60/D54 -> 0.053309318 | E15: =E60/E54 -> 0.098712264 | F15: =F60/F54 -> 0.11062446 | G15: =G60/G54 -> 0.11491025 | H15: =IFERROR(AVERAGE(C15:G15),"") -> 0.088458638
B16: Return on Equity (RoE) | C16: =C60/C71 -> 0.11731061 | D16: =D60/D71 -> 0.081449821 | E16: =E60/E71 -> 0.25989385 | F16: =F60/F71 -> 0.29787094 | G16: =G60/G71 -> 8.8099472 | H16: =IFERROR(AVERAGE(C16:G16),"") -> 1.9132945
B17: Return on Invested Capital (ROIC) | C17: =(C60+C59)/(C70+C71) -> 0.049756108 | D17: =(D60+D59)/(D70+D71) -> 0.050868576 | E17: =(E60+E59)/(E70+E71) -> 0.091447457 | F17: =(F60+F59)/(F70+F71) -> 0.13003932 | G17: =(G60+G59)/(G70+G71) -> 0.2252738 | H17: =IFERROR(AVERAGE(C17:G17),"") -> 0.10947705 | K17: Worst value
B18: Solvency | H18: =IFERROR(AVERAGE(C18:G18),"")
B19: Debt/Assets | C19: =C70/C67 -> 0.189086 | D19: =D70/D67 -> 0.27222478 | E19: =E70/E67 -> 0.35283823 | F19: =F70/F67 -> 0.2698772 | G19: =G70/G67 -> 0.60436725 | H19: =IFERROR(AVERAGE(C19:G19),"") -> 0.33767869
B20: Net Debt/EBITDA | C20: =(C70-C62)/C56 -> 0.36478578 | D20: =(D70-D62)/D56 -> 2.9626846 | E20: =(E70-E62)/E56 -> 2.3122377 | F20: =(F70-F62)/F56 -> 1.514681 | G20: =(G70-G62)/G56 -> 2.16741 | H20: =IFERROR(AVERAGE(C20:G20),"") -> 1.8643598
B21: Interest Coverage Ratio | C21: =-C56/C58 -> 61.578923 | D21: =-D56/D58 -> 13.508121 | E21: =-E56/E58 -> 11.762322 | F21: =-F56/F58 -> 12.835535 | G21: =-G56/G58 -> 15.441656 | H21: =IFERROR(AVERAGE(C21:G21),"") -> 23.025311
B22: Liquidity
B23: Current Ratio | C23: =C65/C69 -> 1.6746338 | D23: =D65/D69 -> 1.0284609 | E23: =E65/E69 -> 1.6267245 | F23: =F65/F69 -> 1.2573581 | G23: =G65/G69 -> 1.0487398 | H23: =IFERROR(AVERAGE(C23:G23),"") -> 1.3271834
B24: Quick Ratio | C24: =(C62+C63)/C69 -> 0.90028227 | D24: =(D62+D63)/D69 -> 0.64315082 | E24: =(E62+E63)/E69 -> 1.1227141 | F24: =(F62+F63)/F69 -> 0.72751179 | G24: =(G62+G63)/G69 -> 0.51380672 | H24: =IFERROR(AVERAGE(C24:G24),"") -> 0.78149315
B25: Activity | H25: =IFERROR(AVERAGE(C25:G25),"")
B26: Inventory Turnover | C26: =C55/C64 -> 2.6677545 | D26: =D55/D64 -> 5.6646983 | E26: =E55/E64 -> 5.9107081 | F26: =F55/F64 -> 4.7713873 | G26: =G55/G64 -> 3.9900713 | H26: =IFERROR(AVERAGE(C26:G26),"") -> 4.6009239
B27: Acc. Receivable Turnover | C27: =C54/C63 -> 5.7944625 | D27: =D54/D63 -> 4.3473844 | E27: =E54/E63 -> 5.7575201 | F27: =F54/F63 -> 5.7767536 | G27: =G54/G63 -> 5.6891878 | H27: =IFERROR(AVERAGE(C27:G27),"") -> 5.4730617
A28: Price/Sales | B28: Payables Turnover | C28: =C55/C68 -> 7.514886 | D28: =D55/D68 -> 3.9710212 | E28: =E55/E68 -> 5.3968202 | F28: =F55/F68 -> 5.6979009 | G28: =G55/G68 -> 7.2654789 | H28: =IFERROR(AVERAGE(C28:G28),"") -> 5.9692215
B29: Fixed Asset Turnover | C29: =C54/C66 -> 4.4193402 | D29: =D54/D66 -> 5.9074036 | E29: =E54/E66 -> 7.624388 | F29: =F54/F66 -> 10.302725 | G29: =G54/G66 -> 5.8337174 | H29: =IFERROR(AVERAGE(C29:G29),"") -> 6.8175148
B30: Total Asset Turnover | C30: =C54/C67 -> 0.92515618 | D30: =D54/D67 -> 0.60094426 | E30: =E54/E67 -> 0.83020087 | F30: =F54/F67 -> 0.91085855 | G30: =G54/G67 -> 1.6098346 | H30: =IFERROR(AVERAGE(C30:G30),"") -> 0.9753989
B31: Valuation | H31: =IFERROR(AVERAGE(C31:G31),"")
B32: Price/Earnings | C32: =C9/C60 -> 28.41581 | D32: =D9/D60 -> 36.267291 | E32: =E9/E60 -> 22.433089 | F32: =F9/F60 -> 26.683669 | G32: =G9/G60 -> 24.859493 | H32: =IFERROR(AVERAGE(C32:G32),"") -> 27.73187
B33: Price/Sales | C33: =C9/C54 -> 1.8395513 | D33: =D9/D54 -> 1.9333845 | E33: =E9/E54 -> 2.2144209 | F33: =F9/F54 -> 2.9518665 | G33: =G9/G54 -> 2.8566106 | H33: =IFERROR(AVERAGE(C33:G33),"") -> 2.3591668
B34: Price/Book | C34: =C9/C71 -> 3.3334761 | D34: =D9/D71 -> 2.9539643 | E34: =E9/E71 -> 5.8302218 | F34: =F9/F71 -> 7.9482896 | G34: =G9/G71 -> 219.01082 | H34: =IFERROR(AVERAGE(C34:G34),"") -> 47.815354
B35: EV/Sales | C35: =(C9+C70-C62)/C54 -> 1.8888039 | D35: =(D9+D70-D62)/D54 -> 2.3106888 | E35: =(E9+E70-E62)/E54 -> 2.4923642 | F35: =(F9+F70-F62)/F54 -> 3.2056513 | G35: =(G9+G70-G62)/G54 -> 3.2213229 | H35: =IFERROR(AVERAGE(C35:G35),"") -> 2.6237662
B36: EV/EBITDA | C36: =(C9+C70-C62)/C56 -> 13.989293 | D36: =(D9+D70-D62)/D56 -> 18.144089 | E36: =(E9+E70-E62)/E56 -> 20.734226 | F36: =(F9+F70-F62)/F56 -> 19.132505 | G36: =(G9+G70-G62)/G56 -> 19.143657 | H36: =IFERROR(AVERAGE(C36:G36),"") -> 18.228754
B37: Stock Info | H37: =IFERROR(AVERAGE(C37:G37),"")
B38: Float | C38: =OP!M17 -> 0.91467577 | D38: 0.997 | E38: 0.9884 | F38: 0.9967 | G38: 0.981 | H38: =IFERROR(AVERAGE(C38:G38),"") -> 0.97555515
B39: b (Yahoo) | C39: =OP!M19 -> 0.9 | D39: 1.24 | E39: 1.24 | F39: 1.21 | G39: 0.72 | H39: =IFERROR(AVERAGE(C39:G39),"") -> 1.062
B40: Dividend Yield (yahoo finance) | C40: 0.0084 | D40: 0.0203 | E40: 0.0125 | F40: 0.014 | G40: 0.0193 | H40: =IFERROR(AVERAGE(C40:G40),"") -> 0.0149
B41: Stock Performance
...

Sheet ESG
B1: Company GICS Sector: | T1: Yes
B2: Industrials | C2: <- Select Industry | T2: No
B3: ESG Analysis | K3: Relative ESG Analysis
B4: Parameters | C4: Impact | D4: Do they report? | E4: Ranking | F4: Mitigation Plan | G4: Traffic Lights | H4: Improvement over time? | I4: Targets / Goals? | J4: Comments | K4: Parameters | L4: =Peers!C7 -> Daikin Industries,Ltd. (6367.T) | M4: =Peers!D7 -> #VALUE! | N4: =Peers!E7 -> #VALUE! | O4: =Peers!F7 -> #VALUE! | P4: =Peers!G7 -> #VALUE!
B5: Environmental | K5: Ratios
A6: 1 | B6: CO2 Direct Emissions | C6: =VLOOKUP($B$2,'[1]Sector Impact'!$K$4:$AA$16,A6+1,FALSE) -> Very High | D6: Yes | E6: Medium | F6: Yes | H6: No | I6: Achieve carbon neutrality by 2050 | J6: Increased 13% (2020-2021). Highest value per sales of the last 3 years. Achieve 30% reduction in 2025 and over 50% in 2030 | K6: CO2 Emissions/$M Sales | L6: =L12/L$11 -> 0.067865168 | M6: =M12/M$11 -> 0.21884363 | N6: =N12/N$11 -> 0.14331639 | O6: =O12/O$11 -> 0.21966106 | P6: =P12/P$11 -> 1.8582644
A7: 2 | B7: Total Water Consumption | C7: =VLOOKUP($B$2,'[1]Sector Impact'!$K$4:$AA$16,A7+1,FALSE) -> Very High | D7: Yes | E7: Medium | F7: Yes | H7: No | I7: None | J7: Increased 5% (2020-2021). Highest value (2021) in % of sales of the last 2 years | K7: Water Consumption/$M Sales | L7: =L13/L$11 -> 0.002035955 | M7: =M13/M$11 -> 0.36494513 | N7: =N13/N$11 -> 0.00036927043 | O7: =O13/O$11 -> 1.4462547 | P7: =P13/P$11 -> 0.0060311502
A8: 3 | B8: Total Energy Consumption | C8: =VLOOKUP($B$2,'[1]Sector Impact'!$K$4:$AA$16,A8+1,FALSE) -> Very High | D8: Yes | E8: "Villain" | F8: Yes | H8: No | I8: None | J8: Increased 17% (2020-2021). Highest value (2021) in % of sales of the last 4 years | K8: Energy Consumption/$M Sales | L8: =L14/L$11 -> 5.313831 | M8: =M14/M$11 -> 2.1205332 | N8: =N14/N$11 -> 1.6316118 | O8: =O14/O$11 -> 1.4907933 | P8: =P14/P$11 -> 1.1860324
A9: 4 | B9: Waste Management | C9: =VLOOKUP($B$2,'[1]Sector Impact'!$K$4:$AA$16,A9+1,FALSE) -> High | D9: Yes | E9: Medium High | F9: Yes | H9: No | I9: None | J9: Increased 28% (2020-2021). Highest value (2021) in % of sales of the last 5 years. | K9: Waste Production/$M Sales | L9: =L15/L$11 -> 0.013284848 | M9: =M15/M$11 -> 0.021336587 | N9: =N15/N$11 -> 0.026152995 | O9: =O15/O$11 -> 0.003768269 | P9: =P15/P$11 -> 9.6275028e-05
A10: 5 | B10: Land Degradation/Deforestation/Biodiversity loss/Animal sufering/… | C10: =VLOOKUP($B$2,'[1]Sector Impact'!$K$4:$AA$16,A10+1,FALSE) -> High | D10: Yes | E10: Medium High | F10: Yes | H10: None | I10: None | J10: No information | K10: Inputs
B11: Social | K11: Net Sales (¥M) | L11: =M46 -> 3109106 | M11: =M47 -> 3345708.5 | N11: =M48 -> 2913853.7 | O11: =M49 -> 1998265 | P11: =M50 -> 4476758
A12: 6 | B12: Employee Turnover % | C12: =VLOOKUP($B$2,'[1]Sector Impact'!$K$4:$AA$16,A12+1,FALSE) -> Low | D12: Yes | E12: Medium | F12: Yes | H12: No | I12: None | J12: 4,4% (2021), 3,7% (2020), 3,9% (2019), 4% (2018) | K12: CO2 Emissions Total (Tonnes) | L12: 211000 | M12: =M76 -> 732187 | N12: =M78 -> 417603 | O12: =M80 -> 438941 | P12: =M82 -> 8319000
A13: 7 | B13: Salaries & Compensation | C13: =VLOOKUP($B$2,'[1]Sector Impact'!$K$4:$AA$16,A13+1,FALSE) -> Medium | D13: Yes | E13: Medium | F13: Yes | H13: None | I13: None | J13: Starting salary: University grad- 235000 ¥ (1657 $); Masters- 254800 ¥ (1797$); PhD- 278800 ¥ (1966$) | K13: Water Consumption Total (Cubic Meters) | L13: 6330 | M13: =W59 -> 1221000 | N13: =W61 -> 1076 | O13: =W63 -> 2890000 | P13: =W65 -> 27000
A14: 8 | B14: Reputation | C14: =VLOOKUP($B$2,'[1]Sector Impact'!$K$4:$AA$16,A14+1,FALSE) -> High | D14: Yes | E14: Medium High | F14: Yes | H14: None | I14: None | J14: Percentage of Employees in Union: 87% | K14: Energy Consumption Total (Gigajoules) | L14: 16521264 | M14: =M59 -> 7094686 | N14: =M61 -> 4754278 | O14: =M63 -> 2979000 | P14: =M65 -> 5309580
A15: 9 | B15: Discrimination Events | C15: =VLOOKUP($B$2,'[1]Sector Impact'!$K$4:$AA$16,A15+1,FALSE) -> Very High | D15: Yes | E15: Medium | F15: Yes | H15: No | I15: None | J15: Women as % of all employees: 28%. Employment rate of people with disabilities: 2,6% or 362 people (2021) | K15: Waste Production Total (Tonnes) | L15: 41304 | M15: =W76 -> 71386 | N15: =W78 -> 76206 | O15: =W80 -> 7530 | P15: =W82 -> 431
A16: 10 | B16: Work Safety | C16: =VLOOKUP($B$2,'[1]Sector Impact'!$K$4:$AA$16,A16+1,FALSE) -> Medium | D16: Yes | E16: Medium High | F16: Yes | H16: None | I16: None | J16: Percentage of employees taking checkup: 99% (2021); Percentage of employees requiring treatment: 63% (2021) | K16: ESG Scores
A17: 11 | B17: Damage to consumer health | C17: =VLOOKUP($B$2,'[1]Sector Impact'!$K$4:$AA$16,A17+1,FALSE) -> Very High | D17: Yes | E17: Medium | F17: Yes | H17: None | I17: None | J17: Average Hours of Overtime per Employee: 212 hours (2021); 193 (2020): 208 (2019). Percentage of Employees Taking All Paid Leave: 95,8% (2021), Percentage of Japanese workers in the manufacturing industry: 61,6% (2021) | K17: Refinitiv | L17: 67 (119/638) (48/77/75) | M17: 78 (42/638) (95/94/37) | N17: 60 (183/638) (52/82/41) | O17: 80 (34/638) (68/93/78) | P17: 83 (6/66) (98/89/51)
A18: 12 | B18: PXP? | C18: =VLOOKUP($B$2,'[1]Sector Impact'!$K$4:$AA$16,A18+1,FALSE) -> Medium | D18: Yes | E18: Medium High | F18: Yes | H18: None | I18: None | J18: No information | K18: Sustainalytics | L18: 21.7 (medium risk) | M18: 14.4 (Low risk) | N18: 20.4 (medium risk) | O18: 15.2 (Low risk) | P18: 20.8 (medium risk)
A19: 13 | B19: Supply chain | C19: =VLOOKUP($B$2,'[1]Sector Impact'!$K$4:$AA$16,A19+1,FALSE) -> Very High | D19: Yes | E19: Medium | F19: Yes | H19: None | I19: Increase Class A CSR procurement achievment rate among all suppliers | J19: 72% Class A CSR Procurement Achievement Rate (2021) | K19: ISS | L19: C+ | M19: B- | N19: C+ | O19: B- | P19: C+
A20: 14 | B20: Community involvement | C20: =VLOOKUP($B$2,'[1]Sector Impact'!$K$4:$AA$16,A20+1,FALSE) -> Very High | D20: Yes | E20: Medium High | F20: Yes | H20: None | I20: Contribution to environmental conservation, education support, and cooperation with the local community | J20: 1388 million ¥ (10 million $) Expenditure for Social Contribution Activities in 2021 | K20: CDP | L20: A / A- | M20: A-/ B | N20: F/ F | O20: A / B | P20: A-/ A-
A21: 15 | B21: Public Sector | C21: =VLOOKUP($B$2,'[1]Sector Impact'!$K$4:$AA$16,A21+1,FALSE) -> Very High | D21: Yes | E21: Medium | F21: No | H21: None | I21: None | J21: No information | O21: USD/JPY | P21: 141.36
A22: 16 | B22: Litigation | C22: =VLOOKUP($B$2,'[1]Sector Impact'!$K$4:$AA$16,A22+1,FALSE) -> High | D22: Yes | E22: Medium High | F22: Yes | H22: None | I22: None | J22: No major legal violations in the last 3 years. Patent dispute with Chemours-July 2022: Settled before trial (terms were not disclosed)
B23: Corporate Governance
A24: 17 | B24: Diversity (Gender, Age, Industry, Region) | E24: Medium High | F24: Yes | H24: None | I24: Appointment of female officers from inside the compoany: 1 or more in fiscal 2025 | J24: Out of 10 board members: 1 female (10%); Average age of 73 years old; 1 non-Japanese
A25: 18 | B25: % Independence | E25: Medium High | F25: No | H25: None | I25: None | J25: 4 out of 10 are independent (40%)
A26: 19 | B26: Average time as independent directors/ Average Appointment Term for Director | E26: Medium High | F26: No | H26: None | I26: None | J26: 4.75 years/ 9.7 (2021)
A27: 20 | B27: Recent departures of directors / C-level executives? | E27: Medium High | F27: No | H27: None | I27: None | J27: None
A28: 21 | B28: CEO/Chairman duality | E28: Medium High | F28: No | H28: None | I28: None | J28: No. Noriyuki Inoue- Chairman of the board (since 2014); Masanori Togawa- CEO (since 2014)
A29: 22 | B29: Transparency (ESG, segments, acquisitions, other) | E29: Medium High | F29: Yes | H29: None | I29: None | J29: Well reported
A30: 23 | B30: Time taken to report after the end of the quarter / year | E30: Medium | F30: No | H30: None | I30: None | J30: 1 month and 9 days (31st march-9th may)
A31: 24 | B31: Additional participation of the CEO in other boards or excessive participation of Ch. | E31: Medium | F31: No | H31: None | I31: None | J31: Noriyuki Inoue: Chairman of The Daikin Foundation for Contemporary Arts and Nonprofit Corporation of Kansai Philharmonic Orchestra
A32: 25 | B32: Audit / Consulting | D32: Yes | E32: Medium | F32: No | H32: None | I32: None | J32: Deloitte Touche Tohmatsu LLC; Audit expenses: 255 million ¥ (1,8 million $)
A33: 26 | B33: ESG-compensation related | D33: No | E33: Medium | F33: No | H33: None | I33: None | J33: No information
A34: 27 | B34: Management compensation schemes | D34: Yes | E34: Medium High | F34: No | H34: None | I34: None | J34: Down below
B36: PARAMETERS
B37: IMPACT | C37: RANKING | D37: MITIGATION PLAN
B38: Low | C38: "Best in class" | D38: Evidence / plan?
B39: Medium | C39: Medium High
B40: High | C40: Medium
B41: Very high | C41: "Villain"
...

Sheet DCF
A1: VALUATION MODEL
G3: Short Term | K3: Long Term
A4: Section | B4: Line # | C4: ITEM | D4: 2020 (Real) | E4: 2021 (Real) | F4: 2022 (Real) | G4: 2023 | H4: =G4+1 -> 2024 | I4: =H4+1 -> 2025 | J4: =I4+1 -> 2026 | K4: =J4+1 -> 2027 | L4: =K4+1 -> 2028 | M4: =L4+1 -> 2029 | N4: =M4+1 -> 2030 | O4: =N4+1 -> 2031 | ... AF4: =AE4+1 -> 2048
A5: INCOME STATEMENT | B5: 1 | C5: Growth | D5: ='Fin. Data'!D6 -> -0.022318507 | E5: =+E6/D6-1 -> 0.24694131 | F5: =+F6/E6-1 -> 0.28061829 | G5: =+G6/F6-1 -> 0.029742479 | H5: =+H6/G6-1 -> 0.042682927 | I5: =+I6/H6-1 -> 0.064327485 | J5: =+J6/I6-1 -> 0.08 | K5: =+K6/J6-1 -> 0.08 | L5: =+L6/K6-1 -> 0.08 | ... AF5: =+AF6/AE6-1 -> 0.03
B6: 2 | C6: Revenues/Sales | D6: =Inputs!D6 -> 2493386 | E6: =Inputs!C6 -> 3109106 | F6: =Inputs!B6 -> 3981578 | G6: 4100000 | H6: 4275000 | I6: 4550000 | J6: =I6*1.08 -> 4914000 | K6: =J6*1.08 -> 5307120 | L6: =K6*1.08 -> 5731689.6 | M6: =L6*1.08 -> 6190224.8 | N6: =M6*1.08 -> 6685442.7 | O6: =N6*1.06 -> 7086569.3 | P6: =O6*1.06 -> 7511763.5 | Q6: =P6*1.06 -> 7962469.3 | R6: =Q6*1.06 -> 8440217.4 | S6: =R6*1.06 -> 8946630.5 | T6: =S6*1.04 -> 9304495.7 | U6: =T6*1.04 -> 9676675.5 | V6: =U6*1.04 -> 10063743 | W6: =V6*1.04 -> 10466292 | X6: =W6*1.04 -> 10884944 | Y6: =X6*1.03 -> 11211492 | Z6: =Y6*1.03 -> 11547837 | AA6: =Z6*1.03 -> 11894272 | AB6: =AA6*1.03 -> 12251100 | AC6: =AB6*1.03 -> 12618633 | AD6: =AC6*1.03 -> 12997192 | AE6: =AD6*1.03 -> 13387108 | AF6: =AE6*1.03 -> 13788721
B7: 3 | C7: EBIT/Operating Margin | D7: =D8/D6 -> 0.095423252 | E7: =E8/E6 -> 0.10012589 | F7: =F8/F6 -> 0.091645323 | G7: 0.098 | H7: 0.105 | I7: 0.11 | J7: 0.115 | K7: 0.12 | L7: =$K$7 -> 0.12 | M7: =$K$7 -> 0.12 | N7: =$K$7 -> 0.12 | O7: =$K$7 -> 0.12 | P7: =$K$7 -> 0.12 | Q7: =$K$7 -> 0.12 | R7: =$K$7 -> 0.12 | S7: =$K$7 -> 0.12 | ... AF7: =$K$7 -> 0.12
B8: 4 | C8: EBIT | D8: ='Fin. Data'!D11 -> 237927 | E8: ='Fin. Data'!C11 -> 311302 | F8: ='Fin. Data'!B11 -> 364893 | G8: =G7*G6 -> 401800 | H8: =H7*H6 -> 448875 | I8: =I7*I6 -> 500500 | J8: =J7*J6 -> 565110 | K8: =K7*K6 -> 636854.4 | L8: =L7*L6 -> 687802.75 | M8: =M7*M6 -> 742826.97 | N8: =N7*N6 -> 802253.13 | ... AF8: =AF7*AF6 -> 1654646.6
B9: 5a | C9: (Dep) | D9: -36178 | E9: -40952 | F9: -51181 | G9: =$D$53*DCF!F40 -> -48773.182 | H9: =$D$53*DCF!G40 -> -52636.51 | I9: =$D$53*DCF!H40 -> -56664.736 | J9: =$D$53*DCF!I40 -> -60952.089 | K9: =$E$53*DCF!J40 -> -65582.429 | L9: =$E$53*DCF!K40 -> -69415.597 | M9: =$E$53*DCF!L40 -> -73555.418 | N9: =$E$53*DCF!M40 -> -78026.425 | O9: =$E$53*DCF!N40 -> -82855.112 | P9: =$E$53*DCF!O40 -> -87973.521 | Q9: =$E$53*DCF!P40 -> -93399.034 | R9: =$E$53*DCF!Q40 -> -99150.078 | ... AF9: =$E$53*DCF!AE40 -> -210156.04 | AG9: =SUM(D9:AF9) -> -3156751.1
B10: 5b | C10: Amort | D10: -30050 | E10: -32684 | F10: -39496 | G10: =F38*$D$54 -> -39612.826 | H10: =G38*$D$54 -> -44043.986 | I10: =H38*$D$54 -> -48970.825 | J10: =I38*$D$54 -> -54448.788 | K10: =J38*$E$54 -> -60539.526 | L10: =K38*$E$54 -> -67311.584 | M10: =L38*$E$54 -> -74841.177 | N10: =M38*$E$54 -> -83213.044 | O10: =N38*$E$54 -> -92521.402 | P10: =O38*$E$54 -> -102871.01 | Q10: =P38*$E$54 -> -114378.34 | R10: =Q38*$E$54 -> -127172.91 | ... AF10: =AE38*$E$54 -> -561184.63
B11: 5c | C11: (Stock based compensation) | D11: =D20 -> 0 | E11: =E20 -> 0 | F11: =F20 -> 0 | G11: =G6*$D$55 -> 0 | H11: =H6*$D$55 -> 0 | I11: =I6*$D$55 -> 0 | J11: =J6*$D$55 -> 0 | K11: =K6*$D$55 -> 0 | L11: =L6*$D$55 -> 0 | M11: =M6*$D$55 -> 0 | N11: =N6*$D$55 -> 0 | ... AF11: =AF6*$D$55 -> 0
B12: 6 | C12: EBIDTA | D12: =D8-D9-D10 -> 304155 | E12: =E8-E9-E10 -> 384938 | F12: =F8-F9-F10 -> 455570 | G12: =G8-G9-G10 -> 490186.01 | H12: =H8-H9-H10 -> 545555.5 | I12: =I8-I9-I10 -> 606135.56 | J12: =J8-J9-J10 -> 680510.88 | K12: =K8-K9-K10 -> 762976.35 | ... AF12: =AF8-AF9-AF10 -> 2425987.2
B13: 7 | C13: (Net financing cost) | D13: ='Fin. Data'!D14 -> 2772 | E13: ='Fin. Data'!C14 -> -638 | F13: ='Fin. Data'!B14 -> -8730 | G13: =F43*$D$58-F44*$D$57 -> -19995.127 | H13: =G43*$D$58-G44*$D$57 -> -17501.524 | I13: =H43*$D$58-H44*$D$57 -> -18993.626 | J13: =I43*$D$58-I44*$D$57 -> -21805.284 | K13: =J43*$E$58-J44*$E$57 -> -39408.87 | L13: =K43*$E$58-K44*$E$57 -> -44508.181 | M13: =L43*$E$58-L44*$E$57 -> -48577.912 | N13: =M43*$E$58-M44*$E$57 -> -52987.785 | O13: =N43*$E$58-N44*$E$57 -> -57760.004 | P13: =O43*$E$58-O44*$E$57 -> -61322.204 | Q13: =P43*$E$58-P44*$E$57 -> -65078.923 | R13: =Q43*$E$58-Q44*$E$57 -> -69038.772 | ... AF13: =AE43*$E$58-AE44*$E$57 -> -114722.59
B14: 8 | C14: Other income/(cost) | D14: ='Fin. Data'!D15 -> -8652 | E14: ='Fin. Data'!C15 -> 9832 | F14: ='Fin. Data'!B15 -> 9533 | G14: =AVERAGE(D14:F14)*(1+G5) -> 3677.2104 | H14: =AVERAGE(E14:G14)*(1+H5) -> 8008.5731 | I14: =AVERAGE(F14:H14)*(1+I5) -> 7527.9115 | J14: =AVERAGE(G14:I14)*(1+J5) -> 6916.9302 | K14: =AVERAGE(H14:J14)*(1+K5) -> 8083.2293 | L14: =AVERAGE(I14:K14)*(1+L5) -> 8110.1056 | M14: =AVERAGE(J14:L14)*(1+M5) -> 8319.6954 | N14: =AVERAGE(K14:M14)*(1+N5) -> 8824.6909 | ... AF14: =AVERAGE(AC14:AE14)*(1+AF5) -> 12395.794
B15: 9 | C15: Earnings before taxes | D15: =D8+D13+D14 -> 232047 | E15: =E8+E13+E14 -> 320496 | F15: =F8+F13+F14 -> 365696 | G15: =G8+G13+G14 -> 385482.08 | H15: =H8+H13+H14 -> 439382.05 | I15: =I8+I13+I14 -> 489034.29 | J15: =J8+J13+J14 -> 550221.65 | K15: =K8+K13+K14 -> 605528.76 | ... AF15: =AF8+AF13+AF14 -> 1552319.8
B16: 10 | C16: (Income tax) | D16: ='Fin. Data'!D21 -> -75797 | E16: ='Fin. Data'!C21 -> -102786 | F16: ='Fin. Data'!B21 -> -107941 | G16: =-(1*24%)*G15 -> -92515.7 | H16: =-(1*$D$56)*H15 -> -134450.91 | I16: =-(1*$D$56)*I15 -> -149644.49 | J16: =-(1*$D$56)*J15 -> -168367.82 | K16: =-(1*$E$56)*K15 -> -185291.8 | L16: =-(1*$E$56)*L15 -> -199329.83 | M16: =-(1*$E$56)*M15 -> -214986.04 | N16: =-(1*$E$56)*N15 -> -231975.55 | O16: =-(1*$E$56)*O15 -> -245274.78 | P16: =-(1*$E$56)*P15 -> -259885.79 | Q16: =-(1*$E$56)*Q15 -> -275382.48 | R16: =-(1*$E$56)*R15 -> -291789.43 | ... AF16: =-(1*$E$56)*AF15 -> -475009.85
B17: 11 | C17: Net income | D17: ='Fin. Data'!D23 -> 156250 | E17: ='Fin. Data'!C23 -> 217710 | F17: ='Fin. Data'!B23 -> 257755 | G17: =G16+G15 -> 292966.38 | H17: =H16+H15 -> 304931.14 | I17: =I16+I15 -> 339389.79 | J17: =J16+J15 -> 381853.82 | K17: =K16+K15 -> 420236.96 | L17: =L16+L15 -> 452074.85 | M17: =M16+M15 -> 487582.72 | N17: =N16+N15 -> 526114.48 | ... AF17: =AF16+AF15 -> 1077309.9
A19: CASH FLOW STATEMENT | B19: 12 | C19: Operating cash flows before WK | D19: =D22-D20-D21 -> 373351 | E19: =E22-E20-E21 -> 471462 | F19: =F22-F20-F21 -> 551490 | G19: =G17-G10-G9-G11 -> 381352.39 | H19: =H17-H10-H9-H11 -> 401611.64 | I19: =I17-I10-I9-I11 -> 445025.36 | J19: =J17-J10-J9-J11 -> 497254.7 | K19: =K17-K10-K9-K11 -> 546358.91 | L19: =L17-L10-L9-L11 -> 588802.03 | M19: =M17-M10-M9-M11 -> 635979.31 | N19: =N17-N10-N9-N11 -> 687353.95 | ... AF19: =AF17-AF10-AF9-AF11 -> 1848650.6
B20: 13 | C20: (Stock-based compensation) | D20: 0 | E20: 0 | F20: 0 | G20: =G11 -> 0 | H20: =H11 -> 0 | I20: =I11 -> 0 | J20: =J11 -> 0 | K20: =K11 -> 0 | L20: =L11 -> 0 | M20: =M11 -> 0 | N20: =N11 -> 0 | ... AF20: =AF11 -> 0
B21: 14 | C21: (Working Capital Flows) | D21: =Inputs!D62 -> 1282 | E21: =Inputs!C62 -> -227977 | F21: =Inputs!B62 -> -393164 | G21: =$D$60*(G6-F6) -> -68114.428 | H21: =$D$60*(H6-G6) -> -100657.18 | I21: =$D$60*(I6-H6) -> -158175.57 | J21: =$D$60*(J6-I6) -> -209366.94 | K21: =$E$60*(K6-J6) -> -226116.3 | L21: =$E$60*(L6-K6) -> -244205.6 | M21: =$E$60*(M6-L6) -> -263742.05 | N21: =$E$60*(N6-M6) -> -284841.41 | O21: =$E$60*(O6-N6) -> -230721.54 | P21: =$E$60*(P6-O6) -> -244564.84 | Q21: =$E$60*(Q6-P6) -> -259238.73 | R21: =$E$60*(R6-Q6) -> -274793.05 | ... AF21: =$E$60*(AF6-AE6) -> -231001.47
B22: 15 | C22: -Total Operating Cash Flow | D22: =Inputs!D59 -> 374633 | E22: =Inputs!C59 -> 243485 | F22: =Inputs!B59 -> 158326 | G22: =G19+G20+G21 -> 313237.96 | H22: =H19+H20+H21 -> 300954.45 | I22: =I19+I20+I21 -> 286849.78 | J22: =J19+J20+J21 -> 287887.76 | K22: =K19+K20+K21 -> 320242.62 | L22: =L19+L20+L21 -> 344596.43 | M22: =M19+M20+M21 -> 372237.26 | N22: =N19+N20+N21 -> 402512.54 | ... AF22: =AF19+AF20+AF21 -> 1617649.1
B23: 16 | C23: (CAPEX) | D23: ='Fin. Data'!D32 -> -104971 | E23: ='Fin. Data'!C32 -> -114106 | F23: ='Fin. Data'!B32 -> -175076 | G23: =G6*$D$62 -> -160466.34 | H23: =H6*$D$62 -> -167315.52 | I23: =I6*$D$62 -> -178078.5 | J23: =J6*$D$62 -> -192324.78 | K23: =K6*$E$62 -> -159213.6 | L23: =L6*$E$62 -> -171950.69 | M23: =M6*$E$62 -> -185706.74 | N23: =N6*$E$62 -> -200563.28 | O23: =O6*$E$62 -> -212597.08 | P23: =P6*$E$62 -> -225352.9 | Q23: =Q6*$E$62 -> -238874.08 | R23: =R6*$E$62 -> -253206.52 | ... AF23: =AF6*$E$62 -> -413661.64 | AG23: =SUM(D23:AF23) -> -7510977.2
B24: 17 | C24: Adq | D24: =Inputs!D66 -> -43371 | E24: ='Fin. Data'!C33 -> -46221 | F24: ='Fin. Data'!B33 -> -34920 | G24: =G6*$D$63 -> -71455.043 | H24: =H6*$D$63 -> -74504.953 | I24: =I6*$D$63 -> -79297.669 | J24: =J6*$D$63 -> -85641.483 | K24: =K6*$E$63 -> -79606.8 | L24: =L6*$E$63 -> -85975.344 | M24: =M6*$E$63 -> -92853.372 | N24: =N6*$E$63 -> -100281.64 | O24: =O6*$E$63 -> -106298.54 | P24: =P6*$E$63 -> -112676.45 | Q24: =Q6*$E$63 -> -119437.04 | R24: =R6*$E$63 -> -126603.26 | ... AF24: =AF6*$E$63 -> -206830.82 | AH24: =AG9-AG23 -> 4354226
B25: 18 | C25: (Other investing flows) | D25: =Inputs!D67 -> -11324 | E25: =Inputs!C67 -> -20462 | F25: =Inputs!B67 -> -19797 | G25: =(1+G5)*AVERAGE(D25:F25) -> -17705.735 | H25: =(1+H5)*AVERAGE(E25:G25) -> -20146.28 | I25: =(1+I5)*AVERAGE(F25:H25) -> -20452.477 | J25: =(1+J5)*AVERAGE(G25:I25) -> -20989.617 | K25: =(1+K5)*AVERAGE(H25:J25) -> -22171.815 | L25: =(1+L5)*AVERAGE(I25:K25) -> -22901.007 | M25: =(1+M5)*AVERAGE(J25:L25) -> -23782.478 | N25: =(1+N5)*AVERAGE(K25:M25) -> -24787.908 | ... AF25: =(1+AF5)*AVERAGE(AC25:AE25) -> -35049.562
B26: 19 | C26: -Total Investing Flows | D26: =D23+D24+D25 -> -159666 | E26: =E23+E24+E25 -> -180789 | F26: =F23+F24+F25 -> -229793 | G26: =G23+G24+G25 -> -249627.12 | H26: =H23+H24+H25 -> -261966.75 | I26: =I23+I24+I25 -> -277828.65 | J26: =J23+J24+J25 -> -298955.88 | K26: =K23+K24+K25 -> -260992.21 | ... AF26: =AF23+AF24+AF25 -> -655542.02
B27: 20 | C27: (Flows related to leases) | D27: =Inputs!D71+Inputs!D72 -> -28085 | E27: =Inputs!C71+Inputs!C72 -> -27507 | F27: =Inputs!B71+Inputs!B72 -> -40953 | G27: 0 | H27: 0 | I27: 0 | J27: 0 | K27: 0 | L27: 0 | M27: 0 | N27: 0 | O27: 0 | P27: 0 | Q27: 0 | R27: 0 | S27: 0 | T27: 0 | U27: 0 | V27: 0 | W27: 0 | X27: 0 | Y27: 0 | Z27: 0 | AA27: 0 | AB27: 0 | AC27: 0 | AD27: 0 | AE27: 0 | AF27: 0
B28: 21 | C28: Flows related to debt | D28: =+SUM(Inputs!D69:D70) -> 149976 | E28: =+SUM(Inputs!C69:C70) -> 8335 | F28: =+SUM(Inputs!B69:B70) -> -42259 | G28: =G44-F44 -> -140976.16 | H28: =H44-G44 -> 75995.702 | I28: =I44-H44 -> 83147.319 | J28: =J44-I44 -> 102081.57 | K28: =K44-J44 -> 113185.48 | L28: =L44-K44 -> 84483.485 | M28: =M44-L44 -> 91538.312 | N28: =N44-M44 -> 99190.653 | ... AF28: =AF44-AE44 -> 156909.35
B29: 22 | C29: (Respurchases)/Issuance of stock | D29: ='Fin. Data'!D28 -> 0 | E29: ='Fin. Data'!C28 -> 0 | F29: ='Fin. Data'!B28 -> 0 | G29: =-G17*$D$65 -> 0 | H29: =-H17*$D$65 -> 0 | I29: =-I17*$D$65 -> 0 | J29: =-J17*$D$65 -> 0 | K29: =-K17*$E$65 -> 0 | L29: =-L17*$E$65 -> 0 | M29: =-M17*$E$65 -> 0 | N29: =-N17*$E$65 -> 0 | O29: =-O17*$E$65 -> 0 | P29: =-P17*$E$65 -> 0 | Q29: =-Q17*$E$65 -> 0 | R29: =-R17*$E$65 -> 0 | ... AF29: =-AF17*$E$65 -> 0
B30: 23 | C30: (Dividends) | D30: ='Fin. Data'!D27 -> -46721 | E30: ='Fin. Data'!C27 -> -49746 | F30: ='Fin. Data'!B27 -> -61468 | G30: =-$D$64*G17 -> -75091.87 | H30: =-$D$64*H17 -> -78158.625 | I30: =-$D$64*I17 -> -86990.917 | J30: =-$D$64*J17 -> -97875.112 | K30: =-$H$60*K17 -> -168094.78 | L30: =-$H$60*L17 -> -180829.94 | M30: =-$H$60*M17 -> -195033.09 | N30: =-$H$60*N17 -> -210445.79 | O30: =-$H$60*O17 -> -222510.72 | P30: =-$H$60*P17 -> -235765.67 | Q30: =-$H$60*Q17 -> -249824.1 | R30: =-$H$60*R17 -> -264708.32 | ... U30: =-$H$60*U17 -> -303005.39 | V30: =-$H$61*V17 -> -472896.21 | W30: =-$H$61*W17 -> -491382.31 | X30: =-$H$61*X17 -> -510651.3 | Y30: =-$H$61*Y17 -> -525240.3 | Z30: =-$H$61*Z17 -> -540868.31 | AA30: =-$H$61*AA17 -> -557018.31 | AB30: =-$H$61*AB17 -> -573706.15 | AC30: =-$H$61*AC17 -> -590967.09 | ... AF30: =-$H$61*AF17 -> -646385.95
B31: 24 | C31: Other financing flows | D31: =Inputs!D75 -> 23772 | E31: =Inputs!C75 -> 20220 | F31: =Inputs!B75 -> 31592 | G31: =(1+G5)*AVERAGE(D31:F31) -> 25944.019 | H31: =(1+H5)*AVERAGE(E31:G31) -> 27024.958 | I31: =(1+I5)*AVERAGE(F31:H31) -> 30000.19 | J31: =(1+J5)*AVERAGE(G31:I31) -> 29868.9 | K31: =(1+K5)*AVERAGE(H31:J31) -> 31281.857 | L31: =(1+L5)*AVERAGE(I31:K31) -> 32814.341 | M31: =(1+M5)*AVERAGE(J31:L31) -> 33827.435 | N31: =(1+N5)*AVERAGE(K31:M31) -> 35252.508 | ... AF31: =(1+AF5)*AVERAGE(AC31:AE31) -> 49909.163
B32: 25 | C32: -Total Financing flows | D32: =D27+D28+D29+D30+D31 -> 98942 | E32: =E27+E28+E29+E30+E31 -> -48698 | F32: =F27+F28+F29+F30+F31 -> -113088 | G32: =G27+G28+G29+G30+G31 -> -190124.01 | H32: =H27+H28+H29+H30+H31 -> 24862.035 | I32: =I27+I28+I29+I30+I31 -> 26156.593 | J32: =J27+J28+J29+J30+J31 -> 34075.357 | K32: =K27+K28+K29+K30+K31 -> -23627.451 | ... AF32: =AF27+AF28+AF29+AF30+AF31 -> -439567.43
A34: SUMMARY | B34: 26 | C34: Cash before shareholder returns | D34: =D22+D26+D27+D28+D31 -> 360630 | E34: =E22+E26+E27+E28+E31 -> 63744 | F34: =F22+F26+F27+F28+F31 -> -123087 | G34: =G22+G26+G27+G28+G31 -> -51421.298 | H34: =H22+H26+H27+H28+H31 -> 142008.36 | I34: =I22+I26+I27+I28+I31 -> 122168.64 | J34: =J22+J26+J27+J28+J31 -> 120882.34 | K34: =K22+K26+K27+K28+K31 -> 203717.73 | ... AF34: =AF22+AF26+AF27+AF28+AF31 -> 1168925.6
B35: 27 | C35: Returns to shareholders | D35: =-1*(D29+D30) -> 46721 | E35: =-1*(E29+E30) -> 49746 | F35: =-1*(F29+F30) -> 61468 | G35: =-1*(G29+G30) -> 75091.87 | H35: =-1*(H29+H30) -> 78158.625 | I35: =-1*(I29+I30) -> 86990.917 | J35: =-1*(J29+J30) -> 97875.112 | K35: =-1*(K29+K30) -> 168094.78 | ... AF35: =-1*(AF29+AF30) -> 646385.95
B36: 28 | C36: Excess cash acumulation | D36: =D34-D35 -> 313909 | E36: =E34-E35 -> 13998 | F36: =F34-F35 -> -184555 | G36: =G34-G35 -> -126513.17 | H36: =H34-H35 -> 63849.74 | I36: =I34-I35 -> 35177.723 | J36: =J34-J35 -> 23007.23 | K36: =K34-K35 -> 35622.951 | ... AF36: =AF34-AF35 -> 522539.66
A38: BALANCE SHEET | B38: 29 | C38: Intangible assets | D38: 274077 | E38: 306540 | F38: 354123 | G38: =+F38+(-G10) -> 393735.83 | H38: =+G38+(-H10) -> 437779.81 | I38: =+H38+(-I10) -> 486750.64 | J38: =+I38+(-J10) -> 541199.42 | K38: =+J38+(-K10) -> 601738.95 | L38: =+K38+(-L10) -> 669050.53 | M38: =+L38+(-M10) -> 743891.71 | N38: =+M38+(-N10) -> 827104.76 | ... AF38: =+AE38+(-AF10) -> 5577953.4 | AG38: =SUM(G38:AF38) -> 51922809
B39: 30 | C39: Accumulated amorization | F39: =-SUM(D10:F10) -> 102230 | G39: =F39-G10 -> 141842.83 | H39: =G39-H10 -> 185886.81 | I39: =H39-I10 -> 234857.64 | J39: =I39-J10 -> 289306.42 | K39: =J39-K10 -> 349845.95 | L39: =K39-L10 -> 417157.53 | M39: =L39-M10 -> 491998.71 | N39: =M39-N10 -> 575211.76 | ... AF39: =AE39-AF10 -> 5326060.4 | AG39: =SUM(G39:AF39) -> 45373591
B40: 31 | C40: PPE+Right of use Assets | D40: 1533306 | E40: 1752487 | F40: 2025832 | G40: =F40+(-G23) -> 2186298.3 | H40: =G40+(-H23) -> 2353613.9 | I40: =H40+(-I23) -> 2531692.4 | J40: =I40+(-J23) -> 2724017.2 | K40: =J40+(-K23) -> 2883230.8 | L40: =K40+(-L23) -> 3055181.4 | M40: =L40+(-M23) -> 3240888.2 | N40: =M40+(-N23) -> 3441451.5 | ... AF40: =AE40+(-AF23) -> 9142656.2 | AG40: =SUM(G40:AF40) -> 1.3290544e+08
B41: 32 | C41: Accumulated depreciation | D41: 885895 | E41: 1009123 | F41: 1124887 | G41: =F41-G9 -> 1173660.2 | H41: =G41-H9 -> 1226296.7 | I41: =H41-I9 -> 1282961.4 | J41: =I41-J9 -> 1343913.5 | K41: =J41-K9 -> 1409495.9 | L41: =K41-L9 -> 1478911.5 | M41: =L41-M9 -> 1552467 | N41: =M41-N9 -> 1630493.4 | ... AF41: =AE41-AF9 -> 4153327.1 | AG41: =SUM(G41:AF41) -> 60774747
A43: CASH & DEBT & DISCOUNTING | B43: 33 | C43: Ending cash balance | D43: ='Fin. Data'!D39 -> 736098 | E43: =E36+D43 -> 750096 | F43: =F36+E43 -> 565541 | G43: =G36+F43 -> 439027.83 | H43: =H36+G43 -> 502877.57 | I43: =I36+H43 -> 538055.29 | J43: =J36+I43 -> 561062.52 | K43: =K36+J43 -> 596685.48 | L43: =L36+K43 -> 596922.75 | ... AF43: =AF36+AE43 -> 4343202.2
B44: 34 | C44: Total Debt | D44: ='Fin. Data'!D58 -> 674932 | E44: ='Fin. Data'!C58 -> 460332 | F44: ='Fin. Data'!B58 -> 813766 | G44: =G12*Assumptions!$I$18 -> 672789.84 | H44: =H12*Assumptions!$I$18 -> 748785.55 | I44: =I12*Assumptions!$I$18 -> 831932.86 | J44: =J12*Assumptions!$I$18 -> 934014.43 | K44: =K12*Assumptions!$I$18 -> 1047199.9 | L44: =L12*Assumptions!$I$18 -> 1131683.4 | M44: =M12*Assumptions!$I$18 -> 1223221.7 | N44: =N12*Assumptions!$I$18 -> 1322412.4 | ... AF44: =AF12*Assumptions!$I$18 -> 3329714.7
B45: 35 | C45: Discount factor | F45: =1/((1+$F$50)^G50) -> 1 | G45: =1/((1+$F$50)^G49) -> 0.91335895 | H45: =1/((1+$F$50)^H49) -> 0.83422458 | I45: =1/((1+$F$50)^I49) -> 0.76194648 | J45: =1/((1+$F$50)^J49) -> 0.69593064 | K45: =1/((1+$F$50)^K49) -> 0.63563448 | L45: =1/((1+$F$50)^L49) -> 0.58056245 | M45: =1/((1+$F$50)^M49) -> 0.53026191 | N45: =1/((1+$F$50)^N49) -> 0.48431946 | ... AF45: =1/((1+$F$50)^AF49) -> 0.094771715
...

Sheet Assumptions
B2: Tax rate | C2: =107941/373384 -> 0.28908845
B4: Weight | C4: Region | D4: Equity Risk Premium
B5: 0.17 | C5: Japan | E5: 0.0607
B6: 0.32 | C6: US | E6: 0.05 | G6: Weighted Average
B7: 0.18 | C7: Europe | E7: 0.05 | G7: =E5*B5+E6*B6+E7*B7+E8*B8+E9*B9+E10*B10 -> 0.0533598
B8: 0.15 | C8: Asia and Oceania | E8: 0.05
B9: 0.12 | C9: China | E9: 0.0607
B10: 0.06 | C10: Other | E10: =AVERAGEA(E5:E9) -> 0.05428
B12: Year | C12: 2022 | D12: 2021 | E12: 2020 | F12: 2019 | G12: 2018
B13: Capex | C13: 175076 | D13: 114106 | E13: 104971 | F13: 98094 | G13: 85487 | I13: Average
B14: Revenue | C14: 3981578 | D14: 3109106 | E14: 2493386 | F14: 2550305 | G14: 2481109 | I14: =AVERAGE(C15:G15) -> 0.039138133
B15: Capex/Revenue | C15: =C13/C14 -> 0.043971511 | D15: =D13/D14 -> 0.036700582 | E15: =E13/E14 -> 0.042099779 | F15: =F13/F14 -> 0.038463635 | G15: =G13/G14 -> 0.034455157
B17: Debt | C17: ='Fin. Data'!B58 -> 813766 | D17: ='Fin. Data'!C58 -> 460332 | E17: ='Fin. Data'!D58 -> 674932 | F17: ='Fin. Data'!E58 -> 447903 | G17: ='Fin. Data'!F58 -> 493254 | I17: Average
B18: EBITDA | C18: ='Fin. Data'!B19 -> 537584 | D18: ='Fin. Data'!C19 -> 449532 | E18: ='Fin. Data'!D19 -> 380172 | F18: ='Fin. Data'!E19 -> 359040 | G18: ='Fin. Data'!F19 -> 378846 | I18: =AVERAGE(C19:G19) -> 1.3725195
B19: Debt/EBITDA | C19: ='Fin. Data'!B58/'Fin. Data'!B19 -> 1.5137467 | D19: ='Fin. Data'!C58/'Fin. Data'!C19 -> 1.024025 | E19: ='Fin. Data'!D58/'Fin. Data'!D19 -> 1.7753333 | F19: ='Fin. Data'!E58/'Fin. Data'!E19 -> 1.2475017 | G19: ='Fin. Data'!F58/'Fin. Data'!F19 -> 1.3019908
B21: Depreciation | C21: 51181 | D21: 40952 | E21: 36178 | G21: Average
B22: PPE | C22: 2025832 | D22: 1752487 | E22: 1533306 | G22: =AVERAGE(C23:E23) -> 0.02407563
B23: Depreciation/PPE | C23: =C21/C22 -> 0.025264188 | D23: =D21/D22 -> 0.023367934 | E23: =E21/E22 -> 0.023594768
B25: Amortization | C25: 39496 | D25: 32684 | E25: 30050 | G25: Average
B26: Intangible Assets | C26: 274077 | D26: 306540 | E26: 354123 | G26: =AVERAGE(C27:E27) -> 0.11186177
B27: Amortization/Intangible Assets | C27: =C25/C26 -> 0.14410549 | D27: =D25/D26 -> 0.1066223 | E27: =E25/E26 -> 0.084857521
B29: Aquisitions | C29: 34920 | D29: 46221 | E29: 43371 | F29: 41285 | G29: 74237 | I29: Average
B30: Revenue | C30: 3981578 | D30: 3109106 | E30: 2493386 | F30: 2550305 | G30: 2481109 | I30: =AVERAGE(C31:G31) -> 0.017428059
B31: Aquisitions/Revenue | C31: =C29/C30 -> 0.008770392 | D31: =D29/D30 -> 0.014866331 | E31: =E29/E30 -> 0.017394419 | F31: =F29/F30 -> 0.01618826 | G31: =G29/G30 -> 0.029920894
B33: Leases | C33: =Inputs!B49+Inputs!B45 -> 127039 | D33: =Inputs!C49+Inputs!C45 -> 102384 | E33: =Inputs!D49+Inputs!D45 -> 85375 | F33: =Inputs!E49+Inputs!E45 -> 75782 | G33: =Inputs!F49+Inputs!F45 -> 11200 | I33: Average
B34: Revenue | C34: 3981578 | D34: 3109106 | E34: 2493386 | F34: 2550305 | G34: 2481109 | I34: =AVERAGE(C35:G35) -> 0.026661327
B35: Leases/Revenue | C35: =C33/C34 -> 0.031906696 | D35: =D33/D34 -> 0.032930366 | E35: =E33/E34 -> 0.034240587 | F35: =F33/F34 -> 0.029714877 | G35: =G33/G34 -> 0.0045141104
I36: Average
B37: Working Capital Flows/Revenue Change | C37: =Inputs!B62/(Inputs!B6-Inputs!C6) -> -0.45063223 | D37: =Inputs!C62/(Inputs!C6-Inputs!D6) -> -0.37026083 | E37: =Inputs!D62/(Inputs!D6-Inputs!E6) -> -0.022523235 | F37: =Inputs!E62/(Inputs!E6-Inputs!F6) -> -1.3815683 | G37: =Inputs!F62/(Inputs!F6-Inputs!G6) -> -0.65093493 | I37: =AVERAGE(C37:G37) -> -0.5751839
B39: Payout ratio | C39: ='Fin. Data'!B36 -> -0.23847452 | D39: ='Fin. Data'!C36 -> -0.22849662 | E39: ='Fin. Data'!D36 -> -0.2990144 | F39: ='Fin. Data'!E36 -> -0.29127521 | G39: ='Fin. Data'!F36 -> -0.2243175 | I39: =AVERAGE(C39:G39) -> -0.25631565
B41: Company | C41: =Peers!C74 -> Daikin Industries,Ltd. (6367.T) | D41: =Peers!D74 -> #VALUE! | E41: =Peers!E74 -> #VALUE! | F41: =Peers!F74 -> #VALUE! | G41: =Peers!G74 -> #VALUE! | I41: Average
B42: Investment in R&D | C42: =102202*1000 -> 102202000 | D42: =(295*1000000)*147.37 -> 43474150000 | E42: =(539*1000000)*147.37 -> 79432430000 | F42: =(212.2*1000000)*147.37 -> 31271914000 | G42: =212.3*1000000000 -> 212300000000 | I42: =(C42*0.0076+D42+E42+F42+G42*0.0076)/5 -> 3.115855e+10
B43: Net Sales | C43: =Peers!C10*1000 -> 3981578000 | D43: =(25299*1000000)*147.37 -> 3728313630000 | E43: =20421*1000000*147.37 -> 3009442770000 | F43: =12640.8*1000000*147.37 -> 1862874696000 | G43: =Peers!G10*1000000 -> 692443000000 | I43: =(C43*0.0076+D43+E43+F43+G43*0.0076)/5 -> 1.7211848e+12
B44: R&D/Net Sales | C44: =C42/C43 -> 0.025668717 | D44: =D42/D43 -> 0.01166054 | E44: =E42/E43 -> 0.026394398 | F44: =F42/F43 -> 0.016786912 | G44: =G42/G43 -> 0.30659563 | I44: =AVERAGE(C44:G44) -> 0.07742124
G45: =59.1/1947.1 -> 0.030352832
B46: Investment in R&D (in dollars $) | C46: =C42*0.0076 -> 776735.2 | G46: =G42*0.0076 -> 1613480000
B47: Net Sales (in dollars $) | C47: =C43*0.0076 -> 30259993 | G47: =G43*0.0076 -> 5262566800

Sheet Fin. Data
A1: =Inputs!H3 -> Daikin Industries,Ltd. (6367.T)
A2: =Inputs!G2 -> Figures in Millions of JPY
A3: Results
B4: =OP!J17 -> 2022 | C4: =B4-1 -> 2021 | D4: =C4-1 -> 2020 | E4: =D4-1 -> 2019 | F4: =E4-1 -> 2018 | G4: =F4-1 -> 2017 | H4: =G4-1 -> 2016 | I4: =H4-1 -> 2015 | J4: =I4-1 -> 2014 | ... M4: =L4-1 -> 2011
A5: Net Sales | B5: =_xlfn.XLOOKUP($A5,Inputs!$A:$A,Inputs!B:B,,0) -> 3981578 | C5: =_xlfn.XLOOKUP($A5,Inputs!$A:$A,Inputs!C:C,,0) -> 3109106 | D5: =_xlfn.XLOOKUP($A5,Inputs!$A:$A,Inputs!D:D,,0) -> 2493386 | E5: =_xlfn.XLOOKUP($A5,Inputs!$A:$A,Inputs!E:E,,0) -> 2550305 | F5: =_xlfn.XLOOKUP($A5,Inputs!$A:$A,Inputs!F:F,,0) -> 2481109 | G5: =_xlfn.XLOOKUP($A5,Inputs!$A:$A,Inputs!G:G,,0) -> 2290560 | H5: =_xlfn.XLOOKUP($A5,Inputs!$A:$A,Inputs!H:H,,0) -> 2043968 | I5: =_xlfn.XLOOKUP($A5,Inputs!$A:$A,Inputs!I:I,,0) -> 2043691 | J5: =_xlfn.XLOOKUP($A5,Inputs!$A:$A,Inputs!J:J,,0) -> 1915013 | K5: =_xlfn.XLOOKUP($A5,Inputs!$A:$A,Inputs!K:K,,0) -> 1787679 | L5: =_xlfn.XLOOKUP($A5,Inputs!$A:$A,Inputs!L:L,,0) -> 1290903 | M5: =_xlfn.XLOOKUP($A5,Inputs!$A:$A,Inputs!M:M,,0) -> 1218700
A6: Growth vs. Previous year | B6: =IFERROR(B5/C5-1,"-") -> 0.28061829 | C6: =IFERROR(C5/D5-1,"-") -> 0.24694131 | D6: =IFERROR(D5/E5-1,"-") -> -0.022318507 | E6: =IFERROR(E5/F5-1,"-") -> 0.027889142 | F6: =IFERROR(F5/G5-1,"-") -> 0.083188827 | G6: =IFERROR(G5/H5-1,"-") -> 0.12064377 | H6: =IFERROR(H5/I5-1,"-") -> 0.00013553908 | I6: =IFERROR(I5/J5-1,"-") -> 0.067194322 | ... L6: =IFERROR(L5/M5-1,"-") -> 0.059245918 | M6: =IFERROR(M5/#REF!-1,"-") -> -
