Workbook
Name Sectors: '[1]Sector Impact'!$K$4:$K$16
Name Sectors: 'Sector Impact'!$K$4:$K$16

Sheet OP
B2: 45039 | C2: Team 1 | E2: =Inputs!H3 -> #VALUE! | L2: NASDAQ | M2: SIC:
D3: COMPANY DESCRIPTION | H3: CEO & BOARD OF DIRECTORS
D4: {=_FV(Inputs!H3,"Description")} -> Netflix, Inc. is a provider of entertainment services. The Company acquires, licenses and produces content, including original programming. The Company provides paid memberships in approximately 190 countries offering television (TV) series, films and games across a wide variety of genres and languages. Its members can play, pause and resume watching as much as they want, anytime, anywhere, and can change their plans at any time. The Company offers members the ability to receive streaming content through a host of Internet-connected devices, including TVs, digital video players, TV set-top boxes and mobile devices. The Company also has agreements with various cable, satellite and telecommunications operators to make its service available through TV set-top boxes. The Company's paid plans range from the United States dollar equivalent of $1 to $28 per month, and pricing on its extra member sub accounts range from the United States dollar equivalent of $2 to $8 per month. | H4: Name (Gender; Age) | I4: Tenure | J4: Executive? | K4: Other roles
H5: Theodore Sarandos (Male; 59) | I5: July 2020 3 Years | J5: Yes (Co-CEO) | K5: Board of Directors of Spotify Technologies SA, International Documentary Association, Exploring the Arts, Inc., American Film Institute Inc.
H6: Gregory Peters (Male; 52) | I6: January 2023 1 Year | J6: Yes (Co-CEO) | K6: Board of Directors of Highland Transcend Partners I Corp. and Doordash Inc.
H7: Reed Hastings (Male; 63) | I7: August 1998 25 Years | J7: Yes (Founder) | K7: Board of Directors of several Non-Profit Institutions
H8: Anne Sweeney (Female; 66) | I8: March 2015 9 Years | J8: No | K8: Board of Lego A/S, Board of Trustees at the Mayo Clinic and J.P. Getty Trust
H9: Richard Barton (Male; 56) | I9: April 2002 21 Years | J9: No | K9: CEO of Zillow Group, Board of Directors of QVC Group, Art.sy, Inc., Barton Family Foundation, Avvo, Inc. and Atom Digital, Inc.
H10: Timothy Haley (Male; 65) | I10: March 1998 26 Years | J10: No | K10: Managing Director of Insitutional Venture Partners
H11: Jay Hoag (Male; 62) | I11: May 1999 24 Years | J11: No | K11: Board of Directors of Zillow Group, Trip Advisor, Inc., Peloton Interactive, Inc., Menlo School, Vanderbilt University, Technology Crossover Management VIII Ltd. and Founder of TCMI, Inc.
H12: Ann Mather (Female; 63) | I12: July 2010 13 Years | J12: No | K12: Board of Directos of Bumble, Inc., Alphabet, Inc (also audit commitie), Blend Labs, Inc., Color Health, Inc., Dodge and Cox Funds
H13: Mathias Döpfner (Male; 61) | I13: September 2018 5 Years | J13: No | K13: CEO and part owner of Axel Springer SE, Board of Directors of Warner Music Group, office at American Academy, the American Jewish Commitie and the European Publisher Council
H14: Leslie Kilgore (Female; 58) | I14: January 2012 12 Years | J14: No | K14: Board of Directors of Pinterest Inc., Nextdoor Inc., Discord Inc.
H15: Strive Masiyiwa (Male; 63) | I15: December 2020 3 Years | J15: No | K15: Econet South Africa (Pty) Ltd CEO, Board of Directors of Unilever PLC, Bill & Melinda Gates Foundation, The Micronutrient Initiative/L'initiative Pour Les Micronutrim, Econet Investments Ltd. and Founder of Delta Philanthropies
H16: Susan Rice (Female; 59) | I16: September 2023 6 Months | J16: No | K16: Member of the Aspen Strategy Group, the American Academy of Diplomacy, and the Council on Foreign Relations, USA Ambassador at UN, President Bill Clinton and Barack Obama National Security Advisor, President Biden Domestic Policy Advisor
B17: USD MILLIONS | H17: Bradford Smith (Male; 65) | I17: March 2015 9 Years | J17: No | K17: Vice chair and President of Microsoft, Board of Directors of Code.org, The Seattle Foundation, Washington Roundtable and Leadership Council on Legal Diversity, Inc., chairman of Kind, Inc. (United States)
B18: COMPANY OVERVIEW
B19: Stock | D19: Liquidity and Solvency | F19: Segments | I19: Profitability (2023) | L19: Multiples
B20: Last Price | C20: {=_FV(E2,"Price")} -> 818.39 | D20: Total Assets | E20: =_xlfn.XLOOKUP(D20,'Fin. Data'!A:A,'Fin. Data'!B:B,,0) -> 48732 | F20: Regions | H20: % Sales | I20: Reporting Year | J20: 2023 | L20: Float | M20: 0.9848
B21: Outstanding Shares | C21: {=_FV(E2,"Shares outstanding",TRUE)} -> 427458100 | D21: Total Liabilities | E21: =_xlfn.XLOOKUP(D21,'Fin. Data'!A:A,'Fin. Data'!B:B,,0) -> 28144 | F21: =Segments!C5 -> United States and Canada (UCAN) | H21: =Segments!B5 -> 0.4435 | I21: End of Year | J21: 31 December 2023 | L21: Insiders Own | M21: 0.0138
B22: Market Cap. | C22: =C20*C21/1000000 -> 349827.43 | D22: Cash/Share | E22: =_xlfn.XLOOKUP("Cash & Eq.",'Fin. Data'!A:A,'Fin. Data'!B:B,,0)*1000000/C21 -> 16.698713 | F22: =Segments!C6 -> Europe, Middle East and Africa (EMEA) | H22: =Segments!B6 -> 0.313 | I22: EBITDA | K22: =_xlfn.XLOOKUP(I22,'Fin. Data'!A:A,'Fin. Data'!B:B,,0) -> 21508.3 | L22: b (Yahoo) | M22: 1.22
B23: +Total Debt | C23: ='Fin. Data'!B58 -> 16572 | D23: EBITDA/Net Financial Cost (NFC) | E23: =_xlfn.XLOOKUP("EBITDA",'Fin. Data'!A:A,'Fin. Data'!B:B,,0)/_xlfn.XLOOKUP("Net Financial Cost",'Fin. Data'!A:A,'Fin. Data'!B:B,,0) -> -28.716021 | F23: =Segments!C7 -> Latin America (LATAM) | H23: =Segments!B7 -> 0.1318 | I23: Depreciation & Amortization | K23: =_xlfn.XLOOKUP(I23,'Fin. Data'!A:A,'Fin. Data'!B:B,,0) -> 14554.3 | L23: Score (S&P) | M23: BBB+
B24: -Cash | C24: ='Fin. Data'!B39 -> 7138 | D24: Debt/EBITDA | E24: =_xlfn.XLOOKUP("Total Debt",'Fin. Data'!A:A,'Fin. Data'!B:B,,0)/_xlfn.XLOOKUP("EBITDA",'Fin. Data'!A:A,'Fin. Data'!B:B,,0) -> 0.77049325 | F24: =Segments!C8 -> Asia-Pacific (APAC) | H24: =Segments!B8 -> 0.1116 | I24: EBIT | K24: =_xlfn.XLOOKUP(I24,'Fin. Data'!A:A,'Fin. Data'!B:B,,0) -> 6954 | L24: Price/Book Value | M24: =IFERROR((C20*C21/(E20-E21))/1000000,"") -> 16.991812
B25: =Enterprise Value | C25: =C22+C23-C24 -> 359261.43 | D25: "Others Assets"/Asset | E25: =_xlfn.XLOOKUP("Other Assets",'Fin. Data'!A:A,'Fin. Data'!B:B,,0)/_xlfn.XLOOKUP("Total Assets",'Fin. Data'!A:A,'Fin. Data'!B:B,,0) -> 0.68648937 | F25: =Segments!C9 -> 0 | H25: =Segments!B9 -> 0 | I25: Net Income | K25: =_xlfn.XLOOKUP(I25,'Fin. Data'!A:A,'Fin. Data'!B:B,,0) -> 5408 | L25: NCF(3y avg)/Asset | M25: =IFERROR(K31/E20,"") -> 0.10271143
B26: Holdings (nac/int'l) | C26: - | D26: Debt/Assets | E26: =_xlfn.XLOOKUP(D26,'Fin. Data'!A:A,'Fin. Data'!B:B,,0) -> 0.34006402 | F26: Categories | H26: % Sales | I26: EPS | K26: =1000000*K25/C21 -> 12.651532 | L26: Price/Net Inc. (3y avg) | M26: =IFERROR(C22/K30,"") -> 69.890937
B27: t liq. (Holdings/Vol.) | C27: - | D27: EBITDA Margin (average) | E27: =AVERAGE(_xlfn.XLOOKUP("EBITDA Margin",'Fin. Data'!A:A,'Fin. Data'!B:D,,0)) -> 0.62582343 | F27: =Segments!C18 -> Streaming Content Services | H27: =Segments!B18 -> 0.99754357 | I27: ROA | K27: =K25/E20 -> 0.11097431 | L27: EV/Asset | M27: =IFERROR(C25/E20,"") -> 7.3721874
B28: % Short | C28: 0.0187 | D28: Operating Margin (average) | E28: =AVERAGE(_xlfn.XLOOKUP("Operating Margin",'Fin. Data'!A:A,'Fin. Data'!B:D,,0)) -> 0.19765953 | F28: =Segments!C20 -> 0 | H28: =Segments!B20 -> 0 | I28: ROIC | K28: =Peers!C17 -> 0.20187845 | L28: EV/Ebitda (3y average) | M28: =IFERROR(C25/K29,"") -> 18.109487
B29: Traffic ESG | D29: Net Income Margin (average) | E29: =AVERAGE(_xlfn.XLOOKUP("Net Income Margin",'Fin. Data'!A:A,'Fin. Data'!B:D,,0)) -> 0.15823759 | F29: =Segments!C21 -> 0 | H29: =Segments!B21 -> 0 | I29: EBITDA (3y average) | K29: =AVERAGE(_xlfn.XLOOKUP("EBITDA",'Fin. Data'!A:A,'Fin. Data'!B:D,,0)) -> 19838.3 | L29: Price/NCF (3y average) | M29: =IFERROR(C22/K31,"") -> 69.890937
B30: E | F30: =Segments!C22 -> 0 | H30: =Segments!B22 -> 0 | I30: Net Income (3y average) | K30: =AVERAGE(_xlfn.XLOOKUP("Net Income",'Fin. Data'!A:A,'Fin. Data'!B:D,,0)) -> 5005.3333 | L30: Bonds 1,3,5a (USD) | M30: -
B31: S | D31: Net Financial Cost/Avg Net Debt | E31: =-_xlfn.XLOOKUP("Net Financial Cost",'Fin. Data'!A:A,'Fin. Data'!B:B,,0)/AVERAGE(_xlfn.XLOOKUP("Net Debt",'Fin. Data'!A:A,'Fin. Data'!B:D,,0)) -> 0.070892226 | F31: =Segments!C23 -> 0 | H31: =Segments!B23 -> 0 | I31: NCF (3y average) | K31: =AVERAGE(_xlfn.XLOOKUP("Net Income",'Fin. Data'!A:A,'Fin. Data'!B:D,,0)) -> 5005.3333 | L31: Div+Rep.(3y avg)/Price | M31: =-IFERROR(SUM(E52:E54)/(3*C22),"") -> 0.0063319791
B32: G | L32: Div. Yield | M32: =-IFERROR(L53/C22,"") -> 0
B33: INVESTMENT THESIS
B34: Pillars of Recommendation | H34: Recommendation | I34: Valuation Assumptions
B35: Pillar | C35: Explanation | H35: SELL | I35: Check DCF
B36: Healthy Growth | C36: Since their global launch in 2016, they’ve been able to invest heavily in our slate — with content amortization up almost 3X from $4.8B in 2016 to $14.2B in 2023 — while steadily increasing our operating margins (up more than 5X, from 4% to 21% over the same period) and growing our free cash flow (from negative $3.3B in 2019 to positive $6.9B in 2023).
B37: Strategy and Inovation | C37: Netflix plans to continue to invest in and build ads business, expecting strong growth in 2024 but off a small base so it’s not yet a primary driver of the overall revenue growth. However it aims to make ads a more substantial revenue stream that contributes to sustained, healthy revenue growth in 2025 and beyond.
B38: Improvement | C38: Netflix is establishing itself in new areas like advertising and games, which they believe to have a lot more room to grow. Theres a $600B+ opportunity revenue market across pay TV, film, games and branded advertising — and today Netflix accounts for only roughly 5% of that addressable market. And their share of TV viewing is still less than 10% in every country.
B39: Risks of Investment | H39: Price Target | I39: Valuation
B40: Risk | C40: Explanation | H40: =DCF!D76 -> 354.75131 | I40: Discount Rate | J40: =DCF!F50 -> 0.088 | L40: Price M. Upside | M40: =#REF! -> #REF!
B41: Content Costs | C41: With the persuit of original content, Netflix sees its costs increse significantly potentially lowering its margins
...

Sheet Segments
B2: ="Regions "&"("&OP!$J$20&")" -> Regions (2023) | Q2: Products
D3: Nominal value | K3: YoY Growth
B4: Weight | C4: Region | D4: 2023 | E4: =D4-1 -> 2022 | F4: =E4-1 -> 2021 | G4: =F4-1 -> 2020 | H4: =G4-1 -> 2019 | I4: =H4-1 -> 2018 | K4: =OP!J20 -> 2023 | L4: =K4-1 -> 2022 | M4: =L4-1 -> 2021 | N4: =M4-1 -> 2020 | O4: =N4-1 -> 2019 | P4: =O4-1 -> 2018
B5: 0.4435 | C5: United States and Canada (UCAN) | D5: 14957 | E5: 14230 | F5: 13154 | G5: 11695 | K5: =(D5-E5)/E5 -> 0.051089248 | L5: =(E5-F5)/F5 -> 0.081800213 | M5: =(F5-G5)/G5 -> 0.12475417 | P5: -
B6: 0.313 | C6: Europe, Middle East and Africa (EMEA) | D6: 10556 | E6: 9745 | F6: 9700 | G6: 7772 | K6: =(D6-E6)/E6 -> 0.083222165 | L6: =(E6-F6)/F6 -> 0.0046391753 | M6: =(F6-G6)/G6 -> 0.24806999 | P6: -
B7: 0.1318 | C7: Latin America (LATAM) | D7: 4446 | E7: 4070 | F7: 3577 | G7: 3157 | K7: =(D7-E7)/E7 -> 0.092383292 | L7: =(E7-F7)/F7 -> 0.13782499 | M7: =(F7-G7)/G7 -> 0.13303769 | P7: -
B8: 0.1116 | C8: Asia-Pacific (APAC) | D8: 3764 | E8: 3570 | F8: 3267 | G8: 2372 | K8: =(D8-E8)/E8 -> 0.054341737 | L8: =(E8-F8)/F8 -> 0.092745638 | M8: =(F8-G8)/G8 -> 0.37731872 | P8: -
P9: -
P10: -
B11: =IFERROR(D11/$D$13,"") -> 0
B12: =IFERROR(D12/$D$13,"") -> 0
B13: =SUM(B5:B12) -> 0.9999 | C13: TOTAL | D13: =SUM(D5:D12) -> 33723 | E13: =SUM(E5:E12) -> 31615 | F13: =SUM(F5:F12) -> 29698 | G13: =SUM(G5:G12) -> 24996 | H13: =SUM(H5:H12) -> 0 | I13: =SUM(I5:I12) -> 0 | K13: =(D13-E13)/E13 -> 0.06667721 | L13: =(E13-F13)/F13 -> 0.064549801 | M13: =(F13-G13)/G13 -> 0.1881101 | N13: =(G13-H13)/H13 -> #DIV/0! | O13: =(H13-I13)/I13 -> #DIV/0! | P13: -
B15: ="Categories "&"("&OP!$J$20&")" -> Categories (2023)
D16: Nominal value | K16: YoY Growth
B17: Weight | C17: Category | D17: 2023 | E17: =D17-1 -> 2022 | F17: =E17-1 -> 2021 | G17: =F17-1 -> 2020 | H17: =G17-1 -> 2019 | I17: =H17-1 -> 2018 | K17: =OP!J20 -> 2023 | L17: =K17-1 -> 2022 | M17: =L17-1 -> 2021 | N17: =M17-1 -> 2020 | O17: =N17-1 -> 2019 | P17: =O17-1 -> 2018
B18: =IFERROR(D18/$D$24,"") -> 0.99754357 | C18: Streaming Content Services | D18: 33640.458 | E18: 31468.852 | F18: 29515.496 | G18: 24756.675 | H18: 19859.23 | I18: 15428.752 | K18: =(D18-E18)/E18 -> 0.06900811 | L18: =(E18-F18)/F18 -> 0.066180694 | M18: =(F18-G18)/G18 -> 0.19222375 | N18: =(G18-H18)/H18 -> 0.246608 | O18: =(H18-I18)/I18 -> 0.28715725 | P18: -
B19: =IFERROR(D19/$D$24,"") -> 0.0024564324 | C19: DVD services | D19: 82.839 | E19: 145.698 | F19: 182.348 | G19: 239.381 | H19: 297.217 | I19: 365.589
B20: =IFERROR(D20/$D$24,"") -> 0
B21: =IFERROR(D21/$D$24,"") -> 0
B22: =IFERROR(D22/$D$24,"") -> 0
B23: =IFERROR(D23/$D$24,"") -> 0 | P23: -
B24: =SUM(B18:B23) -> 1 | C24: TOTAL | D24: =SUM(D18:D23) -> 33723.297 | E24: =SUM(E18:E23) -> 31614.55 | F24: =SUM(F18:F23) -> 29697.844 | G24: =SUM(G18:G23) -> 24996.056 | H24: =SUM(H18:H23) -> 20156.447 | I24: =SUM(I18:I23) -> 15794.341 | K24: =(D24-E24)/E24 -> 0.066701788 | L24: =(E24-F24)/F24 -> 0.064540241 | M24: =(F24-G24)/G24 -> 0.18810119 | N24: =(G24-H24)/H24 -> 0.24010229 | O24: =(H24-I24)/I24 -> 0.27618158 | P24: -
B26: Categories | D26: Description | I26: Graphs
B27: Streaming content services | D27: Consists in revenues earned mostly from membership fees for services related to streaming content to their members.
B28: DVD services | D28: DVD-by-mail service. This operation was discontinued in september 29, 2023
B34: Industry | J34: Graphs (Industry Forecasts)
B35: Drivers | D35: Description
B36: AI | D36: By providing real-time insight into stream quality, user behavior, and content optimization on a micro level, AI can help aid engineering, development, and marketing teams simultaneously.
B37: Subscription Tiers | D37: Panning ads, no ads, access to all content, access to limited content, monthly and yearly subscriptions, bundles, and potentially new innovations such as loyalty plans. With more options, streamers may be better able to reduce churn—the rate at which people cancel their subscriptions—and keep more subscribers around for longer.
B38: Sales forecast
B39: Source | D39: Market Growth CAGR | G39: Period
B40: Statista | D40: 0.0989 | G40: 2024-2028
B41: Grand View Research | D41: 0.215 | G41: 2023-2030
B44: Company's Strategy / Extra Notes
B47: "Our core strategy is to grow our business globally within the parameters of our operating margin target. We strive to continuously improve our members' experience by offering compelling content that delights them and attracts new members. We seek to drive conversation around our content to further enhance member joy, and we are continuously enhancing our user interface to help our members more easily choose content that they will find enjoyable."

Sheet Acuerdo
A1: Invertir
A2: NO invertir
A3: Mantener sin elevar posición
A4: Mantener (y seguir comprando)
A5: Liquidar
A6: PENDIENTE

Sheet Peers
B1: Peer Logo | C1: Peer Name | D1: Description
C2: #VALUE! | D2: The Walt Disney Company is a diversified company that offers a variety of streaming services to cater to different interests: Disney+: This flagship service focuses on family-friendly content, including Disney and Marvel movies and TV shows. Hulu (US only): Provides a mix of original shows, popular network programs, and movies, geared towards a more general audience. ESPN+: A sports fan's haven, offering live and on-demand sports events, documentaries, and original programming. With this range of options (there is more 2 than this), Disney covers a wide spectrum of viewers, from families with young children to sports enthusiasts and those seeking general entertainment.
C3: #VALUE! | D3: Warner Bros. Discovery is a global media and entertainement company. They has streamlined its streaming offerings into two main services: Max: This is the home for scripted dramas, comedies, movies, and animation. It boasts content from Warner Bros., HBO, DC Comics, and even some Discovery Channel favorites. Discovery+: For reality TV and documentary lovers, Discovery+ offers a vast library of shows on nature, science, exploration, true crime, and lifestyle topics from channels like Discovery, TLC, HGTV, and Food Network. This combined approach lets Warner Bros. Discovery cater to both fans of scripted entertainment and those who prefer factual programming.
C4: #VALUE! | D4: Amazon.com,Inc. provides a range of products and services to costumers. The streaming landscape can be broken down into two main parts: Prime Video: This is included with a Prime membership, offering a mix of Amazon Original movies and TV shows, popular licensed content, and rentals/purchases. Prime Video caters to a broad audience with something for families, action movie buffs, and comedy lovers. Prime Video Channels: This is an add-on service where you can subscribe to individual channels like Paramount+, Starz, or AMC+, providing access to their specific libraries of shows and movies. Prime Video Channels allows viewers to personalize their streaming experience by adding channels that align with their interests. So, Amazon offers both a general streaming service with Prime Video and the option to expand your choices with targeted channels.
C5: #VALUE! | D5: Apple.Inc designs, manufactures and sell smartphones, personal computers, tablets, wearable and accessories, and, as well, a variety of related services. Apple takes a more focused approach to streaming with its service: Apple TV+: This subscription service features Apple Originals – critically acclaimed shows, movies, and documentaries across genres, from comedies and dramas to kids content. New Apple Originals are added regularly, giving viewers something fresh to discover. While Apple TV+ doesn't offer the vast library of other streaming services, it emphasizes high-quality, exclusive content. It caters to viewers who value curated entertainment and are willing to pay for a smaller but prestigious selection.
B7: In Millions USD | C7: =OP!E2 -> #VALUE! | D7: =C2 -> #VALUE! | E7: =C3 -> #VALUE! | F7: =C4 -> #VALUE! | G7: =C5 -> #VALUE! | H7: AVERAGE | I7: Deviation from Average
B8: Company Info | H8: =IFERROR(AVERAGE(C8:G8),"") | K8: TRAFFIC
B9: Market Cap | C9: {=_FV(C7,"Market cap",TRUE)/1000000} -> 349827.43 | D9: {=_FV(D7,"Market cap",TRUE)/1000000} -> 182700.75 | E9: {=_FV(E7,"Market cap",TRUE)/1000000} -> 22545.294 | F9: {=_FV(F7,"Market cap",TRUE)/1000000} -> 2194587.7 | G9: {=_FV(G7,"Market cap",TRUE)/1000000} -> 3387939 | H9: =IFERROR(AVERAGE(C9:G9),"") -> 1227520 | I9: =SQRT((C9-H9)^2) -> 877692.6 | L9: Best Value
B10: Net Sales (current) | C10: =C55 -> 33723 | D10: =D55 -> 88935 | E10: =E55 -> 41321 | F10: =F55 -> 574785 | G10: =G55 -> 385706 | H10: =IFERROR(AVERAGE(C10:G10),"") -> 224894 | I10: =SQRT((C10-H10)^2) -> 191171
B11: Profitability | H11: =IFERROR(AVERAGE(C11:G11),"") | L11: Important Value
B12: Sales Growth (ttm) | C12: =C55/C54-1 -> 0.066643472 | D12: =D55/D54-1 -> 0.075106985 | E12: =E55/E54-1 -> 0.22190023 | F12: =F55/F54-1 -> 0.11829574 | G12: =G55/G54-1 -> -0.021865046 | H12: =IFERROR(AVERAGE(C12:G12),"") -> 0.092016276 | I12: =SQRT((C12-H12)^2) -> 0.025372804
B13: Sales Growth (36m) | C13: =C55/C53-1 -> 0.34913586 | D13: =D55/D53-1 -> 0.36011195 | E13: =E55/E53-1 -> 2.8722706 | F13: =F55/F53-1 -> 0.48883346 | G13: =G55/G53-1 -> 0.40504526 | H13: =IFERROR(AVERAGE(C13:G13),"") -> 0.89507943 | I13: =SQRT((C13-H13)^2) -> 0.54594357 | L13: Worst Value
B14: Operating Margin | C14: =C58/C55 -> 0.20620941 | D14: =D58/D55 -> 0.1117108 | E14: =E58/E55 -> -0.021441882 | F14: =F58/F55 -> 0.064114408 | G14: =G58/G55 -> 0.30763846 | H14: =IFERROR(AVERAGE(C14:G14),"") -> 0.13364624 | I14: =SQRT((C14-H14)^2) -> 0.072563172
B15: Net Income Margin | C15: =C61/C55 -> 0.16036533 | D15: =D61/D55 -> 0.033575083 | E15: =E61/E55 -> -0.075651606 | F15: =F61/F55 -> 0.052932836 | G15: =G61/G55 -> 0.26163192 | H15: =IFERROR(AVERAGE(C15:G15),"") -> 0.086570712 | I15: =SQRT((C15-H15)^2) -> 0.073794618
B16: Return on Equity (RoE) | C16: =C61/C73 -> 0.26267729 | D16: =D61/D73 -> 0.026421973 | E16: =E61/E73 -> -0.067266311 | F16: =F61/F73 -> 0.15071207 | G16: =G61/G73 -> 1.6238052 | H16: =IFERROR(AVERAGE(C16:G16),"") -> 0.39927005 | I16: =SQRT((C16-H16)^2) -> 0.13659276
B17: Return on Invested Capital (ROIC) | C17: =(1+C60/(C58+C59))*C58/(C72+C73-C64) -> 0.20187845 | D17: =(1+D60/(D58+D59))*D58/(D72+D73-D64) -> 0.053965889 | E17: =(1+E60/(E58+E59))*E58/(E72+E73-E64) -> -0.0075122454 | F17: =(1+F60/(F58+F59))*F58/(F72+F73-F64) -> 0.11841239 | G17: =(1+G60/(G58+G59))*G58/(G72+G73-G64) -> 0.90483586 | H17: =IFERROR(AVERAGE(C17:G17),"") -> 0.25431607 | I17: =SQRT((C17-H17)^2) -> 0.052437618
B18: Solvency | H18: =IFERROR(AVERAGE(C18:G18),"")
B19: Debt/Assets | C19: =C72/C69 -> 0.34006402 | D19: =D72/D69 -> 0.24270475 | E19: =E72/E69 -> 0.35573531 | F19: =F72/F69 -> 0.25691005 | G19: =G72/G69 -> 0.31506908 | H19: =IFERROR(AVERAGE(C19:G19),"") -> 0.30209664 | I19: =SQRT((C19-H19)^2) -> 0.03796738
B20: Net Debt/EBITDA | C20: =(C72-C64)/C57 -> 0.43862137 | D20: =(D72-D64)/D57 -> 2.7036869 | E20: =(E72-E64)/E57 -> 1.7833862 | F20: =(F72-F64)/F57 -> 0.54619583 | G20: =(G72-G64)/G57 -> 0.37109764 | H20: =IFERROR(AVERAGE(C20:G20),"") -> 1.1685976 | I20: =SQRT((C20-H20)^2) -> 0.72997622
B21: Interest Coverage Ratio | C21: =-C57/C59 -> 28.716021 | D21: =-D57/D59 -> 11.436364 | E21: =-E57/E59 -> 10.953477 | F21: =-F57/F59 -> 383.69957 | G21: =-G57/G59 -> 236.24248 | H21: =IFERROR(AVERAGE(C21:G21),"") -> 134.20958 | I21: =SQRT((C21-H21)^2) -> 105.49356
B22: Liquidity
B23: Current Ratio | C23: =C67/C71 -> 1.1192868 | D23: =D67/D71 -> 1.0521532 | E23: =E67/E71 -> 0.92734151 | F23: =F67/F71 -> 1.0450772 | G23: =G67/G71 -> 0.98801167 | H23: =IFERROR(AVERAGE(C23:G23),"") -> 1.0263741 | I23: =SQRT((C23-H23)^2) -> 0.09291268
B24: Quick Ratio | C24: =(C64+C65)/C71 -> 0.95079562 | D24: =(D64+D65)/D71 -> 0.78233084 | E24: =(E64+E65)/E71 -> 0.64094704 | F24: =(F64+F65)/F71 -> 0.84304832 | G24: =(G64+G65)/G71 -> 0.62668951 | H24: =IFERROR(AVERAGE(C24:G24),"") -> 0.76876227 | I24: =SQRT((C24-H24)^2) -> 0.18203335
B25: Activity | H25: =IFERROR(AVERAGE(C25:G25),"")
B26: Inventory Turnover | C26: 0 | D26: =D56/D66 -> 29.751401 | E26: 0 | F26: =F56/F66 -> 14.436041 | G26: =G56/G66 -> 33.49155 | H26: =IFERROR(AVERAGE(C26:G26),"") -> 15.535798 | I26: =SQRT((C26-H26)^2) -> 15.535798
B27: Acc. Receivable Turnover | C27: =C55/C65 -> 26.202797 | D27: =D55/D65 -> 8.7371058 | E27: =E55/E65 -> 6.8333058 | F27: =F55/F65 -> 11.000038 | G27: =G55/G65 -> 13.071235 | H27: =IFERROR(AVERAGE(C27:G27),"") -> 13.168896 | I27: =SQRT((C27-H27)^2) -> 13.033901
A28: Price/Sales | B28: Payables Turnover | C28: =C56/C70 -> 3.7811661 | D28: =D56/D70 -> 3.8612893 | E28: =E56/E70 -> 19.465079 | F28: =F56/F70 -> 5.6598534 | G28: =G56/G70 -> 3.3865455 | H28: =IFERROR(AVERAGE(C28:G28),"") -> 7.2307867 | I28: =SQRT((C28-H28)^2) -> 3.4496206
B29: Fixed Asset Turnover | C29: =C55/C68 -> 7.624463 | D29: =D55/D68 -> 1.1467937 | E29: =E55/E68 -> 4.569896 | F29: =F55/F68 -> 1.4485473 | G29: =G55/G68 -> 3.3657013 | H29: =IFERROR(AVERAGE(C29:G29),"") -> 3.6310803 | I29: =SQRT((C29-H29)^2) -> 3.9933828
B30: Total Asset Turnover | C30: =C55/C69 -> 0.69200936 | D30: =D55/D69 -> 0.43260742 | E30: =E55/E69 -> 0.3366081 | F30: =F55/F69 -> 1.0889091 | G30: =G55/G69 -> 1.0939438 | H30: =IFERROR(AVERAGE(C30:G30),"") -> 0.72881555 | I30: =SQRT((C30-H30)^2) -> 0.036806195
B31: Valuation | H31: =IFERROR(AVERAGE(C31:G31),"")
B32: Price/Earnings | C32: =C9/C61 -> 64.687026 | D32: =D9/D61 -> 61.185785 | E32: =E9/E61 -> -7.2121862 | F32: =F9/F61 -> 72.131068 | G32: =G9/G61 -> 33.572869 | H32: =IFERROR(AVERAGE(C32:G32),"") -> 44.872912 | I32: =SQRT((C32-H32)^2) -> 19.814113
B33: Price/Sales | C33: =C9/C55 -> 10.373556 | D33: =D9/D55 -> 2.0543178 | E33: =E9/E55 -> 0.54561347 | F33: =F9/F55 -> 3.818102 | G33: =G9/G55 -> 8.7837342 | H33: =IFERROR(AVERAGE(C33:G33),"") -> 5.1150647 | I33: =SQRT((C33-H33)^2) -> 5.2584914
B34: Price/Book | C34: =C9/C73 -> 16.991812 | D34: =D9/D73 -> 1.6166492 | E34: =E9/E73 -> 0.48513716 | F34: =F9/F73 -> 10.871023 | G34: =G9/G73 -> 54.515801 | H34: =IFERROR(AVERAGE(C34:G34),"") -> 16.896085 | I34: =SQRT((C34-H34)^2) -> 0.09572792
B35: EV/Sales | C35: =(C72+C9-C64)/C55 -> 10.653306 | D35: =(D72+D9-D64)/D55 -> 2.4558807 | E35: =(E72+E9-E64)/E55 -> 1.510958 | F35: =(F72+F9-F64)/F55 -> 3.9030572 | G35: =(G72+G9-G64)/G55 -> 8.9121558 | H35: =IFERROR(AVERAGE(C35:G35),"") -> 5.4870715 | I35: =SQRT((C35-H35)^2) -> 5.1662344
B36: EV/EBITDA | C36: =(C72+C9-C64)/C57 -> 16.703386 | D36: =(D72+D9-D64)/D57 -> 16.535223 | E36: =(E72+E9-E64)/E57 -> 2.7913575 | F36: =(F72+F9-F64)/F57 -> 25.093608 | G36: =(G72+G9-G64)/G57 -> 25.753291 | H36: =IFERROR(AVERAGE(C36:G36),"") -> 17.375373 | I36: =SQRT((C36-H36)^2) -> 0.67198702
B37: Stock Info | H37: =IFERROR(AVERAGE(C37:G37),"")
B38: Float | C38: =OP!M20 -> 0.9848 | D38: 1 | E38: 0.902 | F38: 0.887 | G38: 0.998 | H38: =IFERROR(AVERAGE(C38:G38),"") -> 0.95436 | I38: =SQRT((C38-H38)^2) -> 0.03044
B39: b (Yahoo) | C39: =OP!M22 -> 1.22 | D39: 1.41 | E39: 1.51 | F39: 1.17 | G39: 1.29 | H39: =IFERROR(AVERAGE(C39:G39),"") -> 1.32 | I39: =SQRT((C39-H39)^2) -> 0.1
B40: Dividend Yield (yahoo finance) | C40: =OP!M32 -> 0 | D40: 0.0027 | E40: 0 | F40: 0 | G40: 0.0056 | H40: =IFERROR(AVERAGE(C40:G40),"") -> 0.00166 | I40: =SQRT((C40-H40)^2) -> 0.00166
B41: Stock Performance
...

Sheet ESG
B1: Company GICS Sector: | T1: Yes
B2: Communication Services | C2: <- Select Industry | T2: No
B3: ESG Analysis | K3: Relative ESG Analysis
B4: Parameters | C4: Impact | D4: Do they report? | E4: Ranking | F4: Mitigation Plan | G4: Traffic Lights | H4: Improvement over time? | I4: Targets / Goals? | J4: Comments | K4: Parameters | L4: =Peers!C7 -> #VALUE! | M4: =Peers!D7 -> #VALUE! | N4: =Peers!E7 -> #VALUE! | O4: =Peers!F7 -> #VALUE! | P4: =Peers!G7 -> #VALUE! | Q4: =Peers!#REF! -> #REF! | R4: AVERAGE
B5: Environmental | K5: Ratios
A6: 1 | B6: CO2 Direct Emissions | C6: =VLOOKUP($B$2,'Sector Impact'!$K$4:$AA$16,A6+1,FALSE) -> Low | K6: CO2 Emissions/$M Sales | L6: =L12/L$11 -> 34.097483 | M6: =M12/M$11 -> 75.335919 | N6: =N12/N$11 -> 65.390479 | O6: =O12/O$11 -> 124.46393 | P6: =P12/P$11 -> 53.408555 | Q6: 0 | R6: =IFERROR(AVERAGE(L6:P6),"") -> 70.539273
A7: 2 | B7: Total Water Consumption | C7: =VLOOKUP($B$2,'Sector Impact'!$K$4:$AA$16,A7+1,FALSE) -> Low | K7: Water Consumption/$M Sales | L7: =L13/L$11 -> #VALUE! | M7: =M13/M$11 -> 340.50711 | N7: =N13/N$11 -> #VALUE! | O7: =O13/O$11 -> #VALUE! | P7: =P13/P$11 -> 13.870668 | Q7: 0 | R7: =IFERROR(AVERAGE(L7:P7),"")
A8: 3 | B8: Total Energy Consumption | C8: =VLOOKUP($B$2,'Sector Impact'!$K$4:$AA$16,A8+1,FALSE) -> Medium | D8: Yes | E8: Medium | F8: Yes | K8: Energy Consumption/$M Sales | L8: =L14/L$11 -> #VALUE! | M8: =M14/M$11 -> #VALUE! | N8: =N14/N$11 -> #VALUE! | O8: =O14/O$11 -> #VALUE! | P8: =P14/P$11 -> #VALUE! | Q8: 0 | R8: =IFERROR(AVERAGE(L8:P8),"")
A9: 4 | B9: Waste Management | C9: =VLOOKUP($B$2,'Sector Impact'!$K$4:$AA$16,A9+1,FALSE) -> Low | K9: Waste Production/$M Sales | L9: =L15/L$11 -> #VALUE! | M9: =M15/M$11 -> 1.7091134 | N9: =N15/N$11 -> #VALUE! | O9: =O15/O$11 -> 0.55846969 | P9: =P15/P$11 -> 0.13608811 | Q9: 0 | R9: =IFERROR(AVERAGE(L9:P9),"")
A10: 5 | B10: Land Degradation/Deforestation/Biodiversity loss/Animal sufering/… | C10: =VLOOKUP($B$2,'Sector Impact'!$K$4:$AA$16,A10+1,FALSE) -> Low | K10: Inputs
B11: Social | K11: Net Sales ($M) | L11: 33616 | M11: 88935 | N11: 41321 | O11: 574785 | P11: 385706
A12: 6 | B12: Employee Turnover % | C12: =VLOOKUP($B$2,'Sector Impact'!$K$4:$AA$16,A12+1,FALSE) -> Medium | D12: No | E12: "Best in class" | F12: No | J12: Their employee turnover is only 11% a year, which is below the 13% annual average for tech companies. | K12: CO2 Emissions Total (Tonnes) | L12: 1146221 | M12: 6700000 | N12: 2702000 | O12: 71540000 | P12: 20600000
A13: 7 | B13: Salaries & Compensation | C13: =VLOOKUP($B$2,'Sector Impact'!$K$4:$AA$16,A13+1,FALSE) -> Medium | D13: No | E13: Medium High | F13: No | J13: The company's employees rate the overall compensation and benefits package at 4.5 out of 5 stars. | K13: Water Consumption Total (Cubic Meters) | L13: N / A | M13: 30283000 | N13: N/A | O13: N / A | P13: 5350000
A14: 8 | B14: Reputation | C14: =VLOOKUP($B$2,'Sector Impact'!$K$4:$AA$16,A14+1,FALSE) -> Low | K14: Energy Consumption Total (Gigajoules) | L14: N / A | M14: N / A | N14: N / A | O14: N / A | P14: N / A
A15: 9 | B15: Discrimination Events | C15: =VLOOKUP($B$2,'Sector Impact'!$K$4:$AA$16,A15+1,FALSE) -> Low | F15: Yes | K15: Waste Production Total (Tonnes) | L15: N / A | M15: 152000 | N15: N / A | O15: 321000 | P15: 52490
A16: 10 | B16: Work Safety | C16: =VLOOKUP($B$2,'Sector Impact'!$K$4:$AA$16,A16+1,FALSE) -> High | D16: Yes | E16: Medium High | F16: Yes | I16: None | J16: Netflix employees rate work safety at 4.2 ou of 5 stars. | K16: ESG Scores
A17: 11 | B17: Damage to consumer health | C17: =VLOOKUP($B$2,'Sector Impact'!$K$4:$AA$16,A17+1,FALSE) -> Low | I17: None | K17: Refinitiv | L17: 40 | M17: 68 | N17: 60 | O17: 78 | P17: 80
A18: 12 | B18: PXP? | C18: =VLOOKUP($B$2,'Sector Impact'!$K$4:$AA$16,A18+1,FALSE) -> Low | K18: Sustainalytics | L18: 16.3 (Low risk) | M18: 15.7 (Low risk) | N18: 19.9 (Low risk) | O18: 30.5 (High risk) | P18: 17.2 (Low risk)
A19: 13 | B19: Supply chain | C19: =VLOOKUP($B$2,'Sector Impact'!$K$4:$AA$16,A19+1,FALSE) -> Low | I19: None | K19: ISS | L19: C- | M19: C | N19: D+ | O19: C- | P19: B
A20: 14 | B20: Community involvement | C20: =VLOOKUP($B$2,'Sector Impact'!$K$4:$AA$16,A20+1,FALSE) -> Low | K20: CDP | L20: F | M20: B | N20: N / A | O20: B | P20: A-
A21: 15 | B21: Public Sector | C21: =VLOOKUP($B$2,'Sector Impact'!$K$4:$AA$16,A21+1,FALSE) -> Low | I21: None
A22: 16 | B22: Litigation | C22: =VLOOKUP($B$2,'Sector Impact'!$K$4:$AA$16,A22+1,FALSE) -> Medium | D22: No | E22: Medium High | F22: No | I22: None | J22: Netflix was just the target of a lawsuit recently regarding account sharing, but won in court
B23: Corporate Governance | K23: PARAMETERS
A24: 17 | B24: Diversity (Gender, Age, Industry, Region) | E24: Medium | F24: No | I24: None | J24: The board is composed by 3 women,9 men, 1 black peaople and 11 white people. The average age is 66 years old. | K24: IMPACT | L24: RANKING | M24: MITIGATION PLAN | O24: TRAFFIC
A25: 18 | B25: % Independence | E25: Medium High | F25: No | I25: None | J25: 75% of the board is independent. | K25: Low | L25: "Best in class" | M25: Is there evidence of a plan/program ?
A26: 19 | B26: average time as independent directors | E26: Medium | F26: No | I26: None | J26: The average age of independent directors is 14 years old. | K26: Medium | L26: Medium High
A27: 20 | B27: Recent departures of directors / C-level executives? | E27: Medium High | F27: No | I27: None | K27: High | L27: Medium
A28: 21 | B28: CEO/Chairman duality | E28: "Best in class" | F28: No | I28: None | J28: The CEO and Chairman are not the same person. | K28: Very high | L28: "Villain"
A29: 22 | B29: Transparency (ESG, segments, acquisitions, other) | E29: Medium High | F29: No | I29: None
A30: 23 | B30: Time taken to report after the end of the quarter / year | E30: "Best in class" | F30: No | I30: None | J30: They took about 1 month to report their last year's anunal report.
A31: 24 | B31: Additional participation of the CEO in other boards or excessive participation of Ch. | E31: Medium | F31: No | I31: None | J31: 9 of the 12 board members are members of the board of directors part of other companies.
A32: 25 | B32: Audit / Consulting | D32: Yes | E32: Medium | F32: No | I32: None | J32: Netflix paid a lot of tax fees in the last year
A33: 26 | B33: ESG-compensation related | D33: No | E33: Medium | F33: No | I33: None
A34: 27 | B34: Management compensation schemes | D34: No | E34: Medium | F34: No | I34: None | J34: Netflix recognizes that they don't have wide support for our executive compensation model of the last 20 years.

Sheet DCF
A1: VALUATION MODEL
G3: Short Term | K3: Long Term
A4: Section | B4: Line # | C4: ITEM | D4: 2021 (Real) | E4: 2022 (Real) | F4: 2023 (Real) | G4: 2024 | H4: =G4+1 -> 2025 | I4: =H4+1 -> 2026 | J4: =I4+1 -> 2027 | K4: =J4+1 -> 2028 | L4: =K4+1 -> 2029 | M4: =L4+1 -> 2030 | N4: =M4+1 -> 2031 | O4: =N4+1 -> 2032 | ... AF4: =AE4+1 -> 2049
A5: INCOME STATEMENT | B5: 1 | C5: Growth | D5: ='Fin. Data'!D6 -> 0.1881101 | E5: =+E6/D6-1 -> 0.064583474 | F5: =+F6/E6-1 -> 0.066643472 | G5: =+G6/F6-1 -> 0.13345669 | H5: =+H6/G6-1 -> 0.13876535 | I5: =+I6/H6-1 -> 0.14407401 | J5: =+J6/I6-1 -> 0.14938268 | K5: =+K6/J6-1 -> 0.15469134 | L5: =+L6/K6-1 -> 0.16 | ... AF5: =+AF6/AE6-1 -> 0.02
B6: 2 | C6: Revenues/Sales | D6: =Inputs!D6 -> 29698 | E6: =Inputs!C6 -> 31616 | F6: =Inputs!B6 -> 33723 | G6: =Assumptions!C66 -> 38223.56 | H6: =Assumptions!D66 -> 43527.666 | I6: =Assumptions!E66 -> 49798.871 | J6: =Assumptions!F66 -> 57237.96 | K6: =Assumptions!G66 -> 66092.177 | L6: =Assumptions!H66 -> 76666.925 | M6: =Assumptions!I66 -> 87193.958 | N6: =Assumptions!J66 -> 97187.896 | ... AF6: =Assumptions!AB66 -> 155769.04
B7: 3 | C7: EBIT/Operating Margin | D7: =D8/D6 -> 0.20859991 | E7: =E8/E6 -> 0.17816928 | F7: =F8/F6 -> 0.20620941 | G7: =Assumptions!C77 -> 0.24 | H7: =Assumptions!D77 -> 0.242 | I7: =Assumptions!E77 -> 0.244 | J7: =Assumptions!F77 -> 0.246 | K7: =Assumptions!G77 -> 0.248 | L7: =Assumptions!H77 -> 0.25 | M7: =Assumptions!I77 -> 0.252 | N7: =Assumptions!J77 -> 0.254 | ... AF7: =Assumptions!AB77 -> 0.26
B8: 4 | C8: EBIT | D8: ='Fin. Data'!D11 -> 6195 | E8: ='Fin. Data'!C11 -> 5633 | F8: ='Fin. Data'!B11 -> 6954 | G8: =G7*G6 -> 9173.6544 | H8: =H7*H6 -> 10533.695 | I8: =I7*I6 -> 12150.925 | J8: =J7*J6 -> 14080.538 | K8: =K7*K6 -> 16390.86 | L8: =L7*L6 -> 19166.731 | M8: =M7*M6 -> 21972.877 | N8: =N7*N6 -> 24685.726 | ... AF8: =AF7*AF6 -> 40499.951
B9: 5a | C9: (Dep) | D9: -208 | E9: -337 | F9: -357 | G9: =$D$53*DCF!F40 -> -451.14636 | H9: =$D$53*DCF!G40 -> -508.35612 | I9: =$D$53*DCF!H40 -> -573.5046 | J9: =$D$53*DCF!I40 -> -648.03929 | K9: =$E$53*DCF!J40 -> -431.5927 | L9: =$E$53*DCF!K40 -> -460.68712 | M9: =$E$53*DCF!L40 -> -494.43666 | N9: =$E$53*DCF!M40 -> -532.82029 | O9: =$E$53*DCF!N40 -> -575.60335 | P9: =$E$53*DCF!O40 -> -622.31929 | Q9: =$E$53*DCF!P40 -> -672.26959 | R9: =$E$53*DCF!Q40 -> -723.2189 | ... AF9: =$E$53*DCF!AE40 -> -1553.3572 | AG9: =SUM(D9:AF9) -> -23680.307
B10: 5b | C10: (Amort) | D10: -12230 | E10: -14026 | F10: -14197 | G10: =F38*$D$54 -> -13006.713 | H10: =G38*$D$54 -> -14209.072 | I10: =H38*$D$54 -> -15522.579 | J10: =I38*$D$54 -> -16957.508 | K10: =J38*$E$54 -> -13526.871 | L10: =K38*$E$54 -> -14439.935 | M10: =L38*$E$54 -> -15414.631 | N10: =M38*$E$54 -> -16455.118 | O10: =N38*$E$54 -> -17565.839 | P10: =O38*$E$54 -> -18751.533 | Q10: =P38*$E$54 -> -20017.262 | R10: =Q38*$E$54 -> -21368.427 | ... AF10: =AE38*$E$54 -> -53324.024
B11: 5c | C11: (Stock based compensation) | D11: =D20 -> -403 | E11: =E20 -> -575 | F11: =F20 -> -339 | G11: =G6*$D$55 -> -322.42626 | H11: =H6*$D$55 -> -367.16785 | I11: =I6*$D$55 -> -420.06719 | J11: =J6*$D$55 -> -482.81796 | K11: =K6*$D$55 -> -557.50571 | L11: =L6*$D$55 -> -646.70663 | M11: =M6*$D$55 -> -735.50505 | N11: =N6*$D$55 -> -819.80667 | ... AF11: =AF6*$D$55 -> -1313.9548
B12: 6 | C12: EBITDA | D12: =D8-D9-D10 -> 18633 | E12: =E8-E9-E10 -> 19996 | F12: =F8-F9-F10 -> 21508 | G12: =G8-G9-G10 -> 22631.514 | H12: =H8-H9-H10 -> 25251.123 | I12: =I8-I9-I10 -> 28247.008 | J12: =J8-J9-J10 -> 31686.086 | K12: =K8-K9-K10 -> 30349.324 | ... AF12: =AF8-AF9-AF10 -> 95377.333
B13: 7 | C13: (Net financing cost) | D13: ='Fin. Data'!D14 -> -354 | E13: ='Fin. Data'!C14 -> -369 | F13: ='Fin. Data'!B14 -> -749 | G13: =F43*$D$58-F44*$D$57 -> -507.70461 | H13: =G43*$D$58-G44*$D$57 -> -187.74073 | I13: =H43*$D$58-H44*$D$57 -> 126.97657 | J13: =I43*$D$58-I44*$D$57 -> 488.84954 | K13: =J43*$E$58-J44*$E$57 -> 912.05123 | L13: =K43*$E$58-K44*$E$57 -> 1171.1603 | M13: =L43*$E$58-L44*$E$57 -> 1431.2667 | N13: =M43*$E$58-M44*$E$57 -> 1713.2226 | O13: =N43*$E$58-N44*$E$57 -> 2024.8916 | P13: =O43*$E$58-O44*$E$57 -> 2368.9001 | Q13: =P43*$E$58-P44*$E$57 -> 2747.9897 | R13: =Q43*$E$58-Q44*$E$57 -> 3179.7221 | ... AF13: =AE43*$E$58-AE44*$E$57 -> 13023.284
B14: 8 | C14: Other income/(cost) | D14: ='Fin. Data'!D15 -> 254 | E14: ='Fin. Data'!C15 -> 369 | F14: ='Fin. Data'!B15 -> 0 | G14: =AVERAGE(D14:F14)*(1+G5) -> 235.38117 | H14: =AVERAGE(E14:G14)*(1+H5) -> 229.41611 | I14: =AVERAGE(F14:H14)*(1+I5) -> 177.25417 | J14: =AVERAGE(G14:I14)*(1+J5) -> 245.98761 | K14: =AVERAGE(H14:J14)*(1+K5) -> 251.20614 | L14: =AVERAGE(I14:K14)*(1+L5) -> 260.78652 | M14: =AVERAGE(J14:L14)*(1+M5) -> 287.35251 | N14: =AVERAGE(K14:M14)*(1+N5) -> 296.98799 | ... AF14: =AVERAGE(AC14:AE14)*(1+AF5) -> 366.84506
B15: 9 | C15: Earnings before taxes | D15: =D8+D13+D14 -> 6095 | E15: =E8+E13+E14 -> 5633 | F15: =F8+F13+F14 -> 6205 | G15: =G8+G13+G14 -> 8901.331 | H15: =H8+H13+H14 -> 10575.371 | I15: =I8+I13+I14 -> 12455.155 | J15: =J8+J13+J14 -> 14815.375 | K15: =K8+K13+K14 -> 17554.117 | ... AF15: =AF8+AF13+AF14 -> 53890.08
B16: 10 | C16: (Income tax) | D16: ='Fin. Data'!D21 -> -979 | E16: ='Fin. Data'!C21 -> -1141 | F16: ='Fin. Data'!B21 -> -797 | G16: =-$D$56*G15 -> -1484.0209 | H16: =-$D$56*H15 -> -1763.115 | I16: =-$D$56*I15 -> -2076.5109 | J16: =-$D$56*J15 -> -2470.0043 | K16: =-$E$56*K15 -> -3159.7411 | L16: =-$E$56*L15 -> -3707.762 | M16: =-$E$56*M15 -> -4264.4694 | N16: =-$E$56*N15 -> -4805.2685 | O16: =-$E$56*O15 -> -5309.9507 | P16: =-$E$56*P15 -> -5753.1386 | Q16: =-$E$56*Q15 -> -5967.6656 | R16: =-$E$56*R15 -> -6154.7284 | ... AF16: =-$E$56*AF15 -> -9700.2144
B17: 11 | C17: Net income | D17: ='Fin. Data'!D23 -> 5116 | E17: ='Fin. Data'!C23 -> 4492 | F17: ='Fin. Data'!B23 -> 5408 | G17: =G16+G15 -> 7417.3101 | H17: =H16+H15 -> 8812.2555 | I17: =I16+I15 -> 10378.644 | J17: =J16+J15 -> 12345.371 | K17: =K16+K15 -> 14394.376 | L17: =L16+L15 -> 16890.916 | M17: =M16+M15 -> 19427.027 | N17: =N16+N15 -> 21890.668 | ... AF17: =AF16+AF15 -> 44189.866
A19: CASH FLOW STATEMENT | B19: 12 | C19: Operating cash flows before WK | D19: =392.6+403+242 -> 1037.6 | E19: =2026.3+575+758 -> 3359.3 | F19: =7274.3+339+116 -> 7729.3 | G19: =(G17-G10-G9-G11)*(1+$D$59) -> 10233.081 | H19: =(H17-H10-H9-H11)*(1+$D$59) -> 11536.139 | I19: =(I17-I10-I9-I11)*(1+$D$59) -> 12983.388 | J19: =(J17-J10-J9-J11)*(1+$D$59) -> 14691.802 | K19: =(K17-K10-K9-K11)*(1+$E$59) -> 11388.205 | L19: =(L17-L10-L9-L11)*(1+$E$59) -> 12777.896 | M19: =(M17-M10-M9-M11)*(1+$E$59) -> 14209.127 | N19: =(N17-N10-N9-N11)*(1+$E$59) -> 15637.781 | O19: =(O17-O10-O9-O11)*(1+$E$59) -> 17027.501 | P19: =(P17-P10-P9-P11)*(1+$E$59) -> 18332.679 | Q19: =(Q17-Q10-Q9-Q11)*(1+$E$59) -> 19243.454 | R19: =(R17-R10-R9-R11)*(1+$E$59) -> 20139.142 | ... AF19: =(AF17-AF10-AF9-AF11)*(1+$E$59) -> 39541.613
B20: 13 | C20: (Stock-based compensation) | D20: -403 | E20: -575 | F20: -339 | G20: =G11 -> -322.42626 | H20: =H11 -> -367.16785 | I20: =I11 -> -420.06719 | J20: =J11 -> -482.81796 | K20: =K11 -> -557.50571 | L20: =L11 -> -646.70663 | M20: =M11 -> -735.50505 | N20: =N11 -> -819.80667 | ... AF20: =AF11 -> -1313.9548
B21: 14 | C21: (Working Capital Flows) | D21: =Inputs!D62 -> -242 | E21: =Inputs!C62 -> -758.1 | F21: =Inputs!B62 -> -116.1 | G21: =$D$60*(G6-F6) -> -448.75806 | H21: =$D$60*(H6-G6) -> -528.8809 | I21: =$D$60*(I6-H6) -> -625.31197 | J21: =$D$60*(J6-I6) -> -741.76347 | K21: =$E$60*(K6-J6) -> -882.86815 | L21: =$E$60*(L6-K6) -> -1054.4251 | M21: =$E$60*(M6-L6) -> -1049.6673 | N21: =$E$60*(N6-M6) -> -996.5116 | O21: =$E$60*(O6-N6) -> -890.83275 | P21: =$E$60*(P6-O6) -> -732.61291 | Q21: =$E$60*(Q6-P6) -> -226.28413 | R21: =$E$60*(R6-Q6) -> -230.80982 | ... AF21: =$E$60*(AF6-AE6) -> -304.54865
B22: 15 | C22: -Total Operating Cash Flow | D22: =D19+D20+D21 -> 392.6 | E22: =E19+E20+E21 -> 2026.2 | F22: =F19+F20+F21 -> 7274.2 | G22: =G19+G20+G21 -> 9461.8962 | H22: =H19+H20+H21 -> 10640.09 | I22: =I19+I20+I21 -> 11938.009 | J22: =J19+J20+J21 -> 13467.22 | K22: =K19+K20+K21 -> 9947.8313 | ... AF22: =AF19+AF20+AF21 -> 37923.11
B23: 16 | C23: (CAPEX) | D23: ='Fin. Data'!D32 -> -524.6 | E23: ='Fin. Data'!C32 -> -407.7 | F23: ='Fin. Data'!B32 -> -348.6 | G23: =G6*$D$62 -> -560.87951 | H23: =H6*$D$62 -> -638.71015 | I23: =I6*$D$62 -> -730.73169 | J23: =J6*$D$62 -> -839.89034 | K23: =K6*$E$62 -> -484.90705 | L23: =L6*$E$62 -> -562.49218 | M23: =M6*$E$62 -> -639.72723 | N23: =N6*$E$62 -> -713.05105 | O23: =O6*$E$62 -> -778.59897 | P23: =P6*$E$62 -> -832.505 | Q23: =Q6*$E$62 -> -849.1551 | R23: =R6*$E$62 -> -866.1382 | ... AF23: =AF6*$E$62 -> -1142.851 | AG23: =SUM(D23:AF23) -> -23890.037
B24: 17 | C24: Adq | D24: =Inputs!D66 -> -788.3 | E24: ='Fin. Data'!C33 -> -1668.7 | F24: ='Fin. Data'!B33 -> -504.9 | G24: =G6*$D$63 -> -720.86645 | H24: =H6*$D$63 -> -820.89774 | I24: =I6*$D$63 -> -939.16778 | J24: =J6*$D$63 -> -1079.4632 | K24: =K6*$E$63 -> -623.22339 | L24: =L6*$E$63 -> -722.93913 | M24: =M6*$E$63 -> -822.20493 | N24: =N6*$E$63 -> -916.44386 | O24: =O6*$E$63 -> -1000.6889 | P24: =P6*$E$63 -> -1069.9712 | Q24: =Q6*$E$63 -> -1091.3706 | R24: =R6*$E$63 -> -1113.198 | ... AF24: =AF6*$E$63 -> -1468.8412 | AH24: =AG9-AG23 -> 209.73043
B25: 18 | C25: (Other investing flows) | D25: =Inputs!D67 -> -27 | E25: =Inputs!C67 -> 0 | F25: =Inputs!B67 -> 1395.3 | G25: =(1+G5)*AVERAGE(D25:F25) -> 516.9696 | H25: =(1+H5)*AVERAGE(E25:G25) -> 725.87545 | I25: =(1+I5)*AVERAGE(F25:H25) -> 1006.0777 | J25: =(1+J5)*AVERAGE(G25:I25) -> 861.6243 | K25: =(1+K5)*AVERAGE(H25:J25) -> 998.26049 | L25: =(1+L5)*AVERAGE(I25:K25) -> 1108.1722 | M25: =(1+M5)*AVERAGE(J25:L25) -> 1125.199 | N25: =(1+N5)*AVERAGE(K25:M25) -> 1200.6775 | ... AF25: =(1+AF5)*AVERAGE(AC25:AE25) -> 1479.2528
B26: 19 | C26: -Total Investing Flows | D26: =D23+D24+D25 -> -1339.9 | E26: =E23+E24+E25 -> -2076.4 | F26: =F23+F24+F25 -> 541.8 | G26: =G23+G24+G25 -> -764.77637 | H26: =H23+H24+H25 -> -733.73244 | I26: =I23+I24+I25 -> -663.82173 | J26: =J23+J24+J25 -> -1057.7292 | K26: =K23+K24+K25 -> -109.86995 | ... AF26: =AF23+AF24+AF25 -> -1132.4393
B27: 20 | C27: (Flows related to leases) | D27: =Inputs!D71+Inputs!D72 -> 0 | E27: =Inputs!C71+Inputs!C72 -> 0 | F27: =Inputs!B71+Inputs!B72 -> 0 | G27: =$D$66*G6 -> 0 | H27: =$D$66*H6 -> 0 | I27: =$D$66*I6 -> 0 | J27: =$D$66*J6 -> 0 | K27: =$E$66*K6 -> 0 | L27: =$E$66*L6 -> 0 | M27: =$E$66*M6 -> 0 | N27: =$E$66*N6 -> 0 | O27: =$E$66*O6 -> 0 | P27: =$E$66*P6 -> 0 | Q27: =$E$66*Q6 -> 0 | R27: =$E$66*R6 -> 0 | ... AF27: =$E$66*AF6 -> 0
B28: 21 | C28: Flows related to debt | D28: =+SUM(Inputs!D69:D70) -> 0 | E28: =+SUM(Inputs!C69:C70) -> 0 | F28: =+SUM(Inputs!B69:B70) -> 0 | G28: =G44-F44 -> -5256.2431 | H28: =H44-G44 -> 1309.8048 | I28: =I44-H44 -> 1497.9424 | J28: =J44-I44 -> 1719.5387 | K28: =K44-J44 -> -668.38087 | L28: =L44-K44 -> 1859.0148 | M28: =M44-L44 -> 1907.2956 | N28: =N44-M44 -> 1895.8597 | ... AF28: =AF44-AE44 -> 2116.56
B29: 22 | C29: (Repurchases)/Issuance of stock | D29: ='Fin. Data'!D28 -> -600 | E29: ='Fin. Data'!C28 -> 0 | F29: ='Fin. Data'!B28 -> -6045.3 | G29: =-G17*$D$65 -> -1483.462 | H29: =-H17*$D$65 -> -1762.4511 | I29: =-I17*$D$65 -> -2075.7289 | J29: =-J17*$D$65 -> -2469.0742 | K29: =-K17*$E$65 -> -3555.7652 | L29: =-L17*$E$65 -> -4172.472 | M29: =-M17*$E$65 -> -4798.9539 | N29: =-N17*$E$65 -> -5407.5337 | O29: =-O17*$E$65 -> -5975.4699 | P29: =-P17*$E$65 -> -6474.2045 | Q29: =-Q17*$E$65 -> -6715.619 | R29: =-R17*$E$65 -> -6926.1273 | ... AF29: =-AF17*$E$65 -> -10915.984
B30: 23 | C30: (Dividends) | D30: ='Fin. Data'!D27 -> 0 | E30: ='Fin. Data'!C27 -> 0 | F30: ='Fin. Data'!B27 -> 0 | G30: =-$D$64*G17 -> 0 | H30: =-$D$64*H17 -> 0 | I30: =-$D$64*I17 -> 0 | J30: =-$D$64*J17 -> 0 | K30: =-$E$64*K17 -> 0 | L30: =-$E$64*L17 -> 0 | M30: =-$E$64*M17 -> 0 | N30: =-$E$64*N17 -> 0 | O30: =-$E$64*O17 -> 0 | P30: =-$E$64*P17 -> 0 | Q30: =-$E$64*Q17 -> 0 | R30: =-$E$64*R17 -> 0 | ... AF30: =-$E$64*AF17 -> 0
B31: 24 | C31: Other financing flows | D31: =Inputs!D75 -> -549.8 | E31: =Inputs!C75 -> -664.3 | F31: =Inputs!B75 -> 94.5 | G31: =(1+G5)*AVERAGE(D31:F31) -> -423.00604 | H31: =(1+H5)*AVERAGE(E31:G31) -> -376.85771 | I31: =(1+I5)*AVERAGE(F31:H31) -> -268.99611 | J31: =(1+J5)*AVERAGE(G31:I31) -> -409.50967 | K31: =(1+K5)*AVERAGE(H31:J31) -> -406.20636 | L31: =(1+L5)*AVERAGE(I31:K31) -> -419.42202 | M31: =(1+M5)*AVERAGE(J31:L31) -> -468.2444 | N31: =(1+N5)*AVERAGE(K31:M31) -> -480.72434 | ... AF31: =(1+AF5)*AVERAGE(AC31:AE31) -> -594.5432
B32: 25 | C32: -Total Financing flows | D32: =D27+D28+D29+D30+D31 -> -1149.8 | E32: =E27+E28+E29+E30+E31 -> -664.3 | F32: =F27+F28+F29+F30+F31 -> -5950.8 | G32: =G27+G28+G29+G30+G31 -> -7162.7111 | H32: =H27+H28+H29+H30+H31 -> -829.50405 | I32: =I27+I28+I29+I30+I31 -> -846.78262 | J32: =J27+J28+J29+J30+J31 -> -1159.0451 | K32: =K27+K28+K29+K30+K31 -> -4630.3524 | ... AF32: =AF27+AF28+AF29+AF30+AF31 -> -9393.9677
A34: SUMMARY | B34: 26 | C34: Cash before shareholder returns | D34: =D22+D26+D27+D28+D31 -> -1497.1 | E34: =E22+E26+E27+E28+E31 -> -714.5 | F34: =F22+F26+F27+F28+F31 -> 7910.5 | G34: =G22+G26+G27+G28+G31 -> 3017.8708 | H34: =H22+H26+H27+H28+H31 -> 10839.305 | I34: =I22+I26+I27+I28+I31 -> 12503.133 | J34: =J22+J26+J27+J28+J31 -> 13719.52 | K34: =K22+K26+K27+K28+K31 -> 8763.3741 | ... AF34: =AF22+AF26+AF27+AF28+AF31 -> 38312.687
B35: 27 | C35: Returns to shareholders | D35: =-1*(D29+D30) -> 600 | E35: =-1*(E29+E30) -> 0 | F35: =-1*(F29+F30) -> 6045.3 | G35: =-1*(G29+G30) -> 1483.462 | H35: =-1*(H29+H30) -> 1762.4511 | I35: =-1*(I29+I30) -> 2075.7289 | J35: =-1*(J29+J30) -> 2469.0742 | K35: =-1*(K29+K30) -> 3555.7652 | ... AF35: =-1*(AF29+AF30) -> 10915.984
B36: 28 | C36: Excess cash acumulation | D36: =D34-D35 -> -2097.1 | E36: =E34-E35 -> -714.5 | F36: =F34-F35 -> 1865.2 | G36: =G34-G35 -> 1534.4088 | H36: =H34-H35 -> 9076.8535 | I36: =I34-I35 -> 10427.404 | J36: =J34-J35 -> 11250.446 | K36: =K34-K35 -> 5207.6089 | ... AF36: =AF34-AF35 -> 27396.703
A38: BALANCE SHEET | B38: 29 | C38: Intangible assets | D38: 30920 | E38: 32737 | F38: 31658 | G38: =+(F38+(-G10*$D$61)) -> 34584.51 | H38: =+(G38+(-H10*$D$61)) -> 37781.552 | I38: =+(H38+(-I10*$D$61)) -> 41274.132 | J38: =+(I38+(-J10*$D$61)) -> 45089.571 | K38: =+(J38+(-K10*$E$61)) -> 48133.117 | L38: =+(K38+(-L10*$E$61)) -> 51382.103 | M38: =+(L38+(-M10*$E$61)) -> 54850.395 | N38: =+(M38+(-N10*$E$61)) -> 58552.796 | O38: =+(N38+(-O10*$E$61)) -> 62505.11 | P38: =+(O38+(-P10*$E$61)) -> 66724.205 | Q38: =+(P38+(-Q10*$E$61)) -> 71228.089 | R38: =+(Q38+(-R10*$E$61)) -> 76035.985 | ... AF38: =+(AE38+(-AF10*$E$61)) -> 189744.65 | AG38: =SUM(G38:AF38) -> 2446423.1
B39: 30 | C39: Accumulated amortization | D39: 16859 | E39: 17741 | F39: 18660 | G39: =F39-(G10*$D$61) -> 21586.51 | H39: =G39-(H10*$D$61) -> 24783.552 | I39: =H39-(I10*$D$61) -> 28276.132 | J39: =I39-(J10*$D$61) -> 32091.571 | K39: =J39-(K10*$D$61) -> 35135.117 | L39: =K39-(L10*$D$61) -> 38384.103 | M39: =L39-(M10*$D$61) -> 41852.395 | N39: =M39-(N10*$D$61) -> 45554.796 | ... AF39: =AE39-(AF10*$D$61) -> 176746.65 | AG39: =SUM(G39:AF39) -> 2108475.1
B40: 31 | C40: PPE+Right of use Assets | D40: 4386 | E40: 4379 | F40: 4423 | G40: =F40+(-G23) -> 4983.8795 | H40: =G40+(-H23) -> 5622.5897 | I40: =H40+(-I23) -> 6353.3213 | J40: =I40+(-J23) -> 7193.2117 | K40: =J40+(-K23) -> 7678.1187 | L40: =K40+(-L23) -> 8240.6109 | M40: =L40+(-M23) -> 8880.3381 | N40: =M40+(-N23) -> 9593.3892 | ... AF40: =AE40+(-AF23) -> 27032.137 | AG40: =SUM(G40:AF40) -> 387279.6
B41: 32 | C41: Accumulated depreciation | D41: 616 | E41: 754 | F41: 855 | G41: =F41-G9 -> 1306.1464 | H41: =G41-H9 -> 1814.5025 | I41: =H41-I9 -> 2388.0071 | J41: =I41-J9 -> 3036.0464 | K41: =J41-K9 -> 3467.6391 | L41: =K41-L9 -> 3928.3262 | M41: =L41-M9 -> 4422.7629 | N41: =M41-N9 -> 4955.5831 | ... AF41: =AE41-AF9 -> 23633.307 | AG41: =SUM(G41:AF41) -> 264090.49
A43: CASH & DEBT & DISCOUNTING | B43: 33 | C43: Ending cash balance | D43: ='Fin. Data'!D39 -> 6028 | E43: =E36+D43 -> 5313.5 | F43: =F36+E43 -> 7178.7 | G43: =G36+F43 -> 8713.1088 | H43: =H36+G43 -> 17789.962 | I43: =I36+H43 -> 28217.367 | J43: =J36+I43 -> 39467.813 | K43: =K36+J43 -> 44675.422 | L43: =L36+K43 -> 52842.047 | ... AF43: =AF36+AE43 -> 381104.81
B44: 34 | C44: Total Debt | D44: ='Fin. Data'!D58 -> 17416 | E44: ='Fin. Data'!C58 -> 16932 | F44: ='Fin. Data'!B58 -> 16572 | G44: =G12*$D$68 -> 11315.757 | H44: =H12*$D$68 -> 12625.562 | I44: =I12*$D$68 -> 14123.504 | J44: =J12*$D$68 -> 15843.043 | K44: =K12*$E$68 -> 15174.662 | L44: =L12*$E$68 -> 17033.677 | M44: =M12*$E$68 -> 18940.972 | N44: =N12*$E$68 -> 20836.832 | O44: =O12*$E$68 -> 22654.336 | P44: =P12*$E$68 -> 24324.467 | Q44: =Q12*$E$68 -> 25390.796 | R44: =R12*$E$68 -> 26392.774 | ... AF44: =AF12*$E$68 -> 47688.666
B45: 35 | C45: Discount factor | F45: =1/((1+$F$50)^G50) -> 1 | G45: =1/((1+$F$50)^G49) -> 0.91911765 | H45: =1/((1+$F$50)^H49) -> 0.84477725 | I45: =1/((1+$F$50)^I49) -> 0.77644968 | J45: =1/((1+$F$50)^J49) -> 0.7136486 | K45: =1/((1+$F$50)^K49) -> 0.65592702 | L45: =1/((1+$F$50)^L49) -> 0.6028741 | M45: =1/((1+$F$50)^M49) -> 0.55411223 | N45: =1/((1+$F$50)^N49) -> 0.50929433 | ... AF45: =1/((1+$F$50)^AF49) -> 0.11159602
...

Sheet Assumptions
B2: Assumptions
B4: Prospects:
B6: Links:
C8: 2023 | D8: =C8-1 -> 2022 | E8: =D8-1 -> 2021 | F8: =E8-1 -> 2020 | G8: =F8-1 -> 2019 | I8: Average | K8: Short Term Forecast | L8: Long Term Forecast
B9: Revenue growth | C9: =(Inputs!B6-Inputs!C6)/Inputs!C6 -> 0.066643472 | D9: =(Inputs!C6-Inputs!D6)/Inputs!D6 -> 0.064583474 | E9: =(Inputs!D6-Inputs!E6)/Inputs!E6 -> 0.1881101 | F9: =(Inputs!E6-Inputs!F6)/Inputs!F6 -> 0.24012701 | G9: =(Inputs!F6-Inputs!G6)/Inputs!G6 -> 0.27618083 | I9: =AVERAGE(C9:G9) -> 0.16712898
B10: Operating Margin | C10: =Inputs!B8/Inputs!B6 -> 0.20620941 | D10: =Inputs!C8/Inputs!C6 -> 0.17816928 | E10: =Inputs!D8/Inputs!D6 -> 0.20859991 | F10: =Inputs!E8/Inputs!E6 -> 0.18342935 | G10: =Inputs!F8/Inputs!F6 -> 0.1291923 | I10: =AVERAGE(C10:G10) -> 0.18112005
B12: Tax rate | C12: =+C14/C13 -> 0.1284448 | D12: =+D14/D13 -> 0.21675532 | E12: =+E14/E13 -> 0.16763699 | F12: =+F14/F13 -> 0.16411379 | G12: =+G14/G13 -> 0.15664403
B13: Net Income before Taxes | C13: 6205 | D13: 5264 | E13: 5840 | F13: 3199 | G13: 2062
B14: Income taxes | C14: 797 | D14: 1141 | E14: 979 | F14: 525 | G14: 323
B16: Aa2/AA(current level)
B17: Default spread | I17: 0.007
B18: 30Y US Bond Yield | I18: 0.0433
B19: 5Y US Bond Yield | I19: 0.0417
B20: Country default spread (US) | I20: 0
B21: Short-term cost debt | I21: =I17+I19+I20 -> 0.0487
B22: Long-term cost of debt | I22: =I20+I18+I17 -> 0.0503
B24: Segments | C24: Weight | D24: Country Risk Premium | F24: Equity Risk Premium
B25: =Segments!C5 -> United States and Canada (UCAN) | C25: =Segments!B5 -> 0.4435 | D25: 0 | F25: 0.046
B26: =Segments!C6 -> Europe, Middle East and Africa (EMEA) | C26: =Segments!B6 -> 0.313 | D26: =+(0.88+0.72+0)/300 -> 0.0053333333 | F26: =+(5.48+4.6+5.32)/300 -> 0.051333333
B27: =Segments!C7 -> Latin America (LATAM) | C27: =Segments!B7 -> 0.1318 | D27: =+(4.4+2.78)/200 -> 0.0359 | F27: =+(9+7.38)/200 -> 0.0819
B28: =Segments!C8 -> Asia-Pacific (APAC) | C28: =Segments!B8 -> 0.1116 | D28: =+(3.21+1.03+0)/300 -> 0.014133333 | F28: =+(7.81+5.63+4.6)/300 -> 0.060133333
B29: Total | C29: =SUM(C25:C27) -> 0.8883 | D29: =D25*C25+C26*D26+C27*D27+C28*D28 -> 0.0079782333 | F29: =F25*C25+C26*F26+C27*F27+C28*F28 -> 0.053973633
B32: Modelling Factors
C34: Last 5 Years
C35: =C8 -> 2023 | D35: =D8 -> 2022 | E35: =E8 -> 2021 | F35: =F8 -> 2020 | G35: =G8 -> 2019 | I35: Average | K35: Short Term Forecast | L35: Long Term Forecast | N35: Reference
B36: Depreciation factor | C36: =DCF!F9/(DCF!F40) -> -0.080714447 | D36: =DCF!E9/(DCF!E40) -> -0.07695821 | E36: =DCF!D9/(DCF!D40) -> -0.047423621 | F36: -0.12083333 | G36: -0.1840708 | I36: =AVERAGE(C36:G36) -> -0.10200008 | K36: =I36 -> -0.10200008 | L36: -0.06 | N36: % PPE
B37: Amortization factor | C37: =DCF!E10/(DCF!E38) -> -0.42844488 | D37: =DCF!E10/(DCF!E38) -> -0.42844488 | E37: =DCF!D10/(DCF!D38) -> -0.39553687 | F37: -0.42574062 | G37: -0.37608651 | I37: =AVERAGE(C37:G37) -> -0.41085075 | K37: =I37 -> -0.41085075 | L37: -0.3 | N37: % IA
B38: Stock-based comp | C38: =DCF!F11/DCF!F6 -> -0.010052486 | D38: =DCF!E11/DCF!E6 -> -0.018186994 | E38: =DCF!D11/DCF!D6 -> -0.013569937 | F38: -0.00016602656 | G38: -0.00020093272 | I38: =AVERAGE(C38:G38) -> -0.0084352754 | K38: =I38 -> -0.0084352754 | L38: =K38 -> -0.0084352754 | N38: % revenue
B39: Tax Rate | C39: =C12 -> 0.1284448 | D39: =D12 -> 0.21675532 | E39: =E12 -> 0.16763699 | F39: =F12 -> 0.16411379 | G39: =G12 -> 0.15664403 | I39: =AVERAGE(C39:G39) -> 0.16671899 | K39: =I39 -> 0.16671899 | L39: 0.18 | N39: % (line 9)
B40: Interest Rate on debt | C40: ='Fin. Data'!B14/'Fin. Data'!B58 -> -0.045196717 | D40: ='Fin. Data'!C14/'Fin. Data'!C58 -> -0.021793055 | E40: ='Fin. Data'!D14/'Fin. Data'!D58 -> -0.020326137 | F40: ='Fin. Data'!E14/'Fin. Data'!E58 -> -0.076952973 | G40: ='Fin. Data'!F14/'Fin. Data'!F58 -> -0.03310328 | I40: =AVERAGE(C40:G40) -> -0.039474432 | K40: =I21 -> 0.0487 | L40: =I22 -> 0.0503 | N40: % debt (l29)
B41: Interest Rate on cash | I41: =AVERAGE(C41:G41) -> #DIV/0! | K41: =I19 -> 0.0417 | L41: =I18 -> 0.0433 | N41: % of cash (l28)
B42: Operating cash flows before WK | C42: =C89 -> -0.3591792 | D42: =D89 -> -0.50303011 | E42: =E89 -> -0.5764698 | F42: =F89 -> -0.4518763 | G42: =G89 -> -0.69570847 | I42: =AVERAGE(C42:G42) -> -0.51725278 | K42: =I42 -> -0.51725278 | L42: =C88 -> -0.60608548 | N42: reducing with addicitons to content
B43: Working capital flows | C43: =+Inputs!B62/(Inputs!B6-Inputs!C6) -> -0.055102041 | D43: =+Inputs!C62/(Inputs!C6-Inputs!D6) -> -0.39525547 | E43: =+Inputs!D62/(Inputs!D6-Inputs!E6) -> -0.051467461 | F43: =+Inputs!E62/(Inputs!E6-Inputs!F6) -> -0.0065909091 | G43: =+Inputs!F62/(Inputs!F6-Inputs!G6) -> 0.0098578634 | I43: =AVERAGE(C43:G43) -> -0.099711604 | K43: =I43 -> -0.099711604 | L43: =K43 -> -0.099711604 | N43: % of change revenues (l2)
B44: Intangible Assets | I44: =AVERAGE(C44:G44) -> #DIV/0! | K44: =0.9/4 -> 0.225 | L44: =K44 -> 0.225 | N44: Growing with amortization
B45: CAPEX | C45: =+'Fin. Data'!B32/'Fin. Data'!B5 -> -0.010337159 | D45: =+'Fin. Data'!C32/'Fin. Data'!C5 -> -0.012895369 | E45: =+'Fin. Data'!D32/'Fin. Data'!D5 -> -0.017664489 | F45: =+'Fin. Data'!E32/'Fin. Data'!E5 -> -0.019919187 | G45: =+'Fin. Data'!F32/'Fin. Data'!F5 -> -0.012552094 | I45: =AVERAGE(C45:G45) -> -0.01467366 | K45: =I45 -> -0.01467366 | L45: =K45/2 -> -0.0073368298 | N45: % revenue (l2)
B46: Acquisition factor | C46: =+'Fin. Data'!B33/'Fin. Data'!B5 -> -0.014971978 | D46: =+'Fin. Data'!C33/'Fin. Data'!C5 -> -0.052780238 | E46: =+'Fin. Data'!D33/'Fin. Data'!D5 -> -0.026543875 | F46: =+'Fin. Data'!E33/'Fin. Data'!E5 -> 0 | G46: =+'Fin. Data'!F33/'Fin. Data'!F5 -> 0 | I46: =AVERAGE(C46:G46) -> -0.018859218 | K46: =I46 -> -0.018859218 | L46: =K46/2 -> -0.009429609 | N46: % revenue (l2)
B47: Dividends | C47: 0 | D47: 0 | E47: 0 | F47: 0 | G47: 0 | I47: =AVERAGE(C47:G47) -> 0 | K47: =I47 -> 0 | L47: =K47 -> 0 | N47: % net income (11)
B48: Repurchases | C48: =+'Fin. Data'!B28/'Fin. Data'!B23 -> -1.1178439 | D48: =+'Fin. Data'!C28/'Fin. Data'!C23 -> 0 | E48: =+'Fin. Data'!D28/'Fin. Data'!D23 -> -0.11727912 | F48: =+'Fin. Data'!E28/'Fin. Data'!E23 -> 0 | G48: =+'Fin. Data'!F28/'Fin. Data'!F23 -> 0 | I48: =AVERAGE(C48:G48) -> -0.24702461 | K48: -0.2 | L48: =I48 -> -0.24702461 | N48: % net income (11)
B49: Leases | C49: 0 | D49: 0 | E49: 0 | F49: 0 | G49: 0 | I49: =AVERAGE(C49:G49) -> 0 | K49: =I49 -> 0 | L49: =K49 -> 0 | N49: % revenue (l2)
B50: Cash Costs for EBIT | I50: =AVERAGE(C50:G50) -> #DIV/0! | K50: =I50 -> #DIV/0! | L50: =K50 -> #DIV/0! | N50: % revenue (l2)
...

Sheet Fin. Data
A1: =Inputs!H3 -> #VALUE!
A2: =Inputs!G2 -> Figures in Millions of USD
A3: Results
B4: =OP!J20 -> 2023 | C4: =B4-1 -> 2022 | D4: =C4-1 -> 2021 | E4: =D4-1 -> 2020 | F4: =E4-1 -> 2019 | G4: =F4-1 -> 2018 | H4: =G4-1 -> 2017 | I4: =H4-1 -> 2016 | J4: =I4-1 -> 2015 | ... M4: =L4-1 -> 2012
A5: Net Sales | B5: =_xlfn.XLOOKUP($A5,Inputs!$A:$A,Inputs!B:B,,0) -> 33723 | C5: =_xlfn.XLOOKUP($A5,Inputs!$A:$A,Inputs!C:C,,0) -> 31616 | D5: =_xlfn.XLOOKUP($A5,Inputs!$A:$A,Inputs!D:D,,0) -> 29698 | E5: =_xlfn.XLOOKUP($A5,Inputs!$A:$A,Inputs!E:E,,0) -> 24996 | F5: =_xlfn.XLOOKUP($A5,Inputs!$A:$A,Inputs!F:F,,0) -> 20156 | G5: =_xlfn.XLOOKUP($A5,Inputs!$A:$A,Inputs!G:G,,0) -> 15794 | H5: =_xlfn.XLOOKUP($A5,Inputs!$A:$A,Inputs!H:H,,0) -> 11693 | I5: =_xlfn.XLOOKUP($A5,Inputs!$A:$A,Inputs!I:I,,0) -> 8831 | J5: =_xlfn.XLOOKUP($A5,Inputs!$A:$A,Inputs!J:J,,0) -> 6780 | K5: =_xlfn.XLOOKUP($A5,Inputs!$A:$A,Inputs!K:K,,0) -> 5505 | L5: =_xlfn.XLOOKUP($A5,Inputs!$A:$A,Inputs!L:L,,0) -> 4375 | M5: =_xlfn.XLOOKUP($A5,Inputs!$A:$A,Inputs!M:M,,0) -> 3609
A6: Growth vs. Previous year | B6: =IFERROR(B5/C5-1,"-") -> 0.066643472 | C6: =IFERROR(C5/D5-1,"-") -> 0.064583474 | D6: =IFERROR(D5/E5-1,"-") -> 0.1881101 | E6: =IFERROR(E5/F5-1,"-") -> 0.24012701 | F6: =IFERROR(F5/G5-1,"-") -> 0.27618083 | G6: =IFERROR(G5/H5-1,"-") -> 0.35072265 | H6: =IFERROR(H5/I5-1,"-") -> 0.32408561 | I6: =IFERROR(I5/J5-1,"-") -> 0.30250737 | ... L6: =IFERROR(L5/M5-1,"-") -> 0.21224716 | M6: =IFERROR(M5/#REF!-1,"-") -> -
A7: Gross Profit | B7: =_xlfn.XLOOKUP($A7,Inputs!$A:$A,Inputs!B:B,,0) -> 14008 | C7: =_xlfn.XLOOKUP($A7,Inputs!$A:$A,Inputs!C:C,,0) -> 12447 | D7: =_xlfn.XLOOKUP($A7,Inputs!$A:$A,Inputs!D:D,,0) -> 12365 | E7: =_xlfn.XLOOKUP($A7,Inputs!$A:$A,Inputs!E:E,,0) -> 10821 | F7: =_xlfn.XLOOKUP($A7,Inputs!$A:$A,Inputs!F:F,,0) -> 7716 | G7: =_xlfn.XLOOKUP($A7,Inputs!$A:$A,Inputs!G:G,,0) -> 5827 | H7: =_xlfn.XLOOKUP($A7,Inputs!$A:$A,Inputs!H:H,,0) -> 4033 | I7: =_xlfn.XLOOKUP($A7,Inputs!$A:$A,Inputs!I:I,,0) -> 2801 | J7: =_xlfn.XLOOKUP($A7,Inputs!$A:$A,Inputs!J:J,,0) -> 2188 | K7: =_xlfn.XLOOKUP($A7,Inputs!$A:$A,Inputs!K:K,,0) -> 1752 | L7: =_xlfn.XLOOKUP($A7,Inputs!$A:$A,Inputs!L:L,,0) -> 1257 | M7: =_xlfn.XLOOKUP($A7,Inputs!$A:$A,Inputs!M:M,,0) -> 957
A8: % over sales | B8: =IFERROR(B7/B$5,"-") -> 0.41538416 | C8: =IFERROR(C7/C$5,"-") -> 0.39369307 | D8: =IFERROR(D7/D$5,"-") -> 0.416358 | E8: =IFERROR(E7/E$5,"-") -> 0.43290927 | F8: =IFERROR(F7/F$5,"-") -> 0.38281405 | G8: =IFERROR(G7/G$5,"-") -> 0.36893757 | H8: =IFERROR(H7/H$5,"-") -> 0.34490721 | I8: =IFERROR(I7/I$5,"-") -> 0.31717812 | ... M8: =IFERROR(M7/M$5,"-") -> 0.26517041
A9: Operating expenses | B9: =B5-B11 -> 26769 | C9: =C5-C11 -> 25983 | D9: =D5-D11 -> 23503 | E9: =E5-E11 -> 20411 | F9: =F5-F11 -> 17552 | G9: =G5-G11 -> 14189 | H9: =H5-H11 -> 10854 | I9: =I5-I11 -> 8451 | ... M9: =M5-M11 -> 3559
A10: % over sales | B10: =IFERROR(B9/B$5,"-") -> 0.79379059 | C10: =IFERROR(C9/C$5,"-") -> 0.82183072 | D10: =IFERROR(D9/D$5,"-") -> 0.79140009 | E10: =IFERROR(E9/E$5,"-") -> 0.81657065 | F10: =IFERROR(F9/F$5,"-") -> 0.8708077 | G10: =IFERROR(G9/G$5,"-") -> 0.89837913 | H10: =IFERROR(H9/H$5,"-") -> 0.92824767 | I10: =IFERROR(I9/I$5,"-") -> 0.95696977 | ... M10: =IFERROR(M9/M$5,"-") -> 0.98614575
