Workbook
Name Sectors: '[1]Sector Impact'!$K$4:$K$16
Name Sectors: 'Sector Impact'!$K$4:$K$16

Sheet OP
B2: 45270 | C2: Team 1 | E2: =Inputs!I3 -> #VALUE! | L2: NYSE | M2: SIC: 3577
B3: #VALUE! | D3: COMPANY DESCRIPTION | H3: CEO & BOARD OF DIRECTORS
D4: {=_FV(Inputs!I3,"Description")} -> Fortinet, Inc. provides an integrated platform, the Fortinet Security Fabric, that spans networking, unified Secure Access Service Edge (SASE) and AI-driven security operations to deliver cybersecurity where customers need it. It offers solutions to enterprises, such as in the financial services, retail and operational technology market verticals, communication and security service providers, government organizations and small and medium-sized businesses. Its Secure Networking solutions focuses on the convergence of networking and security via its network firewall and its switches, access points and other secure connectivity solutions. Its Unified SASE solution is a single-vendor SASE solution that includes Firewall, SD-WAN, Secure Web Gateway, Cloud Access Services Broker, and Data Loss Prevention, Zero Trust Network Access and cloud security. Its Security Operations solutions are delivered as a platform that automates detection and response to accelerate discovery and remediation. | H4: Name (Gender; Age) | I4: Tenure | J4: Executive? | K4: Other roles
H5: Kenneth Xie (M, 60) | I5: 10.8 | J5: Co-Founder, Chairman, CEO | K5: Founder of Netscreen Technologies and Stanford Infosystems Intl, Ken Xie 2007 Annuity Trust Trustee
H6: Michael Xie (M, 54) | I6: 22.8 | J6: Co-Founder, President, Director & CTO | K6: Relevant past positions: Vice President-Engineering at ServGate Technologies, Software Director at NetScreen Technologies, Senior Software Engineer for Milkyway Networks Corporation
H7: William H Neukon (M, 81) | I7: 5.6 | J7: Lead Independent Director | K7: Founder of World Justice Project and Neukom Family Foundation, board member of The Asia Foundation, Pacific Council on International Policy and Center for Advanced Study in the Behavioral Sciences; Relevant past positions: Partner at K&L Gates and Preston Gates & Ellis, Chairman of Kirkpatrick & Lockhart, Preston Gates & Ellis and Volterra, EVP-Law & Corporate Affairs at Microsoft, Semiconductor, President at American Bar Association
H8: Ming Hsieh(M, 67) | I8: 10.6 | J8: Independent Director | K8: Founder of Gemalto Cogent, A-MAX Technology and Cogent and Founder, Chairman & CEO of Fulgent Genetics, Board Member of the University of Southern California, Fudan University and Fulgent Pharma
H9: Judith Sim (F, 54) | I9: 8.4 | J9: Independent Director | K9: Board member of DataStax and First Advantage; Relevant past postions: Chiief Marketing Officer of Oracle
H10: Jean X Hu (F, 59) | I10: 4.1 | J10: Independent Director | K10: CFO, Treasurer & Executive VP of Advanced Micro Devices, CFO at Marvell Technology Holdings; Relevant past positions: CEO & CFO, SVP at QLogic, CEO & CFO at Kinoma, President & CFO at Cavium, CFO, Treasurer & SVP-Business Development at Conexant Systems
H11: Kenneth A Goldman (M, 74) | I11: 3.1 | J11: Independent Director | K11: President of Hillspire, Member of The Financial Executives Institute, Advisor at Illuminate Ventures and ForgePoint Capital Management, Principal Executive & Financial Officer, Director at Aabaco Holdings, Member of Sustainability Accounting Standards Board, Managing Member at Gv Partners, Board Member of 17 other companies | N11: ..
H12: James G Starvidis (M, 68) | I12: 2.1 | J12: Independent Director | K12: Member-Advisory Board at Utilidata, Chairman for The Rockefeller Foundation, Managing Director & Vice Chairman-Global Affairs at The Carlyle Group and Board Member of 21 other companies
B17: USD MILLIONS
B18: COMPANY OVERVIEW
B19: Stock | D19: Liquidity and Solvency | F19: Segments | I19: Profitability (2023 TTM) | L19: Multiples
B20: Last Price | C20: {=_FV(E2,"Price")} -> 76.64 | D20: Total Assets | E20: =_xlfn.XLOOKUP(D20,'Fin. Data'!A:A,'Fin. Data'!B:B,,0) -> 7479.3 | F20: Regions | H20: % Sales | I20: Reporting Year | J20: 2023 | L20: Float | M20: 0.842
B21: Outstanding Shares | C21: {=_FV(E2,"Shares outstanding",TRUE)} -> 764908000 | D21: Total Liabilities | E21: =_xlfn.XLOOKUP(D21,'Fin. Data'!A:A,'Fin. Data'!B:B,,0) -> 7405.2 | F21: =Segments!C5 -> United States | H21: =Segments!B5 -> 0.30386452 | I21: Last Report | J21: 2 November 2023 | L21: Insiders Own | M21: 0.1741
B22: Market Cap. | C22: =C20*C21/1000000 -> 58622.549 | D22: Cash/Share | E22: =_xlfn.XLOOKUP("Cash & Eq.",'Fin. Data'!A:A,'Fin. Data'!B:B,,0)*1000000/C21 -> 2.8589059 | F22: =Segments!C6 -> Other Americas | H22: =Segments!B6 -> 0.10739072 | I22: EBITDA | K22: =_xlfn.XLOOKUP(I22,'Fin. Data'!A:A,'Fin. Data'!B:B,,0) -> 1407.2 | L22: b (Yahoo) | M22: 1.14
B23: +Total Debt | C23: ='Fin. Data'!C58 -> 1086.1 | D23: EBITDA/Net Financial Cost (NFC) | E23: =_xlfn.XLOOKUP("EBITDA",'Fin. Data'!A:A,'Fin. Data'!B:B,,0)/_xlfn.XLOOKUP("Net Financial Cost",'Fin. Data'!A:A,'Fin. Data'!B:B,,0) -> 17.994885 | F23: =Segments!C7 -> Europe, Middle East and Africa (EMEA) | H23: =Segments!B7 -> 0.38807586 | I23: Depreciation & Amortization | K23: =_xlfn.XLOOKUP(I23,'Fin. Data'!A:A,'Fin. Data'!B:B,,0) -> 110.5 | L23: Score (S&P) | M23: BBB+
B24: -Cash | C24: ='Fin. Data'!C39 -> 1682.9 | D24: Debt/EBITDA | E24: =_xlfn.XLOOKUP("Total Debt",'Fin. Data'!A:A,'Fin. Data'!B:B,,0)/_xlfn.XLOOKUP("EBITDA",'Fin. Data'!A:A,'Fin. Data'!B:B,,0) -> 0.74921831 | F24: =Segments!C8 -> Asia Pacific (APAC) | H24: =Segments!B8 -> 0.2006689 | I24: EBIT | K24: =_xlfn.XLOOKUP(I24,'Fin. Data'!A:A,'Fin. Data'!B:B,,0) -> 1296.7 | L24: Price/Book Value | M24: =IFERROR((C20*C21/(E20-E21))/1000000,"") -> 791.12752
B25: =Enterprise Value | C25: =C22+C23-C24 -> 58025.749 | D25: "Others Assets"/Asset | E25: =_xlfn.XLOOKUP("Other Assets",'Fin. Data'!A:A,'Fin. Data'!B:B,,0)/_xlfn.XLOOKUP("Total Assets",'Fin. Data'!A:A,'Fin. Data'!B:B,,0) -> 0.32882756 | I25: Net Income | K25: =_xlfn.XLOOKUP(I25,'Fin. Data'!A:A,'Fin. Data'!B:B,,0) -> 1150.7 | L25: NCF(3y avg)/Asset | M25: =IFERROR(K31/E20,"") -> 0.11653497
B26: Holdings (nac/int'l) | C26: - | D26: Debt/Assets | E26: =_xlfn.XLOOKUP(D26,'Fin. Data'!A:A,'Fin. Data'!B:B,,0) -> 0.14096239 | F26: Categories | H26: % Sales | I26: EPS | K26: =1000000*K25/C21 -> 1.5043639 | L26: Price/Net Inc. (3y avg) | M26: =IFERROR(C22/K30,"") -> 67.258546
B27: t liq. (Holdings/Vol.) | C27: - | D27: EBITDA Margin (average) | E27: =AVERAGE(_xlfn.XLOOKUP("EBITDA Margin",'Fin. Data'!A:A,'Fin. Data'!B:D,,0)) -> 0.25184651 | F27: =Segments!C16 -> Products | H27: =Segments!B16 -> 0.38269696 | I27: ROA | K27: =K25/E20 -> 0.1538513 | L27: EV/Asset | M27: =IFERROR(C25/E20,"") -> 7.7581791
B28: % Short | C28: 0.0181 | D28: Operating Margin (average) | E28: =AVERAGE(_xlfn.XLOOKUP("Operating Margin",'Fin. Data'!A:A,'Fin. Data'!B:D,,0)) -> 0.21623167 | F28: =Segments!C18 -> Technical support and other | H28: =Segments!B18 -> 0.27356211 | I28: ROIC | K28: =K25/(E20-(E21-C23)) -> 0.99181176 | L28: EV/Ebitda (3y average) | M28: =IFERROR(C25/K29,"") -> 52.701174
B29: Traffic ESG | D29: Net Income Margin (average) | E29: =AVERAGE(_xlfn.XLOOKUP("Net Income Margin",'Fin. Data'!A:A,'Fin. Data'!B:D,,0)) -> 0.19936228 | F29: =Segments!C17 -> Security subscription | H29: =Segments!B17 -> 0.34374094 | I29: EBITDA (3y average) | K29: =AVERAGE(_xlfn.XLOOKUP("EBITDA",'Fin. Data'!A:A,'Fin. Data'!B:D,,0)) -> 1101.0333 | L29: Price/NCF (3y average) | M29: =IFERROR(C22/K31,"") -> 67.258546
B30: E | I30: Net Income (3y average) | K30: =AVERAGE(_xlfn.XLOOKUP("Net Income",'Fin. Data'!A:A,'Fin. Data'!B:D,,0)) -> 871.6 | L30: Bonds 1,3,5a (USD) | M30: -
B31: S | D31: Net Financial Cost/Avg Net Debt | E31: =-_xlfn.XLOOKUP("Net Financial Cost",'Fin. Data'!A:A,'Fin. Data'!B:B,,0)/AVERAGE(_xlfn.XLOOKUP("Net Debt",'Fin. Data'!A:A,'Fin. Data'!B:D,,0)) -> 0.11770018 | I31: NCF (3y average) | K31: =AVERAGE(_xlfn.XLOOKUP("Net Income",'Fin. Data'!A:A,'Fin. Data'!B:D,,0)) -> 871.6 | L31: Div+Rep.(3y avg)/Price | M31: =-IFERROR(SUM(E52:E54)/(3*C22),"") -> 0.018976202
B32: G | L32: Div. Yield | M32: =-IFERROR(L53/C22,"") -> 0
B33: INVESTMENT THESIS
B34: Pillars of Recommendation | H34: Recommendation | I34: Valuation Assumptions
B35: Pillar | C35: Explanation | H35: SELL | I35: check DCF
B36: High Price | C36: Fortinet is a well-established company with healthy growth and strong strategy being adapted to constantly changing industry trends. Nevertheless, the share price is too high, which was impossible to justify with our valuation. Having that in mind, we issue recommendation to sell.
B39: Risks of Investment | H39: Price Target | I39: Valuation
B40: Risk | C40: Explanation | H40: =DCF!D76 -> 35.199604 | I40: Discount Rate | J40: =DCF!F50 -> 0.112543 | L40: Price M. Upside | M40: =SARD!AJ14 -> #NUM!
B41: adverse economic conditions | C41: Stubborn inflation, rising borrowing costs and risk of recession or staglfation might relust in longer sales cycles, increased products' cost structure, higher default rates from channel partners, reduced sales and growth declining in much faster pace
B42: high competition | C42: Fortinet might fail to innovate enough, develop less effetive products or could not adjust to constantly changing market trends, hence losse its competitive advantage to larger or faster growing competitors. It could result in major decline in sales growth and fall of the share price | I42: Upside | J42: =DCF!D75 -> -0.54071498 | L42: EV M. Upside | M42: =SARD!AM14 -> #NUM!
B43: debt | C43: Company might witness reduced sales growth, hence not be able to maintain its liquidity, taking under consideration recent significant increase of debt. It might affect the assumptions' reliability
B44: FINANCIAL PERFORMANCE
B45: Year | C45: Net Sales | D45: Operating Margin | E45: Dividends + Share Buyback | F45: Net Cash Flow | G45: Debt/Assets | H45: Depreciation & Amortization | I45: Capex + Investments | J45: Cash Flow
B46: =B47-1 -> 2015 | C46: {=_xlfn.SORTBY(TRANSPOSE(_xlfn.XLOOKUP(C$45,'Fin. Data'!$A:$A,'Fin. Data'!$B:$J,,0)),$B$46:$B$54,-1)} -> 1009.3 | D46: {=_xlfn.SORTBY(TRANSPOSE(_xlfn.XLOOKUP(D$45,'Fin. Data'!$A:$A,'Fin. Data'!$B:$J,,0)),$B$46:$B$54,-1)} -> 0.014762707 | E46: {=_xlfn.SORTBY(TRANSPOSE(_xlfn.XLOOKUP(E$45,'Fin. Data'!$A:$A,'Fin. Data'!$B:$J,,0)),$B$46:$B$54,-1)} -> -60 | F46: =Inputs!K77 -> 167.3 | G46: {=_xlfn.SORTBY(TRANSPOSE(_xlfn.XLOOKUP(G$45,'Fin. Data'!$A:$A,'Fin. Data'!$B:$J,,0)),$B$46:$B$54,-1)} -> 0 | H46: {=_xlfn.SORTBY(TRANSPOSE(_xlfn.XLOOKUP(H$45,'Fin. Data'!$A:$A,'Fin. Data'!$B:$J,,0)),$B$46:$B$54,-1)} -> 31.6 | I46: {=_xlfn.SORTBY(TRANSPOSE(_xlfn.XLOOKUP(I$45,'Fin. Data'!$A:$A,'Fin. Data'!$B:$J,,0)),$B$46:$B$54,-1)} -> -1 | L46: =J20 -> 2023 | M46: =L46-1 -> 2022
B47: =B48-1 -> 2016 | C47: 1275.4 | D47: 0.033636506 | E47: -110.8 | F47: =Inputs!J77 -> 259.9 | G47: 0 | H47: 48.5 | I47: -74.1 | J47: Net Income | L47: =_xlfn.XLOOKUP($J47,'Fin. Data'!$A:$A,'Fin. Data'!B:B,,0) -> 1150.7 | M47: =_xlfn.XLOOKUP($J47,'Fin. Data'!$A:$A,'Fin. Data'!C:C,,0) -> 857.3 | N47: =(C47/C46)-1 -> 0.26364807 | O47: =(D47/D46)-1 -> 1.2784782
...

Sheet Segments
B2: ="Regions "&"("&OP!$J$20&")" -> Regions (2023) | P2: Products
D3: Nominal value | K3: YoY Growth
B4: Weight | C4: Region | D4: =OP!J20 -> 2023 | E4: =D4-1 -> 2022 | F4: =E4-1 -> 2021 | G4: =F4-1 -> 2020 | H4: =G4-1 -> 2019 | I4: =H4-1 -> 2018 | K4: =OP!J20 -> 2023 | L4: =K4-1 -> 2022 | M4: =L4-1 -> 2021 | N4: =M4-1 -> 2020 | O4: =N4-1 -> 2019
B5: =IFERROR(D5/$D$11,"") -> 0.30386452 | C5: United States | D5: 1571.8 | E5: 1325 | F5: 1006.8 | G5: 813.3 | H5: 695.5 | I5: 577.2 | K5: =(D5-E5)/E5 -> 0.18626415 | L5: =(E5-F5)/F5 -> 0.31605085 | M5: =(F5-G5)/G5 -> 0.23791959 | N5: =(G5-H5)/H5 -> 0.16937455 | O5: =(H5-I5)/I5 -> 0.20495495
B6: =IFERROR(D6/$D$11,"") -> 0.10739072 | C6: Other Americas | D6: 555.5 | E6: 460 | F6: 352 | G6: 263.9 | H6: 224.7 | I6: 185.7 | K6: =(D6-E6)/E6 -> 0.2076087 | L6: =(E6-F6)/F6 -> 0.30681818 | M6: =(F6-G6)/G6 -> 0.33383858 | N6: =(G6-H6)/H6 -> 0.17445483 | O6: =(H6-I6)/I6 -> 0.21001616
B7: =IFERROR(D7/$D$11,"") -> 0.38807586 | C7: Europe, Middle East and Africa (EMEA) | D7: 2007.4 | E7: 1691.8 | F7: 1275.9 | G7: 991.9 | H7: 816.5 | I7: 678 | K7: =(D7-E7)/E7 -> 0.18654687 | L7: =(E7-F7)/F7 -> 0.32596598 | M7: =(F7-G7)/G7 -> 0.28631919 | N7: =(G7-H7)/H7 -> 0.21481935 | O7: =(H7-I7)/I7 -> 0.20427729
B8: =IFERROR(D8/$D$11,"") -> 0.2006689 | C8: Asia Pacific (APAC) | D8: 1038 | E8: 940.6 | F8: 707.5 | G8: 525.3 | H8: 426.3 | I8: 360.3 | K8: =(D8-E8)/E8 -> 0.10355092 | L8: =(E8-F8)/F8 -> 0.32946996 | M8: =(F8-G8)/G8 -> 0.34684942 | N8: =(G8-H8)/H8 -> 0.23223082 | O8: =(H8-I8)/I8 -> 0.18318068
B9: =IFERROR(D9/$D$11,"") -> 0 | K9: =(D9-E9)/E9 -> #DIV/0!
B10: =IFERROR(D10/$D$11,"") -> 0 | K10: =(D10-E10)/E10 -> #DIV/0!
B11: =SUM(B5:B10) -> 1 | C11: TOTAL | D11: =SUM(D5:D10) -> 5172.7 | E11: =SUM(E5:E10) -> 4417.4 | F11: =SUM(F5:F10) -> 3342.2 | G11: =SUM(G5:G10) -> 2594.4 | H11: =SUM(H5:H10) -> 2163 | I11: =SUM(I5:I10) -> 1801.2 | K11: =(D11-E11)/E11 -> 0.17098293 | L11: =(E11-F11)/F11 -> 0.32170427 | M11: =(F11-G11)/G11 -> 0.2882362 | N11: =(G11-H11)/H11 -> 0.19944521 | O11: =(H11-I11)/I11 -> 0.20086609
B13: ="Categories "&"("&OP!$J$20&")" -> Categories (2023)
D14: Nominal value | K14: YoY Growth
B15: Weight | C15: Category | D15: =OP!J20 -> 2023 | E15: =D15-1 -> 2022 | F15: =E15-1 -> 2021 | G15: =F15-1 -> 2020 | H15: =G15-1 -> 2019 | I15: =H15-1 -> 2018 | K15: =OP!J20 -> 2023 | L15: =K15-1 -> 2022 | M15: =L15-1 -> 2021 | N15: =M15-1 -> 2020 | O15: =N15-1 -> 2019
B16: =IFERROR(D16/$D$19,"") -> 0.38269696 | C16: Products | D16: 1979.5 | E16: 1780.5 | F16: 1255 | G16: 916.4 | H16: 788.5 | I16: 674.4 | K16: =(D16-E16)/E16 -> 0.11176636 | L16: =(E16-F16)/F16 -> 0.4187251 | M16: =(F16-G16)/G16 -> 0.36948931 | N16: =(G16-H16)/H16 -> 0.16220672 | O16: =(H16-I16)/I16 -> 0.16918743
B17: =IFERROR(D17/$D$19,"") -> 0.34374094 | C17: Security subscription | D17: 1778 | E17: 1427 | F17: 1125 | G17: 918.7 | H17: 750.8 | I17: 602.6 | K17: =(D17-E17)/E17 -> 0.24597057 | L17: =(E17-F17)/F17 -> 0.26844444 | M17: =(F17-G17)/G17 -> 0.22455644 | N17: =(G17-H17)/H17 -> 0.22362813 | O17: =(H17-I17)/I17 -> 0.24593428
B18: =IFERROR(D18/$D$19,"") -> 0.27356211 | C18: Technical support and other | D18: 1415 | E18: 1209.9 | F18: 962.2 | G18: 759.3 | H18: 623.7 | I18: 524.2 | K18: =(D18-E18)/E18 -> 0.16951814 | L18: =(E18-F18)/F18 -> 0.25743089 | M18: =(F18-G18)/G18 -> 0.26721981 | N18: =(G18-H18)/H18 -> 0.21741222 | O18: =(H18-I18)/I18 -> 0.18981305
B19: =SUM(B16:B18) -> 1 | C19: TOTAL | D19: =SUM(D16:D18) -> 5172.5 | E19: =SUM(E16:E18) -> 4417.4 | F19: =SUM(F16:F18) -> 3342.2 | G19: =SUM(G16:G18) -> 2594.4 | H19: =SUM(H16:H18) -> 2163 | I19: =SUM(I16:I18) -> 1801.2 | K19: =(D19-E19)/E19 -> 0.17093766 | L19: =(E19-F19)/F19 -> 0.32170427 | M19: =(F19-G19)/G19 -> 0.2882362 | N19: =(G19-H19)/H19 -> 0.19944521 | O19: =(H19-I19)/I19 -> 0.20086609
B21: Categories | D21: Description | I21: Graphs
B22: Products | D22: FortiGate network security products, Fortinet Security Fabric platform products and other products
B23: Security Subscription | D23: Subscriptions for online security solutions for applications; content; web traffic; devices; and users.
B24: Technical Support and other | D24: Service to ensure efficient, effective operations and maintenance of their products
B25: - | D25: -
B26: - | D26: -
B29: Industry | J29: Graphs (Industry Forecasts)
B30: Drivers | D30: Description
B31: Security Driven Networking
B32: Heightned awareness
B33: Increased Investments
B34: Sales forecast
B35: Source | D35: Market Growth CAGR | G35: Period
B36: Mordor Intelligence | D36: 0.176 | G36: 2018-2028
B37: Business Research Insights | D37: 0.1227 | G37: 2022-2031
B38: Vault | D38: 0.2358 | G38: 2019-2015
B39: Statista | D39: 0.0737 | G39: 2023-2028
B40: Average | D40: =AVERAGE(D36:D39) -> 0.15205
B41: Company's Strategy / Extra Notes

Sheet Acuerdo
A1: Invertir
A2: NO invertir
A3: Mantener sin elevar posición
A4: Mantener (y seguir comprando)
A5: Liquidar
A6: PENDIENTE

Sheet Peers
B1: Peer Logo | C1: Peer Name | D1: Description
C2: #VALUE! | D2: Palo Alto NetWorks, Inc. is a gloval cybersecurity provider. The Company's platforms and services help secure entreprise users, networks, clouds and endpoints dy delivering value in four areas, NetWork Security, Cloud Secuirty, Secuirty Operations, Threat Intelligence and Secuirty Consulting. Those solutions are delivered through its Cortex portfolio.
C3: #VALUE! | D3: CrowdStrike Holdings, Inc. is a cybersecuirty company that provides cloud-delivered protection of endpoints, cloud workloads, identity and data via a software-as-a-service (SaaS) subscription-based model. The comapny offers Falcon platform in a SaaS subscription-based model, which delivers technologies that deliver protection and performance, while reducing costumer complexity.
C4: #VALUE! | D4: Check Point develops, markets and supports a wide range of products and services for IT security by offering a multilevel security architecture that defends enterprises’ cloud, network, mobile devices, Endpoints information and IOT solutions. Their solutions operate under a unified security architecture, Infinity, that enables end-to-end security with a single line of unified security gateways and allow a single agent for all endpoint security that can be managed from a single unified management console.
C5: #VALUE! | D5: Cisco designs and sells a broad range of technologies that power the Internet. They are integrating a product portfolios across networking, security, collaboration, applications and the cloud to create highly secure, intelligent platforms for its customers’ digital businesses. The End-to-End Security product category, the segment where Cisco competes with Fortinet, consists of Cloud and Application Security, Industrial Security, Network Security, and User and Device Security offerings. Cisco continues to invest in resources across the security portfolio focused on cloud-based offerings, AI-driven threat detection and end-to-end security architectures. Additionally, the company is invesnting in expanding their SASE architecture by delivering combined network and security functionality in a single cloud-native service.
C6: #VALUE! | D6: Zscaler, Inc. is a cloud security company that developed a platform incorporating core security functionalities needed to enable fast and secure access to cloud resources based on identity, context and organization’s policies. Their solution is a purpose-built, multi-tenant, distributed cloud platform that incorporates the security functionality needed to enable users, applications, and devices to safely and efficiently utilize authorized applications and services based on an organization’s business policies. Zscaler delivers solutions using a software-as-a-service ("SaaS") business model and sell subscriptions to customers to access our cloud platform, together with related support services.
B8: In Millions USD | C8: =OP!E2 -> #VALUE! | D8: =C2 -> #VALUE! | E8: =C3 -> #VALUE! | F8: #VALUE! | G8: =C5 -> #VALUE! | H8: =C6 -> #VALUE! | I8: AVERAGE | J8: Deviation from Average
B9: Company Info | I9: =IFERROR(AVERAGE(C9:H9),"") | L9: TRAFFIC
B10: Market Cap | C10: 39170 | D10: {=_FV(D8,"Market cap",TRUE)/1000000} -> 113172 | E10: {=_FV(E8,"Market cap",TRUE)/1000000} -> 62146.896 | F10: {=_FV(F8,"Market cap",TRUE)/1000000} -> 21435.29 | G10: {=_FV(G8,"Market cap",TRUE)/1000000} -> 195985 | H10: {=_FV(H8,"Market cap",TRUE)/1000000} -> 24442.321 | I10: =IFERROR(AVERAGE(C10:H10),"") -> 76058.584 | J10: =SQRT((C10-I10)^2) -> 36888.584 | M10: Best Value
B11: Net Sales (current) | C11: =C56 -> 5172.7 | D11: =D56 -> 7207.4 | E11: =E56 -> 2847.59 | F11: =F56 -> 2389.7 | G11: =G56 -> 3898 | H11: =H56 -> 1758.11 | I11: =IFERROR(AVERAGE(C11:H11),"") -> 3878.9167 | J11: =SQRT((C11-I11)^2) -> 1293.7833
B12: Profitability | I12: =IFERROR(AVERAGE(C12:H12),"") | M12: Important Value
B13: Sales Growth (ttm) | C13: =C56/C55-1 -> 0.17098293 | D13: =D56/D55-1 -> 0.31007907 | E13: =E56/E55-1 -> 0.39938964 | F13: =F56/F55-1 -> 0.043309321 | G13: =G56/G55-1 -> 0.044200375 | H13: =H56/H55-1 -> 0.44583792 | I13: =IFERROR(AVERAGE(C13:H13),"") -> 0.23563321 | J13: =SQRT((C13-I13)^2) -> 0.06465028
B14: Sales Growth (36m) | C14: =C56/C54-1 -> 0.99379433 | D14: =D56/D54-1 -> 1.1145992 | E14: =E56/E54-1 -> 2.7388593 | F14: =F56/F54-1 -> 0.15729575 | G14: =G56/G54-1 -> 0.21850578 | H14: =H56/H54-1 -> 2.6607463 | I14: =IFERROR(AVERAGE(C14:H14),"") -> 1.3139668 | J14: =SQRT((C14-I14)^2) -> 0.32017244 | M14: Worst Value
B15: Operating Margin | C15: =C59/C56 -> 0.23459702 | D15: =D59/D56 -> 0.085176347 | E15: =E59/E56 -> -0.032718896 | F15: =F59/F56 -> 0.37716031 | H15: =H59/H56 -> -0.12035083 | I15: =IFERROR(AVERAGE(C15:H15),"") -> 0.10877279 | J15: =SQRT((C15-I15)^2) -> 0.12582423
B16: Net Income Margin | C16: =C62/C56 -> 0.22245636 | D16: =D62/D56 -> 0.085176347 | E16: =E62/E56 -> -0.0046671045 | F16: =F62/F56 -> 0.36029627 | H16: =H62/H56 -> -0.057271729 | I16: =IFERROR(AVERAGE(C16:H16),"") -> 0.12119803 | J16: =SQRT((C16-I16)^2) -> 0.10125833
B17: Return on Equity (RoE) | C17: =C62/C74 -> 15.529015 | D17: =D62/D74 -> 0.28283806 | E17: =E62/E74 -> -0.0064487954 | F17: =F62/F74 -> 0.30924503 | H17: =H62/H74 -> -0.12468887 | I17: =IFERROR(AVERAGE(C17:H17),"") -> 3.1979921 | J17: =SQRT((C17-I17)^2) -> 12.331023
B18: Return on Invested Capital (ROIC) | C18: =(C62+C61)/(C73+C74) -> 0.96853952 | D18: =(D62+D61)/(D73+D74) -> 0.1854086 | E18: =(E62+E61)/(E73+E74) -> 0.0037292919 | F18: =(F62+F61)/(F73+F74) -> 0.18043651 | H18: =(H62+H61)/(H73+H74) -> -0.03789354 | I18: =IFERROR(AVERAGE(C18:H18),"") -> 0.26004408 | J18: =SQRT((C18-I18)^2) -> 0.70849545
B19: Solvency | I19: =IFERROR(AVERAGE(C19:H19),"")
B20: Debt/Assets | C20: =C73/C70 -> 0.14096239 | D20: =D73/D70 -> 0.15008272 | E20: =E73/E70 -> 1.3680986 | F20: =F73/F70 -> 0.48458876 | H20: =H73/H70 -> 0.3612364 | I20: =IFERROR(AVERAGE(C20:H20),"") -> 0.50099377 | J20: =SQRT((C20-I20)^2) -> 0.36003138
B21: Net Debt/EBITDA | C21: =(C73-C65)/C58 -> -0.80478965 | D21: =(D73-D65)/D58 -> -0.30178712 | E21: =(E73-E65)/E58 -> -57.863987 | F21: =(F73-F65)/F58 -> 2.4781867 | H21: =(H73-H65)/H58 -> 1.0262991 | I21: =IFERROR(AVERAGE(C21:H21),"") -> -11.093216 | J21: =SQRT((C21-I21)^2) -> 10.288426
B22: Interest Coverage Ratio | C22: =-C58/C60 -> -17.994885 | D22: =-D58/D60 -> 51.427746 | E22: =-E58/E60 -> -1.4624367 | F22: =-F58/F60 -> -39.724576 | H22: =-H58/H60 -> -16.990442 | I22: =IFERROR(AVERAGE(C22:H22),"") -> -4.9489189 | J22: =SQRT((C22-I22)^2) -> 13.045966
B23: Liquidity
B24: Current Ratio | C24: =C68/C72 -> 1.3024664 | D24: =D68/D72 -> 0.86213964 | E24: =E68/E72 -> 1.7354898 | F24: =F68/F72 -> 2.0808971 | H24: =H68/H72 -> 1.9611712 | I24: =IFERROR(AVERAGE(C24:H24),"") -> 1.5884328 | J24: =SQRT((C24-I24)^2) -> 0.28596641
B25: Quick Ratio | C25: =(C65+C66)/C72 -> 0.87711702 | D25: =(D65+D66)/D72 -> 0.51960497 | E25: =(E65+E66)/E72 -> 1.5021741 | F25: =(F65+F66)/F72 -> 0.72461504 | H25: =(H65+H66)/H72 -> 1.1723661 | I25: =IFERROR(AVERAGE(C25:H25),"") -> 0.95917544 | J25: =SQRT((C25-I25)^2) -> 0.082058421
B26: Activity | I26: =IFERROR(AVERAGE(C26:H26),"")
B27: Inventory Turnover | C27: =C57/C67 -> 0.99101604 | D27: =D57/D67 -> #DIV/0! | E27: =E57/E67 -> #DIV/0! | F27: =F57/F67 -> #DIV/0! | H27: =H57/H67 -> #DIV/0! | I27: =IFERROR(AVERAGE(C27:H27),"") | J27: =SQRT((C27-I27)^2) -> #VALUE!
B28: Acc. Receivable Turnover | C28: =C56/C66 -> 5.1022884 | D28: =D56/D66 -> 5.1007785 | E28: =E56/E66 -> 5.0680584 | F28: =F56/F66 -> 6.7315493 | H28: =H56/H66 -> 4.7925799 | I28: =IFERROR(AVERAGE(C28:H28),"") -> 5.3590509 | J28: =SQRT((C28-I28)^2) -> 0.25676248
A29: Price/Sales | B29: Payables Turnover | C29: =C57/C71 -> 1.8247341 | D29: =D57/D71 -> 14.518209 | E29: =E57/E71 -> 12.686677 | F29: =F57/F71 -> 0.59175084 | H29: =H57/H71 -> 17.112785 | I29: =IFERROR(AVERAGE(C29:H29),"") -> 9.3468314 | J29: =SQRT((C29-I29)^2) -> 7.5220972
B30: Fixed Asset Turnover | C30: =C56/C69 -> 3.7754179 | D30: =D56/D69 -> 20.440726 | E30: =E56/E69 -> 4.9008502 | F30: =F56/F69 -> 29.321472 | H30: =H56/H69 -> 6.6196393 | I30: =IFERROR(AVERAGE(C30:H30),"") -> 13.011621 | J30: =SQRT((C30-I30)^2) -> 9.2362033
B31: Total Asset Turnover | C31: =C56/C70 -> 0.69160216 | D31: =D56/D70 -> 0.48670696 | E31: =E56/E70 -> 4.9008502 | F31: =F56/F70 -> 0.44238138 | H31: =H56/H70 -> 0.5223795 | I31: =IFERROR(AVERAGE(C31:H31),"") -> 1.408784 | J31: =SQRT((C31-I31)^2) -> 0.71718188
B32: Valuation | I32: =IFERROR(AVERAGE(C32:H32),"")
B33: Price/Earnings | C33: =C10/C62 -> 34.040149 | D33: 144.17 | E33: Negative | F33: =F10/F62 -> 24.895807 | H33: Negative | I33: =IFERROR(AVERAGE(C33:H33),"") -> 67.701986 | J33: =SQRT((C33-I33)^2) -> 33.661836
B34: Price/Sales | C34: =C10/C56 -> 7.5724477 | D34: =D10/D56 -> 15.702195 | E34: =E10/E56 -> 21.824383 | F34: =F10/F56 -> 8.9698665 | H34: =H10/H56 -> 13.902612 | I34: =IFERROR(AVERAGE(C34:H34),"") -> 13.594301 | J34: =SQRT((C34-I34)^2) -> 6.0218532
B35: Price/Book | C35: =C10/C74 -> 528.60999 | D35: =D10/D74 -> 52.140981 | E35: =E10/E74 -> 30.155953 | F35: =F10/F74 -> 7.6989045 | H35: =H10/H74 -> 30.268004 | I35: =IFERROR(AVERAGE(C35:H35),"") -> 129.77477 | J35: =SQRT((C35-I35)^2) -> 398.83522
B36: EV/Sales | C36: =(C73+C10-C65)/C56 -> 7.3535098 | D36: =(D73+D10-D65)/D56 -> 15.664942 | E36: =(E73+E10-E65)/E56 -> 21.060948 | F36: =(F73+F10-F65)/F56 -> 9.9420806 | H36: =(H73+H10-H65)/H56 -> 13.819597 | I36: =IFERROR(AVERAGE(C36:H36),"") -> 13.568215 | J36: =SQRT((C36-I36)^2) -> 6.2147056
B37: EV/EBITDA | C37: =(C73+C10-C65)/C58 -> 27.030628 | D37: =(D73+D10-D65)/D58 -> 126.90064 | E37: =(E73+E10-E65)/E58 -> 1596.2988 | F37: =(F73+F10-F65)/F58 -> 25.342496 | H37: =(H73+H10-H65)/H58 -> -170.84854 | I37: =IFERROR(AVERAGE(C37:H37),"") -> 320.94481 | J37: =SQRT((C37-I37)^2) -> 293.91418
B38: Stock Info | I38: =IFERROR(AVERAGE(C38:H38),"")
B39: Float | C39: =OP!M20 -> 0.842 | D39: 0.9886 | E39: 93,46% | F39: 77,92% | H39: 60,86% | I39: =IFERROR(AVERAGE(C39:H39),"") -> 0.9153 | J39: =SQRT((C39-I39)^2) -> 0.0733
B40: b (Yahoo) | C40: 1,05 | D40: 1,17 | E40: 1,05 | F40: 0,64 | H40: 0,87 | I40: =IFERROR(AVERAGE(C40:H40),"") | J40: =SQRT((C40-I40)^2) -> #VALUE!
B41: Dividend Yield (yahoo finance) | C41: =OP!M32 -> 0 | D41: 0 | E41: 0 | F41: 0 | H41: 0 | I41: =IFERROR(AVERAGE(C41:H41),"") -> 0 | J41: =SQRT((C41-I41)^2) -> 0
...

Sheet SARD
A1: 1769 | F1: Variables | K1: Rankings | P1: Difference | U1: Results | Y1: Additional Information | AD1: =#REF! -> #REF! | AE1: Selected Peers | AJ1: Price Multiples (TTM) | AM1: Enterprise Value Multiples (TTM)
B2: Ticker | C2: Company Name | D2: TRBC Industry | E2: Country | F2: ROE | G2: DEBT/EBIT | H2: Market Cap | I2: EPS Growth (2019-2023) (Refinitiv Smart Estimate) | J2: EBIT Margin | K2: ROE | L2: DEBT/EBIT | M2: Market Cap | N2: EPS Growth | O2: EBIT Margin | P2: ROE | Q2: DEBT/EBIT | R2: Market Cap | S2: EPS Growth | T2: EBIT Margin | U2: SARD Result | V2: SARD Peers | W2: SARD Peers adjusted Rank | Y2: Suitability | Z2: Relevant Information Missing | AA2: Author's Override | AB2: Observations | AE2: SARD Peers adjusted Rank | AF2: SARD Result | AG2: Ticker | AH2: Company Name | AI2: Country | AJ2: P / E | AK2: P / B | AL2: Price / Sales | AM2: EV / Sales | AN2: EV / EBITDA
A3: Benchmark | C3: Fortinet | D3: Software | E3: United States of America | F3: =Peers!C17% -> 0.15529015 | G3: 0.86880923 | H3: =Peers!C10*1000000 -> 39170000000 | I3: 16.62 | J3: 0.2346 | K3: =IFERROR(_xlfn.RANK.EQ(F3,F$3:F$1770),"N/A") -> 135 | L3: =IFERROR(_xlfn.RANK.EQ(G3,G$3:G$1770),"N/A") -> N/A | M3: =IFERROR(_xlfn.RANK.EQ(H3,H$3:H$1770),"N/A") -> 16 | N3: =IFERROR(_xlfn.RANK.EQ(I3,I$3:I$1770),"N/A") -> 186 | O3: =IFERROR(_xlfn.RANK.EQ(J3,J$3:J$1770),"N/A") -> 206 | P3: - | Q3: - | R3: - | S3: - | T3: - | U3: - | V3: - | W3: - | Y3: =IF(OR(Z3="Y",AA3="Y"),"Not suitable","") | Z3: =IF(N3="N/A","Y","") | AE3: {=_xlfn._xlws.SORT(_xlfn._xlws.FILTER(SARD!W3:W61,SARD!W3:W61<=SMALL(W3:W61,6)),,1)} -> #VALUE! | AF3: =_xlfn.XLOOKUP($AE3,$W:$W,U:U,,0) -> #VALUE! | AG3: =_xlfn.XLOOKUP($AE3,$W:$W,B:B,,0) -> #VALUE! | AH3: =_xlfn.XLOOKUP($AE3,$W:$W,C:C,,0) -> #VALUE! | AI3: =_xlfn.XLOOKUP($AE3,$W:$W,E:E,,0) -> #VALUE!
A4: Comparison | B4: MSFT.OQ | C4: Microsoft Corp | D4: Software | F4: -0.034 | G4: 2.804055 | H4: 2.7569977e+12 | I4: 6.17 | J4: 0.503 | K4: =IFERROR(_xlfn.RANK.EQ(F4,F$3:F$1770),"N/A") -> 335 | L4: =IFERROR(_xlfn.RANK.EQ(G4,G$3:G$1770),"N/A") -> N/A | M4: =IFERROR(_xlfn.RANK.EQ(H4,H$3:H$1770),"N/A") -> 1 | N4: =IFERROR(_xlfn.RANK.EQ(I4,I$3:I$1770),"N/A") -> 261 | O4: =IFERROR(_xlfn.RANK.EQ(J4,J$3:J$1770),"N/A") -> 20 | P4: 4.75 | Q4: 18.09 | R4: 6.02 | S4: 135.55 | T4: 268,966,447.00 | U4: =SUM(P4:T4) -> 0 | V4: =_xlfn.RANK.EQ(U4,$U$4:$U$61,1) -> 1 | W4: =IF(Y4="Not suitable","-",V4) -> 1 | Y4: =IF(OR(Z4="Y",AA4="Y"),"Not suitable","") | Z4: =IF(N4="N/A","Y","") | AF4: =_xlfn.XLOOKUP($AE4,$W:$W,U:U,,0) -> Results | AG4: =_xlfn.XLOOKUP($AE4,$W:$W,B:B,,0) -> 0 | AH4: =_xlfn.XLOOKUP($AE4,$W:$W,C:C,,0) -> 0 | AI4: =_xlfn.XLOOKUP($AE4,$W:$W,E:E,,0) -> 0
B5: ORCL.N | C5: Oracle Corp | D5: Software | F5: 0.393 | G5: 0.71692644 | H5: 3.0919338e+11 | I5: 4.75 | J5: 0.402 | K5: =IFERROR(_xlfn.RANK.EQ(F5,F$3:F$1770),"N/A") -> 32 | L5: =IFERROR(_xlfn.RANK.EQ(G5,G$3:G$1770),"N/A") -> N/A | M5: =IFERROR(_xlfn.RANK.EQ(H5,H$3:H$1770),"N/A") -> 2 | N5: =IFERROR(_xlfn.RANK.EQ(I5,I$3:I$1770),"N/A") -> 272 | O5: =IFERROR(_xlfn.RANK.EQ(J5,J$3:J$1770),"N/A") -> 56 | P5: 19.40 | Q5: 44.78 | R5: 20.15 | S5: 1,118.06 | T5: 24,713,557.00 | U5: =SUM(P5:T5) -> 0 | V5: =_xlfn.RANK.EQ(U5,$U$4:$U$61,1) -> 1 | W5: =IF(Y5="Not suitable","-",V5) -> 1 | Y5: =IF(OR(Z5="Y",AA5="Y"),"Not suitable","") | Z5: =IF(N5="N/A","Y","") | AF5: =_xlfn.XLOOKUP($AE5,$W:$W,U:U,,0) -> Results | AG5: =_xlfn.XLOOKUP($AE5,$W:$W,B:B,,0) -> 0 | AH5: =_xlfn.XLOOKUP($AE5,$W:$W,C:C,,0) -> 0 | AI5: =_xlfn.XLOOKUP($AE5,$W:$W,E:E,,0) -> 0
B6: ADBE.OQ | C6: Adobe Inc | D6: Software | F6: -6.079 | G6: 6.5694475 | H6: 277177534000 | I6: 9.84 | J6: 0.385 | K6: =IFERROR(_xlfn.RANK.EQ(F6,F$3:F$1770),"N/A") -> 506 | L6: =IFERROR(_xlfn.RANK.EQ(G6,G$3:G$1770),"N/A") -> N/A | M6: =IFERROR(_xlfn.RANK.EQ(H6,H$3:H$1770),"N/A") -> 3 | N6: =IFERROR(_xlfn.RANK.EQ(I6,I$3:I$1770),"N/A") -> 230 | O6: =IFERROR(_xlfn.RANK.EQ(J6,J$3:J$1770),"N/A") -> 63 | P6: 0.78 | Q6: 13.59 | S6: 0.07 | T6: 160,694,556.00 | U6: =SUM(P6:T6) -> 0 | V6: =_xlfn.RANK.EQ(U6,$U$4:$U$61,1) -> 1 | W6: =IF(Y6="Not suitable","-",V6) -> 1 | Y6: =IF(OR(Z6="Y",AA6="Y"),"Not suitable","") | Z6: =IF(N6="N/A","Y","") | AF6: =_xlfn.XLOOKUP($AE6,$W:$W,U:U,,0) -> Results | AG6: =_xlfn.XLOOKUP($AE6,$W:$W,B:B,,0) -> 0 | AH6: =_xlfn.XLOOKUP($AE6,$W:$W,C:C,,0) -> 0 | AI6: =_xlfn.XLOOKUP($AE6,$W:$W,E:E,,0) -> 0
B7: SAPG.DE | C7: SAP SE | D7: Software | F7: 0.448 | G7: 0.65167298 | H7: 1.9502593e+11 | I7: -4,05 | J7: 0.254 | K7: =IFERROR(_xlfn.RANK.EQ(F7,F$3:F$1770),"N/A") -> 20 | L7: =IFERROR(_xlfn.RANK.EQ(G7,G$3:G$1770),"N/A") -> N/A | M7: =IFERROR(_xlfn.RANK.EQ(H7,H$3:H$1770),"N/A") -> 4 | N7: =IFERROR(_xlfn.RANK.EQ(I7,I$3:I$1770),"N/A") -> N/A | O7: =IFERROR(_xlfn.RANK.EQ(J7,J$3:J$1770),"N/A") -> 175 | P7: 5.80 | Q7: 22.73 | R7: 4.83 | S7: 159.92 | T7: 1,228,504,232.00 | U7: =SUM(P7:T7) -> 0 | V7: =_xlfn.RANK.EQ(U7,$U$4:$U$61,1) -> 1 | W7: =IF(Y7="Not suitable","-",V7) -> - | Y7: =IF(OR(Z7="Y",AA7="Y"),"Not suitable","") -> Not suitable | Z7: =IF(N7="N/A","Y","") -> Y | AF7: =_xlfn.XLOOKUP($AE7,$W:$W,U:U,,0) -> Results | AG7: =_xlfn.XLOOKUP($AE7,$W:$W,B:B,,0) -> 0 | AH7: =_xlfn.XLOOKUP($AE7,$W:$W,C:C,,0) -> 0 | AI7: =_xlfn.XLOOKUP($AE7,$W:$W,E:E,,0) -> 0
B8: NOW.N | C8: ServiceNow Inc | D8: Software | F8: 0.121 | G8: 2.4128711 | H8: 140974400000 | I8: 12.87 | J8: 0.138 | K8: =IFERROR(_xlfn.RANK.EQ(F8,F$3:F$1770),"N/A") -> 173 | L8: =IFERROR(_xlfn.RANK.EQ(G8,G$3:G$1770),"N/A") -> N/A | M8: =IFERROR(_xlfn.RANK.EQ(H8,H$3:H$1770),"N/A") -> 5 | N8: =IFERROR(_xlfn.RANK.EQ(I8,I$3:I$1770),"N/A") -> 207 | O8: =IFERROR(_xlfn.RANK.EQ(J8,J$3:J$1770),"N/A") -> 372 | S8: 0.01 | T8: 1,411,269,476.00 | U8: =SUM(P8:T8) -> 0 | V8: =_xlfn.RANK.EQ(U8,$U$4:$U$61,1) -> 1 | W8: =IF(Y8="Not suitable","-",V8) -> 1 | Y8: =IF(OR(Z8="Y",AA8="Y"),"Not suitable","") | Z8: =IF(N8="N/A","Y","") | AF8: =_xlfn.XLOOKUP($AE8,$W:$W,U:U,,0) -> Results | AG8: =_xlfn.XLOOKUP($AE8,$W:$W,B:B,,0) -> 0 | AH8: =_xlfn.XLOOKUP($AE8,$W:$W,C:C,,0) -> 0 | AI8: =_xlfn.XLOOKUP($AE8,$W:$W,E:E,,0) -> 0
B9: PANW.OQ | C9: Palo Alto Networks Inc | D9: Software | F9: 0.354 | G9: 4.1859155 | H9: 92575233000 | I9: 18.39 | J9: 0.117 | K9: =IFERROR(_xlfn.RANK.EQ(F9,F$3:F$1770),"N/A") -> 38 | L9: =IFERROR(_xlfn.RANK.EQ(G9,G$3:G$1770),"N/A") -> N/A | M9: =IFERROR(_xlfn.RANK.EQ(H9,H$3:H$1770),"N/A") -> 6 | N9: =IFERROR(_xlfn.RANK.EQ(I9,I$3:I$1770),"N/A") -> 180 | O9: =IFERROR(_xlfn.RANK.EQ(J9,J$3:J$1770),"N/A") -> 439 | P9: 2.83 | R9: 0.73 | S9: 34.85 | T9: 65,514,133.00 | U9: =SUM(P9:T9) -> 0 | V9: =_xlfn.RANK.EQ(U9,$U$4:$U$61,1) -> 1 | W9: =IF(Y9="Not suitable","-",V9) -> 1 | Y9: =IF(OR(Z9="Y",AA9="Y"),"Not suitable","") | Z9: =IF(N9="N/A","Y","") | AE9: Median | AJ9: =MEDIAN(AJ3:AJ8) -> #NUM! | AK9: =MEDIAN(AK3:AK8) -> #NUM! | AL9: =MEDIAN(AL3:AL8) -> #NUM! | AM9: =MEDIAN(AM3:AM8) -> #NUM! | AN9: =MEDIAN(AN3:AN8) -> #NUM!
B10: SNPS.OQ | C10: Synopsys Inc | D10: Software | F10: 1.471 | G10: 5.1420088 | H10: 81219109950 | I10: 10.03 | J10: 0.274 | K10: =IFERROR(_xlfn.RANK.EQ(F10,F$3:F$1770),"N/A") -> 3 | L10: =IFERROR(_xlfn.RANK.EQ(G10,G$3:G$1770),"N/A") -> N/A | M10: =IFERROR(_xlfn.RANK.EQ(H10,H$3:H$1770),"N/A") -> 7 | N10: =IFERROR(_xlfn.RANK.EQ(I10,I$3:I$1770),"N/A") -> 229 | O10: =IFERROR(_xlfn.RANK.EQ(J10,J$3:J$1770),"N/A") -> 153 | P10: 14.47 | Q10: 37.56 | R10: 13.63 | S10: 608.78 | T10: 455,300,000.00 | U10: =SUM(P10:T10) -> 0 | V10: =_xlfn.RANK.EQ(U10,$U$4:$U$61,1) -> 1 | W10: =IF(Y10="Not suitable","-",V10) -> 1 | Y10: =IF(OR(Z10="Y",AA10="Y"),"Not suitable","") | Z10: =IF(N10="N/A","Y","") | AE10: Benchmark Data | AJ10: Price / Share
B11: WDAY.OQ | C11: Workday Inc | D11: Software | F11: 0.298 | G11: 0.013279358 | H11: 71635940000 | I11: 6.89 | J11: 0.043 | K11: =IFERROR(_xlfn.RANK.EQ(F11,F$3:F$1770),"N/A") -> 51 | L11: =IFERROR(_xlfn.RANK.EQ(G11,G$3:G$1770),"N/A") -> N/A | M11: =IFERROR(_xlfn.RANK.EQ(H11,H$3:H$1770),"N/A") -> 8 | N11: =IFERROR(_xlfn.RANK.EQ(I11,I$3:I$1770),"N/A") -> 254 | O11: =IFERROR(_xlfn.RANK.EQ(J11,J$3:J$1770),"N/A") -> 617 | S11: 0.00 | T11: 25,990,731.00 | U11: =SUM(P11:T11) -> 0 | V11: =_xlfn.RANK.EQ(U11,$U$4:$U$61,1) -> 1 | W11: =IF(Y11="Not suitable","-",V11) -> 1 | Y11: =IF(OR(Z11="Y",AA11="Y"),"Not suitable","") | Z11: =IF(N11="N/A","Y","") | AE11: Benchmark | AF11: Multiplier | AG11: # Shares | AH11: -Debt + Cash | AJ11: P / E | AK11: P / B | AL11: Price / Sales | AM11: EV / Sales | AN11: EV / EBITDA
B12: CDNS.OQ | C12: Cadence Design Systems Inc | D12: Software | F12: 0.188 | G12: -13,3930423 | H12: 70591927140 | I12: 9.26 | J12: 0.325 | K12: =IFERROR(_xlfn.RANK.EQ(F12,F$3:F$1770),"N/A") -> 105 | L12: =IFERROR(_xlfn.RANK.EQ(G12,G$3:G$1770),"N/A") -> N/A | M12: =IFERROR(_xlfn.RANK.EQ(H12,H$3:H$1770),"N/A") -> 9 | N12: =IFERROR(_xlfn.RANK.EQ(I12,I$3:I$1770),"N/A") -> 233 | O12: =IFERROR(_xlfn.RANK.EQ(J12,J$3:J$1770),"N/A") -> 99 | P12: 2.34 | Q12: 23.03 | R12: 0.42 | S12: 10.15 | T12: 34,166,450.00 | U12: =SUM(P12:T12) -> 0 | V12: =_xlfn.RANK.EQ(U12,$U$4:$U$61,1) -> 1 | W12: =IF(Y12="Not suitable","-",V12) -> 1 | Y12: =IF(OR(Z12="Y",AA12="Y"),"Not suitable","") | Z12: =IF(N12="N/A","Y","") | AE12: =C3 -> Fortinet | AF12: 1000000 | AH12: =-'Fin. Data'!C58*SARD!AF12+'Fin. Data'!C39*SARD!AF12 -> 596800000 | AJ12: =AJ9*'Fin. Data'!C23*AF$12/AG$12 -> #NUM! | AK12: =AK9*'Fin. Data'!C64*AF$12/AG$12 -> #NUM! | AL12: =AL9*'Fin. Data'!C5*AF$12/AG$12 -> #NUM! | AM12: =(AM9*'Fin. Data'!C5*$AF12+$AH12)/$AG12 -> #NUM! | AN12: =(AN9*'Fin. Data'!C19*$AF12+$AH12)/$AG12 -> #NUM!
B13: DAST.PA | C13: Dassault Systemes SE | D13: Software | F13: 0.428 | G13: 0.69670246 | H13: 6.3032618e+10 | I13: 5.7 | K13: =IFERROR(_xlfn.RANK.EQ(F13,F$3:F$1770),"N/A") -> 25 | L13: =IFERROR(_xlfn.RANK.EQ(G13,G$3:G$1770),"N/A") -> N/A | M13: =IFERROR(_xlfn.RANK.EQ(H13,H$3:H$1770),"N/A") -> 10 | N13: =IFERROR(_xlfn.RANK.EQ(I13,I$3:I$1770),"N/A") -> 264 | O13: =IFERROR(_xlfn.RANK.EQ(J13,J$3:J$1770),"N/A") -> 708 | P13: 10.63 | Q13: 26.13 | R13: 14.17 | S13: 534.80 | T13: 106,822,117.00 | U13: =SUM(P13:T13) -> 0 | V13: =_xlfn.RANK.EQ(U13,$U$4:$U$61,1) -> 1 | W13: =IF(Y13="Not suitable","-",V13) -> 1 | Y13: =IF(OR(Z13="Y",AA13="Y"),"Not suitable","") | Z13: =IF(N13="N/A","Y","") | AE13: By Consolidated Average | AJ13: =AVERAGE(AJ12:AL12) -> #NUM! | AM13: =AVERAGE(AM12:AN12) -> #NUM!
B14: ROP.OQ | C14: Roper Technologies Inc | D14: Software | F14: 0.224 | G14: 2.7048498 | H14: 5.7128468e+10 | I14: 3.39 | J14: 0.407 | K14: =IFERROR(_xlfn.RANK.EQ(F14,F$3:F$1770),"N/A") -> 84 | L14: =IFERROR(_xlfn.RANK.EQ(G14,G$3:G$1770),"N/A") -> N/A | M14: =IFERROR(_xlfn.RANK.EQ(H14,H$3:H$1770),"N/A") -> 11 | N14: =IFERROR(_xlfn.RANK.EQ(I14,I$3:I$1770),"N/A") -> 284 | O14: =IFERROR(_xlfn.RANK.EQ(J14,J$3:J$1770),"N/A") -> 55 | P14: 2.52 | R14: -0.03 | S14: 0.85 | T14: 2,144,492,465.00 | U14: =SUM(P14:T14) -> 0 | V14: =_xlfn.RANK.EQ(U14,$U$4:$U$61,1) -> 1 | W14: =IF(Y14="Not suitable","-",V14) -> 1 | Y14: =IF(OR(Z14="Y",AA14="Y"),"Not suitable","") | Z14: =IF(N14="N/A","Y","") | AE14: Upside | AJ14: =AJ13/OP!C20-1 -> #NUM! | AM14: =AM13/OP!C20-1 -> #NUM!
B15: CSU.TO | C15: Constellation Software Inc | D15: Software | F15: 0.07 | G15: 4.3697606 | H15: 5.1019146e+10 | I15: 0.44 | J15: 0.259 | K15: =IFERROR(_xlfn.RANK.EQ(F15,F$3:F$1770),"N/A") -> 229 | L15: =IFERROR(_xlfn.RANK.EQ(G15,G$3:G$1770),"N/A") -> N/A | M15: =IFERROR(_xlfn.RANK.EQ(H15,H$3:H$1770),"N/A") -> 12 | N15: =IFERROR(_xlfn.RANK.EQ(I15,I$3:I$1770),"N/A") -> 306 | O15: =IFERROR(_xlfn.RANK.EQ(J15,J$3:J$1770),"N/A") -> 168 | P15: 15.62 | S15: 0.03 | T15: 16,331,032.00 | U15: =SUM(P15:T15) -> 0 | V15: =_xlfn.RANK.EQ(U15,$U$4:$U$61,1) -> 1 | W15: =IF(Y15="Not suitable","-",V15) -> 1 | Y15: =IF(OR(Z15="Y",AA15="Y"),"Not suitable","") | Z15: =IF(N15="N/A","Y","")
B16: TEAM.OQ | C16: Atlassian Corp | D16: Software | G16: 2.0261364 | H16: 4.8476349e+10 | I16: 7.46 | J16: -3,1% | K16: =IFERROR(_xlfn.RANK.EQ(F16,F$3:F$1770),"N/A") -> 316 | L16: =IFERROR(_xlfn.RANK.EQ(G16,G$3:G$1770),"N/A") -> N/A | M16: =IFERROR(_xlfn.RANK.EQ(H16,H$3:H$1770),"N/A") -> 13 | N16: =IFERROR(_xlfn.RANK.EQ(I16,I$3:I$1770),"N/A") -> 248 | O16: =IFERROR(_xlfn.RANK.EQ(J16,J$3:J$1770),"N/A") -> N/A | P16: 14.01 | S16: 0.06 | T16: 121,556,731.00 | U16: =SUM(P16:T16) -> 0 | V16: =_xlfn.RANK.EQ(U16,$U$4:$U$61,1) -> 1 | W16: =IF(Y16="Not suitable","-",V16) -> 1 | Y16: =IF(OR(Z16="Y",AA16="Y"),"Not suitable","") | Z16: =IF(N16="N/A","Y","")
B17: ADSK.OQ | C17: Autodesk Inc | D17: Software | F17: 1.003 | G17: -5,338907642 | H17: 47882806348 | I17: 11.13 | J17: 0.236 | K17: =IFERROR(_xlfn.RANK.EQ(F17,F$3:F$1770),"N/A") -> 9 | L17: =IFERROR(_xlfn.RANK.EQ(G17,G$3:G$1770),"N/A") -> N/A | M17: =IFERROR(_xlfn.RANK.EQ(H17,H$3:H$1770),"N/A") -> 14 | N17: =IFERROR(_xlfn.RANK.EQ(I17,I$3:I$1770),"N/A") -> 219 | O17: =IFERROR(_xlfn.RANK.EQ(J17,J$3:J$1770),"N/A") -> 204 | P17: 2.59 | Q17: 11.60 | R17: 0.20 | S17: 3.06 | T17: 252,577,656.00 | U17: =SUM(P17:T17) -> 0 | V17: =_xlfn.RANK.EQ(U17,$U$4:$U$61,1) -> 1 | W17: =IF(Y17="Not suitable","-",V17) -> 1 | Y17: =IF(OR(Z17="Y",AA17="Y"),"Not suitable","") | Z17: =IF(N17="N/A","Y","")
B18: FTNT.OQ | C18: Fortinet Inc | D18: Software | F18: 1.409 | G18: 2.2102713 | H18: 3.9409121e+10 | I18: 16.62 | J18: 0.255 | K18: =IFERROR(_xlfn.RANK.EQ(F18,F$3:F$1770),"N/A") -> 4 | L18: =IFERROR(_xlfn.RANK.EQ(G18,G$3:G$1770),"N/A") -> N/A | M18: =IFERROR(_xlfn.RANK.EQ(H18,H$3:H$1770),"N/A") -> 15 | N18: =IFERROR(_xlfn.RANK.EQ(I18,I$3:I$1770),"N/A") -> 186 | O18: =IFERROR(_xlfn.RANK.EQ(J18,J$3:J$1770),"N/A") -> 173 | P18: 0.93 | S18: 0.26 | T18: 108,008,562.00 | U18: =SUM(P18:T18) -> 0 | V18: =_xlfn.RANK.EQ(U18,$U$4:$U$61,1) -> 1 | W18: =IF(Y18="Not suitable","-",V18) -> 1 | Y18: =IF(OR(Z18="Y",AA18="Y"),"Not suitable","") | Z18: =IF(N18="N/A","Y","")
B19: DDOG.OQ | C19: Datadog Inc | D19: Software | F19: -6.486 | G19: 1.0263212 | H19: 37783672740 | I19: 31.03 | J19: -2,8% | K19: =IFERROR(_xlfn.RANK.EQ(F19,F$3:F$1770),"N/A") -> 507 | L19: =IFERROR(_xlfn.RANK.EQ(G19,G$3:G$1770),"N/A") -> N/A | M19: =IFERROR(_xlfn.RANK.EQ(H19,H$3:H$1770),"N/A") -> 17 | N19: =IFERROR(_xlfn.RANK.EQ(I19,I$3:I$1770),"N/A") -> 141 | O19: =IFERROR(_xlfn.RANK.EQ(J19,J$3:J$1770),"N/A") -> N/A | P19: 1.19 | Q19: 232.61 | S19: 1.76 | T19: 6,574,863.00 | U19: =SUM(P19:T19) -> 0 | V19: =_xlfn.RANK.EQ(U19,$U$4:$U$61,1) -> 1 | W19: =IF(Y19="Not suitable","-",V19) -> 1 | Y19: =IF(OR(Z19="Y",AA19="Y"),"Not suitable","") | Z19: =IF(N19="N/A","Y","")
B20: PLTR.N | C20: Palantir Technologies Inc | D20: Software | F20: 0.276 | G20: -12,58790357 | H20: 3.7453231e+10 | I20: 11.11 | J20: 0.031 | K20: =IFERROR(_xlfn.RANK.EQ(F20,F$3:F$1770),"N/A") -> 60 | L20: =IFERROR(_xlfn.RANK.EQ(G20,G$3:G$1770),"N/A") -> N/A | M20: =IFERROR(_xlfn.RANK.EQ(H20,H$3:H$1770),"N/A") -> 18 | N20: =IFERROR(_xlfn.RANK.EQ(I20,I$3:I$1770),"N/A") -> 220 | O20: =IFERROR(_xlfn.RANK.EQ(J20,J$3:J$1770),"N/A") -> 651 | P20: 1.47 | Q20: 6.21 | R20: 0.13 | S20: 1.62 | T20: 14,535,195.00 | U20: =SUM(P20:T20) -> 0 | V20: =_xlfn.RANK.EQ(U20,$U$4:$U$61,1) -> 1 | W20: =IF(Y20="Not suitable","-",V20) -> 1 | Y20: =IF(OR(Z20="Y",AA20="Y"),"Not suitable","") | Z20: =IF(N20="N/A","Y","")
B21: EA.OQ | C21: Electronic Arts Inc | D21: Software | F21: 0.038 | G21: 0 | H21: 3.6458402e+10 | I21: 3.9 | J21: 0.262 | K21: =IFERROR(_xlfn.RANK.EQ(F21,F$3:F$1770),"N/A") -> 270 | L21: =IFERROR(_xlfn.RANK.EQ(G21,G$3:G$1770),"N/A") -> N/A | M21: =IFERROR(_xlfn.RANK.EQ(H21,H$3:H$1770),"N/A") -> 19 | N21: =IFERROR(_xlfn.RANK.EQ(I21,I$3:I$1770),"N/A") -> 279 | O21: =IFERROR(_xlfn.RANK.EQ(J21,J$3:J$1770),"N/A") -> 162 | P21: 2.31 | Q21: 12.77 | R21: 0.03 | S21: 1.05 | T21: 83,207,397.00 | U21: =SUM(P21:T21) -> 0 | V21: =_xlfn.RANK.EQ(U21,$U$4:$U$61,1) -> 1 | W21: =IF(Y21="Not suitable","-",V21) -> 1 | Y21: =IF(OR(Z21="Y",AA21="Y"),"Not suitable","") | Z21: =IF(N21="N/A","Y","")
B22: TTD.OQ | C22: Trade Desk Inc | D22: Software | F22: 0.241 | G22: 1.2677006 | H22: 3.3722629e+10 | I22: 9.2 | J22: 0.12 | K22: =IFERROR(_xlfn.RANK.EQ(F22,F$3:F$1770),"N/A") -> 72 | L22: =IFERROR(_xlfn.RANK.EQ(G22,G$3:G$1770),"N/A") -> N/A | M22: =IFERROR(_xlfn.RANK.EQ(H22,H$3:H$1770),"N/A") -> 20 | N22: =IFERROR(_xlfn.RANK.EQ(I22,I$3:I$1770),"N/A") -> 235 | O22: =IFERROR(_xlfn.RANK.EQ(J22,J$3:J$1770),"N/A") -> 424 | P22: 9.02 | Q22: 38.02 | R22: 6.60 | S22: 223.84 | T22: 213,915,325.00 | U22: =SUM(P22:T22) -> 0 | V22: =_xlfn.RANK.EQ(U22,$U$4:$U$61,1) -> 1 | W22: =IF(Y22="Not suitable","-",V22) -> 1 | Y22: =IF(OR(Z22="Y",AA22="Y"),"Not suitable","") | Z22: =IF(N22="N/A","Y","")
B23: ZS.OQ | C23: Zscaler Inc | D23: Software | F23: 0.287 | G23: 0 | H23: 2.9672106e+10 | I23: 32.92 | J23: -7,9% | K23: =IFERROR(_xlfn.RANK.EQ(F23,F$3:F$1770),"N/A") -> 58 | L23: =IFERROR(_xlfn.RANK.EQ(G23,G$3:G$1770),"N/A") -> N/A | M23: =IFERROR(_xlfn.RANK.EQ(H23,H$3:H$1770),"N/A") -> 21 | N23: =IFERROR(_xlfn.RANK.EQ(I23,I$3:I$1770),"N/A") -> 134 | O23: =IFERROR(_xlfn.RANK.EQ(J23,J$3:J$1770),"N/A") -> N/A | P23: 0.18 | Q23: 0.20 | S23: 0.30 | T23: 14,920,585.00 | U23: =SUM(P23:T23) -> 0 | V23: =_xlfn.RANK.EQ(U23,$U$4:$U$61,1) -> 1 | W23: =IF(Y23="Not suitable","-",V23) -> 1 | Y23: =IF(OR(Z23="Y",AA23="Y"),"Not suitable","") | Z23: =IF(N23="N/A","Y","")
B24: MDB.OQ | C24: MongoDB Inc | D24: Software | F24: 0.429 | G24: -4,995788973 | H24: 2.7649709e+10 | J24: -14,0% | K24: =IFERROR(_xlfn.RANK.EQ(F24,F$3:F$1770),"N/A") -> 23 | L24: =IFERROR(_xlfn.RANK.EQ(G24,G$3:G$1770),"N/A") -> N/A | M24: =IFERROR(_xlfn.RANK.EQ(H24,H$3:H$1770),"N/A") -> 22 | N24: =IFERROR(_xlfn.RANK.EQ(I24,I$3:I$1770),"N/A") -> N/A | O24: =IFERROR(_xlfn.RANK.EQ(J24,J$3:J$1770),"N/A") -> N/A | S24: 0.00 | T24: 3,302,597.00 | U24: =SUM(P24:T24) -> 0 | V24: =_xlfn.RANK.EQ(U24,$U$4:$U$61,1) -> 1 | W24: =IF(Y24="Not suitable","-",V24) -> - | Y24: =IF(OR(Z24="Y",AA24="Y"),"Not suitable","") -> Not suitable | Z24: =IF(N24="N/A","Y","") -> Y
B25: FICO.N | C25: Fair Isaac Corp | D25: Software | F25: 0.092 | G25: -3,430076012 | H25: 2.763124e+10 | I25: 10.62 | J25: 0.432 | K25: =IFERROR(_xlfn.RANK.EQ(F25,F$3:F$1770),"N/A") -> 203 | L25: =IFERROR(_xlfn.RANK.EQ(G25,G$3:G$1770),"N/A") -> N/A | M25: =IFERROR(_xlfn.RANK.EQ(H25,H$3:H$1770),"N/A") -> 23 | N25: =IFERROR(_xlfn.RANK.EQ(I25,I$3:I$1770),"N/A") -> 222 | O25: =IFERROR(_xlfn.RANK.EQ(J25,J$3:J$1770),"N/A") -> 45 | P25: 1.01 | Q25: 14.27 | S25: 1.42 | T25: 44,732,379.00 | U25: =SUM(P25:T25) -> 0 | V25: =_xlfn.RANK.EQ(U25,$U$4:$U$61,1) -> 1 | W25: =IF(Y25="Not suitable","-",V25) -> 1 | Y25: =IF(OR(Z25="Y",AA25="Y"),"Not suitable","") | Z25: =IF(N25="N/A","Y","")
B26: TTWO.OQ | C26: Take-Two Interactive Software Inc | D26: Software | F26: -0.671 | G26: 2.9048057 | H26: 2.6226128e+10 | I26: -15,03 | J26: 0.132 | K26: =IFERROR(_xlfn.RANK.EQ(F26,F$3:F$1770),"N/A") -> 485 | L26: =IFERROR(_xlfn.RANK.EQ(G26,G$3:G$1770),"N/A") -> N/A | M26: =IFERROR(_xlfn.RANK.EQ(H26,H$3:H$1770),"N/A") -> 24 | N26: =IFERROR(_xlfn.RANK.EQ(I26,I$3:I$1770),"N/A") -> N/A | O26: =IFERROR(_xlfn.RANK.EQ(J26,J$3:J$1770),"N/A") -> 391 | P26: 1.92 | Q26: 10.41 | R26: 0.09 | S26: 1.47 | T26: 83,874,458.00 | U26: =SUM(P26:T26) -> 0 | V26: =_xlfn.RANK.EQ(U26,$U$4:$U$61,1) -> 1 | W26: =IF(Y26="Not suitable","-",V26) -> - | Y26: =IF(OR(Z26="Y",AA26="Y"),"Not suitable","") -> Not suitable | Z26: =IF(N26="N/A","Y","") -> Y
B27: SPLK.OQ | C27: Splunk Inc | D27: Software | F27: 0.352 | G27: -3,342522249 | H27: 25445185000 | J27: 0.019 | K27: =IFERROR(_xlfn.RANK.EQ(F27,F$3:F$1770),"N/A") -> 39 | L27: =IFERROR(_xlfn.RANK.EQ(G27,G$3:G$1770),"N/A") -> N/A | M27: =IFERROR(_xlfn.RANK.EQ(H27,H$3:H$1770),"N/A") -> 25 | N27: =IFERROR(_xlfn.RANK.EQ(I27,I$3:I$1770),"N/A") -> N/A | O27: =IFERROR(_xlfn.RANK.EQ(J27,J$3:J$1770),"N/A") -> 668 | P27: 1.85 | Q27: 15.54 | R27: 0.12 | S27: 3.35 | T27: 57,337,611.00 | U27: =SUM(P27:T27) -> 0 | V27: =_xlfn.RANK.EQ(U27,$U$4:$U$61,1) -> 1 | W27: =IF(Y27="Not suitable","-",V27) -> - | Y27: =IF(OR(Z27="Y",AA27="Y"),"Not suitable","") -> Not suitable | Z27: =IF(N27="N/A","Y","") -> Y
B28: RBLX.N | C28: Roblox Corp | D28: Software | F28: 8.901 | G28: -16,45369969 | H28: 2.4862157e+10 | I28: 38.38 | J28: -38,4% | K28: =IFERROR(_xlfn.RANK.EQ(F28,F$3:F$1770),"N/A") -> 1 | L28: =IFERROR(_xlfn.RANK.EQ(G28,G$3:G$1770),"N/A") -> N/A | M28: =IFERROR(_xlfn.RANK.EQ(H28,H$3:H$1770),"N/A") -> 26 | N28: =IFERROR(_xlfn.RANK.EQ(I28,I$3:I$1770),"N/A") -> 113 | O28: =IFERROR(_xlfn.RANK.EQ(J28,J$3:J$1770),"N/A") -> N/A | P28: 1.15 | Q28: 8.84 | S28: 2.24 | T28: 21,187,619.00 | U28: =SUM(P28:T28) -> 0 | V28: =_xlfn.RANK.EQ(U28,$U$4:$U$61,1) -> 1 | W28: =IF(Y28="Not suitable","-",V28) -> 1 | Y28: =IF(OR(Z28="Y",AA28="Y"),"Not suitable","") | Z28: =IF(N28="N/A","Y","")
B29: ANSS.OQ | C29: ANSYS Inc | D29: Software | F29: -2.075 | G29: -1,07057927 | H29: 2.4855178e+10 | I29: 3.39 | J29: 0.308 | K29: =IFERROR(_xlfn.RANK.EQ(F29,F$3:F$1770),"N/A") -> 499 | L29: 0.46 | M29: =IFERROR(_xlfn.RANK.EQ(H29,H$3:H$1770),"N/A") -> 27 | N29: =IFERROR(_xlfn.RANK.EQ(I29,I$3:I$1770),"N/A") -> 284 | O29: =IFERROR(_xlfn.RANK.EQ(J29,J$3:J$1770),"N/A") -> 118 | P29: 5.77 | Q29: 24.22 | R29: 0.39 | S29: 14.79 | T29: 1,024,369,074.00 | U29: =SUM(P29:T29) -> 0 | V29: =_xlfn.RANK.EQ(U29,$U$4:$U$61,1) -> 1 | W29: =IF(Y29="Not suitable","-",V29) -> 1 | Y29: =IF(OR(Z29="Y",AA29="Y"),"Not suitable","") | Z29: =IF(N29="N/A","Y","")
B30: HUBS.N | C30: HubSpot Inc | D30: Software | F30: 0.149 | G30: 1.2497226 | H30: 2.476464e+10 | I30: 25.84 | J30: -1,6% | K30: =IFERROR(_xlfn.RANK.EQ(F30,F$3:F$1770),"N/A") -> 142 | M30: =IFERROR(_xlfn.RANK.EQ(H30,H$3:H$1770),"N/A") -> 28 | N30: =IFERROR(_xlfn.RANK.EQ(I30,I$3:I$1770),"N/A") -> 156 | O30: =IFERROR(_xlfn.RANK.EQ(J30,J$3:J$1770),"N/A") -> N/A | P30: 1.19 | Q30: 4.36 | S30: 0.08 | T30: 124,603,134.00 | U30: =SUM(P30:T30) -> 0 | V30: =_xlfn.RANK.EQ(U30,$U$4:$U$61,1) -> 1 | W30: =IF(Y30="Not suitable","-",V30) -> 1 | Y30: =IF(OR(Z30="Y",AA30="Y"),"Not suitable","") | Z30: =IF(N30="N/A","Y","")
B31: SNAP.N | C31: Snap Inc | D31: Software | F31: 0.152 | G31: -4,163362389 | H31: 2.4300797e+10 | I31: 7.58 | J31: -27,6% | K31: =IFERROR(_xlfn.RANK.EQ(F31,F$3:F$1770),"N/A") -> 139 | M31: =IFERROR(_xlfn.RANK.EQ(H31,H$3:H$1770),"N/A") -> 29 | N31: =IFERROR(_xlfn.RANK.EQ(I31,I$3:I$1770),"N/A") -> 247 | O31: =IFERROR(_xlfn.RANK.EQ(J31,J$3:J$1770),"N/A") -> N/A | S31: 0.04 | T31: 10,004,131.00 | U31: =SUM(P31:T31) -> 0 | V31: =_xlfn.RANK.EQ(U31,$U$4:$U$61,1) -> 1 | W31: =IF(Y31="Not suitable","-",V31) -> 1 | Y31: =IF(OR(Z31="Y",AA31="Y"),"Not suitable","") | Z31: =IF(N31="N/A","Y","")
B32: SE.N | C32: Sea Ltd | D32: Software | F32: 0.087 | G32: -3,102332063 | H32: 2.390367e+10 | I32: -18,65 | J32: 0.106 | K32: =IFERROR(_xlfn.RANK.EQ(F32,F$3:F$1770),"N/A") -> 207 | L32: 0.94 | M32: =IFERROR(_xlfn.RANK.EQ(H32,H$3:H$1770),"N/A") -> 30 | N32: =IFERROR(_xlfn.RANK.EQ(I32,I$3:I$1770),"N/A") -> N/A | O32: =IFERROR(_xlfn.RANK.EQ(J32,J$3:J$1770),"N/A") -> 468 | P32: 0.89 | Q32: 6.34 | R32: 1.02 | S32: 9.62 | T32: 49,093,055.00 | U32: =SUM(P32:T32) -> 0 | V32: =_xlfn.RANK.EQ(U32,$U$4:$U$61,1) -> 1 | W32: =IF(Y32="Not suitable","-",V32) -> - | Y32: =IF(OR(Z32="Y",AA32="Y"),"Not suitable","") -> Not suitable | Z32: =IF(N32="N/A","Y","") -> Y
B33: ZM.OQ | C33: Zoom Video Communications Inc | D33: Software | F33: -0.344 | G33: -4,229138283 | H33: 2.1897182e+10 | I33: 2.03 | J33: 0.088 | K33: =IFERROR(_xlfn.RANK.EQ(F33,F$3:F$1770),"N/A") -> 455 | L33: 5.11 | M33: =IFERROR(_xlfn.RANK.EQ(H33,H$3:H$1770),"N/A") -> 31 | N33: =IFERROR(_xlfn.RANK.EQ(I33,I$3:I$1770),"N/A") -> 294 | O33: =IFERROR(_xlfn.RANK.EQ(J33,J$3:J$1770),"N/A") -> 524 | P33: 17.92 | Q33: 54.99 | R33: 4.23 | S33: 259.47 | T33: 272,062,000.00 | U33: =SUM(P33:T33) -> 0 | V33: =_xlfn.RANK.EQ(U33,$U$4:$U$61,1) -> 1 | W33: =IF(Y33="Not suitable","-",V33) -> 1 | Y33: =IF(OR(Z33="Y",AA33="Y"),"Not suitable","") | Z33: =IF(N33="N/A","Y","")
B34: 688111.SS | C34: Beijing Kingsoft Office Software Inc | D34: Software | F34: 0.222 | G34: 0 | H34: 2.0106474e+10 | I34: 1.54 | J34: 0.214 | K34: =IFERROR(_xlfn.RANK.EQ(F34,F$3:F$1770),"N/A") -> 85 | L34: 11.28 | M34: =IFERROR(_xlfn.RANK.EQ(H34,H$3:H$1770),"N/A") -> 32 | N34: =IFERROR(_xlfn.RANK.EQ(I34,I$3:I$1770),"N/A") -> 300 | O34: =IFERROR(_xlfn.RANK.EQ(J34,J$3:J$1770),"N/A") -> 231 | P34: 12.38 | Q34: 24.56 | R34: 9.69 | S34: 370.95 | T34: 7,432,262,329.00 | U34: =SUM(P34:T34) -> 0 | V34: =_xlfn.RANK.EQ(U34,$U$4:$U$61,1) -> 1 | W34: =IF(Y34="Not suitable","-",V34) -> 1 | Y34: =IF(OR(Z34="Y",AA34="Y"),"Not suitable","") | Z34: =IF(N34="N/A","Y","")
B35: PTC.OQ | C35: PTC Inc | D35: Software | F35: 0.136 | G35: 0.15017724 | H35: 1.9465514e+10 | I35: 5.78 | J35: 0.277 | K35: =IFERROR(_xlfn.RANK.EQ(F35,F$3:F$1770),"N/A") -> 155 | L35: 0.94 | M35: =IFERROR(_xlfn.RANK.EQ(H35,H$3:H$1770),"N/A") -> 33 | N35: =IFERROR(_xlfn.RANK.EQ(I35,I$3:I$1770),"N/A") -> 263 | O35: =IFERROR(_xlfn.RANK.EQ(J35,J$3:J$1770),"N/A") -> 151 | P35: 2.86 | Q35: 10.91 | R35: 0.89 | S35: 10.68 | T35: 45,589,575.00 | U35: =SUM(P35:T35) -> 0 | V35: =_xlfn.RANK.EQ(U35,$U$4:$U$61,1) -> 1 | W35: =IF(Y35="Not suitable","-",V35) -> 1 | Y35: =IF(OR(Z35="Y",AA35="Y"),"Not suitable","") | Z35: =IF(N35="N/A","Y","")
B36: DIDIY.PK | C36: DiDi Global Inc | D36: Software | F36: 0.208 | G36: 3.5572377 | H36: 1.8611964e+10 | J36: -21,8% | K36: =IFERROR(_xlfn.RANK.EQ(F36,F$3:F$1770),"N/A") -> 92 | L36: 8.68 | M36: =IFERROR(_xlfn.RANK.EQ(H36,H$3:H$1770),"N/A") -> 34 | N36: =IFERROR(_xlfn.RANK.EQ(I36,I$3:I$1770),"N/A") -> N/A | O36: =IFERROR(_xlfn.RANK.EQ(J36,J$3:J$1770),"N/A") -> N/A | P36: 5.00 | Q36: 20.08 | R36: 7.51 | S36: 199.32 | T36: 63,330,441.00 | U36: =SUM(P36:T36) -> 0 | V36: =_xlfn.RANK.EQ(U36,$U$4:$U$61,1) -> 1 | W36: =IF(Y36="Not suitable","-",V36) -> - | Y36: =IF(OR(Z36="Y",AA36="Y"),"Not suitable","") -> Not suitable | Z36: =IF(N36="N/A","Y","") -> Y
B37: IOT.N | C37: Samsara Inc | D37: Software | G37: -0,288371877 | H37: 1.8220805e+10 | I37: 46.44 | J37: -28,8% | K37: =IFERROR(_xlfn.RANK.EQ(F37,F$3:F$1770),"N/A") -> 316 | M37: =IFERROR(_xlfn.RANK.EQ(H37,H$3:H$1770),"N/A") -> 35 | N37: =IFERROR(_xlfn.RANK.EQ(I37,I$3:I$1770),"N/A") -> 90 | O37: =IFERROR(_xlfn.RANK.EQ(J37,J$3:J$1770),"N/A") -> N/A | P37: 0.88 | S37: 0.01 | T37: 428,707,430.00 | U37: =SUM(P37:T37) -> 0 | V37: =_xlfn.RANK.EQ(U37,$U$4:$U$61,1) -> 1 | W37: =IF(Y37="Not suitable","-",V37) -> 1 | Y37: =IF(OR(Z37="Y",AA37="Y"),"Not suitable","") | Z37: =IF(N37="N/A","Y","")
B38: TYL.N | C38: Tyler Technologies Inc | D38: Software | F38: -0.067 | G38: 0 | H38: 1.693982e+10 | I38: 5.28 | J38: 0.182 | K38: =IFERROR(_xlfn.RANK.EQ(F38,F$3:F$1770),"N/A") -> 360 | L38: 2.75 | M38: =IFERROR(_xlfn.RANK.EQ(H38,H$3:H$1770),"N/A") -> 36 | N38: =IFERROR(_xlfn.RANK.EQ(I38,I$3:I$1770),"N/A") -> 268 | O38: =IFERROR(_xlfn.RANK.EQ(J38,J$3:J$1770),"N/A") -> 285 | P38: 2.76 | Q38: 11.55 | R38: 1.92 | S38: 51.27 | T38: 143,500,000.00 | U38: =SUM(P38:T38) -> 0 | V38: =_xlfn.RANK.EQ(U38,$U$4:$U$61,1) -> 1 | W38: =IF(Y38="Not suitable","-",V38) -> 1 | Y38: =IF(OR(Z38="Y",AA38="Y"),"Not suitable","") | Z38: =IF(N38="N/A","Y","")
B39: CHKP.OQ | C39: Check Point Software Technologies Ltd | D39: Software | F39: 0.129 | G39: 4.507617 | H39: 1.6911446e+10 | I39: 3.26 | J39: 0.395 | K39: =IFERROR(_xlfn.RANK.EQ(F39,F$3:F$1770),"N/A") -> 166 | L39: 0.26 | M39: =IFERROR(_xlfn.RANK.EQ(H39,H$3:H$1770),"N/A") -> 37 | N39: =IFERROR(_xlfn.RANK.EQ(I39,I$3:I$1770),"N/A") -> 287 | O39: =IFERROR(_xlfn.RANK.EQ(J39,J$3:J$1770),"N/A") -> 59 | P39: 0.99 | Q39: 5.52 | R39: 2.35 | S39: 4.65 | T39: 30,901,440.00 | U39: =SUM(P39:T39) -> 0 | V39: =_xlfn.RANK.EQ(U39,$U$4:$U$61,1) -> 1 | W39: =IF(Y39="Not suitable","-",V39) -> 1 | Y39: =IF(OR(Z39="Y",AA39="Y"),"Not suitable","") | Z39: =IF(N39="N/A","Y","")
B40: 002230.SZ | C40: iFLYTEK Co Ltd | D40: Software | F40: 0.302 | G40: 0 | H40: 1.5228665e+10 | I40: 19.09 | J40: -2,5% | K40: =IFERROR(_xlfn.RANK.EQ(F40,F$3:F$1770),"N/A") -> 49 | L40: 5.57 | M40: =IFERROR(_xlfn.RANK.EQ(H40,H$3:H$1770),"N/A") -> 38 | N40: =IFERROR(_xlfn.RANK.EQ(I40,I$3:I$1770),"N/A") -> 179 | O40: =IFERROR(_xlfn.RANK.EQ(J40,J$3:J$1770),"N/A") -> N/A | P40: 7.58 | Q40: 18.83 | R40: 5.04 | S40: 112.87 | T40: 2,739,376,061.00 | U40: =SUM(P40:T40) -> 0 | V40: =_xlfn.RANK.EQ(U40,$U$4:$U$61,1) -> 1 | W40: =IF(Y40="Not suitable","-",V40) -> 1 | Y40: =IF(OR(Z40="Y",AA40="Y"),"Not suitable","") | Z40: =IF(N40="N/A","Y","")
...

Sheet ESG
B1: Company GICS Sector: | T1: Yes
B2: Information Technology | C2: <- Select Industry | T2: No
B3: ESG Analysis | K3: Relative ESG Analysis
B4: Parameters | C4: Impact | D4: Do they report? | E4: Ranking | F4: Mitigation Plan | G4: Traffic Lights | H4: Improvement over time? | I4: Targets / Goals? | J4: Comments | K4: Parameters | L4: =Peers!C8 -> #VALUE! | M4: =Peers!D8 -> #VALUE! | N4: =Peers!E8 -> #VALUE! | O4: =Peers!F8 -> #VALUE! | P4: =Peers!G8 -> #VALUE! | Q4: =Peers!H8 -> #VALUE! | R4: AVERAGE | S4: AVERAGE (ex. Cisco)
B5: Environmental | K5: Ratios
A6: 1 | B6: CO2 Direct Emissions | C6: =VLOOKUP($B$2,'Sector Impact'!$K$4:$AA$16,A6+1,FALSE) -> Medium | D6: Yes | E6: Medium | F6: Yes | H6: No | I6: To be carbon neutral by 2050 | J6: Since 2020 CO2 Direct direct emissions has been relatively constant | K6: CO2 Emissions/$M Sales | L6: =L12/L$11 -> 0.23306977 | M6: =M12/M$11 -> 0.12120876 | N6: =N12/N$11 -> #VALUE! | O6: =O12/O$11 -> 0.037661631 | P6: =P12/P$11 -> 116.02847 | Q6: =Q12/Q$11 -> 0.15755556 | R6: =IFERROR(AVERAGE(L6,M6,O6,P6,Q6),"") -> 23.315594 | S6: =IFERROR(AVERAGE(L6,M6,O6,Q6),"") -> 0.13737393
A7: 2 | B7: Total Water Consumption | C7: =VLOOKUP($B$2,'Sector Impact'!$K$4:$AA$16,A7+1,FALSE) -> Low | E7: Medium | K7: Water Consumption/$M Sales | L7: =L13/L$11 -> #VALUE! | M7: =M13/M$11 -> 13.138996 | N7: =N13/N$11 -> #VALUE! | O7: =O13/O$11 -> #VALUE! | P7: =P13/P$11 -> 4.6084916 | Q7: =Q13/Q$11 -> #VALUE! | R7: =IFERROR(AVERAGE(M7,P7),"") -> 8.8737438 | S7: =IFERROR(AVERAGE(M7),"") -> 13.138996
A8: 3 | B8: Total Energy Consumption | C8: =VLOOKUP($B$2,'Sector Impact'!$K$4:$AA$16,A8+1,FALSE) -> High | D8: Yes | E8: Medium | F8: Yes | H8: Has actually seen an increase in consumption levels in the last 3 years | I8: No | J8: Increased focus on renewabilitiy and re-using energy | K8: Energy Consumption/$M Sales | L8: =L14/L$11 -> 27.512904 | M8: =M14/M$11 -> 26.804395 | N8: =N14/N$11 -> #VALUE! | O8: =O14/O$11 -> 30.123865 | P8: =P14/P$11 -> 1136.7613 | Q8: =Q14/Q$11 -> 35.037626 | R8: =IFERROR(AVERAGE(L8,M8,O8,P8,Q8),"") -> 251.24801 | S8: =IFERROR(AVERAGE(L8,M8,O8,Q8),"") -> 29.869698
A9: 4 | B9: Waste Management | C9: =VLOOKUP($B$2,'Sector Impact'!$K$4:$AA$16,A9+1,FALSE) -> Low | H9: No improvement but rather an increase in waste by double, however they have roughly 20% of that waste being recycled | I9: They don't actively have a target/goal byt are commited to implementing the circular economy | K9: Waste Production/$M Sales | L9: =L15/L$11 -> 0.012971949 | M9: =M15/M$11 -> 0.15803202 | N9: =N15/N$11 -> #VALUE! | O9: =O15/O$11 -> #VALUE! | P9: =P15/P$11 -> 4.7462032 | Q9: =Q15/Q$11 -> #VALUE! | R9: =IFERROR(AVERAGE(L9,M9,P9),"") -> 1.6390691 | S9: =IFERROR(AVERAGE(L9,M9),"") -> 0.085501986
A10: 5 | B10: Land Degradation/Deforestation/Biodiversity loss/Animal sufering/… | C10: =VLOOKUP($B$2,'Sector Impact'!$K$4:$AA$16,A10+1,FALSE) -> Low | K10: Inputs
B11: Social | K11: Net Sales ($M) | L11: 5172.7 | M11: =Peers!D11 -> 7207.4 | N11: =Peers!E11 -> 2847.59 | O11: =Peers!F11 -> 2389.7 | P11: 51557 | Q11: =Peers!H11 -> 1758.11
A12: 6 | B12: Employee Turnover % | C12: =VLOOKUP($B$2,'Sector Impact'!$K$4:$AA$16,A12+1,FALSE) -> Low | H12: No improvement but rather saw an increase from 9% to 12% since 2020 | I12: No | K12: CO2 Emissions Total (Tonnes) | L12: 1205.6 | M12: 873.6 | N12: N/A | O12: 90 | P12: 5982080 | Q12: 277
A13: 7 | B13: Salaries & Compensation | C13: =VLOOKUP($B$2,'Sector Impact'!$K$4:$AA$16,A13+1,FALSE) -> Low | H13: Hasn't seen the best improvement and doesn't have the best of average and median salaries in their industry | I13: No | K13: Water Consumption Total (Cubic Meters) | L13: N/A | M13: 94698 | N13: N/A | O13: N/A | P13: 237600 | Q13: N/A
A14: 8 | B14: Reputation | C14: =VLOOKUP($B$2,'Sector Impact'!$K$4:$AA$16,A14+1,FALSE) -> Low | H14: Was recognized as one of the best places to work in 2023 in the United States of America | I14: No specific goals, but are focused on making sure employees are heard and happy | K14: Energy Consumption Total (Gigajoules) | L14: 142316 | M14: 193190 | N14: N/A | O14: 71987 | P14: 58608000 | Q14: 61600
A15: 9 | B15: Discrimination Events | C15: =VLOOKUP($B$2,'Sector Impact'!$K$4:$AA$16,A15+1,FALSE) -> Low | F15: Yes | K15: Waste Production Total (Tonnes) | L15: 67.1 | M15: 1139 | N15: N/A | O15: N/A | P15: 244700 | Q15: N/A
A16: 10 | B16: Work Safety | C16: =VLOOKUP($B$2,'Sector Impact'!$K$4:$AA$16,A16+1,FALSE) -> High | D16: Yes | E16: "Best in class" | F16: Yes | H16: No | I16: No | J16: Have safeguards implemented, improvements over time haven't really been visible because they already excel in the work safety aspect | K16: ESG Scores
A17: 11 | B17: Damage to consumer health | C17: =VLOOKUP($B$2,'Sector Impact'!$K$4:$AA$16,A17+1,FALSE) -> Low | H17: No | I17: No | K17: Refinitiv | L17: 58 | M17: 48 | N17: 27 | O17: 70 | P17: 83 | Q17: 34
A18: 12 | B18: PXP? | C18: =VLOOKUP($B$2,'Sector Impact'!$K$4:$AA$16,A18+1,FALSE) -> Low | K18: Sustainalytics | L18: 18.9 | M18: 13.9 | N18: 18.2 | O18: 18.1 | P18: 13.9 | Q18: 18.3
