Workbook
Name _msoanchor_1: Segments!$C$5
Name Sectors: 'Sector Impact'!$K$4:$K$16

Sheet OP
B2: 45039 | C2: Team 1 | E2: =Inputs!H3 -> #VALUE! | L2: NYSE | M2: SIC:
D3: COMPANY DESCRIPTION | H3: CEO & BOARD OF DIRECTORS
D4: Uber Technologies, Inc. is a technology platform that uses a massive network, leading technology, operational excellence and product expertise to power movement from point A to point B. They develop and operate proprietary technology applications supporting a variety of offerings on their platform. Uber connects consumers with independent providers of ride services for ride sharing services, and connects riders and other consumers with restaurants, grocers and other stores with delivery service providers. Uber uses the same network technology, operational excellence and product expertise to connect shippers with carriers in the freight industry. | H4: Name | I4: Gender | J4: Age | K4: Tenure | L4: Executive? | M4: Other roles
H5: Ronald Sugar | I5: Male | J5: 73 | K5: 4 | L5: No | M5: (Chair)Former Chairperson and CEO, Northrop Grumman
H6: Ursula Burns | I6: Female | J6: 63 | K6: 5 | L6: No | M6: Chairman and Former CEO, VEON
H7: Dara Khosrowshahi | I7: Male | J7: 52 | K7: 5 | L7: Yes | M7: CEO, Uber
H8: Wan Ling Martello | I8: Female | J8: 63 | K8: 5 | L8: No | M8: Co-founder and Partner, BayPine; Former Executive Vice President, Nestle
H9: John ThainFormer | I9: Male | J9: 66 | K9: 5 | L9: No | M9: Chairman and CEO, CIT Group
H10: David TrujilloPartner, | I10: Male | J10: 46 | K10: 5 | L10: No | M10: TPG
H11: Amanda GinsbergFormer | I11: Female | J11: 52 | K11: 3 | L11: No | M11: CEO, Match Group
H12: Robert EckertPartner | I12: Male | J12: 67 | K12: 3 | L12: No | M12: FFL Partners; Former CEO, Mattel
H13: Revathi Advaithi | I13: Female | J13: 54 | K13: 2 | L13: No | M13: CEO, Flex Ltd.
B14: USD MILLIONS | H14: Alexander Wynaendts | I14: Male | J14: 61 | K14: 2 | L14: No | M14: Former CEO and Chairman of Aegon
B15: COMPANY OVERVIEW
B16: Stock | D16: Liquidity and Solvency | F16: Segments | I16: Profitability (2022) | L16: Multiples
B17: Last Price | C17: 47.24 | D17: Total Assets | E17: =_xlfn.XLOOKUP(D17,'Fin. Data'!A:A,'Fin. Data'!B:B,,0) -> 32109 | F17: Regions | H17: % Sales | I17: Reporting Year | J17: 2022 | L17: Float | M17: =1-0.17% -> 0.9983
B18: Outstanding Shares | C18: 2009557000 | D18: Total Liabilities | E18: =_xlfn.XLOOKUP(D18,'Fin. Data'!A:A,'Fin. Data'!B:B,,0) -> 23605 | F18: =+Segments!C5 -> North America (US & Canada) | H18: =+Segments!B5 -> 0.609375 | I18: End of Year | J18: 1 October 2022 | L18: Insiders Own | M18: 0.0017
B19: Market Cap. | C19: =C17*C18/1000000 -> 94931.473 | D19: Cash/Share | E19: =_xlfn.XLOOKUP("Cash & Eq.",'Fin. Data'!A:A,'Fin. Data'!B:B,,0)*1000000/C18 -> 2.0939939 | F19: =+Segments!C6 -> EMEA (Europe Middle East and Africa) | H19: =+Segments!B6 -> 0.21875 | I19: EBITDA | K19: =_xlfn.XLOOKUP(I19,'Fin. Data'!A:A,'Fin. Data'!B:B,,0) -> 6144 | L19: b (Yahoo) | M19: 1.22
B20: +Total Debt | C20: ='Fin. Data'!B58 -> 11139 | D20: EBIDTA/Net Financial Cost (NFC) | E20: ='Fin. Data (Common Size)'!B19/(-'Fin. Data (Common Size)'!B14) -> 14.422535 | F20: =+Segments!C7 -> APAC (Asia Pacific) | H20: =+Segments!B7 -> 0.109375 | I20: Depreciation & Amortization | K20: =_xlfn.XLOOKUP(I20,'Fin. Data'!A:A,'Fin. Data'!B:B,,0) -> 947 | L20: Score (S&P) | M20: -
B21: -Cash | C21: ='Fin. Data'!B39 -> 4208 | D21: Debt/EBITDA | E21: =_xlfn.XLOOKUP("Total Debt",'Fin. Data'!A:A,'Fin. Data'!B:B,,0)/_xlfn.XLOOKUP("EBITDA",'Fin. Data'!A:A,'Fin. Data'!B:B,,0) -> 1.8129883 | F21: =+Segments!C8 -> Latin America | H21: =+Segments!B8 -> 0.0625 | I21: EBIT | K21: =_xlfn.XLOOKUP(I21,'Fin. Data'!A:A,'Fin. Data'!B:B,,0) -> 5197 | L21: Price/Book Value | M21: =IFERROR((C17*C18/(E17-E18))/1000000,"") -> 11.163155
B22: =Enterprise Value | C22: =C19+C20-C21 -> 101862.47 | D22: "Others Assets"/Asset | E22: =_xlfn.XLOOKUP("Other Assets",'Fin. Data'!A:A,'Fin. Data'!B:B,,0)/_xlfn.XLOOKUP("Total Assets",'Fin. Data'!A:A,'Fin. Data'!B:B,,0) -> 0.64533308 | I22: Net Income | K22: =_xlfn.XLOOKUP(I22,'Fin. Data'!A:A,'Fin. Data'!B:B,,0) -> -9141 | L22: NCF(3y avg)/Asset | M22: =IFERROR(K28/E17,"") -> -0.17030531
B23: Holdings (nac/int'l) | C23: - | D23: Debt/Assets | E23: =_xlfn.XLOOKUP(D23,'Fin. Data'!A:A,'Fin. Data'!B:B,,0) -> 0.34691208 | F23: Categories | H23: % Sales | I23: EPS | K23: =1000000*K22/C18 -> -4.5487637 | L23: Price/Net Inc. (3y avg) | M23: =IFERROR(C19/K27,"") -> -17.360221
B24: t liq. (Holdings/Vol.) | C24: - | D24: EBITDA Margin (average) | E24: =AVERAGE(_xlfn.XLOOKUP("EBITDA Margin",'Fin. Data'!A:A,'Fin. Data'!B:D,,0)) -> -0.13430104 | F24: =Segments!C16 -> Mobility | H24: =Segments!B16 -> 0.44009788 | I24: ROA | K24: =K22/E17 -> -0.28468654 | L24: EV/Asset | M24: =IFERROR(C22/E17,"") -> 3.1723963
B25: % Short | C25: 0.0249 | D25: Operating Margin (average) | E25: =AVERAGE(_xlfn.XLOOKUP("Operating Margin",'Fin. Data'!A:A,'Fin. Data'!B:D,,0)) -> -0.23789854 | F25: =Segments!C17 -> Delivery | H25: =Segments!B17 -> 0.3419707 | I25: ROIC | K25: =K22/(E17-(E18-C20)) -> -0.46535662 | L25: EV/Ebidta (3y average) | M25: =IFERROR(C22/K26,"") -> -111.40628
B26: Traffic ESG | D26: Net Income Margin (average) | E26: =AVERAGE(_xlfn.XLOOKUP("Net Income Margin",'Fin. Data'!A:A,'Fin. Data'!B:D,,0)) -> -0.30758978 | F26: =Segments!C18 -> Freight | H26: =Segments!B18 -> 0.21793142 | I26: EBITDA (3y average) | K26: =AVERAGE(_xlfn.XLOOKUP("EBITDA",'Fin. Data'!A:A,'Fin. Data'!B:D,,0)) -> -914.33333 | L26: Price/NCF (3y average) | M26: =IFERROR(C19/K28,"") -> -17.360221
B27: E | F27: =Segments!C19 -> All other | H27: =Segments!B19 -> 0 | I27: Net Income (3y average) | K27: =AVERAGE(_xlfn.XLOOKUP("Net Income",'Fin. Data'!A:A,'Fin. Data'!B:D,,0)) -> -5468.3333 | L27: Bonds 1,3,5a (USD) | M27: -
B28: S | D28: Net Financial Cost/Avg Net Debt | E28: =-_xlfn.XLOOKUP("Net Financial Cost",'Fin. Data'!A:A,'Fin. Data'!B:B,,0)/AVERAGE(_xlfn.XLOOKUP("Net Debt",'Fin. Data'!A:A,'Fin. Data'!B:D,,0)) -> 0.073562424 | I28: NCF (3y average) | K28: =AVERAGE(_xlfn.XLOOKUP("Net Income",'Fin. Data'!A:A,'Fin. Data'!B:D,,0)) -> -5468.3333 | L28: Div+Rep.(3y avg)/Price | M28: =-IFERROR(SUM(E49:E51)/(3*C19),"") -> 0
B29: G | L29: Div. Yield | M29: =-IFERROR(L50/C19,"") -> 0
B30: INVESTMENT THESIS
B31: Pillars of Recommendation | H31: Recommendation
B32: Pillar | C32: Explanation | H32: SELL | I32: CHECK DCF
B33: Competitive Position | C33: It is a market leader in the ride-sharing industry, with a significant share of the global market.
B34: Technological Innovation | C34: Investments in emerging technologies, such as autonomous vehicles and electric scooters
B35: Network Effects | C35: Uber's platform benefits from network effects, as more drivers and riders join, making it more attractive to both parties.
B36: Risks of Investment | H36: Price Target | I36: Valuation
B37: Risk | C37: Explanation | H37: =DCF!D75 -> 37.604479 | I37: Discount Rate | J37: =DCF!F50 -> 0.101 | L37: Downside | M37: =DCF!D74 -> -0.20396953
B38: Regulatory Environment | C38: Changes in regulations can significantly impact Uber's operations.
B39: Dependence on Gig Workers | C39: The model of relying on gig workers can lead to labor disputes and potential increased costs.
B40: Competition | C40: Uber faces strong competition from other ride-sharing and food delivery companies, both domestically and internationally.
B41: FINANCIAL PERFORMANCE
...

Sheet Segments
B2: ="Regions "&"("&OP!J17&")" -> Regions (2022) | Q2: Products
D3: Nominal value | K3: YoY Growth
B4: Weight | C4: Region | D4: =OP!J17 -> 2022 | E4: =D4-1 -> 2021 | F4: =E4-1 -> 2020 | G4: =F4-1 -> 2019 | H4: =G4-1 -> 2018 | I4: =H4-1 -> 2017 | K4: =OP!J17 -> 2022 | L4: =K4-1 -> 2021 | M4: =L4-1 -> 2020 | N4: =M4-1 -> 2019 | O4: =N4-1 -> 2018 | P4: =O4-1 -> 2017
B5: =IFERROR(D5/D11,"") -> 0.609375 | C5: North America (US & Canada) | D5: 19500 | E5: 10000 | F5: 6082 | G5: 8805 | H5: 6521 | K5: =(D5-E5)/E5 -> 0.95 | L5: =(E5-F5)/F5 -> 0.64419599 | M5: =(F5-G5)/G5 -> -0.3092561 | N5: =(G5-H5)/H5 -> 0.35025303 | O5: - | P5: -
B6: =IFERROR(D6/D11,"") -> 0.21875 | C6: EMEA (Europe Middle East and Africa) | D6: 7000 | E6: 3200 | F6: 1800 | G6: 2148 | H6: 1721 | K6: =(D6-E6)/E6 -> 1.1875 | L6: =(E6-F6)/F6 -> 0.77777778 | M6: =(F6-G6)/G6 -> -0.16201117 | N6: =(G6-H6)/H6 -> 0.24811156 | O6: - | P6: -
B7: =IFERROR(D7/D11,"") -> 0.109375 | C7: APAC (Asia Pacific) | D7: 3500 | E7: 2700 | F7: 1500 | G7: 1247 | H7: 1026 | K7: =(D7-E7)/E7 -> 0.2962963 | L7: =(E7-F7)/F7 -> 0.8 | M7: =(F7-G7)/G7 -> 0.20288693 | N7: =(G7-H7)/H7 -> 0.21539961 | O7: - | P7: -
B8: =IFERROR(D8/D11,"") -> 0.0625 | C8: Latin America | D8: 2000 | E8: 1400 | F8: 1300 | G8: 1947 | H8: 2002 | K8: =(D8-E8)/E8 -> 0.42857143 | L8: =(E8-F8)/F8 -> 0.076923077 | M8: =(F8-G8)/G8 -> -0.33230611 | N8: =(G8-H8)/H8 -> -0.027472527 | O8: - | P8: -
B9: =IFERROR(D9/D11,"") -> 0 | G9: =SUM(5032*(D9/$D$11)) -> 0
B10: =IFERROR(D10/D11,"") -> 0 | G10: =SUM(5032*(D10/$D$11)) -> 0
B11: =SUM(B5:B10) -> 1 | C11: TOTAL | D11: =SUM(D5:D10) -> 32000 | E11: =SUM(E5:E10) -> 17300 | F11: =SUM(F5:F10) -> 10682 | G11: =SUM(G5:G10) -> 14147 | H11: =SUM(H5:H10) -> 11270 | I11: =SUM(I5:I10) -> 0 | K11: =(D11-E11)/E11 -> 0.84971098 | L11: =(E11-F11)/F11 -> 0.6195469 | M11: =(F11-G11)/G11 -> -0.24492825 | N11: =(G11-H11)/H11 -> 0.2552795 | O11: =(H11-I11)/I11 -> #DIV/0! | P11: =(I11-J11)/J11 -> #DIV/0!
B13: ="Categories "&"("&OP!J17&")" -> Categories (2022)
D14: Nominal value | K14: YoY Growth
B15: Weight | C15: Category | D15: =OP!J17 -> 2022 | E15: =D15-1 -> 2021 | F15: =E15-1 -> 2020 | G15: =F15-1 -> 2019 | H15: =G15-1 -> 2018 | I15: =H15-1 -> 2017 | K15: =OP!J17 -> 2022 | L15: =K15-1 -> 2021 | M15: =L15-1 -> 2020 | N15: =M15-1 -> 2019 | O15: =N15-1 -> 2018 | P15: =O15-1 -> 2017
B16: =IFERROR(D16/D20,"") -> 0.44009788 | C16: Mobility | D16: 14029 | E16: 6953 | F16: 6089 | G16: 10745 | H16: 9437 | K16: =(D16-E16)/E16 -> 1.0176902 | L16: =(E16-F16)/F16 -> 0.14189522 | M16: =(F16-G16)/G16 -> -0.43331782 | N16: =(G16-H16)/H16 -> 0.13860337 | O16: - | P16: -
B17: =IFERROR(D17/D20,"") -> 0.3419707 | C17: Delivery | D17: 10901 | E17: 8362 | F17: 3904 | G17: 2510 | H17: 1460 | K17: =(D17-E17)/E17 -> 0.30363549 | L17: =(E17-F17)/F17 -> 1.1419057 | M17: =(F17-G16)/G16 -> -0.63666822 | N17: =(G16-H17)/H17 -> 6.359589 | O17: - | P17: -
B18: =IFERROR(D18/D20,"") -> 0.21793142 | C18: Freight | D18: 6947 | E18: 2132 | F18: 1011 | G18: 731 | H18: 356 | K18: =(D18-E18)/E18 -> 2.2584428 | L18: =(E18-F18)/F18 -> 1.1088032 | M18: =(F18-G18)/G18 -> 0.38303694 | N18: =(G18-H18)/H18 -> 1.0533708 | O18: - | P18: -
B19: =IFERROR(D19/D20,"") -> 0 | C19: All other | D19: 0 | E19: 8 | F19: 135 | G19: 119 | H19: 17 | K19: =(D19-E19)/E19 -> -1 | L19: =(E19-F19)/F19 -> -0.94074074 | M19: =(F19-G19)/G19 -> 0.13445378 | N19: =(G19-H19)/H19 -> 6 | O19: - | P19: -
B20: =SUM(B16:B19) -> 1 | C20: TOTAL | D20: =SUM(D16:D19) -> 31877 | E20: =SUM(E16:E19) -> 17455 | F20: =SUM(F16:F19) -> 11139 | G20: =SUM(G16:G19) -> 14105 | H20: =SUM(H16:H19) -> 11270 | K20: =(D20-E20)/E20 -> 0.8262389 | L20: =(E20-F20)/F20 -> 0.56701679 | M20: =(F20-G20)/G20 -> -0.21028004 | N20: =(G20-H20)/H20 -> 0.2515528 | O20: =(H20-I20)/I20 -> #DIV/0! | P20: =(I20-J20)/J20 -> #DIV/0!
B22: Categories | D22: Description | I22: Graphs
B23: Mobility | D23: Mobility products Connect consumers with Drivers who provide rides in a variety of vehicles, such as cars, auto rickshaws, motorbikes, minibuses, or taxis. Mobility also includes activity related to our Financial Partnerships and Transit offerings.
B24: Delivery | D24: Delivery offerings allow consumers to search for and discover local restaurants, order a meal, and either pickup at the restaurant or have the meal delivered. In certain markets, Delivery also includes offerings for grocery, alcohol and convenience store delivery as well as select other goods
B25: Freight | D25: Freight connects carriers with shippers on our platform, and gives carriers upfront, transparent pricing and the ability to book a shipment. Freight also includes transportation management and other logistics services offerings.
B26: All other | D26: This segment includes revenue from other businesses and operations, such as sales of ecosystem products, licensing, and other miscellaneous items.
B30: Industry | I30: Graphs (Industry Forecasts)
B31: Drivers | D31: <
B32: Network effect | D32: One of the most important comparative advantages is the network effect that the platform has. Uber essentially benefits from what can be called hyperlocal network effects. The introduction of a new driver only improves the service for those who live in the same locality. An additional supply unit (i.e. driver) in Lisbon does not necessarily affect someone's experience in Porto. In sum, Uber's strategy is to create such an extensive network that leads to a liquidity network effect. A large driver supply leads to lower wait times and fares, which attracts more riders. Therefore Uber is clearly cheaper than a taxi and on average cheaper than other platforms according to investopedia.
B33: Delivery | D33: Uber Eats stands out from other food applications in its unparalleled understanding of "you." Through meticulous customer order recording and analysis, it accurately discerns individual preferences. By intuitively offering precisely what users desire, the app effortlessly tempts customers, making the ordering process a breeze. Furthermore, UberEats competitors are ignoring a very important perspective of the user ratings and feedback for the creation of a best customer experience. It offers two opinions to customer whether the service and food delivered is good or bad. This customer rating is giving a leverage to UberEATs according to CAA.
B34: Sales forecast
B35: Source | D35: Market Growth CGAR | G35: Period
B36: Grandviewresearch for Mobility | D36: 0.166 | G36: 2023-2030
B37: Grandviewresearch for Delivery | D37: 0.103 | G37: 2023-2030
B38: Coherentmarketinsights for Mobility | D38: 0.19 | G38: 2022-2030
B39: Brandessenceresearch for Mobility | D39: 0.172 | G39: 2018-2025
B40: Average | D40: =AVERAGE(D36:F39) -> 0.15775 | G40: 2023-2028
B41: Company's Strategy / Extra Notes
B42: In view of the need for innovation Uber has launched several iniciatives such as:
B43: 1. "Go-Get" where families can now set up profiles that link multiple Uber accounts together so that customers can pay for rides and deliveries from a centralized account. That centralized account will also be home to real-time location and order updates. This feature is aimes to attract a new set of customers from teens as young as 13 and families who want to link accounts to even those who might feel more comfortable calling for a ride instead of using the app at all.
B44: 2. "Uber Business Comfort" which is a ride type exclusive to business travelers. The offering includes priority pickup, newer cars, more legroom, highly rated drivers, and custom preferences. Travelers using Uber Business Comfort will also have access to a designated, 24/7 personalized support service. Within the Uber and Uber Eats app is a business hub to manage their travel needs, view their employee perks and travel policies, and travel and meal programs. Uber is also experimenting with additional benefits for business travelers, including exclusive Uber One membership promotions and the ability to earn personal perks like Uber Cash.
B45: 3. "Uber Travel", which imports flights, hotel and restaurant reservations into the Uber app to simplify the process of requesting rides related to those bookings. In this app the user will be abel to use Uber Explore, which enables users to book activities from companies including Viator and then reserve a ride to the location as well.
B46: As evident from its track record, Uber exemplifies a proactive and forward-thinking corporate entity that is bound to not only survive but also flourish in the coming years, thanks to its relentless pursuit of innovation and entrepreneurial spirit. The company's unwavering commitment to staying ahead of the curve and anticipating market trends positions it as a potential trailblazer in the ever-evolving business landscape. With its innovative ethos deeply ingrained in its culture, Uber is poised to leverage cutting-edge technologies and novel business models, setting new benchmarks and conquering challenges in the dynamic future ahead.
...

Sheet Acuerdo
A1: Invertir
A2: NO invertir
A3: Mantener sin elevar posición
A4: Mantener (y seguir comprando)
A5: Liquidar
A6: PENDIENTE

Sheet Peers
B1: Peer Logo | C1: Peer Name | D1: Description
C2: #VALUE! | D2: Didi Global is a leading Chinese transportation technology company founded in 2012. It has grown into one of the world's largest ride-hailing platforms, operating in over 15 countries and 400 cities globally. Didi connects millions of riders with a vast network of drivers, offering a range of transportation options from standard cars to premium vehicles. The company places a strong emphasis on safety, employing advanced technology and comprehensive screening processes. Didi's services extend beyond ride-hailing, encompassing solutions like bike-sharing, food delivery, and more. With a commitment to innovation and accessibility, Didi Global continues to shape the landscape of urban mobility worldwide.
C3: #VALUE! | D3: Lyft is a prominent transportation network company founded in 2012, based in San Francisco, California. It operates a user-friendly mobile app that connects riders with drivers for convenient and reliable ridesharing services. Lyft offers various ride options, including standard vehicles, shared rides, and luxury cars, catering to diverse transportation needs. Committed to safety, Lyft implements stringent driver screening and provides real-time tracking for secure journeys. The company has expanded its services to include bike and scooter rentals, and it actively promotes sustainable transportation solutions. Lyft's dedication to accessibility and innovation has solidified its position as a major player in the global ride-hailing industry.
C4: #VALUE! | D4: Grab is a Southeast Asian super app founded in 2012, headquartered in Singapore. It began as a ride-hailing platform but swiftly evolved into a multi-service platform offering services like food delivery, digital payments, and more. Grab operates in over 400 cities across 8 countries, providing a wide range of services to millions of users. The company emphasizes safety, convenience, and accessibility, and aims to address various everyday needs of its diverse user base, making it a dominant player in the Southeast Asian technology and transportation ecosystem.
B6: In Millions USD (exc Market Cap) | C6: #VALUE! | D6: #VALUE! | E6: #VALUE! | F6: #VALUE! | G6: AVERAGE
B7: Company Info | G7: =IFERROR(AVERAGE(C7:F7),"")
B8: Market Cap | C8: =OP!C19 -> 94931.473 | D8: 15430 | E8: 4230 | F8: 12400 | G8: =IFERROR(AVERAGE(C8:F8),"") -> 31747.868
B9: Net Sales (current) | C9: =C51 -> 31877 | D9: =D51 -> 140791.68 | E9: =E51 -> 4095.135 | F9: =F51 -> 1433 | G9: =IFERROR(AVERAGE(C9:F9),"") -> 44549.204
B10: Profitability | G10: =IFERROR(AVERAGE(C10:F10),"")
B11: Sales Growth (ttm) | C11: =C51/C50-1 -> 0.8262389 | D11: =D51/D50-1 -> -0.1900471 | E11: =E51/E50-1 -> 0.27640983 | F11: =F51/F50-1 -> 1.122963 | G11: =IFERROR(AVERAGE(C11:F11),"") -> 0.50889115
B12: Sales Growth (36m) | C12: =C51/C49-1 -> 1.4520769 | D12: =D51/D49-1 -> -0.090411493 | E12: =E51/E49-1 -> 0.73179173 | F12: =F51/F49-1 -> 2.0554371 | G12: =IFERROR(AVERAGE(C12:F12),"") -> 1.0372236
B13: Operating Margin | C13: =C54/C51 -> -0.057470904 | D13: =D54/D51 -> -0.12660167 | E13: =E54/E51 -> -0.3562559 | F13: =F54/F51 -> -0.9581298 | G13: =IFERROR(AVERAGE(C13:F13),"") -> -0.37461457
B14: Net Income Margin | C14: =C57/C51 -> 0.28675848 | D14: =D57/D51 -> 0.16893043 | E14: =E57/E51 -> -0.38704463 | F14: =F57/F51 -> -1.1744592 | G14: =IFERROR(AVERAGE(C14:F14),"") -> -0.27645372
B15: Return on Equity (RoE) | C15: =C57/C68 -> 1.1321526 | D15: =D57/D68 -> 0.24963217 | E15: =E57/E68 -> -4.0780306 | F15: =F57/F68 -> -0.25281658 | G15: =IFERROR(AVERAGE(C15:F15),"") -> -0.73726561
B16: Return on Invested Capital (ROIC) | C16: =(C57+C56)/(C67+C68) -> 0.46635091 | D16: =(D57+D56)/(D67+D68) -> 0.21584026 | E16: =(E57+E56)/(E67+E68) -> 3.5974785 | F16: =(F57+F56)/(F67+F68) -> -0.21214421 | G16: =IFERROR(AVERAGE(C16:F16),"") -> 1.0168814
B17: Solvency | G17: =IFERROR(AVERAGE(C17:F17),"")
B18: Debt/Assets | C18: =C67/C64 -> 0.34691208 | D18: =D67/D64 -> 0.13373675 | E18: =E67/E64 -> 0.17623443 | F18: =F67/F64 -> 0.13609597 | G18: =IFERROR(AVERAGE(C18:F18),"") -> 0.19824481
B19: Net Debt/EBITDA | C19: =(C67-C59)/C53 -> 1.1280924 | D19: =(D67-D59)/D53 -> 0.26077651 | E19: =(E67-E59)/E53 -> -0.3947882 | F19: =(F67-F59)/F53 -> 0.57704918 | G19: =IFERROR(AVERAGE(C19:F19),"") -> 0.39278248
B20: Interest Coverage Ratio | C20: =-C53/C55 -> 14.422535 | D20: =-D53/D55 -> 11.404098 | E20: =-E53/E55 -> -69.578947 | F20: =-F53/F55 -> -3.4560907 | G20: =IFERROR(AVERAGE(C20:F20),"") -> -11.802101
B21: Liquidity
B22: Current Ratio | C22: =C62/C66 -> 1.0447306 | D22: =D62/D66 -> 2.5212799 | E22: =E62/E66 -> 0.82451941 | F22: =F62/F66 -> 5.1850501 | G22: =IFERROR(AVERAGE(C22:F22),"") -> 2.393895
B23: Quick Ratio | C23: =(C59+C60)/C66 -> 0.78922399 | D23: =(D59+D60)/D66 -> 1.1411726 | E23: =(E59+E60)/E66 -> 0.089731635 | F23: =(F59+F60)/F66 -> 2.118505 | G23: =IFERROR(AVERAGE(C23:F23),"") -> 1.0346583
B24: Activity | G24: =IFERROR(AVERAGE(C24:F24),"")
B25: Inventory Turnover | C25: =C52/C61 -> #DIV/0! | D25: =D52/D61 -> #DIV/0! | E25: =E52/E61 -> #DIV/0! | F25: =F52/F61 -> 28.25 | G25: =IFERROR(AVERAGE(C25:F25),"")
B26: Acc. Receivable Turnover | C26: =C51/C60 -> 11.470673 | D26: =D51/D60 -> 62.518509 | E26: =E51/E60 -> #DIV/0! | F26: =F51/F60 -> 3.8521505 | G26: =IFERROR(AVERAGE(C26:F26),"")
A27: Price/Sales | B27: Payables Turnover | C27: =C52/C65 -> 27.004121 | D27: =D52/D65 -> 40.348396 | E27: =E52/E65 -> 22.594744 | F27: =F52/F65 -> 1.4533762 | G27: =IFERROR(AVERAGE(C27:F27),"") -> 22.850159
B28: Fixed Asset Turnover | C28: =C51/C63 -> 15.310759 | D28: =D51/D63 -> 24.62254 | E28: =E51/E63 -> 13.066716 | F28: =F51/F63 -> 2.9126016 | G28: =IFERROR(AVERAGE(C28:F28),"") -> 13.978154
B29: Total Asset Turnover | C29: =C51/C64 -> 0.99277461 | D29: =D51/D64 -> 1.073001 | E29: =E51/E64 -> 0.89875936 | F29: =F51/F64 -> 0.15627045 | G29: =IFERROR(AVERAGE(C29:F29),"") -> 0.78020136
B30: Valuation | G30: =IFERROR(AVERAGE(C30:F30),"")
B31: Price/Earnings | C31: =C8/C57 -> 10.385239 | D31: =D8/D57 -> 0.64875547 | E31: =E8/E57 -> -2.6687697 | F31: =F8/F57 -> -7.3677956 | G31: =IFERROR(AVERAGE(C31:F31),"") -> 0.24935737
B32: Price/Sales | C32: 2.83 | D32: =D8/D51 -> 0.10959454 | E32: =E8/E51 -> 1.032933 | F32: =F8/F51 -> 8.6531752 | G32: =IFERROR(AVERAGE(C32:F32),"") -> 3.1564257
B33: Price/Book | C33: =12.98 -> 12.98 | D33: =D8/D68 -> 0.16195024 | E33: =E8/E68 -> 10.883325 | F33: =F8/F68 -> 1.8627009 | G33: =IFERROR(AVERAGE(C33:F33),"") -> 6.4719939
B34: EV/Sales | C34: =(C67+C8-C59)/C51 -> 3.1954849 | D34: =(D67+D8-D59)/D51 -> 0.086105939 | E34: =(E67+E8-E59)/E51 -> 1.1603793 | F34: =(F67+F8-F59)/F51 -> 8.1618981 | G34: =IFERROR(AVERAGE(C34:F34),"") -> 3.1509671
B35: EV/EBITDA | C35: =(C67+C8-C59)/C53 -> 16.579178 | D35: =(D67+D8-D59)/D53 -> -0.95597025 | E35: =(E67+E8-E59)/E53 -> -3.5944856 | F35: =(F67+F8-F59)/F53 -> -9.5868852 | G35: =IFERROR(AVERAGE(C35:F35),"") -> 0.61045934
B36: Stock Info | G36: =IFERROR(AVERAGE(C36:F36),"")
B37: Float | C37: =OP!M17 -> 0.9983 | D37: 0.991 | E37: 0.1734 | F37: 0.5269 | G37: =IFERROR(AVERAGE(C37:F37),"") -> 0.6724
B38: b (Yahoo) | C38: =OP!M19 -> 1.22 | D38: 0.66 | E38: 0.99 | F38: 0.17 | G38: =IFERROR(AVERAGE(C38:F38),"") -> 0.76
B39: Dividend Yield (yahoo finance) | C39: =OP!M29 -> 0 | D39: 0.0252 | E39: 0 | F39: 0.0262 | G39: =IFERROR(AVERAGE(C39:F39),"") -> 0.01285
B40: Stock Performance
B41: 1y | C41: 0.59 | D41: 0.94 | E41: -0.18 | F41: 0.2 | G41: =IFERROR(AVERAGE(C41:F41),"") -> 0.3875
...

Sheet ESG
B1: Company GICS Sector: | T1: Yes
B2: Information Technology | C2: <- Select Industry | T2: No
B3: ESG Analysis | K3: Relative ESG Analysis
B4: Parameters | C4: Impact | D4: Do they report? | E4: Ranking | F4: Mitigation Plan | G4: Traffic Lights | H4: Improvement over time? | I4: Targets / Goals? | J4: Comments | K4: Parameters | L4: UBER TECHNOLOGIES, INC. (XNYS:UBER) | M4: #VALUE! | N4: #VALUE! | O4: #VALUE!
B5: Environmental | K5: Ratios
A6: 1 | B6: CO2 Direct Emissions | C6: =VLOOKUP($B$2,'Sector Impact'!$K$4:$AA$16,A6+1,FALSE) -> Medium | D6: Yes | E6: Medium | F6: Yes | H6: Yes | I6: • Targets • 2030: 100% of rides in Canada, Europe, and the US are zero-emission • 2030: Net-zero climate emissions from all corporate operations (such as offices and data centers) • 2040: 100% of rides globally are in zero-emission vehicles (ZEVs), on micromobility, and/or on public transit • 2040: Net-zero climate emissions across all lines of business (mobility, delivery, and freight) and operations | K6: CO2 Emissions/$M Sales | L6: =L12/L$11 -> 0.72189133 | M6: =M12/M$11 -> 0 | N6: =N12/N$11 -> 0.3395025 | O6: =O12/O$11 -> 4.9144356 | P6: =P12/P$11 -> #DIV/0! | Q6: =Q12/Q$11 -> #DIV/0!
A7: 2 | B7: Total Water Consumption | C7: =VLOOKUP($B$2,'Sector Impact'!$K$4:$AA$16,A7+1,FALSE) -> Low | K7: Water Consumption/$M Sales | L7: =L13/L$11 -> 0.025169495 | M7: =M13/M$11 -> 0 | N7: =N13/N$11 -> 0 | O7: =O13/O$11 -> 0 | P7: =P13/P$11 -> #DIV/0! | Q7: =Q13/Q$11 -> #DIV/0!
A8: 3 | B8: Total Energy Consumption | C8: =VLOOKUP($B$2,'Sector Impact'!$K$4:$AA$16,A8+1,FALSE) -> High | D8: Yes | E8: "Villain" | F8: Yes | H8: No | I8: Uber is committed to matching 100% of energy use in our US workplaces with renewable energy by 2025 | K8: Energy Consumption/$M Sales | L8: =L14/L$11 -> 11.533057 | M8: =M14/M$11 -> 0 | N8: =N14/N$11 -> 0.0004545 | O8: =O14/O$11 -> 116.23975 | P8: =P14/P$11 -> #DIV/0! | Q8: =Q14/Q$11 -> #DIV/0!
A9: 4 | B9: Waste Management | C9: =VLOOKUP($B$2,'Sector Impact'!$K$4:$AA$16,A9+1,FALSE) -> Low | K9: Waste Production/$M Sales | L9: =L15/L$11 -> 0.001 | M9: =M15/M$11 -> 0.001 | N9: =N15/N$11 -> 0.001 | O9: =O15/O$11 -> 0.001 | P9: =P15/P$11 -> #DIV/0! | Q9: =Q15/Q$11 -> #DIV/0!
A10: 5 | B10: Land Degradation/Deforestation/Biodiversity loss/Animal sufering/… | C10: =VLOOKUP($B$2,'Sector Impact'!$K$4:$AA$16,A10+1,FALSE) -> Low | K10: Inputs | L10: UBER TECHNOLOGIES, INC. (XNYS:UBER) | M10: DiDi Global Inc. (OTCM:DIDIY) | N10: LYFT, INC. (XNAS:LYFT) | O10: #VALUE!
B11: Social | K11: Net Sales ($M) | L11: =L15*1000 -> 31877000 | M11: =M15*1000 -> 20412875000 | N11: =N15*1000 -> 4000000 | O11: =O15*1000 -> 675000
A12: 6 | B12: Employee Turnover % | C12: =VLOOKUP($B$2,'Sector Impact'!$K$4:$AA$16,A12+1,FALSE) -> Low | K12: CO2 Emissions Total (Tonnes)/Scope 3 | L12: 23011730 | N12: 1358010 | O12: 3317244
A13: 7 | B13: Salaries & Compensation | C13: =VLOOKUP($B$2,'Sector Impact'!$K$4:$AA$16,A13+1,FALSE) -> Low | K13: Water Consumption Total (Cubic Meters) | L13: 802328
A14: 8 | B14: Reputation | C14: =VLOOKUP($B$2,'Sector Impact'!$K$4:$AA$16,A14+1,FALSE) -> Low | K14: Energy Consumption Total (Gigajoules) | L14: 367639268 | N14: 1818 | O14: 78461833
A15: 9 | B15: Discrimination Events | C15: =VLOOKUP($B$2,'Sector Impact'!$K$4:$AA$16,A15+1,FALSE) -> Low | F15: Yes | K15: Waste Production Total (Tonnes) | L15: 31877 | M15: 20412875 | N15: 4000 | O15: 675
A16: 10 | B16: Work Safety | C16: =VLOOKUP($B$2,'Sector Impact'!$K$4:$AA$16,A16+1,FALSE) -> High | D16: Yes | E16: "Villain" | F16: No | H16: Increase in total recordable incident rate (TRIR) (direct employees/ contractors) | I16: Not clear | J16: Only report US data | K16: ESG Scores
A17: 11 | B17: Damage to consumer health | C17: =VLOOKUP($B$2,'Sector Impact'!$K$4:$AA$16,A17+1,FALSE) -> Low | K17: Refinitiv
A18: 12 | B18: PXP? | C18: =VLOOKUP($B$2,'Sector Impact'!$K$4:$AA$16,A18+1,FALSE) -> Low | K18: Sustainalytics
A19: 13 | B19: Supply chain | C19: =VLOOKUP($B$2,'Sector Impact'!$K$4:$AA$16,A19+1,FALSE) -> Low | K19: ISS
A20: 14 | B20: Community involvement | C20: =VLOOKUP($B$2,'Sector Impact'!$K$4:$AA$16,A20+1,FALSE) -> Low | K20: CDP
A21: 15 | B21: Public Sector | C21: =VLOOKUP($B$2,'Sector Impact'!$K$4:$AA$16,A21+1,FALSE) -> Medium | D21: No | E21: "Villain" | F21: Yes
A22: 16 | B22: Litigation | C22: =VLOOKUP($B$2,'Sector Impact'!$K$4:$AA$16,A22+1,FALSE) -> Very High | D22: Yes | E22: "Villain" | F22: Yes
B23: Corporate Governance | K23: PARAMETERS
A24: 17 | B24: Diversity (Gender, Age, Industry, Region) | E24: "Best in class" | F24: Yes | K24: IMPACT | L24: RANKING | M24: MITIGATION PLAN
A25: 18 | B25: % Independence | E25: "Best in class" | F25: Yes | J25: 90% Independent | K25: Low | L25: "Best in class" | M25: Evidence / plan?
A26: 19 | B26: average time as independent directors | E26: Medium | F26: Yes | J26: 4.4 Avg years of tenure | K26: Medium | L26: Medium High
A27: 20 | B27: Recent departures of directors / C-level executives? | K27: High | L27: Medium
A28: 21 | B28: CEO/Chairman duality | E28: "Best in class" | F28: No | J28: CEO : Dara Khosrowshahi / Ronald Sugar (Chair) | K28: Very high | L28: "Villain"
A29: 22 | B29: Transparency (ESG, segments, acquisitions, other) | E29: "Best in class"
A30: 23 | B30: Time taken to report after the end of the quarter / year | E30: Medium High
A31: 24 | B31: Additional participation of the CEO in other boards or excessive participation of Ch. | E31: "Best in class" | J31: Good balance between Committee Composition
A32: 25 | B32: Audit / Consulting | D32: Yes | E32: Medium High | F32: No | J32: PWC
A33: 26 | B33: ESG-compensation related | D33: Yes | E33: Medium | F33: Yes | I33: CEO’s compensation is tied to the achievement of climate-related objectives | J33: CEO’s compensation is tied to the achievement of climate-related objectives
A34: 27 | B34: Management compensation schemes | D34: Yes | E34: Medium High | F34: Yes | I34: ESG. We continued our progress on our ESG goals in 2022 with the advancement of our zero emission commitments. We started the year with approximately 17,000 average monthly active electric vehicles on the platform and ended the year with approximately 45,700. Usage of our sustainable products (Uber Green, Uber Planet in LATAM, and Comfort Electric in the United States) has also grown by more than 150% year over year. We also submitted our science based targets to the Science Based Targets initiative (SBTi) for validation, and in 2023, Uber’s near and long-term science-based emissions reduction targets were approved by the SBTi. | J34: . The Compensation Committee considers diversity, equity, and inclusion (DEI) metrics when developing compensation plans and includes DEI and cultural goals as metrics in the compensation for Uber’s most senior executives. The Compensation Committee also receives summaries of employee engagement survey results and related matters

Sheet DCF
A1: VALUATION MODEL
G3: Short Term | K3: Long Term
A4: Section | B4: Line # | C4: ITEM | D4: 2020 (Real) | E4: 2021 (Real) | F4: 2022 (Real) | G4: 2023 | H4: =G4+1 -> 2024 | I4: =H4+1 -> 2025 | J4: =I4+1 -> 2026 | K4: =J4+1 -> 2027 | L4: =K4+1 -> 2028 | M4: =L4+1 -> 2029 | N4: =M4+1 -> 2030 | O4: =N4+1 -> 2031 | ... AF4: =AE4+1 -> 2048
A5: INCOME STATEMENT | B5: 1 | C5: Growth | D5: ='Fin. Data'!D6 -> -0.14315385 | E5: =+E6/D6-1 -> 0.56701679 | F5: =+F6/E6-1 -> 0.8262389 | G5: 0.25 | H5: 0.2 | I5: 0.15 | J5: 0.15 | K5: 0.1 | L5: 0.09 | M5: 0.09 | N5: 0.08 | O5: 0.08 | P5: 0.07 | Q5: 0.07 | R5: 0.06 | S5: 0.05 | T5: 0.05 | U5: 0.05 | V5: 0.05 | W5: 0.05 | X5: 0.05 | Y5: =+X5-0.005 -> 0.045 | Z5: =+Y5-0.005 -> 0.04 | AA5: =+Z5-0.005 -> 0.035 | AB5: =+AA5-0.005 -> 0.03 | AC5: =+AB5-0.005 -> 0.025 | AD5: =+AC5-0.005 -> 0.02 | AE5: =+AD5-0.005 -> 0.015 | AF5: =+AE5-0.005 -> 0.01
B6: 2 | C6: Revenues/Sales | D6: =+Inputs!D6 -> 11139 | E6: =+Inputs!C6 -> 17455 | F6: =+Inputs!B6 -> 31877 | G6: =+F6*(1+G5) -> 39846.25 | H6: =+G6*(1+H5) -> 47815.5 | I6: =+H6*(1+I5) -> 54987.825 | J6: =+I6*(1+J5) -> 63235.999 | K6: =+J6*(1+K5) -> 69559.599 | L6: =+K6*(1+L5) -> 75819.963 | M6: =+L6*(1+M5) -> 82643.759 | N6: =+M6*(1+N5) -> 89255.26 | ... AF6: =+AE6*(1+AF5) -> 194672.88
B7: 3 | C7: Operating Margin | D7: =D8/D6 -> -0.4365742 | E7: =E8/E6 -> -0.21965053 | F7: =F8/F6 -> -0.057470904 | G7: -0.036 | H7: =+_xlfn.FORECAST.LINEAR(H4,'Fin. Data'!$B$12:$H$12,'Fin. Data'!$B$4:$H$4) -> -0.01331898 | I7: 0.02 | J7: 0.04 | K7: 0.06 | L7: 0.08 | M7: 0.09 | N7: 0.1 | O7: 0.11 | P7: 0.12 | Q7: 0.13 | R7: 0.14 | S7: 0.14 | T7: 0.14 | U7: 0.14 | V7: 0.13 | W7: 0.12 | X7: 0.11 | Y7: 0.1 | Z7: 0.1 | AA7: 0.1 | AB7: 0.1 | AC7: 0.1 | AD7: 0.1 | AE7: 0.1 | AF7: 0.1
B8: 4 | C8: EBIT | D8: ='Fin. Data'!D11 -> -4863 | E8: ='Fin. Data'!C11 -> -3834 | F8: ='Fin. Data'!B11 -> -1832 | G8: =G7*G6 -> -1434.465 | H8: =H7*H6 -> -636.85367 | I8: =I7*I6 -> 1099.7565 | J8: =J7*J6 -> 2529.4399 | K8: =K7*K6 -> 4173.5759 | L8: =L7*L6 -> 6065.597 | M8: =M7*M6 -> 7437.9383 | N8: =N7*N6 -> 8925.526 | ... AF8: =AF7*AF6 -> 19467.288
B9: 5a | C9: (Dep) | D9: 420 | E9: 463 | F9: 424 | G9: =+Assumptions!I17 -> 473.92944 | H9: =+Assumptions!J17 -> 503.13269 | I9: =+Assumptions!K17 -> 536.71644 | J9: =+Assumptions!L17 -> 575.33775 | K9: =+Assumptions!M17 -> 617.82118 | L9: =+Assumptions!N17 -> 598.08772 | M9: =+Assumptions!O17 -> 643.54313 | N9: =+Assumptions!P17 -> 692.63498 | ... AF9: =+Assumptions!AH17 -> 10691.354 | AG9: =SUM(D9:AF9) -> 95744.379
B10: 5b | C10: Amort | D10: 155 | E10: 439 | F10: 523 | G10: =+Assumptions!I24 -> 259.82767 | H10: =+Assumptions!J24 -> 275.8381 | I10: =+Assumptions!K24 -> 294.25009 | J10: =+Assumptions!L24 -> 315.42389 | K10: =+Assumptions!M24 -> 338.71506 | L10: =+Assumptions!N24 -> 364.10244 | M10: =+Assumptions!O24 -> 391.77468 | N10: =+Assumptions!P24 -> 421.6607 | ... AF10: =+Assumptions!AH24 -> 7227.3385
B11: 5c | C11: (Stock based compensation) | D11: =D20 -> 827 | E11: =E20 -> 1168 | F11: =F20 -> 1793 | G11: =G6*$D$55 -> 2621.9633 | H11: =H6*$D$55 -> 3146.3559 | I11: =I6*$D$55 -> 3618.3093 | J11: =J6*$D$55 -> 4161.0557 | K11: =K6*$D$55 -> 4577.1613 | L11: =L6*$D$55 -> 4989.1058 | M11: =M6*$D$55 -> 5438.1253 | N11: =N6*$D$55 -> 5873.1753 | ... AF11: =AF6*$D$55 -> 12809.866
B12: 6 | C12: EBIDTA | D12: =D8-D9-D10 -> -5438 | E12: =E8-E9-E10 -> -4736 | F12: =F8-F9-F10 -> -2779 | G12: =G8-G9-G10 -> -2168.2221 | H12: =H8-H9-H10 -> -1415.8245 | I12: =I8-I9-I10 -> 268.78997 | J12: =J8-J9-J10 -> 1638.6783 | K12: =K8-K9-K10 -> 3217.0397 | ... AF12: =AF8-AF9-AF10 -> 1548.5954
B13: 7 | C13: (Net financing cost) | D13: ='Fin. Data'!D14 -> -403 | E13: ='Fin. Data'!C14 -> -446 | F13: ='Fin. Data'!B14 -> -426 | G13: =-F44*$D$57 -> 0 | H13: =-G44*$D$57 -> 0 | I13: =-H44*$D$57 -> 0 | J13: =-I44*$D$57 -> 0 | K13: =-J44*$D$57 -> 0 | L13: =-K44*$D$57 -> 0 | M13: =-L44*$D$57 -> 0 | N13: =-M44*$E$57 -> -885.43805 | O13: =-N44*$E$57 -> -952.98805 | P13: =-O44*$E$57 -> -1025.018 | Q13: =-P44*$E$57 -> -1101.7424 | R13: =-Q44*$E$57 -> -1154.7856 | S13: =-R44*$E$57 -> -1208.7495 | T13: =-S44*$E$57 -> -1263.5354 | U13: =-T44*$E$57 -> -1319.03 | ... AF13: =-AE44*$E$57 -> -2665.8932
B14: 8 | C14: Other income/(cost) | D14: ='Fin. Data'!D15 -> -1625 | E14: ='Fin. Data'!C15 -> 3292 | F14: ='Fin. Data'!B15 -> -7029 | G14: =AVERAGE(D14:F14)*(1+G5) -> -2234.1667 | H14: =AVERAGE(E14:G14)*(1+H5) -> -2388.4667 | I14: =AVERAGE(E14:H14)*(1+I5) -> -2403.3946 | J14: =AVERAGE(G14:I14)*(1+J5) -> -2693.3107 | K14: =AVERAGE(H14:J14)*(1+K5) -> -2744.563 | L14: =AVERAGE(I14:K14)*(1+L5) -> -2848.9942 | M14: =AVERAGE(J14:L14)*(1+M5) -> -3010.8953 | N14: =AVERAGE(K14:M14)*(1+N5) -> -3097.6029 | O14: =AVERAGE(L14:N14)*(1+O5) -> -3224.6973 | P14: =AVERAGE(M14:O14)*(1+P5) -> -3328.8397 | Q14: =AVERAGE(N14:P14)*(1+Q5) -> -3442.2399 | ... AF14: =AVERAGE(AC14:AE14)*(1+AF5) -> -4489.1639
B15: 9 | C15: Earnings before taxes | D15: =D8+D13+D14 -> -6891 | E15: =E8+E13+E14 -> -988 | F15: =F8+F13+F14 -> -9287 | G15: =G8+G13+G14 -> -3668.6317 | H15: =H8+H13+H14 -> -3025.3203 | I15: =I8+I13+I14 -> -1303.6381 | J15: =J8+J13+J14 -> -163.87075 | K15: =K8+K13+K14 -> 1429.0129 | ... AF15: =AF8+AF13+AF14 -> 12312.231
B16: 10 | C16: (Income tax) | D16: ='Fin. Data'!D21 -> -192 | E16: ='Fin. Data'!C21 -> -492 | F16: ='Fin. Data'!B21 -> -181 | G16: =(1*$D$56)*G15 -> -541.49003 | H16: =(1*$D$56)*H15 -> -446.53728 | I16: =(1*$D$56)*I15 -> -192.41698 | J16: =(1*$D$56)*J15 -> -24.187323 | K16: =-(1*$E$56)*K15 -> -191.3734 | L16: =-(1*$E$56)*L15 -> -430.76745 | M16: =-(1*$E$56)*M15 -> -592.8696 | N16: =-(1*$E$56)*N15 -> -661.89759 | O16: =-(1*$E$56)*O15 -> -860.54843 | P16: =-(1*$E$56)*P15 -> -1074.4867 | Q16: =-(1*$E$56)*Q15 -> -1312.8528 | R16: =-(1*$E$56)*R15 -> -1565.6994 | ... AF16: =-(1*$E$56)*AF15 -> -1648.8539
B17: 11 | C17: Net income | D17: ='Fin. Data'!D23 -> -6768 | E17: ='Fin. Data'!C23 -> -496 | F17: ='Fin. Data'!B23 -> -9141 | G17: =G16+G15 -> -4210.1217 | H17: =H16+H15 -> -3471.8576 | I17: =I16+I15 -> -1496.0551 | J17: =J16+J15 -> -188.05807 | K17: =K16+K15 -> 1237.6395 | L17: =L16+L15 -> 2785.8354 | M17: =M16+M15 -> 3834.1734 | N17: =N16+N15 -> 4280.5874 | ... AF17: =AF16+AF15 -> 10663.377
I18: =+J8/I8-1 -> 1.3 | J18: =+K8/J8-1 -> 0.65 | K18: =+L8/K8-1 -> 0.45333333 | L18: =+M8/L8-1 -> 0.22625 | M18: =+N8/M8-1 -> 0.2 | N18: =+O8/N8-1 -> 0.188 | O18: =+P8/O8-1 -> 0.16727273 | P18: =+Q8/P8-1 -> 0.15916667 | ... AF18: =+AG8/AF8-1 -> -1
A19: CASH FLOW STATEMENT | B19: 12 | C19: Operating cash flows before WK | D19: =+D22-D21 -> -3583 | E19: =+E22-E21 -> -1186 | F19: =+F22-F21 -> 170 | G19: =+G17+G10+G9 -> -3476.3646 | H19: =+H17+H10+H9 -> -2692.8868 | I19: =+I17+I10+I9 -> -665.08853 | J19: =+J17+J10+J9 -> 702.70356 | K19: =+K17+K10+K9 -> 2194.1757 | L19: =+L17+L10+L9 -> 3748.0255 | M19: =+M17+M10+M9 -> 4869.4912 | N19: =+N17+N10+N9 -> 5394.8831 | ... AF19: =+AF17+AF10+AF9 -> 28582.069
B20: 13 | C20: (Stock-based compensation) | D20: 827 | E20: 1168 | F20: 1793 | G20: =G11 -> 2621.9633 | H20: =H11 -> 3146.3559 | I20: =I11 -> 3618.3093 | J20: =J11 -> 4161.0557 | K20: =K11 -> 4577.1613 | L20: =L11 -> 4989.1058 | M20: =M11 -> 5438.1253 | N20: =N11 -> 5873.1753 | ... AF20: =AF11 -> 12809.866
B21: 14 | C21: (Working Capital Flows) | D21: =+Assumptions!M117 -> 838 | E21: =+Assumptions!N117 -> 741 | F21: =+Assumptions!O117 -> 472 | G21: =+Assumptions!P117 -> 555.58944 | H21: =+Assumptions!Q117 -> 545.33481 | I21: =+Assumptions!R117 -> 500.40809 | J21: =+Assumptions!S117 -> 579.61222 | K21: =+Assumptions!T117 -> 458.13307 | ... AF21: =+Assumptions!AO117 -> 247.10265
B22: 15 | C22: -Total Operating Cash Flow | D22: =+'Fin. Data'!D67 -> -2745 | E22: =+'Fin. Data'!C67 -> -445 | F22: =+'Fin. Data'!B67 -> 642 | G22: =G19+G20+G21 -> -298.8119 | H22: =H19+H20+H21 -> 998.80388 | I22: =I19+I20+I21 -> 3453.6289 | J22: =J19+J20+J21 -> 5443.3715 | K22: =K19+K20+K21 -> 7229.47 | L22: =L19+L20+L21 -> 9197.3214 | M22: =M19+M20+M21 -> 10812.651 | N22: =N19+N20+N21 -> 11765.314 | ... AF22: =AF19+AF20+AF21 -> 41639.038
B23: 16 | C23: (CAPEX) | D23: ='Fin. Data'!D32 -> -616 | E23: ='Fin. Data'!C32 -> -298 | F23: ='Fin. Data'!B32 -> -252 | G23: =+Assumptions!I51 -> -497.637 | H23: =+Assumptions!J51 -> -597.16439 | I23: =+Assumptions!K51 -> -686.73905 | J23: =+Assumptions!L51 -> -789.74991 | K23: =+Assumptions!M51 -> -868.7249 | L23: =+Assumptions!N51 -> -946.91014 | M23: =+Assumptions!O51 -> -1032.1321 | N23: =+Assumptions!P51 -> -1114.7026 | ... AF23: =+Assumptions!AH51 -> -6280.4824 | AG23: =SUM(D23:AF23) -> -91443.814
B24: 17 | C24: Adq | D24: =Inputs!D66 -> -2131 | E24: ='Fin. Data'!C33 -> -618 | F24: ='Fin. Data'!B33 -> -1139 | G24: =G6*$D$63 -> -1356.9881 | H24: =H6*$D$63 -> -1628.3858 | I24: =I6*$D$63 -> -1872.6436 | J24: =J6*$D$63 -> -2153.5402 | K24: =K6*$E$63 -> -2167.7129 | L24: =L6*$E$63 -> -2362.8071 | M24: =M6*$E$63 -> -2575.4597 | N24: =N6*$E$63 -> -2781.4965 | O24: =O6*$E$63 -> -3004.0163 | P24: =P6*$E$63 -> -3214.2974 | Q24: =Q6*$E$63 -> -3439.2982 | R24: =R6*$E$63 -> -3645.6561 | ... AF24: =AF6*$E$63 -> -6066.6669 | AH24: =AG9-AG23 -> 187188.19
B25: 18 | C25: (Other investing flows) | D25: =Inputs!D67 -> -122 | E25: =Inputs!C67 -> -285 | F25: =Inputs!B67 -> -246 | G25: =(1+G5)*AVERAGE(D25:F25) -> -272.08333 | H25: =(1+H5)*AVERAGE(E25:G25) -> -321.23333 | I25: =(1+I5)*AVERAGE(F25:H25) -> -321.73806 | J25: =(1+J5)*AVERAGE(G25:I25) -> -350.77098 | K25: =(1+K5)*AVERAGE(H25:J25) -> -364.3722 | L25: =(1+L5)*AVERAGE(I25:K25) -> -376.73351 | M25: =(1+M5)*AVERAGE(J25:L25) -> -396.7152 | N25: =(1+N5)*AVERAGE(K25:M25) -> -409.61553 | ... AF25: =(1+AF5)*AVERAGE(AC25:AE25) -> -592.91565
B26: 19 | C26: -Total Investing Flows | D26: =D23+D24+D25 -> -2869 | E26: =E23+E24+E25 -> -1201 | F26: =F23+F24+F25 -> -1637 | G26: =G23+G24+G25 -> -2126.7085 | H26: =H23+H24+H25 -> -2546.7835 | I26: =I23+I24+I25 -> -2881.1207 | J26: =J23+J24+J25 -> -3294.0611 | K26: =K23+K24+K25 -> -3400.81 | ... AF26: =AF23+AF24+AF25 -> -12940.065
B27: 20 | C27: (Flows related to leases) | D27: =Inputs!D71+Inputs!D72 -> -224 | E27: =Inputs!C71+Inputs!C72 -> -116 | F27: =Inputs!B71+Inputs!B72 -> -139 | G27: =+Assumptions!I88 -> -384.94039 | H27: =+Assumptions!J88 -> -461.92846 | I27: =+Assumptions!K88 -> -531.21773 | J27: =+Assumptions!L88 -> -610.90039 | K27: =+Assumptions!M88 -> -671.99043 | L27: =+Assumptions!N88 -> -732.46957 | M27: =+Assumptions!O88 -> -798.39183 | N27: =+Assumptions!P88 -> -862.26318 | ... AF27: =+Assumptions!AH88 -> -1880.6651
B28: 21 | C28: Flows related to debt | D28: =+SUM(Inputs!D69:D70) -> 4046 | E28: =+SUM(Inputs!C69:C70) -> 1818 | F28: =+SUM(Inputs!B69:B70) -> 80 | G28: =G44-F44 -> 2921.91 | H28: =H44-G44 -> 2469.4433 | I28: =I44-H44 -> 92.188064 | J28: =J44-I44 -> 1065.9113 | K28: =K44-J44 -> 1384.635 | L28: =L44-K44 -> 1480.76 | M28: =M44-L44 -> 1582.1036 | N28: =N44-M44 -> 1688.7501 | ... AF28: =AF44-AE44 -> 4392.8634
B29: 22 | C29: (Respurchases)/Issuance of stock | D29: ='Fin. Data'!D28 -> 0 | E29: ='Fin. Data'!C28 -> 0 | F29: ='Fin. Data'!B28 -> 0 | G29: =-G17*$D$65 -> 0 | H29: =-H17*$D$65 -> 0 | I29: =-I17*$D$65 -> 0 | J29: =-J17*$D$65 -> 0 | K29: =+Assumptions!N96 -> 247.52789 | L29: =+Assumptions!O96 -> 696.45885 | M29: =+Assumptions!P96 -> 1150.252 | N29: =+Assumptions!Q96 -> 1498.2056 | O29: =+Assumptions!R96 -> 2226.1164 | P29: =+Assumptions!S96 -> 3056.5653 | Q29: =+Assumptions!T96 -> 3734.6393 | R29: =+Assumptions!U96 -> 4453.9058 | ... AF29: =+Assumptions!AI96 -> 4690.4533
B30: 23 | C30: (Dividends) | D30: ='Fin. Data'!D27 -> 0 | E30: ='Fin. Data'!C27 -> 0 | F30: ='Fin. Data'!B27 -> 0 | G30: =-$D$64*G17 -> 0 | H30: =-$D$64*H17 -> 0 | I30: =-$D$64*I17 -> 0 | J30: =-$D$64*J17 -> 0 | K30: =-$D$64*K17 -> 0 | L30: 0 | M30: 0 | N30: =+Assumptions!Q98 -> 428.05874 | O30: =+Assumptions!R98 -> 834.79367 | P30: =+Assumptions!S98 -> 1389.7722 | Q30: =+Assumptions!T98 -> 2122.6022 | R30: =+Assumptions!U98 -> 3037.6814 | S30: =+Assumptions!V98 -> 3587.0105 | T30: =+Assumptions!W98 -> 3792.1261 | U30: =+Assumptions!X98 -> 4011.1524 | ... AF30: =+Assumptions!AI98 -> 3566.7826
B31: 24 | C31: Other financing flows | D31: =Inputs!D75 -> -2443 | E31: =Inputs!C75 -> 78 | F31: =Inputs!B75 -> 74 | G31: =(1+G5)*AVERAGE(E31:F31) -> 95 | H31: =(1+H5)*AVERAGE(E31:G31) -> 98.8 | I31: =(1+I5)*AVERAGE(F31:H31) -> 102.65667 | J31: =(1+J5)*AVERAGE(G31:I31) -> 113.64172 | K31: =(1+K5)*AVERAGE(H31:J31) -> 115.53608 | L31: =(1+L5)*AVERAGE(I31:K31) -> 120.56652 | M31: =(1+M5)*AVERAGE(J31:L31) -> 127.07377 | N31: =(1+N5)*AVERAGE(K31:M31) -> 130.74349 | O31: =(1+O5)*AVERAGE(L31:N31) -> 136.21816 | ... AF31: =(1+AF5)*AVERAGE(AC31:AE31) -> 189.55381
B32: 25 | C32: -Total Financing flows | D32: =D27+D28+D29+D30+D31 -> 1379 | E32: =E27+E28+E29+E30+E31 -> 1780 | F32: =F27+F28+F29+F30+F31 -> 15 | G32: =G27+G28+G29+G30+G31 -> 2631.9696 | H32: =H27+H28+H29+H30+H31 -> 2106.3148 | I32: =I27+I28+I29+I30+I31 -> -336.373 | J32: =J27+J28+J29+J30+J31 -> 568.65259 | K32: =K27+K28+K29+K30+K31 -> 1075.7086 | ... AF32: =AF27+AF28+AF29+AF30+AF31 -> 10958.988
A34: SUMMARY | B34: 26 | C34: Cash before shareholder returns | D34: =D22+D26+D29+D30+D32 -> -4235 | E34: =E22+E26+E29+E30+E32 -> 134 | F34: =F22+F26+F29+F30+F32 -> -980 | G34: =G22+G26+G29+G30+G32 -> 206.44923 | H34: =H22+H26+H29+H30+H32 -> 558.33518 | I34: =I22+I26+I29+I30+I32 -> 236.13511 | J34: =J22+J26+J29+J30+J32 -> 2717.963 | K34: =K22+K26+K29+K30+K32 -> 5151.8965 | ... AF34: =AF22+AF26+AF29+AF30+AF32 -> 47915.197
B35: 27 | C35: Returns to shareholders | D35: =-1*(D29+D30) -> 0 | E35: =-1*(E29+E30) -> 0 | F35: =-1*(F29+F30) -> 0 | G35: =-1*(G29+G30) -> 0 | H35: =-1*(H29+H30) -> 0 | I35: =-1*(I29+I30) -> 0 | J35: =-1*(J29+J30) -> 0 | K35: =-1*(K29+K30) -> -247.52789 | ... AF35: =-1*(AF29+AF30) -> -8257.236
B36: 28 | C36: Excess cash acumulation | D36: =D34-D35 -> -4235 | E36: =E34-E35 -> 134 | F36: =F34-F35 -> -980 | G36: =G34-G35 -> 206.44923 | H36: =H34-H35 -> 558.33518 | I36: =I34-I35 -> 236.13511 | J36: =J34-J35 -> 2717.963 | K36: =K34-K35 -> 5399.4243 | ... AF36: =AF34-AF35 -> 56172.433
A38: BALANCE SHEET | B38: 29 | C38: Intangible assets | D38: 1564 | E38: 2412 | F38: 1847 | G38: =+F38+(G10) -> 2106.8277 | H38: =+G38+(H10) -> 2382.6658 | I38: =+H38+(I10) -> 2676.9159 | J38: =+I38+(J10) -> 2992.3397 | K38: =+J38+(K10) -> 3331.0548 | L38: =+K38+(L10) -> 3695.1572 | M38: =+L38+(M10) -> 4086.9319 | N38: =+M38+(N10) -> 4508.5926 | ... AF38: =+AE38+(AF10) -> 65106.608 | AG38: =SUM(G38:AF38) -> 483547.42
B39: 30 | C39: Accumulated amorization | D39: =+Assumptions!L129 -> 175 | E39: =+Assumptions!M129 -> 620 | F39: =+Assumptions!N129 -> 1119 | G39: =F39+G10 -> 1378.8277 | H39: =G39+H10 -> 1654.6658 | I39: =H39+I10 -> 1948.9159 | J39: =I39+J10 -> 2264.3397 | K39: =J39+K10 -> 2603.0548 | L39: =K39+L10 -> 2967.1572 | M39: =L39+M10 -> 3358.9319 | N39: =M39+N10 -> 3780.5926 | ... AF39: =AE39+AF10 -> 64378.608 | AG39: =SUM(G39:AF39) -> 464619.42
B40: 31 | C40: PPE+Right of use Assets | D40: 1814 | E40: 1853 | F40: 2082 | G40: =F40+(-G23)+G27 -> 2194.6966 | H40: =G40+(-H23)+H27 -> 2329.9325 | I40: =H40+(-I23)+I27 -> 2485.4539 | J40: =I40+(-J23)+J27 -> 2664.3034 | K40: =J40+(-K23)+K27 -> 2861.0378 | L40: =K40+(-L23)+L27 -> 3075.4784 | M40: =L40+(-M23)+M27 -> 3309.2186 | N40: =M40+(-N23)+N27 -> 3561.6581 | ... AF40: =AE40+(-AF23)+AF27 -> 61047.445 | AG40: =SUM(G40:AF40) -> 534337.42
B41: 32 | C41: Accumulated depreciation | D41: =+Assumptions!L130 -> 841 | E41: =+Assumptions!M130 -> 562 | F41: =+Assumptions!N130 -> 166 | G41: =F41+G9 -> 639.92944 | H41: =G41+H9 -> 1143.0621 | I41: =H41+I9 -> 1679.7786 | J41: =I41+J9 -> 2255.1163 | K41: =J41+K9 -> 2872.9375 | L41: =K41+L9 -> 3471.0252 | M41: =L41+M9 -> 4114.5684 | N41: =M41+N9 -> 4807.2033 | ... AF41: =AE41+AF9 -> 94603.379 | AG41: =SUM(G41:AF41) -> 667324.36
A43: CASH & DEBT & DISCOUNTING | B43: 33 | C43: Ending cash balance | D43: ='Fin. Data'!E39+D36 -> 6638 | E43: =+'Fin. Data'!D39+E36 -> 5781 | F43: =+'Fin. Data'!C39+F36 -> 3315 | G43: =G36+F43 -> 3521.4492 | H43: =H36+G43 -> 4079.7844 | I43: =I36+H43 -> 4315.9195 | J43: =J36+I43 -> 7033.8825 | K43: =K36+J43 -> 12433.307 | L43: =L36+K43 -> 20902.411 | M43: =M36+L43 -> 32072.297 | N43: =N36+M43 -> 46267.819 | ... AF43: =AF36+AE43 -> 813824.45
B44: 34 | C44: Total Debt | D44: ='Fin. Data'!D58 -> 9279 | E44: ='Fin. Data'!C58 -> 11105 | F44: ='Fin. Data'!B58 -> 11139 | G44: =+Assumptions!I83 -> 14060.91 | H44: =+Assumptions!J83 -> 16530.353 | I44: =+Assumptions!K83 -> 16622.541 | J44: =+Assumptions!L83 -> 17688.453 | K44: =+Assumptions!M83 -> 19073.088 | L44: =+Assumptions!N83 -> 20553.848 | M44: =+Assumptions!O83 -> 22135.951 | N44: =+Assumptions!P83 -> 23824.701 | ... AF44: =+Assumptions!AH83 -> 71040.193
...

Sheet Assumptions
B2: Market Projected to grow at 16,3%
B3: https://www.fortunebusinessinsights.com/ride-sharing-market-103336
C7: Last 5 Years | I7: Short Term Forecast
C8: 2017 | D8: 2018 | E8: 2019 | F8: 2020 | G8: 2021 | H8: 2022 | I8: 2023 | J8: =I8+1 -> 2024 | K8: =J8+1 -> 2025 | L8: =K8+1 -> 2026 | M8: =L8+1 -> 2027 | N8: =M8+1 -> 2028 | O8: =N8+1 -> 2029 | P8: =O8+1 -> 2030 | Q8: =P8+1 -> 2031 | ... AH8: =AG8+1 -> 2048
B9: Net Sales | C9: =+'Fin. Data'!G5 -> 7932 | D9: =+'Fin. Data'!F5 -> 10433 | E9: =+'Fin. Data'!E5 -> 13000 | F9: =+'Fin. Data'!D5 -> 11139 | G9: =+'Fin. Data'!C5 -> 17455 | H9: =+'Fin. Data'!B5 -> 31877 | I9: =+H9*(1+I10) -> 39846.25 | J9: =+I9*(1+J10) -> 47815.5 | K9: =+J9*(1+K10) -> 54987.825 | L9: =+K9*(1+L10) -> 63235.999 | M9: =+L9*(1+M10) -> 69559.599 | N9: =M9*(1+N10) -> 75819.963 | O9: =N9*(1+O10) -> 82643.759 | P9: =O9*(1+P10) -> 89255.26 | Q9: =P9*(1+Q10) -> 96395.681 | R9: =Q9*(1+R10) -> 103143.38 | S9: =R9*(1+S10) -> 110363.41 | T9: =S9*(1+T10) -> 116985.22 | U9: =T9*(1+U10) -> 122834.48 | ... AH9: =AG9*(1+AH10) -> 194672.88
B10: % Growth | D10: =+D9/C9-1 -> 0.31530509 | E10: =+E9/D9-1 -> 0.2460462 | F10: =+F9/E9-1 -> -0.14315385 | G10: =+G9/F9-1 -> 0.56701679 | H10: =+H9/G9-1 -> 0.8262389 | I10: 0.25 | J10: 0.2 | K10: 0.15 | L10: 0.15 | M10: 0.1 | N10: 0.09 | O10: 0.09 | P10: 0.08 | Q10: 0.08 | R10: 0.07 | S10: 0.07 | T10: 0.06 | U10: 0.05 | V10: 0.05 | W10: 0.05 | X10: 0.05 | Y10: 0.05 | Z10: 0.05 | AA10: =+Z10-0.005 -> 0.045 | AB10: =+AA10-0.005 -> 0.04 | AC10: =+AB10-0.005 -> 0.035 | AD10: =+AC10-0.005 -> 0.03 | AE10: =+AD10-0.005 -> 0.025 | AF10: =+AE10-0.005 -> 0.02 | AG10: =+AF10-0.005 -> 0.015 | AH10: =+AG10-0.005 -> 0.01
B11: Actual 5y Average | H11: =+AVERAGE(D10:H10) -> 0.36229063 | M11: =AVERAGE(I10:M10) -> 0.17 | R11: =+AVERAGE(N10:R10) -> 0.082 | W11: =+AVERAGE(S10:W10) -> 0.056 | AB11: =+AVERAGE(X10:AB10) -> 0.047 | AG11: =+AVERAGE(AC10:AG10) -> 0.025
B12: Target 5y Average | M12: 0.163
C15: Last 5 Years | I15: Short Term Forecast
C16: 2017 | D16: 2018 | E16: 2019 | F16: 2020 | G16: 2021 | H16: 2022 | I16: 2023 | J16: =I16+1 -> 2024 | K16: =J16+1 -> 2025 | L16: =K16+1 -> 2026 | M16: =L16+1 -> 2027 | N16: =M16+1 -> 2028 | O16: =N16+1 -> 2029 | P16: =O16+1 -> 2030 | Q16: =P16+1 -> 2031 | ... AH16: =AG16+1 -> 2048
B17: Depretiation | C17: 504 | D17: 411 | E17: 456 | F17: 420 | G17: 463 | H17: 424 | I17: =+DCF!G40*I18 -> 473.92944 | J17: =+DCF!H40*J18 -> 503.13269 | K17: =+DCF!I40*K18 -> 536.71644 | L17: =+DCF!J40*L18 -> 575.33775 | M17: =+DCF!K40*M18 -> 617.82118 | N17: =+DCF!L40*N18 -> 598.08772 | O17: =+DCF!M40*O18 -> 643.54313 | P17: =+DCF!N40*P18 -> 692.63498 | ... AH17: =+DCF!AF40*AH18 -> 10691.354
B18: % of PPE | C18: =+C17/'Fin. Data'!$G$42 -> 0.42281879 | D18: =+D17/'Fin. Data'!F42 -> 0.25045704 | E18: =+E17/'Fin. Data'!E42 -> 0.26343154 | F18: =+F17/'Fin. Data'!D42 -> 0.23153252 | G18: =+G17/'Fin. Data'!C42 -> 0.24986508 | H18: =+H17/'Fin. Data'!B42 -> 0.20365034 | I18: =+$H$19*(1-(-$H$20)) -> 0.21594303 | J18: =+$H$19*(1-(-$H$20)) -> 0.21594303 | K18: =+$H$19*(1-(-$H$20)) -> 0.21594303 | L18: =+$H$19*(1-(-$H$20)) -> 0.21594303 | M18: =+$H$19*(1-(-$H$20)) -> 0.21594303 | N18: =+$N$19 -> 0.19446981 | O18: =+$N$19 -> 0.19446981 | P18: =+$N$19 -> 0.19446981 | Q18: =+$N$19 -> 0.19446981 | R18: =+$N$19 -> 0.19446981 | S18: =+$S$19 -> 0.17513188 | T18: =+$S$19 -> 0.17513188 | U18: =+$S$19 -> 0.17513188 | V18: =+$S$19 -> 0.17513188 | W18: =+$S$19 -> 0.17513188 | X18: =+$S$19 -> 0.17513188 | Y18: =+$S$19 -> 0.17513188 | Z18: =+$S$19 -> 0.17513188 | ... AH18: =+$S$19 -> 0.17513188
B19: Target 5y Average | H19: =+AVERAGE(D18:H18) -> 0.23978731 | N19: =+I18*(1-(-H20)) -> 0.19446981 | S19: =+N19*(1-(-H20)) -> 0.17513188
B20: Average Growth % Sales | D20: =+D18/C18-1 -> -0.40764923 | E20: =+E18/D18-1 -> 0.051803312 | F20: =+F18/E18-1 -> -0.12109035 | G20: =+G18/F18-1 -> 0.079179195 | H20: =+AVERAGE(D20:G20) -> -0.099439268
C22: Last 5 Years | I22: Short Term Forecast
C23: 2017 | D23: 2018 | E23: 2019 | F23: 2020 | G23: 2021 | H23: 2022 | I23: 2023 | J23: =I23+1 -> 2024 | K23: =J23+1 -> 2025 | L23: =K23+1 -> 2026 | M23: =L23+1 -> 2027 | N23: =M23+1 -> 2028 | O23: =N23+1 -> 2029 | P23: =O23+1 -> 2030 | Q23: =P23+1 -> 2031 | ... AH23: =AG23+1 -> 2048
B24: Amortizatioon | C24: 7 | D24: 15 | E24: 16 | F24: 155 | G24: 439 | H24: 523 | I24: =+DCF!G40*I25 -> 259.82767 | J24: =+DCF!H40*J25 -> 275.8381 | K24: =+DCF!I40*K25 -> 294.25009 | L24: =+DCF!J40*L25 -> 315.42389 | M24: =+DCF!K40*M25 -> 338.71506 | N24: =+DCF!L40*N25 -> 364.10244 | O24: =+DCF!M40*O25 -> 391.77468 | P24: =+DCF!N40*P25 -> 421.6607 | ... AH24: =+DCF!AF40*AH25 -> 7227.3385
B25: % of PPE | C25: =+C24/'Fin. Data'!$G$42 -> 0.0058724832 | D25: =+D24/'Fin. Data'!F42 -> 0.0091407678 | E25: =+E24/'Fin. Data'!E42 -> 0.009243212 | F25: =+F24/'Fin. Data'!D42 -> 0.085446527 | G25: =+G24/'Fin. Data'!C42 -> 0.23691311 | H25: =+H24/'Fin. Data'!B42 -> 0.25120077 | I25: =+$H$26 -> 0.11838888 | J25: =+$H$26 -> 0.11838888 | K25: =+$H$26 -> 0.11838888 | L25: =+$H$26 -> 0.11838888 | M25: =+$H$26 -> 0.11838888 | N25: =+$N$26 -> 0.11838888 | O25: =+$N$26 -> 0.11838888 | P25: =+$N$26 -> 0.11838888 | Q25: =+$N$26 -> 0.11838888 | R25: =+$N$26 -> 0.11838888 | S25: =+$S$26 -> 0.11838888 | T25: =+$S$26 -> 0.11838888 | U25: =+$S$26 -> 0.11838888 | V25: =+$S$26 -> 0.11838888 | W25: =+$S$26 -> 0.11838888 | X25: =+$S$26 -> 0.11838888 | Y25: =+$S$26 -> 0.11838888 | Z25: =+$S$26 -> 0.11838888 | ... AH25: =+$S$26 -> 0.11838888
B26: Target 5y Average | H26: =+AVERAGE(D25:H25) -> 0.11838888 | N26: =+I25*(1-(-H27)) -> 0.11838888 | S26: =+N26*(1-(-H27)) -> 0.11838888
B27: Average Growth % Sales
C29: Last 5 Years | I29: Short Term Forecast
C30: 2017 | D30: 2018 | E30: 2019 | F30: 2020 | G30: 2021 | H30: 2022 | I30: 2023 | J30: =I30+1 -> 2024 | K30: =J30+1 -> 2025 | L30: =K30+1 -> 2026 | M30: =L30+1 -> 2027 | N30: =M30+1 -> 2028 | O30: =N30+1 -> 2029 | P30: =O30+1 -> 2030 | Q30: =P30+1 -> 2031 | ... AH30: =AG30+1 -> 2048
B31: Stock-based Compensation | F31: 827 | G31: 1168 | H31: 1793 | I31: =+I32*I9 -> 2621.9633 | J31: =+J32*J9 -> 3146.3559 | K31: =+K32*K9 -> 3618.3093 | L31: =+L32*L9 -> 4161.0557 | M31: =+M32*M9 -> 4577.1613 | N31: =+N32*N9 -> 4989.1058 | O31: =+O32*O9 -> 5438.1253 | P31: =+P32*P9 -> 5873.1753 | ... AH31: =+AH32*AH9 -> 12809.866
B32: % of Sales | C32: =C31/C$9 -> 0 | D32: =D31/D$9 -> 0 | E32: =E31/E$9 -> 0 | F32: =F31/F$9 -> 0.074243648 | G32: =G31/G$9 -> 0.066914924 | H32: =H31/H$9 -> 0.056247451 | I32: =+$H$33 -> 0.065802008 | J32: =+$H$33 -> 0.065802008 | K32: =+$H$33 -> 0.065802008 | L32: =+$H$33 -> 0.065802008 | M32: =+$H$33 -> 0.065802008 | N32: =+$H$33 -> 0.065802008 | O32: =+$H$33 -> 0.065802008 | P32: =+$H$33 -> 0.065802008 | ... AH32: =+$H$33 -> 0.065802008
B33: Target 5y Average | H33: =AVERAGE(F32:H32) -> 0.065802008
B35: Weighted-average interest rate on debt and finance leases
C37: Interest rate
B38: • 3.500% ASML Holding NV Fixed Rate Senior Notes due 2025 (XS2631416950); | C38: 0.035
B39: • 1.375% ASML Holding NV Fixed Rate Senior Notes due 2026 (XS1405780963); | C39: 0.01375
B40: • 1.625% ASML Holding NV Fixed Rate Senior Notes due 2027 (XS1527556192); | C40: 0.01625
B41: • 0.625% ASML Holding NV Fixed Rate Senior Notes due 2029 (XS2166219720); | C41: 0.00625
B42: • 0.250% ASML Holding NV Fixed Rate Senior Notes due 2030 (XS2010032378); and • 2.250% ASML Holding NV Fixed Rate Senior Notes due 2032 (XS2473687106). | C42: 0.0025
C43: =AVERAGE(C38:C42) -> 0.01475
C49: Last 5 Years | I49: Short Term Forecast
C50: 2017 | D50: 2018 | E50: 2019 | F50: 2020 | G50: 2021 | H50: 2022 | I50: 2023 | J50: =I50+1 -> 2024 | K50: =J50+1 -> 2025 | L50: =K50+1 -> 2026 | M50: =L50+1 -> 2027 | N50: =M50+1 -> 2028 | O50: =N50+1 -> 2029 | P50: =O50+1 -> 2030 | Q50: =P50+1 -> 2031 | ... AH50: =AG50+1 -> 2048
B51: CAPEX | C51: =+Inputs!G65 -> 0 | D51: =+Inputs!F65 -> -558 | E51: =+Inputs!E65 -> -588 | F51: =+Inputs!D65 -> -616 | G51: =+Inputs!C65 -> -298 | H51: =+Inputs!B65 -> -252 | I51: =+I52*I9 -> -497.637 | J51: =+J52*J9 -> -597.16439 | K51: =+K52*K9 -> -686.73905 | L51: =+L52*L9 -> -789.74991 | M51: =+M52*M9 -> -868.7249 | N51: =+N52*N9 -> -946.91014 | O51: =+O52*O9 -> -1032.1321 | P51: =+P52*P9 -> -1114.7026 | ... AH51: =+AH52*AH9 -> -6280.4824
B52: % of Sales | C52: =C51/C$9 -> 0 | D52: =D51/D$9 -> -0.053484137 | E52: =E51/E$9 -> -0.045230769 | F52: =F51/F$9 -> -0.055301194 | G52: =G51/G$9 -> -0.017072472 | H52: =H51/H$9 -> -0.0079053863 | I52: =+$H$53 -> -0.012488929 | J52: =+$H$53 -> -0.012488929 | K52: =+$H$53 -> -0.012488929 | L52: =+$H$53 -> -0.012488929 | M52: =+$H$53 -> -0.012488929 | N52: =+$H$53 -> -0.012488929 | O52: =+$H$53 -> -0.012488929 | P52: =+$H$53 -> -0.012488929 | ... R52: =+$H$53 -> -0.012488929 | S52: =+$R$53 -> -0.032261723 | T52: =+$R$53 -> -0.032261723 | U52: =+$R$53 -> -0.032261723 | V52: =+$R$53 -> -0.032261723 | W52: =+$R$53 -> -0.032261723 | X52: =+$R$53 -> -0.032261723 | Y52: =+$R$53 -> -0.032261723 | Z52: =+$R$53 -> -0.032261723 | ... AH52: =+$R$53 -> -0.032261723
B53: Target 5y Average | H53: =AVERAGE(G52:H52) -> -0.012488929 | R53: =+I136 -> -0.032261723 | W53: =AVERAGE(S52:W52) -> -0.032261723 | AB53: =AVERAGE(X52:AB52) -> -0.032261723 | AG53: =AVERAGE(AC52:AG52) -> -0.032261723
C56: Last 5 Years | I56: Short Term Forecast
C57: 2017 | D57: 2018 | E57: 2019 | F57: 2020 | G57: 2021 | H57: 2022 | I57: 2023 | J57: =I57+1 -> 2024 | K57: =J57+1 -> 2025 | L57: =K57+1 -> 2026 | M57: =L57+1 -> 2027 | N57: =M57+1 -> 2028 | O57: =N57+1 -> 2029 | P57: =O57+1 -> 2030 | Q57: =P57+1 -> 2031 | ... AH57: =AG57+1 -> 2048
...

Sheet Fin. Data
A1: =Inputs!H3 -> #VALUE!
A2: =Inputs!G2 -> Figures in Millions of USD
A3: Results
B4: =OP!J17 -> 2022 | C4: =B4-1 -> 2021 | D4: =C4-1 -> 2020 | E4: =D4-1 -> 2019 | F4: =E4-1 -> 2018 | G4: =F4-1 -> 2017 | H4: =G4-1 -> 2016 | I4: =H4-1 -> 2015 | J4: =I4-1 -> 2014 | ... M4: =L4-1 -> 2011
A5: Net Sales | B5: =_xlfn.XLOOKUP($A5,Inputs!$A:$A,Inputs!B:B,,0) -> 31877 | C5: =_xlfn.XLOOKUP($A5,Inputs!$A:$A,Inputs!C:C,,0) -> 17455 | D5: =_xlfn.XLOOKUP($A5,Inputs!$A:$A,Inputs!D:D,,0) -> 11139 | E5: =_xlfn.XLOOKUP($A5,Inputs!$A:$A,Inputs!E:E,,0) -> 13000 | F5: =_xlfn.XLOOKUP($A5,Inputs!$A:$A,Inputs!F:F,,0) -> 10433 | G5: =_xlfn.XLOOKUP($A5,Inputs!$A:$A,Inputs!G:G,,0) -> 7932 | H5: =_xlfn.XLOOKUP($A5,Inputs!$A:$A,Inputs!H:H,,0) -> 0 | I5: =_xlfn.XLOOKUP($A5,Inputs!$A:$A,Inputs!I:I,,0) -> 0 | J5: =_xlfn.XLOOKUP($A5,Inputs!$A:$A,Inputs!J:J,,0) -> 0 | K5: =_xlfn.XLOOKUP($A5,Inputs!$A:$A,Inputs!K:K,,0) -> 0 | L5: =_xlfn.XLOOKUP($A5,Inputs!$A:$A,Inputs!L:L,,0) -> 0 | M5: =_xlfn.XLOOKUP($A5,Inputs!$A:$A,Inputs!M:M,,0) -> 0
A6: Growth vs. Previous year | B6: =IFERROR(B5/C5-1,"-") -> 0.8262389 | C6: =IFERROR(C5/D5-1,"-") -> 0.56701679 | D6: =IFERROR(D5/E5-1,"-") -> -0.14315385 | E6: =IFERROR(E5/F5-1,"-") -> 0.2460462 | F6: =IFERROR(F5/G5-1,"-") -> 0.31530509 | G6: =IFERROR(G5/H5-1,"-") -> - | H6: =IFERROR(H5/I5-1,"-") -> - | I6: =IFERROR(I5/J5-1,"-") -> - | ... L6: =IFERROR(L5/M5-1,"-") -> - | M6: =IFERROR(M5/#REF!-1,"-") -> -
A7: Gross Profit | B7: =_xlfn.XLOOKUP($A7,Inputs!$A:$A,Inputs!B:B,,0) -> 12218 | C7: =_xlfn.XLOOKUP($A7,Inputs!$A:$A,Inputs!C:C,,0) -> 8104 | D7: =_xlfn.XLOOKUP($A7,Inputs!$A:$A,Inputs!D:D,,0) -> 5985 | E7: =_xlfn.XLOOKUP($A7,Inputs!$A:$A,Inputs!E:E,,0) -> 6939 | F7: =_xlfn.XLOOKUP($A7,Inputs!$A:$A,Inputs!F:F,,0) -> 5647 | G7: =_xlfn.XLOOKUP($A7,Inputs!$A:$A,Inputs!G:G,,0) -> 3772 | H7: =_xlfn.XLOOKUP($A7,Inputs!$A:$A,Inputs!H:H,,0) -> 0 | I7: =_xlfn.XLOOKUP($A7,Inputs!$A:$A,Inputs!I:I,,0) -> 0 | J7: =_xlfn.XLOOKUP($A7,Inputs!$A:$A,Inputs!J:J,,0) -> 0 | K7: =_xlfn.XLOOKUP($A7,Inputs!$A:$A,Inputs!K:K,,0) -> 0 | L7: =_xlfn.XLOOKUP($A7,Inputs!$A:$A,Inputs!L:L,,0) -> 0 | M7: =_xlfn.XLOOKUP($A7,Inputs!$A:$A,Inputs!M:M,,0) -> 0
A8: % over sales | B8: =IFERROR(B7/B$5,"-") -> 0.38328575 | C8: =IFERROR(C7/C$5,"-") -> 0.46427958 | D8: =IFERROR(D7/D$5,"-") -> 0.53730137 | E8: =IFERROR(E7/E$5,"-") -> 0.53376923 | F8: =IFERROR(F7/F$5,"-") -> 0.5412633 | G8: =IFERROR(G7/G$5,"-") -> 0.47554211 | H8: =IFERROR(H7/H$5,"-") -> - | I8: =IFERROR(I7/I$5,"-") -> - | ... M8: =IFERROR(M7/M$5,"-") -> -
