Workbook
Name Sectors: '[1]Sector Impact'!$K$4:$K$16
Name Sectors: '[2]Sector Impact'!$K$4:$K$16
Name Sectors: '[2]Sector Impact'!$K$4:$K$16
Name Sectors: 'Sector Impact'!$K$4:$K$16

Sheet OP
B2: 45039 | C2: Team 1 | E2: =Inputs!H3 -> SALESFORCE, INC. (XNYS:CRM) | L2: NYSE | M2: SIC:
B3: Logo | D3: COMPANY DESCRIPTION | H3: CEO & BOARD OF DIRECTORS
D4: {=_FV(Inputs!H3,"Description")} -> #VALUE! | H4: Name | I4: Gender | J4: Age | K4: Tenure | L4: Executive? | M4: Other roles
H5: Marc Benioff | I5: Male | J5: 58 | K5: 2000 | L5: Yes | M5: Chair, Chief Executive Officer & Co-Founder
H6: Laura Alber | I6: Female | J6: 54 | K6: 2021 | L6: No | M6: President & CEO, Williams-Sonoma, Inc.
H7: Craig Conway | I7: Male | J7: 68 | K7: 2005 | L7: No | M7: Former President & CEO, PeopleSoft, Inc.
H8: Arnold Donald | I8: Male | J8: 68 | K8: 2023 | L8: No | M8: Former President & CEO, Carnival Corporation & plc
H9: Parker Harris | I9: Male | J9: 56 | K9: 2018 | L9: No | M9: Chief Technology Officer & Co-Founder
H10: Neelie Kroes | I10: Female | J10: 81 | K10: 2016 | L10: No | M10: Former Vice President of the European Commission
H11: Sachin Mehra | I11: Male | J11: 52 | K11: 2023 | L11: No | M11: Financial Expert Chief Financial Officer, Mastercard
H12: G. Mason Morfit | I12: Male | J12: 47 | K12: 2023 | L12: No | M12: CEO & Chief Investment Officer, ValueAct Capital
H13: Oscar Munoz | I13: Male | J13: 64 | K13: 2022 | L13: No | M13: Former Executive Chair & CEO, United Airlines Holdings, Inc.
H14: John V. Roos | I14: Male | J14: 68 | K14: 2013 | L14: No | M14: Former U.S. Ambassador to Japan; Co-Founder, Geodesic Capita
H15: Robin Washington | I15: Female | J15: 60 | K15: 2013 | L15: No | M15: Lead Independent Director & Financial Expert Former EVP & CFO, Gilead Sciences, Inc.
H16: Maynard Webb | I16: Male | J16: 67 | K16: 2006 | L16: No | M16: Founder, Webb Investment Network
B17: USD MILLIONS | H17: Susan Wojcicki | I17: Female | J17: 54 | K17: 2014 | L17: No | M17: Former CEO, YouTube
B18: COMPANY OVERVIEW
B19: Stock | D19: Liquidity and Solvency | F19: Segments | I19: Profitability (2022) | L19: Multiples
B20: Last Price | C20: {=+_FV(Inputs!H3,"price")} -> #VALUE! | D20: Total Assets | E20: =_xlfn.XLOOKUP(D20,'Fin. Data'!A:A,'Fin. Data'!B:B,,0) -> 98849 | F20: Regions | H20: % Sales | I20: Reporting Year | J20: 2022 | L20: Float | M20: =943.57/973 -> 0.96975334
B21: Outstanding Shares | C21: {=_FV(E2,"Shares outstanding",TRUE)} -> #VALUE! | D21: Total Liabilities | E21: =_xlfn.XLOOKUP(D21,'Fin. Data'!A:A,'Fin. Data'!B:B,,0) -> 40490 | F21: =Segments!C5 -> Americas | H21: =Segments!B5 -> 0.6788087 | I21: End of Year | J21: 44957 | L21: Insiders Own | M21: 0.0317
B22: Market Cap. | C22: =C20*C21/1000000 -> #VALUE! | D22: Cash/Share | E22: =_xlfn.XLOOKUP("Cash & Eq.",'Fin. Data'!A:A,'Fin. Data'!B:B,,0)*1000000/C21 -> #VALUE! | F22: =Segments!C6 -> Europe | H22: =Segments!B6 -> 0.22708742 | I22: EBITDA | K22: =_xlfn.XLOOKUP(I22,'Fin. Data'!A:A,'Fin. Data'!B:B,,0) -> 4685 | L22: b (Yahoo) | M22: 1.19
B23: +Total Debt | C23: ='Fin. Data'!B58 -> 11392 | D23: EBITDA/Net Financial Cost (NFC) | E23: =_xlfn.XLOOKUP("EBITDA",'Fin. Data'!A:A,'Fin. Data'!B:B,,0)/_xlfn.XLOOKUP("Net Financial Cost",'Fin. Data'!A:A,'Fin. Data'!B:B,,0) -> -35.763359 | F23: =Segments!C7 -> Asia Pacific | H23: =Segments!B7 -> 0.09410388 | I23: Depreciation & Amortization | K23: =_xlfn.XLOOKUP(I23,'Fin. Data'!A:A,'Fin. Data'!B:B,,0) -> 3786 | L23: Score (S&P) | M23: A+
B24: -Cash | C24: ='Fin. Data'!B39 -> 12508 | D24: Debt/EBITDA | E24: =_xlfn.XLOOKUP("Total Debt",'Fin. Data'!A:A,'Fin. Data'!B:B,,0)/_xlfn.XLOOKUP("EBITDA",'Fin. Data'!A:A,'Fin. Data'!B:B,,0) -> 2.4315902 | I24: EBIT | K24: =_xlfn.XLOOKUP(I24,'Fin. Data'!A:A,'Fin. Data'!B:B,,0) -> 899 | L24: Price/Book Value | M24: =IFERROR((C20*C21/(E20-E21))/1000000,"")
B25: =Enterprise Value | C25: =C22+C23-C24 -> #VALUE! | D25: "Others Assets"/Asset | E25: =_xlfn.XLOOKUP("Other Assets",'Fin. Data'!A:A,'Fin. Data'!B:B,,0)/_xlfn.XLOOKUP("Total Assets",'Fin. Data'!A:A,'Fin. Data'!B:B,,0) -> 0.1594351 | I25: Net Income | K25: =_xlfn.XLOOKUP(I25,'Fin. Data'!A:A,'Fin. Data'!B:B,,0) -> 208 | L25: NCF(3y avg)/Asset | M25: =IFERROR(K31/E20,"") -> 0.019302168
B26: Holdings (nac/int'l) | C26: - | D26: Debt/Assets | E26: =_xlfn.XLOOKUP(D26,'Fin. Data'!A:A,'Fin. Data'!B:B,,0) -> 0.11524649 | F26: Categories | H26: % Sales | I26: EPS | K26: =1000000*K25/C21 -> #VALUE! | L26: Price/Net Inc. (3y avg) | M26: =IFERROR(C22/K30,"")
B27: t liq. (Holdings/Vol.) | C27: - | D27: EBITDA Margin (average) | E27: =AVERAGE(_xlfn.XLOOKUP("EBITDA Margin",'Fin. Data'!A:A,'Fin. Data'!B:D,,0)) -> 0.13670732 | F27: =+Segments!C15 -> Professional services and other | H27: =+Segments!B15 -> 0.069266194 | I27: ROA | K27: =K25/E20 -> 0.0021042196 | L27: EV/Asset | M27: =IFERROR(C25/E20,"")
B28: % Short of float | C28: 0.0079 | D28: Operating Margin (average) | E28: =AVERAGE(_xlfn.XLOOKUP("Operating Margin",'Fin. Data'!A:A,'Fin. Data'!B:D,,0)) -> 0.024982669 | F28: =+Segments!C16 -> Subscription and Support | H28: =+Segments!B16 -> 0.93073381 | I28: ROIC | K28: =K25/(E20-(E21-C23)) -> 0.0029820361 | L28: EV/Ebitda (3y average) | M28: =IFERROR(C25/K29,"")
B29: Traffic ESG | D29: Net Income Margin (average) | E29: =AVERAGE(_xlfn.XLOOKUP("Net Income Margin",'Fin. Data'!A:A,'Fin. Data'!B:D,,0)) -> 0.084248954 | I29: EBITDA (3y average) | K29: =AVERAGE(_xlfn.XLOOKUP("EBITDA",'Fin. Data'!A:A,'Fin. Data'!B:D,,0)) -> 3647 | L29: Price/NCF (3y average) | M29: =IFERROR(C22/K31,"")
B30: E | I30: Net Income (3y average) | K30: =AVERAGE(_xlfn.XLOOKUP("Net Income",'Fin. Data'!A:A,'Fin. Data'!B:D,,0)) -> 1908 | L30: Bonds 1,3,5a (USD) | M30: -
B31: S | D31: Net Financial Cost/Avg Net Debt | E31: =-_xlfn.XLOOKUP("Net Financial Cost",'Fin. Data'!A:A,'Fin. Data'!B:B,,0)/AVERAGE(_xlfn.XLOOKUP("Net Debt",'Fin. Data'!A:A,'Fin. Data'!B:D,,0)) -> -0.039934966 | I31: NCF (3y average) | K31: =AVERAGE(_xlfn.XLOOKUP("Net Income",'Fin. Data'!A:A,'Fin. Data'!B:D,,0)) -> 1908 | L31: Div+Rep.(3y avg)/Price | M31: =-IFERROR(SUM(E52:E54)/(3*C22),"") -> #VALUE!
B32: G | L32: Div. Yield | M32: =-IFERROR(L53/C22,"") -> #VALUE!
B33: INVESTMENT THESIS
B34: Pillars of Recommendation | H34: Recommendation | I34: Valuation Assumptions
B35: Pillar | C35: Explanation | H35: HOLD | I35: * Salesforce will start distributing dividends in 2025. * Debt/equity will decrease over time * Revenue growth reducing over time * Net working capital estimated through DPO and DSO
B36: High Discount Rate | C36: Higher discount rate lowers the present value of future earnings for stocks. When this occurs, stock prices tend to face downward pressure, as it is the current case for Salesforce
B37: Loyal Costumers | C37: They work with over 150,000 businesses of all sizes and their subscription services account for around 93% of total revenues. Sticky customers are an industry characteristic,
B38: Indusstry Potential Growth | C38: The growing use of digital channels by customers to communicate with brands and organizations is estimated to boost the customer relationship management (CRM) market growth over the forecast period
B39: Risks of Investment | H39: Price Target | I39: Valuation
B40: Risk | C40: Explanation | H40: =DCF!D76 -> #VALUE! | I40: Discount Rate | L40: =DCF!F50 -> 0.106
B41: Partnership dependence | C41: Partnerships are a key strength for Salesforce, the company depends on these partnerships to deliver certain features and services
...

Sheet Segments
B2: ="Regions "&"("&OP!$J$20&")" -> Regions (2022) | Q2: Products
D3: Nominal value | K3: YoY Growth
B4: Weight | C4: Region | D4: =OP!J20 -> 2022 | E4: =D4-1 -> 2021 | F4: =E4-1 -> 2020 | G4: =F4-1 -> 2019 | H4: =G4-1 -> 2018 | I4: =H4-1 -> 2017 | K4: =OP!J20 -> 2022 | L4: =K4-1 -> 2021 | M4: =L4-1 -> 2020 | N4: =M4-1 -> 2019 | O4: =N4-1 -> 2018 | P4: =O4-1 -> 2017
B5: =IFERROR(D5/$D$10,"") -> 0.6788087 | C5: Americas | D5: 17983 | E5: 14736 | F5: 12051 | G5: 9445 | H5: 7621 | I5: 6259 | K5: =(D5-E5)/E5 -> 0.22034473 | L5: =(E5-F5)/F5 -> 0.22280309 | M5: =(F5-G5)/G5 -> 0.27591318 | N5: =(G5-H5)/H5 -> 0.23933867 | O5: =(H5-I5)/I5 -> 0.21760665 | P5: -
B6: =IFERROR(D6/$D$10,"") -> 0.22708742 | C6: Europe | D6: 6016 | E6: 4501 | F6: 3430 | G6: 2553 | H6: 1916 | I6: 1383 | K6: =(D6-E6)/E6 -> 0.33659187 | L6: =(E6-F6)/F6 -> 0.3122449 | M6: =(F6-G6)/G6 -> 0.34351743 | N6: =(G6-H6)/H6 -> 0.33246347 | O6: =(H6-I6)/I6 -> 0.38539407 | P6: -
B7: =IFERROR(D7/$D$10,"") -> 0.09410388 | C7: Asia Pacific | D7: 2493 | E7: 2015 | F7: 1617 | G7: 1284 | H7: 1003 | I7: 795 | K7: =(D7-E7)/E7 -> 0.23722084 | L7: =(E7-F7)/F7 -> 0.24613482 | M7: =(F7-G7)/G7 -> 0.25934579 | N7: =(G7-H7)/H7 -> 0.28015952 | O7: =(H7-I7)/I7 -> 0.26163522 | P7: -
B8: =IFERROR(D8/$D$10,"") -> 0
B9: =IFERROR(D9/$D$10,"") -> 0
B10: =SUM(B5:B9) -> 1 | C10: TOTAL | D10: =SUM(D5:D9) -> 26492 | E10: =SUM(E5:E9) -> 21252 | F10: =SUM(F5:F9) -> 17098 | G10: =SUM(G5:G9) -> 13282 | H10: =SUM(H5:H9) -> 10540 | I10: =SUM(I5:I9) -> 8437 | K10: =(D10-E10)/E10 -> 0.24656503 | L10: =(E10-F10)/F10 -> 0.24295239 | M10: =(F10-G10)/G10 -> 0.28730613 | N10: =(G10-H10)/H10 -> 0.2601518 | O10: =(H10-I10)/I10 -> 0.24925922 | P10: -
B12: ="Categories "&"("&OP!$J$20&")" -> Categories (2022)
D13: Nominal value | K13: YoY Growth
B14: Weight | C14: Category | D14: =OP!J20 -> 2022 | E14: =D14-1 -> 2021 | F14: =E14-1 -> 2020 | G14: =F14-1 -> 2019 | H14: =G14-1 -> 2018 | I14: =H14-1 -> 2017 | K14: =OP!J20 -> 2022 | L14: =K14-1 -> 2021 | M14: =L14-1 -> 2020 | N14: =M14-1 -> 2019 | O14: =N14-1 -> 2018 | P14: =O14-1 -> 2017
B15: =IFERROR(D15/$D$17,"") -> 0.069266194 | C15: Professional services and other | D15: 1835 | E15: 1276 | F15: 1055 | G15: 869 | H15: 774 | I15: 638 | K15: =(D15-E15)/E15 -> 0.43808777 | L15: =(E15-G15)/G15 -> 0.46835443 | M15: =(G15-#REF!)/#REF! -> #REF! | N15: =(#REF!-H15)/H15 -> #REF! | O15: =(H15-I15)/I15 -> 0.21316614 | P15: -
B16: =IFERROR(D16/$D$17,"") -> 0.93073381 | C16: Subscription and Support | D16: 24657 | E16: 19976 | F16: 16043 | G16: 12413 | H16: 9766 | I16: 7799 | K16: =(D16-E16)/E16 -> 0.2343312 | L16: =(E16-F16)/F16 -> 0.24515365 | M16: =(F16-G16)/G16 -> 0.29243535 | N16: =(G16-H16)/H16 -> 0.27104239 | O16: =(H16-I16)/I16 -> 0.25221182 | P16: -
B17: =SUM(B15:B16) -> 1 | C17: TOTAL | D17: =SUM(D15:D16) -> 26492 | E17: =SUM(E15:E16) -> 21252 | F17: =SUM(F15:F16) -> 17098 | G17: =SUM(G15:G16) -> 13282 | H17: =SUM(H15:H16) -> 10540 | I17: =SUM(I15:I16) -> 8437 | K17: =(D17-E17)/E17 -> 0.24656503 | L17: =(E17-F17)/F17 -> 0.24295239 | M17: =(F17-G17)/G17 -> 0.28730613 | N17: =(G17-H17)/H17 -> 0.2601518 | O17: =(H17-I17)/I17 -> 0.24925922 | P17: -
B19: Categories | D19: Description | I19: Graphs
B20: Professional services and other | D20: This segment is category of offerings and activities that are distinct from the core software products provided by Salesforce. This segment encompasses a range of specialized services and solutions that are tailored to meet specific business needs and requirements
B21: Subscription and Support | D21: Subscription and support revenues include subscription fees from customers accessing the enterprise cloud computing services (collectively, “Cloud Services”), software license revenues from the sales of term and perpetual licenses, and support revenues from the sale of support and updates beyond the basic subscription fees or related to the sales of software licenses. Cloud Services allow customers to use the multi-tenant software without taking possession of the software.
B24: Industry | J24: Graphs (Industry Forecasts)
B25: Drivers | D25: Description
B26: Innovative Technology and Product Expansion | D26: Salesforce is recognized as a trailblazer in the realm of cloud computing, offering cutting-edge CRM (Customer Relationship Management) solutions. By leveraging this technology, businesses not only benefit from enhanced scalability and accessibility, but also experience a reduction in the necessity for on-premise infrastructure and associated maintenance costs. The commitment to continuous innovation is a hallmark of Salesforce. Substantial investments in research and development ensure that their platform remains at the forefront of technological advancements. This includes the integration of artificial intelligence (AI), machine learning, Internet of Things (IoT), and other emerging technologies. Furthermore, strategic acquisitions such as Tableau and MuleSoft have expanded Salesforce's capabilities in the realms of data analytics and integration, thereby augmenting its overall value proposition.
B27: Prioritize Customer-Centricity | D27: The Customer Success Platform offered by Salesforce positions itself as a platform that prioritizes the needs and satisfaction of customers. Its primary objective is to assist businesses in establishing and maintaining strong relationships with their customers. This is accomplished through the utilization of a variety of tools and features that facilitate personalized communication, automate sales processes, and enhance customer support. One of the key features of Salesforce is its ability to provide companies with a comprehensive view of their customers. By consolidating data from various touchpoints, businesses are able to gain a holistic understanding of their customers. This, in turn, enables them to implement more personalized marketing strategies, streamline sales processes, and enhance the overall customer service experience. In addition to its platform, Salesforce boasts a thriving community of users, developers, and administrators. These individuals actively engage in forums, share their knowledge, and contribute to a vast array of resources. Furthermore, Salesforce offers extensive training and certification programs, empowering both individuals and companies to fully maximize the potential of the platform.
B28: Sales forecast
B29: Source | D29: Market Growth CAGR | G29: Period
B30: https://www.statista.com/outlook/tmo/software/europe | D30: 0.062 | G30: 2023-2028
B31: https://www.grandviewresearch.com/industry-analysis/software-market-report | D31: 0.151 | G31: 2023-2030
B32: https://www.grandviewresearch.com/industry-analysis/sales-force-automation-software-market | D32: 0.087 | G32: 2023-2030
D33: 0.1
B34: Company's Strategy / Extra Notes

Sheet Acuerdo
A1: Invertir
A2: NO invertir
A3: Mantener sin elevar posición
A4: Mantener (y seguir comprando)
A5: Liquidar
A6: PENDIENTE

Sheet Peers
B1: Peer Logo | C1: Peer Name | D1: Description
C2: #VALUE! | D2: {=_FV(C2,"Descrição")} -> A MICROSOFT CORPORATION é uma empresa de tecnologia. A Empresa desenvolve, licencia e oferece suporte a uma gama de produtos de software, serviços e dispositivos. Seus segmentos são Produtividade e Processos de Negócio, Nuvem Inteligente e Outras Soluções de Computação Pessoal. Seus produtos incluem sistemas operacionais; aplicativos de produtividade de dispositivos cruzados; aplicativos de servidor; aplicativos de soluções de negócio; ferramentas de gerenciamento de desktop e servidor; ferramentas de desenvolvimento de software; videojogos, e treinamento e certificação de integradores e desenvolvedores de sistemas de computador. Ela também projeta, fabrica e vende dispositivos, incluindo computadores pessoais, tablets, consoles para jogos e entretenimento, telefones, outros dispositivos inteligentes e acessórios relacionados, que se integram com suas ofertas baseadas em nuvem. Ela oferece uma variedade de serviços, incluindo soluções baseadas em nuvem, que fornecem aos clientes software, serviços, plataformas e conteúdo, além de oferecer serviços de suporte e consultoria de soluções. Ela também oferece publicidade online.
C3: #VALUE! | D3: {=_FV(C3,"Descrição")} -> A SAP SE (SAP) é uma empresa sediada na Alemanha que oferece software de aplicativos corporativos. A Companhia opera em três segmentos: segmento de Aplicativos, Tecnologia e Serviços, que atua na venda de licenças de software, assinaturas de seus aplicativos na nuvem e serviços relacionados, principalmente serviços de suporte e vários serviços profissionais e serviços de suporte, além de serviços de implementação de seus produtos de software e serviços de educação sobre o uso de seus produtos; o segmento SAP Business Network, que inclui suas redes e serviços de negócios colaborativos baseados na nuvem relacionados ao SAP Business Network, incluindo aplicativos em nuvem, serviços profissionais e serviços educacionais, bem como o mercado da Empresa e vende as ofertas em nuvem desenvolvidas pela SAP Ariba, SAP Fieldglass e Concur e o segmento Customer Experience, que inclui produtos locais e baseados em nuvem que executam funções de front office em toda a experiência do cliente.
C4: #VALUE! | D4: {=_FV(C4,"Descrição")} -> A Oracle Corporation (Oracle) fornece produtos e serviços que atendem a ambientes de tecnologia da informação empresarial. Os negócios da Empresa incluem nuvem e licença, hardware e serviços. Seus produtos e serviços incluem aplicativos e ofertas de infraestrutura que são entregues por meio de uma variedade de modelos de implantação de TI. Seus clientes incluem agências governamentais, instituições educacionais e revendedores. Usando as tecnologias Oracle, seus clientes criam, implantam, executam, gerenciam e dão suporte a seus produtos, serviços e operações comerciais internos e externos. Suas ofertas de Oracle Cloud Services incluem Oracle Software as a Service (SaaS) e infraestrutura Oracle como serviço (IaaS), que fornece uma pilha de aplicativos e serviços de infraestrutura fornecidos por meio de modelos de implantação baseados em nuvem. O Oracle Cloud Services integra o software, hardware e serviços em nome do cliente em um ambiente de TI baseado em nuvem.
C5: #VALUE! | D5: {=_FV(C5,"Descrição")} -> A Adobe Systems Incorporated fornece software de design gráfico, publicação e imagem para impressão, Web e produção de vídeo. Seus clientes incluem profissionais criativos, como designers gráficos, web designers, cinegrafistas, fotógrafos e editores profissionais, usuários corporativos, como gerentes de tecnologia da informação (TI), a linha de gerentes e executivos de negócios e consumidores, como entusiastas e entusiastas de imagem digital e vídeo digital. A Abode categoriza seus produtos em quatro segmentos de negócios: Imagem e Vídeo Digital, Creative Professional, Documentos Inteligentes e Original Equipment Manufacturers (OEM) PostScript e Outros. Em 3 de dezembro de 2005, a Companhia concluiu a aquisição da Macromedia, Inc. Em 21 de abril de 2006, a empresa adquiriu a Trade and Technologies France. Em outubro de 2006, a Companhia adquiriu a Serious Magic Inc., fabricante de software de vídeo para os mercados de negócios, consumo e educação.
C6: #VALUE! | D6: {=_FV(C6,"Descrição")} -> A Zendesk, Inc. é uma empresa de desenvolvimento de software que fornece soluções de software como serviço (SaaS). A Companhia oferece uma variedade de soluções de produtos, que incluem os Zendesk Support, Zendesk Chat, Zendesk Talk, Zendesk Guide, Zendesk Gather, Zendesk Explore, Zendesk Sell e Zendesk Apps. O Zendesk Support é um sistema para rastrear, priorizar e resolver tíquetes de suporte ao cliente em vários canais. O Zendesk Chat é um software de chat e mensagens ao vivo. O Zendesk Talk é um software de call center baseado em nuvem. O Zendesk Guide é uma base de conhecimento que potencializa o autoatendimento do cliente e a produtividade do agente de suporte. O Zendesk Gather é um software de fórum da comunidade. O Zendesk Explore fornece análises para que organizações avaliem e melhorem toda a experiência do cliente. O Zendesk Sell é uma solução de produto de gerenciamento de relacionamento com o cliente (GRC) de vendas. As plataformas da Companhia incluem as Zendesk Sunshine, Sunshine Conversations, Zendesk Sunshine Developer Tools, Zendesk Apps, Zendesk API e outros.
B8: In Millions USD (exc Market Cap) | C8: =OP!E2 -> SALESFORCE, INC. (XNYS:CRM) | D8: =C2 -> #VALUE! | E8: =C3 -> #VALUE! | F8: =C4 -> #VALUE! | G8: =C5 -> #VALUE! | H8: =C6 -> #VALUE! | I8: AVERAGE | J8: Deviation from Average
B9: Company Info | I9: =IFERROR(AVERAGE(C9:H9),"") | L9: TRAFFIC
B10: Market Cap | C10: =OP!C22 -> #VALUE! | D10: 2350000 | E10: 150000 | F10: 295000 | G10: 234000 | H10: 9625 | I10: =IFERROR(AVERAGE(C10:H10),"") | J10: =SQRT((C10-I10)^2) -> #VALUE! | M10: Best Value
B11: Net Sales (current) | C11: =C56 -> 31352 | D11: =D56 -> 198270 | E11: =E56 -> 32974 | F11: =F56 -> 42440 | G11: =G56 -> 17430 | H11: =H56 -> 1.587 | I11: =IFERROR(AVERAGE(C11:H11),"") -> 53744.598 | J11: =SQRT((C11-I11)^2) -> 22392.598
B12: Profitability | I12: =IFERROR(AVERAGE(C12:H12),"") | M12: Middle Ground
B13: Sales Growth (ttm) | C13: =C56/C55-1 -> 0.18345161 | D13: =D56/D55-1 -> 0.17956071 | E13: =E56/E55-1 -> 0.041437686 | F13: =F56/F55-1 -> 0.048444873 | G13: =G56/G55-1 -> 0.10316456 | H13: =H56/H55-1 -> 0.19323308 | I13: =IFERROR(AVERAGE(C13:H13),"") -> 0.12488209 | J13: =SQRT((C13-I13)^2) -> 0.058569523
B14: Sales Growth (36m) | C14: =C56/C54-1 -> 0.83366476 | D14: =D56/D54-1 -> 0.38635807 | E14: =E56/E54-1 -> -0.014230194 | F14: =F56/F54-1 -> 0.086311047 | G14: =G56/G54-1 -> 0.35431235 | H14: =H56/H54-1 -> 0.54227405 | I14: =IFERROR(AVERAGE(C14:H14),"") -> 0.36478168 | J14: =SQRT((C14-I14)^2) -> 0.46888307 | M14: Worst Value
B15: Operating Margin | C15: =C59/C56 -> 0.032852769 | D15: =D59/D56 -> 0.42055278 | E15: =E59/E56 -> 0.15114939 | F15: =F59/F56 -> 0.30850613 | G15: =G59/G56 -> 0.33964429 | H15: =H59/H56 -> -0.16131065 | I15: =IFERROR(AVERAGE(C15:H15),"") -> 0.18189912 | J15: =SQRT((C15-I15)^2) -> 0.14904635
B16: Net Income Margin | C16: =C62/C56 -> 0.0066343455 | D16: =D62/D56 -> 0.36686337 | E16: =E62/E56 -> 0.055285983 | F16: =F62/F56 -> 0.20035344 | G16: =G62/G56 -> 0.2761331 | H16: =H62/H56 -> -0.17769376 | I16: =IFERROR(AVERAGE(C16:H16),"") -> 0.12126275 | J16: =SQRT((C16-I16)^2) -> 0.1146284
B17: Return on Equity (RoE) | C17: =C62/C74 -> 0.0035641461 | D17: =D62/D74 -> 0.43675469 | E17: =E62/E74 -> 0.042505071 | F17: =F62/F74 -> 7.9245107 | G17: =G62/G74 -> 0.3425379 | H17: =H62/H74 -> -0.58506224 | I17: =IFERROR(AVERAGE(C17:H17),"") -> 1.3608017 | J17: =SQRT((C17-I17)^2) -> 1.3572376
B18: Return on Invested Capital (ROIC) | C18: =(C62+C61)/(C73+C74) -> 0.0094622299 | D18: =(D62+D61)/(D73+D74) -> 0.22945949 | E18: =(E62+E61)/(E73+E74) -> 0.042824495 | F18: =(F62+F61)/(F73+F74) -> 0.067910376 | G18: =(G62+G61)/(G73+G74) -> 0.31893599 | H18: =(H62+H61)/(H73+H74) -> -0.11179111 | I18: =IFERROR(AVERAGE(C18:H18),"") -> 0.092800245 | J18: =SQRT((C18-I18)^2) -> 0.083338015
B19: Solvency | I19: =IFERROR(AVERAGE(C19:H19),"")
B20: Debt/Assets | C20: =C73/C70 -> 0.11524649 | D20: =D73/D70 -> 0.54352045 | E20: =E73/E70 -> 0.44308679 | F20: =F73/F70 -> 0.99201536 | G20: =G73/G70 -> 0.17055034 | H20: =H73/H70 -> 0.80334557 | I20: =IFERROR(AVERAGE(C20:H20),"") -> 0.51129417 | J20: =SQRT((C20-I20)^2) -> 0.39604768
B21: Net Debt/EBITDA | C21: =(C73-C65)/C58 -> -0.23820704 | D21: =(D73-D65)/D58 -> 1.8779233 | E21: =(E73-E65)/E58 -> 3.193355 | F21: =(F73-F65)/F58 -> 5.9729441 | G21: =(G73-G65)/G58 -> -0.33562744 | H21: =(H73-H65)/H58 -> -13.45045 | I21: =IFERROR(AVERAGE(C21:H21),"") -> -0.49667707 | J21: =SQRT((C21-I21)^2) -> 0.25847003
B22: Interest Coverage Ratio | C22: =-C58/C60 -> 35.763359 | D22: =-D58/D60 -> -47.588948 | E22: =-E58/E60 -> -3.2617935 | F22: =-F58/F60 -> -5.3463623 | G22: =-G58/G60 -> -38.919643 | H22: =-H58/H60 -> -0.43359375 | I22: =IFERROR(AVERAGE(C22:H22),"") -> -9.964497 | J22: =SQRT((C22-I22)^2) -> 45.727856
B23: Liquidity
B24: Current Ratio | C24: =C68/C72 -> 1.0194662 | D24: =D68/D72 -> 1.784607 | E24: =E68/E72 -> 1.0075697 | F24: =F68/F72 -> 0.90965786 | G24: =G68/G72 -> 1.1067913 | H24: =H68/H72 -> 1.5565313 | I24: =IFERROR(AVERAGE(C24:H24),"") -> 1.2307706 | J24: =SQRT((C24-I24)^2) -> 0.21130433
B25: Quick Ratio | C25: =(C65+C66)/C72 -> 0.96709281 | D25: =(D65+D66)/D72 -> 0.6120191 | E25: =(E65+E66)/E72 -> 0.88983733 | F25: =(F65+F66)/F72 -> 1.2255522 | G25: =(G65+G66)/G72 -> 1.00406 | H25: =(H65+H66)/H72 -> 0.82217344 | I25: =IFERROR(AVERAGE(C25:H25),"") -> 0.92012248 | J25: =SQRT((C25-I25)^2) -> 0.046970328
B26: Activity | I26: =IFERROR(AVERAGE(C26:H26),"")
B27: Inventory Turnover | C27: =IFERROR(C57/C67,"No Inventory") -> No Inventory | D27: =IFERROR(D57/D67,"No Inventory") -> 16.742384 | E27: =IFERROR(E57/E67,"No Inventory") -> No Inventory | F27: =IFERROR(F57/F67,"No Inventory") -> No Inventory | G27: =IFERROR(G57/G67,"No Inventory") -> No Inventory | H27: =IFERROR(H57/H67,"No Inventory") -> No Inventory | I27: =IFERROR(AVERAGE(C27:H27),"") -> 16.742384 | J27: =SQRT((C27-I27)^2) -> #VALUE!
B28: Acc. Receivable Turnover | C28: =C56/C66 -> 2.5019552 | D28: =D56/D66 -> 4.4795644 | E28: =E56/E66 -> 4.7369631 | F28: =F56/F66 -> 6.1373825 | G28: =G56/G66 -> 8.440678 | H28: =H56/H66 -> 5.8131868 | I28: =IFERROR(AVERAGE(C28:H28),"") -> 5.3516217 | J28: =SQRT((C28-I28)^2) -> 2.8496665
A29: Price/Sales | B29: Payables Turnover | C29: =C57/C71 -> #DIV/0! | D29: =D57/D71 -> 1.8575071 | E29: =E57/E71 -> 3.4475309 | F29: =F57/F71 -> 4.1645686 | G29: =G57/G71 -> #DIV/0! | H29: =H57/H71 -> 0 | I29: =IFERROR(AVERAGE(C29:H29),"") | J29: =SQRT((C29-I29)^2) -> #DIV/0!
B30: Fixed Asset Turnover | C30: =C56/C69 -> 4.756068 | D30: =D56/D69 -> 1.0159565 | E30: =E56/E69 -> 0.57600531 | F30: =F56/F69 -> 0.37431646 | G30: =G56/G69 -> 0.95932633 | H30: =H56/H69 -> 1.5377907 | I30: =IFERROR(AVERAGE(C30:H30),"") -> 1.5365772 | J30: =SQRT((C30-I30)^2) -> 3.2194908
B31: Total Asset Turnover | C31: =C56/C70 -> 0.31717063 | D31: =D56/D70 -> 0.5434437 | E31: =E56/E70 -> 0.42816704 | F31: =F56/F70 -> 0.31581376 | G31: =G56/G70 -> 0.64163446 | H31: =H56/H70 -> 0.64749082 | I31: =IFERROR(AVERAGE(C31:H31),"") -> 0.48228673 | J31: =SQRT((C31-I31)^2) -> 0.1651161
B32: Valuation | I32: =IFERROR(AVERAGE(C32:H32),"")
B33: Price/Earnings | C33: =C10/C62 -> #VALUE! | D33: =D10/D62 -> 32.307735 | E33: =E10/E62 -> 82.281953 | F33: =F10/F62 -> 34.693638 | G33: =G10/G62 -> 48.618325 | H33: =H10/H62 -> -34131.206 | I33: =IFERROR(AVERAGE(C33:H33),"") | J33: =SQRT((C33-I33)^2) -> #VALUE!
B34: Price/Sales | C34: =C10/C56 -> #VALUE! | D34: =D10/D56 -> 11.852524 | E34: =E10/E56 -> 4.5490386 | F34: =F10/F56 -> 6.9509896 | G34: =G10/G56 -> 13.425129 | H34: =H10/H56 -> 6064.9023 | I34: =IFERROR(AVERAGE(C34:H34),"") | J34: =SQRT((C34-I34)^2) -> #VALUE!
B35: Price/Book | C35: =C10/C74 -> #VALUE! | D35: =D10/D74 -> 14.110555 | E35: =E10/E74 -> 3.4974003 | F35: =F10/F74 -> 274.9301 | G35: =G10/G74 -> 16.653619 | H35: =H10/H74 -> 19968.88 | I35: =IFERROR(AVERAGE(C35:H35),"") | J35: =SQRT((C35-I35)^2) -> #VALUE!
B36: EV/Sales | C36: =(C73+C10-C65)/C56 -> #VALUE! | D36: =(D73+D10-D65)/D56 -> 12.782403 | E36: =(E73+E10-E65)/E56 -> 5.2923212 | F36: =(F73+F10-F65)/F56 -> 9.5882893 | G36: =(G73+G10-G65)/G56 -> 13.341193 | H36: =(H73+H10-H65)/H56 -> 6065.8431 | I36: =IFERROR(AVERAGE(C36:H36),"") | J36: =SQRT((C36-I36)^2) -> #VALUE!
B37: EV/EBITDA | C37: =(C73+C10-C65)/C58 -> #VALUE! | D37: =(D73+D10-D65)/D58 -> 25.814527 | E37: =(E73+E10-E65)/E58 -> 22.737329 | F37: =(F73+F10-F65)/F58 -> 21.715513 | G37: =(G73+G10-G65)/G58 -> 53.34641 | H37: =(H73+H10-H65)/H58 -> -86725.162 | I37: =IFERROR(AVERAGE(C37:H37),"") | J37: =SQRT((C37-I37)^2) -> #VALUE!
B38: Stock Info | I38: =IFERROR(AVERAGE(C38:H38),"")
B39: Float | C39: =OP!M20 -> 0.96975334 | D39: =7.42/7.43 -> 0.9986541 | E39: =1.03/1.17 -> 0.88034188 | F39: =1.59/2.47 -> 0.6437247 | G39: =454.32/455.3 -> 0.99784757 | I39: =IFERROR(AVERAGE(C39:H39),"") -> 0.89806432 | J39: =SQRT((C39-I39)^2) -> 0.071689021
B40: b (Yahoo) | C40: =OP!M22 -> 1.19 | D40: 0.9 | E40: 0.98 | F40: 1.02 | G40: 1.34 | I40: =IFERROR(AVERAGE(C40:H40),"") -> 1.086 | J40: =SQRT((C40-I40)^2) -> 0.104
B41: Dividend Yield (yahoo finance) | C41: =OP!M32 -> #VALUE! | D41: 0.00092 | E41: 0.0171 | F41: 0.0148 | G41: 0 | I41: =IFERROR(AVERAGE(C41:H41),"") | J41: =SQRT((C41-I41)^2) -> #VALUE!
...

Sheet ESG
B1: Company GICS Sector: | T1: Yes
B2: Information Technology | C2: <- Select Industry | T2: No
B3: ESG Analysis | K3: Relative ESG Analysis
B4: Parameters | C4: Impact | D4: Do they report? | E4: Ranking | F4: Mitigation Plan | G4: Traffic Lights | H4: Improvement over time? | I4: Targets / Goals? | J4: Comments | K4: Parameters | L4: #VALUE! | M4: =Peers!D8 -> #VALUE! | N4: =Peers!E8 -> #VALUE! | O4: =Peers!F8 -> #VALUE! | P4: =Peers!G8 -> #VALUE! | Q4: =Peers!H8 -> #VALUE! | R4: AVERAGE
B5: Environmental | K5: Ratios
A6: 1 | B6: CO2 Direct Emissions | C6: =VLOOKUP($B$2,'Sector Impact'!$K$4:$AA$16,A6+1,FALSE) -> Medium | D6: Yes | E6: Medium High | F6: Yes | H6: Yes. 1. During the last few years they have reduced their net emissions measured by metrics tons of CO2. In 2021 they reduced about 4,5%, in 2022 20,3% and in 2023 44% | I6: They have both a medium term and long term, the first to reduce carbon emissions up to 50% and and the latter up to +90%. Furthermore the data shows they are in a successful path | J6: - | K6: CO2 Emissions/$M Sales | L6: =L12/L$11 -> 42.676703 | M6: =M12/M$11 -> 65.567156 | N6: =N12/N$11 -> 2.5777886 | O6: =O12/O$11 -> 26.263525 | P6: =P12/P$11 -> 30.245209 | Q6: =Q12/Q$11 -> 31073.724 | R6: =IFERROR(AVERAGE(L6:Q6),"") -> 5206.8424
A7: 2 | B7: Total Water Consumption | C7: =VLOOKUP($B$2,'Sector Impact'!$K$4:$AA$16,A7+1,FALSE) -> Low | F7: No | G7: grg | I7: SF considers water consumption to be negligible, since we do not consume water for any products or processes and almost all water is discharged except for trace amounts consumed in the offices. | K7: Water Consumption/$M Sales | L7: =L13/L$11 -> 1.770222e-05 | M7: =M13/M$11 -> 7.7167499e-05 | N7: =N13/N$11 -> 2.6627039e-05 | O7: =O13/O$11 -> 7.5459052e-06 | P7: =P13/P$11 -> 1.6221687e-05 | Q7: =+IFERROR(Q13/Q$11,"N/A") -> N/A | R7: =IFERROR(AVERAGE(L7:Q7),"") -> 2.905287e-05
A8: 3 | B8: Total Energy Consumption | C8: =VLOOKUP($B$2,'Sector Impact'!$K$4:$AA$16,A8+1,FALSE) -> High | D8: Yes | E8: "Best in class" | F8: Yes | H8: Over time they have been increasing their energy use. Although, the energy they use is entierly powered by renewable sources | I8: They have met their main goal this year by achieving 100% renewable energy. | J8: - | K8: Energy Consumption/$M Sales | L8: =L14/L$11 -> 0.02771753 | M8: =M14/M$11 -> 6.808897e-05 | N8: =N14/N$11 -> 0.027476193 | O8: =O14/O$11 -> 0.055225259 | P8: =P14/P$11 -> 0.011846586 | Q8: =Q14/Q$11 -> 4.6616257 | R8: =IFERROR(AVERAGE(L8:Q8),"") -> 0.79732656
A9: 4 | B9: Waste Management | C9: =VLOOKUP($B$2,'Sector Impact'!$K$4:$AA$16,A9+1,FALSE) -> Low | H9: As a software technology company, their operational waste footprint is relatively small. | I9: They provide recycling and compost collection where local infrastructure allows. They offer reusable dishware, cups and cutlery, bulk snack options, and employee fridges for storing leftovers from catered meetings. Furthermore, they also periodically engage in employee-facing education campaigns on proper waste sorting and waste reduction best practices. | K9: Waste Production/$M Sales | L9: =IFERROR(L15/L$11,"N/A") -> N/A | M9: =M14/M$11 -> 6.808897e-05 | N9: =N15/N$11 -> 0.00030326924 | O9: =IFERROR(O15/O$11,"N/A") -> N/A | P9: =P15/P$11 -> 0.00011428571 | Q9: =IFERROR(Q15/Q$11,"N/A") -> N/A | R9: =IFERROR(AVERAGE(L9:Q9),"") -> 0.00016188131
A10: 5 | B10: Land Degradation/Deforestation/Biodiversity loss/Animal sufering/… | C10: =VLOOKUP($B$2,'Sector Impact'!$K$4:$AA$16,A10+1,FALSE) -> Low | H10: Since their ambitious goal was announced, we have supported 20+ projects throughout the world and funded over 40 million trees | I10: Salesforce set a goal to support and mobilize the conservation, restoration, and growth of 100 million trees by the end of 2030. | K10: Inputs
B11: Social | K11: Net Sales ($M) | L11: 31352 | M11: =Peers!D56 -> 198270 | N11: =Peers!E56 -> 32974 | O11: =Peers!F56 -> 42440 | P11: =Peers!G56 -> 17430 | Q11: =Peers!H56 -> 1.587
A12: 6 | B12: Employee Turnover % | C12: =VLOOKUP($B$2,'Sector Impact'!$K$4:$AA$16,A12+1,FALSE) -> Low | H12: About 1/3 of open positions are filled by internal candidates. | I12: - | K12: CO2 Emissions Total (metric tonnes) | L12: 1338000 | M12: 13000000 | N12: 85000 | O12: 1114624 | P12: 527174 | Q12: 49314
A13: 7 | B13: Salaries & Compensation | C13: =VLOOKUP($B$2,'Sector Impact'!$K$4:$AA$16,A13+1,FALSE) -> Low | H13: They have had improvements over time. One of the last iniciatives was thev equal pay startegy, where they try to mitigate any salary disparity based in any factor related to gender, race,, sexual orientation and so on. | I13: - | K13: Water Consumption Total (millions m3) | L13: 0.555 | M13: 15.3 | N13: 0.878 | O13: 0.32024822 | P13: 0.282744 | Q13: Not disclosed
A14: 8 | B14: Reputation | C14: =VLOOKUP($B$2,'Sector Impact'!$K$4:$AA$16,A14+1,FALSE) -> Low | H14: - | I14: - | K14: Energy Consumption Total (Gigawatts) | L14: 869 | M14: 13.5 | N14: 906 | O14: 2343.76 | P14: 206.486 | Q14: 7.398
A15: 9 | B15: Discrimination Events | C15: =VLOOKUP($B$2,'Sector Impact'!$K$4:$AA$16,A15+1,FALSE) -> Low | K15: Waste Production Total (Tonnes) | L15: Near zero | M15: 13.403 | N15: 10 | O15: Near zero | P15: 1.992 | Q15: Not disclosed
A16: 10 | B16: Work Safety | C16: =VLOOKUP($B$2,'Sector Impact'!$K$4:$AA$16,A16+1,FALSE) -> High | D16: Yes | E16: Medium High | F16: Yes | H16: - | I16: - | J16: They implement a health and safety management system which ensures open communication, proactive identification and management of health and safety risks, and compliance with applicable laws and regulations. | K16: ESG Scores
A17: 11 | B17: Damage to consumer health | C17: =VLOOKUP($B$2,'Sector Impact'!$K$4:$AA$16,A17+1,FALSE) -> Low | H17: - | I17: - | J17: safety management system which ensures open communication, proactive identification and | K17: Refinitiv
A18: 12 | B18: PXP? | C18: =VLOOKUP($B$2,'Sector Impact'!$K$4:$AA$16,A18+1,FALSE) -> Low | J18: management of health and safety risks, and compliance with applicable laws and regulations | K18: Sustainalytics | L18: 14.9 | M18: 15.1 | N18: 12.7 | O18: 13.9 | P18: 13.1
A19: 13 | B19: Supply chain | C19: =VLOOKUP($B$2,'Sector Impact'!$K$4:$AA$16,A19+1,FALSE) -> Low | K19: ISS
A20: 14 | B20: Community involvement | C20: =VLOOKUP($B$2,'Sector Impact'!$K$4:$AA$16,A20+1,FALSE) -> Low | K20: CDP | L20: A- | M20: A | N20: A- | O20: B | P20: A | Q20: -
A21: 15 | B21: Public Sector | C21: =VLOOKUP($B$2,'Sector Impact'!$K$4:$AA$16,A21+1,FALSE) -> Medium | D21: No
A22: 16 | B22: Litigation | C22: =VLOOKUP($B$2,'Sector Impact'!$K$4:$AA$16,A22+1,FALSE) -> Very High | D22: No
B23: Corporate Governance | K23: PARAMETERS
A24: 17 | B24: Diversity (Gender, Age, Industry, Region) | E24: "Best in class" | F24: Yes | H24: Over the last 3 years SF has been growing its workforce diversity. The numbers show that the percentage of women, and other ethnicities has been gradually growing. | I24: Keep on the diversification | K24: IMPACT | L24: RANKING | M24: MITIGATION PLAN | O24: TRAFFIC
A25: 18 | B25: % Independence | E25: Medium | J25: A majority of our board members are independent of Salesforce and its management | K25: Low | L25: "Best in class" | M25: Is there evidence of a plan/program ?
A26: 19 | B26: average time as independent directors | E26: Medium | J26: Board average tenure has been decreasing | K26: Medium | L26: Medium High
A27: 20 | B27: Recent departures of directors / C-level executives? | K27: High | L27: Medium
A28: 21 | B28: CEO/Chairman duality | E28: "Best in class" | J28: Management and board are Independent | K28: Very high | L28: "Villain"
A29: 22 | B29: Transparency (ESG, segments, acquisitions, other) | E29: Medium High
A30: 23 | B30: Time taken to report after the end of the quarter / year | E30: Medium | J30: About 2-3 months
A31: 24 | B31: Additional participation of the CEO in other boards or excessive participation of Ch.
A32: 25 | B32: Audit / Consulting | D32: Yes | E32: Medium High
A33: 26 | B33: ESG-compensation related | D33: No
A34: 27 | B34: Management compensation schemes | D34: Yes

Sheet DCF
A1: VALUATION MODEL
G3: Short Term | K3: Long Term
A4: Section | B4: Line # | C4: ITEM | D4: 2020 (Real) | E4: 2021 (Real) | F4: 2022 (Real) | G4: 2023 | H4: =G4+1 -> 2024 | I4: =H4+1 -> 2025 | J4: =I4+1 -> 2026 | K4: =J4+1 -> 2027 | L4: =K4+1 -> 2028 | M4: =L4+1 -> 2029 | N4: =M4+1 -> 2030 | O4: =N4+1 -> 2031 | ... AF4: =AE4+1 -> 2048
A5: INCOME STATEMENT | B5: 1 | C5: Growth | D5: ='Fin. Data'!D6 -> 0.24295239 | E5: =+E6/D6-1 -> 0.24656503 | F5: =+F6/E6-1 -> 0.18345161 | G5: =+G6/F6-1 -> 0.24408539 | H5: =+H6/G6-1 -> 0.19408539 | I5: =+I6/H6-1 -> 0.16908539 | J5: =+J6/I6-1 -> 0.13908539 | K5: =+K6/J6-1 -> 0.11908539 | L5: =+L6/K6-1 -> 0.11408539 | ... AF5: =+AF6/AE6-1 -> 0.02
B6: 2 | C6: Revenues/Sales | D6: =Inputs!D6 -> 21252 | E6: =Inputs!C6 -> 26492 | F6: =Inputs!B6 -> 31352 | G6: =+Assumptions!I41 -> 39004.565 | H6: =+Assumptions!J41 -> 46574.782 | I6: =+Assumptions!K41 -> 54449.897 | J6: =+Assumptions!L41 -> 62023.082 | K6: =+Assumptions!M41 -> 69409.125 | L6: =+Assumptions!N41 -> 77327.692 | M6: =+Assumptions!O41 -> 86072.325 | N6: =+Assumptions!P41 -> 95719.775 | ... AF6: =+Assumptions!AH41 -> 380527.31
B7: 3 | C7: EBIT/Operating Margin | D7: =D8/D6 -> 0.22619048 | E7: =E8/E6 -> 0.18231919 | F7: =F8/F6 -> 0.14180913 | G7: 0.1 | H7: 0.09 | I7: 0.09 | J7: 0.09 | K7: 0.09 | L7: 0.09 | M7: =+_xlfn.FORECAST.LINEAR(M4,'Fin. Data'!$B$12:$M$12,'Fin. Data'!$B$4:$M$4) -> 0.093040236 | N7: =+_xlfn.FORECAST.LINEAR(N4,'Fin. Data'!$B$12:$M$12,'Fin. Data'!$B$4:$M$4) -> 0.10002407 | O7: =+_xlfn.FORECAST.LINEAR(O4,'Fin. Data'!$B$12:$M$12,'Fin. Data'!$B$4:$M$4) -> 0.10700791 | P7: =+_xlfn.FORECAST.LINEAR(P4,'Fin. Data'!$B$12:$M$12,'Fin. Data'!$B$4:$M$4) -> 0.11399175 | Q7: =+_xlfn.FORECAST.LINEAR(Q4,'Fin. Data'!$B$12:$M$12,'Fin. Data'!$B$4:$M$4) -> 0.12097559 | R7: =+_xlfn.FORECAST.LINEAR(R4,'Fin. Data'!$B$12:$M$12,'Fin. Data'!$B$4:$M$4) -> 0.12795943 | S7: =+_xlfn.FORECAST.LINEAR(S4,'Fin. Data'!$B$12:$M$12,'Fin. Data'!$B$4:$M$4) -> 0.13494327 | T7: =+_xlfn.FORECAST.LINEAR(T4,'Fin. Data'!$B$12:$M$12,'Fin. Data'!$B$4:$M$4) -> 0.14192711 | ... AF7: =+_xlfn.FORECAST.LINEAR(AF4,'Fin. Data'!$B$12:$M$12,'Fin. Data'!$B$4:$M$4) -> 0.22573317
B8: 4 | C8: EBITDA | D8: =+D12+D9+D10 -> 4807 | E8: =+E12+E9+E10 -> 4830 | F8: =+F12+F9+F10 -> 4446 | G8: =G7*G6+G9+G10 -> 6827.0785 | H8: =H7*H6+H9+H10 -> 7701.3378 | I8: =I7*I6+I9+I10 -> 9106.2327 | J8: =J7*J6+J9+J10 -> 10601.66 | K8: =K7*K6+K9+K10 -> 10392.55 | L8: =L7*L6+L9+L10 -> 11747.525 | M8: =M7*M6+M9+M10 -> 13511.803 | N8: =N7*N6+N9+N10 -> 15874.399 | ... AF8: =AF7*AF6+AF9+AF10 -> 130070.89
B9: 5a | C9: (Dep) | D9: 2846 | E9: 3298 | F9: 3786 | G9: =$D$53*DCF!F40 -> 2926.622 | H9: =$D$53*DCF!G40 -> 3509.6075 | I9: =$D$53*DCF!H40 -> 4205.742 | J9: =$D$53*DCF!I40 -> 5019.5826 | K9: =$E$53*DCF!J40 -> 4145.7286 | L9: =$E$53*DCF!K40 -> 4788.0325 | M9: =$E$53*DCF!L40 -> 5503.614 | N9: =$E$53*DCF!M40 -> 6300.1173 | O9: =$E$53*DCF!N40 -> 7185.8969 | P9: =$E$53*DCF!O40 -> 8170.0738 | Q9: =$E$53*DCF!P40 -> 9262.5941 | R9: =$E$53*DCF!Q40 -> 10475.292 | ... AF9: =$E$53*DCF!AE40 -> 44173.254 | AG9: =SUM(D9:AF9) -> 443574.28
B10: 5b | C10: Amort | G10: =F38*$D$54 -> 0 | H10: =G38*$D$54 -> 0 | I10: =H38*$D$54 -> 0 | J10: =I38*$D$54 -> 0 | K10: =J38*$E$54 -> 0 | L10: =K38*$E$54 -> 0 | M10: =L38*$E$54 -> 0 | N10: =M38*$E$54 -> 0 | O10: =N38*$E$54 -> 0 | P10: =O38*$E$54 -> 0 | Q10: =P38*$E$54 -> 0 | R10: =Q38*$E$54 -> 0 | ... AF10: =AE38*$E$54 -> 0
B11: 5c | C11: (Stock based compensation) | D11: =D20 -> 1785 | E11: =E20 -> 2190 | F11: =F20 -> 2779 | G11: =G6*$D$55 -> 3319.2527 | H11: =H6*$D$55 -> 3963.4711 | I11: =I6*$D$55 -> 4633.6362 | J11: =J6*$D$55 -> 5278.1073 | K11: =K6*$E55 -> 4511.5931 | L11: =L6*$E55 -> 5026.3 | M11: =M6*$E55 -> 5594.7011 | N11: =N6*$E55 -> 6221.7854 | O11: =O6*$E55 -> 6912.9348 | P11: =P6*$E55 -> 7673.948 | Q11: =Q6*$E55 -> 8518.0823 | R11: =R6*$E55 -> 9455.0713 | ... AF11: =AF6*$E55 -> 24734.275
B12: 6 | C12: EBIT | D12: =D15-D14-D13 -> 1961 | E12: =E15-E14-E13 -> 1532 | F12: =F15-F14-F13 -> 660 | G12: =+G8-G9-G10-G11 -> 581.20386 | H12: =+H8-H9-H10-H11 -> 228.25922 | I12: =+I8-I9-I10-I11 -> 266.85452 | J12: =+J8-J9-J10-J11 -> 303.97009 | K12: =+K8-K9-K10-K11 -> 1735.2281 | L12: =+L8-L9-L10-L11 -> 1933.1923 | M12: =+M8-M9-M10-M11 -> 2413.4883 | N12: =+N8-N9-N10-N11 -> 3352.4965 | ... AF12: =+AF8-AF9-AF10-AF11 -> 61163.359
B13: 7 | C13: (Net financing cost) | D13: ='Fin. Data'!D14 -> -64 | E13: ='Fin. Data'!C14 -> -227 | F13: ='Fin. Data'!B14 -> -131 | G13: =F43*$D$58-F44*$D$57 -> 376.07984 | H13: =G43*$D$58-G44*$D$57 -> 850.63014 | I13: =H43*$D$58-H44*$D$57 -> 1414.0304 | J13: =I43*$D$58-I44*$D$57 -> 2037.3424 | K13: =J43*$E$58-J44*$E$57 -> 1918.6266 | L13: =K43*$E$58-K44*$E$57 -> 2467.185 | M13: =L43*$E$58-L44*$E$57 -> 3111.7727 | N13: =M43*$E$58-M44*$E$57 -> 3835.0547 | O13: =N43*$E$58-N44*$E$57 -> 4767.6657 | P13: =O43*$E$58-O44*$E$57 -> 5870.0993 | Q13: =P43*$E$58-P44*$E$57 -> 7170.5368 | R13: =Q43*$E$58-Q44*$E$57 -> 8698.4132 | ... AF13: =AE43*$E$58-AE44*$E$57 -> 76905.424
B14: 8 | C14: Other income/(cost) | D14: ='Fin. Data'!D15 -> 664 | E14: ='Fin. Data'!C15 -> 227 | F14: ='Fin. Data'!B15 -> 131 | G14: =AVERAGE(D14:F14)*(1+G5) -> 423.81842 | H14: =AVERAGE(E14:G14)*(1+H5) -> 311.18599 | I14: =AVERAGE(F14:H14)*(1+I5) -> 337.4777 | J14: =AVERAGE(G14:I14)*(1+J5) -> 407.21624 | K14: =AVERAGE(H14:J14)*(1+K5) -> 393.87327 | L14: =AVERAGE(I14:K14)*(1+L5) -> 422.82036 | M14: =AVERAGE(J14:L14)*(1+M5) -> 454.1054 | N14: =AVERAGE(K14:M14)*(1+N5) -> 471.07901 | ... AF14: =AVERAGE(AC14:AE14)*(1+AF5) -> 918.14991
B15: 9 | C15: Earnings before taxes | D15: =+D17+D16 -> 2561 | E15: =+E17+E16 -> 1532 | F15: =+F17+F16 -> 660 | G15: =G12+G13+G14 -> 1381.1021 | H15: =H12+H13+H14 -> 1390.0753 | I15: =I12+I13+I14 -> 2018.3626 | J15: =J12+J13+J14 -> 2748.5287 | K15: =K12+K13+K14 -> 4047.728 | L15: =L12+L13+L14 -> 4823.1977 | M15: =M12+M13+M14 -> 5979.3665 | N15: =N12+N13+N14 -> 7658.6303 | ... AF15: =AF12+AF13+AF14 -> 138986.93
B16: 10 | C16: (Income tax) | D16: ='Fin. Data'!D21 -> -1511 | E16: ='Fin. Data'!C21 -> 88 | F16: ='Fin. Data'!B21 -> 452 | G16: =(1*$D$56)*G15 -> 414.33064 | H16: =(1*$D$56)*H15 -> 417.0226 | I16: =(1*$D$56)*I15 -> 605.50878 | J16: =(1*$D$56)*J15 -> 824.55861 | K16: =(1*$E$56)*K15 -> 1649.4492 | L16: =(1*$E$56)*L15 -> 1965.4531 | M16: =(1*$E$56)*M15 -> 2436.5918 | N16: =(1*$E$56)*N15 -> 3120.8918 | O16: =(1*$E$56)*O15 -> 3966.8398 | P16: =(1*$E$56)*P15 -> 4963.832 | Q16: =(1*$E$56)*Q15 -> 6136.9642 | R16: =(1*$E$56)*R15 -> 7514.8686 | ... AF16: =(1*$E$56)*AF15 -> 56637.175
B17: 11 | C17: Net income | D17: ='Fin. Data'!D23 -> 4072 | E17: ='Fin. Data'!C23 -> 1444 | F17: ='Fin. Data'!B23 -> 208 | G17: =+G15-G16 -> 966.77149 | H17: =+H15-H16 -> 973.05274 | I17: =+I15-I16 -> 1412.8538 | J17: =+J15-J16 -> 1923.9701 | K17: =+K15-K16 -> 2398.2789 | L17: =+L15-L16 -> 2857.7446 | M17: =+M15-M16 -> 3542.7746 | N17: =+N15-N16 -> 4537.7384 | ... AF17: =+AF15-AF16 -> 82349.758
A19: CASH FLOW STATEMENT | B19: 12 | C19: Operating cash flows before WK | D19: =+D22-(D21+D20) -> -415 | E19: =+E22-(E21+E20) -> 2972 | F19: =+F22-(F21+F20) -> 4589 | G19: =G17+G10+G9 -> 3893.3935 | H19: =H17+H10+H9 -> 4482.6602 | I19: =I17+I10+I9 -> 5618.5958 | J19: =J17+J10+J9 -> 6943.5527 | K19: =K17+K10+K9 -> 6544.0074 | L19: =L17+L10+L9 -> 7645.7772 | M19: =M17+M10+M9 -> 9046.3886 | N19: =N17+N10+N9 -> 10837.856 | ... AF19: =AF17+AF10+AF9 -> 126523.01
B20: 13 | C20: (Stock-based compensation) | D20: 1785 | E20: 2190 | F20: 2779 | G20: =G11 -> 3319.2527 | H20: =H11 -> 3963.4711 | I20: =I11 -> 4633.6362 | J20: =J11 -> 5278.1073 | K20: =K11 -> 4511.5931 | L20: =L11 -> 5026.3 | M20: =M11 -> 5594.7011 | N20: =N11 -> 6221.7854 | ... AF20: =AF11 -> 24734.275
B21: 14 | C21: (Working Capital Flows) | D21: =+Assumptions!D151 -> 3431 | E21: =+Assumptions!E151 -> 838 | F21: =+Assumptions!F151 -> -257 | G21: =+Assumptions!G151 -> 1390.9345 | H21: =+Assumptions!H151 -> 1048.6307 | I21: =+Assumptions!I151 -> 1090.8654 | J21: =+Assumptions!J151 -> 1049.0419 | K21: =+Assumptions!K151 -> 1023.1189 | ... AF21: =+Assumptions!AF151 -> 1140.5259
B22: 15 | C22: -Total Operating Cash Flow | D22: =+'Fin. Data'!D67 -> 4801 | E22: =+'Fin. Data'!C67 -> 6000 | F22: =+'Fin. Data'!B67 -> 7111 | G22: =G19+G20+G21 -> 8603.5806 | H22: =H19+H20+H21 -> 9494.762 | I22: =I19+I20+I21 -> 11343.097 | J22: =J19+J20+J21 -> 13270.702 | K22: =K19+K20+K21 -> 12078.719 | L22: =L19+L20+L21 -> 14323.32 | M22: =M19+M20+M21 -> 15915.091 | N22: =N19+N20+N21 -> 18465.173 | ... AF22: =AF19+AF20+AF21 -> 152397.81
B23: 16 | C23: (CAPEX) | D23: ='Fin. Data'!D32 -> -710 | E23: ='Fin. Data'!C32 -> -717 | F23: ='Fin. Data'!B32 -> -798 | G23: =G6*$D$62 -> -1313.1318 | H23: =H6*$D$62 -> -1567.9915 | I23: =I6*$D$62 -> -1833.1159 | J23: =J6*$D$62 -> -2088.0756 | K23: =K6*$E$62 -> -2075.2013 | L23: =L6*$E$62 -> -2311.9515 | M23: =M6*$E$62 -> -2573.3994 | N23: =N6*$E$62 -> -2861.8399 | O23: =O6*$E$62 -> -3179.7485 | P23: =P6*$E$62 -> -3529.7924 | Q23: =Q6*$E$62 -> -3918.0695 | R23: =R6*$E$62 -> -4349.0572 | ... AF23: =AF6*$E$62 -> -11377.046 | AG23: =SUM(D23:AF23) -> -149728.14
B24: 17 | C24: Adq | D24: =Inputs!D66 -> -1281 | E24: ='Fin. Data'!C33 -> -14876 | F24: ='Fin. Data'!B33 -> -439 | G24: =G6*$D$63 -> -1246.3317 | H24: =H6*$D$63 -> -1488.2265 | I24: =I6*$D$63 -> -1739.8638 | J24: =J6*$D$63 -> -1981.8535 | K24: =K6*$E$63 -> -1843.3755 | L24: =L6*$E$63 -> -2053.6777 | M24: =M6*$E$63 -> -2285.9187 | N24: =N6*$E$63 -> -2542.1368 | O24: =O6*$E$63 -> -2824.531 | P24: =P6*$E$63 -> -3135.4706 | Q24: =Q6*$E$63 -> -3480.3724 | R24: =R6*$E$63 -> -3863.2134 | ... AF24: =AF6*$E$63 -> -10106.088 | AH24: =AG9-AG23 -> 593302.42
B25: 18 | C25: (Other investing flows) | D25: =Inputs!D67 -> -1980 | E25: =Inputs!C67 -> 1057 | F25: =Inputs!B67 -> -752 | G25: =(1+G5)*AVERAGE(D25:F25) -> -694.61434 | H25: =(1+H5)*AVERAGE(E25:G25) -> -155.0776 | I25: =(1+I5)*AVERAGE(F25:H25) -> -624.17155 | J25: =(1+J5)*AVERAGE(G25:I25) -> -559.61879 | K25: =(1+K5)*AVERAGE(H25:J25) -> -499.43585 | L25: =(1+L5)*AVERAGE(I25:K25) -> -625.08591 | M25: =(1+M5)*AVERAGE(J25:L25) -> -624.86408 | N25: =(1+N5)*AVERAGE(K25:M25) -> -648.48881 | ... AF25: =(1+AF5)*AVERAGE(AC25:AE25) -> -1278.6736
B26: 19 | C26: -Total Investing Flows | D26: =D23+D24+D25 -> -3971 | E26: =E23+E24+E25 -> -14536 | F26: =F23+F24+F25 -> -1989 | G26: =G23+G24+G25 -> -3254.0778 | H26: =H23+H24+H25 -> -3211.2955 | I26: =I23+I24+I25 -> -4197.1513 | J26: =J23+J24+J25 -> -4629.5478 | K26: =K23+K24+K25 -> -4418.0127 | ... AF26: =AF23+AF24+AF25 -> -22761.807
B27: 20 | C27: (Flows related to leases) | D27: =Inputs!D71+Inputs!D72 -> 0 | E27: =Inputs!C71+Inputs!C72 -> 0 | F27: =Inputs!B71+Inputs!B72 -> 0 | G27: 0 | H27: 0 | I27: 0 | J27: 0 | K27: 0 | L27: 0 | M27: 0 | N27: 0 | O27: 0 | P27: 0 | Q27: 0 | R27: 0 | S27: 0 | T27: 0 | U27: 0 | V27: 0 | W27: 0 | X27: 0 | Y27: 0 | Z27: 0 | AA27: 0 | AB27: 0 | AC27: 0 | AD27: 0 | AE27: 0 | AF27: 0
B28: 21 | C28: Flows related to debt | D28: =+SUM(Inputs!D69:D70) -> -107 | E28: =+SUM(Inputs!C69:C70) -> 5192 | F28: =+SUM(Inputs!B69:B70) -> -423 | G28: =G44-F44 -> 3451.3031 | H28: =H44-G44 -> 4197.5713 | I28: =I44-H44 -> 4331.5033 | J28: =J44-I44 -> 2843.7626 | K28: =K44-J44 -> 601.45079 | L28: =L44-K44 -> 424.85261 | M28: =M44-L44 -> 1533.9494 | N28: =N44-M44 -> 1475.8537 | ... AF28: =AF44-AE44 -> 2127.6877
B29: 22 | C29: (Repurchases)/Issuance of stock | D29: ='Fin. Data'!D28 -> 0 | E29: ='Fin. Data'!C28 -> 0 | F29: ='Fin. Data'!B28 -> -4000 | G29: =-G17*$D$65 -> 0 | H29: =+Assumptions!K132 -> 194.61055 | I29: =+Assumptions!L132 -> 282.57076 | J29: =+Assumptions!M132 -> 384.79402 | K29: =+Assumptions!N132 -> 479.65577 | L29: =+Assumptions!O132 -> 571.54893 | M29: =+Assumptions!P132 -> 708.55492 | N29: =+Assumptions!Q132 -> 2198.5946 | O29: =+Assumptions!R132 -> 2794.545 | ... AF29: =+Assumptions!AI132 -> 39899.553
B30: 23 | C30: (Dividends) | D30: ='Fin. Data'!D27 -> 0 | E30: ='Fin. Data'!C27 -> 0 | F30: ='Fin. Data'!B27 -> 0 | G30: =-$D$64*G17 -> 0 | H30: =-$D$64*H17 -> 0 | I30: =+Assumptions!L134 -> 353.21345 | J30: =+Assumptions!M134 -> 480.99252 | K30: =+Assumptions!N134 -> 599.56971 | L30: =+Assumptions!O134 -> 714.43616 | M30: =+Assumptions!P134 -> 885.69366 | N30: =+Assumptions!Q134 -> 1543.3382 | O30: =+Assumptions!R134 -> 1961.675 | P30: =+Assumptions!S134 -> 2454.7059 | ... AF30: =+Assumptions!AI134 -> 28008.122
B31: 24 | C31: Other financing flows | D31: =Inputs!D75 -> 1301 | E31: =Inputs!C75 -> 2646 | F31: =Inputs!B75 -> 861 | G31: =(1+G5)*AVERAGE(D31:F31) -> 1993.8542 | H31: =(1+H5)*AVERAGE(E31:G31) -> 2189.4965 | I31: =(1+I5)*AVERAGE(F31:H31) -> 1965.7589 | J31: =(1+J5)*AVERAGE(G31:I31) -> 2334.787 | K31: =(1+K5)*AVERAGE(H31:J31) -> 2420.9706 | L31: =(1+L5)*AVERAGE(I31:K31) -> 2496.1144 | M31: =(1+M5)*AVERAGE(J31:L31) -> 2690.6509 | N31: =(1+N5)*AVERAGE(K31:M31) -> 2820.1507 | ... AF31: =(1+AF5)*AVERAGE(AC31:AE31) -> 5465.5638
B32: 25 | C32: -Total Financing flows | D32: =D27+D28+D29+D30+D31 -> 1194 | E32: =E27+E28+E29+E30+E31 -> 7838 | F32: =F27+F28+F29+F30+F31 -> -3562 | G32: =G27+G28-G29-G30+G31 -> 5445.1573 | H32: =H27+H28-H29-H30+H31 -> 6192.4573 | I32: =I27+I28-I29-I30+I31 -> 5661.478 | J32: =J27+J28-J29-J30+J31 -> 4312.763 | K32: =K27+K28-K29-K30+K31 -> 1943.1959 | L32: =L27+L28-L29-L30+L31 -> 1634.982 | M32: =M27+M28-M29-M30+M31 -> 2630.3518 | N32: =N27+N28-N29-N30+N31 -> 554.07149 | ... AF32: =AF27+AF28-AF29-AF30+AF31 -> -60314.423
A34: SUMMARY | B34: 26 | C34: Cash before shareholder returns | D34: =D22+D26+D27+D28+D31 -> 2024 | E34: =E22+E26+E27+E28+E31 -> -698 | F34: =F22+F26+F27+F28+F31 -> 5560 | G34: =G22+G26+G27+G28+G31 -> 10794.66 | H34: =H22+H26+H27+H28+H31 -> 12670.534 | I34: =I22+I26+I27+I28+I31 -> 13443.208 | J34: =J22+J26+J27+J28+J31 -> 13819.704 | K34: =K22+K26+K27+K28+K31 -> 10683.128 | ... AF34: =AF22+AF26+AF27+AF28+AF31 -> 137229.26
B35: 27 | C35: Returns to shareholders | D35: =-1*(D29+D30) -> 0 | E35: =-1*(E29+E30) -> 0 | F35: =-1*(F29+F30) -> 4000 | G35: =-1*(G29+G30) -> 0 | H35: =-1*(H29+H30) -> -194.61055 | I35: =-1*(I29+I30) -> -635.78422 | J35: =-1*(J29+J30) -> -865.78654 | K35: =-1*(K29+K30) -> -1079.2255 | ... AF35: =-1*(AF29+AF30) -> -67907.675
B36: 28 | C36: Excess cash acumulation | D36: =D34-D35 -> 2024 | E36: =E34-E35 -> -698 | F36: =F34-F35 -> 1560 | G36: =G34-G35 -> 10794.66 | H36: =H34-H35 -> 12865.145 | I36: =I34-I35 -> 14078.992 | J36: =J34-J35 -> 14685.49 | K36: =K34-K35 -> 11762.354 | ... AF36: =AF34-AF35 -> 205136.93
A38: BALANCE SHEET | B38: 29 | C38: Intangible assets | D38: 4114 | E38: 8978 | F38: 7125 | G38: =+F38+(-G10) -> 7125 | H38: =+G38+(-H10) -> 7125 | I38: =+H38+(-I10) -> 7125 | J38: =+I38+(-J10) -> 7125 | K38: =+J38+(-K10) -> 7125 | L38: =+K38+(-L10) -> 7125 | M38: =+L38+(-M10) -> 7125 | N38: =+M38+(-N10) -> 7125 | ... AF38: =+AE38+(-AF10) -> 7125 | AG38: =SUM(G38:AF38) -> 185250
B39: 30 | C39: Accumulated amortization | D39: 2746 | E39: 3995 | F39: 4713 | G39: =F39-G10 -> 4713 | H39: =G39-H10 -> 4713 | I39: =H39-I10 -> 4713 | J39: =I39-J10 -> 4713 | K39: =J39-K10 -> 4713 | L39: =K39-L10 -> 4713 | M39: =L39-M10 -> 4713 | N39: =M39-N10 -> 4713 | ... AF39: =AE39-AF10 -> 4713 | AG39: =SUM(G39:AF39) -> 122538
B40: 31 | C40: PPE+Right of use Assets | D40: 5663 | E40: 5695 | F40: 6592 | G40: =F40+(-G23) -> 7905.1318 | H40: =G40+(-H23) -> 9473.1233 | I40: =H40+(-I23) -> 11306.239 | J40: =I40+(-J23) -> 13394.315 | K40: =J40+(-K23) -> 15469.516 | L40: =K40+(-L23) -> 17781.468 | M40: =L40+(-M23) -> 20354.867 | N40: =M40+(-N23) -> 23216.707 | ... AF40: =AE40+(-AF23) -> 154095.14 | AG40: =SUM(G40:AF40) -> 1533227.9
B41: 32 | C41: Accumulated depreciation | D41: 1955 | E41: 2401 | F41: 2702 | G41: =F41-G9 -> -224.622 | H41: =G41-H9 -> -3734.2295 | I41: =H41-I9 -> -7939.9715 | J41: =I41-J9 -> -12959.554 | K41: =J41-K9 -> -17105.283 | L41: =K41-L9 -> -21893.315 | M41: =L41-M9 -> -27396.929 | N41: =M41-N9 -> -33697.046 | ... AF41: =AE41-AF9 -> -430942.28 | AG41: =SUM(G41:AF41) -> -3454080.2
A43: CASH & DEBT & DISCOUNTING | B43: 33 | C43: Ending cash balance | D43: ='Fin. Data'!D39 -> 11966 | E43: =E36+D43 -> 11268 | F43: =F36+E43 -> 12828 | G43: =G36+F43 -> 23622.66 | H43: =H36+G43 -> 36487.805 | I43: =I36+H43 -> 50566.797 | J43: =J36+I43 -> 65252.288 | K43: =K36+J43 -> 77014.641 | L43: =L36+K43 -> 90554.198 | ... AF43: =AF36+AE43 -> 1827144.5
B44: 34 | C44: Total Debt | D44: ='Fin. Data'!D58 -> 2801 | E44: ='Fin. Data'!C58 -> 10977 | F44: ='Fin. Data'!B58 -> 11392 | G44: =+Assumptions!I123 -> 14843.303 | H44: =+Assumptions!J123 -> 19040.874 | I44: =+Assumptions!K123 -> 23372.378 | J44: =+Assumptions!L123 -> 26216.14 | K44: =+Assumptions!M123 -> 26817.591 | L44: =+Assumptions!N123 -> 27242.444 | M44: =+Assumptions!O123 -> 28776.393 | N44: =+Assumptions!P123 -> 30252.247 | ... AF44: =+Assumptions!AH123 -> 59426.741
B45: 35 | C45: Discount factor | F45: =1/((1+$F$50)^G50) -> 1 | G45: =1/((1+$F$50)^G49) -> 0.90415913 | H45: =1/((1+$F$50)^H49) -> 0.81750374 | I45: =1/((1+$F$50)^I49) -> 0.73915347 | J45: =1/((1+$F$50)^J49) -> 0.66831236 | K45: =1/((1+$F$50)^K49) -> 0.60426072 | L45: =1/((1+$F$50)^L49) -> 0.54634785 | M45: =1/((1+$F$50)^M49) -> 0.4939854 | N45: =1/((1+$F$50)^N49) -> 0.44664141 | ... AF45: =1/((1+$F$50)^AF49) -> 0.072839457
...

Sheet Assumptions
B2: Assumptions
B4: Prospects:
B6: Links:
C8: 2022 | D8: =C8-1 -> 2021 | E8: =D8-1 -> 2020 | F8: =E8-1 -> 2019 | G8: =F8-1 -> 2018 | I8: Average | K8: Short Term Forecast | L8: Long Term Forecast
B9: Revenue growth | C9: =(Inputs!B6-Inputs!C6)/Inputs!C6 -> 0.18345161 | D9: =(Inputs!C6-Inputs!D6)/Inputs!D6 -> 0.24656503 | E9: =(Inputs!D6-Inputs!E6)/Inputs!E6 -> 0.24295239 | F9: =(Inputs!E6-Inputs!F6)/Inputs!F6 -> 0.28730613 | G9: =(Inputs!F6-Inputs!G6)/Inputs!G6 -> 0.2601518 | I9: =AVERAGE(C9:G9) -> 0.24408539 | K9: =+AVERAGE(C9:I9) -> 0.24408539
B10: Operating Margin | C10: =Inputs!B8/Inputs!B6 -> 0.032852769 | D10: =Inputs!C8/Inputs!C6 -> 0.02068549 | E10: =Inputs!D8/Inputs!D6 -> 0.02140975 | F10: =Inputs!E8/Inputs!E6 -> 0.017370453 | G10: =Inputs!F8/Inputs!F6 -> 0.040280078 | I10: =AVERAGE(C10:G10) -> 0.026519708 | K10: =+AVERAGE(C10:I10) -> 0.026519708
B13: Modelling Factors
C15: Last 5 Years
C16: 2018 | D16: 2019 | E16: 2020 | F16: 2021 | G16: 2022 | I16: Short Term Forecast | J16: Long Term Forecast | L16: Reference
B17: Depreciation and Amortization factor | C17: =C50 -> 0.38674884 | D17: =D50 -> 0.46903949 | E17: =E50 -> 0.39427516 | F17: =F50 -> 0.50256048 | G17: =G50 -> 0.57910448 | I17: 0.44396572 | J17: =AVERAGE(M50,M51,R51,W51,AB51,AG51,) -> 0.30951405
B18: Stock-based comp | C18: - | D18: - | E18: =+F64 -> 0.083992095 | F18: =+G64 -> 0.082666465 | G18: =+H64 -> 0.088638683 | I18: =+AVERAGE(E18:G18) -> 0.085099081 | J18: 0.065
B19: Tax Rate | C19: -0.13 | D19: 0.82 | E19: 0.59 | F19: 0.68 | G19: 0.06 | I19: =AVERAGE(C19,E19:G19) -> 0.3 | J19: =AVERAGE(E19,F19:I19) -> 0.4075
B20: Interest Rate on debt | I20: =+F83 -> 0.025767359 | J20: 0.04915
B21: Interest Rate on cash | I21: 0.05477 | J21: 0.04915
B22: PPE+ROA | I22: =I25 -> -0.033666105 | J22: =J25 -> -0.029898105
B23: Working capital flows | C23: 0.0067760879 | D23: -0.1120014 | E23: -0.045925089 | F23: -0.063037898 | G23: -0.08066471 | I23: -0.072813896 | J23: -0.061277818
B24: Intangible Assets | C24: =1027/Assumptions!D41 -> 0.077322692 | D24: =1429/Assumptions!E41 -> 0.083577027 | E24: =DCF!D38/Assumptions!F41 -> 0.19358178 | F24: =DCF!E38/Assumptions!G41 -> 0.33889476 | G24: =DCF!F38/Assumptions!H41 -> 0.22725823 | I24: =AVERAGE(C24:G24) -> 0.1841269 | J24: =AVERAGE(I24,D24:G24) -> 0.20548774
B25: CAPEX | C25: -0.04479747 | D25: -0.037606738 | E25: -0.03340862 | F25: -0.027064774 | G25: -0.025452922 | I25: =+AVERAGE(C25:G25) -> -0.033666105 | J25: =+AVERAGE(E25:I25) -> -0.029898105
B26: Acquisition factor | C26: ='Fin. Data'!F33/Assumptions!D41 -> -0.38510766 | D26: ='Fin. Data'!E33/Assumptions!E41 -> -0.021581472 | E26: ='Fin. Data'!D33/Assumptions!F41 -> -0.06027668 | F26: ='Fin. Data'!C33/Assumptions!G41 -> -0.56152801 | G26: ='Fin. Data'!B33/Assumptions!H41 -> -0.014002297 | I26: =AVERAGE(D26,E26,G26) -> -0.031953483 | J26: =AVERAGE(,E26,G26,I26) -> -0.026558115
B27: Dividends | C27: 0 | D27: 0 | E27: 0 | F27: 0 | G27: 0 | I27: =AVERAGE(C27:G27) -> 0 | J27: =+Q135 -> 0.34011177 | K27: According to the average of the industry the % (in terms of Net Income) of buyback is much more higher than the % o dividends payouts. This may be na indicator that Salesforce is now entering the same trend as the industry due to the recent repurchase they did. And in accordance with our estimates, this might indicate that in the medium term (10y) salesforce will be paying out dividends for their investors at a rate of 10,6% of Net Income. Furthermore, historically speaking when companies make large repurchases it because CFO´s believe that the stock is undervalue.
B28: Repurchases | C28: 0 | D28: 0 | E28: 0 | F28: 0 | G28: ='Fin. Data'!B36 -> -19.230769 | I28: =AVERAGE(C28:F28) -> 0 | J28: =+Q133 -> 0.4845133
B29: Leases
B30: Cash Costs for EBIT
B31: Total Debt | C31: =Assumptions!D123/Assumptions!D41 -> 0.27450685 | D31: =Assumptions!E123/Assumptions!E41 -> 0.17885133 | E31: =Assumptions!F123/Assumptions!F41 -> 0.13179936 | F31: =Assumptions!G123/Assumptions!G41 -> 0.4143515 | G31: =Assumptions!H123/Assumptions!H41 -> 0.363358 | I31: =AVERAGE(C31:G31) -> 0.27257341 | J31: =I31+H126 -> 0.3275634
B34: Forecasts
C39: Last 5 Years | I39: Short Term Forecast
C40: 2017 | D40: 2018 | E40: 2019 | F40: 2020 | G40: 2021 | H40: 2022 | I40: 2023 | J40: =I40+1 -> 2024 | K40: =J40+1 -> 2025 | L40: =K40+1 -> 2026 | M40: =L40+1 -> 2027 | N40: =M40+1 -> 2028 | O40: =N40+1 -> 2029 | P40: =O40+1 -> 2030 | Q40: =P40+1 -> 2031 | ... AH40: =AG40+1 -> 2048
B41: Net Sales | C41: ='Fin. Data'!G5 -> 10540 | D41: ='Fin. Data'!F5 -> 13282 | E41: ='Fin. Data'!E5 -> 17098 | F41: ='Fin. Data'!D5 -> 21252 | G41: ='Fin. Data'!C5 -> 26492 | H41: ='Fin. Data'!B5 -> 31352 | I41: =+H41*(1+$H$43) -> 39004.565 | J41: =+I41*(1+$H$43-0.05) -> 46574.782 | K41: =+J41*(1+$J$42-0.025) -> 54449.897 | L41: =+K41*(1+$K$42-0.03) -> 62023.082 | M41: =+L41*(1+$L$42-0.02) -> 69409.125 | N41: =+M41*(1+$M$42-0.005) -> 77327.692 | O41: =+N41*(1+$N$42-0.001) -> 86072.325 | P41: =+O41*(1+$O$42-0.001) -> 95719.775 | Q41: =+P41*(1+$P$42-0.001) -> 106352.84 | R41: =+Q41*(1+$Q$42-0.001) -> 118060.74 | S41: =+R41*(1+$R$44) -> 131047.42 | T41: =+S41*(1+$R$44) -> 145462.64 | U41: =+T41*(1+$R$44) -> 161463.53 | V41: =+U41*(1+$R$44) -> 179224.51 | W41: =+V41*(1+$R$44) -> 198939.21 | X41: =+W41*(1+$W$44) -> 214854.35 | Y41: =+X41*(1+$W$44) -> 232042.69 | Z41: =+Y41*(1+$W$44) -> 250606.11 | AA41: =+Z41*(1+$W$44) -> 270654.6 | AB41: =+AA41*(1+$W$44) -> 292306.97 | AC41: =+AB41*(1+$AB$44) -> 306922.31 | AD41: =+AC41*(1+$AB$44) -> 322268.43 | AE41: =+AD41*(1+$AB$44) -> 338381.85 | AF41: =+AE41*(1+$AB$44) -> 355300.94 | AG41: =+AF41*(1+$AB$44) -> 373065.99 | AH41: =+AG41*(1+$AG$44) -> 380527.31
B42: % Growth | D42: =D41/C41-1 -> 0.2601518 | E42: =E41/D41-1 -> 0.28730613 | F42: =F41/E41-1 -> 0.24295239 | G42: =G41/F41-1 -> 0.24656503 | H42: =H41/G41-1 -> 0.18345161 | I42: =I41/H41-1 -> 0.24408539 | J42: =J41/I41-1 -> 0.19408539 | K42: =K41/J41-1 -> 0.16908539 | ... R42: =R41/Q41-1 -> 0.11008539 | S42: 0.11 | T42: 0.11 | U42: 0.11 | V42: 0.11 | W42: 0.11 | X42: =X41/W41-1 -> 0.08 | Y42: =Y41/X41-1 -> 0.08 | Z42: =Z41/Y41-1 -> 0.08 | AA42: =AA41/Z41-1 -> 0.08 | AB42: =AB41/AA41-1 -> 0.08 | AC42: =AC41/AB41-1 -> 0.05 | AD42: =AD41/AC41-1 -> 0.05 | AE42: =AE41/AD41-1 -> 0.05 | ... AH42: =AH41/AG41-1 -> 0.02
B43: Actual 5y Average | H43: =AVERAGE(D42:H42) -> 0.24408539 | R43: =+AVERAGE(N42:R42) -> 0.11208539 | AB43: =+AVERAGE(X42:AB42) -> 0.08 | AG43: =+AVERAGE(AC42:AG42) -> 0.05
