Workbook
Name Sectors: 'Sector Impact'!$K$4:$K$16

Sheet OP
B2: 45141 | C2: Team 5 | D2: 45169 | E2: =Inputs!H3 -> #VALUE! | L2: NYSE | M2: SIC:
D3: COMPANY DESCRIPTION | H3: CEO & BOARD OF DIRECTORS
D4: {=_FV(Inputs!H3,"Description")} -> Costco Wholesale Corporation operates membership warehouses and e-commerce websites. The Company operates 861 warehouses, including 591 in the United States and Puerto Rico, 107 in Canada, 40 in Mexico, 33 in Japan, 29 in the United Kingdom, 18 in Korea, 15 in Australia, 14 in Taiwan, five in China, four in Spain, two in France, and one each in Iceland, New Zealand and Sweden. It also operates e-commerce sites in the United States, Canada, the United Kingdom, Mexico, Korea, Taiwan, Japan and Australia. It provides a wide selection of merchandise, convenience of specialty departments and exclusive member services. It operates through three segments: United States Operations, Canadian Operations, and Other International Operations. The Company offers merchandise categories (foods and sundries, non-foods, and fresh foods), warehouse ancillary (gasoline, pharmacy, optical, food court, hearing aids and tire installation) and other businesses (e-commerce, business centers, travel and other). | H4: Name | I4: Gender | J4: Age | K4: Tenure | L4: Executive? | M4: Other roles
H5: W. Craig Jelinek | I5: Male | J5: 70 | K5: 11.6 | L5: Yes | M5: CEO & Director
H6: Ron Vachris | I6: Male | J6: 58 | K6: 1.5 | L6: Yes | M6: President
H7: Richard Galanti | I7: Male | J7: 67 | K7: 28.6 | L7: Yes | M7: Executive VP
H8: Jeffrey Raikes | I8: Male | J8: 65 | K8: 14.7 | L8: No | M8: Independent Director
H9: Kenneth Denman | I9: Male | J9: 64 | K9: 6.4 | L9: No | M9: Independent Vice Chairman of the Board
H10: Susan Decker | I10: Female | J10: 60 | K10: 18.8 | L10: No | M10: Independent Director
H11: Mary Wilderotter | I11: Female | J11: 68 | K11: 7.8 | L11: No | M11: Independent Director
H12: Charles Munger | I12: Male | J12: 99 | K12: 26.6 | L12: No | M12: Independent Director
H13: John Stanton | I13: Male | J13: 68 | K13: 7.8 | L13: No | M13: Independent Director
H14: Hamilton James | I14: Male | J14: 72 | K14: 35 | L14: No | M14: Independent Chairman of the Board
H15: Sarah Margaret Jewell | I15: Female | J15: 67 | K15: 3.6 | L15: No | M15: Independent Director
B17: USD MILLIONS
B18: COMPANY OVERVIEW
B19: Stock | D19: Liquidity and Solvency | F19: Segments | I19: Profitability (2022) | L19: Multiples
B20: Last Price | C20: {=_FV(E2,"Price")} -> 842.9 | D20: Total Assets | E20: =_xlfn.XLOOKUP(D20,'Fin. Data'!A:A,'Fin. Data'!B:B,,0) -> 64166 | F20: Regions | H20: % Sales | I20: Reporting Year | J20: 2022 | L20: Float | M20: =441.99/443.15 -> 0.99738238
B21: Outstanding Shares | C21: {=_FV(E2,"Shares outstanding",TRUE)} -> 443335000 | D21: Total Liabilities | E21: =_xlfn.XLOOKUP(D21,'Fin. Data'!A:A,'Fin. Data'!B:B,,0) -> 43519 | F21: =Segments!C5 -> United States and Canada | H21: =Segments!B5 -> 0.86788072 | I21: End of Year | J21: 1 October 2022 | L21: Insiders Own | M21: 0.002
B22: Market Cap. | C22: =C20*C21/1000000 -> 373687.07 | D22: Cash/Share | E22: =_xlfn.XLOOKUP("Cash & Eq.",'Fin. Data'!A:A,'Fin. Data'!B:B,,0)*1000000/C21 -> 24.922463 | F22: =Segments!C6 -> Other International | H22: =Segments!B6 -> 0.13211928 | I22: EBITDA | K22: =_xlfn.XLOOKUP(I22,'Fin. Data'!A:A,'Fin. Data'!B:B,,0) -> 25546 | L22: b (Yahoo) | M22: 0.79
B23: +Total Debt | C23: ='Fin. Data'!B58 -> 10906 | D23: EBIDTA/Net Financial Cost (NFC) | E23: ='Fin. Data (Common Size)'!B19/(-'Fin. Data (Common Size)'!B14) -> 102.68041 | I23: Depreciation & Amortization | K23: =_xlfn.XLOOKUP(I23,'Fin. Data'!A:A,'Fin. Data'!B:B,,0) -> 1900 | L23: Score (S&P) | M23: A+
B24: -Cash | C24: ='Fin. Data'!B39 -> 11049 | D24: Debt/EBITDA | E24: =_xlfn.XLOOKUP("Total Debt",'Fin. Data'!A:A,'Fin. Data'!B:B,,0)/_xlfn.XLOOKUP("EBITDA",'Fin. Data'!A:A,'Fin. Data'!B:B,,0) -> 0.42691615 | I24: EBIT | K24: =_xlfn.XLOOKUP(I24,'Fin. Data'!A:A,'Fin. Data'!B:B,,0) -> 7919 | L24: Price/Book Value | M24: =IFERROR((C20*C21/(E20-E21))/1000000,"") -> 18.098856
B25: =Enterprise Value | C25: =C22+C23-C24 -> 373544.07 | D25: "Others Assets"/Asset | E25: =_xlfn.XLOOKUP("Other Assets",'Fin. Data'!A:A,'Fin. Data'!B:B,,0)/_xlfn.XLOOKUP("Total Assets",'Fin. Data'!A:A,'Fin. Data'!B:B,,0) -> 0.038821183 | I25: Net Income | K25: =_xlfn.XLOOKUP(I25,'Fin. Data'!A:A,'Fin. Data'!B:B,,0) -> 5844 | L25: NCF(3y avg)/Asset | M25: =IFERROR(K31/E20,"") -> 0.077159243
B26: Holdings (nac/int'l) | C26: - | D26: Debt/Assets | E26: =_xlfn.XLOOKUP(D26,'Fin. Data'!A:A,'Fin. Data'!B:B,,0) -> 0.1699654 | F26: Categories | H26: % Sales | I26: EPS | K26: =1000000*K25/C21 -> 13.181905 | L26: Price/Net Inc. (3y avg) | M26: =IFERROR(C22/K30,"") -> 75.47709
B27: t liq. (Holdings/Vol.) | C27: - | D27: EBITDA Margin (average) | E27: =AVERAGE(_xlfn.XLOOKUP("EBITDA Margin",'Fin. Data'!A:A,'Fin. Data'!B:D,,0)) -> 0.11759095 | F27: =Segments!C14 -> Foods and Sundries | H27: =Segments!B14 -> 0.38445203 | I27: ROA | K27: =K25/E20 -> 0.091076271 | L27: EV/Asset | M27: =IFERROR(C25/E20,"") -> 5.8215265
B28: % Short | D28: Operating Margin (average) | E28: =AVERAGE(_xlfn.XLOOKUP("Operating Margin",'Fin. Data'!A:A,'Fin. Data'!B:D,,0)) -> 0.033721933 | F28: =Segments!C15 -> Non-Foods | H28: =Segments!B15 -> 0.27432317 | I28: ROIC | K28: =K25/(E20-(E21-C23)) -> 0.18521218 | L28: EV/Ebidta (3y average) | M28: =IFERROR(C25/K29,"") -> 16.221769
B29: Traffic ESG | D29: Net Income Margin (average) | E29: =AVERAGE(_xlfn.XLOOKUP("Net Income Margin",'Fin. Data'!A:A,'Fin. Data'!B:D,,0)) -> 0.025101101 | F29: =Segments!C16 -> Fresh Foods | H29: =Segments!B16 -> 0.13256858 | I29: EBITDA (3y average) | K29: =AVERAGE(_xlfn.XLOOKUP("EBITDA",'Fin. Data'!A:A,'Fin. Data'!B:D,,0)) -> 23027.333 | L29: Price/NCF (3y average) | M29: =IFERROR(C22/K31,"") -> 75.47709
B30: E | F30: =Segments!C17 -> Warehouse Ancillary and Other Businesses | H30: =Segments!B17 -> 0.20865622 | I30: Net Income (3y average) | K30: =AVERAGE(_xlfn.XLOOKUP("Net Income",'Fin. Data'!A:A,'Fin. Data'!B:D,,0)) -> 4951 | L30: Bonds 1,3,5a (USD) | M30: -
B31: S | D31: Net Financial Cost/Avg Net Debt | E31: =-_xlfn.XLOOKUP("Net Financial Cost",'Fin. Data'!A:A,'Fin. Data'!B:B,,0)/AVERAGE(_xlfn.XLOOKUP("Net Debt",'Fin. Data'!A:A,'Fin. Data'!B:D,,0)) -> 0.092971246 | F31: =Segments!#REF! -> #REF! | H31: =Segments!#REF! -> #REF! | I31: NCF (3y average) | K31: =AVERAGE(_xlfn.XLOOKUP("Net Income",'Fin. Data'!A:A,'Fin. Data'!B:D,,0)) -> 4951 | L31: Div+Rep.(3y avg)/Price | M31: =-IFERROR(SUM(E53:E55)/(3*C22),"") -> 0.0057365289
B32: G | L32: Div. Yield | M32: =-IFERROR(L54/C22,"") -> 0.0040087017
B33: INVESTMENT THESIS
B34: Pillars of Recommendation | H34: Recommendation | I34: Valuation Assumptions
B35: Pillar | C35: Explanation | H35: BUY | I35: CHECK DCF + ASSUMPTIONS
B36: Expansion Projections | C36: Costco has entered in new markets by partening with local companies, which is apparentely a way to overcoming government regulations, setting up local infrastructure and managing different types of risks in foreign markets
B37: Market share stability | C37: Costco is one of the worlds leading global retailer with its presence in eight countries. In spite of heavy competition in the retail industry, Costco has built a strong brand image by offering high-quality products at low prices with excellent customer service, along with other key factors.
B38: Customer retention and loyalty | C38: Costco has a membership warehouse model, which enables high-quality products at lower prices to its consumers. Unlike other competitors in the market, Costco allowed its customers to cancel their membership any time of the year and also reimbursed the unused portion of the membership
B39: Relationship with employees | C39: Costco has been considered one of the best places to work in the US.
B40: Risks of Investment | H40: Price Target | I40: Valuation
B41: Risk | C41: Explanation | H41: =DCF!D75 -> 623.05999 | I41: Discount Rate | J41: =DCF!F50 -> 0.099456414 | L41: Upside | M41: =DCF!D74 -> -0.26081387
B42: Growth & Expansion Risk | C42: "Our growth is dependent, in part, on our ability to acquire property and build or lease new warehouses and depots. We compete with other retailers and businesses for suitable locations. Local land use and other regulations restricting the construction and operation of our warehouses and depots, as well as local community actions opposed to the location of our warehouses or depots at specific sites and the adoption of local laws restricting our operations and environmental regulations, may impact our ability to find suitable locations and increase the cost of sites and of constructing, leasing and operating warehouses and depots. We also may have difficulty negotiating leases or purchase agreements on acceptable terms. In addition, certain jurisdictions have enacted or proposed laws and regulations that would prevent or restrict the operation or expansion plans of certain large retailers and warehouse clubs, including us. Failure to effectively manage these and other similar factors may affect our ability to timely build or lease and operate new warehouses and depots, which could have a material adverse effect on our future growth and profitability." - 10-K Form
...

Sheet Segments
A1: PE
B2: ="Regions "&"("&OP!$J$20&")" -> Regions (2022) | Q2: Products
D3: Nominal value | K3: YoY Growth
B4: Weight | C4: Region | D4: =OP!J20 -> 2022 | E4: =D4-1 -> 2021 | F4: =E4-1 -> 2020 | G4: =F4-1 -> 2019 | H4: =G4-1 -> 2018 | I4: =H4-1 -> 2017 | K4: =OP!J20 -> 2022 | L4: =K4-1 -> 2021 | M4: =L4-1 -> 2020 | N4: =M4-1 -> 2019 | O4: =N4-1 -> 2018 | P4: =O4-1 -> 2017
B5: =IFERROR(D5/$D$9,"") -> 0.86788072 | C5: United States and Canada | D5: =165294+31675 -> 196969 | E5: =141398+27298 -> 168696 | F5: =122142+22434 -> 144576 | G5: =111751+21366 -> 133117 | H5: =102286+20689 -> 122975 | I5: =93889+18775 -> 112664 | K5: =(D5-E5)/E5 -> 0.16759733 | L5: =(E5-F5)/F5 -> 0.16683267 | M5: =(F5-G5)/G5 -> 0.086082168 | N5: =(G5-H5)/H5 -> 0.082472047 | O5: =(H5-I5)/I5 -> 0.091519918
B6: =IFERROR(D6/$D$9,"") -> 0.13211928 | C6: Other International | D6: =29985 -> 29985 | E6: 27233 | F6: 22185 | G6: 19586 | H6: 18601 | I6: 16361 | K6: =(D6-E6)/E6 -> 0.10105387 | L6: =(E6-F6)/F6 -> 0.22754113 | M6: =(F6-G6)/G6 -> 0.13269682 | N6: =(G6-H6)/H6 -> 0.052954142 | O6: =(H6-I6)/I6 -> 0.13691095
B7: =IFERROR(D7/$D$9,"") -> 0
B8: =IFERROR(D8/$D$9,"") -> 0
B9: =SUM(B5:B8) -> 1 | C9: TOTAL | D9: =SUM(D5:D8) -> 226954 | E9: =SUM(E5:E8) -> 195929 | F9: =SUM(F5:F8) -> 166761 | G9: =SUM(G5:G8) -> 152703 | H9: =SUM(H5:H8) -> 141576 | I9: =SUM(I5:I8) -> 129025 | K9: =(D9-E9)/E9 -> 0.15834818 | L9: =(E9-F9)/F9 -> 0.174909 | M9: =(F9-G9)/G9 -> 0.09206106 | N9: =(G9-H9)/H9 -> 0.078593829 | O9: =(H9-I9)/I9 -> 0.097275722 | P9: 0.037
B11: ="Categories "&"("&OP!$J$20&")" -> Categories (2022)
D12: Nominal value | K12: YoY Growth
B13: Weight | C13: Category | D13: =OP!J20 -> 2022 | E13: =D13-1 -> 2021 | F13: =E13-1 -> 2020 | G13: =F13-1 -> 2019 | H13: =G13-1 -> 2018 | I13: =H13-1 -> 2017 | K13: =OP!J20 -> 2022 | L13: =K13-1 -> 2021 | M13: =L13-1 -> 2020 | N13: =M13-1 -> 2019 | O13: =N13-1 -> 2018 | P13: =O13-1 -> 2017
B14: =IFERROR(D14/$D$18,"") -> 0.38445203 | C14: Foods and Sundries | D14: 85629 | E14: 77277 | F14: 68659 | G14: 59672 | H14: 56073 | I14: 52362 | K14: =(D14-E14)/E14 -> 0.10807873 | L14: =(E14-F14)/F14 -> 0.12551887 | M14: =(F14-G14)/G14 -> 0.15060665 | N14: =(G14-H14)/H14 -> 0.064184188 | O14: =(H14-I14)/I14 -> 0.070872006
B15: =IFERROR(D15/$D$18,"") -> 0.27432317 | C15: Non-Foods | D15: 61100 | E15: 55966 | F15: 44807 | G15: =24570+16590 -> 41160 | H15: =22620+15387 -> 38007 | I15: =20583+14537 -> 35120 | K15: =(D15-E15)/E15 -> 0.091734267 | L15: =(E15-F15)/F15 -> 0.24904591 | M15: =(F15-G15)/G15 -> 0.088605442 | N15: =(G15-H15)/H15 -> 0.082958402 | O15: =(H15-I15)/I15 -> 0.082203872
B16: =IFERROR(D16/$D$18,"") -> 0.13256858 | C16: Fresh Foods | D16: 29527 | E16: 27183 | F16: 23204 | G16: 19948 | H16: 18879 | I16: 17849 | K16: =(D16-E16)/E16 -> 0.086230365 | L16: =(E16-F16)/F16 -> 0.17147906 | M16: =(F16-G16)/G16 -> 0.16322438 | N16: =(G16-H16)/H16 -> 0.056623762 | O16: =(H16-I16)/I16 -> 0.057706314
B17: =IFERROR(D17/$D$18,"") -> 0.20865622 | C17: Warehouse Ancillary and Other Businesses | D17: 46474 | E17: 31626 | F17: 26550 | G17: 28571 | H17: 25475 | I17: 20841 | K17: =(D17-E17)/E17 -> 0.46948713 | L17: =(E17-F17)/F17 -> 0.19118644 | M17: =(F17-G17)/G17 -> -0.070736061 | N17: =(G17-H17)/H17 -> 0.12153091 | O17: =(H17-I17)/I17 -> 0.22235018
B18: =SUM(B14:B17) -> 1 | C18: TOTAL | D18: =SUM(D14:D17) -> 222730 | E18: =SUM(E14:E17) -> 192052 | F18: =SUM(F14:F17) -> 163220 | G18: =SUM(G14:G17) -> 149351 | H18: =SUM(H14:H17) -> 138434 | I18: =SUM(I14:I17) -> 126172 | K18: =(D18-E18)/E18 -> 0.15973799 | L18: =(E18-F18)/F18 -> 0.17664502 | M18: =(F18-G18)/G18 -> 0.092861782 | N18: =(G18-H18)/H18 -> 0.078860685 | O18: =(H18-I18)/I18 -> 0.097184795 | P18: 0.037
B20: Categories | D20: Description | I20: Graphs
B21: Foods and Sundries | D21: This categorie includes sundries, dry grocery, candy, cooler, freezer, deli, liquor and tobacco
B22: Non-Foods | D22: Including major appliances, electronics, health and beauty aids, hardware, garden and patio, sporting goods, tires, toys and seasonal, office supplies, automotive care, postage, tickets, apparel, small appliances, furniture, domestics, housewares, special order kiosk and jewelry
B23: Fresh Foods | D23: including meat, produce, service deli and bakery
B24: Warehouse Ancillary and Other Businesses | D24: Warehouse ancillary includes gasoline, pharmacy, optical, food court, hearing aids and tire installation. Other Businesses includes e-commerce, business centers, travel and other
B28: Industry | J28: Graphs (Industry Forecasts)
B29: Drivers | D29: Description
B30: Consumer preferences | D30: Consumer Staples are in constant demand. Usually, economic cycles do not affect this sector, what makes the demand stable and predictable. Also, in 2022, consumer staples earned its reputation as a defensive sector, by outperforming the broad market.
B31: Merchandise Quality and Selection
B32: Distribution Strategy
B33: Price competition | D33: Price competition strategies are common in the sector, which requires economies of scale, as well as, some market share stability.
B34: Sales forecast
B35: Source | D35: Market Growth CGAR | G35: Period
B36: https://simplywall.st/markets/us/consumer-staples | D36: 0.12 | G36: 2023-2027
B40: Company's Strategy / Extra Notes

Sheet Acuerdo
A1: Invertir
A2: NO invertir
A3: Mantener sin elevar posición
A4: Mantener (y seguir comprando)
A5: Liquidar
A6: PENDIENTE

Sheet Peers
B1: Peer Logo | C1: Peer Name | D1: Description
C2: =D8 -> #VALUE! | D2: With over 11,500 stores globally, Walmart is the largest retailer chain in the world and the top Costco competitor in 2021. The retail giant was founded in 1962 by Sam Walton and now employs over 2 million people across 27 countries. In FY2020, Walmart’s annual revenue was $524.4 billion and ranked 19th most valuable brand in the world on Forbes’ Global 2000 list. Walmart offers apparel, appliances, electronics, home improvement, jewelry, games, household essentials, pharmaceutical products, and many more. It also owns Sam’s Club, which a membership-only wholesaler that competes against Costco for bulk buyers. Walmart is Costco’s top competitor for many reasons.
C3: =E8 -> #VALUE! | D3: Established in 1994 by Jeff Bezos, Amazon has grown to become the global powerhouse in the eCommerce sector. Costco’s private labels like Kirkland accounts for 25% of its $118.7 billion in annual sales. Amazon has invested heavily to expand its private-label offerings and currently has 146 private-label brands and 640 exclusive brands. These private labels can eliminate Costco’s main competitive edge. According to a price comparison by Cheapism, items offered by Costco are about 25% cheaper on average compared to Amazon’s prices. Offering consumers value for money can help Costco fend off Amazon’s threat.
C4: =F8 -> #VALUE! | D4: Founded in 1883 in Ohio, Kroger is one of the largest food retailers in the world. The retailer operates over 2,764 supermarkets across 35 states in the US. In 2018, Kroger’s partnership with online retailer Ocado delivered 20 automated fulfillment centers, more than 2,000 pickup locations, and 2,400 delivery locations by 2020. These resources expanded Kroger’s reach to 97% of its customers and boosted its revenue for Q1 2020 by 11.5% year-over-year to $41.5 billion. Kroger has also built a stronger eCommerce than Costco, which boosted its digital sales by 92% in 2020. Kroger’s fulfillment centers and robust eCommerce makes it one of the top Costco competitors in 2021.
C5: =G8 -> #VALUE! | D5: Simply known as Walgreens, WBA was founded in 1901 by Charles Walgreen and provides drug store services primarily in the U.S. and Europe. It has 400 distribution centers and more than 18,750 stores spread across 11 countries. Every year, the chain’s distribution centers reach more than 25,000 pharmacies, doctors, hospitals, and health centers across the world. In 2020, footfall in its stores dropped by about 85% due to the crisis leading to a net loss of $1.71 billion in the third quarter. Its overdependence on medical services is a major weakness over Costco.
C6: =H8 -> #VALUE! | D6: Founded in 1902, Target is one of the largest retailers in the world and a strong Costco competitor. It operates over 1,000 stores in the US alone and 360,000 employees spread across 50 states. Even though both Target and Costco are offering in-store and curbside pickup, Target’s initiatives are more effective and include Shipt, Drive Up services, and Target+ marketplace. In 2020, Target’s gross margins averaged out to 29%, while Costco’s gross margins were only 13%. Target also has a membership program just like Costco. But Target does not charge annual membership fees, which gives it an edge over Costco.
B8: In Millions USD (exc Market Cap) | C8: =OP!E2 -> #VALUE! | D8: #VALUE! | E8: #VALUE! | F8: #VALUE! | G8: #VALUE! | H8: #VALUE! | I8: AVERAGE
B9: Company Info | I9: =IFERROR(AVERAGE(C9:H9),"")
B10: Market Cap | C10: {=_FV(C8,"Market cap",TRUE)/1000000} -> 373687.1 | D10: {=_FV(D8,"Market cap",TRUE)/1000000} -> 556934.9 | E10: {=_FV(E8,"Market cap",TRUE)/1000000} -> 2023985 | F10: {=_FV(F8,"Market cap",TRUE)/1000000} -> 37886.8 | G10: {=_FV(G8,"Market cap",TRUE)/1000000} -> 9927.663 | H10: {=_FV(H8,"Market cap",TRUE)/1000000} -> 70714 | I10: =IFERROR(AVERAGE(C10:H10),"") -> 512189.24
B11: Net Sales (current) | C11: =C53 -> 226954 | D11: =D53 -> 611289 | E11: =E53 -> 513983 | F11: =F53 -> 148258 | G11: =G53 -> 133291 | H11: =H53 -> 109120 | I11: =IFERROR(AVERAGE(C11:H11),"") -> 290482.5
B12: Profitability | I12: =IFERROR(AVERAGE(C12:H12),"")
B13: Sales Growth (ttm) | C13: =C53/C52-1 -> 0.15834818 | D13: =D53/D52-1 -> 0.067280194 | E13: =E53/E52-1 -> 0.093995173 | F13: =F53/F52-1 -> 0.075205964 | G13: =G53/G52-1 -> 0.0044309473 | H13: =H53/H52-1 -> 0.029385406 | I13: =IFERROR(AVERAGE(C13:H13),"") -> 0.071440977
B14: Sales Growth (36m) | C14: =C53/C51-1 -> 0.48624454 | D14: =D53/D51-1 -> 0.16666221 | E14: =E53/E51-1 -> 0.83223776 | F14: =F53/F51-1 -> 0.21237744 | G14: =G53/G51-1 -> -0.044762321 | H14: =H53/H51-1 -> 0.39696846 | I14: =IFERROR(AVERAGE(C14:H14),"") -> 0.34162135
B15: Operating Margin | C15: =C56/C53 -> 0.034337355 | D15: =D56/D53 -> 0.033417909 | E15: =E56/E53 -> 0.023829582 | F15: =F56/F53 -> 0.027829864 | G15: =G56/G53 -> -0.055817722 | H15: =H56/H53 -> 0.03526393 | I15: =IFERROR(AVERAGE(C15:H15),"") -> 0.016476819
B16: Net Income Margin | C16: =C59/C53 -> 0.025749711 | D16: =D59/D53 -> 0.019107165 | E16: =E59/E53 -> 0.005295895 | F16: =F59/F53 -> 0.015135777 | G16: =G59/G53 -> -0.023587489 | H16: =H59/H53 -> 0.02547654 | I16: =IFERROR(AVERAGE(C16:H16),"") -> 0.011196267
B17: Return on Equity (RoE) | C17: =C59/C70 -> 0.2831121 | D17: =D59/D70 -> 0.13940609 | E17: =E59/E70 -> 0.018638346 | F17: =F59/F70 -> 0.22408628 | G17: =G59/G70 -> -0.10339384 | H17: =H59/H70 -> 0.24750712 | I17: =IFERROR(AVERAGE(C17:H17),"") -> 0.13489268
B18: Return on Invested Capital (ROIC) | C18: =(C59+C58)/(C69+C70) -> 0.24625967 | D18: =(D59+D58)/(D69+D70) -> 0.14695229 | E18: =(E59+E58)/(E69+E70) -> 0.040611089 | F18: =(F59+F58)/(F69+F70) -> 0.45443306 | G18: =(G59+G58)/(G69+G70) -> -0.13025727 | H18: =(H59+H58)/(H69+H70) -> 0.22972725 | I18: =IFERROR(AVERAGE(C18:H18),"") -> 0.16462101
B19: Solvency | I19: =IFERROR(AVERAGE(C19:H19),"")
B20: Debt/Assets | C20: =C69/C66 -> 0.1699654 | D20: =D69/D66 -> 0.14247297 | E20: =E69/E66 -> 0.14513427 | F20: =F69/F66 -> 0.026399049 | G20: =G69/G66 -> 0.39364653 | H20: =H69/H66 -> 0.30015937 | I20: =IFERROR(AVERAGE(C20:H20),"") -> 0.19629627
B21: Net Debt/EBITDA | C21: =(C69-C61)/C55 -> -0.0055977452 | D21: =(D69-D61)/D55 -> 0.86490079 | E21: =(E69-E61)/E55 -> 0.34579683 | F21: =(F69-F61)/F55 -> 0.026083238 | G21: =(G69-G61)/G55 -> -11.184344 | H21: =(H69-H61)/H55 -> 2.0891449 | I21: =IFERROR(AVERAGE(C21:H21),"") -> -1.3106694
B22: Interest Coverage Ratio | C22: =-C55/C57 -> -263.36082 | D22: =-D55/D57 -> 16.05603 | E22: =-E55/E57 -> 27.83164 | F22: =-F55/F57 -> 13.114019 | G22: =-G55/G57 -> -6.332618 | H22: =-H55/H57 -> 13.799163 | I22: =IFERROR(AVERAGE(C22:H22),"") -> -33.148765
B23: Liquidity
B24: Current Ratio | C24: =C64/C68 -> 1.0218139 | D24: =D64/D68 -> 0.82057095 | E24: =E64/E68 -> 0.94464358 | F24: =F64/F68 -> 0.73500406 | G24: =G64/G68 -> 0.74843909 | H24: =H64/H68 -> 0.91517949 | I24: =IFERROR(AVERAGE(C24:H24),"") -> 0.86427517
B25: Quick Ratio | C25: =(C61+C62)/C68 -> 0.41533846 | D25: =(D61+D62)/D68 -> 0.17959175 | E25: =(E61+E62)/E68 -> 0.55844858 | F25: =(F61+F62)/F68 -> 0.19497622 | G25: =(G61+G62)/G68 -> 0.33162113 | H25: =(H61+H62)/H68 -> 0.17425641 | I25: =IFERROR(AVERAGE(C25:H25),"") -> 0.30903876
B26: Activity | I26: =IFERROR(AVERAGE(C26:H26),"")
B27: Inventory Turnover | C27: =C54/C63 -> 11.134305 | D27: =D54/D63 -> 8.196426 | E27: =E54/E63 -> 12.973202 | F27: =F54/F63 -> 15.407407 | G27: =G54/G63 -> 12.725847 | H27: =H54/H63 -> 6.091037 | I27: =IFERROR(AVERAGE(C27:H27),"") -> 11.088037
B28: Acc. Receivable Turnover | C28: =C53/C62 -> 101.27354 | D28: =D53/D62 -> 77.056473 | E28: =E53/E62 -> 15.626858 | F28: =F53/F62 -> 66.364369 | G28: =G53/G62 -> 26.567869 | H28: =H53/H62 -> 93.344739 | I28: =IFERROR(AVERAGE(C28:H28),"") -> 63.372308
A29: Price/Sales | B29: Payables Turnover | C29: =C54/C67 -> 11.171112 | D29: =D54/D67 -> 8.6286517 | E29: =E54/E67 -> 5.6073241 | F29: =F54/F67 -> 16.361849 | G29: =G54/G67 -> 9.3746362 | H29: =H54/H67 -> 6.0969081 | I29: =IFERROR(AVERAGE(C29:H29),"") -> 9.5400801
B30: Fixed Asset Turnover | C30: =C53/C65 -> 5.1201101 | D30: =D53/D65 -> 3.6485717 | E30: =E53/E65 -> 3.2067619 | F30: =F53/F65 -> 5.9960366 | G30: =G53/G65 -> 1.9255583 | H30: =H53/H65 -> 3.1405054 | I30: =IFERROR(AVERAGE(C30:H30),"") -> 3.8395907
B31: Total Asset Turnover | C31: =C53/C66 -> 3.5369822 | D31: =D53/D66 -> 2.5135549 | E31: =E53/E66 -> 1.1108943 | F31: =F53/F66 -> 2.9876872 | G31: =G53/G66 -> 1.4789734 | H31: =H53/H66 -> 2.0459361 | I31: =IFERROR(AVERAGE(C31:H31),"") -> 2.2790047
B32: Valuation | I32: =IFERROR(AVERAGE(C32:H32),"")
B33: Price/Earnings | C33: =C10/C59 -> 63.94372 | D33: =D10/D59 -> 47.682783 | E33: =E10/E59 -> 743.56539 | F33: =F10/F59 -> 16.883601 | G33: =G10/G59 -> -3.1576536 | H33: =H10/H59 -> 25.436691 | I33: =IFERROR(AVERAGE(C33:H33),"") -> 149.05909
B34: Price/Sales | C34: =C10/C53 -> 1.6465323 | D34: =D10/D53 -> 0.91108281 | E34: =E10/E53 -> 3.9378442 | F34: =F10/F53 -> 0.25554641 | G34: =G10/G53 -> 0.07448112 | H34: =H10/H53 -> 0.64803886 | I34: =IFERROR(AVERAGE(C34:H34),"") -> 1.2455876
B35: Price/Book | C35: =C10/C70 -> 18.103241 | D35: =D10/D70 -> 6.6472704 | E35: =E10/E70 -> 13.858829 | F35: =F10/F70 -> 3.7833833 | G35: =G10/G70 -> 0.32648195 | H35: =H10/H70 -> 6.2957621 | I35: =IFERROR(AVERAGE(C35:H35),"") -> 8.1691613
B36: EV/Sales | C36: =(C69+C10-C61)/C53 -> 1.6459023 | D36: =(D69+D10-D61)/D53 -> 0.95365515 | E36: =(E69+E10-E61)/E53 -> 3.9636467 | F36: =(F69+F10-F61)/F53 -> 0.25678075 | G36: =(G69+G10-G61)/G53 -> 0.32209724 | H36: =(H69+H10-H61)/H53 -> 0.77432185 | I36: =IFERROR(AVERAGE(C36:H36),"") -> 1.3194006
B37: EV/EBITDA | C37: =(C69+C10-C61)/C55 -> 14.622411 | D37: =(D69+D10-D61)/D55 -> 19.374486 | E37: =(E69+E10-E61)/E55 -> 53.119707 | F37: =(F69+F10-F61)/F55 -> 5.4261403 | G37: =(G69+G10-G61)/G55 -> -14.548513 | H37: =(H69+H10-H61)/H55 -> 12.809885 | I37: =IFERROR(AVERAGE(C37:H37),"") -> 15.134019
B38: Stock Info | I38: =IFERROR(AVERAGE(C38:H38),"")
B39: Float | C39: =OP!M20 -> 0.99738238 | D39: 0.989 | E39: 0.989 | F39: 0.9718 | G39: 0.948 | H39: 0.9789 | I39: =IFERROR(AVERAGE(C39:H39),"") -> 0.97901373
B40: b (Yahoo) | C40: =OP!M22 -> 0.79 | D40: 0.5 | E40: 1.26 | F40: 0.48 | G40: 0.67 | H40: 1.01 | I40: =IFERROR(AVERAGE(C40:H40),"") -> 0.59
B41: Dividend Yield (yahoo finance) | C41: =OP!M32 -> 0.0040087017 | D41: 1.45% | E41: 0 | F41: 0.0241 | G41: 6.27% | H41: 3.23% | I41: =IFERROR(AVERAGE(C41:H41),"") -> 0.0093695672
...

Sheet ESG
B1: Company GICS Sector: | T1: Yes
B2: Consumer Staples | C2: <- Select Industry | T2: No
B3: ESG Analysis | K3: Relative ESG Analysis
B4: Parameters | C4: Impact | D4: Do they report? | E4: Ranking | F4: Mitigation Plan | G4: Traffic Lights | H4: Improvement over time? | I4: Targets / Goals? | J4: Comments | K4: Parameters | L4: Costco | M4: Walmart | N4: Amazon | O4: Kroger | P4: Walgreens | Q4: Target
B5: Environmental | K5: Ratios
A6: 1 | B6: CO2 Direct Emissions | C6: =VLOOKUP($B$2,'Sector Impact'!$K$4:$AA$16,A6+1,FALSE) -> High | D6: Yes | E6: Medium High | F6: Yes | H6: High | I6: 39% cumulative absolute CO2 reduction 2030 | J6: “We align our decarbonization objectives with our commitments to human rights, diversity, equity and inclusion, life above land and below water, water conservation, and waste reduction,” the company’s mission statement says. | K6: CO2 Emissions/$M Sales | L6: =L12/L$11 -> 0.00063625228 | M6: =M12/M$11 -> 0.00022886065 | N6: =N12/N$11 -> 0.00013866217 | O6: =O12/O$11 -> 0.035417988 | P6: =P12/P$11 -> 0.011831256 | Q6: =Q12/Q$11 -> 0.015460044
A7: 2 | B7: Total Water Consumption | C7: =VLOOKUP($B$2,'Sector Impact'!$K$4:$AA$16,A7+1,FALSE) -> Very High | D7: Yes | E7: Medium | F7: Yes | H7: HIgh | J7: Costco is committed to improving water use efficiency and reducing operational water waste. | K7: Water Consumption/$M Sales | L7: =L13/L$11 -> 73.92 | M7: =M13/M$11 -> 0 | N7: =N13/N$11 -> 0 | O7: =O13/O$11 -> 0 | P7: =P13/P$11 -> 0 | Q7: =Q13/Q$11 -> 0.10446298
A8: 3 | B8: Total Energy Consumption | C8: =VLOOKUP($B$2,'Sector Impact'!$K$4:$AA$16,A8+1,FALSE) -> High | D8: Yes | E8: Medium High | F8: Yes | H8: High | K8: Energy Consumption/$M Sales | L8: =L14/L$11 -> 0 | M8: =M14/M$11 -> 0 | N8: =N14/N$11 -> 0 | O8: =O14/O$11 -> 79.108804 | P8: =P14/P$11 -> 0 | Q8: =Q14/Q$11 -> 184.68824
A9: 4 | B9: Waste Management | C9: =VLOOKUP($B$2,'Sector Impact'!$K$4:$AA$16,A9+1,FALSE) -> High | D9: Yes | E9: Medium | F9: Yes | H9: Medium | I9: "We have a goal to divert 80% of what might otherwise end up in a landfill, by reducing waste through donations, recycling and composting." | J9: Costco’s goal is to continually decrease the amount of waste going to landfills through reducing food waste at source, feeding hungry people and animals, supporting industrial programs (i.e., biofuel), composting and other recycling and donation programs. | K9: Waste Production/$M Sales | L9: =L15/L$11 -> 0 | M9: =M15/M$11 -> 0 | N9: =N15/N$11 -> 0 | O9: =O15/O$11 -> 0.018730861 | P9: =P15/P$11 -> 0.0018080741 | Q9: =Q15/Q$11 -> 0
A10: 5 | B10: Land Degradation/Deforestation/Biodiversity loss/Animal sufering/… | C10: =VLOOKUP($B$2,'Sector Impact'!$K$4:$AA$16,A10+1,FALSE) -> High | D10: No | K10: Inputs
B11: Social | K11: Net Sales ($M) | L11: 226954 | M11: 611289 | N11: 513983 | O11: 148258 | P11: 133291 | Q11: 109120
A12: 6 | B12: Employee Turnover % | C12: =VLOOKUP($B$2,'Sector Impact'!$K$4:$AA$16,A12+1,FALSE) -> Medium | D12: Yes | E12: "Best in class" | F12: Yes | H12: Over 60% of U.S. employees have five or more years with Costco, and over one-third have more than 10 years | J12: With respect to the compensation of their employees, the philosophy is not to seek to minimize their wages and benefits. Rather, Cosco believes that achieving their longer-term objectives of reducing employee turnover and enhancing employee satisfaction requires maintaining compensation levels that are better than the industry average for much of our workforce | K12: CO2 Emissions Total (Tonnes) | L12: 144.4 | M12: 139.9 | N12: 71.27 | O12: 5251 | P12: 1577 | Q12: 1687
A13: 7 | B13: Salaries & Compensation | C13: =VLOOKUP($B$2,'Sector Impact'!$K$4:$AA$16,A13+1,FALSE) -> High | D13: Yes | E13: Medium High | J13: The employees are the foundation of Costco’s business, the heart of the Company’s culture, and the driver for their success. In the spirit of acknowledging and rewarding the excellence of employees, in fiscal 2022, they instituted several wage increases and provided additional benefits to the majority of their employees. | K13: Water Consumption Total (Cubic Meters) | L13: =73.92*'Fin. Data'!B5 -> 16776440 | Q13: 11399
A14: 8 | B14: Reputation | C14: =VLOOKUP($B$2,'Sector Impact'!$K$4:$AA$16,A14+1,FALSE) -> High | D14: No | E14: Medium High | K14: Energy Consumption Total (Gigajoules) | O14: 11728513 | Q14: 20153181
A15: 9 | B15: Discrimination Events | C15: =VLOOKUP($B$2,'Sector Impact'!$K$4:$AA$16,A15+1,FALSE) -> Low | F15: Yes | K15: Waste Production Total (Tonnes) | O15: 2777 | P15: 241
A16: 10 | B16: Work Safety | C16: High | K16: ESG Scores
A17: 11 | B17: Damage to consumer health | C17: =VLOOKUP($B$2,'Sector Impact'!$K$4:$AA$16,A17+1,FALSE) -> Medium | K17: Refinitiv | L17: 72 | M17: 83 | N17: 81 | O17: 85 | P17: 90 | Q17: 85
A18: 12 | B18: PXP? | C18: =VLOOKUP($B$2,'Sector Impact'!$K$4:$AA$16,A18+1,FALSE) -> Low | K18: Sustainalytics | L18: 23.6 | M18: 16.3 | N18: 30.5 | O18: 21.3 | P18: 16.3 | Q18: 14.4
A19: 13 | B19: Supply chain | C19: =VLOOKUP($B$2,'Sector Impact'!$K$4:$AA$16,A19+1,FALSE) -> High | K19: ISS | L19: C- | M19: C- | N19: C- | O19: C | P19: C | Q19: C+
A20: 14 | B20: Community involvement | C20: =VLOOKUP($B$2,'Sector Impact'!$K$4:$AA$16,A20+1,FALSE) -> Low | K20: CDP | L20: D | M20: C | O20: B- | P20: B | Q20: A-
A21: 15 | B21: Public Sector | C21: =VLOOKUP($B$2,'Sector Impact'!$K$4:$AA$16,A21+1,FALSE) -> Very High
A22: 16 | B22: Litigation | C22: =VLOOKUP($B$2,'Sector Impact'!$K$4:$AA$16,A22+1,FALSE) -> Low | D22: Yes
B23: Corporate Governance | K23: PARAMETERS
A24: 17 | B24: Diversity (Gender, Age, Industry, Region) | E24: "Villain" | F24: Yes | K24: IMPACT | L24: RANKING | M24: MITIGATION PLAN
A25: 18 | B25: % Independence | E25: Medium | J25: In 2022, they appointed a new Chief Diversity and Inclusion Officer. Embracing differences is important to the growth of their Company. It leads to more opportunities, innovation, and employee satisfaction and connects us to the communities where they do business. | K25: Low | L25: "Best in class" | M25: Evidence / plan?
A26: 19 | B26: average time as independent directors | E26: "Villain" | K26: Medium | L26: Medium High
A27: 20 | B27: Recent departures of directors / C-level executives? | E27: Medium | K27: High | L27: Medium
A28: 21 | B28: CEO/Chairman duality | E28: "Villain" | K28: Very high | L28: "Villain"
A29: 22 | B29: Transparency (ESG, segments, acquisitions, other)
A30: 23 | B30: Time taken to report after the end of the quarter / year
A31: 24 | B31: Additional participation of the CEO in other boards or excessive participation of Ch.
A32: 25 | B32: Audit / Consulting
A33: 26 | B33: ESG-compensation related
A34: 27 | B34: Management compensation schemes

Sheet DCF
A1: VALUATION MODEL
G3: Short Term | K3: Long Term
A4: Section | B4: Line # | C4: ITEM | D4: 2020 (Real) | E4: 2021 (Real) | F4: 2022 (Real) | G4: 2023 | H4: =G4+1 -> 2024 | I4: =H4+1 -> 2025 | J4: =I4+1 -> 2026 | K4: =J4+1 -> 2027 | L4: =K4+1 -> 2028 | M4: =L4+1 -> 2029 | N4: =M4+1 -> 2030 | O4: =N4+1 -> 2031 | ... AF4: =AE4+1 -> 2048
A5: INCOME STATEMENT | B5: 1 | C5: Growth | D5: ='Fin. Data'!D6 -> 0.09206106 | E5: =+E6/D6-1 -> 0.174909 | F5: =+F6/E6-1 -> 0.15834818 | G5: =+G6/F6-1 -> 0.062 | H5: =+H6/G6-1 -> 0.05 | I5: =+I6/H6-1 -> 0.070178785 | J5: =+J6/I6-1 -> 0.050089392 | K5: =+K6/J6-1 -> 0.03 | L5: =+L6/K6-1 -> 0.063846173 | ... AF5: =+AF6/AE6-1 -> 0.031846173
B6: 2 | C6: Revenues/Sales | D6: ='Fin. Data'!D5 -> 166761 | E6: ='Fin. Data'!C5 -> 195929 | F6: ='Fin. Data'!B5 -> 226954 | G6: ='Assumptions '!I23 -> 241025.15 | H6: ='Assumptions '!J23 -> 253076.41 | I6: ='Assumptions '!K23 -> 270837 | J6: ='Assumptions '!L23 -> 284403.06 | K6: ='Assumptions '!M23 -> 292935.15 | L6: ='Assumptions '!N23 -> 311637.94 | M6: ='Assumptions '!O23 -> 328897.89 | N6: ='Assumptions '!P23 -> 345026.54 | ... AF6: ='Assumptions '!AH23 -> 705773.25
B7: 3 | C7: EBIT/Operating Margin | D7: =D8/D6 -> 0.032591553 | E7: =E8/E6 -> 0.034236892 | F7: =F8/F6 -> 0.034337355 | G7: ='Assumptions '!I36 -> 0.02634165 | H7: ='Assumptions '!J36 -> 0.027126195 | I7: ='Assumptions '!K36 -> 0.027570088 | J7: ='Assumptions '!L36 -> 0.027291366 | K7: ='Assumptions '!M36 -> 0.027012644 | L7: ='Assumptions '!N36 -> 0.030475821 | M7: ='Assumptions '!O36 -> 0.026436856 | N7: ='Assumptions '!P36 -> 0.023407632 | ... AF7: ='Assumptions '!AH36 -> 0.016783516
B8: 4 | C8: EBIT | D8: ='Fin. Data'!D11 -> 5435 | E8: ='Fin. Data'!C11 -> 6708 | F8: ='Fin. Data'!B11 -> 7793 | G8: =G6*G7 -> 6349 | H8: =H6*H7 -> 6865 | I8: =I6*I7 -> 7467 | J8: =J6*J7 -> 7761.7481 | K8: =K6*K7 -> 7912.9531 | L8: =L6*L7 -> 9497.4223 | M8: =M6*M7 -> 8695.0263 | N8: =N6*N7 -> 8076.2544 | ... AF8: =AF6*AF7 -> 11845.357
B9: 5a | C9: (Dep) | D9: -1900 | E9: -1781 | F9: -1645 | G9: =-'Assumptions '!I57 -> -2277.5339 | H9: =-'Assumptions '!J57 -> -2391.4106 | I9: =-'Assumptions '!K57 -> -2559.2369 | J9: =-'Assumptions '!L57 -> -2687.4275 | K9: =-'Assumptions '!M57 -> -2768.0503 | L9: =-'Assumptions '!N57 -> -2793.2234 | M9: =-'Assumptions '!O57 -> -2818.6254 | N9: =-'Assumptions '!P57 -> -2844.2584 | ... AF9: =-'Assumptions '!AH57 -> -3310.3729
B10: 5b | C10: Amort | D10: 0 | E10: 0 | F10: 0 | G10: =F38*(-$D$54) -> -9.3832166 | H10: =G38*(-$D$54) -> -9.471882 | I10: =H38*(-$D$54) -> -9.5613853 | J10: =I38*(-$D$54) -> -9.6517342 | K10: =J38*(-$D$54) -> -9.742937 | L10: =K38*(-$D$54) -> -9.8350015 | M10: =L38*(-$D$54) -> -9.927936 | N10: =M38*(-$D$54) -> -10.021749 | ... AF10: =AE38*(-$D$54) -> -11.870396
B11: 5c | C11: (Stock based compensation) | D11: =-D20 -> -619 | E11: =-E20 -> -665 | F11: =-F20 -> -724 | G11: =-'Assumptions '!I82 -> -869.37632 | H11: =-'Assumptions '!J82 -> -912.84514 | I11: =-'Assumptions '!K82 -> -976.9075 | J11: =-'Assumptions '!L82 -> -1025.8402 | K11: =-'Assumptions '!M82 -> -1056.6154 | L11: =-'Assumptions '!N82 -> -1060.4266 | M11: =-'Assumptions '!O82 -> -1064.2516 | N11: =-'Assumptions '!P82 -> -1068.0903 | ... AF11: =-'Assumptions '!AH82 -> -1139.6046
B12: 6 | C12: EBITDA | D12: =D8-D9-D10 -> 7335 | E12: =E8-E9-E10 -> 8489 | F12: =F8-F9-F10 -> 9438 | G12: =G8-G9-G10 -> 8635.9171 | H12: =H8-H9-H10 -> 9265.8825 | I12: =I8-I9-I10 -> 10035.798 | J12: =J8-J9-J10 -> 10458.827 | K12: =K8-K9-K10 -> 10690.746 | ... AF12: =AF8-AF9-AF10 -> 15167.6
B13: 7 | C13: (Net financing cost) | D13: =-'Fin. Data'!D14 -> -71 | E13: =-'Fin. Data'!C14 -> -130 | F13: =-'Fin. Data'!B14 -> -97 | G13: =F43*$D$58-F44*$D$57 -> 72.10592 | H13: =G43*$D$58-G44*$D$57 -> 8.7244583 | I13: =H43*$D$58-H44*$D$57 -> 137.50118 | J13: =I43*$D$58-I44*$D$57 -> 287.81482 | K13: =J43*$E$58-J44*$E$57 -> 412.14337 | L13: =K43*$E$58-K44*$E$57 -> 566.88107 | M13: =L43*$E$58-L44*$E$57 -> 755.75103 | N13: =M43*$E$58-M44*$E$57 -> 907.21603 | O13: =N43*$E$58-N44*$E$57 -> 1050.756 | P13: =O43*$E$58-O44*$E$57 -> 1189.3487 | Q13: =P43*$E$58-P44*$E$57 -> 1278.9986 | R13: =Q43*$E$58-Q44*$E$57 -> 1448.2725 | ... AF13: =AE43*$E$58-AE44*$E$57 -> 12380.629
B14: 8 | C14: Other income/(cost) | D14: =-160+89-71+7-4 -> -139 | E14: =-171+41-130+56+46 -> -158 | F14: =-158+61-97+106+38 -> -50 | G14: =AVERAGE(D14:F14)*(1+G5) -> -122.838 | H14: =AVERAGE(E14:G14)*(1+H5) -> -115.7933 | I14: =AVERAGE(F14:H14)*(1+I5) -> -102.96236 | J14: =AVERAGE(G14:I14)*(1+J5) -> -119.56796 | K14: =AVERAGE(H14:J14)*(1+K5) -> -116.15778 | L14: =AVERAGE(I14:K14)*(1+L5) -> -120.10401 | M14: =AVERAGE(J14:L14)*(1+M5) -> -125.17908 | N14: =AVERAGE(K14:M14)*(1+N5) -> -126.38846 | ... AF14: =AVERAGE(AC14:AE14)*(1+AF5) -> -180.80622
B15: 9 | C15: Earnings before taxes | D15: =D8+D13+D14 -> 5225 | E15: =E8+E13+E14 -> 6420 | F15: =F8+F13+F14 -> 7646 | G15: =G8+G13+G14 -> 6298.2679 | H15: =H8+H13+H14 -> 6757.9312 | I15: =I8+I13+I14 -> 7501.5388 | J15: =J8+J13+J14 -> 7929.995 | K15: =K8+K13+K14 -> 8208.9387 | ... AF15: =AF8+AF13+AF14 -> 24045.179
B16: 10 | C16: (Income tax) | D16: =-'Fin. Data'!D21 -> -1308 | E16: =-'Fin. Data'!C21 -> -1601 | F16: =-'Fin. Data'!B21 -> -1925 | G16: ='Assumptions '!I47 -> 1561.073 | H16: ='Assumptions '!J47 -> 1687.9455 | I16: ='Assumptions '!K47 -> 1835.9635 | J16: ='Assumptions '!L47 -> 1886.0694 | K16: ='Assumptions '!M47 -> 1937.0172 | L16: ='Assumptions '!N47 -> 2343.7908 | M16: ='Assumptions '!O47 -> 2835.9868 | N16: ='Assumptions '!P47 -> 3431.544 | ... AF16: ='Assumptions '!AH47 -> 106078.22
B17: 11 | C17: Net income | D17: ='Fin. Data'!D23 -> 4002 | E17: ='Fin. Data'!C23 -> 5007 | F17: ='Fin. Data'!B23 -> 5844 | G17: =G16+G15 -> 7859.3409 | H17: =H16+H15 -> 8445.8767 | I17: =I16+I15 -> 9337.5023 | J17: =J16+J15 -> 9816.0644 | K17: =K16+K15 -> 10145.956 | L17: =L16+L15 -> 12287.99 | M17: =M16+M15 -> 12161.585 | N17: =N16+N15 -> 12288.626 | ... AF17: =AF16+AF15 -> 130123.4
A19: CASH FLOW STATEMENT | B19: 12 | C19: Operating cash flows before WK | D19: 4059 | E19: 5079 | F19: 5915 | G19: =G17-G10-G9-G11 -> 11015.634 | H19: =H17-H10-H9-H11 -> 11759.604 | I19: =I17-I10-I9-I11 -> 12883.208 | J19: =J17-J10-J9-J11 -> 13538.984 | K19: =K17-K10-K9-K11 -> 13980.365 | L19: =L17-L10-L9-L11 -> 16151.475 | M19: =M17-M10-M9-M11 -> 16054.39 | N19: =N17-N10-N9-N11 -> 16210.996 | ... AF19: =AF17-AF10-AF9-AF11 -> 134585.25
B20: 13 | C20: (Stock-based compensation) | D20: 619 | E20: 665 | F20: 724 | G20: =G11 -> -869.37632 | H20: =H11 -> -912.84514 | I20: =I11 -> -976.9075 | J20: =J11 -> -1025.8402 | K20: =K11 -> -1056.6154 | L20: =L11 -> -1060.4266 | M20: =M11 -> -1064.2516 | N20: =N11 -> -1068.0903 | ... AF20: =AF11 -> -1139.6046
B21: 14 | C21: (Working Capital Flows) | D21: ='Assumptions '!F72 -> -2447 | E21: ='Assumptions '!G72 -> -1378 | F21: ='Assumptions '!H72 -> 1034 | G21: ='Assumptions '!I72 -> -1360.0919 | H21: ='Assumptions '!J72 -> -1428.0965 | I21: ='Assumptions '!K72 -> -1528.3185 | J21: ='Assumptions '!L72 -> -1604.8711 | K21: ='Assumptions '!M72 -> -1653.0172 | ... AF21: ='Assumptions '!AH72 -> -1467.8001
B22: 15 | C22: -Total Operating Cash Flow | D22: =D19-D20-D21 -> 5887 | E22: =E19-E20-E21 -> 5792 | F22: =F19-F20-F21 -> 4157 | G22: =G19-G20-G21 -> 13245.103 | H22: =H19-H20-H21 -> 14100.546 | I22: =I19-I20-I21 -> 15388.434 | J22: =J19-J20-J21 -> 16169.695 | K22: =K19-K20-K21 -> 16689.997 | ... AF22: =AF19-AF20-AF21 -> 137192.66
B23: 16 | C23: (CAPEX) | D23: ='Fin. Data'!D32 -> -2810 | E23: ='Fin. Data'!C32 -> -3588 | F23: ='Fin. Data'!B32 -> -3891 | G23: =G6*$D$62 -> -4478.807 | H23: =H6*$D$62 -> -4702.7474 | I23: =I6*$D$62 -> -5032.7805 | J23: =J6*$D$62 -> -5284.8694 | K23: =K6*$E$62 -> -5303.466 | L23: =L6*$E$62 -> -5642.072 | M23: =M6*$E$62 -> -5954.556 | N23: =N6*$E$62 -> -6246.5584 | O23: =O6*$E$62 -> -6523.1488 | P23: =P6*$E$62 -> -6718.8433 | Q23: =Q6*$E$62 -> -6932.8127 | R23: =R6*$E$62 -> -7150.3965 | ... AF23: =AF6*$E$62 -> -12777.724 | AG23: =SUM(D23:AF23) -> -218954.04
B24: 17 | C24: Adq | D24: =Inputs!D66 -> -1019 | E24: ='Fin. Data'!C33 -> 101 | F24: ='Fin. Data'!B33 -> 3 | G24: =G6*$D$63 -> -208.76401 | H24: =H6*$D$63 -> -219.20221 | I24: =I6*$D$63 -> -234.58555 | J24: =J6*$D$63 -> -246.3358 | K24: =K6*$E$63 -> -315.23038 | L24: =L6*$E$63 -> -335.35663 | M24: =M6*$E$63 -> -353.93023 | N24: =N6*$E$63 -> -371.28643 | O24: =O6*$E$63 -> -387.72657 | P24: =P6*$E$63 -> -399.35837 | Q24: =Q6*$E$63 -> -412.0764 | R24: =R6*$E$63 -> -425.00927 | ... AF24: =AF6*$E$63 -> -759.48948 | AH24: =AG9-AG23 -> 218954.04
B25: 18 | C25: (Other investing flows) | D25: =Inputs!D67 -> -62 | E25: =Inputs!C67 -> -48 | F25: =Inputs!B67 -> -27 | G25: =(1+G5)*AVERAGE(D25:F25) -> -48.498 | H25: =(1+H5)*AVERAGE(E25:G25) -> -43.2243 | I25: =(1+I5)*AVERAGE(F25:H25) -> -42.351362 | J25: =(1+J5)*AVERAGE(G25:I25) -> -46.929777 | K25: =(1+K5)*AVERAGE(H25:J25) -> -45.493534 | L25: =(1+L5)*AVERAGE(I25:K25) -> -47.793173 | M25: =(1+M5)*AVERAGE(J25:L25) -> -49.327441 | N25: =(1+N5)*AVERAGE(K25:M25) -> -49.869243 | ... AF25: =(1+AF5)*AVERAGE(AC25:AE25) -> -71.408644
B26: 19 | C26: -Total Investing Flows | D26: =D23+D24+D25 -> -3891 | E26: =E23+E24+E25 -> -3535 | F26: =F23+F24+F25 -> -3915 | G26: =G23+G24+G25 -> -4736.0691 | H26: =H23+H24+H25 -> -4965.1739 | I26: =I23+I24+I25 -> -5309.7174 | J26: =J23+J24+J25 -> -5578.135 | K26: =K23+K24+K25 -> -5664.1899 | ... AF26: =AF23+AF24+AF25 -> -13608.622
B27: 20 | C27: (Flows related to leases) | D27: =Inputs!D71+Inputs!D72 -> 0 | E27: =Inputs!C71+Inputs!C72 -> 0 | F27: =Inputs!B71+Inputs!B72 -> 0 | G27: 0 | H27: 0 | I27: 0 | J27: 0 | K27: 0 | L27: 0 | M27: 0 | N27: 0 | O27: 0 | P27: 0 | Q27: 0 | R27: 0 | S27: 0 | T27: 0 | U27: 0 | V27: 0 | W27: 0 | X27: 0 | Y27: 0 | Z27: 0 | AA27: 0 | AB27: 0 | AC27: 0 | AD27: 0 | AE27: 0 | AF27: 0
B28: 21 | C28: Flows related to debt | D28: =+SUM(Inputs!D69:D70) -> 792 | E28: =+SUM(Inputs!C69:C70) -> -94 | F28: =+SUM(Inputs!B69:B70) -> -800 | G28: =G44-F44 -> -7022.7438 | H28: =H44-G44 -> 283.27239 | I28: =I44-H44 -> 346.20299 | J28: =J44-I44 -> 190.22072 | K28: =K44-J44 -> 104.2855 | L28: =L44-K44 -> 723.83865 | M28: =M44-L44 -> -349.34401 | N28: =N44-M44 -> -266.67069 | ... AF28: =AF44-AE44 -> 1475.5583
B29: 22 | C29: (Respurchases)/Issuance of stock | D29: ='Fin. Data'!D28 -> -526 | E29: ='Fin. Data'!C28 -> -808 | F29: ='Fin. Data'!B28 -> -802 | G29: =-G17*$D$65 -> -1375.1758 | H29: =-H17*$D$65 -> -1477.8039 | I29: =-I17*$D$65 -> -1633.8147 | J29: =-J17*$D$65 -> -1717.5504 | K29: =-K17*$E$65 -> -1717.5204 | L29: =-L17*$E$65 -> -2080.1267 | M29: =-M17*$E$65 -> -2058.7287 | N29: =-N17*$E$65 -> -2080.2344 | O29: =-O17*$E$65 -> -2147.9812 | P29: =-P17*$E$65 -> -1929.2997 | Q29: =-Q17*$E$65 -> -2419.3516 | R29: =-R17*$E$65 -> -2894.2702 | ... AF29: =-AF17*$E$65 -> -22027.457
B30: 23 | C30: (Dividends) | D30: ='Fin. Data'!D27 -> -1479 | E30: ='Fin. Data'!C27 -> -1318 | F30: ='Fin. Data'!B27 -> -1498 | G30: =-$D$64*G17 -> -2548.1821 | H30: =-$D$64*H17 -> -2738.3507 | I30: =-$D$64*I17 -> -3027.4366 | J30: =-$D$64*J17 -> -3182.5976 | K30: =-$E$64*K17 -> -3425.5888 | L30: =-$E$64*L17 -> -4148.8059 | M30: =-$E$64*M17 -> -4106.1276 | N30: =-$E$64*N17 -> -4149.0206 | O30: =-$E$64*O17 -> -4284.1414 | P30: =-$E$64*P17 -> -3847.9819 | Q30: =-$E$64*Q17 -> -4825.3888 | R30: =-$E$64*R17 -> -5772.6124 | ... AF30: =-$E$64*AF17 -> -43933.69
B31: 24 | C31: Other financing flows | D31: =Inputs!D75 -> -5275 | E31: =Inputs!C75 -> -2063 | F31: =Inputs!B75 -> -790 | G31: =(1+G5)*AVERAGE(D31:F31) -> -2877.312 | H31: =(1+H5)*AVERAGE(E31:G31) -> -2005.6092 | I31: =(1+I5)*AVERAGE(F31:H31) -> -2023.68 | J31: =(1+J5)*AVERAGE(G31:I31) -> -2417.5162 | K31: =(1+K5)*AVERAGE(H31:J31) -> -2213.4032 | L31: =(1+L5)*AVERAGE(I31:K31) -> -2359.8234 | M31: =(1+M5)*AVERAGE(J31:L31) -> -2459.3075 | N31: =(1+N5)*AVERAGE(K31:M31) -> -2459.1329 | ... AF31: =(1+AF5)*AVERAGE(AC31:AE31) -> -3535.0307
B32: 25 | C32: -Total Financing flows | D32: =D27+D28+D29+D30+D31 -> -6488 | E32: =E27+E28+E29+E30+E31 -> -4283 | F32: =F27+F28+F29+F30+F31 -> -3890 | G32: =G27+G28+G29+G30+G31 -> -13823.414 | H32: =H27+H28+H29+H30+H31 -> -5938.4915 | I32: =I27+I28+I29+I30+I31 -> -6338.7283 | J32: =J27+J28+J29+J30+J31 -> -7127.4435 | K32: =K27+K28+K29+K30+K31 -> -7252.2269 | ... AF32: =AF27+AF28+AF29+AF30+AF31 -> -68020.619
A34: SUMMARY | B34: 26 | C34: Cash before shareholder returns | D34: =D22+D26+D27+D28+D31 -> -2487 | E34: =E22+E26+E27+E28+E31 -> 100 | F34: =F22+F26+F27+F28+F31 -> -1348 | G34: =G22+G26+G27+G28+G31 -> -1391.0223 | H34: =H22+H26+H27+H28+H31 -> 7413.0352 | I34: =I22+I26+I27+I28+I31 -> 8401.2397 | J34: =J22+J26+J27+J28+J31 -> 8364.2647 | K34: =K22+K26+K27+K28+K31 -> 8916.6896 | ... AF34: =AF22+AF26+AF27+AF28+AF31 -> 121524.56
B35: 27 | C35: Returns to shareholders | D35: =-1*(D29+D30) -> 2005 | E35: =-1*(E29+E30) -> 2126 | F35: =-1*(F29+F30) -> 2300 | G35: =-1*(G29+G30) -> 3923.3579 | H35: =-1*(H29+H30) -> 4216.1547 | I35: =-1*(I29+I30) -> 4661.2513 | J35: =-1*(J29+J30) -> 4900.148 | K35: =-1*(K29+K30) -> 5143.1092 | ... AF35: =-1*(AF29+AF30) -> 65961.146
B36: 28 | C36: Excess cash acumulation | D36: =D34-D35 -> -4492 | E36: =E34-E35 -> -2026 | F36: =F34-F35 -> -3648 | G36: =G34-G35 -> -5314.3802 | H36: =H34-H35 -> 3196.8805 | I36: =I34-I35 -> 3739.9884 | J36: =J34-J35 -> 3464.1167 | K36: =K34-K35 -> 3773.5804 | ... AF36: =AF34-AF35 -> 55563.416
A38: BALANCE SHEET | B38: 29 | C38: Intangible assets | D38: 988 | E38: 996 | F38: 993 | G38: =+F38+(-G10) -> 1002.3832 | H38: =+G38+(-H10) -> 1011.8551 | I38: =+H38+(-I10) -> 1021.4165 | J38: =+I38+(-J10) -> 1031.0682 | K38: =+J38+(-K10) -> 1040.8112 | L38: =+K38+(-L10) -> 1050.6462 | M38: =+L38+(-M10) -> 1060.5741 | N38: =+M38+(-N10) -> 1070.5958 | ... AF38: =+AE38+(-AF10) -> 1268.0817 | AG38: =SUM(G38:AF38) -> 29386.221
B39: 30 | C39: Accumulated amorization | D39: -12896 | E39: -14166 | F39: -15286 | G39: =F39-G10 -> -15276.617 | H39: =G39-H10 -> -15267.145 | I39: =H39-I10 -> -15257.584 | J39: =I39-J10 -> -15247.932 | K39: =J39-K10 -> -15238.189 | L39: =K39-L10 -> -15228.354 | M39: =L39-M10 -> -15218.426 | N39: =M39-N10 -> -15208.404 | ... AF39: =AE39-AF10 -> -15010.918 | AG39: =SUM(G39:AF39) -> -393867.78
B40: 31 | C40: PPE+Right of use Assets | D40: =Inputs!D33 -> 38083 | E40: =Inputs!C33 -> 41258 | F40: =Inputs!B33 -> 44326 | G40: =F40+(-G23) -> 48804.807 | H40: =G40+(-H23) -> 53507.554 | I40: =H40+(-I23) -> 58540.335 | J40: =I40+(-J23) -> 63825.204 | K40: =J40+(-K23) -> 69128.67 | L40: =K40+(-L23) -> 74770.742 | M40: =L40+(-M23) -> 80725.298 | N40: =M40+(-N23) -> 86971.857 | ... AF40: =AE40+(-AF23) -> 252991.04 | AG40: =SUM(G40:AF40) -> 3492508.7
B41: 32 | C41: Accumulated depreciation | D41: -1296000 | E41: -14166000 | F41: -15286000 | G41: =F41-G9 -> -15283722 | H41: =G41-H9 -> -15281331 | I41: =H41-I9 -> -15278772 | J41: =I41-J9 -> -15276084 | K41: =J41-K9 -> -15273316 | L41: =K41-L9 -> -15270523 | M41: =L41-M9 -> -15267704 | N41: =M41-N9 -> -15264860 | ... AF41: =AE41-AF9 -> -15209243 | AG41: =SUM(G41:AF41) -> -3.9644799e+08
A43: CASH & DEBT & DISCOUNTING | B43: 33 | C43: Ending cash balance | D43: ='Fin. Data'!D39 -> 13305 | E43: =E36+D43 -> 11279 | F43: =F36+E43 -> 7631 | G43: =G36+F43 -> 2316.6198 | H43: =H36+G43 -> 5513.5004 | I43: =I36+H43 -> 9253.4887 | J43: =J36+I43 -> 12717.605 | K43: =K36+J43 -> 16491.186 | L43: =L36+K43 -> 21456.638 | ... AF43: =AF36+AE43 -> 355681.82
B44: 34 | C44: Total Debt | D44: ='Fin. Data'!D58 -> 11086 | E44: ='Fin. Data'!C58 -> 11407 | F44: ='Fin. Data'!B58 -> 10906 | G44: =G12*'Assumptions '!$H$130 -> 3883.2562 | H44: =H12*'Assumptions '!$H$130 -> 4166.5286 | I44: =I12*'Assumptions '!$H$130 -> 4512.7316 | J44: =J12*'Assumptions '!$H$130 -> 4702.9523 | K44: =K12*'Assumptions '!$H$130 -> 4807.2378 | L44: =L12*'Assumptions '!$H$130 -> 5531.0765 | M44: =M12*'Assumptions '!$H$130 -> 5181.7325 | N44: =N12*'Assumptions '!$H$130 -> 4915.0618 | ... AF44: =AF12*'Assumptions '!$H$130 -> 6820.3153
B45: 35 | C45: Discount factor | F45: =1/((1+$F$50)^G50) -> 1 | G45: =1/((1+$F$50)^G49) -> 0.90954038 | H45: =1/((1+$F$50)^H49) -> 0.8272637 | I45: =1/((1+$F$50)^I49) -> 0.75242973 | J45: =1/((1+$F$50)^J49) -> 0.68436522 | K45: =1/((1+$F$50)^K49) -> 0.6224578 | L45: =1/((1+$F$50)^L49) -> 0.5661505 | M45: =1/((1+$F$50)^M49) -> 0.51493674 | N45: =1/((1+$F$50)^N49) -> 0.46835576 | ... AF45: =1/((1+$F$50)^AF49) -> 0.084990729
...

Sheet Assumptions 
B2: Assumptions
B4: Future perspectives: | C4: Costco to increase its membership fee every 5y. The last time the company raised fees was in July 2017. Therefore, it is expected to raise it again in 2023, 2028, 2033, etc.
C5: Expeced growth opportunities on its international expansion
B8: Average Annual Net Sales Growth (past 5y) | C8: =AVERAGE(D24:H24) -> 0.12023756
B9: Forecast Annual Net Sales Growth (next 5y) | C9: 0.089
B11: Switches | E11: Scenarios
B12: Revenue | C12: 2 | E12: Conservative | G12: Base | I12: Optimistic
B13: EBIT | C13: 2 | E13: Revenue 2023 | F13: =1+($C$9-0.08) -> 1.009 | G13: Revenue 2023 | H13: =I23 -> 241025.15 | I13: Revenue 2023 | J13: =1+($C$9+0.08) -> 1.169
E14: Revenue 2027 | F14: =1+($C$9-0.08) -> 1.009 | G14: Revenue 2027 | H14: ='Inflation Projections'!E24+0.01 -> 0.03 | I14: Revenue 2027 | J14: =1+($C$9+0.08) -> 1.169
E15: EBIT 2023 | F15: 0.9 | G15: EBIT 2023 | H15: =I41 -> 0.02634165 | I15: EBIT 2023 | J15: 1.1
E16: EBIT 2027 | F16: 0.9 | G16: EBIT 2027 | H16: =AVERAGE(I41:K41) -> 0.027012644 | I16: EBIT 2027 | J16: 1.1
B19: I/S
C21: Last 5 Years | I21: Short Term Forecast
C22: 2017 | D22: 2018 | E22: 2019 | F22: 2020 | G22: 2021 | H22: 2022 | I22: 2023 | J22: =I22+1 -> 2024 | K22: =J22+1 -> 2025 | L22: =K22+1 -> 2026 | M22: =L22+1 -> 2027 | N22: =M22+1 -> 2028 | O22: =N22+1 -> 2029 | P22: =O22+1 -> 2030 | Q22: =P22+1 -> 2031 | ... AH22: =AG22+1 -> 2048
B23: Net Sales | C23: =Inputs!G6 -> 129025 | D23: =Inputs!F6 -> 141576 | E23: =Inputs!E6 -> 152703 | F23: =Inputs!D6 -> 166761 | G23: =Inputs!C6 -> 195929 | H23: =Inputs!B6 -> 226954 | I23: =H23*(1+I24) -> 241025.15 | J23: =I23*(1+J24) -> 253076.41 | K23: 270837 | L23: =K23*(1+L24) -> 284403.06 | M23: =L23*(1+M24) -> 292935.15 | N23: =M23*(1+N24) -> 311637.94 | O23: =N23*(1+O24) -> 328897.89 | P23: =O23*(1+P24) -> 345026.54 | Q23: =P23*(1+Q24) -> 360303.92 | R23: =Q23*(1+R24) -> 371113.04 | S23: =R23*(1+S24) -> 382931.57 | ... AH23: =AG23*(1+AH24) -> 705773.25
B24: % Growth | D24: =D23/C23-1 -> 0.097275722 | E24: =E23/D23-1 -> 0.078593829 | F24: =F23/E23-1 -> 0.09206106 | G24: =G23/F23-1 -> 0.174909 | H24: =H23/G23-1 -> 0.15834818 | I24: =I29 -> 0.062 | J24: =J27 -> 0.05 | K24: =K27 -> 0.070178785 | L24: =L27 -> 0.050089392 | M24: =M27 -> 0.03 | N24: =N29 -> 0.063846173 | O24: =O27 -> 0.05538463 | P24: =P27 -> 0.049038472 | Q24: =Q27 -> 0.044278854 | R24: =R27 -> 0.03 | S24: =S29 -> 0.031846173 | T24: =T27 -> 0.03138463 | U24: =U27 -> 0.031038472 | V24: =V27 -> 0.030778854 | W24: =W27 -> 0.03 | X24: =X29 -> 0.062 | Y24: =Y27 -> 0.054 | Z24: =Z27 -> 0.048 | AA24: =AA27 -> 0.0435 | AB24: =AB27 -> 0.03 | AC24: =AC29 -> 0.060153827 | AD24: =AD27 -> 0.05261537 | AE24: =AE27 -> 0.046961528 | AF24: =AF27 -> 0.042721146 | AG24: =AG27 -> 0.03 | AH24: =AH29 -> 0.031846173
B25: Actual 5y Average | H25: =AVERAGE(D24:H24) -> 0.12023756 | M25: =AVERAGE(I24:M24) -> 0.052453635 | R25: =AVERAGE(N24:R24) -> 0.048509626 | W25: =AVERAGE(S24:W24) -> 0.031009626 | AB25: =AVERAGE(X24:AB24) -> 0.0475 | AG25: =AVERAGE(AC24:AG24) -> 0.046490374
B26: Target 5y Average | M26: =C9 -> 0.089 | R26: =H9 -> 0 | W26: =M9 -> 0 | AB26: =R9 -> 0 | AG26: =W9 -> 0
B27: Annual Growth Rate | I27: =OFFSET(I27,$C$12,0) -> 0.062 | J27: =OFFSET(J27,$C$12,0) -> 0.05 | K27: =OFFSET(K27,$C$12,0) -> 0.070178785 | L27: =OFFSET(L27,$C$12,0) -> 0.050089392 | M27: =OFFSET(M27,$C$12,0) -> 0.03 | N27: =OFFSET(N27,$C$12,0) -> 0.063846173 | O27: =OFFSET(O27,$C$12,0) -> 0.05538463 | P27: =OFFSET(P27,$C$12,0) -> 0.049038472 | ... AH27: =OFFSET(AH27,$C$12,0) -> 0.031846173
B28: =E12 -> Conservative | I28: =I24 -> 0.062 | J28: =J29*($F$13) -> 0.05045 | K28: =K29*($F$13) -> 0.070810394 | L28: =L29*($F$13) -> 0.050540197 | M28: =M29*($F$13) -> 0.03027 | N28: =N24 -> 0.063846173 | O28: =O29*($F$13) -> 0.055883092 | P28: =P29*($F$13) -> 0.049479819 | Q28: =Q29*($F$13) -> 0.044677364 | R28: =R29*($F$13) -> 0.03027 | S28: =S24 -> 0.031846173 | T28: =T29*($F$13) -> 0.031667092 | U28: =U29*($F$13) -> 0.031317819 | V28: =V29*($F$13) -> 0.031055864 | W28: =W29*($F$13) -> 0.03027 | X28: =X24 -> 0.062 | Y28: =Y29*($F$13) -> 0.054486 | Z28: =Z29*($F$13) -> 0.048432 | AA28: =AA29*($F$13) -> 0.0438915 | AB28: =AB29*($F$13) -> 0.03027 | AC28: =AC24 -> 0.060153827 | AD28: =AD29*($F$13) -> 0.053088908 | AE28: =AE29*($F$13) -> 0.047384181 | AF28: =AF29*($F$13) -> 0.043105636 | AG28: =AG29*($F$13) -> 0.03027 | AH28: =AH24 -> 0.031846173
B29: =G12 -> Base | I29: 0.062 | J29: 0.05 | K29: =K23/J23-1 -> 0.070178785 | L29: =K29+($M$29-K29)/($M$22-$K$22) -> 0.050089392 | M29: =H14 -> 0.03 | N29: =(('Fin. Data'!G6-'Fin. Data'!H6))/(1+'Inflation Projections'!E24) -> 0.063846173 | O29: =N29+($R$29-N29)/($R$22-$N$22) -> 0.05538463 | P29: =O29+($R$29-O29)/($R$22-$N$22) -> 0.049038472 | Q29: =P29+($R$29-P29)/($R$22-$N$22) -> 0.044278854 | R29: 0.03 | S29: =R29+(N29-I29) -> 0.031846173 | T29: =S29+($R$29-S29)/($R$22-$N$22) -> 0.03138463 | U29: =T29+($R$29-T29)/($R$22-$N$22) -> 0.031038472 | V29: =U29+($R$29-U29)/($R$22-$N$22) -> 0.030778854 | W29: 0.03 | X29: =W29+(N29-S29) -> 0.062 | Y29: =X29+($R$29-X29)/($R$22-$N$22) -> 0.054 | Z29: =Y29+($R$29-Y29)/($R$22-$N$22) -> 0.048 | AA29: =Z29+($R$29-Z29)/($R$22-$N$22) -> 0.0435 | AB29: 0.03 | AC29: =AB29+(X29-S29) -> 0.060153827 | AD29: =AC29+($R$29-AC29)/($R$22-$N$22) -> 0.05261537 | AE29: =AD29+($R$29-AD29)/($R$22-$N$22) -> 0.046961528 | AF29: =AE29+($R$29-AE29)/($R$22-$N$22) -> 0.042721146 | AG29: 0.03 | AH29: =AG29+(X29-AC29) -> 0.031846173
B30: =I12 -> Optimistic | I30: =I24 -> 0.062 | J30: =J29*($J$13) -> 0.05845 | K30: =K29*($J$13) -> 0.082038999 | L30: =L29*($J$13) -> 0.0585545 | M30: =M29*($J$13) -> 0.03507 | N30: =N24 -> 0.063846173 | O30: =O29*($J$13) -> 0.064744632 | P30: =P29*($J$13) -> 0.057325974 | Q30: =Q29*($J$13) -> 0.051761981 | R30: =R29*($J$13) -> 0.03507 | S30: =S24 -> 0.031846173 | T30: =T29*($J$13) -> 0.036688632 | U30: =U29*($J$13) -> 0.036283974 | V30: =V29*($J$13) -> 0.035980481 | W30: =W29*($J$13) -> 0.03507 | X30: =X24 -> 0.062 | Y30: =Y29*($J$13) -> 0.063126 | Z30: =Z29*($J$13) -> 0.056112 | AA30: =AA29*($J$13) -> 0.0508515 | AB30: =AB29*($J$13) -> 0.03507 | AC30: =AC24 -> 0.060153827 | AD30: =AD29*($J$13) -> 0.061507368 | AE30: =AE29*($J$13) -> 0.054898026 | AF30: =AF29*($J$13) -> 0.049941019 | AG30: =AG29*($J$13) -> 0.03507 | AH30: =AH24 -> 0.031846173
C33: Last 5 Years | I33: Short Term Forecast
C34: 2017 | D34: 2018 | E34: 2019 | F34: 2020 | G34: 2021 | H34: 2022 | I34: 2023 | J34: =I34+1 -> 2024 | K34: =J34+1 -> 2025 | L34: =K34+1 -> 2026 | M34: =L34+1 -> 2027 | N34: =M34+1 -> 2028 | O34: =N34+1 -> 2029 | P34: =O34+1 -> 2030 | Q34: =P34+1 -> 2031 | ... AH34: =AG34+1 -> 2048
B35: EBIT | C35: =Inputs!G8 -> 4123 | D35: =Inputs!F8 -> 4526 | E35: =Inputs!E8 -> 4737 | F35: =Inputs!D8 -> 5435 | G35: =Inputs!C8 -> 6708 | H35: =Inputs!B8 -> 7793 | I35: 6349 | J35: 6865 | K35: 7467 | L35: =K35*(1+L36) -> 7670.7846 | M35: =L35*(1+M36) -> 7877.9928 | N35: =M35*(1+N36) -> 8118.0811 | O35: =N35*(1+O36) -> 8332.6977 | P35: =O35*(1+P36) -> 8527.7464 | Q35: =P35*(1+Q36) -> 8707.9864 | R35: =Q35*(1+R36) -> 8832.6844 | S35: =R35*(1+S36) -> 8995.6839 | ... AH35: =AG35*(1+AH36) -> 12787.611
B36: % of Sales | C36: =C35/C23 -> 0.031955047 | D36: =D35/D23 -> 0.031968695 | E36: =E35/E23 -> 0.031021002 | F36: =F35/F23 -> 0.032591553 | G36: =G35/G23 -> 0.034236892 | H36: =H35/H23 -> 0.034337355 | I36: =I41 -> 0.02634165 | J36: =J41 -> 0.027126195 | K36: =K41 -> 0.027570088 | L36: =L41 -> 0.027291366 | M36: =M41 -> 0.027012644 | N36: =N41 -> 0.030475821 | O36: =O41 -> 0.026436856 | P36: =P41 -> 0.023407632 | ... S36: =S41 -> 0.018454132 | T36: =T39 -> 0.021340599 | U36: =U39 -> 0.023505449 | V36: =V39 -> 0.025129087 | W36: =W39 -> 0.017384316 | X36: =X41 -> 0.029406006 | Y36: =Y39 -> 0.029554505 | Z36: =Z39 -> 0.029665878 | AA36: =AA39 -> 0.029749409 | AB36: =AB39 -> 0.014228713 | AC36: =AC41 -> 0.025180587 | AD36: =AD39 -> 0.02638544 | AE36: =AE39 -> 0.02728908 | AF36: =AF39 -> 0.02796681 | AG36: =AG39 -> 0.012558097 | AH36: =AH41 -> 0.016783516
B37: Actual 5y Average | H37: =AVERAGE(D36:H36) -> 0.032831099 | M37: =AVERAGE(I36:M36) -> 0.027068389 | R37: =AVERAGE(N36:R36) -> 0.023155197 | W37: =AVERAGE(S36:W36) -> 0.021162717 | AB37: =AVERAGE(X36:AB36) -> 0.026520902 | AG37: =AVERAGE(AC36:AG36) -> 0.023876003
B38: Target 5y Average | M38: 0.03 | R38: =H20 -> 0 | W38: =M20 -> 0 | AB38: =R20 -> 0 | AG38: =W20 -> 0
B39: Averages | I39: =OFFSET(I39,$C$13,0) -> 0.02634165 | J39: =OFFSET(J39,$C$12,0) -> 0.027126195 | K39: =OFFSET(K39,$C$12,0) -> 0.027570088 | L39: =OFFSET(L39,$C$12,0) -> 0.027291366 | M39: =OFFSET(M39,$C$12,0) -> 0.027012644 | N39: =OFFSET(N39,$C$12,0) -> 0.030475821 | O39: =OFFSET(O39,$C$12,0) -> 0.026436856 | P39: =OFFSET(P39,$C$12,0) -> 0.023407632 | Q39: =OFFSET(Q39,$C$12,0) -> 0.021135714 | ... AH39: =OFFSET(AH39,$C$12,0) -> 0.016783516
B40: =B28 -> Conservative | I40: =I41*$F$15 -> 0.023707485 | J40: =J41*$F$15 -> 0.024413576 | K40: =K41*$F$15 -> 0.024813079 | L40: =L41*$F$15 -> 0.02456223 | M40: =M41*$F$15 -> 0.02431138 | N40: =N41*$F$15 -> 0.027428239 | O40: =O41*$F$15 -> 0.02379317 | P40: =P41*$F$15 -> 0.021066869 | ... R40: =R41*$F$15 -> 0.012887964 | S40: =S36 -> 0.018454132 | T40: =T41*($F$13) -> 0.021532664 | U40: =U41*($F$13) -> 0.023716998 | V40: =V41*($F$13) -> 0.025355249 | W40: =W41*($F$13) -> 0.017540775 | X40: =X36 -> 0.029406006 | Y40: =Y41*($F$13) -> 0.029820495 | Z40: =Z41*($F$13) -> 0.029932871 | AA40: =AA41*($F$13) -> 0.030017154 | AB40: =AB41*($F$13) -> 0.014356771 | AC40: =AC36 -> 0.025180587 | AD40: =AD41*($F$13) -> 0.026622909 | AE40: =AE41*($F$13) -> 0.027534682 | AF40: =AF41*($F$13) -> 0.028218511 | AG40: =AG41*($F$13) -> 0.01267112 | AH40: =AH36 -> 0.016783516
B41: =B29 -> Base | I41: =I35/I23 -> 0.02634165 | J41: =J35/J23 -> 0.027126195 | K41: =K35/K23 -> 0.027570088 | L41: =K41+($M$41-K41)/($M$34-$K$34) -> 0.027291366 | M41: =H16 -> 0.027012644 | N41: =M41*(N29/M29-1) -> 0.030475821 | O41: =N41+($R$41-N41)/($R$34-$N$34) -> 0.026436856 | P41: =O41+($R$41-O41)/($R$34-$N$34) -> 0.023407632 | Q41: =P41+($R$41-P41)/($R$34-$N$34) -> 0.021135714 | R41: =N41*(1+(R27/N27-1)) -> 0.01431996 | S41: =R41+(N41-I41) -> 0.018454132 | T41: =S41+($R$29-S41)/($R$22-$N$22) -> 0.021340599 | U41: =T41+($R$29-T41)/($R$22-$N$22) -> 0.023505449 | V41: =U41+($R$29-U41)/($R$22-$N$22) -> 0.025129087 | W41: =S41*(1+(W27/S27-1)) -> 0.017384316 | X41: =W41+(N41-S41) -> 0.029406006 | Y41: =X41+($R$29-X41)/($R$22-$N$22) -> 0.029554505 | Z41: =Y41+($R$29-Y41)/($R$22-$N$22) -> 0.029665878 | AA41: =Z41+($R$29-Z41)/($R$22-$N$22) -> 0.029749409 | AB41: =X41*(1+(AB27/X27-1)) -> 0.014228713 | AC41: =AB41+(X41-S41) -> 0.025180587 | AD41: =AC41+($R$29-AC41)/($R$22-$N$22) -> 0.02638544 | AE41: =AD41+($R$29-AD41)/($R$22-$N$22) -> 0.02728908 | AF41: =AE41+($R$29-AE41)/($R$22-$N$22) -> 0.02796681 | AG41: =AC41*(1+(AG27/AC27-1)) -> 0.012558097 | AH41: =AG41+(X41-AC41) -> 0.016783516
