Workbook
Name Sectors: '[1]Sector Impact'!$K$4:$K$16
Name Sectors: 'Sector Impact'!$K$4:$K$16

Sheet OP
B2: 45410 | C2: Team 12 | D2: 30th April 2024 | E2: =Inputs!H3 -> #VALUE! | L2: {=_FV(E2,"Bolsa")} -> Nasdaq Stock Market | M2: SIC:
B3: #VALUE! | D3: COMPANY DESCRIPTION | H3: CEO & BOARD OF DIRECTORS
D4: PACCAR Inc. represents a hallmark of American innovation and industrial might, focusing on the specialized design and manufacturing of heavy commercial vehicles. This enterprise orchestrates its global operations through a trio of distinguished subsidiaries: DAF, Kenworth, and Peterbilt. Each of these brands has carved out a significant presence in the trucking industry, offering a wide range of products that cater to various markets worldwide. The essence of PACCAR's operation lies in its ability to combine cutting-edge technology with rigorous quality standards, ensuring that each vehicle that rolls off the production line is a marvel of engineering and a tool designed to withstand the demands of heavy-duty transportation. | H4: Name (Gender;Age) | I4: Tenure | J4: Executive? | K4: Other roles
H5: R. Preston Feight (M;56) | I5: 5 years | J5: Yes | K5: CEO (since 2019); Was an enginner at Ford for six years
H6: Franklin L. Feder (M;72) | I6: 6 years | J6: Yes | K6: Director of Minerals Technologies (since 2017) ; Former CEO of Alcoa Latin Mareica & Caribbean (2004-2014)
H7: Dame Alison J. Carnwath (F;71) | I7: 19 years | J7: Yes | K7: Senior advisor to Evercore Partners (since 2005); Director of Coller Capital (since 2015) and EG Group Ltd. And ASDA Group Ltd. (since 2021)
H8: Kirk S. Hachigian (M;64) | I8: 16 years | J8: Yes | K8: Chairman of Allegion PLC (since 2023); Director of NextEra Energy (since 2013); Former Chairman of JELD-WEN Holding (2016-2019)
H9: Barbara B. Hulit (F;57) | I9: 1 year | J9: No | K9: Former CEO of Advanced Healthcare Solutions (2019-2022); Director of Envista Holdings (since 2021) and Novanta Corporation (since 2022)
H10: Roderick C. Mcgeary (M;73) | I10: 12 years | J10: Yes | K10: Director of Raymond James Financial (since 2015); Former chairman of BearingPoint (2004-2009)
H11: Cynthia A. Niekamp (F;64) | I11: 1 year | J11: No | K11: Vice-President of Automotive Coating at PPG Industries; Former President of BorgWarner's TorqTransfer Systems (2004-2008); Director of Ball Corporation (since 2016)
H12: John M. Pigott (M;60) | I12: 15 years | J12: No | K12: Borther of Mark C. Pigott; Partner in Beta Business Ventures
H13: Mark C. Pigott (M;70) | I13: 30 years | J13: No | K13: Executive Chairman; Former director of Franklin Resources Inc.
H14: Ganesh Ramaswamy (M;55) | I14: 3 years | J14: Yes | K14: Executive Vice President of Industrial & Energy Technology at Baker Hughes; Former President of Global Services for Johnson Controls (2019-2022)
H15: Mark A. Schulz (M;71) | I15: 4 years | J15: Yes | K15: President and CEO of M.A. Schulz and Associates; Founding partner of Fontinalis Partners LLC
B16: {=_FV(E2,"Moeda")&" MILLIONS"} -> USD MILLIONS | H16: Gregory M. E. Spierkel (M;67) | I16: 16 years | J16: Yes | K16: Former CEO of Ingram Micro (2005-2012); Director of sChneider Electric SE (Paris) (since 2014)
B17: COMPANY OVERVIEW
B18: Stock | D18: Liquidity and Solvency | F18: Segments | I18: ="Profitability ("&J19&")" -> Profitability (2023) | L18: Multiples
B19: Last Price | C19: 105.92 | D19: Total Assets | E19: =_xlfn.XLOOKUP(D19,'Fin. Data'!A:A,'Fin. Data'!B:B,,0) -> 40823 | F19: Regions | H19: % Sales | I19: Reporting Year | J19: 2023 | L19: Float | M19: =Inputs!B82 -> 0.9814
B20: Outstanding Shares | C20: {=_FV(E2,"Ações em circulação",TRUE)} -> 524010700 | D20: Total Liabilities | E20: =_xlfn.XLOOKUP(D20,'Fin. Data'!A:A,'Fin. Data'!B:B,,0) -> 24945 | F20: =Segments!C5 -> United States and Canada | H20: =Segments!B5 -> 0.53637901 | I20: End of Year | J20: 45291 | L20: Insiders Own | M20: =Inputs!B83 -> 0.0186
B21: Market Cap. | C21: =C19*C20/1000000 -> 55503.213 | D21: Cash/Share | E21: =_xlfn.XLOOKUP("Cash & Eq.",'Fin. Data'!A:A,'Fin. Data'!B:B,,0)*1000000/C20 -> 13.705827 | F21: =Segments!C6 -> Europe | H21: =Segments!B6 -> 0.24884848 | I21: EBITDA | K21: =_xlfn.XLOOKUP(I21,'Fin. Data'!A:A,'Fin. Data'!B:B,,0) -> 6770.9 | L21: b (Yahoo) | M21: {=_FV(E2,"Beta")} -> 0.9418
B22: +Total Debt | C22: ='Fin. Data'!B58 -> 14238 | D22: EBITDA/Net Financial Cost (NFC) | E22: =_xlfn.XLOOKUP("EBITDA",'Fin. Data'!A:A,'Fin. Data'!B:B,,0)/_xlfn.XLOOKUP("Net Financial Cost",'Fin. Data'!A:A,'Fin. Data'!B:B,,0) -> -52.487597 | F22: =Segments!C7 -> Other | H22: =Segments!B7 -> 0.21477251 | I22: Depreciation & Amortization | K22: =_xlfn.XLOOKUP(I22,'Fin. Data'!A:A,'Fin. Data'!B:B,,0) -> #N/A | L22: Credit Score | M22: =Inputs!B84 -> A+/A1
B23: -Cash | C23: ='Fin. Data'!B39 -> 7182 | D23: Debt/EBITDA | E23: =_xlfn.XLOOKUP("Total Debt",'Fin. Data'!A:A,'Fin. Data'!B:B,,0)/_xlfn.XLOOKUP("EBITDA",'Fin. Data'!A:A,'Fin. Data'!B:B,,0) -> 2.1028224 | I23: EBIT | K23: =_xlfn.XLOOKUP(I23,'Fin. Data'!A:A,'Fin. Data'!B:B,,0) -> 5847 | L23: Price/Book Value | M23: =IFERROR((C19*C20/(E19-E20))/1000000,"") -> 3.4956048
B24: =Enterprise Value | C24: =C21+C22-C23 -> 62559.213 | D24: "Others Assets"/Asset | E24: =_xlfn.XLOOKUP("Other Assets",'Fin. Data'!A:A,'Fin. Data'!B:B,,0)/_xlfn.XLOOKUP("Total Assets",'Fin. Data'!A:A,'Fin. Data'!B:B,,0) -> 0.48125811 | I24: Net Income | K24: =_xlfn.XLOOKUP(I24,'Fin. Data'!A:A,'Fin. Data'!B:B,,0) -> 4601 | L24: NCF(3y avg)/Asset | M24: =IFERROR(K30/E19,"") -> -0.0019433489
B25: Holdings (nac/int'l) | C25: - | D25: Debt/Assets | E25: =_xlfn.XLOOKUP(D25,'Fin. Data'!A:A,'Fin. Data'!B:B,,0) -> 0.34877398 | F25: Categories | H25: % Sales | I25: EPS | K25: =1000000*K24/C20 -> 8.7803551 | L25: Price/Net Inc. (3y avg) | M25: =IFERROR(C21/K29,"") -> 17.592144
B26: t liq. (Holdings/Vol.) | C26: - | D26: EBITDA Margin (average) | E26: =AVERAGE(_xlfn.XLOOKUP("EBITDA Margin",'Fin. Data'!A:A,'Fin. Data'!B:D,,0)) -> 0.16583335 | F26: =Segments!C13 -> Trucks | H26: =Segments!B13 -> 0.7642581 | I26: ROA | K26: =K24/E19 -> 0.11270607 | L26: EV/Asset | M26: =IFERROR(C24/E19,"") -> 1.5324502
B27: % Short | C27: =Inputs!B88 -> 0.0165 | D27: Operating Margin (average) | E27: =AVERAGE(_xlfn.XLOOKUP("Operating Margin",'Fin. Data'!A:A,'Fin. Data'!B:D,,0)) -> 0.13512585 | F27: =Segments!C14 -> Parts | H27: =Segments!B14 -> 0.18260389 | I27: ROIC | K27: =K24/(E19-(E20-C22)) -> 0.15277593 | L27: EV/Ebitda (3y average) | M27: =IFERROR(C24/K28,"") -> 12.680579
B28: Traffic ESG | D28: Net Income Margin (average) | E28: =AVERAGE(_xlfn.XLOOKUP("Net Income Margin",'Fin. Data'!A:A,'Fin. Data'!B:D,,0)) -> 0.10474247 | F28: =Segments!C15 -> Financial Services | H28: =Segments!B15 -> 0.051580817 | I28: EBITDA (3y average) | K28: =AVERAGE(_xlfn.XLOOKUP("EBITDA",'Fin. Data'!A:A,'Fin. Data'!B:D,,0)) -> 4933.4667 | L28: Price/NCF (3y average) | M28: =IFERROR(C21/K30,"") -> -699.62034
B29: E | F29: =Segments!C16 -> Other | H29: =Segments!B16 -> 0.001557189 | I29: Net Income (3y average) | K29: =AVERAGE(_xlfn.XLOOKUP("Net Income",'Fin. Data'!A:A,'Fin. Data'!B:D,,0)) -> 3155 | L29: Bonds 1,3,5a (USD) | M29: -
B30: S | D30: Net Financial Cost/Avg Net Debt | E30: =-_xlfn.XLOOKUP("Net Financial Cost",'Fin. Data'!A:A,'Fin. Data'!B:B,,0)/AVERAGE(_xlfn.XLOOKUP("Net Debt",'Fin. Data'!A:A,'Fin. Data'!B:D,,0)) -> 0.018565603 | I30: NCF (3y average) | K30: =AVERAGE(_xlfn.XLOOKUP("Net Financial Cost",'Fin. Data'!A:A,'Fin. Data'!B:D,,0)) -> -79.333333 | L30: Div+Rep.(3y avg)/Price | M30: =-IFERROR(SUM(E51:E53)/(3*C21),"") -> 0.019448724
B31: G | L31: Div. Yield | M31: =-IFERROR(L52/C21,"") -> 0.027360578
B32: INVESTMENT THESIS
B33: Pillars of Recommendation | H33: Recommendation | I33: Valuation Assumptions
B34: Pillar | C34: Explanation | H34: HOLD | I34: Check DCF
B35: Industry | C35: The industry it's in is very stable and PACCAR seems it be performing well amidst the industry.
B36: Diversification of Products | C36: Their expansion into the EV market could increase overall revenue and diversify it's source.
B37: Increase of Global Commerce | C37: The increase of international commerce entails a need for transportation, which boosts the industry's activity.
B38: Risks of Investment | H38: Price Target | I38: Valuation
B39: Risk | C39: Explanation | H39: =DCF!D75 -> 98.051639 | I39: Discount Rate | J39: =DCF!F50 -> 0.0925 | L39: Price M. Upside | M39: =SARD!AJ14 -> 0.11047345
B40: Cyclical | C40: The company is very dependant on economic cycles, so if international shipment decreases, it'll affect the company a lot.
B41: Dependancy on other Industries | C41: The transportation industry is heavily dependant on other industries, a decrease of activity on other industries will decrease the activity of the transportation industry. | I41: Upside | J41: =DCF!D74 -> -0.07428589 | L41: EV M. Upside | M41: =SARD!AM14 -> 0.010642162
...

Sheet Acuerdo
A1: Invertir
A2: NO invertir
A3: Mantener sin elevar posición
A4: Mantener (y seguir comprando)
A5: Liquidar
A6: PENDIENTE

Sheet Segments
B2: ="Regions "&"("&OP!$J$19&")" -> Regions (2023) | Q2: Products
D3: Nominal value | K3: YoY Growth
B4: Weight | C4: Region (Plant) | D4: =OP!J19 -> 2023 | E4: =D4-1 -> 2022 | F4: =E4-1 -> 2021 | G4: =F4-1 -> 2020 | H4: =G4-1 -> 2019 | I4: =H4-1 -> 2018 | K4: =OP!J19 -> 2023 | L4: =K4-1 -> 2022 | M4: =L4-1 -> 2021 | N4: =M4-1 -> 2020 | O4: =N4-1 -> 2019 | P4: =O4-1 -> 2018
B5: =IFERROR(D5/$D$8,"") -> 0.53637901 | C5: United States and Canada | D5: 18841.6 | E5: 15379.2 | F5: 12388.8 | G5: 10526.6 | H5: 15119.3 | I5: 13165.7 | K5: =IFERROR((D5-E5)/E5,"-") -> 0.22513525 | L5: =IFERROR((E5-F5)/F5,"-") -> 0.24137931 | M5: =IFERROR((F5-G5)/G5,"-") -> 0.17690422 | N5: =IFERROR((G5-H5)/H5,"-") -> -0.30376406 | O5: =IFERROR((H5-I5)/I5,"-") -> 0.14838558 | P5: =IFERROR((I5-J5)/J5,"-") -> -
B6: =IFERROR(D6/$D$8,"") -> 0.24884848 | C6: Europe | D6: 8741.4 | E6: 7486.5 | F6: 6325.4 | G6: 4871.2 | H6: 6104.7 | I6: 6071.9 | K6: =IFERROR((D6-E6)/E6,"-") -> 0.16762172 | L6: =IFERROR((E6-F6)/F6,"-") -> 0.18356151 | M6: =IFERROR((F6-G6)/G6,"-") -> 0.29853014 | N6: =IFERROR((G6-H6)/H6,"-") -> -0.20205743 | O6: =IFERROR((H6-I6)/I6,"-") -> 0.0054019335 | P6: =IFERROR((I6-J6)/J6,"-") -> -
B7: =IFERROR(D7/$D$8,"") -> 0.21477251 | C7: Other | D7: 7544.4 | E7: 5954 | F7: 4808.1 | G7: 3330.7 | H7: 4375.7 | I7: 4258.1 | K7: =IFERROR((D7-E7)/E7,"-") -> 0.26711454 | L7: =IFERROR((E7-F7)/F7,"-") -> 0.23832699 | M7: =IFERROR((F7-G7)/G7,"-") -> 0.44357042 | N7: =IFERROR((G7-H7)/H7,"-") -> -0.23881893 | O7: =IFERROR((H7-I7)/I7,"-") -> 0.027617952 | P7: =IFERROR((I7-J7)/J7,"-") -> -
B8: =SUM(B5:B7) -> 1 | C8: TOTAL | D8: =SUM(D5:D7) -> 35127.4 | E8: =SUM(E5:E7) -> 28819.7 | F8: =SUM(F5:F7) -> 23522.3 | G8: =SUM(G5:G7) -> 18728.5 | H8: =SUM(H5:H7) -> 25599.7 | I8: =SUM(I5:I7) -> 23495.7 | K8: =(D8-E8)/E8 -> 0.21886765 | L8: =(E8-F8)/F8 -> 0.22520757 | M8: =(F8-G8)/G8 -> 0.25596284 | N8: =(G8-H8)/H8 -> -0.2684094 | O8: =(H8-I8)/I8 -> 0.0895483 | P8: -
B10: ="Categories "&"("&OP!$J$19&")" -> Categories (2023)
D11: Nominal value | K11: YoY Growth
B12: Weight | C12: Category | D12: =OP!J19 -> 2023 | E12: =D12-1 -> 2022 | F12: =E12-1 -> 2021 | G12: =F12-1 -> 2020 | H12: =G12-1 -> 2019 | I12: =H12-1 -> 2018 | K12: =OP!J19 -> 2023 | L12: =K12-1 -> 2022 | M12: =L12-1 -> 2021 | N12: =M12-1 -> 2020 | O12: =N12-1 -> 2019 | P12: =O12-1 -> 2018
B13: =IFERROR(D13/$D$17,"") -> 0.7642581 | C13: Trucks | D13: 26846.4 | E13: 21486.2 | F13: 16799.7 | G13: 13164.8 | H13: 19989.5 | I13: 18187 | K13: =IFERROR((D13-E13)/E13,"-") -> 0.24947175 | L13: =IFERROR((E13-F13)/F13,"-") -> 0.27896331 | M13: =IFERROR((F13-G13)/G13,"-") -> 0.2761075 | N13: =IFERROR((G13-H13)/H13,"-") -> -0.34141424 | O13: =IFERROR((H13-I13)/I13,"-") -> 0.099109254 | P13: =IFERROR((I13-J13)/J13,"-") -> -
B14: =IFERROR(D14/$D$17,"") -> 0.18260389 | C14: Parts | D14: 6414.4 | E14: 5764.3 | F14: 4944.3 | G14: 3912.9 | H14: 4024.9 | I14: 3838.9 | K14: =IFERROR((D14-E14)/E14,"-") -> 0.11278039 | L14: =IFERROR((E14-F14)/F14,"-") -> 0.16584754 | M14: =IFERROR((F14-G14)/G14,"-") -> 0.26358966 | N14: =IFERROR((G14-H14)/H14,"-") -> -0.027826778 | O14: =IFERROR((H14-I14)/I14,"-") -> 0.048451379 | P14: =IFERROR((I14-J14)/J14,"-") -> -
B15: =IFERROR(D15/$D$17,"") -> 0.051580817 | C15: Financial Services | D15: 1811.9 | E15: 1505.4 | F15: 1687.8 | G15: 1574.2 | H15: 1480 | I15: 1357.1 | K15: =IFERROR((D15-E15)/E15,"-") -> 0.20360037 | L15: =IFERROR((E15-F15)/F15,"-") -> -0.10806968 | M15: =IFERROR((F15-G15)/G15,"-") -> 0.072163639 | N15: =IFERROR((G15-H15)/H15,"-") -> 0.063648649 | O15: =IFERROR((H15-I15)/I15,"-") -> 0.090560755 | P15: =IFERROR((I15-J15)/J15,"-") -> -
B16: =IFERROR(D16/$D$17,"") -> 0.001557189 | C16: Other | D16: 54.7 | E16: 63.8 | F16: 90.5 | G16: 76.6 | H16: 105.3 | I16: 112.7 | K16: =IFERROR((D16-E16)/E16,"-") -> -0.14263323 | L16: =IFERROR((E16-F16)/F16,"-") -> -0.29502762 | M16: =IFERROR((F16-G16)/G16,"-") -> 0.18146214 | N16: =IFERROR((G16-H16)/H16,"-") -> -0.27255461 | O16: =IFERROR((H16-I16)/I16,"-") -> -0.065661047 | P16: =IFERROR((I16-J16)/J16,"-") -> -
B17: =SUM(B13:B16) -> 1 | C17: TOTAL | D17: =SUM(D13:D16) -> 35127.4 | E17: =SUM(E13:E16) -> 28819.7 | F17: =SUM(F13:F16) -> 23522.3 | G17: =SUM(G13:G16) -> 18728.5 | H17: =SUM(H13:H16) -> 25599.7 | I17: =SUM(I13:I16) -> 23495.7 | K17: =(D17-E17)/E17 -> 0.21886765 | L17: =(E17-F17)/F17 -> 0.22520757 | M17: =(F17-G17)/G17 -> 0.25596284 | N17: =(G17-H17)/H17 -> -0.2684094 | O17: =(H17-I17)/I17 -> 0.0895483 | P17: -
B19: Categories | D19: Description | I19: Graphs
B20: =C13 -> Trucks | D20: The Truck segment includes the design and manufacture of high-quality, light-, medium- and heavyduty commercial trucks
B21: =C14 -> Parts | D21: Parts segment includes the distribution of aftermarket parts for trucks and related commercial vehicles, both of which are sold through the same network of independent dealers
B22: =C15 -> Financial Services | D22: Financing or leasing of PACCAR products and services provided to truck customers and dealers
B23: =C16 -> Other | D23: Other includes the winch business as well as sales, income and expenses not attributable to a reportable segment
B24: Industry | J24: Graphs (Industry Forecasts)
B25: Drivers | D25: Description
B26: Economy's strenght | D26: Economic factors such as GDP growth, consumer spending, industrial production, and construction activity play a significant role for Paccar business. If there is a strong economic growth that will, most likely, lead to an increase in freight transportation needs. | E26: Economic Conditions: Economic factors such as GDP growth, consumer spending, industrial production, and construction activity play a significant role in driving demand for trucks. Strong economic growth typically leads to increased freight transportation needs, boosting demand for new trucks.
B27: Dependent sectors | D27: This industry is interconnected with other sectors such as manufacturing, agriculture, retail, and logistics. Changes in supply chain dynamics and shifts in trade patterns will impact demand for trucks. (e.g.: e-commerce)
B28: Environmental adaptability | D28: The recent environmental issues and sustainability concerns are increasing demand for cleaner, more fuel-efficient trucks with lower carbon emissions. Regulatory initiatives and efforts are influencing manufacturers to develop eco-friendly solutions.
B29: Sales forecast
B30: Source | D30: Market Growth CAGR | G30: Period
B31: The Brainy Insights | D31: 0.0683 | G31: 2023 - 2032
B32: Mordor Intelligence | D32: 0.074 | G32: 2019 - 2029
B33: Zion | D33: 0.039 | G33: 2020 - 2026
B34: AVERAGE | D34: =AVERAGE(D31:F33) -> 0.060433333 | G34: {=SMALL(_xlfn.NUMBERVALUE(LEFT(G31:G33,4)),1)&" - "&LARGE(_xlfn.NUMBERVALUE(RIGHT(G31:G33,4)),1)} -> 2019 - 2032
B35: Company's Strategy / Extra Notes
B36: >The company has a differentiated approach to research and development, partnering with suppliers and technology companies in early stages of technology development, and scaling direct investments closer to the time of commercialization >Conservative approach to financial management and a long-term business perspective >Customer loyalty: strong emphasis on building high-quality and reliable trucks. Its brands, including Peterbilt, Kenworth, and DAF, are known for their durability, performance, and long-term value, attracting loyal customers worldwide.
S40: The Company evaluates the performance of its Truck and Parts segments based on operating profits, which excludes investment income, other income and expense, and income taxes

Sheet Peers
B1: Peer Logo | C1: Peer Name | D1: Description | G1: Currency | H1: End of Fiscal Year | I1: Next Earnings Date
B2: #VALUE! | C2: #VALUE! | D2: {=_FV(C2,"Description")} -> Volvo Car AB is a Sweden-based automotive brand. Volvo Car Group is focused on the design, engineering, manufacturing, distribution and sale of passenger cars, with particular focus on sustainability, fully electric cars and direct consumer relations, including subscription and other new mobility services. Volvo Car Group’s addressable market is the global premium passenger car market. Moreover, the Company’s intention is to be a pure electric car company and as a result it is undergoing a shift in its business model to a direct sales model in most of its markets. Volvo Cars’ commitment to electrification also results in the launch of Polestar, a progressive stand-alone electric performance car brand, in which Volvo Cars owns shares. Volvo Cars also holds shares in the automotive brand LYNK&CO, which focuses on young open-minded urban people through a flexible customer offering. | G2: {=_FV(C2,"Currency")} -> SEK | H2: 45291 | I2: 45399
B3: #VALUE! | C3: #VALUE! | D3: {=_FV(C3,"Description")} -> Tesla, Inc. designs, develops, manufactures, sells and leases high-performance fully electric vehicles and energy generation and storage systems, and offer services related to its products. The Company's segments include automotive, and energy generation and storage. The automotive segment includes the design, development, manufacturing, sales and leasing of high-performance fully electric vehicles, and sales of automotive regulatory credits. This segment also includes sales of used vehicles, non-warranty after-sales vehicle services, body shop and parts, paid supercharging, vehicle insurance and retail merchandise. Its consumer vehicles include the Model 3, Y, S, X and Cybertruck. The energy generation and storage segment includes the design, manufacture, installation, sales and leasing of solar energy generation and energy storage products and related services and sales of solar energy systems incentives. Its lithium-ion battery energy storage products include Powerwall and Megapack. | G3: {=_FV(C3,"Currency")} -> USD | H3: 45291 | I3: 45405
B4: #VALUE! | C4: #VALUE! | D4: {=_FV(C4,"Description")} -> Daimler Truck Holding AG is a Germany-based company, which is now operating as an independent entity. It manufactures commercial vehicles, develops new solutions, and invents new technologies. The Company is engaged in the manufacturing of Medium Duty Truck (MDT) and Heavy-Duty Trucks (HDT). The Company produces buses and trucks under brands, such as Bharat Benz, Freightliner, FUSO, Mercedes-Benz, Setra, Thomas Built Buses, and Western Star. The Company also offers tailored financial services to support the purchase and use of its trucks and buses. The Company has operations in France, Germany, India, Mexico, Brazil, and the United States of America, The Company's truck product range includes light, medium, and heavy trucks for long-distance distribution and construction site haulage, special vehicles which are used in municipal application as well as industrial engines. | G4: {=_FV(C4,"Currency")} -> EUR | H4: 45291 | I4: 45415
B5: #VALUE! | C5: #VALUE! | D5: {=_FV(C5,"Description")} -> Renault SA is a France-based company that designs, manufactures and sells passenger cars and light commercial vehicles and related services. Its brand portfolio consists of Renault, Dacia (both operating globally), Alpine (active in Europe, Japan and Australia), Renault Samsung Motors (operates only in South Korea) and Lada (operates only in Russia). The Group operating segments are three: Automotive excluding AVTOVAZ, Sales Financing and AVTOVAZ. Automotive excluding AVTOVAZ consists of the Group’s automotive activities comprising the production, sales, and distribution of passenger and light commercial vehicles, automobile service for the Renault, Dacia and Samsung brands and investments in Nissan, among others. Sales Financing, carried out by RCI Banque, covers the financing operations for sales of vehicles to dealers and end-users. AVTOVAZ, consists of the Russian automotive group AVTOVAZ and its parent company, the joint venture lliance Rostec Auto b.v. | G5: {=_FV(C5,"Currency")} -> EUR | H5: 45291 | I5: 45404
D6: {=_FV(C6,"Descrição")} -> #VALUE! | G6: {=_FV(C6,"Moeda")} -> #VALUE!
B8: {="In Millions "&_FV(OP!E2,"Moeda")} -> In Millions USD | C8: =OP!E2 -> #VALUE! | D8: =C2 -> #VALUE! | E8: =C3 -> #VALUE! | F8: =C4 -> #VALUE! | G8: =C5 -> #VALUE! | H8: AVERAGE | I8: Deviation from Average
B9: Company Info | H9: =IFERROR(AVERAGE(C9:F9),"") | L9: TRAFFIC
B10: Market Cap | C10: {=_FV(C8,"Capitalização de mercado",TRUE)/1000000} -> 59359.932 | D10: {=_FV(D8,"Market cap",TRUE)/1000000*0.099334} -> 11818.004 | E10: {=_FV(E8,"Market cap",TRUE)/1000000} -> 549790.47 | F10: {=_FV(F8,"Market cap",TRUE)/1000000*1.103594} -> 42740.121 | G10: {=_FV(G8,"Market cap",TRUE)/1000000*1.103594} -> 14828.043 | H10: =IFERROR(AVERAGE(C10:G10),"") -> 135707.31 | I10: =SQRT((C10-H10)^2) -> 76347.382 | M10: Best Value
B11: Net Sales (current) | C11: =C60 -> 35127 | D11: =D60 -> 60424 | E11: =E60 -> 96773 | F11: =F60 -> 60424 | G11: =G60 -> 56625 | H11: =IFERROR(AVERAGE(C11:G11),"") -> 61874.6 | I11: =SQRT((C11-H11)^2) -> 26747.6
B12: Profitability | H12: =IFERROR(AVERAGE(C12:F12),"") | M12: Important Value
B13: Sales Growth (ttm) | C13: =C60/C59-1 -> 0.21884108 | D13: =D60/D59-1 -> 0.12836601 | E13: =E60/E59-1 -> 0.79798599 | F13: =F60/F59-1 -> 0.12836601 | G13: =G60/G59-1 -> 0.16120499 | H13: =IFERROR(AVERAGE(C13:G13),"") -> 0.28695282 | I13: =SQRT((C13-H13)^2) -> 0.068111735
B14: Sales Growth (36m) | C14: =C60/C58-1 -> 0.87554061 | D14: =D60/D58-1 -> 0.47210447 | E14: =E60/E58-1 -> 2.0686517 | F14: =F60/F58-1 -> 0.47210447 | G14: =G60/G58-1 -> 0.14280813 | H14: =IFERROR(AVERAGE(C14:G14),"") -> 0.80624187 | I14: =SQRT((C14-H14)^2) -> 0.069298731 | M14: Worst Value
B15: Operating Margin | C15: =C63/C60 -> 0.16645316 | D15: =D63/D60 -> 0.09706408 | E15: =E63/E60 -> 0.0918748 | F15: =F63/F60 -> 0.09706408 | G15: =G63/G60 -> 0.038463576 | H15: =IFERROR(AVERAGE(C15:G15),"") -> 0.098183939 | I15: =SQRT((C15-H15)^2) -> 0.068269217
B16: Net Income Margin | C16: =C66/C60 -> 0.13098187 | D16: =D66/D60 -> 0.067555938 | E16: =E66/E60 -> 0.15499158 | F16: =F66/F60 -> 0.067555938 | G16: =G66/G60 -> 0.041960265 | H16: =IFERROR(AVERAGE(C16:G16),"") -> 0.092609117 | I16: =SQRT((C16-H16)^2) -> 0.038372749
B17: Return on Equity (RoE) | C17: =C66/C79 -> 0.28977201 | D17: =D66/D79 -> 0.32518123 | E17: =E66/E79 -> 0.23947058 | F17: =F66/F79 -> 0.17121047 | G17: =G66/G79 -> 0.072364013 | H17: =IFERROR(AVERAGE(C17:G17),"") -> 0.21959966 | I17: =SQRT((C17-H17)^2) -> 0.070172352
B18: Return on Invested Capital (ROIC) | C18: =(C66+C65)/(C78+C79) -> 0.11568601 | D18: =(D66+D65)/(D78+D79) -> 0.29231912 | E18: =(E66+E65)/(E78+E79) -> 0.14732406 | F18: =(F66+F65)/(F78+F79) -> 0.11085575 | G18: =(G66+G65)/(G78+G79) -> 0.02791276 | H18: =IFERROR(AVERAGE(C18:G18),"") -> 0.13881954 | I18: =SQRT((C18-H18)^2) -> 0.023133526
B19: Solvency | H19: =IFERROR(AVERAGE(C19:F19),"")
B20: Debt/Assets | C20: =C78/C74 -> 0.34877398 | D20: =D78/D74 -> 0.10181079 | E20: =E78/E74 -> 0.049053631 | F20: =F78/F74 -> 0.33332909 | G20: =G78/G74 -> 0.53908817 | H20: =IFERROR(AVERAGE(C20:G20),"") -> 0.27441113 | I20: =SQRT((C20-H20)^2) -> 0.074362846
B21: Net Debt/EBITDA | C21: =(C78-C69)/C62 -> 1.0421067 | D21: =(D78-D69)/D62 -> 0.69337733 | E21: =(E78-E69)/E62 -> -0.54012391 | F21: =(F78-F69)/F62 -> 2.4067242 | G21: =(G78-G69)/G62 -> 7.9151254 | H21: =IFERROR(AVERAGE(C21:G21),"") -> 2.3034419 | I21: =SQRT((C21-H21)^2) -> 1.2613353
B22: Debt/Assets (Leases Free Debt) | C22: =(C78-C77)/C74 -> 0.3443157 | D22: =(D78-D77)/D74 -> 0.10181079 | E22: =(E78-E77)/E74 -> 0.049053631 | F22: =(F78-F77)/F74 -> 0.33332909 | G22: =(G78-G77)/G74 -> 0.53908817 | H22: =IFERROR(AVERAGE(C22:G22),"") -> 0.27351948 | I22: =SQRT((C22-H22)^2) -> 0.070796229
B23: Net Debt/EBIT (Leases Free Debt) | C23: =((C78-C77)-C69)/C62 -> 1.0152269 | D23: =((D78-D77)-D69)/D62 -> 0.69337733 | E23: =((E78-E77)-E69)/E64 -> -8.0472527 | F23: =((F78-F77)-F69)/F62 -> 2.4067242 | G23: =((G78-G77)-G69)/G62 -> 7.9151254 | H23: =IFERROR(AVERAGE(C23:G23),"") -> 0.79664023 | I23: =SQRT((C23-H23)^2) -> 0.2185867
B24: Leasing Debt/Total Debt | C24: =C77/C78 -> 0.012782694 | D24: =D77/D78 -> 0 | E24: =E77/E78 -> 0 | F24: =F77/F78 -> 0 | G24: =G77/G78 -> 0 | H24: =IFERROR(AVERAGE(C24:G24),"") -> 0.0025565388 | I24: =SQRT((C24-H24)^2) -> 0.010226155
B25: Interest Coverage Ratio | C25: =-C62/C64 -> 52.487597 | D25: =-D62/D64 -> -23.971751 | E25: =-E62/E64 -> -14.898901 | F25: =-F62/F64 -> -35.719626 | G25: =-G62/G64 -> -82.229167 | H25: =IFERROR(AVERAGE(C25:G25),"") -> -20.86637 | I25: =SQRT((C25-H25)^2) -> 73.353967
B26: Liquidity
B27: Current Ratio | C27: =C72/C76 -> 0.9077795 | D27: =D72/D76 -> 0.97492496 | E27: =E72/E76 -> 1.725894 | F27: =F72/F76 -> 1.6458441 | G27: =G72/G76 -> 1.1077948 | H27: =IFERROR(AVERAGE(C27:G27),"") -> 1.2724475 | I27: =SQRT((C27-H27)^2) -> 0.36466797
B28: Quick Ratio | C28: =(C69+C70)/C76 -> 0.96651211 | D28: =(D69+D70)/D76 -> 0.1612056 | E28: =(E69+E70)/E76 -> 0.55868234 | F28: =(F69+F70)/F76 -> 0.53957349 | G28: =(G69+G70)/G76 -> 0.76405135 | H28: =IFERROR(AVERAGE(C28:G28),"") -> 0.59800498 | I28: =SQRT((C28-H28)^2) -> 0.36850713
B29: Activity | H29: =IFERROR(AVERAGE(C29:F29),"")
B30: Inventory Turnover | C30: =C61/C71 -> 10.436166 | D30: =D61/D71 -> 8.3865561 | E30: =E61/E71 -> 5.8060326 | F30: =F61/F71 -> 4.7050381 | G30: =G61/G71 -> 8.2396025 | H30: =IFERROR(AVERAGE(C30:G30),"") -> 7.5146791 | I30: =SQRT((C30-H30)^2) -> 2.921487
B31: Acc. Receivable Turnover | C31: =C60/C70 -> 15.981347 | D31: =D60/D70 -> 31.536534 | E31: =E60/E70 -> 27.586374 | F31: =F60/F70 -> 10.43953 | G31: =G60/G70 -> 1.017246 | H31: =IFERROR(AVERAGE(C31:G31),"") -> 17.312206 | I31: =SQRT((C31-H31)^2) -> 1.3308596
A32: Price/Sales | B32: Payables Turnover | C32: =C61/C75 -> 16.152553 | D32: =D61/D75 -> 7.6805623 | E32: =E61/E75 -> 5.4821565 | F32: =F61/F75 -> 8.5142397 | G32: =G61/G75 -> 5.0937429 | H32: =IFERROR(AVERAGE(C32:G32),"") -> 8.5846508 | I32: =SQRT((C32-H32)^2) -> 7.5679018
B33: Fixed Asset Turnover | C33: =C60/C73 -> 9.1153726 | D33: =D60/D74 -> 1.7069409 | E33: =E59/E72 -> 1.0847912 | F33: =F60/F73 -> 4.3769649 | G33: =G60/G73 -> 4.1882396 | H33: =IFERROR(AVERAGE(C33:G33),"") -> 4.0944618 | I33: =SQRT((C33-H33)^2) -> 5.0209108
B34: Total Asset Turnover | C34: =C60/C74 -> 0.86047081 | D34: =D60/D74 -> 1.7069409 | E34: =E60/E74 -> 0.907661 | F34: =F60/F74 -> 0.76886078 | G34: =G60/G74 -> 0.42087229 | H34: =IFERROR(AVERAGE(C34:G34),"") -> 0.93296115 | I34: =SQRT((C34-H34)^2) -> 0.072490338
B35: Valuation | H35: =IFERROR(AVERAGE(C35:F35),"")
B36: Price/Earnings | C36: =C10/C66 -> 12.901528 | D36: =D10/D66 -> 2.8951505 | E36: =E10/E66 -> 36.655142 | F36: =F10/F66 -> 10.470387 | G36: =G10/G66 -> 6.240759 | H36: =IFERROR(AVERAGE(C36:G36),"") -> 13.832593 | I36: =SQRT((C36-H36)^2) -> 0.931065
B37: Price/Sales | C37: =C10/C60 -> 1.6898663 | D37: =D10/D60 -> 0.19558461 | E37: =E10/E60 -> 5.6812383 | F37: =F10/F60 -> 0.70733683 | G37: =G10/G60 -> 0.2618639 | H37: =IFERROR(AVERAGE(C37:G37),"") -> 1.707178 | I37: =SQRT((C37-H37)^2) -> 0.017311714
B38: Price/Book | C38: =C10/C79 -> 3.7385018 | D38: =D10/D79 -> 0.94144861 | E38: =E10/E79 -> 8.7778279 | F38: =F10/F79 -> 1.7926399 | G38: =G10/G79 -> 0.45160637 | H38: =IFERROR(AVERAGE(C38:G38),"") -> 3.1404049 | I38: =SQRT((C38-H38)^2) -> 0.59809692
B39: EV/Sales | C39: =(C78+C10-C69)/C60 -> 1.8907374 | D39: =(D78+D10-D69)/D60 -> 0.24427387 | E39: =(E78+E10-E69)/E60 -> 5.6055663 | F39: =(F78+F10-F69)/F60 -> 1.0118019 | G39: =(G78+G10-G69)/G60 -> 1.3652988 | H39: =IFERROR(AVERAGE(C39:G39),"") -> 2.0235357 | I39: =SQRT((C39-H39)^2) -> 0.13279828
B40: EV/EBITDA | C40: =(C78+C10-C69-C77)/C62 -> 9.782146 | D40: =(D78+D10-D69-D77)/D62 -> 3.4786718 | E40: =(E78+E10-E69-E77)/E62 -> 40.010877 | F40: =(F78+F10-F69-F77)/F62 -> 7.9980535 | G40: =(G78+G10-G69-G77)/G62 -> 9.7935196 | H40: =IFERROR(AVERAGE(C40:G40),"") -> 14.212654 | I40: =SQRT((C40-H40)^2) -> 4.4305076
B41: Stock Info | H41: =IFERROR(AVERAGE(C41:F41),"")
...

Sheet SARD
C1: in AUD | F1: Variables | K1: Rankings | P1: Difference | U1: Results | Y1: Additional Information | AD1: =#REF! -> #REF! | AE1: Selected Peers | AJ1: Price Multiples (TTM) | AM1: Enterprise Value Multiples (TTM)
B2: Ticker | C2: Company Name | D2: TRBC Industry | E2: Country | F2: ROE | G2: DEBT/EBIT | H2: Market Cap | I2: EPS Growth (2022-2023) (Refinitiv Smart Estimate) | J2: EBIT Margin | K2: ROE | L2: DEBT/EBIT | M2: Market Cap | N2: EPS Growth | O2: EBIT Margin | P2: ROE | Q2: DEBT/EBIT | R2: Market Cap | S2: EPS Growth | T2: EBIT Margin | U2: SARD Result | V2: SARD Peers | W2: SARD Peers adjusted Rank | Y2: Suitability | Z2: Relevant Information Missing | AA2: Author's Override | AB2: Observations | AE2: SARD Peers adjusted Rank | AF2: SARD Result | AG2: Ticker | AH2: Company Name | AI2: Country | AJ2: P / E | AK2: P / B | AL2: Price / Sales | AM2: EV / Sales | AN2: EV / EBITDA | AS2: Net Income After Taxes | AT2: Total Equity | AU2: Total Debt | AV2: Operating Income | AW2: Revenue | AX2: Company Market Cap | AY2: Earnings per Share (FY1) | AZ2: Earnings per Share (FY0)
A3: Benchmark | B3: PCAR.OQ | C3: Paccar Inc | E3: United States of America | F3: =AS3/AT3 -> 0.28974482 | G3: =AU3/AV3 -> 2.4349068 | H3: =AX3 -> 6.4458564e+10 | I3: =(AY3/AZ3)-1 -> -0.097023153 | J3: =AV3/AX3 -> 0.090709437 | K3: =IFERROR(_xlfn.RANK.EQ(F3,F$3:F$62),"N/A") -> 8 | L3: =IFERROR(_xlfn.RANK.EQ(G3,G$3:G$62),"N/A") -> 33 | M3: =IFERROR(_xlfn.RANK.EQ(H3,H$3:H$62),"N/A") -> 3 | N3: =IFERROR(_xlfn.RANK.EQ(I3,I$3:I$326),"N/A") -> 76 | O3: =IFERROR(_xlfn.RANK.EQ(J3,J$3:J$62),"N/A") -> 35 | P3: - | Q3: - | R3: - | S3: - | T3: - | U3: - | V3: - | W3: - | Y3: =IF(OR(Z3="Y",AA3="Y"),"Not suitable","") | AE3: 1 | AF3: =_xlfn.XLOOKUP(AE3,$W$4:$W$102,$U$4:$U$102,"N/A",0,1) -> 16 | AG3: =_xlfn.XLOOKUP(AE3,$W$4:$W$102,$B$4:$B$102,"N/A",0,1) -> DE.N | AH3: =_xlfn.XLOOKUP(AE3,$W$4:$W$102,$C$4:$C$102,"N/A",0,1) -> Deere & Co | AI3: =_xlfn.XLOOKUP(AE3,$W$4:$W$102,$E$4:$E$102,"N/A",0,1) -> United States of America | AJ3: 12.978082 | AK3: 3.6370669 | AL3: 1.1698261 | AM3: 1.4478308 | AN3: 7.9540112 | AS3: 4600800000 | AT3: 15878800000 | AU3: 14236900000 | AV3: 5847000000 | AW3: 35127400000 | AX3: 6.4458564e+10 | AY3: 8.19 | AZ3: 9.07
A4: Comparison | B4: BAWJ.J | C4: Barloworld Ltd | E4: South Africa | F4: =AS4/AT4 -> 0.12272755 | G4: =AU4/AV4 -> 2.6998633 | H4: =AX4 -> 6.0342132e+08 | I4: =IFERROR((AY4/AZ4)-1,"-") -> -0.16285865 | J4: =AV4/AX4 -> 0.38444572 | K4: =IFERROR(_xlfn.RANK.EQ(F4,F$3:F$102),"N/A") -> 58 | L4: =IFERROR(_xlfn.RANK.EQ(G4,G$3:G$102),"N/A") -> 49 | M4: =IFERROR(_xlfn.RANK.EQ(H4,H$3:H$102),"N/A") -> 78 | N4: =IFERROR(_xlfn.RANK.EQ(I4,I$3:I$102),"N/A") -> 80 | O4: =IFERROR(_xlfn.RANK.EQ(J4,J$3:J$102),"N/A") -> 2 | P4: =IFERROR(ABS(K$3-K4),"N/A") -> 50 | Q4: =IFERROR(ABS(L$3-L4),"N/A") -> 16 | R4: =IFERROR(ABS(M$3-M4),"N/A") -> 75 | S4: =IFERROR(ABS(N$3-N4),"N/A") -> 4 | T4: =IFERROR(ABS(O$3-O4),"N/A") -> 33 | U4: =SUM(P4:T4) -> 178 | V4: =_xlfn.RANK.EQ(U4,$U$4:$U$102,1) -> 54 | W4: =IF(Y4="Not suitable","-",V4) -> 54 | Y4: =IF(OR(Z4="Y",AA4="Y"),"Not suitable","") | Z4: =IF(OR(N4="N/A",O4="N/A"),"Y","") | AE4: 2 | AF4: =_xlfn.XLOOKUP(AE4,$W$4:$W$102,$U$4:$U$102,"N/A",0,1) -> 34 | AG4: =_xlfn.XLOOKUP(AE4,$W$4:$W$102,$B$4:$B$102,"N/A",0,1) -> VOLVb.ST | AH4: =_xlfn.XLOOKUP(AE4,$W$4:$W$102,$C$4:$C$102,"N/A",0,1) -> Volvo AB | AI4: =_xlfn.XLOOKUP(AE4,$W$4:$W$102,$E$4:$E$102,"N/A",0,1) -> Sweden | AJ4: 17.695393 | AK4: 9.129633 | AL4: 2.6539377 | AM4: 3.1148533 | AN4: 12.345276 | AS4: 1.0742683e+08 | AT4: 8.7532778e+08 | AU4: 6.2632169e+08 | AV4: 2.3198274e+08 | AW4: 2.3805194e+09 | AX4: 6.0342132e+08 | AY4: 0.4985384 | AZ4: 0.59552476
B5: FSS.N | C5: Federal Signal Corp | E5: United States of America | F5: =AS5/AT5 -> 0.15710151 | G5: =AU5/AV5 -> 1.3318486 | H5: =AX5 -> 5.0276069e+09 | I5: =IFERROR((AY5/AZ5)-1,"-") -> 0.20904073 | J5: =AV5/AX5 -> 0.044653452 | K5: =IFERROR(_xlfn.RANK.EQ(F5,F$3:F$102),"N/A") -> 45 | L5: =IFERROR(_xlfn.RANK.EQ(G5,G$3:G$102),"N/A") -> 70 | M5: =IFERROR(_xlfn.RANK.EQ(H5,H$3:H$102),"N/A") -> 30 | N5: =IFERROR(_xlfn.RANK.EQ(I5,I$3:I$102),"N/A") -> 36 | O5: =IFERROR(_xlfn.RANK.EQ(J5,J$3:J$102),"N/A") -> 82 | P5: =IFERROR(ABS(K$3-K5),"N/A") -> 37 | Q5: =IFERROR(ABS(L$3-L5),"N/A") -> 37 | R5: =IFERROR(ABS(M$3-M5),"N/A") -> 27 | S5: =IFERROR(ABS(N$3-N5),"N/A") -> 40 | T5: =IFERROR(ABS(O$3-O5),"N/A") -> 47 | U5: =SUM(P5:T5) -> 188 | V5: =_xlfn.RANK.EQ(U5,$U$4:$U$102,1) -> 63 | W5: =IF(Y5="Not suitable","-",V5) -> 63 | Y5: =IF(OR(Z5="Y",AA5="Y"),"Not suitable","") | Z5: =IF(OR(N5="N/A",O5="N/A"),"Y","") | AE5: 3 | AF5: =_xlfn.XLOOKUP(AE5,$W$4:$W$102,$U$4:$U$102,"N/A",0,1) -> 53 | AG5: =_xlfn.XLOOKUP(AE5,$W$4:$W$102,$B$4:$B$102,"N/A",0,1) -> DTGGe.DE | AH5: =_xlfn.XLOOKUP(AE5,$W$4:$W$102,$C$4:$C$102,"N/A",0,1) -> Daimler Truck Holding AG | AI5: =_xlfn.XLOOKUP(AE5,$W$4:$W$102,$E$4:$E$102,"N/A",0,1) -> Germany | AJ5: 11.607458 | AK5: 5.0834413 | AL5: 1.8249784 | AM5: 2.7813492 | AN5: 9.6343922 | AS5: 157400000 | AT5: 1001900000 | AU5: 299000000 | AV5: 224500000 | AW5: 1722700000 | AX5: 5.0276069e+09 | AY5: 3.01166 | AZ5: 2.49095
B6: VOLVb.ST | C6: Volvo AB | E6: Sweden | F6: =AS6/AT6 -> 0.28084661 | G6: =AU6/AV6 -> 3.496571 | H6: =AX6 -> 6.1121149e+10 | I6: =IFERROR((AY6/AZ6)-1,"-") -> -0.19102138 | J6: =AV6/AX6 -> 0.10853776 | K6: =IFERROR(_xlfn.RANK.EQ(F6,F$3:F$102),"N/A") -> 13 | L6: =IFERROR(_xlfn.RANK.EQ(G6,G$3:G$102),"N/A") -> 42 | M6: =IFERROR(_xlfn.RANK.EQ(H6,H$3:H$102),"N/A") -> 4 | N6: =IFERROR(_xlfn.RANK.EQ(I6,I$3:I$102),"N/A") -> 84 | O6: =IFERROR(_xlfn.RANK.EQ(J6,J$3:J$102),"N/A") -> 46 | P6: =IFERROR(ABS(K$3-K6),"N/A") -> 5 | Q6: =IFERROR(ABS(L$3-L6),"N/A") -> 9 | R6: =IFERROR(ABS(M$3-M6),"N/A") -> 1 | S6: =IFERROR(ABS(N$3-N6),"N/A") -> 8 | T6: =IFERROR(ABS(O$3-O6),"N/A") -> 11 | U6: =SUM(P6:T6) -> 34 | V6: =_xlfn.RANK.EQ(U6,$U$4:$U$102,1) -> 2 | W6: =IF(Y6="Not suitable","-",V6) -> 2 | Y6: =IF(OR(Z6="Y",AA6="Y"),"Not suitable","") | Z6: =IF(OR(N6="N/A",O6="N/A"),"Y","") | AE6: 4 | AF6: =_xlfn.XLOOKUP(AE6,$W$4:$W$102,$U$4:$U$102,"N/A",0,1) -> 61 | AG6: =_xlfn.XLOOKUP(AE6,$W$4:$W$102,$B$4:$B$102,"N/A",0,1) -> CNHI.N | AH6: =_xlfn.XLOOKUP(AE6,$W$4:$W$102,$C$4:$C$102,"N/A",0,1) -> CNH Industrial NV | AI6: =_xlfn.XLOOKUP(AE6,$W$4:$W$102,$E$4:$E$102,"N/A",0,1) -> United Kingdom | AJ6: 32.628737 | AK6: 5.9932603 | AL6: 2.1133665 | AM6: 2.3376157 | AN6: 15.586887 | AS6: 4.9599682e+09 | AT6: 1.7660773e+10 | AU6: 2.3196086e+10 | AV6: 6.6339525e+09 | AW6: 5.4908513e+10 | AX6: 6.1121149e+10 | AY6: 2.223804 | AZ6: 2.7489033
B7: FTT.TO | C7: Finning International Inc | E7: Canada | F7: =AS7/AT7 -> 0.20723946 | G7: =AU7/AV7 -> 2.9626374 | H7: =AX7 -> 4.0309796e+09 | I7: =IFERROR((AY7/AZ7)-1,"-") -> 0.0079973492 | J7: =AV7/AX7 -> 0.17044287 | K7: =IFERROR(_xlfn.RANK.EQ(F7,F$3:F$102),"N/A") -> 22 | L7: =IFERROR(_xlfn.RANK.EQ(G7,G$3:G$102),"N/A") -> 45 | M7: =IFERROR(_xlfn.RANK.EQ(H7,H$3:H$102),"N/A") -> 35 | N7: =IFERROR(_xlfn.RANK.EQ(I7,I$3:I$102),"N/A") -> 64 | O7: =IFERROR(_xlfn.RANK.EQ(J7,J$3:J$102),"N/A") -> 25 | P7: =IFERROR(ABS(K$3-K7),"N/A") -> 14 | Q7: =IFERROR(ABS(L$3-L7),"N/A") -> 12 | R7: =IFERROR(ABS(M$3-M7),"N/A") -> 32 | S7: =IFERROR(ABS(N$3-N7),"N/A") -> 12 | T7: =IFERROR(ABS(O$3-O7),"N/A") -> 10 | U7: =SUM(P7:T7) -> 80 | V7: =_xlfn.RANK.EQ(U7,$U$4:$U$102,1) -> 7 | W7: =IF(Y7="Not suitable","-",V7) -> 7 | Y7: =IF(OR(Z7="Y",AA7="Y"),"Not suitable","") | Z7: =IF(OR(N7="N/A",O7="N/A"),"Y","") | AE7: 5 | AF7: =_xlfn.XLOOKUP(AE7,$W$4:$W$102,$U$4:$U$102,"N/A",0,1) -> 68 | AG7: =_xlfn.XLOOKUP(AE7,$W$4:$W$102,$B$4:$B$102,"N/A",0,1) -> CAT.N | AH7: =_xlfn.XLOOKUP(AE7,$W$4:$W$102,$C$4:$C$102,"N/A",0,1) -> Caterpillar Inc | AI7: =_xlfn.XLOOKUP(AE7,$W$4:$W$102,$E$4:$E$102,"N/A",0,1) -> United States of America | AJ7: 10.182114 | AK7: 1.754149 | AL7: 0.69293461 | AM7: 0.95883191 | AN7: 7.5926772 | AS7: 3.9335598e+08 | AT7: 1.8980747e+09 | AU7: 2.0354851e+09 | AV7: 6.8705172e+08 | AW7: 7.9479049e+09 | AX7: 4.0309796e+09 | AY7: 2.9298186 | AZ7: 2.9065737
B8: DEZG.DE | C8: DEUTZ AG | E8: Germany | F8: =AS8/AT8 -> 0.14383746 | G8: =AU8/AV8 -> 2.0526316 | H8: =AX8 -> 8.0990641e+08 | I8: =IFERROR((AY8/AZ8)-1,"-") -> 0.12527417 | J8: =AV8/AX8 -> 0.16828353 | K8: =IFERROR(_xlfn.RANK.EQ(F8,F$3:F$102),"N/A") -> 50 | L8: =IFERROR(_xlfn.RANK.EQ(G8,G$3:G$102),"N/A") -> 60 | M8: =IFERROR(_xlfn.RANK.EQ(H8,H$3:H$102),"N/A") -> 72 | N8: =IFERROR(_xlfn.RANK.EQ(I8,I$3:I$102),"N/A") -> 46 | O8: =IFERROR(_xlfn.RANK.EQ(J8,J$3:J$102),"N/A") -> 26 | P8: =IFERROR(ABS(K$3-K8),"N/A") -> 42 | Q8: =IFERROR(ABS(L$3-L8),"N/A") -> 27 | R8: =IFERROR(ABS(M$3-M8),"N/A") -> 69 | S8: =IFERROR(ABS(N$3-N8),"N/A") -> 30 | T8: =IFERROR(ABS(O$3-O8),"N/A") -> 9 | U8: =SUM(P8:T8) -> 177 | V8: =_xlfn.RANK.EQ(U8,$U$4:$U$102,1) -> 52 | W8: =IF(Y8="Not suitable","-",V8) -> 52 | Y8: =IF(OR(Z8="Y",AA8="Y"),"Not suitable","") | Z8: =IF(OR(N8="N/A",O8="N/A"),"Y","") | AE8: 6 | AF8: =_xlfn.XLOOKUP(AE8,$W$4:$W$102,$U$4:$U$102,"N/A",0,1) -> 71 | AG8: =_xlfn.XLOOKUP(AE8,$W$4:$W$102,$B$4:$B$102,"N/A",0,1) -> ALSN.N | AH8: =_xlfn.XLOOKUP(AE8,$W$4:$W$102,$C$4:$C$102,"N/A",0,1) -> Allison Transmission Holdings Inc | AI8: =_xlfn.XLOOKUP(AE8,$W$4:$W$102,$E$4:$E$102,"N/A",0,1) -> United States of America | AJ8: 14.439075 | AK8: 2.4781742 | AL8: 0.99669039 | AM8: 1.0836228 | AN8: 8.0335946 | AS8: 1.1797424e+08 | AT8: 8.2019136e+08 | AU8: 2.7976118e+08 | AV8: 1.3629391e+08 | AW8: 2.276936e+09 | AX8: 8.0990641e+08 | AY8: 0.85331832 | AZ8: 0.75832036
B9: FSTR.OQ | C9: L B Foster Co | E9: United States of America | F9: =AS9/AT9 -> 0.0091407421 | G9: =AU9/AV9 -> 58.551907 | H9: =AX9 -> 2.971543e+08 | I9: =IFERROR((AY9/AZ9)-1,"-") -> 5.2665065 | J9: =AV9/AX9 -> 0.0031768008 | K9: =IFERROR(_xlfn.RANK.EQ(F9,F$3:F$102),"N/A") -> 92 | L9: =IFERROR(_xlfn.RANK.EQ(G9,G$3:G$102),"N/A") -> 1 | M9: =IFERROR(_xlfn.RANK.EQ(H9,H$3:H$102),"N/A") -> 89 | N9: =IFERROR(_xlfn.RANK.EQ(I9,I$3:I$102),"N/A") -> 1 | O9: =IFERROR(_xlfn.RANK.EQ(J9,J$3:J$102),"N/A") -> 93 | P9: =IFERROR(ABS(K$3-K9),"N/A") -> 84 | Q9: =IFERROR(ABS(L$3-L9),"N/A") -> 32 | R9: =IFERROR(ABS(M$3-M9),"N/A") -> 86 | S9: =IFERROR(ABS(N$3-N9),"N/A") -> 75 | T9: =IFERROR(ABS(O$3-O9),"N/A") -> 58 | U9: =SUM(P9:T9) -> 335 | V9: =_xlfn.RANK.EQ(U9,$U$4:$U$102,1) -> 97 | W9: =IF(Y9="Not suitable","-",V9) -> 97 | Y9: =IF(OR(Z9="Y",AA9="Y"),"Not suitable","") | Z9: =IF(OR(N9="N/A",O9="N/A"),"Y","") | AE9: Median | AJ9: =MEDIAN(AJ3:AJ8) -> 13.708579 | AK9: =MEDIAN(AK3:AK8) -> 4.3602541 | AL9: =MEDIAN(AL3:AL8) -> 1.4974023 | AM9: =MEDIAN(AM3:AM8) -> 1.8927232 | AN9: =MEDIAN(AN3:AN8) -> 8.8339934 | AS9: 1299000 | AT9: 142111000 | AU9: 55273000 | AV9: 944000 | AW9: 543744000 | AX9: 2.971543e+08 | AY9: 1.09526 | AZ9: 0.17478
B10: MANP.PA | C10: Manitou BF SA | E10: France | F10: =AS10/AT10 -> 0.16038357 | G10: =AU10/AV10 -> 2.287254 | H10: =AX10 -> 1.0853628e+09 | I10: =IFERROR((AY10/AZ10)-1,"-") -> 0.22217785 | J10: =AV10/AX10 -> 0.21113702 | K10: =IFERROR(_xlfn.RANK.EQ(F10,F$3:F$102),"N/A") -> 42 | L10: =IFERROR(_xlfn.RANK.EQ(G10,G$3:G$102),"N/A") -> 57 | M10: =IFERROR(_xlfn.RANK.EQ(H10,H$3:H$102),"N/A") -> 66 | N10: =IFERROR(_xlfn.RANK.EQ(I10,I$3:I$102),"N/A") -> 33 | O10: =IFERROR(_xlfn.RANK.EQ(J10,J$3:J$102),"N/A") -> 15 | P10: =IFERROR(ABS(K$3-K10),"N/A") -> 34 | Q10: =IFERROR(ABS(L$3-L10),"N/A") -> 24 | R10: =IFERROR(ABS(M$3-M10),"N/A") -> 63 | S10: =IFERROR(ABS(N$3-N10),"N/A") -> 43 | T10: =IFERROR(ABS(O$3-O10),"N/A") -> 20 | U10: =SUM(P10:T10) -> 184 | V10: =_xlfn.RANK.EQ(U10,$U$4:$U$102,1) -> 59 | W10: =IF(Y10="Not suitable","-",V10) -> 59 | Y10: =IF(OR(Z10="Y",AA10="Y"),"Not suitable","") | Z10: =IF(OR(N10="N/A",O10="N/A"),"Y","") | AE10: Benchmark Data | AJ10: Price / Share | AS10: 1.5837021e+08 | AT10: 9.8744661e+08 | AU10: 5.2414775e+08 | AV10: 2.2916028e+08 | AW10: 3.1687639e+09 | AX10: 1.0853628e+09 | AY10: 3.8197986 | AZ10: 3.1254032
B11: ASTE.OQ | C11: Astec Industries Inc | E11: United States of America | F11: =AS11/AT11 -> 0.05157637 | G11: =AU11/AV11 -> 1.7098765 | H11: =AX11 -> 9.6136263e+08 | I11: =IFERROR((AY11/AZ11)-1,"-") -> 0.14694792 | J11: =AV11/AX11 -> 0.050553244 | K11: =IFERROR(_xlfn.RANK.EQ(F11,F$3:F$102),"N/A") -> 85 | L11: =IFERROR(_xlfn.RANK.EQ(G11,G$3:G$102),"N/A") -> 68 | M11: =IFERROR(_xlfn.RANK.EQ(H11,H$3:H$102),"N/A") -> 69 | N11: =IFERROR(_xlfn.RANK.EQ(I11,I$3:I$102),"N/A") -> 42 | O11: =IFERROR(_xlfn.RANK.EQ(J11,J$3:J$102),"N/A") -> 76 | P11: =IFERROR(ABS(K$3-K11),"N/A") -> 77 | Q11: =IFERROR(ABS(L$3-L11),"N/A") -> 35 | R11: =IFERROR(ABS(M$3-M11),"N/A") -> 66 | S11: =IFERROR(ABS(N$3-N11),"N/A") -> 34 | T11: =IFERROR(ABS(O$3-O11),"N/A") -> 41 | U11: =SUM(P11:T11) -> 253 | V11: =_xlfn.RANK.EQ(U11,$U$4:$U$102,1) -> 84 | W11: =IF(Y11="Not suitable","-",V11) -> 84 | Y11: =IF(OR(Z11="Y",AA11="Y"),"Not suitable","") | Z11: =IF(OR(N11="N/A",O11="N/A"),"Y","") | AE11: Benchmark | AF11: Multiplier | AG11: # Shares | AH11: -Debt + Cash | AJ11: P / E | AK11: P / B | AL11: Price / Sales | AM11: EV / Sales | AN11: EV / EBITDA | AS11: 33700000 | AT11: 653400000 | AU11: 83100000 | AV11: 48600000 | AW11: 1338200000 | AX11: 9.6136263e+08 | AY11: 2.73445 | AZ11: 2.38411
B12: LNN.N | C12: Lindsay Corp | E12: United States of America | F12: =AS12/AT12 -> 0.1586214 | G12: =AU12/AV12 -> 1.1292375 | H12: =AX12 -> 1.2945906e+09 | I12: =IFERROR((AY12/AZ12)-1,"-") -> 0.0018217496 | J12: =AV12/AX12 -> 0.078931514 | K12: =IFERROR(_xlfn.RANK.EQ(F12,F$3:F$102),"N/A") -> 44 | L12: =IFERROR(_xlfn.RANK.EQ(G12,G$3:G$102),"N/A") -> 73 | M12: =IFERROR(_xlfn.RANK.EQ(H12,H$3:H$102),"N/A") -> 58 | N12: =IFERROR(_xlfn.RANK.EQ(I12,I$3:I$102),"N/A") -> 66 | O12: =IFERROR(_xlfn.RANK.EQ(J12,J$3:J$102),"N/A") -> 60 | P12: =IFERROR(ABS(K$3-K12),"N/A") -> 36 | Q12: =IFERROR(ABS(L$3-L12),"N/A") -> 40 | R12: =IFERROR(ABS(M$3-M12),"N/A") -> 55 | S12: =IFERROR(ABS(N$3-N12),"N/A") -> 10 | T12: =IFERROR(ABS(O$3-O12),"N/A") -> 25 | U12: =SUM(P12:T12) -> 166 | V12: =_xlfn.RANK.EQ(U12,$U$4:$U$102,1) -> 44 | W12: =IF(Y12="Not suitable","-",V12) -> 44 | Y12: =IF(OR(Z12="Y",AA12="Y"),"Not suitable","") | Z12: =IF(OR(N12="N/A",O12="N/A"),"Y","") | AE12: =C3 -> Paccar Inc | AF12: 1000000 | AG12: =OP!C20 -> 524010700 | AH12: =-'Fin. Data'!B58*SARD!AF12+'Fin. Data'!B39*SARD!AF12 -> -7056000000 | AJ12: =AJ9*'Fin. Data'!B23*AF$12/AG$12 -> 120.36619 | AK12: =AK9*'Fin. Data'!B64*AF$12/AG$12 -> 132.11966 | AL12: =AL9*'Fin. Data'!B5*AF$12/AG$12 -> 100.3782 | AM12: =(AM9*'Fin. Data'!B5*$AF12+$AH12)/$AG12 -> 113.41312 | AN12: =(AN9*'Fin. Data'!B19*$AF12+$AH12)/$AG12 -> 100.68131 | AS12: 72276000 | AT12: 455651000 | AU12: 115390000 | AV12: 102184000 | AW12: 674084000 | AX12: 1.2945906e+09 | AY12: 5.91717 | AZ12: 5.90641
B13: KEPL3.SA | C13: Kepler Weber SA | E13: Brazil | F13: =AS13/AT13 -> 0.33766591 | G13: =AU13/AV13 -> 0.65205102 | H13: =AX13 -> 3.7019596e+08 | I13: =IFERROR((AY13/AZ13)-1,"-") -> -0.25032692 | J13: =AV13/AX13 -> 0.16800597 | K13: =IFERROR(_xlfn.RANK.EQ(F13,F$3:F$102),"N/A") -> 7 | L13: =IFERROR(_xlfn.RANK.EQ(G13,G$3:G$102),"N/A") -> 82 | M13: =IFERROR(_xlfn.RANK.EQ(H13,H$3:H$102),"N/A") -> 87 | N13: =IFERROR(_xlfn.RANK.EQ(I13,I$3:I$102),"N/A") -> 89 | O13: =IFERROR(_xlfn.RANK.EQ(J13,J$3:J$102),"N/A") -> 27 | P13: =IFERROR(ABS(K$3-K13),"N/A") -> 1 | Q13: =IFERROR(ABS(L$3-L13),"N/A") -> 49 | R13: =IFERROR(ABS(M$3-M13),"N/A") -> 84 | S13: =IFERROR(ABS(N$3-N13),"N/A") -> 13 | T13: =IFERROR(ABS(O$3-O13),"N/A") -> 8 | U13: =SUM(P13:T13) -> 155 | V13: =_xlfn.RANK.EQ(U13,$U$4:$U$102,1) -> 41 | W13: =IF(Y13="Not suitable","-",V13) -> 41 | Y13: =IF(OR(Z13="Y",AA13="Y"),"Not suitable","") | Z13: =IF(OR(N13="N/A",O13="N/A"),"Y","") | AE13: By Consolidated Average | AJ13: =AVERAGE(AJ12:AL12) -> 117.62135 | AM13: =AVERAGE(AM12:AN12) -> 107.04722 | AS13: 50537705 | AT13: 1.4966777e+08 | AU13: 40554399 | AV13: 62195132 | AW13: 3.1164527e+08 | AX13: 3.7019596e+08 | AY13: 0.28088985 | AZ13: 0.37468313
B14: MTW.N | C14: Manitowoc Company Inc | E14: United States of America | F14: =AS14/AT14 -> 0.064975966 | G14: =AU14/AV14 -> 4.0270563 | H14: =AX14 -> 4.7973697e+08 | I14: =IFERROR((AY14/AZ14)-1,"-") -> -0.24282759 | J14: =AV14/AX14 -> 0.19260554 | K14: =IFERROR(_xlfn.RANK.EQ(F14,F$3:F$102),"N/A") -> 79 | L14: =IFERROR(_xlfn.RANK.EQ(G14,G$3:G$102),"N/A") -> 35 | M14: =IFERROR(_xlfn.RANK.EQ(H14,H$3:H$102),"N/A") -> 85 | N14: =IFERROR(_xlfn.RANK.EQ(I14,I$3:I$102),"N/A") -> 88 | O14: =IFERROR(_xlfn.RANK.EQ(J14,J$3:J$102),"N/A") -> 23 | P14: =IFERROR(ABS(K$3-K14),"N/A") -> 71 | Q14: =IFERROR(ABS(L$3-L14),"N/A") -> 2 | R14: =IFERROR(ABS(M$3-M14),"N/A") -> 82 | S14: =IFERROR(ABS(N$3-N14),"N/A") -> 12 | T14: =IFERROR(ABS(O$3-O14),"N/A") -> 12 | U14: =SUM(P14:T14) -> 179 | V14: =_xlfn.RANK.EQ(U14,$U$4:$U$102,1) -> 56 | W14: =IF(Y14="Not suitable","-",V14) -> 56 | Y14: =IF(OR(Z14="Y",AA14="Y"),"Not suitable","") | Z14: =IF(OR(N14="N/A",O14="N/A"),"Y","") | AE14: Upside | AJ14: =AJ13/OP!C19-1 -> 0.11047345 | AM14: =AM13/OP!C19-1 -> 0.010642162 | AS14: 39200000 | AT14: 603300000 | AU14: 372100000 | AV14: 92400000 | AW14: 2227800000 | AX14: 4.7973697e+08 | AY14: 1.26285 | AZ14: 1.66785
B15: CAT.N | C15: Caterpillar Inc | E15: United States of America | F15: =AS15/AT15 -> 0.52677747 | G15: =AU15/AV15 -> 2.9213327 | H15: =AX15 -> 1.7797306e+11 | I15: =IFERROR((AY15/AZ15)-1,"-") -> 0.026531404 | J15: =AV15/AX15 -> 0.072853721 | K15: =IFERROR(_xlfn.RANK.EQ(F15,F$3:F$102),"N/A") -> 3 | L15: =IFERROR(_xlfn.RANK.EQ(G15,G$3:G$102),"N/A") -> 46 | M15: =IFERROR(_xlfn.RANK.EQ(H15,H$3:H$102),"N/A") -> 1 | N15: =IFERROR(_xlfn.RANK.EQ(I15,I$3:I$102),"N/A") -> 59 | O15: =IFERROR(_xlfn.RANK.EQ(J15,J$3:J$102),"N/A") -> 66 | P15: =IFERROR(ABS(K$3-K15),"N/A") -> 5 | Q15: =IFERROR(ABS(L$3-L15),"N/A") -> 13 | R15: =IFERROR(ABS(M$3-M15),"N/A") -> 2 | S15: =IFERROR(ABS(N$3-N15),"N/A") -> 17 | T15: =IFERROR(ABS(O$3-O15),"N/A") -> 31 | U15: =SUM(P15:T15) -> 68 | V15: =_xlfn.RANK.EQ(U15,$U$4:$U$102,1) -> 5 | W15: =IF(Y15="Not suitable","-",V15) -> 5 | Y15: =IF(OR(Z15="Y",AA15="Y"),"Not suitable","") | Z15: =IF(OR(N15="N/A",O15="N/A"),"Y","") | AS15: 10269000000 | AT15: 19494000000 | AU15: 37878000000 | AV15: 12966000000 | AW15: 67060000000 | AX15: 1.7797306e+11 | AY15: 21.28402 | AZ15: 20.73392
B16: 6305.T | C16: Hitachi Construction Machinery Co Ltd | E16: Japan | F16: =AS16/AT16 -> 0.11473169 | G16: =AU16/AV16 -> 4.3452479 | H16: =AX16 -> 6.6159762e+09 | I16: =IFERROR((AY16/AZ16)-1,"-") -> 0.25087742 | J16: =AV16/AX16 -> 0.15174117 | K16: =IFERROR(_xlfn.RANK.EQ(F16,F$3:F$102),"N/A") -> 60 | L16: =IFERROR(_xlfn.RANK.EQ(G16,G$3:G$102),"N/A") -> 30 | M16: =IFERROR(_xlfn.RANK.EQ(H16,H$3:H$102),"N/A") -> 27 | N16: =IFERROR(_xlfn.RANK.EQ(I16,I$3:I$102),"N/A") -> 30 | O16: =IFERROR(_xlfn.RANK.EQ(J16,J$3:J$102),"N/A") -> 30 | P16: =IFERROR(ABS(K$3-K16),"N/A") -> 52 | Q16: =IFERROR(ABS(L$3-L16),"N/A") -> 3 | R16: =IFERROR(ABS(M$3-M16),"N/A") -> 24 | S16: =IFERROR(ABS(N$3-N16),"N/A") -> 46 | T16: =IFERROR(ABS(O$3-O16),"N/A") -> 5 | U16: =SUM(P16:T16) -> 130 | V16: =_xlfn.RANK.EQ(U16,$U$4:$U$102,1) -> 26 | W16: =IF(Y16="Not suitable","-",V16) -> 26 | Y16: =IF(OR(Z16="Y",AA16="Y"),"Not suitable","") | Z16: =IF(OR(N16="N/A",O16="N/A"),"Y","") | AS16: 5.7023872e+08 | AT16: 4.9701935e+09 | AU16: 4.3622637e+09 | AV16: 1.003916e+09 | AW16: 9.6352737e+09 | AX16: 6.6159762e+09 | AY16: 2.9053742 | AZ16: 2.322669
B17: 6301.T | C17: Komatsu Ltd | E17: Japan | F17: =AS17/AT17 -> 0.13422645 | G17: =AU17/AV17 -> 2.1466051 | H17: =AX17 -> 2.8954079e+10 | I17: =IFERROR((AY17/AZ17)-1,"-") -> 0.11032005 | J17: =AV17/AX17 -> 0.12767776 | K17: =IFERROR(_xlfn.RANK.EQ(F17,F$3:F$102),"N/A") -> 52 | L17: =IFERROR(_xlfn.RANK.EQ(G17,G$3:G$102),"N/A") -> 58 | M17: =IFERROR(_xlfn.RANK.EQ(H17,H$3:H$102),"N/A") -> 7 | N17: =IFERROR(_xlfn.RANK.EQ(I17,I$3:I$102),"N/A") -> 49 | O17: =IFERROR(_xlfn.RANK.EQ(J17,J$3:J$102),"N/A") -> 40 | P17: =IFERROR(ABS(K$3-K17),"N/A") -> 44 | Q17: =IFERROR(ABS(L$3-L17),"N/A") -> 25 | R17: =IFERROR(ABS(M$3-M17),"N/A") -> 4 | S17: =IFERROR(ABS(N$3-N17),"N/A") -> 27 | T17: =IFERROR(ABS(O$3-O17),"N/A") -> 5 | U17: =SUM(P17:T17) -> 105 | V17: =_xlfn.RANK.EQ(U17,$U$4:$U$102,1) -> 15 | W17: =IF(Y17="Not suitable","-",V17) -> 15 | Y17: =IF(OR(Z17="Y",AA17="Y"),"Not suitable","") | Z17: =IF(OR(N17="N/A",O17="N/A"),"Y","") | AS17: 2.5671135e+09 | AT17: 1.9125243e+10 | AU17: 7.9355524e+09 | AV17: 3.6967919e+09 | AW17: 2.6684803e+10 | AX17: 2.8954079e+10 | AY17: 2.735151 | AZ17: 2.4633897
B18: DE.N | C18: Deere & Co | E18: United States of America | F18: =AS18/AT18 -> 0.46582511 | G18: =AU18/AV18 -> 4.0749952 | H18: =AX18 -> 1.1093131e+11 | I18: =IFERROR((AY18/AZ18)-1,"-") -> -0.19491144 | J18: =AV18/AX18 -> 0.14027599 | K18: =IFERROR(_xlfn.RANK.EQ(F18,F$3:F$102),"N/A") -> 4 | L18: =IFERROR(_xlfn.RANK.EQ(G18,G$3:G$102),"N/A") -> 33 | M18: =IFERROR(_xlfn.RANK.EQ(H18,H$3:H$102),"N/A") -> 2 | N18: =IFERROR(_xlfn.RANK.EQ(I18,I$3:I$102),"N/A") -> 85 | O18: =IFERROR(_xlfn.RANK.EQ(J18,J$3:J$102),"N/A") -> 33 | P18: =IFERROR(ABS(K$3-K18),"N/A") -> 4 | Q18: =IFERROR(ABS(L$3-L18),"N/A") -> 0 | R18: =IFERROR(ABS(M$3-M18),"N/A") -> 1 | S18: =IFERROR(ABS(N$3-N18),"N/A") -> 9 | T18: =IFERROR(ABS(O$3-O18),"N/A") -> 2 | U18: =SUM(P18:T18) -> 16 | V18: =_xlfn.RANK.EQ(U18,$U$4:$U$102,1) -> 1 | W18: =IF(Y18="Not suitable","-",V18) -> 1 | Y18: =IF(OR(Z18="Y",AA18="Y"),"Not suitable","") | Z18: =IF(OR(N18="N/A",O18="N/A"),"Y","") | AS18: 10148000000 | AT18: 21785000000 | AU18: 63411000000 | AV18: 15561000000 | AW18: 61218000000 | AX18: 1.1093131e+11 | AY18: 27.34819 | AZ18: 33.96917
B19: OSK.N | C19: Oshkosh Corp | E19: United States of America | F19: =AS19/AT19 -> 0.16398132 | G19: =AU19/AV19 -> 0.99307545 | H19: =AX19 -> 7.8939627e+09 | I19: =IFERROR((AY19/AZ19)-1,"-") -> 0.083763981 | J19: =AV19/AX19 -> 0.1061064 | K19: =IFERROR(_xlfn.RANK.EQ(F19,F$3:F$102),"N/A") -> 40 | L19: =IFERROR(_xlfn.RANK.EQ(G19,G$3:G$102),"N/A") -> 76 | M19: =IFERROR(_xlfn.RANK.EQ(H19,H$3:H$102),"N/A") -> 22 | N19: =IFERROR(_xlfn.RANK.EQ(I19,I$3:I$102),"N/A") -> 53 | O19: =IFERROR(_xlfn.RANK.EQ(J19,J$3:J$102),"N/A") -> 47 | P19: =IFERROR(ABS(K$3-K19),"N/A") -> 32 | Q19: =IFERROR(ABS(L$3-L19),"N/A") -> 43 | R19: =IFERROR(ABS(M$3-M19),"N/A") -> 19 | S19: =IFERROR(ABS(N$3-N19),"N/A") -> 23 | T19: =IFERROR(ABS(O$3-O19),"N/A") -> 12 | U19: =SUM(P19:T19) -> 129 | V19: =_xlfn.RANK.EQ(U19,$U$4:$U$102,1) -> 24 | W19: =IF(Y19="Not suitable","-",V19) -> 24 | Y19: =IF(OR(Z19="Y",AA19="Y"),"Not suitable","") | Z19: =IF(OR(N19="N/A",O19="N/A"),"Y","") | AS19: 607600000 | AT19: 3705300000 | AU19: 831800000 | AV19: 837600000 | AW19: 9657900000 | AX19: 7.8939627e+09 | AY19: 10.39981 | AZ19: 9.59601
B20: 6294.T | C20: Okada Aiyon Corp | E20: Japan | F20: =AS20/AT20 -> 0.1013061 | G20: =AU20/AV20 -> 4.9067575 | H20: =AX20 -> 1.7498242e+08 | I20: =IFERROR((AY20/AZ20)-1,"-") -> 0.40887707 | J20: =AV20/AX20 -> 0.083981886 | K20: =IFERROR(_xlfn.RANK.EQ(F20,F$3:F$102),"N/A") -> 65 | L20: =IFERROR(_xlfn.RANK.EQ(G20,G$3:G$102),"N/A") -> 25 | M20: =IFERROR(_xlfn.RANK.EQ(H20,H$3:H$102),"N/A") -> 97 | N20: =IFERROR(_xlfn.RANK.EQ(I20,I$3:I$102),"N/A") -> 18 | O20: =IFERROR(_xlfn.RANK.EQ(J20,J$3:J$102),"N/A") -> 57 | P20: =IFERROR(ABS(K$3-K20),"N/A") -> 57 | Q20: =IFERROR(ABS(L$3-L20),"N/A") -> 8 | R20: =IFERROR(ABS(M$3-M20),"N/A") -> 94 | S20: =IFERROR(ABS(N$3-N20),"N/A") -> 58 | T20: =IFERROR(ABS(O$3-O20),"N/A") -> 22 | U20: =SUM(P20:T20) -> 239 | V20: =_xlfn.RANK.EQ(U20,$U$4:$U$102,1) -> 79 | W20: =IF(Y20="Not suitable","-",V20) -> 79 | Y20: =IF(OR(Z20="Y",AA20="Y"),"Not suitable","") | Z20: =IF(OR(N20="N/A",O20="N/A"),"Y","") | AS20: 10650990 | AT20: 1.0513671e+08 | AU20: 72106537 | AV20: 14695354 | AW20: 1.7754116e+08 | AX20: 1.7498242e+08 | AY20: 1.8202837 | AZ20: 1.2920103
B21: TEX.N | C21: Terex Corp | E21: United States of America | F21: =AS21/AT21 -> 0.30897566 | G21: =AU21/AV21 -> 0.97910448 | H21: =AX21 -> 3015000000 | I21: =IFERROR((AY21/AZ21)-1,"-") -> -0.01649684 | J21: =AV21/AX21 -> 0.21111111 | K21: =IFERROR(_xlfn.RANK.EQ(F21,F$3:F$102),"N/A") -> 10 | L21: =IFERROR(_xlfn.RANK.EQ(G21,G$3:G$102),"N/A") -> 77 | M21: =IFERROR(_xlfn.RANK.EQ(H21,H$3:H$102),"N/A") -> 41 | N21: =IFERROR(_xlfn.RANK.EQ(I21,I$3:I$102),"N/A") -> 69 | O21: =IFERROR(_xlfn.RANK.EQ(J21,J$3:J$102),"N/A") -> 16 | P21: =IFERROR(ABS(K$3-K21),"N/A") -> 2 | Q21: =IFERROR(ABS(L$3-L21),"N/A") -> 44 | R21: =IFERROR(ABS(M$3-M21),"N/A") -> 38 | S21: =IFERROR(ABS(N$3-N21),"N/A") -> 7 | T21: =IFERROR(ABS(O$3-O21),"N/A") -> 19 | U21: =SUM(P21:T21) -> 110 | V21: =_xlfn.RANK.EQ(U21,$U$4:$U$102,1) -> 18 | W21: =IF(Y21="Not suitable","-",V21) -> 18 | Y21: =IF(OR(Z21="Y",AA21="Y"),"Not suitable","") | Z21: =IF(OR(N21="N/A",O21="N/A"),"Y","") | AS21: 516700000 | AT21: 1672300000 | AU21: 623200000 | AV21: 636500000 | AW21: 5151500000 | AX21: 3015000000 | AY21: 6.96394 | AZ21: 7.08075
B22: TTC.N | C22: Toro Co | E22: United States of America | F22: =AS22/AT22 -> 0.21821431 | G22: =AU22/AV22 -> 2.3949385 | H22: =AX22 -> 9312042492 | I22: =IFERROR((AY22/AZ22)-1,"-") -> 0.05104826 | J22: =AV22/AX22 -> 0.046251937 | K22: =IFERROR(_xlfn.RANK.EQ(F22,F$3:F$102),"N/A") -> 21 | L22: =IFERROR(_xlfn.RANK.EQ(G22,G$3:G$102),"N/A") -> 54 | M22: =IFERROR(_xlfn.RANK.EQ(H22,H$3:H$102),"N/A") -> 19 | N22: =IFERROR(_xlfn.RANK.EQ(I22,I$3:I$102),"N/A") -> 56 | O22: =IFERROR(_xlfn.RANK.EQ(J22,J$3:J$102),"N/A") -> 80 | P22: =IFERROR(ABS(K$3-K22),"N/A") -> 13 | Q22: =IFERROR(ABS(L$3-L22),"N/A") -> 21 | R22: =IFERROR(ABS(M$3-M22),"N/A") -> 16 | S22: =IFERROR(ABS(N$3-N22),"N/A") -> 20 | T22: =IFERROR(ABS(O$3-O22),"N/A") -> 45 | U22: =SUM(P22:T22) -> 115 | V22: =_xlfn.RANK.EQ(U22,$U$4:$U$102,1) -> 21 | W22: =IF(Y22="Not suitable","-",V22) -> 21 | Y22: =IF(OR(Z22="Y",AA22="Y"),"Not suitable","") | Z22: =IF(OR(N22="N/A",O22="N/A"),"Y","") | AS22: 329700000 | AT22: 1510900000 | AU22: 1031500000 | AV22: 430700000 | AW22: 4553200000 | AX22: 9312042492 | AY22: 4.28587 | AZ22: 4.07771
B23: TIH.TO | C23: Toromont Industries Ltd | E23: Canada | F23: =AS23/AT23 -> 0.19714463 | G23: =AU23/AV23 -> 0.9685244 | H23: =AX23 -> 7.7876213e+09 | I23: =IFERROR((AY23/AZ23)-1,"-") -> 0.028357979 | J23: =AV23/AX23 -> 0.068274182 | K23: =IFERROR(_xlfn.RANK.EQ(F23,F$3:F$102),"N/A") -> 27 | L23: =IFERROR(_xlfn.RANK.EQ(G23,G$3:G$102),"N/A") -> 78 | M23: =IFERROR(_xlfn.RANK.EQ(H23,H$3:H$102),"N/A") -> 23 | N23: =IFERROR(_xlfn.RANK.EQ(I23,I$3:I$102),"N/A") -> 58 | O23: =IFERROR(_xlfn.RANK.EQ(J23,J$3:J$102),"N/A") -> 69 | P23: =IFERROR(ABS(K$3-K23),"N/A") -> 19 | Q23: =IFERROR(ABS(L$3-L23),"N/A") -> 45 | R23: =IFERROR(ABS(M$3-M23),"N/A") -> 20 | S23: =IFERROR(ABS(N$3-N23),"N/A") -> 18 | T23: =IFERROR(ABS(O$3-O23),"N/A") -> 34 | U23: =SUM(P23:T23) -> 136 | V23: =_xlfn.RANK.EQ(U23,$U$4:$U$102,1) -> 28 | W23: =IF(Y23="Not suitable","-",V23) -> 28 | Y23: =IF(OR(Z23="Y",AA23="Y"),"Not suitable","") | Z23: =IF(OR(N23="N/A",O23="N/A"),"Y","") | AS23: 3.9947678e+08 | AT23: 2.0263133e+09 | AU23: 5.149581e+08 | AV23: 5.3169347e+08 | AW23: 3.489846e+09 | AX23: 7.7876213e+09 | AY23: 4.7987224 | AZ23: 4.666393
B24: TRN.N | C24: Trinity Industries Inc | E24: United States of America | F24: =AS24/AT24 -> 0.1349918 | G24: =AU24/AV24 -> 13.799041 | H24: =AX24 -> 2.2462071e+09 | I24: =IFERROR((AY24/AZ24)-1,"-") -> 0.16952113 | J24: =AV24/AX24 -> 0.18564629 | K24: =IFERROR(_xlfn.RANK.EQ(F24,F$3:F$102),"N/A") -> 51 | L24: =IFERROR(_xlfn.RANK.EQ(G24,G$3:G$102),"N/A") -> 4 | M24: =IFERROR(_xlfn.RANK.EQ(H24,H$3:H$102),"N/A") -> 47 | N24: =IFERROR(_xlfn.RANK.EQ(I24,I$3:I$102),"N/A") -> 39 | O24: =IFERROR(_xlfn.RANK.EQ(J24,J$3:J$102),"N/A") -> 24 | P24: =IFERROR(ABS(K$3-K24),"N/A") -> 43 | Q24: =IFERROR(ABS(L$3-L24),"N/A") -> 29 | R24: =IFERROR(ABS(M$3-M24),"N/A") -> 44 | S24: =IFERROR(ABS(N$3-N24),"N/A") -> 37 | T24: =IFERROR(ABS(O$3-O24),"N/A") -> 11 | U24: =SUM(P24:T24) -> 164 | V24: =_xlfn.RANK.EQ(U24,$U$4:$U$102,1) -> 43 | W24: =IF(Y24="Not suitable","-",V24) -> 43 | Y24: =IF(OR(Z24="Y",AA24="Y"),"Not suitable","") | Z24: =IF(OR(N24="N/A",O24="N/A"),"Y","") | AS24: 140000000 | AT24: 1037100000 | AU24: 5754200000 | AV24: 417000000 | AW24: 2983300000 | AX24: 2.2462071e+09 | AY24: 1.40601 | AZ24: 1.20221
B25: 000425.SZ | C25: XCMG Construction Machinery Co Ltd | E25: China | F25: =AS25/AT25 -> 0.080644995 | G25: =AU25/AV25 -> 15.951746 | H25: =AX25 -> 1.0133849e+10 | I25: =IFERROR((AY25/AZ25)-1,"-") -> -0.13201458 | J25: =AV25/AX25 -> 0.07144149 | K25: =IFERROR(_xlfn.RANK.EQ(F25,F$3:F$102),"N/A") -> 73 | L25: =IFERROR(_xlfn.RANK.EQ(G25,G$3:G$102),"N/A") -> 3 | M25: =IFERROR(_xlfn.RANK.EQ(H25,H$3:H$102),"N/A") -> 16 | N25: =IFERROR(_xlfn.RANK.EQ(I25,I$3:I$102),"N/A") -> 78 | O25: =IFERROR(_xlfn.RANK.EQ(J25,J$3:J$102),"N/A") -> 67 | P25: =IFERROR(ABS(K$3-K25),"N/A") -> 65 | Q25: =IFERROR(ABS(L$3-L25),"N/A") -> 30 | R25: =IFERROR(ABS(M$3-M25),"N/A") -> 13 | S25: =IFERROR(ABS(N$3-N25),"N/A") -> 2 | T25: =IFERROR(ABS(O$3-O25),"N/A") -> 32 | U25: =SUM(P25:T25) -> 142 | V25: =_xlfn.RANK.EQ(U25,$U$4:$U$102,1) -> 33 | W25: =IF(Y25="Not suitable","-",V25) -> 33 | Y25: =IF(OR(Z25="Y",AA25="Y"),"Not suitable","") | Z25: =IF(OR(N25="N/A",O25="N/A"),"Y","") | AS25: 6.2266803e+08 | AT25: 7.7210996e+09 | AU25: 1.1548701e+10 | AV25: 7.2397726e+08 | AW25: 1.3602204e+10 | AX25: 1.0133849e+10 | AY25: 0.071923729 | AZ25: 0.082862831
B26: WNC.N | C26: Wabash National Corp | E26: United States of America | F26: =AS26/AT26 -> 0.4219412 | G26: =AU26/AV26 -> 1.2709289 | H26: =AX26 -> 1.2808873e+09 | I26: =IFERROR((AY26/AZ26)-1,"-") -> -0.52120622 | J26: =AV26/AX26 -> 0.24354133 | K26: =IFERROR(_xlfn.RANK.EQ(F26,F$3:F$102),"N/A") -> 5 | L26: =IFERROR(_xlfn.RANK.EQ(G26,G$3:G$102),"N/A") -> 71 | M26: =IFERROR(_xlfn.RANK.EQ(H26,H$3:H$102),"N/A") -> 59 | N26: =IFERROR(_xlfn.RANK.EQ(I26,I$3:I$102),"N/A") -> 97 | O26: =IFERROR(_xlfn.RANK.EQ(J26,J$3:J$102),"N/A") -> 9 | P26: =IFERROR(ABS(K$3-K26),"N/A") -> 3 | Q26: =IFERROR(ABS(L$3-L26),"N/A") -> 38 | R26: =IFERROR(ABS(M$3-M26),"N/A") -> 56 | S26: =IFERROR(ABS(N$3-N26),"N/A") -> 21 | T26: =IFERROR(ABS(O$3-O26),"N/A") -> 26 | U26: =SUM(P26:T26) -> 144 | V26: =_xlfn.RANK.EQ(U26,$U$4:$U$102,1) -> 35 | W26: =IF(Y26="Not suitable","-",V26) -> 35 | Y26: =IF(OR(Z26="Y",AA26="Y"),"Not suitable","") | Z26: =IF(OR(N26="N/A",O26="N/A"),"Y","") | AS26: 231855000 | AT26: 549496000 | AU26: 396465000 | AV26: 311949000 | AW26: 2536500000 | AX26: 1.2808873e+09 | AY26: 2.23127 | AZ26: 4.66019
