Workbook
Name Sectors: '[1]Sector Impact'!$K$4:$K$16
Name Sectors: 'Sector Impact'!$K$4:$K$16

Sheet OP
B2: 45382 | C2: Team 12 | D2: 24th April, 2024 | E2: ='Inputs (AUD)'!H3 -> #VALUE! | L2: {=_FV(E2,"Exchange abbreviation",TRUE)} -> XASX | M2: SIC:
D3: COMPANY DESCRIPTION | H3: CEO & BOARD OF DIRECTORS
D4: Pilbara Minerals Limited is an Australia-based lithium company, The Company is primarily engaged in the exploration, development, and mining of minerals in Australia, Its 100% owned Pilgangoora hard-rock lithium operation consists of two processing plants: the Pilgan Plant, located on the northern side and produces spodumene and tantalite concentrates, and the Ngungaju Plant is located to the south produces spodumene concentrate, It owns 70% of the Mt Francisco project, and hosts the large occurrence of outcropping pegmatites, It is also pursuing a proposed downstream joint venture (JV) for the development of an approximately 43,000 tons per annum (tpa) lithium carbonate equivalent (LCE) lithium chemical conversion facility in South Korea, | H4: Name (Sex;Age) | I4: Tenure | J4: Executive? | K4: Other roles
H5: Dale Henderson (M;) | I5: 2 years | J5: YES | K5: Chief Executive Officer of Pilbara Minerals
H6: Kathleen Conlon (F;) | I6: 2 months | J6: NO | K6: Non-Executive Director of Aristocrat Leisure Limited and BlueScope Steel Limited, and Chairs the Corporate Governance Committee of the Australian Institute of Company Directors
H7: Sally-Anne Layman (F;) | I7: 6 years | J7: NO | K7: Non-Executive Director of IMDEX Ltd, Beach Energy Ltd and Newmount Corporation.
H8: Nick Cernotta (M;) | I8: 7 years | J8: NO | K8: Non-Executive Chair of Panoramic Resources Limited and a Non-Executive Director of Northern Star Resources Limited and New Century Resources. Limited
H9: Steve Scudamore (M;) | I9: 8 years | J9: NO | K9: Vice Chair of the Western Australian Museum and WA Committee Chair of the Australian British Chamber of Commerce and member of the National Board
H10: Miriam Stanborough (F;) | I10: 2 years | J10: NO | K10: Chair of the Minerals Research Institute of Western Australia (MRIWA), Deputy Chair of the Northern Agricultural Catchments Council (NACC), and Deputy Chair of Scouts | O10: https://www,marketscreener,com/quote/stock/PILBARA-MINERALS-LIMITED-10354122/company/
H11: EXECUTIVE LEADERSHIP TEAM
H12: =H5 -> Dale Henderson (M;) | I12: =I5 -> 2 years | J12: =J5 -> YES | K12: =K5 -> Chief Executive Officer of Pilbara Minerals
H13: Vince De Carolis (M;) | I13: 1 year | J13: YES | K13: Chief Operating Officer
H14: Luke Bortoli (M;) | I14: 1 year | J14: YES | K14: Chief Financial Officer
H15: Sandra McInnes (F;) | I15: 1 year | J15: YES | K15: Chief Sustainability Officer
H16: John Stanning (M;) | I16: 1 year | J16: YES | K16: Chief Development Officer
H17: Paul Laybourne (M;) | I17: 1 year | J17: YES | K17: Project Director
B18: {=_FV(E2,"Currency")&" MILLIONS"} -> AUD MILLIONS | H18: Jen Mintz (F;) | I18: 1 month | J18: YES | K18: General Counsel
B19: COMPANY OVERVIEW
B20: Stock | D20: Liquidity and Solvency | F20: Segments | I20: Profitability (2023) | L20: Multiples
B21: Last Price | C21: {=_FV(E2,"Price")} -> 3.83 | D21: Total Assets | E21: =_xlfn.XLOOKUP(D21,'Fin. Data'!A:A,'Fin. Data'!B:B,,0) -> 5198.8 | F21: Regions | H21: % Sales | I21: Reporting Year | J21: 2023 | L21: Float | M21: ='Inputs (AUD)'!B82 -> 0.9037
B22: Outstanding Shares | C22: {=_FV(E2,"Shares outstanding",TRUE)} -> 3009468000 | D22: Total Liabilities | E22: =_xlfn.XLOOKUP(D22,'Fin. Data'!A:A,'Fin. Data'!B:B,,0) -> 1808.8 | F22: =Segments!C5 -> Pilgan | H22: =Segments!B5 -> 0.69622735 | I22: End of Year | J22: 45107 | L22: Insiders Own | M22: ='Inputs (AUD)'!B83 -> 0.0963
B23: Market Cap. | C23: =C21*C22/1000000 -> 11526.262 | D23: Cash/Share | E23: =_xlfn.XLOOKUP("Cash & Eq.",'Fin. Data'!A:A,'Fin. Data'!B:B,,0)*1000000/C22 -> 1.0004094 | F23: =Segments!C6 -> Ngungaju | H23: =Segments!B6 -> 0.36616828 | I23: EBITDA | K23: =_xlfn.XLOOKUP(I23,'Fin. Data'!A:A,'Fin. Data'!B:B,,0) -> 3098.7 | L23: b (Yahoo) | M23: {=_FV(E2,"Beta")} -> 1.9343
B24: +Total Debt | C24: ='Fin. Data'!B58 -> 472 | D24: EBITDA/Net Financial Cost (NFC) | E24: =_xlfn.XLOOKUP("EBITDA",'Fin. Data'!A:A,'Fin. Data'!B:B,,0)/_xlfn.XLOOKUP("Net Financial Cost",'Fin. Data'!A:A,'Fin. Data'!B:B,,0) -> 69.013363 | F24: =Segments!C7 -> (elimination of by-product) | H24: =Segments!B7 -> -0.00050762558 | I24: Depreciation & Amortization | K24: =_xlfn.XLOOKUP(I24,'Fin. Data'!A:A,'Fin. Data'!B:B,,0) -> 1.5 | L24: Score (S&P) | M24: ='Inputs (AUD)'!B84 -> None
B25: -Cash | C25: ='Fin. Data'!B39 -> 3010.7 | D25: Debt/EBITDA | E25: =_xlfn.XLOOKUP("Total Debt",'Fin. Data'!A:A,'Fin. Data'!B:B,,0)/_xlfn.XLOOKUP("EBITDA",'Fin. Data'!A:A,'Fin. Data'!B:B,,0) -> 0.15232194 | F25: =Segments!C8 -> (provisional price adjustment) | H25: =Segments!B8 -> -0.061659653 | I25: EBIT | K25: =_xlfn.XLOOKUP(I25,'Fin. Data'!A:A,'Fin. Data'!B:B,,0) -> 3097.2 | L25: Price/Book Value | M25: =IFERROR((C21*C22/(E21-E22))/1000000,"") -> 3.4000774
B26: =Enterprise Value | C26: =C23+C24-C25 -> 8987.5624 | D26: "Others Assets"/Asset | E26: =_xlfn.XLOOKUP("Other Assets",'Fin. Data'!A:A,'Fin. Data'!B:B,,0)/_xlfn.XLOOKUP("Total Assets",'Fin. Data'!A:A,'Fin. Data'!B:B,,0) -> 0.078287297 | F26: =Segments!C9 -> (hedge close-outs) | H26: =Segments!B9 -> -0.00022834539 | I26: Net Income | K26: =_xlfn.XLOOKUP(I26,'Fin. Data'!A:A,'Fin. Data'!B:B,,0) -> 2391.1 | L26: NCF(3y avg)/Asset | M26: =IFERROR(K32/E21,"") -> 0.18521582
B27: Holdings (nac/int'l) | C27: - | D27: Debt/Assets | E27: =_xlfn.XLOOKUP(D27,'Fin. Data'!A:A,'Fin. Data'!B:B,,0) -> 0.090790182 | F27: Categories | H27: % Sales | I27: EPS | K27: =1000000*K26/C22 -> 0.79452581 | L27: Price/Net Inc. (3y avg) | M27: =IFERROR(C23/K31,"") -> 11.917556
B28: t liq. (Holdings/Vol.) | C28: - | D28: EBITDA Margin (average) | E28: =AVERAGE(_xlfn.XLOOKUP("EBITDA Margin",'Fin. Data'!A:A,'Fin. Data'!B:D,,0)) -> 0.39491807 | F28: =Segments!C15 -> Spodumene | H28: =Segments!B15 -> 1.061888 | I28: ROA | K28: =K26/E21 -> 0.45993306 | L28: EV/Asset | M28: =IFERROR(C26/E21,"") -> 1.7287763
B29: % Short | C29: N/A | D29: Operating Margin (average) | E29: =AVERAGE(_xlfn.XLOOKUP("Operating Margin",'Fin. Data'!A:A,'Fin. Data'!B:D,,0)) -> 0.40216289 | F29: =Segments!C16 -> Tantalite | H29: =Segments!B16 -> 0.00050762558 | I29: ROIC | K29: =K26/(E21-(E22-C24)) -> 0.61913516 | L29: EV/Ebitda (3y average) | M29: =IFERROR(C26/K30,"") -> 7.1094759
B30: Traffic ESG | D30: Net Income Margin (average) | E30: =AVERAGE(_xlfn.XLOOKUP("Net Income Margin",'Fin. Data'!A:A,'Fin. Data'!B:D,,0)) -> 0.25608103 | F30: =Segments!C17 -> (elimination of by-product) | H30: =Segments!B17 -> -0.00050762558 | I30: EBITDA (3y average) | K30: =AVERAGE(_xlfn.XLOOKUP("EBITDA",'Fin. Data'!A:A,'Fin. Data'!B:D,,0)) -> 1264.1667 | L30: Price/NCF (3y average) | M30: =IFERROR(C23/K32,"") -> 11.970363
B31: E | F31: =Segments!C18 -> (provisional price adjustment) | H31: =Segments!B18 -> -0.061659653 | I31: Net Income (3y average) | K31: =AVERAGE(_xlfn.XLOOKUP("Net Income",'Fin. Data'!A:A,'Fin. Data'!B:D,,0)) -> 967.16667 | L31: Bonds 1,3,5a (USD) | M31: -
B32: S | D32: Net Financial Cost/Avg Net Debt | E32: =-_xlfn.XLOOKUP("Net Financial Cost",'Fin. Data'!A:A,'Fin. Data'!B:B,,0)/AVERAGE(_xlfn.XLOOKUP("Net Debt",'Fin. Data'!A:A,'Fin. Data'!B:D,,0)) -> 0.050530817 | F32: =Segments!C19 -> (hedge close-outs) | H32: =Segments!B19 -> -0.00022834539 | I32: NCF (3y average) | K32: =AVERAGE(_xlfn.XLOOKUP("Net Cash Flow",'Fin. Data'!A:A,'Fin. Data'!B:D,,0)) -> 962.9 | L32: Div+Rep.(3y avg)/Price | M32: =-IFERROR(SUM(E53:E55)/(3*C23),"") -> 0.0024668303
B33: G | L33: Div. Yield | M33: =-IFERROR(L54/C23,"") -> 0.028612918
B34: INVESTMENT THESIS
B35: Pillars of Recommendation | H35: Recommendation | I35: Valuation Assumptions
B36: Pillar | C36: Explanation | H36: BUY | I36: Check DCF
B37: Growing Company | C37: In general mining companies have a higher than average profit margins when compared with other companies publicly traded companies. Pilbara's financials have been growing exponentially in the last years and they have been able to maintain a very health balance sheet.
B38: Government Incentives and Support | C38: Governments around the world are focused on reaching a greener atmosphere by 2030, therefore they are investing heavily and incentivesing the purchase of EV's and consequently their compontents. This government support and fiscal incentives to produce more, will come with a positive side for Pilbara and the whole market.
B39: Lithium Demand | C39: Currently the supply chain has caught up to the demand, sending the current price per ton down and lowering profit margins for all market players; However, forecasts of demand point to an increase in 2025 signaling a possible increase in revenues and subsequent growth of the companies.
B40: Risks of Investment | H40: Price Target | I40: Valuation
B41: Risk | C41: Explanation | H41: =DCF!D76 -> 4.2230708 | I41: Discount Rate | J41: =DCF!F50 -> 0.095 | L41: Price M. Upside | M41: =SARD!AJ14 -> 0.52057587
...

Sheet Acuerdo
A1: Invertir
A2: NO invertir
A3: Mantener sin elevar posición
A4: Mantener (y seguir comprando)
A5: Liquidar
A6: PENDIENTE

Sheet Segments
B2: ="Regions "&"("&OP!$J$21&")" -> Regions (2023) | Q2: Products
D3: Nominal value | K3: YoY Growth
B4: Weight | C4: Region (Plant) | D4: =OP!J21 -> 2023 | E4: =D4-1 -> 2022 | F4: =E4-1 -> 2021 | G4: =F4-1 -> 2020 | H4: =G4-1 -> 2019 | I4: =H4-1 -> 2018 | K4: =OP!J21 -> 2023 | L4: =K4-1 -> 2022 | M4: =L4-1 -> 2021 | N4: =M4-1 -> 2020 | O4: =N4-1 -> 2019 | P4: =O4-1 -> 2018
B5: =IFERROR(D5/$D$10,"") -> 0.69622735 | C5: Pilgan | D5: =+(D15*38/58+D16) -> 2829.4812 | E5: =+E15*38/58+E16 -> 766.81931 | F5: =+F15+F16 -> 170.45 | G5: =+G15+G16 -> 92.854 | H5: =+H15+H16 -> 44.498 | I5: =+I15+I16 -> 9.88 | K5: =IFERROR((D5-E5)/E5,"-") -> 2.689893 | L5: =IFERROR((E5-F5)/F5,"-") -> 3.4987933 | M5: =IFERROR((F5-G5)/G5,"-") -> 0.83567752 | N5: =IFERROR((G5-H5)/H5,"-") -> 1.0867005 | O5: =IFERROR((H5-I5)/I5,"-") -> 3.5038462 | P5: =IFERROR((I5-J5)/J5,"-") -> -
B6: =IFERROR(D6/$D$10,"") -> 0.36616828 | C6: Ngungaju | D6: =+D15*20/58 -> 1488.1148 | E6: =+E15*20/58 -> 400.77069 | F6: - | G6: - | H6: - | I6: - | K6: =IFERROR((D6-E6)/E6,"-") -> 2.7131329 | L6: =IFERROR((E6-F6)/F6,"-") -> - | M6: =IFERROR((F6-G6)/G6,"-") -> - | N6: =IFERROR((G6-H6)/H6,"-") -> - | O6: =IFERROR((H6-I6)/I6,"-") -> - | P6: =IFERROR((I6-J6)/J6,"-") -> -
B7: =IFERROR(D7/$D$10,"") -> -0.00050762558 | C7: =+C17 -> (elimination of by-product) | D7: =+D17 -> -2.063 | E7: =+E17 -> -5.355 | F7: =+F17 -> -5.982 | G7: =+G17 -> -7.463 | H7: =+H17 -> -2.293 | I7: =+I17 -> - | K7: =IFERROR((D7-E7)/E7,"-") -> -0.61475257 | L7: =IFERROR((E7-F7)/F7,"-") -> -0.10481444 | M7: =IFERROR((F7-G7)/G7,"-") -> -0.19844567 | N7: =IFERROR((G7-H7)/H7,"-") -> 2.2546882 | O7: =IFERROR((H7-I7)/I7,"-") -> - | P7: =IFERROR((I7-J7)/J7,"-") -> -
B8: =IFERROR(D8/$D$10,"") -> -0.061659653 | C8: =+C18 -> (provisional price adjustment) | D8: =+D18 -> -250.586 | E8: =+E18 -> 27.356 | F8: =+F18 -> 11.356 | G8: =+G18 -> -1.194 | H8: =+H18 -> - | I8: =+I18 -> - | K8: =IFERROR((D8-E8)/E8,"-") -> -10.160184 | L8: =IFERROR((E8-F8)/F8,"-") -> 1.4089468 | M8: =IFERROR((F8-G8)/G8,"-") -> -10.510888 | N8: =IFERROR((G8-H8)/H8,"-") -> - | O8: =IFERROR((H8-I8)/I8,"-") -> - | P8: =IFERROR((I8-J8)/J8,"-") -> -
B9: =IFERROR(D9/$D$10,"") -> -0.00022834539 | C9: =+C19 -> (hedge close-outs) | D9: =+D19 -> -0.928 | E9: =+E19 -> - | F9: =+F19 -> - | G9: =+G19 -> -0.05 | H9: =+H19 -> 0.58 | I9: =+I19 -> 0.308 | K9: =IFERROR((D9-E9)/E9,"-") -> - | L9: =IFERROR((E9-F9)/F9,"-") -> - | M9: =IFERROR((F9-G9)/G9,"-") -> - | N9: =IFERROR((G9-H9)/H9,"-") -> -1.0862069 | O9: =IFERROR((H9-I9)/I9,"-") -> 0.88311688 | P9: =IFERROR((I9-J9)/J9,"-") -> -
B10: =SUM(B5:B9) -> 1 | C10: TOTAL | D10: =SUM(D5:D9) -> 4064.019 | E10: =SUM(E5:E9) -> 1189.591 | F10: =SUM(F5:F9) -> 175.824 | G10: =SUM(G5:G9) -> 84.147 | H10: =SUM(H5:H9) -> 42.785 | I10: =SUM(I5:I9) -> 10.188 | K10: =(D10-E10)/E10 -> 2.4163162 | L10: =(E10-F10)/F10 -> 5.7658056 | M10: =(F10-G10)/G10 -> 1.0894863 | N10: =(G10-H10)/H10 -> 0.96674068 | O10: =(H10-I10)/I10 -> 3.1995485 | P10: -
B12: ="Categories "&"("&OP!$J$21&")" -> Categories (2023)
D13: Nominal value | K13: YoY Growth
B14: Weight | C14: Category | D14: =OP!J21 -> 2023 | E14: =D14-1 -> 2022 | F14: =E14-1 -> 2021 | G14: =F14-1 -> 2020 | H14: =G14-1 -> 2019 | I14: =H14-1 -> 2018 | K14: =OP!J21 -> 2023 | L14: =K14-1 -> 2022 | M14: =L14-1 -> 2021 | N14: =M14-1 -> 2020 | O14: =N14-1 -> 2019 | P14: =O14-1 -> 2018
B15: =IFERROR(D15/$D$20,"") -> 1.061888 | C15: Spodumene | D15: =4315533000/1000000 -> 4315.533 | E15: =1162235000/1000000 -> 1162.235 | F15: =164468000/1000000 -> 164.468 | G15: =85391000/1000000 -> 85.391 | H15: =42205000/1000000 -> 42.205 | I15: =9880000/1000000 -> 9.88 | K15: =IFERROR((D15-E15)/E15,"-") -> 2.7131329 | L15: =IFERROR((E15-F15)/F15,"-") -> 6.066633 | M15: =IFERROR((F15-G15)/G15,"-") -> 0.92605778 | N15: =IFERROR((G15-H15)/H15,"-") -> 1.0232437 | O15: =IFERROR((H15-I15)/I15,"-") -> 3.2717611 | P15: =IFERROR((I15-J15)/J15,"-") -> -
B16: =IFERROR(D16/$D$20,"") -> 0.00050762558 | C16: Tantalite | D16: =2063000/1000000 -> 2.063 | E16: =5355000/1000000 -> 5.355 | F16: =5982000/1000000 -> 5.982 | G16: =7463000/1000000 -> 7.463 | H16: =2293000/1000000 -> 2.293 | I16: 0 | K16: =IFERROR((D16-E16)/E16,"-") -> -0.61475257 | L16: =IFERROR((E16-F16)/F16,"-") -> -0.10481444 | M16: =IFERROR((F16-G16)/G16,"-") -> -0.19844567 | N16: =IFERROR((G16-H16)/H16,"-") -> 2.2546882 | O16: =IFERROR((H16-I16)/I16,"-") -> - | P16: =IFERROR((I16-J16)/J16,"-") -> -
B17: =IFERROR(D17/$D$20,"") -> -0.00050762558 | C17: (elimination of by-product) | D17: =-D16 -> -2.063 | E17: =-E16 -> -5.355 | F17: =-F16 -> -5.982 | G17: =-G16 -> -7.463 | H17: =-H16 -> -2.293 | I17: - | K17: =IFERROR((D17-E17)/E17,"-") -> -0.61475257 | L17: =IFERROR((E17-F17)/F17,"-") -> -0.10481444 | M17: =IFERROR((F17-G17)/G17,"-") -> -0.19844567 | N17: =IFERROR((G17-H17)/H17,"-") -> 2.2546882 | O17: =IFERROR((H17-I17)/I17,"-") -> - | P17: =IFERROR((I17-J17)/J17,"-") -> -
B18: =IFERROR(D18/$D$20,"") -> -0.061659653 | C18: (provisional price adjustment) | D18: =-250586000/1000000 -> -250.586 | E18: =27356000/1000000 -> 27.356 | F18: =11356000/1000000 -> 11.356 | G18: =-1194000/1000000 -> -1.194 | H18: - | I18: - | K18: =IFERROR((D18-E18)/E18,"-") -> -10.160184 | L18: =IFERROR((E18-F18)/F18,"-") -> 1.4089468 | M18: =IFERROR((F18-G18)/G18,"-") -> -10.510888 | N18: =IFERROR((G18-H18)/H18,"-") -> - | O18: =IFERROR((H18-I18)/I18,"-") -> - | P18: =IFERROR((I18-J18)/J18,"-") -> -
B19: =IFERROR(D19/$D$20,"") -> -0.00022834539 | C19: (hedge close-outs) | D19: =-928000/1000000 -> -0.928 | E19: - | F19: - | G19: =-50000/1000000 -> -0.05 | H19: =580000/1000000 -> 0.58 | I19: =308000/1000000 -> 0.308 | K19: =IFERROR((D19-E19)/E19,"-") -> - | L19: =IFERROR((E19-F19)/F19,"-") -> - | M19: =IFERROR((F19-G19)/G19,"-") -> - | N19: =IFERROR((G19-H19)/H19,"-") -> -1.0862069 | O19: =IFERROR((H19-I19)/I19,"-") -> 0.88311688 | P19: =IFERROR((I19-J19)/J19,"-") -> -
B20: =SUM(B15:B19) -> 1 | C20: TOTAL | D20: =SUM(D15:D19) -> 4064.019 | E20: =SUM(E15:E19) -> 1189.591 | F20: =SUM(F15:F19) -> 175.824 | G20: =SUM(G15:G19) -> 84.147 | H20: =SUM(H15:H19) -> 42.785 | I20: =SUM(I15:I19) -> 10.188 | K20: =(D20-E20)/E20 -> 2.4163162 | L20: =(E20-F20)/F20 -> 5.7658056 | M20: =(F20-G20)/G20 -> 1.0894863 | N20: =(G20-H20)/H20 -> 0.96674068 | O20: =(H20-I20)/I20 -> 3.1995485 | P20: -
B22: Categories | D22: Description | I22: Graphs
B23: Spodumene | D23: Spodumene is one of the sources of lithium. Spodumene is first mined and crushed into powder, then is heated to high temperatures in a kiln, then is mixed with chemicals to form a lithium compound, which is then separated and purified into a concentrated lithium product.
B24: Tantalite | D24: Tantalite is the primary source of the chemical element tantalum, a corrosion (heat and acid) resistant metal. It's mainly used in alloys and glass.
B27: Industry | J27: Graphs (Industry Forecasts)
B28: Drivers | D28: Description
B29: Consumer Electronics | D29: According to the Grand View Research, the consumer electronics segment is the one with the highest CAGR (more than 17.2% from 2024 to 2030). It's composed of electronic devices such as mobile phones, laptops, cameras and speakers, which use lithiom-ion batteries.
B30: EVs | D30: The demand for electric vehicles is also a great driver for Pilbara Mineral's revenues, since they also use a great deal of lithium batteries.
B31: Lithium Prices | D31: Every company in this industry is affected by the prices of lithium since its volatility is one of the main drivers for their revenue, specially Pilbara Minerals since the almost deal solely with lithium. The prices have also decreased with an increase of supply these last few years which could turn into a rebound opportunity, since many professionals forecast prices increasing again.
B32: China | D32: The company's exposure to China's economic policies is significant and could impact commodity prices, capital flows and general confidence and sentiment. This happens because China is the biggest importer of lithium and is the responsible for a large part of total lithium processing. In recent times, China has also imposed restrictions to commodities coming from australia.
B33: Sales forecast
B34: Source | D34: Market Growth CAGR | G34: Period
B35: Acumen | D35: 0.234 | G35: 2022 - 2030
B36: Mordor Intelligence | D36: 0.1957 | G36: 2024 - 2029
B37: Grand View Research | D37: 0.128 | G37: 2024 - 2030
B38: Straits Research | D38: 0.221 | G38: 2023 - 2031
B39: AVERAGE | D39: =AVERAGE(D35:F38) -> 0.194675 | G39: 2023 - 2031
B40: Company's Strategy / Extra Notes
B41: Their strategy is 1) Delivering their performance operative commitments; 2) Achieve full potential of the Pilgangoora asset; 3) Extract greater value along the batteries materials chain and 4) Diversify revenue beyond the Pilgangoora asset. To do so they are implementing a number of iniciatives, namely: Downstream Lithium Chemical Facility In joint venture with POSCO, a 43 ktpa Lithium Hydroxide Chemical Facility was commissioned in Gwangyang, South Korea. This would diversify their assets beyond the Pilgangoora operation and diversifying beyond China by estabilishing a link with another country. The first of 2 trains is already open with a nameplate capacity of 21,5 ktpa of lithium hydroxide. There's also a joint feasibility study with Ganfeng, a chinese lithium company, for a 32 ktpa lithium conversion plant. The feasibility study is expected to be completed in March Quarter 2025 with an option to progress to a final investment decision and formation of a joint venture following that. This would fortify their links with China which is the main buyer of lithium, besides their collaboration with South Korea. Mid-stream Demonstration Plant The development of a Mid-stream Demonstration Plant on site at the Pilgangoora Operation was approved by our Board in August 2023. The facility is aimed at demonstrating the potential to enhance the battery materials supply chain by decarbonising spodumene processing, decreasing transport volumes and improving value-add processing at the mine site. Expansion The P680 and the P1000 projects aims to increase total spodumene concentrate production capacity at the Pilgangoora Operation to up to 1 Mtpa. Pilbara Minerals prefers to expand it's mining operation rather than expanding through M&A.

Sheet Peers
B1: Peer Logo | C1: Peer Name | D1: Description | G1: Currency | H1: End of Fiscal Year | I1: Next Earnings Date
B2: #VALUE! | C2: #VALUE! | D2: Albemarle Corporation is a global developer, manufacturer, and marketer of advanced engineering materials. The company produces a variety of specialty chemicals, primarily focusing on lithium and advanced materials as well as bromine and refining catalyst segments. Its lithium and advanced materials segment consist of two product categories: battery-grade lithium compounds and other specialty chemical products. These are used in a range of applications such as fire safety and soundproofing, energy storage, automotive applications, lubricants, pharmaceuticals, crop protection, and customized chemical services. The company has partnerships and joint ventures in various parts of the world and as of December 31, 2016, had 31 office and production sites globally. | G2: {=_FV(C2,"Moeda")} -> USD | H2: 31st December 2023 | I2: Q1 (1st May 2024)
B3: #VALUE! | C3: #VALUE! | D3: Sociedad Química y Minera de Chile, or SQM, is a producer and distributor of potassium nitrate and iodine. The company produces plant nutrients and industrial chemicals derived from solar evaporation ponds in the Atacama Desert. Its segments include plant nutrients (such as potassium nitrate), iodine derivatives, lithium, and industrial chemicals. The company's products are used in fertilizers to improve agricultural yield, industrial applications such as glass manufacturing and industrial nitrates, and they produce and sell iodine and its derivatives which have applications in x-ray contrast media and other uses. Lithium and its derivatives, including lithium carbonate, are used in batteries, greases, and air treatment systems and are sold globally. | G3: {=_FV(C3,"Moeda")} -> USD | H3: 31st December 2023 | I3: Q1 (22th May 2024)
B4: #VALUE! | C4: #VALUE! | D4: Mineral Resources is an Australian-based mining services company operating through six segments: Mining Services, Iron Ore, Lithium, Energy, Other Commodities, and Central. Their mining services division provides end-to-end solutions, including their subsidiary Crushing Mining Services (CSI) that offers crushing, screening, and processing solutions for mining operations. The company has three iron ore hubs in Western Australia and lithium operations in the Pilbara and Goldfields regions. The Mt Marion lithium project is located 40 kilometers southwest of Kalgoorlie, and the Wodgina lithium project is 120 kilometers south of Port Hedland, in the Pilbara region near the iron ore hubs. It includes two wells in the Perth Basin. | G4: {=_FV(C4,"Moeda")} -> AUD | H4: 30th June 2023 | I4: Q3 (26th April 2024)
B5: #VALUE! | C5: #VALUE! | D5: Arcadium Lithium PLC is an international lithium chemicals producer with a diversified product range. They produce lithium hydroxide, carbonate, spodumene, and other specialties. The company offers various lithium products such as specialty lithium, hydroxide, carbonate, battery-grade lithium hydroxide, and other lithium-ion battery grade carbonate, among others. They focus on direct lithium extraction from hard rock mining, chemical processing, and conventional brine extraction, which is said to be more efficient and less environmentally impactful than traditional methods. The company's operations span across different geographies, including the South American Lithium Triangle, Western Australia, and Canada. | G5: {=_FV(C5,"Moeda")} -> AUD | H5: 31st December 2023 | I5: Q1 (2nd May 2024)
D6: {=_FV(C6,"Descrição")} -> #VALUE! | G6: {=_FV(C6,"Moeda")} -> #VALUE!
B8: {=_FV(OP!E2,"Currency")&" MILLIONS"} -> AUD MILLIONS | C8: =OP!E2 -> #VALUE! | D8: =C2 -> #VALUE! | E8: =C3 -> #VALUE! | F8: =C4 -> #VALUE! | G8: =C5 -> #VALUE! | H8: AVERAGE | I8: Deviation from Average
B9: Company Info | H9: =IFERROR(AVERAGE(C9:F9),"") | K9: TRAFFIC
B10: Market Cap | C10: {=_FV(C8,"Market cap",TRUE)/1000000} -> 11526.26 | D10: {=(_FV(D8,"Capitalização de mercado",TRUE)*_FV($K$64,"Preço"))/1000000} -> 23385.868 | E10: {=(_FV(E8,"Capitalização de mercado",TRUE)*_FV($K$64,"Preço"))/1000000} -> 20785.91 | F10: {=_FV(F8,"Capitalização de mercado",TRUE)/1000000} -> 13832.86 | G10: {=_FV(G8,"Capitalização de mercado",TRUE)/1000000} -> 4630.654 | H10: =IFERROR(AVERAGE(C10:G10),"") -> 14832.31 | I10: =SQRT((C10-H10)^2) -> 3306.0503 | L10: Best Value
B11: Net Sales (current) | C11: =C60 -> 4064 | D11: =D60 -> 14490 | E11: =E59 -> 15450 | F11: =F60 -> 4779.1 | G11: =G60 -> 1795.8 | H11: =IFERROR(AVERAGE(C11:G11),"") -> 8115.78 | I11: =SQRT((C11-H11)^2) -> 4051.78
B12: Profitability | H12: =IFERROR(AVERAGE(C12:F12),"") | L12: Important Value
B13: Sales Growth (ttm) | C13: =C60/C59-1 -> 2.4162744 | D13: =D60/D59-1 -> 0.37228904 | E13: =E59/E60-1 -> 0.37321127 | F13: =F60/F59-1 -> 0.39821533 | G13: =G60/G59-1 -> 0.74858812 | H13: =IFERROR(AVERAGE(C13:G13),"") -> 0.86171563 | I13: =SQRT((C13-H13)^2) -> 1.5545587
B14: Sales Growth (36m) | C14: =C60/C58-1 -> 47.323424 | D14: =D60/D58-1 -> 2.1860158 | E14: =E60/E58-1 -> 3.2601287 | F14: =F60/F58-1 -> 1.2493058 | G14: =G60/G58-1 -> 19.736721 | H14: =IFERROR(AVERAGE(C14:G14),"") -> 14.751119 | I14: =SQRT((C14-H14)^2) -> 32.572305 | L14: Worst Value
B15: Operating Margin | C15: =C63/C60 -> 0.79032972 | D15: =D63/D60 -> 0.026501035 | E15: =E63/E60 -> 0.38094392 | F15: =F63/F60 -> 0.10809567 | G15: =G63/G60 -> 0.64717675 | H15: =IFERROR(AVERAGE(C15:G15),"") -> 0.39060942 | I15: =SQRT((C15-H15)^2) -> 0.39972031
B16: Net Income Margin | C16: =C66/C60 -> 0.58836122 | D16: =D66/D60 -> -0.019116632 | E16: =E66/E59 -> 0.19695793 | F16: =F66/F60 -> 0.051118411 | G16: =G66/G60 -> 0.43434681 | H16: =IFERROR(AVERAGE(C16:G16),"") -> 0.25033355 | I16: =SQRT((C16-H16)^2) -> 0.33802767
B17: Return on Equity (RoE) | C17: =C66/C79 -> 0.70533923 | D17: =D66/D79 -> -0.020041965 | E17: =E66/E79 -> 0.37470755 | F17: =F66/F79 -> 0.070300135 | G17: =G66/G79 -> 0.1527824 | H17: =IFERROR(AVERAGE(C17:G17),"") -> 0.25661747 | I17: =SQRT((C17-H17)^2) -> 0.44872176
B18: Return on Invested Capital (ROIC) | C18: =(C66+C65)/(C78+C79) -> 0.36527706 | D18: =(D66+D65)/(D78+D79) -> -0.046389168 | E18: =(E66+E65)/(E78+E79) -> 0.12618918 | F18: =(F66+F65)/(F78+F79) -> 0.01910809 | G18: =(G66+G65)/(G78+G79) -> 0.058249652 | H18: =IFERROR(AVERAGE(C18:G18),"") -> 0.10448696 | I18: =SQRT((C18-H18)^2) -> 0.2607901
B19: Solvency | H19: =IFERROR(AVERAGE(C19:F19),"")
B20: Debt/Assets | C20: =C78/C74 -> 0.090790182 | D20: =D78/D74 -> 0.2280741 | E20: =E78/E74 -> 0.38367561 | F20: =F78/F74 -> 0.38523204 | G20: =G78/G74 -> 0.062773107 | H20: =IFERROR(AVERAGE(C20:G20),"") -> 0.23010901 | I20: =SQRT((C20-H20)^2) -> 0.13931882
B21: Net Debt/EBITDA | C21: =(C78-C69)/C62 -> -0.81927905 | D21: =(D78-D69)/D62 -> 3.623494 | E21: =(E78-E69)/E62 -> 1.177918 | F21: =(F78-F69)/F62 -> 1.0799157 | G21: =(G78-G69)/G62 -> -0.54726736 | H21: =IFERROR(AVERAGE(C21:G21),"") -> 0.90295625 | I21: =SQRT((C21-H21)^2) -> 1.7222353
B22: Debt/Assets (Leases Free Debt) | C22: =(C78-C77)/C74 -> 0.052415942 | D22: =(D78-D77)/D74 -> 0.2280741 | E22: =(E78-E77)/E74 -> 0.38367561 | F22: =(F78-F77)/F74 -> 0.38523204 | G22: =(G78-G77)/G74 -> 0.062773107 | H22: =IFERROR(AVERAGE(C22:G22),"") -> 0.22243416 | I22: =SQRT((C22-H22)^2) -> 0.17001822
B23: Net Debt/EBIT (Leases Free Debt) | C23: =((C78-C77)-C69)/C62 -> -0.88366089 | D23: =((D78-D77)-D69)/D62 -> 3.623494 | E23: =((E78-E77)-E69)/E62 -> 1.177918 | F23: =((F78-F77)-F69)/F62 -> 1.0799157 | G23: =((G78-G77)-G69)/G62 -> -0.54726736 | H23: =IFERROR(AVERAGE(C23:G23),"") -> 0.89007988 | I23: =SQRT((C23-H23)^2) -> 1.7737408
B24: Leasing Debt/Total Debt | C24: =C77/C78 -> 0.42266949 | D24: =D77/D78 -> 0 | E24: =E77/E78 -> 0 | F24: =F77/F78 -> 0 | G24: =G77/G78 -> 0 | H24: =IFERROR(AVERAGE(C24:G24),"") -> 0.084533898 | I24: =SQRT((C24-H24)^2) -> 0.33813559
B25: Interest Coverage Ratio | C25: =-C62/C64 -> -69.013363 | D25: =-D62/D64 -> 7.5885714 | E25: =-E62/E64 -> 63.4 | F25: =-F62/F64 -> 7.6496732 | G25: =-G62/G64 -> -47.013889 | H25: =IFERROR(AVERAGE(C25:G25),"") -> -7.4778015 | I25: =SQRT((C25-H25)^2) -> 61.535562
B26: Liquidity
B27: Current Ratio | C27: =C72/C76 -> 2.846724 | D27: =D72/D76 -> 1.4653787 | E27: =E72/E76 -> 2.495365 | F27: =F72/F76 -> 2.7698501 | G27: =G72/G76 -> 2.5159988 | H27: =IFERROR(AVERAGE(C27:G27),"") -> 2.4186633 | I27: =SQRT((C27-H27)^2) -> 0.42806065
B28: Quick Ratio | C28: =(C69+C70)/C76 -> 9.1692855 | D28: =(D69+D70)/D76 -> 0.59066565 | E28: =(E69+E70)/E76 -> 0.6216686 | F28: =(F69+F70)/F76 -> 1.591199 | G28: =(G69+G70)/G76 -> 2.0626495 | H28: =IFERROR(AVERAGE(C28:G28),"") -> 2.8070936 | I28: =SQRT((C28-H28)^2) -> 6.3621919
B29: Activity | H29: =IFERROR(AVERAGE(C29:F29),"")
B30: Inventory Turnover | C30: =C61/C71 -> 7.9773895 | D30: =D61/D71 -> 3.9971645 | E30: =E61/E71 -> 2.5395242 | F30: =F61/F71 -> 2.5966359 | G30: =G61/G71 -> 1.1128097 | H30: =IFERROR(AVERAGE(C30:G30),"") -> 3.6447047 | I30: =SQRT((C30-H30)^2) -> 4.3326848
B31: Acc. Receivable Turnover | C31: =C60/C70 -> 49.500609 | D31: =D60/D70 -> 8.1358787 | E31: =E60/E70 -> 9.7664931 | F31: =F60/F70 -> 7.2652782 | G31: =G60/G70 -> 12.199728 | H31: =IFERROR(AVERAGE(C31:G31),"") -> 17.373597 | I31: =SQRT((C31-H31)^2) -> 32.127012
A32: Price/Sales | B32: Payables Turnover | C32: =C61/C75 -> 5.7538918 | D32: =D61/D75 -> 4.1379648 | E32: =E61/E75 -> 10.197227 | F32: =F61/F75 -> 1.8281667 | G32: =G61/G75 -> 1.1035024 | H32: =IFERROR(AVERAGE(C32:G32),"") -> 4.6041504 | I32: =SQRT((C32-H32)^2) -> 1.1497413
B33: Fixed Asset Turnover | C33: =C60/C73 -> 2.9353557 | D33: =D60/D74 -> 0.54008722 | E33: =E59/E72 -> 1.7935918 | F33: =F60/F73 -> 1.0558514 | G33: =G60/G73 -> 0.35094782 | H33: =IFERROR(AVERAGE(C33:G33),"") -> 1.3351668 | I33: =SQRT((C33-H33)^2) -> 1.6001889
B34: Total Asset Turnover | C34: =C60/C74 -> 0.78171886 | D34: =D60/D74 -> 0.54008722 | E34: =E60/E74 -> 0.65454651 | F34: =F60/F74 -> 0.56926577 | G34: =G60/G74 -> 0.22944829 | H34: =IFERROR(AVERAGE(C34:G34),"") -> 0.55501333 | I34: =SQRT((C34-H34)^2) -> 0.22670553
B35: Valuation | H35: =IFERROR(AVERAGE(C35:F35),"")
B36: Price/Earnings | C36: =C10/C66 -> 4.8204843 | D36: =D10/D66 -> -84.425515 | E36: =E10/E66 -> 6.8307295 | F36: =F10/F66 -> 56.622431 | G36: =G10/G66 -> 5.9367359 | H36: =IFERROR(AVERAGE(C36:G36),"") -> -2.0430268 | I36: =SQRT((C36-H36)^2) -> 6.8635111
B37: Price/Sales | C37: =C10/C60 -> 2.836186 | D37: =D10/D60 -> 1.6139315 | E37: =E10/E60 -> 1.8474722 | F37: =F10/F60 -> 2.8944487 | G37: =G10/G60 -> 2.5786023 | H37: =IFERROR(AVERAGE(C37:G37),"") -> 2.3541282 | I37: =SQRT((C37-H37)^2) -> 0.48205786
B38: Price/Book | C38: =C10/C79 -> 3.4000767 | D38: =D10/D79 -> 1.6920532 | E38: =E10/E79 -> 2.5595259 | F38: =F10/F79 -> 3.9805646 | G38: =G10/G79 -> 0.90702877 | H38: =IFERROR(AVERAGE(C38:G38),"") -> 2.5078498 | I38: =SQRT((C38-H38)^2) -> 0.89222686
B39: EV/Sales | C39: =(C78+C10-C69)/C60 -> 2.2115059 | D39: =(D78+D10-D69)/D60 -> 1.9460226 | E39: =(E78+E10-E69)/E60 -> 2.3452946 | F39: =(F78+F10-F69)/F60 -> 3.2911552 | G39: =(G78+G10-G69)/G60 -> 2.1659728 | H39: =IFERROR(AVERAGE(C39:G39),"") -> 2.3919902 | I39: =SQRT((C39-H39)^2) -> 0.18048434
B40: EV/EBITDA | C40: =(C78+C10-C69-C77)/C62 -> 2.8360474 | D40: =(D78+D10-D69-D77)/D62 -> 21.233334 | E40: =(E78+E10-E69-E77)/E62 -> 5.5492976 | F40: =(F78+F10-F69-F77)/F62 -> 8.9591934 | G40: =(G78+G10-G69-G77)/G62 -> 2.8727134 | H40: =IFERROR(AVERAGE(C40:G40),"") -> 8.2901172 | I40: =SQRT((C40-H40)^2) -> 5.4540698
B41: Stock Info | H41: =IFERROR(AVERAGE(C41:F41),"")
...

Sheet SARD
C1: in AUD | F1: Variables | K1: Rankings | P1: Difference | U1: Results | Y1: Additional Information | AD1: =B3 -> PLS.AX | AE1: Selected Peers | AJ1: Price Multiples (TTM) | AM1: Enterprise Value Multiples (TTM)
B2: Ticker | C2: Company Name | D2: TRBC Industry | E2: Country | F2: ROE | G2: DEBT/EBIT | H2: Market Cap | I2: EPS Growth (2022-2023) (Refinitiv Smart Estimate) | J2: EBIT Margin | K2: ROE | L2: DEBT/EBIT | M2: Market Cap | N2: EPS Growth | O2: EBIT Margin | P2: ROE | Q2: DEBT/EBIT | R2: Market Cap | S2: EPS Growth | T2: EBIT Margin | U2: SARD Result | V2: SARD Peers | W2: SARD Peers adjusted Rank | Y2: Suitability | Z2: Relevant Information Missing | AA2: Author's Override | AB2: Observations | AE2: SARD Peers adjusted Rank | AF2: SARD Result | AG2: Ticker | AH2: Company Name | AI2: Country | AJ2: P / E | AK2: P / B | AL2: Price / Sales | AM2: EV / Sales | AN2: EV / EBITDA | AS2: Net Income After Taxes | AT2: Total Equity | AU2: Total Debt | AV2: Operating Income | AW2: Revenue | AX2: Company Market Cap | AY2: Earnings per Share (FY1) | AZ2: Earnings per Share (FY0)
A3: Benchmark | B3: PLS.AX | C3: Pilbara Minerals Ltd | D3: Diversified Mining | E3: Australia | F3: =AS3/AT3 -> 0.70534498 | G3: =AU3/AV3 -> 0.14693659 | H3: =AX3 -> 1.3271754e+10 | I3: =(AY3/AZ3)-1 -> -0.85219897 | J3: =AV3/AW3 -> 0.79033169 | K3: =IFERROR(_xlfn.RANK.EQ(F3,F$3:F$64),"N/A") -> 2 | L3: =IFERROR(_xlfn.RANK.EQ(G3,G$3:G$64),"N/A") -> 27 | M3: =IFERROR(_xlfn.RANK.EQ(H3,H$3:H$64),"N/A") -> 11 | N3: =IFERROR(_xlfn.RANK.EQ(I3,I$3:I$64),"N/A") -> 45 | O3: =IFERROR(_xlfn.RANK.EQ(J3,J$3:J$64),"N/A") -> 2 | P3: - | Q3: - | R3: - | S3: - | T3: - | U3: - | V3: - | W3: - | Y3: =IF(OR(Z3="Y",AA3="Y"),"Not suitable","") | Z3: =IF(OR(N3="N/A",O3="N/A"),"Y","") | AE3: 1 | AF3: =_xlfn.XLOOKUP(AE3,$W$4:$W$64,$U$4:$U$64,"N/A",0,1) -> 24 | AG3: =_xlfn.XLOOKUP(AE3,$W$4:$W$64,$B$4:$B$64,"N/A",0,1) -> HZNC.NS | AH3: =_xlfn.XLOOKUP(AE3,$W$4:$W$64,$C$4:$C$64,"N/A",0,1) -> Hindustan Zinc Ltd | AI3: =_xlfn.XLOOKUP(AE3,$W$4:$W$64,$E$4:$E$64,"N/A",0,1) -> India | AJ3: 16.403313 | AK3: 9.6729016 | AL3: 4.4130356 | AM3: 4.4209976 | AN3: 9.2660538 | AS3: 2391135000 | AT3: 3390022000 | AU3: 471949000 | AV3: 3211923000 | AW3: 4064019000 | AX3: 1.3271754e+10 | AY3: 0.11181 | AZ3: 0.75649
A4: Comparison | B4: AIS.AX | C4: Aeris Resources Ltd | D4: Diversified Mining | E4: Australia | F4: =AS4/AT4 -> -0.52466316 | G4: =AU4/AV4 -> -0.18904627 | H4: =AX4 -> 1.1126544e+08 | I4: =(AY4/AZ4)-1 -> -0.78780178 | J4: =AV4/AW4 -> -0.21427778 | K4: =IFERROR(_xlfn.RANK.EQ(F4,F$3:F$64),"N/A") -> 53 | L4: =IFERROR(_xlfn.RANK.EQ(G4,G$3:G$64),"N/A") -> 43 | M4: =IFERROR(_xlfn.RANK.EQ(H4,H$3:H$64),"N/A") -> 42 | N4: =IFERROR(_xlfn.RANK.EQ(I4,I$3:I$64),"N/A") -> 44 | O4: =IFERROR(_xlfn.RANK.EQ(J4,J$3:J$64),"N/A") -> 40 | P4: =IFERROR(ABS(K$3-K4),"N/A") -> 51 | Q4: =IFERROR(ABS(L$3-L4),"N/A") -> 16 | R4: =IFERROR(ABS(M$3-M4),"N/A") -> 31 | S4: =IFERROR(ABS(N$3-N4),"N/A") -> 1 | T4: =IFERROR(ABS(O$3-O4),"N/A") -> 38 | U4: =SUM(P4:T4) -> 137 | V4: =_xlfn.RANK.EQ(U4,$U$4:$U$64,1) -> 36 | W4: =IF(Y4="Not suitable","-",V4) -> 36 | Y4: =IF(OR(Z4="Y",AA4="Y"),"Not suitable","") | Z4: =IF(OR(N4="N/A",O4="N/A"),"Y","") | AE4: 3 | AF4: =_xlfn.XLOOKUP(AE4,$W$4:$W$64,$U$4:$U$64,"N/A",0,1) -> 42 | AG4: =_xlfn.XLOOKUP(AE4,$W$4:$W$64,$B$4:$B$64,"N/A",0,1) -> DPM.TO | AH4: =_xlfn.XLOOKUP(AE4,$W$4:$W$64,$C$4:$C$64,"N/A",0,1) -> Dundee Precious Metals Inc | AI4: =_xlfn.XLOOKUP(AE4,$W$4:$W$64,$E$4:$E$64,"N/A",0,1) -> Canada | AJ4: 6.9517221 | AK4: 1.1274434 | AL4: 2.4291069 | AM4: 1.308628 | AN4: 2.4998279 | AS4: -139754000 | AT4: 266369000 | AU4: 24811000 | AV4: -131243000 | AW4: 612490000 | AX4: 1.1126544e+08 | AY4: -0.0334 | AZ4: -0.1574
B5: ATY.V | C5: Atico Mining Corp | D5: Diversified Mining | E5: Canada | F5: =AS5/AT5 -> -0.053334092 | G5: =AU5/AV5 -> 2.5020665 | H5: =AX5 -> 16458205 | I5: =(AY5/AZ5)-1 -> -2.0162852 | J5: =AV5/AW5 -> 0.14057106 | K5: =IFERROR(_xlfn.RANK.EQ(F5,F$3:F$64),"N/A") -> 34 | L5: =IFERROR(_xlfn.RANK.EQ(G5,G$3:G$64),"N/A") -> 12 | M5: =IFERROR(_xlfn.RANK.EQ(H5,H$3:H$64),"N/A") -> 60 | N5: =IFERROR(_xlfn.RANK.EQ(I5,I$3:I$64),"N/A") -> 61 | O5: =IFERROR(_xlfn.RANK.EQ(J5,J$3:J$64),"N/A") -> 20 | P5: =IFERROR(ABS(K$3-K5),"N/A") -> 32 | Q5: =IFERROR(ABS(L$3-L5),"N/A") -> 15 | R5: =IFERROR(ABS(M$3-M5),"N/A") -> 49 | S5: =IFERROR(ABS(N$3-N5),"N/A") -> 16 | T5: =IFERROR(ABS(O$3-O5),"N/A") -> 18 | U5: =SUM(P5:T5) -> 130 | V5: =_xlfn.RANK.EQ(U5,$U$4:$U$64,1) -> 32 | W5: =IF(Y5="Not suitable","-",V5) -> 32 | Y5: =IF(OR(Z5="Y",AA5="Y"),"Not suitable","") | Z5: =IF(OR(N5="N/A",O5="N/A"),"Y","") | AE5: 4 | AF5: =_xlfn.XLOOKUP(AE5,$W$4:$W$64,$U$4:$U$64,"N/A",0,1) -> 44 | AG5: =_xlfn.XLOOKUP(AE5,$W$4:$W$64,$B$4:$B$64,"N/A",0,1) -> ALS.TO | AH5: =_xlfn.XLOOKUP(AE5,$W$4:$W$64,$C$4:$C$64,"N/A",0,1) -> Altius Minerals Corp | AI5: =_xlfn.XLOOKUP(AE5,$W$4:$W$64,$E$4:$E$64,"N/A",0,1) -> Canada | AJ5: 47.935592 | AK5: 1.6986928 | AL5: 11.104905 | AM5: 13.326728 | AN5: 18.741649 | AS5: -4922787.3 | AT5: 92300949 | AU5: 33641855 | AV5: 13445628 | AW5: 95650041 | AX5: 16458205 | AY5: -0.0152207 | AZ5: 0.0149768
B6: GORO.A | C6: Gold Resource Corp | D6: Diversified Mining | E6: United States of America | F6: =AS6/AT6 -> -0.056556673 | G6: =AU6/AV6 -> 0 | H6: =AX6 -> 35338995 | I6: =(AY6/AZ6)-1 -> 3.0178865 | J6: =AV6/AW6 -> 0.042083562 | K6: =IFERROR(_xlfn.RANK.EQ(F6,F$3:F$64),"N/A") -> 36 | L6: =IFERROR(_xlfn.RANK.EQ(G6,G$3:G$64),"N/A") -> 31 | M6: =IFERROR(_xlfn.RANK.EQ(H6,H$3:H$64),"N/A") -> 55 | N6: =IFERROR(_xlfn.RANK.EQ(I6,I$3:I$64),"N/A") -> 5 | O6: =IFERROR(_xlfn.RANK.EQ(J6,J$3:J$64),"N/A") -> 28 | P6: =IFERROR(ABS(K$3-K6),"N/A") -> 34 | Q6: =IFERROR(ABS(L$3-L6),"N/A") -> 4 | R6: =IFERROR(ABS(M$3-M6),"N/A") -> 44 | S6: =IFERROR(ABS(N$3-N6),"N/A") -> 40 | T6: =IFERROR(ABS(O$3-O6),"N/A") -> 26 | U6: =SUM(P6:T6) -> 148 | V6: =_xlfn.RANK.EQ(U6,$U$4:$U$64,1) -> 42 | W6: =IF(Y6="Not suitable","-",V6) -> 42 | Y6: =IF(OR(Z6="Y",AA6="Y"),"Not suitable","") | Z6: =IF(OR(N6="N/A",O6="N/A"),"Y","") | AE6: 5 | AF6: =_xlfn.XLOOKUP(AE6,$W$4:$W$64,$U$4:$U$64,"N/A",0,1) -> 45 | AG6: =_xlfn.XLOOKUP(AE6,$W$4:$W$64,$B$4:$B$64,"N/A",0,1) -> VDAN.NS | AH6: =_xlfn.XLOOKUP(AE6,$W$4:$W$64,$C$4:$C$64,"N/A",0,1) -> Vedanta Ltd | AI6: =_xlfn.XLOOKUP(AE6,$W$4:$W$64,$E$4:$E$64,"N/A",0,1) -> India | AJ6: 9.1279843 | AK6: 3.2111772 | AL6: 0.70243227 | AM6: 1.0843165 | AN6: 4.4156085 | AS6: -9277837.4 | AT6: 1.6404496e+08 | AU6: 0 | AV6: 8568899.6 | AW6: 2.0361631e+08 | AX6: 35338995 | AY6: -0.2968294 | AZ6: -0.073877
B7: 5711.T | C7: Mitsubishi Materials Corp | D7: Diversified Mining | E7: Japan | F7: =AS7/AT7 -> 0.043106223 | G7: =AU7/AV7 -> 28.205249 | H7: =AX7 -> 3.5156424e+09 | I7: =(AY7/AZ7)-1 -> 4.7127466 | J7: =AV7/AW7 -> 0.012303705 | K7: =IFERROR(_xlfn.RANK.EQ(F7,F$3:F$64),"N/A") -> 25 | L7: =IFERROR(_xlfn.RANK.EQ(G7,G$3:G$64),"N/A") -> 1 | M7: =IFERROR(_xlfn.RANK.EQ(H7,H$3:H$64),"N/A") -> 17 | N7: =IFERROR(_xlfn.RANK.EQ(I7,I$3:I$64),"N/A") -> 3 | O7: =IFERROR(_xlfn.RANK.EQ(J7,J$3:J$64),"N/A") -> 31 | P7: =IFERROR(ABS(K$3-K7),"N/A") -> 23 | Q7: =IFERROR(ABS(L$3-L7),"N/A") -> 26 | R7: =IFERROR(ABS(M$3-M7),"N/A") -> 6 | S7: =IFERROR(ABS(N$3-N7),"N/A") -> 42 | T7: =IFERROR(ABS(O$3-O7),"N/A") -> 29 | U7: =SUM(P7:T7) -> 126 | V7: =_xlfn.RANK.EQ(U7,$U$4:$U$64,1) -> 30 | W7: =IF(Y7="Not suitable","-",V7) -> 30 | Y7: =IF(OR(Z7="Y",AA7="Y"),"Not suitable","") | Z7: =IF(OR(N7="N/A",O7="N/A"),"Y","") | AE7: 6 | AF7: =_xlfn.XLOOKUP(AE7,$W$4:$W$64,$U$4:$U$64,"N/A",0,1) -> 49 | AG7: =_xlfn.XLOOKUP(AE7,$W$4:$W$64,$B$4:$B$64,"N/A",0,1) -> BHP.AX | AH7: =_xlfn.XLOOKUP(AE7,$W$4:$W$64,$C$4:$C$64,"N/A",0,1) -> BHP Group Ltd | AI7: =_xlfn.XLOOKUP(AE7,$W$4:$W$64,$E$4:$E$64,"N/A",0,1) -> Australia | AJ7: 19.805163 | AK7: 3.5871445 | AL7: 2.6427476 | AM7: 2.9260532 | AN7: 5.2801592 | AS7: 2.8811569e+08 | AT7: 6.6838537e+09 | AU7: 6.3562764e+09 | AV7: 2.2535793e+08 | AW7: 1.8316266e+10 | AX7: 3.5156424e+09 | AY7: 2.8906603 | AZ7: 0.50600185
B8: GLEN.L | C8: Glencore PLC | D8: Diversified Mining | E8: Switzerland | F8: =AS8/AT8 -> 0.073657641 | G8: =AU8/AV8 -> 5.9518183 | H8: =AX8 -> 9.0491119e+10 | I8: =(AY8/AZ8)-1 -> -0.21937301 | J8: =AV8/AW8 -> 0.024868131 | K8: =IFERROR(_xlfn.RANK.EQ(F8,F$3:F$64),"N/A") -> 20 | L8: =IFERROR(_xlfn.RANK.EQ(G8,G$3:G$64),"N/A") -> 5 | M8: =IFERROR(_xlfn.RANK.EQ(H8,H$3:H$64),"N/A") -> 4 | N8: =IFERROR(_xlfn.RANK.EQ(I8,I$3:I$64),"N/A") -> 29 | O8: =IFERROR(_xlfn.RANK.EQ(J8,J$3:J$64),"N/A") -> 30 | P8: =IFERROR(ABS(K$3-K8),"N/A") -> 18 | Q8: =IFERROR(ABS(L$3-L8),"N/A") -> 22 | R8: =IFERROR(ABS(M$3-M8),"N/A") -> 7 | S8: =IFERROR(ABS(N$3-N8),"N/A") -> 16 | T8: =IFERROR(ABS(O$3-O8),"N/A") -> 28 | U8: =SUM(P8:T8) -> 91 | V8: =_xlfn.RANK.EQ(U8,$U$4:$U$64,1) -> 24 | W8: =IF(Y8="Not suitable","-",V8) -> 24 | Y8: =IF(OR(Z8="Y",AA8="Y"),"Not suitable","") | Z8: =IF(OR(N8="N/A",O8="N/A"),"Y","") | AE8: 7 | AF8: 49 | AG8: GMEXICOB.MX | AH8: Grupo Mexico SAB de CV | AI8: Mexico | AJ8: 11.199677 | AK8: 2.0000184 | AL8: 2.6456077 | AM8: 3.0065953 | AN8: 6.0797373 | AS8: 4713660300 | AT8: 63994179400 | AU8: 47343651630 | AV8: 7954485310 | AW8: 319866638470 | AX8: 9.0491119e+10 | AY8: 0.61596778 | AZ8: 0.78906799
B9: BCM.V | C9: Bear Creek Mining Corp | D9: Diversified Mining | E9: Canada | F9: =AS9/AT9 -> -0.19798537 | G9: =AU9/AV9 -> -1.1148915 | H9: =AX9 -> 46322122 | I9: =(AY9/AZ9)-1 -> 2.0574454 | J9: =AV9/AW9 -> -0.3028769 | K9: =IFERROR(_xlfn.RANK.EQ(F9,F$3:F$64),"N/A") -> 47 | L9: =IFERROR(_xlfn.RANK.EQ(G9,G$3:G$64),"N/A") -> 50 | M9: =IFERROR(_xlfn.RANK.EQ(H9,H$3:H$64),"N/A") -> 53 | N9: =IFERROR(_xlfn.RANK.EQ(I9,I$3:I$64),"N/A") -> 6 | O9: =IFERROR(_xlfn.RANK.EQ(J9,J$3:J$64),"N/A") -> 42 | P9: =IFERROR(ABS(K$3-K9),"N/A") -> 45 | Q9: =IFERROR(ABS(L$3-L9),"N/A") -> 23 | R9: =IFERROR(ABS(M$3-M9),"N/A") -> 42 | S9: =IFERROR(ABS(N$3-N9),"N/A") -> 39 | T9: =IFERROR(ABS(O$3-O9),"N/A") -> 40 | U9: =SUM(P9:T9) -> 189 | V9: =_xlfn.RANK.EQ(U9,$U$4:$U$64,1) -> 58 | W9: =IF(Y9="Not suitable","-",V9) -> 58 | Y9: =IF(OR(Z9="Y",AA9="Y"),"Not suitable","") | Z9: =IF(OR(N9="N/A",O9="N/A"),"Y","") | AE9: Median | AJ9: =MEDIAN(AJ3:AJ8) -> 13.801495 | AK9: =MEDIAN(AK3:AK8) -> 2.6055978 | AL9: =MEDIAN(AL3:AL8) -> 2.6441777 | AM9: =MEDIAN(AM3:AM8) -> 2.9663243 | AN9: =MEDIAN(AN3:AN8) -> 5.6799482 | AS9: -33176231 | AT9: 1.675691e+08 | AU9: 30252414 | AV9: -27134849 | AW9: 89590356 | AX9: 46322122 | AY9: -0.3191013 | AZ9: -0.1043686
B10: IMA.AX | C10: Image Resources NL | D10: Diversified Mining | E10: Australia | F10: =AS10/AT10 -> 0.13053693 | G10: =AU10/AV10 -> 0.0081939938 | H10: =AX10 -> 63147962 | I10: =(AY10/AZ10)-1 -> -1 | J10: =AV10/AW10 -> 0.14015635 | K10: =IFERROR(_xlfn.RANK.EQ(F10,F$3:F$64),"N/A") -> 12 | L10: =IFERROR(_xlfn.RANK.EQ(G10,G$3:G$64),"N/A") -> 30 | M10: =IFERROR(_xlfn.RANK.EQ(H10,H$3:H$64),"N/A") -> 49 | N10: =IFERROR(_xlfn.RANK.EQ(I10,I$3:I$64),"N/A") -> 47 | O10: =IFERROR(_xlfn.RANK.EQ(J10,J$3:J$64),"N/A") -> 21 | P10: =IFERROR(ABS(K$3-K10),"N/A") -> 10 | Q10: =IFERROR(ABS(L$3-L10),"N/A") -> 3 | R10: =IFERROR(ABS(M$3-M10),"N/A") -> 38 | S10: =IFERROR(ABS(N$3-N10),"N/A") -> 2 | T10: =IFERROR(ABS(O$3-O10),"N/A") -> 19 | U10: =SUM(P10:T10) -> 72 | V10: =_xlfn.RANK.EQ(U10,$U$4:$U$64,1) -> 15 | W10: =IF(Y10="Not suitable","-",V10) -> 15 | Y10: =IF(OR(Z10="Y",AA10="Y"),"Not suitable","") | Z10: =IF(OR(N10="N/A",O10="N/A"),"Y","") | AE10: Benchmark Data | AJ10: Price / Share | AS10: 15168000 | AT10: 116197000 | AU10: 197000 | AV10: 24042000 | AW10: 171537000 | AX10: 63147962 | AZ10: 0.058
B11: S.TO | C11: Sherritt International Corp | D11: Diversified Mining | E11: Canada | F11: =AS11/AT11 -> -0.1047914 | G11: =AU11/AV11 -> -8.9122807 | H11: =AX11 -> 1.2579232e+08 | I11: =(AY11/AZ11)-1 -> 0.33359291 | J11: =AV11/AW11 -> -0.17868339 | K11: =IFERROR(_xlfn.RANK.EQ(F11,F$3:F$64),"N/A") -> 41 | L11: =IFERROR(_xlfn.RANK.EQ(G11,G$3:G$64),"N/A") -> 60 | M11: =IFERROR(_xlfn.RANK.EQ(H11,H$3:H$64),"N/A") -> 41 | N11: =IFERROR(_xlfn.RANK.EQ(I11,I$3:I$64),"N/A") -> 12 | O11: =IFERROR(_xlfn.RANK.EQ(J11,J$3:J$64),"N/A") -> 37 | P11: =IFERROR(ABS(K$3-K11),"N/A") -> 39 | Q11: =IFERROR(ABS(L$3-L11),"N/A") -> 33 | R11: =IFERROR(ABS(M$3-M11),"N/A") -> 30 | S11: =IFERROR(ABS(N$3-N11),"N/A") -> 33 | T11: =IFERROR(ABS(O$3-O11),"N/A") -> 35 | U11: =SUM(P11:T11) -> 170 | V11: =_xlfn.RANK.EQ(U11,$U$4:$U$64,1) -> 54 | W11: =IF(Y11="Not suitable","-",V11) -> 54 | Y11: =IF(OR(Z11="Y",AA11="Y"),"Not suitable","") | Z11: =IF(OR(N11="N/A",O11="N/A"),"Y","") | AE11: Benchmark | AF11: Multiplier | AG11: # Shares | AH11: -Debt + Cash | AJ11: P / E | AK11: P / B | AL11: Price / Sales | AM11: EV / Sales | AN11: EV / EBITDA | AS11: -71287315 | AT11: 6.8027833e+08 | AU11: 3.9424214e+08 | AV11: -44235830 | AW11: 2.4756544e+08 | AX11: 1.2579232e+08 | AY11: -0.16810808 | AZ11: -0.12605652
B12: SOSIL.NGM | C12: Sotkamo Silver AB | D12: Diversified Mining | E12: Sweden | F12: =AS12/AT12 -> 0.091798853 | G12: =AU12/AV12 -> 4.161919 | H12: =AX12 -> 32538544 | I12: =(AY12/AZ12)-1 -> 1.5725809 | J12: =AV12/AW12 -> 0.16197183 | K12: =IFERROR(_xlfn.RANK.EQ(F12,F$3:F$64),"N/A") -> 15 | L12: =IFERROR(_xlfn.RANK.EQ(G12,G$3:G$64),"N/A") -> 8 | M12: =IFERROR(_xlfn.RANK.EQ(H12,H$3:H$64),"N/A") -> 57 | N12: =IFERROR(_xlfn.RANK.EQ(I12,I$3:I$64),"N/A") -> 8 | O12: =IFERROR(_xlfn.RANK.EQ(J12,J$3:J$64),"N/A") -> 19 | P12: =IFERROR(ABS(K$3-K12),"N/A") -> 13 | Q12: =IFERROR(ABS(L$3-L12),"N/A") -> 19 | R12: =IFERROR(ABS(M$3-M12),"N/A") -> 46 | S12: =IFERROR(ABS(N$3-N12),"N/A") -> 37 | T12: =IFERROR(ABS(O$3-O12),"N/A") -> 17 | U12: =SUM(P12:T12) -> 132 | V12: =_xlfn.RANK.EQ(U12,$U$4:$U$64,1) -> 33 | W12: =IF(Y12="Not suitable","-",V12) -> 33 | Y12: =IF(OR(Z12="Y",AA12="Y"),"Not suitable","") | Z12: =IF(OR(N12="N/A",O12="N/A"),"Y","") | AE12: =C3 -> Pilbara Minerals Ltd | AF12: 1000000 | AG12: =OP!C22 -> 3009468000 | AH12: =-'Fin. Data'!B58*SARD!AF12+'Fin. Data'!B39*SARD!AF12 -> 2538700000 | AJ12: =AJ9*'Fin. Data'!B23*AF$12/AG$12 -> 10.965644 | AK12: =AK9*'Fin. Data'!B64*AF$12/AG$12 -> 2.9350624 | AL12: =AL9*'Fin. Data'!B5*AF$12/AG$12 -> 3.5707102 | AM12: =(AM9*'Fin. Data'!B5*$AF12+$AH12)/$AG12 -> 4.8493095 | AN12: =(AN9*'Fin. Data'!B19*$AF12+$AH12)/$AG12 -> 6.6919321 | AS12: 3967547 | AT12: 43220007 | AU12: 40492318 | AV12: 9729242.2 | AW12: 60067495 | AX12: 32538544 | AY12: 0.021951647 | AZ12: 0.0085329278
B13: 29M.AX | C13: 29Metals Ltd | D13: Diversified Mining | E13: Australia | F13: =AS13/AT13 -> -1.042901 | G13: =AU13/AV13 -> -0.76254834 | H13: =AX13 -> 2.4896694e+08 | I13: =(AY13/AZ13)-1 -> -0.76524996 | J13: =AV13/AW13 -> -0.79116305 | K13: =IFERROR(_xlfn.RANK.EQ(F13,F$3:F$64),"N/A") -> 59 | L13: =IFERROR(_xlfn.RANK.EQ(G13,G$3:G$64),"N/A") -> 47 | M13: =IFERROR(_xlfn.RANK.EQ(H13,H$3:H$64),"N/A") -> 33 | N13: =IFERROR(_xlfn.RANK.EQ(I13,I$3:I$64),"N/A") -> 43 | O13: =IFERROR(_xlfn.RANK.EQ(J13,J$3:J$64),"N/A") -> 47 | P13: =IFERROR(ABS(K$3-K13),"N/A") -> 57 | Q13: =IFERROR(ABS(L$3-L13),"N/A") -> 20 | R13: =IFERROR(ABS(M$3-M13),"N/A") -> 22 | S13: =IFERROR(ABS(N$3-N13),"N/A") -> 2 | T13: =IFERROR(ABS(O$3-O13),"N/A") -> 45 | U13: =SUM(P13:T13) -> 146 | V13: =_xlfn.RANK.EQ(U13,$U$4:$U$64,1) -> 40 | W13: =IF(Y13="Not suitable","-",V13) -> 40 | Y13: =IF(OR(Z13="Y",AA13="Y"),"Not suitable","") | Z13: =IF(OR(N13="N/A",O13="N/A"),"Y","") | AE13: By Consolidated Average | AJ13: =AVERAGE(AJ12:AL12) -> 5.8238056 | AM13: =AVERAGE(AM12:AN12) -> 5.7706208 | AS13: -440463000 | AT13: 422344000 | AU13: 271333000 | AV13: -355824000 | AW13: 449748000 | AX13: 2.4896694e+08 | AY13: -0.11345 | AZ13: -0.48328
B14: USA.TO | C14: Americas Gold and Silver Corporation | D14: Diversified Mining | E14: Canada | F14: =AS14/AT14 -> -0.55630517 | G14: =AU14/AV14 -> -0.43411831 | H14: =AX14 -> 72364913 | I14: =(AY14/AZ14)-1 -> -0.29834755 | J14: =AV14/AW14 -> -0.41956808 | K14: =IFERROR(_xlfn.RANK.EQ(F14,F$3:F$64),"N/A") -> 54 | L14: =IFERROR(_xlfn.RANK.EQ(G14,G$3:G$64),"N/A") -> 46 | M14: =IFERROR(_xlfn.RANK.EQ(H14,H$3:H$64),"N/A") -> 47 | N14: =IFERROR(_xlfn.RANK.EQ(I14,I$3:I$64),"N/A") -> 33 | O14: =IFERROR(_xlfn.RANK.EQ(J14,J$3:J$64),"N/A") -> 44 | P14: =IFERROR(ABS(K$3-K14),"N/A") -> 52 | Q14: =IFERROR(ABS(L$3-L14),"N/A") -> 19 | R14: =IFERROR(ABS(M$3-M14),"N/A") -> 36 | S14: =IFERROR(ABS(N$3-N14),"N/A") -> 12 | T14: =IFERROR(ABS(O$3-O14),"N/A") -> 42 | U14: =SUM(P14:T14) -> 161 | V14: =_xlfn.RANK.EQ(U14,$U$4:$U$64,1) -> 49 | W14: =IF(Y14="Not suitable","-",V14) -> 49 | Y14: =IF(OR(Z14="Y",AA14="Y"),"Not suitable","") | Z14: =IF(OR(N14="N/A",O14="N/A"),"Y","") | AE14: Upside | AJ14: =AJ13/OP!C21-1 -> 0.52057587 | AM14: =AM13/OP!C21-1 -> 0.50668951 | AS14: -66324575 | AT14: 1.1922337e+08 | AU14: 22728573 | AV14: -52355713 | AW14: 1.2478478e+08 | AX14: 72364913 | AY14: -0.23335445 | AZ14: -0.3325784
B15: SMT.TO | C15: Sierra Metals Inc | D15: Diversified Mining | E15: Canada | F15: =AS15/AT15 -> -1.0819957 | G15: =AU15/AV15 -> -1.2420035 | H15: =AX15 -> 1.9204638e+08 | I15: =(AY15/AZ15)-1 -> -1.2972789 | J15: =AV15/AW15 -> -0.39396936 | K15: =IFERROR(_xlfn.RANK.EQ(F15,F$3:F$64),"N/A") -> 60 | L15: =IFERROR(_xlfn.RANK.EQ(G15,G$3:G$64),"N/A") -> 53 | M15: =IFERROR(_xlfn.RANK.EQ(H15,H$3:H$64),"N/A") -> 36 | N15: =IFERROR(_xlfn.RANK.EQ(I15,I$3:I$64),"N/A") -> 58 | O15: =IFERROR(_xlfn.RANK.EQ(J15,J$3:J$64),"N/A") -> 43 | P15: =IFERROR(ABS(K$3-K15),"N/A") -> 58 | Q15: =IFERROR(ABS(L$3-L15),"N/A") -> 26 | R15: =IFERROR(ABS(M$3-M15),"N/A") -> 25 | S15: =IFERROR(ABS(N$3-N15),"N/A") -> 13 | T15: =IFERROR(ABS(O$3-O15),"N/A") -> 41 | U15: =SUM(P15:T15) -> 163 | V15: =_xlfn.RANK.EQ(U15,$U$4:$U$64,1) -> 50 | W15: =IF(Y15="Not suitable","-",V15) -> 50 | Y15: =IF(OR(Z15="Y",AA15="Y"),"Not suitable","") | Z15: =IF(OR(N15="N/A",O15="N/A"),"Y","") | AS15: -1.2961378e+08 | AT15: 1.197914e+08 | AU15: 1.3798013e+08 | AV15: -1.110948e+08 | AW15: 2.8198843e+08 | AX15: 1.9204638e+08 | AY15: 0.0767815 | AZ15: -0.258281
B16: LUCA.V | C16: Luca Mining Corp | D16: Diversified Mining | E16: Canada | F16: =AS16/AT16 -> -0.40923034 | G16: =AU16/AV16 -> -4.5051262 | H16: =AX16 -> 45950630 | I16: =(AY16/AZ16)-1 -> 4.7391051 | J16: =AV16/AW16 -> -0.1960377 | K16: =IFERROR(_xlfn.RANK.EQ(F16,F$3:F$64),"N/A") -> 52 | L16: =IFERROR(_xlfn.RANK.EQ(G16,G$3:G$64),"N/A") -> 59 | M16: =IFERROR(_xlfn.RANK.EQ(H16,H$3:H$64),"N/A") -> 54 | N16: =IFERROR(_xlfn.RANK.EQ(I16,I$3:I$64),"N/A") -> 2 | O16: =IFERROR(_xlfn.RANK.EQ(J16,J$3:J$64),"N/A") -> 39 | P16: =IFERROR(ABS(K$3-K16),"N/A") -> 50 | Q16: =IFERROR(ABS(L$3-L16),"N/A") -> 32 | R16: =IFERROR(ABS(M$3-M16),"N/A") -> 43 | S16: =IFERROR(ABS(N$3-N16),"N/A") -> 43 | T16: =IFERROR(ABS(O$3-O16),"N/A") -> 37 | U16: =SUM(P16:T16) -> 205 | V16: =_xlfn.RANK.EQ(U16,$U$4:$U$64,1) -> 61 | W16: =IF(Y16="Not suitable","-",V16) -> 61 | Y16: =IF(OR(Z16="Y",AA16="Y"),"Not suitable","") | Z16: =IF(OR(N16="N/A",O16="N/A"),"Y","") | AS16: -12574007 | AT16: 30725990 | AU16: 56647490 | AV16: -12574007 | AW16: 64140762 | AX16: 45950630 | AY16: -0.12416357 | AZ16: -0.021634657
B17: MND.TO | C17: Mandalay Resources Corp | D17: Diversified Mining | E17: Canada | F17: =AS17/AT17 -> 0.039917332 | G17: =AU17/AV17 -> 1.2211354 | H17: =AX17 -> 1.6077143e+08 | I17: =(AY17/AZ17)-1 -> 1.7688616 | J17: =AV17/AW17 -> 0.11147199 | K17: =IFERROR(_xlfn.RANK.EQ(F17,F$3:F$64),"N/A") -> 26 | L17: =IFERROR(_xlfn.RANK.EQ(G17,G$3:G$64),"N/A") -> 18 | M17: =IFERROR(_xlfn.RANK.EQ(H17,H$3:H$64),"N/A") -> 37 | N17: =IFERROR(_xlfn.RANK.EQ(I17,I$3:I$64),"N/A") -> 7 | O17: =IFERROR(_xlfn.RANK.EQ(J17,J$3:J$64),"N/A") -> 25 | P17: =IFERROR(ABS(K$3-K17),"N/A") -> 24 | Q17: =IFERROR(ABS(L$3-L17),"N/A") -> 9 | R17: =IFERROR(ABS(M$3-M17),"N/A") -> 26 | S17: =IFERROR(ABS(N$3-N17),"N/A") -> 38 | T17: =IFERROR(ABS(O$3-O17),"N/A") -> 23 | U17: =SUM(P17:T17) -> 120 | V17: =_xlfn.RANK.EQ(U17,$U$4:$U$64,1) -> 27 | W17: =IF(Y17="Not suitable","-",V17) -> 27 | Y17: =IF(OR(Z17="Y",AA17="Y"),"Not suitable","") | Z17: =IF(OR(N17="N/A",O17="N/A"),"Y","") | AS17: 11543328 | AT17: 2.8918086e+08 | AU17: 34649074 | AV17: 28374473 | AW17: 2.5454353e+08 | AX17: 1.6077143e+08 | AY17: 0.3423642 | AZ17: 0.123648
B18: GSVR.V | C18: Guanajuato Silver Company Ltd | D18: Diversified Mining | E18: Canada | F18: =AS18/AT18 -> -0.82344251 | G18: =AU18/AV18 -> -0.88894473 | H18: =AX18 -> 62032415 | I18: =(AY18/AZ18)-1 -> 0.15617613 | J18: =AV18/AW18 -> -0.62312542 | K18: =IFERROR(_xlfn.RANK.EQ(F18,F$3:F$64),"N/A") -> 57 | L18: =IFERROR(_xlfn.RANK.EQ(G18,G$3:G$64),"N/A") -> 49 | M18: =IFERROR(_xlfn.RANK.EQ(H18,H$3:H$64),"N/A") -> 50 | N18: =IFERROR(_xlfn.RANK.EQ(I18,I$3:I$64),"N/A") -> 13 | O18: =IFERROR(_xlfn.RANK.EQ(J18,J$3:J$64),"N/A") -> 46 | P18: =IFERROR(ABS(K$3-K18),"N/A") -> 55 | Q18: =IFERROR(ABS(L$3-L18),"N/A") -> 22 | R18: =IFERROR(ABS(M$3-M18),"N/A") -> 39 | S18: =IFERROR(ABS(N$3-N18),"N/A") -> 32 | T18: =IFERROR(ABS(O$3-O18),"N/A") -> 44 | U18: =SUM(P18:T18) -> 192 | V18: =_xlfn.RANK.EQ(U18,$U$4:$U$64,1) -> 59 | W18: =IF(Y18="Not suitable","-",V18) -> 59 | Y18: =IF(OR(Z18="Y",AA18="Y"),"Not suitable","") | Z18: =IF(OR(N18="N/A",O18="N/A"),"Y","") | AS18: -39294804 | AT18: 47720155 | AU18: 29985028 | AV18: -33731038 | AW18: 54132020 | AX18: 62032415 | AY18: -0.1194384 | AZ18: -0.10330468
B19: AMI.AX | C19: Aurelia Metals Ltd | D19: Diversified Mining | E19: Australia | F19: =AS19/AT19 -> -0.16854999 | G19: =AU19/AV19 -> -0.18348199 | H19: =AX19 -> 2.3656744e+08 | I19: =(AY19/AZ19)-1 -> -1.0032833 | J19: =AV19/AW19 -> -0.18735814 | K19: =IFERROR(_xlfn.RANK.EQ(F19,F$3:F$64),"N/A") -> 46 | L19: =IFERROR(_xlfn.RANK.EQ(G19,G$3:G$64),"N/A") -> 42 | M19: =IFERROR(_xlfn.RANK.EQ(H19,H$3:H$64),"N/A") -> 34 | N19: =IFERROR(_xlfn.RANK.EQ(I19,I$3:I$64),"N/A") -> 56 | O19: =IFERROR(_xlfn.RANK.EQ(J19,J$3:J$64),"N/A") -> 38 | P19: =IFERROR(ABS(K$3-K19),"N/A") -> 44 | Q19: =IFERROR(ABS(L$3-L19),"N/A") -> 15 | R19: =IFERROR(ABS(M$3-M19),"N/A") -> 23 | S19: =IFERROR(ABS(N$3-N19),"N/A") -> 11 | T19: =IFERROR(ABS(O$3-O19),"N/A") -> 36 | U19: =SUM(P19:T19) -> 129 | V19: =_xlfn.RANK.EQ(U19,$U$4:$U$64,1) -> 31 | W19: =IF(Y19="Not suitable","-",V19) -> 31 | Y19: =IF(OR(Z19="Y",AA19="Y"),"Not suitable","") | Z19: =IF(OR(N19="N/A",O19="N/A"),"Y","") | AS19: -52221000 | AT19: 309825000 | AU19: 12692000 | AV19: -69173000 | AW19: 369202000 | AX19: 2.3656744e+08 | AY19: 7e-05 | AZ19: -0.02132
B20: VDAN.NS | C20: Vedanta Ltd | D20: Diversified Mining | E20: India | F20: =AS20/AT20 -> 0.36795779 | G20: =AU20/AV20 -> 2.7517449 | H20: =AX20 -> 1.8998025e+10 | I20: =(AY20/AZ20)-1 -> -0.48843879 | J20: =AV20/AW20 -> 0.16436989 | K20: =IFERROR(_xlfn.RANK.EQ(F20,F$3:F$64),"N/A") -> 4 | L20: =IFERROR(_xlfn.RANK.EQ(G20,G$3:G$64),"N/A") -> 10 | M20: =IFERROR(_xlfn.RANK.EQ(H20,H$3:H$64),"N/A") -> 9 | N20: =IFERROR(_xlfn.RANK.EQ(I20,I$3:I$64),"N/A") -> 37 | O20: =IFERROR(_xlfn.RANK.EQ(J20,J$3:J$64),"N/A") -> 18 | P20: =IFERROR(ABS(K$3-K20),"N/A") -> 2 | Q20: =IFERROR(ABS(L$3-L20),"N/A") -> 17 | R20: =IFERROR(ABS(M$3-M20),"N/A") -> 2 | S20: =IFERROR(ABS(N$3-N20),"N/A") -> 8 | T20: =IFERROR(ABS(O$3-O20),"N/A") -> 16 | U20: =SUM(P20:T20) -> 45 | V20: =_xlfn.RANK.EQ(U20,$U$4:$U$64,1) -> 5 | W20: =IF(Y20="Not suitable","-",V20) -> 5 | Y20: =IF(OR(Z20="Y",AA20="Y"),"Not suitable","") | Z20: =IF(OR(N20="N/A",O20="N/A"),"Y","") | AS20: 2.6411125e+09 | AT20: 7.1777594e+09 | AU20: 1.2130983e+10 | AV20: 4.4084694e+09 | AW20: 2.6820419e+10 | AX20: 1.8998025e+10 | AY20: 0.27362083 | AZ20: 0.53487409
B21: PEOLES.MX | C21: Industrias Penoles SAB de CV | D21: Diversified Mining | E21: Mexico | F21: =AS21/AT21 -> 0.079909452 | G21: =AU21/AV21 -> 7.9476189 | H21: =AX21 -> 7.7914558e+09 | I21: =(AY21/AZ21)-1 -> -0.30565796 | J21: =AV21/AW21 -> 0.06870603 | K21: =IFERROR(_xlfn.RANK.EQ(F21,F$3:F$64),"N/A") -> 19 | L21: =IFERROR(_xlfn.RANK.EQ(G21,G$3:G$64),"N/A") -> 4 | M21: =IFERROR(_xlfn.RANK.EQ(H21,H$3:H$64),"N/A") -> 14 | N21: =IFERROR(_xlfn.RANK.EQ(I21,I$3:I$64),"N/A") -> 34 | O21: =IFERROR(_xlfn.RANK.EQ(J21,J$3:J$64),"N/A") -> 26 | P21: =IFERROR(ABS(K$3-K21),"N/A") -> 17 | Q21: =IFERROR(ABS(L$3-L21),"N/A") -> 23 | R21: =IFERROR(ABS(M$3-M21),"N/A") -> 3 | S21: =IFERROR(ABS(N$3-N21),"N/A") -> 11 | T21: =IFERROR(ABS(O$3-O21),"N/A") -> 24 | U21: =SUM(P21:T21) -> 78 | V21: =_xlfn.RANK.EQ(U21,$U$4:$U$64,1) -> 16 | W21: =IF(Y21="Not suitable","-",V21) -> 16 | Y21: =IF(OR(Z21="Y",AA21="Y"),"Not suitable","") | Z21: =IF(OR(N21="N/A",O21="N/A"),"Y","") | AS21: 4.7787247e+08 | AT21: 5.9801746e+09 | AU21: 4.4268626e+09 | AV21: 5.570049e+08 | AW21: 8.1070744e+09 | AX21: 7.7914558e+09 | AY21: 0.2309115 | AZ21: 0.3325616
B22: DR0G.DE | C22: Deutsche Rohstoff AG | D22: Diversified Mining | E22: Germany | F22: =AS22/AT22 -> 0.51322015 | G22: =AU22/AV22 -> 1.1338421 | H22: =AX22 -> 2.6475409e+08 | I22: =(AY22/AZ22)-1 -> 0.012673817 | J22: =AV22/AW22 -> 0.58583497 | K22: =IFERROR(_xlfn.RANK.EQ(F22,F$3:F$64),"N/A") -> 3 | L22: =IFERROR(_xlfn.RANK.EQ(G22,G$3:G$64),"N/A") -> 19 | M22: =IFERROR(_xlfn.RANK.EQ(H22,H$3:H$64),"N/A") -> 32 | N22: =IFERROR(_xlfn.RANK.EQ(I22,I$3:I$64),"N/A") -> 21 | O22: =IFERROR(_xlfn.RANK.EQ(J22,J$3:J$64),"N/A") -> 3 | P22: =IFERROR(ABS(K$3-K22),"N/A") -> 1 | Q22: =IFERROR(ABS(L$3-L22),"N/A") -> 8 | R22: =IFERROR(ABS(M$3-M22),"N/A") -> 21 | S22: =IFERROR(ABS(N$3-N22),"N/A") -> 24 | T22: =IFERROR(ABS(O$3-O22),"N/A") -> 1 | U22: =SUM(P22:T22) -> 55 | V22: =_xlfn.RANK.EQ(U22,$U$4:$U$64,1) -> 8 | W22: =IF(Y22="Not suitable","-",V22) -> 8 | Y22: =IF(OR(Z22="Y",AA22="Y"),"Not suitable","") | Z22: =IF(OR(N22="N/A",O22="N/A"),"Y","") | AS22: 1.0396609e+08 | AT22: 2.0257601e+08 | AU22: 1.7262139e+08 | AV22: 1.5224465e+08 | AW22: 2.5987634e+08 | AX22: 2.6475409e+08 | AY22: 21.884575 | AZ22: 21.610685
B23: A1M.AX | C23: AIC Mines Ltd | D23: Diversified Mining | E23: Australia | F23: =AS23/AT23 -> -0.037688768 | G23: =AU23/AV23 -> -0.39186384 | H23: =AX23 -> 1.433659e+08 | I23: =(AY23/AZ23)-1 -> -1.7399001 | J23: =AV23/AW23 -> -0.057523779 | K23: =IFERROR(_xlfn.RANK.EQ(F23,F$3:F$64),"N/A") -> 33 | L23: =IFERROR(_xlfn.RANK.EQ(G23,G$3:G$64),"N/A") -> 44 | M23: =IFERROR(_xlfn.RANK.EQ(H23,H$3:H$64),"N/A") -> 39 | N23: =IFERROR(_xlfn.RANK.EQ(I23,I$3:I$64),"N/A") -> 60 | O23: =IFERROR(_xlfn.RANK.EQ(J23,J$3:J$64),"N/A") -> 32 | P23: =IFERROR(ABS(K$3-K23),"N/A") -> 31 | Q23: =IFERROR(ABS(L$3-L23),"N/A") -> 17 | R23: =IFERROR(ABS(M$3-M23),"N/A") -> 28 | S23: =IFERROR(ABS(N$3-N23),"N/A") -> 15 | T23: =IFERROR(ABS(O$3-O23),"N/A") -> 30 | U23: =SUM(P23:T23) -> 121 | V23: =_xlfn.RANK.EQ(U23,$U$4:$U$64,1) -> 28 | W23: =IF(Y23="Not suitable","-",V23) -> 28 | Y23: =IF(OR(Z23="Y",AA23="Y"),"Not suitable","") | Z23: =IF(OR(N23="N/A",O23="N/A"),"Y","") | AS23: -5815000 | AT23: 154290000 | AU23: 2832000 | AV23: -7227000 | AW23: 125635000 | AX23: 1.433659e+08 | AY23: 0.0163 | AZ23: -0.02203
B24: AAL.L | C24: Anglo American PLC | D24: Diversified Mining | E24: United Kingdom | F24: =AS24/AT24 -> 0.053637706 | G24: =AU24/AV24 -> 4.4823748 | H24: =AX24 -> 4.5674651e+10 | I24: =(AY24/AZ24)-1 -> -0.072794502 | J24: =AV24/AW24 -> 0.12309148 | K24: =IFERROR(_xlfn.RANK.EQ(F24,F$3:F$64),"N/A") -> 24 | L24: =IFERROR(_xlfn.RANK.EQ(G24,G$3:G$64),"N/A") -> 7 | M24: =IFERROR(_xlfn.RANK.EQ(H24,H$3:H$64),"N/A") -> 6 | N24: =IFERROR(_xlfn.RANK.EQ(I24,I$3:I$64),"N/A") -> 25 | O24: =IFERROR(_xlfn.RANK.EQ(J24,J$3:J$64),"N/A") -> 23 | P24: =IFERROR(ABS(K$3-K24),"N/A") -> 22 | Q24: =IFERROR(ABS(L$3-L24),"N/A") -> 20 | R24: =IFERROR(ABS(M$3-M24),"N/A") -> 5 | S24: =IFERROR(ABS(N$3-N24),"N/A") -> 20 | T24: =IFERROR(ABS(O$3-O24),"N/A") -> 21 | U24: =SUM(P24:T24) -> 88 | V24: =_xlfn.RANK.EQ(U24,$U$4:$U$64,1) -> 21 | W24: =IF(Y24="Not suitable","-",V24) -> 21 | Y24: =IF(OR(Z24="Y",AA24="Y"),"Not suitable","") | Z24: =IF(OR(N24="N/A",O24="N/A"),"Y","") | AS24: 1973569920 | AT24: 36794450510 | AU24: 24834088160 | AV24: 5540386390 | AW24: 45010316360 | AX24: 4.5674651e+10 | AY24: 3.2940196 | AZ24: 3.5526316
