Workbook
Name Sectors: '[1]Sector Impact'!$K$4:$K$16
Name Sectors: 'Sector Impact'!$K$4:$K$16

Sheet OP
B2: 45390 | C2: Team 12 | D2: 26th April, 2024 | E2: ='Inputs (AUD)'!H3 -> #VALUE! | L2: {=_FV(E2,"Exchange abbreviation",TRUE)} -> XASX | M2: SIC:
D3: COMPANY DESCRIPTION | H3: CEO & BOARD OF DIRECTORS
D4: Pilbara Minerals Limited is an Australia-based lithium company, The Company is primarily engaged in the exploration, development, and mining of minerals in Australia, Its 100% owned Pilgangoora hard-rock lithium operation consists of two processing plants: the Pilgan Plant, located on the northern side and produces spodumene and tantalite concentrates, and the Ngungaju Plant is located to the south produces spodumene concentrate, It owns 70% of the Mt Francisco project, and hosts the large occurrence of outcropping pegmatites, It is also pursuing a proposed downstream joint venture (JV) for the development of an approximately 43,000 tons per annum (tpa) lithium carbonate equivalent (LCE) lithium chemical conversion facility in South Korea, | H4: Name (Sex;Age) | I4: Tenure | J4: Executive? | K4: Other roles
H5: Dale Henderson (M;?) | I5: 2 years | J5: YES | K5: Chief Executive Officer of Pilbara Minerals
H6: Kathleen Conlon (F;?) | I6: 2 months | J6: NO | K6: Non-Executive Director of Aristocrat Leisure Limited and BlueScope Steel Limited, and Chairs the Corporate Governance Committee of the Australian Institute of Company Directors | P6: {=_FV(E2,"Description")} -> Pilbara Minerals Limited is an Australia-based lithium company. The Company is primarily engaged in the exploration, development, and mining of minerals in Australia. Its 100% owned Pilgangoora hard-rock lithium operation is located approximately 120 kilometers (kms) from Port Hedland in Western Australia’s resource-rich Pilbara region. The operation consists of two processing plants: the Pilgan Plant, located on the northern side of the Pilgangoora area and produces spodumene and tantalite concentrates, and the Ngungaju Plant is located to the south produces spodumene concentrate. It owns 70% of the Mt Francisco project, which is located 50 km south-west of the Pilgangoora Project and hosts the large occurrence of outcropping pegmatites located nearby to Port Hedland. It is also pursuing a proposed downstream joint venture (JV) for the development of an approximately 43,000 tons per annum (tpa) lithium carbonate equivalent (LCE) lithium chemical conversion facility in South Korea.
H7: Sally-Anne Layman (F;?) | I7: 6 years | J7: NO | K7: Non-Executive Director of IMDEX Ltd, Beach Energy Ltd and Newmount Corporation.
H8: Nick Cernotta (M;?) | I8: 7 years | J8: NO | K8: Non-Executive Chair of Panoramic Resources Limited and a Non-Executive Director of Northern Star Resources Limited and New Century Resources. Limited
H9: Steve Scudamore (M;?) | I9: 8 years | J9: NO | K9: Vice Chair of the Western Australian Museum and WA Committee Chair of the Australian British Chamber of Commerce and member of the National Board
H10: Miriam Stanborough (F;?) | I10: 2 years | J10: NO | K10: Chair of the Minerals Research Institute of Western Australia (MRIWA), Deputy Chair of the Northern Agricultural Catchments Council (NACC), and Deputy Chair of Scouts | O10: https://www,marketscreener,com/quote/stock/PILBARA-MINERALS-LIMITED-10354122/company/
H11: EXECUTIVE LEADERSHIP TEAM
H12: =H5 -> Dale Henderson (M;?) | I12: =I5 -> 2 years | J12: =J5 -> YES | K12: =K5 -> Chief Executive Officer of Pilbara Minerals
H13: Vince De Carolis (M;?) | I13: 1 year | J13: YES | K13: Chief Operating Officer
H14: Luke Bortoli (M;?) | I14: 1 year | J14: YES | K14: Chief Financial Officer
H15: Sandra McInnes (F;?) | I15: 1 year | J15: YES | K15: Chief Sustainability Officer
H16: John Stanning (M;?) | I16: 1 year | J16: YES | K16: Chief Development Officer
H17: Paul Laybourne (M;?) | I17: 1 year | J17: YES | K17: Project Director
B18: {=_FV(E2,"Currency")&" MILLIONS"} -> AUD MILLIONS | H18: Jen Mintz (F;?) | I18: 1 month | J18: YES | K18: General Counsel
B19: COMPANY OVERVIEW
B20: Stock | D20: Liquidity and Solvency | F20: Segments | I20: Profitability (2023) | L20: Multiples
B21: Last Price | C21: {=_FV(E2,"Price")} -> 3.13 | D21: Total Assets | E21: =_xlfn.XLOOKUP(D21,'Fin. Data'!A:A,'Fin. Data'!B:B,,0) -> 5198.8 | F21: Regions | H21: % Sales | I21: Reporting Year | J21: 2023 | L21: Float | M21: ='Inputs (AUD)'!B82 -> 0.9037
B22: Outstanding Shares | C22: {=_FV(E2,"Shares outstanding",TRUE)} -> 3011485000 | D22: Total Liabilities | E22: =_xlfn.XLOOKUP(D22,'Fin. Data'!A:A,'Fin. Data'!B:B,,0) -> 1808.8 | F22: =Segments!C5 -> Pilgan | H22: =Segments!B5 -> 0.69622735 | I22: End of Year | J22: 45107 | L22: Insiders Own | M22: ='Inputs (AUD)'!B83 -> 0.0963
B23: Market Cap. | C23: =C21*C22/1000000 -> 9425.9481 | D23: Cash/Share | E23: =_xlfn.XLOOKUP("Cash & Eq.",'Fin. Data'!A:A,'Fin. Data'!B:B,,0)*1000000/C22 -> 1.1086225 | F23: =Segments!C6 -> Ngungaju | H23: =Segments!B6 -> 0.36616828 | I23: EBITDA | K23: =_xlfn.XLOOKUP(I23,'Fin. Data'!A:A,'Fin. Data'!B:B,,0) -> 3098.7 | L23: b (Yahoo) | M23: {=_FV(E2,"Beta")} -> 2.0207
B24: +Total Debt | C24: ='Fin. Data'!B58 -> 472 | D24: EBITDA/Net Financial Cost (NFC) | E24: =_xlfn.XLOOKUP("EBITDA",'Fin. Data'!A:A,'Fin. Data'!B:B,,0)/_xlfn.XLOOKUP("Net Financial Cost",'Fin. Data'!A:A,'Fin. Data'!B:B,,0) -> 69.013363 | F24: =Segments!C7 -> (elimination of by-product) | H24: =Segments!B7 -> -0.00050762558 | I24: Depreciation & Amortization | K24: =_xlfn.XLOOKUP(I24,'Fin. Data'!A:A,'Fin. Data'!B:B,,0) -> 1.5 | L24: Score (S&P) | M24: ='Inputs (AUD)'!B84 -> None
B25: -Cash | C25: ='Fin. Data'!B39 -> 3338.6 | D25: Debt/EBITDA | E25: =_xlfn.XLOOKUP("Total Debt",'Fin. Data'!A:A,'Fin. Data'!B:B,,0)/_xlfn.XLOOKUP("EBITDA",'Fin. Data'!A:A,'Fin. Data'!B:B,,0) -> 0.15232194 | F25: =Segments!C8 -> (provisional price adjustment) | H25: =Segments!B8 -> -0.061659653 | I25: EBIT | K25: =_xlfn.XLOOKUP(I25,'Fin. Data'!A:A,'Fin. Data'!B:B,,0) -> 3097.2 | L25: Price/Book Value | M25: =IFERROR((C21*C22/(E21-E22))/1000000,"") -> 2.7805156
B26: =Enterprise Value | C26: =C23+C24-C25 -> 6559.3481 | D26: "Others Assets"/Asset | E26: =_xlfn.XLOOKUP("Other Assets",'Fin. Data'!A:A,'Fin. Data'!B:B,,0)/_xlfn.XLOOKUP("Total Assets",'Fin. Data'!A:A,'Fin. Data'!B:B,,0) -> 0.01521505 | F26: =Segments!C9 -> (hedge close-outs) | H26: =Segments!B9 -> -0.00022834539 | I26: Net Income | K26: =_xlfn.XLOOKUP(I26,'Fin. Data'!A:A,'Fin. Data'!B:B,,0) -> 2391.1 | L26: NCF(3y avg)/Asset | M26: =IFERROR(K32/E21,"") -> 0.20305968
B27: Holdings (nac/int'l) | C27: - | D27: Debt/Assets | E27: =_xlfn.XLOOKUP(D27,'Fin. Data'!A:A,'Fin. Data'!B:B,,0) -> 0.090790182 | F27: Categories | H27: % Sales | I27: EPS | K27: =1000000*K26/C22 -> 0.79399366 | L27: Price/Net Inc. (3y avg) | M27: =IFERROR(C23/K31,"") -> 9.7459397
B28: t liq. (Holdings/Vol.) | C28: - | D28: EBITDA Margin (average) | E28: =AVERAGE(_xlfn.XLOOKUP("EBITDA Margin",'Fin. Data'!A:A,'Fin. Data'!B:D,,0)) -> 0.39491807 | F28: =Segments!C15 -> Spodumene | H28: =Segments!B15 -> 1.061888 | I28: ROA | K28: =K26/E21 -> 0.45993306 | L28: EV/Asset | M28: =IFERROR(C26/E21,"") -> 1.2617042
B29: % Short | C29: N/A | D29: Operating Margin (average) | E29: =AVERAGE(_xlfn.XLOOKUP("Operating Margin",'Fin. Data'!A:A,'Fin. Data'!B:D,,0)) -> 0.40216289 | F29: =Segments!C16 -> Tantalite | H29: =Segments!B16 -> 0.00050762558 | I29: ROIC | K29: =K26/(E21-(E22-C24)) -> 0.61913516 | L29: EV/Ebitda (3y average) | M29: =IFERROR(C26/K30,"") -> 5.1886735
B30: Traffic ESG | D30: Net Income Margin (average) | E30: =AVERAGE(_xlfn.XLOOKUP("Net Income Margin",'Fin. Data'!A:A,'Fin. Data'!B:D,,0)) -> 0.25608103 | F30: =Segments!C17 -> (elimination of by-product) | H30: =Segments!B17 -> -0.00050762558 | I30: EBITDA (3y average) | K30: =AVERAGE(_xlfn.XLOOKUP("EBITDA",'Fin. Data'!A:A,'Fin. Data'!B:D,,0)) -> 1264.1667 | L30: Price/NCF (3y average) | M30: =IFERROR(C23/K32,"") -> 8.9289056
B31: E | F31: =Segments!C18 -> (provisional price adjustment) | H31: =Segments!B18 -> -0.061659653 | I31: Net Income (3y average) | K31: =AVERAGE(_xlfn.XLOOKUP("Net Income",'Fin. Data'!A:A,'Fin. Data'!B:D,,0)) -> 967.16667 | L31: Bonds 1,3,5a (USD) | M31: -
B32: S | D32: Net Financial Cost/Avg Net Debt | E32: =-_xlfn.XLOOKUP("Net Financial Cost",'Fin. Data'!A:A,'Fin. Data'!B:B,,0)/AVERAGE(_xlfn.XLOOKUP("Net Debt",'Fin. Data'!A:A,'Fin. Data'!B:D,,0)) -> 0.043464232 | F32: =Segments!C19 -> (hedge close-outs) | H32: =Segments!B19 -> -0.00022834539 | I32: NCF (3y average) | K32: =AVERAGE(_xlfn.XLOOKUP("Net Cash Flow",'Fin. Data'!A:A,'Fin. Data'!B:D,,0)) -> 1055.6667 | L32: Div+Rep.(3y avg)/Price | M32: =-IFERROR(SUM(E53:E55)/(3*C23),"") -> 0.0030164959
B33: G | L33: Div. Yield | M33: =-IFERROR(L54/C23,"") -> 0.034988523
B34: INVESTMENT THESIS
B35: Pillars of Recommendation | H35: Recommendation | I35: Valuation Assumptions
B36: Pillar | C36: Explanation | H36: HOLD | I36: Check DCF
B37: Growing Company | C37: In general mining companies have a higher than average profit margins when compared with other companies publicly traded companies. Pilbara's financials have been growing exponentially in the last years and they have been able to maintain a very health balance sheet.
B38: Government Incentives and Support | C38: Governments around the world are focused on reaching a greener atmosphere by 2030, therefore they are investing heavily and incentivesing the purchase of EV's and consequently their compontents. This government support and fiscal incentives to produce more, will come with a positive side for Pilbara and the whole market.
B39: Lithium Demand | C39: Currently the supply chain has caught up to the demand, sending the current price per ton down and lowering profit margins for all market players; However, forecasts of demand point to an increase in 2025 signaling a possible increase in revenues and subsequent growth of the companies.
B40: Risks of Investment | H40: Price Target | I40: Valuation
B41: Risk | C41: Explanation | H41: =DCF!D76 -> 4.1785239 | I41: Discount Rate | J41: =DCF!F50 -> 0.091 | L41: Price M. Upside | M41: =SARD!AJ14 -> 0.85939456
...

Sheet Acuerdo
A1: Invertir
A2: NO invertir
A3: Mantener sin elevar posición
A4: Mantener (y seguir comprando)
A5: Liquidar
A6: PENDIENTE

Sheet Segments
B2: ="Regions "&"("&OP!$J$21&")" -> Regions (2023) | Q2: Products
D3: Nominal value | K3: YoY Growth
B4: Weight | C4: Region (Plant) | D4: =OP!J21 -> 2023 | E4: =D4-1 -> 2022 | F4: =E4-1 -> 2021 | G4: =F4-1 -> 2020 | H4: =G4-1 -> 2019 | I4: =H4-1 -> 2018 | K4: =OP!J21 -> 2023 | L4: =K4-1 -> 2022 | M4: =L4-1 -> 2021 | N4: =M4-1 -> 2020 | O4: =N4-1 -> 2019 | P4: =O4-1 -> 2018
B5: =IFERROR(D5/$D$10,"") -> 0.69622735 | C5: Pilgan | D5: =+(D15*38/58+D16) -> 2829.4812 | E5: =+E15*38/58+E16 -> 766.81931 | F5: =+F15+F16 -> 170.45 | G5: =+G15+G16 -> 92.854 | H5: =+H15+H16 -> 44.498 | I5: =+I15+I16 -> 9.88 | K5: =IFERROR((D5-E5)/E5,"-") -> 2.689893 | L5: =IFERROR((E5-F5)/F5,"-") -> 3.4987933 | M5: =IFERROR((F5-G5)/G5,"-") -> 0.83567752 | N5: =IFERROR((G5-H5)/H5,"-") -> 1.0867005 | O5: =IFERROR((H5-I5)/I5,"-") -> 3.5038462 | P5: =IFERROR((I5-J5)/J5,"-") -> -
B6: =IFERROR(D6/$D$10,"") -> 0.36616828 | C6: Ngungaju | D6: =+D15*20/58 -> 1488.1148 | E6: =+E15*20/58 -> 400.77069 | F6: - | G6: - | H6: - | I6: - | K6: =IFERROR((D6-E6)/E6,"-") -> 2.7131329 | L6: =IFERROR((E6-F6)/F6,"-") -> - | M6: =IFERROR((F6-G6)/G6,"-") -> - | N6: =IFERROR((G6-H6)/H6,"-") -> - | O6: =IFERROR((H6-I6)/I6,"-") -> - | P6: =IFERROR((I6-J6)/J6,"-") -> -
B7: =IFERROR(D7/$D$10,"") -> -0.00050762558 | C7: =+C17 -> (elimination of by-product) | D7: =+D17 -> -2.063 | E7: =+E17 -> -5.355 | F7: =+F17 -> -5.982 | G7: =+G17 -> -7.463 | H7: =+H17 -> -2.293 | I7: =+I17 -> - | K7: =IFERROR((D7-E7)/E7,"-") -> -0.61475257 | L7: =IFERROR((E7-F7)/F7,"-") -> -0.10481444 | M7: =IFERROR((F7-G7)/G7,"-") -> -0.19844567 | N7: =IFERROR((G7-H7)/H7,"-") -> 2.2546882 | O7: =IFERROR((H7-I7)/I7,"-") -> - | P7: =IFERROR((I7-J7)/J7,"-") -> -
B8: =IFERROR(D8/$D$10,"") -> -0.061659653 | C8: =+C18 -> (provisional price adjustment) | D8: =+D18 -> -250.586 | E8: =+E18 -> 27.356 | F8: =+F18 -> 11.356 | G8: =+G18 -> -1.194 | H8: =+H18 -> - | I8: =+I18 -> - | K8: =IFERROR((D8-E8)/E8,"-") -> -10.160184 | L8: =IFERROR((E8-F8)/F8,"-") -> 1.4089468 | M8: =IFERROR((F8-G8)/G8,"-") -> -10.510888 | N8: =IFERROR((G8-H8)/H8,"-") -> - | O8: =IFERROR((H8-I8)/I8,"-") -> - | P8: =IFERROR((I8-J8)/J8,"-") -> -
B9: =IFERROR(D9/$D$10,"") -> -0.00022834539 | C9: =+C19 -> (hedge close-outs) | D9: =+D19 -> -0.928 | E9: =+E19 -> - | F9: =+F19 -> - | G9: =+G19 -> -0.05 | H9: =+H19 -> 0.58 | I9: =+I19 -> 0.308 | K9: =IFERROR((D9-E9)/E9,"-") -> - | L9: =IFERROR((E9-F9)/F9,"-") -> - | M9: =IFERROR((F9-G9)/G9,"-") -> - | N9: =IFERROR((G9-H9)/H9,"-") -> -1.0862069 | O9: =IFERROR((H9-I9)/I9,"-") -> 0.88311688 | P9: =IFERROR((I9-J9)/J9,"-") -> -
B10: =SUM(B5:B9) -> 1 | C10: TOTAL | D10: =SUM(D5:D9) -> 4064.019 | E10: =SUM(E5:E9) -> 1189.591 | F10: =SUM(F5:F9) -> 175.824 | G10: =SUM(G5:G9) -> 84.147 | H10: =SUM(H5:H9) -> 42.785 | I10: =SUM(I5:I9) -> 10.188 | K10: =(D10-E10)/E10 -> 2.4163162 | L10: =(E10-F10)/F10 -> 5.7658056 | M10: =(F10-G10)/G10 -> 1.0894863 | N10: =(G10-H10)/H10 -> 0.96674068 | O10: =(H10-I10)/I10 -> 3.1995485 | P10: -
B12: ="Categories "&"("&OP!$J$21&")" -> Categories (2023)
D13: Nominal value | K13: YoY Growth
B14: Weight | C14: Category | D14: =OP!J21 -> 2023 | E14: =D14-1 -> 2022 | F14: =E14-1 -> 2021 | G14: =F14-1 -> 2020 | H14: =G14-1 -> 2019 | I14: =H14-1 -> 2018 | K14: =OP!J21 -> 2023 | L14: =K14-1 -> 2022 | M14: =L14-1 -> 2021 | N14: =M14-1 -> 2020 | O14: =N14-1 -> 2019 | P14: =O14-1 -> 2018
B15: =IFERROR(D15/$D$20,"") -> 1.061888 | C15: Spodumene | D15: =4315533000/1000000 -> 4315.533 | E15: =1162235000/1000000 -> 1162.235 | F15: =164468000/1000000 -> 164.468 | G15: =85391000/1000000 -> 85.391 | H15: =42205000/1000000 -> 42.205 | I15: =9880000/1000000 -> 9.88 | K15: =IFERROR((D15-E15)/E15,"-") -> 2.7131329 | L15: =IFERROR((E15-F15)/F15,"-") -> 6.066633 | M15: =IFERROR((F15-G15)/G15,"-") -> 0.92605778 | N15: =IFERROR((G15-H15)/H15,"-") -> 1.0232437 | O15: =IFERROR((H15-I15)/I15,"-") -> 3.2717611 | P15: =IFERROR((I15-J15)/J15,"-") -> -
B16: =IFERROR(D16/$D$20,"") -> 0.00050762558 | C16: Tantalite | D16: =2063000/1000000 -> 2.063 | E16: =5355000/1000000 -> 5.355 | F16: =5982000/1000000 -> 5.982 | G16: =7463000/1000000 -> 7.463 | H16: =2293000/1000000 -> 2.293 | I16: 0 | K16: =IFERROR((D16-E16)/E16,"-") -> -0.61475257 | L16: =IFERROR((E16-F16)/F16,"-") -> -0.10481444 | M16: =IFERROR((F16-G16)/G16,"-") -> -0.19844567 | N16: =IFERROR((G16-H16)/H16,"-") -> 2.2546882 | O16: =IFERROR((H16-I16)/I16,"-") -> - | P16: =IFERROR((I16-J16)/J16,"-") -> -
B17: =IFERROR(D17/$D$20,"") -> -0.00050762558 | C17: (elimination of by-product) | D17: =-D16 -> -2.063 | E17: =-E16 -> -5.355 | F17: =-F16 -> -5.982 | G17: =-G16 -> -7.463 | H17: =-H16 -> -2.293 | I17: - | K17: =IFERROR((D17-E17)/E17,"-") -> -0.61475257 | L17: =IFERROR((E17-F17)/F17,"-") -> -0.10481444 | M17: =IFERROR((F17-G17)/G17,"-") -> -0.19844567 | N17: =IFERROR((G17-H17)/H17,"-") -> 2.2546882 | O17: =IFERROR((H17-I17)/I17,"-") -> - | P17: =IFERROR((I17-J17)/J17,"-") -> -
B18: =IFERROR(D18/$D$20,"") -> -0.061659653 | C18: (provisional price adjustment) | D18: =-250586000/1000000 -> -250.586 | E18: =27356000/1000000 -> 27.356 | F18: =11356000/1000000 -> 11.356 | G18: =-1194000/1000000 -> -1.194 | H18: - | I18: - | K18: =IFERROR((D18-E18)/E18,"-") -> -10.160184 | L18: =IFERROR((E18-F18)/F18,"-") -> 1.4089468 | M18: =IFERROR((F18-G18)/G18,"-") -> -10.510888 | N18: =IFERROR((G18-H18)/H18,"-") -> - | O18: =IFERROR((H18-I18)/I18,"-") -> - | P18: =IFERROR((I18-J18)/J18,"-") -> -
B19: =IFERROR(D19/$D$20,"") -> -0.00022834539 | C19: (hedge close-outs) | D19: =-928000/1000000 -> -0.928 | E19: - | F19: - | G19: =-50000/1000000 -> -0.05 | H19: =580000/1000000 -> 0.58 | I19: =308000/1000000 -> 0.308 | K19: =IFERROR((D19-E19)/E19,"-") -> - | L19: =IFERROR((E19-F19)/F19,"-") -> - | M19: =IFERROR((F19-G19)/G19,"-") -> - | N19: =IFERROR((G19-H19)/H19,"-") -> -1.0862069 | O19: =IFERROR((H19-I19)/I19,"-") -> 0.88311688 | P19: =IFERROR((I19-J19)/J19,"-") -> -
B20: =SUM(B15:B19) -> 1 | C20: TOTAL | D20: =SUM(D15:D19) -> 4064.019 | E20: =SUM(E15:E19) -> 1189.591 | F20: =SUM(F15:F19) -> 175.824 | G20: =SUM(G15:G19) -> 84.147 | H20: =SUM(H15:H19) -> 42.785 | I20: =SUM(I15:I19) -> 10.188 | K20: =(D20-E20)/E20 -> 2.4163162 | L20: =(E20-F20)/F20 -> 5.7658056 | M20: =(F20-G20)/G20 -> 1.0894863 | N20: =(G20-H20)/H20 -> 0.96674068 | O20: =(H20-I20)/I20 -> 3.1995485 | P20: -
B22: Categories | D22: Description | I22: Graphs
B23: Spodumene | D23: Spodumene is one of the sources of lithium. Spodumene is first mined and crushed into powder, then is heated to high temperatures in a kiln, then is mixed with chemicals to form a lithium compound, which is then separated and purified into a concentrated lithium product.
B24: Tantalite | D24: Tantalite is the primary source of the chemical element tantalum, a corrosion (heat and acid) resistant metal. It's mainly used in alloys and glass.
B27: Industry | J27: Graphs (Industry Forecasts)
B28: Drivers | D28: Description
B29: Consumer Electronics | D29: According to the Grand View Research, the consumer electronics segment is the one with the highest CAGR (more than 17.2% from 2024 to 2030). It's composed of electronic devices such as mobile phones, laptops, cameras and speakers, which use lithiom-ion batteries.
B30: EVs | D30: The demand for electric vehicles is also a great driver for Pilbara Mineral's revenues, since they also use a great deal of lithium batteries.
B31: Lithium Prices | D31: Every company in this industry is affected by the prices of lithium since its volatility is one of the main drivers for their revenue, specially Pilbara Minerals since the almost deal solely with lithium. The prices have also decreased with an increase of supply these last few years which could turn into a rebound opportunity, since many professionals forecast prices increasing again.
B32: China | D32: The company's exposure to China's economic policies is significant and could impact commodity prices, capital flows and general confidence and sentiment. This happens because China is the biggest importer of lithium and is the responsible for a large part of total lithium processing. In recent times, China has also imposed restrictions to commodities coming from australia.
B33: Sales forecast
B34: Source | D34: Market Growth CAGR | G34: Period
B35: Acumen | D35: 0.234 | G35: 2022 - 2030
B36: Mordor Intelligence | D36: 0.1957 | G36: 2024 - 2029
B37: Grand View Research | D37: 0.128 | G37: 2024 - 2030
B38: Straits Research | D38: 0.221 | G38: 2023 - 2031
B39: AVERAGE | D39: =AVERAGE(D35:F38) -> 0.194675 | G39: 2022 - 2031
B40: Company's Strategy / Extra Notes
B41: Their strategy is 1) Delivering their performance operative commitments; 2) Achieve full potential of the Pilgangoora asset; 3) Extract greater value along the batteries materials chain and 4) Diversify revenue beyond the Pilgangoora asset. To do so they are implementing a number of iniciatives, namely: Downstream Lithium Chemical Facility In joint venture with POSCO, a 43 ktpa Lithium Hydroxide Chemical Facility was commissioned in Gwangyang, South Korea. This would diversify their assets beyond the Pilgangoora operation and diversifying beyond China by estabilishing a link with another country. The first of 2 trains is already open with a nameplate capacity of 21,5 ktpa of lithium hydroxide. There's also a joint feasibility study with Ganfeng, a chinese lithium company, for a 32 ktpa lithium conversion plant. The feasibility study is expected to be completed in March Quarter 2025 with an option to progress to a final investment decision and formation of a joint venture following that. This would fortify their links with China which is the main buyer of lithium, besides their collaboration with South Korea. Mid-stream Demonstration Plant The development of a Mid-stream Demonstration Plant on site at the Pilgangoora Operation was approved by our Board in August 2023. The facility is aimed at demonstrating the potential to enhance the battery materials supply chain by decarbonising spodumene processing, decreasing transport volumes and improving value-add processing at the mine site. Expansion The P680 and the P1000 projects aims to increase total spodumene concentrate production capacity at the Pilgangoora Operation to up to 1 Mtpa. Pilbara Minerals prefers to expand it's mining operation rather than expanding through M&A.

Sheet Peers
B1: Peer Logo | C1: Peer Name | D1: Description | G1: Next Earnings Date | H1: Lithium Revenues | I1: Currency | J1: End of Fiscal Year
B2: #VALUE! | C2: #VALUE! | D2: Albemarle Corporation is a global developer, manufacturer, and marketer of advanced engineering materials. The company produces a variety of specialty chemicals, primarily focusing on lithium and advanced materials as well as bromine and refining catalyst segments. Its lithium and advanced materials segment consist of two product categories: battery-grade lithium compounds and other specialty chemical products. These are used in a range of applications such as fire safety and soundproofing, energy storage, automotive applications, lubricants, pharmaceuticals, crop protection, and customized chemical services. The company has partnerships and joint ventures in various parts of the world and as of December 31, 2016, had 31 office and production sites globally. | G2: Q1 (1st May 2024) | H2: 0.89 | I2: {=_FV(C2,"Moeda")} -> USD | J2: 31st December 2023
B3: #VALUE! | C3: #VALUE! | D3: Sociedad Química y Minera de Chile, or SQM, is a producer and distributor of potassium nitrate and iodine. The company produces plant nutrients and industrial chemicals derived from solar evaporation ponds in the Atacama Desert. Its segments include plant nutrients (such as potassium nitrate), iodine derivatives, lithium, and industrial chemicals. The company's products are used in fertilizers to improve agricultural yield, industrial applications such as glass manufacturing and industrial nitrates, and they produce and sell iodine and its derivatives which have applications in x-ray contrast media and other uses. Lithium and its derivatives, including lithium carbonate, are used in batteries, greases, and air treatment systems and are sold globally. | G3: FY23 (25th April 2024) | H3: 0.72 | I3: {=_FV(C3,"Moeda")} -> USD | J3: 31st December 2023
B4: #VALUE! | C4: #VALUE! | D4: Mineral Resources is an Australian-based mining services company operating through six segments: Mining Services, Iron Ore, Lithium, Energy, Other Commodities, and Central. Their mining services division provides end-to-end solutions, including their subsidiary Crushing Mining Services (CSI) that offers crushing, screening, and processing solutions for mining operations. The company has three iron ore hubs in Western Australia and lithium operations in the Pilbara and Goldfields regions. The Mt Marion lithium project is located 40 kilometers southwest of Kalgoorlie, and the Wodgina lithium project is 120 kilometers south of Port Hedland, in the Pilbara region near the iron ore hubs. It includes two wells in the Perth Basin. | G4: Q3 (26th April 2024) | H4: 0.3958 | I4: {=_FV(C4,"Moeda")} -> AUD | J4: 30th June 2023
B5: #VALUE! | C5: #VALUE! | D5: Arcadium Lithium PLC is an international lithium chemicals producer with a diversified product range. They produce lithium hydroxide, carbonate, spodumene, and other specialties. The company offers various lithium products such as specialty lithium, hydroxide, carbonate, battery-grade lithium hydroxide, and other lithium-ion battery grade carbonate, among others. They focus on direct lithium extraction from hard rock mining, chemical processing, and conventional brine extraction, which is said to be more efficient and less environmentally impactful than traditional methods. The company's operations span across different geographies, including the South American Lithium Triangle, Western Australia, and Canada. | G5: Q1 (2nd May 2024) | H5: =511/883 -> 0.57870895 | I5: {=_FV(C5,"Moeda")} -> AUD | J5: 31st December 2023
D6: {=_FV(C6,"Descrição")} -> #VALUE! | G6: {=_FV(C6,"Moeda")} -> #VALUE!
B8: {=_FV(OP!E2,"Currency")&" MILLIONS"} -> AUD MILLIONS | C8: =OP!E2 -> #VALUE! | D8: =C2 -> #VALUE! | E8: =C3 -> #VALUE! | F8: =C4 -> #VALUE! | G8: =C5 -> #VALUE! | H8: AVERAGE | I8: Deviation from Average
B9: Company Info | H9: =IFERROR(AVERAGE(C9:F9),"") | K9: TRAFFIC
B10: Market Cap | C10: {=_FV(C8,"Market cap",TRUE)/1000000} -> 8913.995 | D10: {=(_FV(D8,"Capitalização de mercado",TRUE)*_FV($D$55,"Preço"))/1000000} -> 18547.685 | E10: {=(_FV(E8,"Capitalização de mercado",TRUE)*_FV($D$55,"Preço"))/1000000} -> 15963.254 | F10: {=_FV(F8,"Capitalização de mercado",TRUE)/1000000} -> 7560.071 | G10: {=_FV(G8,"Capitalização de mercado",TRUE)/1000000} -> 5764.135 | H10: =IFERROR(AVERAGE(C10:G10),"") -> 11349.828 | I10: =SQRT((C10-H10)^2) -> 2435.8329 | L10: Best Value
B11: Net Sales (current) | C11: =C61 -> 4064 | D11: =D61 -> 14490 | E11: =E60 -> 15450 | F11: =F61 -> 4779.1 | G11: =G61 -> 1795.8 | H11: =IFERROR(AVERAGE(C11:G11),"") -> 8115.78 | I11: =SQRT((C11-H11)^2) -> 4051.78
B12: Profitability | H12: =IFERROR(AVERAGE(C12:F12),"") | L12: Important Value
B13: Sales Growth (ttm) | C13: =C61/C60-1 -> 2.4162744 | D13: =D61/D60-1 -> 0.37228904 | E13: =E60/E61-1 -> 0.37321127 | F13: =F61/F60-1 -> 0.39821533 | G13: =G61/G60-1 -> 0.74858812 | H13: =IFERROR(AVERAGE(C13:G13),"") -> 0.86171563 | I13: =SQRT((C13-H13)^2) -> 1.5545587
B14: Sales Growth (36m) | C14: =C61/C59-1 -> 47.323424 | D14: =D61/D59-1 -> 2.1860158 | E14: =E61/E59-1 -> 3.2601287 | F14: =F61/F59-1 -> 1.2493058 | G14: =G61/G59-1 -> 19.736721 | H14: =IFERROR(AVERAGE(C14:G14),"") -> 14.751119 | I14: =SQRT((C14-H14)^2) -> 32.572305 | L14: Worst Value
B15: Operating Margin | C15: =C64/C61 -> 0.79032972 | D15: =D64/D61 -> 0.026501035 | E15: =E64/E61 -> 0.38094392 | F15: =F64/F61 -> 0.10809567 | G15: =G64/G61 -> 0.64717675 | H15: =IFERROR(AVERAGE(C15:G15),"") -> 0.39060942 | I15: =SQRT((C15-H15)^2) -> 0.39972031
B16: EBITDA Margin | C16: =C63/C61 -> 0.76247539 | D16: =D63/D61 -> 0.091649413 | E16: =E63/E61 -> 0.4226291 | F16: =F63/F61 -> 0.3673495 | G16: =G63/G61 -> 0.75398151 | H16: =IFERROR(AVERAGE(C16:G16),"") -> 0.47961698 | I16: =SQRT((C16-H16)^2) -> 0.28285841
B17: Net Income Margin | C17: =C67/C61 -> 0.58836122 | D17: =D67/D61 -> 0.16363009 | E17: =E67/E60 -> 0.19624595 | F17: =F67/F61 -> 0.050909167 | G17: =G67/G61 -> 0.36574229 | H17: =IFERROR(AVERAGE(C17:G17),"") -> 0.27297774 | I17: =SQRT((C17-H17)^2) -> 0.31538348
B18: Return on Equity (RoE) | C18: =C67/C80 -> 0.70533923 | D18: =D67/D80 -> 0.17155054 | E18: =E67/E80 -> 0.37335304 | F18: =F67/F80 -> 0.070012374 | G18: =G67/G80 -> 0.12865062 | H18: =IFERROR(AVERAGE(C18:G18),"") -> 0.28978116 | I18: =SQRT((C18-H18)^2) -> 0.41555807
B19: Return on Invested Capital (ROIC) | C19: =(C67+C66)/(C79+C80) -> 0.36527706 | D19: =(D67+D66)/(D79+D80) -> 0.086409228 | E19: =(E67+E66)/(E79+E80) -> 0.1254417 | F19: =(F67+F66)/(F79+F80) -> 0.018959041 | G19: =(G67+G66)/(G79+G80) -> 0.036236286 | H19: =IFERROR(AVERAGE(C19:G19),"") -> 0.12646466 | I19: =SQRT((C19-H19)^2) -> 0.2388124
B20: Solvency | H20: =IFERROR(AVERAGE(C20:F20),"")
B21: Debt/Assets | C21: =C79/C75 -> 0.090790182 | D21: =D79/D75 -> 0.2280741 | E21: =E79/E75 -> 0.38367561 | F21: =F79/F75 -> 0.38523204 | G21: =G79/G75 -> 0.062773107 | H21: =IFERROR(AVERAGE(C21:G21),"") -> 0.23010901 | I21: =SQRT((C21-H21)^2) -> 0.13931882
B22: Net Debt/EBITDA | C22: =(C79-C70)/C63 -> -0.92509762 | D22: =(D79-D70)/D63 -> 3.623494 | E22: =(E79-E70)/E63 -> 1.177918 | F22: =(F79-F70)/F63 -> 1.0566758 | G22: =(G79-G70)/G63 -> -0.54726736 | H22: =IFERROR(AVERAGE(C22:G22),"") -> 0.87714455 | I22: =SQRT((C22-H22)^2) -> 1.8022422
B23: Debt/Assets (Leases Free Debt) | C23: =(C79-C78)/C75 -> 0.052415942 | D23: =(D79-D78)/D75 -> 0.2280741 | E23: =(E79-E78)/E75 -> 0.38367561 | F23: =(F79-F78)/F75 -> 0.38523204 | G23: =(G79-G78)/G75 -> 0.062773107 | H23: =IFERROR(AVERAGE(C23:G23),"") -> 0.22243416 | I23: =SQRT((C23-H23)^2) -> 0.17001822
B24: Net Debt/EBIT (Leases Free Debt) | C24: =((C79-C78)-C70)/C63 -> -0.98947946 | D24: =((D79-D78)-D70)/D63 -> 3.623494 | E24: =((E79-E78)-E70)/E63 -> 1.177918 | F24: =((F79-F78)-F70)/F63 -> 1.0566758 | G24: =((G79-G78)-G70)/G63 -> -0.54726736 | H24: =IFERROR(AVERAGE(C24:G24),"") -> 0.86426818 | I24: =SQRT((C24-H24)^2) -> 1.8537476
B25: Leasing Debt/Total Debt | C25: =C78/C79 -> 0.42266949 | D25: =D78/D79 -> 0 | E25: =E78/E79 -> 0 | F25: =F78/F79 -> 0 | G25: =G78/G79 -> 0 | H25: =IFERROR(AVERAGE(C25:G25),"") -> 0.084533898 | I25: =SQRT((C25-H25)^2) -> 0.33813559
B26: Interest Coverage Ratio | C26: =-C63/C65 -> -69.013363 | D26: =-D63/D65 -> 7.5885714 | E26: =-E63/E65 -> 63.4 | F26: =-F63/F65 -> -44.785714 | G26: =-G63/G65 -> -47.013889 | H26: =IFERROR(AVERAGE(C26:G26),"") -> -17.964879 | I26: =SQRT((C26-H26)^2) -> 51.048484
B27: Liquidity
B28: Current Ratio | C28: =C73/C77 -> 2.7570512 | D28: =D73/D77 -> 1.4653787 | E28: =E73/E77 -> 2.495365 | F28: =F73/F77 -> 2.7698501 | G28: =G73/G77 -> 2.5159988 | H28: =IFERROR(AVERAGE(C28:G28),"") -> 2.4007288 | I28: =SQRT((C28-H28)^2) -> 0.35632245
B29: Quick Ratio | C29: =(C70+C71)/C77 -> 2.6433042 | D29: =(D70+D71)/D77 -> 0.59066565 | E29: =(E70+E71)/E77 -> 0.6216686 | F29: =(F70+F71)/F77 -> 1.6237245 | G29: =(G70+G71)/G77 -> 2.0626495 | H29: =IFERROR(AVERAGE(C29:G29),"") -> 1.5084025 | I29: =SQRT((C29-H29)^2) -> 1.1349017
B30: Activity | H30: =IFERROR(AVERAGE(C30:F30),"")
B31: Inventory Turnover | C31: =C62/C72 -> 7.9773895 | D31: =D62/D72 -> 3.9971645 | E31: =E62/E72 -> 2.5395242 | F31: =F62/F72 -> 2.5966359 | G31: =G62/G72 -> 1.1128097 | H31: =IFERROR(AVERAGE(C31:G31),"") -> 3.6447047 | I31: =SQRT((C31-H31)^2) -> 4.3326848
B32: Acc. Receivable Turnover | C32: =C61/C71 -> 49.500609 | D32: =D61/D71 -> 8.1358787 | E32: =E61/E71 -> 9.7664931 | F32: =F61/F71 -> 7.2652782 | G32: =G61/G71 -> 12.199728 | H32: =IFERROR(AVERAGE(C32:G32),"") -> 17.373597 | I32: =SQRT((C32-H32)^2) -> 32.127012
A33: Price/Sales | B33: Payables Turnover | C33: =C62/C76 -> 0.81379744 | D33: =D62/D76 -> 4.1379648 | E33: =E62/E76 -> 10.197227 | F33: =F62/F76 -> 1.8281667 | G33: =G62/G76 -> 1.1035024 | H33: =IFERROR(AVERAGE(C33:G33),"") -> 3.6161316 | I33: =SQRT((C33-H33)^2) -> 2.8023341
B34: Fixed Asset Turnover | C34: =C61/C74 -> 2.9353557 | D34: =D61/D75 -> 0.54008722 | E34: =E60/E73 -> 1.7935918 | F34: =F61/F74 -> 1.0558514 | G34: =G61/G74 -> 0.35094782 | H34: =IFERROR(AVERAGE(C34:G34),"") -> 1.3351668 | I34: =SQRT((C34-H34)^2) -> 1.6001889
B35: Total Asset Turnover | C35: =C61/C75 -> 0.78171886 | D35: =D61/D75 -> 0.54008722 | E35: =E61/E75 -> 0.65454651 | F35: =F61/F75 -> 0.56926577 | G35: =G61/G75 -> 0.22944829 | H35: =IFERROR(AVERAGE(C35:G35),"") -> 0.55501333 | I35: =SQRT((C35-H35)^2) -> 0.22670553
B36: Valuation | H36: =IFERROR(AVERAGE(C36:F36),"")
B37: Price/Earnings | C37: =C10/C67 -> 3.7279892 | D37: =D10/D67 -> 7.8227266 | E37: =E10/E67 -> 5.2649254 | F37: =F10/F67 -> 31.073042 | G37: =G10/G67 -> 8.7760886 | H37: =IFERROR(AVERAGE(C37:G37),"") -> 11.332954 | I37: =SQRT((C37-H37)^2) -> 7.6049651
B38: Price/Sales | C38: =C10/C61 -> 2.1934043 | D38: =D10/D61 -> 1.2800335 | E38: =E10/E61 -> 1.4188298 | F38: =F10/F61 -> 1.5819027 | G38: =G10/G61 -> 3.2097867 | H38: =IFERROR(AVERAGE(C38:G38),"") -> 1.9367914 | I38: =SQRT((C38-H38)^2) -> 0.2566129
B39: Price/Book | C39: =C10/C80 -> 2.6294971 | D39: =D10/D80 -> 1.341993 | E39: =E10/E80 -> 1.9656759 | F39: =F10/F80 -> 2.1754974 | G39: =G10/G80 -> 1.1290492 | H39: =IFERROR(AVERAGE(C39:G39),"") -> 1.8483425 | I39: =SQRT((C39-H39)^2) -> 0.78115455
B40: EV/Sales | C40: =(C79+C10-C70)/C61 -> 1.4880401 | D40: =(D79+D10-D70)/D61 -> 1.6121246 | E40: =(E79+E10-E70)/E61 -> 1.9166522 | F40: =(F79+F10-F70)/F61 -> 1.970072 | G40: =(G79+G10-G70)/G61 -> 2.7971573 | H40: =IFERROR(AVERAGE(C40:G40),"") -> 1.9568092 | I40: =SQRT((C40-H40)^2) -> 0.46876911
B41: EV/EBITDA | C41: =(C79+C10-C70)/C63 -> 1.951591 | D41: =(D79+D10-D70)/D63 -> 17.590124 | E41: =(E79+E10-E70)/E63 -> 4.5350692 | F41: =(F79+F10-F70)/F63 -> 5.3629363 | G41: =(G79+G10-G70)/G63 -> 3.7098486 | H41: =IFERROR(AVERAGE(C41:G41),"") -> 6.6299138 | I41: =SQRT((C41-H41)^2) -> 4.6783228
...

Sheet Peers (TTM)
B1: Peer Logo | C1: Peer Name | D1: Description | G1: Next Earnings Date | H1: Lithium Revenues | I1: Currency | J1: End of Fiscal Year | AC1: PLS.AX | Statement App | Income Statement
B2: #VALUE! | C2: #VALUE! | D2: Albemarle Corporation is a global developer, manufacturer, and marketer of advanced engineering materials. The company produces a variety of specialty chemicals, primarily focusing on lithium and advanced materials as well as bromine and refining catalyst segments. Its lithium and advanced materials segment consist of two product categories: battery-grade lithium compounds and other specialty chemical products. These are used in a range of applications such as fire safety and soundproofing, energy storage, automotive applications, lubricants, pharmaceuticals, crop protection, and customized chemical services. The company has partnerships and joint ventures in various parts of the world and as of December 31, 2016, had 31 office and production sites globally. | G2: Q1 (1st May 2024) | H2: 0.89 | I2: {=_FV(C2,"Moeda")} -> USD | J2: 31st December 2023 | AC2: Mean | Annual & Interim
B3: #VALUE! | C3: #VALUE! | D3: Sociedad Química y Minera de Chile, or SQM, is a producer and distributor of potassium nitrate and iodine. The company produces plant nutrients and industrial chemicals derived from solar evaporation ponds in the Atacama Desert. Its segments include plant nutrients (such as potassium nitrate), iodine derivatives, lithium, and industrial chemicals. The company's products are used in fertilizers to improve agricultural yield, industrial applications such as glass manufacturing and industrial nitrates, and they produce and sell iodine and its derivatives which have applications in x-ray contrast media and other uses. Lithium and its derivatives, including lithium carbonate, are used in batteries, greases, and air treatment systems and are sold globally. | G3: FY23 (25th April 2024) | H3: 0.72 | I3: {=_FV(C3,"Moeda")} -> USD | J3: 31st December 2023 | AC3: Consolidated | AUD
B4: #VALUE! | C4: #VALUE! | D4: Mineral Resources is an Australian-based mining services company operating through six segments: Mining Services, Iron Ore, Lithium, Energy, Other Commodities, and Central. Their mining services division provides end-to-end solutions, including their subsidiary Crushing Mining Services (CSI) that offers crushing, screening, and processing solutions for mining operations. The company has three iron ore hubs in Western Australia and lithium operations in the Pilbara and Goldfields regions. The Mt Marion lithium project is located 40 kilometers southwest of Kalgoorlie, and the Wodgina lithium project is 120 kilometers south of Port Hedland, in the Pilbara region near the iron ore hubs. It includes two wells in the Perth Basin. | G4: Q3 (26th April 2024) | H4: 0.3958 | I4: {=_FV(C4,"Moeda")} -> AUD | J4: 30th June 2023
B5: #VALUE! | C5: #VALUE! | D5: Arcadium Lithium PLC is an international lithium chemicals producer with a diversified product range. They produce lithium hydroxide, carbonate, spodumene, and other specialties. The company offers various lithium products such as specialty lithium, hydroxide, carbonate, battery-grade lithium hydroxide, and other lithium-ion battery grade carbonate, among others. They focus on direct lithium extraction from hard rock mining, chemical processing, and conventional brine extraction, which is said to be more efficient and less environmentally impactful than traditional methods. The company's operations span across different geographies, including the South American Lithium Triangle, Western Australia, and Canada. | G5: Q1 (2nd May 2024) | H5: =511/883 -> 0.57870895 | I5: {=_FV(C5,"Moeda")} -> AUD | J5: 31st December 2023 | AC5: Next Earning Report
D6: {=_FV(C6,"Descrição")} -> #VALUE! | G6: {=_FV(C6,"Moeda")} -> #VALUE!
AE7: HISTORICAL (ACTUALS)
B8: {=_FV(OP!E2,"Currency")&" MILLIONS"} -> AUD MILLIONS | C8: =OP!E2 -> #VALUE! | D8: =C2 -> #VALUE! | E8: =C3 -> #VALUE! | F8: =C4 -> #VALUE! | G8: =C5 -> #VALUE! | H8: AVERAGE | I8: Deviation from Average | AE8: FY 2024
B9: Company Info | H9: =IFERROR(AVERAGE(C9:F9),"") | K9: TRAFFIC | AD9: SAN2 Jun-23 | AE9: SAN1 Dec-23
B10: Market Cap | C10: {=_FV(C8,"Market cap",TRUE)/1000000} -> 8913.995 | D10: {=(_FV(D8,"Capitalização de mercado",TRUE)*_FV($D$55,"Preço"))/1000000} -> 18547.685 | E10: {=(_FV(E8,"Capitalização de mercado",TRUE)*_FV($D$55,"Preço"))/1000000} -> 15963.254 | F10: {=_FV(F8,"Capitalização de mercado",TRUE)/1000000} -> 7560.071 | G10: {=_FV(G8,"Capitalização de mercado",TRUE)/1000000} -> 5764.135 | H10: =IFERROR(AVERAGE(C10:G10),"") -> 11349.828 | I10: =SQRT((C10-H10)^2) -> 2435.8329 | L10: Best Value | AC10: REVENUE | AD10: 1883.892 | AE10: 757.231
B11: Net Sales (current) | C11: =C61 -> 2641.123 | D11: =D61 -> 14490 | E11: =E60 -> 15450 | F11: =F61 -> 4943.7 | G11: =G61 -> 1795.8 | H11: =IFERROR(AVERAGE(C11:G11),"") -> 7864.1246 | I11: =SQRT((C11-H11)^2) -> 5223.0016 | AC11: YoY Growth % | AD11: 1.0981884 | AE11: -0.65266656
B12: Profitability | H12: =IFERROR(AVERAGE(C12:F12),"") | L12: Important Value | AC12: Actual/Predicted Surprise % | AD12: -0.03271 | AE12: -0.00717
B13: Sales Growth (ttm) | C13: =C61/C60-1 -> -0.1419334 | D13: =D61/D60-1 -> 0.37228904 | E13: =E60/E61-1 -> 0.37321127 | F13: =F61/F60-1 -> 0.11985231 | G13: =G61/G60-1 -> 0.74858812 | H13: =IFERROR(AVERAGE(C13:G13),"") -> 0.29440147 | I13: =SQRT((C13-H13)^2) -> 0.43633487 | AC13: Mean at time of Report | AD13: 1947.6 | AE13: 762.69833
B14: Sales Growth (36m) | C14: =C61/C59-1 -> 5.6510944 | D14: =D61/D59-1 -> 2.1860158 | E14: =E61/E59-1 -> 3.2601287 | F14: =F61/F59-1 -> 0.85254441 | G14: =G61/G59-1 -> 19.736721 | H14: =IFERROR(AVERAGE(C14:G14),"") -> 6.3373008 | I14: =SQRT((C14-H14)^2) -> 0.68620635 | L14: Worst Value | AC14: COST OF GOODS SOLD | AD14: 396.516 | AE14: 340.953
B15: Operating Margin | C15: =C64/C61 -> 0.68330782 | D15: =D64/D61 -> 0.026501035 | E15: =E64/E61 -> 0.38094392 | F15: =F64/F61 -> 0.10117928 | G15: =G64/G61 -> 0.64717675 | H15: =IFERROR(AVERAGE(C15:G15),"") -> 0.36782176 | I15: =SQRT((C15-H15)^2) -> 0.31548606 | AC15: YoY Growth % | AD15: 0.60526944 | AE15: -0.10440504
B16: EBITDA Margin | C16: =C63/C61 -> 0.73006823 | D16: =D63/D61 -> 0.091649413 | E16: =E63/E61 -> 0.4226291 | F16: =F63/F61 -> 0.27730243 | G16: =G63/G61 -> 0.75398151 | H16: =IFERROR(AVERAGE(C16:G16),"") -> 0.45512614 | I16: =SQRT((C16-H16)^2) -> 0.2749421 | AC16: Actual/Predicted Surprise % | AD16: 0.01932 | AE16: -0.00014
B17: Net Income Margin | C17: =C67/C61 -> 0.51849157 | D17: =D67/D61 -> 0.16363009 | E17: =E67/E60 -> 0.19624595 | F17: =F67/F61 -> 0.079292837 | G17: =G67/G61 -> 0.36574229 | H17: =IFERROR(AVERAGE(C17:G17),"") -> 0.26468055 | I17: =SQRT((C17-H17)^2) -> 0.25381102 | AC17: Mean at time of Report | AD17: 389 | AE17: 341
B18: Return on Equity (RoE) | C18: =C67/C80 -> 0.42724323 | D18: =D67/D80 -> 0.17155054 | E18: =E67/E80 -> 0.37335304 | F18: =F67/F80 -> 0.099115044 | G18: =G67/G80 -> 0.12865062 | H18: =IFERROR(AVERAGE(C18:G18),"") -> 0.23998249 | I18: =SQRT((C18-H18)^2) -> 0.18726074 | AC18: Guidance | AD18: - | AE18: -
B19: Return on Invested Capital (ROIC) | C19: =(C67+C66)/(C79+C80) -> 0.21161573 | D19: =(D67+D66)/(D79+D80) -> 0.086409228 | E19: =(E67+E66)/(E79+E80) -> 0.1254417 | F19: =(F67+F66)/(F79+F80) -> 0.032436691 | G19: =(G67+G66)/(G79+G80) -> 0.036236286 | H19: =IFERROR(AVERAGE(C19:G19),"") -> 0.098427927 | I19: =SQRT((C19-H19)^2) -> 0.11318781 | AC19: GROSS INCOME | AD19: 1488.331 | AE19: -
B20: Solvency | H20: =IFERROR(AVERAGE(C20:F20),"") | AC20: YoY Growth % | AD20: - | AE20: -
B21: Debt/Assets | C21: =C79/C75 -> 0.13135333 | D21: =D79/D75 -> 0.2280741 | E21: =E79/E75 -> 0.38367561 | F21: =F79/F75 -> 0.4500639 | G21: =G79/G75 -> 0.062773107 | H21: =IFERROR(AVERAGE(C21:G21),"") -> 0.25118801 | I21: =SQRT((C21-H21)^2) -> 0.11983468 | AC21: Margin % | AD21: 79.00299 | AE21: -
B22: Net Debt/EBITDA | C22: =(C79-C70)/C63 -> -0.81506068 | D22: =(D79-D70)/D63 -> 3.623494 | E22: =(E79-E70)/E63 -> 1.177918 | F22: =(F79-F70)/F63 -> 2.5873514 | G22: =(G79-G70)/G63 -> -0.54726736 | H22: =IFERROR(AVERAGE(C22:G22),"") -> 1.2052871 | I22: =SQRT((C22-H22)^2) -> 2.0203477 | AC22: Actual/Predicted Surprise % | AD22: - | AE22: -
B23: Debt/Assets (Leases Free Debt) | C23: =(C79-C78)/C75 -> 0.13135333 | D23: =(D79-D78)/D75 -> 0.2280741 | E23: =(E79-E78)/E75 -> 0.38367561 | F23: =(F79-F78)/F75 -> 0.4500639 | G23: =(G79-G78)/G75 -> 0.062773107 | H23: =IFERROR(AVERAGE(C23:G23),"") -> 0.25118801 | I23: =SQRT((C23-H23)^2) -> 0.11983468 | AC23: Mean at time of Report | AD23: - | AE23: -
B24: Net Debt/EBIT (Leases Free Debt) | C24: =((C79-C78)-C70)/C63 -> -0.81506068 | D24: =((D79-D78)-D70)/D63 -> 3.623494 | E24: =((E79-E78)-E70)/E63 -> 1.177918 | F24: =((F79-F78)-F70)/F63 -> 2.5873514 | G24: =((G79-G78)-G70)/G63 -> -0.54726736 | H24: =IFERROR(AVERAGE(C24:G24),"") -> 1.2052871 | I24: =SQRT((C24-H24)^2) -> 2.0203477 | AC24: GROSS PROFIT MARGIN | AD24: - | AE24: -
B25: Leasing Debt/Total Debt | C25: =C78/C79 -> 0 | D25: =D78/D79 -> 0 | E25: =E78/E79 -> 0 | F25: =F78/F79 -> 0 | G25: =G78/G79 -> 0 | H25: =IFERROR(AVERAGE(C25:G25),"") -> 0 | I25: =SQRT((C25-H25)^2) -> 0 | AC25: YoY Growth | AD25: - | AE25: -
B26: Interest Coverage Ratio | C26: =-C63/C65 -> -21.568233 | D26: =-D63/D65 -> 7.5885714 | E26: =-E63/E65 -> 63.4 | F26: =-F63/F65 -> -27.472946 | G26: =-G63/G65 -> -47.013889 | H26: =IFERROR(AVERAGE(C26:G26),"") -> -5.0132992 | I26: =SQRT((C26-H26)^2) -> 16.554933 | AC26: Actual/Predicted Surprise % | AD26: - | AE26: -
B27: Liquidity | AC27: Mean at time of Report | AD27: - | AE27: -
B28: Current Ratio | C28: =C73/C77 -> 4.355966 | D28: =D73/D77 -> 1.4653787 | E28: =E73/E77 -> 2.495365 | F28: =F73/F77 -> 1.5483693 | G28: =G73/G77 -> 2.5159988 | H28: =IFERROR(AVERAGE(C28:G28),"") -> 2.4762156 | I28: =SQRT((C28-H28)^2) -> 1.8797504
B29: Quick Ratio | C29: =(C70+C71)/C77 -> 3.9619772 | D29: =(D70+D71)/D77 -> 0.59066565 | E29: =(E70+E71)/E77 -> 0.6216686 | F29: =(F70+F71)/F77 -> 1.1514649 | G29: =(G70+G71)/G77 -> 2.0626495 | H29: =IFERROR(AVERAGE(C29:G29),"") -> 1.6776852 | I29: =SQRT((C29-H29)^2) -> 2.284292 | AC29: R&D EXPENSE | AD29: - | AE29: -
B30: Activity | H30: =IFERROR(AVERAGE(C30:F30),"") | AC30: YoY Growth % | AD30: - | AE30: -
B31: Inventory Turnover | C31: =C62/C72 -> 6.0349345 | D31: =D62/D72 -> 3.9971645 | E31: =E62/E72 -> 2.5395242 | F31: =F62/F72 -> 2.9389831 | G31: =G62/G72 -> 1.1128097 | H31: =IFERROR(AVERAGE(C31:G31),"") -> 3.3246832 | I31: =SQRT((C31-H31)^2) -> 2.7102513 | AC31: Actual/Predicted Surprise % | AD31: - | AE31: -
B32: Acc. Receivable Turnover | C32: =C61/C71 -> 67.721103 | D32: =D61/D71 -> 8.1358787 | E32: =E61/E71 -> 9.7664931 | F32: =F61/F71 -> 7.0624286 | G32: =G61/G71 -> 12.199728 | H32: =IFERROR(AVERAGE(C32:G32),"") -> 20.977126 | I32: =SQRT((C32-H32)^2) -> 46.743976 | AC32: Mean at time of Report | AD32: - | AE32: -
A33: Price/Sales | B33: Payables Turnover | C33: =C62/C76 -> 2.7162762 | D33: =D62/D76 -> 4.1379648 | E33: =E62/E76 -> 10.197227 | F33: =F62/F76 -> 1.7574324 | G33: =G62/G76 -> 1.1035024 | H33: =IFERROR(AVERAGE(C33:G33),"") -> 3.9824805 | I33: =SQRT((C33-H33)^2) -> 1.2662042 | AC33: GENERAL & ADMIN EXPENSE | AD33: - | AE33: -
B34: Fixed Asset Turnover | C34: =C61/C74 -> 1.5415415 | D34: =D61/D75 -> 0.54008722 | E34: =E60/E73 -> 1.7935918 | F34: =F61/F74 -> 0.68930563 | G34: =G61/G74 -> 0.35094782 | H34: =IFERROR(AVERAGE(C34:G34),"") -> 0.98309479 | I34: =SQRT((C34-H34)^2) -> 0.55844668 | AC34: YoY Growth % | AD34: - | AE34: -
B35: Total Asset Turnover | C35: =C61/C75 -> 0.60062379 | D35: =D61/D75 -> 0.54008722 | E35: =E61/E75 -> 0.65454651 | F35: =F61/F75 -> 0.45131459 | G35: =G61/G75 -> 0.22944829 | H35: =IFERROR(AVERAGE(C35:G35),"") -> 0.49520408 | I35: =SQRT((C35-H35)^2) -> 0.10541971 | AC35: Actual/Predicted Surprise % | AD35: - | AE35: -
B36: Valuation | H36: =IFERROR(AVERAGE(C36:F36),"") | AC36: Mean at time of Report | AD36: - | AE36: -
B37: Price/Earnings | C37: =C10/C67 -> 6.5094165 | D37: =D10/D67 -> 7.8227266 | E37: =E10/E67 -> 5.2649254 | F37: =F10/F67 -> 19.285895 | G37: =G10/G67 -> 8.7760886 | H37: =IFERROR(AVERAGE(C37:G37),"") -> 9.5318105 | I37: =SQRT((C37-H37)^2) -> 3.022394 | AC37: SG&A EXPENSE | AD37: - | AE37: -
B38: Price/Sales | C38: =C10/C61 -> 3.3750776 | D38: =D10/D61 -> 1.2800335 | E38: =E10/E61 -> 1.4188298 | F38: =F10/F61 -> 1.5292334 | G38: =G10/G61 -> 3.2097867 | H38: =IFERROR(AVERAGE(C38:G38),"") -> 2.1625922 | I38: =SQRT((C38-H38)^2) -> 1.2124854 | AC38: YoY Growth % | AD38: - | AE38: -
B39: Price/Book | C39: =C10/C80 -> 2.7811041 | D39: =D10/D80 -> 1.341993 | E39: =E10/E80 -> 1.9656759 | F39: =F10/F80 -> 1.9115224 | G39: =G10/G80 -> 1.1290492 | H39: =IFERROR(AVERAGE(C39:G39),"") -> 1.8258689 | I39: =SQRT((C39-H39)^2) -> 0.95523522 | AC39: Actual/Predicted Surprise % | AD39: - | AE39: -
B40: EV/Sales | C40: =(C79+C10-C70)/C61 -> 2.7800277 | D40: =(D79+D10-D70)/D61 -> 1.6121246 | E40: =(E79+E10-E70)/E61 -> 1.9166522 | F40: =(F79+F10-F70)/F61 -> 2.2467122 | G40: =(G79+G10-G70)/G61 -> 2.7971573 | H40: =IFERROR(AVERAGE(C40:G40),"") -> 2.2705348 | I40: =SQRT((C40-H40)^2) -> 0.50949289 | AC40: Mean at time of Report | AD40: - | AE40: -
...

Sheet Peers (NTM)
B1: Peer Logo | C1: Peer Name | D1: Description | G1: Next Earnings Date | H1: Lithium Revenues | I1: Currency | J1: End of Fiscal Year | AC1: PLS.AX | Statement App | Income Statement
B2: #VALUE! | C2: #VALUE! | D2: Albemarle Corporation is a global developer, manufacturer, and marketer of advanced engineering materials. The company produces a variety of specialty chemicals, primarily focusing on lithium and advanced materials as well as bromine and refining catalyst segments. Its lithium and advanced materials segment consist of two product categories: battery-grade lithium compounds and other specialty chemical products. These are used in a range of applications such as fire safety and soundproofing, energy storage, automotive applications, lubricants, pharmaceuticals, crop protection, and customized chemical services. The company has partnerships and joint ventures in various parts of the world and as of December 31, 2016, had 31 office and production sites globally. | G2: Q1 (1st May 2024) | H2: 0.89 | I2: {=_FV(C2,"Moeda")} -> USD | J2: 31st December 2023 | AC2: Mean | Annual & Interim
B3: #VALUE! | C3: #VALUE! | D3: Sociedad Química y Minera de Chile, or SQM, is a producer and distributor of potassium nitrate and iodine. The company produces plant nutrients and industrial chemicals derived from solar evaporation ponds in the Atacama Desert. Its segments include plant nutrients (such as potassium nitrate), iodine derivatives, lithium, and industrial chemicals. The company's products are used in fertilizers to improve agricultural yield, industrial applications such as glass manufacturing and industrial nitrates, and they produce and sell iodine and its derivatives which have applications in x-ray contrast media and other uses. Lithium and its derivatives, including lithium carbonate, are used in batteries, greases, and air treatment systems and are sold globally. | G3: FY23 (25th April 2024) | H3: 0.72 | I3: {=_FV(C3,"Moeda")} -> USD | J3: 31st December 2023 | AC3: Consolidated | AUD
B4: #VALUE! | C4: #VALUE! | D4: Mineral Resources is an Australian-based mining services company operating through six segments: Mining Services, Iron Ore, Lithium, Energy, Other Commodities, and Central. Their mining services division provides end-to-end solutions, including their subsidiary Crushing Mining Services (CSI) that offers crushing, screening, and processing solutions for mining operations. The company has three iron ore hubs in Western Australia and lithium operations in the Pilbara and Goldfields regions. The Mt Marion lithium project is located 40 kilometers southwest of Kalgoorlie, and the Wodgina lithium project is 120 kilometers south of Port Hedland, in the Pilbara region near the iron ore hubs. It includes two wells in the Perth Basin. | G4: Q3 (26th April 2024) | H4: 0.3958 | I4: {=_FV(C4,"Moeda")} -> AUD | J4: 30th June 2023
B5: #VALUE! | C5: #VALUE! | D5: Arcadium Lithium PLC is an international lithium chemicals producer with a diversified product range. They produce lithium hydroxide, carbonate, spodumene, and other specialties. The company offers various lithium products such as specialty lithium, hydroxide, carbonate, battery-grade lithium hydroxide, and other lithium-ion battery grade carbonate, among others. They focus on direct lithium extraction from hard rock mining, chemical processing, and conventional brine extraction, which is said to be more efficient and less environmentally impactful than traditional methods. The company's operations span across different geographies, including the South American Lithium Triangle, Western Australia, and Canada. | G5: Q1 (2nd May 2024) | H5: =511/883 -> 0.57870895 | I5: {=_FV(C5,"Moeda")} -> AUD | J5: 31st December 2023 | AC5: Next Earning Report
D6: {=_FV(C6,"Descrição")} -> #VALUE! | G6: {=_FV(C6,"Moeda")} -> #VALUE!
AE7: HISTORICAL (ACTUALS)
B8: {=_FV(OP!E2,"Currency")&" MILLIONS"} -> AUD MILLIONS | C8: =OP!E2 -> #VALUE! | D8: =C2 -> #VALUE! | E8: =C3 -> #VALUE! | F8: =C4 -> #VALUE! | G8: =C5 -> #VALUE! | H8: AVERAGE | I8: Deviation from Average | AE8: FY 2024
B9: Company Info | H9: =IFERROR(AVERAGE(C9:F9),"") | K9: TRAFFIC | AD9: SAN2 Jun-23 | AE9: SAN1 Dec-23
B10: Market Cap | C10: {=_FV(C8,"Market cap",TRUE)/1000000} -> 8913.995 | D10: {=(_FV(D8,"Capitalização de mercado",TRUE)*_FV($D$54,"Preço"))/1000000} -> 18547.685 | E10: {=(_FV(E8,"Capitalização de mercado",TRUE)*_FV($D$54,"Preço"))/1000000} -> 15963.254 | F10: {=_FV(F8,"Capitalização de mercado",TRUE)/1000000} -> 7560.071 | G10: {=_FV(G8,"Capitalização de mercado",TRUE)/1000000} -> 5764.135 | H10: =IFERROR(AVERAGE(C10:G10),"") -> 11349.828 | I10: =SQRT((C10-H10)^2) -> 2435.8329 | L10: Best Value | AC10: REVENUE | AD10: 1883.892 | AE10: 757.231
B11: Net Sales (current) | C11: =C59 -> 1040.469 | D11: =D59 -> 8901.0109 | E11: =E58 -> 11251 | F11: =F59 -> 4903.149 | G11: =G59 -> 1918.1916 | H11: =IFERROR(AVERAGE(C11:G11),"") -> 5602.7641 | I11: =SQRT((C11-H11)^2) -> 4562.2951 | AC11: YoY Growth % | AD11: 1.0981884 | AE11: -0.65266656
B12: Profitability | H12: =IFERROR(AVERAGE(C12:F12),"") | L12: Important Value | AC12: Actual/Predicted Surprise % | AD12: -0.03271 | AE12: -0.00717
B13: Sales Growth (ntm) | C13: =C59/C58-1 -> -0.74397908 | D13: =D59/D58-1 -> -0.38571353 | E13: =E58/E59-1 -> 0.37705603 | F13: =F59/F58-1 -> 0.025956561 | G13: =G59/G58-1 -> 0.068154339 | H13: =IFERROR(AVERAGE(C13:G13),"") -> -0.13170514 | I13: =SQRT((C13-H13)^2) -> 0.61227395 | AC13: Mean at time of Report | AD13: 1947.6 | AE13: 762.69833
B14: Operating Margin | C14: =C62/C59 -> 0.43441948 | D14: =D62/D59 -> 0.079625113 | E14: =E62/E59 -> 0.51041008 | F14: =F62/F59 -> 0.13358762 | G14: =G62/G59 -> 0.2746656 | H14: =IFERROR(AVERAGE(C14:G14),"") -> 0.28654158 | I14: =SQRT((C14-H14)^2) -> 0.1478779 | L14: Worst Value | AC14: COST OF GOODS SOLD | AD14: 396.516 | AE14: 340.953
B15: EBITDA Margin | C15: =C61/C59 -> 0.31187859 | D15: =D61/D59 -> 0.207246 | E15: =E61/E59 -> 0.41090646 | F15: =F61/F59 -> 0.22254412 | G15: =G61/G59 -> 0.37284998 | H15: =IFERROR(AVERAGE(C15:G15),"") -> 0.30508503 | I15: =SQRT((C15-H15)^2) -> 0.0067935556 | AC15: YoY Growth % | AD15: 0.60526944 | AE15: -0.10440504
B16: Net Income Margin | C16: =C65/C59 -> 0.20855979 | D16: =D65/D59 -> 0.075845192 | E16: =E65/E58 -> 0.17355737 | F16: =F65/F59 -> 0.051347817 | G16: =G65/G59 -> 0.17652499 | H16: =IFERROR(AVERAGE(C16:G16),"") -> 0.13716703 | I16: =SQRT((C16-H16)^2) -> 0.071392762 | AC16: Actual/Predicted Surprise % | AD16: 0.01932 | AE16: -0.00014
B17: Return on Equity (RoE) | C17: =C65/C77 -> 0.07309294 | D17: =D65/D77 -> 0.040842501 | E17: =E65/E77 -> 0.21497431 | F17: =F65/F77 -> 0.059952191 | G17: =G65/G77 -> 0.033919562 | H17: =IFERROR(AVERAGE(C17:G17),"") -> 0.0845563 | I17: =SQRT((C17-H17)^2) -> 0.01146336 | AC17: Mean at time of Report | AD17: 389 | AE17: 341
B18: Return on Invested Capital (ROIC) | C18: =(C65+C64)/(C76+C77) -> -0.026621857 | D18: =(D65+D64)/(D76+D77) -> 0.020348551 | E18: =(E65+E64)/(E76+E77) -> 0.067194797 | F18: =(F65+F64)/(F76+F77) -> 0.016279893 | G18: =(G65+G64)/(G76+G77) -> 0.017106616 | H18: =IFERROR(AVERAGE(C18:G18),"") -> 0.0188616 | I18: =SQRT((C18-H18)^2) -> 0.045483457 | AC18: Guidance | AD18: - | AE18: -
B19: Solvency | H19: =IFERROR(AVERAGE(C19:F19),"") | AC19: GROSS INCOME | AD19: 1488.331 | AE19: -
B20: Debt/Assets | C20: =C76/C73 -> 0.091886923 | D20: =D76/D73 -> 0.23897892 | E20: =E76/E73 -> 0.27579915 | F20: =F76/F73 -> 0.45102134 | G20: =G76/G73 -> 0.044657996 | H20: =IFERROR(AVERAGE(C20:G20),"") -> 0.22046887 | I20: =SQRT((C20-H20)^2) -> 0.12858194 | AC20: YoY Growth % | AD20: - | AE20: -
B21: Net Debt/EBITDA | C21: =(C76-C68)/C61 -> -4.3803544 | D21: =(D76-D68)/D61 -> 2.887248 | E21: =(E76-E68)/E61 -> 0.034857924 | F21: =(F76-F68)/F61 -> 4.1898376 | G21: =(G76-G68)/G61 -> -0.72611131 | H21: =IFERROR(AVERAGE(C21:G21),"") -> 0.40109556 | I21: =SQRT((C21-H21)^2) -> 4.78145 | AC21: Margin % | AD21: 79.00299 | AE21: -
B22: Debt/Assets | C22: =(C76-#REF!)/C73 -> #REF! | D22: =(D76-#REF!)/D73 -> #REF! | E22: =(E76-#REF!)/E73 -> #REF! | F22: =(F76-#REF!)/F73 -> #REF! | G22: =(G76-#REF!)/G73 -> #REF! | H22: =IFERROR(AVERAGE(C22:G22),"") | I22: =SQRT((C22-H22)^2) -> #REF! | AC22: Actual/Predicted Surprise % | AD22: - | AE22: -
B23: Net Debt/EBIT (Leases Free Debt) | C23: =((C76-#REF!)-C68)/C61 -> #REF! | D23: =((D76-#REF!)-D68)/D61 -> #REF! | E23: =((E76-#REF!)-E68)/E61 -> #REF! | F23: =((F76-#REF!)-F68)/F61 -> #REF! | G23: =((G76-#REF!)-G68)/G61 -> #REF! | H23: =IFERROR(AVERAGE(C23:G23),"") | I23: =SQRT((C23-H23)^2) -> #REF! | AC23: Mean at time of Report | AD23: - | AE23: -
B24: Leasing Debt/Total Debt | C24: =#REF!/C76 -> #REF! | D24: =#REF!/D76 -> #REF! | E24: =#REF!/E76 -> #REF! | F24: =#REF!/F76 -> #REF! | G24: =#REF!/G76 -> #REF! | H24: =IFERROR(AVERAGE(C24:G24),"") | I24: =SQRT((C24-H24)^2) -> #REF! | AC24: GROSS PROFIT MARGIN | AD24: - | AE24: -
B25: Interest Coverage Ratio | C25: =-C61/C63 -> #DIV/0! | D25: =-D61/D63 -> 7.0758144 | E25: =-E61/E63 -> 26.379507 | F25: =-F61/F63 -> 3.3503353 | G25: =-G61/G63 -> 30.538401 | H25: =IFERROR(AVERAGE(C25:G25),"") | I25: =SQRT((C25-H25)^2) -> #DIV/0! | AC25: YoY Growth | AD25: - | AE25: -
B26: Liquidity | AC26: Actual/Predicted Surprise % | AD26: - | AE26: -
B27: Current Ratio | C27: =C71/C75 -> 3.7487031 | D27: =D71/D75 -> 0.48987931 | E27: =E71/E75 -> 2.2734514 | F27: =F71/F75 -> 1.1693881 | G27: =G71/G75 -> 3.2514713 | H27: =IFERROR(AVERAGE(C27:G27),"") -> 2.1865786 | I27: =SQRT((C27-H27)^2) -> 1.5621245 | AC27: Mean at time of Report | AD27: - | AE27: -
B28: Quick Ratio | C28: =(C68+C69)/C75 -> #VALUE! | D28: =(D68+D69)/D75 -> #VALUE! | E28: =(E68+E69)/E75 -> #VALUE! | F28: =(F68+F69)/F75 -> #VALUE! | G28: =(G68+G69)/G75 -> #VALUE! | H28: =IFERROR(AVERAGE(C28:G28),"") | I28: =SQRT((C28-H28)^2) -> #VALUE!
B29: Activity | H29: =IFERROR(AVERAGE(C29:F29),"") | AC29: R&D EXPENSE | AD29: - | AE29: -
B30: Inventory Turnover | C30: =C60/C70 -> 6.0183486 | D30: =D60/D70 -> 2.6281013 | E30: =E60/E70 -> 3.4551437 | F30: =F60/F70 -> 3.7592408 | G30: =G60/G70 -> 2.1756915 | H30: =IFERROR(AVERAGE(C30:G30),"") -> 3.6073052 | I30: =SQRT((C30-H30)^2) -> 2.4110434 | AC30: YoY Growth % | AD30: - | AE30: -
B31: Acc. Receivable Turnover | C31: =C59/C69 -> #VALUE! | D31: =D59/D69 -> #VALUE! | E31: =E59/E69 -> #VALUE! | F31: =F59/F69 -> #VALUE! | G31: =G59/G69 -> #VALUE! | H31: =IFERROR(AVERAGE(C31:G31),"") | I31: =SQRT((C31-H31)^2) -> #VALUE! | AC31: Actual/Predicted Surprise % | AD31: - | AE31: -
B32: Payables Turnover | C32: =C60/C74 -> #VALUE! | D32: =D60/D74 -> #VALUE! | E32: =E60/E74 -> #VALUE! | F32: =F60/F74 -> #VALUE! | G32: =G60/G74 -> #VALUE! | H32: =IFERROR(AVERAGE(C32:G32),"") | I32: =SQRT((C32-H32)^2) -> #VALUE! | AC32: Mean at time of Report | AD32: - | AE32: -
A33: Price/Sales | B33: Fixed Asset Turnover | C33: =C59/C72 -> #VALUE! | D33: =D59/D73 -> 0.32058231 | E33: =E58/E71 -> 1.049495 | F33: =F59/F72 -> #VALUE! | G33: =G59/G72 -> #VALUE! | H33: =IFERROR(AVERAGE(C33:G33),"") | I33: =SQRT((C33-H33)^2) -> #VALUE! | AC33: GENERAL & ADMIN EXPENSE | AD33: - | AE33: -
B34: Total Asset Turnover | C34: =C59/C73 -> 0.2391333 | D34: =D59/D73 -> 0.32058231 | E34: =E59/E73 -> 0.41655014 | F34: =F59/F73 -> 0.44228496 | G34: =G59/G73 -> 0.14769879 | H34: =IFERROR(AVERAGE(C34:G34),"") -> 0.3132499 | I34: =SQRT((C34-H34)^2) -> 0.074116599 | AC34: YoY Growth % | AD34: - | AE34: -
B35: Valuation | H35: =IFERROR(AVERAGE(C35:F35),"") | AC35: Actual/Predicted Surprise % | AD35: - | AE35: -
B36: Price/Earnings | C36: =C10/C65 -> 41.078318 | D36: =D10/D65 -> 27.474027 | E36: =E10/E65 -> 8.17499 | F36: =F10/F65 -> 30.028165 | G36: =G10/G65 -> 17.022995 | H36: =IFERROR(AVERAGE(C36:G36),"") -> 24.755699 | I36: =SQRT((C36-H36)^2) -> 16.322619 | AC36: Mean at time of Report | AD36: - | AE36: -
B37: Price/Sales | C37: =C10/C59 -> 8.5672855 | D37: =D10/D59 -> 2.0837728 | E37: =E10/E59 -> 1.9538081 | F37: =F10/F59 -> 1.5418807 | G37: =G10/G59 -> 3.004984 | H37: =IFERROR(AVERAGE(C37:G37),"") -> 3.4303462 | I37: =SQRT((C37-H37)^2) -> 5.1369393 | AC37: SG&A EXPENSE | AD37: - | AE37: -
B38: Price/Book | C38: =C10/C77 -> 3.002535 | D38: =D10/D77 -> 1.122108 | E38: =E10/E77 -> 1.7574128 | F38: =F10/F77 -> 1.8002543 | G38: =G10/G77 -> 0.57741254 | H38: =IFERROR(AVERAGE(C38:G38),"") -> 1.6519445 | I38: =SQRT((C38-H38)^2) -> 1.3505905 | AC38: YoY Growth % | AD38: - | AE38: -
B39: EV/Sales | C39: =(C76+C10-C68)/C59 -> 7.2011468 | D39: =(D76+D10-D68)/D59 -> 2.6821435 | E39: =(E76+E10-E68)/E59 -> 1.9681315 | F39: =(F76+F10-F68)/F59 -> 2.4743045 | G39: =(G76+G10-G68)/G59 -> 2.7342534 | H39: =IFERROR(AVERAGE(C39:G39),"") -> 3.4119959 | I39: =SQRT((C39-H39)^2) -> 3.7891509 | AC39: Actual/Predicted Surprise % | AD39: - | AE39: -
B40: EV/EBITDA | C40: =(C76+C10-C68)/C61 -> 23.089584 | D40: =(D76+D10-D68)/D61 -> 12.941834 | E40: =(E76+E10-E68)/E61 -> 4.7897311 | F40: =(F76+F10-F68)/F61 -> 11.118265 | G40: =(G76+G10-G68)/G61 -> 7.3333877 | H40: =IFERROR(AVERAGE(C40:G40),"") -> 11.85456 | I40: =SQRT((C40-H40)^2) -> 11.235024 | AC40: Mean at time of Report | AD40: - | AE40: -
...

Sheet SARD
C1: in AUD | F1: Variables | K1: Rankings | P1: Difference | U1: Results | Y1: Additional Information | AD1: =B3 -> PLS.AX | AE1: Selected Peers | AJ1: Price Multiples (TTM) | AM1: Enterprise Value Multiples (TTM)
