Workbook
Name Sectors: '[1]Sector Impact'!$K$4:$K$16
Name Sectors: 'Sector Impact'!$K$4:$K$16

Sheet OP
B2: 45039 | C2: Team 1 | D2: 45303 | E2: UNITEDHEALTH GROUP INCORPORATED (XNYS:UNH) | L2: NYSE | M2: SIC: 6321
D3: COMPANY DESCRIPTION | H3: CEO & BOARD OF DIRECTORS
D4: {=_FV(Inputs!H3,"Description")} -> UnitedHealth Group Incorporated is a healthcare company. The Company has two businesses, Optum and UnitedHealthcare. Optum serves the health care marketplace, including patients and consumers, payers, care providers, employers, governments and life sciences companies. UnitedHealthcare offers a full range of health benefits designed to simplify the health care experience and make it more affordable for consumers to access care. UnitedHealthcare Employer & Individual serves consumers and employers, ranging from sole proprietorships to large, multi-site and national employers and public sector employers. UnitedHealthcare Medicare & Retirement delivers health and well-being benefits to seniors and other Medicare eligible consumers. The Company’s segments include Optum Health, Optum Insight, Optum Rx and UnitedHealthcare. UnitedHealthcare segment includes UnitedHealthcare Employer & Individual, UnitedHealthcare Medicare & Retirement and UnitedHealthcare Community & State. | H4: Name (Gender;Age) | I4: Tenure | J4: Executive? | K4: Other roles
H5: Charles Baker (M; 67) | I5: 0 | J5: No | K5: Current President of NCAA
H6: Timothy Flynn (M; 65) | I6: 6 | J6: No | K6: Chairman and CEO of KPMG International
H7: Paul Garcia (M; 69) | I7: 2 | J7: No | K7: Retired Chair & Chief Executive Officer Global Payments Inc.
H8: Kristen Gil (W; 50) | I8: 1 | J8: No | K8: Vice President of Business and Operations at Google
H9: Stephen Hemsley (M; 71) | I9: 23 | J9: Yes | K9: Executive Chairman of the Board UnitedHealth Group
H10: Michele Hooper (W; 72) | I10: 16 | J10: No | K10: Board Member of Black Directors Health Equity Agenda
H11: F. William McNabb III (M; 66) | I11: 5 | J11: No | K11: None
H12: Valerie Montgomery Rice, M.D. (W; 62) | I12: 6 | J12: No | K12: President and CEO, Morehouse School of Medicine
H13: John Noseworthy, M.D. (M; 72) | I13: 4 | J13: No | K13: Board Member at: Mitre an AlixPartners, Executive Chair at Caire and Chairman at Aegis Ventures
H14: Sir Andrew Witty (M; 59) | I14: 2 | J14: Yes | K14: CEO of UnitedHealth Group
B17: USD MILLIONS
B18: COMPANY OVERVIEW
B19: Stock | D19: Liquidity and Solvency | F19: Segments | I19: Profitability (2022) | L19: Multiples
B20: Last Price | C20: 523.28 | D20: Total Assets | E20: =_xlfn.XLOOKUP(D20,'[2]Fin. Data1'!A:A,'[2]Fin. Data1'!B:B,,0) -> 245705 | F20: Regions | H20: % Sales | I20: Reporting Year | J20: 2022 | L20: Float | M20: 0.996
B21: Outstanding Shares | C21: 924925300 | D21: Total Liabilities | E21: =_xlfn.XLOOKUP(D21,'[2]Fin. Data1'!A:A,'[2]Fin. Data1'!B:B,,0) -> 159358 | F21: =Segments!C5 -> USA | H21: =[2]Segments1!B5 -> 0.89631492 | I21: End of Year | J21: 1 October 2022 | L21: Insiders Own | M21: 0.0025
B22: Market Cap. | C22: =C20*C21/1000000 -> 483994.91 | D22: Cash/Share | E22: =_xlfn.XLOOKUP("Cash & Eq.",'[2]Fin. Data1'!A:A,'[2]Fin. Data1'!B:B,,0)*1000000/C21 -> 30.176491 | F22: =Segments!C6 -> Global | H22: =[2]Segments1!B6 -> 0.10368508 | I22: EBITDA | K22: =_xlfn.XLOOKUP(I22,'[2]Fin. Data1'!A:A,'[2]Fin. Data1'!B:B,,0) -> 31835 | L22: b (Yahoo) | M22: 0.55
B23: +Total Debt | C23: ='[2]Fin. Data1'!B58 -> 63467 | D23: EBITDA/Net Financial Cost (NFC) | E23: =_xlfn.XLOOKUP("EBITDA",'[2]Fin. Data1'!A:A,'[2]Fin. Data1'!B:B,,0)/_xlfn.XLOOKUP("Net Financial Cost",'[2]Fin. Data1'!A:A,'[2]Fin. Data1'!B:B,,0) -> -15.217495 | I23: Depreciation & Amortization | K23: =_xlfn.XLOOKUP(I23,'[2]Fin. Data1'!A:A,'[2]Fin. Data1'!B:B,,0) -> 3400 | L23: Score (S&P)
B24: -Cash | C24: ='[2]Fin. Data1'!B39 -> 27911 | D24: Debt/EBITDA | E24: =_xlfn.XLOOKUP("Total Debt",'[2]Fin. Data1'!A:A,'[2]Fin. Data1'!B:B,,0)/_xlfn.XLOOKUP("EBITDA",'[2]Fin. Data1'!A:A,'[2]Fin. Data1'!B:B,,0) -> 1.9936234 | I24: EBIT | K24: =_xlfn.XLOOKUP(I24,'[2]Fin. Data1'!A:A,'[2]Fin. Data1'!B:B,,0) -> 28435 | L24: Price/Book Value | M24: =IFERROR((C20*C21/(E20-E21))/1000000,"") -> 5.6052313
B25: =Enterprise Value | C25: =C22+C23-C24 -> 519550.91 | D25: "Others Assets"/Asset | E25: =_xlfn.XLOOKUP("Other Assets",'[2]Fin. Data1'!A:A,'[2]Fin. Data1'!B:B,,0)/_xlfn.XLOOKUP("Total Assets",'[2]Fin. Data1'!A:A,'[2]Fin. Data1'!B:B,,0) -> 0.52904092 | I25: Net Income | K25: =_xlfn.XLOOKUP(I25,'[2]Fin. Data1'!A:A,'[2]Fin. Data1'!B:B,,0) -> 20639 | L25: NCF(3y avg)/Asset | M25: =IFERROR(K31/E20,"") -> 0.073448512
B26: Holdings (nac/int'l) | C26: - | D26: Debt/Assets | E26: =_xlfn.XLOOKUP(D26,'[2]Fin. Data1'!A:A,'[2]Fin. Data1'!B:B,,0) -> 0.25830569 | F26: Categories | H26: % Sales | I26: EPS | K26: =1000000*K25/C21 -> 22.314234 | L26: Price/Net Inc. (3y avg) | M26: =IFERROR(C22/K30,"") -> 26.819075
B27: t liq. (Holdings/Vol.) | C27: - | D27: EBITDA Margin (average) | E27: =AVERAGE(_xlfn.XLOOKUP("EBITDA Margin",'[2]Fin. Data1'!A:A,'[2]Fin. Data1'!B:D,,0)) -> 0.096905436 | F27: =[2]Segments1!C14 -> UnitedHealthcare | H27: =[2]Segments1!B14 -> 0.45708633 | I27: ROA | K27: =K25/E20 -> 0.083999105 | L27: EV/Asset | M27: =IFERROR(C25/E20,"") -> 2.1145313
B28: % Short | C28: 0.0065 | D28: Operating Margin (average) | E28: =AVERAGE(_xlfn.XLOOKUP("Operating Margin",'[2]Fin. Data1'!A:A,'[2]Fin. Data1'!B:D,,0)) -> 0.086065155 | F28: =[2]Segments1!C16 -> Optum Insight | H28: =[2]Segments1!B16 -> 0.043686033 | I28: ROIC | K28: =K25/(E20-(E21-C23)) -> 0.13776416 | L28: EV/Ebitda (3y average) | M28: =IFERROR(C25/K29,"") -> 18.510436
B29: Traffic ESG | D29: Net Income Margin (average) | E29: =AVERAGE(_xlfn.XLOOKUP("Net Income Margin",'[2]Fin. Data1'!A:A,'[2]Fin. Data1'!B:D,,0)) -> 0.062216278 | F29: =[2]Segments1!C17 -> Optum Rx | H29: =[2]Segments1!B17 -> 0.29413627 | I29: EBITDA (3y average) | K29: =AVERAGE(_xlfn.XLOOKUP("EBITDA",'[2]Fin. Data1'!A:A,'[2]Fin. Data1'!B:D,,0)) -> 28068 | L29: Price/NCF (3y average) | M29: =IFERROR(C22/K31,"") -> 26.819075
B30: E | F30: =Segments!C15 -> Optum Health | H30: =Segments!B15 -> 0.20509137 | I30: Net Income (3y average) | K30: =AVERAGE(_xlfn.XLOOKUP("Net Income",'[2]Fin. Data1'!A:A,'[2]Fin. Data1'!B:D,,0)) -> 18046.667 | L30: Bonds 1,3,5a (USD) | M30: -
B31: S | D31: Net Financial Cost/Avg Net Debt | E31: =-_xlfn.XLOOKUP("Net Financial Cost",'[2]Fin. Data1'!A:A,'[2]Fin. Data1'!B:B,,0)/AVERAGE(_xlfn.XLOOKUP("Net Debt",'[2]Fin. Data1'!A:A,'[2]Fin. Data1'!B:D,,0)) -> 0.067207093 | I31: NCF (3y average) | K31: =AVERAGE(_xlfn.XLOOKUP("Net Income",'[2]Fin. Data1'!A:A,'[2]Fin. Data1'!B:D,,0)) -> 18046.667 | L31: Div+Rep.(3y avg)/Price | M31: =-IFERROR(SUM(E52:E54)/(3*C22),"") -> 0.019323206
B32: G | L32: Div. Yield | M32: =-IFERROR(L53/C22,"") -> 0.012378229
B33: INVESTMENT THESIS
B34: Pillars of Recommendation | H34: Recommendation | I34: Valuation Assumptions
B35: Pillar | C35: Explanation | H35: Sell | I35: CHECK DCF
B36: Inorganic Growth | C36: UNH has high anticipation of acquisition as a growth strategy.
B37: Backed Investment | C37: Although UNH is considered overvalued and its stock price is inflated, it would not be reasonable to sell for mulitple reasons. Company and stock are considered safe bets as default and bankruptcy risk is low, company is able to sell off assets and companies in the case of emergency ('too big to fail'). High speculation of price increase by other investors/institutions. Majority shareholders (institutional) are Vanguard and Fidelity, which have high investing and political influence, and can therefore lobby for favourable conditions for UNH in the case of emergency.
B38: Safe Industry to Invest in | C38: Healthcare in general is typically a more stable industry to invest in. Even in times of economic/social/catastrophic/other distresses, individuals need to go to the doctor, buy medicine and other medical aids, and especially need insurance. This causes the industry to sometimes profit during times of distress (ie. Covid) as well.
B39: Risks of Investment | H39: Price Target | I39: Valuation
B40: Risk | C40: Explanation | H40: $550 | I40: Discount Rate | J40: =DCF!F50 -> 0.0805 | L40: Price M. Upside | M40: =SARD!AJ14 -> -0.3625604
B41: Regulatory risk | C41: Healthcare and Insurance industries in the US is highly subject to regulations, which are highly dependant upon political motives of the countries leaders. (Thinking ahead to 2024 presidential election and onwards)
B42: Political risk | C42: UNH is closely related to (and even employs) current or former politicians with certain ideologies. Possible cause for negative perception due to political preference of customers. | I42: Upside | J42: =DCF!D76 -> -0.068100445 | L42: EV M. Upside | M42: =SARD!AM14 -> -0.53244397
B43: Exchange Rate risk | C43: Around 10% of UNH's revenue is from out of the US and this portion is subject to exchance rate risk.
...

Sheet Segments
B2: ="Regions "&"("&[2]OP1!$J$20&")" -> Regions (2022) | Q2: Products
D3: Nominal value ($ Million) | K3: YoY Growth | Q3: Neither United Health Group nor Optum manufacture any products, they are a services company. Althought they do sell some medicines and pharmaceutical products, even direct-to-consumer, they sell it as retailers rather than manufacturers. Additionally, they specialize in different management and logisitics services regarding healthcare and pharamceuticals, again however, they do not actually manufacture any products
B4: Weight | C4: Region | D4: =[2]OP1!J20 -> 2022 | E4: =D4-1 -> 2021 | F4: =E4-1 -> 2020 | G4: =F4-1 -> 2019 | H4: =G4-1 -> 2018 | I4: =H4-1 -> 2017 | K4: =[2]OP1!J20 -> 2022 | L4: =K4-1 -> 2021 | M4: =L4-1 -> 2020 | N4: =M4-1 -> 2019 | O4: =N4-1 -> 2018 | P4: =O4-1 -> 2017
B5: =IFERROR(D5/$D$9,"") -> 0.89631492 | C5: USA | D5: =D21*(46335000/51695000) -> 290551.24 | E5: =E21*(45120000/50630000) -> 256298.18 | F5: =F21*(43010000/48435000) -> 228339.72 | G5: =G21*(43430000/49150000) -> 213973.38 | H5: =H21*(42855000/49075000) -> 197571.37 | I5: =I21*(42595000/46675000) -> 183575.1 | K5: =(D5-E5)/E5 -> 0.13364536 | L5: =(E5-F5)/F5 -> 0.12244236 | M5: =(F5-G5)/G5 -> 0.067140786 | N5: =(G5-H5)/H5 -> 0.083018132 | O5: =(H5-I5)/I5 -> 0.076242794 | P5: -
B6: =IFERROR(D6/$D$9,"") -> 0.10368508 | C6: Global | D6: =D21*(5360000/51695000) -> 33610.762 | E6: =E21*(5510000/50630000) -> 31298.824 | F6: =F21*(5425000/48435000) -> 28801.279 | G6: =G21*(5720000/49150000) -> 28181.62 | H6: =H21*(6220000/49075000) -> 28675.626 | I6: =I21*(4080000/46675000) -> 17583.904 | K6: =(D6-E6)/E6 -> 0.073866588 | L6: =(E6-F6)/F6 -> 0.086716487 | M6: =(F6-G6)/G6 -> 0.021988054 | N6: =(G6-H6)/H6 -> -0.017227395 | O6: =(H6-I6)/I6 -> 0.63078835 | P6: -
B7: =IFERROR(D7/$D$9,"") -> 0
B8: =IFERROR(D8/$D$9,"") -> 0
B9: =SUM(B5:B8) -> 1 | C9: TOTAL | D9: =SUM(D5:D8) -> 324162 | E9: =SUM(E5:E8) -> 287597 | F9: =SUM(F5:F8) -> 257141 | G9: =SUM(G5:G8) -> 242155 | H9: =SUM(H5:H8) -> 226247 | I9: =SUM(I5:I8) -> 201159 | K9: =(D9-E9)/E9 -> 0.12713971 | L9: =(E9-F9)/F9 -> 0.11844086 | M9: =(F9-G9)/G9 -> 0.061885982 | N9: =(G9-H9)/H9 -> 0.070312535 | O9: =(H9-I9)/I9 -> 0.12471726 | P9: -
B11: ="Categories "&"("&[2]OP1!$J$20&")" -> Categories (2022)
D12: Nominal value ($ Million) | K12: YoY Growth
B13: Weight | C13: Category | D13: =[2]OP1!J20 -> 2022 | E13: =D13-1 -> 2021 | F13: =E13-1 -> 2020 | G13: =F13-1 -> 2019 | H13: =G13-1 -> 2018 | I13: =H13-1 -> 2017 | K13: =[2]OP1!J20 -> 2022 | L13: =K13-1 -> 2021 | M13: =L13-1 -> 2020 | N13: =M13-1 -> 2019 | O13: =N13-1 -> 2018 | P13: =O13-1 -> 2017
B14: =IFERROR(D14/$D$18,"") -> 0.45708633 | C14: UnitedHealthcare | D14: 249741 | E14: 222899 | F14: 200875 | G14: 193842 | H14: 183476 | I14: 163257 | K14: =(D14-E14)/E14 -> 0.12042225 | L14: =(E14-F14)/F14 -> 0.10964032 | M14: =(F14-G14)/G14 -> 0.036282127 | N14: =(G14-H14)/H14 -> 0.056497853 | O14: =(H14-I14)/I14 -> 0.12384768 | P14: -
B15: =IFERROR(D15/$D$18,"") -> 0.20509137 | C15: Optum Health | D15: 112057 | E15: 83299 | F15: 62289 | G15: 48283 | H15: 39027 | I15: 32999 | K15: =(D15-E15)/E15 -> 0.34523824 | L15: =(E15-F15)/F15 -> 0.33729872 | M15: =(F15-G15)/G15 -> 0.2900814 | N15: =(G15-H15)/H15 -> 0.23716914 | O15: =(H15-I15)/I15 -> 0.1826722 | P15: -
B16: =IFERROR(D16/$D$18,"") -> 0.043686033 | C16: Optum Insight | D16: 23869 | E16: 20066 | F16: 17743 | G16: 16245 | H16: 14604 | I16: 13214 | K16: =(D16-E16)/E16 -> 0.18952457 | L16: =(E16-F16)/F16 -> 0.13092487 | M16: =(F16-G16)/G16 -> 0.092212989 | N16: =(G16-H16)/H16 -> 0.11236647 | O16: =(H16-I16)/I16 -> 0.10519146 | P16: -
B17: =IFERROR(D17/$D$18,"") -> 0.29413627 | C17: Optum Rx | D17: 160709 | E17: 147093 | F17: 139918 | G17: 116381 | H17: 108976 | I17: 100709 | K17: =(D17-E17)/E17 -> 0.092567287 | L17: =(E17-F17)/F17 -> 0.051280035 | M17: =(F17-G17)/G17 -> 0.20224092 | N17: =(G17-H17)/H17 -> 0.067950741 | O17: =(H17-I17)/I17 -> 0.082087996 | P17: -
B18: =SUM(B14:B17) -> 1 | C18: TOTAL | D18: =SUM(D14:D17) -> 546376 | E18: =SUM(E14:E17) -> 473357 | F18: =SUM(F14:F17) -> 420825 | G18: =SUM(G14:G17) -> 374751 | H18: =SUM(H14:H17) -> 346083 | I18: =SUM(I14:I17) -> 310179 | K18: =(D18-E18)/E18 -> 0.15425778 | L18: =(E18-F18)/F18 -> 0.12483099 | M18: =(F18-G18)/G18 -> 0.12294564 | N18: =(G18-H18)/H18 -> 0.08283562 | O18: =(H18-I18)/I18 -> 0.11575252 | P18: -
C19: Intersegment Reconcilliation | D19: =111107*2 -> 222214 | E19: =92880*2 -> 185760 | F19: =81842*2 -> 163684 | G19: =129274+3322 -> 132596 | H19: =117018+2818 -> 119836 | I19: =54510*2 -> 109020
C20: as a % of total Revenue | D20: =D19/D18 -> 0.40670527 | E20: =E19/E18 -> 0.39243108 | F20: =F19/F18 -> 0.38895978 | G20: =G19/G18 -> 0.35382427 | H20: =H19/H18 -> 0.34626376 | I20: =I19/I18 -> 0.35147447
B21: =B18 -> 1 | C21: TOTAL (Net of Intersegment Revenue) | D21: =D18-D19 -> 324162 | E21: =E18-E19 -> 287597 | F21: =F18-F19 -> 257141 | G21: =G18-G19 -> 242155 | H21: =H18-H19 -> 226247 | I21: =I18-I19 -> 201159 | K21: =(D21-E21)/E21 -> 0.12713971 | L21: =(E21-F21)/F21 -> 0.11844086 | M21: =(F21-G21)/G21 -> 0.061885982 | N21: =(G21-H21)/H21 -> 0.070312535 | O21: =(H21-I21)/I21 -> 0.12471726 | P21: -
B23: Categories | D23: Description | I23: Graphs
B24: UnitedHealthcare | D24: variety of health insurance products and services to individuals, employers, and government programs; this includes health plans, dental plans, vision plans, and other related products
B25: Optum Health | D25: broad range of health management services, including care delivery and management, wellness programs, and behavioral health services; aims to improve the overall health and well-being of individuals
B26: Optum Insight | D26: services such as data analytics, technology solutions, and consulting services to help health care organizations optimize their operations and improve efficiency
B27: Optum Rx | D27: management of prescription benefits, including pharmacy benefit management, mail order pharmacy services, specialty pharmacy services, and more. aims to help individuals access their medications in a cost-effective and efficient manner
B31: Industry | J31: Graphs (Industry Forecasts)
B32: Drivers | D32: Description
B33: Perscription Drug Costs | D33: Typically drives the cost of UHG's revenues, because they act as a retailer for pharmaceutical products and other healthcare products (ie. wrist brace, first-aid kit, etc.)
B34: Healthcare Spending | D34: Within UHG's main market (US), the healthcare insurance system is privatized rather than public, which results in many regulatory precedents in place, to mitigate monopolies and other potential business malpractices in the economy. In the US Healthcare spending accounts for around 18% (2022) of the country's GDP, making it one of the largest contributing factors.
B35: Healthcare Software Development | D35: Drives the markets within which UHG's Optum arm operates in, as they provide majority of their services related to software and data analytics. The increased demand within this industry drives the competitive edge companies may get by being innovative and creating the most efficient, comprehensive and user-friendly solutions.
B36: Sales forecast
B37: Source | D37: Market Growth CAGR | G37: Period
B38: Grand View Research | D38: 0.0608 | G38: 2023-2030
B39: IMARC Group | D39: 0.062 | G39: 2023-2032
B40: Mordor Intelligence | D40: 0.0795 | G40: 2023-2028
B41: Mordor Intelligence | D41: 0.129 | H41: 2022-2027
B42: IMARC Group | D42: 0.118 | G42: 2024-2032
B43: Grand View Research | D43: 0.1125 | G43: 2023-2030
B44: Company's Strategy / Extra Notes
B45: – One of UnitedHealth growth strategies encompasses inorganic growth through acquisitions. These acquisitions aim at increasing UHG's cover of the healthcare value chain and markets as well as diversifying their operations. – Most recently UHG acquired Healthcare Associates of Texas for $300mn and Optum acquired Refresh Mental Health. In addition to this, when considering the increasing YoY intersegment revenue (45% most recently), it is evident that UHG is employing a conservative strategy, where they try to rely as little as possible on outside suppliers and products in order to conduct their core business activities. – Although UHG does conduct business internationally (UK, Ireland, India, Brazil, Philippines, Colombia, Puerto Rico), their major revenue source (accounting for 90% of revenue) comes from the US. UHG has an effort to expand, however mainly within the US which is further supported with the most recent acquisitions (specifically Healthcare Associates of Texas). As the US has the largest and most lucrative healthcare market, this motivate UHG to concentrate majority of their efforts within the region. – UHG claims that they have 5 strategic growth priorities: Value-Based Comprehensive Care Delivery, Health Benefits, Health Technology, Health Financial Services, and Pharmacy Care Services. – UHG also embraces a very technological and innovation-oriented growth, evident through its Optum brand, which it created in 2011 by merging its existing pharmacy and care delivery services. In summary, UHG channels growth through innovation-oriented business activities as well as acquisitions, aimed at diversifying the company's market reach as well as optimizing the overall healthcare experience.
C58: https://www2.deloitte.com/us/en/blog/health-care-blog/2022/will-digital-players-reinvent-health-insurance.html
...

Sheet Acuerdo
A1: Invertir
A2: NO invertir
A3: Mantener sin elevar posición
A4: Mantener (y seguir comprando)
A5: Liquidar
A6: PENDIENTE

Sheet SARD
F1: Variables | K1: Rankings | P1: Difference | U1: Results | Y1: Additional Information | AD1: =B3 -> UNH.N | AE1: Selected Peers | AJ1: Price Multiples (TTM) | AM1: Enterprise Value Multiples (TTM)
B2: Ticker | C2: Company Name | D2: TRBC Industry | E2: Country | F2: ROE | G2: DEBT/EBIT | H2: Market Cap | I2: EPS Growth (2019-2023) (Refinitiv Smart Estimate) | J2: EBIT Margin | K2: ROE | L2: DEBT/EBIT | M2: Market Cap | N2: EPS Growth | O2: EBIT Margin | P2: ROE | Q2: DEBT/EBIT | R2: Market Cap | S2: EPS Growth | T2: EBIT Margin | U2: SARD Result | V2: SARD Peers | W2: SARD Peers adjusted Rank | Y2: Suitability | Z2: Relevant Information Missing | AA2: Author's Override | AB2: Observations | AE2: SARD Peers adjusted Rank | AF2: SARD Result | AG2: Ticker | AH2: Company Name | AI2: Country | AJ2: P / E | AK2: P / B | AL2: Price / Sales | AM2: EV / Sales | AN2: EV / EBITDA
A3: Benchmark | B3: UNH.N | C3: UnitedHealth Group Inc | D3: Managed Healthcare | E3: United States of America | F3: 0.26537828 | G3: 2.0264814 | H3: 5.0894939e+11 | I3: 24.95 | J3: 0.087718486 | K3: =IFERROR(_xlfn.RANK.EQ(F3,F$3:F$14),"N/A") -> 3 | L3: =IFERROR(_xlfn.RANK.EQ(G3,G$3:G$14),"N/A") -> 7 | M3: =IFERROR(_xlfn.RANK.EQ(H3,H$3:H$15),"N/A") -> 1 | N3: =IFERROR(_xlfn.RANK.EQ(I3,I$3:I$15),"N/A") -> 3 | O3: =IFERROR(_xlfn.RANK.EQ(J3,J$3:J$15),"N/A") -> 3 | P3: - | Q3: - | R3: - | S3: - | T3: - | U3: - | V3: - | W3: - | Y3: =IF(OR(Z3="Y",AA3="Y"),"Not suitable","") | Z3: =IF(N3="N/A","Y","") | AE3: {=_xlfn._xlws.SORT(_xlfn._xlws.FILTER(SARD!W3:W14,SARD!W3:W14<=SMALL(W4:W14,6)),,1)} -> 1 | AF3: =_xlfn.XLOOKUP($AE3,$W:$W,U:U,,0) -> 10 | AG3: =_xlfn.XLOOKUP($AE3,$W:$W,B:B,,0) -> ELV.N | AH3: =_xlfn.XLOOKUP($AE3,$W:$W,C:C,,0) -> Elevance Health Inc | AI3: =_xlfn.XLOOKUP($AE3,$W:$W,E:E,,0) -> United States of America | AJ3: 18.923728 | AK3: 2.95 | AL3: 0.67169202 | AM3: 0.75 | AN3: 11.1
A4: Comparison | B4: HUM.N | C4: Humana Inc | D4: Managed Healthcare | E4: United States of America | F4: 0.18326693 | G4: 2.8298241 | H4: 61598448752 | I4: 28.3 | J4: 0.043648906 | K4: =IFERROR(_xlfn.RANK.EQ(F4,F$3:F$14),"N/A") -> 4 | L4: =IFERROR(_xlfn.RANK.EQ(G4,G$3:G$14),"N/A") -> 3 | M4: =IFERROR(_xlfn.RANK.EQ(H4,H$3:H$14),"N/A") -> 4 | N4: =IFERROR(_xlfn.RANK.EQ(I4,I$3:I$14),"N/A") -> 2 | O4: =IFERROR(_xlfn.RANK.EQ(J4,J$3:J$14),"N/A") -> 6 | P4: =IFERROR(ABS(K$3-K4),"N/A") -> 1 | Q4: =IFERROR(ABS(L$3-L4),"N/A") -> 4 | R4: =IFERROR(ABS(M$3-M4),"N/A") -> 3 | S4: =IFERROR(ABS(N$3-N4),"N/A") -> 1 | T4: =IFERROR(ABS(O$3-O4),"N/A") -> 3 | U4: =SUM(P4:T4) -> 12 | V4: =_xlfn.RANK.EQ(U4,$U$4:$U$14,1) -> 2 | W4: =IF(Y4="Not suitable","-",V4) -> 2 | Y4: =IF(OR(Z4="Y",AA4="Y"),"Not suitable","") | Z4: =IF(N4="N/A","Y","") | AE4: 2 | AF4: =_xlfn.XLOOKUP($AE4,$W:$W,U:U,,0) -> 12 | AG4: =_xlfn.XLOOKUP($AE4,$W:$W,B:B,,0) -> HUM.N | AH4: =_xlfn.XLOOKUP($AE4,$W:$W,C:C,,0) -> Humana Inc | AI4: =_xlfn.XLOOKUP($AE4,$W:$W,E:E,,0) -> United States of America | AJ4: 20.740747 | AK4: 3.6343412 | AL4: 0.60183534 | AM4: 0.57 | AN4: 10.69
B5: CI.N | C5: Cigna Group | D5: Managed Healthcare | E5: United States of America | F5: 0.15100168 | G5: 3.0858476 | H5: 7.5431575e+10 | I5: 24.85 | J5: 0.055817767 | K5: =IFERROR(_xlfn.RANK.EQ(F5,F$3:F$14),"N/A") -> 6 | L5: =IFERROR(_xlfn.RANK.EQ(G5,G$3:G$14),"N/A") -> 2 | M5: =IFERROR(_xlfn.RANK.EQ(H5,H$3:H$14),"N/A") -> 3 | N5: =IFERROR(_xlfn.RANK.EQ(I5,I$3:I$14),"N/A") -> 4 | O5: =IFERROR(_xlfn.RANK.EQ(J5,J$3:J$14),"N/A") -> 4 | P5: =IFERROR(ABS(K$3-K5),"N/A") -> 3 | Q5: =IFERROR(ABS(L$3-L5),"N/A") -> 5 | R5: =IFERROR(ABS(M$3-M5),"N/A") -> 2 | S5: =IFERROR(ABS(N$3-N5),"N/A") -> 1 | T5: =IFERROR(ABS(O$3-O5),"N/A") -> 1 | U5: =SUM(P5:T5) -> 12 | V5: =_xlfn.RANK.EQ(U5,$U$4:$U$14,1) -> 2 | W5: 3 | Y5: =IF(OR(Z5="Y",AA5="Y"),"Not suitable","") | Z5: =IF(N5="N/A","Y","") | AE5: 3 | AF5: =_xlfn.XLOOKUP($AE5,$W:$W,U:U,,0) -> 12 | AG5: =_xlfn.XLOOKUP($AE5,$W:$W,B:B,,0) -> CI.N | AH5: =_xlfn.XLOOKUP($AE5,$W:$W,C:C,,0) -> Cigna Group | AI5: =_xlfn.XLOOKUP($AE5,$W:$W,E:E,,0) -> United States of America | AJ5: 14.545081 | AK5: 1.6547433 | AL5: 0.39721317 | AM5: 0.51 | AN5: 8.65
B6: ELV.N | C6: Elevance Health Inc | D6: Managed Healthcare | E6: United States of America | F6: 0.16607345 | G6: 2.7974478 | H6: 1.1326205e+11 | I6: 33.06 | J6: 0.055377104 | K6: =IFERROR(_xlfn.RANK.EQ(F6,F$3:F$14),"N/A") -> 5 | L6: =IFERROR(_xlfn.RANK.EQ(G6,G$3:G$14),"N/A") -> 4 | M6: =IFERROR(_xlfn.RANK.EQ(H6,H$3:H$14),"N/A") -> 2 | N6: =IFERROR(_xlfn.RANK.EQ(I6,I$3:I$14),"N/A") -> 1 | O6: =IFERROR(_xlfn.RANK.EQ(J6,J$3:J$14),"N/A") -> 5 | P6: =IFERROR(ABS(K$3-K6),"N/A") -> 2 | Q6: =IFERROR(ABS(L$3-L6),"N/A") -> 3 | R6: =IFERROR(ABS(M$3-M6),"N/A") -> 1 | S6: =IFERROR(ABS(N$3-N6),"N/A") -> 2 | T6: =IFERROR(ABS(O$3-O6),"N/A") -> 2 | U6: =SUM(P6:T6) -> 10 | V6: =_xlfn.RANK.EQ(U6,$U$4:$U$14,1) -> 1 | W6: =IF(Y6="Not suitable","-",V6) -> 1 | Y6: =IF(OR(Z6="Y",AA6="Y"),"Not suitable","") | Z6: =IF(N6="N/A","Y","") | AE6: 4 | AF6: =_xlfn.XLOOKUP($AE6,$W:$W,U:U,,0) -> 13 | AG6: =_xlfn.XLOOKUP($AE6,$W:$W,B:B,,0) -> MOH.N | AH6: =_xlfn.XLOOKUP($AE6,$W:$W,C:C,,0) -> Molina Healthcare Inc | AI6: =_xlfn.XLOOKUP($AE6,$W:$W,E:E,,0) -> Brazil | AJ6: 20.87184 | AK6: 5.4874968 | AL6: 0.64354979 | AM6: 0.42 | AN6: 7.62
B7: CNC.N | C7: Centene Corp | D7: Managed Healthcare | E7: United States of America | F7: 0.049964667 | G7: 13.367953 | H7: 40070417010 | I7: 6.65 | J7: 0.009325686 | K7: =IFERROR(_xlfn.RANK.EQ(F7,F$3:F$14),"N/A") -> 9 | L7: =IFERROR(_xlfn.RANK.EQ(G7,G$3:G$14),"N/A") -> 1 | M7: =IFERROR(_xlfn.RANK.EQ(H7,H$3:H$14),"N/A") -> 5 | N7: =IFERROR(_xlfn.RANK.EQ(I7,I$3:I$14),"N/A") -> 6 | O7: =IFERROR(_xlfn.RANK.EQ(J7,J$3:J$14),"N/A") -> 9 | P7: =IFERROR(ABS(K$3-K7),"N/A") -> 6 | Q7: =IFERROR(ABS(L$3-L7),"N/A") -> 6 | R7: =IFERROR(ABS(M$3-M7),"N/A") -> 4 | S7: =IFERROR(ABS(N$3-N7),"N/A") -> 3 | T7: =IFERROR(ABS(O$3-O7),"N/A") -> 6 | U7: =SUM(P7:T7) -> 25 | V7: =_xlfn.RANK.EQ(U7,$U$4:$U$14,1) -> 8 | W7: =IF(Y7="Not suitable","-",V7) -> 8 | Y7: =IF(OR(Z7="Y",AA7="Y"),"Not suitable","") | Z7: =IF(N7="N/A","Y","") | AE7: 5 | AF7: =_xlfn.XLOOKUP($AE7,$W:$W,U:U,,0) -> 20 | AG7: =_xlfn.XLOOKUP($AE7,$W:$W,B:B,,0) -> ODPV3.SA | AH7: =_xlfn.XLOOKUP($AE7,$W:$W,C:C,,0) -> Odontoprev SA | AI7: =_xlfn.XLOOKUP($AE7,$W:$W,E:E,,0) -> Italy | AJ7: 12.416288 | AK7: 4.1591911 | AL7: 2.9462169 | AM7: 2.7 | AN7: 8.77
B8: MOH.N | C8: Molina Healthcare Inc | D8: Managed Healthcare | E8: Brazil | F8: 0.26720648 | G8: 2.0571185 | H8: 21396100000 | I8: 20.87 | J8: 0.036686057 | K8: =IFERROR(_xlfn.RANK.EQ(F8,F$3:F$14),"N/A") -> 2 | L8: =IFERROR(_xlfn.RANK.EQ(G8,G$3:G$14),"N/A") -> 6 | M8: =IFERROR(_xlfn.RANK.EQ(H8,H$3:H$14),"N/A") -> 6 | N8: =IFERROR(_xlfn.RANK.EQ(I8,I$3:I$14),"N/A") -> 5 | O8: =IFERROR(_xlfn.RANK.EQ(J8,J$3:J$14),"N/A") -> 7 | P8: =IFERROR(ABS(K$3-K8),"N/A") -> 1 | Q8: =IFERROR(ABS(L$3-L8),"N/A") -> 1 | R8: =IFERROR(ABS(M$3-M8),"N/A") -> 5 | S8: =IFERROR(ABS(N$3-N8),"N/A") -> 2 | T8: =IFERROR(ABS(O$3-O8),"N/A") -> 4 | U8: =SUM(P8:T8) -> 13 | V8: =_xlfn.RANK.EQ(U8,$U$4:$U$14,1) -> 4 | W8: =IF(Y8="Not suitable","-",V8) -> 4 | Y8: =IF(OR(Z8="Y",AA8="Y"),"Not suitable","") | Z8: =IF(N8="N/A","Y","") | AE8: 6 | AF8: =_xlfn.XLOOKUP($AE8,$W:$W,U:U,,0) -> 22 | AG8: =_xlfn.XLOOKUP($AE8,$W:$W,B:B,,0) -> PGNY.OQ | AH8: =_xlfn.XLOOKUP($AE8,$W:$W,C:C,,0) -> Progyny Inc | AI8: =_xlfn.XLOOKUP($AE8,$W:$W,E:E,,0) -> United States of America | AJ8: 68.365985 | AK8: 6.5683503 | AL8: 3.279651 | AM8: 2.95 | AN8: 56.75
B9: ODPV3.SA | C9: Odontoprev SA | D9: Managed Healthcare | E9: Italy | F9: 0.38116587 | G9: 0.045917736 | H9: 1.2382017e+09 | I9: 0.18 | J9: 0.30150566 | K9: =IFERROR(_xlfn.RANK.EQ(F9,F$3:F$14),"N/A") -> 1 | L9: =IFERROR(_xlfn.RANK.EQ(G9,G$3:G$14),"N/A") -> 9 | M9: =IFERROR(_xlfn.RANK.EQ(H9,H$3:H$14),"N/A") -> 10 | N9: =IFERROR(_xlfn.RANK.EQ(I9,I$3:I$14),"N/A") -> 8 | O9: =IFERROR(_xlfn.RANK.EQ(J9,J$3:J$14),"N/A") -> 1 | P9: =IFERROR(ABS(K$3-K9),"N/A") -> 2 | Q9: =IFERROR(ABS(L$3-L9),"N/A") -> 2 | R9: =IFERROR(ABS(M$3-M9),"N/A") -> 9 | S9: =IFERROR(ABS(N$3-N9),"N/A") -> 5 | T9: =IFERROR(ABS(O$3-O9),"N/A") -> 2 | U9: =SUM(P9:T9) -> 20 | V9: =_xlfn.RANK.EQ(U9,$U$4:$U$14,1) -> 5 | W9: =IF(Y9="Not suitable","-",V9) -> 5 | Y9: =IF(OR(Z9="Y",AA9="Y"),"Not suitable","") | Z9: =IF(N9="N/A","Y","") | AE9: Median | AJ9: =MEDIAN(AJ3:AJ8) -> 19.832238 | AK9: =MEDIAN(AK3:AK8) -> 3.8967662 | AL9: =MEDIAN(AL3:AL8) -> 0.6576209 | AM9: =MEDIAN(AM3:AM8) -> 0.66 | AN9: =MEDIAN(AN3:AN8) -> 9.73
B10: HIA.MI | C10: Health Italia SpA | D10: Managed Healthcare | E10: Brazil | F10: 0.1167753 | G10: 2.6976918 | H10: 27967938 | I10: 0.17 | J10: 0.15918176 | K10: =IFERROR(_xlfn.RANK.EQ(F10,F$3:F$14),"N/A") -> 7 | L10: =IFERROR(_xlfn.RANK.EQ(G10,G$3:G$14),"N/A") -> 5 | M10: =IFERROR(_xlfn.RANK.EQ(H10,H$3:H$14),"N/A") -> 12 | N10: =IFERROR(_xlfn.RANK.EQ(I10,I$3:I$14),"N/A") -> 9 | O10: =IFERROR(_xlfn.RANK.EQ(J10,J$3:J$14),"N/A") -> 2 | P10: =IFERROR(ABS(K$3-K10),"N/A") -> 4 | Q10: =IFERROR(ABS(L$3-L10),"N/A") -> 2 | R10: =IFERROR(ABS(M$3-M10),"N/A") -> 11 | S10: =IFERROR(ABS(N$3-N10),"N/A") -> 6 | T10: =IFERROR(ABS(O$3-O10),"N/A") -> 1 | U10: =SUM(P10:T10) -> 24 | V10: =_xlfn.RANK.EQ(U10,$U$4:$U$14,1) -> 7 | W10: =IF(Y10="Not suitable","-",V10) -> 7 | Y10: =IF(OR(Z10="Y",AA10="Y"),"Not suitable","") | Z10: =IF(N10="N/A","Y","") | AE10: Benchmark Data | AJ10: Price / Share
B11: HAPV3.SA | C11: Hapvida Participacoes e Investimentos SA | D11: Managed Healthcare | E11: United States of America | F11: -0.01591483 | G11: -90.254672 | H11: 6.6975316e+09 | I11: 0 | J11: -0.006563152 | K11: =IFERROR(_xlfn.RANK.EQ(F11,F$3:F$14),"N/A") -> 10 | L11: =IFERROR(_xlfn.RANK.EQ(G11,G$3:G$14),"N/A") -> 12 | M11: =IFERROR(_xlfn.RANK.EQ(H11,H$3:H$14),"N/A") -> 7 | N11: =IFERROR(_xlfn.RANK.EQ(I11,I$3:I$14),"N/A") -> 10 | O11: =IFERROR(_xlfn.RANK.EQ(J11,J$3:J$14),"N/A") -> 10 | P11: =IFERROR(ABS(K$3-K11),"N/A") -> 7 | Q11: =IFERROR(ABS(L$3-L11),"N/A") -> 5 | R11: =IFERROR(ABS(M$3-M11),"N/A") -> 6 | S11: =IFERROR(ABS(N$3-N11),"N/A") -> 7 | T11: =IFERROR(ABS(O$3-O11),"N/A") -> 7 | U11: =SUM(P11:T11) -> 32 | V11: =_xlfn.RANK.EQ(U11,$U$4:$U$14,1) -> 9 | W11: =IF(Y11="Not suitable","-",V11) -> 9 | Y11: =IF(OR(Z11="Y",AA11="Y"),"Not suitable","") | Z11: =IF(N11="N/A","Y","") | AE11: Benchmark | AF11: Multiplier | AG11: # Shares | AH11: -Debt + Cash | AJ11: P / E | AK11: P / B | AL11: Price / Sales | AM11: EV / Sales | AN11: EV / EBITDA
B12: PGNY.OQ | C12: Progyny Inc | D12: Managed Healthcare | E12: United States of America | F12: 0.080532035 | G12: 0.27770875 | H12: 3.3878107e+09 | I12: 0.58 | J12: 0.029661475 | K12: =IFERROR(_xlfn.RANK.EQ(F12,F$3:F$14),"N/A") -> 8 | L12: =IFERROR(_xlfn.RANK.EQ(G12,G$3:G$14),"N/A") -> 8 | M12: =IFERROR(_xlfn.RANK.EQ(H12,H$3:H$14),"N/A") -> 8 | N12: =IFERROR(_xlfn.RANK.EQ(I12,I$3:I$14),"N/A") -> 7 | O12: =IFERROR(_xlfn.RANK.EQ(J12,J$3:J$14),"N/A") -> 8 | P12: =IFERROR(ABS(K$3-K12),"N/A") -> 5 | Q12: =IFERROR(ABS(L$3-L12),"N/A") -> 1 | R12: =IFERROR(ABS(M$3-M12),"N/A") -> 7 | S12: =IFERROR(ABS(N$3-N12),"N/A") -> 4 | T12: =IFERROR(ABS(O$3-O12),"N/A") -> 5 | U12: =SUM(P12:T12) -> 22 | V12: =_xlfn.RANK.EQ(U12,$U$4:$U$14,1) -> 6 | W12: =IF(Y12="Not suitable","-",V12) -> 6 | Y12: =IF(OR(Z12="Y",AA12="Y"),"Not suitable","") | Z12: =IF(N12="N/A","Y","") | AE12: =C3 -> UnitedHealth Group Inc | AF12: 1000000 | AG12: 924925293 | AH12: =-'Fin. Data'!B58*SARD!AF12+'Fin. Data'!B39*SARD!AF12 -> -35556000000 | AJ12: =AJ9*'Fin. Data'!B23*AF$12/AG$12 -> 442.54121 | AK12: =AK9*'Fin. Data'!B64*AF$12/AG$12 -> 327.65814 | AL12: =AL9*'Fin. Data'!B5*AF$12/AG$12 -> 230.47884 | AM12: =(AM9*'Fin. Data'!B5*$AF12+$AH12)/$AG12 -> 192.87063 | AN12: =(AN9*'Fin. Data'!B19*$AF12+$AH12)/$AG12 -> 296.45481
B13: CLOV.OQ | C13: Clover Health Investments Corp | D13: Managed Healthcare | E13: United States of America | F13: -0.94944338 | G13: -0.016858555 | H13: 4.6087228e+08 | I13: -0.41 | J13: -0.099979665 | K13: =IFERROR(_xlfn.RANK.EQ(F13,F$3:F$14),"N/A") -> 12 | L13: =IFERROR(_xlfn.RANK.EQ(G13,G$3:G$14),"N/A") -> 10 | M13: =IFERROR(_xlfn.RANK.EQ(H13,H$3:H$14),"N/A") -> 11 | N13: =IFERROR(_xlfn.RANK.EQ(I13,I$3:I$14),"N/A") -> 11 | O13: =IFERROR(_xlfn.RANK.EQ(J13,J$3:J$14),"N/A") -> 12 | P13: =IFERROR(ABS(K$3-K13),"N/A") -> 9 | Q13: =IFERROR(ABS(L$3-L13),"N/A") -> 3 | R13: =IFERROR(ABS(M$3-M13),"N/A") -> 10 | S13: =IFERROR(ABS(N$3-N13),"N/A") -> 8 | T13: =IFERROR(ABS(O$3-O13),"N/A") -> 9 | U13: =SUM(P13:T13) -> 39 | V13: =_xlfn.RANK.EQ(U13,$U$4:$U$14,1) -> 11 | W13: =IF(Y13="Not suitable","-",V13) -> 11 | Y13: =IF(OR(Z13="Y",AA13="Y"),"Not suitable","") | Z13: =IF(N13="N/A","Y","") | AE13: By Consolidated Average | AJ13: =AVERAGE(AJ12:AL12) -> 333.5594 | AM13: =AVERAGE(AM12:AN12) -> 244.66272
B14: ALHC.OQ | C14: Alignment Healthcare Inc | D14: Managed Healthcare | E14: United States of America | F14: -0.62840261 | G14: -1.2318875 | H14: 1.4674143e+09 | I14: -0.77 | J14: -0.091227681 | K14: =IFERROR(_xlfn.RANK.EQ(F14,F$3:F$14),"N/A") -> 11 | L14: =IFERROR(_xlfn.RANK.EQ(G14,G$3:G$14),"N/A") -> 11 | M14: =IFERROR(_xlfn.RANK.EQ(H14,H$3:H$14),"N/A") -> 9 | N14: =IFERROR(_xlfn.RANK.EQ(I14,I$3:I$14),"N/A") -> 12 | O14: =IFERROR(_xlfn.RANK.EQ(J14,J$3:J$14),"N/A") -> 11 | P14: =IFERROR(ABS(K$3-K14),"N/A") -> 8 | Q14: =IFERROR(ABS(L$3-L14),"N/A") -> 4 | R14: =IFERROR(ABS(M$3-M14),"N/A") -> 8 | S14: =IFERROR(ABS(N$3-N14),"N/A") -> 9 | T14: =IFERROR(ABS(O$3-O14),"N/A") -> 8 | U14: =SUM(P14:T14) -> 37 | V14: =_xlfn.RANK.EQ(U14,$U$4:$U$14,1) -> 10 | W14: =IF(Y14="Not suitable","-",V14) -> 10 | Y14: =IF(OR(Z14="Y",AA14="Y"),"Not suitable","") | Z14: =IF(N14="N/A","Y","") | AE14: Upside | AJ14: =AJ13/OP!C20-1 -> -0.3625604 | AM14: =AM13 /OP!C20-1 -> -0.53244397
Y15: =IF(OR(Z15="Y",AA15="Y"),"Not suitable","") | Z15: =IF(N15="N/A","Y","")

Sheet Peers
B1: Peer Logo | C1: Peer Name | D1: Description
C2: #VALUE! | D2: {=_FV(C2,"Description")} -> Elevance Health, Inc. is a health company. It operates as a health insurer in the United States. The Company operates through four segments: Health Benefit, CarelonRx, Carelon Services, and Corporate & Other. The Health Benefits segment offers a comprehensive suite of health plans and services to Individual, employer group risk-based, employer group fee-based, BlueCard, Medicare, Medicaid and federal employees health benefits (FEHB) program members. The CarelonRx segment includes its pharmacy business. CarelonRx markets and offers pharmacy services to affiliated health plan customers, as well as to external customers outside of the health plans. It also offers infusible and injectable therapies. Carelon Services offers healthcare-related services and capabilities to internal and external customers including integrated care delivery, behavioral health, palliative care, utilization management, payment integrity services and subrogation services, as well as health and wellness programs.
C3: #VALUE! | D3: {=_FV(C3,"Description")} -> CVS Health Corporation is a health solutions company. The Company operates in four segments: Health Care Benefits, Health Services, Pharmacy & Consumer Wellness, and Corporate/Other. Its Health Care Benefits segment offer a range of traditional, voluntary and consumer-directed health insurance products and related services, including medical, pharmacy, dental and behavioral health plans, medical management capabilities, Medicare Advantage and Medicare supplement plans, and Medicaid health care management services. Its Health Services segment provides a full range of pharmacy benefit management solutions, delivers health care services in its medical clinics, virtually, and in the home, and offers provider enablement solutions. The Pharmacy & Consumer Wellness segment dispenses prescriptions in its retail pharmacies and through its infusion operations, provides ancillary pharmacy services, including pharmacy patient care programs, diagnostic testing and vaccination administration.
C4: #VALUE! | D4: {=_FV(C4,"Description")} -> Humana Inc. is a healthcare company. It operates through two segments: Insurance and CenterWell. The Insurance segment consists of Medicare benefits, marketed to individuals or directly through group Medicare accounts. It also includes its contract with the Centers for Medicare and Medicaid Services (CMS) to administer the Limited Income Newly Eligible Transition (LI-NET), a prescription drug plan program and contracts with various states to provide Medicaid, dual eligible demonstration, and Long-Term Support Services benefits. It also includes products consisting of employer group commercial fully insured medical and specialty health insurance benefits. The CenterWell segment includes pharmacy solutions, primary care, and home solutions operations. It also includes its strategic partnerships with Welsh, Carson, Anderson & Stowe (WCAS) to develop and operate senior-focused, payor-agnostic, primary care centers, as well as a minority ownership interest in Gentiva Hospice operations.
B6: In Millions USD | C6: =OP!E2 -> UNITEDHEALTH GROUP INCORPORATED (XNYS:UNH) | D6: =C2 -> #VALUE! | E6: =C3 -> #VALUE! | F6: =C4 -> #VALUE! | G6: AVERAGE | H6: Deviation from Average
B7: Company Info | G7: =IFERROR(AVERAGE(A7:F7),"") | L7: TRAFFIC
B8: Market Cap | C8: =OP!C22 -> 483994.91 | D8: {=_FV(D6,"Market cap",TRUE)/1000000} -> 127732 | E8: {=_FV(E6,"Market cap",TRUE)/1000000} -> 72937.64 | F8: {=_FV(F6,"Market cap",TRUE)/1000000} -> 38716.36 | G8: =IFERROR(AVERAGE($C$8:$F$8),"") -> 180845.23 | H8: =SQRT(($C$8-$G$8)^2) -> 303149.68 | M8: Best Value
B9: Net Sales (current) | C9: =C54 -> 324162 | D9: =D54 -> 155660 | E9: =E54 -> 321629 | F9: =F54 -> 92488 | G9: =IFERROR(AVERAGE($C$9:$F$9),"") -> 223484.75 | H9: =SQRT(($C$9-$G$9)^2) -> 100677.25
B10: Profitability | G10: =IFERROR(AVERAGE(A10:F10),"") | M10: Important Value
B11: Sales Growth (ttm) | C11: =C54/C53-1 -> 0.12713971 | D11: =D54/D53-1 -> 0.1366773 | E11: =E54/E53-1 -> 0.10558863 | F11: =F54/F53-1 -> 0.11596704 | G11: =IFERROR(AVERAGE($C$11:$F$11),"") -> 0.12134317 | H11: =SQRT(($C$11-$G$11)^2) -> 0.0057965419
B12: Sales Growth (36m) | C12: =C54/C52-1 -> 0.33865499 | D12: =D54/D52-1 -> 0.50919615 | E12: =E54/E52-1 -> 0.25751764 | F12: =F54/F52-1 -> 0.43643903 | G12: =IFERROR(AVERAGE($C$12:$F$12),"") -> 0.38545195 | H12: =SQRT(($C$12-$G$12)^2) -> 0.046796961 | M12: Worst Value
B13: Operating Margin | C13: =C57/C54 -> 0.087718486 | D13: =D57/D54 -> 0.055377104 | E13: =E57/E54 -> 0.024083649 | F13: =F57/F54 -> 0.041086411 | G13: =IFERROR(AVERAGE($C$13:$F$13),"") -> 0.052066413 | H13: =SQRT(($C$13-$G$13)^2) -> 0.035652074
B14: Net Income Margin | C14: =C60/C54 -> 0.063668783 | D14: =D60/D54 -> 0.038667609 | E14: =E60/E54 -> 0.012949703 | F14: =F60/F54 -> 0.030295822 | G14: =IFERROR(AVERAGE($C$14:$F$14),"") -> 0.036395479 | H14: =SQRT(($C$14-$G$14)^2) -> 0.027273304
B15: Return on Equity (RoE) | C15: =C60/C72 -> 0.26537829 | D15: =D60/D72 -> 0.1657807 | E15: =E60/E72 -> 0.058402861 | F15: =F60/F72 -> 0.18230319 | G15: =IFERROR(AVERAGE($C$15:$F$15),"") -> 0.16796626 | H15: =SQRT(($C$15-$G$15)^2) -> 0.097412026
B16: Return on Invested Capital (ROIC) | C16: =(C60+C59)/(C71+C72) -> 0.10574275 | D16: =(D60+D59)/(D71+D72) -> 0.070654243 | E16: =(E60+E59)/(E71+E72) -> 0.019021873 | F16: =(F60+F59)/(F71+F72) -> 0.13449564 | G16: =IFERROR(AVERAGE($C$16:$F$16),"") -> 0.082478626 | H16: =SQRT(($C$16-$G$16)^2) -> 0.023264122
B17: Solvency | G17: =IFERROR(AVERAGE(A17:F17),"")
B18: Debt/Assets | C18: =C71/C68 -> 0.25830569 | D18: =D71/D68 -> 0.23463589 | E18: =E71/E68 -> 0.30985434 | F18: =F71/F68 -> 0.25848334 | G18: =IFERROR(AVERAGE($C$18:$F$18),"") -> 0.26531982 | H18: =SQRT(($C$18-$G$18)^2) -> 0.0070141238
B19: Net Debt/EBITDA | C19: =(C71-C63)/C56 -> 1.1168839 | D19: =(D71-D63)/D56 -> 1.7819325 | E19: =(E71-E63)/E56 -> 4.7514389 | F19: =(F71-F63)/F56 -> 1.3457529 | G19: =IFERROR(AVERAGE($C$19:$F$19),"") -> 2.2490021 | H19: =SQRT(($C$19-$G$19)^2) -> 1.1321181
B20: Interest Coverage Ratio | C20: =-C56/C58 -> 15.217495 | D20: =-D56/D58 -> 11.030552 | E20: =-E56/E58 -> 5.3178837 | F20: =-F56/F58 -> 11.244389 | G20: =IFERROR(AVERAGE($C$20:$F$20),"") -> 10.70258 | H20: =SQRT(($C$20-$G$20)^2) -> 4.5149152
B21: Liquidity
B22: Current Ratio | C22: =C66/C70 -> 0.77399509 | D22: =D66/D70 -> 1.4010732 | E22: =E66/E70 -> 0.94186647 | F22: =F66/F70 -> 1.524217 | G22: =IFERROR(AVERAGE($C$22:$F$22),"") -> 1.1602879 | H22: =SQRT(($C$22-$G$22)^2) -> 0.38629284
B23: Quick Ratio | C23: =(C63+C64)/C70 -> 0.65400002 | D23: =(D63+D64)/D70 -> 0.59026098 | E23: =(E63+E64)/E70 -> 0.57676093 | F23: =(F63+F64)/F70 -> 0.39207125 | G23: =IFERROR(AVERAGE($C$23:$F$23),"") -> 0.5532733 | H23: =SQRT(($C$23-$G$23)^2) -> 0.10072673
B24: Activity | G24: =IFERROR(AVERAGE(A24:F24),"")
B25: Inventory Turnover | C25: =C55/C65 -> 1.3743425 | D25: 0 | E25: =E55/E65 -> 10.313882 | F25: 0 | G25: =IFERROR(AVERAGE($C$25:$F$25),"") -> 2.922056 | H25: =SQRT(($C$25-$G$25)^2) -> 1.5477136
B26: Acc. Receivable Turnover | C26: =C54/C64 -> 10.645714 | D26: =D54/D64 -> 9.7020693 | E26: =E54/E64 -> 11.791648 | F26: =F54/F64 -> 55.249701 | G26: =IFERROR(AVERAGE($C$26:$F$26),"") -> 21.847283 | H26: =SQRT(($C$26-$G$26)^2) -> 11.201569
A27: Price/Sales | B27: Payables Turnover | C27: =C55/C69 -> 0.59366578 | D27: =D55/D70 -> 0.32837062 | E27: =E55/E70 -> 2.8233911 | F27: =F55/F70 -> 0 | G27: =IFERROR(AVERAGE($C$27:$F$27),"") -> 0.93635687 | H27: =SQRT(($C$27-$G$27)^2) -> 0.34269109
B28: Fixed Asset Turnover | C28: =C54/C67 -> 32.006517 | D28: =D54/D67 -> 36.065802 | E28: =E54/E67 -> 24.984774 | F28: =F54/F67 -> 28.714064 | G28: =IFERROR(AVERAGE($C$28:$F$28),"") -> 30.442789 | H28: =SQRT(($C$28-$G$28)^2) -> 1.5637275
B29: Total Asset Turnover | C29: =C54/C68 -> 1.3193138 | D29: =D54/D68 -> 1.5146149 | E29: =E54/E68 -> 1.4089541 | F29: =F54/F68 -> 2.1481361 | G29: =IFERROR(AVERAGE($C$29:$F$29),"") -> 1.5977547 | H29: =SQRT(($C$29-$G$29)^2) -> 0.27844091
B30: Valuation | G30: =IFERROR(AVERAGE(A30:F30),"")
B31: Price/Earnings | C31: =C8/C60 -> 23.450502 | D31: =D8/D60 -> 21.221465 | E31: =E8/E60 -> 17.512038 | F31: =F8/F60 -> 13.817402 | G31: =IFERROR(AVERAGE($C$31:$F$31),"") -> 19.000352 | H31: =SQRT(($C$31-$G$31)^2) -> 4.4501501
B32: Price/Sales | C32: =C8/C54 -> 1.4930649 | D32: =D8/D54 -> 0.82058332 | E32: =E8/E54 -> 0.22677569 | F32: =F8/F54 -> 0.41860955 | G32: =IFERROR(AVERAGE($C$32:$F$32),"") -> 0.73975837 | H32: =SQRT(($C$32-$G$32)^2) -> 0.75330655
B33: Price/Book | C33: =C8/C72 -> 6.223254 | D33: =D8/D72 -> 3.5181095 | E33: =E8/E72 -> 1.0227531 | F33: =F8/F72 -> 2.5189564 | G33: =IFERROR(AVERAGE($C$33:$F$33),"") -> 3.3207683 | H33: =SQRT(($C$33-$G$33)^2) -> 2.9024858
B34: EV/Sales | C34: =(C71+C8-C63)/C54 -> 1.6027508 | D34: =(D71+D8-D63)/D54 -> 0.92804189 | E34: =(E71+E8-E63)/E54 -> 0.40644544 | F34: =(F71+F8-F63)/F54 -> 0.48421806 | G34: =IFERROR(AVERAGE($C$34:$F$34),"") -> 0.85536405 | H34: =SQRT(($C$34-$G$34)^2) -> 0.74738677
B35: EV/EBITDA | C35: =(C71+C8-C63)/C56 -> 16.320117 | D35: =(D71+D8-D63)/D56 -> 15.389262 | E35: =(E71+E8-E63)/E56 -> 10.748614 | F35: =(F71+F8-F63)/F56 -> 9.9322156 | G35: =IFERROR(AVERAGE($C$35:$F$35),"") -> 13.097552 | H35: =SQRT(($C$35-$G$35)^2) -> 3.2225647
B36: Stock Info | G36: =IFERROR(AVERAGE(A36:F36),"")
B37: Float | C37: =OP!M20 -> 0.996 | D37: 0.995 | E37: 0.9924 | F37: 0.9967 | G37: =IFERROR(AVERAGE($C$37:$F$37),"") -> 0.995025 | H37: =SQRT(($C$37-$G$37)^2) -> 0.000975
B38: b (Yahoo) | C38: =OP!M22 -> 0.55 | D38: 0.78 | E38: 0.49 | F38: 0.47 | G38: =IFERROR(AVERAGE($C$38:$F$38),"") -> 0.5725 | H38: =SQRT(($C$38-$G$38)^2) -> 0.0225
B39: Dividend Yield (yahoo finance) | C39: =[2]OP1!M32 -> 0.011818344 | D39: 0.0128 | E39: 3.49% | F39: 0.0096 | G39: =IFERROR(AVERAGE($C$39:$F$39),"") -> 0.011406115 | H39: =SQRT(($C$39-$G$39)^2) -> 0.00041222939
B40: Stock Performance
B41: 1y | C41: 0.0658 | D41: 0.0519 | E41: -0.125 | F41: -0.271 | G41: =IFERROR(AVERAGE($C$41:$F$41),"") -> -0.069575 | H41: =SQRT(($C$41-$G$41)^2) -> 0.135375
...

Sheet ESG
B1: Company GICS Sector: | T1: Yes
B2: Health Care | T2: No
B3: ESG Analysis | K3: Relative ESG Analysis
B4: Parameters | C4: Impact | D4: Do they report? | E4: Ranking | F4: Mitigation Plan | G4: Traffic Lights | H4: Improvement over time? | I4: Targets / Goals? | J4: Comments | K4: Parameters | L4: UNITEDHEALTH GROUP INCORPORATED (XNYS:UNH) | M4: ELEVANCE HEALTH, INC. (XNYS:ELV) | N4: CVS HEALTH CORPORATION (XNYS:CVS) | O4: HUMANA INC. (XNYS:HUM) | P4: AVERAGE | Q4: Deviation from Average | R4: AVERAGE
B5: Environmental | K5: Ratios
A6: 1 | B6: CO2 Direct Emissions | C6: =VLOOKUP($B$2,'Sector Impact'!$K$4:$AA$16,A6+1,FALSE) -> Low | D6: Yes | E6: Medium | F6: Yes | H6: No | I6: Operational net-zero by 2035 | J6: Operational net-zero by 2035, with 60% scope 1 and 2 reduction and 100% renewable energy by 2030 | K6: CO2 Emissions/$M Sales | L6: =L12/L$11 -> 0.00037758898 | M6: =M12/M$11 -> 0.00010086085 | N6: =N12/N$11 -> 0.00077729309 | O6: =O12/O$11 -> 0.00051249892 | P6: =P12/P$11 -> 0.00048716971 | Q6: =Q12/Q$11 -> 0.00013434018 | R6: =IFERROR(AVERAGE(L6:Q6),"") -> 0.00039829196
A7: 2 | B7: Total Water Consumption | C7: =VLOOKUP($B$2,'Sector Impact'!$K$4:$AA$16,A7+1,FALSE) -> Medium | D7: Yes | E7: Medium High | F7: Yes | H7: Yes | I7: UnitedHealth Group plan to create a holistic approach to water conservation across the enterprise, including creating design guidelines for water efficiency and water quality. | J7: UNH have plumbing and irrigation projects, as well as sustainable landscape projects to reduce their water usage. In 2021 they implemented a holistic water-tracking program, that showed that 47% of total water usage is currently treated/recycled water instead of fresh water. In 2022 they expanded this effort. | K7: Water Consumption/$M Sales | L7: =L13/L$11 -> 0.0013184766 | M7: =M13/M$11 -> 0.0010381601 | N7: =N13/N$11 -> 0.0054876892 | O7: =O13/O$11 -> 0.0081556526 | P7: =P13/P$11 -> 0.0034770829 | Q7: =Q13/Q$11 -> 0.0034732276 | R7: =IFERROR(AVERAGE(L7:Q7),"") -> 0.0038250482
A8: 3 | B8: Total Energy Consumption | C8: =VLOOKUP($B$2,'Sector Impact'!$K$4:$AA$16,A8+1,FALSE) -> Low | E8: Medium | F8: Yes | H8: No | K8: Energy Consumption/$M Sales | L8: =L14/L$11 -> 0.0048876796 | M8: =M14/M$11 -> 0.0015810099 | N8: =N14/N$11 -> 0.0096468291 | O8: =O14/O$11 -> 0.0038859095 | P8: =P14/P$11 -> 0.0059205382 | Q8: =Q14/Q$11 -> 0.0025949259 | R8: =IFERROR(AVERAGE(L8:Q8),"") -> 0.0047528154
A9: 4 | B9: Waste Management | C9: =VLOOKUP($B$2,'Sector Impact'!$K$4:$AA$16,A9+1,FALSE) -> Low | D9: Yes | E9: "Villain" | F9: Yes | H9: No | K9: Waste Production/$M Sales | L9: =L15/L$11 -> 0.00030848773 | M9: =M15/M$11 -> 7.7091096e-06 | N9: =N15/N$11 -> 2.9848055e-05 | O9: =O15/O$11 -> 9.62287e-05 | P9: =P15/P$11 -> 0.00013390175 | Q9: =Q15/Q$11 -> 0.0006960361 | R9: =IFERROR(AVERAGE(L9:Q9),"") -> 0.00021203524
A10: 5 | B10: Land Degradation/Deforestation/Biodiversity loss/Animal sufering/… | C10: =VLOOKUP($B$2,'Sector Impact'!$K$4:$AA$16,A10+1,FALSE) -> Low | D10: No | K10: Inputs
B11: Social | K11: Net Sales ($M) | L11: 324162 | M11: 155660 | N11: 321629 | O11: 92488 | P11: =IFERROR(AVERAGE($L$11:$O$11),"") -> 223484.75 | Q11: =SQRT(($L$11-$P$11)^2) -> 100677.25
A12: 6 | B12: Employee Turnover % | C12: =VLOOKUP($B$2,'Sector Impact'!$K$4:$AA$16,A12+1,FALSE) -> Low | D12: Yes | F12: No | H12: No | I12: None | J12: UNH had an employee turnover of 20% in 2022. | K12: CO2 Emissions Total (Tonnes) | L12: 122.4 | M12: 15.7 | N12: 250 | O12: 47.4 | P12: =IFERROR(AVERAGE($L$12:$O$12),"") -> 108.875 | Q12: =SQRT(($L$12-$P$12)^2) -> 13.525
A13: 7 | B13: Salaries & Compensation | C13: =VLOOKUP($B$2,'Sector Impact'!$K$4:$AA$16,A13+1,FALSE) -> Low | J13: Diference between highest and lowest paid: $180k. Highest paid sector: Legal, with over 182k. Lowest paid sector: Administration, with barely 59k. Workers say they are being paid fairly and are also satisfied with UNH perks and benefits. | K13: Water Consumption Total (Cubic Meters) | L13: =1810-1382.6 -> 427.4 | M13: 161.6 | N13: 1765 | O13: 754.3 | P13: =IFERROR(AVERAGE($L$13:$O$13),"") -> 777.075 | Q13: =SQRT(($L$13-$P$13)^2) -> 349.675
A14: 8 | B14: Reputation | C14: =VLOOKUP($B$2,'Sector Impact'!$K$4:$AA$16,A14+1,FALSE) -> Medium | D14: Yes | E14: Medium | F14: No | I14: None | J14: UNH is facing a class action lawsuit by KKR-owned doctors group for breache the contract between the two companies by unilaterally reducing reimbursement rates for its physician’s services and not paid its bills. UNH is also facing a action lawsuit for following an algorithm that overrode physicians recommendations, and denied eldery pations claims for stays extended care facilities. Also, back in 2019, it was discovered that an algorithm sold by Optum significantly underestimated the amount of care black patients need compared with white patients | K14: Energy Consumption Total (Gigajoules) | L14: 1584.4 | M14: 246.1 | N14: 3102.7 | O14: 359.4 | P14: =IFERROR(AVERAGE($L$14:$O$14),"") -> 1323.15 | Q14: =SQRT(($L$14-$P$14)^2) -> 261.25
A15: 9 | B15: Discrimination Events | C15: =VLOOKUP($B$2,'Sector Impact'!$K$4:$AA$16,A15+1,FALSE) -> Low | F15: Yes | K15: Waste Production Total (Tonnes) | L15: 100 | M15: 1.2 | N15: 9.6 | O15: 8.9 | P15: =IFERROR(AVERAGE($L$15:$O$15),"") -> 29.925 | Q15: =SQRT(($L$15-$P$15)^2) -> 70.075
A16: 10 | B16: Work Safety | C16: =VLOOKUP($B$2,'Sector Impact'!$K$4:$AA$16,A16+1,FALSE) -> High | D16: No | E16: "Best in class" | F16: No | I16: None | J16: UNH did not state any accident | K16: ESG Scores
A17: 11 | B17: Damage to consumer health | C17: =VLOOKUP($B$2,'Sector Impact'!$K$4:$AA$16,A17+1,FALSE) -> Low | D17: Yes | F17: Yes | H17: Yes | I17: None | J17: It's a health company. | K17: Refinitiv | L17: 80 | M17: 83 | N17: 91 | O17: 88 | P17: 85.5 | Q17: 5.5
A18: 12 | B18: PXP? | C18: =VLOOKUP($B$2,'Sector Impact'!$K$4:$AA$16,A18+1,FALSE) -> Low | K18: Sustainalytics | L18: 15.3 | M18: 10.6 | N18: 22 | O18: 22.5 | P18: 17.6 | Q18: 2.3
A19: 13 | B19: Supply chain | C19: =VLOOKUP($B$2,'Sector Impact'!$K$4:$AA$16,A19+1,FALSE) -> Low | D19: Yes | H19: None | I19: UNH plan to improve their emissions calculation and assess supplier performance with the help of some select suppliers, as well as update supplier trainings. | K19: ISS | L19: C+ | M19: B- | N19: C | O19: C+ | P19: C | Q19: -
A20: 14 | B20: Community involvement | C20: =VLOOKUP($B$2,'Sector Impact'!$K$4:$AA$16,A20+1,FALSE) -> Low | I20: h | K20: CDP | L20: B | M20: B | N20: B | O20: B | P20: B | Q20: -
A21: 15 | B21: Public Sector | C21: =VLOOKUP($B$2,'Sector Impact'!$K$4:$AA$16,A21+1,FALSE) -> Low | D21: Yes | I21: None | J21: UnitedHealthcare is subject to extensive government regulation. During the 2022 election cycle, UNH contributed at least $360,000 to members of congress who opposed federal voting rights legislation, and key UNH staff have made large contributions totaling $37,300 to anti-democracy federal legislators. UNH has released statements in support of democracy
A22: 16 | B22: Litigation | C22: =VLOOKUP($B$2,'Sector Impact'!$K$4:$AA$16,A22+1,FALSE) -> Low | D22: Yes
B23: Corporate Governance | K23: PARAMETERS
A24: 17 | B24: Diversity (Gender, Age, Industry, Region) | E24: Medium High | F24: No | I24: There are not any especific goals regarding diversity | J24: 1/3 of the directors nominees are ethically diverse, 1/3 are women and 2/9 are African American | K24: IMPACT | L24: RANKING | M24: MITIGATION PLAN | O24: TRAFFIC
A25: 17 | B25: % Independence | E25: Medium High | F25: No | I25: Nothing is stated | J25: 78% of the Board members are independent | K25: Low | L25: "Best in class" | M25: Is there evidence of a plan/program ?
A26: 17 | B26: average time as independent directors | E26: Medium High | F26: No | I26: Nothing is stated | J26: All board members apart from the CEO and the Chairman are independent | K26: Medium | L26: Medium High
A27: 17 | B27: Recent departures of directors / C-level executives? | E27: Medium High | F27: No | I27: UNH target´s is to keep the average tenue of the board below 7 years | J27: UNH strives to maintain a balance of tenure on the Board. Long-serving directors bring experience while newer directors contribute fresh perspective | K27: High | L27: Medium
A28: 17 | B28: CEO/Chairman duality | E28: "Best in class" | F28: No | I28: Nothing is stated | J28: UHN separates CEO and Chair of the Board | K28: Very high | L28: "Villain"
A29: 17 | B29: Transparency (ESG, segments, acquisitions, other) | E29: "Best in class" | F29: No | I29: Nothing is stated | J29: UNH does a ful disclosure of corporate governance policies and pratices
A30: 17 | B30: Time taken to report after the end of the quarter / year | E30: "Best in class" | F30: No | I30: Nothing is stated | J30: The audit is done by an independant consulting firm and is completely independent from the UHN
A31: 17 | B31: Additional participation of the CEO in other boards or excessive participation of Ch. | E31: Medium High | F31: No | I31: Nothing is stated | J31: The CEO and the Chairman are the only board members who are not independent, therefore they participate in other boards
A32: 17 | B32: Audit / Consulting | D32: Yes | E32: "Best in class" | F32: No | I32: Nothing is stated | J32: The company uses an independent consultant (Delloitte & Touche LLP) to assure transparency. Delloite & Touche LLP is responsible for consolidated financinal statements, internal control over financial reporting, quarterly reviews, other statutory and legal entity audtis and consultations on techinal matters
A33: 17 | B33: ESG-compensation related | D33: No | E33: Medium | F33: No | I33: Nothing is stated | J33: They don't state nothing about it.
A34: 17 | B34: Management compensation schemes | D34: Yes | E34: Medium High | F34: No | I34: Nothing is stated | J34: The company as a compensation scheme in two ways: Cash and stocks
U48: GHG Scope 1 Emissions (tonnes) | AC48: Net Sales ($M) | AK48: GHG Scope 1 Emissions / Net Sales ($M)
U49: UNH | V49: ELV | W49: CVS | X49: HUM | AC49: UNH | AD49: ELV | AE49: CVS | AF49: HUM | AK49: UNH | AL49: ELV | AM49: CVS | AN49: HUM
T50: 2011 | U50: X | V50: X | W50: 234.1 | X50: X | AB50: 2011 | AC50: 101862 | AD50: 60710.7 | AE50: 107100 | AF50: =36832 -> 36832 | AJ50: 2011 | AM50: =W50/AE50 -> 0.0021858077
T51: 2012 | U51: X | V51: X | W51: 156.1 | X51: 12.7 | AB51: 2012 | AC51: 110618 | AD51: 61497.2 | AE51: 123133 | AF51: =39126 -> 39126 | AJ51: 2012 | AM51: =W51/AE51 -> 0.0012677349 | AN51: =X51/AF51 -> 0.00032459234
T52: 2013 | U52: X | V52: X | W52: 245.6 | X52: 17.5 | AB52: 2013 | AC52: 122489 | AD52: 71023.5 | AE52: 126761 | AF52: =41313 -> 41313 | AJ52: 2013 | AM52: =W52/AE52 -> 0.0019375044 | AN52: =X52/AF52 -> 0.00042359548
T53: 2014 | U53: X | V53: X | W53: 188.5 | X53: 16.9 | AB53: 2014 | AC53: 130474 | AD53: 73874.1 | AE53: 139367 | AF53: =48500 -> 48500 | AJ53: 2014 | AM53: =W53/AE53 -> 0.001352544 | AN53: =X53/AF53 -> 0.00034845361
...

Sheet DCF
A1: VALUATION MODEL
G3: Short Term | K3: Long Term
A4: Section | B4: Line # | C4: ITEM | D4: 2020 (Real) | E4: 2021 (Real) | F4: 2022 (Real) | G4: 2023 | H4: =G4+1 -> 2024 | I4: =H4+1 -> 2025 | J4: =I4+1 -> 2026 | K4: =J4+1 -> 2027 | L4: =K4+1 -> 2028 | M4: =L4+1 -> 2029 | N4: =M4+1 -> 2030 | O4: =N4+1 -> 2031 | ... AF4: =AE4+1 -> 2048
A5: INCOME STATEMENT | B5: 1 | C5: Growth | D5: ='Fin. Data'!D6 -> 0.061885982 | E5: =+E6/D6-1 -> 0.11844086 | F5: =+F6/E6-1 -> 0.12713971 | G5: =+G6/F6-1 -> 0.14809822 | H5: =+H6/G6-1 -> 0.087109583 | I5: =+I6/H6-1 -> 0.095035682 | J5: =+J6/I6-1 -> 0.11791771 | K5: =+K6/J6-1 -> 0.11791771 | L5: =+L6/K6-1 -> 0.093633333 | ... AF5: =+AF6/AE6-1 -> 0.02
B6: 2 | C6: Revenues/Sales | D6: =Inputs!D6 -> 257141 | E6: =Inputs!C6 -> 287597 | F6: =Inputs!B6 -> 324162 | G6: =Assumptions!G43 -> 372169.82 | H6: =Assumptions!H43 -> 404589.37 | I6: =Assumptions!I43 -> 443039.8 | J6: =Assumptions!J43 -> 495282.04 | K6: =Assumptions!K43 -> 553684.57 | L6: =Assumptions!L43 -> 605527.9 | M6: =Assumptions!M43 -> 662225.49 | N6: =Assumptions!N43 -> 724231.87 | ... AF6: =Assumptions!AF43 -> 1274956.7
B7: 3 | C7: EBIT/Operating Margin | D7: =D8/D6 -> 0.087131185 | E7: =E8/E6 -> 0.083345793 | F7: =F8/F6 -> 0.087718486 | G7: 0.0885 | H7: 0.087 | I7: 0.086 | J7: 0.082 | K7: =Assumptions!$L$15 -> 0.079659229 | L7: =7.97% -> 0.0797 | M7: =7.97% -> 0.0797 | N7: =7.97% -> 0.0797 | O7: =7.97% -> 0.0797 | P7: =7.97% -> 0.0797 | Q7: =7.97% -> 0.0797 | R7: =7.97% -> 0.0797 | S7: =7.97% -> 0.0797 | ... AE7: =7.97% -> 0.0797 | AF7: 0.0797
B8: 4 | C8: EBIT | D8: ='Fin. Data'!D11 -> 22405 | E8: ='Fin. Data'!C11 -> 23970 | F8: ='Fin. Data'!B11 -> 28435 | G8: =G7*G6 -> 32937.029 | H8: =H7*H6 -> 35199.276 | I8: =I7*I6 -> 38101.423 | J8: =J7*J6 -> 40613.127 | K8: =K7*K6 -> 44106.085 | L8: =L7*L6 -> 48260.573 | M8: =M7*M6 -> 52779.372 | N8: =N7*N6 -> 57721.28 | ... AF8: =AF7*AF6 -> 101614.05
B9: 5a | C9: (Dep) | D9: -1450 | E9: -1560 | F9: -1700 | G9: =$D$53*DCF!F40 -> -1754.5796 | H9: =$D$53*DCF!G40 -> -2060.8296 | I9: =$D$53*DCF!H40 -> -2393.7569 | J9: =$D$53*DCF!I40 -> -2758.3242 | K9: =$E$53*DCF!J40 -> -3505.223 | L9: =$E$53*DCF!K40 -> -4009.6735 | M9: =$E$53*DCF!L40 -> -4561.3573 | N9: =$E$53*DCF!M40 -> -5164.6971 | O9: =$E$53*DCF!N40 -> -5824.5297 | P9: =$E$53*DCF!O40 -> -6546.1446 | Q9: =$E$53*DCF!P40 -> -7335.3266 | R9: =$E$53*DCF!Q40 -> -8198.4025 | ... AF9: =$E$53*DCF!AE40 -> -22260.857 | AG9: =SUM(D9:AF9) -> -274549.51
B10: 5b | C10: Amort | D10: -1441 | E10: -1543 | F10: -1700 | G10: =F38*$D$54 -> -1831.1782 | H10: =G38*$D$54 -> -1860.6208 | I10: =H38*$D$54 -> -1890.5367 | J10: =I38*$D$54 -> -1920.9337 | K10: =J38*$E$54 -> -1712.3955 | L10: =K38*$E$54 -> -1736.5509 | M10: =L38*$E$54 -> -1761.047 | N10: =M38*$E$54 -> -1785.8886 | O10: =N38*$E$54 -> -1811.0807 | P10: =O38*$E$54 -> -1836.6282 | Q10: =P38*$E$54 -> -1862.536 | R10: =Q38*$E$54 -> -1888.8092 | ... AF10: =AE38*$E$54 -> -2298.0322
B11: 5c | C11: (Stock based compensation) | D11: -647 | E11: -729 | F11: -875 | G11: =G6*$D$55 -> -987.72182 | H11: =H6*$D$55 -> -1073.7619 | I11: =I6*$D$55 -> -1175.8076 | J11: =J6*$D$55 -> -1314.4561 | K11: =K6*$D$55 -> -1469.4537 | L11: =L6*$D$55 -> -1607.0436 | M11: =M6*$D$55 -> -1757.5164 | N11: =N6*$D$55 -> -1922.0786 | ... AF11: =AF6*$D$55 -> -3383.6772
B12: 6 | C12: EBITDA | D12: =D8-D9-D10 -> 25296 | E12: =E8-E9-E10 -> 27073 | F12: =F8-F9-F10 -> 31835 | G12: =G8-G9-G10 -> 36522.787 | H12: =H8-H9-H10 -> 39120.726 | I12: =I8-I9-I10 -> 42385.717 | J12: =J8-J9-J10 -> 45292.385 | K12: =K8-K9-K10 -> 49323.704 | ... AF12: =AF8-AF9-AF10 -> 126172.94
B13: 7 | C13: (Net financing cost) | D13: ='Fin. Data'!D14 -> -1663 | E13: ='Fin. Data'!C14 -> -1660 | F13: ='Fin. Data'!B14 -> -2092 | G13: =F43*$D$58-F44*$D$57 -> -1059.1611 | H13: =G43*$D$58-G44*$D$57 -> -1013.7534 | I13: =H43*$D$58-H44*$D$57 -> -1074.1282 | J13: =I43*$D$58-I44*$D$57 -> -1097.8406 | K13: =J43*$E$58-J44*$E$57 -> -1685.2453 | L13: =K43*$E$58-K44*$E$57 -> -1789.9198 | M13: =L43*$E$58-L44*$E$57 -> -1930.4154 | N13: =M43*$E$58-M44*$E$57 -> -2088.9274 | O13: =N43*$E$58-N44*$E$57 -> -2263.2042 | P13: =O43*$E$58-O44*$E$57 -> -2455.6338 | Q13: =P43*$E$58-P44*$E$57 -> -2669.1916 | R13: =Q43*$E$58-Q44*$E$57 -> -2905.147 | ... AF13: =AE43*$E$58-AE44*$E$57 -> -6180.7069
B14: 8 | C14: Other income/(cost) | D14: ='Fin. Data'!D15 -> 0 | E14: ='Fin. Data'!C15 -> 0 | F14: ='Fin. Data'!B15 -> 0 | G14: =AVERAGE(D14:F14)*(1+G5) -> 0 | H14: =AVERAGE(E14:G14)*(1+H5) -> 0 | I14: =AVERAGE(F14:H14)*(1+I5) -> 0 | J14: =AVERAGE(G14:I14)*(1+J5) -> 0 | K14: =AVERAGE(H14:J14)*(1+K5) -> 0 | L14: =AVERAGE(I14:K14)*(1+L5) -> 0 | M14: =AVERAGE(J14:L14)*(1+M5) -> 0 | N14: =AVERAGE(K14:M14)*(1+N5) -> 0 | ... AF14: =AVERAGE(AC14:AE14)*(1+AF5) -> 0
B15: 9 | C15: Earnings before taxes | D15: =D8+D13+D14 -> 20742 | E15: =E8+E13+E14 -> 22310 | F15: =F8+F13+F14 -> 26343 | G15: =G8+G13+G14 -> 31877.868 | H15: =H8+H13+H14 -> 34185.522 | I15: =I8+I13+I14 -> 37027.295 | J15: =J8+J13+J14 -> 39515.287 | K15: =K8+K13+K14 -> 42420.84 | ... AF15: =AF8+AF13+AF14 -> 95433.34
B16: 10 | C16: (Income tax) | D16: ='Fin. Data'!D21 -> -4973 | E16: ='Fin. Data'!C21 -> -4578 | F16: ='Fin. Data'!B21 -> -5704 | G16: =-(1*$D$56)*G15 -> -6968.49 | H16: =-(1*$D$56)*H15 -> -7472.9424 | I16: =-(1*$D$56)*I15 -> -8094.1529 | J16: =-(1*$D$56)*J15 -> -8638.027 | K16: =-(1*$E$56)*K15 -> -9273.1799 | L16: =-(1*$E$56)*L15 -> -10158.468 | M16: =-(1*$E$56)*M15 -> -11115.563 | N16: =-(1*$E$56)*N15 -> -12161.212 | O16: =-(1*$E$56)*O15 -> -13304.566 | P16: =-(1*$E$56)*P15 -> -14554.576 | Q16: =-(1*$E$56)*Q15 -> -15920.948 | R16: =-(1*$E$56)*R15 -> -16199.457 | ... AF16: =-(1*$E$56)*AF15 -> -20861.693
B17: 11 | C17: Net income | D17: ='Fin. Data'!D23 -> 15769 | E17: ='Fin. Data'!C23 -> 17732 | F17: ='Fin. Data'!B23 -> 20639 | G17: =G16+G15 -> 24909.378 | H17: =H16+H15 -> 26712.58 | I17: =I16+I15 -> 28933.142 | J17: =J16+J15 -> 30877.26 | K17: =K16+K15 -> 33147.66 | L17: =L16+L15 -> 36312.186 | M17: =M16+M15 -> 39733.393 | N17: =N16+N15 -> 43471.141 | ... AF17: =AF16+AF15 -> 74571.647
