Workbook
Name businessresearchinsights: '[1]Segments- LR'!$D$38,'[1]Segments- LR'!$B$38
Name Sectors: '[2]Sector Impact'!$K$4:$K$16
Name Sectors: 'Sector Impact'!$K$4:$K$16

Sheet OP
B2: 45252 | C2: Team 4 | D2: 44949 | E2: =Inputs!H3 -> #VALUE! | L2: NYSE | M2: SIC:
D3: COMPANY DESCRIPTION | H3: CEO & BOARD OF DIRECTORS
D4: {=_FV(Inputs!H3,"Description")} -> Verizon Communications Inc. is a holding company. The Company, through its subsidiaries, provides communications, information and entertainment products and services to consumers, businesses and governmental agencies. Its reportable segments are Verizon Consumer Group and Verizon Business Group. Its Consumer segment provides wireless and wireline communications services. Its wireless services are provided across wireless networks in the United States (U.S.) under the Verizon brands. Its wireline services are provided in nine states in the Mid-Atlantic and Northeastern U.S., as well as Washington D.C., over its fiber-optic network under the Fios brand and over a traditional copper-based network. Its Business segment provides wireless and wireline communications services and products, including data, video and conferencing services, security and managed network services, local and long-distance voice services and network access to deliver various Internet of Things services and products. | H4: Name | I4: Gender | J4: Age | K4: Tenure | L4: Executive? | M4: Other roles
H5: Hans Vestberg | I5: M | J5: 57 | K5: 5 | L5: Yes | M5: Chairman and Chief Executive Officer of verizon Communications Inc.
H6: Clarence Otis, Jr. | I6: M | J6: 67 | K6: 17 | L6: No | M6: Former Chairmanand Chief executive Officer of Darden Restaurents, Inc.
H7: Shellye L. Archambeau | I7: F | J7: 61 | K7: 10 | L7: No | M7: Former Chief Execituve Officer of MetricStream, Inc.
H8: Roxanne S. Austin | I8: F | J8: 61 | K8: 3 | L8: No | M8: President and Chief Executive Officer of Austin Investement Advisors
H9: Mark T. Bertolini | I9: M | J9: 67 | K9: 8 | L9: No | M9: Chief Executive Officer of Oscar Health, Inc.
H10: Vittorio Colao | I10: M | J10: 61 | K10: 1 | L10: No | M10: Former Italian Minister for Innovation, Digital Transition and Space and Former Chief Executive of Vodafine Group Plc
H11: Melanie L. Healey | I11: F | J11: 62 | K11: 12 | L11: No | M11: Former Group President of The Procter & Gamble Company
H12: Laxman Narasimhan | I12: M | J12: 56 | K12: 2 | L12: No | M12: Chief Executive Officer of Starbucks Corporation
H13: Daniel H. Schulman | I13: M | J13: 65 | K13: 5 | L13: No | M13: Presindet and Chied Executive Officer of PayPal Holdings, Inc.
H14: Rodney E. Slater | I14: M | J14: 68 | K14: 13 | L14: No | M14: Partner at Squire Patton Boggs LLP
H15: Carol B. Tomé | I15: F | J15: 66 | K15: 2 | L15: No | M15: Chief Executive officer, United Parcel Service, Inc.
B16: USD MILLIONS | H16: Gregory G. Weaver | I16: M | J16: 70 | K16: 8 | L16: No | M16: Former Chairman and Chief Executive Officer of Delotte & Touche LLP
B17: COMPANY OVERVIEW
B18: Stock | D18: Liquidity and Solvency | F18: Segments | I18: Profitability (2022) | L18: Multiples
B19: Last Price | C19: {=_FV(E2,"Price")} -> 40.335 | D19: Total Assets | E19: =_xlfn.XLOOKUP(D19,'Fin. Data'!A:A,'Fin. Data'!B:B,,0) -> 379680 | F19: Regions | H19: % Sales | I19: Reporting Year | J19: 2022 | L19: Float | M19: =100%-M20 -> 0.9997
B20: Outstanding Shares | C20: {=_FV(E2,"Shares outstanding",TRUE)} -> 4204272000 | D20: Total Liabilities | E20: =_xlfn.XLOOKUP(D20,'Fin. Data'!A:A,'Fin. Data'!B:B,,0) -> 288536 | F20: =Segments!C5 -> United States (U.S.) | H20: =Segments!B5 -> 1 | I20: End of Year | J20: 1 October 2022 | L20: Insiders Own | M20: 0.0003
B21: Market Cap. | C21: =C19*C20/1000000 -> 169579.31 | D21: Cash/Share | E21: =_xlfn.XLOOKUP("Cash & Eq.",'Fin. Data'!A:A,'Fin. Data'!B:B,,0)*1000000/C20 -> 0.61960787 | I21: EBITDA | K21: =_xlfn.XLOOKUP(I21,'Fin. Data'!A:A,'Fin. Data'!B:B,,0) -> 46193 | L21: b (Yahoo) | M21: 0.33
B22: +Total Debt | C22: ='Fin. Data'!B58 -> 150639 | D22: EBIDTA/Net Financial Cost (NFC) | E22: ='Fin. Data (Common Size)'!B19/(-'Fin. Data (Common Size)'!B14) -> 12.942841 | I22: Depreciation & Amortization | K22: =_xlfn.XLOOKUP(I22,'Fin. Data'!A:A,'Fin. Data'!B:B,,0) -> 17099 | L22: Score (S&P) | M22: BBB+
B23: -Cash | C23: ='Fin. Data'!B39 -> 2605 | D23: Debt/EBITDA | E23: =_xlfn.XLOOKUP("Total Debt",'Fin. Data'!A:A,'Fin. Data'!B:B,,0)/_xlfn.XLOOKUP("EBITDA",'Fin. Data'!A:A,'Fin. Data'!B:B,,0) -> 3.2610785 | I23: EBIT | K23: =_xlfn.XLOOKUP(I23,'Fin. Data'!A:A,'Fin. Data'!B:B,,0) -> 29094 | L23: Price/Book Value | M23: =IFERROR((C19*C20/(E19-E20))/1000000,"") -> 1.8605647
B24: =Enterprise Value | C24: =C21+C22-C23 -> 317613.31 | D24: "Others Assets"/Asset | E24: =_xlfn.XLOOKUP("Other Assets",'Fin. Data'!A:A,'Fin. Data'!B:B,,0)/_xlfn.XLOOKUP("Total Assets",'Fin. Data'!A:A,'Fin. Data'!B:B,,0) -> 0.49888327 | I24: Net Income | K24: =_xlfn.XLOOKUP(I24,'Fin. Data'!A:A,'Fin. Data'!B:B,,0) -> 21748 | L24: NCF(3y avg)/Asset | M24: =IFERROR(K30/E19,"") -> 0.055058646
B25: Holdings (nac/int'l) | C25: - | D25: Debt/Assets | E25: =_xlfn.XLOOKUP(D25,'Fin. Data'!A:A,'Fin. Data'!B:B,,0) -> 0.39675253 | F25: Categories | H25: % Sales | I25: EPS | K25: =1000000*K24/C20 -> 5.1728337 | L25: Price/Net Inc. (3y avg) | M25: =IFERROR(C21/K29,"") -> 8.1120313
B26: t liq. (Holdings/Vol.) | C26: - | D26: EBITDA Margin (average) | E26: =AVERAGE(_xlfn.XLOOKUP("EBITDA Margin",'Fin. Data'!A:A,'Fin. Data'!B:D,,0)) -> 0.35291332 | F26: =Segments!C11 -> Verizon Consumer Group | H26: =Segments!B11 -> 0.75499689 | I26: ROA | K26: =K24/E19 -> 0.057279815 | L26: EV/Asset | M26: =IFERROR(C24/E19,"") -> 0.83652895
B27: % Short | C27: 0.0098 | D27: Operating Margin (average) | E27: =AVERAGE(_xlfn.XLOOKUP("Operating Margin",'Fin. Data'!A:A,'Fin. Data'!B:D,,0)) -> 0.22999265 | F27: =Segments!C12 -> Verizon Business Group | H27: =Segments!B12 -> 0.22700333 | I27: ROIC | K27: =K24/(E19-(E20-C22)) -> 0.089948425 | L27: EV/Ebidta (3y average) | M27: =IFERROR(C24/K28,"") -> 6.7751725
B28: Traffic ESG | D28: Net Income Margin (average) | E28: =AVERAGE(_xlfn.XLOOKUP("Net Income Margin",'Fin. Data'!A:A,'Fin. Data'!B:D,,0)) -> 0.15707779 | F28: =Segments!C13 -> Corporate and other | H28: =Segments!B13 -> 0.017999781 | I28: EBITDA (3y average) | K28: =AVERAGE(_xlfn.XLOOKUP("EBITDA",'Fin. Data'!A:A,'Fin. Data'!B:D,,0)) -> 46879 | L28: Price/NCF (3y average) | M28: =IFERROR(C21/K30,"") -> 8.1120313
B29: E | I29: Net Income (3y average) | K29: =AVERAGE(_xlfn.XLOOKUP("Net Income",'Fin. Data'!A:A,'Fin. Data'!B:D,,0)) -> 20904.667 | L29: Bonds 1,3,5a (USD) | M29: -
B30: S | D30: Net Financial Cost/Avg Net Debt | E30: =-_xlfn.XLOOKUP("Net Financial Cost",'Fin. Data'!A:A,'Fin. Data'!B:B,,0)/AVERAGE(_xlfn.XLOOKUP("Net Debt",'Fin. Data'!A:A,'Fin. Data'!B:D,,0)) -> 0.026576679 | I30: NCF (3y average) | K30: =AVERAGE(_xlfn.XLOOKUP("Net Income",'Fin. Data'!A:A,'Fin. Data'!B:D,,0)) -> 20904.667 | L30: Div+Rep.(3y avg)/Price | M30: =-IFERROR(SUM(E51:E53)/(3*C21),"") -> 0.061882549
B31: G | L31: Div. Yield | M31: =IFERROR(L52/C21,"") -> 0.063716499
B32: INVESTMENT THESIS
B33: Pillars of Recommendation | H33: Recommendation | I33: Valuation Assumptions
B34: Pillar | C34: Explanation | H34: BUY | I34: Check DCF
B35: 5G | C35: Verizon has been leading the development of 5G wireless technology industry standards and the ecosystems for fixed and mobile 5G wireless services.
B36: Steady Demand | C36: It's anticipate that demand will continue to increase over time, driven by growth in customer connections and the increased usage of wireless broadband services that use more bandwidth and require faster rates of speed, providing a reliable source of revenue.
B37: Network quality | C37: Their network differentiation will be the cornerstone of their service revenue growth and that will allow the attraction the highest quality customer base in the industry and maintain a market-leading share of the B2B market.
B38: Risks of Investment | H38: Price Target | I38: Valuation
B39: Risk | C39: Explanation | H39: =DCF!D74 -> 46.729073 | I39: Discount Rate | J39: =DCF!F50 -> 0.1041 | L39: Upside | M39: =DCF!D73 -> 0.15852419
B40: Competitive market | C40: Many other companies have strong market presence, brand recognition and existing customer relationships, all of which contribute to intensifying competition that may affect future revenue growth.
B41: Cybersecurity | C41: The inability to operate or use the networks and systems or those of suppliers, vendors and other service providers as a result of cyber attacks, even for a limited period of time, may result in significant expenses to Verizon and/or a loss of marketshare to our competitors.
...

Sheet Segments
B2: ="Regions "&"("&OP!$J$19&")" -> Regions (2022) | Q2: Products
D3: Nominal value | K3: YoY Growth | AH3: Consumer Segment
B4: Weight | C4: Region | D4: =OP!J19 -> 2022 | E4: =D4-1 -> 2021 | F4: =E4-1 -> 2020 | G4: =F4-1 -> 2019 | H4: =G4-1 -> 2018 | I4: =H4-1 -> 2017 | K4: =OP!J19 -> 2022 | L4: =K4-1 -> 2021 | M4: =L4-1 -> 2020 | N4: =M4-1 -> 2019 | O4: =N4-1 -> 2018 | P4: =O4-1 -> 2017 | Q4: Verizon Consumer Group
B5: =IFERROR(D5/$D$6,"") -> 1 | C5: United States (U.S.) | D5: 136835 | E5: 133613 | F5: 128292 | G5: 131868 | H5: 130863 | I5: 126034 | K5: =(D5-E5)/E5 -> 0.02411442 | L5: =(E5-F5)/F5 -> 0.041475696 | M5: =(F5-G5)/G5 -> -0.027118027 | N5: =(G5-H5)/H5 -> 0.0076797873 | O5: =(H5-I5)/I5 -> 0.038315058 | Q5: Services | R5: 73139
B6: =SUM(B5:B5) -> 1 | C6: TOTAL | D6: =SUM(D5:D5) -> 136835 | E6: =SUM(E5:E5) -> 133613 | F6: =SUM(F5:F5) -> 128292 | G6: =SUM(G5:G5) -> 131868 | H6: =SUM(H5:H5) -> 130863 | I6: =SUM(I5:I5) -> 126034 | K6: =(D6-E6)/E6 -> 0.02411442 | L6: =(E6-F6)/F6 -> 0.041475696 | M6: =(F6-G6)/G6 -> -0.027118027 | N6: =(G6-H6)/H6 -> 0.0076797873 | O6: =(H6-I6)/I6 -> 0.038315058 | P6: 0.037 | Q6: Wireless equipment | R6: 23168
Q7: Other | R7: 7199
B8: ="Categories "&"("&OP!$J$19&")" -> Categories (2022) | Q8: Total Operating Revenues | R8: 103506
D9: Nominal value | K9: YoY Growth
B10: Weight | C10: Category | D10: =OP!J19 -> 2022 | E10: =D10-1 -> 2021 | F10: =E10-1 -> 2020 | G10: =F10-1 -> 2019 | H10: =G10-1 -> 2018 | I10: =H10-1 -> 2017 | K10: =OP!J19 -> 2022 | L10: =K10-1 -> 2021 | M10: =L10-1 -> 2020 | N10: =M10-1 -> 2019 | O10: =N10-1 -> 2018 | P10: =O10-1 -> 2017 | Q10: Verizon Business Group
B11: =IFERROR(D11/$D$14,"") -> 0.75499689 | C11: Verizon Consumer Group | D11: =103310 -> 103310 | E11: 94999 | F11: 88137 | G11: 90725 | H11: 89510 | K11: =(D11-E11)/E11 -> 0.087485131 | L11: =(E11-F11)/F11 -> 0.077856065 | M11: =(F11-G11)/G11 -> -0.028525765 | N11: =(G11-H11)/H11 -> 0.013573902 | O11: =(H11-I11)/I11 -> #DIV/0!
B12: =IFERROR(D12/$D$14,"") -> 0.22700333 | C12: Verizon Business Group | D12: 31062 | E12: 30998 | F12: 30790 | G12: 31385 | H12: 31407 | K12: =(D12-E12)/E12 -> 0.0020646493 | L12: =(E12-F12)/F12 -> 0.0067554401 | M12: =(F12-G12)/G12 -> -0.018958101 | N12: =(G12-H12)/H12 -> -0.00070048078 | O12: =(H12-I12)/I12 -> #DIV/0! | Q12: Small and Medium Business | R12: 12595
B13: =IFERROR(D13/$D$14,"") -> 0.017999781 | C13: Corporate and other | D13: 2463 | E13: 7616 | F13: 9365 | G13: 9758 | H13: 9946 | K13: =(D13-E13)/E13 -> -0.67660189 | L13: =(E13-F13)/F13 -> -0.18675921 | M13: =(F13-G13)/G13 -> -0.040274646 | N13: =(G13-H13)/H13 -> -0.018902071 | O13: =(H13-I13)/I13 -> #DIV/0! | Q13: Global Enterprise | R13: 9733
B14: =SUM(B11:B13) -> 1 | C14: TOTAL | D14: =SUM(D11:D13) -> 136835 | E14: =SUM(E11:E13) -> 133613 | F14: =SUM(F11:F13) -> 128292 | G14: =SUM(G11:G13) -> 131868 | H14: =SUM(H11:H13) -> 130863 | I14: =SUM(I11:I13) -> 0 | K14: =(D14-E14)/E14 -> 0.02411442 | L14: =(E14-F14)/F14 -> 0.041475696 | M14: =(F14-G14)/G14 -> -0.027118027 | N14: =(G14-H14)/H14 -> 0.0076797873 | O14: =(H14-I14)/I14 -> #DIV/0! | P14: 0.037 | Q14: Public Sector and Other | R14: 6117 | AH14: Business Segment
Q15: Wholesale | R15: 2584
B16: Categories | D16: Description | I16: Graphs | Q16: Total Operating Revenues | R16: 31072
B17: Verizon Consumer Group | D17: Provides consumer-focused wireless and wireline communications services and products.
B18: Verizon Business Group | D18: Provides wireless and wireline communications services and products to businesses, government customers and wireless and wireline carriers across the U.S. and select products and services to customers around the world.
B19: Corporate and other | D19: Primarily includes insurance captives, investments in unconsolidated businesses and development stage businesses.
B21: Industry | J21: Graphs (Industry Forecasts)
B22: Drivers | D22: Description
B23: Consumer Satisfaction | D23: Growth based on delivering what customers want and need in the digital world.
B24: 5G Technology Advancements | D24: Deploying new network architecture and technologies to secure leadership in both fourth-generation (4G) and fifth-generation (5G) wireless networks creates new opportunities in the business market in a cost efficient manner.
B25: Cybersecurity | D25: Regulatory changes in this area are important to the development of tecnology and security and managed network services.
B26: Sales forecast
B27: Source | D27: Market Growth CGAR | G27: Period
B28: Grand View Research | D28: 0.062 | G28: 2023-2030
B29: Statista | D29: 0.0202 | G29: 2023-2028
B30: Analysys Mason | D30: 0.0204 | G30: 2021-2026
B31: Transparency Market Research | D31: 0.05 | G31: 2020-2030
B32: Company's Strategy / Extra Notes
B35: To compete effectively in today’s dynamic marketplace, we are focused on the capabilities of our high-performing networks to drive growth based on delivering what customers want and need in the digital world. In 2022, we focused on maintaining our network leadership, including by rapidly deploying C-Band spectrum; retaining and growing our high-quality customer base while balancing profitability in challenging market conditions; and driving monetization of our networks, platforms and solutions. We are creating business value by earning the trust of our stakeholders, limiting our environmental impact and supporting our customer base growth while creating social benefit through our products and services.

Sheet Acuerdo
A1: Invertir
A2: NO invertir
A3: Mantener sin elevar posición
A4: Mantener (y seguir comprando)
A5: Liquidar
A6: PENDIENTE

Sheet Peers
B1: Peer Logo | C1: Peer Name | D1: Description
C2: =D8 -> #VALUE! | D2: AT&T Inc. is a holding company. The Company is a provider of telecommunications and technology services globally. The Company operates through two segments, namely Communications and Latin America. The Communications segment provides wireless and wireline telecom and broadband services to consumers located in the United States and globally. The business units of the Communication segment include Mobility, Business Wireline, and Consumer Wireline.
C3: =E8 -> #VALUE! | D3: T-Mobile US, Inc. is a provider of mobile communications services, including voice, messaging and data, under its flagship brands, T-Mobile and Metro by T-Mobile, in the United States, Puerto Rico and the United States Virgin Islands. The Company provides mobile communications services primarily using its fourth generation (4G) long term evolution network and its fifth generation (5G) technology network. It also offers a selection of wireless devices, including handsets, tablets and other mobile communication devices, and accessories for sale, as well as financing through equipment installment plans and leasing through JUMP! On Demand.
C4: =F8 -> #VALUE! | D4: Comcast Corporation is a global media and technology company. The Company provides broadband, wireless, and video through Xfinity, Comcast Business, and Sky; produce, distribute, and stream entertainment, sports, and news through brands, including NBC, Telemundo, Universal, Peacock, and Sky; and brings theme parks and attractions to life through Universal Destinations and Experiences. The Company operates through two primary businesses, namely Connectivity & Platforms and Content & Experiences.
C5: =G8 -> #VALUE! | D5: Charter Communications, Inc. is a broadband connectivity company and cable operator serving more than 32 million customers in 41 states through its Spectrum brand. The Company offers a range of residential and business services including Spectrum Internet, television (TV), mobile and voice. The Company also distributes news coverage and sports programming to its customers through Spectrum Networks. Its Spectrum Mobile service is offered to customers subscribing to its Internet service, and runs on Verizon Communications Inc.(Verizon) mobile network, combined with Spectrum WiFi.
C6: =H8 -> #VALUE! | D6: Lumen Technologies, Inc. is an international facilities-based technology and communications company. The Company is engaged primarily in providing a range of integrated services to its business and mass-market customers. It conducts its operations under three brands: Lumen, which is its flagship brand for serving the enterprise and wholesale markets; Quantum Fiber, which provides fiber-based services to residential and small business customers, and CenturyLink, which offers mass-marketed legacy copper-based services. The Company’s segments include Business Segment and Mass Markets Segment.
B8: In Millions USD (exc Market Cap) | C8: #VALUE! | D8: #VALUE! | E8: #VALUE! | F8: #VALUE! | G8: #VALUE! | H8: #VALUE! | I8: AVERAGE | J8: Deviation from Average
B9: Company Info | I9: =IFERROR(AVERAGE(C9:H9),"") | L9: TRAFFIC
B10: Market Cap | C10: =OP!C21 -> 169579.31 | D10: {=_FV(D8,"Capitalização de mercado",TRUE)/1000000} -> 120882.2 | E10: {=_FV(E8,"Capitalização de mercado",TRUE)/1000000} -> 191085.75 | F10: {=_FV(F8,"Capitalização de mercado",TRUE)/1000000} -> 157801.88 | G10: {=_FV(G8,"Capitalização de mercado",TRUE)/1000000} -> 42403.554 | H10: {=_FV(H8,"Capitalização de mercado",TRUE)/1000000} -> 1388.4145 | I10: =IFERROR(AVERAGE(C10:H10),"") -> 113856.85 | J10: =SQRT((C10-I10)^2) -> 55722.46 | M10: Best Value
B11: Net Sales (current) | C11: =C55 -> 136835 | D11: =D55 -> 120741 | E11: =E55 -> 79571 | F11: =F55 -> 121427 | G11: =G55 -> 54022 | H11: =H55 -> 17478 | I11: =IFERROR(AVERAGE(C11:H11),"") -> 88345.667 | J11: =SQRT((C11-I11)^2) -> 48489.333
B12: Profitability | I12: =IFERROR(AVERAGE(C12:H12),"") | M12: Middle Ground
B13: Sales Growth (ttm) | C13: =C55/C54-1 -> 0.02411442 | D13: =D55/D54-1 -> -0.099203211 | E13: =E55/E54-1 -> -0.0068274295 | F13: =F55/F54-1 -> 0.043321734 | G13: =G55/G54-1 -> 0.045276886 | H13: =H55/H54-1 -> -0.11220602 | I13: =IFERROR(AVERAGE(C13:H13),"") -> -0.017587271 | J13: =SQRT((C13-I13)^2) -> 0.041701691
B14: Sales Growth (36m) | C14: =C55/C53-1 -> 0.037666454 | D14: =D55/D53-1 -> -0.3336332 | E14: =E55/E53-1 -> 0.76832304 | F14: =F55/F53-1 -> 0.11460227 | G14: =G55/G53-1 -> 0.12318856 | H14: =H55/H53-1 -> -0.21976697 | I14: =IFERROR(AVERAGE(C14:H14),"") -> 0.081730023 | J14: =SQRT((C14-I14)^2) -> 0.044063569 | M14: Worst Value
B15: Operating Margin | C15: =C58/C55 -> 0.22265502 | D15: =D58/D55 -> 0.18975327 | E15: =E58/E55 -> 0.10188385 | F15: =F58/F55 -> 0.11563326 | G15: =G58/G55 -> 0.22662989 | H15: =H58/H55 -> 0.18840828 | I15: =IFERROR(AVERAGE(C15:H15),"") -> 0.1741606 | J15: =SQRT((C15-I15)^2) -> 0.048494425
B16: Net Income Margin | C16: =C61/C55 -> 0.15893594 | D16: =D61/D55 -> -0.058430856 | E16: =E61/E55 -> 0.032549547 | F16: =F61/F55 -> 0.040559348 | G16: =G61/G55 -> 0.093572989 | H16: =H61/H55 -> -0.088568486 | I16: =IFERROR(AVERAGE(C16:H16),"") -> 0.029769748 | J16: =SQRT((C16-I16)^2) -> 0.1291662
B17: Return on Equity (RoE) | C17: =C61/C72 -> 0.24211522 | D17: =D61/D72 -> -0.066270889 | E17: =E61/E72 -> 0.037182727 | F17: =F61/F72 -> 0.061679691 | G17: =G61/G72 -> 0.40282094 | H17: =H61/H72 -> -0.14831848 | I17: =IFERROR(AVERAGE(C17:H17),"") -> 0.088201535 | J17: =SQRT((C17-I17)^2) -> 0.15391369
B18: Return on Invested Capital (ROIC) | C18: =(C61+C60)/(C71+C72) -> 0.063315091 | D18: =(D61+D60)/(D71+D72) -> -0.012541358 | E18: =(E61+E60)/(E71+E72) -> 0.0096243932 | F18: =(F61+F60)/(F71+F72) -> 0.0030616109 | G18: =(G61+G60)/(G71+G72) -> 0.031314537 | H18: =(H61+H60)/(H71+H72) -> -0.046181523 | I18: =IFERROR(AVERAGE(C18:H18),"") -> 0.0080987919 | J18: =SQRT((C18-I18)^2) -> 0.055216299
B19: Solvency | I19: =IFERROR(AVERAGE(C19:H19),"")
B20: Debt/Assets | C20: =C71/C68 -> 0.39675253 | D20: =D71/D68 -> 0.38395891 | E20: =E71/E68 -> 0.67040475 | F20: =F71/F68 -> 0.40820911 | G20: =G71/G68 -> 0.67371975 | H20: =H71/H68 -> 0.77102301 | I20: =IFERROR(AVERAGE(C20:H20),"") -> 0.55067801 | J20: =SQRT((C20-I20)^2) -> 0.15392548
B21: Net Debt/EBITDA | C21: =(C71-C63)/C57 -> 3.2046847 | D21: =(D71-D63)/D57 -> 7.1774661 | E21: =(E71-E63)/E57 -> 6.803978 | F21: =(F71-F63)/F57 -> 3.4910351 | G21: =(G71-G63)/G57 -> 4.5740566 | H21: =(H71-H63)/H57 -> 9.4673184 | I21: =IFERROR(AVERAGE(C21:H21),"") -> 5.7864231 | J21: =SQRT((C21-I21)^2) -> 2.5817384
B22: Interest Coverage Ratio | C22: =-C57/C59 -> 12.942841 | D22: =-D57/D59 -> -3.4438441 | E22: =-E57/E59 -> 5.9931629 | F22: =-F57/F59 -> 7.3724333 | G22: =-G57/G59 -> 4.6413521 | H22: =-H57/H59 -> 2.6876877 | I22: =IFERROR(AVERAGE(C22:H22),"") -> 5.0322722 | J22: =SQRT((C22-I22)^2) -> 7.910569
B23: Liquidity
B24: Current Ratio | C24: =C66/C70 -> 0.75455941 | D24: =D66/D70 -> 0.58939348 | E24: =E66/E70 -> 0.77063293 | F24: =F66/F70 -> 0.78265859 | G24: =G66/G70 -> 0.33294654 | H24: =H66/H70 -> 1.1284614 | I24: =IFERROR(AVERAGE(C24:H24),"") -> 0.72644205 | J24: =SQRT((C24-I24)^2) -> 0.028117353
B25: Quick Ratio | C25: =(C63+C64)/C70 -> 0.54037193 | D25: =(D63+D64)/D70 -> 0.27000516 | E25: =(E63+E64)/E70 -> 0.36181392 | F25: =(F63+F64)/F70 -> 0.62466382 | G25: =(G63+G64)/G70 -> 0.29556569 | H25: =(H63+H64)/H70 -> 0.56797835 | I25: =IFERROR(AVERAGE(C25:H25),"") -> 0.44339981 | J25: =SQRT((C25-I25)^2) -> 0.096972117
B26: Activity | I26: =IFERROR(AVERAGE(C26:H26),"")
B27: Inventory Turnover | C27: =C56/C65 -> 24.762563 | D27: =D56/D65 -> 34.385207 | E27: =E56/E65 -> 19.217622 | F27: - | G27: - | H27: =H56/H65 -> 46.381356 | I27: =IFERROR(AVERAGE(C27:H27),"") -> 31.186687 | J27: =SQRT((C27-I27)^2) -> 6.424124
B28: Acc. Receivable Turnover | C28: =C55/C64 -> 5.5837346 | D28: =D55/D64 -> 10.530351 | E28: =E55/E64 -> 17.901237 | F28: =F55/F64 -> 9.5830637 | G28: =G55/G64 -> 18.494351 | H28: =H55/H64 -> 11.833446 | I28: =IFERROR(AVERAGE(C28:H28),"") -> 12.321031 | J28: =SQRT((C28-I28)^2) -> 6.737296
A29: Price/Sales | B29: Payables Turnover | C29: =C56/C69 -> 6.7580571 | D29: =D56/D69 -> 2.5181737 | E29: =E56/E69 -> 5.019548 | F29: =F56/F69 -> 6.774713 | G29: =G56/G69 -> 3.1147324 | H29: =H56/H69 -> 11.522105 | I29: =IFERROR(AVERAGE(C29:H29),"") -> 5.9512216 | J29: =SQRT((C29-I29)^2) -> 0.80683556
B30: Fixed Asset Turnover | C30: =C55/C67 -> 1.0244901 | D30: =D55/D67 -> 0.94739692 | E30: =E55/E67 -> 1.8906762 | F30: =F55/F67 -> 2.1884654 | G30: =G55/G67 -> 1.4989872 | H30: =H55/H67 -> 0.91192737 | I30: =IFERROR(AVERAGE(C30:H30),"") -> 1.4103239 | J30: =SQRT((C30-I30)^2) -> 0.38583374 | U30: 1000000
B31: Total Asset Turnover | C31: =C55/C68 -> 0.3603956 | D31: =D55/D68 -> 0.29971478 | E31: =E55/E68 -> 0.37651061 | F31: =F55/F68 -> 0.47197357 | G31: =G55/G68 -> 0.37379517 | H31: =H55/H68 -> 0.38344924 | I31: =IFERROR(AVERAGE(C31:H31),"") -> 0.37763983 | J31: =SQRT((C31-I31)^2) -> 0.017244234
B32: Valuation | I32: =IFERROR(AVERAGE(C32:H32),"")
B33: Price/Earnings | C33: =C10/C61 -> 7.7974669 | D33: =D10/D61 -> -17.134259 | E33: =E10/E61 -> 73.778281 | F33: =F10/F61 -> 32.040991 | G33: =G10/G61 -> 8.3884379 | H33: =H10/H61 -> -0.89690859 | I33: =IFERROR(AVERAGE(C33:H33),"") -> 17.329001 | J33: =SQRT((C33-I33)^2) -> 9.5315345
B34: Price/Sales | C34: =C10/C55 -> 1.2392978 | D34: =D10/D55 -> 1.0011694 | E34: =E10/E55 -> 2.4014496 | F34: =F10/F55 -> 1.2995617 | G34: =G10/G55 -> 0.7849312 | H34: =H10/H55 -> 0.079437836 | I34: =IFERROR(AVERAGE(C34:H34),"") -> 1.1343079 | J34: =SQRT((C34-I34)^2) -> 0.10498984
B35: Price/Book | C35: =C10/C72 -> 1.8878855 | D35: =D10/D72 -> 1.1355026 | E35: =E10/E72 -> 2.7432777 | F35: =F10/F72 -> 1.9762784 | G35: =G10/G72 -> 3.3790385 | H35: =H10/H72 -> 0.13302812 | I35: =IFERROR(AVERAGE(C35:H35),"") -> 1.8758351 | J35: =SQRT((C35-I35)^2) -> 0.012050341
B36: EV/Sales | C36: =(C71+(C10/1000000)-C63)/C55 -> 1.0818443 | D36: =(D71+(D10/1000000)-D63)/D55 -> 1.2504296 | E36: =(E71+(E10/1000000)-E63)/E55 -> 1.7239345 | F36: =(F71+(F10/1000000)-F63)/F55 -> 0.82578963 | G36: =(G71+(G10/1000000)-G63)/G55 -> 1.790438 | H36: =(H71+(H10/1000000)-H63)/H55 -> 1.9391808 | I36: =IFERROR(AVERAGE(C36:H36),"") -> 1.4352695 | J36: =SQRT((C36-I36)^2) -> 0.35342514
B37: EV/EBITDA | C37: =(C71+(C10/1000000)-C63)/C57 -> 3.2046884 | D37: =(D71+(D10/1000000)-D63)/D57 -> 7.1774719 | E37: =(E71+(E10/1000000)-E63)/E57 -> 6.8039875 | F37: =(F71+(F10/1000000)-F63)/F57 -> 3.4910406 | G37: =(G71+(G10/1000000)-G63)/G57 -> 4.5740586 | H37: =(H71+(H10/1000000)-H63)/H57 -> 9.4673188 | I37: =IFERROR(AVERAGE(C37:H37),"") -> 5.7864276 | J37: =SQRT((C37-I37)^2) -> 2.5817392
B38: Stock Info | I38: =IFERROR(AVERAGE(C38:H38),"")
B39: Float | C39: 0.99 | D39: 0.991 | E39: 0.9964 | F39: 0.99 | G39: 0.66 | H39: 0.99 | I39: =IFERROR(AVERAGE(C39:H39),"") -> 0.93623333 | J39: =SQRT((C39-I39)^2) -> 0.053766667
B40: b (Yahoo) | C40: 0.33 | D40: 0.66 | E40: 0.79 | F40: 0.99 | G40: 1.12 | H40: 1.01 | I40: =IFERROR(AVERAGE(C40:H40),"") -> 0.81666667 | J40: =SQRT((C40-I40)^2) -> 0.48666667
B41: Dividend Yield (yahoo finance) | C41: 0.078 | D41: 0.0252 | E41: 0.0197 | F41: 0.02546917 | G41: 0 | H41: 0.1534 | I41: =IFERROR(AVERAGE(C41:H41),"") -> 0.050294862 | J41: =SQRT((C41-I41)^2) -> 0.027705138
...

Sheet ESG
B1: Company GICS Sector: | T1: Yes
B2: Communication Services | C2: <- Select Industry | T2: No
B3: ESG Analysis | K3: Relative ESG Analysis
B4: Parameters | C4: Impact | D4: Do they report? | E4: Ranking | F4: Mitigation Plan | G4: Traffic Lights | H4: Improvement over time? | I4: Targets / Goals? | J4: Comments | K4: Parameters | L4: =Peers!C8 -> #VALUE! | M4: =Peers!D8 -> #VALUE! | N4: =Peers!E8 -> #VALUE! | O4: =Peers!F8 -> #VALUE! | P4: =Peers!G8 -> #VALUE! | Q4: =Peers!H8 -> #VALUE!
B5: Environmental | K5: Ratios
A6: 1 | B6: CO2 Direct Emissions | C6: =VLOOKUP($B$2,'Sector Impact'!$K$4:$AA$16,A6+1,FALSE) -> Low | K6: CO2 Emissions/$M Sales | L6: =L12/L$11 -> 0.11157373 | M6: =M12/M$11 -> 0.16867154 | N6: =N12/N$11 -> 0.092170401 | O6: =O12/O$11 -> 0.14856416 | P6: =P12/P$11 -> 0.017211229 | Q6: =Q12/Q$11 -> 0.10190811
A7: 2 | B7: Total Water Consumption | C7: =VLOOKUP($B$2,'Sector Impact'!$K$4:$AA$16,A7+1,FALSE) -> Low | K7: Water Consumption/$M Sales | L7: =L13/L$11 -> 1.4762305e-05 | M7: =M13/M$11 -> 8.4064237e-05 | N7: =N13/N$11 -> 0.013253359 | O7: =O13/O$11 -> 0 | P7: =P13/P$11 -> 0 | Q7: =Q13/Q$11 -> 0.024660736
A8: 3 | B8: Total Energy Consumption | C8: =VLOOKUP($B$2,'Sector Impact'!$K$4:$AA$16,A8+1,FALSE) -> Medium | D8: Yes | E8: "Best in class" | F8: Yes | J8: For the 10th consecutive year, the EPA named Verizon an ENERGY STAR Partner of the Year and was again recognized with a Sustained Excellence designation. | K8: Energy Consumption/$M Sales | L8: =L14/M$11 -> 0.054401984 | M8: =M14/M$11 -> 0.14079724 | N8: =N14/N$11 -> 0.100896 | O8: =O14/O$11 -> 0.18079613 | P8: =P14/P$11 -> 0 | Q8: =Q14/Q$11 -> 0.29882864
A9: 4 | B9: Waste Management | C9: =VLOOKUP($B$2,'Sector Impact'!$K$4:$AA$16,A9+1,FALSE) -> Low | K9: Waste Production/$M Sales | L9: =L15/M$11 -> 0.00035944708 | M9: =M15/M$11 -> 0.0015754632 | N9: =N15/N$11 -> 0.00014578175 | O9: =O15/O$11 -> 0 | P9: =P15/P$11 -> 0.00051493836 | Q9: =Q15/Q$11 -> 0.0022404165
A10: 5 | B10: Land Degradation/Deforestation/Biodiversity loss/Animal sufering/… | C10: =VLOOKUP($B$2,'Sector Impact'!$K$4:$AA$16,A10+1,FALSE) -> Low | K10: Inputs
B11: Social | K11: Net Sales ($M) | L11: =Peers!C55 -> 136835 | M11: =Peers!D55 -> 120741 | N11: =Peers!E55 -> 79571 | O11: =Peers!F55 -> 121427 | P11: =Peers!G55 -> 54022 | Q11: =Peers!H55 -> 17478
A12: 6 | B12: Employee Turnover % | C12: =VLOOKUP($B$2,'Sector Impact'!$K$4:$AA$16,A12+1,FALSE) -> Medium | D12: No | E12: "Best in class" | F12: No | J12: Employee’s turnover sits below 5% | K12: CO2 Emissions Total (Tonnes) | L12: 15267.192 | M12: 20365.571 | N12: 7334.091 | O12: 18039.7 | P12: 929.785 | Q12: 1781.15
A13: 7 | B13: Salaries & Compensation | C13: =VLOOKUP($B$2,'Sector Impact'!$K$4:$AA$16,A13+1,FALSE) -> Medium | D13: Yes | E13: Medium High | F13: No | J13: In 2022, Verizon invested $2.5 billion to provide healthcare benefits and services to approximately 460,000 employees, eligible retirees and their dependents. | K13: Water Consumption Total (Cubic Meters) | L13: 2.02 | M13: 10.15 | N13: 1054.583 | O13: 0 | Q13: 431.02034
A14: 8 | B14: Reputation | C14: =VLOOKUP($B$2,'Sector Impact'!$K$4:$AA$16,A14+1,FALSE) -> Low | K14: Energy Consumption Total (Gigajoules) | L14: 6568.55 | M14: 17000 | N14: 8028.396 | O14: 21953.532 | Q14: 5222.927
A15: 9 | B15: Discrimination Events | C15: =VLOOKUP($B$2,'Sector Impact'!$K$4:$AA$16,A15+1,FALSE) -> Low | F15: Yes | K15: Waste Production Total (Tonnes) | L15: 43.4 | M15: 190.223 | N15: 11.6 | O15: 0 | P15: 27.818 | Q15: 39.158
A16: 10 | B16: Work Safety | C16: =VLOOKUP($B$2,'Sector Impact'!$K$4:$AA$16,A16+1,FALSE) -> High | D16: Yes | E16: "Best in class" | F16: Yes | I16: None | J16: In 2022, occupational injuries and illnesses rate was 1.1 per 100 employees, well below the Bureau of Labor Statistics telecommunications industry average of 1.7 | K16: ESG Scores
A17: 11 | B17: Damage to consumer health | C17: =VLOOKUP($B$2,'Sector Impact'!$K$4:$AA$16,A17+1,FALSE) -> Low | I17: None | K17: Refinitiv | L17: 72/100 | M17: 76/100 | N17: 64/100 | O17: 66/100 | P17: 43/100 | Q17: Not scored
A18: 12 | B18: PXP? | C18: =VLOOKUP($B$2,'Sector Impact'!$K$4:$AA$16,A18+1,FALSE) -> Low | K18: Sustainalytics | L18: 18,6 (Low Risk) | M18: 23,9 (Medium Risk) | N18: 24,7 (Medium Risk) | O18: 23,1 (Medium risk) | P18: 24,2 (Medium Risk) | Q18: 26,1 (Medium Risk)
A19: 13 | B19: Supply chain | C19: Medium | D19: Yes | E19: Medium High | F19: Yes | I19: supplier diversity for over 15 years | K19: ISS
A20: 14 | B20: Community involvement | C20: =VLOOKUP($B$2,'Sector Impact'!$K$4:$AA$16,A20+1,FALSE) -> Low | K20: CDP | L20: B | M20: A | N20: A- | O20: B | P20: Not Scored | Q20: B
A21: 15 | B21: Public Sector | C21: =VLOOKUP($B$2,'Sector Impact'!$K$4:$AA$16,A21+1,FALSE) -> Low | I21: None
A22: 16 | B22: Litigation | C22: =VLOOKUP($B$2,'Sector Impact'!$K$4:$AA$16,A22+1,FALSE) -> Medium | D22: Yes | E22: Medium | F22: Yes | H22: None | I22: None | J22: Verizon is involved in various litigation and regulatory proceedings at the state and federal level but they don't believe that any pending legal proceedings to which they're subject are required to be disclosed as material legal proceedings in the report.
B23: Corporate Governance | K23: PARAMETERS
A24: 17 | B24: Diversity (Gender, Age, Industry, Region) | E24: Medium High | F24: Yes | I24: None | J24: As of December 31, 2022, the 12-member Board included four women and five Directors who self-identify as racially or ethnically diverse. | K24: IMPACT | L24: RANKING | M24: MITIGATION PLAN | O24: TRAFFIC
A25: 18 | B25: % Independence | E25: Medium High | F25: No | I25: None | J25: 91.67% of board members are independent. | K25: Low | L25: "Best in class" | M25: Is there evidence of a plan/program ?
A26: 19 | B26: average time as independent directors | E26: "Best in class" | F26: No | I26: None | J26: 6.98 Yrs average board tenure. | K26: Medium | L26: Medium High
A27: 20 | B27: Recent departures of directors / C-level executives? | E27: Medium High | F27: No | I27: None | J27: Mr. Colao was elected to the Board in November 2022 as an independent Director. | K27: High | L27: Medium
A28: 21 | B28: CEO/Chairman duality | E28: "Villain" | F28: No | I28: None | J28: Hans Vestberg is the CEO and Chairman since 2019. | K28: Very high | L28: "Villain"
A29: 22 | B29: Transparency (ESG, segments, acquisitions, other) | E29: "Best in class" | F29: No | I29: None | J29: The information of the board about their public profile is available and accurately disclosed.
A30: 23 | B30: Time taken to report after the end of the quarter / year | E30: Medium High | F30: No | I30: None | J30: 1Q was released on 27/04/2023 and the Annual Report was released on 10/02/2023.
A31: 24 | B31: Additional participation of the CEO in other boards or excessive participation of Ch. | E31: Medium High | F31: No | I31: None | J31: None
A32: 25 | B32: Audit / Consulting | D32: Yes | E32: Medium High | F32: No | I32: None | J32: The company hasn't paid for any extra services.
A33: 26 | B33: ESG-compensation related | D33: Yes | E33: Medium High | F33: No | I33: None | J33: For over 20 years, our short-term incentive program has included an ESG metric.
A34: 27 | B34: Management compensation schemes | D34: Yes | E34: "Best in class" | F34: No | I34: None | J34: Directors and executive officers have interests in other stock-based units under Verizon deferred compensation plans and stock-based long-term incentive awards. There is alignment with shareholders' interests and the same incentives to drive the company's success.

Sheet DCF
A1: VALUATION MODEL
G3: Short Term | K3: Long Term
A4: Section | B4: Line # | C4: ITEM | D4: 2020 (Real) | E4: 2021 (Real) | F4: 2022 (Real) | G4: 2023 | H4: =G4+1 -> 2024 | I4: =H4+1 -> 2025 | J4: =I4+1 -> 2026 | K4: =J4+1 -> 2027 | L4: =K4+1 -> 2028 | M4: =L4+1 -> 2029 | N4: =M4+1 -> 2030 | O4: =N4+1 -> 2031 | ... AF4: =AE4+1 -> 2048
A5: INCOME STATEMENT | B5: 1 | C5: Growth | D5: ='Fin. Data'!D6 -> -0.027118027 | E5: =+E6/D6-1 -> 0.041475696 | F5: =+F6/E6-1 -> 0.02411442 | G5: 0.03 | H5: =+G5+($K$5-$G$5)/4 -> 0.025 | I5: =+H5+($K$5-$G$5)/4 -> 0.02 | J5: =+I5+($K$5-$G$5)/4 -> 0.015 | K5: =+Assumptions!$M$6 -> 0.01 | L5: =+Assumptions!$M$6 -> 0.01 | M5: =+Assumptions!$M$6 -> 0.01 | N5: =+Assumptions!$M$6 -> 0.01 | O5: =+Assumptions!$M$6 -> 0.01 | P5: =+Assumptions!$M$6 -> 0.01 | Q5: =+Assumptions!$M$6 -> 0.01 | R5: =+Assumptions!$M$6 -> 0.01 | ... AF5: =+Assumptions!$M$6 -> 0.01
B6: 2 | C6: Revenues/Sales | D6: 128292 | E6: 133613 | F6: 136835 | G6: =F6*(1+G5) -> 140940.05 | H6: =G6*(1+H5) -> 144463.55 | I6: =H6*(1+I5) -> 147352.82 | J6: =I6*(1+J5) -> 149563.11 | K6: =J6*(1+K5) -> 151058.75 | L6: =K6*(1+L5) -> 152569.33 | M6: =L6*(1+M5) -> 154095.03 | N6: =M6*(1+N5) -> 155635.98 | ... AF6: =AE6*(1+AF5) -> 186163.58
B7: 3 | C7: EBIT/Operating Margin | D7: =D8/D6 -> 0.2244723 | E7: =E8/E6 -> 0.24285062 | F7: =F8/F6 -> 0.22265502 | G7: 0.23 | H7: =$G$7 -> 0.23 | I7: =$G$7 -> 0.23 | J7: =$G$7 -> 0.23 | K7: 0.22 | L7: =$K$7 -> 0.22 | M7: =$K$7 -> 0.22 | N7: =$K$7 -> 0.22 | O7: =$K$7 -> 0.22 | P7: =$K$7 -> 0.22 | Q7: =$K$7 -> 0.22 | R7: =$K$7 -> 0.22 | S7: =$K$7 -> 0.22 | ... AE7: =$K$7 -> 0.22 | AF7: 0.22
B8: 4 | C8: EBIT | D8: ='Fin. Data'!D11 -> 28798 | E8: ='Fin. Data'!C11 -> 32448 | F8: ='Fin. Data'!B11 -> 30467 | G8: =G7*G6 -> 32416.212 | H8: =H7*H6 -> 33226.617 | I8: =I7*I6 -> 33891.149 | J8: =J7*J6 -> 34399.516 | K8: =K7*K6 -> 33232.924 | L8: =L7*L6 -> 33565.253 | M8: =M7*M6 -> 33900.906 | N8: =N7*N6 -> 34239.915 | ... AF8: =AF7*AF6 -> 40955.988
B9: 5a | C9: (Dep) | D9: -14275 | E9: -14119 | F9: -14592 | G9: =$D$53*DCF!F40 -> -15092.975 | H9: =$D$53*DCF!G40 -> -15975.924 | I9: =$D$53*DCF!H40 -> -16968.009 | J9: =$D$53*DCF!I40 -> -17979.937 | K9: =$E$53*DCF!J40 -> -17436.696 | L9: =$E$53*DCF!K40 -> -18252.413 | M9: =$E$53*DCF!L40 -> -19076.287 | N9: =$E$53*DCF!M40 -> -19908.401 | O9: =$E$53*DCF!N40 -> -20748.835 | P9: =$E$53*DCF!O40 -> -21597.673 | Q9: =$E$53*DCF!P40 -> -22455 | R9: =$E$53*DCF!Q40 -> -23320.901 | ... AF9: =$E$53*DCF!AE40 -> -36393.307 | AG9: =SUM(D9:AF9) -> -694221.68
B10: 5b | C10: Amort | D10: -2445 | E10: -2087 | F10: -2507 | G10: =F38*$D$54 -> -2444.96 | H10: =G38*$D$54 -> -2640.5568 | I10: =H38*$D$54 -> -2851.8013 | J10: =I38*$D$54 -> -3079.9455 | K10: =J38*$E$54 -> -2910.5485 | L10: =K38*$E$54 -> -3114.2868 | M10: =L38*$E$54 -> -3332.2869 | N10: =M38*$E$54 -> -3565.547 | O10: =N38*$E$54 -> -3815.1353 | P10: =O38*$E$54 -> -4082.1948 | Q10: =P38*$E$54 -> -4367.9484 | R10: =Q38*$E$54 -> -4673.7048 | ... AF10: =AE38*$E$54 -> -12051.307
B11: 5c | C11: (Stock based compensation) | D11: -780 | E11: -625 | F11: -609 | G11: =G6*$D$55 -> -714.48076 | H11: =H6*$D$55 -> -732.34278 | I11: =I6*$D$55 -> -746.98964 | J11: =J6*$D$55 -> -758.19448 | K11: =K6*$D$55 -> -765.77643 | L11: =L6*$D$55 -> -773.43419 | M11: =M6*$D$55 -> -781.16853 | N11: =N6*$D$55 -> -788.98022 | ... AF11: =AF6*$D$55 -> -943.7367
B12: 6 | C12: EBIDTA | D12: =D8-D9-D10 -> 45518 | E12: =E8-E9-E10 -> 48654 | F12: =F8-F9-F10 -> 47566 | G12: =G8-G9-G10 -> 49954.147 | H12: =H8-H9-H10 -> 51843.097 | I12: =I8-I9-I10 -> 53710.96 | J12: =J8-J9-J10 -> 55459.399 | K12: =K8-K9-K10 -> 53580.168 | ... AF12: =AF8-AF9-AF10 -> 89400.602
B13: 7 | C13: (Net financing cost) | D13: ='Fin. Data'!D14 -> -4247 | E13: ='Fin. Data'!C14 -> -3340 | F13: ='Fin. Data'!B14 -> -3569 | G13: =F43*$D$58-F44*$D$57 -> -8913.06 | H13: =G43*$D$58-G44*$D$57 -> -8869.6826 | I13: =H43*$D$58-H44*$D$57 -> -8870.5033 | J13: =I43*$D$58-I44*$D$57 -> -8896.6603 | K13: =J43*$E$58-J44*$E$57 -> -5251.5397 | L13: =K43*$E$58-K44*$E$57 -> -5134.5037 | M13: =L43*$E$58-L44*$E$57 -> -5142.547 | N13: =M43*$E$58-M44*$E$57 -> -5131.6922 | O13: =N43*$E$58-N44*$E$57 -> -4759.0034 | P13: =O43*$E$58-O44*$E$57 -> -4705.962 | Q13: =P43*$E$58-P44*$E$57 -> -4361.8887 | R13: =Q43*$E$58-Q44*$E$57 -> -4264.9652 | ... AF13: =AE43*$E$58-AE44*$E$57 -> -600.14201
B14: 8 | C14: Other income/(cost) | D14: ='Fin. Data'!D15 -> -584 | E14: ='Fin. Data'!C15 -> 312 | F14: ='Fin. Data'!B15 -> 1373 | G14: =AVERAGE(D14:F14)*(1+G5) -> 378.01 | H14: =AVERAGE(E14:G14)*(1+H5) -> 704.86175 | I14: =AVERAGE(F14:H14)*(1+I5) -> 834.9964 | J14: =AVERAGE(G14:I14)*(1+J5) -> 648.87872 | K14: =AVERAGE(H14:J14)*(1+K5) -> 736.87475 | L14: =AVERAGE(I14:K14)*(1+L5) -> 747.65245 | M14: =AVERAGE(J14:L14)*(1+M5) -> 718.24666 | N14: =AVERAGE(K14:M14)*(1+N5) -> 741.60053 | ... AF14: =AVERAGE(AC14:AE14)*(1+AF5) -> 806.39601
B15: 9 | C15: Earnings before taxes | D15: =D8+D13+D14 -> 23967 | E15: =E8+E13+E14 -> 29420 | F15: =F8+F13+F14 -> 28271 | G15: =G8+G13+G14 -> 23881.162 | H15: =H8+H13+H14 -> 25061.796 | I15: =I8+I13+I14 -> 25855.642 | J15: =J8+J13+J14 -> 26151.735 | K15: =K8+K13+K14 -> 28718.259 | ... AF15: =AF8+AF13+AF14 -> 41162.242
B16: 10 | C16: (Income tax) | D16: ='Fin. Data'!D21 -> -5619 | E16: ='Fin. Data'!C21 -> -6802 | F16: ='Fin. Data'!B21 -> -6523 | G16: =-(1*24%)*G15 -> -5731.4788 | H16: =-(1*$D$56)*H15 -> -5817.5259 | I16: =-(1*$D$56)*I15 -> -6001.7993 | J16: =-(1*$D$56)*J15 -> -6070.5304 | K16: =-(1*$E$56)*K15 -> -7753.93 | L16: =-(1*$E$56)*L15 -> -7878.1686 | M16: =-(1*$E$56)*M15 -> -7958.6835 | N16: =-(1*$E$56)*N15 -> -8059.4523 | O16: =-(1*$E$56)*O15 -> -8252.9556 | P16: =-(1*$E$56)*P15 -> -8360.2435 | Q16: =-(1*$E$56)*Q15 -> -8549.5803 | R16: =-(1*$E$56)*R15 -> -8671.7242 | ... AF16: =-(1*$E$56)*AF15 -> -11113.805
B17: 11 | C17: Net income | D17: =Inputs!D12 -> 18348 | E17: =Inputs!C12 -> 22618 | F17: =Inputs!B12 -> 21748 | G17: =G16+G15 -> 18149.683 | H17: =H16+H15 -> 19244.27 | I17: =I16+I15 -> 19853.843 | J17: =J16+J15 -> 20081.204 | K17: =K16+K15 -> 20964.329 | L17: =L16+L15 -> 21300.234 | M17: =M16+M15 -> 21517.922 | N17: =N16+N15 -> 21790.371 | ... AF17: =AF16+AF15 -> 30048.436
A19: CASH FLOW STATEMENT | B19: 12 | C19: Operating cash flows before WK | D19: =+D22-D20-D21 -> 39712 | E19: =+E22-E20-E21 -> 41147 | F19: =+F22-F20-F21 -> 41984 | G19: =G17-G10-G9-G11 -> 36402.099 | H19: =H17-H10-H9-H11 -> 38593.093 | I19: =I17-I10-I9-I11 -> 40420.643 | J19: =J17-J10-J9-J11 -> 41899.281 | K19: =K17-K10-K9-K11 -> 42077.35 | L19: =L17-L10-L9-L11 -> 43440.368 | M19: =M17-M10-M9-M11 -> 44707.665 | N19: =N17-N10-N9-N11 -> 46053.299 | ... AF19: =AF17-AF10-AF9-AF11 -> 79436.787
B20: 13 | C20: (Stock-based compensation) | D20: -780 | E20: -625 | F20: -609 | G20: =G11 -> -714.48076 | H20: =H11 -> -732.34278 | I20: =I11 -> -746.98964 | J20: =J11 -> -758.19448 | K20: =K11 -> -765.77643 | L20: =L11 -> -773.43419 | M20: =M11 -> -781.16853 | N20: =N11 -> -788.98022 | ... AF20: =AF11 -> -943.7367
B21: 14 | C21: (Working Capital Flows) | D21: =Inputs!D62 -> 2836 | E21: =Inputs!C62 -> -983 | F21: =Inputs!B62 -> -4234 | G21: =$D$60*(G6-F6) -> -5282.3709 | H21: =$D$60*(H6-G6) -> -4534.035 | I21: =$D$60*(I6-H6) -> -3717.9087 | J21: =$D$60*(J6-I6) -> -2844.2002 | K21: =$E$60*(K6-J6) -> -1924.5754 | L21: =$E$60*(L6-K6) -> -1943.8212 | M21: =$E$60*(M6-L6) -> -1963.2594 | N21: =$E$60*(N6-M6) -> -1982.892 | O21: =$E$60*(O6-N6) -> -2002.7209 | P21: =$E$60*(P6-O6) -> -2022.7481 | Q21: =$E$60*(Q6-P6) -> -2042.9756 | R21: =$E$60*(R6-Q6) -> -2063.4054 | ... AF21: =$E$60*(AF6-AE6) -> -2371.8313
B22: 15 | C22: -Total Operating Cash Flow | D22: 41768 | E22: 39539 | F22: 37141 | G22: =G19+G20+G21 -> 30405.247 | H22: =H19+H20+H21 -> 33326.716 | I22: =I19+I20+I21 -> 35955.745 | J22: =J19+J20+J21 -> 38296.887 | K22: =K19+K20+K21 -> 39386.998 | L22: =L19+L20+L21 -> 40723.112 | M22: =M19+M20+M21 -> 41963.237 | N22: =N19+N20+N21 -> 43281.427 | ... AF22: =AF19+AF20+AF21 -> 76121.219
B23: 16 | C23: (CAPEX) | D23: ='Fin. Data'!D32 -> -20318 | E23: ='Fin. Data'!C32 -> -67882 | F23: ='Fin. Data'!B32 -> -26740 | G23: -18000 | H23: =H6*$D$62 -> -20224.897 | I23: =I6*$D$62 -> -20629.395 | J23: =J6*$D$62 -> -20938.836 | K23: =K6*$E$62 -> -18127.049 | L23: =L6*$E$62 -> -18308.32 | M23: =M6*$E$62 -> -18491.403 | N23: =N6*$E$62 -> -18676.317 | O23: =O6*$E$62 -> -18863.08 | P23: =P6*$E$62 -> -19051.711 | Q23: =Q6*$E$62 -> -19242.228 | R23: =R6*$E$62 -> -19434.651 | ... AF23: =AF6*$E$62 -> -22339.63 | AG23: =SUM(D23:AF23) -> -638330.78
B24: 17 | C24: Adq | D24: =Inputs!D66 -> -520 | E24: ='Fin. Data'!C33 -> -4065 | F24: ='Fin. Data'!B33 -> 248 | G24: =G6*$D$63 -> -976.48955 | H24: =H6*$D$63 -> -1000.9018 | I24: =I6*$D$63 -> -1020.9198 | J24: =J6*$D$63 -> -1036.2336 | K24: =K6*$E$63 -> -1046.596 | L24: =L6*$E$63 -> -1057.0619 | M24: =M6*$E$63 -> -1067.6325 | N24: =N6*$E$63 -> -1078.3089 | O24: =O6*$E$63 -> -1089.092 | P24: =P6*$E$63 -> -1099.9829 | Q24: =Q6*$E$63 -> -1110.9827 | R24: =R6*$E$63 -> -1122.0925 | ... AF24: =AF6*$E$63 -> -1289.8164 | AH24: =AG9-AG23 -> -55890.9
B25: 18 | C25: (Other investing flows) | D25: =Inputs!D67 -> -2674 | E25: =Inputs!C67 -> 4794 | F25: =Inputs!B67 -> -2170 | G25: =(1+G5)*AVERAGE(Inputs!B67:M67) -> 2216.8175 | H25: =(1+H5)*AVERAGE(E25:G25) -> 1653.946 | I25: =(1+I5)*AVERAGE(F25:H25) -> 578.25958 | J25: =(1+J5)*AVERAGE(G25:I25) -> 1505.2528 | K25: =(1+K5)*AVERAGE(H25:J25) -> 1258.2776 | L25: =(1+L5)*AVERAGE(I25:K25) -> 1125.0693 | M25: =(1+M5)*AVERAGE(J25:L25) -> 1309.1619 | N25: =(1+N5)*AVERAGE(K25:M25) -> 1243.1447 | O25: =(1+O5)*AVERAGE(L25:N25) -> 1238.0499 | ... AF25: =(1+AF5)*AVERAGE(AC25:AE25) -> 1366.7305
B26: 19 | C26: -Total Investing Flows | D26: =D23+D24+D25 -> -23512 | E26: =E23+E24+E25 -> -67153 | F26: =F23+F24+F25 -> -28662 | G26: =G23+G24+G25 -> -16759.672 | H26: =H23+H24+H25 -> -19571.853 | I26: =I23+I24+I25 -> -21072.055 | J26: =J23+J24+J25 -> -20469.817 | K26: =K23+K24+K25 -> -17915.368 | ... AF26: =AF23+AF24+AF25 -> -22262.716
B27: 20 | C27: (Flows related to leases) | D27: =Inputs!D71+Inputs!D72 -> 0 | E27: =Inputs!C71+Inputs!C72 -> 0 | F27: =Inputs!B71+Inputs!B72 -> 0 | G27: =AVERAGE(D27:F27) -> 0 | H27: =AVERAGE(E27:G27) -> 0 | I27: =AVERAGE(F27:H27) -> 0 | J27: =AVERAGE(G27:I27) -> 0 | K27: =AVERAGE(H27:J27) -> 0 | L27: =AVERAGE(I27:K27) -> 0 | M27: =AVERAGE(J27:L27) -> 0 | N27: =AVERAGE(K27:M27) -> 0 | ... AF27: =AVERAGE(AC27:AE27) -> 0
B28: 21 | C28: Flows related to debt | D28: =+SUM(Inputs!D69:D70) -> 14269 | E28: =+SUM(Inputs!C69:C70) -> 22554 | F28: =+SUM(Inputs!B69:B70) -> 4348 | G28: =G44-F44 -> -776.56009 | H28: =H44-G44 -> 482.54215 | I28: =I44-H44 -> 5416.8016 | J28: =J44-I44 -> 5070.4725 | K28: =K44-J44 -> -5449.7681 | L28: =L44-K44 -> 3920.1761 | M28: =M44-L44 -> 3994.8283 | N28: =N44-M44 -> -19012.836 | ... AF28: =AF44-AE44 -> 4816.3239
B29: 22 | C29: (Respurchases)/Issuance of stock | D29: ='Fin. Data'!D28 -> 0 | E29: ='Fin. Data'!C28 -> 0 | F29: ='Fin. Data'!B28 -> 0 | G29: =-G17*$D$65 -> 0 | H29: =-H17*$D$65 -> 0 | I29: =-I17*$D$65 -> 0 | J29: =-J17*$D$65 -> 0 | K29: =K17*$E$65 -> -2096.4329 | L29: =L17*$E$65 -> -2130.0234 | M29: =M17*$E$65 -> -2151.7922 | N29: =N17*$E$65 -> -2179.0371 | O29: =O17*$E$65 -> -2231.3547 | P29: =P17*$E$65 -> -2260.3621 | Q29: =Q17*$E$65 -> -2311.5532 | R29: =R17*$E$65 -> -2344.5773 | ... AF29: =AF17*$E$65 -> -3004.8436
B30: 23 | C30: (Dividends) | D30: ='Fin. Data'!D27 -> -10232 | E30: ='Fin. Data'!C27 -> -10445 | F30: ='Fin. Data'!B27 -> -10805 | G30: =-$D$64*G17 -> -9982.3255 | H30: =-$D$64*H17 -> -10584.349 | I30: =-$D$64*I17 -> -10919.614 | J30: =-$D$64*J17 -> -11044.662 | K30: =-$E$64*K17 -> -14675.03 | L30: =-$E$64*L17 -> -14910.163 | M30: =-$E$64*M17 -> -15062.545 | N30: =-$E$64*N17 -> -15253.26 | O30: =-$E$64*O17 -> -15619.483 | P30: =-$E$64*P17 -> -15822.535 | Q30: =-$E$64*Q17 -> -16180.872 | R30: =-$E$64*R17 -> -16412.041 | ... AF30: =-$E$64*AF17 -> -21033.906
B31: 24 | C31: Other financing flows | D31: =Inputs!D75 -> -2712 | E31: =Inputs!C75 -> -3832 | F31: =Inputs!B75 -> -2072 | G31: =(1+G5)*AVERAGE(D31:F31) -> -2958.16 | H31: =(1+H5)*AVERAGE(E31:G31) -> -3027.9047 | I31: =(1+I5)*AVERAGE(F31:H31) -> -2739.742 | J31: =(1+J5)*AVERAGE(G31:I31) -> -2952.2313 | K31: =(1+K5)*AVERAGE(H31:J31) -> -2935.6922 | L31: =(1+L5)*AVERAGE(I31:K31) -> -2904.6474 | M31: =(1+M5)*AVERAGE(J31:L31) -> -2960.1655 | N31: =(1+N5)*AVERAGE(K31:M31) -> -2962.8367 | ... AF31: =(1+AF5)*AVERAGE(AC31:AE31) -> -3239.7706
B32: 25 | C32: -Total Financing flows | D32: =D27+D28+D29+D30+D31 -> 1325 | E32: =E27+E28+E29+E30+E31 -> 8277 | F32: =F27+F28+F29+F30+F31 -> -8529 | G32: =G27+G28+G29+G30+G31 -> -13717.046 | H32: =H27+H28+H29+H30+H31 -> -13129.711 | I32: =I27+I28+I29+I30+I31 -> -8242.554 | J32: =J27+J28+J29+J30+J31 -> -8926.4211 | K32: =K27+K28+K29+K30+K31 -> -25156.924 | ... AF32: =AF27+AF28+AF29+AF30+AF31 -> -22462.196
A34: SUMMARY | B34: 26 | C34: Cash before shareholder returns | D34: =D22+D26+D27+D28+D31 -> 29813 | E34: =E22+E26+E27+E28+E31 -> -8892 | F34: =F22+F26+F27+F28+F31 -> 10755 | G34: =G22+G26+G27+G28+G31 -> 9910.8549 | H34: =H22+H26+H27+H28+H31 -> 11209.5 | I34: =I22+I26+I27+I28+I31 -> 17560.749 | J34: =J22+J26+J27+J28+J31 -> 19945.311 | K34: =K22+K26+K27+K28+K31 -> 13086.17 | ... AF34: =AF22+AF26+AF27+AF28+AF31 -> 55435.057
B35: 27 | C35: Returns to shareholders | D35: =-1*(D29+D30) -> 10232 | E35: =-1*(E29+E30) -> 10445 | F35: =-1*(F29+F30) -> 10805 | G35: =-1*(G29+G30) -> 9982.3255 | H35: =-1*(H29+H30) -> 10584.349 | I35: =-1*(I29+I30) -> 10919.614 | J35: =-1*(J29+J30) -> 11044.662 | K35: =-1*(K29+K30) -> 16771.463 | ... AF35: =-1*(AF29+AF30) -> 24038.749
B36: 28 | C36: Excess cash acumulation | D36: =D34-D35 -> 19581 | E36: =E34-E35 -> -19337 | F36: =F34-F35 -> -50 | G36: =G34-G35 -> -71.470651 | H36: =H34-H35 -> 625.15149 | I36: =I34-I35 -> 6641.1356 | J36: =J34-J35 -> 8900.6485 | K36: =K34-K35 -> -3685.2935 | ... AF36: =AF34-AF35 -> 31396.308
A38: BALANCE SHEET | B38: 29 | C38: Intangible assets | D38: 27477 | E38: 28485 | F38: 30562 | G38: =+F38+(-G10) -> 33006.96 | H38: =+G38+(-H10) -> 35647.517 | I38: =+H38+(-I10) -> 38499.318 | J38: =+I38+(-J10) -> 41579.264 | K38: =+J38+(-K10) -> 44489.812 | L38: =+K38+(-L10) -> 47604.099 | M38: =+L38+(-M10) -> 50936.386 | N38: =+M38+(-N10) -> 54501.933 | ... AF38: =+AE38+(-AF10) -> 184212.84 | AG38: =SUM(G38:AF38) -> 2328989.2
B39: 30 | C39: Accumulated amorization | D39: 18064 | E39: 16808 | F39: 19101 | G39: =F39-G10 -> 21545.96 | H39: =G39-H10 -> 24186.517 | I39: =H39-I10 -> 27038.318 | J39: =I39-J10 -> 30118.264 | K39: =J39-K10 -> 33028.812 | L39: =K39-L10 -> 36143.099 | M39: =L39-M10 -> 39475.386 | N39: =M39-N10 -> 43040.933 | ... AF39: =AE39-AF10 -> 172751.84 | AG39: =SUM(G39:AF39) -> 2031003.2
B40: 31 | C40: PPE+Right of use Assets | D40: 279737 | E40: 289897 | F40: 307689 | G40: =F40+(-G23) -> 325689 | H40: =G40+(-H23) -> 345913.9 | I40: =H40+(-I23) -> 366543.29 | J40: =I40+(-J23) -> 387482.13 | K40: =J40+(-K23) -> 405609.18 | L40: =K40+(-L23) -> 423917.5 | M40: =L40+(-M23) -> 442408.9 | N40: =M40+(-N23) -> 461085.22 | ... AF40: =AE40+(-AF23) -> 831079.78 | AG40: x
B41: 32 | C41: Accumulated depreciation | D41: 184904 | E41: 190201 | F41: 200225 | G41: =F41-G9 -> 215317.98 | H41: =G41-H9 -> 231293.9 | I41: =H41-I9 -> 248261.91 | J41: =I41-J9 -> 266241.85 | K41: =J41-K9 -> 283678.54 | L41: =K41-L9 -> 301930.95 | M41: =L41-M9 -> 321007.24 | N41: =M41-N9 -> 340915.64 | ... AF41: =AE41-AF9 -> 851460.68 | AG41: =SUM(G41:AF41) -> 12749616
A43: CASH & DEBT & DISCOUNTING | B43: 33 | C43: Ending cash balance | D43: ='Fin. Data'!D39 -> 22171 | E43: =E36+D43 -> 2834 | F43: =F36+E43 -> 2784 | G43: =G36+F43 -> 2712.5293 | H43: =H36+G43 -> 3337.6808 | I43: =I36+H43 -> 9978.8165 | J43: =J36+I43 -> 18879.465 | K43: =K36+J43 -> 15194.171 | L43: =L36+K43 -> 21652.313 | ... AF43: =AF36+AE43 -> 337152.96
B44: 34 | C44: Total Debt | D44: ='Fin. Data'!D58 -> 129062 | E44: ='Fin. Data'!C58 -> 150868 | F44: ='Fin. Data'!B58 -> 150639 | G44: =G12*3 -> 149862.44 | H44: =H12*Assumptions!$O$41 -> 150344.98 | I44: =I12*Assumptions!$O$41 -> 155761.78 | J44: =J12*Assumptions!$O$41 -> 160832.26 | K44: =K12*Assumptions!$O$41 -> 155382.49 | L44: =L12*Assumptions!$O$41 -> 159302.66 | M44: =M12*Assumptions!$O$41 -> 163297.49 | N44: =N12*Assumptions!$O$42 -> 144284.66 | O44: =O12*Assumptions!$O$42 -> 147865.71 | P44: =P12*Assumptions!$O$43 -> 133337.61 | Q44: =Q12*Assumptions!$O$43 -> 136620.81 | R44: =R12*Assumptions!$O$43 -> 139974.56 | S44: =S12*Assumptions!$O$43 -> 143402.2 | T44: =T12*Assumptions!$O$43 -> 146907.31 | U44: =U12*Assumptions!$O$43 -> 150493.67 | V44: =V12*Assumptions!$O$43 -> 154165.35 | W44: =W12*Assumptions!$O$43 -> 157926.64 | ... AF44: =AF12*Assumptions!$O$43 -> 196681.32
B45: 35 | C45: Discount factor | F45: =1/((1+$F$50)^G50) -> 1 | G45: =1/((1+$F$50)^G49) -> 0.90571506 | H45: =1/((1+$F$50)^H49) -> 0.82031977 | I45: =1/((1+$F$50)^I49) -> 0.74297597 | J45: =1/((1+$F$50)^J49) -> 0.67292453 | K45: =1/((1+$F$50)^K49) -> 0.60947788 | L45: =1/((1+$F$50)^L49) -> 0.5520133 | M45: =1/((1+$F$50)^M49) -> 0.49996676 | N45: =1/((1+$F$50)^N49) -> 0.45282742 | ... AF45: =1/((1+$F$50)^AF49) -> 0.076169542
...

Sheet Debt
B1: Amount outstanding (at maturity) | C1: Coupon rate | D1: Maturity date | E1: Company totals | F1: Total
A2: Dollars in millions
A4: Debt maturing within one year
A6: Commericail Paper | B6: 500 | E6: 500
A8: Verizon Communications Inc. | B8: €685(a) | C8: 0.01625 | D8: 45352
A9: Verizon Communications Inc. | B9: 999 | C9: 0.0075 | D9: 45373
A10: Verizon Communications Inc. | B10: 95 | C10: SOFR+0.50% | D10: 45373
A11: Verizon Communications Inc. | B11: £413(a) | C11: 0.04073 | D11: 45461 | E11: 2453
A13: Private placements | B13: 9487 | E13: 9487
A15: Total debt maturing within one year | F15: 12440
A17: Long-term debt
A18: Verizon Pennsylvania LLC | B18: 44 | C18: 0.06 | D18: 47088
A19: Verizon Pennsylvania LLC | B19: 31 | C19: 0.0835 | D19: 11307
A20: Verizon Pennsylvania LLC | B20: 35 | C20: 0.0875 | D20: 11550 | E20: 110
A22: Verizon Maryland LLC | B22: 20 | C22: 0.08 | D22: 47406
A23: Verizon Maryland LLC | B23: 21 | C23: 0.083 | D23: 11536
A24: Verizon Maryland LLC | B24: 139 | C24: 0.05125 | D24: 12220 | E24: 180
A26: Verizon Virginia LLC | B26: 9 | C26: 0.08375 | D26: 47392 | E26: 9
A28: Verizon Delaware LLC | B28: 2 | C28: 0.08625 | D28: 11611 | E28: 2
A30: Verizon New Jersey Inc. | B30: 45 | C30: 0.0785 | D30: 47437 | E30: 45
A32: Verizon New England Inc. | B32: 133 | C32: 0.07875 | D32: 47437 | E32: 133
A34: Verizon New York Inc. | B34: 35 | C34: 0.065 | D34: 46858
A35: Verizon New York Inc. | B35: 99 | C35: 0.07375 | D35: 11780 | E35: 134
A37: Alltel Corporation | B37: 38 | C37: 0.068 | D37: 47239
A38: Alltel Corporation | B38: 56 | C38: 0.07875 | D38: 11871 | E38: 94
A40: Verizon Communications Inc. | B40: 1161 | C40: 0.035 | D40: 45597
A41: Verizon Communications Inc. | B41: 1340 | C41: 0.03376 | D41: 45703
A42: Verizon Communications Inc. | B42: €1,000(a) | C42: 0.00875 | D42: 45749
A43: Verizon Communications Inc. | B43: 889 | C43: LIBOR+1.10% | D43: 45792
A44: Verizon Communications Inc. | B44: 1404 | C44: 0.0085 | D44: 45981
A45: Verizon Communications Inc. | B45: €1,250(a) | C45: 0.0325 | D45: 46070
A46: Verizon Communications Inc. | B46: 1916 | C46: 0.0145 | D46: 46101
A47: Verizon Communications Inc. | B47: 526 | C47: SOFR+0.79% | D47: 46101
A48: Verizon Communications Inc. | B48: 4 | C48: 0.011 | D48: 46188
A49: Verizon Communications Inc. | B49: 2 | C49: 0.0105 | D49: 46188
A50: Verizon Communications Inc. | B50: 1869 | C50: 0.02625 | D50: 46249
A51: Verizon Communications Inc. | B51: €1,250(a) | C51: 0.01375 | D51: 46322
A52: Verizon Communications Inc. | B52: 3250 | C52: 0.04125 | D52: 46462
A53: Verizon Communications Inc. | B53: 750 | C53: 0.03 | D53: 46468
A54: Verizon Communications Inc. | B54: €1,250(a) | C54: 0.00875 | D54: 46485
...

Sheet Assumptions
C2: Assumptions
D5: 2022 | E5: =D5-1 -> 2021 | F5: =E5-1 -> 2020 | G5: =F5-1 -> 2019 | H5: =G5-1 -> 2018 | J5: Average | L5: Short Term Forecast | M5: Long Term Forecast
C6: Revenue growth | D6: =(Inputs!B6-Inputs!C6)/Inputs!C6 -> 0.02411442 | E6: =(Inputs!C6-Inputs!D6)/Inputs!D6 -> 0.041475696 | F6: =(Inputs!D6-Inputs!E6)/Inputs!E6 -> -0.027118027 | G6: =(Inputs!E6-Inputs!F6)/Inputs!F6 -> 0.0076797873 | H6: =(Inputs!F6-Inputs!G6)/Inputs!G6 -> 0.038315058 | J6: =AVERAGE(D6:H6) -> 0.016893387 | L6: 0.03 | M6: 0.01
C7: Operating Margin | D7: =Inputs!B8/Inputs!B6 -> 0.22265502 | E7: =Inputs!C8/Inputs!C6 -> 0.24285062 | F7: =Inputs!D8/Inputs!D6 -> 0.2244723 | G7: =Inputs!E8/Inputs!E6 -> 0.23036673 | H7: =Inputs!F8/Inputs!F6 -> 0.17023911 | J7: =AVERAGE(D7:H7) -> 0.21811676 | L7: 0.224 | M7: =J7 -> 0.21811676
C10: Modelling Factors
D12: Last 5 Years
D13: 2018 | E13: 2019 | F13: 2020 | G13: 2021 | H13: 2022 | J13: Average | L13: Short Term Forecast | M13: Long Term Forecast | O13: Reference
C14: Depreciation factor | F14: =DCF!D9/DCF!D40 -> -0.051030075 | G14: =DCF!E9/DCF!E40 -> -0.048703505 | H14: =DCF!F9/DCF!F40 -> -0.04742451 | J14: =AVERAGE(D14:H14) -> -0.049052697 | L14: =J14 -> -0.049052697 | M14: =L14 -> -0.049052697
C15: Amortization factor | F15: =DCF!D10/DCF!D38 -> -0.088983513 | G15: =DCF!E10/DCF!E38 -> -0.073266632 | H15: =DCF!F10/DCF!F38 -> -0.082029972 | J15: =AVERAGE(D15:H15) -> -0.081426706 | L15: =J15 -> -0.081426706 | M15: =L15 -> -0.081426706
C16: Stock-based comp | F16: =+DCF!D11/DCF!D6 -> -0.0060798803 | G16: =+DCF!E11/DCF!E6 -> -0.0046776885 | H16: =+DCF!F11/DCF!F6 -> -0.0044506157 | J16: =AVERAGE(D16:H16) -> -0.0050693948 | L16: =J16 -> -0.0050693948 | M16: =L16 -> -0.0050693948
C17: Tax Rate | F17: =DCF!D16/DCF!D15 -> -0.23444737 | G17: =DCF!E16/DCF!E15 -> -0.23120326 | H17: =DCF!F16/DCF!F15 -> -0.23073114 | J17: =AVERAGE(D17:H17) -> -0.23212726 | L17: =J17 -> -0.23212726 | M17: =L17 -> -0.23212726
C18: Interest Rate on debt | D18: =H36 -> 0.04274608 | E18: =G36 -> 0.04242571 | F18: =F36 -> 0.033115867 | G18: =E36 -> 0.023099663 | H18: =D36 -> 0.023984493 | J18: =AVERAGE(D18:H18) -> 0.033074363 | L18: =J18 -> 0.033074363 | M18: {=-AVERAGE('Fin. Data'!B14:M14/'Fin. Data'!B58:M58)} -> 0.038521455
C19: Interest Rate on cash | L19: =J19 -> 0 | M19: =L19 -> 0
C20: PPE+ROA | L20: =J20 -> 0 | M20: =L20 -> 0
C21: Working capital flows | D21: =+Inputs!F62/(Inputs!F6-Inputs!G6) -> -0.54607579 | E21: =+Inputs!E62/(Inputs!E6-Inputs!F6) -> -3.5960199 | F21: =+Inputs!D62/(Inputs!D6-Inputs!E6) -> -0.79306488 | G21: =+Inputs!C62/(Inputs!C6-Inputs!D6) -> -0.18473971 | H21: =+Inputs!B62/(Inputs!B6-Inputs!C6) -> -1.3140906 | J21: =AVERAGE(D21:H21) -> -1.2867982 | L21: =J21 -> -1.2867982 | M21: =L21 -> -1.2867982
C22: Intangible Assets | L22: =J22 -> 0 | M22: =L22 -> 0
C23: CAPEX | D23: =+'Fin. Data'!F32/'Fin. Data'!F5 -> -0.13821325 | E23: =+'Fin. Data'!E32/'Fin. Data'!E5 -> -0.14284739 | F23: =+'Fin. Data'!D32/'Fin. Data'!D5 -> -0.15837309 | G23: =+'Fin. Data'!C32/'Fin. Data'!C5 -> -0.50804937 | H23: =+'Fin. Data'!B32/'Fin. Data'!B5 -> -0.19541784 | J23: =AVERAGE(D23:H23) -> -0.22858019 | L23: =J23 -> -0.22858019 | M23: {=AVERAGE('Fin. Data'!B32:M32/'Fin. Data'!B5:M5)} -> -0.18627613
C24: Acquisition factor | D24: ='Fin. Data'!F33/'Fin. Data'!F5 -> -0.0017575633 | E24: ='Fin. Data'!E33/'Fin. Data'!E5 -> -0.00021991689 | F24: ='Fin. Data'!D33/'Fin. Data'!D5 -> -0.0040532535 | G24: ='Fin. Data'!C33/'Fin. Data'!C5 -> -0.030423686 | H24: ='Fin. Data'!B33/'Fin. Data'!B5 -> 0.0018124018 | J24: =AVERAGE(D24:H24) -> -0.0069284036 | L24: =J24 -> -0.0069284036 | M24: {=AVERAGE('Fin. Data'!B33:M33/'Fin. Data'!B5:M5)} -> -0.014145907
C25: Dividends | D25: =-'Fin. Data'!F27/'Fin. Data'!F23 -> 0.60926492 | E25: =-'Fin. Data'!E27/'Fin. Data'!E23 -> 0.50616535 | F25: =-'Fin. Data'!D27/'Fin. Data'!D23 -> 0.55766296 | G25: =-'Fin. Data'!C27/'Fin. Data'!C23 -> 0.46180034 | H25: =-'Fin. Data'!B27/'Fin. Data'!B23 -> 0.49682729 | J25: =AVERAGE(D25:H25) -> 0.52634417 | L25: =J25 -> 0.52634417 | M25: {=-AVERAGE('Fin. Data'!B27:M27/'Fin. Data'!B23:M23)} -> 0.50265893
C26: Repurchases | D26: =-'Fin. Data'!F28/'Fin. Data'!F23 -> 0 | E26: =-'Fin. Data'!E28/'Fin. Data'!E23 -> 0 | F26: =-'Fin. Data'!D28/'Fin. Data'!D23 -> 0 | G26: =-'Fin. Data'!C28/'Fin. Data'!C23 -> 0 | H26: =-'Fin. Data'!B28/'Fin. Data'!B23 -> 0 | J26: =AVERAGE(D26:H26) -> 0 | L26: =J26 -> 0 | M26: =L26 -> 0
C29: Forecasts
B32: Interest Rate on Debt
D33: 2022 | E33: 2021 | F33: 2020 | G33: 2019 | H33: 2018 | I33: 2017 | J33: 2016 | K33: 2015 | L33: 2014 | M33: 2013 | N33: Average 10Y
B34: Interest Expense | D34: -3613 | E34: -3485 | F34: -4274 | G34: -4730 | H34: -4833 | I34: -4733 | J34: -4376 | K34: -4920 | L34: -4915 | M34: -2667
B35: Debt | D35: ='Fin. Data'!B58 -> 150639 | E35: ='Fin. Data'!C58 -> 150868 | F35: ='Fin. Data'!D58 -> 129062 | G35: ='Fin. Data'!E58 -> 111489 | H35: ='Fin. Data'!F58 -> 113063 | I35: ='Fin. Data'!G58 -> 117095 | J35: ='Fin. Data'!H58 -> 108078 | K35: ='Fin. Data'!I58 -> 109729 | ... M35: ='Fin. Data'!K58 -> 93591
D36: =-D34/D35 -> 0.023984493 | E36: =-E34/E35 -> 0.023099663 | F36: =-F34/F35 -> 0.033115867 | G36: =-G34/G35 -> 0.04242571 | H36: =-H34/H35 -> 0.04274608 | I36: =-I34/I35 -> 0.040420172 | J36: =-J34/J35 -> 0.040489276 | K36: =-K34/K35 -> 0.044837737 | ... M36: =-M34/M35 -> 0.02849633
B39: Debt/Ebitda | D39: ='Fin. Data'!B58/'Fin. Data'!B19 -> 3.2610785 | E39: ='Fin. Data'!C58/'Fin. Data'!C19 -> 3.1208473 | F39: ='Fin. Data'!D58/'Fin. Data'!D19 -> 2.7994881 | G39: ='Fin. Data'!E58/'Fin. Data'!E19 -> 2.2308954 | H39: ='Fin. Data'!F58/'Fin. Data'!F19 -> 3.0147722 | I39: ='Fin. Data'!G58/'Fin. Data'!G19 -> 2.5194182 | J39: ='Fin. Data'!H58/'Fin. Data'!H19 -> 2.4187181 | K39: ='Fin. Data'!I58/'Fin. Data'!I19 -> 2.240419 | ... M39: ='Fin. Data'!K58/'Fin. Data'!K19 -> 1.92582 | N39: =AVERAGE(D39:M39) -> 2.671806
O41: 2.9 | P41: Short term
B42: A3/A-(current level) | O42: 2.5 | P42: Medium term
B43: Default spread | I43: 0.02 | O43: 2.2 | P43: Long term
B44: 30Y US Bond Yield | I44: 0.0487
B45: 5Y US Bond Yield | I45: 0.0472
B46: Country default spread (US) | I46: 0
B47: Short-term cost debt | I47: =I43+I45+I46 -> 0.0672
B48: Long-term cost of debt | I48: =I46+I44+I43 -> 0.0687

Sheet Fin. Data
A1: =Inputs!H3 -> #VALUE!
A2: =Inputs!G2 -> Figures in Millions of USD
A3: Results
B4: =OP!J19 -> 2022 | C4: =B4-1 -> 2021 | D4: =C4-1 -> 2020 | E4: =D4-1 -> 2019 | F4: =E4-1 -> 2018 | G4: =F4-1 -> 2017 | H4: =G4-1 -> 2016 | I4: =H4-1 -> 2015 | J4: =I4-1 -> 2014 | ... M4: =L4-1 -> 2011
