Workbook
Name Benchmark: [1]ControlsH!$B$3
Name BestConsOv: #REF!
Name Broker_Name: OFFSET(#REF!,0,0,[1]ControlsH!$E$5, 1)
Name calCODE: [1]ControlsH!$C$4
Name Chart_Benchmark_100_Size: OFFSET(#REF!, 0, 0, [1]ControlsH!$E$3, 1)
Name Chart_Date_Size: OFFSET(#REF!, 0, 0, [1]ControlsH!$E$3, 1)
Name Chart_Date_VAL1_Size: OFFSET(#REF!, 0, 0, [1]ControlsH!$I$3, 1)
Name Chart_Date_VAL2_Size: OFFSET(#REF!, 0, 0, [1]ControlsH!$I$5, 1)
Name Chart_Peer_100_Size: OFFSET(#REF!, 0, 0, [1]ControlsH!$E$3, 1)
Name Chart_Price_100_Size: OFFSET(#REF!, 0, 0, [1]ControlsH!$E$3, 1)
Name Chart_Price_Size: OFFSET(#REF!, 0, 0, [1]ControlsH!$E$3, 1)
Name Chart_VAL1_FY1_Size: OFFSET(#REF!, 0, 0, [1]ControlsH!$F$3, 1)
Name Chart_VAL1_FY2_Size: OFFSET(#REF!, 0, 0, [1]ControlsH!$G$3, 1)
Name Chart_VAL1_FY3_Size: OFFSET(#REF!, 0, 0, [1]ControlsH!$H$3, 1)
Name Chart_VAL2_FY1_Size: OFFSET(#REF!, 0, 0, [1]ControlsH!$F$5, 1)
Name Chart_VAL2_FY2_Size: OFFSET(#REF!, 0, 0, [1]ControlsH!$G$5, 1)
Name Chart_VAL2_FY3_Size: OFFSET(#REF!, 0, 0, [1]ControlsH!$H$5, 1)
Name Chart_Volume_Size: OFFSET(#REF!, 0, 0, [1]ControlsH!$E$3, 1)
Name compNAME: [1]ControlsH!$B$6
Name CURRENCY: [1]ControlsH!$B$9
Name currPRICE: [1]Overview!$E$19
Name custBenchmark: [1]Overview!$C$9
Name custED: #REF!
Name custSD: #REF!
Name dayCODE: [1]ControlsH!$C$5
Name ED: [1]ControlsH!$B$5
Name ESTBrokersItem: #REF!
Name ESTBrokersPeriod: #REF!
Name ESTDetailBroker: #REF!
Name ESTDetailBroker2: #REF!
Name ESTDetailPeriod: #REF!
Name EstDetPerO: #REF!
Name EstDetPerT: #REF!
Name FinancialsPeriod: #REF!
Name fundTICKER: [1]ControlsH!$B$15
Name GraphValRatio1: #REF!
Name GraphValRatio2: #REF!
Name Index1: #REF!
Name Lang: [1]Overview!$D$11
Name newCrncy: [1]ControlsH!$B$21:$B$199
Name newEstBrokerPeriod: #REF!
Name newEstBrokersItem: #REF!
Name newEstDetailBroker: #REF!
Name newEstDetailBroker2: #REF!
Name newEstDetailPeriod: #REF!
Name newFinancialsPeriod: #REF!
Name newOverviewCon: #REF!
Name newOverviewYear: #REF!
Name newOwners: #REF!
Name newPeersRatio: #REF!
Name newPeriod: #REF!
Name newValRatio1: #REF!
Name newValRatio2: #REF!
Name OverviewValRatioPeriod: [1]Overview!$D$30
Name PeerDate1: [1]Peers!$S$11
Name peerHist1: #REF!
Name PeerIndex: [1]ControlsH!$F$35:$F$36
Name Peers: OFFSET([1]Peers!$C$18,0,0,MAX(COUNTA([1]Peers!$C$18:$C$47),1),1)
Name peersWEIGHT: [1]ControlsH!$B$13
Name PERIODICITY: [1]ControlsH!$C$3

Sheet OP
B2: (date of last modification) | C2: Analista: Research | D2: Report (quarter): (date) | E2: ANSYS Inc. (ANSS) | K2: (stock market) | L2: SIC: Sí
B3: #VALUE! | D3: DESCRIPTION: (write relevant information about the company, 1-2 lines is enough. If you find segments and key products relevant for this part, you can also write it here)
D4: CEO & BOARD: Name (Chairman or not; age; board member since; current board presence; previous jobs); note: *Independent members, green: new members
B5: Millones de USD
B6: Acción | D6: Liquidez y Solvencia | F6: =Segments!B2 -> Regions (2023) | I6: Rentabilidad (2024) | K6: Múltiplos
B7: Último Precio | C7: 334 | D7: Activo: | E7: =Cifras_en_Millones!B45 -> 8051.431 | H7: %Vts; %Op.Mg.; D | I7: Año termina: | J7: 31 December | K7: Float: | L7: =(96.87+0.61)/100 -> 0.9748
B8: Outstanding Shares | C8: 87.45 | D8: Pasivo: | E8: =Cifras_en_Millones!B57 -> 1096 | F8: =Segments!B4 -> US | H8: =+Segments!J4 -> 49%; NA; 18% | K8: Insiders Own: | L8: 0.0061
B9: Market Cap. | C9: =C7*C8 -> 29208.3 | D9: Cash/Precio | E9: =1000000*C11/C8 -> 16543659 | F9: =Segments!B5 -> Germany | H9: =+Segments!J5 -> 8%; NA; 5% | I9: EBIT | K9: b (Bloomberg; Yahoo) | L9: 1.12
B10: +Deuda Total | C10: =Cifras_en_Millones!B60 -> 86.93 | D10: Ebidta/CIF | F10: =Segments!B6 -> Japan | H10: =+Segments!J6 -> 7%; NA; -9% | I10: +Dep&Amort | J10: =Cifras_en_Millones!B17 -> 142.672 | K10: Calificación (S&P)
B11: -Cash | C11: =Cifras_en_Millones!B40 -> 1446.743 | D11: Deuda/Ebidta | E11: =Cifras_en_Millones!B60/Cifras_en_Millones!B19 -> 0.10063626 | F11: =Segments!B7 -> China and Hong Kong | H11: =+Segments!J7 -> 5%; NA; 14% | I11: =EBIDTA | J11: =J9+J10 -> 142.672 | K11: Precio/Valor en libros | L11: =((C7*C8)/1000000)/(E7-E8) -> 4.1993516e-06
B12: =Enterprise Value | C12: =C9+C10-C11 -> 27848.487 | D12: "Otros activos"/Activo | E12: =Cifras_en_Millones!B44/Cifras_en_Millones!B45 -> 0.68213862 | F12: =Segments!B8 -> South Korea | H12: =+Segments!J8 -> 4%; NA; 6% | I12: Utilidad Neta | J12: =Cifras_en_Millones!B23 -> 575.692 | K12: FNP(p)/Activos | L12: =J18/E7 -> 0
B13: Tenencia % (nac/int'l) | D13: Deuda/Activo | E13: =C10/E7 -> 0.010796838 | F13: Company reports only one product segment | I13: UPA | J13: =1000000*J12/C8 -> 6583098.9 | K13: Precio/Utilidad(p) | L13: =C9/J17 -> 54.772683 | N13: =C10/J11 -> 0.60929965
B14: t liq. (Pos prom./Vol.) | D14: Margen de Operación (p) | E14: =Cifras_en_Millones!B12 -> 0.2822327 | G14: NA | H14: NA | I14: ROA | J14: =J12/E7 -> 0.071501824 | K14: EV/Activos | L14: =C12/E7 -> 3.4588245
B15: % Short | C15: 0.019 | D15: Margen neto (p) | E15: =Cifras_en_Millones!B24 -> 0.22629403 | G15: NA | H15: NA | I15: ROIC | J15: =J12/(E7-(E8-C10)) -> 0.081747016 | K15: EV/Ebidta (p) | L15: =C12/J16 -> 35.088333
B16: Semáforo ESG | D16: Ebidta/Ingresos(p) | E16: =Cifras_en_Millones!B19/Cifras_en_Millones!B5 -> 0.3395456 | I16: Ebidta(p) | J16: =AVERAGE(Cifras_en_Millones!B19:D19) -> 793.668 | K16: Precio/FNP (p) | L16: =C9/J18 -> #DIV/0!
B17: E | D17: CIF/Deuda Neta Promedio | I17: Utilidad Neta (p) | J17: =AVERAGE(Cifras_en_Millones!B23:D23) -> 533.264 | K17: Bonos 1;5;40a (USD) | L17: 4.0%; 4.4%; 5% | N17: 12
B18: S | I18: FNP (p) | J18: =SUM(F35:F37)/3 -> 0 | K18: TDY(p)/Precio | L18: =SUM(E35:E37)/(3*C9) -> 0
B19: G | I19: Tax (p) últ. 5a | J19: 0.16 | K19: Div. Yield: | L19: =K33/C9 -> 0
B20: Tesis de inversión | H20: Acuerdo | I20: Supuestos de valuación | L20: DCF Value
B21: (Investment thesis) | H21: Mantener sin elevar posición | I21: VER DCF | L21: =DCFF!D66 -> 379.47843
B23: KSF | H23: PO / Precio Stand By | L23: =DCFF!D65 -> 0.13616296
H24: =DCFF!D71 -> -0.086599655 | I24: Tasa de descuento: | J24: =DCFF!D47 -> 0.0806
B25: Año | C25: Ingresos | D25: Margen Operativo | E25: Div.+Recompra | F25: FNP | G25: Deuda/Activo | H25: Depreciación | I25: Capex + Adq | J25: Cash Flow
B26: =B27-1 -> 2013 | C26: 861.3 | D26: 0.37373737 | K26: 2022 | L26: =K26-1 -> 2021
B27: =B28-1 -> 2014 | C27: 936 | D27: 0.37126068 | J27: Profit | N27: =C27/C26-1 -> 0.086729363 | O27: =D27/D26-1 -> -0.0066268191
B28: =B29-1 -> 2015 | C28: 942.8 | D28: 0.3751591 | J28: Cash Flow from Operations (BWC) | N28: =C28/C27-1 -> 0.0072649573 | O28: =D28/D27-1 -> 0.010500484 | P28: =E28/E27-1 -> #DIV/0! | Q28: =F28/F27-1 -> #DIV/0! | R28: =H28/H27-1 -> #DIV/0! | S28: =I28/I27-1 -> #DIV/0! | BT28: 4303
B29: =B30-1 -> 2016 | C29: 988.5 | D29: 0.38057663 | J29: Working Capital | N29: =C29/C28-1 -> 0.048472635 | O29: =D29/D28-1 -> 0.014440622 | P29: =E29/E28-1 -> #DIV/0! | Q29: =F29/F28-1 -> #DIV/0! | R29: =H29/H28-1 -> #DIV/0! | S29: =I29/I28-1 -> #DIV/0! | BT29: 3066
B30: =B31-1 -> 2017 | C30: 1095.3 | D30: 0.35670593 | J30: Investing Activities | N30: =C30/C29-1 -> 0.10804249 | O30: =D30/D29-1 -> -0.062722469 | P30: =E30/E29-1 -> #DIV/0! | Q30: =F30/F29-1 -> #DIV/0! | R30: =H30/H29-1 -> #DIV/0! | S30: =I30/I29-1 -> #DIV/0! | BT30: 3283
B31: =B32-1 -> 2018 | C31: 1293.6 | D31: 0.36842919 | J31: Capex | N31: =C31/C30-1 -> 0.18104629 | O31: =D31/D30-1 -> 0.032865348 | P31: =E31/E30-1 -> #DIV/0! | Q31: =F31/F30-1 -> #DIV/0! | R31: =H31/H30-1 -> #DIV/0! | S31: =I31/I30-1 -> #DIV/0!
B32: =B33-1 -> 2019 | C32: 1515.9 | D32: 0.33973217 | J32: Adquisiones | N32: =C32/C31-1 -> 0.17184601 | O32: =D32/D31-1 -> -0.077890184 | P32: =E32/E31-1 -> #DIV/0! | Q32: =F32/F31-1 -> #DIV/0! | R32: =H32/H31-1 -> #DIV/0! | S32: =I32/I31-1 -> #DIV/0!
B33: =B34-1 -> 2020 | C33: 1681.3 | D33: 0.29524772 | J33: Dividends | N33: =C33/C32-1 -> 0.1091101 | O33: =D33/D32-1 -> -0.13093975 | P33: =E33/E32-1 -> #DIV/0! | Q33: =F33/F32-1 -> #DIV/0! | R33: =H33/H32-1 -> #DIV/0! | S33: =I33/I32-1 -> #DIV/0!
B34: =B35-1 -> 2021 | C34: 1906.7 | D34: 0.26920858 | J34: Stock Repurchases | N34: =C34/C33-1 -> 0.13406293 | O34: =D34/D33-1 -> -0.088194226 | P34: =E34/E33-1 -> #DIV/0! | Q34: =F34/F33-1 -> #DIV/0! | R34: =H34/H33-1 -> #DIV/0! | S34: =I34/I33-1 -> #DIV/0!
B35: =B36-1 -> 2022 | C35: 2065.6 | D35: 0.28693842 | J35: Endeudamiento Neto | N35: =C35/C34-1 -> 0.083337704 | O35: =D35/D34-1 -> 0.065859118 | P35: =E35/E34-1 -> #DIV/0! | Q35: =F35/F34-1 -> #DIV/0! | R35: =H35/H34-1 -> #DIV/0! | S35: =I35/I34-1 -> #DIV/0!
B36: =B37-1 -> 2023 | C36: 2269.9 | D36: 0.27582713 | J36: Otros Financiemientos | N36: =C36/C35-1 -> 0.098905887 | O36: =D36/D35-1 -> -0.038723608
B37: 2024 | C37: 2544 | D37: 0.2822327 | N37: =C37/C36-1 -> 0.12075422 | O37: =D37/D36-1 -> 0.023223152
B38: 2024 Est. | C38: =DCFF!H6 -> 2509 | D38: =DCFF!H7 -> 0.23595058
B39: CAGR | C39: =(C37/C32)^(1/5)-1 -> 0.10909644 | D39: =(D37/D26)^(1/11)-1 -> -0.025206105 | J39: FX | K39: 0 | L39: 0
B40: AAG | C40: =AVERAGE(N27:N37) -> 0.1045066 | D40: =AVERAGE(O27:O37) -> -0.023473485 | J40: D Cash and Equivalents | K40: =K28+K29+K30+K33+K34+K35+K36+K39 -> 0 | L40: =L28+L29+L30+L33+L34+L35+L36+L39 -> 0
B41: CVAR | C41: =STDEV(C26:C37)/AVERAGE(C26:C37) -> 0.38473903 | D41: =STDEV(D26:D37)/AVERAGE(D26:D37) -> 0.13638766 | J41: Inv/D Vts | K41: =SUM(I33:I37)/(C37-C32) -> 0 | L41: =(SUM(I33:I37)-SUM(H33:H37))/(C37-C32) -> 0
B42: Último Año | C42: =C37/C36-1 -> 0.12075422 | D42: =D37/D36-1 -> 0.023223152 | J42: t inversiones; t adq. neto dep. | K42: =K41/E14 -> 0 | L42: =L41/E14 -> 0
...

Sheet COVID-19 impact
A1: https://www.apple.com/newsroom/2020/03/apples-covid-19-response/ | G1: https://glg.it/articles/how-might-the-wuhan-coronavirus-impact-apples-supply-chain/ | N1: https://www.cnbc.com/2020/02/18/the-significance-of-apples-coronavirus-warning.html
A2: March 13 | G2: January 29 | N2: Ferbuary 18
A23: Otros:
A24: https://www.macrumors.com/guide/covid-19-coronavirus/

Sheet Cifras_en_Millones
A1: =Cifras_Originales!G5 -> (Company name) ((ticker))
A2: =Cifras_Originales!C4 -> Cifras en Millones de USD
A4: Resultados | B4: 2024 | C4: =Cifras_Originales!B7 -> 2023 | D4: =Cifras_Originales!C7 -> 2022 | E4: =Cifras_Originales!D7 -> 2021 | F4: =Cifras_Originales!E7 -> 2020 | G4: =Cifras_Originales!F7 -> 2019 | H4: =Cifras_Originales!G7 -> 2018 | I4: =Cifras_Originales!H7 -> 2017 | J4: =Cifras_Originales!I7 -> 2016 | ... M4: =Cifras_Originales!L7 -> 2013
A5: Ventas Netas | B5: =Cifras_Originales!N8 -> 2544 | C5: =Cifras_Originales!B8 -> 2269.9 | D5: =Cifras_Originales!C8 -> 2065.6 | E5: =Cifras_Originales!D8 -> 1906.7 | F5: =Cifras_Originales!E8 -> 1681.3 | G5: =Cifras_Originales!F8 -> 1515.9 | H5: =Cifras_Originales!G8 -> 1293.6 | I5: =Cifras_Originales!H8 -> 1095.3 | J5: =Cifras_Originales!I8 -> 988.5 | ... M5: =Cifras_Originales!L8 -> 861.3
A6: Crecimiento vs. Año pasado | B6: =B5/C5-1 -> 0.12075422 | C6: =C5/D5-1 -> 0.098905887 | D6: =D5/E5-1 -> 0.083337704 | E6: =E5/F5-1 -> 0.13406293 | F6: =F5/G5-1 -> 0.1091101 | G6: =G5/H5-1 -> 0.17184601 | H6: =H5/I5-1 -> 0.18104629 | I6: =I5/J5-1 -> 0.10804249 | ... L6: =L5/M5-1 -> 0.086729363
A7: Utilidad Bruta | B7: =Cifras_Originales!N9 -> 2264 | C7: =Cifras_Originales!B9 -> 1998.7 | D7: =Cifras_Originales!C9 -> 1814.9 | E7: =Cifras_Originales!D9 -> 1648.7 | F7: =Cifras_Originales!E9 -> 1456 | G7: =Cifras_Originales!F9 -> 1349.6 | H7: =Cifras_Originales!G9 -> 1137.8 | I7: =Cifras_Originales!H9 -> 945.1 | J7: =Cifras_Originales!I9 -> 841.6 | ... M7: =Cifras_Originales!L9 -> 714.6
A8: porcentaje sobre ventas | B8: =B7/B5 -> 0.88993711 | C8: =C7/C5 -> 0.88052337 | D8: =D7/D5 -> 0.87863091 | E8: =E7/E5 -> 0.86468768 | F8: =F7/F5 -> 0.86599655 | G8: =G7/G5 -> 0.89029619 | H8: =H7/H5 -> 0.87956092 | I8: =I7/I5 -> 0.86286862 | ... M8: =M7/M5 -> 0.82967607
A9: Gastos de Operación | B9: =B5-B11 -> 1826 | C9: =C5-C11 -> 1643.8 | D9: =D5-D11 -> 1472.9 | E9: =E5-E11 -> 1393.4 | F9: =F5-F11 -> 1184.9 | G9: =G5-G11 -> 1000.9 | H9: =H5-H11 -> 817 | I9: =I5-I11 -> 704.6 | ... M9: =M5-M11 -> 539.4
A10: porcentaje sobre ventas | B10: =B9/B5 -> 0.7177673 | C10: =C9/C5 -> 0.72417287 | D10: =D9/D5 -> 0.71306158 | E10: =E9/E5 -> 0.73079142 | F10: =F9/F5 -> 0.70475228 | G10: =G9/G5 -> 0.66026783 | H10: =H9/H5 -> 0.63157081 | I10: =I9/I5 -> 0.64329407 | ... M10: =M9/M5 -> 0.62626263
A11: Utilidad de Operación | B11: =Cifras_Originales!N10 -> 718 | C11: =Cifras_Originales!B10 -> 626.1 | D11: =Cifras_Originales!C10 -> 592.7 | E11: =Cifras_Originales!D10 -> 513.3 | F11: =Cifras_Originales!E10 -> 496.4 | G11: =Cifras_Originales!F10 -> 515 | H11: =Cifras_Originales!G10 -> 476.6 | I11: =Cifras_Originales!H10 -> 390.7 | J11: =Cifras_Originales!I10 -> 376.2 | ... M11: =Cifras_Originales!L10 -> 321.9
A12: porcentaje sobre ventas | B12: =B11/B5 -> 0.2822327 | C12: =C11/C5 -> 0.27582713 | D12: =D11/D5 -> 0.28693842 | E12: =E11/E5 -> 0.26920858 | F12: =F11/F5 -> 0.29524772 | G12: =G11/G5 -> 0.33973217 | H12: =H11/H5 -> 0.36842919 | I12: =I11/I5 -> 0.35670593 | ... M12: =M11/M5 -> 0.37373737
A13: Crecimiento vs año anterior | B13: =B11/C11-1 -> 0.14678166 | C13: =C11/D11-1 -> 0.056352286 | D13: =D11/E11-1 -> 0.15468537 | E13: =E11/F11-1 -> 0.034045125 | F13: =F11/G11-1 -> -0.036116505 | G13: =G11/H11-1 -> 0.080570709 | H13: =H11/I11-1 -> 0.21986179 | I13: =I11/J11-1 -> 0.038543328 | ... L13: =L11/M11-1 -> 0.079527804
A14: CIF (Productos Financieros) | B14: =Cifras_Originales!N11 -> -3.29 | C14: =Cifras_Originales!B11 -> 43.9 | D14: =Cifras_Originales!C11 -> -5.4 | E14: =Cifras_Originales!D11 -> 5 | F14: =Cifras_Originales!E11 -> 4.2 | G14: =Cifras_Originales!F11 -> 56.2 | H14: =Cifras_Originales!G11 -> -13.3 | I14: =Cifras_Originales!H11 -> 55.1 | J14: =Cifras_Originales!I11 -> 38.8 | ... M14: =Cifras_Originales!L11 -> -28.2
A15: Otros Gastos (Productos) | B15: =Cifras_Originales!N12 -> -3.132 | C15: =Cifras_Originales!B12 -> -34 | D15: =Cifras_Originales!C12 -> -17.34 | E15: =Cifras_Originales!D12 -> 2.08 | F15: =Cifras_Originales!E12 -> -2.43 | G15: =Cifras_Originales!F12 -> 7.54 | H15: =Cifras_Originales!G12 -> 10.51 | I15: =Cifras_Originales!H12 -> 4.97 | J15: =Cifras_Originales!I12 -> 4.07 | ... M15: =Cifras_Originales!L12 -> 0.626
A16: Utilidad antes de Impuestos y partidas extra. | B16: =B11-B14-B15 -> 724.422 | C16: =C11-C14-C15 -> 616.2 | D16: =D11-D14-D15 -> 615.44 | E16: =E11-E14-E15 -> 506.22 | F16: =F11-F14-F15 -> 494.63 | G16: =G11-G14-G15 -> 451.26 | H16: =H11-H14-H15 -> 479.39 | I16: =I11-I14-I15 -> 330.63 | ... M16: =M11-M14-M15 -> 349.474
A17: Depreciación y amortización del ejercicio | B17: =Cifras_Originales!N13 -> 142.672 | C17: =Cifras_Originales!B13 -> 132.5 | D17: =Cifras_Originales!C13 -> 114.56 | E17: =Cifras_Originales!D13 -> 106.87 | F17: =Cifras_Originales!E13 -> 106.25 | G17: =Cifras_Originales!F13 -> 78.97 | H17: =Cifras_Originales!G13 -> 59.26 | I17: =Cifras_Originales!H13 -> 67.68 | J17: =Cifras_Originales!I13 -> 69.59 | ... M17: =Cifras_Originales!L13 -> 80.7
A18: Capital de Trabajo | B18: =Cifras_Originales!N14 -> 189 | C18: =Cifras_Originales!B14 -> 1160.3 | D18: =Cifras_Originales!C14 -> 869.3 | E18: =Cifras_Originales!D14 -> 860.1 | F18: =Cifras_Originales!E14 -> 990.4 | G18: =Cifras_Originales!F14 -> 860.4 | H18: =Cifras_Originales!G14 -> 786.4 | I18: =Cifras_Originales!H14 -> 661.7 | J18: =Cifras_Originales!I14 -> 630.3 | ... M18: =Cifras_Originales!L14 -> 627.2
A19: EBITDA (flujo operativo) | B19: =B11-B15+B17 -> 863.804 | C19: =C11-C15+C17 -> 792.6 | D19: =D11-D15+D17 -> 724.6 | E19: =E11-E15+E17 -> 618.09 | F19: =F11-F15+F17 -> 605.08 | G19: =G11-G15+G17 -> 586.43 | H19: =H11-H15+H17 -> 525.35 | I19: =I11-I15+I17 -> 453.41 | ... M19: =M11-M15+M17 -> 401.974
A20: porcentaje sobre ventas | B20: =B19/B5 -> 0.3395456 | C20: =C19/C5 -> 0.34917838 | D20: =D19/D5 -> 0.35079396 | E20: =E19/E5 -> 0.32416741 | F20: =F19/F5 -> 0.35988818 | G20: =G19/G5 -> 0.38685269 | H20: =H19/H5 -> 0.40611472 | I20: =I19/I5 -> 0.41395965 | ... M20: =M19/M5 -> 0.46670614
A21: I.S.R Y P.T.U. | B21: 142.346 | C21: =Cifras_Originales!B17 -> 115.8 | D21: =Cifras_Originales!C17 -> 91.7 | E21: =Cifras_Originales!D17 -> 51.6 | F21: =Cifras_Originales!E17 -> 60.7 | G21: =Cifras_Originales!F17 -> 0 | H21: =Cifras_Originales!G17 -> 60 | I21: =Cifras_Originales!H17 -> 71.3 | J21: =Cifras_Originales!I17 -> 67.7 | ... M21: =Cifras_Originales!L17 -> 104.2
A22: % Tax | B22: =+B21/B16 -> 0.19649597 | C22: =+C21/C16 -> 0.187926 | D22: =+D21/D16 -> 0.14899909 | E22: =+E21/E16 -> 0.10193197 | F22: =+F21/F16 -> 0.12271799 | G22: =+G21/G16 -> 0 | H22: =+H21/H16 -> 0.12515906 | I22: =+I21/I16 -> 0.21564891 | ... M22: =+M21/M16 -> 0.29816238
A23: Utilidad Neta | B23: =Cifras_Originales!N18 -> 575.692 | C23: =Cifras_Originales!B18 -> 500.4 | D23: =Cifras_Originales!C18 -> 523.7 | E23: =Cifras_Originales!D18 -> 454.6 | F23: =Cifras_Originales!E18 -> 433.9 | G23: =Cifras_Originales!F18 -> 451.3 | H23: =Cifras_Originales!G18 -> 419.4 | I23: =Cifras_Originales!H18 -> 259.3 | J23: =Cifras_Originales!I18 -> 265.6 | ... M23: =Cifras_Originales!L18 -> 245.3
A24: porcentaje sobre ventas | B24: =B23/B5 -> 0.22629403 | C24: =C23/C5 -> 0.22045024 | D24: =D23/D5 -> 0.25353408 | E24: =E23/E5 -> 0.23842241 | F24: =F23/F5 -> 0.25807411 | G24: =G23/G5 -> 0.29771093 | H24: =H23/H5 -> 0.3242115 | I24: =I23/I5 -> 0.23673879 | ... M24: =M23/M5 -> 0.28480204
A25: Crecimiento vs año anterior | B25: =B23/C23-1 -> 0.15046363 | C25: =C23/D23-1 -> -0.044491121 | D25: =D23/E23-1 -> 0.15200176 | E25: =E23/F23-1 -> 0.047706845 | F25: =F23/G23-1 -> -0.038555285 | G25: =G23/H23-1 -> 0.07606104 | H25: =H23/I23-1 -> 0.61743155 | I25: =I23/J23-1 -> -0.02371988 | ... L25: =L23/M23-1 -> 0.038320424
A26: Efectivo Generado | B26: =B40-C40 -> 586.543 | C26: =C40-D40 -> 245.8 | D26: =D40-E40 -> -53.3 | E26: =E40-F40 -> -245 | F26: =F40-G40 -> 40.6 | G26: =G40-H40 -> 95 | H26: =H40-I40 -> -104.4 | I26: =I40-J40 -> 59 | ... M26: =M40-N40 -> 742.5
A27: Dividendos | B27: 0 | C27: =Cifras_Originales!B19 -> 0 | D27: =Cifras_Originales!C19 -> 0 | E27: =Cifras_Originales!D19 -> 0 | F27: =Cifras_Originales!E19 -> 0 | G27: =Cifras_Originales!F19 -> 0 | H27: =Cifras_Originales!G19 -> 0 | I27: =Cifras_Originales!H19 -> 0 | J27: =Cifras_Originales!I19 -> 0 | ... M27: =Cifras_Originales!L19 -> 0
A29: Recompra de Acciones | B29: 0 | C29: =Cifras_Originales!B20 -> -47.2 | D29: =Cifras_Originales!C20 -> -69.2 | E29: =Cifras_Originales!D20 -> -175.9 | F29: =Cifras_Originales!E20 -> -294.3 | G29: =Cifras_Originales!F20 -> -282.5 | H29: =Cifras_Originales!G20 -> -294.7 | I29: =Cifras_Originales!H20 -> -257.7 | J29: =Cifras_Originales!I20 -> -67.5 | ... M29: =Cifras_Originales!L20 -> -244.2
A30: FNP | B30: =SUM(B26:B29) -> 586.543 | C30: =SUM(C26:C29) -> 198.6 | D30: =SUM(D26:D29) -> -122.5 | E30: =SUM(E26:E29) -> -420.9 | F30: =SUM(F26:F29) -> -253.7 | G30: =SUM(G26:G29) -> -187.5 | H30: =SUM(H26:H29) -> -399.1 | I30: =SUM(I26:I29) -> -198.7 | ... M30: =SUM(M26:M29) -> 498.3
A31: FNP (ajustado por deuda) | B31: =B30-(B60-C60) -> 552.713 | C31: =C30-(C60-D60) -> 145.5 | D31: =D30-(D60-E60) -> -122.5 | E31: =E30-(E60-F60) -> -420.9 | F31: =F30-(F60-G60) -> -253.7 | G31: =G30-(G60-H60) -> -187.5 | H31: =H30-(H60-I60) -> -399.1 | I31: =I30-(I60-J60) -> 519.8 | ... M31: =M30-(M60-N60) -> -526.5
A32: FNP (ajustado por inversiones) | B32: =B31+B34 -> 552.713 | C32: =C31+C34 -> 145.5 | D32: =D31+D34 -> -122.5 | E32: =E31+E34 -> -420.9 | F32: =F31+F34 -> -253.7 | G32: =G31+G34 -> -187.5 | H32: =H31+H34 -> -399.1 | I32: =I31+I34 -> 519.8 | ... M32: =M31+M34 -> -526.761
A33: Capex | B33: -44 | C33: =Cifras_Originales!B15 -> -25.3 | D33: =Cifras_Originales!C15 -> -24.37 | E33: =Cifras_Originales!D15 -> -23.02 | F33: =Cifras_Originales!E15 -> -35.37 | G33: =Cifras_Originales!F15 -> -44.94 | H33: =Cifras_Originales!G15 -> -21.76 | I33: =Cifras_Originales!H15 -> -19.15 | J33: =Cifras_Originales!I15 -> -12.44 | ... M33: =Cifras_Originales!L15 -> -28.85
A34: Inversiones | B34: 0 | C34: =Cifras_Originales!B16 -> 0 | D34: =Cifras_Originales!C16 -> 0 | E34: =Cifras_Originales!D16 -> 0 | F34: =Cifras_Originales!E16 -> 0 | G34: =Cifras_Originales!F16 -> 0 | H34: =Cifras_Originales!G16 -> 0 | I34: =Cifras_Originales!H16 -> 0 | J34: =Cifras_Originales!I16 -> 0 | ... M34: =Cifras_Originales!L16 -> -0.261
A35: Capex + Inversiones | B35: =B33+C34 -> -44 | C35: =+C34+C33 -> -25.3 | D35: =+D34+D33 -> -24.37 | E35: =+E34+E33 -> -23.02 | F35: =+F34+F33 -> -35.37 | G35: =+G34+G33 -> -44.94 | H35: =+H34+H33 -> -21.76 | I35: =+I34+I33 -> -19.15 | J35: =+J34+J33 -> -12.44 | ... M35: =+M34+M33 -> -29.111
B36: =+B35/B5 -> -0.017295597 | C36: =+C35/C5 -> -0.011145865 | D36: =+D35/D5 -> -0.011798025 | E36: =+E35/E5 -> -0.012073216 | F36: =+F35/F5 -> -0.021037293 | G36: =+G35/G5 -> -0.029645755 | H36: =+H35/H5 -> -0.016821274 | I36: =+I35/I5 -> -0.017483794 | ... M36: =+M35/M5 -> -0.033798909
A37: Dividendos + Recompra de Acciones | B37: =SUM(B27:B29) -> 0 | C37: =SUM(C27:C29) -> -47.2 | D37: =SUM(D27:D29) -> -69.2 | E37: =SUM(E27:E29) -> -175.9 | F37: =SUM(F27:F29) -> -294.3 | G37: =SUM(G27:G29) -> -282.5 | H37: =SUM(H27:H29) -> -294.7 | I37: =SUM(I27:I29) -> -257.7 | ... M37: =SUM(M27:M29) -> -244.2
A39: Activo
A40: Caja | B40: 1446.743 | C40: =Cifras_Originales!B24 -> 860.2 | D40: =Cifras_Originales!C24 -> 614.4 | E40: =Cifras_Originales!D24 -> 667.7 | F40: =Cifras_Originales!E24 -> 912.7 | G40: =Cifras_Originales!F24 -> 872.1 | H40: =Cifras_Originales!G24 -> 777.1 | I40: =Cifras_Originales!H24 -> 881.5 | J40: =Cifras_Originales!I24 -> 822.5 | ... M40: =Cifras_Originales!L24 -> 742.5
A41: Cuentas y documentos por cobrar | B41: 1022.85 | C41: =Cifras_Originales!B25 -> 864.5 | D41: =Cifras_Originales!C25 -> 760.3 | E41: =Cifras_Originales!D25 -> 645.9 | F41: =Cifras_Originales!E25 -> 537.6 | G41: =Cifras_Originales!F25 -> 433.5 | H41: =Cifras_Originales!G25 -> 317.7 | I41: =Cifras_Originales!H25 -> 124.7 | J41: =Cifras_Originales!I25 -> 107.2 | ... M41: =Cifras_Originales!L25 -> 97.8
A42: Inventarios | B42: 0 | C42: =Cifras_Originales!B26 -> 0 | D42: =Cifras_Originales!C26 -> 0 | E42: =Cifras_Originales!D26 -> 0 | F42: =Cifras_Originales!E26 -> 0 | G42: =Cifras_Originales!F26 -> 0 | H42: =Cifras_Originales!G26 -> 0 | I42: =Cifras_Originales!H26 -> 0 | J42: =Cifras_Originales!I26 -> 0 | ... M42: =Cifras_Originales!L26 -> 0
A43: Activos Fijos (Net Plant) | B43: 89.646 | C43: =Cifras_Originales!B27 -> 194.8 | D43: =Cifras_Originales!C27 -> 210 | E43: =Cifras_Originales!D27 -> 208.8 | F43: =Cifras_Originales!E27 -> 234.2 | G43: =Cifras_Originales!F27 -> 189.3 | H43: =Cifras_Originales!G27 -> 61.7 | I43: =Cifras_Originales!H27 -> 57.1 | J43: =Cifras_Originales!I27 -> 54.7 | ... M43: =Cifras_Originales!L27 -> 60.5 | P43: 24 | Q43: =P43-1 -> 23 | R43: =Q43-1 -> 22 | S43: =R43-1 -> 21 | T43: =S43-1 -> 20 | U43: =T43-1 -> 19 | V43: =U43-1 -> 18 | W43: =V43-1 -> 17 | X43: =W43-1 -> 16 | ... AA43: =Z43-1 -> 13
...

Sheet Segments
B2: Regions (2023) | L2: Proyectado | N2: Escenario de estrés | X2: Escenario de estrés
C3: 2024 | D3: =C3-1 -> 2023 | E3: Ut. Operativa | F3: % Vts | G3: Margen | H3: Crec | L3: Crecimiento | M3: 2022 (Real) | N3: 2023 (Real) | O3: 2024 (Real) | P3: 2025 | Q3: 2026 | R3: 2027 | S3: 2028 | T3: 2029 | V3: Márgenes (regional) | W3: 2022 (Real) | X3: 2023 (Real) | Y3: 2024 (Real) | Z3: 2025 | AA3: 2026 | AB3: 2027 | AC3: 2028 | AD3: 2029
B4: US | C4: 1251892 | D4: 1058293 | E4: NA | F4: =C4/$C$14 -> 0.49193947 | G4: NA | H4: =C4/D4-1 -> 0.18293516 | J4: =IF(C4="","",IF(F4=0,"NA",TEXT(F4,"0%"))&"; "&IF(G4=0,"NA",TEXT(G4,"0.0%"))&"; "&IF(H4=0,"NA",TEXT(H4,"0%"))) -> 49%; NA; 18% | L4: =B17 -> 0 | V4: =B4 -> US | W4: 932587
B5: Germany | C5: 209714 | D5: 199068 | E5: NA | F5: =C5/$C$14 -> 0.082408542 | G5: NA | H5: =C5/D5-1 -> 0.053479213 | J5: =IF(C5="","",IF(F5=0,"NA",TEXT(F5,"0%"))&"; "&IF(G5=0,"NA",TEXT(G5,"0.0%"))&"; "&IF(H5=0,"NA",TEXT(H5,"0%"))) -> 8%; NA; 5% | L5: =B18 -> 0 | V5: =B5 -> Germany | W5: 198612
B6: Japan | C6: 184547 | D6: 203013 | E6: NA | F6: =C6/$C$14 -> 0.072518998 | G6: NA | H6: =C6/D6-1 -> -0.090959692 | J6: =IF(C6="","",IF(F6=0,"NA",TEXT(F6,"0%"))&"; "&IF(G6=0,"NA",TEXT(G6,"0.0%"))&"; "&IF(H6=0,"NA",TEXT(H6,"0%"))) -> 7%; NA; -9% | L6: =B19 -> 0 | V6: =B6 -> Japan | W6: 186199
B7: China and Hong Kong | C7: 126628 | D7: 111467 | E7: NA | F7: =C7/$C$14 -> 0.049759334 | G7: NA | H7: =C7/D7-1 -> 0.13601335 | J7: =IF(C7="","",IF(F7=0,"NA",TEXT(F7,"0%"))&"; "&IF(G7=0,"NA",TEXT(G7,"0.0%"))&"; "&IF(H7=0,"NA",TEXT(H7,"0%"))) -> 5%; NA; 14% | L7: =B20 -> 0 | V7: =B7 -> China and Hong Kong | W7: 105101
B8: South Korea | C8: 112895 | D8: 106261 | E8: NA | F8: =C8/$C$14 -> 0.044362858 | G8: NA | H8: =C8/D8-1 -> 0.062431184 | J8: =IF(C8="","",IF(F8=0,"NA",TEXT(F8,"0%"))&"; "&IF(G8=0,"NA",TEXT(G8,"0.0%"))&"; "&IF(H8=0,"NA",TEXT(H8,"0%"))) -> 4%; NA; 6% | L8: =B21 -> 0 | V8: =B8 -> South Korea
B9: Other EMEA | C9: 445791 | D9: 406719 | E9: NA | F9: =C9/$C$14 -> 0.1751766 | G9: NA | H9: =C9/D9-1 -> 0.096066326 | J9: =IF(C9="","",IF(F9=0,"NA",TEXT(F9,"0%"))&"; "&IF(G9=0,"NA",TEXT(G9,"0.0%"))&"; "&IF(H9=0,"NA",TEXT(H9,"0%"))) -> 18%; NA; 10% | L9: % vts. | V9: Margen Operativp | W9: =(#REF!*W12+#REF!*W13+#REF!*W14+#REF!*W15+W8*W16)/SUM(W12:W16)+W10 -> #REF! | X9: =(X4*X12+X5*X13+X6*X14+X7*X15+X8*X16)/SUM(X12:X16)+X10 -> #DIV/0! | Y9: =(Y4*Y12+Y5*Y13+Y6*Y14+Y7*Y15+Y8*Y16)/SUM(Y12:Y16)+Y10 -> #DIV/0! | Z9: =(Z4*Z12+Z5*Z13+Z6*Z14+Z7*Z15+Z8*Z16)/SUM(Z12:Z16)+Z10 -> #DIV/0! | AA9: =(AA4*AA12+AA5*AA13+AA6*AA14+AA7*AA15+AA8*AA16)/SUM(AA12:AA16)+AA10 -> #DIV/0! | AB9: =(AB4*AB12+AB5*AB13+AB6*AB14+AB7*AB15+AB8*AB16)/SUM(AB12:AB16)+AB10 -> #DIV/0! | AC9: =(AC4*AC12+AC5*AC13+AC6*AC14+AC7*AC15+AC8*AC16)/SUM(AC12:AC16)+AC10 -> #DIV/0! | AD9: =(AD4*AD12+AD5*AD13+AD6*AD14+AD7*AD15+AD8*AD16)/SUM(AD12:AD16)+AD10 -> #DIV/0!
B10: Other International | C10: 213342 | D10: 185128 | E10: NA | F10: =C10/$C$14 -> 0.08383419 | G10: NA | H10: =C10/D10-1 -> 0.15240266 | J10: =IF(C10="","",IF(F10=0,"NA",TEXT(F10,"0%"))&"; "&IF(G10=0,"NA",TEXT(G10,"0.0%"))&"; "&IF(H10=0,"NA",TEXT(H10,"0%"))) -> 8%; NA; 15% | L10: =B17 -> 0 | V10: Ajuste R&D | W10: =(-6200-18752)/274515 -> -0.090894851 | X10: =(-6143-21914)/365817 -> -0.076696818 | Y10: =(-7207-26251)/394328 -> -0.084848147 | Z10: -0.1 | AA10: -0.1 | AB10: -0.1 | AC10: -0.1 | AD10: -0.1
J11: =IF(C11="","",IF(F11=0,"NA",TEXT(F11,"0%"))&"; "&IF(G11=0,"NA",TEXT(G11,"0.0%"))&"; "&IF(H11=0,"NA",TEXT(H11,"0%"))) | L11: =B18 -> 0 | V11: % vts.
J12: =IF(C12="","",IF(F12=0,"NA",TEXT(F12,"0%"))&"; "&IF(G12=0,"NA",TEXT(G12,"0.0%"))&"; "&IF(H12=0,"NA",TEXT(H12,"0%"))) | L12: =B19 -> 0 | V12: =V4 -> US
J13: =IF(C13="","",IF(F13=0,"NA",TEXT(F13,"0%"))&"; "&IF(G13=0,"NA",TEXT(G13,"0.0%"))&"; "&IF(H13=0,"NA",TEXT(H13,"0%"))) | L13: =B20 -> 0 | V13: =V5 -> Germany
B14: TOTAL | C14: =SUM(C4:C12) -> 2544809 | D14: =SUM(D4:D12) -> 2269949 | E14: NA | F14: =C14/SUM($C$4:$C$13) -> 1 | G14: NA | H14: =C14/D14-1 -> 0.12108642 | L14: =B21 -> 0 | V14: =V6 -> Japan
M15: =SUM(M10:M14) -> 0 | N15: =SUM(N10:N14) -> 0 | O15: =SUM(O10:O14) -> 0 | P15: =SUM(P10:P14) -> 0 | Q15: =SUM(Q10:Q14) -> 0 | R15: =SUM(R10:R14) -> 0 | S15: =SUM(S10:S14) -> 0 | T15: =SUM(T10:T14) -> 0 | V15: =V7 -> China and Hong Kong
N16: =N15/M15-1 -> #DIV/0! | O16: =O15/N15-1 -> #DIV/0! | P16: =P15/O15-1 -> #DIV/0! | Q16: =Q15/P15-1 -> #DIV/0! | R16: =R15/Q15-1 -> #DIV/0! | S16: =S15/R15-1 -> #DIV/0! | T16: =T15/S15-1 -> #DIV/0! | V16: =V8 -> South Korea
W17: =SUM(W12:W16) -> 0 | X17: =SUM(X12:X16) -> 0 | Y17: =SUM(Y12:Y16) -> 0 | Z17: =SUM(Z12:Z16) -> 0 | AA17: =SUM(AA12:AA16) -> 0 | AB17: =SUM(AB12:AB16) -> 0 | AC17: =SUM(AC12:AC16) -> 0 | AD17: =SUM(AD12:AD16) -> 0

Sheet Peers
A2: Multiplos (USD) | B2: ANSS | C2: DSY.PA | D2: ALTR | E2: PTC
B3: Ansys | C3: Dassault Systèmes | D3: Altair Engineering | E3: PTC
A4: Ventas | B4: =Cifras_en_Millones!B5 -> 2544 | C4: 6213 | D4: 665.788 | E4: 2298.472 | G4: Averages
A5: Crecimiento (1S23/1S22) | B5: 9.89% | C5: 5.05% | D5: 5.04% | E5: 8.47% | G5: =AVERAGE(B5:E5) -> #DIV/0!
A6: Crecimiento (1S23/1S19) | B6: 45.7% | C6: 48.1% | D6: 30.9% | E6: 0.67 | G6: =AVERAGE(B6:E6) -> 0.67
A7: Deuda | B7: 122278 | C7: 82110 | D7: 26772 | E7: 100504 | G7: =AVERAGE(B7:E7) -> 82916
A8: Activos | B8: 323888 | C8: 301311 | D8: 319616 | E8: 321195 | G8: =AVERAGE(B8:E8) -> 316502.5
A9: Deuda/Activos | B9: =Cifras_Originales!$B$41/Cifras_Originales!$B$29 -> 0.10004233 | C9: =14622/14622 -> 1 | D9: =652162/1363493 -> 0.47830242 | E9: =3611552/6288842 -> 0.57427933 | G9: =AVERAGE(B9:E9) -> 0.53815602
A10: Deuda/EBITDA | B10: =733/793 -> 0.92433796 | C10: =(14622.5/1241.9) -> 11.774297 | D10: =652.162/31.09 -> 20.976584 | E10: =6288.842/498.5 -> 12.615531 | G10: =AVERAGE(B10:E10) -> 11.572688
A11: (Capex + Adq.)/Revenue | B11: =-DCFF!G22/DCFF!G6 -> 0.011013701 | C11: 3.19% | D11: 6.86% | E11: 9.53% | G11: =AVERAGE(B11:E11) -> 0.011013701
A12: ROA (p) | B12: 7.18% | C12: 7.18% | D12: -0.0065 | E12: 3.9% | G12: =AVERAGE(B12:E12) -> -0.0065
A13: ROIC (p) | B13: 6.34% | C13: 12.08% | D13: =-0.0192%% -> -1.92e-06 | E13: 10.15% | G13: =AVERAGE(B13:E13) -> -1.92e-06
A14: Margen Operativo 2024 | B14: 24.27% | C14: 20.86% | D14: 0.02656 | E14: 21.86% | G14: =AVERAGE(B14:E14) -> 0.02656
A15: Margen Operativo 2023 | B15: 26.31% | C15: 22.99% | D15: 0.0003966 | E15: 23.14% | G15: =AVERAGE(B15:E15) -> 0.0003966
A16: Float | B16: 87.26 | C16: 668.54 | D16: 46.51 | E16: 113.92 | G16: =AVERAGE(B16:E16) -> #DIV/0!
A17: b | B17: 1.12 | C17: 0.62 | D17: 1.42 | E17: 1.19 | G17: =AVERAGE(B17:E17) -> 1.42
A18: Precio/Utilidad | B18: 51.02 | C18: 44.13 | D18: 698.62 | E18: 49.74 | G18: =AVERAGE(B18:E18) -> 210.8775
A19: Precio/Ventas | B19: 11.99 | C19: 7.34 | D19: 14.61 | E19: 9.66 | G19: =AVERAGE(B19:E19) -> 10.9
A20: EV/Activos | B20: 3.6082474 | C20: 2.7491961 | D20: 6.2377632 | E20: 3.7241379 | G20: =AVERAGE(B20:E20) -> 4.0798362
A21: EV/Ebitda | B21: 33.24 | C21: 22.21 | D21: 91.2 | E21: 32.59 | G21: =AVERAGE(B21:E21) -> 44.81
A22: Div. Yield: | B22: 0 | C22: 0.58% | D22: 0 | E22: 0
B24: *Nota: Estos múltiplos no consideran el promedio de los últimos 3 años, únicamente valores del último año reportado
B25: **Cifras en USD
A27: (You can make up a table with different indicators in order to link them to the multiples/ratios. At the end, put the table unvisible with white color)

Sheet Acuerdo
A1: Invertir
A2: NO invertir
A3: Mantener sin elevar posición
A4: Mantener (y seguir comprando)
A5: Liquidar
A6: PENDIENTE

Sheet ESG
B2: Análisis ESG | J2: PARÁMETROS
C3: Impacto | D3: ¿Reporta? | E3: Ranking | F3: Mitigación | G3: Semáforo | H3: Comentarios | J3: IMPACTO | L3: RANKING | M3: MITIGACIÓN
B4: Ambiental | J4: NONE | K4: 0 | L4: "Best in class" | M4: Is there evidence of progam/plan/etc…
B5: Emisiones directas CO2 | C5: 0 | D5: Si | E5: "Best in class" | J5: LOW | K5: 1 | L5: Medium high
B6: Uso total de agua | D6: No | J6: MEDIUM | K6: 2 | L6: Medium
B7: Total Energy Consumption | C7: 1 | D7: Si | E7: "Best in class" | J7: HIGH | K7: 3 | L7: "Villain"
B8: Waste Management | D8: No
B9: Land Degradation/Deforestation/Biodiversity loss/Animal sufering/… | D9: No | J9: TRAFFIC LIGHTS
B10: Social
B11: % Rotación de empleados | C11: 0 | D11: Si | E11: "Best in class"
B12: Sueldos y compensaciones | C12: 1 | D12: Si | E12: Medium high
B13: Temas de reputación | C13: 0 | D13: Si | E13: "Best in class"
B14: Temas de discriminación | D14: No
B15: Seguridad laboral | D15: No
B16: Daños a la salud | D16: No
B17: PXP?
B18: Supply chain | D18: No
B19: Community involvement | C19: Medium | D19: Si
B20: Public Sector | D20: No
B21: Litigios | D21: No
B22: Gobierno
B23: Diversidad (Género, edad, industria, región)
B24: % independientes
B25: tiempo promedio como consejeros independientes
B26: Salidas recientes de consejeros/C-level executives?
B27: CEO/Chairman
B28: Transparencia (segmentos, fuente de riqueza, adquisiciones, otros)
B29: Tiempo que tardan en reportar luego del final del trimestre/año
B30: Participación adicional del CEO en otros consejos o excesiva del Ch.
B31: Auditoría/Consultoría | D31: Si
B32: Esquemas de compensación al management | D32: Si

Sheet DCF
A1: Discounted Cash Flow
A3: Ventas | E3: Margen Operativo
A16: Inversiones | E16: Utilidad Neta
D31: 0.001 | E31: =1/((1+$B$59+$D31)^(E35-2021)) -> 0.92250923 | F31: =1/((1+$B$59+$D31)^(F35-2021)) -> 0.85102327 | G31: =1/((1+$B$59+$D31)^(G35-2021)) -> 0.78507682 | H31: =1/((1+$B$59+$D31)^(H35-2021)) -> 0.72424061 | I31: =1/((1+$B$59+$D31)^(I35-2021)) -> 0.66811864 | J31: =1/((1+$B$59+$D31)^(J35-2021)) -> 0.61634561 | K31: =1/((1+$B$59+$D31)^(K35-2021)) -> 0.56858451 | L31: =1/((1+$B$59+$D31)^(L35-2021)) -> 0.52452446 | ... AC31: =1/((1+$B$59+$D31)^(AC35-2021)) -> 0.13312755
D32: 0.005 | E32: =1/((1+$B$59+$D32)^(E35-2021)) -> 0.91911765 | F32: =1/((1+$B$59+$D32)^(F35-2021)) -> 0.84477725 | G32: =1/((1+$B$59+$D32)^(G35-2021)) -> 0.77644968 | H32: =1/((1+$B$59+$D32)^(H35-2021)) -> 0.7136486 | I32: =1/((1+$B$59+$D32)^(I35-2021)) -> 0.65592702 | J32: =1/((1+$B$59+$D32)^(J35-2021)) -> 0.6028741 | K32: =1/((1+$B$59+$D32)^(K35-2021)) -> 0.55411223 | L32: =1/((1+$B$59+$D32)^(L35-2021)) -> 0.50929433 | ... AC32: =1/((1+$B$59+$D32)^(AC35-2021)) -> 0.12141647
D33: Normal | E33: =1/((1+$B$59)^(E35-2021)) -> 0.92336103 | F33: =1/((1+$B$59)^(F35-2021)) -> 0.8525956 | G33: =1/((1+$B$59)^(G35-2021)) -> 0.78725355 | H33: =1/((1+$B$59)^(H35-2021)) -> 0.72691926 | I33: =1/((1+$B$59)^(I35-2021)) -> 0.67120892 | J33: =1/((1+$B$59)^(J35-2021)) -> 0.61976816 | K33: =1/((1+$B$59)^(K35-2021)) -> 0.57226977 | L33: =1/((1+$B$59)^(L35-2021)) -> 0.5284116 | ... AC33: =1/((1+$B$59)^(AC35-2021)) -> 0.13623496
B35: 2019 (Real) | C35: 2020 (Real) | D35: 2021 | E35: =D35+1 -> 2022 | F35: =E35+1 -> 2023 | G35: =F35+1 -> 2024 | H35: =G35+1 -> 2025 | I35: =H35+1 -> 2026 | J35: =I35+1 -> 2027 | K35: =J35+1 -> 2028 | L35: =K35+1 -> 2029 | ... AC35: =AB35+1 -> 2046
A36: Crecimiento | B36: =OP!N34 -> 0.13406293 | C36: =OP!N35 -> 0.083337704 | D36: 0.35 | E36: 0.034 | F36: 0.095 | G36: 0.095 | H36: 0.095 | I36: 0.095 | J36: 0.095 | K36: 0.08 | L36: 0.06 | M36: 0.05 | N36: 0.04 | O36: 0.035 | P36: 0.035 | Q36: 0.035 | R36: 0.035 | S36: 0.035 | T36: 0.035 | U36: 0.035 | V36: 0.035 | W36: 0.035 | X36: 0.035 | Y36: 0.035 | Z36: 0.035 | AA36: 0.035 | AB36: 0.035 | AC36: 0.035
A37: Ventas | B37: =OP!C34 -> 1906.7 | C37: =OP!C35 -> 2065.6 | D37: =OP!C34*(1+D36) -> 2574.045 | E37: =D37*(1+E36) -> 2661.5625 | F37: =E37*(1+F36) -> 2914.411 | G37: =F37*(1+G36) -> 3191.28 | H37: =G37*(1+H36) -> 3494.4516 | I37: =H37*(1+I36) -> 3826.4245 | J37: =I37*(1+J36) -> 4189.9348 | K37: =J37*(1+K36) -> 4525.1296 | L37: =K37*(1+L36) -> 4796.6374 | ... AC37: =AB37*(1+AC36) -> 8775.3566
A38: Margen Operativo | B38: =+OP!D34 -> 0.26920858 | C38: =+OP!D35 -> 0.28693842 | D38: =108166.4/365513.2 -> 0.29593022 | E38: =108162.8/377959.8 -> 0.28617541 | F38: 0.27 | G38: 0.275 | H38: 0.26 | I38: 0.255 | J38: 0.25 | K38: 0.25 | L38: 0.25 | M38: 0.25 | N38: 0.25 | O38: 0.25 | P38: 0.25 | Q38: 0.25 | R38: 0.25 | S38: 0.25 | T38: 0.25 | U38: 0.25 | V38: 0.25 | W38: 0.25 | X38: 0.25 | Y38: 0.25 | Z38: 0.25 | AA38: 0.25 | AB38: 0.25 | AC38: 0.25
A39: EBIT | B39: 63930 | C39: 66288 | D39: =D37*D38 -> 761.73769 | E39: =E37*E38 -> 761.67374 | F39: =F37*F38 -> 786.89096 | G39: =G37*G38 -> 877.602 | H39: =H37*H38 -> 908.55742 | I39: =I37*I38 -> 975.73825 | J39: =J37*J38 -> 1047.4837 | K39: =K37*K38 -> 1131.2824 | ... AC39: =AC37*AC38 -> 2193.8392
A40: Dep&Amort | B40: =OP!H34 -> 0 | C40: =OP!H35 -> 0 | D40: 11000 | E40: =D40*(1+E36*$H$59) -> 11374 | F40: =E40*(1+F36*$H$59) -> 12454.53 | G40: =F40*(1+G36*$H$59) -> 13637.71 | H40: =G40*(1+H36*$H$59) -> 14933.293 | I40: =H40*(1+I36*$I$59) -> 16351.956 | J40: =I40*(1+J36*$I$59) -> 17905.391 | K40: =J40*(1+K36*$I$59) -> 19337.823 | L40: =K40*(1+L36*$I$59) -> 20498.092 | M40: =L40*(1+M36*$I$59) -> 21522.997 | N40: =M40*(1+N36*$I$59) -> 22383.917 | O40: =N40*(1+O36*$I$59) -> 23167.354 | P40: =O40*(1+P36*$I$59) -> 23978.211 | ... AC40: =AB40*(1+AC36*$I$59) -> 37500.868
A41: EBIDTA | B41: =+B39+B40 -> 63930 | C41: =+C39+C40 -> 66288 | D41: =D39+D40 -> 11761.738 | E41: =E39+E40 -> 12135.674 | F41: =F39+F40 -> 13241.421 | G41: =G39+G40 -> 14515.312 | H41: =H39+H40 -> 15841.85 | I41: =I39+I40 -> 17327.694 | J41: =J39+J40 -> 18952.875 | K41: =K39+K40 -> 20469.105 | ... AC41: =AC39+AC40 -> 39694.708
A42: CIF | B42: -1385 | C42: -890 | D42: =(C48)*$H$60 -> -1124.36 | E42: =(D48)*$H$60 -> -1113.1164 | F42: =(E48)*$H$60 -> -1113.1164 | G42: =(F48)*$H$60 -> -1113.1164 | H42: =(G48)*$H$60 -> -1113.1164 | I42: =(H48)*$H$60 -> -1113.1164 | J42: =(I48)*$H$60 -> -1113.1164 | K42: =(J48)*$H$60 -> -1113.1164 | ... AC42: =(AB48)*$H$60 -> -1113.1164
A43: Otros Gastos | B43: =-422-2817 -> -3239 | C43: =87-3634 -> -3547 | D43: =-C43*(1+D36) -> 4788.45 | E43: =D43*(1+E36*0.5) -> 4869.8537 | F43: =E43*(1+F36*0.5) -> 5101.1717 | G43: =F43*(1+G36*0.5) -> 5343.4774 | H43: =G43*(1+H36*0.5) -> 5597.2925 | I43: =H43*(1+I36*0.5) -> 5863.1639 | J43: =I43*(1+J36*0.5) -> 6141.6642 | K43: =J43*(1+K36*0.5) -> 6387.3308 | L43: =K43*(1+L36*0.5) -> 6578.9507 | ... AC43: =AB43*(1+AC36*0.5) -> 8922.7133
A44: Utilidad antes de Impuestos | B44: =B39-B42-B43 -> 68554 | C44: =C39-C42-C43 -> 70725 | D44: =D39-D42-D43 -> -2902.3523 | E44: =E39-E42-E43 -> -2995.0635 | F44: =F39-F42-F43 -> -3201.1643 | G44: =G39-G42-G43 -> -3352.759 | H44: =H39-H42-H43 -> -3575.6187 | I44: =I39-I42-I43 -> -3774.3093 | ... AC44: =AC39-AC42-AC43 -> -5615.7577
A45: ISR & PTU | B45: 10481 | C45: 9680 | D45: =$H$61*D44 -> -609.49398 | E45: =$H$61*E44 -> -628.96334 | F45: =$H$61*F44 -> -672.24451 | G45: =$I$61*G44 -> -771.13456 | H45: =$I$61*H44 -> -822.3923 | I45: =$I$61*I44 -> -868.09113 | J45: =$I$61*J44 -> -915.64474 | K45: =$I$61*K44 -> -952.87435 | L45: =$I$61*L44 -> -981.33524 | M45: =$I$61*M44 -> -1005.3739 | N45: =$I$61*N44 -> -1024.8097 | ... AC45: =$I$61*AC44 -> -1291.6243
A46: Utilidad Neta | B46: =B44-B45 -> 58073 | C46: =C44-C45 -> 61045 | D46: =D44-D45 -> -2292.8583 | E46: =E44-E45 -> -2366.1002 | F46: =F44-F45 -> -2528.9198 | G46: =G44-G45 -> -2581.6244 | H46: =H44-H45 -> -2753.2264 | I46: =I44-I45 -> -2906.2181 | ... AC46: =AC44-AC45 -> -4324.1334
A47: Inversiones y Capex | B47: =OP!I34 -> 0 | C47: =OP!I35 -> 0 | D47: 10000 | E47: =D47*(1+E36*$H$62) -> 10408 | F47: =E47*(1+F36*$H$62) -> 11594.512 | G47: =F47*(1+G36*$H$62) -> 12916.286 | H47: =G47*(1+H36*$H$62) -> 14388.743 | I47: =H47*(1+I36*$H$62) -> 16029.06 | J47: =I47*(1+J36*$H$62) -> 17856.373 | K47: =J47*(1+K36*$H$62) -> 19570.584 | L47: =K47*(1+L36*$H$62) -> 20979.666 | ... AC47: =AB47*(1+AC36*$H$62) -> 43199.777
A48: Deuda + Lease Liabilities | B48: 108047 | C48: 112436 | D48: =C48*0.99 -> 111311.64 | E48: =D48 -> 111311.64 | F48: =E48 -> 111311.64 | G48: =F48 -> 111311.64 | H48: =G48 -> 111311.64 | I48: =H48 -> 111311.64 | J48: =I48 -> 111311.64 | K48: =J48 -> 111311.64 | L48: =K48 -> 111311.64 | ... AC48: =AB48 -> 111311.64
A49: Deuda/EBITDA | B49: =B48/B41 -> 1.6900829 | C49: =C48/C41 -> 1.6961743 | D49: =D48/D41 -> 9.4638771 | E49: =E48/E41 -> 9.172267
A50: FNP | B50: =OP!F34 -> 0 | C50: =OP!F35 -> 0 | D50: =D41-D42-D43-D45-D47+D48-C48 -> -2417.2183 | E50: =E41-E42-E43-E45-E47+E48-D48 -> -1400.1002 | F50: =F41-F42-F43-F45-F47+F48-E48 -> -1668.9018 | G50: =G41-G42-G43-G45-G47+G48-F48 -> -1860.2004 | H50: =H41-H42-H43-H45-H47+H48-G48 -> -2208.6766 | I50: =I41-I42-I43-I45-I47+I48-H48 -> -2583.3222 | J50: =J41-J42-J43-J45-J47+J48-I48 -> -3016.4004 | K50: =K41-K42-K43-K45-K47+K48-J48 -> -3422.8191 | ... AC50: =AC41-AC42-AC43-AC45-AC47+AC48-AB48 -> -10023.042
A51: F(t) | B51: 0 | C51: 0 | D51: =C51*(1+$B$59)+D50 -> -2417.2183 | E51: =D51*(1+$B$59)+E50 -> -4017.9476 | F51: =E51*(1+$B$59)+F50 -> -6020.3391 | G51: =F51*(1+$B$59)+G50 -> -8380.2276 | H51: =G51*(1+$B$59)+H50 -> -11284.463 | I51: =H51*(1+$B$59)+I50 -> -14804.396 | J51: =I51*(1+$B$59)+J50 -> -19049.561 | K51: =J51*(1+$B$59)+K50 -> -24053.494 | ... AC51: =AB51*(1+$B$59)+AC50 -> -324050.68
AB52: =AB51-AB48 -> -401272.53 | AC52: =AC50/(B59-AC36) -> -208813.38
A53: EPS | C53: =1000000*C46/OP!$C$8 -> 6.9805603e+08 | D53: =1000000*D46/OP!$C$8 -> -26219077 | E53: =1000000*E46/OP!$C$8 -> -27056606 | F53: =1000000*F46/OP!$C$8 -> -28918466
A54: Consenso EPS | C54: 3.3 | D54: 5.6 | E54: 5.6
A55: E$/UN | D55: =$B$61/D46 -> 36.249528 | E55: =$B$61/E46 -> 35.127436 | F55: =$B$61/F46 -> 32.865824
A56: EEV/EBIDA | D56: =($B$61+D48-D51)/D41 -> 2.6028318 | E56: =($B$61+E48-E51)/E41 -> 2.6545337 | F56: =($B$61+F48-F51)/F41 -> 2.5840842
C58: "TELP" | D58: CER | E58: D Analista | H58: CP | I58: LP
A59: Tasa de descuento: | B59: =SUM(C59:E59) -> 0.083 | C59: 0.0307 | D59: 0.0523 | E59: 0 | G59: Factor D&A | H59: 1 | I59: 1
G60: Factor CIF | H60: -0.01
A61: VPN*@i% | B61: =C62+C63 -> -83115.033 | C61: Normal | D61: =D31 -> 0.001 | E61: =D32 -> 0.005 | G61: Factor ISR | H61: 0.21 | I61: 0.23
A62: DCF 25Y | B62: =C62/B61 -> 0.65773118 | C62: =AB52/(1+B59)^25 -> -54667.349 | D62: =SUMPRODUCT(E50:AB50,E31:AB31) -> -39909.169 | E62: =SUMPRODUCT(E50:AB50,E32:AB32) -> -38157.285 | G62: Factor inv | H62: 1.2
A63: Perpetuidad | B63: =1-B62 -> 0.34226882 | C63: =AC52/(1+B59)^25 -> -28447.684 | D63: =(AC50/($B$59+D31-$AC$36))*AC31 -> -27231.492 | E63: =(AC50/($B$59+D32-$AC$36))*AC32 -> -22961.556 | G63: Suma D&A | H63: =SUM(40:40) -> 628429.57
A64: VPN/Acción | B64: =1000000*B61/OP!C8 -> -9.5042919e+08 | D64: =1000000*SUM(D62:D63)/OP!C8 -> -7.6776056e+08 | E64: =1000000*SUM(E62:E63)/OP!C8 -> -6.9890041e+08 | G64: Suma Inv. | H64: =SUM(47:47) -> 672845.39
B65: =B64/OP!C7-1 -> -2845597.4 | D65: =D64/B64-1 -> -0.19219594 | E65: =E64/B64-1 -> -0.26464757 | G65: Inv.+Goodwill | H65: =SUM(47:47)+(OP!E12*OP!E7) -> 678337.59
A67: Duración | B67: =B62*D68+B63*D69 -> 21.117542 | E67: 1 | F67: 2 | G67: 3 | H67: 4 | I67: 5 | J67: 6 | K67: 7 | L67: 8 | M67: 9 | N67: 10 | O67: 11 | P67: 12 | Q67: 13 | R67: 14 | S67: 15 | T67: 16 | U67: 17 | V67: 18 | W67: 19 | X67: 20 | Y67: 21 | Z67: 22 | AA67: 23 | AB67: 24 | AC67: 25
A68: 0.001 | B68: =-$B$67*A68 -> -0.021117542 | D68: =SUM(E68:AB68)/SUMPRODUCT(E50:AB50,E33:AB33) -> 12.307204 | E68: =E67*E50*E33 -> -1292.7979 | F68: =F67*F50*F33 -> -2845.7967 | G68: =G67*G50*G33 -> -4393.3482 | H68: =H67*H50*H33 -> -6422.1182 | I68: =I67*I50*I33 -> -8669.7445 | J68: =J67*J50*J33 -> -11216.814 | K68: =K67*K50*K33 -> -13711.431 | L68: =L67*L50*L33 -> -15923.848 | ... AC68: =AC67*AC50*AC33 -> -34137.221
A69: 0.005 | B69: =-$B$67*A69 -> -0.10558771 | D69: =(1+B59)/B59+AC67 -> 38.048193

Sheet DCFF
C1: VALUATION MODEL
C2: Año fiscal de Apple cierra en septiembre
D3: =D19/D6 -> -0.086599655 | E3: =E19/E6 -> -0.087061415 | F3: =F19/F6 -> -0.081380713 | G3: 0 | H3: 0.25 | I3: =H3+1 -> 1.25 | J3: =I3+1 -> 2.25 | K3: =J3+1 -> 3.25 | L3: =K3+1 -> 4.25 | M3: =L3+1 -> 5.25 | N3: =M3+1 -> 6.25 | O3: =N3+1 -> 7.25 | P3: =O3+1 -> 8.25 | ... AF3: =AE3+1 -> 24.25
A4: Section | B4: Line # | C4: ITEM | D4: 2020 (Real) | E4: 2021 (Real) | F4: 2022 (Real) | G4: 2023 (Real) | H4: 2024 | I4: =+H4+1 -> 2025 | J4: =+I4+1 -> 2026 | K4: =+J4+1 -> 2027 | L4: =+K4+1 -> 2028 | M4: =+L4+1 -> 2029 | N4: =+M4+1 -> 2030 | O4: =+N4+1 -> 2031 | P4: =+O4+1 -> 2032 | ... AF4: =+AE4+1 -> 2048 | AG4: Notes
A5: INCOME STATEMENT | B5: 1 | C5: Growth | D5: 0.08 | E5: =Cifras_en_Millones!E6 -> 0.13406293 | F5: =Cifras_en_Millones!D6 -> 0.083337704 | G5: =Cifras_en_Millones!C6 -> 0.098905887 | H5: =H6/G6-1 -> 0.10533504 | I5: =I6/H6-1 -> 0.092865684 | J5: =J6/I6-1 -> 0.134 | K5: =K6/J6-1 -> 0.134 | L5: =L6/K6-1 -> 0.134 | M5: =M6/L6-1 -> 0.134 | N5: =N6/M6-1 -> 0.134 | O5: =O6/N6-1 -> 0.07 | ... AE5: =AE6/AD6-1 -> 0.07 | AF5: 0.02
B6: 2 | C6: Revenues/Sales | D6: 1681.3 | E6: 1906.7 | F6: 2065.6 | G6: 2269.9 | H6: 2509 | I6: 2742 | J6: =I6*(1.134) -> 3109.428 | K6: =J6*(1.134) -> 3526.0914 | L6: =K6*(1.134) -> 3998.5876 | M6: =L6*(1.134) -> 4534.3983 | N6: =M6*(1.134) -> 5142.0077 | O6: =N6*1.07 -> 5501.9482 | P6: =O6*1.07 -> 5887.0846 | Q6: =P6*1.07 -> 6299.1805 | R6: =Q6*1.07 -> 6740.1232 | S6: =R6*1.07 -> 7211.9318 | T6: =S6*1.07 -> 7716.767 | U6: =T6*1.07 -> 8256.9407 | V6: =U6*1.07 -> 8834.9266 | ... AF6: =AE6*1.07 -> 17379.638
B7: 3 | C7: EBIT/Operating Margin | D7: =523/DCFF!D6 -> 0.31106882 | E7: =494/E6 -> 0.25908638 | F7: =515/F6 -> 0.24932223 | G7: =757/G6 -> 0.33349487 | H7: =H8/H6 -> 0.23595058 | I7: =AVERAGE(D7:H7) -> 0.27778457 | J7: =AVERAGE(E7:I7) -> 0.27112773 | K7: =AVERAGE(F7:J7) -> 0.273536 | L7: =AVERAGE(G7:K7) -> 0.27837875 | M7: =L7*1.02 -> 0.28394632 | N7: =M7*1.02 -> 0.28962525 | O7: =N7*1.02 -> 0.29541775 | P7: =O7*1.02 -> 0.30132611 | Q7: =P7*1.02 -> 0.30735263 | R7: =Q7*1.02 -> 0.31349968 | S7: =R7*1.02 -> 0.31976968 | T7: =S7*1.02 -> 0.32616507 | ... AF7: =AE7*1.02 -> 0.41365618
B8: 4 | C8: EBIT | D8: 496 | E8: 513 | F8: 593 | G8: 626 | H8: 592 | I8: =I7*I6 -> 761.6853 | J8: =J7*J6 -> 843.05214 | K8: =K7*K6 -> 964.51291 | L8: =L7*L6 -> 1113.1218 | M8: =M7*M6 -> 1287.5257 | N8: =N7*N6 -> 1489.2553 | O8: =O7*O6 -> 1625.3732 | P8: =P7*P6 -> 1773.9323 | ... AF8: =AF7*AF6 -> 7189.1945
B9: 5a | C9: (Dep&Amort) | D9: -85.3 | E9: -106.9 | F9: -114.6 | G9: -132.5 | H9: {=G9*0.7+0.3*(-$D$50*AVERAGE(-1*(D22:G22)))} -> -94.306077 | I9: {=H9*0.7+0.3*(-$D$50*AVERAGE(-1*(E22:H22)))} -> -67.567717 | J9: {=I9*0.7+0.3*(-$D$50*AVERAGE(-1*(F22:I22)))} -> -49.06979 | K9: {=J9*0.7+0.3*(-$D$50*AVERAGE(-1*(G22:J22)))} -> -36.39978 | L9: {=K9*0.7+0.3*(-$D$50*AVERAGE(-1*(H22:K22)))} -> -27.878863 | M9: {=L9*0.7+0.3*(-$D$50*AVERAGE(-1*(I22:L22)))} -> -22.426805 | N9: {=M9*0.7+0.3*(-$D$50*AVERAGE(-1*(J22:M22)))} -> -19.212465 | O9: {=N9*0.7+0.3*(-$D$50*AVERAGE(-1*(K22:N22)))} -> -17.645209 | ... AF9: {=AE9*0.7+0.3*(-$D$50*AVERAGE(-1*(AB22:AE22)))} -> -43.391047
B10: 5b | C10: (Stock based compensation) | D10: -145.6 | E10: -166.3 | F10: -168.1 | G10: -221.9 | H10: =($D$51*H6)*-1 -> -221.39211 | I10: =($D$51*I6)*-1 -> -241.95184 | J10: =($D$51*J6)*-1 -> -274.37339 | K10: =($D$51*K6)*-1 -> -311.13942 | L10: =($D$51*L6)*-1 -> -352.8321 | M10: =($D$51*M6)*-1 -> -400.11161 | N10: =($D$51*N6)*-1 -> -453.72656 | O10: =($D$51*O6)*-1 -> -485.48742 | ... AF10: =($D$51*AF6)*-1 -> -1533.565
B11: 6 | C11: EBIDTA | D11: =-D9+D8 -> 581.3 | E11: =-E9+E8 -> 619.9 | F11: =-F9+F8 -> 707.6 | G11: =-G9+G8 -> 758.5 | H11: =-H9+H8 -> 686.30608 | I11: =-I9+I8 -> 829.25302 | J11: =-J9+J8 -> 892.12193 | K11: =-K9+K8 -> 1000.9127 | ... AF11: =-AF9+AF8 -> 7232.5856
B12: 7 | C12: (Net financing cost) | D12: =Cifras_Originales!E11 -> 4.2 | E12: =Cifras_Originales!D11 -> 5 | F12: =Cifras_Originales!C11 -> -5.4 | G12: =Cifras_Originales!B11 -> 43.9 | H12: =-$D$53*G37+G36*$D$54 -> 38.59592 | I12: =-$D$53*H37+H36*$D$54 -> 57.678667 | J12: =-$D$53*I37+I36*$D$54 -> 79.622607 | K12: =-$D$53*J37+J36*$D$54 -> 103.9971 | L12: =-$D$53*K37+K36*$D$54 -> 131.08106 | M12: =-$D$53*L37+L36*$D$54 -> 161.27488 | N12: =-$D$53*M37+M36*$D$54 -> 195.55392 | O12: =-$D$53*N37+N36*$D$54 -> 234.36027 | ... AF12: =-$D$53*AE37+AE36*$D$54 -> 1721.9618
B13: 8 | C13: Other income/(cost) | D13: =Cifras_Originales!E12 -> -2.43 | E13: =Cifras_Originales!D12 -> 2.08 | F13: =Cifras_Originales!C12 -> -17.34 | G13: =Cifras_Originales!B12 -> -34 | H13: -21 | I13: =H13*(1+I5) -> -22.950179 | J13: =I13*(1+J5) -> -26.025503 | K13: =J13*(1+K5) -> -29.512921 | L13: =K13*(1+L5) -> -33.467652 | M13: =L13*(1+M5) -> -37.952318 | N13: =M13*(1+N5) -> -43.037928 | O13: =N13*(1+O5) -> -46.050583 | P13: =O13*(1+P5) -> -49.274124 | ... AF13: =AE13*(1+AF5) -> -138.66784
B14: 9 | C14: Earnings before taxes | D14: =D8+D12+D13 -> 497.77 | E14: =E8+E12+E13 -> 520.08 | F14: =F8+F12+F13 -> 570.26 | G14: =G8+G12+G13 -> 635.9 | H14: =H8+H12+H13 -> 609.59592 | I14: =I8+I12+I13 -> 796.41379 | J14: =J8+J12+J13 -> 896.64925 | K14: =K8+K12+K13 -> 1038.9971 | ... AF14: =AF8+AF12+AF13 -> 8772.4885
B15: 10 | C15: (Income tax) | D15: =-Cifras_Originales!E17 -> -60.7 | E15: =-Cifras_Originales!D17 -> -51.6 | F15: =-Cifras_Originales!C17 -> -91.7 | G15: =-Cifras_Originales!B17 -> -115.8 | H15: =(-1*$D$52)*H14 -> -115.82322 | I15: =(-1*$D$52)*I14 -> -151.31862 | J15: =(-1*$D$52)*J14 -> -170.36336 | K15: =(-1*$D$52)*K14 -> -197.40945 | L15: =(-1*$D$52)*L14 -> -230.03969 | M15: =(-1*$D$52)*M14 -> -268.06118 | N15: =(-1*$E$52)*N14 -> -322.75617 | O15: =(-1*$E$52)*O14 -> -356.55232 | P15: =(-1*$E$52)*P14 -> -393.21239 | Q15: =(-1*$E$52)*Q14 -> -433.20026 | R15: =(-1*$E$52)*R14 -> -476.8233 | S15: =(-1*$E$52)*S14 -> -524.41186 | T15: =(-1*$E$52)*T14 -> -576.32582 | U15: =(-1*$E$52)*U14 -> -632.95962 | ... AF15: =(-1*$E$52)*AF14 -> -1724.5854
B16: 11 | C16: Net income | D16: =D14+D15 -> 437.07 | E16: =E14+E15 -> 468.48 | F16: =F14+F15 -> 478.56 | G16: =G14+G15 -> 520.1 | H16: =H14+H15 -> 493.7727 | I16: =I14+I15 -> 645.09517 | J16: =J14+J15 -> 726.28589 | K16: =K14+K15 -> 841.58764 | ... AF16: =AF14+AF15 -> 7047.903
A18: CASH FLOW STATEMENT | B18: 12 | C18: Operating cash flows before WK | D18: 663 | E18: 774 | F18: 710 | G18: 692 | H18: =H11+H12+H13+H15 -> 588.07877 | I18: =I11+I12+I13+I15 -> 712.66289 | J18: =J11+J12+J13+J15 -> 775.35568 | K18: =K11+K12+K13+K15 -> 877.98742 | L18: =L11+L12+L13+L15 -> 1008.5744 | M18: =M11+M12+M13+M15 -> 1165.2139 | N18: =N11+N12+N13+N15 -> 1338.2275 | O18: =O11+O12+O13+O15 -> 1474.7758 | ... AF18: =AF11+AF12+AF13+AF15 -> 7091.2941
B19: 13 | C19: (Stock-based compensation) | D19: -145.6 | E19: -166 | F19: -168.1 | G19: -221.9 | H19: =$D$55*H6 -> 208.62313 | I19: =$D$55*I6 -> 227.99706 | J19: =$D$55*J6 -> 258.54867 | K19: =$D$55*K6 -> 293.19419 | L19: =$D$55*L6 -> 332.48221 | M19: =$D$55*M6 -> 377.03483 | N19: =$D$55*N6 -> 427.5575 | O19: =$D$55*O6 -> 457.48652 | ... AF19: =$D$55*AF6 -> 1445.1154
B20: 14 | C20: (Working Capital Flows) | D20: =T94 -> 130 | E20: =U94 -> -130 | F20: =V94 -> 9 | G20: =W94 -> 331 | H20: =$D$56*(H6-G6) -> 40.755691 | I20: =$D$56*(I6-H6) -> 39.715918 | J20: =$D$56*(J6-I6) -> 62.629786 | K20: =$D$56*(K6-J6) -> 71.022178 | L20: =$E$56*(L6-K6) -> 80.539149 | M20: =$E$56*(M6-L6) -> 91.331395 | N20: =$E$56*(N6-M6) -> 103.5698 | O20: =$E$56*(O6-N6) -> 61.353514 | P20: =$E$56*(P6-O6) -> 65.64826 | Q20: =$E$56*(Q6-P6) -> 70.243639 | R20: =$E$56*(R6-Q6) -> 75.160693 | S20: =$E$56*(S6-R6) -> 80.421942 | ... AF20: =$E$56*(AF6-AE6) -> 193.80441
B21: 15 | C21: -Total Operating Cash Flow | D21: =D18+D19+D20 -> 647.4 | E21: =E18+E19+E20 -> 478 | F21: =F18+F19+F20 -> 550.9 | G21: =G18+G19+G20 -> 801.1 | H21: =H18+H19+H20 -> 837.4576 | I21: =I18+I19+I20 -> 980.37587 | J21: =J18+J19+J20 -> 1096.5341 | K21: =K18+K19+K20 -> 1242.2038 | ... AF21: =AF18+AF19+AF20 -> 8730.2139
B22: 16 | C22: (CAPEX and Acquisitions) | D22: -35 | E22: -23 | F22: -24 | G22: -25 | H22: =-$D$57*H6 -> -34.820248 | I22: =-$D$57*I6 -> -38.053854 | J22: =-$D$57*J6 -> -43.153071 | K22: =-$D$57*K6 -> -48.935582 | L22: =-$E$57*L6 -> -70.066913 | M22: =-$E$57*M6 -> -79.455879 | N22: =-$E$57*N6 -> -90.102967 | O22: =-$E$57*O6 -> -96.410174 | P22: =-$E$57*P6 -> -103.15889 | Q22: =-$E$57*Q6 -> -110.38001 | R22: =-$E$57*R6 -> -118.10661 | S22: =-$E$57*S6 -> -126.37407 | ... AF22: =-$E$57*AF6 -> -304.54192
B23: 17 | C23: (Other investing flows) | D23: -7 | E23: -3 | F23: -0.7 | G23: -5.8 | H23: 0 | I23: 0 | J23: 0 | K23: 0 | L23: 0 | M23: 0 | N23: 0 | O23: 0 | P23: 0 | Q23: 0 | R23: 0 | S23: 0 | T23: 0 | U23: 0 | V23: 0 | W23: 0 | X23: 0 | Y23: 0 | Z23: 0 | AA23: 0 | AB23: 0 | AC23: 0 | AD23: 0 | AE23: 0 | AF23: 0
B24: 18 | C24: -Total Investing Flows | D24: =D22+D23 -> -42 | E24: =E22+E23 -> -26 | F24: =F22+F23 -> -24.7 | G24: =G22+G23 -> -30.8 | H24: =H22+H23 -> -34.820248 | I24: =I22+I23 -> -38.053854 | J24: =J22+J23 -> -43.153071 | K24: =K22+K23 -> -48.935582 | ... AF24: =AF22+AF23 -> -304.54192
B25: 19 | C25: (Flows related to leases) | D25: -23 | E25: -22 | F25: -23 | G25: -24 | H25: =AVERAGE(D25:G25) -> -23 | I25: =AVERAGE(E25:H25) -> -23 | J25: =AVERAGE(F25:I25) -> -23.25 | K25: =AVERAGE(G25:J25) -> -23.3125 | L25: =AVERAGE(H25:K25) -> -23.140625 | M25: =AVERAGE(I25:L25) -> -23.175781 | N25: =AVERAGE(J25:M25) -> -23.219727 | O25: =AVERAGE(K25:N25) -> -23.212158 | ... AF25: =AVERAGE(AB25:AE25) -> -23.199998
B26: 20 | C26: Flows related to debt | D26: 300 | E26: -45 | F26: 0 | G26: 0 | H26: =(H37-G37) -> 0 | I26: =(I37-H37) -> 0 | J26: =(J37-I37) -> 0 | K26: =(K37-J37) -> 0 | L26: =(L37-K37) -> 0 | M26: =(M37-L37) -> 0 | N26: =(N37-M37) -> 0 | O26: =(O37-N37) -> 0 | ... AF26: =(AF37-AE37) -> 0
B27: 21 | C27: (Respurchases)/Issuance of stock | D27: -161 | E27: -135 | F27: -206 | G27: -196 | H27: =AVERAGE(D27:G27) -> -174.5 | I27: =AVERAGE(E27:H27) -> -177.875 | J27: =AVERAGE(F27:I27) -> -188.59375 | K27: =AVERAGE(G27:J27) -> -184.24219 | L27: =AVERAGE(H27:K27) -> -181.30273 | M27: =AVERAGE(I27:L27) -> -183.00342 | N27: =AVERAGE(J27:M27) -> -184.28552 | O27: =AVERAGE(K27:N27) -> -183.20847 | ... AF27: =AVERAGE(AB27:AE27) -> -183.30014
B28: 22 | C28: (Dividends) | D28: =Cifras_Originales!E19 -> 0 | E28: =Cifras_Originales!D19 -> 0 | F28: =Cifras_Originales!C19 -> 0 | G28: =Cifras_Originales!B19 -> 0 | H28: =(1+$D$58)*G28 -> 0 | I28: =(1+$D$58)*H28 -> 0 | J28: =(1+$D$58)*I28 -> 0 | K28: =(1+$D$58)*J28 -> 0 | L28: =(1+$E$58)*K28 -> 0 | M28: =(1+$E$58)*L28 -> 0 | N28: =(1+$E$58)*M28 -> 0 | O28: =(1+$E$58)*N28 -> 0 | P28: =(1+$E$58)*O28 -> 0 | Q28: =(1+$E$58)*P28 -> 0 | R28: =(1+$E$58)*Q28 -> 0 | S28: =(1+$E$58)*R28 -> 0 | ... AF28: =(1+$E$58)*AE28 -> 0
B29: 23 | C29: Other financing flows | D29: -0.9 | E29: -0.5 | F29: -1.3 | G29: -1.3 | H29: 0 | I29: 0 | J29: 0 | K29: 0 | L29: 0 | M29: 0 | N29: 0 | O29: 0 | P29: 0 | Q29: 0 | R29: 0 | S29: 0 | T29: 0 | U29: 0 | V29: 0 | W29: 0 | X29: 0 | Y29: 0 | Z29: 0 | AA29: 0 | AB29: 0 | AC29: 0 | AD29: 0 | AE29: 0 | AF29: 0
B30: 24 | C30: -Total Financing flows | D30: =SUM(D25:D29) -> 115.1 | E30: =SUM(E25:E29) -> -202.5 | F30: =SUM(F25:F29) -> -230.3 | G30: =SUM(G25:G29) -> -221.3 | H30: =SUM(H25:H29) -> -197.5 | I30: =SUM(I25:I29) -> -200.875 | J30: =SUM(J25:J29) -> -211.84375 | K30: =SUM(K25:K29) -> -207.55469 | ... AF30: =SUM(AF25:AF29) -> -206.50014
A32: SUMMARY | B32: 25 | C32: Cash before shareholder returns | D32: =D21+D24+D25+D26+D29 -> 881.5 | E32: =E21+E24+E25+E26+E29 -> 384.5 | F32: =F21+F24+F25+F26+F29 -> 501.9 | G32: =G21+G24+G25+G26+G29 -> 745 | H32: =H21+H24+H25+H26+H29 -> 779.63735 | I32: =I21+I24+I25+I26+I29 -> 919.32201 | J32: =J21+J24+J25+J26+J29 -> 1030.1311 | K32: =K21+K24+K25+K26+K29 -> 1169.9557 | ... AF32: =AF21+AF24+AF25+AF26+AF29 -> 8402.472
B33: 26 | C33: Returns to shareholders | D33: =(D27+D28) -> -161 | E33: =(E27+E28) -> -135 | F33: =(F27+F28) -> -206 | G33: =(G27+G28) -> -196 | H33: =(H27+H28) -> -174.5 | I33: =(I27+I28) -> -177.875 | J33: =(J27+J28) -> -188.59375 | K33: =(K27+K28) -> -184.24219 | ... AF33: =(AF27+AF28) -> -183.30014
B34: 27 | C34: Excess cash acumulation | D34: =D32-D33 -> 1042.5 | E34: =E32-E33 -> 519.5 | F34: =F32-F33 -> 707.9 | G34: =G32-G33 -> 941 | H34: =H32-H33 -> 954.13735 | I34: =I32-I33 -> 1097.197 | J34: =J32-J33 -> 1218.7248 | K34: =K32-K33 -> 1354.1979 | ... AF34: =AF32-AF33 -> 8585.7721
A36: CASH & DEBT & DISCOUNTING | B36: 28 | C36: Ending cash balance | D36: 912.7 | E36: =D36+E34 -> 1432.2 | F36: =E36+F34 -> 2140.1 | G36: =F36+G34 -> 3081.1 | H36: =G36+H34 -> 4035.2373 | I36: =H36+I34 -> 5132.4344 | J36: =I36+J34 -> 6351.1592 | K36: =J36+K34 -> 7705.3571 | L36: =K36+L34 -> 9215.048 | ... AF36: =AE36+AF34 -> 95835.166
B37: 29 | C37: Total Debt | D37: 942.7 | E37: 880.8 | F37: 889.2 | G37: 877.7 | H37: =G37 -> 877.7 | I37: =H37 -> 877.7 | J37: =I37 -> 877.7 | K37: =J37 -> 877.7 | L37: =K37 -> 877.7 | M37: =L37 -> 877.7 | N37: =M37 -> 877.7 | O37: =N37 -> 877.7 | ... AF37: =AE37 -> 877.7
B38: 30 | C38: Discount factor | G38: =1/((1+$D$47)^G3) -> 1 | H38: =1/((1+$D$47)^H3) -> 0.98080746 | I38: =1/((1+$D$47)^I3) -> 0.9076508 | J38: =1/((1+$D$47)^J3) -> 0.83995077 | K38: =1/((1+$D$47)^K3) -> 0.77730036 | L38: =1/((1+$D$47)^L3) -> 0.71932293 | M38: =1/((1+$D$47)^M3) -> 0.66566994 | N38: =1/((1+$D$47)^N3) -> 0.61601882 | ... AF38: =1/((1+$D$47)^AF3) -> 0.15262464
F39: =1/((1+$D$48+0.001)^F$3) -> 1.0000813 | G39: =1/((1+$D$47+0.001)^G$3) -> 1 | H39: =1/((1+$D$47+0.001)^H$3) -> 0.98058068 | I39: =1/((1+$D$47+0.001)^I$3) -> 0.90660196 | J39: =1/((1+$D$47+0.001)^J$3) -> 0.83820447 | K39: =1/((1+$D$47+0.001)^K$3) -> 0.77496715 | L39: =1/((1+$D$47+0.001)^L$3) -> 0.71650069 | M39: =1/((1+$D$47+0.001)^M$3) -> 0.66244517 | N39: =1/((1+$D$47+0.001)^N$3) -> 0.6124678 | ... AE39: =1/((1+$D$47+0.001)^AE$3) -> 0.16141717
F40: =1/((1+$D$48+0.005)^F$3) -> 1.000406 | G40: =1/((1+$D$47+0.005)^G$3) -> 1 | H40: =1/((1+$D$47+0.005)^H$3) -> 0.97967616 | I40: =1/((1+$D$47+0.005)^I$3) -> 0.9024283 | J40: =1/((1+$D$47+0.005)^J$3) -> 0.83127146 | K40: =1/((1+$D$47+0.005)^K$3) -> 0.76572537 | L40: =1/((1+$D$47+0.005)^L$3) -> 0.70534762 | M40: =1/((1+$D$47+0.005)^M$3) -> 0.64973067 | N40: =1/((1+$D$47+0.005)^N$3) -> 0.59849914 | ... AE40: =1/((1+$D$47+0.005)^AE$3) -> 0.14814137
C42: EPS | H42: =1000000*H16/OP!C8 -> 5646343 | I42: =1000000*I16/OP!$C8 -> 7376731.5 | J42: =1000000*J16/OP!$C8 -> 8305156
C43: Consenso EPS
C44: E$/UN | H44: =$D$64/H16 -> 67.207824 | I44: =$D$64/I16 -> 51.442624
...

Sheet Cifras_Originales
B1: 936 | C1: 942.8 | D1: 988.5 | E1: 1095.3 | F1: 1293.6 | G1: 1515.9 | H1: 1681.3 | I1: 1906.7 | J1: 2065.6 | K1: 2269.9
B2: {=_xlfn.SORTBY(B1:K1, _xlfn.SEQUENCE(1, COLUMNS(B1:K1), COLUMNS(B1:K1), -1))} -> 2269.9 | C2: 2065.6 | D2: 1906.7 | E2: 1681.3 | F2: 1515.9 | G2: 1293.6 | H2: 1095.3 | I2: 988.5 | J2: 942.8 | K2: 936 | L2: 861.3 | M2: 798
A3: USD
A4: Millones | C4: ="Cifras en "&A4&" de "&A3 -> Cifras en Millones de USD
A5: (Company name) | G5: =A5&" ("&A6&")" -> (Company name) ((ticker))
A6: (ticker)
A7: RESULTADOS | B7: 2023 | C7: =B7-1 -> 2022 | D7: =C7-1 -> 2021 | E7: =D7-1 -> 2020 | F7: =E7-1 -> 2019 | G7: =F7-1 -> 2018 | H7: =G7-1 -> 2017 | I7: =H7-1 -> 2016 | J7: =I7-1 -> 2015 | ... M7: =L7-1 -> 2012 | N7: 2024
A8: Ventas Netas | B8: 2269.9 | C8: 2065.6 | D8: 1906.7 | E8: 1681.3 | F8: 1515.9 | G8: 1293.6 | H8: 1095.3 | I8: 988.5 | J8: 942.8 | K8: 936 | L8: 861.3 | M8: 798 | N8: 2544
A9: Utilidad Bruta | B9: 1998.7 | C9: 1814.9 | D9: 1648.7 | E9: 1456 | F9: 1349.6 | G9: 1137.8 | H9: 945.1 | I9: 841.6 | J9: 795.5 | K9: 782.2 | L9: 714.6 | M9: 658.5 | N9: 2264
A10: Utilidad de Operación | B10: 626.1 | C10: 592.7 | D10: 513.3 | E10: 496.4 | F10: 515 | G10: 476.6 | H10: 390.7 | I10: 376.2 | J10: 353.7 | K10: 347.5 | L10: 321.9 | M10: 294.3 | N10: 718
A11: CIF (Poductos) | B11: 43.9 | C11: -5.4 | D11: 5 | E11: 4.2 | F11: 56.2 | G11: -13.3 | H11: 55.1 | I11: 38.8 | J11: -38.3 | K11: -22.6 | L11: -28.2 | M11: -1.9 | N11: -3.29 | S11: =C7 -> 2022 | T11: =D7 -> 2021 | U11: =E7 -> 2020 | V11: =F7 -> 2019 | W11: =G7 -> 2018 | X11: =H7 -> 2017 | Y11: =I7 -> 2016 | Z11: =J7 -> 2015 | ... AB11: =L7 -> 2013
A12: Otros Gastos (Ingresos) | B12: -34 | C12: -17.34 | D12: 2.08 | E12: -2.43 | F12: 7.54 | G12: 10.51 | H12: 4.97 | I12: 4.07 | J12: 3.09 | K12: 0.689 | L12: 0.626 | M12: -0.706 | N12: -3.132 | R12: Inventories | S12: =C26 -> 0 | T12: =D26 -> 0 | U12: =E26 -> 0 | V12: =F26 -> 0 | W12: =G26 -> 0 | X12: =H26 -> 0 | Y12: =I26 -> 0 | Z12: =J26 -> 0 | ... AC12: =M26 -> 0
A13: Depreciación y amortización | B13: 132.5 | C13: 114.56 | D13: 106.87 | E13: 106.25 | F13: 78.97 | G13: 59.26 | H13: 67.68 | I13: 69.59 | J13: 77.67 | K13: 81.92 | L13: 80.7 | M13: 85.42 | N13: 142.672 | R13: Por cobrar | S13: =C25 -> 760.3 | T13: =D25 -> 645.9 | U13: =E25 -> 537.6 | V13: =F25 -> 433.5 | W13: =G25 -> 317.7 | X13: =H25 -> 124.7 | Y13: =I25 -> 107.2 | Z13: =J25 -> 91.6 | ... AC13: =M25 -> 96.6
A14: Capital de Trabajo | B14: 1160.3 | C14: 869.3 | D14: 860.1 | E14: 990.4 | F14: 860.4 | G14: 786.4 | H14: 661.7 | I14: 630.3 | J14: 592.3 | K14: 617.2 | L14: 627.2 | M14: 436 | N14: 189 | R14: Por pagar
