Workbook
Name Sectors: '[1]Sector Impact'!$K$4:$K$16
Name Sectors: 'Sector Impact'!$K$4:$K$16

Sheet OP
B2: (Date of last update) | C2: Team 1 | D2: (Date of next Quarter/Annual Report) | E2: =Inputs!I3 -> #VALUE! | L2: {=_FV(E2,"Exchange")} -> New York Stock Exchange | M2: SIC:
D3: COMPANY DESCRIPTION | H3: CEO & BOARD OF DIRECTORS
D4: {=_FV(Inputs!I3,"Description")} -> Constellation Brands, Inc. is a producer and marketer of beer, wine, and spirits with operations in the United States, Mexico, New Zealand, and Italy with brands, such as Corona Extra, Modelo Especial, Robert Mondavi Winery, Kim Crawford, Meiomi, The Prisoner Wine Company, High West, Casa Noble, and Mi CAMPO. Its segments include Beer, Wine and Spirits, and Corporate Operations and Other. In the Beer segment, its portfolio consists of high-end imported beer brands and ABAs. It has a perpetual brand license to produce its Mexican beer portfolio and to import, market, and sell such portfolio in the United States. In the Wine and Spirits segment, it sells a portfolio that includes higher-end wine brands complemented by certain higher-end spirits brands. Its Corporate Operations and Other segment consist of costs of corporate development, corporate finance, corporate strategy, executive management, growth, human resources, internal audit, investor relations, IT, legal and public relations. | H4: Name, Age and Tenure | I4: Gender | J4: Executive? | L4: Other roles
H5: Bill Newlands (-,6) | I5: M | J5: President and CEO (yes) | L5: Lead Director of Hormel Foods Corporation;
H6: Jim Bourdeau (-,7 ) | I6: M | J6: Chief Legal Officer (yes) | L6: N/A
H7: Christy Clark (58,5 ) | I7: F | J7: No | L7: Senior Advisor at Bennett Jones LLP
H8: Jennifer Daniels (-,6) | I8: F | J8: No | L8: Chief Legal Officer and Secretary of Colgate-Palmolive Company
H9: Nicholas Fink (-, 4) | I9: M | J9: No | L9: Chief Executive Officer, Fortune Brands Innovations, Inc.
H10: William T. Giles | I10: M | J10: No | L10: Former Chief Financial Officer and Executive Vice President of AutoZone, Inc
H11: Richar Sands (74, ) | I11: M | J11: No | L11: Non-Management Director
H12: Rob Sands ( 66, ) | I12: M | J12: No | L12: Non-Management Director
H13: Luca Zaramella (, 1) | I13: M | J13: No | L13: Executive Vice President, Chief Financial Officer of Mondelēz International
H14: Ernesto M. Hernández | I14: M | J14: No | L14: Former President and Managing Director of General Motors de Mexico, S. de R.L. de C.V.
B15: {=_FV(E2,"Currency")&" MILLIONS"} -> USD MILLIONS | H15: Daniel J. McCarthy | I15: M | J15: No | L15: Former President and Chief Executive Officer of Frontier Communications Corporation
B18: COMPANY OVERVIEW
B19: Stock | D19: Liquidity and Solvency | F19: Segments | I19: ="Profitability ("&J20&")" -> Profitability (2024) | L19: Multiples
B20: Last Price | C20: {=_FV(E2,"Price")} -> 248.17 | D20: Total Assets | E20: =_xlfn.XLOOKUP(D20,'Fin. Data'!A:A,'Fin. Data'!B:B,,0) -> 25691.7 | F20: Regions | H20: % Sales | I20: Reporting Year | J20: 2024 | L20: Float | M20: =164.92/181.54 -> 0.90844993
B21: Outstanding Shares | C21: {=_FV(E2,"Shares outstanding",TRUE)} -> 182192400 | D21: Total Liabilities | E21: =_xlfn.XLOOKUP(D21,'Fin. Data'!A:A,'Fin. Data'!B:B,,0) -> 15627.1 | F21: =Segments!C5 -> U.S. | H21: =Segments!B5 -> 0.97854805 | I21: End of Year | J21: 45291 | L21: Insiders Own | M21: 0.1194
B22: Market Cap. | C22: =C20*C21/1000000 -> 45214.688 | D22: Cash/Share | E22: =_xlfn.XLOOKUP("Cash & Eq.",'Fin. Data'!A:A,'Fin. Data'!B:B,,0)*1000000/C21 -> 0.83647836 | I22: EBITDA | K22: =_xlfn.XLOOKUP(I22,'Fin. Data'!A:A,'Fin. Data'!B:B,,0) -> 4111.4 | L22: b (Yahoo) | M22: {=IF(_FV(E2,"Beta") <> "",_FV(E2,"Beta"),"")} -> 0.8734
B23: +Total Debt | C23: ='Fin. Data'!B58 -> 12575.4 | D23: EBITDA/Net Financial Cost (NFC) | E23: =IFERROR(_xlfn.XLOOKUP("EBITDA",'Fin. Data'!A:A,'Fin. Data'!B:B,,0)/_xlfn.XLOOKUP("Net Financial Cost",'Fin. Data'!A:A,'Fin. Data'!B:B,,0),"") -> -9.4428112 | I23: Depreciation & Amortization | K23: =_xlfn.XLOOKUP(I23,'Fin. Data'!A:A,'Fin. Data'!B:B,,0) -> 429.2 | L23: Score (S&P) | M23: BBB+
B24: -Cash | C24: ='Fin. Data'!B39 -> 152.4 | D24: Debt/EBITDA | E24: =IFERROR(_xlfn.XLOOKUP("Total Debt",'Fin. Data'!A:A,'Fin. Data'!B:B,,0)/_xlfn.XLOOKUP("EBITDA",'Fin. Data'!A:A,'Fin. Data'!B:B,,0),"") -> 3.0586661 | F24: =Segments!C6 -> Non-U.S. | H24: =Segments!B6 -> 0.021451946 | I24: EBIT | K24: =_xlfn.XLOOKUP(I24,'Fin. Data'!A:A,'Fin. Data'!B:B,,0) -> 3682.2 | L24: Price/Book Value | M24: =IFERROR((C20*C21/(E20-E21))/1000000,"") -> 4.4924476
B25: =Enterprise Value | C25: =C22+C23-C24 -> 57637.688 | D25: "Others Assets"/Asset | E25: =IFERROR(_xlfn.XLOOKUP("Other Assets",'Fin. Data'!A:A,'Fin. Data'!B:B,,0)/_xlfn.XLOOKUP("Total Assets",'Fin. Data'!A:A,'Fin. Data'!B:B,,0),"") -> 0.53663635 | I25: Net Income | K25: =_xlfn.XLOOKUP(I25,'Fin. Data'!A:A,'Fin. Data'!B:B,,0) -> 1765.2 | L25: NCF(3y avg)/Asset | M25: =IFERROR(K31/E20,"") -> -0.015445974
B26: Holdings (nac/int'l) | C26: - | D26: Debt/Assets | E26: =_xlfn.XLOOKUP(D26,'Fin. Data'!A:A,'Fin. Data'!B:B,,0) -> 0.48947325 | F26: Categories | H26: % Sales | I26: EPS | K26: =1000000*K25/C21 -> 9.6886588 | L26: Price/Net Inc. (3y avg) | M26: =IFERROR(C22/K30,"") -> 78.511353
B27: t liq. (Holdings/Vol.) | C27: - | D27: EBITDA Margin (average) | E27: =IFERROR(AVERAGE(_xlfn.XLOOKUP("EBITDA Margin",'Fin. Data'!A:A,'Fin. Data'!B:D,,0)),"") -> 0.4885634 | F27: =Segments!C18 -> Beer | H27: =Segments!B18 -> 0.81939007 | I27: ROA | K27: =IFERROR(K25/E20,"") -> 0.068707014 | L27: EV/Asset | M27: =IFERROR(C25/E20,"") -> 2.2434361
B28: % Short | C28: 0.01274 | D28: Operating Margin (average) | E28: =IFERROR(AVERAGE(_xlfn.XLOOKUP("Operating Margin",'Fin. Data'!A:A,'Fin. Data'!B:D,,0)),"") -> 0.2944276 | I28: ROIC | K28: =IFERROR(Peers!C18,"") -> 0.12488643 | L28: EV/Ebitda (3y average) | M28: =IFERROR(C25/K29,"") -> 12.57193
B29: Traffic ESG | D29: Net Income Margin (average) | E29: =IFERROR(AVERAGE(_xlfn.XLOOKUP("Net Income Margin",'Fin. Data'!A:A,'Fin. Data'!B:D,,0)),"") -> 0.057745769 | F29: =Segments!C19 -> Wine | H29: =Segments!B19 -> 0.15580518 | I29: EBITDA (3y average) | K29: =AVERAGE(_xlfn.XLOOKUP("EBITDA",'Fin. Data'!A:A,'Fin. Data'!B:D,,0)) -> 4584.6333 | L29: Price/NCF (3y average) | M29: =IFERROR(C22/K31,"") -> -113.93873
B30: E | I30: Net Income (3y average) | K30: =AVERAGE(_xlfn.XLOOKUP("Net Income",'Fin. Data'!A:A,'Fin. Data'!B:D,,0)) -> 575.9 | L30: Bonds 1,3,5a (USD) | M30: -
B31: S | D31: Net Financial Cost/Avg Net Debt | E31: =IFERROR(-_xlfn.XLOOKUP("Net Financial Cost",'Fin. Data'!A:A,'Fin. Data'!B:B,,0)/AVERAGE(_xlfn.XLOOKUP("Net Debt",'Fin. Data'!A:A,'Fin. Data'!B:D,,0)),"") -> 0.036222058 | F31: =Segments!C20 -> Spirits | H31: =Segments!B20 -> 0.024804754 | I31: NCF (3y average) | K31: =AVERAGE(_xlfn.XLOOKUP("Net Financial Cost",'Fin. Data'!A:A,'Fin. Data'!B:D,,0)) -> -396.83333 | L31: Div+Rep.(3y avg)/Price | M31: =-IFERROR(SUM(E53:E55)/(3*C22),"") -> 0.038003137
B32: G | L32: Div. Yield | M32: =-IFERROR(L54/C22,"") -> 0.014459903
B33: INVESTMENT THESIS
B34: Pillars of Recommendation | H34: Recommendation | I34: Valuation Assumptions
B35: Pillar | C35: Explanation | H35: Hold | I35: Check DCF
B36: Strong Brand Portfolio | C36: Constellation Brands Inc. possesses numerous renowned brands that are recognized globally that follows the trend of "premiumization" (focus on premium products).
B37: Adaptive strategic oversight from the board | C37: Constellation's board is effectively shifting focus from lower-profit segments like wine and spirits, prioritizing higher-growth, high-margin investments instead.
B38: Leader in the U.S. imported beer market | C38: Constellation is a leader in the U.S. imported beer market, with a strong presence in the high-end beer.
B39: Risks of Investment | H39: Price Target | I39: Valuation
B40: Risk | C40: Explanation | H40: =DCF!D75 -> 188.41005 | I40: Discount Rate | J40: =DCF!F50 -> 0.0875 | L40: Price M. Upside | M40: -
B41: Competition | C41: The intense competition may impact its market position and profitability.
B42: Project cancellations | C42: Constellation Brands Inc. has a high incidence of project cancellations, like the Mexicali brewery, the project of craft beer | I42: Upside | J42: =IFERROR(DCF!D74,"") -> -0.24080247 | L42: EV M. Upside | M42: -
B43: Changing Consumer Preferences | C43: Shifts in consumer tastes toward healthier options or non-alcoholic beverages could affect sales in traditional alcohol categories.
...

Sheet Segments
B2: ="Regions "&"("&OP!$J$20&")" -> Regions (2024) | Q2: Products
D3: Nominal value | K3: YoY Growth
B4: Weight | C4: Region | D4: 2024 | E4: =D4-1 -> 2023 | F4: =E4-1 -> 2022 | G4: =F4-1 -> 2021 | H4: =G4-1 -> 2020 | I4: =H4-1 -> 2019 | K4: 2024 | L4: =K4-1 -> 2023 | M4: =L4-1 -> 2022 | N4: =M4-1 -> 2021 | O4: =N4-1 -> 2020 | P4: =O4-1 -> 2019
B5: =IFERROR(D5/$D$13,"") -> 0.97854805 | C5: U.S. | D5: 9748.1 | E5: 9194.5 | F5: 8585.8 | G5: 8396.5 | H5: 8116.2 | I5: 7894.8 | K5: =(D5-E5)/E5 -> 0.060209908 | L5: =(E5-F5)/F5 -> 0.070896131 | M5: =(F5-G5)/G5 -> 0.022545108 | N5: =(G5-H5)/H5 -> 0.034535867 | O5: =(H5-I5)/I5 -> 0.028043776 | P5: -
B6: =IFERROR(D6/$D$13,"") -> 0.021451946 | C6: Non-U.S. | D6: 213.7 | E6: 258.1 | F6: 234.9 | G6: 218.4 | H6: 227.3 | I6: 221.2 | K6: =(D6-E6)/E6 -> -0.17202635 | L6: =(E6-F6)/F6 -> 0.098765432 | M6: =(F6-G6)/G6 -> 0.075549451 | N6: =(G6-H6)/H6 -> -0.039155301 | O6: =(H6-I6)/I6 -> 0.027576854 | P6: -
B7: =IFERROR(D7/$D$13,"") -> 0 | K7: =(D7-E7)/E7 -> #DIV/0! | L7: =(E7-F7)/F7 -> #DIV/0! | M7: =(F7-G7)/G7 -> #DIV/0! | N7: =(G7-H7)/H7 -> #DIV/0! | O7: =(H7-I7)/I7 -> #DIV/0! | P7: -
B8: =IFERROR(D8/$D$13,"") -> 0 | K8: =(D8-E8)/E8 -> #DIV/0! | L8: =(E8-F8)/F8 -> #DIV/0! | M8: =(F8-G8)/G8 -> #DIV/0! | N8: =(G8-H8)/H8 -> #DIV/0! | O8: =(H8-I8)/I8 -> #DIV/0! | P8: -
B9: =IFERROR(D9/$D$13,"") -> 0 | K9: =(D9-E9)/E9 -> #DIV/0! | L9: =(E9-F9)/F9 -> #DIV/0! | M9: =(F9-G9)/G9 -> #DIV/0! | N9: =(G9-H9)/H9 -> #DIV/0! | O9: =(H9-I9)/I9 -> #DIV/0! | P9: -
B10: =IFERROR(D10/$D$13,"") -> 0 | K10: =(D10-E10)/E10 -> #DIV/0! | L10: =(E10-F10)/F10 -> #DIV/0! | M10: =(F10-G10)/G10 -> #DIV/0! | N10: =(G10-H10)/H10 -> #DIV/0! | O10: =(H10-I10)/I10 -> #DIV/0! | P10: -
B11: =IFERROR(D11/$D$13,"") -> 0
B12: =IFERROR(D12/$D$13,"") -> 0
B13: =SUM(B5:B12) -> 1 | C13: TOTAL | D13: =SUM(D5:D12) -> 9961.8 | E13: =SUM(E5:E12) -> 9452.6 | F13: =SUM(F5:F12) -> 8820.7 | G13: =SUM(G5:G12) -> 8614.9 | H13: =SUM(H5:H12) -> 8343.5 | I13: =SUM(I5:I12) -> 8116 | K13: =(D13-E13)/E13 -> 0.053868777 | L13: =(E13-F13)/F13 -> 0.071638305 | M13: =(F13-G13)/G13 -> 0.023888844 | N13: =(G13-H13)/H13 -> 0.032528315 | O13: =(H13-I13)/I13 -> 0.02803105 | P13: -
B15: ="Categories "&"("&OP!$J$20&")" -> Categories (2024)
D16: Nominal value | K16: YoY Growth
B17: Weight | C17: Category | D17: 2024 | E17: =D17-1 -> 2023 | F17: =E17-1 -> 2022 | G17: =F17-1 -> 2021 | H17: =G17-1 -> 2020 | I17: =H17-1 -> 2019 | K17: 2024 | L17: =K17-1 -> 2023 | M17: =L17-1 -> 2022 | N17: =M17-1 -> 2021 | O17: =N17-1 -> 2020 | P17: =O17-1 -> 2019
B18: =IFERROR(D18/$D$24,"") -> 0.81939007 | C18: Beer | D18: 8162.6 | E18: 7465 | F18: 6751.6 | G18: 6074.6 | H18: 5615.9 | I18: 5202.1 | K18: =(D18-E18)/E18 -> 0.093449431 | L18: =(E18-F18)/F18 -> 0.10566384 | M18: =(F18-G18)/G18 -> 0.11144767 | N18: =(G18-H18)/H18 -> 0.081678805 | O18: =(H18-I18)/I18 -> 0.079544799 | P18: -
B19: =IFERROR(D19/$D$24,"") -> 0.15580518 | C19: Wine | D19: 1552.1 | E19: 1722.7 | F19: 1819.3 | G19: 2208.4 | H19: 2367.5 | I19: 2532.5 | K19: =(D19-E19)/E19 -> -0.099030592 | L19: =(E19-F19)/F19 -> -0.053097345 | M19: =(F19-G19)/G19 -> -0.17619091 | N19: =(G19-H19)/H19 -> -0.06720169 | O19: =(H19-I19)/I19 -> -0.065153011 | P19: -
B20: =IFERROR(D20/$D$24,"") -> 0.024804754 | C20: Spirits | D20: 247.1 | E20: 264.9 | F20: 249.8 | G20: 331.9 | H20: 360.1 | I20: 381.4 | K20: =(D20-E20)/E20 -> -0.067195168 | L20: =(E20-F20)/F20 -> 0.060448359 | M20: =(F20-G20)/G20 -> -0.24736366 | N20: =(G20-H20)/H20 -> -0.07831158 | O20: =(H20-I20)/I20 -> -0.05584688 | P20: -
B21: =IFERROR(D21/$D$24,"") -> 0 | K21: =(D21-E21)/E21 -> #DIV/0! | L21: =(E21-F21)/F21 -> #DIV/0! | M21: =(F21-G21)/G21 -> #DIV/0! | N21: =(G21-H21)/H21 -> #DIV/0! | O21: =(H21-I21)/I21 -> #DIV/0! | P21: -
B22: =IFERROR(D22/$D$24,"") -> 0 | K22: =(D22-E22)/E22 -> #DIV/0! | L22: =(E22-F22)/F22 -> #DIV/0! | M22: =(F22-G22)/G22 -> #DIV/0! | N22: =(G22-H22)/H22 -> #DIV/0! | O22: =(H22-I22)/I22 -> #DIV/0! | P22: -
B23: =IFERROR(D23/$D$24,"") -> 0 | K23: =(D23-E23)/E23 -> #DIV/0! | L23: =(E23-F23)/F23 -> #DIV/0! | M23: =(F23-G23)/G23 -> #DIV/0! | N23: =(G23-H23)/H23 -> #DIV/0! | O23: =(H23-I23)/I23 -> #DIV/0! | P23: -
B24: =SUM(B18:B23) -> 1 | C24: TOTAL | D24: =SUM(D18:D23) -> 9961.8 | E24: =SUM(E18:E23) -> 9452.6 | F24: =SUM(F18:F23) -> 8820.7 | G24: =SUM(G18:G23) -> 8614.9 | H24: =SUM(H18:H23) -> 8343.5 | I24: =SUM(I18:I23) -> 8116 | K24: =(D24-E24)/E24 -> 0.053868777 | L24: =(E24-F24)/F24 -> 0.071638305 | M24: =(F24-G24)/G24 -> 0.023888844 | N24: =(G24-H24)/H24 -> 0.032528315 | O24: =(H24-I24)/I24 -> 0.02803105 | P24: -
B26: Categories' operating margin
D27: Nominal value | K27: YoY Growth
B28: Category | D28: 2024 | E28: =D28-1 -> 2023 | F28: =E28-1 -> 2022 | G28: =F28-1 -> 2021 | H28: =G28-1 -> 2020 | I28: =H28-1 -> 2019 | K28: 2024 | L28: =K28-1 -> 2023 | M28: =L28-1 -> 2022 | N28: =M28-1 -> 2021 | O28: =N28-1 -> 2020 | P28: =O28-1 -> 2019
B29: Beer | D29: 0.379 | E29: 0.383 | F29: 0.4 | G29: 0.411 | H29: 0.4 | I29: 0.393 | K29: =(D29-E29)/E29 -> -0.010443864 | L29: =(E29-F29)/F29 -> -0.0425 | M29: =(F29-G29)/G29 -> -0.02676399 | N29: =(G29-H29)/H29 -> 0.0275 | O29: =(H29-I29)/I29 -> 0.017811705 | P29: -
B30: Wine and Spirits | D30: 0.222 | E30: 0.228 | F30: 0.227 | G30: 0.245 | H30: 0.26 | I30: 0.265 | K30: =(D30-E30)/E30 -> -0.026315789 | L30: =(E30-F30)/F30 -> 0.0044052863 | M30: =(F30-G30)/G30 -> -0.073469388 | N30: =(G30-H30)/H30 -> -0.057692308 | O30: =(H30-I30)/I30 -> -0.018867925 | P30: -
C31: Spirits | K31: =(D31-E31)/E31 -> #DIV/0! | L31: =(E31-F31)/F31 -> #DIV/0! | M31: =(F31-G31)/G31 -> #DIV/0! | N31: =(G31-H31)/H31 -> #DIV/0! | O31: =(H31-I31)/I31 -> #DIV/0! | P31: -
K32: =(D32-E32)/E32 -> #DIV/0! | L32: =(E32-F32)/F32 -> #DIV/0! | M32: =(F32-G32)/G32 -> #DIV/0! | N32: =(G32-H32)/H32 -> #DIV/0! | O32: =(H32-I32)/I32 -> #DIV/0! | P32: -
K33: =(D33-E33)/E33 -> #DIV/0! | L33: =(E33-F33)/F33 -> #DIV/0! | M33: =(F33-G33)/G33 -> #DIV/0! | N33: =(G33-H33)/H33 -> #DIV/0! | O33: =(H33-I33)/I33 -> #DIV/0! | P33: -
K34: =(D34-E34)/E34 -> #DIV/0! | L34: =(E34-F34)/F34 -> #DIV/0! | M34: =(F34-G34)/G34 -> #DIV/0! | N34: =(G34-H34)/H34 -> #DIV/0! | O34: =(H34-I34)/I34 -> #DIV/0! | P34: -
B35: TOTAL | D35: =SUM(D29:D34) -> 0.601 | E35: =SUM(E29:E34) -> 0.611 | F35: =SUM(F29:F34) -> 0.627 | G35: =SUM(G29:G34) -> 0.656 | H35: =SUM(H29:H34) -> 0.66 | I35: =SUM(I29:I34) -> 0.658 | K35: =(D35-E35)/E35 -> -0.016366612 | L35: =(E35-F35)/F35 -> -0.025518341 | M35: =(F35-G35)/G35 -> -0.044207317 | N35: =(G35-H35)/H35 -> -0.0060606061 | O35: =(H35-I35)/I35 -> 0.0030395137 | P35: -
B37: Number of units shipped (in million)
D38: Nominal value | K38: YoY Growth
B39: Category | D39: 2024 | E39: =D39-1 -> 2023 | F39: =E39-1 -> 2022 | G39: =F39-1 -> 2021 | H39: =G39-1 -> 2020 | I39: =H39-1 -> 2019 | K39: 2024 | L39: =K39-1 -> 2023 | M39: =L39-1 -> 2022 | N39: =M39-1 -> 2021 | O39: =N39-1 -> 2020 | P39: =O39-1 -> 2019
B40: Beer | D40: 4181 | E40: 3892 | F40: 3642 | G40: 3346 | H40: 3119 | I40: 2941 | K40: =(D40-E40)/E40 -> 0.074254882 | L40: =(E40-F40)/F40 -> 0.068643602 | M40: =(F40-G40)/G40 -> 0.088463837 | N40: =(G40-H40)/H40 -> 0.072779737 | O40: =(H40-I40)/I40 -> 0.060523631 | P40: -
B41: Wine and Spirits | D41: 238 | E41: 271 | F41: 299 | G41: 450 | H41: 536 | I41: 585 | K41: =(D41-E41)/E41 -> -0.12177122 | L41: =(E41-F41)/F41 -> -0.093645485 | M41: =(F41-G41)/G41 -> -0.33555556 | N41: =(G41-H41)/H41 -> -0.16044776 | O41: =(H41-I41)/I41 -> -0.083760684 | P41: -
B44: Categories | D44: Description | J44: Graphs
B45: Beer | D45: This segment positions Constellation as a leader in the U.S. imported beer market, with a strong presence in the high-end beer segment, featuring well-known names like Corona, Modelo, and Pacifico.
B46: Wine and Spirits | D46: This segment features a diverse portfolio, focusing on premium and luxury wines such as Robert Mondavi and The Prisoner Wine Company, as well as popular spirits like High West Whiskey and SVEDKA Vodka. It emphasizes premiumization to cater to evolving consumer preferences.
...

Sheet Acuerdo
A1: Invertir
A2: NO invertir
A3: Mantener sin elevar posición
A4: Mantener (y seguir comprando)
A5: Liquidar
A6: PENDIENTE

Sheet Peers
B1: Peer Logo | C1: Peer Name | D1: Description
C2: #VALUE! | D2: Established in 2005 throught the merger of Molson, a canadian brewerie, and Coors, na american beer producer, Molson Coors Beverage Company is a leading multinational beverage and brewing company, that primarily produces beer, along with various hard seltzers and ready-to-drink cocktails. It operates worldwide, with a strong presence in North America and Europe.
C3: #VALUE! | D3: Diageo plc is a British alcoholic incorporated in 1886 and it specializes in the production, marketing and sales of various alcoholic beverages. It has a portfolios of iconic brands ranging form spirits to beers, and including gin, vodka, cider, liquer, wine, etc.
C4: #VALUE! | D4: Anheuser-Busch Inbev SA is a multinational beverage and brewing company, headquartered in Belgium, that produces, distributes, exports, markets, and sells beer and beverages.
C5: #VALUE! | D5: Pernod Ricard is a wine and spirits producers and seller. The company operates worldwine and is know for its diverse portfolio that includes whiskey, vodka, gin, rum, liqueur and bitters, champagne, tequila and mezcal, and aperitif.
C6: #VALUE! | D6: Brown-Forman is a well-known multinacional beverage company that manufactures, exports, markets, and sells various alcoholic beverages. It provides wines, whiskey spirits, whiskey-based flavored liqueurs, ready-to-drink cocktails, ready-to-pour products, vodkas, tequilas, gin, brandy, rum, bourbons, and liqueurs.
B8: In Millions USD | C8: =OP!E2 -> #VALUE! | D8: =C2 -> #VALUE! | E8: =C3 -> #VALUE! | F8: =C4 -> #VALUE! | G8: =C5 -> #VALUE! | H8: =C6 -> #VALUE! | I8: AVERAGE | J8: Deviation from Average
B9: Company Info | I9: =IFERROR(AVERAGE(C9:H9),"") | L9: TRAFFIC
B10: Market Cap | C10: {=_FV(C8,"Market cap",TRUE)/1000000} -> 45214.688 | D10: 11728 | E10: 78614 | F10: 126627 | G10: 35107 | H10: 22706 | I10: =IFERROR(AVERAGE(C10:H10),"") -> 53332.781 | J10: =SQRT((C10-I10)^2) -> 8118.0934 | M10: Best Value
B11: Net Sales (current) | C11: =C56 -> 9961.8 | D11: =D56 -> 11702 | E11: =E56 -> 20269 | F11: =F56 -> 59380 | G11: =G56 -> 13753 | H11: =H56 -> 4178 | I11: =IFERROR(AVERAGE(C11:H11),"") -> 19873.967 | J11: =SQRT((C11-I11)^2) -> 9912.1667
B12: Profitability | I12: =IFERROR(AVERAGE(C12:H12),"") | M12: Important Value
B13: Sales Growth (ttm) | C13: =C56/C55-1 -> 0.053868777 | D13: =D56/D55-1 -> 0.09354266 | E13: =E56/E55-1 -> -0.01391389 | F13: =F56/F55-1 -> 0.027584536 | G13: =G56/G55-1 -> 0.038040607 | H13: =H56/H55-1 -> -0.011825922 | I13: =IFERROR(AVERAGE(C13:H13),"") -> 0.031216128 | J13: =SQRT((C13-I13)^2) -> 0.022652649
B14: Sales Growth (36m) | C14: =C56/C54-1 -> 0.1563454 | D14: =D56/D54-1 -> -0.0018764927 | E14: =E56/E54-1 -> 0.15073237 | F14: =F56/F54-1 -> 0.26661121 | G14: =G56/G54-1 -> 0.31431575 | H14: =H56/H54-1 -> 0.22521994 | I14: =IFERROR(AVERAGE(C14:H14),"") -> 0.1852247 | J14: =SQRT((C14-I14)^2) -> 0.028879295 | M14: Worst Value
B15: Operating Margin | C15: =C59/C56 -> 0.31818547 | D15: =D59/D56 -> 0.12288498 | E15: =E59/E56 -> 0.29606789 | F15: =F59/F56 -> 0.2401482 | G15: =G59/G56 -> 0.21209918 | H15: =H59/H56 -> 0.26352322 | I15: =IFERROR(AVERAGE(C15:H15),"") -> 0.24215149 | J15: =SQRT((C15-I15)^2) -> 0.076033981
B16: Net Income Margin | C16: =C62/C56 -> 0.17719689 | D16: =D62/D56 -> 0.099897453 | E16: =E62/E56 -> 0.19093197 | F16: =F62/F56 -> 0.08994611 | G16: =G62/G56 -> 0.11422962 | H16: =H62/H56 -> 0.23647678 | I16: =IFERROR(AVERAGE(C16:H16),"") -> 0.15144647 | J16: =SQRT((C16-I16)^2) -> 0.025750421
B17: Return on Equity (RoE) | C17: =C62/C74 -> 0.18117437 | D17: =D62/D74 -> 0.087193257 | E17: =E62/E74 -> 0.38576555 | F17: =F62/F74 -> 0.065255107 | G17: =G62/G74 -> 0.093157021 | H17: =H62/H74 -> 0.28092124 | I17: =IFERROR(AVERAGE(C17:H17),"") -> 0.18224442 | J17: =SQRT((C17-I17)^2) -> 0.0010700546
B18: Return on Invested Capital (ROIC) | C18: =(1+C61/(C59+C60))*C59/(C73+C74-C65) -> 0.12488643 | D18: =(1+D61/(D59+D60))*D59/(D73+D74-D65) -> 0.062712614 | E18: =(1+E61/(E59+E60))*E59/(E73+E74-E65) -> 0.1624451 | F18: =(1+F61/(F59+F60))*F59/(F73+F74-F65) -> 0.083735629 | G18: =(1+G61/(G59+G60))*G59/(G73+G74-G65) -> 0.080745074 | H18: =(1+H61/(H59+H60))*H59/(H73+H74-H65) -> 0.13814683 | I18: =IFERROR(AVERAGE(C18:H18),"") -> 0.10877861 | J18: =SQRT((C18-I18)^2) -> 0.016107817
B19: Solvency | I19: =IFERROR(AVERAGE(C19:H19),"")
B20: Debt/Assets | C20: =C73/C70 -> 0.48947325 | D20: =D73/D70 -> 0.23772512 | E20: =E73/E70 -> 0.47281963 | F20: =F73/F70 -> 0.35637823 | G20: =G73/G70 -> 0.34752973 | H20: =H73/H70 -> 0.37962283 | I20: =IFERROR(AVERAGE(C20:H20),"") -> 0.38059146 | J20: =SQRT((C20-I20)^2) -> 0.10888179
B21: Net Debt/EBITDA | C21: =(C73-C65)/C58 -> 3.0215985 | D21: =(D73-D65)/D58 -> 2.4900876 | E21: =(E73-E65)/E58 -> 2.8243262 | F21: =(F73-F65)/F58 -> 3.5427362 | G21: =(G73-G65)/G58 -> 3.4297012 | H21: =(H73-H65)/H58 -> 1.8054422 | I21: =IFERROR(AVERAGE(C21:H21),"") -> 2.8523153 | J21: =SQRT((C21-I21)^2) -> 0.16928317
B22: Interest Coverage Ratio | C22: =-C58/C60 -> -9.4428112 | D22: =-D58/D60 -> -10.397891 | E22: =-E58/E60 -> -8.0079096 | F22: =-F58/F60 -> -4.625 | G22: =-G58/G60 -> -7.5032967 | H22: =-H58/H60 -> -13.00885 | I22: =IFERROR(AVERAGE(C22:H22),"") -> -8.8309596 | J22: =SQRT((C22-I22)^2) -> 0.61185158
B23: Liquidity
B24: Current Ratio | C24: =C68/C72 -> 1.1778122 | D24: =D68/D72 -> 0.69606645 | E24: =E68/E72 -> 1.5328334 | F24: =F68/F72 -> 0.62888901 | G24: =G68/G72 -> 1.6583699 | H24: =H68/H72 -> 2.588839 | I24: =IFERROR(AVERAGE(C24:H24),"") -> 1.3804683 | J24: =SQRT((C24-I24)^2) -> 0.20265611
B25: Quick Ratio | C25: =(C65+C66)/C72 -> 0.33190715 | D25: =(D65+D66)/D72 -> 0.39750794 | E25: =(E65+E66)/E72 -> 0.50385083 | F25: =(F65+F66)/F72 -> 0.39686726 | G25: =(G65+G66)/G72 -> 0.60446221 | H25: =(H65+H66)/H72 -> 0.77934573 | I25: =IFERROR(AVERAGE(C25:H25),"") -> 0.50232352 | J25: =SQRT((C25-I25)^2) -> 0.17041637
B26: Activity | I26: =IFERROR(AVERAGE(C26:H26),"")
B27: Inventory Turnover | C27: =C57/C67 -> 2.3790117 | D27: =D57/D67 -> 9.1433915 | E27: =E57/E67 -> 0.83034979 | F27: =F57/F67 -> 5.014827 | G27: =G57/G67 -> 0.5600181 | H27: =H57/H67 -> 0.64593114 | I27: =IFERROR(AVERAGE(C27:H27),"") -> 3.0955882 | J27: =SQRT((C27-I27)^2) -> 0.71657652
B28: Acc. Receivable Turnover | C28: =C56/C66 -> 11.961816 | D28: =D56/D66 -> 15.437995 | E28: =E56/E66 -> 5.812733 | F28: =F56/F66 -> 13.659995 | G28: =G56/G66 -> 7.5815877 | H28: =H56/H66 -> 5.4330299 | I28: =IFERROR(AVERAGE(C28:D28,F28,H28),"") -> 11.623209 | J28: =SQRT((C28-I28)^2) -> 0.33860666
A29: Price/Sales | B29: Payables Turnover | C29: =C57/C71 -> 5.2515135 | D29: =D57/D71 -> 3.0490644 | E29: =E57/E71 -> 1.2122259 | F29: =F57/F71 -> 1.5452648 | G29: =G57/G71 -> 0.96491228 | H29: =H57/H71 -> 6.1835206 | I29: =IFERROR(AVERAGE(C29:D29,F29,H29),"") -> 4.0073409 | J29: =SQRT((C29-I29)^2) -> 1.2441727
B30: Fixed Asset Turnover | C30: =C56/C69 -> 1.2366918 | D30: =D56/D69 -> 0.49738598 | E30: =E56/E69 -> 0.66788586 | F30: =F56/F69 -> 0.30300092 | G30: =G56/G69 -> 0.49927394 | H30: =H56/H69 -> 1.0116223 | I30: =IFERROR(AVERAGE(C30:H30),"") -> 0.70264347 | J30: =SQRT((C30-I30)^2) -> 0.53404836
B31: Total Asset Turnover | C31: =C56/C70 -> 0.3877439 | D31: =D56/D70 -> 0.44367773 | E31: =E56/E70 -> 0.44572723 | F31: =F56/F70 -> 0.27072125 | G31: =G56/G70 -> 0.32777235 | H31: =H56/H70 -> 0.5116336 | I31: =IFERROR(AVERAGE(C31:H31),"") -> 0.39787934 | J31: =SQRT((C31-I31)^2) -> 0.010135442
B32: Valuation | I32: =IFERROR(AVERAGE(C32:H32),"")
B33: Price/Earnings | C33: =C10/C62 -> 25.614484 | D33: =D10/D62 -> 10.032506 | E33: =E10/E62 -> 20.313695 | F33: =F10/F62 -> 23.708482 | G33: =G10/G62 -> 22.346913 | H33: =H10/H62 -> 22.981781 | I33: =IFERROR(AVERAGE(C33:H33),"") -> 20.832977 | J33: =SQRT((C33-I33)^2) -> 4.7815075
B34: Price/Sales | C34: =C10/C56 -> 4.538807 | D34: =D10/D56 -> 1.0022218 | E34: =E10/E56 -> 3.8785337 | F34: =F10/F56 -> 2.1324857 | G34: =G10/G56 -> 2.5526794 | H34: =H10/H56 -> 5.4346577 | I34: =IFERROR(AVERAGE(C34:H34),"") -> 3.2565642 | J34: =SQRT((C34-I34)^2) -> 1.2822428
B35: Price/Book | C35: =C10/C74 -> 4.6406881 | D35: =D10/D74 -> 0.87476691 | E35: =E10/E74 -> 7.8363238 | F35: =F10/F74 -> 1.5470995 | G35: =G10/G74 -> 2.0817718 | H35: =H10/H74 -> 6.4560705 | I35: =IFERROR(AVERAGE(C35:H35),"") -> 3.9061201 | J35: =SQRT((C35-I35)^2) -> 0.73456797
B36: EV/Sales | C36: =(C73+C10-C65)/C56 -> 5.7858708 | D36: =(D73+D10-D65)/D56 -> 1.4637669 | E36: =(E73+E10-E65)/E56 -> 4.8660516 | F36: =(F73+F10-F65)/F56 -> 3.2737622 | G36: =(G73+G10-G65)/G56 -> 3.4040573 | H36: =(H73+H10-H65)/H56 -> 6.0698899 | I36: =IFERROR(AVERAGE(C36:H36),"") -> 4.1438998 | J36: =SQRT((C36-I36)^2) -> 1.641971
B37: EV/EBITDA | C37: =(C73+C10-C65)/C58 -> 14.018993 | D37: =(D73+D10-D65)/D58 -> 7.8971876 | E37: =(E73+E10-E65)/E58 -> 13.917031 | F37: =(F73+F10-F65)/F58 -> 10.162371 | G37: =(G73+G10-G65)/G58 -> 13.712947 | H37: =(H73+H10-H65)/H58 -> 17.251701 | I37: =IFERROR(AVERAGE(C37:H37),"") -> 12.826705 | J37: =SQRT((C37-I37)^2) -> 1.1922879
B38: Stock Info | I38: =IFERROR(AVERAGE(C38:H38),"")
B39: Float | C39: =OP!M20 -> 0.90844993 | D39: 0.893 | E39: 1 | F39: 0.3988 | G39: 0.7639 | H39: 0.6902 | I39: =IFERROR(AVERAGE(C39:H39),"") -> 0.77572499 | J39: =SQRT((C39-I39)^2) -> 0.13272494
B40: b (Yahoo) | C40: =OP!M22 -> 0.8734 | D40: 0.81 | E40: 0.36 | F40: 0.98 | G40: 0.5 | H40: 0.75 | I40: =IFERROR(AVERAGE(C40:H40),"") -> 0.71223333 | J40: =SQRT((C40-I40)^2) -> 0.16116667
B41: Dividend Yield (yahoo finance) | C41: =OP!M32 -> 0.014459903 | D41: 0.031 | E41: 0.0074 | F41: 0.0132 | G41: 0.0357 | H41: 0.018 | I41: =IFERROR(AVERAGE(C41:H41),"") -> 0.019959984 | J41: =SQRT((C41-I41)^2) -> 0.0055000809
...

Sheet ESG
B1: Company GICS Sector: | T1: Yes
B2: Consumer Staples | C2: <- Select Industry | T2: No
B3: ESG Analysis | K3: Relative ESG Analysis
B4: Parameters | C4: Impact | D4: Do they report? | E4: Ranking | F4: Mitigation Plan | G4: Traffic Lights | H4: Improvement over time? | I4: Targets / Goals? | J4: Comments | K4: Parameters | L4: =Peers!C8 -> #VALUE! | M4: =Peers!D8 -> #VALUE! | N4: =Peers!E8 -> #VALUE! | O4: =Peers!F8 -> #VALUE! | P4: =Peers!G8 -> #VALUE! | Q4: =Peers!H8 -> #VALUE! | R4: AVERAGE
B5: Environmental | K5: Ratios
A6: 1 | B6: CO2 Direct Emissions | C6: =VLOOKUP($B$2,'Sector Impact'!$K$4:$AA$16,A6+1,FALSE) -> High | D6: Yes | E6: Medium High | F6: Yes | H6: Co2 emissions have increased in the last five years, but slower every year | I6: reducing scope 1 and 2 emissions by 15% by 2025 | J6: no info about 2024 | K6: CO2 Emissions/$M Sales | L6: =L12/L$11 -> #DIV/0! | M6: =#REF!/M$11 -> #REF! | N6: =N12/N$11 -> #DIV/0! | O6: =O12/O$11 -> 61.986123 | P6: =P12/P$11 -> #DIV/0! | Q6: =Q12/Q$11 -> #DIV/0! | R6: =IFERROR(AVERAGE(L6:Q6),"")
A7: 2 | B7: Total Water Consumption | C7: =VLOOKUP($B$2,'Sector Impact'!$K$4:$AA$16,A7+1,FALSE) -> Very High | D7: Yes | E7: Medium High | F7: Yes | H7: inconsistent | I7: nothing especific | J7: vague goals and strategies | K7: Water Consumption/$M Sales | L7: =L13/L$11 -> #DIV/0! | M7: =M12/M$11 -> 81.04495 | N7: =N13/N$11 -> #DIV/0! | O7: =O13/O$11 -> #VALUE! | P7: =P13/P$11 -> #DIV/0! | Q7: =Q13/Q$11 -> #DIV/0! | R7: =IFERROR(AVERAGE(L7:Q7),"")
A8: 3 | B8: Total Energy Consumption | C8: =VLOOKUP($B$2,'Sector Impact'!$K$4:$AA$16,A8+1,FALSE) -> High | D8: No | E8: "Villain" | F8: No | H8: - | I8: no | J8: 6/10 years unreported, including 2023. Increase in consumption in the years reported, implementation of renewable energy sources. | K8: Energy Consumption/$M Sales | L8: =L14/L$11 -> #DIV/0! | M8: =M14/M$11 -> 2040.0252 | N8: =N14/N$11 -> #DIV/0! | O8: =O14/O$11 -> 933.8161 | P8: =P14/P$11 -> #DIV/0! | Q8: =Q14/Q$11 -> #DIV/0! | R8: =IFERROR(AVERAGE(L8:Q8),"")
A9: 4 | B9: Waste Management | C9: =VLOOKUP($B$2,'Sector Impact'!$K$4:$AA$16,A9+1,FALSE) -> High | D9: No | E9: Medium | F9: Yes | H9: - | I9: reducing packaging, increase percentage of recicled materials used in packaging to 80% | J9: only reported up to 2016 | K9: Waste Production/$M Sales | L9: =L15/L$11 -> #DIV/0! | M9: =M15/M$11 -> 70.383951 | N9: =N15/N$11 -> #DIV/0! | O9: =O15/O$11 -> #VALUE! | P9: =P15/P$11 -> #DIV/0! | Q9: =Q15/Q$11 -> #DIV/0! | R9: =IFERROR(AVERAGE(L9:Q9),"")
A10: 5 | B10: Land Degradation/Deforestation/Biodiversity loss/Animal sufering/… | C10: =VLOOKUP($B$2,'Sector Impact'!$K$4:$AA$16,A10+1,FALSE) -> High | D10: Yes | E10: Medium High | F10: Yes | H10: - | I10: environmental partnerships, donations and restoration iniciatives | J10: - | K10: Inputs
B11: Social | K11: Net Sales ($M) | M11: 11702 | O11: 59380
A12: 6 | B12: Employee Turnover % | C12: =VLOOKUP($B$2,'Sector Impact'!$K$4:$AA$16,A12+1,FALSE) -> Medium | D12: No | E12: Medium | F12: No | H12: - | I12: - | J12: - | K12: CO2 Emissions Total (Tonnes) | M12: 948388 | O12: 3680736
A13: 7 | B13: Salaries & Compensation | C13: =VLOOKUP($B$2,'Sector Impact'!$K$4:$AA$16,A13+1,FALSE) -> High | D13: No | E13: Medium | F13: No | H13: - | I13: - | J13: - | K13: Water Consumption Total (Cubic Meters) | M13: - | O13: -
A14: 8 | B14: Reputation | C14: =VLOOKUP($B$2,'Sector Impact'!$K$4:$AA$16,A14+1,FALSE) -> High | D14: No | E14: Medium High | F14: No | H14: - | I14: - | J14: nothing relevant found | K14: Energy Consumption Total (Gigajoules) | M14: 23872375 | O14: 55450000
A15: 9 | B15: Discrimination Events | C15: =VLOOKUP($B$2,'Sector Impact'!$K$4:$AA$16,A15+1,FALSE) -> Low | F15: Yes | K15: Waste Production Total (Tonnes) | M15: 823633 | O15: -
A16: 10 | B16: Work Safety | C16: =VLOOKUP($B$2,'Sector Impact'!$K$4:$AA$16,A16+1,FALSE) -> Medium | D16: No | E16: "Best in class" | F16: No | H16: - | I16: - | J16: no incidents found | K16: ESG Scores
A17: 11 | B17: Damage to consumer health | C17: =VLOOKUP($B$2,'Sector Impact'!$K$4:$AA$16,A17+1,FALSE) -> Medium | D17: No | E17: Medium High | F17: No | H17: - | I17: - | J17: promotion of responsible alcohol consumption, member of Responsability.org | K17: Refinitiv | L17: 37 | M17: 65 | O17: -
A18: 12 | B18: PXP? | C18: =VLOOKUP($B$2,'Sector Impact'!$K$4:$AA$16,A18+1,FALSE) -> Low | K18: Sustainalytics | L18: 26.4 | M18: 25.5 | O18: 22.1
A19: 13 | B19: Supply chain | C19: =VLOOKUP($B$2,'Sector Impact'!$K$4:$AA$16,A19+1,FALSE) -> High | D19: No | E19: Medium | F19: No | H19: - | I19: - | J19: suppliers are not disclosed, but a code of conduct has been published | K19: ISS | L19: C+ | M19: C | O19: C
A20: 14 | B20: Community involvement | C20: =VLOOKUP($B$2,'Sector Impact'!$K$4:$AA$16,A20+1,FALSE) -> Low | K20: CDP | L20: A-,A- | M20: - | O20: A,A
A21: 15 | B21: Public Sector | C21: =VLOOKUP($B$2,'Sector Impact'!$K$4:$AA$16,A21+1,FALSE) -> Very High | D21: No | E21: Medium High | F21: No | H21: - | I21: - | J21: -
A22: 16 | B22: Litigation | C22: =VLOOKUP($B$2,'Sector Impact'!$K$4:$AA$16,A22+1,FALSE) -> Low | D22: Yes
B23: Corporate Governance | K23: PARAMETERS
A24: 17 | B24: Diversity (Gender, Age, Industry, Region) | E24: Medium | F24: No | H24: - | I24: - | J24: barelly any diversity in age, gender and ethnicity, however quite diverse regarding backrounds | K24: IMPACT | L24: RANKING | M24: MITIGATION PLAN | O24: TRAFFIC
A25: 18 | B25: % Independence | E25: Medium High | F25: Yes | H25: Yes | I25: - | J25: 10 out of 13 independent board members, seven of which have been added in the last 5 years | K25: Low | L25: "Best in class" | M25: Is there evidence of a plan/program ?
A26: 19 | B26: average time as independent directors | E26: "Best in class" | F26: No | H26: - | I26: - | J26: average 5.3 years. | K26: Medium | L26: Medium High
A27: 20 | B27: Recent departures of directors / C-level executives? | E27: Medium High | F27: Yes | H27: - | I27: to increase nr of independent directors | J27: executive vice-president and president of the company’s wine and spirits division has stepped down in february | K27: High | L27: Medium
A28: 21 | B28: CEO/Chairman duality | E28: "Best in class" | F28: No | H28: - | I28: - | J28: CEO and chairman are independent | K28: Very high | L28: "Villain"
A29: 22 | B29: Transparency (ESG, segments, acquisitions, other) | E29: Medium | F29: No | H29: - | I29: - | J29: the data found for this company regarding environment, and social measures is mainly taken from 2023 documents, since 2024 sustainability report has not yet been published.
A30: 23 | B30: Time taken to report after the end of the quarter / year | E30: Medium High | F30: No | H30: - | I30: - | J30: 3 months
A31: 24 | B31: Additional participation of the CEO in other boards or excessive participation of Ch. | E31: "Best in class" | F31: No | H31: - | I31: - | J31: -
A32: 25 | B32: Audit / Consulting | D32: Yes | E32: "Villain" | F32: No | H32: no, on the contrary | I32: - | J32: "other fees" where reported in the proxy statement in the value of $13,000
A33: 26 | B33: ESG-compensation related | D33: No | E33: Medium | F33: No | H33: - | I33: - | J33: -
A34: 27 | B34: Management compensation schemes | D34: Yes | E34: "Best in class" | F34: No | H34: - | I34: - | J34: -
B37: the data found for this company regarding environment, and social measures is mainly taken from 2023 documents, since 2024 sustainability report has not yet been published.

Sheet DCF
A1: VALUATION MODEL
G3: Short Term | K3: Long Term
A4: Section | B4: Line # | C4: ITEM | D4: 2022 (Real) | E4: 2023 (Real) | F4: 2024 (Real) | G4: 2025 | H4: =G4+1 -> 2026 | I4: =H4+1 -> 2027 | J4: =I4+1 -> 2028 | K4: =J4+1 -> 2029 | L4: =K4+1 -> 2030 | M4: =L4+1 -> 2031 | N4: =M4+1 -> 2032 | O4: =N4+1 -> 2033 | ... AF4: =AE4+1 -> 2050
A5: INCOME STATEMENT | B5: 1 | C5: Growth | D5: ='Fin. Data'!D6 -> 0.023888844 | E5: =+E6/D6-1 -> 0.071638305 | F5: =+F6/E6-1 -> 0.053868777 | G5: =Assumptions!D39 -> 0.05 | H5: =Assumptions!E39 -> 0.045 | I5: =Assumptions!F39 -> 0.04 | J5: =Assumptions!G39 -> 0.04 | K5: =Assumptions!H39 -> 0.03 | L5: =Assumptions!I39 -> 0.03 | M5: =Assumptions!J39 -> 0.03 | N5: =Assumptions!K39 -> 0.03 | ... AE5: =Assumptions!AB39 -> 0.03 | AF5: =Assumptions!AD39 -> 0.03
B6: 2 | C6: Revenues/Sales | D6: =Inputs!D6 -> 8820.7 | E6: =Inputs!C6 -> 9452.6 | F6: =Inputs!B6 -> 9961.8 | G6: =F6*(1+G5) -> 10459.89 | H6: =G6*(1+H5) -> 10930.585 | I6: =H6*(1+I5) -> 11367.808 | J6: =I6*(1+J5) -> 11822.521 | K6: =J6*(1+K5) -> 12177.196 | L6: =K6*(1+L5) -> 12542.512 | M6: =L6*(1+M5) -> 12918.788 | N6: =M6*(1+N5) -> 13306.351 | ... AF6: =AE6*(1+AF5) -> 22653.172
B7: 3 | C7: EBIT/Operating Margin | D7: =D8/D6 -> 0.2643441 | E7: =E8/E6 -> 0.30075323 | F7: =F8/F6 -> 0.31818547 | G7: =Assumptions!D40 -> 0.33 | H7: =Assumptions!E40 -> 0.33 | I7: =Assumptions!F40 -> 0.33 | J7: =Assumptions!G40 -> 0.33 | K7: =Assumptions!H40 -> 0.345 | L7: =Assumptions!I40 -> 0.345 | M7: =Assumptions!J40 -> 0.345 | N7: =Assumptions!K40 -> 0.345 | ... AE7: =Assumptions!AB40 -> 0.345 | AF7: =Assumptions!AD40 -> 0.345
B8: 4 | C8: EBIT | D8: ='Fin. Data'!D11 -> 2331.7 | E8: ='Fin. Data'!C11 -> 2842.9 | F8: ='Fin. Data'!B11 -> 3169.7 | G8: =G7*G6 -> 3451.7637 | H8: =H7*H6 -> 3607.0931 | I8: =I7*I6 -> 3751.3768 | J8: =J7*J6 -> 3901.4319 | K8: =K7*K6 -> 4201.1328 | L8: =L7*L6 -> 4327.1667 | M8: =M7*M6 -> 4456.9817 | N8: =N7*N6 -> 4590.6912 | ... AF8: =AF7*AF6 -> 7815.3445
B9: 5a | C9: (Dep) | D9: -218.1 | E9: -439.6 | F9: -341.2 | G9: =$D$53*DCF!F40 -> -479.7156 | H9: =$D$53*DCF!G40 -> -540.6156 | I9: =$D$53*DCF!H40 -> -604.88744 | J9: =$D$53*DCF!I40 -> -671.73015 | K9: =$E$53*DCF!J40 -> -705.94912 | L9: =$E$53*DCF!K40 -> -769.27054 | M9: =$E$53*DCF!L40 -> -834.49161 | N9: =$E$53*DCF!M40 -> -901.6693 | O9: =$E$53*DCF!N40 -> -970.86233 | P9: =$E$53*DCF!O40 -> -1042.1311 | Q9: =$E$53*DCF!P40 -> -1115.538 | R9: =$E$53*DCF!Q40 -> -1191.1471 | ... AF9: =$E$53*DCF!AE40 -> -2521.785 | AG9: =SUM(D9:AF9) -> -36845.432
B10: 5b | C10: (Amort) | D10: -5.1 | E10: =-3.2 -> -3.2 | F10: -1.3 | G10: =F38*$D$54 -> -1.36585 | H10: =G38*$D$54 -> -1.3665329 | I10: =H38*$D$54 -> -1.3672162 | J10: =I38*$D$54 -> -1.3678998 | K10: =J38*$E$54 -> -2.189734 | L10: =K38*$E$54 -> -2.1914858 | M10: =L38*$E$54 -> -2.193239 | N10: =M38*$E$54 -> -2.1949936 | O10: =N38*$E$54 -> -2.1967496 | P10: =O38*$E$54 -> -2.198507 | Q10: =P38*$E$54 -> -2.2002658 | R10: =Q38*$E$54 -> -2.202026 | ... AF10: =AE38*$E$54 -> -2.2268173
B11: 5c | C11: (Stock based compensation) | D11: -44.9 | E11: -68.5 | F11: -63.6 | G11: =G6*$D$55 -> -83.67912 | H11: =H6*$D$55 -> -87.44468 | I11: =I6*$D$55 -> -90.942468 | J11: =J6*$D$55 -> -94.580166 | K11: =K6*$D$55 -> -97.417571 | L11: =L6*$D$55 -> -100.3401 | M11: =M6*$D$55 -> -103.3503 | N11: =N6*$D$55 -> -106.45081 | ... AF11: =AF6*$D$55 -> -181.22538
B12: 6 | C12: EBITDA | D12: =D8-D9-D10 -> 2554.9 | E12: =E8-E9-E10 -> 3285.7 | F12: =F8-F9-F10 -> 3512.2 | G12: =G8-G9-G10 -> 3932.8452 | H12: =H8-H9-H10 -> 4149.0752 | I12: =I8-I9-I10 -> 4357.6314 | J12: =J8-J9-J10 -> 4574.5299 | K12: =K8-K9-K10 -> 4909.2716 | ... AF12: =AF8-AF9-AF10 -> 10339.356
B13: 7 | C13: (Net financing cost) | D13: ='Fin. Data'!D14 -> -356.4 | E13: ='Fin. Data'!C14 -> -398.7 | F13: ='Fin. Data'!B14 -> -435.4 | G13: =F43*$D$58-F44*$D$57 -> -377.262 | H13: =G43*$D$58-G44*$D$57 -> -360.783 | I13: =H43*$D$58-H44*$D$57 -> -339.918 | J13: =I43*$D$58-I44*$D$57 -> -321.969 | K13: =J43*$E$58-J44*$E$57 -> -346.32675 | L13: =K43*$E$58-K44*$E$57 -> -350.12075 | M13: =L43*$E$58-L44*$E$57 -> -369.50725 | N13: =M43*$E$58-M44*$E$57 -> -384.55725 | O13: =N43*$E$58-N44*$E$57 -> -402.38975 | P13: =O43*$E$58-O44*$E$57 -> -399.08575 | Q13: =P43*$E$58-P44*$E$57 -> -408.16125 | R13: =Q43*$E$58-Q44*$E$57 -> -427.41125 | ... AF13: =AE43*$E$58-AE44*$E$57 -> -410.57975
B14: 8 | C14: Other income/(cost) | D14: ='Fin. Data'!D15 -> -1664.9 | E14: ='Fin. Data'!C15 -> -2060.6 | F14: ='Fin. Data'!B15 -> -512.5 | G14: -1600 | H14: =AVERAGE(F14)*(1+H5)*1.2 -> -642.675 | I14: =AVERAGE(F14,H14)*(1+I5)*1.2 -> -720.8292 | J14: =AVERAGE(F14,H14:I14)*(1+J5)*1.2 -> -780.41775 | K14: =AVERAGE(H14:J14)*(1+K5) -> -736.07987 | L14: =AVERAGE(I14:K14)*(1+L5) -> -768.14887 | M14: =AVERAGE(J14:L14)*(1+M5) -> -784.39529 | N14: =AVERAGE(K14:M14)*(1+N5) -> -785.76092 | O14: =AVERAGE(L14:N14)*(1+O5) -> -802.81808 | P14: =AVERAGE(M14:O14)*(1+P5) -> -814.72117 | Q14: =AVERAGE(N14:P14)*(1+Q5) -> -825.13306 | R14: =AVERAGE(O14:Q14)*(1+R5) -> -838.65083 | ... AF14: =AVERAGE(AC14:AE14)*(1+AF5) -> -1031.5879
B15: 9 | C15: Earnings before taxes | D15: =D8+D13+D14 -> 310.4 | E15: =E8+E13+E14 -> 383.6 | F15: =F8+F13+F14 -> 2221.8 | G15: =G8+G13+G14 -> 1474.5017 | H15: =H8+H13+H14 -> 2603.6351 | I15: =I8+I13+I14 -> 2690.6296 | J15: =J8+J13+J14 -> 2799.0451 | K15: =K8+K13+K14 -> 3118.7261 | ... AF15: =AF8+AF13+AF14 -> 6373.1768
B16: 10 | C16: (Income tax) | D16: ='Fin. Data'!D21 -> -309.4 | E16: ='Fin. Data'!C21 -> -422.1 | F16: ='Fin. Data'!B21 -> -456.6 | G16: =-11%*G15 -> -162.19519 | H16: =-$D$56*H15 -> -520.72701 | I16: =-$D$56*I15 -> -538.12592 | J16: =-$D$56*J15 -> -559.80902 | K16: =-$E$56*K15 -> -623.74523 | L16: =-$E$56*L15 -> -641.77942 | M16: =-$E$56*M15 -> -660.61584 | N16: =-$E$56*N15 -> -684.07461 | O16: =-$E$56*O15 -> -704.64082 | P16: =-$E$56*P15 -> -731.29147 | Q16: =-$E$56*Q15 -> -756.61558 | R16: =-$E$56*R15 -> -780.16026 | ... AF16: =-$E$56*AF15 -> -1274.6354
B17: 11 | C17: Net income | D17: ='Fin. Data'!D23 -> 1 | E17: ='Fin. Data'!C23 -> -38.5 | F17: ='Fin. Data'!B23 -> 1765.2 | G17: =G16+G15 -> 1312.3065 | H17: =H16+H15 -> 2082.9081 | I17: =I16+I15 -> 2152.5037 | J17: =J16+J15 -> 2239.2361 | K17: =K16+K15 -> 2494.9809 | L17: =L16+L15 -> 2567.1177 | M17: =M16+M15 -> 2642.4634 | N17: =N16+N15 -> 2736.2984 | ... AF17: =AF16+AF15 -> 5098.5414
A19: CASH FLOW STATEMENT | B19: 12 | C19: Operating cash flows before WK | D19: =Inputs!D59-DCF!D20-DCF!D21 -> 1901.3 | E19: =Inputs!C59-DCF!E20-DCF!E21 -> 1894.8 | F19: =Inputs!B59-DCF!F20-DCF!F21 -> 2364.9 | G19: =G17-G10-G9-G11 -> 1877.0671 | H19: =H17-H10-H9-H11 -> 2712.3349 | I19: =I17-I10-I9-I11 -> 2849.7008 | J19: =J17-J10-J9-J11 -> 3006.9143 | K19: =K17-K10-K9-K11 -> 3300.5373 | L19: =L17-L10-L9-L11 -> 3438.9198 | M19: =M17-M10-M9-M11 -> 3582.4985 | N19: =N17-N10-N9-N11 -> 3746.6135 | ... AF19: =AF17-AF10-AF9-AF11 -> 7803.7786
B20: 13 | C20: (Stock-based compensation) | D20: -44.9 | E20: -63.6 | F20: -68.5 | G20: =G11 -> -83.67912 | H20: =H11 -> -87.44468 | I20: =I11 -> -90.942468 | J20: =J11 -> -94.580166 | K20: =K11 -> -97.417571 | L20: =L11 -> -100.3401 | M20: =M11 -> -103.3503 | N20: =N11 -> -106.45081 | ... AF20: =AF11 -> -181.22538
B21: 14 | C21: (Working Capital Flows) | D21: =Inputs!D62 -> 849 | E21: =Inputs!C62 -> 925.7 | F21: =Inputs!B62 -> 483.6 | G21: =D60*(G6-F6) -> 597.708 | H21: =$D$60*(H6-G6) -> 564.83406 | I21: =$D$60*(I6-H6) -> 524.66808 | J21: =$D$60*(J6-I6) -> 545.65481 | K21: =$E$60*(K6-J6) -> 638.41612 | L21: =$E$60*(L6-K6) -> 657.56861 | M21: =$E$60*(M6-L6) -> 677.29566 | N21: =$E$60*(N6-M6) -> 697.61453 | O21: =$E$60*(O6-N6) -> 718.54297 | P21: =$E$60*(P6-O6) -> 740.09926 | Q21: =$E$60*(Q6-P6) -> 762.30224 | R21: =$E$60*(R6-Q6) -> 785.1713 | ... AF21: =$E$60*(AF6-AE6) -> 1187.642
B22: 15 | C22: -Total Operating Cash Flow | D22: =D19+D20+D21 -> 2705.4 | E22: =E19+E20+E21 -> 2756.9 | F22: =F19+F20+F21 -> 2780 | G22: =G19+G20+G21 -> 2391.096 | H22: =H19+H20+H21 -> 3189.7242 | I22: =I19+I20+I21 -> 3283.4264 | J22: =J19+J20+J21 -> 3457.989 | K22: =K19+K20+K21 -> 3841.5359 | ... AF22: =AF19+AF20+AF21 -> 8810.1953
B23: 16 | C23: (CAPEX) | D23: ='Fin. Data'!D32 -> -1022.7 | E23: ='Fin. Data'!C32 -> -1028.7 | F23: ='Fin. Data'!B32 -> -1269.1 | G23: -1450 | H23: =H6*$D$62 -> -1530.2819 | I23: =I6*$D$62 -> -1591.4932 | J23: =J6*$D$62 -> -1655.1529 | K23: =K6*$E$62 -> -1583.0355 | L23: =L6*$E$62 -> -1630.5266 | M23: =M6*$E$62 -> -1679.4424 | N23: =N6*$E$62 -> -1729.8257 | O23: =O6*$E$62 -> -1781.7204 | P23: =P6*$E$62 -> -1835.1721 | Q23: =Q6*$E$62 -> -1890.2272 | R23: =R6*$E$62 -> -1946.934 | ... AF23: =AF6*$E$62 -> -2944.9124 | AG23: =SUM(D23:AF23) -> -57888.236
B24: 17 | C24: Adq | D24: =Inputs!E66 -> 757.2 | E24: ='Fin. Data'!C33 -> 28.8 | F24: ='Fin. Data'!B33 -> 47.8 | G24: =G6*$D$63 -> 52.29945 | H24: =H6*$D$63 -> 54.652925 | I24: =I6*$D$63 -> 56.839042 | J24: =J6*$D$63 -> 59.112604 | K24: =K6*$E$63 -> -365.31589 | L24: =L6*$E$63 -> -376.27537 | M24: =M6*$E$63 -> -387.56363 | N24: =N6*$E$63 -> -399.19054 | O24: =O6*$E$63 -> -411.16626 | P24: =P6*$E$63 -> -423.50124 | Q24: =Q6*$E$63 -> -436.20628 | R24: =R6*$E$63 -> -449.29247 | ... AF24: =AF6*$E$63 -> -679.59517 | AH24: =AG9-AG23 -> 21042.805
B25: 18 | C25: (Other investing flows) | D25: =Inputs!D67 -> -2 | E25: =Inputs!C67 -> 0.5 | F25: =Inputs!B67 -> -64.6 | G25: =(1+G5)*AVERAGE(D25:F25) -> -23.135 | H25: =(1+H5)*AVERAGE(E25:G25) -> -30.386858 | I25: =(1+I5)*AVERAGE(F25:H25) -> -40.948911 | J25: =(1+J5)*AVERAGE(G25:I25) -> -32.749867 | K25: =(1+K5)*AVERAGE(H25:J25) -> -35.736068 | L25: =(1+L5)*AVERAGE(I25:K25) -> -37.57263 | M25: =(1+M5)*AVERAGE(J25:L25) -> -36.413441 | N25: =(1+N5)*AVERAGE(K25:M25) -> -37.671268 | ... AF25: =(1+AF5)*AVERAGE(AC25:AE25) -> -49.096977
B26: 19 | C26: -Total Investing Flows | D26: =D23+D24+D25 -> -267.5 | E26: =E23+E24+E25 -> -999.4 | F26: =F23+F24+F25 -> -1285.9 | G26: =G23+G24+G25 -> -1420.8356 | H26: =H23+H24+H25 -> -1506.0158 | I26: =I23+I24+I25 -> -1575.6031 | J26: =J23+J24+J25 -> -1628.7902 | K26: =K23+K24+K25 -> -1984.0875 | ... AF26: =AF23+AF24+AF25 -> -3673.6046
B27: 20 | C27: (Flows related to leases) | D27: =Inputs!D71+Inputs!D72 -> -5.9 | E27: =Inputs!C71+Inputs!C72 -> -8.8 | F27: =Inputs!B71+Inputs!B72 -> -9.7 | G27: =G6*$D$66 -> -10.45989 | H27: =H6*$D$66 -> -10.930585 | I27: =I6*$D$66 -> -11.367808 | J27: =J6*$D$66 -> -11.822521 | K27: =$E$66*K6 -> -12.177196 | L27: =$E$66*L6 -> -12.542512 | M27: =$E$66*M6 -> -12.918788 | N27: =$E$66*N6 -> -13.306351 | O27: =$E$66*O6 -> -13.705542 | P27: =$E$66*P6 -> -14.116708 | Q27: =$E$66*Q6 -> -14.540209 | R27: =$E$66*R6 -> -14.976416 | ... AF27: =$E$66*AF6 -> -22.653172
B28: 21 | C28: Flows related to debt | D28: =+SUM(Inputs!D69:D70) -> -727.3 | E28: =+SUM(Inputs!C69:C70) -> 306.7 | F28: =+SUM(Inputs!B69:B70) -> -596.9 | G28: =G44-F44 -> -549.3 | H28: =H44-G44 -> -695.5 | I28: =I44-H44 -> -598.3 | J28: =J44-I44 -> -837.25 | K28: =K44-J44 -> 108.4 | L28: =L44-K44 -> 553.9 | M28: =M44-L44 -> 430 | N28: =N44-M44 -> 509.5 | ... AF28: =AF44-AE44 -> -350
B29: 22 | C29: (Repurchases)/Issuance of stock | D29: ='Fin. Data'!D28 -> -1390.5 | E29: ='Fin. Data'!C28 -> -1700.2 | F29: ='Fin. Data'!B28 -> -249.7 | G29: =-G17*$D$65 -> -183.72291 | H29: =-H17*$D$65 -> -291.60713 | I29: =-I17*$D$65 -> -301.35051 | J29: =-J17*$D$65 -> -313.49305 | K29: =-K17*$E$65 -> -1247.4905 | L29: =-L17*$E$65 -> -1283.5588 | M29: =-M17*$E$65 -> -1321.2317 | N29: =-N17*$E$65 -> -1368.1492 | O29: =-O17*$E$65 -> -1409.2816 | P29: =-P17*$E$65 -> -1462.5829 | Q29: =-Q17*$E$65 -> -1513.2312 | R29: =-R17*$E$65 -> -1560.3205 | ... AF29: =-AF17*$E$65 -> -2549.2707
B30: 23 | C30: (Dividends) | D30: ='Fin. Data'!D27 -> -573 | E30: ='Fin. Data'!C27 -> -587.7 | F30: ='Fin. Data'!B27 -> -653.8 | G30: =$D$64*G17 -> -524.92261 | H30: =$D$64*H17 -> -833.16322 | I30: =$D$64*I17 -> -861.00147 | J30: =$D$64*J17 -> -895.69444 | K30: =$E$64*K17 -> -1247.4905 | L30: =$E$64*L17 -> -1283.5588 | M30: =$E$64*M17 -> -1321.2317 | N30: =$E$64*N17 -> -1368.1492 | O30: =$E$64*O17 -> -1409.2816 | P30: =$E$64*P17 -> -1462.5829 | Q30: =$E$64*Q17 -> -1513.2312 | R30: =$E$64*R17 -> -1560.3205 | ... AF30: =$E$64*AF17 -> -2549.2707
B31: 24 | C31: Other financing flows | D31: =Inputs!D75 -> 767.2 | E31: =Inputs!C75 -> 170.1 | F31: =Inputs!B75 -> 35.5 | G31: =(1+G5)*AVERAGE(D31:F31) -> 340.48 | H31: =(1+H5)*AVERAGE(E31:G31) -> 190.21787 | I31: =(1+I5)*AVERAGE(F31:H31) -> 196.28193 | J31: =(1+J5)*AVERAGE(G31:I31) -> 252.01966 | K31: =(1+K5)*AVERAGE(H31:J31) -> 219.22501 | L31: =(1+L5)*AVERAGE(I31:K31) -> 229.18413 | M31: =(1+M5)*AVERAGE(J31:L31) -> 240.48056 | N31: =(1+N5)*AVERAGE(K31:M31) -> 236.5188 | ... AF31: =(1+AF5)*AVERAGE(AC31:AE31) -> 311.98955
B32: 25 | C32: -Total Financing flows | D32: =D27+D28+D29+D30+D31 -> -1929.5 | E32: =E27+E28+E29+E30+E31 -> -1819.9 | F32: =F27+F28+F29+F30+F31 -> -1474.6 | G32: =G27+G28+G29+G30+G31 -> -927.92541 | H32: =H27+H28+H29+H30+H31 -> -1640.9831 | I32: =I27+I28+I29+I30+I31 -> -1575.7379 | J32: =J27+J28+J29+J30+J31 -> -1806.2403 | K32: =K27+K28+K29+K30+K31 -> -2179.5331 | ... AF32: =AF27+AF28+AF29+AF30+AF31 -> -5159.2051
A34: SUMMARY | B34: 26 | C34: Cash before shareholder returns | D34: =D22+D26+D27+D28+D31 -> 2471.9 | E34: =E22+E26+E27+E28+E31 -> 2225.5 | F34: =F22+F26+F27+F28+F31 -> 923 | G34: =G22+G26+G27+G28+G31 -> 750.98052 | H34: =H22+H26+H27+H28+H31 -> 1167.4957 | I34: =I22+I26+I27+I28+I31 -> 1294.4375 | J34: =J22+J26+J27+J28+J31 -> 1232.1459 | K34: =K22+K26+K27+K28+K31 -> 2172.8962 | ... AF34: =AF22+AF26+AF27+AF28+AF31 -> 5075.9271
B35: 27 | C35: Returns to shareholders | D35: =-1*(D29+D30) -> 1963.5 | E35: =-1*(E29+E30) -> 2287.9 | F35: =-1*(F29+F30) -> 903.5 | G35: =-1*(G29+G30) -> 708.64552 | H35: =-1*(H29+H30) -> 1124.7703 | I35: =-1*(I29+I30) -> 1162.352 | J35: =-1*(J29+J30) -> 1209.1875 | K35: =-1*(K29+K30) -> 2494.9809 | ... AF35: =-1*(AF29+AF30) -> 5098.5414
B36: 28 | C36: Excess cash acumulation | D36: =D34-D35 -> 508.4 | E36: =E34-E35 -> -62.4 | F36: =F34-F35 -> 19.5 | G36: =G34-G35 -> 42.335006 | H36: =H34-H35 -> 42.725339 | I36: =I34-I35 -> 132.08549 | J36: =J34-J35 -> 22.958429 | K36: =K34-K35 -> -322.0847 | ... AF36: =AF34-AF35 -> -22.614366
A38: BALANCE SHEET | B38: 29 | C38: Intangible assets | D38: 2755.2 | E38: 2728.1 | F38: 2731.7 | G38: =+F38+(-G10) -> 2733.0658 | H38: =+G38+(-H10) -> 2734.4324 | I38: =+H38+(-I10) -> 2735.7996 | J38: =+I38+(-J10) -> 2737.1675 | K38: =+J38+(-K10) -> 2739.3572 | L38: =+K38+(-L10) -> 2741.5487 | M38: =+L38+(-M10) -> 2743.742 | N38: =+M38+(-N10) -> 2745.937 | ... AF38: =+AE38+(-AF10) -> 2785.7485 | AG38: =SUM(G38:AF38) -> 71715.268
B39: 30 | C39: Accumulated amortization | D39: 86.3 | E39: 88.8 | F39: 89.6 | G39: =F39-G10 -> 90.96585 | H39: =G39-H10 -> 92.332383 | I39: =H39-I10 -> 93.699599 | J39: =I39-J10 -> 95.067499 | K39: =J39-K10 -> 97.257233 | L39: =K39-L10 -> 99.448719 | M39: =L39-M10 -> 101.64196 | N39: =M39-N10 -> 103.83695 | ... AF39: =AE39-AF10 -> 143.64848 | AG39: =SUM(G39:AF39) -> 3020.6679
B40: 31 | C40: PPE+Right of use Assets | D40: =Assumptions!AC19 -> 8512.6 | E40: =Assumptions!AB19 -> 9726.5 | F40: =Assumptions!AA19 -> 11421.8 | G40: =F40+(-G23) -> 12871.8 | H40: =G40+(-H23) -> 14402.082 | I40: =H40+(-I23) -> 15993.575 | J40: =I40+(-J23) -> 17648.728 | K40: =J40+(-K23) -> 19231.764 | L40: =K40+(-L23) -> 20862.29 | M40: =L40+(-M23) -> 22541.733 | N40: =M40+(-N23) -> 24271.558 | ... AF40: =AE40+(-AF23) -> 65989.536 | AG40: =SUM(G40:AF40) -> 947996.56
B41: 32 | C41: Accumulated depreciation | D41: =Assumptions!AC16 -> 1952.3 | E41: =Assumptions!AB16 -> 2391.9 | F41: =Assumptions!AA16 -> 2733.1 | G41: =F41-G9 -> 3212.8156 | H41: =G41-H9 -> 3753.4312 | I41: =H41-I9 -> 4358.3186 | J41: =I41-J9 -> 5030.0488 | K41: =J41-K9 -> 5735.9979 | L41: =K41-L9 -> 6505.2685 | M41: =L41-M9 -> 7339.7601 | N41: =M41-N9 -> 8241.4294 | ... AF41: =AE41-AF9 -> 38579.632 | AG41: =SUM(G41:AF41) -> 436687.98
A43: CASH & DEBT & DISCOUNTING | B43: 33 | C43: Ending cash balance | D43: ='Fin. Data'!D39 -> 199.4 | E43: =E36+D43 -> 137 | F43: =F36+E43 -> 156.5 | G43: =G36+F43 -> 198.83501 | H43: =H36+G43 -> 241.56034 | I43: =I36+H43 -> 373.64584 | J43: =J36+I43 -> 396.60427 | K43: =K36+J43 -> 74.519567 | L43: =L36+K43 -> 229.71722 | ... AF43: =AF36+AE43 -> 70.293292
B44: 34 | C44: Total Debt | D44: ='Fin. Data'!D58 -> 10974.1 | E44: ='Fin. Data'!C58 -> 12996.7 | F44: ='Fin. Data'!B58 -> 12575.4 | G44: =Assumptions!C84 -> 12026.1 | H44: =Assumptions!D84 -> 11330.6 | I44: =Assumptions!E84 -> 10732.3 | J44: =Assumptions!F84 -> 9895.05 | K44: =Assumptions!G84 -> 10003.45 | L44: =Assumptions!H84 -> 10557.35 | M44: =Assumptions!I84 -> 10987.35 | N44: =Assumptions!J84 -> 11496.85 | ... AF44: =Assumptions!AB84 -> 11380.85
B45: 35 | C45: Discount factor | F45: =1/((1+$F$50)^G50) -> 1 | G45: =1/((1+$F$50)^G49) -> 0.91954023 | H45: =1/((1+$F$50)^H49) -> 0.84555423 | I45: =1/((1+$F$50)^I49) -> 0.77752114 | J45: =1/((1+$F$50)^J49) -> 0.71496196 | K45: =1/((1+$F$50)^K49) -> 0.65743629 | L45: =1/((1+$F$50)^L49) -> 0.60453912 | M45: =1/((1+$F$50)^M49) -> 0.55589804 | N45: =1/((1+$F$50)^N49) -> 0.51117061 | ... AF45: =1/((1+$F$50)^AF49) -> 0.11293774
...

Sheet Assumptions
B2: Assumptions
B4: Prospects: | C4: =HYPERLINK("#Assumptions!DA1035","Guidance") -> Guidance
B6: Links: | C6: https://www.cbrands.com/blogs/news/constellation-brands-updates-fiscal-2025-outlook
C8: 2024 | D8: =C8-1 -> 2023 | E8: =D8-1 -> 2022 | F8: =E8-1 -> 2021 | G8: =F8-1 -> 2020 | H8: =G8-1 -> 2019 | I8: =H8-1 -> 2018 | J8: =I8-1 -> 2017 | K8: =J8-1 -> 2016 | ... M8: =L8-1 -> 2014 | O8: 10Y Average | P8: 5Y Average | Q8: 3Y Average | S8: Short Term Forecast | T8: Long Term Forecast
B9: Revenue growth | C9: =(Inputs!C6-Inputs!D6)/Inputs!D6 -> 0.071638305 | D9: =(Inputs!D6-Inputs!E6)/Inputs!E6 -> 0.023888844 | E9: =(Inputs!E6-Inputs!F6)/Inputs!F6 -> 0.032528315 | F9: =(Inputs!F6-Inputs!G6)/Inputs!G6 -> 0.02803105 | G9: =(Inputs!G6-Inputs!H6)/Inputs!H6 -> 0.070006592 | H9: =(Inputs!H6-Inputs!I6)/Inputs!I6 -> 0.034576826 | I9: =(Inputs!I6-Inputs!J6)/Inputs!J6 -> 0.11958646 | J9: =(Inputs!J6-Inputs!K6)/Inputs!K6 -> 0.086330458 | ... M9: =(Inputs!M6-Inputs!N6)/Inputs!N6 -> 0.053422748 | O9: =AVERAGE(C9:M9) -> 0.1362969 | P9: =AVERAGE(C9:G9) -> 0.045218621 | Q9: =AVERAGE(C9:E9) -> 0.042685155 | S9: 0.04 | T9: 0.03
B10: Operating Margin | C10: =Inputs!C8/Inputs!C6 -> 0.30075323 | D10: =Inputs!D8/Inputs!D6 -> 0.2643441 | E10: =Inputs!E8/Inputs!E6 -> 0.32398519 | F10: =Inputs!F8/Inputs!F6 -> 0.25822497 | G10: =Inputs!G8/Inputs!G6 -> 0.29721538 | H10: =Inputs!H8/Inputs!H6 -> 0.30118655 | I10: =Inputs!I8/Inputs!I6 -> 0.32727273 | J10: =Inputs!J8/Inputs!J6 -> 0.26954676 | ... M10: =Inputs!M8/Inputs!M6 -> 0.18701048 | O10: =AVERAGE(C10:M10) -> 0.26744333 | P10: =AVERAGE(C10:G10) -> 0.28890457 | Q10: =AVERAGE(C10:E10) -> 0.29636084 | S10: 0.33 | T10: 0.345
B13: Modelling Factors
C15: Last 10 Years | Z15: Values in M. | AA15: 2024 | AB15: =AA15-1 -> 2023 | AC15: =AB15-1 -> 2022 | AD15: =AC15-1 -> 2021 | AE15: =AD15-1 -> 2020 | AF15: =AE15-1 -> 2019 | AG15: =AF15-1 -> 2018 | AH15: =AG15-1 -> 2017 | AI15: =AH15-1 -> 2016 | ... AK15: =AJ15-1 -> 2014 | AL15: 2013
C16: =C8 -> 2024 | D16: =D8 -> 2023 | E16: =E8 -> 2022 | F16: =F8 -> 2021 | G16: =G8 -> 2020 | H16: =H8 -> 2019 | I16: =I8 -> 2018 | J16: =J8 -> 2017 | ... M16: =M8 -> 2014 | O16: =O8 -> 10Y Average | P16: =P8 -> 5Y Average | Q16: =Q8 -> 3Y Average | S16: Short Term Forecast | T16: Long Term Forecast | V16: Reference | Z16: Accumulated Depreciation | AA16: 2733.1 | AB16: 2391.9 | AC16: 1952.3 | AD16: 1734.2 | AE16: 1458.2 | AF16: 1705.2 | AG16: 1484 | AH16: 1277 | AI16: 1179.3 | AJ16: 1050.2 | AK16: 924.7
B17: Depreciation factor | C17: =AA29/AA24 -> 0.039663339 | D17: =AB29/AB24 -> 0.041460068 | E17: =AC29/AC24 -> 0.042099876 | F17: =AD29/AD24 -> 0.038884036 | G17: =AE29/AE24 -> 0.048076923 | H17: =AF29/AF24 -> 0.047773395 | I17: =AG29/AG24 -> 0.046830419 | J17: =AH29/AH24 -> 0.045587163 | ... M17: =AK29/AK24 -> 0.0475672 | O17: =AVERAGE(C17:M17) -> 0.043755183 | P17: =AVERAGE(C17:G17) -> 0.042036849 | Q17: =AVERAGE(C17:E17) -> 0.041074428 | S17: 0.042 | T17: 0.04 | V17: % PPE | Z17: Accumulated Amortization | AA17: =AA18-AA26 -> 89.6 | AB17: =AB18-AB26 -> 88.8 | AC17: =AC18-AC26 -> 86.3 | AD17: =AD18-AD26 -> 81.8 | AE17: =AE18-AE26 -> 75.5 | AF17: =AF18-AF26 -> 70.4 | AG17: =AG18-AG26 -> 64.5 | AH17: =AH18-AH26 -> 58.7 | ... AK17: =AK18-AK26 -> 186.6
B18: Amortization factor | C18: =AA30/AA18 -> 0.00046078049 | D18: =AB30/AB18 -> 0.0011360006 | E18: =AC30/AC18 -> 0.0017948267 | F18: =AD30/AD18 -> 0.0018835069 | G18: =AE30/AE18 -> 0.0020397939 | H18: =AF30/AF18 -> 0.0018357045 | I18: =AG30/AG18 -> 0.0017511056 | J18: =AH30/AH18 -> 0.003026423 | ... M18: =AK30/AK18 -> 0.0045352137 | O18: =AVERAGE(C18:M18) -> 0.0038388968 | P18: =AVERAGE(C18:G18) -> 0.0014629817 | Q18: =AVERAGE(C18:E18) -> 0.0011305359 | S18: 0.0005 | T18: 0.0008 | V18: % IA | Z18: Intangible Assets (Gross) | AA18: =2715.2+106.1 -> 2821.3 | AB18: =2710.4+106.5 -> 2816.9 | AC18: =108+2733.5 -> 2841.5 | AD18: =108.3+2705.6 -> 2813.9 | AE18: =107.6+2686.8 -> 2794.4 | AF18: =110.4+3158.1 -> 3268.5 | AG18: =110.1+3259.2 -> 3369.3 | AH18: =109+3327.4 -> 3436.4 | AI18: =193.1+3337.9 -> 3531 | AJ18: =190.2+3078.3 -> 3268.5 | AK18: =186.6+3231.1 -> 3417.7
B19: Stock-based comp | C19: =AA20/Inputs!B6 -> 0.0063843884 | D19: =AB20/Inputs!C6 -> 0.0072466835 | E19: =AC20/Inputs!D6 -> 0.005090299 | F19: =AD20/Inputs!E6 -> 0.0073129114 | G19: =AE20/Inputs!F6 -> 0.0072391682 | H19: =AF20/Inputs!G6 -> 0.0078979793 | I19: =AG20/Inputs!H6 -> 0.0080290046 | J19: =AH20/Inputs!I6 -> 0.007651913 | ... M19: =AK20/Inputs!L6 -> 0.010251248 | O19: =AVERAGE(C19:M19) -> 0.007679452 | P19: =AVERAGE(C19:G19) -> 0.0066546901 | Q19: =AVERAGE(C19:E19) -> 0.0062404569 | S19: 0.008 | T19: 0.01 | V19: % Revenue | Z19: PPE+ROA | AA19: =AA24+AA25 -> 11421.8 | AB19: =AB24+AB25 -> 9726.5 | AC19: =AC24+AC25 -> 8512.6 | AD19: =AD24+AD25 -> 8050.7 | AE19: =AE24+AE25 -> 7299.2 | AF19: =AF24+AF25 -> 6972.5 | AG19: =AG24+AG25 -> 6273.7 | AH19: =AH24+AH25 -> 5209.8 | ... AK19: =AK24+AK25 -> 2939
B20: Tax Rate | C20: ='Fin. Data'!B21/('Fin. Data'!B21-'Fin. Data'!B23) -> 0.20550905 | D20: ='Fin. Data'!C21/('Fin. Data'!C21-'Fin. Data'!C23) -> 1.100365 | E20: ='Fin. Data'!D21/('Fin. Data'!D21-'Fin. Data'!D23) -> 0.99677835 | F20: ='Fin. Data'!E21/('Fin. Data'!E21-'Fin. Data'!E23) -> 0.20099099 | G20: ='Fin. Data'!F21/('Fin. Data'!F21-'Fin. Data'!F23) -> 1.0226407 | H20: ='Fin. Data'!G21/('Fin. Data'!G21-'Fin. Data'!G23) -> 0.16547648 | I20: ='Fin. Data'!H21/('Fin. Data'!H21-'Fin. Data'!H23) -> 0.005079609 | J20: ='Fin. Data'!I21/('Fin. Data'!I21-'Fin. Data'!I23) -> 0.26473679 | ... M20: ='Fin. Data'!L21/('Fin. Data'!L21-'Fin. Data'!L23) -> 0.11769514 | O20: =AVERAGE(C20:M20) -> 0.42398966 | P20: =AVERAGE(C20:G20) -> 0.70525681 | Q20: =AVERAGE(C20:E20) -> 0.76755079 | S20: 0.2 | T20: 0.2 | V20: % EBT | Z20: Stock Based Compensation | AA20: 63.6 | AB20: 68.5 | AC20: 44.9 | AD20: 63 | AE20: 60.4 | AF20: 64.1 | AG20: 60.9 | AH20: 56.1 | AI20: 54 | AJ20: 55 | AK20: 49.9
B21: Interest Rate on debt | C21: =AA21/AA23 -> 0.034623153 | D21: =AB21/AB23 -> 0.030677018 | E21: =AC21/AC23 -> 0.032476467 | F21: =AD21/AD23 -> 0.035070969 | G21: =AE21/AE23 -> 0.033572184 | H21: =AF21/AF23 -> 0.027841222 | I21: =AG21/AG23 -> 0.032817301 | J21: =AH21/AH23 -> 0.036273693 | ... M21: =AK21/AK23 -> 0.047520572 | O21: =AVERAGE(C21:M21) -> 0.036026287 | P21: =AVERAGE(C21:G21) -> 0.033283958 | Q21: =AVERAGE(C21:E21) -> 0.032592213 | S21: 0.03 | T21: 0.035 | V21: % Debt | Z21: Interest expenses | AA21: 435.4 | AB21: 398.7 | AC21: 356.4 | AD21: 385.7 | AE21: 428.7 | AF21: 379.1 | AG21: 334.3 | AH21: 335.1 | AI21: 314.7 | AJ21: 339.1 | AK21: 330.9
B22: Interest Rate on cash | C22: =AA22/Inputs!B28 -> 0 | D22: =AB22/Inputs!C28 -> 0 | E22: =AC22/Inputs!D28 -> 0 | F22: =AD22/Inputs!E28 -> 0 | G22: =AE22/Inputs!F28 -> 0 | H22: =AF22/Inputs!G28 -> 0.12820513 | I22: =AG22/Inputs!H28 -> 0.025470653 | J22: =AH22/Inputs!I28 -> 0.010146561 | ... M22: =AK22/Inputs!L28 -> 0.12050078 | O22: =AVERAGE(C22:M22) -> 0.027878709 | P22: =AVERAGE(C22:G22) -> 0 | Q22: =AVERAGE(C22:E22) -> 0 | S22: 0 | T22: 0 | V22: % Cash | Z22: Interest income | AA22: 0 | AB22: 0 | AC22: 0 | AD22: 0 | AE22: 0 | AF22: 12 | AG22: 2.3 | AH22: 1.8 | AI22: 0.8 | AJ22: 1.4 | AK22: 7.7
B23: PPE+ROA | C23: =Inputs!B33/Inputs!C33-1 -> 0.17333799 | D23: =Inputs!C33/Inputs!D33-1 -> 0.13294607 | E23: =Inputs!D33/Inputs!E33-1 -> 0.040882232 | F23: =Inputs!E33/Inputs!F33-1 -> 0.091618226 | G23: =Inputs!F33/Inputs!G33-1 -> 0.012473184 | H23: =Inputs!G33/Inputs!H33-1 -> 0.09971397 | I23: =Inputs!H33/Inputs!I33-1 -> 0.21788548 | J23: =Inputs!I33/Inputs!J33-1 -> 0.1798164 | ... M23: =Inputs!L33/Inputs!M33-1 -> 0.63897478 | O23: =AVERAGE(C23:M23) -> 0.19654486 | P23: =AVERAGE(C23:G23) -> 0.090251541 | Q23: =AVERAGE(C23:E23) -> 0.1157221 | S23: - - | T23: - - | V23: Growing with CAPEX | Z23: Total Debt | AA23: ='Fin. Data'!B58 -> 12575.4 | AB23: ='Fin. Data'!C58 -> 12996.7 | AC23: ='Fin. Data'!D58 -> 10974.1 | AD23: ='Fin. Data'!E58 -> 10997.7 | AE23: ='Fin. Data'!F58 -> 12769.5 | AF23: ='Fin. Data'!G58 -> 13616.5 | AG23: ='Fin. Data'!H58 -> 10186.7 | AH23: ='Fin. Data'!I58 -> 9238.1 | ... AK23: ='Fin. Data'!L58 -> 6963.3
