Workbook
Name Benchmark: [1]ControlsH!$B$3
Name BestConsOv: #REF!
Name BestConsOv: #REF!
Name Broker_Name: OFFSET(#REF!,0,0,[1]ControlsH!$E$5, 1)
Name Broker_Name: OFFSET(#REF!,0,0,[1]ControlsH!$E$5, 1)
Name calCODE: [1]ControlsH!$C$4
Name Chart_Benchmark_100_Size: OFFSET(#REF!, 0, 0, [1]ControlsH!$E$3, 1)
Name Chart_Date_Size: OFFSET(#REF!, 0, 0, [1]ControlsH!$E$3, 1)
Name Chart_Date_Size: OFFSET(#REF!, 0, 0, [1]ControlsH!$E$3, 1)
Name Chart_Date_VAL1_Size: OFFSET(#REF!, 0, 0, [1]ControlsH!$I$3, 1)
Name Chart_Date_VAL1_Size: OFFSET(#REF!, 0, 0, [1]ControlsH!$I$3, 1)
Name Chart_Date_VAL2_Size: OFFSET(#REF!, 0, 0, [1]ControlsH!$I$5, 1)
Name Chart_Date_VAL2_Size: OFFSET(#REF!, 0, 0, [1]ControlsH!$I$5, 1)
Name Chart_Peer_100_Size: OFFSET(#REF!, 0, 0, [1]ControlsH!$E$3, 1)
Name Chart_Peer_100_Size: OFFSET(#REF!, 0, 0, [1]ControlsH!$E$3, 1)
Name Chart_Price_100_Size: OFFSET(#REF!, 0, 0, [1]ControlsH!$E$3, 1)
Name Chart_Price_100_Size: OFFSET(#REF!, 0, 0, [1]ControlsH!$E$3, 1)
Name Chart_Price_Size: OFFSET(#REF!, 0, 0, [1]ControlsH!$E$3, 1)
Name Chart_Price_Size: OFFSET(#REF!, 0, 0, [1]ControlsH!$E$3, 1)
Name Chart_VAL1_FY1_Size: OFFSET(#REF!, 0, 0, [1]ControlsH!$F$3, 1)
Name Chart_VAL1_FY1_Size: OFFSET(#REF!, 0, 0, [1]ControlsH!$F$3, 1)
Name Chart_VAL1_FY2_Size: OFFSET(#REF!, 0, 0, [1]ControlsH!$G$3, 1)
Name Chart_VAL1_FY2_Size: OFFSET(#REF!, 0, 0, [1]ControlsH!$G$3, 1)
Name Chart_VAL1_FY3_Size: OFFSET(#REF!, 0, 0, [1]ControlsH!$H$3, 1)
Name Chart_VAL1_FY3_Size: OFFSET(#REF!, 0, 0, [1]ControlsH!$H$3, 1)
Name Chart_VAL2_FY1_Size: OFFSET(#REF!, 0, 0, [1]ControlsH!$F$5, 1)
Name Chart_VAL2_FY1_Size: OFFSET(#REF!, 0, 0, [1]ControlsH!$F$5, 1)
Name Chart_VAL2_FY2_Size: OFFSET(#REF!, 0, 0, [1]ControlsH!$G$5, 1)
Name Chart_VAL2_FY2_Size: OFFSET(#REF!, 0, 0, [1]ControlsH!$G$5, 1)
Name Chart_VAL2_FY3_Size: OFFSET(#REF!, 0, 0, [1]ControlsH!$H$5, 1)
Name Chart_VAL2_FY3_Size: OFFSET(#REF!, 0, 0, [1]ControlsH!$H$5, 1)
Name Chart_Volume_Size: OFFSET(#REF!, 0, 0, [1]ControlsH!$E$3, 1)
Name Chart_Volume_Size: OFFSET(#REF!, 0, 0, [1]ControlsH!$E$3, 1)
Name compNAME: [1]ControlsH!$B$6
Name CURRENCY: [1]ControlsH!$B$9
Name currPRICE: [1]Overview!$E$19
Name custBenchmark: [1]Overview!$C$9
Name custED: #REF!
Name custED: #REF!
Name custSD: #REF!
Name custSD: #REF!
Name dayCODE: [1]ControlsH!$C$5
Name ED: [1]ControlsH!$B$5
Name ESTBrokersItem: #REF!
Name ESTBrokersItem: #REF!
Name ESTBrokersPeriod: #REF!
Name ESTBrokersPeriod: #REF!
Name ESTDetailBroker: #REF!
Name ESTDetailBroker: #REF!
Name ESTDetailBroker2: #REF!
Name ESTDetailBroker2: #REF!
Name ESTDetailPeriod: #REF!
Name ESTDetailPeriod: #REF!
Name EstDetPerO: #REF!
Name EstDetPerO: #REF!
Name EstDetPerT: #REF!
Name EstDetPerT: #REF!
Name FinancialsPeriod: #REF!
Name FinancialsPeriod: #REF!
Name fundTICKER: [1]ControlsH!$B$15

Sheet OP
B2: (26/02/2025) | C2: Analista: LIS | D2: Annual Report 2024 | E2: {=_FV(N2,"Name")} -> Dassault Systemes SE | K2: Euronext Paris | L2: SIC: sí | N2: #VALUE!
D3: DESCRIPTION: Dassault Systèmes SE is a French company that provides software solutions for 3D design, simulation, data management, and product lifecycle management across various industries. Its key offerings include SOLIDWORKS, CATIA, SIMULIA, and the 3DEXPERIENCE platform
D4: CEO & BOARD: Pascal Daloz (CEO s.2024; 54;dir.s. 2020); Bernard Charlès (67; dir.s. 1993; Ex. Chairman of the Board of Directors, CEO from 1995 to 2022); Charles Edelstenne (86, , dir.s. 1993, Founder & Honorary Chairman); *Geneviève Berger(69, ,dir.s.2023, Indep. dir & Lead director of Sustainable Development); *Xavier Cauchois(66, , dir.s. 2018, Indep. dir); Catherine Dassault(56, ,dir.s. 2016, dir); *Laurence Daures(50, ,dir.s.2016, Indep. dir. & Lead indep. dir); *Odile Desforges(74, , dir.s.2013, indep. dir); *Soumitra Dutta(60, , dir.s.2017, indep. dir); Olivier Costa de Beauregard(65; , dir.) Anne-Laure Chevalier( , emp. repre); Christine Defert( emp.repre)
B5: Milliones de USD
B6: Acción | D6: Liquidez y Solvencia | F6: Regiones (2023) | I6: Rentabilidad (2024) | K6: Múltiplos
B7: Último Precio | C7: {=_FV(N2,"Previous close",TRUE)} -> 26.21 | D7: Activo: | E7: =Cifras_en_Millones!C45 -> 15545.9 | H7: %Vts; %Op.Mg.; Change | I7: Año termina: | J7: 31/12/2024 | K7: Float: | L7: 0.5104
B8: Outstanding Shares | C8: {=_FV(N2,"Shares outstanding",TRUE)} -> 1341456000 | D8: Pasivo: | E8: =Cifras_en_Millones!C57 -> 6465.2 | F8: =+Segments!B4 -> Americas | H8: =+Segments!F4 -> 0.39962687 | K8: Insiders Own: | L8: 0.4812
B9: Market Cap. | C9: =C7*C8/1000000 -> 35159.562 | D9: Cash/Precio | E9: =+C11/C8*1000000 -> 2.9464999 | F9: =+Segments!B5 -> Europe | H9: =+Segments!F5 -> 0.37817164 | I9: EBIT | J9: =Cifras_en_Millones!C11 -> 1359.6 | K9: b (Bloomberg; Yahoo) | L9: 0,82
B10: +Deuda Total | C10: =Cifras_en_Millones!C60 -> 2493.6 | D10: Ebidta/CIF | E10: =Cifras_en_Millones!C19/Cifras_en_Millones!C14 -> -6.7449324 | F10: =+Segments!B6 -> Asia | H10: =+Segments!F6 -> 0.22220149 | I10: +Dep&Amort | J10: =Cifras_en_Millones!C17 -> -561 | K10: Calificación (S&P) | L10: A
B11: -Cash | C11: =Cifras_en_Millones!C40 -> 3952.6 | D11: Deuda/Ebidta | E11: =Cifras_en_Millones!C60/Cifras_en_Millones!C19 -> 3.1224643 | I11: =EBIDTA | J11: =+J9+J10 -> 798.6 | K11: Precio/Valor en libros | L11: =((C7*C8)/1000000)/(E7-E8) -> 3.8718999
B12: =Enterprise Value | C12: =C9+C10-C11 -> 33700.562 | D12: "Otros activos"/Activo | E12: =Cifras_en_Millones!C44/Cifras_en_Millones!C45 -> 0.54654282 | I12: Utilidad Neta | J12: =Cifras_en_Millones!C23 -> 1198.1 | K12: FNP(p)/Activos | L12: =J18/E7 -> 0.042463501
B13: Tenencia % (nac/int'l) | D13: Deuda/Activo | E13: =Cifras_en_Millones!C60/Cifras_en_Millones!C45 -> 0.16040242 | F13: Productos (2023) | I13: UPA | J13: =+J12/C8*1000000 -> 0.89313403 | K13: Precio/Utilidad(p) | L13: =C9/J17 -> 31.276575
B14: t liq. (Pos prom./Vol.) | D14: Margen de Operación (p) | E14: =AVERAGE(Cifras_en_Millones!C12:E12) -> 0.21915431 | H14: %Vts; %Op.Mg.; Change | I14: ROA | J14: =+J12/E7 -> 0.077068552 | K14: EV/Activos | L14: =C12/E7 -> 2.1678103
B15: % Short | D15: Margen neto (p) | E15: =AVERAGE(Cifras_en_Millones!C24:E24) -> 0.17782473 | F15: =+Segments!B17 -> Industrial Innovation | H15: =+Segments!F17 -> 0.54253731 | I15: ROIC | J15: =J12/(E7-(E8-C10)) -> 0.10351382 | K15: EV/Ebidta (p) | L15: =C12/J16 -> 66.941459
B16: Semáforo ESG | D16: Ebidta/Ingresos(p) | E16: =AVERAGE(Cifras_en_Millones!C20:E20) -> 0.12490169 | F16: =+Segments!B18 -> Life Sciences | H16: =+Segments!F18 -> 0.21623134 | I16: Ebidta(p) | J16: =AVERAGE(Cifras_en_Millones!B19:D19) -> 503.43333 | K16: Precio/FNP (p) | L16: =C9/J18 -> 53.261303
B17: E | D17: CIF/Deuda Neta Promedio | E17: =Cifras_en_Millones!C14/AVERAGE(Cifras_en_Millones!C59:D59) -> 0.16601234 | F17: =+Segments!B19 -> Mainstream Innovation | H17: =+Segments!F19 -> 0.24123134 | I17: Utilidad Neta (p) | J17: =AVERAGE(Cifras_en_Millones!B23:D23) -> 1124.15 | K17: Bonos 1;5;40a (USD)
B18: S | I18: FNP (p) | J18: =SUM(F36:F37)/3 -> 660.13333 | K18: TDY(p)/Precio | L18: =SUM(E34:E36)/(3*C9) -> -0.010787013
B19: G | I19: Tax (p) últ. 5a | J19: =AVERAGE(Cifras_en_Millones!C22:G22) -> -0.22648854 | K19: Div. Yield: | L19: =-K33/C9 -> 0.0086093223
B20: Tese de Inversión
B21: The decision to sell is based on a negative DCF valuation, which sets a price target of $23.3, implying a -43% downside compared to the current share price of $37.98. While the software market has strong growth potential, risks related to geopolitical uncertainty, raw material price volatility, and a potential slowdown in demand add further concerns. It is also important to note that the valuation model used was the Dividend Discount Model, which only considers dividends paid and share buybacks, potentially undervaluing the company. If a valuation approach based on Free Cash Flow to the Firm had been used, the price target might have been higher, better reflecting the company's growth potential. | H21: SELL | I21: VER DCF | L21: =DCFF!D66 -> 29.300464
B23: KSF | L23: =DCFF!D65 -> 0.14053967
H24: =+DCFF!D66 -> 29.300464 | I24: Tasa de descuento | J24: =DCFF!D47 -> 0.08
B25: Año | C25: Ingresos | D25: Margen Operativo | E25: Div.+Recompra | F25: FNP | G25: Deuda/Activo | H25: Depreciación | I25: Capex + Adq | J25: Cash Flow
B26: 2012 | C26: =Cifras_Originales!N6 -> 2028.342 | D26: =Cifras_Originales!N8/C26 -> 0.24698054 | E26: =Cifras_Originales!N17+Cifras_Originales!N18 -> -64.2 | F26: =Cifras_Originales!$N$16 -> 338.829 | G26: =Cifras_Originales!$N$39/Cifras_Originales!$N$27 -> 0.34860481 | H26: =Cifras_Originales!$N$11 -> -132.1 | I26: =Cifras_Originales!$N$13+Cifras_Originales!$N$14 -> -218.8 | K26: 2024 | L26: 2023
B27: =B26+1 -> 2013 | C27: =Cifras_Originales!M6 -> 2066.1 | D27: =Cifras_Originales!M8/C27 -> 0.24345385 | E27: =Cifras_Originales!M17+Cifras_Originales!M18 -> -51.5 | F27: =Cifras_Originales!$M$16 -> 355.2 | G27: =Cifras_Originales!$M$39/Cifras_Originales!$M$27 -> 0.37338523 | H27: =Cifras_Originales!$M$11 -> -141.3 | I27: =Cifras_Originales!$M$13+Cifras_Originales!$M$14 -> -168.6 | J27: Utilidad Neta | K27: =Cifras_Originales!B16 -> 1198.1 | L27: =Cifras_Originales!C16 -> 1050.2 | N27: =C27/C26-1 -> 0.018615204 | O27: =D27/D26-1 -> -0.014279216
B28: =B27+1 -> 2014 | C28: =Cifras_Originales!L6 -> 2294.3 | D28: =Cifras_Originales!L8/C28 -> 0.18776969 | E28: =Cifras_Originales!L17+Cifras_Originales!L18 -> -149.6 | F28: =Cifras_Originales!$L$16 -> 292.5 | G28: =Cifras_Originales!$L$39/Cifras_Originales!$L$27 -> 0.40361519 | H28: =Cifras_Originales!$L$11 -> -176.3 | I28: =Cifras_Originales!$L$13+Cifras_Originales!$L$14 -> -1000.9 | J28: Cash Flow from Operations (BWC) | K28: =+K29+1660 -> 1373.7 | L28: =1565+L29 -> 1325.5 | N28: =C28/C27-1 -> 0.11044964 | O28: =D28/D27-1 -> -0.22872573 | P28: =E28/E27-1 -> 1.9048544 | Q28: =F28/F27-1 -> -0.17652027 | R28: =H28/H27-1 -> 0.24769993 | S28: =I28/I27-1 -> 4.9365362
B29: =B28+1 -> 2015 | C29: =Cifras_Originales!K6 -> 2839.5 | D29: =Cifras_Originales!K8/C29 -> 0.22299701 | E29: =Cifras_Originales!K17+Cifras_Originales!K18 -> -90.8 | F29: =Cifras_Originales!$K$16 -> 406 | G29: =Cifras_Originales!$K$39/Cifras_Originales!$K$27 -> 0.44739677 | H29: =Cifras_Originales!$K$11 -> -211.4 | I29: =Cifras_Originales!$K$13+Cifras_Originales!$K$14 -> -60.5 | J29: Working Capital | K29: =Cifras_Originales!B12 -> -286.3 | L29: =Cifras_Originales!C12 -> -239.5 | N29: =C29/C28-1 -> 0.23763239 | O29: =D29/D28-1 -> 0.18760917 | P29: =E29/E28-1 -> -0.39304813 | Q29: =F29/F28-1 -> 0.38803419 | R29: =H29/H28-1 -> 0.19909246 | S29: =I29/I28-1 -> -0.9395544
B30: =B29+1 -> 2016 | C30: =Cifras_Originales!J6 -> 3055.6 | D30: =Cifras_Originales!J8/C30 -> 0.21992407 | E30: =Cifras_Originales!J17+Cifras_Originales!J18 -> -202.3 | F30: =Cifras_Originales!$J$16 -> 452.2 | G30: =Cifras_Originales!$J$39/Cifras_Originales!$J$27 -> 0.44075413 | H30: =Cifras_Originales!$J$11 -> -206.4 | I30: =Cifras_Originales!$J$13+Cifras_Originales!$J$14 -> -299 | J30: Investing Activities | K30: -191.7 | L30: -161.6 | N30: =C30/C29-1 -> 0.076104948 | O30: =D30/D29-1 -> -0.013780152 | P30: =E30/E29-1 -> 1.2279736 | Q30: =F31/F29-1 -> 0.28103448 | R30: =H30/H29-1 -> -0.023651845 | S30: =I30/I29-1 -> 3.9421488
B31: =B30+1 -> 2017 | C31: =Cifras_Originales!I6 -> 3228 | D31: =Cifras_Originales!I8/C31 -> 0.22583643 | E31: =Cifras_Originales!I17+Cifras_Originales!I18 -> -121.9 | F31: =Cifras_Originales!$I$16 -> 520.1 | G31: =Cifras_Originales!$I$39/Cifras_Originales!$I$27 -> 0.43156278 | H31: =Cifras_Originales!$I$11 -> -217.7 | I31: =Cifras_Originales!$I$13+Cifras_Originales!$I$14 -> -367.4 | J31: Capex | K31: =Cifras_Originales!B13 -> -193.4 | L31: =Cifras_Originales!C13 -> -145.3 | N31: =C31/C30-1 -> 0.056420998 | O31: =D31/D30-1 -> 0.02688363 | P31: =#REF!/E30-1 -> #REF! | Q31: =F32/F31-1 -> 0.083253221 | R31: =H31/H30-1 -> 0.054748062 | S31: =I31/I30-1 -> 0.22876254
B32: =B31+1 -> 2018 | C32: =Cifras_Originales!H6 -> 3477.4 | D32: =Cifras_Originales!H8/C32 -> 0.22091218 | E32: =Cifras_Originales!H17+Cifras_Originales!H18 -> -174.4 | F32: =Cifras_Originales!$H$16 -> 563.4 | G32: =Cifras_Originales!$H$39/Cifras_Originales!$H$27 -> 0.4198771 | H32: =Cifras_Originales!$H$11 -> -237.7 | I32: =Cifras_Originales!$H$13+Cifras_Originales!$H$14 -> -323.2 | J32: Adquisiones | K32: =Cifras_en_Millones!C34 -> 1.6 | L32: =+Cifras_Originales!C33 -> 66.5 | N32: =C32/C31-1 -> 0.077261462 | O32: =D32/D31-1 -> -0.021804522 | P32: =E31/#REF!-1 -> #REF! | Q32: =F33/F32-1 -> 0.076144835 | R32: =H32/H31-1 -> 0.091869545 | S32: =I32/I31-1 -> -0.12030484
B33: =B32+1 -> 2019 | C33: =Cifras_Originales!G6 -> 4018.2 | D33: =Cifras_Originales!G8/C33 -> 0.20227963 | E33: =Cifras_Originales!G17+Cifras_Originales!G18 -> -212.2 | F33: =Cifras_Originales!$G$16 -> 606.3 | G33: =Cifras_Originales!$G$39/Cifras_Originales!$G$27 -> 0.6206551 | H33: =Cifras_Originales!$G$11 -> -396 | I33: =Cifras_Originales!$G$13+Cifras_Originales!$G$14 -> -5334.8 | J33: Dividends | K33: =Cifras_Originales!B17 -> -302.7 | L33: =Cifras_Originales!C17 -> -276.2 | N33: =C33/C32-1 -> 0.15551849 | O33: =D33/D32-1 -> -0.08434369 | P33: =E32/E31-1 -> 0.43068089 | Q33: =F34/F33-1 -> -0.1992413 | R33: =H33/H32-1 -> 0.6659655 | S33: =I33/I32-1 -> 15.506188
B34: =B33+1 -> 2020 | C34: =Cifras_Originales!F6 -> 4452.3 | D34: =Cifras_Originales!F8/C34 -> 0.15041664 | E34: =Cifras_Originales!F17+Cifras_Originales!F18 -> -261 | F34: =Cifras_Originales!$F$16 -> 485.5 | G34: =Cifras_Originales!$F$39/Cifras_Originales!$F$27 -> 0.60613844 | H34: =Cifras_Originales!$F$11 -> -604.5 | I34: =Cifras_Originales!$F$13+Cifras_Originales!$F$14 -> -208 | J34: Stock Repurchases | K34: =Cifras_Originales!B18 -> -325.6 | L34: =Cifras_Originales!C18 -> -162.3 | N34: =C34/C33-1 -> 0.10803345 | O34: =D34/D33-1 -> -0.25639255 | P34: =E33/E32-1 -> 0.21674312 | Q34: =F35/F34-1 -> 0.59402678 | R34: =H34/H33-1 -> 0.52651515 | S34: =I34/I33-1 -> -0.96101072
B35: =B34+1 -> 2021 | C35: =Cifras_Originales!E6 -> 4860 | D35: =Cifras_Originales!E8/C35 -> 0.20975309 | E35: =Cifras_Originales!E17+Cifras_Originales!E18 -> -274.3 | F35: =Cifras_Originales!$E$16 -> 773.9 | G35: =Cifras_Originales!$E$39/Cifras_Originales!$E$27 -> 0.56318088 | H35: =Cifras_Originales!$E$11 -> -574.6 | I35: =Cifras_Originales!$E$13+Cifras_Originales!$E$14 -> -160.4 | J35: Endeudamiento Neto | K35: =(Cifras_en_Millones!$C$54+Cifras_en_Millones!$C$50)-(Cifras_en_Millones!$D$50+Cifras_en_Millones!$D$54) -> -497.1 | L35: =(Cifras_en_Millones!$D$54+Cifras_en_Millones!$D$50)-(Cifras_en_Millones!$E$50+Cifras_en_Millones!$E54) -> -5.3 | N35: =C35/C34-1 -> 0.091570649 | O35: =D35/D34-1 -> 0.39448061 | P35: =E34/E33-1 -> 0.22997172 | Q35: =F36/F35-1 -> 0.20196408 | R35: =H35/H34-1 -> -0.049462366 | S35: =I35/I34-1 -> -0.22884615
B36: =B35+1 -> 2022 | C36: =Cifras_Originales!D6 -> 5665.3 | D36: =Cifras_Originales!D8/C36 -> 0.22997899 | E36: =Cifras_Originales!D17+Cifras_Originales!D18 -> -602.5 | F36: =Cifras_Originales!$D$16 -> 930.2 | G36: =Cifras_Originales!$D$39/Cifras_Originales!$D$27 -> 0.48637202 | H36: =Cifras_Originales!$D$11 -> -596.8 | I36: =Cifras_Originales!$D$13+Cifras_Originales!$D$14 -> -213.9 | J36: Otros Financiemientos | K36: =1211.9-OP!$K$33-OP!$K$35 -> 2011.7 | L36: =537-OP!$L$33-OP!$L$35 -> 818.5 | N36: =C36/C35-1 -> 0.16569959 | O36: =D36/D35-1 -> 0.096427227
B37: =B36+1 -> 2023 | C37: =Cifras_Originales!C6 -> 5951.4 | D37: =Cifras_Originales!C8/C37 -> 0.20867359 | E37: =Cifras_Originales!C17+Cifras_Originales!C18 -> -438.5 | F37: =Cifras_Originales!$C16 -> 1050.2 | G37: =Cifras_Originales!$C$39/Cifras_Originales!$C$27 -> 0.46342598 | H37: =Cifras_Originales!$C$11 -> -569.5 | I37: =Cifras_Originales!$C$13+Cifras_Originales!$C$14 -> -161.7 | N37: =C37/C36-1 -> 0.050500415 | O37: =D37/D36-1 -> -0.092640658
B38: 2024 | C38: =Cifras_Originales!B6 -> 6213.6 | D38: =Cifras_Originales!B8/Cifras_Originales!B6 -> 0.21881035 | E38: =Cifras_Originales!B17+Cifras_Originales!B18 -> -628.3 | F38: =Cifras_Originales!B16 -> 1198.1 | G38: =Cifras_Originales!$B$39/Cifras_Originales!$B$27 -> 0.41587814 | H38: =Cifras_Originales!$B$11 -> -561 | I38: =Cifras_Originales!$B$13+Cifras_Originales!$B$14 -> -191.8
B39: CAGR | C39: =(C38/C26)^(1/($B$38-$B$26))-1 -> 0.097783863 | D39: =(D38/D26)^(1/($B$38-$B$26))-1 -> -0.01004126 | E39: =(E38/E26)^(1/($B$38-$B$26))-1 -> 0.20935184 | F39: =(F38/F26)^(1/($B$38-$B$26))-1 -> 0.11098802 | G39: =(G38/G26)^(1/($B$38-$B$26))-1 -> 0.01481309 | H39: =(H38/H26)^(1/($B$38-$B$26))-1 -> 0.12807594 | I39: =(I38/I26)^(1/($B$38-$B$26))-1 -> -0.010915399 | J39: FX | K39: -67.5 | L39: 128.2
B40: AAG | C40: =AVERAGE(N27:N37) -> 0.10434611 | D40: =AVERAGE(O27:O37) -> -0.00059689773 | E40: =(E38-E26)/13 -> -43.392308 | F40: =AVERAGE(Q27:Q37) -> 0.156087 | G40: =AVERAGE(R27:R37) -> 0.21409705 | H40: =AVERAGE(S27:S37) -> 2.7954899 | J40: Change in Cash and Eq. | K40: =Cifras_en_Millones!C40-Cifras_en_Millones!D40 -> 384.3 | L40: =Cifras_en_Millones!D40-Cifras_en_Millones!E40 -> 799.3
B41: CVAR | C41: =+STDEV(C26:C37)/AVERAGE(C26:C37) -> 0.3663778 | D41: =+STDEV(D26:D37)/AVERAGE(D26:D37) -> 0.12139251 | E41: =+STDEV(E26:E36)/AVERAGE(E26:E36) -> -0.76177535 | F41: =+STDEV(F26:F37)/AVERAGE(F26:F37) -> 0.42389175 | G41: =+STDEV(G26:G37)/AVERAGE(G26:G37) -> 0.18704179 | H41: =+STDEV(H26:H37)/AVERAGE(H26:H37) -> -0.57420508 | I41: =+STDEV(I26:I37)/AVERAGE(I26:I37) -> -2.0796445 | J41: Inv/Change in Vts | K41: =K31/(Cifras_en_Millones!C5-Cifras_en_Millones!D5) -> -0.73760488 | L41: =L31/(Cifras_en_Millones!D5-Cifras_en_Millones!E5) -> -0.50786438
B42: Último Año | C42: =C37/C36-1 -> 0.050500415 | D42: =D37/D36-1 -> -0.092640658 | E42: =E36/E35-1 -> 1.1965002 | F42: =F37/F36-1 -> 0.12900452 | G42: =G37/G36-1 -> -0.047177966 | H42: =H37/H36-1 -> -0.045743968 | I42: =I37/I36-1 -> -0.24403927 | J42: t inversiones; t adq. neto dep. | K42: =K32-Cifras_en_Millones!C17 -> 562.6 | L42: =L32-Cifras_en_Millones!D17 -> 636
...

Sheet COVID-19 impact
A1: https://www.apple.com/newsroom/2020/03/apples-covid-19-response/ | G1: https://glg.it/articles/how-might-the-wuhan-coronavirus-impact-apples-supply-chain/ | N1: https://www.cnbc.com/2020/02/18/the-significance-of-apples-coronavirus-warning.html
A2: March 13 | G2: January 29 | N2: Ferbuary 18
A23: Otros:
A24: https://www.macrumors.com/guide/covid-19-coronavirus/

Sheet Segments
B2: Regions (2024)
C3: 2024 | D3: =C3-1 -> 2023 | E3: Ut. Operativa | F3: % Vts | G3: Margen | H3: Crec
B4: Americas | C4: 2214.7 | D4: 2142 | F4: =D4/SUM($D$4:$D$6) -> 0.39962687 | H4: =+C4/D4-1 -> 0.033940243 | J4: =IF(D4="","",IF(F4=0,"NA",TEXT(F4,"0%"))&"; "&IF(G4=0,"NA",TEXT(G4,"0.0%"))&"; "&IF(H4=0,"NA",TEXT(H4,"0%"))) -> 40%; NA; 3% | M4: 40% USD
B5: Europe | C5: 2150.4 | D5: 2027 | F5: =D5/SUM($D$4:$D$6) -> 0.37817164 | H5: =+C5/D5-1 -> 0.060878145 | J5: =IF(D5="","",IF(F5=0,"NA",TEXT(F5,"0%"))&"; "&IF(G5=0,"NA",TEXT(G5,"0.0%"))&"; "&IF(H5=0,"NA",TEXT(H5,"0%"))) -> 38%; NA; 6% | M5: 38% EUR
B6: Asia | C6: 1248.1 | D6: 1191 | F6: =D6/SUM($D$4:$D$6) -> 0.22220149 | H6: =+C6/D6-1 -> 0.047942905 | J6: =IF(D6="","",IF(F6=0,"NA",TEXT(F6,"0%"))&"; "&IF(G6=0,"NA",TEXT(G6,"0.0%"))&"; "&IF(H6=0,"NA",TEXT(H6,"0%"))) -> 22%; NA; 5% | M6: 22% YEN
J7: =IF(C7="","",IF(F7=0,"NA",TEXT(F7,"0%"))&"; "&IF(G7=0,"NA",TEXT(G7,"0.0%"))&"; "&IF(H7=0,"NA",TEXT(H7,"0%")))
J8: =IF(C8="","",IF(F8=0,"NA",TEXT(F8,"0%"))&"; "&IF(G8=0,"NA",TEXT(G8,"0.0%"))&"; "&IF(H8=0,"NA",TEXT(H8,"0%")))
J9: =IF(C9="","",IF(F9=0,"NA",TEXT(F9,"0%"))&"; "&IF(G9=0,"NA",TEXT(G9,"0.0%"))&"; "&IF(H9=0,"NA",TEXT(H9,"0%")))
J10: =IF(C10="","",IF(F10=0,"NA",TEXT(F10,"0%"))&"; "&IF(G10=0,"NA",TEXT(G10,"0.0%"))&"; "&IF(H10=0,"NA",TEXT(H10,"0%")))
J11: =IF(C11="","",IF(F11=0,"NA",TEXT(F11,"0%"))&"; "&IF(G11=0,"NA",TEXT(G11,"0.0%"))&"; "&IF(H11=0,"NA",TEXT(H11,"0%")))
J12: =IF(C12="","",IF(F12=0,"NA",TEXT(F12,"0%"))&"; "&IF(G12=0,"NA",TEXT(G12,"0.0%"))&"; "&IF(H12=0,"NA",TEXT(H12,"0%")))
J13: =IF(C13="","",IF(F13=0,"NA",TEXT(F13,"0%"))&"; "&IF(G13=0,"NA",TEXT(G13,"0.0%"))&"; "&IF(H13=0,"NA",TEXT(H13,"0%")))
B14: TOTAL | C14: =SUM(C4:C12) -> 5613.2 | D14: =SUM(D4:D12) -> 5360 | E14: =SUM(E4:E13) -> 0 | F14: =C14/SUM($C$4:$C$13) -> 1 | G14: =E14/C14 -> 0 | H14: =C14/D14-1 -> 0.047238806
B15: Segments (2024)
C16: =2024 -> 2024 | D16: =C16-1 -> 2023 | E16: Ut. Op. | F16: % Vts | G16: Margen | H16: Crec
B17: Industrial Innovation | C17: 3019.6 | D17: 2908 | F17: =D17/SUM($D$17:$D$19) -> 0.54253731 | H17: =+C17/D17-1 -> 0.038376891 | J17: =IF(D17="","",IF(F17=0,"NA",TEXT(F17,"0%"))&"; "&IF(G17=0,"NA",TEXT(G17,"0.0%"))&"; "&IF(H17=0,"NA",TEXT(H17,"0%"))) -> 54%; NA; 4%
B18: Life Sciences | C18: 1144.2 | D18: 1159 | F18: =D18/SUM($D$17:$D$19) -> 0.21623134 | H18: =+C18/D18-1 -> -0.012769629 | J18: =IF(D18="","",IF(F18=0,"NA",TEXT(F18,"0%"))&"; "&IF(G18=0,"NA",TEXT(G18,"0.0%"))&"; "&IF(H18=0,"NA",TEXT(H18,"0%"))) -> 22%; NA; -1%
B19: Mainstream Innovation | C19: 1449.4 | D19: 1293 | F19: =D19/SUM($D$17:$D$19) -> 0.24123134 | H19: =+C19/D19-1 -> 0.12095901 | J19: =IF(D19="","",IF(F19=0,"NA",TEXT(F19,"0%"))&"; "&IF(G19=0,"NA",TEXT(G19,"0.0%"))&"; "&IF(H19=0,"NA",TEXT(H19,"0%"))) -> 24%; NA; 12%
J20: =IF(C20="","",IF(F20=0,"NA",TEXT(F20,"0%"))&"; "&IF(G20=0,"NA",TEXT(G20,"0.0%"))&"; "&IF(H20=0,"NA",TEXT(H20,"0%")))
J21: =IF(C21="","",IF(F21=0,"NA",TEXT(F21,"0%"))&"; "&IF(G21=0,"NA",TEXT(G21,"0.0%"))&"; "&IF(H21=0,"NA",TEXT(H21,"0%")))
J22: =IF(C22="","",IF(F22=0,"NA",TEXT(F22,"0%"))&"; "&IF(G22=0,"NA",TEXT(G22,"0.0%"))&"; "&IF(H22=0,"NA",TEXT(H22,"0%")))
J23: =IF(C23="","",IF(F23=0,"NA",TEXT(F23,"0%"))&"; "&IF(G23=0,"NA",TEXT(G23,"0.0%"))&"; "&IF(H23=0,"NA",TEXT(H23,"0%")))
J24: =IF(C24="","",IF(F24=0,"NA",TEXT(F24,"0%"))&"; "&IF(G24=0,"NA",TEXT(G24,"0.0%"))&"; "&IF(H24=0,"NA",TEXT(H24,"0%")))
J25: =IF(C25="","",IF(F25=0,"NA",TEXT(F25,"0%"))&"; "&IF(G25=0,"NA",TEXT(G25,"0.0%"))&"; "&IF(H25=0,"NA",TEXT(H25,"0%")))
J26: =IF(C26="","",IF(F26=0,"NA",TEXT(F26,"0%"))&"; "&IF(G26=0,"NA",TEXT(G26,"0.0%"))&"; "&IF(H26=0,"NA",TEXT(H26,"0%")))
B27: TOTAL | C27: =SUM(C17:C26) -> 5613.2 | D27: =SUM(D17:D26) -> 5360 | E27: =SUM(E17:E26) -> 0 | F27: =C27/SUM(C17:C26) -> 1 | G27: =E27/C27 -> 0 | H27: =C27/D27-1 -> 0.047238806

Sheet Peers
B1: #VALUE! | C1: #VALUE! | D1: #VALUE! | E1: #VALUE!
A2: Multiplos (USD) | B2: {=+_FV(B1,"Ticker symbol",TRUE)} -> DSY | C2: {=+_FV(C1,"Ticker symbol",TRUE)} -> PTC | D2: {=+_FV(D1,"Ticker symbol",TRUE)} -> SIE | E2: {=+_FV(E1,"Ticker symbol",TRUE)} -> ADSK
B3: {=+_FV(B1,"Name")} -> Dassault Systemes SE | C3: {=+_FV(C1,"Name")} -> PTC INC. | D3: {=+_FV(D1,"Name")} -> Siemens AG | E3: {=+_FV(E1,"Name")} -> AUTODESK, INC.
A4: Ventas | B4: 5951.4 | C4: 2097.1 | D4: 74882 | E4: 5005
A5: Crecimiento (1S23/1S22) | B5: =(B4-5665.3)/5665.3 -> 0.050500415 | C5: =(C4-1933.3)/1933.3 -> 0.084725599 | D5: =(D4-71977)/71977 -> 0.040360115 | E5: =(E4-4386)/4386 -> 0.14113087
A6: Crecimiento (1S23/1S19) | B6: =(5951-4018)/4018 -> 0.48108512 | C6: =(C4-1255.6)/1255.6 -> 0.67019752 | D6: =(D4-58483)/58483 -> 0.28040627 | E6: =(E4-2569.8)/2569.8 -> 0.94762238
A7: Deuda | B7: 3600.9 | C7: 1889 | D7: 46596 | E7: 2666
A8: Activos | B8: 14622.5 | C8: 6288.8 | D8: 145071 | E8: 9438
A9: Deuda/Activos | B9: =B7/B8 -> 0.24625748 | C9: =C7/C8 -> 0.30037527 | D9: =D7/D8 -> 0.32119445 | E9: =E7/E8 -> 0.2824751
A10: Deuda/EBITDA | B10: 2.3 | C10: 3 | D10: 3.6 | E10: 2.2
A11: (Capex + Adq.)/Revenue | B11: =(-145.3-16.1)/B4 -> -0.027119669 | C11: =(-23.8-828.3)/C4 -> -0.40632302 | D11: =(-2146-407)/D4 -> -0.034093641 | E11: =(-36.8-88.3)/E4 -> -0.024995005
A12: ROA (p) | B12: 0.0562 | C12: 0.0544 | D12: 0.0396 | E12: 0.0713
A13: ROIC (p) | B13: 0.0943 | C13: 0.0859 | D13: 0.0683 | E13: 0.2224
A14: Margen Operativo | B14: =1298/B4 -> 0.21809994 | C14: =477.9/C4 -> 0.22788613 | D14: =9401/D4 -> 0.12554419 | E14: =1170/E4 -> 0.23376623
A15: Margen Operativo 2022 | B15: =1319.1/5665.3 -> 0.23283851 | C15: =498.6/1933.3 -> 0.257901 | D15: =7276/71977 -> 0.10108785 | E15: =618/4386 -> 0.14090287
A16: Float | B16: =668.54/1310 -> 0.51033588 | C16: =113.92/120.32 -> 0.94680851 | D16: =785.88/783.22 -> 1.0033962 | E16: =213.5/215.51 -> 0.99067329
A17: b | B17: 0.62 | C17: 1.19 | D17: 1.22 | E17: 1.43
A18: Precio/Utilidad | B18: 54.7 | C18: 91.2 | D18: 14.8 | E18: 60
A19: Precio/Ventas | B19: 9.6 | C19: 7.9 | D19: 1.5 | E19: 9.8
A20: EV/Activos | B20: =56285.4/B8 -> 3.8492323 | C20: =18105.6/C8 -> 2.879023 | D20: =157667.5/D8 -> 1.0868299 | E20: =45482.4/E8 -> 4.8190718
A21: EV/Ebitda | B21: 35.8 | C21: 28.9 | D21: 11.5 | E21: 41.3
A22: Div. Yield: | B22: {=+(-B28*1000000/_FV(B1,"Shares outstanding",TRUE))/_xlfn.STOCKHISTORY(B2,B29-2,B29-2,0,0,1)} -> 0.0046545876 | C22: {=+(-C28*1000000/_FV(C1,"Shares outstanding",TRUE))/_xlfn.STOCKHISTORY(C2,C29-2,C29-2,0,0,1)} -> 0 | D22: {=+(-D28*1000000/_FV(D1,"Shares outstanding",TRUE))/_xlfn.STOCKHISTORY(D2,D29-2,D29-2,0,0,1)} -> 0.024732227 | E22: {=+(-E28*1000000/_FV(E1,"Shares outstanding",TRUE))/_xlfn.STOCKHISTORY(E2,E29-2,E29-2,0,0,1)} -> 0
B24: *Nota: Estos múltiplos no consideran el promedio de los últimos 3 años, únicamente valores del último año reportado
B25: **Cifras en USD
A27: (You can make up a table with different indicators in order to link them to the multiples/ratios. At the end, put the table unvisible with white color)
A28: Dividends | B28: -276.2 | C28: 0 | D28: -3362 | E28: 0
A29: Year end | B29: 45291 | C29: 45291 | D29: 45291 | E29: 45291

Sheet Acuerdo
A1: Invertir
A2: NO invertir
A3: Mantener sin elevar posición
A4: Mantener (y seguir comprando)
A5: Liquidar
A6: PENDIENTE

Sheet ESG
B2: Análisis ESG | J2: PARÁMETROS
C3: Impacto | D3: ¿Reporta? | E3: Ranking | F3: Mitigación | G3: Semáforo | H3: Comentarios | J3: IMPACTO | L3: RANKING | M3: MITIGACIÓN
B4: Ambiental | J4: NONE | K4: 0 | L4: "Best in class" | M4: Is there evidence of progam/plan/etc…
B5: Emisiones directas CO2 | C5: LOW | D5: Yes | E5: Best in Class | F5: Yes | H5: A pesar del impacto que otras empresas tienen en la reducción de emisiones con sus softwares (como Virtual Twin), también está comprometida con los objetivos de reucción aprovador por la SBTi | J5: LOW | K5: 1 | L5: Medium high
B6: Uso total de agua | C6: NONE | D6: Yes | E6: Best in Class | F6: Yes | H6: El agua no es esnecial para sus operaciones, por lo que tienes niveles de consumo muy bajos. | J6: MEDIUM | K6: 2 | L6: Medium
B7: Total Energy Consumption | C7: MEDIUM | D7: Yes | E7: Medium High | F7: Yes | H7: Apoyan fuentes de energía descentralizadas y con bajas emisiones de carbono, como las micro centrales nucleares. También ayudan en la construcción de infraestructuras para reducir los costes energéticos, por ejemplo manipulando dos flujos de calor. | J7: HIGH | K7: 3 | L7: "Villain"
B8: Waste Management | C8: NONE | D8: Yes | E8: Best in Class | F8: Yes | H8: Colabora con la iniciativa EECONE, que tiene como objetivo reducir los residuos electrónicos. 3DEXPERIENCE Lab apoya a startups como Atacama Biomaterials, que desarrolló Woodpack, una alternativa biodegradable a los envases plásticos.
B9: Land Degradation/Deforestation/Biodiversity loss/Animal sufering/… | C9: NONE | D9: Yes | E9: Best in Class | F9: N/A | J9: TRAFFIC LIGHTS
B10: Social
B11: % Rotación de empleados | C11: MEDIUM | D11: No | E11: Villain | F11: No | H11: El 'Comparably' menciona que están en el 5% inferior entre más de 4000 empresas de tamaño similar, y es el segundo peor entre 5 competidores.
B12: Sueldos y compensaciones | C12: NONE | D12: No | E12: Medium High | F12: No | H12: Tienen salarios promedio altos, generalmente más de 100,000 USD.
B13: Temas de reputación | C13: MEDIUM | D13: Yes | E13: Villain | F13: No | H13: La evaluación promédia en Glassdoor es 2/5, con más de 4800 reviews. Familia Dassault tuve problemas de reputación, como corrupción.
B14: Temas de discriminación | C14: LOW | D14: Yes | E14: Best in Class | F14: Yes | H14: Tienen iniciativas para mujeres en STEM. La proporción de mujeres entre los directivos ejecutivos es del 31,9 %. No tienes litigios de discriminacións.
B15: Seguridad laboral | C15: LOW | D15: No | E15: Best in Class | F15: No | H15: Como una empresa de softwares, no tienen riesgos claros de seguridad laboral.
B16: Daños a la salud | C16: LOW | D16: No | E16: Best in Class | F16: No | H16: Tampoco hay riesgos directos a la salúd.
B17: PXP? | D17: Yes | E17: Best in Class | F17: Yes | H17: Hay violaciones de derechos de autor y de capital humano. Pierden algunos de sus empleados para otras empresas competidoras.
B18: Supply chain | C18: NONE | D18: Yes | E18: Best in Class | F18: Yes | H18: La empresa no tiene inventarios, pero sus proveedores de energía fueron mencionados anteriormente.
B19: Community involvement | H19: Más de 147 nacionalidades. Tienen iniciativas comunitárias para minorias. Ofrecen programas de capacitación para ayudar a los empleados y a las comunidades externas a adaptarse a los cambios tecnológicos.
B20: Public Sector | C20: HIGH | D20: Yes | E20: Best in Class | F20: Yes | H20: Recibe ayuda financiera del gobierno francés. Ofrece servicios a los gobiernos.
B21: Litigios | C21: HIGH | D21: Yes | E21: Best in Class | F21: Yes | H21: Han presentado múltiples demandas por violación de derechos de autor, la mayoría de las cuales ganaron.
B22: Gobierno
B23: Diversidad (Género, edad, industria, región) | E23: Medium High | F23: Yes | H23: Diversidad en género y edad, pero el board és en su mayoria de nacionalidad francesa.
B24: % independientes | E24: Medium High | F24: Yes | H24: 80%. Two members are part of the Dassault family.
B25: tiempo promedio como consejeros independientes | E25: Medium High | F25: No | H25: Solo 2 de 10 tienen mandatos que excedan 12 años.
B26: Salidas recientes de consejeros/C-level executives? | E26: Best in Class | F26: N/A | H26: Bernard Charles fue director general durante casi 30 años, renunció en 2024 y fue reemplazado por su sucesor Pascal Daloz.
B27: CEO/Chairman | E27: Best in Class | F27: N/A | H27: Pascal Daloz se unió a Dassault en 2001, desempeñando funciones como VP de R&D, COO and CFO, preparándose para convertirse en CEO.
B28: Transparencia (segmentos, fuente de riqueza, adquisiciones, otros) | E28: Best in Class | F28: N/A
B29: Tiempo que tardan en reportar luego del final del trimestre/año | E29: Best in Class | F29: N/A | H29: Compartieron los resultados del cuarto trimestre en el 4 de Febrero.
B30: Participación adicional del CEO en otros consejos o excesiva del Ch. | E30: Medium | F30: No | H30: Se desempeña como miembro independiente de la board de Sopra-Steria y STMicroelectronics, ambas empresas que cotizan en bolsa.
B31: Auditoría/Consultoría | H31: Cofrac Inspection Accreditation
B32: Esquemas de compensación al management | C32: LOW | D32: Yes | E32: Medium High | F32: Yes | H32: 450.000 acciones para el CEO, el crecimiento en EPS es el 80% de los criterios, la evaluación ESG es el 20%

Sheet DCF
A1: Discounted Cash Flow
A3: Ventas | E3: Margen Operativo
A16: Inversiones | E16: Utilidad Neta
D31: 0.001 | E31: =1/((1+$B$59+$D31)^(E35-2021)) -> 0.92250923 | F31: =1/((1+$B$59+$D31)^(F35-2021)) -> 0.85102327 | G31: =1/((1+$B$59+$D31)^(G35-2021)) -> 0.78507682 | H31: =1/((1+$B$59+$D31)^(H35-2021)) -> 0.72424061 | I31: =1/((1+$B$59+$D31)^(I35-2021)) -> 0.66811864 | J31: =1/((1+$B$59+$D31)^(J35-2021)) -> 0.61634561 | K31: =1/((1+$B$59+$D31)^(K35-2021)) -> 0.56858451 | L31: =1/((1+$B$59+$D31)^(L35-2021)) -> 0.52452446 | ... AC31: =1/((1+$B$59+$D31)^(AC35-2021)) -> 0.13312755
D32: 0.005 | E32: =1/((1+$B$59+$D32)^(E35-2021)) -> 0.91911765 | F32: =1/((1+$B$59+$D32)^(F35-2021)) -> 0.84477725 | G32: =1/((1+$B$59+$D32)^(G35-2021)) -> 0.77644968 | H32: =1/((1+$B$59+$D32)^(H35-2021)) -> 0.7136486 | I32: =1/((1+$B$59+$D32)^(I35-2021)) -> 0.65592702 | J32: =1/((1+$B$59+$D32)^(J35-2021)) -> 0.6028741 | K32: =1/((1+$B$59+$D32)^(K35-2021)) -> 0.55411223 | L32: =1/((1+$B$59+$D32)^(L35-2021)) -> 0.50929433 | ... AC32: =1/((1+$B$59+$D32)^(AC35-2021)) -> 0.12141647
D33: Normal | E33: =1/((1+$B$59)^(E35-2021)) -> 0.92336103 | F33: =1/((1+$B$59)^(F35-2021)) -> 0.8525956 | G33: =1/((1+$B$59)^(G35-2021)) -> 0.78725355 | H33: =1/((1+$B$59)^(H35-2021)) -> 0.72691926 | I33: =1/((1+$B$59)^(I35-2021)) -> 0.67120892 | J33: =1/((1+$B$59)^(J35-2021)) -> 0.61976816 | K33: =1/((1+$B$59)^(K35-2021)) -> 0.57226977 | L33: =1/((1+$B$59)^(L35-2021)) -> 0.5284116 | ... AC33: =1/((1+$B$59)^(AC35-2021)) -> 0.13623496
B35: 2019 (Real) | C35: 2020 (Real) | D35: 2021 | E35: =D35+1 -> 2022 | F35: =E35+1 -> 2023 | G35: =F35+1 -> 2024 | H35: =G35+1 -> 2025 | I35: =H35+1 -> 2026 | J35: =I35+1 -> 2027 | K35: =J35+1 -> 2028 | L35: =K35+1 -> 2029 | ... AC35: =AB35+1 -> 2046
A36: Crecimiento | B36: =#REF! -> #REF! | C36: =#REF! -> #REF! | D36: 0.35 | E36: 0.034 | F36: 0.095 | G36: 0.095 | H36: 0.095 | I36: 0.095 | J36: 0.095 | K36: 0.08 | L36: 0.06 | M36: 0.05 | N36: 0.04 | O36: 0.035 | P36: 0.035 | Q36: 0.035 | R36: 0.035 | S36: 0.035 | T36: 0.035 | U36: 0.035 | V36: 0.035 | W36: 0.035 | X36: 0.035 | Y36: 0.035 | Z36: 0.035 | AA36: 0.035 | AB36: 0.035 | AC36: 0.035
A37: Ventas | B37: =#REF! -> #REF! | C37: =#REF! -> #REF! | D37: =#REF!*(1+D36) -> #REF! | E37: =D37*(1+E36) -> #REF! | F37: =E37*(1+F36) -> #REF! | G37: =F37*(1+G36) -> #REF! | H37: =G37*(1+H36) -> #REF! | I37: =H37*(1+I36) -> #REF! | J37: =I37*(1+J36) -> #REF! | K37: =J37*(1+K36) -> #REF! | L37: =K37*(1+L36) -> #REF! | ... AC37: =AB37*(1+AC36) -> #REF!
A38: Margen Operativo | B38: =+#REF! -> #REF! | C38: =+#REF! -> #REF! | D38: =108166.4/365513.2 -> 0.29593022 | E38: =108162.8/377959.8 -> 0.28617541 | F38: 0.27 | G38: 0.275 | H38: 0.26 | I38: 0.255 | J38: 0.25 | K38: 0.25 | L38: 0.25 | M38: 0.25 | N38: 0.25 | O38: 0.25 | P38: 0.25 | Q38: 0.25 | R38: 0.25 | S38: 0.25 | T38: 0.25 | U38: 0.25 | V38: 0.25 | W38: 0.25 | X38: 0.25 | Y38: 0.25 | Z38: 0.25 | AA38: 0.25 | AB38: 0.25 | AC38: 0.25
A39: EBIT | B39: 63930 | C39: 66288 | D39: =D37*D38 -> #REF! | E39: =E37*E38 -> #REF! | F39: =F37*F38 -> #REF! | G39: =G37*G38 -> #REF! | H39: =H37*H38 -> #REF! | I39: =I37*I38 -> #REF! | J39: =J37*J38 -> #REF! | K39: =K37*K38 -> #REF! | ... AC39: =AC37*AC38 -> #REF!
A40: Dep&Amort | B40: =#REF! -> #REF! | C40: =#REF! -> #REF! | D40: 11000 | E40: =D40*(1+E36*$H$59) -> 11374 | F40: =E40*(1+F36*$H$59) -> 12454.53 | G40: =F40*(1+G36*$H$59) -> 13637.71 | H40: =G40*(1+H36*$H$59) -> 14933.293 | I40: =H40*(1+I36*$I$59) -> 16351.956 | J40: =I40*(1+J36*$I$59) -> 17905.391 | K40: =J40*(1+K36*$I$59) -> 19337.823 | L40: =K40*(1+L36*$I$59) -> 20498.092 | M40: =L40*(1+M36*$I$59) -> 21522.997 | N40: =M40*(1+N36*$I$59) -> 22383.917 | O40: =N40*(1+O36*$I$59) -> 23167.354 | P40: =O40*(1+P36*$I$59) -> 23978.211 | ... AC40: =AB40*(1+AC36*$I$59) -> 37500.868
A41: EBIDTA | B41: =+B39+B40 -> #REF! | C41: =+C39+C40 -> #REF! | D41: =D39+D40 -> #REF! | E41: =E39+E40 -> #REF! | F41: =F39+F40 -> #REF! | G41: =G39+G40 -> #REF! | H41: =H39+H40 -> #REF! | I41: =I39+I40 -> #REF! | J41: =J39+J40 -> #REF! | K41: =K39+K40 -> #REF! | ... AC41: =AC39+AC40 -> #REF!
A42: CIF | B42: -1385 | C42: -890 | D42: =(C48)*$H$60 -> -1124.36 | E42: =(D48)*$H$60 -> -1113.1164 | F42: =(E48)*$H$60 -> -1113.1164 | G42: =(F48)*$H$60 -> -1113.1164 | H42: =(G48)*$H$60 -> -1113.1164 | I42: =(H48)*$H$60 -> -1113.1164 | J42: =(I48)*$H$60 -> -1113.1164 | K42: =(J48)*$H$60 -> -1113.1164 | ... AC42: =(AB48)*$H$60 -> -1113.1164
A43: Otros Gastos | B43: =-422-2817 -> -3239 | C43: =87-3634 -> -3547 | D43: =-C43*(1+D36) -> 4788.45 | E43: =D43*(1+E36*0.5) -> 4869.8537 | F43: =E43*(1+F36*0.5) -> 5101.1717 | G43: =F43*(1+G36*0.5) -> 5343.4774 | H43: =G43*(1+H36*0.5) -> 5597.2925 | I43: =H43*(1+I36*0.5) -> 5863.1639 | J43: =I43*(1+J36*0.5) -> 6141.6642 | K43: =J43*(1+K36*0.5) -> 6387.3308 | L43: =K43*(1+L36*0.5) -> 6578.9507 | ... AC43: =AB43*(1+AC36*0.5) -> 8922.7133
A44: Utilidad antes de Impuestos | B44: =B39-B42-B43 -> 68554 | C44: =C39-C42-C43 -> 70725 | D44: =D39-D42-D43 -> #REF! | E44: =E39-E42-E43 -> #REF! | F44: =F39-F42-F43 -> #REF! | G44: =G39-G42-G43 -> #REF! | H44: =H39-H42-H43 -> #REF! | I44: =I39-I42-I43 -> #REF! | ... AC44: =AC39-AC42-AC43 -> #REF!
A45: ISR & PTU | B45: 10481 | C45: 9680 | D45: =$H$61*D44 -> #REF! | E45: =$H$61*E44 -> #REF! | F45: =$H$61*F44 -> #REF! | G45: =$I$61*G44 -> #REF! | H45: =$I$61*H44 -> #REF! | I45: =$I$61*I44 -> #REF! | J45: =$I$61*J44 -> #REF! | K45: =$I$61*K44 -> #REF! | L45: =$I$61*L44 -> #REF! | M45: =$I$61*M44 -> #REF! | N45: =$I$61*N44 -> #REF! | ... AC45: =$I$61*AC44 -> #REF!
A46: Utilidad Neta | B46: =B44-B45 -> 58073 | C46: =C44-C45 -> 61045 | D46: =D44-D45 -> #REF! | E46: =E44-E45 -> #REF! | F46: =F44-F45 -> #REF! | G46: =G44-G45 -> #REF! | H46: =H44-H45 -> #REF! | I46: =I44-I45 -> #REF! | ... AC46: =AC44-AC45 -> #REF!
A47: Inversiones y Capex | B47: =#REF! -> #REF! | C47: =#REF! -> #REF! | D47: 10000 | E47: =D47*(1+E36*$H$62) -> 10408 | F47: =E47*(1+F36*$H$62) -> 11594.512 | G47: =F47*(1+G36*$H$62) -> 12916.286 | H47: =G47*(1+H36*$H$62) -> 14388.743 | I47: =H47*(1+I36*$H$62) -> 16029.06 | J47: =I47*(1+J36*$H$62) -> 17856.373 | K47: =J47*(1+K36*$H$62) -> 19570.584 | L47: =K47*(1+L36*$H$62) -> 20979.666 | ... AC47: =AB47*(1+AC36*$H$62) -> 43199.777
A48: Deuda + Lease Liabilities | B48: 108047 | C48: 112436 | D48: =C48*0.99 -> 111311.64 | E48: =D48 -> 111311.64 | F48: =E48 -> 111311.64 | G48: =F48 -> 111311.64 | H48: =G48 -> 111311.64 | I48: =H48 -> 111311.64 | J48: =I48 -> 111311.64 | K48: =J48 -> 111311.64 | L48: =K48 -> 111311.64 | ... AC48: =AB48 -> 111311.64
A49: Deuda/EBITDA | B49: =B48/B41 -> #REF! | C49: =C48/C41 -> #REF! | D49: =D48/D41 -> #REF! | E49: =E48/E41 -> #REF!
A50: FNP | B50: =#REF! -> #REF! | C50: =#REF! -> #REF! | D50: =D41-D42-D43-D45-D47+D48-C48 -> #REF! | E50: =E41-E42-E43-E45-E47+E48-D48 -> #REF! | F50: =F41-F42-F43-F45-F47+F48-E48 -> #REF! | G50: =G41-G42-G43-G45-G47+G48-F48 -> #REF! | H50: =H41-H42-H43-H45-H47+H48-G48 -> #REF! | I50: =I41-I42-I43-I45-I47+I48-H48 -> #REF! | J50: =J41-J42-J43-J45-J47+J48-I48 -> #REF! | K50: =K41-K42-K43-K45-K47+K48-J48 -> #REF! | ... AC50: =AC41-AC42-AC43-AC45-AC47+AC48-AB48 -> #REF!
A51: F(t) | B51: 0 | C51: 0 | D51: =C51*(1+$B$59)+D50 -> #REF! | E51: =D51*(1+$B$59)+E50 -> #REF! | F51: =E51*(1+$B$59)+F50 -> #REF! | G51: =F51*(1+$B$59)+G50 -> #REF! | H51: =G51*(1+$B$59)+H50 -> #REF! | I51: =H51*(1+$B$59)+I50 -> #REF! | J51: =I51*(1+$B$59)+J50 -> #REF! | K51: =J51*(1+$B$59)+K50 -> #REF! | ... AC51: =AB51*(1+$B$59)+AC50 -> #REF!
AB52: =AB51-AB48 -> #REF! | AC52: =AC50/(B59-AC36) -> #REF!
A53: EPS | C53: =1000000*C46/#REF! -> #REF! | D53: =1000000*D46/#REF! -> #REF! | E53: =1000000*E46/#REF! -> #REF! | F53: =1000000*F46/#REF! -> #REF!
A54: Consenso EPS | C54: 3.3 | D54: 5.6 | E54: 5.6
A55: E$/UN | D55: =$B$61/D46 -> #REF! | E55: =$B$61/E46 -> #REF! | F55: =$B$61/F46 -> #REF!
A56: EEV/EBIDA | D56: =($B$61+D48-D51)/D41 -> #REF! | E56: =($B$61+E48-E51)/E41 -> #REF! | F56: =($B$61+F48-F51)/F41 -> #REF!
C58: "TELP" | D58: CER | E58: D Analista | H58: CP | I58: LP
A59: Tasa de descuento: | B59: =SUM(C59:E59) -> 0.083 | C59: 0.0307 | D59: 0.0523 | E59: 0 | G59: Factor D&A | H59: 1 | I59: 1
G60: Factor CIF | H60: -0.01
A61: VPN*@i% | B61: =C62+C63 -> #REF! | C61: Normal | D61: =D31 -> 0.001 | E61: =D32 -> 0.005 | G61: Factor ISR | H61: 0.21 | I61: 0.23
A62: DCF 25Y | B62: =C62/B61 -> #REF! | C62: =AB52/(1+B59)^25 -> #REF! | D62: =SUMPRODUCT(E50:AB50,E31:AB31) -> #REF! | E62: =SUMPRODUCT(E50:AB50,E32:AB32) -> #REF! | G62: Factor inv | H62: 1.2
A63: Perpetuidad | B63: =1-B62 -> #REF! | C63: =AC52/(1+B59)^25 -> #REF! | D63: =(AC50/($B$59+D31-$AC$36))*AC31 -> #REF! | E63: =(AC50/($B$59+D32-$AC$36))*AC32 -> #REF! | G63: Suma D&A | H63: =SUM(40:40) -> #REF!
A64: VPN/Acción | B64: =1000000*B61/#REF! -> #REF! | D64: =1000000*SUM(D62:D63)/#REF! -> #REF! | E64: =1000000*SUM(E62:E63)/#REF! -> #REF! | G64: Suma Inv. | H64: =SUM(47:47) -> #REF!
B65: =B64/#REF!-1 -> #REF! | D65: =D64/B64-1 -> #REF! | E65: =E64/B64-1 -> #REF! | G65: Inv.+Goodwill | H65: =SUM(47:47)+(#REF!*#REF!) -> #REF!
A67: Duración | B67: =B62*D68+B63*D69 -> #REF! | E67: 1 | F67: 2 | G67: 3 | H67: 4 | I67: 5 | J67: 6 | K67: 7 | L67: 8 | M67: 9 | N67: 10 | O67: 11 | P67: 12 | Q67: 13 | R67: 14 | S67: 15 | T67: 16 | U67: 17 | V67: 18 | W67: 19 | X67: 20 | Y67: 21 | Z67: 22 | AA67: 23 | AB67: 24 | AC67: 25
A68: 0.001 | B68: =-$B$67*A68 -> #REF! | D68: =SUM(E68:AB68)/SUMPRODUCT(E50:AB50,E33:AB33) -> #REF! | E68: =E67*E50*E33 -> #REF! | F68: =F67*F50*F33 -> #REF! | G68: =G67*G50*G33 -> #REF! | H68: =H67*H50*H33 -> #REF! | I68: =I67*I50*I33 -> #REF! | J68: =J67*J50*J33 -> #REF! | K68: =K67*K50*K33 -> #REF! | L68: =L67*L50*L33 -> #REF! | ... AC68: =AC67*AC50*AC33 -> #REF!
A69: 0.005 | B69: =-$B$67*A69 -> #REF! | D69: =(1+B59)/B59+AC67 -> 38.048193

Sheet DCFF
C1: VALUATION MODEL
C2: Año fiscal de Apple cierra en septiembre
D3: =D19/D6 -> 0.035308642 | E3: =E19/E6 -> 0.029424744 | F3: =F19/F6 -> 0.030917095 | G3: 0 | H3: 0.25 | I3: =H3+1 -> 1.25 | J3: =I3+1 -> 2.25 | K3: =J3+1 -> 3.25 | L3: =K3+1 -> 4.25 | M3: =L3+1 -> 5.25 | N3: =M3+1 -> 6.25 | O3: =N3+1 -> 7.25 | P3: =O3+1 -> 8.25 | ... AF3: =AE3+1 -> 24.25
A4: Section | B4: Line # | C4: ITEM | D4: 2021 | E4: =+D4+1 -> 2022 | F4: =+E4+1 -> 2023 | G4: =+F4+1 -> 2024 | H4: 2025 | I4: =+H4+1 -> 2026 | J4: =+I4+1 -> 2027 | K4: =+J4+1 -> 2028 | L4: =+K4+1 -> 2029 | M4: =+L4+1 -> 2030 | N4: =+M4+1 -> 2031 | O4: =+N4+1 -> 2032 | P4: =+O4+1 -> 2033 | ... AF4: =+AE4+1 -> 2049 | AG4: Notes
A5: INCOME STATEMENT | B5: 1 | C5: Growth | D5: =Cifras_en_Millones!F6 -> 0.091570649 | E5: =Cifras_en_Millones!E6 -> 0.16569959 | F5: =Cifras_en_Millones!D6 -> 0.050500415 | G5: =Cifras_en_Millones!C6 -> 0.044056861 | H5: =H6/G6-1 -> 0.080050212 | I5: =I6/H6-1 -> 0.079272836 | J5: 0.057 | K5: 0.057 | L5: 0.057 | M5: 0.057 | N5: =+M5-($M$5-$AF$5)/($AF$4-$M$4) -> 0.055315789 | O5: =+N5-($M$5-$AF$5)/($AF$4-$M$4) -> 0.053631579 | P5: =+O5-($M$5-$AF$5)/($AF$4-$M$4) -> 0.051947368 | Q5: =+P5-($M$5-$AF$5)/($AF$4-$M$4) -> 0.050263158 | R5: =+Q5-($M$5-$AF$5)/($AF$4-$M$4) -> 0.048578947 | S5: =+R5-($M$5-$AF$5)/($AF$4-$M$4) -> 0.046894737 | T5: =+S5-($M$5-$AF$5)/($AF$4-$M$4) -> 0.045210526 | U5: =+T5-($M$5-$AF$5)/($AF$4-$M$4) -> 0.043526316 | ... AE5: =+AD5-($M$5-$AF$5)/($AF$4-$M$4) -> 0.026684211 | AF5: 0.025
B6: 2 | C6: Revenues/Sales | D6: =Cifras_en_Millones!F5 -> 4860 | E6: =Cifras_en_Millones!E5 -> 5665.3 | F6: =Cifras_en_Millones!D5 -> 5951.4 | G6: =Cifras_en_Millones!C5 -> 6213.6 | H6: 6711 | I6: 7243 | J6: =+I6*(1+J5) -> 7655.851 | K6: =+J6*(1+K5) -> 8092.2345 | L6: =+K6*(1+L5) -> 8553.4919 | M6: =+L6*(1+M5) -> 9041.0409 | N6: =+M6*(1+N5) -> 9541.1532 | O6: =+N6*(1+O5) -> 10052.86 | P6: =+O6*(1+P5) -> 10575.08 | Q6: =+P6*(1+Q5) -> 11106.617 | ... AF6: =+AE6*(1+AF5) -> 19088.862
B7: 3 | C7: EBIT/Operating Margin | D7: =Cifras_en_Millones!F12 -> 0.20975309 | E7: =Cifras_en_Millones!E12 -> 0.22997899 | F7: =Cifras_en_Millones!D12 -> 0.20867359 | G7: =Cifras_en_Millones!C12 -> 0.21881035 | H7: 0.21 | I7: 0.215 | J7: 0.22 | K7: 0.225 | L7: 0.23 | M7: =+L7 -> 0.23 | N7: =+M7 -> 0.23 | O7: =+N7 -> 0.23 | P7: =+O7 -> 0.23 | Q7: =+P7 -> 0.23 | R7: =+Q7 -> 0.23 | S7: =+R7 -> 0.23 | T7: =+S7 -> 0.23 | ... AF7: =+AE7 -> 0.23
B8: 4 | C8: EBIT | D8: =D6*D7 -> 1019.4 | E8: =E6*E7 -> 1302.9 | F8: =F6*F7 -> 1241.9 | G8: =G7*G6 -> 1359.6 | H8: =+H6*H7 -> 1409.31 | I8: =+I6*I7 -> 1557.245 | J8: =J7*J6 -> 1684.2872 | K8: =K7*K6 -> 1820.7528 | L8: =L7*L6 -> 1967.3031 | M8: =M7*M6 -> 2079.4394 | N8: =N7*N6 -> 2194.4652 | O8: =O7*O6 -> 2312.1579 | P8: =P7*P6 -> 2432.2684 | Q8: =Q7*Q6 -> 2554.5219 | ... AF8: =AF7*AF6 -> 4390.4382
B9: 5a | C9: (Dep&Amort) | D9: =Cifras_en_Millones!F17 -> -574.6 | E9: =Cifras_en_Millones!E17 -> -596.8 | F9: =Cifras_en_Millones!D17 -> -569.5 | G9: =Cifras_en_Millones!C17 -> -561 | H9: =-H95 -> -548.2555 | I9: =-I95 -> -554.39633 | J9: =-J95 -> -565.17415 | K9: =-K95 -> -579.54657 | L9: =-L95 -> -597.29191 | M9: =-M95 -> -618.23696 | N9: =-N95 -> -642.13844 | O9: =-O95 -> -668.7171 | ... AF9: =-AF95 -> -1334.5234
B10: 5b | C10: (Stock based compensation) | D10: =D19 -> 171.6 | E10: =E19 -> 166.7 | F10: =F19 -> 184 | G10: =G19 -> 185 | H10: =-$D$51*H6 -> -210.7254 | I10: =-$D$51*I6 -> -227.4302 | J10: =-$D$51*J6 -> -240.39372 | K10: =-$D$51*K6 -> -254.09616 | L10: =-$E$51*L6 -> -268.57964 | M10: =-$E$51*M6 -> -283.88868 | N10: =-$E$51*N6 -> -299.59221 | O10: =-$E$51*O6 -> -315.65981 | P10: =-$E$51*P6 -> -332.05751 | Q10: =-$E$51*Q6 -> -348.74777 | R10: =-$E$51*R6 -> -365.68957 | S10: =-$E$51*S6 -> -382.83849 | ... AF10: =-$E$51*AF6 -> -599.39025
B11: 6 | C11: EBIDTA | D11: =-D9+D8 -> 1594 | E11: =-E9+E8 -> 1899.7 | F11: =-F9+F8 -> 1811.4 | G11: =-G9+G8 -> 1920.6 | H11: =-H9+H8 -> 1957.5655 | I11: =-I9+I8 -> 2111.6413 | J11: =-J9+J8 -> 2249.4614 | K11: =-K9+K8 -> 2400.2993 | ... AF11: =-AF9+AF8 -> 5724.9615
B12: 7 | C12: (Net financing cost) | D12: =Cifras_Originales!E9 -> 16.8 | E12: =Cifras_Originales!D9 -> -13.8 | F12: =Cifras_Originales!C9 -> -98.3 | G12: =Cifras_Originales!B9 -> -118.4 | H12: =-$D$53*G37+G36*$D$54 -> 103.0109 | I12: =-$D$53*H37+H36*$D$54 -> 128.38183 | J12: =-$D$53*I37+I36*$D$54 -> 137.9474 | K12: =-$D$53*J37+J36*$D$54 -> 168.85875 | L12: =-$D$53*K37+K36*$D$54 -> 201.00796 | M12: =-$D$53*L37+L36*$D$54 -> 210.35868 | N12: =-$D$53*M37+M36*$D$54 -> 234.21901 | O12: =-$D$53*N37+N36*$D$54 -> 268.07102 | ... AF12: =-$D$53*AE37+AE36*$D$54 -> 844.49227
B13: 8 | C13: Other income/(cost) | D13: =Cifras_Originales!E10 -> 1.7 | E13: =Cifras_Originales!D10 -> -11.1 | F13: =Cifras_Originales!C10 -> -39.3 | G13: =Cifras_Originales!B10 -> 0 | H13: =AVERAGE(D13:G13)*(1+H5) -> -13.149611 | I13: =AVERAGE(E13:H13)*(1+I5) -> -17.146842 | J13: =AVERAGE(F13:I13)*(1+J5) -> -18.390863 | K13: =AVERAGE(G13:J13)*(1+K5) -> -12.865623 | L13: =AVERAGE(H13:K13)*(1+L5) -> -16.265364 | M13: =AVERAGE(I13:L13)*(1+M5) -> -17.088702 | N13: =AVERAGE(J13:M13)*(1+N5) -> -17.046134 | O13: =AVERAGE(K13:N13)*(1+O5) -> -16.664718 | ... AF13: =AVERAGE(AB13:AE13)*(1+AF5) -> -21.976897
B14: 9 | C14: Earnings before taxes | D14: =D8-D12+D13 -> 1004.3 | E14: =E8-E12+E13 -> 1305.6 | F14: =F8-F12+F13 -> 1300.9 | G14: =G8-G12+G13 -> 1478 | H14: =H8+H12+H13 -> 1499.1713 | I14: =I8+I12+I13 -> 1668.48 | J14: =J8+J12+J13 -> 1803.8438 | K14: =K8+K12+K13 -> 1976.7459 | L14: =L8+L12+L13 -> 2152.0457 | M14: =M8+M12+M13 -> 2272.7094 | N14: =N8+N12+N13 -> 2411.6381 | O14: =O8+O12+O13 -> 2563.5642 | ... AF14: =AF8+AF12+AF13 -> 5212.9535
B15: 10 | C15: (Income tax) | D15: =Cifras_en_Millones!F21 -> -230.4 | E15: =Cifras_en_Millones!E21 -> -375.4 | F15: =Cifras_en_Millones!D21 -> -250.7 | G15: =Cifras_en_Millones!C21 -> -279.9 | H15: =(-1*$D$52)*H14 -> -337.01371 | I15: =(-1*$D$52)*I14 -> -375.0743 | J15: =(-1*$D$52)*J14 -> -405.50408 | K15: =(-1*$D$52)*K14 -> -444.37248 | L15: =(-1*$E$52)*L14 -> -483.77988 | M15: =(-1*$E$52)*M14 -> -510.90507 | N15: =(-1*$E$52)*N14 -> -542.13625 | O15: =(-1*$E$52)*O14 -> -576.28923 | P15: =(-1*$E$52)*P14 -> -611.09779 | Q15: =(-1*$E$52)*Q14 -> -646.99483 | R15: =(-1*$E$52)*R14 -> -683.28691 | S15: =(-1*$E$52)*S14 -> -720.37872 | ... AF15: =(-1*$E$52)*AF14 -> -1171.872
B16: 11 | C16: Net income | D16: =D14+D15 -> 773.9 | E16: =E14+E15 -> 930.2 | F16: =F14+F15 -> 1050.2 | G16: =G14+G15 -> 1198.1 | H16: =H14+H15 -> 1162.1576 | I16: =I14+I15 -> 1293.4057 | J16: =J14+J15 -> 1398.3397 | K16: =K14+K15 -> 1532.3734 | ... AF16: =AF14+AF15 -> 4041.0816
A18: CASH FLOW STATEMENT | B18: 12 | C18: Operating cash flows before WK | D18: =+D16-D9 -> 1348.5 | E18: =+E16-E9 -> 1527 | F18: =+F16-F9 -> 1619.7 | G18: =+G16-G9 -> 1759.1 | H18: =H11+H12+H13+H15 -> 1710.4131 | I18: =I11+I12+I13+I15 -> 1847.802 | J18: =J11+J12+J13+J15 -> 1963.5138 | K18: =K11+K12+K13+K15 -> 2111.92 | L18: =L11+L12+L13+L15 -> 2265.5578 | M18: =M11+M12+M13+M15 -> 2380.0413 | N18: =N11+N12+N13+N15 -> 2511.6403 | O18: =O11+O12+O13+O15 -> 2655.992 | ... AF18: =AF11+AF12+AF13+AF15 -> 5375.605
B19: 13 | C19: (Stock-based compensation) | D19: 171.6 | E19: 166.7 | F19: 184 | G19: 185 | H19: =-H10 -> 210.7254 | I19: =-I10 -> 227.4302 | J19: =-J10 -> 240.39372 | K19: =-K10 -> 254.09616 | L19: =-L10 -> 268.57964 | M19: =-M10 -> 283.88868 | N19: =-N10 -> 299.59221 | O19: =-O10 -> 315.65981 | ... AF19: =-AF10 -> 599.39025
B20: 14 | C20: (Working Capital Flows) | D20: =+Cifras_Originales!E12 -> 93.2 | E20: =+Cifras_Originales!D12 -> -169.8 | F20: =+Cifras_Originales!C12 -> -239.5 | G20: =+Cifras_Originales!B12 -> -286.3 | H20: =$D$56*(H6-G6) -> -353.154 | I20: =$D$56*(I6-H6) -> -377.72 | J20: =$D$56*(J6-I6) -> -293.12421 | K20: =$D$56*(K6-J6) -> -309.83229 | L20: =$E$56*(L6-K6) -> -327.49273 | M20: =$E$56*(M6-L6) -> -346.15982 | N20: =$E$56*(N6-M6) -> -355.07974 | O20: =$E$56*(O6-N6) -> -363.31205 | P20: =$E$56*(P6-O6) -> -370.77594 | Q20: =$E$56*(Q6-P6) -> -377.39121 | R20: =$E$56*(R6-Q6) -> -383.07891 | S20: =$E$56*(S6-R6) -> -387.76212 | ... AF20: =$E$56*(AF6-AE6) -> -330.56321
B21: 15 | C21: -Total Operating Cash Flow | D21: =D18+D19+D20 -> 1613.3 | E21: =E18+E19+E20 -> 1523.9 | F21: =F18+F19+F20 -> 1564.2 | G21: =G18+G19+G20 -> 1657.8 | H21: =H18+H19+H20 -> 1567.9845 | I21: =I18+I19+I20 -> 1697.5122 | J21: =J18+J19+J20 -> 1910.7833 | K21: =K18+K19+K20 -> 2056.1839 | ... AF21: =AF18+AF19+AF20 -> 5644.432
B22: 16 | C22: (CAPEX and Acquisitions) | D22: =-103.7-21.4 -> -125.1 | E22: =-132.3-46.4 -> -178.7 | F22: =-145.3-16.1 -> -161.4 | G22: =-193.4-22.5 -> -215.9 | H22: =-$D$57*H6 -> -217.4364 | I22: =-$D$57*I6 -> -234.6732 | J22: =-$D$57*J6 -> -248.04957 | K22: =-$D$57*K6 -> -262.1884 | L22: =-$E$57*L6 -> -277.13314 | M22: =-$E$57*M6 -> -292.92973 | N22: =-$E$57*N6 -> -309.13336 | O22: =-$E$57*O6 -> -325.71267 | P22: =-$E$57*P6 -> -342.63259 | Q22: =-$E$57*Q6 -> -359.85439 | R22: =-$E$57*R6 -> -377.33573 | S22: =-$E$57*S6 -> -395.03079 | ... AF22: =-$E$57*AF6 -> -618.47912
B23: 17 | C23: (Other investing flows) | D23: =-35.3 -> -35.3 | E23: -35.2 | F23: -0.3 | G23: 24 | H23: =+AVERAGE(D23:G23)*(1+H5) -> -12.636587 | I23: =+AVERAGE(E23:H23)*(1+I5) -> -6.5124908 | J23: =+AVERAGE(F23:I23)*(1+J5) -> 1.2025811 | K23: =+AVERAGE(G23:J23)*(1+K5) -> 1.5996381 | L23: =+AVERAGE(H23:K23)*(1+L5) -> -4.3196575 | M23: =+AVERAGE(I23:L23)*(1+M5) -> -2.1219088 | N23: =+AVERAGE(J23:M23)*(1+N5) -> -0.96016512 | O23: =+AVERAGE(K23:N23)*(1+O5) -> -1.5283172 | ... AF23: =+AVERAGE(AB23:AE23)*(1+AF5) -> -2.3025638
B24: 18 | C24: -Total Investing Flows | D24: =D22+D23 -> -160.4 | E24: =E22+E23 -> -213.9 | F24: =F22+F23 -> -161.7 | G24: =G22+G23 -> -191.9 | H24: =H22+H23 -> -230.07299 | I24: =I22+I23 -> -241.18569 | J24: =J22+J23 -> -246.84699 | K24: =K22+K23 -> -260.58876 | ... AF24: =AF22+AF23 -> -620.78168
B25: 19 | C25: (Flows related to leases) | D25: -97.6 | E25: -102 | F25: -89.4 | G25: -79.7 | H25: =AVERAGE(D25:G25)*(1+H5) -> -99.553628 | I25: =AVERAGE(E25:H25)*(1+I5) -> -100.0091 | J25: =AVERAGE(F25:I25)*(1+J5) -> -97.419125 | K25: =AVERAGE(G25:J25)*(1+K5) -> -99.538179 | L25: =AVERAGE(H25:K25)*(1+L5) -> -104.78042 | M25: =AVERAGE(I25:L25)*(1+M5) -> -106.1616 | N25: =AVERAGE(J25:M25)*(1+N5) -> -107.61565 | O25: =AVERAGE(K25:N25)*(1+O5) -> -110.12975 | ... AF25: =AVERAGE(AB25:AE25)*(1+AF5) -> -141.11344
B26: 20 | C26: Flows related to debt | D26: =1.3-341.2 -> -339.9 | E26: =257.8-1143.9 -> -886.1 | F26: =20-28.1 -> -8.1 | G26: =-700.9+200.2 -> -500.7 | H26: =(H37-G37) -> 0 | I26: =(I37-H37) -> -900 | J26: =(J37-I37) -> 0 | K26: =(K37-J37) -> 0 | L26: =(L37-K37) -> -1150 | M26: =(M37-L37) -> -443.6 | N26: =(N37-M37) -> 0 | O26: =(O37-N37) -> 0 | ... AF26: =(AF37-AE37) -> 0
B27: 21 | C27: (Repurchases)/Issuance of stock | D27: -283.2 | E27: -639.6 | F27: -375.4 | G27: -374 | H27: =+H16*$D$55 -> -500.6428 | I27: =+I16*$D$55 -> -557.18283 | J27: =+J16*$D$55 -> -602.38707 | K27: =+K16*$D$55 -> -660.1271 | L27: =+L16*$D$55 -> -718.66785 | M27: =+M16*$D$55 -> -758.96304 | N27: =+N16*$D$55 -> -805.35778 | O27: =+O16*$D$55 -> -856.09294 | P27: =+P16*$D$55 -> -907.80198 | Q27: =+Q16*$E$55 -> -1028.0609 | R27: =+R16*$E$55 -> -1085.7282 | S27: =+S16*($E$55-10%) -> -1393.0816 | T27: =+T16*($E$55-10%) -> -1462.44 | U27: =+U16*($E$55-20%) -> -1806.3881 | V27: =+V16*($E$55-20%) -> -1885.8648 | W27: =+W16*($E$55-20%) -> -1966.1409 | X27: =+X16*($E$55-20%) -> -2047.0447 | Y27: =+Y16*($E$55-25%) -> -2289.458 | Z27: =+Z16*($E$55-25%) -> -2374.1333 | AA27: =+AA16*($E$55-25%) -> -2458.7293 | AB27: =+AB16*($E$55-25%) -> -2543.0191 | AC27: =+AC16*($E$55-25%) -> -2626.7688 | AD27: =+AD16*($E$55-25%) -> -2709.7354 | AE27: =+AE16*($E$55-25%) -> -2791.6767 | AF27: =+AF16*($E$55-25%) -> -2872.3497
B28: 22 | C28: (Dividends) | D28: -147.1 | E28: -223.5 | F28: -276.2 | G28: -302.7 | H28: =+$D$58*H16 -> -290.5394 | I28: =+$D$58*I16 -> -323.35142 | J28: =+$D$58*J16 -> -349.58492 | K28: =+$D$58*K16 -> -383.09335 | L28: =+$E$58*L16 -> -500.47975 | M28: =+$E$58*M16 -> -528.54129 | N28: =+$E$58*N16 -> -560.85056 | O28: =+$E$58*O16 -> -596.18248 | P28: =+$E$58*P16 -> -632.19262 | Q28: =+$E$58*Q16 -> -669.32882 | R28: =+$E$58*R16 -> -706.87369 | S28: =+$E$58*S16 -> -745.24589 | ... AF28: =+$E$58*AF16 -> -1212.3245
B29: 23 | C29: Other financing flows | D29: =156-0.1+90 -> 245.9 | E29: =62+198.6-1.8+71 -> 329.8 | F29: =-0.9+67+146.1+67.5 -> 279.7 | G29: =48.4-3.3+128 -> 173.1 | H29: =(1+H5)*AVERAGE(D29:G29) -> 277.70791 | I29: =(1+I5)*AVERAGE(E29:H29) -> 286.09038 | J29: =(1+J5)*AVERAGE(F29:I29) -> 268.6361 | K29: =(1+K5)*AVERAGE(G29:J29) -> 265.71246 | L29: =(1+L5)*AVERAGE(H29:K29) -> 290.18531 | M29: =(1+M5)*AVERAGE(I29:L29) -> 293.48246 | N29: =(1+N5)*AVERAGE(J29:M29) -> 294.96507 | O29: =(1+O5)*AVERAGE(K29:N29) -> 301.42959 | ... AF29: =(1+AF5)*AVERAGE(AB29:AE29) -> 387.61872
B30: 24 | C30: -Total Financing flows | D30: =SUM(D25:D29) -> -621.9 | E30: =SUM(E25:E29) -> -1521.4 | F30: =SUM(F25:F29) -> -469.4 | G30: =SUM(G25:G29) -> -1084 | H30: =SUM(H25:H29) -> -613.02792 | I30: =SUM(I25:I29) -> -1594.453 | J30: =SUM(J25:J29) -> -780.75501 | K30: =SUM(K25:K29) -> -877.04617 | ... AF30: =SUM(AF25:AF29) -> -3838.1689
A32: SUMMARY | B32: 25 | C32: Cash before shareholder returns | D32: =D21+D24+D25+D26+D29 -> 1261.3 | E32: =E21+E24+E25+E26+E29 -> 651.7 | F32: =F21+F24+F25+F26+F29 -> 1584.7 | G32: =G21+G24+G25+G26+G29 -> 1058.6 | H32: =H21+H24+H25+H26+H29 -> 1516.0658 | I32: =I21+I24+I25+I26+I29 -> 742.4078 | J32: =J21+J24+J25+J26+J29 -> 1835.1533 | K32: =K21+K24+K25+K26+K29 -> 1961.7694 | ... AF32: =AF21+AF24+AF25+AF26+AF29 -> 5270.1556
B33: 26 | C33: Returns to shareholders | D33: =-1*(D27+D28) -> 430.3 | E33: =-1*(E27+E28) -> 863.1 | F33: =-1*(F27+F28) -> 651.6 | G33: =-1*(G27+G28) -> 676.7 | H33: =-1*(H27+H28) -> 791.1822 | I33: =-1*(I27+I28) -> 880.53425 | J33: =-1*(J27+J28) -> 951.97199 | K33: =-1*(K27+K28) -> 1043.2205 | ... AF33: =-1*(AF27+AF28) -> 4084.6742
B34: 27 | C34: Excess cash acumulation | D34: =D32-D33 -> 831 | E34: =E32-E33 -> -211.4 | F34: =F32-F33 -> 933.1 | G34: =G32-G33 -> 381.9 | H34: =H32-H33 -> 724.88358 | I34: =I32-I33 -> -138.12645 | J34: =J32-J33 -> 883.18134 | K34: =K32-K33 -> 918.54892 | ... AF34: =AF32-AF33 -> 1185.4814
A36: CASH & DEBT & DISCOUNTING | B36: 28 | C36: Ending cash balance | D36: =+Cifras_Originales!E22 -> 2979.5 | E36: =D36+E34 -> 2768.1 | F36: =E36+F34 -> 3701.2 | G36: =F36+G34 -> 4083.1 | H36: =G36+H34 -> 4807.9836 | I36: =H36+I34 -> 4669.8571 | J36: =I36+J34 -> 5553.0385 | K36: =J36+K34 -> 6471.5874 | L36: =K36+L34 -> 6213.0366 | ... AF36: =AE36+AF34 -> 25313.832
B37: 29 | C37: Total Debt | D37: =Cifras_en_Millones!F60 -> 4470.7 | E37: =Cifras_en_Millones!E60 -> 3576.7 | F37: =Cifras_en_Millones!D60 -> 3600.9 | G37: =Cifras_en_Millones!C60 -> 2493.6 | H37: =+G37 -> 2493.6 | I37: =+H37-900 -> 1593.6 | J37: =+I37 -> 1593.6 | K37: =+J37 -> 1593.6 | L37: =+K37-1150 -> 443.6 | M37: =L352 -> 0 | N37: =M37 -> 0 | O37: =N37 -> 0 | P37: =O37 -> 0 | Q37: =P37 -> 0 | R37: =Q37 -> 0 | S37: =R37 -> 0 | T37: =S37 -> 0 | U37: =T37 -> 0 | ... AF37: =AE37 -> 0
B38: 30 | C38: Discount factor | G38: =1/((1+$D$47)^G3) -> 1 | H38: =1/((1+$D$47)^H3) -> 0.98094365 | I38: =1/((1+$D$47)^I3) -> 0.90828116 | J38: =1/((1+$D$47)^J3) -> 0.84100107 | K38: =1/((1+$D$47)^K3) -> 0.7787047 | L38: =1/((1+$D$47)^L3) -> 0.72102287 | M38: =1/((1+$D$47)^M3) -> 0.66761377 | N38: =1/((1+$D$47)^N3) -> 0.6181609 | ... AF38: =1/((1+$D$47)^AF3) -> 0.15469416
F39: =1/((1+$D$48+0.001)^F$3) -> 0.9999691 | G39: =1/((1+$D$47+0.001)^G$3) -> 1 | H39: =1/((1+$D$47+0.001)^H$3) -> 0.98071671 | I39: =1/((1+$D$47+0.001)^I$3) -> 0.907231 | J39: =1/((1+$D$47+0.001)^J$3) -> 0.83925162 | K39: =1/((1+$D$47+0.001)^K$3) -> 0.77636598 | L39: =1/((1+$D$47+0.001)^L$3) -> 0.71819239 | M39: =1/((1+$D$47+0.001)^M$3) -> 0.66437779 | N39: =1/((1+$D$47+0.001)^N$3) -> 0.61459555 | ... AE39: =1/((1+$D$47+0.001)^AE$3) -> 0.16351312
F40: =1/((1+$D$48+0.005)^F$3) -> 0.99984581 | G40: =1/((1+$D$47+0.005)^G$3) -> 1 | H40: =1/((1+$D$47+0.005)^H$3) -> 0.97981157 | I40: =1/((1+$D$47+0.005)^I$3) -> 0.90305214 | J40: =1/((1+$D$47+0.005)^J$3) -> 0.83230612 | K40: =1/((1+$D$47+0.005)^K$3) -> 0.76710242 | L40: =1/((1+$D$47+0.005)^L$3) -> 0.70700684 | M40: =1/((1+$D$47+0.005)^M$3) -> 0.6516192 | N40: =1/((1+$D$47+0.005)^N$3) -> 0.60057069 | ... AE40: =1/((1+$D$47+0.005)^AE$3) -> 0.1500578
C42: EPS | H42: {=1000000*H16/_FV(OP!$N$2,"Shares outstanding",TRUE)} -> 0.86634044 | I42: {=1000000*I16/_FV(OP!$N$2,"Shares outstanding",TRUE)} -> 0.96418047 | J42: {=1000000*J16/_FV(OP!$N$2,"Shares outstanding",TRUE)} -> 1.0424044 | M42: =+E28/D28-1 -> 0.51937458 | N42: =+F28/E28-1 -> 0.23579418 | O42: =+G28/F28-1 -> 0.095944967 | P42: =+H28/G28-1 -> -0.040173783
C43: Consenso EPS
C44: E$/UN | H44: =$D$64/H16 -> 33.820958 | I44: =$D$64/I16 -> 30.388983
...

Sheet Cifras_en_Millones
A1: =Cifras_Originales!G3 -> Dassault Systemes SE (DSY)
A2: =Cifras_Originales!C2 -> Cifras en Millones de USD
A4: Resultados | B4: 2025 | C4: =Cifras_Originales!B5 -> 2024 | D4: =Cifras_Originales!C5 -> 2023 | E4: =Cifras_Originales!D5 -> 2022 | F4: =Cifras_Originales!E5 -> 2021 | G4: =Cifras_Originales!F5 -> 2020 | H4: =Cifras_Originales!G5 -> 2019 | I4: =Cifras_Originales!H5 -> 2018 | J4: =Cifras_Originales!I5 -> 2017 | ... M4: =Cifras_Originales!L5 -> 2014
A5: Ventas Netas | C5: =Cifras_Originales!B6 -> 6213.6 | D5: =Cifras_Originales!C6 -> 5951.4 | E5: =Cifras_Originales!D6 -> 5665.3 | F5: =Cifras_Originales!E6 -> 4860 | G5: =Cifras_Originales!F6 -> 4452.3 | H5: =Cifras_Originales!G6 -> 4018.2 | I5: =Cifras_Originales!H6 -> 3477.4 | J5: =Cifras_Originales!I6 -> 3228 | ... M5: =Cifras_Originales!L6 -> 2294.3
A6: Crecimiento vs. Año pasado | B6: =B5/C5-1 -> -1 | C6: =C5/D5-1 -> 0.044056861 | D6: =D5/E5-1 -> 0.050500415 | E6: =E5/F5-1 -> 0.16569959 | F6: =F5/G5-1 -> 0.091570649 | G6: =G5/H5-1 -> 0.10803345 | H6: =H5/I5-1 -> 0.15551849 | I6: =I5/J5-1 -> 0.077261462 | ... L6: =L5/M5-1 -> 0.23763239
A7: Utilidad Bruta | C7: =Cifras_Originales!B7 -> 5197.3 | D7: =Cifras_Originales!C7 -> 4980.4 | E7: =Cifras_Originales!D7 -> 4746 | F7: =Cifras_Originales!E7 -> 4069.7 | G7: =Cifras_Originales!F7 -> 3702.6 | H7: =Cifras_Originales!G7 -> 3384.6 | I7: =Cifras_Originales!H7 -> 2966.6 | J7: =Cifras_Originales!I7 -> 2754 | ... M7: =Cifras_Originales!L7 -> 1951
A8: porcentaje sobre ventas | B8: =B7/B5 -> #DIV/0! | C8: =C7/C5 -> 0.83643942 | D8: =D7/D5 -> 0.83684511 | E8: =E7/E5 -> 0.83773145 | F8: =F7/F5 -> 0.83738683 | G8: =G7/G5 -> 0.83161512 | H8: =H7/H5 -> 0.84231746 | I8: =I7/I5 -> 0.85310864 | ... M8: =M7/M5 -> 0.8503683
A9: Gastos de Operación | B9: =B5-B11 -> 0 | C9: =C5-C11 -> 4854 | D9: =D5-D11 -> 4709.5 | E9: =E5-E11 -> 4362.4 | F9: =F5-F11 -> 3840.6 | G9: =G5-G11 -> 3782.6 | H9: =H5-H11 -> 3205.4 | I9: =I5-I11 -> 2709.2 | ... M9: =M5-M11 -> 1863.5
A10: porcentaje sobre ventas | B10: =B9/B5 -> #DIV/0! | C10: =C9/C5 -> 0.78118965 | D10: =D9/D5 -> 0.79132641 | E10: =E9/E5 -> 0.77002101 | F10: =F9/F5 -> 0.79024691 | G10: =G9/G5 -> 0.84958336 | H10: =H9/H5 -> 0.79772037 | I10: =I9/I5 -> 0.77908782 | ... M10: =M9/M5 -> 0.81223031
