Workbook
Name Benchmark: [1]ControlsH!$B$3
Name BestConsOv: #REF!
Name Broker_Name: OFFSET(#REF!,0,0,[1]ControlsH!$E$5, 1)
Name calCODE: [1]ControlsH!$C$4
Name Chart_Benchmark_100_Size: OFFSET(#REF!, 0, 0, [1]ControlsH!$E$3, 1)
Name Chart_Date_Size: OFFSET(#REF!, 0, 0, [1]ControlsH!$E$3, 1)
Name Chart_Date_VAL1_Size: OFFSET(#REF!, 0, 0, [1]ControlsH!$I$3, 1)
Name Chart_Date_VAL2_Size: OFFSET(#REF!, 0, 0, [1]ControlsH!$I$5, 1)
Name Chart_Peer_100_Size: OFFSET(#REF!, 0, 0, [1]ControlsH!$E$3, 1)
Name Chart_Price_100_Size: OFFSET(#REF!, 0, 0, [1]ControlsH!$E$3, 1)
Name Chart_Price_Size: OFFSET(#REF!, 0, 0, [1]ControlsH!$E$3, 1)
Name Chart_VAL1_FY1_Size: OFFSET(#REF!, 0, 0, [1]ControlsH!$F$3, 1)
Name Chart_VAL1_FY2_Size: OFFSET(#REF!, 0, 0, [1]ControlsH!$G$3, 1)
Name Chart_VAL1_FY3_Size: OFFSET(#REF!, 0, 0, [1]ControlsH!$H$3, 1)
Name Chart_VAL2_FY1_Size: OFFSET(#REF!, 0, 0, [1]ControlsH!$F$5, 1)
Name Chart_VAL2_FY2_Size: OFFSET(#REF!, 0, 0, [1]ControlsH!$G$5, 1)
Name Chart_VAL2_FY3_Size: OFFSET(#REF!, 0, 0, [1]ControlsH!$H$5, 1)
Name Chart_Volume_Size: OFFSET(#REF!, 0, 0, [1]ControlsH!$E$3, 1)
Name compNAME: [1]ControlsH!$B$6
Name CURRENCY: [1]ControlsH!$B$9
Name currPRICE: [1]Overview!$E$19
Name custBenchmark: [1]Overview!$C$9
Name custED: #REF!
Name custSD: #REF!
Name dayCODE: [1]ControlsH!$C$5
Name ED: [1]ControlsH!$B$5
Name ESTBrokersItem: #REF!
Name ESTBrokersPeriod: #REF!
Name ESTDetailBroker: #REF!
Name ESTDetailBroker2: #REF!
Name ESTDetailPeriod: #REF!
Name EstDetPerO: #REF!
Name EstDetPerT: #REF!
Name FinancialsPeriod: #REF!
Name fundTICKER: [1]ControlsH!$B$15
Name GraphValRatio1: #REF!
Name GraphValRatio2: #REF!
Name Index1: #REF!
Name Lang: [1]Overview!$D$11
Name newCrncy: [1]ControlsH!$B$21:$B$199
Name newEstBrokerPeriod: #REF!
Name newEstBrokersItem: #REF!
Name newEstDetailBroker: #REF!
Name newEstDetailBroker2: #REF!
Name newEstDetailPeriod: #REF!
Name newFinancialsPeriod: #REF!
Name newOverviewCon: #REF!
Name newOverviewYear: #REF!
Name newOwners: #REF!
Name newPeersRatio: #REF!
Name newPeriod: #REF!
Name newValRatio1: #REF!
Name newValRatio2: #REF!
Name OverviewValRatioPeriod: [1]Overview!$D$30
Name PeerDate1: [1]Peers!$S$11
Name peerHist1: #REF!
Name PeerIndex: [1]ControlsH!$F$35:$F$36
Name Peers: OFFSET([1]Peers!$C$18,0,0,MAX(COUNTA([1]Peers!$C$18:$C$47),1),1)
Name peersWEIGHT: [1]ControlsH!$B$13
Name PERIODICITY: [1]ControlsH!$C$3

Sheet COVID-19 impact
A1: https://www.apple.com/newsroom/2020/03/apples-covid-19-response/ | G1: https://glg.it/articles/how-might-the-wuhan-coronavirus-impact-apples-supply-chain/ | N1: https://www.cnbc.com/2020/02/18/the-significance-of-apples-coronavirus-warning.html
A2: March 13 | G2: January 29 | N2: Ferbuary 18
A23: Otros:
A24: https://www.macrumors.com/guide/covid-19-coronavirus/

Sheet OP
B2: 45712 | C2: Analista: Research | D2: Report (quarter): 31/12/2024 | E2: #VALUE! | K2: {=_FV(E2,"Bolsa")} -> Nasdaq Stock Market | L2: SIC: Sí
B3: #VALUE! | D3: DESCRIPTION: Continuous Glucose Monitoring (CGM), Dexcom G6, Dexcom G7, Dexcom Follow, Dexcom Share, Insulin Management, Diabetes Care, Mobile App Integration, Remote Monitoring… Leader in CGM technology, revolutionizing diabetes management worldwide, founded in 1999, launched their first CGM System in 2006. (Current Market Cap: $34,6 Bn)
D4: CEO & BOARD: Kevin Sayer (67a; CEO d. 2011; Medical Device Innovation Consortium; ex Biosensors Intl. Grp., ex Specialty Laboratories, ex MiniMed); Steven R. Altman (63a; d. 2013; University of California at San Diego, Brain Corp, AJL Investments LLC, Yembo Inc., Course Key Inc., Amionx Inc., ex DLA Piper, ex Qualcomm, ex QTL); Nick Augustinos (65a, d. 2009; Aver Inc., ex Cardinal Health, ex Cisco Systems Inc., ex Audax Health); Richard Collins (66a; d. 2017; ex Golden Rule Insurance Corp., ex Golden Rule Financial Co., ex United Healthcare); Karen Dahut (61a; d. 2020; CEO Google Public Sector; ex Booz Allen Hamilton; ex Tech Data Corp.); Rimma Driscoll (52a; d. 2023; Zoetis Inc., Pumpkin Insurance Services Inc.; ex P&G Pharmaceuticals); Mark Foletta (63a; d. 2015; AMN Healthcare Services Inc, Enanta Pharmaceuticals Inc.; ex Forte Biosciences, ex Regulus Therapeutics Inc., ex Biocept Inc.); Bridgette Heller (64a; d. 2019; VNovartis AG, Aramark, Integral Ad Science Hold. Corp.; ex Wound Care, ex Danone, ex Kraft Foods); Kyle Malady (57a; d. 2020; Verizon Communications Inc.); Eric J. Topol (70a; d. 2009; National Institutes of Health, Gary & Mary West Wireless Health Institute; ex Volcano Coporation, ex Myokardia Inc.)
B5: Millones de USD
B6: Acción | D6: Liquidez y Solvencia | F6: =Segments!B2 -> Regions (2023) | I6: Rentabilidad (2022) | K6: Múltiplos
B7: Último Precio | C7: {=_FV(E2,"Preço")} -> 66.47 | D7: Activo: | E7: =Cifras_en_Millones!C45 -> 6264.5 | H7: %Vts; %Op.Mg.; D | I7: Año termina: | J7: 44926 | K7: Float: | L7: =387900000/C8 -> 0.98926952
B8: Outstanding Shares | C8: {=_FV(E2,"Ações em circulação",TRUE)} -> 392107500 | D8: Pasivo: | E8: =Cifras_en_Millones!C57 -> 4195.9 | F8: =Segments!B4 -> U.S. | H8: =+Segments!J4 -> 72%; N/A; 10% | K8: Insiders Own: | L8: 0.0109
B9: Market Cap. | C9: =C7*C8/1000000 -> 26063.386 | D9: Cash/Precio | E9: =1000000*C11/C8 -> 6.578298 | F9: =Segments!B5 -> International | H9: =+Segments!J5 -> 28%; N/A; 15% | I9: EBIT | J9: 391.2 | K9: b (Bloomberg; Yahoo) | L9: {=_FV(E2,"Beta")} -> 1.3985
B10: +Deuda Total | C10: 2587.4 | D10: Ebidta/CIF | E10: =Cifras_en_Millones!C19/Cifras_en_Millones!C14 -> -6.9590235 | F10: =Segments!#REF! -> #REF! | H10: =+Segments!#REF! -> #REF! | I10: +Dep&Amort | J10: =Cifras_Originales!C11 -> 172.3 | K10: Calificación (S&P) | L10: -
B11: -Cash | C11: 2579.4 | D11: Deuda/Ebidta | E11: =OP!C10/Cifras_en_Millones!C19 -> 3.2415435 | F11: =Segments!#REF! -> #REF! | H11: =+Segments!#REF! -> #REF! | I11: =EBIDTA | J11: =J9+J10 -> 563.5 | K11: Precio/Valor en libros | L11: =((C7*C8)/1000000)/(E7-E8) -> 12.599529
B12: =Enterprise Value | C12: =C9+C10-C11 -> 26071.386 | D12: "Otros activos"/Activo | E12: =Cifras_en_Millones!C44/Cifras_en_Millones!C45 -> 0.13127943 | F12: =Segments!#REF! -> #REF! | H12: =+Segments!#REF! -> #REF! | I12: Utilidad Neta | J12: =Cifras_Originales!C16 -> 341.2 | K12: FNP(p)/Activos | L12: =J18/E7 -> -0.061755394
B13: Tenencia % (nac/int'l) | C13: - | D13: Deuda/Activo | E13: =C10/E7 -> 0.41302578 | F13: =Segments!B7 -> Products (2023) | I13: UPA | J13: =1000000*J12/C8 -> 0.87016953 | K13: Precio/Utilidad(p) | L13: =C9/J17 -> 59.053779 | N13: =C10/J11 -> 4.5916593
B14: t liq. (Pos prom./Vol.) | C14: - | D14: Margen de Operación (p) | E14: =AVERAGE(Cifras_en_Millones!C11/Cifras_en_Millones!C5,Cifras_en_Millones!D11/Cifras_en_Millones!D5,Cifras_en_Millones!E11/Cifras_en_Millones!E5) -> 0.13600908 | H14: %Vts; D | I14: ROA | J14: =J12/E7 -> 0.05446564 | K14: EV/Activos | L14: =C12/E7 -> 4.1617664
B15: % Short | C15: 0.0252 | D15: Margen neto (p) | E15: =AVERAGE(Cifras_en_Millones!C23/C37,Cifras_en_Millones!E23/C35) -> 0.11903775 | F15: =Segments!B9 -> Sensor | H15: =+Segments!J9 -> 95%; N/A; 11% | I15: ROIC | J15: =J12/(E7-(E8-C10)) -> 0.073281787 | K15: EV/Ebidta (p) | L15: =C12/J16 -> 57.203362
B16: Semáforo ESG | D16: Ebidta/Ingresos(p) | E16: =AVERAGE(Cifras_en_Millones!C19/C37,Cifras_en_Millones!D19/C36,Cifras_en_Millones!E19/C35) -> 0.19227056 | F16: =Segments!B10 -> Hardware | H16: =+Segments!J10 -> 5%; N/A; -43% | I16: Ebidta(p) | J16: =AVERAGE(Cifras_en_Millones!B19:D19) -> 455.76667 | K16: Precio/FNP (p) | L16: =C9/J18 -> -67.370461
B17: E | D17: CIF/Deuda Neta Promedio | E17: =Cifras_en_Millones!C14/AVERAGE(Cifras_en_Millones!C59:M59) -> 0.52808471 | F17: =Segments!#REF! -> #REF! | H17: =+Segments!#REF! -> #REF! | I17: Utilidad Neta (p) | J17: =AVERAGE(Cifras_en_Millones!B23:D23) -> 441.35 | K17: Bonos 1;5;40a (USD) | L17: 4.0%; 4.4%; 5% | N17: 12
B18: S | F18: =Segments!#REF! -> #REF! | H18: =+Segments!#REF! -> #REF! | I18: FNP (p) | J18: =SUM(F35:F37)/3 -> -386.86667 | K18: TDY(p)/Precio | L18: =SUM(E35:E37)/(3*C9) -> -0.015053046
B19: G | F19: =Segments!#REF! -> #REF! | H19: =+Segments!#REF! -> #REF! | I19: Tax (p) últ. 5a | J19: 0.16 | K19: Div. Yield: | L19: =K33/C9 -> 0
B20: Tesis de inversión | H20: Acuerdo | I20: Supuestos de valuación | L20: DCF Value
B21: Dexcom is in a growing market, with the overall cases of diabetes and the need for CGM equipments growing. The company has provided steady YoY growth in revenue, while being able more recently to expand their manufactoring capabilities and also lauching share buybacks programs that benefit the shareholders. After the stock's meltdown after Q2 last year with holders jumping ship for more short-term profit stocks, the price should be more stable this year if Dexcom is able to keep the steady growth of the last decade. | H21: Mantener sin elevar posición | I21: VER DCF | L21: =DCFF!D66 -> 58.260765
B23: KSF | H23: PO / Precio Stand By | L23: =DCFF!D65 -> -0.12350286
B24: Dexcom shows a ROIC and ROA that are below the industry average, even though they aren't bad figures by themselves. Their operating margin is also a bit behind the market average over the last 3 years. | H24: =+DCFF!D66 -> 58.260765 | I24: Tasa de descuento: | J24: =DCFF!D47 -> 0.085 | K24: Buy
B25: Año | C25: Ingresos | D25: Margen Operativo | E25: Div.+Recompra | F25: FNP | G25: Deuda/Activo | H25: Depreciación | I25: Capex + Adq | J25: Cash Flow
B26: 2012 | C26: 99.9 | D26: =Cifras_Originales!M8/C26 -> -0.55755756 | E26: =Cifras_Originales!M18+Cifras_Originales!M22-81.9 -> -29.6 | F26: =Cifras_Originales!M18 -> 3.6 | G26: =(Cifras_Originales!M32+Cifras_Originales!M36)/Cifras_Originales!M27 -> 0.066037736 | H26: =Cifras_Originales!M11 -> 6.6 | I26: =Cifras_Originales!M13 -> 28.4 | K26: 2022 | L26: =K26-1 -> 2021
B27: =B26+1 -> 2013 | C27: 160 | D27: =Cifras_en_Millones!M11/C27 -> -0.180625 | E27: =Cifras_Originales!L18 -> 12 | F27: =Cifras_en_Millones!M30 -> 17.9 | G27: =Cifras_en_Millones!M61 -> 0.055510204 | H27: =Cifras_Originales!L11 -> 7 | I27: =Cifras_en_Millones!M35 -> 32.7 | J27: Profit | K27: =Cifras_en_Millones!D23 -> 341.2 | L27: =Cifras_en_Millones!E23 -> 216.9 | N27: =C27/C26-1 -> 0.6016016 | O27: =D27/D26-1 -> -0.67604241
B28: =B27+1 -> 2014 | C28: 259.2 | D28: =Cifras_en_Millones!L11/C28 -> -0.082947531 | E28: =Cifras_Originales!K18 -> 24 | F28: =Cifras_en_Millones!L30 -> 53 | G28: =Cifras_en_Millones!L61 -> 0.024918743 | H28: =Cifras_Originales!K11 -> 8.4 | I28: =Cifras_en_Millones!L35 -> 5 | J28: Cash Flow from Operations (BWC) | K28: 669.5 | L28: 442.5 | N28: =C28/C27-1 -> 0.62 | O28: =D28/D27-1 -> -0.54077492 | P28: =E28/E27-1 -> 1 | Q28: =F28/F27-1 -> 1.9608939 | R28: =H28/H27-1 -> 0.2 | S28: =I28/I27-1 -> -0.8470948 | BT28: 4303
B29: =B28+1 -> 2015 | C29: 402 | D29: =Cifras_en_Millones!K11/C29 -> -0.1420398 | E29: =Cifras_Originales!J18 -> 19.1 | F29: =Cifras_en_Millones!K30 -> 50.7 | G29: =Cifras_en_Millones!K61 -> 0.0078767123 | H29: =Cifras_Originales!J11 -> 10.8 | I29: =Cifras_en_Millones!K35 -> -34.7 | J29: Working Capital | K29: =Cifras_en_Millones!D18 -> 1829.5 | L29: =Cifras_en_Millones!E18 -> 2963.6 | N29: =C29/C28-1 -> 0.55092593 | O29: =D29/D28-1 -> 0.71240541 | P29: =E29/E28-1 -> -0.20416667 | Q29: =F29/F28-1 -> -0.043396226 | R29: =H29/H28-1 -> 0.28571429 | S29: =I29/I28-1 -> -7.94 | BT29: 3066
B30: =B29+1 -> 2016 | C30: 573.3 | D30: =Cifras_en_Millones!J11/C30 -> -0.11145997 | E30: =Cifras_Originales!I18 -> 10.4 | F30: =Cifras_en_Millones!J30 -> 18.9 | G30: =Cifras_en_Millones!J61 -> 0 | H30: =Cifras_Originales!I11 -> 15 | I30: =Cifras_en_Millones!J35 -> -111.6 | J30: Investing Activities | K30: -521.5 | L30: -216.1 | N30: =C30/C29-1 -> 0.4261194 | O30: =D30/D29-1 -> -0.21529059 | P30: =E30/E29-1 -> -0.45549738 | Q30: =F30/F29-1 -> -0.62721893 | R30: =H30/H29-1 -> 0.38888889 | S30: =I30/I29-1 -> 2.2161383 | BT30: 3283
B31: =B30+1 -> 2017 | C31: 718.5 | D31: =Cifras_en_Millones!I11/C31 -> -0.059151009 | E31: =Cifras_Originales!H18 -> 10.1 | F31: =Cifras_en_Millones!I30 -> 435 | G31: =Cifras_en_Millones!I61 -> 0.3623493 | H31: =Cifras_Originales!H11 -> 16.1 | I31: =Cifras_en_Millones!I35 -> -210.4 | J31: Capex | K31: =Cifras_Originales!C13 -> -236.6 | L31: =Cifras_Originales!D13 -> -389.2 | N31: =C31/C30-1 -> 0.25327054 | O31: =D31/D30-1 -> -0.46930714 | P31: =E31/E30-1 -> -0.028846154 | Q31: =F31/F30-1 -> 22.015873 | R31: =H31/H30-1 -> 0.073333333 | S31: =I31/I30-1 -> 0.88530466
B32: =B31+1 -> 2018 | C32: 1031.6 | D32: =Cifras_en_Millones!H11/C32 -> -0.18059325 | E32: =Cifras_Originales!G18 -> -89.2 | F32: =Cifras_en_Millones!H30 -> 747.8 | G32: =Cifras_en_Millones!H61 -> 0.52729645 | H32: =Cifras_Originales!G11 -> 29.1 | I32: =Cifras_en_Millones!H35 -> -206.9 | J32: Adquisiones | K32: -3.9 | L32: -30.2 | N32: =C32/C31-1 -> 0.43576896 | O32: =D32/D31-1 -> 2.0530883 | P32: =E32/E31-1 -> -9.8316832 | Q32: =F32/F31-1 -> 0.71908046 | R32: =H32/H31-1 -> 0.80745342 | S32: =I32/I31-1 -> -0.016634981
B33: =B32+1 -> 2019 | C33: 1476 | D33: =Cifras_en_Millones!G11/C33 -> 0.096409214 | E33: =Cifras_Originales!F18 -> 11.9 | F33: =Cifras_en_Millones!G30 -> 159.6 | G33: =Cifras_en_Millones!G61 -> 0.52680585 | H33: =Cifras_Originales!F11 -> 48.7 | I33: =Cifras_en_Millones!G35 -> -1195.2 | J33: Dividends | K33: 0 | L33: 0 | N33: =C33/C32-1 -> 0.43078713 | O33: =D33/D32-1 -> -1.5338473 | P33: =E33/E32-1 -> -1.1334081 | Q33: =F33/F32-1 -> -0.78657395 | R33: =H33/H32-1 -> 0.67353952 | S33: =I33/I32-1 -> 4.7767037
B34: =B33+1 -> 2020 | C34: 1926.7 | D34: =Cifras_en_Millones!F11/C34 -> 0.15544714 | E34: =Cifras_Originales!E18 -> 15.3 | F34: =Cifras_en_Millones!F30 -> 1189.7 | G34: =Cifras_en_Millones!F61 -> 0.47299849 | H34: =Cifras_Originales!E11 -> 67.1 | I34: =Cifras_en_Millones!F35 -> -1217 | J34: Stock Repurchases | K34: =Cifras_en_Millones!D29 -> -535.2 | L34: =Cifras_en_Millones!E29 -> 20.3 | N34: =C34/C33-1 -> 0.3053523 | O34: =D34/D33-1 -> 0.61236806 | P34: =E34/E33-1 -> 0.28571429 | Q34: =F34/F33-1 -> 6.4542607 | R34: =H34/H33-1 -> 0.37782341 | S34: =I34/I33-1 -> 0.018239625
B35: =B34+1 -> 2021 | C35: 2448.5 | D35: =Cifras_en_Millones!E11/C35 -> 0.10855626 | E35: =Cifras_Originales!D18 -> 20.3 | F35: =Cifras_en_Millones!E30 -> 43.8 | G35: =Cifras_en_Millones!E61 -> 0.47444915 | H35: =Cifras_Originales!D11 -> 120 | I35: =Cifras_en_Millones!E35 -> -226.2 | J35: Endeudamiento Neto | K35: =Cifras_en_Millones!D59 -> -128.1 | L35: =Cifras_en_Millones!E59 -> -390.6 | N35: =C35/C34-1 -> 0.27082576 | O35: =D35/D34-1 -> -0.30165161 | P35: =E35/E34-1 -> 0.32679739 | Q35: =F35/F34-1 -> -0.963184 | R35: =H35/H34-1 -> 0.78837556 | S35: =I35/I34-1 -> -0.81413311
B36: =B35+1 -> 2022 | C36: 2909.8 | D36: =Cifras_en_Millones!D11/C36 -> 0.13444223 | E36: =Cifras_Originales!C18 -> -535.2 | F36: =Cifras_en_Millones!D30 -> -810.2 | G36: =Cifras_en_Millones!D61 -> 0.43179331 | H36: =Cifras_Originales!C11 -> 172.3 | I36: =Cifras_en_Millones!D35 -> -509.1 | J36: Otros Financiemientos | K36: -17.3 | L36: -9.9 | N36: =C36/C35-1 -> 0.18840106 | O36: =D36/D35-1 -> 0.23845673
B37: =B36+1 -> 2023 | C37: 3622.3 | D37: =Cifras_en_Millones!C11/C37 -> 0.16500566 | E37: =Cifras_Originales!B18 -> -662.1 | F37: =Cifras_en_Millones!C30 -> -394.2 | G37: =Cifras_en_Millones!C61 -> 0.44108867 | H37: =Cifras_Originales!B11 -> 202.5 | I37: =Cifras_en_Millones!C35 -> -192 | N37: =C37/C36-1 -> 0.24486219 | O37: =D37/D36-1 -> 0.22733504
B38: 2024 Est. | C38: =DCFF!H6 -> 4033 | D38: 0.1637
B39: CAGR | C39: =(C37/C32)^(1/5)-1 -> 0.28556671 | D39: =(D37/D26)^(1/11)-1 -> -1.8952166 | J39: FX | K39: 0 | L39: 0
B40: AAG | C40: =AVERAGE(N27:N37) -> 0.39344681 | D40: =AVERAGE(O27:O37) -> 0.0097036007 | J40: D Cash and Equivalents | K40: =K28+K29+K30+K33+K34+K35+K36+K39 -> 1296.9 | L40: =L28+L29+L30+L33+L34+L35+L36+L39 -> 2809.8
B41: CVAR | C41: =STDEV(C26:C37)/AVERAGE(C26:C37) -> 0.90544539 | D41: =STDEV(D26:D37)/AVERAGE(D26:D37) -> -3.805614 | J41: Inv/D Vts | K41: =SUM(I33:I37)/(C37-C32) -> -1.2890339 | L41: =(SUM(I33:I37)-SUM(H33:H37))/(C37-C32) -> -1.524723
B42: Último Año | C42: =C37/C36-1 -> 0.24486219 | D42: =D37/D36-1 -> 0.22733504 | J42: t inversiones; t adq. neto dep. | K42: =K41/E14 -> -9.477557 | L42: =L41/E14 -> -11.21045
...

Sheet Peers
A2: Multiplos (USD) | B2: DXCM | C2: MDT | D2: ABT | E2: SENS
B3: Dexcom (2023) | C3: Medtronic | D3: Abbott Laboratories | E3: Senseonics Holdings, Inc.
A4: Ventas | B4: 3622300 | C4: 31227000 | D4: 40109000 | E4: 22390
A5: Crecimiento (1S23/1S22) | B5: 21.7% | C5: -0.056 | D5: 0.115 | E5: 0.366
A6: Crecimiento (1S23/1S19) | B6: 0.2716 | C6: -0.022 | D6: 0.2531 | E6: 0.47
A7: Deuda | B7: 122278 | C7: 82110 | D7: 26772 | E7: 100504
A8: Activos | B8: 323888 | C8: 301311 | D8: 319616 | E8: 321195
A9: Deuda/Activos | B9: =OP!C10/OP!E7 -> 0.41302578 | C9: 0.27 | D9: 0.21 | E9: 0.35
A10: Deuda/EBITDA | B10: =OP!C10/Cifras_en_Millones!C19 -> 3.2415435 | C10: 2.8 | D10: 1.47 | E10: -1
A11: (Capex + Adq.)/Revenue | C11: 0.02 | D11: 0.05 | E11: 0.02
A12: ROA (p) | B12: 0.0874 | C12: 4.33% | D12: 7.61% | E12: -40.31%
A13: ROIC (p) | B13: 19.30% | C13: 5.26% | D13: 10.63% | E13: -272.41%.
A14: Margen Operativo | B14: 0.1651 | C14: 0.1745 | D14: 0.1615 | E14: -345.45%
A15: Margen Operativo 2022 | B15: 0.1344 | C15: 0.1859 | D15: 0.1916 | E15: -405.88%
A16: Float | B16: 387.9 M | C16: 1.28B | D16: 1.72B | E16: 562.95M
A17: b | B17: 0.92 | C17: 0.66 | D17: 0.59 | E17: 2
A18: Precio/Utilidad | B18: 21.09 | C18: 1.83 | D18: 5.09 | E18: 5.81
A19: Precio/Ventas | B19: 15.60 | C19: 2.98 | D19: 4.82 | E19: 16.49
A20: EV/Activos | B20: =OP!C12/OP!E7 -> 4.1617664 | C20: 3.52 | D20: 4.99 | E20: 11.19
A21: EV/Ebitda | B21: =OP!C12/OP!J11 -> 46.266878 | C21: 12.56 | D21: 19.84 | E21: -15.03
A22: Div. Yield: | B22: 0 | C22: 3.41% | D22: 1.85% | E22: 0
B24: *Nota: Estos múltiplos no consideran el promedio de los últimos 3 años, únicamente valores del último año reportado
B25: **Cifras en USD
A27: (You can make up a table with different indicators in order to link them to the multiples/ratios. At the end, put the table unvisible with white color)

Sheet Segments
B2: Regions (2023)
C3: 2024 | D3: =C3-1 -> 2023 | E3: Ut. Operativa | F3: % Vts | G3: Margen | H3: Crec
B4: U.S. | C4: 2889.8 | D4: 2625.3 | E4: N/A | F4: =C4/(C4+C5) -> 0.71653856 | G4: N/A | H4: =C4/D4-1 -> 0.10075039 | J4: =IF(C4="","",IF(F4=0,"NA",TEXT(F4,"0%"))&"; "&IF(G4=0,"NA",TEXT(G4,"0.0%"))&"; "&IF(H4=0,"NA",TEXT(H4,"0%"))) -> 72%; N/A; 10%
B5: International | C5: 1143.2 | D5: 997 | E5: N/A | F5: =C5/(C4+C5) -> 0.28346144 | G5: N/A | H5: =C5/D5-1 -> 0.14663992 | J5: =IF(C5="","",IF(F5=0,"NA",TEXT(F5,"0%"))&"; "&IF(G5=0,"NA",TEXT(G5,"0.0%"))&"; "&IF(H5=0,"NA",TEXT(H5,"0%"))) -> 28%; N/A; 15%
B6: TOTAL | C6: =SUM(C4:C5) -> 4033 | D6: =SUM(D4:D5) -> 3622.3 | E6: =SUM(E4:E5) -> 0 | F6: =C6/SUM($C$4:$C$5) -> 1 | G6: =E6/C6 -> 0 | H6: =C6/D6-1 -> 0.113381
B7: Products (2023)
C8: 2024 | D8: 2023 | E8: Ut. Op. | F8: % Vts | G8: Margen | H8: Crec
B9: Sensor | C9: 4033 | D9: 3622.3 | E9: N/A | F9: =C9/(C9+C10) -> 0.9501932 | G9: N/A | H9: =(C9/D9)-1 -> 0.113381 | J9: =IF(C9="","",IF(F9=0,"NA",TEXT(F9,"0%"))&"; "&IF(G9=0,"NA",TEXT(G9,"0.0%"))&"; "&IF(H9=0,"NA",TEXT(H9,"0%"))) -> 95%; N/A; 11%
B10: Hardware | C10: 211.4 | D10: 371.6 | E10: N/A | F10: =C10/(C10+C9) -> 0.049806804 | G10: N/A | H10: =(C10/D10)-1 -> -0.43110872 | J10: =IF(C10="","",IF(F10=0,"NA",TEXT(F10,"0%"))&"; "&IF(G10=0,"NA",TEXT(G10,"0.0%"))&"; "&IF(H10=0,"NA",TEXT(H10,"0%"))) -> 5%; N/A; -43%
B11: TOTAL | C11: =SUM(C9:C10) -> 4244.4 | D11: =SUM(D9:D10) -> 3993.9 | E11: =SUM(E9:E10) -> 0 | F11: =C11/SUM(C9:C10) -> 1 | G11: =E11/C11 -> 0 | H11: =C11/D11-1 -> 0.062720649
L17: Dexcom G7
P19: Dexcom G6

Sheet Acuerdo
A1: Invertir
A2: NO invertir
A3: Mantener sin elevar posición
A4: Mantener (y seguir comprando)
A5: Liquidar
A6: PENDIENTE

Sheet ESG
B2: Análisis ESG | J2: PARÁMETROS
C3: Impacto | D3: ¿Reporta? | E3: Ranking | F3: Mitigación | G3: Semáforo | H3: Comentarios | J3: IMPACTO | L3: RANKING | M3: MITIGACIÓN
B4: Ambiental | J4: NONE | K4: 0 | L4: "Best in class" | M4: Is there evidence of progam/plan/etc…
B5: Emisiones directas CO2 | C5: low | D5: yes | E5: medium high | F5: yes | H5: committed to TCFD( carbon emissions, extreme weather events, …) | J5: LOW | K5: 1 | L5: Medium high
B6: Uso total de agua | C6: low | D6: yes | E6: medium high | F6: yes | H6: disclose water usage but not committed to TNFD (biodiversity loss, deforestation, and water scarcity) | J6: MEDIUM | K6: 2 | L6: Medium
B7: Total Energy Consumption | C7: medium | D7: yes | E7: villain | F7: yes | H7: Production is nearly 50% more energy efficient in 2023 vs. 2022 although worst among peers | J7: HIGH | K7: 3 | L7: "Villain"
B8: Waste Management | C8: medium | D8: yes | E8: medium | F8: yes | H8: Has waste reduction policy, however, 43% of waste still ended up in landfills, indicating ongoing environmental challenges.
B9: Land Degradation/Deforestation/Biodiversity loss/Animal sufering/… | C9: none | D9: no | E9: - | F9: no | H9: Negative effect is nil | J9: TRAFFIC LIGHTS
B10: Social
B11: % Rotación de empleados | C11: medium | D11: no | E11: medium | F11: no | H11: N/A
B12: Sueldos y compensaciones | C12: medium | D12: yes | E12: medium | F12: yes | H12: Dexcom offers Retirement Savings,Life/Death and Disability Insurance, Mental Health Assistance, Employee Stock Purchase Plan
B13: Temas de reputación | C13: high | D13: no | E13: medium | F13: no | H13: FDA sent a warning letter to Dexcom for making unathorized changes to its products and falling to comply with quality during inspections
B14: Seguridad laboral | C14: medium | D14: yes | E14: medium | F14: yes | H14: Require ccupational Health and Safety training for employees, but Total Recordable Incident Rate (TRIR) and Days Away, Restricted, or Transferred (DART) rates increased in 2023
B15: Daños a la salud | C15: high | D15: no | E15: medium | F15: no | H15: N/A
B16: PXP? | D16: yes | E16: medium | F16: yes | H16: defined contribution 401(k) plan
B17: Supply chain | C17: high | D17: yes | E17: medium high | F17: no | H17: Dexcom is expanding global manufacturing capacity, especially with new facilities in Malaysia and Ireland, to scale production and meet growing demand.
B18: Community involvement | C18: low | D18: yes | E18: medium | F18: yes | H18: The Dexcom Warrior program is a global community of over 25,000 Dexcom CGM users who share their personal diabetes journeys to inspire others, raise awareness, and advocate for broader access to diabetes care.
B19: Public Sector | C19: high | D19: yes | E19: medium | F19: yes | H19: Dexcom works with the Centers for Medicare and Medicaid Services, which expanded coverage in 2023 to include people with type 2 diabetes using basal insulin and individuals at risk of hypoglycemia.
B20: Litigios | C20: high | D20: no | E20: medium | F20: no | H20: Dexcom and Abbott have been involved in patent disputes over continuous glucose monitoring technologies. In December 2024, they settled all litigation, agreeing to a 10-year cross-licensing deal without financial compensation.
B21: Gobierno
B22: Diversidad (Género, edad, industria, región) | E22: medium high | F22: yes | H22: launched a dedicated regional program in EMEA
B23: % independientes | E23: medium high | F23: no | H23: 10 of 11 are independent (except the CEO)
B24: tiempo promedio como consejeros independientes | E24: medium high | F24: no | H24: 4 members have served 0–5 years, 2 members have served 6–10 years, 5 members have served 11+ years
B25: Salidas recientes de consejeros/C-level executives? | E25: medium | F25: no | H25: In October 2024, Dexcom announced the retirement of Chief Commercial Officer Teri Lawver, effective at the end of the year
B26: CEO/Chairman | E26: villain | F26: no | H26: Abbott and Medtronic also have the same CEO/Chairman
B27: Transparencia (segmentos, fuente de riqueza, adquisiciones, otros) | E27: medium high | F27: no | H27: Do not publish segments, as well as its peers
B28: Tiempo que tardan en reportar luego del final del trimestre/año | E28: medium | F28: no | H28: 6-7 weeks for the Form 10-K and 12 weeks for Sustainability Report:
B29: Participación adicional del CEO en otros consejos o excesiva del Ch. | E29: medium high | F29: no | H29: N/A
B30: Auditoría/Consultoría | D30: yes | E30: medium | F30: no | H30: Dexcom's manufacturing facilities undergo third-party audit programs concentrating on manufacturing processes, quality management systems, and product quality.
B31: Esquemas de compensación al management | D31: yes | E31: medium | F31: no | H31: mix of salary, stock incentives, and performance-based rewards:

Sheet DCF
A1: Discounted Cash Flow
A3: Ventas | E3: Margen Operativo
A16: Inversiones | E16: Utilidad Neta
D31: 0.001 | E31: =1/((1+$B$59+$D31)^(E35-2021)) -> 0.92250923 | F31: =1/((1+$B$59+$D31)^(F35-2021)) -> 0.85102327 | G31: =1/((1+$B$59+$D31)^(G35-2021)) -> 0.78507682 | H31: =1/((1+$B$59+$D31)^(H35-2021)) -> 0.72424061 | I31: =1/((1+$B$59+$D31)^(I35-2021)) -> 0.66811864 | J31: =1/((1+$B$59+$D31)^(J35-2021)) -> 0.61634561 | K31: =1/((1+$B$59+$D31)^(K35-2021)) -> 0.56858451 | L31: =1/((1+$B$59+$D31)^(L35-2021)) -> 0.52452446 | ... AC31: =1/((1+$B$59+$D31)^(AC35-2021)) -> 0.13312755
D32: 0.005 | E32: =1/((1+$B$59+$D32)^(E35-2021)) -> 0.91911765 | F32: =1/((1+$B$59+$D32)^(F35-2021)) -> 0.84477725 | G32: =1/((1+$B$59+$D32)^(G35-2021)) -> 0.77644968 | H32: =1/((1+$B$59+$D32)^(H35-2021)) -> 0.7136486 | I32: =1/((1+$B$59+$D32)^(I35-2021)) -> 0.65592702 | J32: =1/((1+$B$59+$D32)^(J35-2021)) -> 0.6028741 | K32: =1/((1+$B$59+$D32)^(K35-2021)) -> 0.55411223 | L32: =1/((1+$B$59+$D32)^(L35-2021)) -> 0.50929433 | ... AC32: =1/((1+$B$59+$D32)^(AC35-2021)) -> 0.12141647
D33: Normal | E33: =1/((1+$B$59)^(E35-2021)) -> 0.92336103 | F33: =1/((1+$B$59)^(F35-2021)) -> 0.8525956 | G33: =1/((1+$B$59)^(G35-2021)) -> 0.78725355 | H33: =1/((1+$B$59)^(H35-2021)) -> 0.72691926 | I33: =1/((1+$B$59)^(I35-2021)) -> 0.67120892 | J33: =1/((1+$B$59)^(J35-2021)) -> 0.61976816 | K33: =1/((1+$B$59)^(K35-2021)) -> 0.57226977 | L33: =1/((1+$B$59)^(L35-2021)) -> 0.5284116 | ... AC33: =1/((1+$B$59)^(AC35-2021)) -> 0.13623496
B35: 2019 (Real) | C35: 2020 (Real) | D35: 2021 | E35: =D35+1 -> 2022 | F35: =E35+1 -> 2023 | G35: =F35+1 -> 2024 | H35: =G35+1 -> 2025 | I35: =H35+1 -> 2026 | J35: =I35+1 -> 2027 | K35: =J35+1 -> 2028 | L35: =K35+1 -> 2029 | ... AC35: =AB35+1 -> 2046
A36: Crecimiento | B36: =OP!N34 -> 0.3053523 | C36: =OP!N35 -> 0.27082576 | D36: 0.35 | E36: 0.034 | F36: 0.095 | G36: 0.095 | H36: 0.095 | I36: 0.095 | J36: 0.095 | K36: 0.08 | L36: 0.06 | M36: 0.05 | N36: 0.04 | O36: 0.035 | P36: 0.035 | Q36: 0.035 | R36: 0.035 | S36: 0.035 | T36: 0.035 | U36: 0.035 | V36: 0.035 | W36: 0.035 | X36: 0.035 | Y36: 0.035 | Z36: 0.035 | AA36: 0.035 | AB36: 0.035 | AC36: 0.035
A37: Ventas | B37: =OP!C34 -> 1926.7 | C37: =OP!C35 -> 2448.5 | D37: =OP!C34*(1+D36) -> 2601.045 | E37: =D37*(1+E36) -> 2689.4805 | F37: =E37*(1+F36) -> 2944.9812 | G37: =F37*(1+G36) -> 3224.7544 | H37: =G37*(1+H36) -> 3531.1061 | I37: =H37*(1+I36) -> 3866.5611 | J37: =I37*(1+J36) -> 4233.8844 | K37: =J37*(1+K36) -> 4572.5952 | L37: =K37*(1+L36) -> 4846.9509 | ... AC37: =AB37*(1+AC36) -> 8867.4042
A38: Margen Operativo | B38: =+OP!D34 -> 0.15544714 | C38: =+OP!D35 -> 0.10855626 | D38: =108166.4/365513.2 -> 0.29593022 | E38: =108162.8/377959.8 -> 0.28617541 | F38: 0.27 | G38: 0.275 | H38: 0.26 | I38: 0.255 | J38: 0.25 | K38: 0.25 | L38: 0.25 | M38: 0.25 | N38: 0.25 | O38: 0.25 | P38: 0.25 | Q38: 0.25 | R38: 0.25 | S38: 0.25 | T38: 0.25 | U38: 0.25 | V38: 0.25 | W38: 0.25 | X38: 0.25 | Y38: 0.25 | Z38: 0.25 | AA38: 0.25 | AB38: 0.25 | AC38: 0.25
A39: EBIT | B39: 63930 | C39: 66288 | D39: =D37*D38 -> 769.72781 | E39: =E37*E38 -> 769.66319 | F39: =F37*F38 -> 795.14492 | G39: =G37*G38 -> 886.80746 | H39: =H37*H38 -> 918.08758 | I39: =I37*I38 -> 985.97309 | J39: =J37*J38 -> 1058.4711 | K39: =K37*K38 -> 1143.1488 | ... AC39: =AC37*AC38 -> 2216.8511
A40: Dep&Amort | B40: =OP!H34 -> 67.1 | C40: =OP!H35 -> 120 | D40: 11000 | E40: =D40*(1+E36*$H$59) -> 11374 | F40: =E40*(1+F36*$H$59) -> 12454.53 | G40: =F40*(1+G36*$H$59) -> 13637.71 | H40: =G40*(1+H36*$H$59) -> 14933.293 | I40: =H40*(1+I36*$I$59) -> 16351.956 | J40: =I40*(1+J36*$I$59) -> 17905.391 | K40: =J40*(1+K36*$I$59) -> 19337.823 | L40: =K40*(1+L36*$I$59) -> 20498.092 | M40: =L40*(1+M36*$I$59) -> 21522.997 | N40: =M40*(1+N36*$I$59) -> 22383.917 | O40: =N40*(1+O36*$I$59) -> 23167.354 | P40: =O40*(1+P36*$I$59) -> 23978.211 | ... AC40: =AB40*(1+AC36*$I$59) -> 37500.868
A41: EBIDTA | B41: =+B39+B40 -> 63997.1 | C41: =+C39+C40 -> 66408 | D41: =D39+D40 -> 11769.728 | E41: =E39+E40 -> 12143.663 | F41: =F39+F40 -> 13249.675 | G41: =G39+G40 -> 14524.518 | H41: =H39+H40 -> 15851.38 | I41: =I39+I40 -> 17337.929 | J41: =J39+J40 -> 18963.863 | K41: =K39+K40 -> 20480.972 | ... AC41: =AC39+AC40 -> 39717.72
A42: CIF | B42: -1385 | C42: -890 | D42: =(C48)*$H$60 -> -1124.36 | E42: =(D48)*$H$60 -> -1113.1164 | F42: =(E48)*$H$60 -> -1113.1164 | G42: =(F48)*$H$60 -> -1113.1164 | H42: =(G48)*$H$60 -> -1113.1164 | I42: =(H48)*$H$60 -> -1113.1164 | J42: =(I48)*$H$60 -> -1113.1164 | K42: =(J48)*$H$60 -> -1113.1164 | ... AC42: =(AB48)*$H$60 -> -1113.1164
A43: Otros Gastos | B43: =-422-2817 -> -3239 | C43: =87-3634 -> -3547 | D43: =-C43*(1+D36) -> 4788.45 | E43: =D43*(1+E36*0.5) -> 4869.8537 | F43: =E43*(1+F36*0.5) -> 5101.1717 | G43: =F43*(1+G36*0.5) -> 5343.4774 | H43: =G43*(1+H36*0.5) -> 5597.2925 | I43: =H43*(1+I36*0.5) -> 5863.1639 | J43: =I43*(1+J36*0.5) -> 6141.6642 | K43: =J43*(1+K36*0.5) -> 6387.3308 | L43: =K43*(1+L36*0.5) -> 6578.9507 | ... AC43: =AB43*(1+AC36*0.5) -> 8922.7133
A44: Utilidad antes de Impuestos | B44: =B39-B42-B43 -> 68554 | C44: =C39-C42-C43 -> 70725 | D44: =D39-D42-D43 -> -2894.3622 | E44: =E39-E42-E43 -> -2987.0741 | F44: =F39-F42-F43 -> -3192.9104 | G44: =G39-G42-G43 -> -3343.5535 | H44: =H39-H42-H43 -> -3566.0886 | I44: =I39-I42-I43 -> -3764.0744 | ... AC44: =AC39-AC42-AC43 -> -5592.7458
A45: ISR & PTU | B45: 10481 | C45: 9680 | D45: =$H$61*D44 -> -607.81606 | E45: =$H$61*E44 -> -627.28555 | F45: =$H$61*F44 -> -670.51118 | G45: =$I$61*G44 -> -769.0173 | H45: =$I$61*H44 -> -820.20037 | I45: =$I$61*I44 -> -865.73712 | J45: =$I$61*J44 -> -913.11764 | K45: =$I$61*K44 -> -950.14508 | L45: =$I$61*L44 -> -978.44221 | M45: =$I$61*M44 -> -1002.3362 | N45: =$I$61*N44 -> -1021.6506 | ... AC45: =$I$61*AC44 -> -1286.3315
A46: Utilidad Neta | B46: =B44-B45 -> 58073 | C46: =C44-C45 -> 61045 | D46: =D44-D45 -> -2286.5461 | E46: =E44-E45 -> -2359.7885 | F46: =F44-F45 -> -2522.3992 | G46: =G44-G45 -> -2574.5362 | H46: =H44-H45 -> -2745.8882 | I46: =I44-I45 -> -2898.3373 | ... AC46: =AC44-AC45 -> -4306.4143
A47: Inversiones y Capex | B47: =OP!I34 -> -1217 | C47: =OP!I35 -> -226.2 | D47: 10000 | E47: =D47*(1+E36*$H$62) -> 10408 | F47: =E47*(1+F36*$H$62) -> 11594.512 | G47: =F47*(1+G36*$H$62) -> 12916.286 | H47: =G47*(1+H36*$H$62) -> 14388.743 | I47: =H47*(1+I36*$H$62) -> 16029.06 | J47: =I47*(1+J36*$H$62) -> 17856.373 | K47: =J47*(1+K36*$H$62) -> 19570.584 | L47: =K47*(1+L36*$H$62) -> 20979.666 | ... AC47: =AB47*(1+AC36*$H$62) -> 43199.777
A48: Deuda + Lease Liabilities | B48: 108047 | C48: 112436 | D48: =C48*0.99 -> 111311.64 | E48: =D48 -> 111311.64 | F48: =E48 -> 111311.64 | G48: =F48 -> 111311.64 | H48: =G48 -> 111311.64 | I48: =H48 -> 111311.64 | J48: =I48 -> 111311.64 | K48: =J48 -> 111311.64 | L48: =K48 -> 111311.64 | ... AC48: =AB48 -> 111311.64
A49: Deuda/EBITDA | B49: =B48/B41 -> 1.6883109 | C49: =C48/C41 -> 1.6931093 | D49: =D48/D41 -> 9.4574524 | E49: =E48/E41 -> 9.1662325
A50: FNP | B50: =OP!F34 -> 1189.7 | C50: =OP!F35 -> 43.8 | D50: =D41-D42-D43-D45-D47+D48-C48 -> -2410.9061 | E50: =E41-E42-E43-E45-E47+E48-D48 -> -1393.7885 | F50: =F41-F42-F43-F45-F47+F48-E48 -> -1662.3812 | G50: =G41-G42-G43-G45-G47+G48-F48 -> -1853.1122 | H50: =H41-H42-H43-H45-H47+H48-G48 -> -2201.3384 | I50: =I41-I42-I43-I45-I47+I48-H48 -> -2575.4414 | J50: =J41-J42-J43-J45-J47+J48-I48 -> -3007.9401 | K50: =K41-K42-K43-K45-K47+K48-J48 -> -3413.682 | ... AC50: =AC41-AC42-AC43-AC45-AC47+AC48-AB48 -> -10005.323
A51: F(t) | B51: 0 | C51: 0 | D51: =C51*(1+$B$59)+D50 -> -2410.9061 | E51: =D51*(1+$B$59)+E50 -> -4004.7999 | F51: =E51*(1+$B$59)+F50 -> -5999.5794 | G51: =F51*(1+$B$59)+G50 -> -8350.6567 | H51: =G51*(1+$B$59)+H50 -> -11245.1 | I51: =H51*(1+$B$59)+I50 -> -14753.884 | J51: =I51*(1+$B$59)+J50 -> -18986.397 | K51: =J51*(1+$B$59)+K50 -> -23975.95 | ... AC51: =AB51*(1+$B$59)+AC50 -> -323243.9
AB52: =AB51-AB48 -> -400543.93 | AC52: =AC50/(B59-AC36) -> -208444.23
A53: EPS | C53: =1000000*C46/OP!$C$8 -> 155.68435 | D53: =1000000*D46/OP!$C$8 -> -5.8314267 | E53: =1000000*E46/OP!$C$8 -> -6.0182182 | F53: =1000000*F46/OP!$C$8 -> -6.4329277
A54: Consenso EPS | C54: 3.3 | D54: 5.6 | E54: 5.6
A55: E$/UN | D55: =$B$61/D46 -> 36.284193 | E55: =$B$61/E46 -> 35.158016 | F55: =$B$61/F46 -> 32.891495
A56: EEV/EBIDA | D56: =($B$61+D48-D51)/D41 -> 2.613235 | E56: =($B$61+E48-E51)/E41 -> 2.6640197 | F56: =($B$61+F48-F51)/F41 -> 2.5921947
C58: "TELP" | D58: CER | E58: D Analista | H58: CP | I58: LP
A59: Tasa de descuento: | B59: =SUM(C59:E59) -> 0.083 | C59: 0.0307 | D59: 0.0523 | E59: 0 | G59: Factor D&A | H59: 1 | I59: 1
G60: Factor CIF | H60: -0.01
A61: VPN*@i% | B61: =C62+C63 -> -82965.482 | C61: Normal | D61: =D31 -> 0.001 | E61: =D32 -> 0.005 | G61: Factor ISR | H61: 0.21 | I61: 0.23
A62: DCF 25Y | B62: =C62/B61 -> 0.65772039 | C62: =AB52/(1+B59)^25 -> -54568.089 | D62: =SUMPRODUCT(E50:AB50,E31:AB31) -> -39808.984 | E62: =SUMPRODUCT(E50:AB50,E32:AB32) -> -38060.962 | G62: Factor inv | H62: 1.2
A63: Perpetuidad | B63: =1-B62 -> 0.34227961 | C63: =AC52/(1+B59)^25 -> -28397.393 | D63: =(AC50/($B$59+D31-$AC$36))*AC31 -> -27183.351 | E63: =(AC50/($B$59+D32-$AC$36))*AC32 -> -22920.964 | G63: Suma D&A | H63: =SUM(40:40) -> 628616.67
A64: VPN/Acción | B64: =1000000*B61/OP!C8 -> -211.58861 | D64: =1000000*SUM(D62:D63)/OP!C8 -> -170.85196 | E64: =1000000*SUM(E62:E63)/OP!C8 -> -155.52349 | G64: Suma Inv. | H64: =SUM(47:47) -> 671402.19
B65: =B64/OP!C7-1 -> -4.1832197 | D65: =D64/B64-1 -> -0.19252762 | E65: =E64/B64-1 -> -0.26497232 | G65: Inv.+Goodwill | H65: =SUM(47:47)+(OP!E12*OP!E7) -> 672224.59
A67: Duración | B67: =B62*D68+B63*D69 -> 21.120319 | E67: 1 | F67: 2 | G67: 3 | H67: 4 | I67: 5 | J67: 6 | K67: 7 | L67: 8 | M67: 9 | N67: 10 | O67: 11 | P67: 12 | Q67: 13 | R67: 14 | S67: 15 | T67: 16 | U67: 17 | V67: 18 | W67: 19 | X67: 20 | Y67: 21 | Z67: 22 | AA67: 23 | AB67: 24 | AC67: 25
A68: 0.001 | B68: =-$B$67*A68 -> -0.021120319 | D68: =SUM(E68:AB68)/SUMPRODUCT(E50:AB50,E33:AB33) -> 12.311004 | E68: =E67*E50*E33 -> -1286.97 | F68: =F67*F50*F33 -> -2834.6778 | G68: =G67*G50*G33 -> -4376.6075 | H68: =H67*H50*H33 -> -6400.781 | I68: =I67*I50*I33 -> -8643.2961 | J68: =J67*J50*J33 -> -11185.353 | K68: =K67*K50*K33 -> -13674.829 | L68: =L67*L50*L33 -> -15882.906 | ... AC68: =AC67*AC50*AC33 -> -34076.872
A69: 0.005 | B69: =-$B$67*A69 -> -0.10560159 | D69: =(1+B59)/B59+AC67 -> 38.048193

Sheet DCFF
C1: VALUATION MODEL
C2: Año fiscal de Dexcom cierra en septiembre
D3: =D19/D6 -> 0.061971246 | E3: =E19/E6 -> 0.04631407 | F3: =F19/F6 -> 0.043473778 | G3: 0 | H3: 0.25 | I3: =H3+1 -> 1.25 | J3: =I3+1 -> 2.25 | K3: =J3+1 -> 3.25 | L3: =K3+1 -> 4.25 | M3: =L3+1 -> 5.25 | N3: =M3+1 -> 6.25 | O3: =N3+1 -> 7.25 | P3: =O3+1 -> 8.25 | ... AF3: =AE3+1 -> 24.25
A4: Section | B4: Line # | C4: ITEM | D4: 2020 (Real) | E4: 2021 (Real) | F4: 2022 (Real) | G4: 2023 (Real) | H4: 2024 (Real) | I4: 2025 | J4: =+I4+1 -> 2026 | K4: =+J4+1 -> 2027 | L4: =+K4+1 -> 2028 | M4: =+L4+1 -> 2029 | N4: =+M4+1 -> 2030 | O4: =+N4+1 -> 2031 | P4: =+O4+1 -> 2032 | Q4: =+P4+1 -> 2033 | ... AF4: =+AE4+1 -> 2048 | AG4: Notes
A5: INCOME STATEMENT | B5: 1 | C5: Growth | D5: =[2]Cifras_en_Millones!F6 -> 0.3053523 | E5: =E6/D6-1 -> 0.27082576 | F5: =F6/E6-1 -> 0.18840106 | G5: =G6/F6-1 -> 0.24486219 | H5: =H6/G6-1 -> 0.113381 | I5: 0.145 | J5: 0.13 | K5: 0.17 | L5: =+K5-($K$5-$AF$5)/($AF$4-$K$4) -> 0.16285714 | M5: =+L5-($K$5-$AF$5)/($AF$4-$K$4) -> 0.15571429 | N5: =+M5-($K$5-$AF$5)/($AF$4-$K$4) -> 0.14857143 | O5: =+N5-($K$5-$AF$5)/($AF$4-$K$4) -> 0.14142857 | P5: =+O5-($K$5-$AF$5)/($AF$4-$K$4) -> 0.13428571 | Q5: =+P5-($K$5-$AF$5)/($AF$4-$K$4) -> 0.12714286 | R5: =+Q5-($K$5-$AF$5)/($AF$4-$K$4) -> 0.12 | S5: =+R5-($K$5-$AF$5)/($AF$4-$K$4) -> 0.11285714 | ... AE5: =+AD5-($K$5-$AF$5)/($AF$4-$K$4) -> 0.027142857 | AF5: 0.02
B6: 2 | C6: Revenues/Sales | D6: 1926.7 | E6: 2448.5 | F6: 2909.8 | G6: 3622.3 | H6: 4033 | I6: =H6*(1+I5) -> 4617.785 | J6: =I6*(1+J5) -> 5218.097 | K6: =J6*(1+K5) -> 6105.1735 | L6: =K6*(1+L5) -> 7099.4447 | M6: =L6*(1+M5) -> 8204.9296 | N6: =M6*(1+N5) -> 9423.9477 | O6: =N6*(1+O5) -> 10756.763 | P6: =O6*(1+P5) -> 12201.243 | ... AF6: =AE6*(1+AF5) -> 37707.539
B7: 3 | C7: EBIT/Operating Margin | D7: =+D8/D6 -> 0.15544714 | E7: =+E8/E6 -> 0.10855626 | F7: =+F8/F6 -> 0.13444223 | G7: =+G8/G6 -> 0.16500566 | H7: =+H8/H6 -> 0.14877263 | I7: 0.16 | J7: 0.175 | K7: 0.19 | L7: 0.19 | M7: 0.19 | N7: 0.19 | O7: 0.19 | P7: 0.19 | Q7: 0.19 | R7: 0.19 | S7: 0.19 | T7: 0.19 | U7: 0.19 | V7: 0.19 | W7: 0.19 | X7: 0.19 | Y7: 0.19 | Z7: 0.19 | AA7: 0.19 | AB7: 0.19 | AC7: 0.19 | AD7: 0.19 | AE7: 0.19 | AF7: 0.19
B8: 4 | C8: EBIT | D8: =+Cifras_en_Millones!F11 -> 299.5 | E8: =+Cifras_en_Millones!E11 -> 265.8 | F8: =+Cifras_en_Millones!D11 -> 391.2 | G8: =+Cifras_en_Millones!C11 -> 597.7 | H8: 600 | I8: =I7*I6 -> 738.8456 | J8: =J7*J6 -> 913.16698 | K8: =K7*K6 -> 1159.983 | L8: =L7*L6 -> 1348.8945 | M8: =M7*M6 -> 1558.9366 | N8: =N7*N6 -> 1790.5501 | O8: =O7*O6 -> 2043.785 | P8: =P7*P6 -> 2318.2361 | ... AF8: =AF7*AF6 -> 7164.4323
B9: 5a | C9: (Dep&Amort) | D9: =-Cifras_en_Millones!F17 -> -67.1 | E9: =-Cifras_en_Millones!E17 -> -120 | F9: =-Cifras_en_Millones!D17 -> -172.3 | G9: =-Cifras_en_Millones!C17 -> -202.5 | H9: -234.4 | I9: =H9*0.7+0.3*(-$D$50*AVERAGE((D22:H22))) -> -225.20387 | J9: =I9*0.7+0.3*(-$D$50*AVERAGE((E22:I22))) -> -198.23646 | K9: =J9*0.7+0.3*(-$D$50*AVERAGE((F22:J22))) -> -186.03182 | L9: =K9*0.7+0.3*(-$D$50*AVERAGE((G22:K22))) -> -178.86902 | M9: =L9*0.7+0.3*(-$D$50*AVERAGE((H22:L22))) -> -185.97652 | N9: =M9*0.7+0.3*(-$D$50*AVERAGE((I22:M22))) -> -205.74672 | O9: =N9*0.7+0.3*(-$D$50*AVERAGE((J22:N22))) -> -231.20896 | P9: =O9*0.7+0.3*(-$D$50*AVERAGE((K22:O22))) -> -262.4271 | ... AF9: =AE9*0.7+0.3*(-$D$50*AVERAGE((AA22:AE22))) -> -1245.9234
B10: 5b | C10: (Stock based compensation) | D10: =-D19 -> -119.4 | E10: =-E19 -> -113.4 | F10: =-F19 -> -126.5 | G10: =-G19 -> -150.8 | H10: -170.4 | I10: =-$D$51*I6 -> -195.68034 | J10: =-$D$51*J6 -> -221.11878 | K10: =-$D$51*K6 -> -258.70898 | L10: =-$E$51*L6 -> -70.994447 | M10: =-$E$51*M6 -> -82.049296 | N10: =-$E$51*N6 -> -94.239477 | O10: =-$E$51*O6 -> -107.56763 | P10: =-$E$51*P6 -> -122.01243 | Q10: =-$E$51*Q6 -> -137.52544 | R10: =-$E$51*R6 -> -154.02849 | S10: =-$E$51*S6 -> -171.4117 | ... AF10: =-$E$51*AF6 -> -377.07539
B11: 6 | C11: EBIDTA | D11: =-D9+D8 -> 366.6 | E11: =-E9+E8 -> 385.8 | F11: =-F9+F8 -> 563.5 | G11: =-G9+G8 -> 800.2 | H11: =-H9+H8 -> 834.4 | I11: =-I9+I8 -> 964.04947 | J11: =-J9+J8 -> 1111.4034 | K11: =-K9+K8 -> 1346.0148 | ... AF11: =-AF9+AF8 -> 8410.3557
B12: 7 | C12: (Net financing cost) | D12: =+Cifras_en_Millones!F14 -> 1.6 | E12: =+Cifras_en_Millones!E14 -> 17.1 | F12: =+Cifras_en_Millones!D14 -> 6 | G12: =+Cifras_en_Millones!C14 -> -114.7 | H12: -115.2 | I12: =-$D$53*H37+H36*$D$54 -> -118.292 | J12: =-$D$53*I37+I36*$D$54 -> -117.95446 | K12: =-$D$53*J37+J36*$D$54 -> -117.51858 | L12: =-$D$53*K37+K36*$D$54 -> -116.91286 | M12: =-$D$53*L37+L36*$D$54 -> -116.50768 | N12: =-$D$53*M37+M36*$D$54 -> -116.01222 | O12: =-$D$53*N37+N36*$D$54 -> -115.40013 | P12: =-$D$53*O37+O36*$D$54 -> -114.65157 | ... AF12: =-$D$53*AE37+AE36*$D$54 -> 38.755798
B13: 8 | C13: Other income/(cost) | D13: =+Cifras_en_Millones!F15 -> 0 | E13: =+Cifras_en_Millones!E15 -> -8.1 | F13: =+Cifras_en_Millones!D15 -> -5.6 | G13: =+Cifras_en_Millones!C15 -> 2 | H13: 6.2 | I13: =+AVERAGE(D13:H13)*(1+I5) -> -1.2595 | J13: =+AVERAGE(E13:I13)*(1+J5) -> -1.527647 | K13: =+AVERAGE(F13:J13)*(1+K5) -> -0.043792398 | L13: =+AVERAGE(G13:K13)*(1+L5) -> 1.2486901 | M13: =+AVERAGE(H13:L13)*(1+M5) -> 1.0673601 | N13: =+AVERAGE(I13:M13)*(1+N5) -> -0.11827741 | O13: =+AVERAGE(J13:N13)*(1+O5) -> 0.14298296 | P13: =+AVERAGE(K13:O13)*(1+P5) -> 0.52108254 | ... AF13: =+AVERAGE(AA13:AE13)*(1+AF5) -> 0.61554734
B14: 9 | C14: Earnings before taxes | D14: =D8-D12-D13 -> 297.9 | E14: =E8-E12-E13 -> 256.8 | F14: =F8-F12-F13 -> 390.8 | G14: =G8-G12-G13 -> 710.4 | H14: =H8-H12-H13 -> 709 | I14: =I8-I12-I13 -> 858.3971 | J14: =J8-J12-J13 -> 1032.6491 | K14: =K8-K12-K13 -> 1277.5453 | ... AF14: =AF8-AF12-AF13 -> 7125.061
B15: 10 | C15: (Income tax) | D15: =-Cifras_en_Millones!F21 -> 251.8 | E15: =-Cifras_en_Millones!E21 -> -39.9 | F15: =-Cifras_en_Millones!D21 -> -49.6 | G15: =-Cifras_en_Millones!C21 -> -168.9 | H15: -132.8 | I15: =(1*$D$52)*I14 -> -166.58651 | J15: =(1*$D$52)*J14 -> -200.40306 | K15: =(1*$D$52)*K14 -> -247.92933 | L15: =(1*$D$52)*L14 -> -284.22244 | M15: =(1*$D$52)*M14 -> -324.94123 | N15: =(1*$D$52)*N14 -> -370.02369 | O15: =(1*$D$52)*O14 -> -418.99874 | P15: =(1*$D$52)*P14 -> -472.04198 | ... AF15: =(1*$D$52)*AF14 -> -1382.7389
B16: 11 | C16: Net income | D16: =D14+D15 -> 549.7 | E16: =E14+E15 -> 216.9 | F16: =F14+F15 -> 341.2 | G16: =G14+G15 -> 541.5 | H16: =H14+H15 -> 576.2 | I16: =I14+I15 -> 691.81059 | J16: =J14+J15 -> 832.24602 | K16: =K14+K15 -> 1029.616 | ... AF16: =AF14+AF15 -> 5742.3221
A18: CASH FLOW STATEMENT | B18: 12 | C18: Operating cash flows before WK | D18: =+D16-D9 -> 616.8 | E18: =+E16-E9-11.6+87.1 -> 412.4 | F18: =+F16-F9 -> 513.5 | G18: =+G16-G9 -> 744 | H18: =+H16-H9 -> 810.6 | I18: =I11+I12+I13+I15 -> 677.91146 | J18: =J11+J12+J13+J15 -> 791.51828 | K18: =K11+K12+K13+K15 -> 980.52309 | L18: =L11+L12+L13+L15 -> 1127.8769 | M18: =M11+M12+M13+M15 -> 1304.5316 | N18: =N11+N12+N13+N15 -> 1510.1426 | O18: =O11+O12+O13+O15 -> 1740.7381 | P18: =P11+P12+P13+P15 -> 1994.4908 | ... AF18: =AF11+AF12+AF13+AF15 -> 7066.9882
B19: 13 | C19: (Stock-based compensation) | D19: 119.4 | E19: 113.4 | F19: 126.5 | G19: 150.8 | H19: 170.4 | I19: =-I10 -> 195.68034 | J19: =-J10 -> 221.11878 | K19: =-K10 -> 258.70898 | L19: =-L10 -> 70.994447 | M19: =-M10 -> 82.049296 | N19: =-N10 -> 94.239477 | O19: =-O10 -> 107.56763 | P19: =-P10 -> 122.01243 | ... AF19: =-AF10 -> 377.07539
B20: 14 | C20: (Working Capital Flows) | D20: =-239.8-142.3-114.5+194.5+18.6+22.9 -> -260.6 | E20: =48.7-75.5-112.2+58+8.7-11 -> -83.3 | F20: =2.8-199.9+49.3+295.1+11.1-128.9 -> 29.5 | G20: =-149.5-260.1-252.6+466.5-2.6+52 -> -146.3 | H20: =-100.3-35+12.4+211.7-8-72.3 -> 8.5 | I20: =$D$56*(I6-H6) -> -27.693466 | J20: =$D$56*(J6-I6) -> -28.428775 | K20: =$D$56*(K6-J6) -> -42.008982 | L20: =$E$56*(L6-K6) -> -17.257228 | M20: =$E$56*(M6-L6) -> -19.187529 | N20: =$E$56*(N6-M6) -> -21.158086 | O20: =$E$56*(O6-N6) -> -23.133228 | P20: =$E$56*(P6-O6) -> -25.071345 | Q20: =$E$56*(Q6-P6) -> -26.925405 | R20: =$E$56*(R6-Q6) -> -28.64379 | S20: =$E$56*(S6-R6) -> -30.171459 | ... AF20: =$E$56*(AF6-AE6) -> -12.832882
B21: 15 | C21: -Total Operating Cash Flow | D21: =D18+D19+D20 -> 475.6 | E21: =E18+E19+E20 -> 442.5 | F21: =F18+F19+F20 -> 669.5 | G21: =G18+G19+G20 -> 748.5 | H21: =H18+H19+H20 -> 989.5 | I21: =I18+I19+I20 -> 845.89833 | J21: =J18+J19+J20 -> 984.20829 | K21: =K18+K19+K20 -> 1197.2231 | ... AF21: =AF18+AF19+AF20 -> 7431.2307
B22: 16 | C22: (CAPEX and Acquisitions) | D22: =+Cifras_en_Millones!F35+11.3 -> -1205.7 | E22: =+Cifras_en_Millones!E35 -> -226.2 | F22: =+Cifras_en_Millones!D35 -> -509.1 | G22: =+Cifras_en_Millones!C35 -> -192 | H22: =-358.8+166.8 -> -192 | I22: =$D$57*I6 -> -424.7852 | J22: =$D$57*J6 -> -480.00728 | K22: =$D$57*K6 -> -561.60852 | L22: =$D$57*L6 -> -653.07047 | M22: =$D$57*M6 -> -754.76288 | N22: =$D$57*N6 -> -866.89907 | O22: =$D$57*O6 -> -989.50337 | P22: =$D$57*P6 -> -1122.3795 | ... AF22: =$D$57*AF6 -> -3468.6769
B23: 17 | C23: (Other investing flows) | D23: -11.3 | E23: 10.1 | F23: 0.2 | G23: 1.9 | H23: -15.5 | I23: =H23*1.04 -> -16.12 | J23: =I23*1.04 -> -16.7648 | K23: =J23*1.04 -> -17.435392 | L23: =K23*1.04 -> -18.132808 | M23: =L23*1.04 -> -18.85812 | N23: =M23*1.04 -> -19.612445 | O23: =N23*1.04 -> -20.396943 | P23: =O23*1.04 -> -21.21282 | Q23: =P23*0.98 -> -20.788564 | R23: =Q23*0.98 -> -20.372793 | S23: =R23*0.98 -> -19.965337 | T23: =S23*0.98 -> -19.56603 | U23: =T23*0.98 -> -19.174709 | V23: =U23*0.98 -> -18.791215 | W23: =V23*0.98 -> -18.415391 | X23: =W23*0.98 -> -18.047083 | ... AF23: =AE23*0.98 -> -15.353791
B24: 18 | C24: -Total Investing Flows | D24: =D22+D23 -> -1217 | E24: =E22+E23 -> -216.1 | F24: =F22+F23 -> -508.9 | G24: =G22+G23 -> -190.1 | H24: =H22+H23 -> -207.5 | I24: =I22+I23 -> -440.9052 | J24: =J22+J23 -> -496.77208 | K24: =K22+K23 -> -579.04391 | ... AF24: =AF22+AF23 -> -3484.0307
B25: 19 | C25: (Flows related to leases) | D25: 0 | E25: 0 | F25: 0 | G25: 0 | H25: 0 | I25: 0 | J25: 0 | K25: 0 | L25: 0 | M25: 0 | N25: 0 | O25: 0 | P25: 0 | Q25: 0 | R25: 0 | S25: 0 | T25: 0 | U25: 0 | V25: 0 | W25: 0 | X25: 0 | Y25: 0 | Z25: 0 | AA25: 0 | AB25: 0 | AC25: 0 | AD25: 0 | AE25: 0 | AF25: 0
B26: 20 | C26: Flows related to debt | D26: =1188.8-282.6 -> 906.2 | E26: 0 | F26: 0 | G26: =1230.6-787.3 -> 443.3 | H26: =(H37-G37) -> 0 | I26: =(I37-H37) -> 0 | J26: =(J37-I37) -> 0 | K26: =(K37-J37) -> 0 | L26: =(L37-K37) -> 0 | M26: =(M37-L37) -> 0 | N26: =(N37-M37) -> 0 | O26: =(O37-N37) -> 0 | ... AF26: =(AF37-AE37) -> 0
B27: 21 | C27: (Repurchases)/Issuance of stock | D27: 15.3 | E27: 20.3 | F27: =22.5-557.7 -> -535.2 | G27: =-688.7+26.6 -> -662.1 | H27: =-750+28.2 -> -721.8 | I27: =+$D$55*(I21+I24) -> -373.81591 | J27: =+$D$55*(J21+J24) -> -449.91235 | K27: =+$D$55*(K21+K24) -> -570.59045 | L27: =+$D$55*(L21+L24) -> -471.11833 | M27: =+$D$55*(M21+M24) -> -548.06253 | N27: =+$D$55*(N21+N24) -> -643.07809 | O27: =+$D$55*(O21+O24) -> -752.51081 | P27: =+$D$55*(P21+P24) -> -874.87282 | Q27: =+$E$55*(Q21+Q24) -> -955.59413 | R27: =+$E$55*(R21+R24) -> -1107.3626 | S27: =+$E$55*(S21+S24)+500 -> -756.22651 | T27: =+$E$55*(T21+T24)+500 -> -937.87122 | U27: =+$E$55*(U21+U24)+500 -> -1127.3575 | V27: =+$E$55*(V21+V24)+500 -> -1323.1506 | W27: =+$E$55*(W21+W24)+V37 -> -1760.3319 | X27: =+$E$55*(X21+X24) -> -2215.4267 | Y27: =+$E$55*(Y21+Y24) -> -2395.3418 | Z27: =+$E$55*(Z21+Z24) -> -2573.103 | AA27: =+$E$55*(AA21+AA24) -> -2746.1143 | AB27: =+$E$55*(AB21+AB24) -> -2911.6891 | AC27: =+$E$55*(AC21+AC24) -> -3067.1002 | AD27: =+$E$55*(AD21+AD24) -> -3209.6466 | AE27: =+$E$55*(AE21+AE24) -> -3336.7373 | AF27: =+$E$55*(AF21+AF24) -> -3445.9762
B28: 22 | C28: (Dividends) | D28: 0 | E28: 0 | F28: 0 | G28: 0 | H28: =(1+$D$58)*G28 -> 0 | I28: =(1+$D$58)*H28 -> 0 | J28: =(1+$D$58)*I28 -> 0 | K28: =(1+$D$58)*J28 -> 0 | L28: =(1+$E$58)*K28 -> 0 | M28: =(1+$E$58)*L28 -> 0 | N28: =(1+$E$58)*M28 -> 0 | O28: =(1+$E$58)*N28 -> 0 | P28: =(1+$E$58)*O28 -> 0 | Q28: =$E$58*(Q21+Q24) -> -54.729355 | R28: =$E$58*(R21+R24) -> -63.421531 | S28: =$E$58*(S21+S24) -> -71.947351 | T28: =$E$58*(T21+T24) -> -82.350615 | U28: =$E$58*(U21+U24) -> -93.202988 | V28: =$E$58*(V21+V24) -> -104.41656 | W28: =$E$58*(W21+W24) -> -115.89292 | X28: =$E$58*(X21+X24) -> -126.88324 | ... AF28: =$E$58*(AF21+AF24) -> -197.36
B29: 23 | C29: Other financing flows | D29: -9.4 | E29: -9.9 | F29: -17.3 | G29: -99.8 | H29: -13 | I29: =H29*1.1 -> -14.3 | J29: =I29*1.1 -> -15.73 | K29: =J29*1.1 -> -17.303 | L29: =K29*1.1 -> -19.0333 | M29: =L29*1.1 -> -20.93663 | N29: =M29*1.1 -> -23.030293 | O29: =N29*1.1 -> -25.333322 | P29: =O29*1.1 -> -27.866655 | ... AF29: =AE29*1.1 -> -128.04652
B30: 24 | C30: -Total Financing flows | D30: =SUM(D25:D29) -> 912.1 | E30: =SUM(E25:E29) -> 10.4 | F30: =SUM(F25:F29) -> -552.5 | G30: =SUM(G25:G29) -> -318.6 | H30: =SUM(H25:H29) -> -734.8 | I30: =SUM(I25:I29) -> -388.11591 | J30: =SUM(J25:J29) -> -465.64235 | K30: =SUM(K25:K29) -> -587.89345 | ... AF30: =SUM(AF25:AF29) -> -3771.3827
A32: SUMMARY | B32: 25 | C32: Cash before shareholder returns | D32: =D21+D24+D25+D26+D29 -> 155.4 | E32: =E21+E24+E25+E26+E29 -> 216.5 | F32: =F21+F24+F25+F26+F29 -> 143.3 | G32: =G21+G24+G25+G26+G29 -> 901.9 | H32: =H21+H24+H25+H26+H29 -> 769 | I32: =I21+I24+I25+I26+I29 -> 390.69313 | J32: =J21+J24+J25+J26+J29 -> 471.70621 | K32: =K21+K24+K25+K26+K29 -> 600.87618 | ... AF32: =AF21+AF24+AF25+AF26+AF29 -> 3819.1534
B33: 26 | C33: Returns to shareholders | D33: =-1*(D27+D28) -> -15.3 | E33: =-1*(E27+E28) -> -20.3 | F33: =-1*(F27+F28) -> 535.2 | G33: =-1*(G27+G28) -> 662.1 | H33: =-1*(H27+H28) -> 721.8 | I33: =-1*(I27+I28) -> 373.81591 | J33: =-1*(J27+J28) -> 449.91235 | K33: =-1*(K27+K28) -> 570.59045 | ... AF33: =-1*(AF27+AF28) -> 3643.3362
B34: 27 | C34: Excess cash acumulation | D34: =D32-D33 -> 170.7 | E34: =E32-E33 -> 236.8 | F34: =F32-F33 -> -391.9 | G34: =G32-G33 -> 239.8 | H34: =H32-H33 -> 47.2 | I34: =I32-I33 -> 16.877221 | J34: =J32-J33 -> 21.793862 | K34: =K32-K33 -> 30.28573 | ... AF34: =AF32-AF33 -> 175.8172
A36: CASH & DEBT & DISCOUNTING | B36: 28 | C36: Ending cash balance | D36: =D34 -> 170.7 | E36: =D36+E34 -> 407.5 | F36: =E36+F34 -> 15.6 | G36: =F36+G34 -> 255.4 | H36: =G36+H34 -> 302.6 | I36: =H36+I34 -> 319.47722 | J36: =I36+J34 -> 341.27108 | K36: =J36+K34 -> 371.55681 | L36: =K36+L34 -> 391.81601 | ... AF36: =AE36+AF34 -> 2114.0571
B37: 29 | C37: Total Debt | D37: =Cifras_en_Millones!F60 -> 2029.4 | E37: =Cifras_en_Millones!E60 -> 2340.6 | F37: =Cifras_en_Millones!D60 -> 2328.1 | G37: =Cifras_en_Millones!C60 -> 2763.2 | H37: =G37 -> 2763.2 | I37: =H37-1207.5+1207.5 -> 2763.2 | J37: =I37 -> 2763.2 | K37: =J37 -> 2763.2 | L37: =K37-1250+1250 -> 2763.2 | M37: =L37 -> 2763.2 | N37: =M37 -> 2763.2 | O37: =N37 -> 2763.2 | P37: =O37 -> 2763.2 | Q37: =P37-500 -> 2263.2 | R37: =Q37 -> 2263.2 | S37: =R37-500 -> 1763.2 | T37: =S37-500 -> 1263.2 | U37: =T37-500 -> 763.2 | V37: =U37-500 -> 263.2 | W37: =V37-263 -> 0.2 | X37: =+W37 -> 0.2 | Y37: =+X37 -> 0.2 | Z37: =+Y37 -> 0.2 | AA37: =+Z37 -> 0.2 | AB37: =+AA37 -> 0.2 | AC37: =+AB37 -> 0.2 | AD37: =+AC37 -> 0.2 | AE37: =+AD37 -> 0.2 | AF37: =+AE37 -> 0.2
B38: 30 | C38: Discount factor | G38: =1/((1+$D$47)^F3) -> 0.99645969 | H38: =1/((1+$D$47)^G3) -> 1 | I38: =1/((1+$D$47)^H3) -> 0.97981157 | J38: =1/((1+$D$47)^H3) -> 0.97981157 | K38: =1/((1+$D$47)^I3) -> 0.90305214 | L38: =1/((1+$D$47)^J3) -> 0.83230612 | M38: =1/((1+$D$47)^K3) -> 0.76710242 | N38: =1/((1+$D$47)^L3) -> 0.70700684 | O38: =1/((1+$D$47)^M3) -> 0.6516192 | P38: =1/((1+$D$47)^N3) -> 0.60057069 | Q38: =1/((1+$D$47)^O3) -> 0.55352138 | ... AF38: =1/((1+$D$47)^AD3) -> 0.16281272 | AG38: =1/((1+$D$47)^AF3) -> 0.13830212
F39: =1/((1+$D$48+0.001)^F$3) -> 0.99995655 | G39: =1/((1+$D$47+0.001)^F$3) -> 0.99641978 | H39: =1/((1+$D$47+0.001)^G$3) -> 1 | I39: =1/((1+$D$47+0.001)^H$3) -> 0.97958594 | J39: =1/((1+$D$47+0.001)^H$3) -> 0.97958594 | K39: =1/((1+$D$47+0.001)^I$3) -> 0.90201284 | L39: =1/((1+$D$47+0.001)^J$3) -> 0.83058272 | M39: =1/((1+$D$47+0.001)^K$3) -> 0.76480914 | N39: =1/((1+$D$47+0.001)^L$3) -> 0.70424414 | O39: =1/((1+$D$47+0.001)^M$3) -> 0.64847527 | P39: =1/((1+$D$47+0.001)^N$3) -> 0.59712271 | Q39: =1/((1+$D$47+0.001)^O$3) -> 0.54983675 | ... AF39: =1/((1+$D$47+0.001)^AD$3) -> 0.15950944
F40: =1/((1+$D$48+0.005)^F$3) -> 0.9997832 | G40: =1/((1+$D$47+0.005)^F$3) -> 0.99626054 | H40: =1/((1+$D$47+0.005)^G$3) -> 1 | I40: =1/((1+$D$47+0.005)^H$3) -> 0.978686 | J40: =1/((1+$D$47+0.005)^H$3) -> 0.978686 | K40: =1/((1+$D$47+0.005)^I$3) -> 0.89787706 | L40: =1/((1+$D$47+0.005)^J$3) -> 0.82374043 | M40: =1/((1+$D$47+0.005)^K$3) -> 0.75572516 | N40: =1/((1+$D$47+0.005)^L$3) -> 0.69332584 | O40: =1/((1+$D$47+0.005)^M$3) -> 0.63607875 | P40: =1/((1+$D$47+0.005)^N$3) -> 0.58355848 | Q40: =1/((1+$D$47+0.005)^O$3) -> 0.53537476 | ... AF40: =1/((1+$D$47+0.005)^AD$3) -> 0.14698074
C42: EPS | H42: =1000000*H16/[3]OP!C8 -> 1.4745247 | I42: =1000000*I16/[3]OP!C8 -> 1.7703779 | J42: =1000000*J16/[3]OP!C8 -> 2.1297593
C43: Consenso EPS
C44: E$/UN | H44: =$D$64/H16 -> 39.646794 | I44: =$D$64/I16 -> 33.021297
...

Sheet Cifras_en_Millones
A1: =Cifras_Originales!G3 -> DexCom, Inc. (DXCM)
A2: =Cifras_Originales!C2 -> Cifras en Millones de USD
A4: Resultados | B4: 2024 | C4: =Cifras_Originales!B5 -> 2023 | D4: =Cifras_Originales!C5 -> 2022 | E4: =Cifras_Originales!D5 -> 2021 | F4: =Cifras_Originales!E5 -> 2020 | G4: =Cifras_Originales!F5 -> 2019 | H4: =Cifras_Originales!G5 -> 2018 | I4: =Cifras_Originales!H5 -> 2017 | J4: =Cifras_Originales!I5 -> 2016 | ... M4: =Cifras_Originales!L5 -> 2013
A5: Ventas Netas | C5: =Cifras_Originales!B6 -> 3622.3 | D5: =Cifras_Originales!C6 -> 2909.3 | E5: =Cifras_Originales!D6 -> 2448.5 | F5: =Cifras_Originales!E6 -> 1926.7 | G5: =Cifras_Originales!F6 -> 1476 | H5: =Cifras_Originales!G6 -> 1031.6 | I5: =Cifras_Originales!H6 -> 718.5 | J5: =Cifras_Originales!I6 -> 573.3 | ... M5: =Cifras_Originales!L6 -> 160
A6: Crecimiento vs. Año pasado | B6: =B5/C5-1 -> -1 | C6: =C5/D5-1 -> 0.24507614 | D6: =D5/E5-1 -> 0.18819686 | E6: =E5/F5-1 -> 0.27082576 | F6: =F5/G5-1 -> 0.3053523 | G6: =G5/H5-1 -> 0.43078713 | H6: =H5/I5-1 -> 0.43576896 | I6: =I5/J5-1 -> 0.25327054 | ... L6: =L5/M5-1 -> 0.62
A7: Utilidad Bruta | C7: =Cifras_Originales!B7 -> 2288.9 | D7: =Cifras_Originales!C7 -> 1883.1 | E7: =Cifras_Originales!D7 -> 1680.5 | F7: =Cifras_Originales!E7 -> 1280.1 | G7: =Cifras_Originales!F7 -> 931.5 | H7: =Cifras_Originales!G7 -> 663.9 | I7: =Cifras_Originales!H7 -> 492.1 | J7: =Cifras_Originales!I7 -> 378.4 | ... M7: =Cifras_Originales!L7 -> 100.1
A8: porcentaje sobre ventas | B8: =B7/B5 -> #DIV/0! | C8: =C7/C5 -> 0.63189134 | D8: =D7/D5 -> 0.6472691 | E8: =E7/E5 -> 0.68633857 | F8: =F7/F5 -> 0.66440027 | G8: =G7/G5 -> 0.63109756 | H8: =H7/H5 -> 0.6435634 | I8: =I7/I5 -> 0.6848991 | ... M8: =M7/M5 -> 0.625625
A9: Gastos de Operación | B9: =B5-B11 -> 0 | C9: =C5-C11 -> 3024.6 | D9: =D5-D11 -> 2518.1 | E9: =E5-E11 -> 2182.7 | F9: =F5-F11 -> 1627.2 | G9: =G5-G11 -> 1333.7 | H9: =H5-H11 -> 1217.9 | I9: =I5-I11 -> 761 | ... M9: =M5-M11 -> 188.9
A10: porcentaje sobre ventas | B10: =B9/B5 -> #DIV/0! | C10: =C9/C5 -> 0.83499434 | D10: =D9/D5 -> 0.86553466 | E10: =E9/E5 -> 0.89144374 | F10: =F9/F5 -> 0.84455286 | G10: =G9/G5 -> 0.90359079 | H10: =H9/H5 -> 1.1805933 | I10: =I9/I5 -> 1.059151 | ... M10: =M9/M5 -> 1.180625
A11: Utilidad de Operación | C11: =Cifras_Originales!B8 -> 597.7 | D11: =Cifras_Originales!C8 -> 391.2 | E11: =Cifras_Originales!D8 -> 265.8 | F11: =Cifras_Originales!E8 -> 299.5 | G11: =Cifras_Originales!F8 -> 142.3 | H11: =Cifras_Originales!G8 -> -186.3 | I11: =Cifras_Originales!H8 -> -42.5 | J11: =Cifras_Originales!I8 -> -63.9 | ... M11: =Cifras_Originales!L8 -> -28.9
A12: porcentaje sobre ventas | B12: =B11/B5 -> #DIV/0! | C12: =C11/C5 -> 0.16500566 | D12: =D11/D5 -> 0.13446534 | E12: =E11/E5 -> 0.10855626 | F12: =F11/F5 -> 0.15544714 | G12: =G11/G5 -> 0.096409214 | H12: =H11/H5 -> -0.18059325 | I12: =I11/I5 -> -0.059151009 | ... M12: =M11/M5 -> -0.180625
A13: Crecimiento vs año anterior | B13: =B11/C11-1 -> -1 | C13: =C11/D11-1 -> 0.52786299 | D13: =D11/E11-1 -> 0.4717833 | E13: =E11/F11-1 -> -0.11252087 | F13: =F11/G11-1 -> 1.1047084 | G13: =G11/H11-1 -> -1.7638218 | H13: =H11/I11-1 -> 3.3835294 | I13: =I11/J11-1 -> -0.33489828 | ... L13: =L11/M11-1 -> -0.25605536
A14: CIF (Productos Financieros) | C14: =Cifras_Originales!B9 -> -114.7 | D14: =Cifras_Originales!C9 -> 6 | E14: =Cifras_Originales!D9 -> 17.1 | F14: =Cifras_Originales!E9 -> 1.6 | G14: =Cifras_Originales!F9 -> 33.9 | H14: =Cifras_Originales!G9 -> 20.3 | I14: =Cifras_Originales!H9 -> 9.5 | J14: =Cifras_Originales!I9 -> 0.3 | ... M14: =Cifras_Originales!L9 -> 0.9
A15: Otros Gastos (Productos) | C15: =Cifras_Originales!B10 -> 2 | D15: =Cifras_Originales!C10 -> -5.6 | E15: =Cifras_Originales!D10 -> -8.1 | F15: =Cifras_Originales!E10 -> 0 | G15: =Cifras_Originales!F10 -> 4.2 | H15: =Cifras_Originales!G10 -> -80.1 | I15: =Cifras_Originales!H10 -> -3.4 | J15: =Cifras_Originales!I10 -> 0.7 | ... M15: =Cifras_Originales!L10 -> 0
A16: Utilidad antes de Impuestos y partidas extra. | B16: =B11-B14-B15 -> 0 | C16: =C11-C14-C15 -> 710.4 | D16: =D11-D14-D15 -> 390.8 | E16: =E11-E14-E15 -> 256.8 | F16: =F11-F14-F15 -> 297.9 | G16: =G11-G14-G15 -> 104.2 | H16: =H11-H14-H15 -> -126.5 | I16: =I11-I14-I15 -> -48.6 | ... M16: =M11-M14-M15 -> -29.8
A17: Depreciación y amortización del ejercicio | C17: =Cifras_Originales!B11 -> 202.5 | D17: =Cifras_Originales!C11 -> 172.3 | E17: =Cifras_Originales!D11 -> 120 | F17: =Cifras_Originales!E11 -> 67.1 | G17: =Cifras_Originales!F11 -> 48.7 | H17: =Cifras_Originales!G11 -> 29.1 | I17: =Cifras_Originales!H11 -> 16.1 | J17: =Cifras_Originales!I11 -> 15 | ... M17: =Cifras_Originales!L11 -> 7
A18: Capital de Trabajo | C18: =Cifras_Originales!B12 -> 2869.9 | D18: =Cifras_Originales!C12 -> 1829.5 | E18: =Cifras_Originales!D12 -> 2963.6 | F18: =Cifras_Originales!E12 -> 2810.7 | G18: =Cifras_Originales!F12 -> 1609.2 | H18: =Cifras_Originales!G12 -> 1477.1 | I18: =Cifras_Originales!H12 -> 605.8 | J18: =Cifras_Originales!I12 -> 177.6 | ... M18: =Cifras_Originales!L12 -> 61
A19: EBITDA (flujo operativo) | B19: =B11-B15+B17 -> 0 | C19: =C11-C15+C17 -> 798.2 | D19: =D11-D15+D17 -> 569.1 | E19: =E11-E15+E17 -> 393.9 | F19: =F11-F15+F17 -> 366.6 | G19: =G11-G15+G17 -> 186.8 | H19: =H11-H15+H17 -> -77.1 | I19: =I11-I15+I17 -> -23 | ... M19: =M11-M15+M17 -> -21.9
A20: porcentaje sobre ventas | B20: =B19/B5 -> #DIV/0! | C20: =C19/C5 -> 0.22035723 | D20: =D19/D5 -> 0.19561407 | E20: =E19/E5 -> 0.160874 | F20: =F19/F5 -> 0.19027352 | G20: =G19/G5 -> 0.12655827 | H20: =H19/H5 -> -0.074738271 | I20: =I19/I5 -> -0.032011134 | ... M20: =M19/M5 -> -0.136875
A21: I.S.R Y P.T.U. | C21: =Cifras_Originales!B15 -> 168.9 | D21: =Cifras_Originales!C15 -> 49.6 | E21: =Cifras_Originales!D15 -> 39.9 | F21: =Cifras_Originales!E15 -> -251.8 | G21: =Cifras_Originales!F15 -> 3.1 | H21: =Cifras_Originales!G15 -> 0.6 | I21: =Cifras_Originales!H15 -> 1.6 | J21: =Cifras_Originales!I15 -> 0.7 | ... M21: =Cifras_Originales!L15 -> 0
A22: % Tax | B22: =+B21/B16 -> #DIV/0! | C22: =+C21/C16 -> 0.23775338 | D22: =+D21/D16 -> 0.12691914 | E22: =+E21/E16 -> 0.15537383 | F22: =+F21/F16 -> -0.84525008 | G22: =+G21/G16 -> 0.02975048 | H22: =+H21/H16 -> -0.004743083 | I22: =+I21/I16 -> -0.032921811 | ... M22: =+M21/M16 -> 0
A23: Utilidad Neta | C23: =Cifras_Originales!B16 -> 541.5 | D23: =Cifras_Originales!C16 -> 341.2 | E23: =Cifras_Originales!D16 -> 216.9 | F23: =Cifras_Originales!E16 -> 549.7 | G23: =Cifras_Originales!F16 -> 101.1 | H23: =Cifras_Originales!G16 -> -127.1 | I23: =Cifras_Originales!H16 -> -50.2 | J23: =Cifras_Originales!I16 -> -65.6 | ... M23: =Cifras_Originales!L16 -> -29.8
A24: porcentaje sobre ventas | B24: =B23/B5 -> #DIV/0! | C24: =C23/C5 -> 0.14949066 | D24: =D23/D5 -> 0.11727907 | E24: =E23/E5 -> 0.088584848 | F24: =F23/F5 -> 0.28530648 | G24: =G23/G5 -> 0.068495935 | H24: =H23/H5 -> -0.12320667 | I24: =I23/I5 -> -0.06986778 | ... M24: =M23/M5 -> -0.18625
A25: Crecimiento vs año anterior | B25: =B23/C23-1 -> -1 | C25: =C23/D23-1 -> 0.58704572 | D25: =D23/E23-1 -> 0.57307515 | E25: =E23/F23-1 -> -0.60542114 | F25: =F23/G23-1 -> 4.4371909 | G25: =G23/H23-1 -> -1.7954367 | H25: =H23/I23-1 -> 1.5318725 | I25: =I23/J23-1 -> -0.2347561 | ... L25: =L23/M23-1 -> -0.24832215
A26: Efectivo Generado | B26: =B40-C40 -> -2724.1 | C26: =C40-D40 -> 267.9 | D26: =D40-E40 -> -275 | E26: =E40-F40 -> 23.5 | F26: =F40-G40 -> 1174.4 | G26: =G40-H40 -> 147.7 | H26: =H40-I40 -> 837 | I26: =I40-J40 -> 424.9 | ... L26: =L40-M40 -> 29 | M26: =M40-Cifras_Originales!M22 -> 5.9
