Workbook
Name Benchmark: [1]ControlsH!$B$3
Name BestConsOv: #REF!
Name Broker_Name: OFFSET(#REF!,0,0,[1]ControlsH!$E$5, 1)
Name calCODE: [1]ControlsH!$C$4
Name Chart_Benchmark_100_Size: OFFSET(#REF!, 0, 0, [1]ControlsH!$E$3, 1)
Name Chart_Date_Size: OFFSET(#REF!, 0, 0, [1]ControlsH!$E$3, 1)
Name Chart_Date_VAL1_Size: OFFSET(#REF!, 0, 0, [1]ControlsH!$I$3, 1)
Name Chart_Date_VAL2_Size: OFFSET(#REF!, 0, 0, [1]ControlsH!$I$5, 1)
Name Chart_Peer_100_Size: OFFSET(#REF!, 0, 0, [1]ControlsH!$E$3, 1)
Name Chart_Price_100_Size: OFFSET(#REF!, 0, 0, [1]ControlsH!$E$3, 1)
Name Chart_Price_Size: OFFSET(#REF!, 0, 0, [1]ControlsH!$E$3, 1)
Name Chart_VAL1_FY1_Size: OFFSET(#REF!, 0, 0, [1]ControlsH!$F$3, 1)
Name Chart_VAL1_FY2_Size: OFFSET(#REF!, 0, 0, [1]ControlsH!$G$3, 1)
Name Chart_VAL1_FY3_Size: OFFSET(#REF!, 0, 0, [1]ControlsH!$H$3, 1)
Name Chart_VAL2_FY1_Size: OFFSET(#REF!, 0, 0, [1]ControlsH!$F$5, 1)
Name Chart_VAL2_FY2_Size: OFFSET(#REF!, 0, 0, [1]ControlsH!$G$5, 1)
Name Chart_VAL2_FY3_Size: OFFSET(#REF!, 0, 0, [1]ControlsH!$H$5, 1)
Name Chart_Volume_Size: OFFSET(#REF!, 0, 0, [1]ControlsH!$E$3, 1)
Name compNAME: [1]ControlsH!$B$6
Name CURRENCY: [1]ControlsH!$B$9
Name currPRICE: [1]Overview!$E$19
Name custBenchmark: [1]Overview!$C$9
Name custED: #REF!
Name custSD: #REF!
Name dayCODE: [1]ControlsH!$C$5
Name ED: [1]ControlsH!$B$5
Name ESTBrokersItem: #REF!
Name ESTBrokersPeriod: #REF!
Name ESTDetailBroker: #REF!
Name ESTDetailBroker2: #REF!
Name ESTDetailPeriod: #REF!
Name EstDetPerO: #REF!
Name EstDetPerT: #REF!
Name FinancialsPeriod: #REF!
Name fundTICKER: [1]ControlsH!$B$15
Name GraphValRatio1: #REF!
Name GraphValRatio2: #REF!
Name Index1: #REF!
Name Lang: [1]Overview!$D$11
Name newCrncy: [1]ControlsH!$B$21:$B$199
Name newEstBrokerPeriod: #REF!
Name newEstBrokersItem: #REF!
Name newEstDetailBroker: #REF!
Name newEstDetailBroker2: #REF!
Name newEstDetailPeriod: #REF!
Name newFinancialsPeriod: #REF!
Name newOverviewCon: #REF!
Name newOverviewYear: #REF!
Name newOwners: #REF!
Name newPeersRatio: #REF!
Name newPeriod: #REF!
Name newValRatio1: #REF!
Name newValRatio2: #REF!
Name OverviewValRatioPeriod: [1]Overview!$D$30
Name PeerDate1: [1]Peers!$S$11
Name peerHist1: #REF!
Name PeerIndex: [1]ControlsH!$F$35:$F$36
Name Peers: OFFSET([1]Peers!$C$18,0,0,MAX(COUNTA([1]Peers!$C$18:$C$47),1),1)
Name peersWEIGHT: [1]ControlsH!$B$13
Name PERIODICITY: [1]ControlsH!$C$3

Sheet OP
B2: 45728 | C2: Analista: Research | D2: Report (quarter): 26/11/2024 | E2: DICK'S Sporting Goods, Inc. | K2: NYSE | L2: SIC: Sí
D3: DESCRIPTION: Dick’s Sporting Goods is a leading U.S. retailer offering sports equipment, apparel, and footwear, catering to athletes and outdoor enthusiasts. Founded in 1948, it operates hundreds of stores nationwide.
D4: Lauren R. Hobart (55 yo; dir. s. 2018; Pres. & CEO; ex Senior VP and CMO), Edward W. Stack (69 yo; Ch; dir. s. 1984; ex CEO), William J. Colombo (68 yo; dir. s. 2002; Vice Ch; ex Pres. & COO), Mark J. Barrenechea (59 yo; dir. s. 2014; CEO & CTO OpenText Corp.), Emanuel Chirico (66 yo; dir. s. 2003; ex Ch & CEO PVH Corp.), Robert W. Eddy (51 yo; dir. s. 2023; Ch, Pres & CEO BJ's Wholesale Club Holdings, Inc.), Anne Fink (60 yo; dir. s. 2019; Pres. Global Foodservice PepsiCo, Inc.), Larry Fitzgerald Jr. (40 yo; dir. s. 2020; Pres. Larry Fitzgerald Enterprises), Sandeep Mathrani (61 yo; dir. s. 2020; dir. Sycamore Partners; ex CEO WeWork), Desiree Ralls-Morrison (57 yo; dir. s. 2020; Exec. VP McDonald's Corporation), Lawrence J. Schorr (70 yo; dir. s. 1985; Lead dir. DICK's Sporting Goods, Inc.; Deputy Ch SURTECO North America), Larry D. Stone (72 yo; dir. s. 2007; ex Pres. & COO Lowe's Companies Inc.)
B5: Millones de USD
B6: Acción | D6: Liquidez y Solvencia | F6: =Segments!B2 -> Regions (2023) | I6: Rentabilidad (2022) | K6: Múltiplos
B7: Último Precio | C7: 198.97 | D7: Activo: | E7: =Cifras_en_Millones!C45 -> 9311.752 | H7: %Vts; %Op.Mg.; D | I7: Año termina: | J7: 44954 | K7: Float: | L7: 0.963
B8: Outstanding Shares | C8: 81470000 | D8: Pasivo: | E8: =Cifras_en_Millones!C57 -> 6694.077 | F8: =Segments!B4 -> United States | H8: =+Segments!I4 -> 100%; 1.0%; 5% | K8: Insiders Own: | L8: 0.0379
B9: Market Cap. | C9: =C7*C8/1000000 -> 16210.086 | D9: Cash/Precio | E9: =1000000*C11/C8 -> 22.108997 | I9: EBIT | J9: 1478.968 | K9: b (Bloomberg; Yahoo) | L9: 1.6
B10: +Deuda Total | C10: 4263.83 | D10: Ebidta/CIF | E10: =Cifras_en_Millones!C19/Cifras_en_Millones!C14 -> 12.854742 | I10: +Dep&Amort | J10: =Cifras_en_Millones!D17 -> 375 | K10: Calificación (S&P) | L10: BBB
B11: -Cash | C11: =Cifras_Originales!C22 -> 1801.22 | D11: Deuda/Ebidta | E11: =OP!C10/Cifras_en_Millones!C19 -> 2.4088101 | I11: =EBIDTA | J11: =J9+J10 -> 1853.968 | K11: Precio/Valor en libros | L11: =((C7*C8)/1000000)/(E7-E8) -> 6.192551
B12: =Enterprise Value | C12: =C9+C10-C11 -> 18672.696 | D12: "Otros activos"/Activo | E12: =Cifras_en_Millones!C44/Cifras_en_Millones!C45 -> 0.31236839 | I12: Utilidad Neta | J12: =Cifras_en_Millones!D23 -> 1043 | K12: FNP(p)/Activos | L12: =J18/E7 -> 0.12603397
B13: Tenencia % (nac/int'l) | C13: - | D13: Deuda/Activo | E13: =C10/E7 -> 0.45789772 | F13: =Segments!B15 -> Products (2023) | I13: UPA | J13: =1000000*J12/C8 -> 12.802259 | K13: Precio/Utilidad(p) | L13: =C9/J17 -> 15.515615 | N13: =C10/J11 -> 2.2998401
B14: t liq. (Pos prom./Vol.) | C14: - | D14: Margen de Operación (p) | E14: =AVERAGE(Cifras_en_Millones!C11/Cifras_en_Millones!C5,Cifras_en_Millones!D11/Cifras_en_Millones!D5,Cifras_en_Millones!E11/Cifras_en_Millones!E5) -> 0.12751558 | H14: %Vts; D | I14: ROA | J14: =J12/E7 -> 0.112009 | K14: EV/Activos | L14: =C12/E7 -> 2.0052828
B15: % Short | C15: 0.0565 | D15: Margen neto (p) | E15: =AVERAGE(Cifras_en_Millones!C23/12984.399,Cifras_en_Millones!D23/12368.198,Cifras_en_Millones!E23/12293.368) -> 0.096186925 | F15: =Segments!B17 -> Hardlines | H15: =+Segments!I17 -> 38%; NA; -1% | I15: ROIC | J15: =J12/(E7-(E8-C10)) -> 0.15156568 | K15: EV/Ebidta (p) | L15: =C12/J16 -> 15.457248
B16: Semáforo ESG | D16: Ebidta/Ingresos(p) | E16: =AVERAGE(Cifras_en_Millones!C19/12984.399,Cifras_en_Millones!D19/12368.198,Cifras_en_Millones!E19/12293.368) -> 0.15980005 | F16: =Segments!B18 -> Apparel | H16: =+Segments!I18 -> 33%; NA; 3% | I16: Ebidta(p) | J16: =AVERAGE(Cifras_en_Millones!B19:D19) -> 1208.022 | K16: Precio/FNP (p) | L16: =C9/J18 -> 13.812309
B17: E | D17: CIF/Deuda Neta Promedio | E17: =Cifras_en_Millones!C14/AVERAGE(Cifras_en_Millones!C59:M59) -> 0.058763075 | F17: =Segments!B19 -> Footwear | H17: =+Segments!I19 -> 26%; NA; 14% | I17: Utilidad Neta (p) | J17: =AVERAGE(Cifras_en_Millones!B23:D23) -> 1044.7595 | K17: Bonos 1;5;40a (USD) | L17: 4.0%; 4.4%; 5% | N17: 12
B18: S | F18: =Segments!B20 -> Other | H18: =+Segments!I20 -> 3%; NA; 60% | I18: FNP (p) | J18: =SUM(F35:F37)/3 -> 1173.5971 | K18: TDY(p)/Precio | L18: =SUM(E35:E37)/(3*C9) -> 0.069455488
B19: G | I19: Tax (p) últ. 5a | J19: 0.16 | K19: Div. Yield: | L19: =K33/C9 -> 0.010061637
B20: Tesis de inversión | H20: Acuerdo | I20: Supuestos de valuación | L20: DCF Value
B21: Investment in e-commerce - The company has successfully integrated online and offline sales, with a variety of options for customer shopping. Investments in technology enhance efficiency and position DICK’S well for future retail trends. Growing demand for sporting goods - With the population's increased purchasing power and its growing interest in sporting goods, the company's revenue is expected to grow. | H21: Mantener sin elevar posición | I21: VER DCF | L21: =DCFF!D66 -> 143.81382
B23: KSF | H23: PO / Precio Stand By | L23: =DCFF!D65 -> -0.27720855
B24: Sensitivity to economy downturns - Sportings goods are not an essential good. Therefore, in case of a lower disposable income due to unfortunate economic circumstances, clients will buy less sporting goods. Supply chain problems - Increased protectionist measures by the USA and the continuation of wars and political tensions may impact the company's supply chain, resulting in a decrease in revenues. | H24: =DCFF!D71 -> 0 | I24: Tasa de descuento: | J24: =DCFF!D47 -> 0.09 | K24: HOLD
B25: Año | C25: Ingresos | D25: Margen Operativo | E25: Div.+Recompra | F25: FNP | G25: Deuda/Activo | H25: Depreciación | I25: Capex + Adq | J25: Cash Flow
B26: 2012 | C26: 5836 | D26: =Cifras_Originales!N8/OP!C26 -> 0.089731666 | E26: =Cifras_Originales!N17+Cifras_Originales!N18 -> 307.1934 | F26: 652 | G26: =(Cifras_Originales!N32+Cifras_Originales!N36)/Cifras_Originales!N27 -> 0.29548581 | H26: =Cifras_Originales!N11 -> 125.096 | I26: =Cifras_Originales!N13 -> 258 | K26: 2022 | L26: =K26-1 -> 2021
B27: =B26+1 -> 2013 | C27: 6213 | D27: =Cifras_en_Millones!M11/OP!C27 -> 0.086401416 | E27: =Cifras_en_Millones!M37 -> 214.468 | F27: =Cifras_en_Millones!M30 -> 396.199 | G27: =Cifras_en_Millones!M59/Cifras_en_Millones!M45 -> 0.23166792 | H27: =Cifras_en_Millones!M17 -> 154.928 | I27: =Cifras_en_Millones!M35 -> 285.668 | J27: Profit | K27: =Cifras_en_Millones!D23 -> 1043 | L27: =Cifras_en_Millones!E23 -> 1519.871 | N27: =C27/C26-1 -> 0.06459904 | O27: =D27/D26-1 -> -0.037113422
B28: =B27+1 -> 2014 | C28: 6814 | D28: =Cifras_en_Millones!L11/OP!C28 -> 0.081311858 | E28: =Cifras_en_Millones!L37 -> 61.324063 | F28: =Cifras_en_Millones!L30 -> 101.27206 | G28: =Cifras_en_Millones!L59/Cifras_en_Millones!L45 -> 0.22562786 | H28: =Cifras_en_Millones!L17 -> 179.431 | I28: =Cifras_en_Millones!L35 -> 349.007 | J28: Cash Flow from Operations (BWC) | K28: 921.881 | L28: 1616.872 | N28: =C28/C27-1 -> 0.096732657 | O28: =D28/D27-1 -> -0.058905961 | P28: =E28/E27-1 -> -0.71406427 | Q28: =F28/F27-1 -> -0.74439092 | R28: =H28/H27-1 -> 0.15815734 | S28: =I28/I27-1 -> 0.22172242 | BT28: 4303
B29: =B28+1 -> 2015 | C29: 7271 | D29: =Cifras_en_Millones!K11/OP!C29 -> 0.073606382 | E29: =Cifras_en_Millones!K37 -> 122.08546 | F29: =Cifras_en_Millones!K30 -> 19.342465 | G29: =Cifras_en_Millones!K59/Cifras_en_Millones!K45 -> 0.25289296 | H29: =Cifras_en_Millones!K17 -> 193.594 | I29: =Cifras_en_Millones!K35 -> 370.028 | J29: Working Capital | K29: =Cifras_en_Millones!D18 -> 359.155 | L29: =Cifras_en_Millones!E18 -> -248.731 | N29: =C29/C28-1 -> 0.067067802 | O29: =D29/D28-1 -> -0.094764486 | P29: =E29/E28-1 -> 0.99082478 | Q29: =F29/F28-1 -> -0.80900493 | R29: =H29/H28-1 -> 0.078932849 | S29: =I29/I28-1 -> 0.060230884 | BT29: 3066
B30: =B29+1 -> 2016 | C30: 7922 | D30: =Cifras_en_Millones!J11/OP!C30 -> 0.056785408 | E30: =Cifras_en_Millones!J37 -> 97.931005 | F30: =Cifras_en_Millones!J30 -> 143.772 | G30: =Cifras_en_Millones!J59/Cifras_en_Millones!J45 -> 0.25467068 | H30: =Cifras_en_Millones!J17 -> 233.834 | I30: =Cifras_en_Millones!J35 -> 242 | J30: Investing Activities | K30: -392.894 | L30: -343.979 | N30: =C30/C29-1 -> 0.089533764 | O30: =D30/D29-1 -> -0.22852603 | P30: =E30/E29-1 -> -0.19784878 | Q30: =F30/F29-1 -> 6.4329722 | R30: =H30/H29-1 -> 0.20785768 | S30: =I30/I29-1 -> -0.34599544 | BT30: 3283
B31: =B30+1 -> 2017 | C31: 8590 | D31: =Cifras_en_Millones!I11/OP!C31 -> 0.055596508 | E31: =Cifras_en_Millones!I37 -> 115.705 | F31: =Cifras_en_Millones!I30 -> 52.181 | G31: =Cifras_en_Millones!I59/Cifras_en_Millones!I45 -> 0.28116417 | H31: =Cifras_en_Millones!I17 -> 237.651 | I31: =Cifras_en_Millones!I35 -> 372.6 | J31: Capex | K31: =Cifras_en_Millones!D33 -> 328 | L31: =Cifras_en_Millones!E33 -> 268.1 | N31: =C31/C30-1 -> 0.084322141 | O31: =D31/D30-1 -> -0.02093672 | P31: =E31/E30-1 -> 0.18149508 | Q31: =F31/F30-1 -> -0.6370573 | R31: =H31/H30-1 -> 0.016323546 | S31: =I31/I30-1 -> 0.53966942
B32: =B31+1 -> 2018 | C32: 8437 | D32: =Cifras_en_Millones!H11/OP!C32 -> 0.05271222 | E32: =Cifras_en_Millones!H37 -> 123.41161 | F32: =Cifras_en_Millones!H30 -> 135.81161 | G32: =Cifras_en_Millones!H59/Cifras_en_Millones!H45 -> 0.29445692 | H32: =Cifras_en_Millones!H17 -> 243.83 | I32: =Cifras_en_Millones!H35 -> 170.5 | J32: Adquisiones | K32: 0 | L32: 0 | N32: =C32/C31-1 -> -0.017811409 | O32: =D32/D31-1 -> -0.051878935 | P32: =E32/E31-1 -> 0.066605715 | Q32: =F32/F31-1 -> 1.6027024 | R32: =H32/H31-1 -> 0.026000311 | S32: =I32/I31-1 -> -0.54240472
B33: =B32+1 -> 2019 | C33: 8751 | D33: =Cifras_en_Millones!G11/OP!C33 -> 0.042922295 | E33: =Cifras_en_Millones!G37 -> 500.60078 | F33: =Cifras_en_Millones!G30 -> 456.29178 | G33: =Cifras_en_Millones!G59/Cifras_en_Millones!G45 -> 0.67402332 | H33: =Cifras_en_Millones!G17 -> 335.746 | I33: =Cifras_en_Millones!G35 -> 179.5 | J33: Dividends | K33: =Cifras_en_Millones!D27 -> 163.1 | L33: =Cifras_en_Millones!E27 -> 603 | N33: =C33/C32-1 -> 0.03721702 | O33: =D33/D32-1 -> -0.18572402 | P33: =E33/E32-1 -> 3.0563507 | Q33: =F33/F32-1 -> 2.3597405 | R33: =H33/H32-1 -> 0.37696756 | S33: =I33/I32-1 -> 0.052785924
B34: =B33+1 -> 2020 | C34: 9584.019 | D34: =Cifras_en_Millones!F11/OP!C34 -> 0.077365978 | E34: =Cifras_en_Millones!F37 -> 107.79947 | F34: =Cifras_en_Millones!F30 -> 1696.5225 | G34: =Cifras_en_Millones!F59/Cifras_en_Millones!F45 -> 0.4269029 | H34: =Cifras_en_Millones!F17 -> 326.014 | I34: =Cifras_en_Millones!F35 -> 175.8 | J34: Stock Repurchases | K34: =Cifras_en_Millones!D29 -> 426.7 | L34: =Cifras_en_Millones!E29 -> 1180 | N34: =C34/C33-1 -> 0.095191292 | O34: =D34/D33-1 -> 0.80246602 | P34: =E34/E33-1 -> -0.7846598 | Q34: =F34/F33-1 -> 2.7180649 | R34: =H34/H33-1 -> -0.028986198 | S34: =I34/I33-1 -> -0.020612813
B35: =B34+1 -> 2021 | C35: 12293.368 | D35: =Cifras_en_Millones!E11/OP!C35 -> 0.16549598 | E35: =Cifras_en_Millones!E37 -> 1787.6145 | F35: =Cifras_en_Millones!E30 -> 2772.7525 | G35: =Cifras_en_Millones!E59/Cifras_en_Millones!E45 -> 0.41827621 | H35: =Cifras_en_Millones!E17 -> 322.551 | I35: =Cifras_en_Millones!E35 -> 268.1 | J35: Endeudamiento Neto | K35: =Cifras_en_Millones!D59 -> 4025.142 | L35: =Cifras_en_Millones!E59 -> 3781.918 | N35: =C35/C34-1 -> 0.28269445 | O35: =D35/D34-1 -> 1.1391313 | P35: =E35/E34-1 -> 15.582776 | Q35: =F35/F34-1 -> 0.63437418 | R35: =H35/H34-1 -> -0.010622243 | S35: =I35/I34-1 -> 0.52502844
B36: =B35+1 -> 2022 | C36: 12368.198 | D36: =Cifras_en_Millones!D11/OP!C36 -> 0.11828878 | E36: =Cifras_en_Millones!D37 -> 589.07048 | F36: =Cifras_en_Millones!D30 -> -129.74852 | G36: =Cifras_en_Millones!D59/Cifras_en_Millones!D45 -> 0.44762614 | H36: =Cifras_en_Millones!D17 -> 375 | I36: =Cifras_en_Millones!D35 -> 328 | J36: Otros Financiemientos | K36: 0 | L36: 0 | N36: =C36/C35-1 -> 0.0060870219 | O36: =D36/D35-1 -> -0.28524684
B37: =B36+1 -> 2023 | C37: 12984.399 | D37: =Cifras_en_Millones!C11/OP!C37 -> 0.098761984 | E37: =Cifras_en_Millones!C37 -> 1000.9533 | F37: =Cifras_en_Millones!C30 -> 877.78728 | G37: =Cifras_en_Millones!C59/Cifras_en_Millones!C45 -> 0.46783355 | H37: =Cifras_en_Millones!C17 -> 393.933 | I37: =Cifras_en_Millones!C35 -> 520.4 | N37: =C37/C36-1 -> 0.049821405 | O37: =D37/D36-1 -> -0.1650773
B38: 2024 Est. | C38: =DCFF!H6 -> 13425.869 | D38: =DCFF!H7 -> 0.112
B39: CAGR | C39: =(C37/C32)^(1/5)-1 -> 0.090050857 | D39: =(D37/D26)^(1/11)-1 -> 0.0087552895 | J39: FX | K39: 0 | L39: 0
B40: AAG | C40: =AVERAGE(N27:N37) -> 0.077768653 | D40: =AVERAGE(O27:O37) -> 0.073947597 | J40: D Cash and Equivalents | K40: =K28+K29+K30+K33+K34+K35+K36+K39 -> 5503.084 | L40: =L28+L29+L30+L33+L34+L35+L36+L39 -> 6589.08
B41: CVAR | C41: =STDEV(C26:C37)/AVERAGE(C26:C37) -> 0.27369085 | D41: =STDEV(D26:D37)/AVERAGE(D26:D37) -> 0.40396024 | J41: Inv/D Vts | K41: =SUM(I33:I37)/(C37-C32) -> 0.32365755 | L41: =(SUM(I33:I37)-SUM(H33:H37))/(C37-C32) -> -0.061891204
B42: Último Año | C42: =C37/C36-1 -> 0.049821405 | D42: =D37/D36-1 -> -0.1650773 | J42: t inversiones; t adq. neto dep. | K42: =K41/E14 -> 2.5381804 | L42: =L41/E14 -> -0.4853619
...

Sheet Segments
B2: Regions (2023)
C3: 2023 | D3: =C3-1 -> 2022 | E3: Ut. Operativa | F3: % Vts | G3: Margen | H3: Crec
B4: United States | C4: =+Cifras_en_Millones!C5 -> 12984.399 | D4: =+Cifras_en_Millones!D5 -> 12368.198 | E4: 1282.4 | F4: =+C4/$C$27 -> 1 | G4: =+E4/C14 -> 0.098764679 | H4: =+C4/D4-1 -> 0.049821405 | I4: =IF(C4="","",IF(F4=0,"NA",TEXT(F4,"0%"))&"; "&IF(G4=0,"NA",TEXT(G4,"0.0%"))&"; "&IF(H4=0,"NA",TEXT(H4,"0%"))) -> 100%; 1.0%; 5%
I5: =IF(C5="","",IF(F5=0,"NA",TEXT(F5,"0%"))&"; "&IF(G5=0,"NA",TEXT(G5,"0.0%"))&"; "&IF(H5=0,"NA",TEXT(H5,"0%")))
I6: =IF(C6="","",IF(F6=0,"NA",TEXT(F6,"0%"))&"; "&IF(G6=0,"NA",TEXT(G6,"0.0%"))&"; "&IF(H6=0,"NA",TEXT(H6,"0%")))
I7: =IF(C7="","",IF(F7=0,"NA",TEXT(F7,"0%"))&"; "&IF(G7=0,"NA",TEXT(G7,"0.0%"))&"; "&IF(H7=0,"NA",TEXT(H7,"0%")))
I8: =IF(C8="","",IF(F8=0,"NA",TEXT(F8,"0%"))&"; "&IF(G8=0,"NA",TEXT(G8,"0.0%"))&"; "&IF(H8=0,"NA",TEXT(H8,"0%")))
I9: =IF(C9="","",IF(F9=0,"NA",TEXT(F9,"0%"))&"; "&IF(G9=0,"NA",TEXT(G9,"0.0%"))&"; "&IF(H9=0,"NA",TEXT(H9,"0%")))
I10: =IF(C10="","",IF(F10=0,"NA",TEXT(F10,"0%"))&"; "&IF(G10=0,"NA",TEXT(G10,"0.0%"))&"; "&IF(H10=0,"NA",TEXT(H10,"0%")))
I11: =IF(C11="","",IF(F11=0,"NA",TEXT(F11,"0%"))&"; "&IF(G11=0,"NA",TEXT(G11,"0.0%"))&"; "&IF(H11=0,"NA",TEXT(H11,"0%")))
I12: =IF(C12="","",IF(F12=0,"NA",TEXT(F12,"0%"))&"; "&IF(G12=0,"NA",TEXT(G12,"0.0%"))&"; "&IF(H12=0,"NA",TEXT(H12,"0%")))
I13: =IF(C13="","",IF(F13=0,"NA",TEXT(F13,"0%"))&"; "&IF(G13=0,"NA",TEXT(G13,"0.0%"))&"; "&IF(H13=0,"NA",TEXT(H13,"0%")))
B14: TOTAL | C14: =SUM(C4:C12) -> 12984.399 | D14: =SUM(D4:D12) -> 12368.198 | E14: =SUM(E4:E13) -> 1282.4 | F14: =C14/SUM($C$4:$C$13) -> 1 | G14: =E14/C14 -> 0.098764679 | H14: =C14/D14-1 -> 0.049821405
B15: Products (2023)
C16: 2023 | D16: =C16-1 -> 2022 | E16: Ut. Op. | F16: % Vts | G16: Margen | H16: Crec
B17: Hardlines | C17: =+C198 -> 4915.5 | D17: 4952.2 | E17: NA | F17: =+C17/$C$27 -> 0.3785697 | G17: NA | H17: =+C17/D17-1 -> -0.0074108477 | I17: =IF(C17="","",IF(F17=0,"NA",TEXT(F17,"0%"))&"; "&IF(G17=0,"NA",TEXT(G17,"0.0%"))&"; "&IF(H17=0,"NA",TEXT(H17,"0%"))) -> 38%; NA; -1%
B18: Apparel | C18: =+Segments!C200 -> 4329.8 | D18: 4218.1 | E18: NA | F18: =+C18/$C$27 -> 0.33346172 | G18: NA | H18: =+C18/D18-1 -> 0.026481117 | I18: =IF(C18="","",IF(F18=0,"NA",TEXT(F18,"0%"))&"; "&IF(G18=0,"NA",TEXT(G18,"0.0%"))&"; "&IF(H18=0,"NA",TEXT(H18,"0%"))) -> 33%; NA; 3%
B19: Footwear | C19: =+C202 -> 3388.7 | D19: 2979.1 | E19: NA | F19: =+C19/$C$27 -> 0.26098243 | G19: NA | H19: =+C19/D19-1 -> 0.13749119 | I19: =IF(C19="","",IF(F19=0,"NA",TEXT(F19,"0%"))&"; "&IF(G19=0,"NA",TEXT(G19,"0.0%"))&"; "&IF(H19=0,"NA",TEXT(H19,"0%"))) -> 26%; NA; 14%
B20: Other | C20: =+C204 -> 350.4 | D20: 218.8 | E20: NA | F20: =+C20/$C$27 -> 0.026986232 | G20: NA | H20: =+C20/D20-1 -> 0.60146252 | I20: =IF(C20="","",IF(F20=0,"NA",TEXT(F20,"0%"))&"; "&IF(G20=0,"NA",TEXT(G20,"0.0%"))&"; "&IF(H20=0,"NA",TEXT(H20,"0%"))) -> 3%; NA; 60%
E21: =+E4 -> 1282.4 | I21: =IF(C21="","",IF(F21=0,"NA",TEXT(F21,"0%"))&"; "&IF(G21=0,"NA",TEXT(G21,"0.0%"))&"; "&IF(H21=0,"NA",TEXT(H21,"0%")))
I22: =IF(C22="","",IF(F22=0,"NA",TEXT(F22,"0%"))&"; "&IF(G22=0,"NA",TEXT(G22,"0.0%"))&"; "&IF(H22=0,"NA",TEXT(H22,"0%")))
I23: =IF(C23="","",IF(F23=0,"NA",TEXT(F23,"0%"))&"; "&IF(G23=0,"NA",TEXT(G23,"0.0%"))&"; "&IF(H23=0,"NA",TEXT(H23,"0%")))
I24: =IF(C24="","",IF(F24=0,"NA",TEXT(F24,"0%"))&"; "&IF(G24=0,"NA",TEXT(G24,"0.0%"))&"; "&IF(H24=0,"NA",TEXT(H24,"0%")))
I25: =IF(C25="","",IF(F25=0,"NA",TEXT(F25,"0%"))&"; "&IF(G25=0,"NA",TEXT(G25,"0.0%"))&"; "&IF(H25=0,"NA",TEXT(H25,"0%")))
I26: =IF(C26="","",IF(F26=0,"NA",TEXT(F26,"0%"))&"; "&IF(G26=0,"NA",TEXT(G26,"0.0%"))&"; "&IF(H26=0,"NA",TEXT(H26,"0%")))
B27: TOTAL | C27: =+Cifras_en_Millones!C5 -> 12984.399 | D27: =+Cifras_en_Millones!D5 -> 12368.198 | E27: =SUM(E17:E26) -> 1282.4 | F27: =C27/SUM(C17:C26) -> 0.99999992 | G27: =E27/C27 -> 0.098764679 | H27: =C27/D27-1 -> 0.049821405
L29: 45622
B30: Factories By Region: | C30: % | L30: Question by:
B31: Asia | C31: 0.89 | L31: Adrienne Yih, Analyst at Barclays Capital, Inc. :
B32: North America | C32: 0.05 | L32: I guess officially the Tariff Man has come up. So, we had an update
B33: Latin America | C33: 0.04 | L33: yesterday evening, 25% Canada, Mexico and obviously the 10% in China. Historically, you've already told us that
B34: EMEA | C34: 0.02 | L34: you don't have much exposure. But for the private label, so can you just update us? I'm assuming that this doesn't
B35: 9% of factories based on High-risk countries based on BSCI criteria | L35: change the answer that you've given us before, but just remind us now that we have some quazi-official numbers.
B36: % of Factories Doesn't correlate to Production % | L36: How are you thinking about that? Thank you.
L37: Navdeep Gupta, Executive Vice President & Chief Financial Officer, Dick's Sporting Goods, Inc. :
L38: In terms of tariffs, I think so I would
D39: (See Comment) | L39: say does that a slightly more information is known. We still don't know about the timing and likely – the categories
B40: 39 Weeks Ended Nov 2, 2024 | C40: DKS | D40: Specialty Concept Stores | E40: Total | L40: that would be impacted. So, still a lot to be learned more, but like you said, we have navigated the situation back
B41: Beginning Stores | C41: 724 | D41: 131 | E41: 855 | L41: in 2018, 2019 effectively as well. Vertical brands perspective, we have a very small or actually very, very
B42: Q1 New Stores | C42: 1 | D42: 3 | E42: 4 | L42: negligible amount of exposure because we have diversified our supply chain, both from China as well as there's
...

Sheet COVID-19 impact
A1: https://www.apple.com/newsroom/2020/03/apples-covid-19-response/ | G1: https://glg.it/articles/how-might-the-wuhan-coronavirus-impact-apples-supply-chain/ | N1: https://www.cnbc.com/2020/02/18/the-significance-of-apples-coronavirus-warning.html
A2: March 13 | G2: January 29 | N2: Ferbuary 18
A23: Otros:
A24: https://www.macrumors.com/guide/covid-19-coronavirus/

Sheet Peers
A2: Multiplos (USD) | B2: (DKS) | C2: (HIBB) | D2: (ASO) | E2: (FL)
B3: (DICK´S Sporting Goods) | C3: (Hibbett Sports) | D3: (Academy Sports and Outdoors) | E3: (Foot Locker)
A4: Ventas | B4: 13,425.4M | C4: 1,703.0M | D4: 6,051.4M | E4: 8,124.0M
A5: Crecimiento (1S23/1S22) | B5: 0.0154 | C5: 0.0101 | D5: 0.0376 | E5: -0.0909
A6: Crecimiento (1S23/1S19) | B6: 0.369 | C6: 0.6927 | D6: 0.3704 | E6: 0.1604
A7: Deuda | B7: 122278 | C7: 82110 | D7: 26772 | E7: 100504
A8: Activos | B8: 323888 | C8: 301311 | D8: 319616 | E8: 321195
A9: Deuda/Activos | B9: =OP!C10/OP!E7 -> 0.45789772 | C9: 0.0513 | D9: 0.3513 | E9: 0.4131
A10: Deuda/EBITDA | B10: =OP!C10/OP!J11 -> 2.2998401 | C10: 0.2511 | D10: 2.5318 | E10: 8.488
A11: (Capex + Adq.)/Revenue | B11: =-DCFF!G22/DCFF!G6 -> 0.045240908 | C11: 0.0334 | D11: 0.0316 | E11: 0.0322
A12: ROA (p) | B12: =OP!J14 -> 0.112009 | C12: 0.1135 | D12: 0.0734 | E12: 0.0114
A13: ROIC (p) | B13: =OP!J15 -> 0.15156568 | C13: 0.1479 | D13: 0.1234 | E13: 0.044
A14: Margen Operativo | B14: =OP!D37 -> 0.098761984 | C14: 0.0792 | D14: 0.0971 | E14: 0.016
A15: Margen Operativo 2022 | B15: =OP!D36 -> 0.11828878 | C15: 0.135 | D15: 0.134 | E15: 0.1169
A16: Float | B16: =OP!L7 -> 0.963 | C16: 0.777 | D16: 0.9855 | E16: 0.679
A17: b | B17: =OP!L9 -> 1.6 | C17: 1.88 | D17: 1.37 | E17: 1.43
A18: Precio/Utilidad | B18: 17.18 | C18: 10.77 | D18: 8.58 | E18: 9.72
A19: Precio/Ventas | B19: 1.48 | C19: 0.63 | D19: 0.64 | E19: 0.22
A20: EV/Activos | B20: =OP!C12/OP!E7 -> 2.0052828 | C20: 2.71 | D20: 0.98 | E20: 0.63
A21: EV/Ebitda | B21: 12.5 | C21: 5.91 | D21: 6.86 | E21: 12.98
A22: Div. Yield: | B22: =OP!L19 -> 0.010061637 | C22: 0.011 | D22: 0.0067 | E22: 0.0385
B24: *Nota: Estos múltiplos no consideran el promedio de los últimos 3 años, únicamente valores del último año reportado
B25: **Cifras en USD
A27: (You can make up a table with different indicators in order to link them to the multiples/ratios. At the end, put the table unvisible with white color)

Sheet Acuerdo
A1: Invertir
A2: NO invertir
A3: Mantener sin elevar posición
A4: Mantener (y seguir comprando)
A5: Liquidar
A6: PENDIENTE

Sheet ESG
B2: Análisis ESG | J2: PARÁMETROS
C3: Impacto | D3: ¿Reporta? | E3: Ranking | F3: Mitigación | G3: Semáforo | H3: Comentarios | J3: IMPACTO | L3: RANKING | M3: MITIGACIÓN
B4: Ambiental | J4: NONE | K4: 0 | L4: "Best in class" | M4: Is there evidence of progam/plan/etc…
B5: Emisiones directas CO2 | C5: 2 | D5: Yes | E5: Medium | F5: Yes | H5: The firm has taken steps to reduce carbon emissions by optimizing its supply chain and investing in more energy-efficient logistics. | J5: LOW | K5: 1 | L5: Medium high
B6: Uso total de agua | C6: 1 | D6: Yes | E6: Best in class | F6: Yes | H6: The firm is one of the best in the industry regarding this metric. | J6: MEDIUM | K6: 2 | L6: Medium
B7: Total Energy Consumption | C7: 2 | D7: Yes | E7: Medium high | F7: No | H7: The company is committed to increasing energy efficiency across its stores, with some locations using LED lighting and other energy-saving technologies. | J7: HIGH | K7: 3 | L7: "Villain"
B8: Waste Management | C8: 1 | D8: Yes | E8: Medium high | F8: Yes | H8: The company has implemented recycling programs and is working to reduce plastic usage in packaging.
B9: Land Degradation/Deforestation/Biodiversity loss/Animal sufering/… | C9: 3 | D9: Yes | E9: Medium | F9: Yes | H9: Dick’s has policies to source sustainable products, including eco-friendly athletic wear and responsibly sourced outdoor gear. | J9: TRAFFIC LIGHTS
B10: Social
B11: % Rotación de empleados | C11: 3 | D11: Yes | E11: Medium High | F11: No | H11: The company does not disclose employee turnover %. Most employees do not stay with the company for more than a year.
B12: Sueldos y compensaciones | C12: 1 | D12: No | E12: Medium | F12: No | H12: The company offers medical, dental, vision, disability and life insurance, flexible paid time off programs covering parental and family leave and hybrid work arrangements.
B13: Temas de reputación | C13: 1 | D13: No | E13: Villain | F13: Yes | H13: The company has faced some lawsuits.
B14: Temas de discriminación | C14: 1 | D14: No | E14: Medium | F14: Yes | H14: Dick’s has been recognized for its diversity, equity, and inclusion (DEI) initiatives, ensuring fair hiring and promotion practices.
B15: Seguridad laboral | C15: 2 | D15: Yes | E15: Medium | F15: Yes | H15: The company applies required employee training and special training in stores that sell firearms. The company has suffered some cases of data breaching, which puts it employees at risk, though there have been investments in the improvement of cybersecurity protocols.
B16: Daños a la salud | C16: 3 | D16: No | E16: Villain | F16: Yes | H16: The company has faced lawsuits regarding this matter.
B17: PXP? | D17: Yes | E17: Medium high | F17: Yes | H17: The company offers a company-matched retirement savings 401K plan that vests immediately and is open for all teammates.
B18: Supply chain | C18: 3 | D18: Yes | E18: Medium high | F18: No | H18: The company had some ethical issues about sourcing policies to ensure suppliers follow labor practices.
B19: Community involvement | C19: 2 | D19: No | E19: Medium | F19: Yes | H19: Dick’s Sporting Goods Foundation supports youth sports through grants and donations.
B20: Public Sector | C20: 3 | D20: No | E20: Medium | F20: Yes | H20: The company rarely engages in advocacy related to sports policies and youth development.
B21: Litigios | C21: 2 | D21: No | E21: Medium | F21: Yes | H21: Dick’s has faced some legal disputes, including employment-related cases, but actively addresses compliance and workplace policies.
B22: Gobierno
B23: Diversidad (Género, edad, industria, región) | E23: Medium high | F23: Yes | H23: The company plans to achieve 50% female employees compared to the total workforce.
B24: % independientes | E24: Medium high | F24: Yes | H24: A portion of the board consists of independent directors to ensure balanced decision-making.
B25: tiempo promedio como consejeros independientes | E25: Medium | F25: No | H25: Board members serve standard terms with periodic reviews to bring fresh perspectives.
B26: Salidas recientes de consejeros/C-level executives? | E26: Medium | F26: No | H26: The company has experienced leadership changes, such as the transition of CEO Lauren Hobart in 2021
B27: CEO/Chairman | E27: Medium high | F27: No | H27: The CEO and Chairman roles are separate, reinforcing independent leadership.
B28: Transparencia (segmentos, fuente de riqueza, adquisiciones, otros) | E28: Medium | F28: No | H28: Dick’s provides clear financial reports and corporate social responsibility (CSR) disclosures.
B29: Tiempo que tardan en reportar luego del final del trimestre/año | E29: Medium | F29: No | H29: The company follows standard reporting timelines in compliance with SEC regulations.
B30: Participación adicional del CEO en otros consejos o excesiva del Ch. | E30: Medium | F30: No | H30: CEO involvement in external boards is balanced to ensure focus on the company.
B31: Auditoría/Consultoría | D31: No | E31: Medium | F31: Yes | H31: The company undergoes independent financial audits to maintain credibility.
B32: Esquemas de compensación al management | D32: No | E32: Villain | F32: Yes | H32: Executive pay is tied to performance metrics, with bonuses based on company success. However its rare that employees get a raise

Sheet DCF
A1: Discounted Cash Flow
A3: Ventas | E3: Margen Operativo
A16: Inversiones | E16: Utilidad Neta
D31: 0.001 | E31: =1/((1+$B$59+$D31)^(E35-2021)) -> 0.92250923 | F31: =1/((1+$B$59+$D31)^(F35-2021)) -> 0.85102327 | G31: =1/((1+$B$59+$D31)^(G35-2021)) -> 0.78507682 | H31: =1/((1+$B$59+$D31)^(H35-2021)) -> 0.72424061 | I31: =1/((1+$B$59+$D31)^(I35-2021)) -> 0.66811864 | J31: =1/((1+$B$59+$D31)^(J35-2021)) -> 0.61634561 | K31: =1/((1+$B$59+$D31)^(K35-2021)) -> 0.56858451 | L31: =1/((1+$B$59+$D31)^(L35-2021)) -> 0.52452446 | ... AC31: =1/((1+$B$59+$D31)^(AC35-2021)) -> 0.13312755
D32: 0.005 | E32: =1/((1+$B$59+$D32)^(E35-2021)) -> 0.91911765 | F32: =1/((1+$B$59+$D32)^(F35-2021)) -> 0.84477725 | G32: =1/((1+$B$59+$D32)^(G35-2021)) -> 0.77644968 | H32: =1/((1+$B$59+$D32)^(H35-2021)) -> 0.7136486 | I32: =1/((1+$B$59+$D32)^(I35-2021)) -> 0.65592702 | J32: =1/((1+$B$59+$D32)^(J35-2021)) -> 0.6028741 | K32: =1/((1+$B$59+$D32)^(K35-2021)) -> 0.55411223 | L32: =1/((1+$B$59+$D32)^(L35-2021)) -> 0.50929433 | ... AC32: =1/((1+$B$59+$D32)^(AC35-2021)) -> 0.12141647
D33: Normal | E33: =1/((1+$B$59)^(E35-2021)) -> 0.92336103 | F33: =1/((1+$B$59)^(F35-2021)) -> 0.8525956 | G33: =1/((1+$B$59)^(G35-2021)) -> 0.78725355 | H33: =1/((1+$B$59)^(H35-2021)) -> 0.72691926 | I33: =1/((1+$B$59)^(I35-2021)) -> 0.67120892 | J33: =1/((1+$B$59)^(J35-2021)) -> 0.61976816 | K33: =1/((1+$B$59)^(K35-2021)) -> 0.57226977 | L33: =1/((1+$B$59)^(L35-2021)) -> 0.5284116 | ... AC33: =1/((1+$B$59)^(AC35-2021)) -> 0.13623496
B35: 2019 (Real) | C35: 2020 (Real) | D35: 2021 | E35: =D35+1 -> 2022 | F35: =E35+1 -> 2023 | G35: =F35+1 -> 2024 | H35: =G35+1 -> 2025 | I35: =H35+1 -> 2026 | J35: =I35+1 -> 2027 | K35: =J35+1 -> 2028 | L35: =K35+1 -> 2029 | ... AC35: =AB35+1 -> 2046
A36: Crecimiento | B36: =OP!N34 -> 0.095191292 | C36: =OP!N35 -> 0.28269445 | D36: 0.35 | E36: 0.034 | F36: 0.095 | G36: 0.095 | H36: 0.095 | I36: 0.095 | J36: 0.095 | K36: 0.08 | L36: 0.06 | M36: 0.05 | N36: 0.04 | O36: 0.035 | P36: 0.035 | Q36: 0.035 | R36: 0.035 | S36: 0.035 | T36: 0.035 | U36: 0.035 | V36: 0.035 | W36: 0.035 | X36: 0.035 | Y36: 0.035 | Z36: 0.035 | AA36: 0.035 | AB36: 0.035 | AC36: 0.035
A37: Ventas | B37: =OP!C34 -> 9584.019 | C37: =OP!C35 -> 12293.368 | D37: =OP!C34*(1+D36) -> 12938.426 | E37: =D37*(1+E36) -> 13378.332 | F37: =E37*(1+F36) -> 14649.274 | G37: =F37*(1+G36) -> 16040.955 | H37: =G37*(1+H36) -> 17564.845 | I37: =H37*(1+I36) -> 19233.506 | J37: =I37*(1+J36) -> 21060.689 | K37: =J37*(1+K36) -> 22745.544 | L37: =K37*(1+L36) -> 24110.276 | ... AC37: =AB37*(1+AC36) -> 44109.291
A38: Margen Operativo | B38: =+OP!D34 -> 0.077365978 | C38: =+OP!D35 -> 0.16549598 | D38: =108166.4/365513.2 -> 0.29593022 | E38: =108162.8/377959.8 -> 0.28617541 | F38: 0.27 | G38: 0.275 | H38: 0.26 | I38: 0.255 | J38: 0.25 | K38: 0.25 | L38: 0.25 | M38: 0.25 | N38: 0.25 | O38: 0.25 | P38: 0.25 | Q38: 0.25 | R38: 0.25 | S38: 0.25 | T38: 0.25 | U38: 0.25 | V38: 0.25 | W38: 0.25 | X38: 0.25 | Y38: 0.25 | Z38: 0.25 | AA38: 0.25 | AB38: 0.25 | AC38: 0.25
A39: EBIT | B39: 63930 | C39: 66288 | D39: =D37*D38 -> 3828.8711 | E39: =E37*E38 -> 3828.5497 | F39: =F37*F38 -> 3955.3039 | G39: =G37*G38 -> 4411.2625 | H39: =H37*H38 -> 4566.8598 | I39: =I37*I38 -> 4904.5439 | J39: =J37*J38 -> 5265.1722 | K39: =K37*K38 -> 5686.386 | ... AC39: =AC37*AC38 -> 11027.323
A40: Dep&Amort | B40: =OP!H34 -> 326.014 | C40: =OP!H35 -> 322.551 | D40: 11000 | E40: =D40*(1+E36*$H$59) -> 11374 | F40: =E40*(1+F36*$H$59) -> 12454.53 | G40: =F40*(1+G36*$H$59) -> 13637.71 | H40: =G40*(1+H36*$H$59) -> 14933.293 | I40: =H40*(1+I36*$I$59) -> 16351.956 | J40: =I40*(1+J36*$I$59) -> 17905.391 | K40: =J40*(1+K36*$I$59) -> 19337.823 | L40: =K40*(1+L36*$I$59) -> 20498.092 | M40: =L40*(1+M36*$I$59) -> 21522.997 | N40: =M40*(1+N36*$I$59) -> 22383.917 | O40: =N40*(1+O36*$I$59) -> 23167.354 | P40: =O40*(1+P36*$I$59) -> 23978.211 | ... AC40: =AB40*(1+AC36*$I$59) -> 37500.868
A41: EBIDTA | B41: =+B39+B40 -> 64256.014 | C41: =+C39+C40 -> 66610.551 | D41: =D39+D40 -> 14828.871 | E41: =E39+E40 -> 15202.55 | F41: =F39+F40 -> 16409.834 | G41: =G39+G40 -> 18048.973 | H41: =H39+H40 -> 19500.153 | I41: =I39+I40 -> 21256.5 | J41: =J39+J40 -> 23170.564 | K41: =K39+K40 -> 25024.209 | ... AC41: =AC39+AC40 -> 48528.191
A42: CIF | B42: -1385 | C42: -890 | D42: =(C48)*$H$60 -> -1124.36 | E42: =(D48)*$H$60 -> -1113.1164 | F42: =(E48)*$H$60 -> -1113.1164 | G42: =(F48)*$H$60 -> -1113.1164 | H42: =(G48)*$H$60 -> -1113.1164 | I42: =(H48)*$H$60 -> -1113.1164 | J42: =(I48)*$H$60 -> -1113.1164 | K42: =(J48)*$H$60 -> -1113.1164 | ... AC42: =(AB48)*$H$60 -> -1113.1164
A43: Otros Gastos | B43: =-422-2817 -> -3239 | C43: =87-3634 -> -3547 | D43: =-C43*(1+D36) -> 4788.45 | E43: =D43*(1+E36*0.5) -> 4869.8537 | F43: =E43*(1+F36*0.5) -> 5101.1717 | G43: =F43*(1+G36*0.5) -> 5343.4774 | H43: =G43*(1+H36*0.5) -> 5597.2925 | I43: =H43*(1+I36*0.5) -> 5863.1639 | J43: =I43*(1+J36*0.5) -> 6141.6642 | K43: =J43*(1+K36*0.5) -> 6387.3308 | L43: =K43*(1+L36*0.5) -> 6578.9507 | ... AC43: =AB43*(1+AC36*0.5) -> 8922.7133
A44: Utilidad antes de Impuestos | B44: =B39-B42-B43 -> 68554 | C44: =C39-C42-C43 -> 70725 | D44: =D39-D42-D43 -> 164.78109 | E44: =E39-E42-E43 -> 71.812404 | F44: =F39-F42-F43 -> -32.751406 | G44: =G39-G42-G43 -> 180.90158 | H44: =H39-H42-H43 -> 82.683667 | I44: =I39-I42-I43 -> 154.49642 | ... AC44: =AC39-AC42-AC43 -> 3217.7258
A45: ISR & PTU | B45: 10481 | C45: 9680 | D45: =$H$61*D44 -> 34.604029 | E45: =$H$61*E44 -> 15.080605 | F45: =$H$61*F44 -> -6.8777954 | G45: =$I$61*G44 -> 41.607364 | H45: =$I$61*H44 -> 19.017243 | I45: =$I$61*I44 -> 35.534178 | J45: =$I$61*J44 -> 54.423605 | K45: =$I$61*K44 -> 94.799462 | L45: =$I$61*L44 -> 129.19901 | M45: =$I$61*M44 -> 160.68708 | N45: =$I$61*N44 -> 187.89365 | ... AC45: =$I$61*AC44 -> 740.07694
A46: Utilidad Neta | B46: =B44-B45 -> 58073 | C46: =C44-C45 -> 61045 | D46: =D44-D45 -> 130.17706 | E46: =E44-E45 -> 56.731799 | F46: =F44-F45 -> -25.873611 | G46: =G44-G45 -> 139.29422 | H46: =H44-H45 -> 63.666424 | I46: =I44-I45 -> 118.96225 | ... AC46: =AC44-AC45 -> 2477.6489
A47: Inversiones y Capex | B47: =OP!I34 -> 175.8 | C47: =OP!I35 -> 268.1 | D47: 10000 | E47: =D47*(1+E36*$H$62) -> 10408 | F47: =E47*(1+F36*$H$62) -> 11594.512 | G47: =F47*(1+G36*$H$62) -> 12916.286 | H47: =G47*(1+H36*$H$62) -> 14388.743 | I47: =H47*(1+I36*$H$62) -> 16029.06 | J47: =I47*(1+J36*$H$62) -> 17856.373 | K47: =J47*(1+K36*$H$62) -> 19570.584 | L47: =K47*(1+L36*$H$62) -> 20979.666 | ... AC47: =AB47*(1+AC36*$H$62) -> 43199.777
A48: Deuda + Lease Liabilities | B48: 108047 | C48: 112436 | D48: =C48*0.99 -> 111311.64 | E48: =D48 -> 111311.64 | F48: =E48 -> 111311.64 | G48: =F48 -> 111311.64 | H48: =G48 -> 111311.64 | I48: =H48 -> 111311.64 | J48: =I48 -> 111311.64 | K48: =J48 -> 111311.64 | L48: =K48 -> 111311.64 | ... AC48: =AB48 -> 111311.64
A49: Deuda/EBITDA | B49: =B48/B41 -> 1.681508 | C49: =C48/C41 -> 1.6879608 | D49: =D48/D41 -> 7.5064136 | E49: =E48/E41 -> 7.321906
A50: FNP | B50: =OP!F34 -> 1696.5225 | C50: =OP!F35 -> 2772.7525 | D50: =D41-D42-D43-D45-D47+D48-C48 -> 5.8170605 | E50: =E41-E42-E43-E45-E47+E48-D48 -> 1022.7318 | F50: =F41-F42-F43-F45-F47+F48-E48 -> 834.14439 | G50: =G41-G42-G43-G45-G47+G48-F48 -> 860.7182 | H50: =H41-H42-H43-H45-H47+H48-G48 -> 608.21624 | I50: =I41-I42-I43-I45-I47+I48-H48 -> 441.85818 | J50: =J41-J42-J43-J45-J47+J48-I48 -> 231.21968 | K50: =K41-K42-K43-K45-K47+K48-J48 -> 84.61058 | ... AC50: =AC41-AC42-AC43-AC45-AC47+AC48-AB48 -> -3221.2601
A51: F(t) | B51: 0 | C51: 0 | D51: =C51*(1+$B$59)+D50 -> 5.8170605 | E51: =D51*(1+$B$59)+E50 -> 1029.0317 | F51: =E51*(1+$B$59)+F50 -> 1948.5857 | G51: =F51*(1+$B$59)+G50 -> 2971.0365 | H51: =G51*(1+$B$59)+H50 -> 3825.8488 | I51: =H51*(1+$B$59)+I50 -> 4585.2524 | J51: =I51*(1+$B$59)+J50 -> 5197.048 | K51: =J51*(1+$B$59)+K50 -> 5713.0136 | ... AC51: =AB51*(1+$B$59)+AC50 -> -14352.673
AB52: =AB51-AB48 -> -121589.95 | AC52: =AC50/(B59-AC36) -> -67109.585
A53: EPS | C53: =1000000*C46/OP!$C$8 -> 749.29422 | D53: =1000000*D46/OP!$C$8 -> 1.5978527 | E53: =1000000*E46/OP!$C$8 -> 0.69635202 | F53: =1000000*F46/OP!$C$8 -> -0.31758452
A54: Consenso EPS | C54: 3.3 | D54: 5.6 | E54: 5.6
A55: E$/UN | D55: =$B$61/D46 -> -197.48084 | E55: =$B$61/E46 -> -453.14048 | F55: =$B$61/F46 -> 993.57894
A56: EEV/EBIDA | D56: =($B$61+D48-D51)/D41 -> 5.7724116 | E56: =($B$61+E48-E51)/E41 -> 5.5632203 | F56: =($B$61+F48-F51)/F41 -> 5.0978931
C58: "TELP" | D58: CER | E58: D Analista | H58: CP | I58: LP
A59: Tasa de descuento: | B59: =SUM(C59:E59) -> 0.083 | C59: 0.0307 | D59: 0.0523 | E59: 0 | G59: Factor D&A | H59: 1 | I59: 1
G60: Factor CIF | H60: -0.01
A61: VPN*@i% | B61: =C62+C63 -> -25707.475 | C61: Normal | D61: =D31 -> 0.001 | E61: =D32 -> 0.005 | G61: Factor ISR | H61: 0.21 | I61: 0.23
A62: DCF 25Y | B62: =C62/B61 -> 0.64435745 | C62: =AB52/(1+B59)^25 -> -16564.803 | D62: =SUMPRODUCT(E50:AB50,E31:AB31) -> -1451.4891 | E62: =SUMPRODUCT(E50:AB50,E32:AB32) -> -1182.0448 | G62: Factor inv | H62: 1.2
A63: Perpetuidad | B63: =1-B62 -> 0.35564255 | C63: =AC52/(1+B59)^25 -> -9142.672 | D63: =(AC50/($B$59+D31-$AC$36))*AC31 -> -8751.8055 | E63: =(AC50/($B$59+D32-$AC$36))*AC32 -> -7379.5102 | G63: Suma D&A | H63: =SUM(40:40) -> 629078.14
A64: VPN/Acción | B64: =1000000*B61/OP!C8 -> -315.54529 | D64: =1000000*SUM(D62:D63)/OP!C8 -> -125.2399 | E64: =1000000*SUM(E62:E63)/OP!C8 -> -105.08844 | G64: Suma Inv. | H64: =SUM(47:47) -> 673289.29
B65: =B64/OP!C7-1 -> -2.5858938 | D65: =D64/B64-1 -> -0.60310009 | E65: =E64/B64-1 -> -0.66696243 | G65: Inv.+Goodwill | H65: =SUM(47:47)+(OP!E12*OP!E7) -> 676197.99
A67: Duración | B67: =B62*D68+B63*D69 -> 46.32178 | E67: 1 | F67: 2 | G67: 3 | H67: 4 | I67: 5 | J67: 6 | K67: 7 | L67: 8 | M67: 9 | N67: 10 | O67: 11 | P67: 12 | Q67: 13 | R67: 14 | S67: 15 | T67: 16 | U67: 17 | V67: 18 | W67: 19 | X67: 20 | Y67: 21 | Z67: 22 | AA67: 23 | AB67: 24 | AC67: 25
A68: 0.001 | B68: =-$B$67*A68 -> -0.04632178 | D68: =SUM(E68:AB68)/SUMPRODUCT(E50:AB50,E33:AB33) -> 50.888251 | E68: =E67*E50*E33 -> 944.35069 | F68: =F67*F50*F33 -> 1422.3757 | G68: =G67*G50*G33 -> 2032.8104 | H68: =H67*H50*H33 -> 1768.4964 | I68: =I67*I50*I33 -> 1482.8958 | J68: =J67*J50*J33 -> 859.81557 | K68: =K67*K50*K33 -> 338.94054 | L68: =L67*L50*L33 -> -207.29982 | ... AC68: =AC67*AC50*AC33 -> -10971.206
A69: 0.005 | B69: =-$B$67*A69 -> -0.2316089 | D69: =(1+B59)/B59+AC67 -> 38.048193

Sheet DCFF
C1: VALUATION MODEL
C2: Año fiscal de DICK'S Sporting Goods cierra en febrero
D3: =D19/D6 -> -0.0052354863 | E3: =E19/E6 -> -0.0042949987 | F3: =F19/F6 -> -0.0040913802 | G3: 0 | H3: 0.25 | I3: =H3+1 -> 1.25 | J3: =I3+1 -> 2.25 | K3: =J3+1 -> 3.25 | L3: =K3+1 -> 4.25 | M3: =L3+1 -> 5.25 | N3: =M3+1 -> 6.25 | O3: =N3+1 -> 7.25 | P3: =O3+1 -> 8.25 | ... AF3: =AE3+1 -> 24.25 | AH3: interest expense as percentage of revenues
A4: Section | B4: Line # | C4: ITEM | D4: 2020 (Real) | E4: 2021 (Real) | F4: 2022 (Real) | G4: 2023 (Real) | H4: 2024 | I4: =+H4+1 -> 2025 | J4: =+I4+1 -> 2026 | K4: =+J4+1 -> 2027 | L4: =+K4+1 -> 2028 | M4: =+L4+1 -> 2029 | N4: =+M4+1 -> 2030 | O4: =+N4+1 -> 2031 | P4: =+O4+1 -> 2032 | ... AF4: =+AE4+1 -> 2048 | AG4: Notes | AH4: interest expense | AI4: -2.929 | AJ4: -3.215 | AK4: -4.012 | AL4: -5.856 | AM4: -8.047 | AN4: -10.248 | AO4: -17.012 | AP4: -48.812 | AQ4: -57.839 | AR4: -95.22 | AS4: -58.023
A5: INCOME STATEMENT | B5: 1 | C5: Growth | D5: =Cifras_en_Millones!F6 -> 0.095223457 | E5: =Cifras_en_Millones!E6 -> 0.28269445 | F5: =Cifras_en_Millones!D6 -> 0.0060870219 | G5: =Cifras_en_Millones!C6 -> 0.049821405 | H5: 0.034 | I5: 0.035 | J5: 0.0429 | K5: 0.048 | L5: 0.042 | M5: 0.04 | N5: 0.04 | O5: 0.038 | P5: 0.038 | Q5: 0.036 | R5: 0.036 | S5: 0.034 | T5: 0.034 | U5: 0.032 | V5: 0.032 | W5: 0.03 | X5: 0.03 | Y5: 0.028 | Z5: 0.028 | AA5: 0.026 | AB5: 0.026 | AC5: 0.024 | AD5: 0.022 | AE5: 0.022 | AF5: 0.02 | AH5: revenues | AI5: 6213.173 | AJ5: 6814.479 | AK5: 7270.965 | AL5: 7921.981 | AM5: 8590.472 | AN5: 8436.57 | AO5: 8750.743 | AP5: 9584.019 | AQ5: 12293.368 | AR5: 12368.198 | AS5: 12984.399
B6: 2 | C6: Revenues/Sales | D6: 9584.019 | E6: 12293.368 | F6: 12368.198 | G6: 12984.399 | H6: =G6*(1+H5) -> 13425.869 | I6: =H6*(1+I5) -> 13895.774 | J6: =I6*(1+J5) -> 14491.903 | K6: =J6*(1+K5) -> 15187.514 | L6: =K6*(1+L5) -> 15825.39 | M6: =L6*(1+M5) -> 16458.405 | N6: =M6*(1+N5) -> 17116.741 | O6: =N6*(1+O5) -> 17767.178 | ... AF6: =AE6*(1+AF5) -> 29019.712 | AH6: interest expense as percentage of revenues | AI6: =AI4/AI5 -> -0.00047141774 | AJ6: =AJ4/AJ5 -> -0.00047178955 | AK6: =AK4/AK5 -> -0.0005517837 | AL6: =AL4/AL5 -> -0.00073920904 | AM6: =AM4/AM5 -> -0.00093673549 | AN6: =AN4/AN5 -> -0.0012147117 | AO6: =AO4/AO5 -> -0.0019440635 | AP6: =AP4/AP5 -> -0.0050930617 | ... AS6: =AS4/AS5 -> -0.0044686704
B7: 3 | C7: EBIT/Operating Margin | D7: =D8/D6 -> 0.077365978 | E7: =E8/E6 -> 0.16549598 | F7: =F8/F6 -> 0.11828878 | G7: =G8/G6 -> 0.098761984 | H7: 0.112 | I7: 0.11 | J7: 0.11 | K7: 0.11 | L7: 0.085 | M7: 0.085 | N7: 0.085 | O7: 0.085 | P7: 0.085 | Q7: 0.085 | R7: 0.085 | S7: 0.085 | T7: 0.085 | U7: 0.085 | V7: 0.085 | W7: 0.085 | X7: 0.085 | Y7: 0.085 | Z7: 0.085 | AA7: 0.085 | AB7: 0.085 | AC7: 0.085 | AD7: 0.085 | AE7: 0.085 | AF7: 0.085 | AH7: short term average | AI7: =AVERAGE(AP6:AS6) -> -0.005491351
B8: 4 | C8: EBIT | D8: 741.477 | E8: 2034.503 | F8: 1463.019 | G8: 1282.365 | H8: =H6*H7 -> 1503.6973 | I8: =I6*I7 -> 1528.5351 | J8: =J6*J7 -> 1594.1093 | K8: =K6*K7 -> 1670.6265 | L8: =L6*L7 -> 1345.1581 | M8: =M6*M7 -> 1398.9644 | N8: =N6*N7 -> 1454.923 | O8: =O6*O7 -> 1510.2101 | ... AF8: =AF6*AF7 -> 2466.6755 | AH8: long term average | AI8: =AVERAGE(AI6:AS6) -> -0.0025722831
B9: 5a | C9: (Dep&Amort) | D9: -326.014 | E9: -322.551 | F9: -365.475 | G9: -393.933 | H9: =H22*$D50 -> -100.69401 | I9: =I22*$D50 -> -104.2183 | J9: =J22*$D50 -> -108.68927 | K9: =K22*$D50 -> -113.90635 | L9: =L22*$E50 -> -118.69042 | M9: =M22*$E50 -> -123.43804 | N9: =N22*$E50 -> -128.37556 | O9: =O22*$E50 -> -133.25383 | P9: =P22*$E50 -> -138.31748 | Q9: =Q22*$E50 -> -143.29691 | R9: =R22*$E50 -> -148.4556 | S9: =S22*$E50 -> -153.50309 | ... AF9: =AF22*$E50 -> -217.64784
B10: 5b | C10: (Stock based compensation) | D10: -50.177 | E10: -52.8 | F10: -50.603 | G10: -57.285 | H10: =H6*$D51 -> -60.416409 | I10: =I6*$D51 -> -62.530983 | J10: =J6*$D51 -> -65.213562 | K10: =K6*$D51 -> -68.343813 | L10: =L6*$D51 -> -71.214253 | M10: =M6*$D51 -> -74.062823 | N10: =N6*$D51 -> -77.025336 | O10: =O6*$D51 -> -79.952299 | ... AF10: =AF6*$D51 -> -130.5887
B11: 6 | C11: EBIDTA | D11: =D8-D9-D10 -> 1117.668 | E11: =E8-E9-E10 -> 2409.854 | F11: =F8-F9-F10 -> 1879.097 | G11: =G8-G9-G10 -> 1733.583 | H11: =H8-H9 -> 1604.3913 | I11: =I8-I9 -> 1632.7534 | J11: =J8-J9 -> 1702.7986 | K11: =K8-K9 -> 1784.5329 | L11: =L8-L9 -> 1463.8485 | M11: =M8-M9 -> 1522.4025 | N11: =N8-N9 -> 1583.2986 | O11: =O8-O9 -> 1643.4639 | ... AF11: =AF8-AF9 -> 2684.3234 | AH11: other income/cost as % of capex
B12: 7 | C12: (Interest Expense) | D12: -48.812 | E12: -57.839 | F12: -95.22 | G12: -58.023 | H12: =H6*$AI7 -> -73.726156 | I12: =I6*$AI7 -> -76.306572 | J12: =J6*$AI7 -> -79.580124 | K12: =K6*$AI7 -> -83.399969 | L12: =L6*$AI8 -> -40.707383 | M12: =M6*$AI8 -> -42.335678 | N12: =N6*$AI8 -> -44.029105 | O12: =O6*$AI8 -> -45.702211 | P12: =P6*$AI8 -> -47.438895 | Q12: =Q6*$AI8 -> -49.146695 | R12: =R6*$AI8 -> -50.915976 | S12: =S6*$AI8 -> -52.64712 | ... AF12: =AF6*$AI8 -> -74.646916 | AH12: other income/cost | AM12: 31.81 | AN12: -2.565 | AO12: 15.324 | AP12: 19.07 | AQ12: 17.774 | AR12: 15.949 | AS12: 93.809
B13: 8 | C13: Other income/(cost) | D13: 19.07 | E13: 17.774 | F13: 15.949 | G13: 93.809 | H13: =H22*$AP16 -> 34.868778 | I13: =I22*$AP16 -> 36.089185 | J13: =J22*$AP16 -> 37.637411 | K13: =K22*$AP16 -> 39.444007 | L13: =L22*$AM17 -> 31.936046 | M13: =M22*$AM17 -> 33.213487 | N13: =N22*$AM17 -> 34.542027 | O13: =O22*$AM17 -> 35.854624 | P13: =P22*$AM17 -> 37.2171 | Q13: =Q22*$AM17 -> 38.556915 | R13: =R22*$AM17 -> 39.944964 | S13: =S22*$AM17 -> 41.303093 | ... AF13: =AF22*$AM17 -> 58.56253 | AH13: Capex | AM13: -474.347 | AN13: -198.219 | AO13: =-(217.461) -> -217.461 | AP13: -224.027 | AQ13: -308.261 | AR13: -364.075 | AS13: -587.426
B14: 9 | C14: Earnings before taxes | D14: =D8+D12+D13 -> 711.735 | E14: =E8+E12+E13 -> 1994.438 | F14: =F8+F12+F13 -> 1383.748 | G14: =G8+G12+G13 -> 1318.151 | H14: =H8+H12+H13 -> 1464.8399 | I14: =I8+I12+I13 -> 1488.3177 | J14: =J8+J12+J13 -> 1552.1666 | K14: =K8+K12+K13 -> 1626.6706 | ... AF14: =AF8+AF12+AF13 -> 2450.5911 | AH14: short term | AP14: =AP12/AP13 -> -0.085123668 | AQ14: =AQ12/AQ13 -> -0.057658932 | AR14: =AR12/AR13 -> -0.043806908 | AS14: =AS12/AS13 -> -0.15969501
B15: 10 | C15: (Income tax) | D15: -181.484 | E15: -474.567 | F15: -340.61 | G15: -271.632 | H15: =-H14*$D52 -> -351.56158 | I15: =-I14*$D52 -> -357.19626 | J15: =-J14*$D52 -> -372.51998 | K15: =-K14*$D52 -> -390.40094 | L15: =-L14*$D52 -> -320.73283 | M15: =-M14*$D52 -> -333.56214 | N15: =-N14*$D52 -> -346.90463 | O15: =-O14*$D52 -> -360.087 | ... AF15: =-AF14*$D52 -> -588.14187 | AH15: long term | AM15: =AM12/AM13 -> -0.067060612 | AN15: =AN12/AN13 -> 0.012940233 | AO15: =AO12/AO13 -> -0.070467808 | AP15: =AP12/AP13 -> -0.085123668 | AQ15: =AQ12/AQ13 -> -0.057658932 | AR15: =AR12/AR13 -> -0.043806908 | AS15: =AS12/AS13 -> -0.15969501
B16: 11 | C16: Net income | D16: =D14+D15 -> 530.251 | E16: =E15+E14 -> 1519.871 | F16: =F14+F15 -> 1043.138 | G16: =G14+G15 -> 1046.519 | H16: =H14+H15 -> 1113.2783 | I16: =I14+I15 -> 1131.1215 | J16: =J14+J15 -> 1179.6466 | K16: =K14+K15 -> 1236.2696 | L16: =L14+L15 -> 1015.654 | M16: =M14+M15 -> 1056.2801 | ... AF16: =AF14+AF15 -> 1862.4493 | AL16: average short | AP16: =SUM(AP14:AS14)/4 -> -0.086571129
AL17: average long | AM17: =SUM(AM15:AS15)/7 -> -0.067267529
A18: CASH FLOW STATEMENT | B18: 12 | C18: Operating cash flows before WK | D18: 831.596 | E18: 1889.667 | F18: 1451.269 | G18: 1455.491 | H18: =H11+H12+H13+H15 -> 1213.9723 | I18: =I11+I12+I13+I15 -> 1235.3398 | J18: =J11+J12+J13+J15 -> 1288.3359 | K18: =K11+K12+K13+K15 -> 1350.176 | L18: =L11+L12+L13+L15 -> 1134.3444 | M18: =M11+M12+M13+M15 -> 1179.7181 | N18: =N11+N12+N13+N15 -> 1226.9069 | O18: =O11+O12+O13+O15 -> 1273.5293 | ... AF18: =AF11+AF12+AF13+AF15 -> 2080.0971
B19: 13 | C19: (Stock-based compensation) | D19: -50.177 | E19: -52.8 | F19: -50.603 | G19: -57.285 | H19: =H10 -> -60.416409 | I19: =I10 -> -62.530983 | J19: =J10 -> -65.213562 | K19: =K10 -> -68.343813 | L19: =L10 -> -71.214253 | M19: =M10 -> -74.062823 | N19: =N10 -> -77.025336 | O19: =O10 -> -79.952299 | ... AF19: =AF10 -> -130.5887
B20: 14 | C20: (Working Capital Flows) | D20: 670.996 | E20: -325.595 | F20: -579.991 | G20: 14.559 | H20: =$D56*(H6-G6) -> -551.83696 | I20: =$D56*(I6-H6) -> -587.38175 | J20: =$D56*(J6-I6) -> -745.16088 | K20: =$D56*(K6-J6) -> -869.51416 | L20: =$E56*(L6-K6) -> -797.34448 | M20: =$E56*(M6-L6) -> -791.26948 | N20: =$E56*(N6-M6) -> -822.92026 | O20: =$E56*(O6-N6) -> -813.04522 | P20: =$E56*(P6-O6) -> -843.94093 | Q20: =$E56*(Q6-P6) -> -829.90486 | R20: =$E56*(R6-Q6) -> -859.78144 | S20: =$E56*(S6-R6) -> -841.24837 | ... AF20: =$E56*(AF6-AE6) -> -711.26745
B21: 15 | C21: -Total Operating Cash Flow | D21: =D18-D19+D20 -> 1552.769 | E21: =E18-E19+E20 -> 1616.872 | F21: =F18-F19+F20 -> 921.881 | G21: =G18-G19+G20 -> 1527.335 | H21: =H18-H19+H20 -> 722.55179 | I21: =I18-I19+I20 -> 710.48903 | J21: =J18-J19+J20 -> 608.38855 | K21: =K18-K19+K20 -> 549.00565 | ... AF21: =AF18-AF19+AF20 -> 1499.4184
B22: 16 | C22: (CAPEX and Acquisitions) | D22: -224.027 | E22: -308.261 | F22: -364.075 | G22: -587.426 | H22: =-$D$57*H6 -> -402.77606 | I22: =-$D$57*I6 -> -416.87322 | J22: =-$D$57*J6 -> -434.75708 | K22: =-$D$57*K6 -> -455.62542 | L22: =-$E$57*L6 -> -474.76169 | M22: =-$E$57*M6 -> -493.75216 | N22: =-$E$57*N6 -> -513.50224 | O22: =-$E$57*O6 -> -533.01533 | P22: =-$E$57*P6 -> -553.26991 | Q22: =-$E$57*Q6 -> -573.18763 | R22: =-$E$57*R6 -> -593.82238 | S22: =-$E$57*S6 -> -614.01234 | ... AF22: =-$E$57*AF6 -> -870.59136
B23: 17 | C23: (Other investing flows) | D23: -0.137 | E23: -35.718 | F23: -28.819 | G23: -27.25 | H23: 0 | I23: 0 | J23: 0 | K23: 0 | L23: 0 | M23: 0 | N23: 0 | O23: 0 | P23: 0 | Q23: 0 | R23: 0 | S23: 0 | T23: 0 | U23: 0 | V23: 0 | W23: 0 | X23: 0 | Y23: 0 | Z23: 0 | AA23: 0 | AB23: 0 | AC23: 0 | AD23: 0 | AE23: 0 | AF23: 0
B24: 18 | C24: -Total Investing Flows | D24: =D22+D23 -> -224.164 | E24: =E22+E23 -> -343.979 | F24: =F22+F23 -> -392.894 | G24: =G22+G23 -> -614.676 | H24: =H22+H23 -> -402.77606 | I24: =I22+I23 -> -416.87322 | J24: =J22+J23 -> -434.75708 | K24: =K22+K23 -> -455.62542 | ... AF24: =AF22+AF23 -> -870.59136
B25: 19 | C25: (Flows related to leases) | D25: -0.826 | E25: -0.726 | F25: -0.74 | G25: -0.823 | H25: 0 | I25: 0 | J25: 0 | K25: 0 | L25: 0 | M25: 0 | N25: 0 | O25: 0 | P25: 0 | Q25: 0 | R25: 0 | S25: 0 | T25: 0 | U25: 0 | V25: 0 | W25: 0 | X25: 0 | Y25: 0 | Z25: 0 | AA25: 0 | AB25: 0 | AC25: 0 | AD25: 0 | AE25: 0 | AF25: 0
B26: 20 | C26: Flows related to debt | D26: 172.447 | E26: 1481.403 | F26: -515.865 | G26: -0.137 | H26: 300 | I26: 500 | J26: 600 | K26: 700 | L26: 700 | M26: 700 | N26: 700 | O26: 600 | P26: 700 | Q26: 700 | R26: 700 | S26: 700 | T26: 700 | U26: 700 | V26: 700 | W26: 700 | X26: 700 | Y26: 700 | Z26: 700 | AA26: 700 | AB26: 700 | AC26: 700 | AD26: 700 | AE26: 700 | AF26: 700
B27: 21 | C27: (Repurchases)/Issuance of stock | D27: 138.631 | E27: -1150.882 | F27: -478.711 | G27: -732.266 | H27: =H16*$D55 -> -445.31133 | I27: =I16*$D55 -> -452.4486 | J27: =J16*$D55 -> -471.85864 | K27: =K16*$D55 -> -494.50786 | L27: =L16*$E55 -> -406.26158 | M27: =M16*$E55 -> -422.51204 | N27: =N16*$E55 -> -439.41253 | O27: =O16*$E55 -> -456.1102 | P27: =P16*$E55 -> -473.44239 | Q27: =Q16*$E55 -> -490.48631 | R27: =R16*$E55 -> -508.14382 | S27: =S16*$E55 -> -525.42071 | ... AF27: =AF16*$E55 -> -744.97971
B28: 22 | C28: (Dividends) | D28: -107.404 | E28: -602.964 | F28: -163.081 | G28: -351.201 | H28: =H16*$D58 -> -300.58515 | I28: =I16*$D58 -> -305.4028 | J28: =J16*$D58 -> -318.50458 | K28: =K16*$D58 -> -333.7928 | L28: =L16*$E58 -> -253.91349 | M28: =M16*$E58 -> -264.07003 | N28: =N16*$E58 -> -274.63283 | O28: =O16*$E58 -> -285.06888 | P28: =P16*$E58 -> -295.90149 | Q28: =Q16*$E58 -> -306.55395 | R28: =R16*$E58 -> -317.58989 | S28: =S16*$E58 -> -328.38795 | ... AF28: =AF16*$E58 -> -465.61232
B29: 23 | C29: Other financing flows | D29: 57.209 | E29: -14.553 | F29: -89.239 | G29: 48.679 | H29: =G29*(1+H5) -> 50.334086 | I29: =H29*(1+I5) -> 52.095779 | J29: =I29*(1+J5) -> 54.330688 | K29: =J29*(1+K5) -> 56.938561 | L29: =K29*(1+L5) -> 59.329981 | M29: =L29*(1+M5) -> 61.70318 | N29: =M29*(1+N5) -> 64.171307 | O29: =N29*(1+O5) -> 66.609817 | ... AF29: =AE29*(1+AF5) -> 108.79599
B30: 24 | C30: -Total Financing flows | D30: 260.057 | E30: =SUM(E25:E29) -> -287.722 | F30: =SUM(F25:F29) -> -1247.636 | G30: =SUM(G25:G29) -> -1035.748 | H30: =SUM(H25:H29) -> -395.56239 | I30: =SUM(I25:I29) -> -205.75562 | J30: =SUM(J25:J29) -> -136.03254 | K30: =SUM(K25:K29) -> -71.362097 | L30: =SUM(L25:L29) -> 99.154912 | ... AF30: =SUM(AF25:AF29) -> -401.79603
A32: SUMMARY | B32: 25 | C32: Cash before shareholder returns | D32: =D21+D24+D25+D26+D29 -> 1557.435 | E32: =E21+E24+E25+E26+E29 -> 2739.017 | F32: =F21+F24+F25+F26+F29 -> -76.857 | G32: =G21+G24+G25+G26+G29 -> 960.378 | H32: =H21+H24+H25+H26+H29 -> 670.10982 | I32: =I21+I24+I25+I26+I29 -> 845.71159 | J32: =J21+J24+J25+J26+J29 -> 827.96216 | K32: =K21+K24+K25+K26+K29 -> 850.31879 | ... AF32: =AF21+AF24+AF25+AF26+AF29 -> 1437.623
B33: 26 | C33: Returns to shareholders | D33: =-1*(D27+D28) -> -31.227 | E33: =-1*(E27+E28) -> 1753.846 | F33: =-1*(F27+F28) -> 641.792 | G33: =-1*(G27+G28) -> 1083.467 | H33: =-1*(H27+H28) -> 745.89648 | I33: =-1*(I27+I28) -> 757.8514 | J33: =-1*(J27+J28) -> 790.36322 | K33: =-1*(K27+K28) -> 828.30066 | ... AF33: =-1*(AF27+AF28) -> 1210.592
B34: 27 | C34: Excess cash acumulation | D34: =D32-D33 -> 1588.662 | E34: =E32-E33 -> 985.171 | F34: =F32-F33 -> -718.649 | G34: =G32-G33 -> -123.089 | H34: =H32-H33 -> -75.786658 | I34: =I32-I33 -> 87.86019 | J34: =J32-J33 -> 37.59894 | K34: =K32-K33 -> 22.01813 | ... AF34: =AF32-AF33 -> 227.03096
A36: CASH & DEBT & DISCOUNTING | B36: 28 | C36: Ending cash balance | D36: 1658.067 | E36: =D36+E34 -> 2643.238 | F36: =E36+F34 -> 1924.589 | G36: =F36+G34 -> 1801.5 | H36: =G36+H34 -> 1725.7133 | I36: =H36+I34 -> 1813.5735 | J36: =I36+J34 -> 1851.1725 | K36: =J36+K34 -> 1873.1906 | L36: =K36+L34 -> 1905.798 | ... AF36: =AE36+AF34 -> 3063.5178
B37: 29 | C37: Total Debt | D37: =Cifras_en_Millones!F60 -> 4967.785 | E37: =Cifras_en_Millones!E60 -> 6425.123 | F37: =Cifras_en_Millones!D60 -> 5949.528 | G37: =Cifras_en_Millones!C60 -> 6157.57 | H37: =G37 -> 6157.57 | I37: =H37 -> 6157.57 | J37: =I37 -> 6157.57 | K37: =J37 -> 6157.57 | L37: =K37 -> 6157.57 | M37: =L37 -> 6157.57 | N37: =M37 -> 6157.57 | O37: =N37 -> 6157.57 | ... AF37: =AE37 -> 6157.57
B38: 30 | C38: Discount factor | G38: =1/((1+$D$47)^G3) -> 1 | H38: =1/((1+$D$47)^H3) -> 0.978686 | I38: =1/((1+$D$47)^I3) -> 0.89787706 | J38: =1/((1+$D$47)^J3) -> 0.82374043 | K38: =1/((1+$D$47)^K3) -> 0.75572516 | L38: =1/((1+$D$47)^L3) -> 0.69332584 | M38: =1/((1+$D$47)^M3) -> 0.63607875 | N38: =1/((1+$D$47)^N3) -> 0.58355848 | ... AF38: =1/((1+$D$47)^AF3) -> 0.12371075
F39: =1/((1+$D$48+0.001)^F$3) -> 1.0000041 | G39: =1/((1+$D$47+0.001)^G$3) -> 1 | H39: =1/((1+$D$47+0.001)^H$3) -> 0.97846166 | I39: =1/((1+$D$47+0.001)^I$3) -> 0.89684845 | J39: =1/((1+$D$47+0.001)^J$3) -> 0.82204258 | K39: =1/((1+$D$47+0.001)^K$3) -> 0.75347624 | L39: =1/((1+$D$47+0.001)^L$3) -> 0.690629 | M39: =1/((1+$D$47+0.001)^M$3) -> 0.63302383 | N39: =1/((1+$D$47+0.001)^N$3) -> 0.58022349 | ... AE39: =1/((1+$D$47+0.001)^AE$3) -> 0.13200019
F40: =1/((1+$D$48+0.005)^F$3) -> 1.0000204 | G40: =1/((1+$D$47+0.005)^G$3) -> 1 | H40: =1/((1+$D$47+0.005)^H$3) -> 0.97756686 | I40: =1/((1+$D$47+0.005)^I$3) -> 0.89275512 | J40: =1/((1+$D$47+0.005)^J$3) -> 0.81530148 | K40: =1/((1+$D$47+0.005)^K$3) -> 0.74456756 | L40: =1/((1+$D$47+0.005)^L$3) -> 0.67997038 | M40: =1/((1+$D$47+0.005)^M$3) -> 0.62097751 | N40: =1/((1+$D$47+0.005)^N$3) -> 0.56710275 | ... AE40: =1/((1+$D$47+0.005)^AE$3) -> 0.12123324
C42: EPS | H42: =1000000*H16/OP!C8 -> 13.664887 | I42: =1000000*I16/OP!$C8 -> 13.883902 | J42: =1000000*J16/OP!$C8 -> 14.479521
C43: Consenso EPS
...

Sheet Cifras_en_Millones
A1: =Cifras_Originales!H3 -> DICK'S Sporting Goods, Inc. (DKS)
A2: =Cifras_Originales!D2 -> Cifras en Millones de USD
A4: Resultados | B4: 2024 | C4: =Cifras_Originales!C5 -> 2023 | D4: =Cifras_Originales!D5 -> 2022 | E4: =Cifras_Originales!E5 -> 2021 | F4: =Cifras_Originales!F5 -> 2020 | G4: =Cifras_Originales!G5 -> 2019 | H4: =Cifras_Originales!H5 -> 2018 | I4: =Cifras_Originales!I5 -> 2017 | J4: =Cifras_Originales!J5 -> 2016 | ... M4: =Cifras_Originales!M5 -> 2013
A5: Ventas Netas | C5: =Cifras_Originales!C6 -> 12984.399 | D5: =Cifras_Originales!D6 -> 12368.198 | E5: =Cifras_Originales!E6 -> 12293.368 | F5: =Cifras_Originales!F6 -> 9584.019 | G5: =Cifras_Originales!G6 -> 8750.743 | H5: =Cifras_Originales!H6 -> 8436.57 | I5: =Cifras_Originales!I6 -> 8590.472 | J5: =Cifras_Originales!J6 -> 7921.981 | ... M5: =Cifras_Originales!M6 -> 6213.173
A6: Crecimiento vs. Año pasado | B6: =B5/C5-1 -> -1 | C6: =C5/D5-1 -> 0.049821405 | D6: =D5/E5-1 -> 0.0060870219 | E6: =E5/F5-1 -> 0.28269445 | F6: =F5/G5-1 -> 0.095223457 | G6: =G5/H5-1 -> 0.037239423 | H6: =H5/I5-1 -> -0.01791543 | I6: =I5/J5-1 -> 0.084384323 | ... L6: =L5/M5-1 -> 0.096779214
A7: Utilidad Bruta | C7: =Cifras_Originales!C7 -> 4533.375 | D7: =Cifras_Originales!D7 -> 4284.558 | E7: =Cifras_Originales!E7 -> 4711.886 | F7: =Cifras_Originales!F7 -> 3050.707 | G7: =Cifras_Originales!G7 -> 2554.558 | H7: =Cifras_Originales!H7 -> 2437.782 | I7: =Cifras_Originales!I7 -> 2489.06 | J7: =Cifras_Originales!J7 -> 2365.783 | ... M7: =Cifras_Originales!M7 -> 1943.95
A8: porcentaje sobre ventas | B8: =B7/B5 -> #DIV/0! | C8: =C7/C5 -> 0.34914015 | D8: =D7/D5 -> 0.34641732 | E8: =E7/E5 -> 0.38328683 | F8: =F7/F5 -> 0.31831187 | G8: =G7/G5 -> 0.2919247 | H8: =H7/H5 -> 0.28895416 | I8: =I7/I5 -> 0.28974659 | ... M8: =M7/M5 -> 0.31287556
A9: Gastos de Operación | B9: =B5-B11 -> 0 | C9: =C5-C11 -> 11702.034 | D9: =D5-D11 -> 10905.179 | E9: =E5-E11 -> 10258.865 | F9: =F5-F11 -> 8842.542 | G9: =G5-G11 -> 8375.13 | H9: =H5-H11 -> 7991.837 | I9: =I5-I11 -> 8112.898 | ... M9: =M5-M11 -> 5676.361
A10: porcentaje sobre ventas | B10: =B9/B5 -> #DIV/0! | C10: =C9/C5 -> 0.90123802 | D10: =D9/D5 -> 0.88171122 | E10: =E9/E5 -> 0.83450402 | F10: =F9/F5 -> 0.92263402 | G10: =G9/G5 -> 0.95707644 | H10: =H9/H5 -> 0.94728509 | I10: =I9/I5 -> 0.94440655 | ... M10: =M9/M5 -> 0.91360099
A11: Utilidad de Operación | C11: =Cifras_Originales!C8 -> 1282.365 | D11: =Cifras_Originales!D8 -> 1463.019 | E11: =Cifras_Originales!E8 -> 2034.503 | F11: =Cifras_Originales!F8 -> 741.477 | G11: =Cifras_Originales!G8 -> 375.613 | H11: =Cifras_Originales!H8 -> 444.733 | I11: =Cifras_Originales!I8 -> 477.574 | J11: =Cifras_Originales!J8 -> 449.854 | ... M11: =Cifras_Originales!M8 -> 536.812
A12: porcentaje sobre ventas | B12: =B11/B5 -> #DIV/0! | C12: =C11/C5 -> 0.098761984 | D12: =D11/D5 -> 0.11828878 | E12: =E11/E5 -> 0.16549598 | F12: =F11/F5 -> 0.077365978 | G12: =G11/G5 -> 0.042923555 | H12: =H11/H5 -> 0.052714907 | I12: =I11/I5 -> 0.055593453 | ... M12: =M11/M5 -> 0.086399011
A13: Crecimiento vs año anterior | B13: =B11/C11-1 -> -1 | C13: =C11/D11-1 -> -0.12348028 | D13: =D11/E11-1 -> -0.28089612 | E13: =E11/F11-1 -> 1.7438518 | F13: =F11/G11-1 -> 0.97404509 | G13: =G11/H11-1 -> -0.15541909 | H13: =H11/I11-1 -> -0.068766306 | I13: =I11/J11-1 -> 0.061619992 | ... L13: =L11/M11-1 -> 0.032128566
A14: CIF (Productos Financieros) | C14: =Cifras_Originales!C9 -> 137.7 | D14: =Cifras_Originales!D9 -> 95.22 | E14: =Cifras_Originales!E9 -> 57.839 | F14: =Cifras_Originales!F9 -> 48.812 | G14: =Cifras_Originales!G9 -> 17.012 | H14: =Cifras_Originales!H9 -> 11.1 | I14: =Cifras_Originales!I9 -> 8.047 | J14: =Cifras_Originales!J9 -> 5.856 | ... M14: =Cifras_Originales!M9 -> 3.129
A15: Otros Gastos (Productos) | C15: =Cifras_Originales!C10 -> -93.8 | D15: =Cifras_Originales!D10 -> -15.949 | E15: =Cifras_Originales!E10 -> -17.744 | F15: =Cifras_Originales!F10 -> -19.07 | G15: =Cifras_Originales!G10 -> -15.324 | H15: =Cifras_Originales!H10 -> 2.565 | I15: =Cifras_Originales!I10 -> -31.81 | J15: =Cifras_Originales!J10 -> -14.424 | ... M15: =Cifras_Originales!M10 -> -12.224
