Workbook
Name Sectors: '[1]Sector Impact'!$K$4:$K$16
Name Sectors: 'Sector Impact'!$K$4:$K$16

Sheet OP
B2: 18/09/2024 | C2: Team 5 | D2: 22/10/2024 | E2: =Inputs!H3 -> #VALUE! | L2: {=_FV(E2,"Exchange")} -> New York Stock Exchange | M2: SIC:
D3: COMPANY DESCRIPTION | H3: CEO & BOARD OF DIRECTORS
D4: {=_FV(Inputs!H3,"Description")} -> Ermenegildo Zegna NV is an Italy-based manufacturer of high-end menswear and accessories. The Company focuses on producing different kinds of apparel, including outerwear such as jackets, suits, blazers, shirts, pants and jeans, as well as shoes, sportswear and accessories. The Company is active worldwide. | H4: Name, Age and Tenure | I4: Gender | J4: Executive? | L4: Other roles
H5: Ermenegildo Zegna, 69, 35 years | I5: Male | J5: Yes | L5: CEO, Chairman
H6: Sergio P. Ermotti, 64, 3 years | I6: Male | J6: No | L6: Lead non-executive director
H7: Andrea C. Bonomi, 59, 3 years | I7: Male | J7: No | L7: -
H8: Angelica Cheung, 58, 3 years | I8: Female | J8: No | L8: -
H9: Domenico de Sole, 80, 19 years | I9: Male | J9: No | L9: -
H10: Ronald B. Johnson, 64, 5 years | I10: Male | J10: No | L10: -
H11: Valerie A. Mars, 65, 3 years | I11: Female | J11: No | L11: Chair of the Audit Comitee
H12: Michele Norsa, 76, 7 years | I12: Male | J12: No | L12: Chair of the Governance & Sustainability Comitee
H13: Henry Peter, 67, 10 years | I13: Male | J13: No | L13: Chair of the Compensation Commitee
H14: Anna Zegna, 67, 6 years | I14: Female | J14: No | L14: -
B15: {=_FV(E2,"Currency")&" MILLIONS"} -> USD MILLIONS | H15: Paolo Zegna, 68, 3 years | I15: Male | J15: No | L15: -
B18: COMPANY OVERVIEW
B19: Stock | D19: Liquidity and Solvency | F19: Segments | I19: ="Profitability ("&J20&")" -> Profitability (2023) | L19: Multiples
B20: Last Price | C20: {=_FV(E2,"Price")} -> 9.44 | D20: Total Assets | E20: =_xlfn.XLOOKUP(D20,'Fin. Data'!A:A,'Fin. Data'!B:B,,0) -> 3053.66 | F20: Regions | H20: % Sales | I20: Reporting Year | J20: 2023 | L20: Float | M20: =IF(Inputs!B82 <> "",Inputs!B82,"") -> 59.07M
B21: Outstanding Shares | C21: {=_FV(E2,"Shares outstanding",TRUE)} -> 254089400 | D21: Total Liabilities | E21: =_xlfn.XLOOKUP(D21,'Fin. Data'!A:A,'Fin. Data'!B:B,,0) -> 2059 | F21: ='Segments '!C5 -> EMEA(excuding Italy and UK) | H21: ='Segments '!B5 -> 0.12490291 | I21: End of Year | J21: 45291 | L21: Insiders Own | M21: =IF(Inputs!B83 <> "",Inputs!B83,"") -> 0.752
B22: Market Cap. | C22: =C20*C21/1000000 -> 2398.6039 | D22: Cash/Share | E22: =_xlfn.XLOOKUP("Cash & Eq.",'Fin. Data'!A:A,'Fin. Data'!B:B,,0)*1000000/C21 -> 1.2869486 | F22: ='Segments '!C6 -> Italy | H22: ='Segments '!B6 -> 0.14791262 | I22: EBITDA | K22: =_xlfn.XLOOKUP(I22,'Fin. Data'!A:A,'Fin. Data'!B:B,,0) -> 491.27 | L22: b (Yahoo) | M22: 0.66
B23: +Total Debt | C23: ='Fin. Data'!B58 -> 1099.57 | D23: EBITDA/Net Financial Cost (NFC) | E23: =IFERROR(_xlfn.XLOOKUP("EBITDA",'Fin. Data'!A:A,'Fin. Data'!B:B,,0)/_xlfn.XLOOKUP("Net Financial Cost",'Fin. Data'!A:A,'Fin. Data'!B:B,,0),"") -> -14.664776 | F23: ='Segments '!C7 -> Japan | H23: ='Segments '!B7 -> 0.044616505 | I23: Depreciation & Amortization | K23: =_xlfn.XLOOKUP(I23,'Fin. Data'!A:A,'Fin. Data'!B:B,,0) -> 211 | L23: Score (S&P) | M23: =IF(Inputs!B84 <> "",Inputs!B84,"")
B24: -Cash | C24: ='Fin. Data'!B39 -> 327 | D24: Debt/EBITDA | E24: =IFERROR(_xlfn.XLOOKUP("Total Debt",'Fin. Data'!A:A,'Fin. Data'!B:B,,0)/_xlfn.XLOOKUP("EBITDA",'Fin. Data'!A:A,'Fin. Data'!B:B,,0),"") -> 2.2382193 | F24: ='Segments '!C8 -> Greater china region | H24: ='Segments '!B8 -> 0.31262136 | I24: EBIT | K24: =_xlfn.XLOOKUP(I24,'Fin. Data'!A:A,'Fin. Data'!B:B,,0) -> 280.27 | L24: Price/Book Value | M24: =IFERROR((C20*C21/(E20-E21))/1000000,"") -> 2.4114812
B25: =Enterprise Value | C25: =C22+C23-C24 -> 3171.1739 | D25: "Others Assets"/Asset | E25: =IFERROR(_xlfn.XLOOKUP("Other Assets",'Fin. Data'!A:A,'Fin. Data'!B:B,,0)/_xlfn.XLOOKUP("Total Assets",'Fin. Data'!A:A,'Fin. Data'!B:B,,0),"") -> 0.16415384 | F25: ='Segments '!C9 -> United States | H25: ='Segments '!B9 -> 0.20184466 | I25: Net Income | K25: =_xlfn.XLOOKUP(I25,'Fin. Data'!A:A,'Fin. Data'!B:B,,0) -> 131.42 | L25: NCF(3y avg)/Asset | M25: =IFERROR(K31/E20,"") -> -0.0073627494
B26: Holdings (nac/int'l) | C26: - | D26: Debt/Assets | E26: =_xlfn.XLOOKUP(D26,'Fin. Data'!A:A,'Fin. Data'!B:B,,0) -> 0.36008265 | F26: Categories | H26: % Sales | I26: EPS | K26: =1000000*K25/C21 -> 0.51721953 | L26: Price/Net Inc. (3y avg) | M26: =IFERROR(C22/K30,"") -> 290.27075
B27: t liq. (Holdings/Vol.) | C27: - | D27: EBITDA Margin (average) | E27: =IFERROR(AVERAGE(_xlfn.XLOOKUP("EBITDA Margin",'Fin. Data'!A:A,'Fin. Data'!B:D,,0)),"") -> 0.2954313 | F27: ='Segments '!C18 -> Zegna branded products | H27: ='Segments '!B18 -> 0.58254553 | I27: ROA | K27: =IFERROR(K25/E20,"") -> 0.04303688 | L27: EV/Asset | M27: =IFERROR(C25/E20,"") -> 1.038483
B28: % Short | D28: Operating Margin (average) | E28: =IFERROR(AVERAGE(_xlfn.XLOOKUP("Operating Margin",'Fin. Data'!A:A,'Fin. Data'!B:D,,0)),"") -> 0.10626811 | F28: ='Segments '!C19 -> Thom Browne | H28: ='Segments '!B19 -> 0.19868611 | I28: ROIC | K28: =IFERROR(#REF!,"") | L28: EV/Ebitda (3y average) | M28: =IFERROR(C25/K29,"") -> 6.3714441
B29: Traffic ESG | D29: Net Income Margin (average) | E29: =IFERROR(AVERAGE(_xlfn.XLOOKUP("Net Income Margin",'Fin. Data'!A:A,'Fin. Data'!B:D,,0)),"") -> -0.0023115197 | F29: ='Segments '!C20 -> Tom Ford Fashion | H29: ='Segments '!B20 -> 0.12366899 | I29: EBITDA (3y average) | K29: =AVERAGE(_xlfn.XLOOKUP("EBITDA",'Fin. Data'!A:A,'Fin. Data'!B:D,,0)) -> 497.71667 | L29: Price/NCF (3y average) | M29: =IFERROR(C22/K31,"") -> -106.68364
B30: E | F30: ='Segments '!C23 -> Textile | H30: ='Segments '!B23 -> 0.079275369 | I30: Net Income (3y average) | K30: =AVERAGE(_xlfn.XLOOKUP("Net Income",'Fin. Data'!A:A,'Fin. Data'!B:D,,0)) -> 8.2633333 | L30: Bonds 1,3,5a (USD) | M30: -
B31: S | D31: Net Financial Cost/Avg Net Debt | E31: =IFERROR(-_xlfn.XLOOKUP("Net Financial Cost",'Fin. Data'!A:A,'Fin. Data'!B:B,,0)/AVERAGE(_xlfn.XLOOKUP("Net Debt",'Fin. Data'!A:A,'Fin. Data'!B:D,,0)),"") -> 0.046328309 | F31: ='Segments '!C22 -> Other | H31: ='Segments '!B22 -> 0.015823999 | I31: NCF (3y average) | K31: =AVERAGE(_xlfn.XLOOKUP("Net Financial Cost",'Fin. Data'!A:A,'Fin. Data'!B:D,,0)) -> -22.483333 | L31: Div+Rep.(3y avg)/Price | M31: =-IFERROR(SUM(E52:E54)/(3*C22),"") -> 0.11617591
B32: G | L32: Div. Yield | M32: =-IFERROR(L53/C22,"") -> 0.011285732
B33: INVESTMENT THESIS
B34: Pillars of Recommendation | H34: Recommendation | I34: Valuation Assumptions
B35: Pillar | C35: Explanation | H35: Hold | I35: Check DCF
B36: Strategic Aqcuisitions | C36: 2023: The acquisition of the Tom Ford brand was set to supercharge the Group's expansion in the luxury business.
B37: Vertical Integration | C37: By owning land and farms, ZEGNA ensures a high level of quality control in its textile development process, strengthening its financial performance.
B39: Risks of Investment | H39: Price Target | I39: Valuation
B40: Risk | C40: Explanation | H40: =IFERROR(DCF!D75,"") -> 6.1422803 | I40: Discount Rate | J40: =DCF!F50 -> 0.085 | L40: Price M. Upside | M40: =IFERROR(#REF!,"")
B41: Changes in consumer's preferences | C41: Luxury market companies are experiencing a slowdown in profits due to shifts in consumer preferences. Zegna's profit in H1 2024 is down by approximately 40% compared to H1 2023.
B42: Dependence on global markets | C42: A global economic recession can reduce disposable incomes, subsequently reducing demand for luxury goods. | I42: Upside | J42: =IFERROR(DCF!D74,"") -> -0.34933472 | L42: EV M. Upside | M42: =IFERROR(#REF!,"")
B43: Declining EPS | C43: Historical data reveals that the company's EPS has declined by 45% annually over the past years.
B44: FINANCIAL PERFORMANCE
...

Sheet Segments 
B2: ="Regions "&"("&[2]OP!$J$20&")" -> Regions (2023) | Q2: Products
D3: Nominal value | K3: YoY Growth
B4: Weight | C4: Region | D4: =[2]OP!J20 -> 2023 | E4: =D4-1 -> 2022 | F4: =E4-1 -> 2021 | G4: =F4-1 -> 2020 | H4: =G4-1 -> 2019 | I4: =H4-1 -> 2018 | K4: =[2]OP!J20 -> 2023 | L4: =K4-1 -> 2022 | M4: =L4-1 -> 2021 | N4: =M4-1 -> 2020 | O4: =N4-1 -> 2019 | P4: =O4-1 -> 2018
B5: =IFERROR(D5/$D$13,"") -> 0.12490291 | C5: EMEA(excuding Italy and UK) | D5: 257.3 | E5: =(182.2*1000)*0.001 -> 182.2 | F5: =(217.6*1000)*0.001 -> 217.6 | G5: =(184.6*1000)*0.001 -> 184.6 | H5: =(260.5*1000)*0.001 -> 260.5 | I5: =(290.5*1000)*0.001 -> 290.5 | K5: =(D5-E5)/E5 -> 0.41218441 | L5: =(E5-F5)/F5 -> -0.16268382 | M5: =(F5-G5)/G5 -> 0.1787649 | N5: =(G5-H5)/H5 -> -0.29136276 | O5: =(H5-I5)/I5 -> -0.10327022 | P5: -
B6: =IFERROR(D6/$D$13,"") -> 0.14791262 | C6: Italy | D6: =(304.7*1000)*0.001 -> 304.7 | E6: =(236.3*1000)*0.001 -> 236.3 | F6: =(187.7*1000)*0.001 -> 187.7 | G6: =(138.4*1000)*0.001 -> 138.4 | H6: =(157.5*1000)*0.001 -> 157.5 | I6: =(113*1000)*0.001 -> 113 | K6: =(D6-E6)/E6 -> 0.28946255 | L6: =(E6-F6)/F6 -> 0.25892381 | M6: =(F6-G6)/G6 -> 0.35621387 | N6: =(G6-H6)/H6 -> -0.12126984 | O6: =(H6-I6)/I6 -> 0.39380531 | P6: -
B7: =IFERROR(D7/$D$13,"") -> 0.044616505 | C7: Japan | D7: =(91.91*1000)*0.001 -> 91.91 | E7: =(68.94*1000)*0.001 -> 68.94 | F7: =(65.62*1000)*0.001 -> 65.62 | G7: =(70.23*1000)*0.001 -> 70.23 | H7: =(101*1000)*0.001 -> 101 | I7: =(84.86*1000)*0.001 -> 84.86 | K7: =(D7-E7)/E7 -> 0.33318828 | L7: =(E7-F7)/F7 -> 0.050594331 | M7: =(F7-G7)/G7 -> -0.065641464 | N7: =(G7-H7)/H7 -> -0.30465347 | O7: =(H7-I7)/I7 -> 0.19019562 | P7: -
B8: =IFERROR(D8/$D$13,"") -> 0.31262136 | C8: Greater china region | D8: =(644*1000)*0.001 -> 644 | E8: =(520.5*1000)*0.001 -> 520.5 | F8: =(696.5*1000)*0.001 -> 696.5 | G8: =(500.2*1000)*0.001 -> 500.2 | H8: =(513.3*1000)*0.001 -> 513.3 | I8: =(477.9*1000)*0.001 -> 477.9 | K8: =(D8-E8)/E8 -> 0.23727185 | L8: =(E8-F8)/F8 -> -0.25269203 | M8: =(F8-G8)/G8 -> 0.39244302 | N8: =(G8-H8)/H8 -> -0.025521138 | O8: =(H8-I8)/I8 -> 0.074074074 | P8: -
B9: =IFERROR(D9/$D$13,"") -> 0.20184466 | C9: United States | D9: =(415.8*1000)*0.001 -> 415.8 | E9: =(284.8*1000)*0.001 -> 284.8 | F9: =(208.3*1000)*0.001 -> 208.3 | G9: =(131.1*1000)*0.001 -> 131.1 | H9: =(230.3*1000)*0.001 -> 230.3 | I9: =(228.6*1000)*0.001 -> 228.6 | K9: =(D9-E9)/E9 -> 0.45997191 | L9: =(E9-F9)/F9 -> 0.36725876 | M9: =(F9-G9)/G9 -> 0.58886346 | N9: =(G9-H9)/H9 -> -0.43074251 | O9: =(H9-I9)/I9 -> 0.0074365704 | P9: -
B10: =IFERROR(D10/$D$13,"") -> 0.16810194 | C10: Other | D10: =(346.29*1000)*0.001 -> 346.29 | E10: =(280.26*1000)*0.001 -> 280.26 | F10: =(153.28*1000)*0.001 -> 153.28 | G10: =(133.47*1000)*0.001 -> 133.47 | H10: =(216.4*1000)*0.001 -> 216.4 | I10: =(201.14*1000)*0.001 -> 201.14 | K10: =(D10-E10)/E10 -> 0.23560265 | L10: =(E10-F10)/F10 -> 0.82841858 | M10: =(F10-G10)/G10 -> 0.14842287 | N10: =(G10-H10)/H10 -> -0.38322551 | O10: =(H10-I10)/I10 -> 0.075867555 | P10: -
B11: =IFERROR(D11/$D$13,"") -> 0
B12: =IFERROR(D12/$D$13,"") -> 0
B13: =SUM(B5:B12) -> 1 | C13: TOTAL | D13: =SUM(D5:D12) -> 2060 | E13: =SUM(E5:E12) -> 1573 | F13: =SUM(F5:F12) -> 1529 | G13: =SUM(G5:G12) -> 1158 | H13: =SUM(H5:H12) -> 1479 | I13: =SUM(I5:I12) -> 1396 | K13: =(D13-E13)/E13 -> 0.30959949 | L13: =(E13-F13)/F13 -> 0.028776978 | M13: =(F13-G13)/G13 -> 0.32037997 | N13: =(G13-H13)/H13 -> -0.21703854 | O13: =(H13-I13)/I13 -> 0.059455587 | P13: -
B15: ="Categories "&"("&[2]OP!$J$20&")" -> Categories (2023)
D16: Nominal value | K16: YoY Growth
B17: Weight | C17: Category | D17: =[2]OP!J20 -> 2023 | E17: =D17-1 -> 2022 | F17: =E17-1 -> 2021 | G17: =F17-1 -> 2020 | H17: =G17-1 -> 2019 | I17: =H17-1 -> 2018 | K17: =[2]OP!J20 -> 2023 | L17: =K17-1 -> 2022 | M17: =L17-1 -> 2021 | N17: =M17-1 -> 2020 | O17: =N17-1 -> 2019 | P17: =O17-1 -> 2018
B18: =IFERROR(D18/$D$24,"") -> 0.58254553 | C18: Zegna branded products | D18: =(1199.77*1000)*0.001 -> 1199.77 | E18: =(973.35*1000)*0.001 -> 973.35 | F18: =(1002.23*1000)*0.001 -> 1002.23 | G18: =(726.52*1000)*0.001 -> 726.52 | H18: =(1029.25*1000)*0.001 -> 1029.25 | I18: =(1097.98*1000)*0.001 -> 1097.98 | K18: =(D18-E18)/E18 -> 0.2326193 | L18: =(E18-F18)/F18 -> -0.028815741 | M18: =(F18-G18)/G18 -> 0.37949403 | N18: =(G18-H18)/H18 -> -0.29412679 | O18: =(H18-I18)/I18 -> -0.062596769 | P18: -
B19: =IFERROR(D19/$D$24,"") -> 0.19868611 | C19: Thom Browne | D19: =(409.2*1000)*0.001 -> 409.2 | E19: =(347.66*1000)*0.001 -> 347.66 | F19: =(311.55*1000)*0.001 -> 311.55 | G19: =(204.88*1000)*0.001 -> 204.88 | H19: =(179.75*1000)*0.001 -> 179.75 | I19: =(22.5*1000)*0.001 -> 22.5 | K19: =(D19-E19)/E19 -> 0.17701202 | L19: =(E19-F19)/F19 -> 0.11590435 | M19: =(F19-G19)/G19 -> 0.52064623 | N19: =(G19-H19)/H19 -> 0.13980529 | O19: =(H19-I19)/I19 -> 6.9888889 | P19: -
B20: =IFERROR(D20/$D$24,"") -> 0.12366899 | C20: Tom Ford Fashion | D20: =(254.7*1000)*0.001 -> 254.7 | E20: N/A | F20: N/A | G20: N/A | H20: N/A | I20: N/A | K20: - | L20: - | M20: - | N20: - | O20: - | P20: -
B21: =IFERROR(D21/$D$24,"") -> 0 | C21: Strategic Alliances | D21: 0 | E21: =(103.02*1000)*0.001 -> 103.02 | F21: =(88.66*1000)*0.001 -> 88.66 | G21: =(93.91*1000)*0.001 -> 93.91 | H21: =(102.66*1000)*0.001 -> 102.66 | I21: =(108.96*1000)*0.001 -> 108.96 | K21: =(D21-E21)/E21 -> -1 | L21: =(E21-F21)/F21 -> 0.16196707 | M21: =(F21-G21)/G21 -> -0.05590459 | N21: =(G21-H21)/H21 -> -0.085232807 | O21: =(H21-I21)/I21 -> -0.057819383 | P21: -
B22: =IFERROR(D22/$D$24,"") -> 0.015823999 | C22: Other | D22: =5.18+27.41 -> 32.59 | E22: =(4.55*1000)*0.001 -> 4.55 | F22: =((3.91+1.41)*1000)*0.001 -> 5.32 | G22: =((18.82+13.86)*1000)*0.001 -> 32.68 | H22: =((26.04+19.84)*1000)*0.001 -> 45.88 | I22: =((29.24+20.71)*1000)*0.001 -> 49.95 | K22: =(D22-E22)/E22 -> 6.1626374 | L22: =(E22-F22)/F22 -> -0.14473684 | M22: =(F22-G22)/G22 -> -0.8372093 | N22: =(G22-H22)/H22 -> -0.28770706 | O22: =(H22-I22)/I22 -> -0.081481481 | P22: -
B23: =IFERROR(D23/$D$24,"") -> 0.079275369 | C23: Textile | D23: =(163.27*1000)*0.001 -> 163.27 | E23: =(144.42*1000)*0.001 -> 144.42 | F23: =(121.24*1000)*0.001 -> 121.24 | G23: =(100.01*1000)*0.001 -> 100.01 | H23: =(121.46*1000)*0.001 -> 121.46 | I23: =(116.61*1000)*0.001 -> 116.61 | K23: =(D23-E23)/E23 -> 0.13052209 | L23: =(E23-F23)/F23 -> 0.19119103 | M23: =(F23-G23)/G23 -> 0.21227877 | N23: =(G23-H23)/H23 -> -0.17660135 | O23: =(H23-I23)/I23 -> 0.04159163 | P23: -
B24: =SUM(B18:B23) -> 1 | C24: TOTAL | D24: =SUM(D18:D23) -> 2059.53 | E24: =SUM(E18:E23) -> 1573 | F24: =SUM(F18:F23) -> 1529 | G24: =SUM(G18:G23) -> 1158 | H24: =SUM(H18:H23) -> 1479 | I24: =SUM(I18:I23) -> 1396 | K24: =(D24-E24)/E24 -> 0.3093007 | L24: =(E24-F24)/F24 -> 0.028776978 | M24: =(F24-G24)/G24 -> 0.32037997 | N24: =(G24-H24)/H24 -> -0.21703854 | O24: =(H24-I24)/I24 -> 0.059455587 | P24: -
B26: Categories | D26: Description | I26: Graphs
B27: Tom ford fashion | D27: Collection of fashion from Tom Ford ranging from glasses to suits
B28: Textile | D28: Sale of raw and transformed material to other luxury companies
B29: Zegna branded products | D29: Products from zegna mainly clothing
B30: Thom Browne | D30: Not so traditional luxury clothing
B31: Strategic Alliances | D31: Alliances mainly to do consultation for other big players in the market
B34: Industry | J34: Graphs (Industry Forecasts)
B35: Drivers | D35: Description
B36: Casualisation | D36: Luxury wear becomes each day more casual and less forma
B37: China | D37: Growing market in China for luxuxry goods
B38: Sales forecast
B39: Source | D39: Market Growth CAGR | G39: Period
B40: https://www.statista.com/outlook/cmo/luxury-goods/luxury-fashion/luxury-apparel/worldwide | D40: 0.0292 | G40: 2024-2029
B41: https://www.grandviewresearch.com/industry-analysis/luxury-goods-market-report | D41: 0.068 | G41: 2024-2030
B42: https://www.cognitivemarketresearch.com/affordable-luxury-fashion-market-report | D42: 0.05 | G42: 2024-2030
B43: Average | D43: =AVERAGE(D40:F42) -> 0.049066667
B44: Company's Strategy / Extra Notes
B47: Group aims for compounded average annual growth of revenues over 10% and of Adjusted EBIT of around 20%, and a strong Cash Surplus. Group sees positive momentum across brands and shares the business strategy for Tom Ford Fashion, where it expects revenues to grow at a compounded average rate1 of over 10% in the medium term.
...

Sheet Acuerdo
A1: Invertir
A2: NO invertir
A3: Mantener sin elevar posición
A4: Mantener (y seguir comprando)
A5: Liquidar
A6: PENDIENTE

Sheet Peers
B1: Peer Logo | C1: Peer Name | D1: Description
C2: #VALUE! | D2: Brunello Cucinelli SpA is an Italy-based company engaged in the fashion industry. The Company designs, manufactures and sells clothing for woman and men, cashmere products and accessories collections. The Company markets its products through direct retail channel; wholesale monobrand channel, consisting of franchised monobrand retail stores, and wholesale multibrand channel. The Company is active globally.
C3: #VALUE! | D3: Moncler SpA is an Italy-based company engaged in fashion industry. The Company designs, produces and distributes clothing and accessories through Moncler brand. The Company offers mainly sportswear, outerwear, knitwear and skiwear. Moncler SpA trades its products through approximately 122 stores, as well as through the wholesale distribution channel. Moncler SpA operates in approximately 66 countries.
C4: #VALUE! | D4: Tod's SpA is an Italy-based holding company. The Company, through its subsidiaries, is primarily engaged in creation, production and distribution of shoes, leather goods and accessories, apparel. The Company operates in the luxury sector under brands, such as TOD'S, ROGER VIVIER, HOGAN and FAY. The Company relies on approximately three channels: directly operated stores (DOS), franchised retail outlets, as well as a series of selected, independent multiband stores.
C5: #VALUE! | D5: Prada SpA is an Italy-based company engaged in fashion industry. The Company is a parent of the Prada Group. The Company, along with its subsidiaries, is engaged in the design, production and distribution of leather goods, handbags, clothing, eyewear, fragrances, footwear and accessories. The Company trades its products through several brands, such as Prada, Miu Miu, The Church and The Car Shoe. Prada SpA operates in approximately 70 countries through directly operated stores, franchise operated stores, a network of selected multi-brand stores and department stores.
C6: #VALUE! | D6: Hugo Boss AG is a Germany-based developer and marketer of men's and women's clothing and accessories for the international fashion market. The Company's brand portfolio comprises BOSS, BOSS Orange, Camel, Green, Black, Blue and HUGO and others: BOSS comprises business wear, leisurewear and evening apparel, as well as watches, eyewear and fragrances; BOSS Orange and BOSS Camel focuses on womenswear; BOSS Green comprises sportswear and BOSS Black focuses on modern tailoring, BOSS Blue focuses on denimwear, HUGO provides apparel for both business and leisure, as well as shoes, accessories and licensed fragrances.
B8: In Millions USD | C8: =OP!E2 -> #VALUE! | D8: =C2 -> #VALUE! | E8: =C3 -> #VALUE! | F8: =C4 -> #VALUE! | G8: =C5 -> #VALUE! | H8: =C6 -> #VALUE! | I8: AVERAGE | J8: Deviation from Average
B9: Company Info | I9: =IFERROR(AVERAGE(C9:H9),"") | L9: TRAFFIC
B10: Market Cap | C10: {=_FV(C8,"Market cap",TRUE)/1000000} -> 2398.6039 | D10: {=_FV(D8,"Market cap",TRUE)/1000000} -> 7024.4 | E10: {=_FV(E8,"Market cap",TRUE)/1000000} -> 13877.7 | F10: {=_FV(F8,"Market cap",TRUE)/1000000} -> 1127.166 | G10: {=_FV(G8,"Market cap",TRUE)/1000000} -> 120264.7 | H10: {=_FV(H8,"Market cap",TRUE)/1000000} -> 2923.712 | I10: =IFERROR(AVERAGE(C10:H10),"") -> 24602.714 | J10: =SQRT((C10-I10)^2) -> 22204.11 | M10: Best Value
B11: Net Sales (current) | C11: =C56 -> 2060 | D11: =D56 -> 1257.4575 | E11: =E56 -> 3293.3652 | F11: =F56 -> 1243.4198 | G11: =G56 -> 2816.7493 | H11: =H56 -> 4631.7857 | I11: =IFERROR(AVERAGE(C11:H11),"") -> 2550.4629 | J11: =SQRT((C11-I11)^2) -> 490.46292
B12: Profitability | I12: =IFERROR(AVERAGE(C12:H12),"") | M12: Important Value
B13: Sales Growth (ttm) | C13: =C56/C55-1 -> 0.30959949 | D13: =D56/D55-1 -> 0.27754496 | E13: =E56/E55-1 -> 0.18227064 | F13: =F56/F55-1 -> 0.15377505 | G13: =G56/G55-1 -> 0.048876729 | H13: =H56/H55-1 -> 0.18541238 | I13: =IFERROR(AVERAGE(C13:H13),"") -> 0.19291321 | J13: =SQRT((C13-I13)^2) -> 0.11668628
B14: Sales Growth (36m) | C14: =C56/C54-1 -> 0.77892919 | D14: =D56/D54-1 -> 0.89261329 | E14: =E56/E54-1 -> 0.87211231 | F14: =F56/F54-1 -> 0.59804135 | G14: =G56/G54-1 -> 0.94034996 | H14: =H56/H54-1 -> 0.94887264 | I14: =IFERROR(AVERAGE(C14:H14),"") -> 0.83848646 | J14: =SQRT((C14-I14)^2) -> 0.059557267 | M14: Worst Value
B15: Operating Margin | C15: =C59/C56 -> 0.1168301 | D15: =D59/D56 -> 0.16447491 | E15: =E59/E56 -> 0.29952212 | F15: =F59/F56 -> 0.057292092 | G15: =G59/G56 -> 0.31681856 | H15: =H59/H56 -> 0.097769121 | I15: =IFERROR(AVERAGE(C15:H15),"") -> 0.17545115 | J15: =SQRT((C15-I15)^2) -> 0.058621052
B16: Net Income Margin | C16: =C62/C56 -> 0.071359223 | D16: =D62/D56 -> 0.10865967 | E16: =E62/E56 -> 0.065578341 | F16: =F62/F56 -> 0.044393361 | G16: =G61/G56 -> 0.094771819 | H16: =H62/H56 -> 0.049797474 | I16: =IFERROR(AVERAGE(C16:H16),"") -> 0.072426648 | J16: =SQRT((C16-I16)^2) -> 0.0010674247
B17: Return on Equity (RoE) | C17: =C62/C74 -> 0.15846323 | D17: =D62/D74 -> 0.27293971 | E17: =E62/E74 -> 0.06088173 | F17: =F62/F74 -> 0.030307896 | G17: =G61/G74 -> 0.085095859 | H17: =H62/H74 -> 0.15942029 | I17: =IFERROR(AVERAGE(C17:H17),"") -> 0.12785145 | J17: =SQRT((C17-I17)^2) -> 0.030611778
B18: Return on Invested Capital (ROIC) | C18: =(1+C61/(C59+C60))*C59/(C73+C74-C65) -> 0.17527185 | D18: =(1+D61/(D59+D60))*D59/(D73+D74-D65) -> 0.205748 | E18: =(1+E61/(E59+E60))*E59/(E73+E74-E65) -> 0.3738004 | F18: =(1+F61/(F59+F60))*F59/(F73+F74-F65) -> 0.03334261 | G18: =(1+G61/(G59+G60))*G59/(G73+G74-G65) -> 0.21285129 | H18: =(1+H61/(H59+H60))*H59/(H73+H74-H65) -> 0.20144744 | I18: =IFERROR(AVERAGE(C18:H18),"") -> 0.20041027 | J18: =SQRT((C18-I18)^2) -> 0.025138416
B19: Solvency | I19: =IFERROR(AVERAGE(C19:H19),"")
B20: Debt/Assets | C20: =C73/C70 -> 0.36008265 | D20: =D73/D70 -> 0.57907934 | E20: =E73/E70 -> 0.1705542 | F20: =F73/F70 -> 0.30266499 | G20: =G73/G70 -> 0.48676847 | H20: =H73/H70 -> 0.36578341 | I20: =IFERROR(AVERAGE(C20:H20),"") -> 0.37748884 | J20: =SQRT((C20-I20)^2) -> 0.01740619
B21: Net Debt/EBITDA | C21: =(C73-C65)/C58 -> 0.50330293 | D21: =(D73-D65)/D58 -> 2.1214219 | E21: - | F21: =(F73-F65)/F58 -> 4.4558659 | G21: =(G73-G65)/G58 -> 1.7049336 | H21: =(H73-H65)/H58 -> 1.5318456 | I21: =IFERROR(AVERAGE(C21:H21),"") -> 2.063474 | J21: =SQRT((C21-I21)^2) -> 1.5601711
B22: Interest Coverage Ratio | C22: - | D22: - | E22: - | F22: - | G22: - | H22: - | I22: =IFERROR(AVERAGE(C22:H22),"") | J22: =SQRT((C22-I22)^2) -> #VALUE!
B23: Liquidity
B24: Current Ratio | C24: =C68/C72 -> 1.2722186 | D24: =D68/D72 -> 1.2420418 | E24: =E68/E72 -> 1.8873561 | F24: =F68/F72 -> 1.629666 | G24: =G68/G72 -> 1.4502655 | H24: =H68/H72 -> 1.6429692 | I24: =IFERROR(AVERAGE(C24:H24),"") -> 1.5207529 | J24: =SQRT((C24-I24)^2) -> 0.24853427
B25: Quick Ratio | C25: =(C65+C66)/C72 -> 0.53716752 | D25: =(D65+D66)/D72 -> 0.43681833 | E25: =(E65+E66)/E72 -> 1.3107334 | F25: =(F65+F66)/F72 -> 0.42581608 | G25: =(G65+G66)/G72 -> 0.80764567 | H25: =(H65+H66)/H72 -> 0.45315114 | I25: =IFERROR(AVERAGE(C25:H25),"") -> 0.66188869 | J25: =SQRT((C25-I25)^2) -> 0.12472118
B26: Activity | I26: =IFERROR(AVERAGE(C26:H26),"")
B27: Inventory Turnover | C27: =C57/C67 -> 1.2756846 | D27: =D57/D67 -> 2.7327031 | E27: =E57/E67 -> 1.507988 | F27: =F57/F67 -> 2.1705546 | G27: =G57/G67 -> 2.1642331 | H27: =H57/H67 -> 1.3744955 | I27: =IFERROR(AVERAGE(C27:H27),"") -> 1.8709431 | J27: =SQRT((C27-I27)^2) -> 0.59525857
B28: Acc. Receivable Turnover | C28: =C56/C66 -> 7.5457875 | D28: =D56/D66 -> 14.57618 | E28: =E56/E66 -> 9.1650604 | F28: =F56/F66 -> 10.587594 | G28: =G56/G66 -> 3.5249628 | H28: =H56/H66 -> 11.162234 | I28: =IFERROR(AVERAGE(C28:H28),"") -> 9.4269698 | J28: =SQRT((C28-I28)^2) -> 1.8811823
A29: Price/Sales | B29: Payables Turnover | C29: =C57/C71 -> 2.3002187 | D29: =D57/D71 -> 4.7224622 | E29: =E57/E71 -> 1.268854 | F29: =F57/F71 -> 5.5193572 | G29: =G57/G71 -> 1.3326669 | H29: =H57/H71 -> 2.5615598 | I29: =IFERROR(AVERAGE(C29:H29),"") -> 2.9508531 | J29: =SQRT((C29-I29)^2) -> 0.65063439
B30: Fixed Asset Turnover | C30: =C56/C69 -> 2.691368 | D30: =D56/D69 -> 1.4725298 | E30: =E56/E69 -> 2.7568334 | F30: =F56/F69 -> 1.539582 | G30: =G56/G69 -> 3.1116964 | H30: =H56/H69 -> 7.6744531 | I30: =IFERROR(AVERAGE(C30:H30),"") -> 3.2077438 | J30: =SQRT((C30-I30)^2) -> 0.51637578
B31: Total Asset Turnover | C31: =C56/C70 -> 0.67460032 | D31: =D56/D70 -> 0.82573847 | E31: =E56/E70 -> 0.59779748 | F31: =F56/F70 -> 0.53666973 | G31: =G56/G70 -> 0.53768812 | H31: =H56/H70 -> 1.2088134 | I31: =IFERROR(AVERAGE(C31:H31),"") -> 0.73021792 | J31: =SQRT((C31-I31)^2) -> 0.055617599
B32: Valuation | I32: =IFERROR(AVERAGE(C32:H32),"")
B33: Price/Earnings | C33: =C10/C62 -> 16.317034 | D33: =D10/D62 -> 51.409991 | E33: =E10/E62 -> 64.256517 | F33: =F10/F62 -> 20.419827 | G33: =G10/G61 -> 450.51657 | H33: =H10/H62 -> 12.6759 | I33: =IFERROR(AVERAGE(C33:H33),"") -> 102.59931 | J33: =SQRT((C33-I33)^2) -> 86.282273
B34: Price/Sales | C34: =C10/C56 -> 1.1643708 | D34: =D10/D56 -> 5.5861926 | E34: =E10/E56 -> 4.2138358 | F34: =F10/F56 -> 0.90650477 | G34: =G10/G56 -> 42.696275 | H34: =H10/H56 -> 0.63122782 | I34: =IFERROR(AVERAGE(C34:H34),"") -> 9.1997344 | J34: =SQRT((C34-I34)^2) -> 8.0353636
B35: Price/Book | C35: =C10/C74 -> 2.5856498 | D35: =D10/D74 -> 14.031828 | E35: =E10/E74 -> 3.9120479 | F35: =F10/F74 -> 0.61888201 | G35: =G10/G74 -> 38.337094 | H35: =H10/H74 -> 2.0207957 | I35: =IFERROR(AVERAGE(C35:H35),"") -> 10.25105 | J35: =SQRT((C35-I35)^2) -> 7.6653998
B36: EV/Sales | C36: =(C73+C10-C65)/C56 -> 1.5394048 | D36: =(D73+D10-D65)/D56 -> 6.1936209 | E36: =(E73+E10-E65)/E56 -> 4.1644463 | F36: =(F73+F10-F65)/F56 -> 1.3951945 | G36: =(G73+G10-G65)/G56 -> 43.513408 | H36: =(H73+H10-H65)/H56 -> 0.90570959 | I36: =IFERROR(AVERAGE(C36:H36),"") -> 9.6186307 | J36: =SQRT((C36-I36)^2) -> 8.0792259
B37: EV/EBITDA | C37: =(C73+C10-C65)/C58 -> 2.0659114 | D37: =(D73+D10-D65)/D58 -> 21.631001 | E37: =(E73+E10-E65)/E58 -> 13.328198 | F37: =(F73+F10-F65)/F58 -> 12.721364 | G37: =(G73+G10-G65)/G58 -> 90.789897 | H37: =(H73+H10-H65)/H58 -> 5.0546427 | I37: =IFERROR(AVERAGE(C37:H37),"") -> 24.265169 | J37: =SQRT((C37-I37)^2) -> 22.199257
B38: Stock Info | I38: =IFERROR(AVERAGE(C38:H38),"")
B39: Float | C39: =OP!M20 -> 59.07M | D39: 33.92 | E39: 219.57 | F39: 6.17 | G39: 512.35 | H39: 47.9 | I39: =IFERROR(AVERAGE(C39:H39),"") -> 163.982 | J39: =SQRT((C39-I39)^2) -> #VALUE!
B40: b (Yahoo) | C40: =OP!M22 -> 0.66 | D40: 1.03 | E40: 1.02 | F40: 0.89 | G40: 1.17 | H40: 1.34 | I40: =IFERROR(AVERAGE(C40:H40),"") -> 1.0183333 | J40: =SQRT((C40-I40)^2) -> 0.35833333
B41: Dividend Yield (yahoo finance) | C41: =OP!M32 -> 0.011285732 | D41: 0.0109 | E41: 0.024 | F41: - | G41: 0.0217 | H41: 0.0357 | I41: =IFERROR(AVERAGE(C41:H41),"") -> 0.020717146 | J41: =SQRT((C41-I41)^2) -> 0.0094314148
...

Sheet ESG
B1: Company GICS Sector: | T1: Yes
B2: Consumer Discretionary | C2: <- Select Industry | T2: No
B3: ESG Analysis | K3: Relative ESG Analysis
B4: Parameters | C4: Impact | D4: Do they report? | E4: Ranking | F4: Mitigation Plan | G4: Traffic Lights | H4: Improvement over time? | I4: Targets / Goals? | J4: Comments | K4: Parameters | L4: =OP!E2 -> #VALUE! | M4: =Peers!C2 -> #VALUE! | N4: =Peers!C3 -> #VALUE! | O4: =Peers!C4 -> #VALUE! | P4: =Peers!C5 -> #VALUE! | Q4: =Peers!C6 -> #VALUE! | R4: AVERAGE
B5: Environmental | K5: Ratios
A6: 1 | B6: CO2 Direct Emissions | C6: =VLOOKUP($B$2,'Sector Impact'!$K$4:$AA$16,A6+1,FALSE) -> Low | K6: CO2 Emissions/$M Sales | L6: =L12/L$11 -> 217.56699 | M6: =M12/M$11 -> 74.285589 | N6: =N12/N$11 -> 357.75958 | O6: =O12/O$11 -> 128.00893 | P6: =P12/P$11 -> 70.230952 | Q6: =Q12/Q$11 -> 289.70227 | R6: =IFERROR(AVERAGE(L6:Q6),"") -> 189.59239
A7: 2 | B7: Total Water Consumption | C7: =VLOOKUP($B$2,'Sector Impact'!$K$4:$AA$16,A7+1,FALSE) -> Low | K7: Water Consumption/$M Sales | L7: =L13/L$11 -> 217.96117 | M7: =M13/M$11 -> 30.731087 | N7: =N13/N$11 -> 105.79829 | O7: =O13/O$11 -> 128.40237 | P7: =P13/P$11 -> 61.034048 | Q7: =Q13/Q$11 -> 54.431115 | R7: =IFERROR(AVERAGE(L7:Q7),"") -> 99.726345
A8: 3 | B8: Total Energy Consumption | C8: =VLOOKUP($B$2,'Sector Impact'!$K$4:$AA$16,A8+1,FALSE) -> Medium | D8: Yes | E8: Medium | F8: Yes | J8: There was an increase of 50,000 Gj of energy consumption between 2022 and 2023. | K8: Energy Consumption/$M Sales | L8: =L14/L$11 -> 172.61505 | M8: =M14/M$11 -> 71.08917 | N8: =N14/N$11 -> 301.93673 | O8: =O14/O$11 -> 151.30178 | P8: =P14/P$11 -> 91.480476 | Q8: =Q14/Q$11 -> 36.251164 | R8: =IFERROR(AVERAGE(L8:Q8),"") -> 137.44573
A9: 4 | B9: Waste Management | C9: =VLOOKUP($B$2,'Sector Impact'!$K$4:$AA$16,A9+1,FALSE) -> Medium | D9: Yes | E9: Medium | F9: Yes | J9: The company was able to reduce 100 tonnes of waste between 2022 and 2023. | K9: Waste Production/$M Sales | L9: =L15/L$11 -> 0.58980583 | M9: =M15/M$11 -> 0.48058627 | N9: =N15/N$11 -> 2.6938593 | O9: =O15/O$11 -> 2.875532 | P9: =P15/P$11 -> 0.54166667 | Q9: =Q15/Q$11 -> 2.4420707 | R9: =IFERROR(AVERAGE(L9:Q9),"") -> 1.6039201
A10: 5 | B10: Land Degradation/Deforestation/Biodiversity loss/Animal sufering/… | C10: =VLOOKUP($B$2,'Sector Impact'!$K$4:$AA$16,A10+1,FALSE) -> Low | K10: Inputs
B11: Social | K11: Net Sales ($M) | L11: 2060 | M11: 1139.4 | N11: 671.75 | O11: 963.3 | P11: 4200 | Q11: 3651
A12: 6 | B12: Employee Turnover % | C12: =VLOOKUP($B$2,'Sector Impact'!$K$4:$AA$16,A12+1,FALSE) -> Medium | D12: No | J12: Could not find any information. | K12: CO2 Emissions Total (Tonnes) | L12: 448188 | M12: 84641 | N12: 240325 | O12: 123311 | P12: 294970 | Q12: 1057703
A13: 7 | B13: Salaries & Compensation | C13: =VLOOKUP($B$2,'Sector Impact'!$K$4:$AA$16,A13+1,FALSE) -> Medium | D13: Yes | E13: "Villain" | F13: No | J13: The median salarie is 102,715 while the average salarie at Ermenegildo Zegna is 87,694. | K13: Water Consumption Total (Cubic Meters) | L13: 449000 | M13: 35015 | N13: 71070 | O13: 123690 | P13: 256343 | Q13: 198728
A14: 8 | B14: Reputation | C14: =VLOOKUP($B$2,'Sector Impact'!$K$4:$AA$16,A14+1,FALSE) -> Low | K14: Energy Consumption Total (Gigajoules) | L14: 355587 | M14: 80999 | N14: 202826 | O14: 145749 | P14: 384218 | Q14: 132353
A15: 9 | B15: Discrimination Events | C15: =VLOOKUP($B$2,'Sector Impact'!$K$4:$AA$16,A15+1,FALSE) -> Low | F15: Yes | K15: Waste Production Total (Tonnes) | L15: 1215 | M15: 547.58 | N15: 1809.6 | O15: 2770 | P15: 2275 | Q15: 8916
A16: 10 | B16: Work Safety | C16: =VLOOKUP($B$2,'Sector Impact'!$K$4:$AA$16,A16+1,FALSE) -> Medium | D16: No | E16: "Best in class" | F16: No | I16: None | J16: There are no reports of recent accidents at work at the company. | K16: ESG Scores
A17: 11 | B17: Damage to consumer health | C17: =VLOOKUP($B$2,'Sector Impact'!$K$4:$AA$16,A17+1,FALSE) -> Medium | D17: No | E17: "Best in class" | F17: No | I17: None | J17: There are no reports of damages to consumer health made by products of the company. | K17: Refinitiv | L17: 40/100 | M17: 50/100 | N17: 81/100 | P17: 52/100 | Q17: 89/100
A18: 12 | B18: PXP? | C18: =VLOOKUP($B$2,'Sector Impact'!$K$4:$AA$16,A18+1,FALSE) -> Medium | D18: No | E18: "Villain" | F18: No | H18: None | I18: None | J18: Could not find any information about the company pension plan. | K18: Sustainalytics | M18: 18.8(Low Risk) | N18: 8.4(negligible risk) | O18: 14.8(Low Risk) | P18: 15.0(Low Risk) | Q18: 12.5(Low Risk)
A19: 13 | B19: Supply chain | C19: =VLOOKUP($B$2,'Sector Impact'!$K$4:$AA$16,A19+1,FALSE) -> High | D19: Yes | E19: "Best in class" | F19: No | I19: None | J19: The company establishes a great relation with their suppliers being a part of their "filera". | K19: ISS | L19: C | M19: C- | N19: C | O19: C- | P19: C+ | Q19: B-
A20: 14 | B20: Community involvement | C20: =VLOOKUP($B$2,'Sector Impact'!$K$4:$AA$16,A20+1,FALSE) -> Low | K20: CDP | L20: /C | M20: A-/ | N20: A/F | O20: F/F | P20: A-/F/B | Q20: B/
A21: 15 | B21: Public Sector | C21: =VLOOKUP($B$2,'Sector Impact'!$K$4:$AA$16,A21+1,FALSE) -> High | D21: No | I21: None | J21: Could not find any information.
A22: 16 | B22: Litigation | C22: =VLOOKUP($B$2,'Sector Impact'!$K$4:$AA$16,A22+1,FALSE) -> Low | D22: Yes
B23: Corporate Governance | K23: PARAMETERS
A24: 17 | B24: Diversity (Gender, Age, Industry, Region) | E24: Medium | F24: No | I24: None | J24: 3 out of 10 members of the board are women. | K24: IMPACT | L24: RANKING | M24: MITIGATION PLAN | O24: TRAFFIC
A25: 18 | B25: % Independence | E25: Medium | F25: No | I25: None | J25: Half of the members of the board are independent. | K25: Low | L25: "Best in class" | M25: Is there evidence of a plan/program ?
A26: 19 | B26: average time as independent directors | E26: "Best in class" | F26: No | I26: None | J26: The average time as independent director is around 5 years. | K26: Medium | L26: Medium High
A27: 20 | B27: Recent departures of directors / C-level executives? | E27: "Best in class" | F27: No | I27: None | J27: The most recent departure was in 2021. | K27: High | L27: Medium
A28: 21 | B28: CEO/Chairman duality | E28: "Villain" | F28: No | I28: None | J28: Both the chairman and CEO positions are occupied by Ermenegildo Zegna | K28: Very high | L28: "Villain"
A29: 22 | B29: Transparency (ESG, segments, acquisitions, other) | E29: Medium | F29: No | I29: None | J29: It was really hard to find the information about the environmental part.
A30: 23 | B30: Time taken to report after the end of the quarter / year | E30: "Best in class" | F30: No | I30: None | J30: The company took 5 months to publish their report.
A31: 24 | B31: Additional participation of the CEO in other boards or excessive participation of Ch. | E31: "Best in class" | F31: No | I31: None | J31: The CEO and chairman of the company is only present on Ermenegildo Zegna board.
A32: 25 | B32: Audit / Consulting | D32: Yes | E32: Medium | F32: No | I32: None | J32: The company spent 6,483 in audit and non-audit fees.
A33: 26 | B33: ESG-compensation related | D33: No | E33: "Villain" | F33: No | I33: None | J33: The company offers no ESG-compensation related.
A34: 27 | B34: Management compensation schemes | D34: Yes | E34: "Best in class" | F34: No | I34: None | J34: The Company will pay Non-Executive directors an annual base fee of 150,000 euros per annum payable 50% in cash and 50% in Company's ordinary shares ("Equity Awards"), subject to a restricted stock award.

Sheet DCF
A1: VALUATION MODEL
G3: Short Term | K3: Long Term
A4: Section | B4: Line # | C4: ITEM | D4: 2021 (Real) | E4: 2022 (Real) | F4: 2023 (Real) | G4: 2024 | H4: =G4+1 -> 2025 | I4: =H4+1 -> 2026 | J4: =I4+1 -> 2027 | K4: =J4+1 -> 2028 | L4: =K4+1 -> 2029 | M4: =L4+1 -> 2030 | N4: =M4+1 -> 2031 | O4: =N4+1 -> 2032 | ... AF4: =AE4+1 -> 2049
A5: INCOME STATEMENT | B5: 1 | C5: Growth | D5: ='Fin. Data'!D6 -> 0.32037997 | E5: =+E6/D6-1 -> 0.028776978 | F5: =+F6/E6-1 -> 0.30959949 | G5: 0.085 | H5: =Assumptions!L9 -> 0.05 | I5: =Assumptions!L9 -> 0.05 | J5: =Assumptions!L9 -> 0.05 | K5: =Assumptions!M9 -> 0.03 | L5: =Assumptions!M9 -> 0.03 | M5: =Assumptions!M9 -> 0.03 | N5: =Assumptions!M9 -> 0.03 | O5: =Assumptions!M9 -> 0.03 | P5: =Assumptions!M9 -> 0.03 | Q5: =Assumptions!$M$9 -> 0.03 | R5: =Assumptions!$M$9 -> 0.03 | S5: =Assumptions!$M$9 -> 0.03 | T5: =Assumptions!$M$9 -> 0.03 | U5: =Assumptions!$M$9 -> 0.03 | V5: =Assumptions!$M$9 -> 0.03 | W5: =Assumptions!$M$9 -> 0.03 | X5: =Assumptions!$M$9 -> 0.03 | ... AE5: =Assumptions!$M$9 -> 0.03 | AF5: =Assumptions!M9 -> 0.03
B6: 2 | C6: Revenues/Sales | D6: =Inputs!D6 -> 1529 | E6: =Inputs!C6 -> 1573 | F6: =Inputs!B6 -> 2060 | G6: =F6*(1+G5) -> 2235.1 | H6: =G6*(1+H5) -> 2346.855 | I6: =H6*(1+I5) -> 2464.1978 | J6: =I6*(1+J5) -> 2587.4076 | K6: =J6*(1+K5) -> 2665.0299 | L6: =K6*(1+L5) -> 2744.9808 | M6: =L6*(1+M5) -> 2827.3302 | N6: =M6*(1+N5) -> 2912.1501 | ... AF6: =AE6*(1+AF5) -> 4957.7406
B7: 3 | C7: EBIT/Operating Margin | D7: =D8/D6 -> 0.092851537 | E7: =E8/E6 -> 0.1091227 | F7: =F8/F6 -> 0.1168301 | G7: =Assumptions!L10 -> 0.13 | H7: =Assumptions!L10 -> 0.13 | I7: =Assumptions!L10 -> 0.13 | J7: =Assumptions!L10 -> 0.13 | K7: =Assumptions!M10 -> 0.14 | L7: =Assumptions!$M$10 -> 0.14 | M7: =Assumptions!$M$10 -> 0.14 | N7: =Assumptions!$M$10 -> 0.14 | O7: =Assumptions!$M$10 -> 0.14 | P7: =Assumptions!$M$10 -> 0.14 | Q7: =Assumptions!$M$10 -> 0.14 | R7: =Assumptions!$M$10 -> 0.14 | S7: =Assumptions!$M$10 -> 0.14 | ... AE7: =Assumptions!$M$10 -> 0.14 | AF7: =Assumptions!M10 -> 0.14
B8: 4 | C8: EBIT | D8: ='Fin. Data'!D11 -> 141.97 | E8: ='Fin. Data'!C11 -> 171.65 | F8: ='Fin. Data'!B11 -> 240.67 | G8: =G7*G6 -> 290.563 | H8: =H7*H6 -> 305.09115 | I8: =I7*I6 -> 320.34571 | J8: =J7*J6 -> 336.36299 | K8: =K7*K6 -> 373.10418 | L8: =L7*L6 -> 384.29731 | M8: =M7*M6 -> 395.82623 | N8: =N7*N6 -> 407.70101 | ... AF8: =AF7*AF6 -> 694.08368 | AG8: 322.78589
B9: 5a | C9: (Dep) | D9: -15.42 | E9: -14.28 | F9: -17.71 | G9: =-G40*$D$53 -> -21.090713 | H9: =-H40*$D$53 -> -23.144211 | I9: =-I40*$D$53 -> -25.300384 | J9: =-J40*$D$53 -> -27.564365 | K9: =-K40*$E$53 -> -29.563138 | L9: =-L40*$E$53 -> -31.621873 | M9: =-M40*$E$53 -> -33.742371 | N9: =-N40*$E$53 -> -35.926484 | O9: =-O40*$E$53 -> -38.176119 | P9: =-P40*$E$53 -> -40.493244 | Q9: =-Q40*$E$53 -> -42.879883 | R9: =-R40*$E$53 -> -45.338121 | ... AF9: =-AF40*$E$53 -> -88.600439 | AG9: -53.797648
B10: 5b | C10: (Amort) | D10: -10 | E10: -12 | F10: -14 | G10: =F10*(1+$D$54) -> -14.35 | H10: =G10*(1+$D$54) -> -14.70875 | I10: =H10*(1+$D$54) -> -15.076469 | J10: =I10*(1+$D$54) -> -15.45338 | K10: =J10*(1+$E$54) -> -15.839715 | L10: =K10*(1+$E$54) -> -16.235708 | M10: =L10*(1+$E$54) -> -16.641601 | N10: =M10*(1+$E$54) -> -17.057641 | O10: =N10*(1+$E$54) -> -17.484082 | P10: =O10*(1+$E$54) -> -17.921184 | Q10: =P10*(1+$E$54) -> -18.369213 | R10: =Q10*(1+$E$54) -> -18.828444 | ... AF10: =AE10*(1+$E$54) -> -26.604098 | AG10: -35.865099
B11: 5c | C11: (Stock based compensation) | D11: -116.4 | E11: -122.6 | F11: -143.22 | G11: =-G6*$D$55 -> -134.106 | H11: =-H6*$D$55 -> -140.8113 | I11: =-I6*$D$55 -> -147.85187 | J11: =-J6*$D$55 -> -155.24446 | K11: =-K6*$E$55 -> -159.90179 | L11: =-L6*$E$55 -> -164.69885 | M11: =-M6*$E$55 -> -169.63981 | N11: =-N6*$E$55 -> -174.72901 | O11: =-O6*$E$55 -> -179.97088 | P11: =-P6*$E$55 -> -185.37 | Q11: =-Q6*$E$55 -> -190.9311 | R11: =-R6*$E$55 -> -196.65904 | ... AF11: =-AF6*$E$55 -> -297.46444 | AG11: -107.5953
B12: 6 | C12: EBITDA | D12: =D8-D9-D10 -> 167.39 | E12: =E8-E9-E10 -> 197.93 | F12: =F8-F9-F10 -> 272.38 | G12: =G8-G9-G10 -> 326.00371 | H12: =H8-H9-H10 -> 342.94411 | I12: =I8-I9-I10 -> 360.72256 | J12: =J8-J9-J10 -> 379.38074 | K12: =K8-K9-K10 -> 418.50703 | ... AF12: =AF8-AF9-AF10 -> 809.28822 | AG12: 233.12314
B13: 7 | C13: (Net financing cost) | D13: ='Fin. Data'!D14 -> -6.21 | E13: ='Fin. Data'!C14 -> -27.74 | F13: ='Fin. Data'!B14 -> -33.5 | G13: =F43*$D$58-F44*$D$57 -> -15.450161 | H13: =G43*$D$58-G44*$D$57 -> -14.153521 | I13: =H43*$D$58-H44*$D$57 -> -12.062645 | J13: =I43*$D$58-I44*$D$57 -> -11.805994 | K13: =J43*$E$58-J44*$E$57 -> -23.436036 | L13: =K43*$E$58-K44*$E$57 -> -23.355336 | M13: =L43*$E$58-L44*$E$57 -> -24.271525 | N13: =M43*$E$58-M44*$E$57 -> -25.203988 | O13: =N43*$E$58-N44*$E$57 -> -26.136888 | P13: =O43*$E$58-O44*$E$57 -> -27.080848 | Q13: =P43*$E$58-P44*$E$57 -> -28.03411 | R13: =Q43*$E$58-Q44*$E$57 -> -28.994271 | ... AF13: =AE43*$E$58-AE44*$E$57 -> -43.320243
B14: 8 | C14: Other income/(cost) | D14: ='Fin. Data'!D15 -> -260.31 | E14: ='Fin. Data'!C15 -> -51.95 | F14: ='Fin. Data'!B15 -> -39.6 | G14: =AVERAGE(D14:F14)*(1+G5) -> -127.25603 | H14: =AVERAGE(E14:G14)*(1+H5) -> -76.582112 | I14: =AVERAGE(F14:H14)*(1+I5) -> -85.203351 | J14: =AVERAGE(G14:I14)*(1+J5) -> -101.16452 | K14: =AVERAGE(H14:J14)*(1+K5) -> -90.279495 | L14: =AVERAGE(I14:K14)*(1+L5) -> -94.982264 | M14: =AVERAGE(J14:L14)*(1+M5) -> -98.33969 | N14: =AVERAGE(K14:M14)*(1+N5) -> -97.369831 | ... AF14: =AVERAGE(AC14:AE14)*(1+AF5) -> -128.28854
B15: 9 | C15: Earnings before taxes | D15: =D8+D13+D14 -> -124.55 | E15: =E8+E13+E14 -> 91.96 | F15: =F8+F13+F14 -> 167.57 | G15: =G8+G13+G14 -> 147.85681 | H15: =H8+H13+H14 -> 214.35552 | I15: =I8+I13+I14 -> 223.07971 | J15: =J8+J13+J14 -> 223.39248 | K15: =K8+K13+K14 -> 259.38865 | ... AF15: =AF8+AF13+AF14 -> 522.4749
B16: 10 | C16: (Income tax) | D16: ='Fin. Data'!D21 -> -36.32 | E16: ='Fin. Data'!C21 -> -37.72 | F16: ='Fin. Data'!B21 -> -36.15 | G16: =-$D$56*G15 -> -35.485633 | H16: =-$D$56*H15 -> -51.445324 | I16: =-$D$56*I15 -> -53.539131 | J16: =-$D$56*J15 -> -53.614194 | K16: =-$E$56*K15 -> -62.253276 | L16: =-$E$56*L15 -> -63.83033 | M16: =-$E$56*M15 -> -65.571603 | N16: =-$E$56*N15 -> -68.430526 | O16: =-$E$56*O15 -> -70.557834 | P16: =-$E$56*P15 -> -72.957469 | Q16: =-$E$56*Q15 -> -75.585813 | R16: =-$E$56*R15 -> -78.137744 | ... AF16: =-$E$56*AF15 -> -125.39398
B17: 11 | C17: Net income | D17: ='Fin. Data'!D23 -> -160.87 | E17: ='Fin. Data'!C23 -> 54.24 | F17: ='Fin. Data'!B23 -> 131.42 | G17: =G16+G15 -> 112.37117 | H17: =H16+H15 -> 162.91019 | I17: =I16+I15 -> 169.54058 | J17: =J16+J15 -> 169.77828 | K17: =K16+K15 -> 197.13537 | L17: =L16+L15 -> 202.12938 | M17: =M16+M15 -> 207.64341 | N17: =N16+N15 -> 216.69667 | ... AF17: =AF16+AF15 -> 397.08093
A19: CASH FLOW STATEMENT | B19: 12 | C19: Operating cash flows before WK | D19: 318.9 | E19: 282.87 | F19: 443.95 | G19: =G17-G10-G9-G11 -> 281.91788 | H19: =H17-H10-H9-H11 -> 341.57445 | I19: =I17-I10-I9-I11 -> 357.7693 | J19: =J17-J10-J9-J11 -> 368.04049 | K19: =K17-K10-K9-K11 -> 402.44002 | L19: =L17-L10-L9-L11 -> 414.6858 | M19: =M17-M10-M9-M11 -> 427.66719 | N19: =N17-N10-N9-N11 -> 444.4098 | ... AF19: =AF17-AF10-AF9-AF11 -> 809.7499
B20: 13 | C20: (Stock-based compensation) | D20: =D11 -> -116.4 | E20: =E11 -> -122.6 | F20: =F11 -> -143.22 | G20: =G11 -> -134.106 | H20: =H11 -> -140.8113 | I20: =I11 -> -147.85187 | J20: =J11 -> -155.24446 | K20: =K11 -> -159.90179 | ... AF20: =AF11 -> -297.46444
B21: 14 | C21: (Working Capital Flows) | D21: =Inputs!D62 -> 24 | E21: =Inputs!C62 -> -40 | F21: =Inputs!B62 -> -22 | G21: =$D$60*(G6-F6) -> -8.755 | H21: =$D$60*(H6-G6) -> -5.58775 | I21: =$D$60*(I6-H6) -> -5.8671375 | J21: =$D$60*(J6-I6) -> -6.1604944 | K21: =$E$60*(K6-J6) -> 62.097783 | L21: =$E$60*(L6-K6) -> 63.960717 | M21: =$E$60*(M6-L6) -> 65.879538 | N21: =$E$60*(N6-M6) -> 67.855924 | O21: =$E$60*(O6-N6) -> 69.891602 | P21: =$E$60*(P6-O6) -> 71.98835 | Q21: =$E$60*(Q6-P6) -> 74.148001 | R21: =$E$60*(R6-Q6) -> 76.372441 | ... AF21: =$E$60*(AF6-AE6) -> 115.52017
B22: 15 | C22: -Total Operating Cash Flow | D22: =D19+D20+D21 -> 226.5 | E22: =E19+E20+E21 -> 120.27 | F22: =F19+F20+F21 -> 278.73 | G22: =G19+G20+G21 -> 139.05688 | H22: =H19+H20+H21 -> 195.1754 | I22: =I19+I20+I21 -> 204.0503 | J22: =J19+J20+J21 -> 206.63553 | K22: =K19+K20+K21 -> 304.63601 | ... AF22: =AF19+AF20+AF21 -> 627.80563
B23: 16 | C23: (CAPEX) | D23: ='Fin. Data'!D32 -> -89.7 | E23: ='Fin. Data'!C32 -> -51.52 | F23: ='Fin. Data'!B32 -> -61.46 | G23: =G6*$D$62 -> -78.2285 | H23: =H6*$D$62 -> -82.139925 | I23: =I6*$D$62 -> -86.246921 | J23: =J6*$D$62 -> -90.559267 | K23: =K6*$E$62 -> -79.950896 | L23: =L6*$E$62 -> -82.349423 | M23: =M6*$E$62 -> -84.819906 | N23: =N6*$E$62 -> -87.364503 | O23: =O6*$E$62 -> -89.985438 | P23: =P6*$E$62 -> -92.685001 | Q23: =Q6*$E$62 -> -95.465551 | R23: =R6*$E$62 -> -98.329518 | ... AF23: =AF6*$E$62 -> -148.73222 | AG23: =SUM(D23:AF23) -> -2981.2976
B24: 17 | C24: Adq | D24: =Inputs!D66 -> -7.3 | E24: ='Fin. Data'!C33 -> -8.48 | F24: ='Fin. Data'!B33 -> 85.46 | G24: =G6*$D$63 -> -33.5265 | H24: =H6*$D$63 -> -35.202825 | I24: =I6*$D$63 -> -36.962966 | J24: =J6*$D$63 -> -38.811115 | K24: =K6*$E$63 -> -106.60119 | L24: =L6*$E$63 -> -109.79923 | M24: =M6*$E$63 -> -113.09321 | N24: =N6*$E$63 -> -116.486 | O24: =O6*$E$63 -> -119.98058 | P24: =P6*$E$63 -> -123.58 | Q24: =Q6*$E$63 -> -127.2874 | R24: =R6*$E$63 -> -131.10602 | ... AF24: =AF6*$E$63 -> -198.30962 | AH24: =AG9-AG23 -> 2927.4999
B25: 18 | C25: (Other investing flows) | D25: =Inputs!D67 -> 0 | E25: =Inputs!C67 -> -0.4 | F25: =Inputs!B67 -> -0.44 | G25: =(1+G5)*AVERAGE(D25:F25) -> -0.3038 | H25: =(1+H5)*AVERAGE(E25:G25) -> -0.40033 | I25: =(1+I5)*AVERAGE(F25:H25) -> -0.4004455 | J25: =(1+J5)*AVERAGE(G25:I25) -> -0.38660143 | K25: =(1+K5)*AVERAGE(H25:J25) -> -0.40766608 | L25: =(1+L5)*AVERAGE(I25:K25) -> -0.4101848 | M25: =(1+M5)*AVERAGE(J25:L25) -> -0.41352862 | N25: =(1+N5)*AVERAGE(K25:M25) -> -0.42277363 | ... AF25: =(1+AF5)*AVERAGE(AC25:AE25) -> -0.55059886
B26: 19 | C26: -Total Investing Flows | D26: =D23+D24+D25 -> -97 | E26: =E23+E24+E25 -> -60.4 | F26: =F23+F24+F25 -> 23.56 | G26: =G23+G24+G25 -> -112.0588 | H26: =H23+H24+H25 -> -117.74308 | I26: =I23+I24+I25 -> -123.61033 | J26: =J23+J24+J25 -> -129.75698 | K26: =K23+K24+K25 -> -186.95976 | ... AF26: =AF23+AF24+AF25 -> -347.59244
B27: 20 | C27: (Flows related to leases) | D27: =Inputs!D71+Inputs!D72 -> 0 | E27: =Inputs!C71+Inputs!C72 -> 0 | F27: =Inputs!B71+Inputs!B72 -> 0 | G27: =G6*$D$66 -> 145.2815 | H27: =H6*$D$66 -> 152.54558 | I27: =I6*$D$66 -> 160.17285 | J27: =J6*$D$66 -> 168.1815 | K27: =$E$66*K6 -> 79.950896 | L27: =$E$66*L6 -> 82.349423 | M27: =$E$66*M6 -> 84.819906 | N27: =$E$66*N6 -> 87.364503 | O27: =$E$66*O6 -> 89.985438 | P27: =$E$66*P6 -> 92.685001 | Q27: =$E$66*Q6 -> 95.465551 | R27: =$E$66*R6 -> 98.329518 | ... AF27: =$E$66*AF6 -> 148.73222
B28: 21 | C28: Flows related to debt | D28: =+SUM(Inputs!D69:D70) -> -168 | E28: =+SUM(Inputs!C69:C70) -> -301 | F28: =+SUM(Inputs!B69:B70) -> -246 | G28: =G44-F44 -> -186.7596 | H28: =H44-G44 -> 47.433115 | I28: =I44-H44 -> 49.779658 | J28: =J44-I44 -> 52.242901 | K28: =K44-J44 -> -15.998483 | L28: =L44-K44 -> 34.119635 | M28: =M44-L44 -> 35.138274 | N28: =N44-M44 -> 36.187348 | ... AF28: =AF44-AE44 -> 61.458039
B29: 22 | C29: (Repurchases)/Issuance of stock | D29: ='Fin. Data'!D28 -> -767 | E29: ='Fin. Data'!C28 -> -15 | F29: ='Fin. Data'!B28 -> -4 | G29: =-G17*$D$65 -> -4.4948469 | H29: =-H17*$D$65 -> -6.5164077 | I29: =-I17*$D$65 -> -6.7816232 | J29: =-J17*$D$65 -> -6.7911312 | K29: =-K17*$E$65 -> -19.713537 | L29: =-L17*$E$65 -> -20.212938 | M29: =-M17*$E$65 -> -20.764341 | N29: =-N17*$E$65 -> -21.669667 | O29: =-O17*$E$65 -> -22.343314 | P29: =-P17*$E$65 -> -23.103198 | Q29: =-Q17*$E$65 -> -23.935507 | R29: =-R17*$E$65 -> -24.743619 | ... AF29: =-AF17*$E$65 -> -39.708093
B30: 23 | C30: (Dividends) | D30: =-'Fin. Data'!D27 -> -0.12 | E30: ='Fin. Data'!C27 -> -23.03 | F30: ='Fin. Data'!B27 -> -27.07 | G30: =-$D$64*G17 -> -22.474234 | H30: =-$D$64*H17 -> -32.582039 | I30: =-$D$64*I17 -> -33.908116 | J30: =-$D$64*J17 -> -33.955656 | K30: =-$E$64*K17 -> -78.85415 | L30: =-$E$64*L17 -> -80.851751 | M30: =-$E$64*M17 -> -83.057363 | N30: =-$E$64*N17 -> -86.678667 | O30: =-$E$64*O17 -> -89.373257 | P30: =-$E$64*P17 -> -92.412793 | Q30: =-$E$64*Q17 -> -95.742029 | R30: =-$E$64*R17 -> -98.974475 | ... AF30: =-$E$64*AF17 -> -158.83237
B31: 24 | C31: Other financing flows | D31: =Inputs!D75 -> 859.05 | E31: =Inputs!C75 -> 26.15 | F31: =Inputs!B75 -> 6.19 | G31: =(1+G5)*AVERAGE(Inputs!B74:M74) -> -142.49667 | H31: =(1+H5)*AVERAGE(Inputs!B74:L74,G31) -> -139.5745 | I31: =(1+I5)*AVERAGE(Inputs!B74:L74,G31,H31) -> -140.44684 | J31: =(1+J5)*AVERAGE(G31:I31) -> -147.8813 | K31: =(1+K5)*AVERAGE(H31:J31) -> -146.91324 | L31: =(1+L5)*AVERAGE(I31:K31) -> -149.43288 | M31: =(1+M5)*AVERAGE(J31:L31) -> -152.51808 | N31: =(1+N5)*AVERAGE(K31:M31) -> -154.11004 | O31: =(1+O5)*AVERAGE(L31:N31) -> -156.58094 | P31: =(1+P5)*AVERAGE(M31:O31) -> -159.03511 | Q31: =(1+Q5)*AVERAGE(N31:P31) -> -161.27263 | ... AF31: =(1+AF5)*AVERAGE(AC31:AE31) -> -201.46887
B32: 25 | C32: -Total Financing flows | D32: =D27+D28+D29+D30+D31 -> -76.07 | E32: =E27+E28+E29+E30+E31 -> -312.88 | F32: =F27+F28+F29+F30+F31 -> -270.88 | G32: =G27+G28+G29+G30+G31 -> -210.94385 | H32: =H27+H28+H29+H30+H31 -> 21.305743 | I32: =I27+I28+I29+I30+I31 -> 28.815932 | J32: =J27+J28+J29+J30+J31 -> 31.796307 | K32: =K27+K28+K29+K30+K31 -> -181.52851 | ... AF32: =AF27+AF28+AF29+AF30+AF31 -> -189.81908
A34: SUMMARY | B34: 26 | C34: Cash before shareholder returns | D34: =D22+D26+D27+D28+D31 -> 820.55 | E34: =E22+E26+E27+E28+E31 -> -214.98 | F34: =F22+F26+F27+F28+F31 -> 62.48 | G34: =G22+G26+G27+G28+G31 -> -156.97669 | H34: =H22+H26+H27+H28+H31 -> 137.83651 | I34: =I22+I26+I27+I28+I31 -> 149.94563 | J34: =J22+J26+J27+J28+J31 -> 149.42164 | K34: =K22+K26+K27+K28+K31 -> 34.715425 | ... AF34: =AF22+AF26+AF27+AF28+AF31 -> 288.93457
B35: 27 | C35: Returns to shareholders | D35: =-1*(D29+D30) -> 767.12 | E35: =-1*(E29+E30) -> 38.03 | F35: =-1*(F29+F30) -> 31.07 | G35: =-1*(G29+G30) -> 26.969081 | H35: =-1*(H29+H30) -> 39.098446 | I35: =-1*(I29+I30) -> 40.689739 | J35: =-1*(J29+J30) -> 40.746787 | K35: =-1*(K29+K30) -> 98.567687 | ... AF35: =-1*(AF29+AF30) -> 198.54046
B36: 28 | C36: Excess cash acumulation | D36: =D34-D35 -> 53.43 | E36: =E34-E35 -> -253.01 | F36: =F34-F35 -> 31.41 | G36: =G34-G35 -> -183.94577 | H36: =H34-H35 -> 98.738067 | I36: =I34-I35 -> 109.25589 | J36: =J34-J35 -> 108.67486 | K36: =K34-K35 -> -63.852262 | ... AF36: =AF34-AF35 -> 90.394111
A38: BALANCE SHEET | B38: 29 | C38: Intangible assets | D38: 483.4 | E38: 487.9 | F38: 631.6 | G38: =+F38+(-G10) -> 645.95 | H38: =+G38+(-H10) -> 660.65875 | I38: =+H38+(-I10) -> 675.73522 | J38: =+I38+(-J10) -> 691.1886 | K38: =+J38+(-K10) -> 707.02831 | L38: =+K38+(-L10) -> 723.26402 | M38: =+L38+(-M10) -> 739.90562 | N38: =+M38+(-N10) -> 756.96326 | ... AF38: =+AE38+(-AF10) -> 1148.368 | AG38: =SUM(G38:AF38) -> 22685.088
B39: 30 | C39: Accumulated amortization | D39: 146.719 | E39: 143.184 | F39: 160.895 | G39: =F39-G10 -> 175.245 | H39: =G39-H10 -> 189.95375 | I39: =H39-I10 -> 205.03022 | J39: =I39-J10 -> 220.4836 | K39: =J39-K10 -> 236.32331 | L39: =K39-L10 -> 252.55902 | M39: =L39-M10 -> 269.20062 | N39: =M39-N10 -> 286.25826 | ... AF39: =AE39-AF10 -> 677.66301 | AG39: =SUM(G39:AF39) -> 10446.758
B40: 31 | C40: PPE+Right of use Assets | D40: 547.9 | E40: 536.87 | F40: 765.4 | G40: =F40+(-G23) -> 843.6285 | H40: =G40+(-H23) -> 925.76842 | I40: =H40+(-I23) -> 1012.0153 | J40: =I40+(-J23) -> 1102.5746 | K40: =J40+(-K23) -> 1182.5255 | L40: =K40+(-L23) -> 1264.8749 | M40: =L40+(-M23) -> 1349.6948 | N40: =M40+(-N23) -> 1437.0593 | ... AF40: =AE40+(-AF23) -> 3544.0176 | AG40: =SUM(G40:AF40) -> 53332.846
B41: 32 | C41: Accumulated depreciation | D41: 447.475 | E41: 435.16 | F41: 436.648 | G41: =F41-G9 -> 457.73871 | H41: =G41-H9 -> 480.88292 | I41: =H41-I9 -> 506.18331 | J41: =I41-J9 -> 533.74767 | K41: =J41-K9 -> 563.31081 | L41: =K41-L9 -> 594.93268 | M41: =L41-M9 -> 628.67505 | N41: =M41-N9 -> 664.60154 | ... AF41: =AE41-AF9 -> 1769.9691 | AG41: =SUM(G41:AF41) -> 25461.792
A43: CASH & DEBT & DISCOUNTING | B43: 33 | C43: Ending cash balance | D43: ='Fin. Data'!D39 -> 523 | E43: =E36+D43 -> 269.99 | F43: =F36+E43 -> 301.4 | G43: =G36+F43 -> 117.45423 | H43: =H36+G43+190 -> 406.1923 | I43: =I36+H43 -> 515.44819 | J43: =J36+I43 -> 624.12305 | K43: =K36+J43 -> 560.27079 | L43: =L36+K43 -> 547.63112 | M43: =M36+L43 -> 536.82979 | N43: =N36+M43 -> 531.1867 | O43: =O36+N43 -> 528.73336 | P43: =P36+O43 -> 529.98342 | ... AF43: =AF36+AE43 -> 1235.1581
B44: 34 | C44: Total Debt | D44: ='Fin. Data'!D58 -> 1212.96 | E44: ='Fin. Data'!C58 -> 978.77 | F44: ='Fin. Data'!B58 -> 1099.57 | G44: =G12*$D$67 -> 912.81039 | H44: =H12*$D$67 -> 960.24351 | I44: =I12*$D$67 -> 1010.0232 | J44: =J12*$D$67 -> 1062.2661 | K44: =K12*$E$67 -> 1046.2676 | L44: =L12*$E$67 -> 1080.3872 | M44: =M12*$E$67 -> 1115.5255 | N44: =N12*$E$67 -> 1151.7128 | O44: =O12*$E$67 -> 1188.9806 | P44: =P12*$E$67 -> 1227.3611 | Q44: =Q12*$E$67 -> 1266.8875 | R44: =R12*$E$67 -> 1307.5941 | ... AF44: =AF12*$E$67 -> 2023.2205
B45: 35 | C45: Discount factor | F45: =1/((1+$F$50)^G50) -> 1 | G45: =1/((1+$F$50)^G49) -> 0.92165899 | H45: =1/((1+$F$50)^H49) -> 0.84945529 | I45: =1/((1+$F$50)^I49) -> 0.7829081 | J45: =1/((1+$F$50)^J49) -> 0.72157428 | K45: =1/((1+$F$50)^K49) -> 0.66504542 | L45: =1/((1+$F$50)^L49) -> 0.61294509 | M45: =1/((1+$F$50)^M49) -> 0.56492635 | N45: =1/((1+$F$50)^N49) -> 0.52066945 | ... AF45: =1/((1+$F$50)^AF49) -> 0.1199021
...

Sheet Assumptions
B2: Assumptions
B4: Prospects:
B6: Links: | C6: Zegna 2023 Annual Report (20-F) | F6: Zegna Q3 2024 earnings call transcript
C8: 2023 | D8: =C8-1 -> 2022 | E8: =D8-1 -> 2021 | F8: =E8-1 -> 2020 | G8: =F8-1 -> 2019 | I8: 5Y Average | L8: Short Term Forecast | M8: Long Term Forecast
B9: Revenue growth | C9: =(Inputs!B6-Inputs!C6)/Inputs!C6 -> 0.30959949 | D9: =(Inputs!C6-Inputs!D6)/Inputs!D6 -> 0.028776978 | E9: =(Inputs!D6-Inputs!E6)/Inputs!E6 -> 0.32037997 | F9: =(Inputs!E6-Inputs!F6)/Inputs!F6 -> -0.21703854 | G9: =(Inputs!F6-Inputs!G6)/Inputs!G6 -> 0.059455587 | I9: =AVERAGE(C9:G9) -> 0.1002347 | L9: 0.05 | M9: 0.03
B10: Operating Margin | C10: =Inputs!B8/Inputs!B6 -> 0.1168301 | D10: =Inputs!C8/Inputs!C6 -> 0.1091227 | E10: =Inputs!D8/Inputs!D6 -> 0.092851537 | F10: =Inputs!E8/Inputs!E6 -> 0.020803109 | G10: =Inputs!F8/Inputs!F6 -> 0.081920216 | I10: =AVERAGE(C10:G10) -> 0.084305531 | L10: 0.13 | M10: 0.14
B13: Modelling Factors
C15: Last 5 Years
C16: =C8 -> 2023 | D16: =D8 -> 2022 | E16: =E8 -> 2021 | F16: =F8 -> 2020 | G16: =G8 -> 2019 | I16: =I8 -> 5Y Average | L16: Short Term Forecast | M16: Long Term Forecast | O16: Reference
B17: Depreciation factor | C17: =DCF!F9/DCF!F40 -> -0.023138228 | D17: =DCF!E9/DCF!E40 -> -0.026598618 | E17: =DCF!D9/DCF!D40 -> -0.028143822 | F17: =-175.8/727.6 -> -0.24161627 | G17: =-173.6/823.9 -> -0.21070518 | I17: =AVERAGE(C17:G17) -> -0.10604042 | L17: 0.025 | M17: 0.025 | O17: % PPE
B18: Amortization factor | C18: =DCF!F10/DCF!F38 -> -0.022165928 | D18: =DCF!E10/DCF!E38 -> -0.024595204 | E18: =DCF!D10/DCF!D38 -> -0.020686802 | F18: =-13.03/473.7 -> -0.027506861 | G18: =-13.73/470.8 -> -0.029163127 | I18: =AVERAGE(C18:G18) -> -0.024823584 | L18: 0.025 | M18: 0.025 | O18: % IA
B19: Stock-based comp | C19: =DCF!F11/DCF!F6 -> -0.069524272 | D19: =DCF!E11/DCF!E6 -> -0.077940242 | E19: =DCF!D11/DCF!D6 -> -0.076128188 | F19: -- | G19: -- | I19: =AVERAGE(C19:E19) -> -0.074530901 | L19: 0.06 | M19: 0.06 | O19: % Revenue
B20: Tax Rate | C20: ='Fin. Data'!B21/('Fin. Data'!B21+'Fin. Data'!B23) -> -0.37944788 | D20: ='Fin. Data'!C21/('Fin. Data'!C21+'Fin. Data'!C23) -> -2.283293 | E20: ='Fin. Data'!D21/('Fin. Data'!D21+'Fin. Data'!D23) -> 0.18418784 | F20: ='Fin. Data'!E21/('Fin. Data'!E21+'Fin. Data'!E23) -> 0.22851797 | G20: ='Fin. Data'!F21/('Fin. Data'!F21+'Fin. Data'!F23) -> 1.9862237 | I20: =AVERAGE(C20:G20) -> -0.052762277 | L20: 0.24 | M20: 0.24 | O20: % EBT
B21: Interest Rate on debt | C21: =32.86/'Fin. Data'!B58 -> 0.029884409 | D21: =15.45/'Fin. Data'!C58 -> 0.015785118 | E21: =13.99/'Fin. Data'!D58 -> 0.011533769 | F21: =16.41/'Fin. Data'!E58 -> 0.01248127 | G21: =18.77/'Fin. Data'!E58 -> 0.014276261 | I21: =AVERAGE(C21:G21) -> 0.016792166 | L21: =I21 -> 0.016792166 | M21: 0.025 | O21: % Debt
B22: Interest Rate on cash | C22: =3.13/'Fin. Data'!B39 -> 0.0095718654 | D22: =1.82/'Fin. Data'!C39 -> 0.0066911765 | E22: =2.91/'Fin. Data'!D39 -> 0.0055640535 | F22: =4.4/'Fin. Data'!E39 -> 0.011340206 | G22: =6.89/'Fin. Data'!F39 -> 0.029194915 | I22: =AVERAGE(C22:G22) -> 0.012472443 | L22: 0.01 | M22: 0.005 | O22: % Cash
B23: PPE+ROA | C23: =Inputs!B33/Inputs!C33-1 -> 0.42568965 | D23: =Inputs!C33/Inputs!D33-1 -> -0.020095641 | E23: =Inputs!D33/Inputs!E33-1 -> -0.24702455 | F23: =Inputs!E33/Inputs!F33-1 -> -0.11686956 | G23: -- | I23: =AVERAGE(C23:F23) -> 0.010424974 | L23: -- | M23: -- | O23: Growing with CAPEX
B24: Working capital flows | C24: =Inputs!B62/(Inputs!B6-Inputs!C6) -> -0.045174538 | D24: =Inputs!C62/(Inputs!C6-Inputs!D6) -> -0.90909091 | E24: =Inputs!D62/(Inputs!D6-Inputs!E6) -> 0.064690027 | F24: =Inputs!E62/(Inputs!E6-Inputs!F6) -> 0.034267913 | G24: =Inputs!F62/(Inputs!F6-Inputs!G6) -> -0.15662651 | I24: =AVERAGE(C24:G24) -> -0.2023868 | L24: -0.05 | M24: 0.8 | O24: % Change in Revenues
B25: Intangible Assets | C25: 0.0002 | D25: 0.0527 | E25: 0.0497 | F25: 0.043 | G25: 0.0519 | I25: =AVERAGE(C25:G25) -> 0.0395 | L25: -- | M25: -- | O25: Growing with Amortization
B26: CAPEX | C26: =Inputs!B65/Inputs!B6 -> -0.029834951 | D26: =Inputs!C65/Inputs!C6 -> -0.032752702 | E26: =Inputs!D65/Inputs!D6 -> -0.058665795 | F26: =Inputs!E65/Inputs!E6 -> -0.025777202 | G26: =Inputs!F65/Inputs!F6 -> -0.035165652 | I26: =AVERAGE(C26:G26) -> -0.03643926 | L26: -0.035 | M26: -0.03 | O26: % Revenue
B27: Acquisition factor | C27: =Inputs!B66/Inputs!B6 -> 0.041485437 | D27: =Inputs!C66/Inputs!C6 -> -0.0053909727 | E27: =Inputs!D66/Inputs!D6 -> -0.0047743623 | F27: =Inputs!E66/Inputs!E6 -> 0.11731434 | G27: =Inputs!F66/Inputs!F6 -> 0.09872211 | I27: =AVERAGE(C27:G27) -> 0.049471309 | L27: -0.015 | M27: -0.04 | O27: % Revenue
B28: Dividends | C28: =Inputs!B73/Inputs!B12 -> -0.20598082 | D28: =Inputs!C73/Inputs!C12 -> -0.4245944 | E28: =Inputs!D73/Inputs!D12 -> -0.00074594393 | F28: =Inputs!E73/Inputs!E12 -> 0 | G28: =Inputs!F73/Inputs!F12 -> 0 | I28: =AVERAGE(C28:G28) -> -0.12626423 | L28: 0.2 | M28: 0.4 | O28: % Net Income
B29: Repurchases | C29: =Inputs!B74/Inputs!B12 -> -0.030436768 | D29: =Inputs!C74/Inputs!C12 -> -0.27654867 | E29: =Inputs!D74/Inputs!D12 -> 4.767825 | F29: =Inputs!E74/Inputs!E12 -> -0.017322016 | G29: =Inputs!F74/Inputs!F12 -> 0 | I29: =AVERAGE(C29:G29) -> 0.8887035 | L29: 0.04 | M29: 0.1 | O29: % Net Income
B30: Leases | C30: =Inputs!B72/Inputs!B6 -> 0.066019417 | D30: =Inputs!C72/Inputs!C6 -> 0.081373172 | E30: =Inputs!D72/Inputs!D6 -> 0.077828646 | F30: =Inputs!E72/Inputs!E6 -> 0.089810017 | G30: =Inputs!F72/Inputs!F6 -> 0.083840433 | I30: =AVERAGE(C30:G30) -> 0.079774337 | L30: 0.065 | M30: 0.03 | O30: % Revenue
B31: Total Debt | C31: ='Fin. Data'!B58/'Fin. Data'!B19 -> 2.2382193 | D31: ='Fin. Data'!C58/'Fin. Data'!C19 -> 2.4072061 | E31: ='Fin. Data'!D58/'Fin. Data'!D19 -> 2.0376294 | F31: ='Fin. Data'!E58/'Fin. Data'!E19 -> 4.2980386 | G31: ='Fin. Data'!F58/'Fin. Data'!F19 -> 3.5266067 | I31: =AVERAGE(C31:G31) -> 2.90154 | L31: 2.8 | M31: 2.5 | O31: % EBITDA
B34: Forecasts

Sheet Fin. Data
A1: =Inputs!H3 -> #VALUE!
A2: =Inputs!G2 -> Figures in Millions of USD
A3: Results
B4: =OP!J20 -> 2023 | C4: =B4-1 -> 2022 | D4: =C4-1 -> 2021 | E4: =D4-1 -> 2020 | F4: =E4-1 -> 2019 | G4: =F4-1 -> 2018 | H4: =G4-1 -> 2017 | I4: =H4-1 -> 2016 | J4: =I4-1 -> 2015 | ... M4: =L4-1 -> 2012
A5: Net Sales | B5: =_xlfn.XLOOKUP($A5,Inputs!$A:$A,Inputs!B:B,,0) -> 2060 | C5: =_xlfn.XLOOKUP($A5,Inputs!$A:$A,Inputs!C:C,,0) -> 1573 | D5: =_xlfn.XLOOKUP($A5,Inputs!$A:$A,Inputs!D:D,,0) -> 1529 | E5: =_xlfn.XLOOKUP($A5,Inputs!$A:$A,Inputs!E:E,,0) -> 1158 | F5: =_xlfn.XLOOKUP($A5,Inputs!$A:$A,Inputs!F:F,,0) -> 1479 | G5: =_xlfn.XLOOKUP($A5,Inputs!$A:$A,Inputs!G:G,,0) -> 1396 | H5: =_xlfn.XLOOKUP($A5,Inputs!$A:$A,Inputs!H:H,,0) -> N/A | I5: =_xlfn.XLOOKUP($A5,Inputs!$A:$A,Inputs!I:I,,0) -> N/A | J5: =_xlfn.XLOOKUP($A5,Inputs!$A:$A,Inputs!J:J,,0) -> N/A | K5: =_xlfn.XLOOKUP($A5,Inputs!$A:$A,Inputs!K:K,,0) -> N/A | L5: =_xlfn.XLOOKUP($A5,Inputs!$A:$A,Inputs!L:L,,0) -> N/A | M5: =_xlfn.XLOOKUP($A5,Inputs!$A:$A,Inputs!M:M,,0) -> N/A
A6: Growth vs. Previous year | B6: =IFERROR(B5/C5-1,"-") -> 0.30959949 | C6: =IFERROR(C5/D5-1,"-") -> 0.028776978 | D6: =IFERROR(D5/E5-1,"-") -> 0.32037997 | E6: =IFERROR(E5/F5-1,"-") -> -0.21703854 | F6: =IFERROR(F5/G5-1,"-") -> 0.059455587 | G6: =IFERROR(G5/H5-1,"-") -> - | H6: =IFERROR(H5/I5-1,"-") -> - | I6: =IFERROR(I5/J5-1,"-") -> - | ... L6: =IFERROR(L5/M5-1,"-") -> - | M6: =IFERROR(M5/#REF!-1,"-") -> -
