Workbook
Name Benchmark: #REF!
Name BestConsOv: #REF!
Name Broker_Name: OFFSET(#REF!,0,0,#REF!, 1)
Name calCODE: #REF!
Name Chart_Benchmark_100_Size: OFFSET(#REF!, 0, 0,#REF!, 1)
Name Chart_Date_Size: OFFSET(#REF!, 0, 0,#REF!, 1)
Name Chart_Date_VAL1_Size: OFFSET(#REF!, 0, 0,#REF!, 1)
Name Chart_Date_VAL2_Size: OFFSET(#REF!, 0, 0,#REF!, 1)
Name Chart_Peer_100_Size: OFFSET(#REF!, 0, 0,#REF!, 1)
Name Chart_Price_100_Size: OFFSET(#REF!, 0, 0,#REF!, 1)
Name Chart_Price_Size: OFFSET(#REF!, 0, 0,#REF!, 1)
Name Chart_VAL1_FY1_Size: OFFSET(#REF!, 0, 0,#REF!, 1)
Name Chart_VAL1_FY2_Size: OFFSET(#REF!, 0, 0,#REF!, 1)
Name Chart_VAL1_FY3_Size: OFFSET(#REF!, 0, 0,#REF!, 1)
Name Chart_VAL2_FY1_Size: OFFSET(#REF!, 0, 0,#REF!, 1)
Name Chart_VAL2_FY2_Size: OFFSET(#REF!, 0, 0,#REF!, 1)
Name Chart_VAL2_FY3_Size: OFFSET(#REF!, 0, 0,#REF!, 1)
Name Chart_Volume_Size: OFFSET(#REF!, 0, 0,#REF!, 1)
Name compNAME: #REF!
Name CURRENCY: #REF!
Name currPRICE: #REF!
Name custBenchmark: #REF!
Name custED: #REF!
Name custSD: #REF!
Name dayCODE: #REF!
Name ED: #REF!
Name ESTBrokersItem: #REF!
Name ESTBrokersPeriod: #REF!
Name ESTDetailBroker: #REF!
Name ESTDetailBroker2: #REF!
Name ESTDetailPeriod: #REF!
Name EstDetPerO: #REF!
Name EstDetPerT: #REF!
Name FinancialsPeriod: #REF!
Name fundTICKER: #REF!
Name GraphValRatio1: #REF!
Name GraphValRatio2: #REF!
Name Index1: #REF!
Name Lang: #REF!
Name newCrncy: #REF!
Name newEstBrokerPeriod: #REF!
Name newEstBrokersItem: #REF!
Name newEstDetailBroker: #REF!
Name newEstDetailBroker2: #REF!
Name newEstDetailPeriod: #REF!
Name newFinancialsPeriod: #REF!
Name newOverviewCon: #REF!
Name newOverviewYear: #REF!
Name newOwners: #REF!
Name newPeersRatio: #REF!
Name newPeriod: #REF!
Name newValRatio1: #REF!
Name newValRatio2: #REF!
Name OverviewValRatioPeriod: #REF!
Name PeerDate1: #REF!
Name peerHist1: #REF!
Name PeerIndex: #REF!
Name Peers: OFFSET(#REF!,0,0,MAX(COUNTA(#REF!),1),1)
Name peersWEIGHT: #REF!
Name PERIODICITY: #REF!

Sheet OP
B2: 45761 | C2: Analista: Research | D2: 31/12/2025 (1st Quarter 2025/05/01) | E2: #VALUE! | K2: {=_FV(E2,"Bolsa")} -> Nasdaq Stock Market | L2: SIC: Sí
B3: #VALUE! | D3: DESCRIPTION: Laureate Education is a company of higher education institutions that focus on offering accesible and quality education to students around the world. The University offers undergraduated and doctoral degrees in business and managment, medical and health sciences, engineering, information and technology, architecture, education, law and communications
D4: Andrew B. Cohen (54yo; Ch; dir. s. 2016; ex Portfolio Manager at S.A.C Capital Advisors); Eilif Serck-Hanssen (58yo; dir. s. 2018; CEO of Laureate Education; ex CFO of XOJET); Leslie Brush (58yo; dir s. 2014: Vice President of Laureate Education; ex Vice President of FIS); Rick Buskirk (57yo; dir. s. 2021; CFO of Laureate Education; ex analyst at Deutsche Bank); Marcelo Cadoso (52yo; dir. s. 2021; COO of Laureate Education; ex CFO of Dell EMC Computer System); Chistian Hearbele (51yo; dir. s. 2022; CEO Peru of Laureate Education; ex Latin America Corporate Audit Director of Pepsi); Adam Smith (59yo; dir s. 2014; Senior Vice President of Laurete Education; ex independent consultant)
B5: Millones de USD
B6: Acción | D6: Liquidez y Solvencia | F6: =Segments!B2 -> Regions (2023) | I6: Rentabilidad (2022) | K6: Múltiplos
B7: Último Precio | C7: {=_FV(E2,"Preço")} -> 30.14 | D7: Activo: | E7: =Cifras_Originales!B27 -> 1972.237 | H7: %Vts; %Op.Mg.; D | I7: Año termina: | J7: 46022 | K7: Float: | L7: 0.91
B8: Outstanding Shares | C8: {=_FV(E2,"Ações em circulação",TRUE)/1000000} -> 147.3631 | D8: Pasivo: | E8: =Cifras_Originales!B39 -> 1196.482 | F8: =Segments!B4 -> Mexico | H8: =+Segments!J4 -> 53%; NA; 27% | K8: Insiders Own: | L8: =Cifras_Originales!B50 -> 0.0232
B9: Market Cap. | C9: {=_FV(E2,"Capitalização de mercado",TRUE)/1000000} -> 4441.5238 | D9: Cash/Precio | E9: =C11/C8 -> 0.5779398 | I9: EBIT | J9: 262.269 | K9: b (Bloomberg; Yahoo) | L9: =0.89 -> 0.89
B10: +Deuda Total | C10: =Cifras_Originales!B39 -> 1196.482 | D10: Ebidta/CIF | E10: =378.3/Cifras_Originales!B9 -> 4.3184932 | F10: =Segments!B5 -> Peru | H10: =+Segments!J5 -> 47%; NA; 12% | I10: +Dep&Amort | J10: =Cifras_Originales!C11 -> 59.132 | K10: Calificación (S&P) | L10: B+
B11: -Cash | C11: =Cifras_Originales!B22 -> 85.167 | D11: Deuda/Ebidta | E11: =E8/378.3 -> 3.1627861 | I11: =EBIDTA | J11: =J9+J10 -> 321.401 | K11: Precio/Valor en libros | L11: 3.02
B12: =Enterprise Value | C12: =C9+C10-C11 -> 5552.8388 | D12: "Otros activos"/Activo | E12: =Cifras_Originales!B26/OP!E7 -> 0.45779234 | F12: =Segments!B6 -> United States | H12: =+Segments!J6 -> 0%; NA; NA | I12: Utilidad Neta | J12: =Cifras_Originales!B16 -> 107.59 | K12: FNP(p)/Activos | L12: =J18/E7 -> -0.01212143
B13: Tenencia % (nac/int'l) | C13: - | D13: Deuda/Activo | E13: =C10/E7 -> 0.60666238 | I13: UPA | J13: =1000000*J12/C8 -> 730101.36 | K13: Precio/Utilidad(p) | L13: =C9/J17 -> 50.140535 | N13: =C10/J11 -> 3.7227078
B14: t liq. (Pos prom./Vol.) | C14: 0.1 | D14: Margen de Operación (p) | E14: 0.231 | F14: =Segments!B7 -> Other Foreign Countries | H14: =+Segments!J7 -> NA; NA; NA | I14: ROA | J14: =J12/E7 -> 0.054552267 | K14: EV/Activos | L14: =C12/E7 -> 2.8155028
B15: % Short | C15: 0.0228 | D15: Margen neto (p) | E15: 0.221 | F15: =Segments!B15 -> Products (2023) | I15: ROIC | J15: =J12/(E7-(E8-C10)) -> 0.054552267 | K15: EV/Ebidta (p) | L15: =C12/J16 -> 22.445265
B16: Semáforo ESG | D16: Ebidta/Ingresos(p) | E16: =140.3/423.4 -> 0.33136514 | F16: Products aren't reported | I16: Ebidta(p) | J16: =AVERAGE(Cifras_en_Millones!B19:D19) -> 247.39467 | K16: Precio/FNP (p) | L16: =C9/J18 -> -185.78858
B17: E | D17: CIF/Deuda Neta Promedio | E17: =Cifras_Originales!B9/(Cifras_Originales!B31+Cifras_Originales!B35) -> 0.073214641 | I17: Utilidad Neta (p) | J17: =AVERAGE(Cifras_en_Millones!B23:D23) -> 88.5815 | K17: Bonos 1;5;40a (USD) | L17: 4.0%; 4.4%; 5% | N17: 12
B18: S | I18: FNP (p) | J18: =SUM(F35:F37)/3 -> -23.906333 | K18: TDY(p)/Precio | L18: =SUM(E35:E37)/(3*C9) -> -0.077174864
B19: G | I19: Tax (p) últ. 5a | J19: 0.16 | K19: Div. Yield: | L19: 0
B20: Tesis de inversión | H20: Acuerdo | I20: Supuestos de valuación | L20: DCF Value
B21: Dividend Payments: Dividend yield = 0.7% (2024). Profitability Margins: 2023 Operating margin = 22.8%; The company is now focusing on maintaining good margins and operational efficiency. Potential Growth: Investments in digital infrastructure could lead to higher enrollments and better margins in the medium-to-long term. | H21: Mantener sin elevar posición | L21: =DCFF!D66 -> 16.276883
B23: KSF | H23: PO / Precio Stand By | L23: =DCFF!D65 -> -0.45995742
B24: Strong Market Presence & Geographic Diversification, Reputation & Accreditation, Scalability & Online Education, Financial Stability & Profitability, Social Impact & ESG Commitment | H24: =L21*0.85 -> 13.835351 | I24: Tasa de descuento: | J24: =DCFF!D47 -> 0.0925
B25: Año | C25: Ingresos | D25: Margen Operativo | E25: Div.+Recompra | F25: FNP | G25: Deuda/Activo | H25: Depreciación y amortización | I25: Capex + Adq | J25: Cash Flow
B26: 2012 | C26: =Cifras_Originales!M6 -> 3567.117 | D26: =Cifras_Originales!M8/Cifras_Originales!M6 -> 0.08648693 | E26: =Cifras_Originales!M17 -> -15.561 | F26: -80.6 | I26: -457.3 | K26: 2024 | L26: 2023
B27: =B26+1 -> 2013 | C27: =Cifras_Originales!L6 -> 3913.881 | D27: =Cifras_en_Millones!M12 -> 0.090507351 | E27: =Cifras_Originales!L17 -> 0 | F27: 132.3 | H27: =Cifras_en_Millones!L17 -> 288.331 | I27: -273.9 | J27: Profit | K27: 39.2 | L27: 26 | N27: =C27/C26-1 -> 0.097211277 | O27: =D27/D26-1 -> 0.046485869
B28: =B27+1 -> 2014 | C28: =Cifras_Originales!K6 -> 4414.682 | D28: =Cifras_en_Millones!L12 -> 0.096334912 | E28: =Cifras_Originales!K17 -> -8.381 | F28: -98.3 | G28: =Cifras_en_Millones!L61 -> 0.4871592 | H28: =Cifras_en_Millones!L17 -> 288.331 | I28: -148.5 | J28: Cash Flow from Operations (BWC) | K28: 90.263 | L28: =117.987-26.87 -> 91.117 | N28: =C28/C27-1 -> 0.12795509 | O28: =D28/D27-1 -> 0.064387709 | P28: =E28/E27-1 -> #DIV/0! | Q28: =F28/F27-1 -> -1.7430083 | R28: =H28/H27-1 -> 0 | S28: =I28/I27-1 -> -0.45783133 | BT28: 4303
B29: =B28+1 -> 2015 | C29: =Cifras_Originales!J6 -> 4291.659 | D29: =Cifras_en_Millones!K12 -> 0.078514393 | E29: =Cifras_Originales!J17 -> -23.054 | F29: -2.9 | G29: =Cifras_en_Millones!K61 -> 0.51542731 | H29: =Cifras_en_Millones!K17 -> 282.946 | I29: -358.9 | J29: Working Capital | K29: -52.2 | L29: -177 | N29: =C29/C28-1 -> -0.027866786 | O29: =D29/D28-1 -> -0.18498505 | P29: =E29/E28-1 -> 1.7507457 | Q29: =F29/F28-1 -> -0.97049847 | R29: =H29/H28-1 -> -0.018676452 | S29: =I29/I28-1 -> 1.416835 | BT29: 3066
B30: =B29+1 -> 2016 | C30: =Cifras_Originales!I6 -> 4244.192 | D30: =Cifras_en_Millones!J12 -> 0.09574449 | E30: =Cifras_Originales!I17 -> -2.159 | F30: 6.3 | G30: =Cifras_en_Millones!J61 -> 0.60642797 | H30: =Cifras_en_Millones!J17 -> 264.879 | I30: -256.7 | J30: Investing Activities | K30: 30.346 | L30: 2044.192 | N30: =C30/C29-1 -> -0.011060292 | O30: =D30/D29-1 -> 0.21945145 | P30: =E30/E29-1 -> -0.90635031 | Q30: =F30/F29-1 -> -3.1724138 | R30: =H30/H29-1 -> -0.063853173 | S30: =I30/I29-1 -> -0.28475899 | BT30: 3283
B31: =B30+1 -> 2017 | C31: =Cifras_Originales!H6 -> 3385.876 | D31: =Cifras_en_Millones!I12 -> 0.10316798 | E31: -19.371 | F31: =2898.836-3038.946 -> -140.11 | G31: =Cifras_en_Millones!I61 -> 0.51612793 | H31: =Cifras_en_Millones!I17 -> 264.742 | I31: -217.6 | J31: Capex | K31: =Cifras_Originales!C13 -> 30.658 | L31: =Cifras_Originales!D13 -> 2100.376 | N31: =C31/C30-1 -> -0.20223308 | O31: =D31/D30-1 -> 0.077534418 | P31: =E32/E30-1 -> 4.1426586 | Q31: =F37/F30-1 -> -15.232698 | R31: =H37/H30-1 -> -0.73717056 | S31: =I31/I30-1 -> -0.15231788
B32: =B31+1 -> 2018 | C32: =Cifras_Originales!G6 -> 3290.213 | D32: =Cifras_en_Millones!H12 -> 0.11843306 | E32: =-11.103 -> -11.103 | F32: =485.47-867.915 -> -382.445 | G32: =Cifras_en_Millones!H61 -> 0.40228404 | H32: =Cifras_en_Millones!H17 -> 239.998 | I32: -168.2 | J32: Adquisiones | K32: 583.493 | L32: 546.795 | N32: =C32/C31-1 -> -0.028253545 | O32: =D32/D31-1 -> 0.14796333 | P32: =#REF!/E32-1 -> #REF! | Q32: =F36/F37-1 -> -1.6975665 | R32: =H36/H37-1 -> -0.15062197 | S32: =#REF!/I31-1 -> #REF!
B33: =B32+1 -> 2019 | C33: =Cifras_Originales!F6 -> 1212.07 | D33: =Cifras_en_Millones!G12 -> -0.51298522 | E33: -99.253 | F33: =1123.179-2507.79 -> -1384.611 | G33: =Cifras_en_Millones!G61 -> 0.38406349 | H33: =Cifras_en_Millones!G17 -> 193.356 | I33: -71.7 | J33: Dividends | K33: =Cifras_Originales!C17 -> 0 | L33: =Cifras_Originales!D17 -> 0 | N33: =C33/C32-1 -> -0.63161352 | O33: =D33/D32-1 -> -5.331436 | P33: =E33/#REF!-1 -> #REF! | Q33: =F33/F36-1 -> -23.136775 | R33: =H35/H36-1 -> 0.71105324 | S33: =#REF!/#REF!-1 -> #REF!
B34: =B33+1 -> 2020 | C34: =Cifras_Originales!E6 -> 1024.917 | D34: =DCFF!D7 -> 0.094481797 | E34: -264.03 | F34: =-74.624+14.538 -> -60.086 | G34: =Cifras_en_Millones!F61 -> 0.25623855 | H34: =Cifras_en_Millones!F17 -> 143.516 | I34: -40.3 | J34: Stock Repurchases | K34: -282.2 | L34: -380.5 | N34: =C34/C33-1 -> -0.15440775 | O34: =D34/D33-1 -> -1.1841803 | P34: =E34/E33-1 -> 1.6601715 | Q34: =F34/F33-1 -> -0.95660442 | R34: =H33/H35-1 -> 0.91104786 | S34: =#REF!/#REF!-1 -> #REF!
B35: =B34+1 -> 2021 | C35: =Cifras_Originales!D6 -> 1086.701 | D35: =DCFF!E7 -> 0.13237588 | E35: -380.505 | F35: =-50.444+5.843 -> -44.601 | G35: =Cifras_en_Millones!E61 -> 0.28656133 | H35: =Cifras_en_Millones!E17 -> 101.178 | I35: -45 | J35: Endeudamiento Neto | K35: 146.946 | L35: -171.131 | N35: =C35/C34-1 -> 0.060281955 | O35: =D35/D34-1 -> 0.40107283 | P35: =E35/E34-1 -> 0.44114305 | Q35: =F35/F34-1 -> -0.25771394 | R35: =H34/H33-1 -> -0.25776288 | S35: =#REF!/#REF!-1 -> #REF!
B36: =B35+1 -> 2022 | C36: =Cifras_Originales!C6 -> 1242.271 | D36: =DCFF!F7 -> 0.21807802 | E36: =-282.151-253.188 -> -535.339 | F36: =496.253-433.705 -> 62.548 | G36: =Cifras_en_Millones!D61 -> 0.2374606 | H36: =Cifras_en_Millones!D17 -> 59.132 | I36: -53.1 | J36: Otros Financiemientos | K36: 0 | L36: 0 | N36: =C36/C35-1 -> 0.14315805 | O36: =D36/D35-1 -> 0.64741509
B37: =B36+1 -> 2023 | C37: =Cifras_Originales!B6 -> 1484.288 | D37: =DCFF!G7 -> 0.23036095 | E37: -112.478 | F37: =153.772-243.438 -> -89.666 | G37: =Cifras_en_Millones!C61 -> 0.30320595 | H37: =Cifras_en_Millones!C17 -> 69.618 | I37: -56.5 | N37: =C37/C36-1 -> 0.1948182 | O37: =D37/D36-1 -> 0.056323577
B38: 2024 Est. | C38: =DCFF!H6 -> 1566.6 | D38: =DCFF!H7 -> 0.225
B39: CAGR | C39: =(C37/C32)^(1/5)-1 -> -0.14717714 | D39: =(D37/D31)^(1/6)-1 -> 0.14325731 | J39: FX | K39: 0 | L39: 0
B40: AAG | C40: =AVERAGE(N27:N37) -> -0.039273671 | D40: =AVERAGE(O32:O37) -> -0.87714025 | J40: D Cash and Equivalents | K40: =K28+K29+K30+K33+K34+K35+K36+K39 -> -66.845 | L40: =L28+L29+L30+L33+L34+L35+L36+L39 -> 1406.678
B41: CVAR | C41: =STDEV(C26:C37)/AVERAGE(C26:C37) -> 0.5127391 | D41: =STDEV(D31:D37)/AVERAGE(D31:D37) -> 4.6714488 | J41: Inv/D Vts | K41: =SUM(H33:H37)/(C37-C32) -> -0.31385578 | L41: =(SUM(H33:H37)-SUM(#REF!))/(C37-C32) -> #REF!
B42: Último Año | C42: =C37/C36-1 -> 0.1948182 | D42: =D37/D36-1 -> 0.056323577 | J42: t inversiones; t adq. neto dep. | K42: =K41/E14 -> -1.358683 | L42: =L41/E14 -> #REF!
...

Sheet COVID-19 impact
A1: https://www.apple.com/newsroom/2020/03/apples-covid-19-response/ | G1: https://glg.it/articles/how-might-the-wuhan-coronavirus-impact-apples-supply-chain/ | N1: https://www.cnbc.com/2020/02/18/the-significance-of-apples-coronavirus-warning.html
A2: March 13 | G2: January 29 | N2: Ferbuary 18
A23: Otros:
A24: https://www.macrumors.com/guide/covid-19-coronavirus/

Sheet Segments
B2: Regions (2023)
C3: 2023 | D3: =C3-1 -> 2022 | E3: Ut. Operativa | F3: % Vts | G3: Margen | H3: Crec
B4: Mexico | C4: 782 | D4: 613.9 | E4: NA | F4: 0.527 | G4: NA | H4: 0.27 | J4: =IF(C4="","",IF(F4=0,"NA",TEXT(F4,"0%"))&"; "&IF(G4=0,"NA",TEXT(G4,"0.0%"))&"; "&IF(H4=0,"NA",TEXT(H4,"0%"))) -> 53%; NA; 27%
B5: Peru | C5: 701.4 | D5: 624.2 | E5: NA | F5: 0.473 | G5: NA | H5: 0.12 | J5: =IF(C5="","",IF(F5=0,"NA",TEXT(F5,"0%"))&"; "&IF(G5=0,"NA",TEXT(G5,"0.0%"))&"; "&IF(H5=0,"NA",TEXT(H5,"0%"))) -> 47%; NA; 12%
B6: United States | C6: 0.8 | D6: 0 | E6: NA | F6: 0.001 | G6: NA | J6: =IF(C6="","",IF(F6=0,"NA",TEXT(F6,"0%"))&"; "&IF(G6=0,"NA",TEXT(G6,"0.0%"))&"; "&IF(H6=0,"NA",TEXT(H6,"0%"))) -> 0%; NA; NA
B7: Other Foreign Countries | C7: 0 | D7: 4.1 | E7: NA | F7: 0 | G7: NA | J7: =IF(C7="","",IF(F7=0,"NA",TEXT(F7,"0%"))&"; "&IF(G7=0,"NA",TEXT(G7,"0.0%"))&"; "&IF(H7=0,"NA",TEXT(H7,"0%"))) -> NA; NA; NA
J8: =IF(C8="","",IF(F8=0,"NA",TEXT(F8,"0%"))&"; "&IF(G8=0,"NA",TEXT(G8,"0.0%"))&"; "&IF(H8=0,"NA",TEXT(H8,"0%")))
J9: =IF(C9="","",IF(F9=0,"NA",TEXT(F9,"0%"))&"; "&IF(G9=0,"NA",TEXT(G9,"0.0%"))&"; "&IF(H9=0,"NA",TEXT(H9,"0%")))
J10: =IF(C10="","",IF(F10=0,"NA",TEXT(F10,"0%"))&"; "&IF(G10=0,"NA",TEXT(G10,"0.0%"))&"; "&IF(H10=0,"NA",TEXT(H10,"0%")))
J11: =IF(C11="","",IF(F11=0,"NA",TEXT(F11,"0%"))&"; "&IF(G11=0,"NA",TEXT(G11,"0.0%"))&"; "&IF(H11=0,"NA",TEXT(H11,"0%")))
J12: =IF(C12="","",IF(F12=0,"NA",TEXT(F12,"0%"))&"; "&IF(G12=0,"NA",TEXT(G12,"0.0%"))&"; "&IF(H12=0,"NA",TEXT(H12,"0%")))
J13: =IF(C13="","",IF(F13=0,"NA",TEXT(F13,"0%"))&"; "&IF(G13=0,"NA",TEXT(G13,"0.0%"))&"; "&IF(H13=0,"NA",TEXT(H13,"0%")))
B14: TOTAL | C14: =SUM(C4:C12) -> 1484.2 | D14: =SUM(D4:D12) -> 1242.2 | E14: =SUM(E4:E13) -> 0 | F14: =C14/SUM($C$4:$C$13) -> 1 | G14: =E14/C14 -> 0 | H14: =C14/D14-1 -> 0.19481565
B15: Products (2023)
B16: Produts aren't reported since 2020

Sheet Peers
A2: Multiplos (USD) | B2: LAUR | C2: STRA | D2: ATGE | E2: PRDO
B3: Laureate Education | C3: Strategic Education | D3: Adtalem Global Education | E3: Perdoceo Education Corporation
A4: Ventas | B4: =Cifras_Originales!B6 -> 1484.288 | C4: 1130 | D4: 448 | E4: 238.184
A5: Crecimiento Ult. Año fiscal | B5: 0.194 | C5: 0.063 | D5: 11.92% | E5: =710004/695208-1 -> 0.021282839
A6: Crecimiento (vs 2019) | B6: 0.225 | C6: 0.133 | D6: 12.84% | E6: =710004/627704-1 -> 0.13111275
A7: Deuda | B7: 122278 | C7: 82110 | D7: 26772 | E7: 100504
A8: Activos | B8: 323888 | C8: 301311 | D8: 319616 | E8: 321195
A9: Deuda/Activos | B9: =OP!C10/OP!E7 -> 0.60666238 | C9: =213325/2125213 -> 0.10037817 | D9: =847853/2741417 -> 0.30927546 | E9: =131537/1237034 -> 0.10633257
A10: Deuda/EBITDA | B10: =OP!C10/OP!J11 -> 3.7227078 | C10: =213325/217795 -> 0.97947611 | D10: =847853/395099 -> 2.1459255 | E10: =131537/216698 -> 0.60700606
A11: (Capex + Adq.)/Revenue | B11: =DCFF!G22/DCFF!G6 -> -0.034964912 | C11: =36943/1065480 -> 0.034672636 | D11: =50375/1687694 -> 0.02984842 | E11: =4625/710004 -> 0.0065140478
A12: ROA (p) | B12: =107.6/2125.6 -> 0.050621001 | C12: =0.06/2.161 -> 0.027764924 | D12: 0.0748 | E12: 0.0995
A13: ROIC (p) | B13: =(1+B29/(B30+B31))*B30/(B32+B33-B34) -> 0.3258084 | C13: =(1+C29/(C30+C31))*C30/(C32+C33-C34) -> 0.13550156 | D13: =(1+D29/(D30+D31))*D30/(D32+D33-D34) -> 0.18961076 | E13: =(1+E29/(E30+E31))*E30/(E32+E33-E34) -> 0.50996078
A14: Margen Operativo (p) | B14: 0.2283 | C14: 0.1212 | D14: 0.1159 | E14: 0.2119
A15: Margen Operativo | B15: 0.2174 | C15: 0.088 | D15: 0.0555 | E15: 0.1865
A16: Float | B16: =OP!L7 -> 0.91 | C16: =1-3.03% -> 0.9697 | D16: =1-3.39% -> 0.9661 | E16: =1-9.95% -> 0.9005
A17: b | B17: =OP!L9 -> 0.89 | C17: 0.58 | D17: 0.97 | E17: 1.06
A18: Precio/Utilidad | B18: 17.39 | C18: 18.12 | D18: 18.98 | E18: 11.48
A19: Precio/Ventas | B19: 1.97 | C19: 1.99 | D19: 2.39 | E19: 2.68
A20: EV/Activos | B20: =OP!C12/OP!E7 -> 2.8155028 | C20: =2410/2125 -> 1.1341176 | D20: =4310/2741 -> 1.5724188 | E20: =1280/1237 -> 1.0347615
A21: EV/Ebitda | B21: =OP!C12/OP!J11 -> 17.276981 | C21: 10.9 | D21: 11.46 | E21: 6.23
A22: Div. Yield: | B22: N/A | C22: 0.0284 | D22: N/A | E22: 0.0192
A24: *Nota: Estos múltiplos no consideran el promedio de los últimos 3 años, únicamente valores del último año reportado
A25: **Cifras en USD
A29: Taxes | B29: 108750 | C29: 52282 | D29: 48840 | E29: 53850
A30: Op. Income | B30: 361212 | C30: 172330 | D30: 329942 | E30: 212425
A31: Net financial cost
A32: Total debt | B32: 582703 | C32: 213325 | D32: 847853 | E32: 131537
A33: Total Equity | B33: 949138 | C33: 1652518 | D33: 1369135 | E33: 959536
A34: Cash and Equivalents | B34: 89392 | C34: 208209 | D34: 219306 | E34: 568925

Sheet Acuerdo
A1: Invertir
A2: NO invertir
A3: Mantener sin elevar posición
A4: Mantener (y seguir comprando)
A5: Liquidar
A6: PENDIENTE

Sheet DCF
A1: Discounted Cash Flow
A3: Ventas | E3: Margen Operativo
A16: Inversiones | E16: Utilidad Neta
D31: 0.001 | E31: =1/((1+$B$59+$D31)^(E35-2021)) -> 0.92250923 | F31: =1/((1+$B$59+$D31)^(F35-2021)) -> 0.85102327 | G31: =1/((1+$B$59+$D31)^(G35-2021)) -> 0.78507682 | H31: =1/((1+$B$59+$D31)^(H35-2021)) -> 0.72424061 | I31: =1/((1+$B$59+$D31)^(I35-2021)) -> 0.66811864 | J31: =1/((1+$B$59+$D31)^(J35-2021)) -> 0.61634561 | K31: =1/((1+$B$59+$D31)^(K35-2021)) -> 0.56858451 | L31: =1/((1+$B$59+$D31)^(L35-2021)) -> 0.52452446 | ... AC31: =1/((1+$B$59+$D31)^(AC35-2021)) -> 0.13312755
D32: 0.005 | E32: =1/((1+$B$59+$D32)^(E35-2021)) -> 0.91911765 | F32: =1/((1+$B$59+$D32)^(F35-2021)) -> 0.84477725 | G32: =1/((1+$B$59+$D32)^(G35-2021)) -> 0.77644968 | H32: =1/((1+$B$59+$D32)^(H35-2021)) -> 0.7136486 | I32: =1/((1+$B$59+$D32)^(I35-2021)) -> 0.65592702 | J32: =1/((1+$B$59+$D32)^(J35-2021)) -> 0.6028741 | K32: =1/((1+$B$59+$D32)^(K35-2021)) -> 0.55411223 | L32: =1/((1+$B$59+$D32)^(L35-2021)) -> 0.50929433 | ... AC32: =1/((1+$B$59+$D32)^(AC35-2021)) -> 0.12141647
D33: Normal | E33: =1/((1+$B$59)^(E35-2021)) -> 0.92336103 | F33: =1/((1+$B$59)^(F35-2021)) -> 0.8525956 | G33: =1/((1+$B$59)^(G35-2021)) -> 0.78725355 | H33: =1/((1+$B$59)^(H35-2021)) -> 0.72691926 | I33: =1/((1+$B$59)^(I35-2021)) -> 0.67120892 | J33: =1/((1+$B$59)^(J35-2021)) -> 0.61976816 | K33: =1/((1+$B$59)^(K35-2021)) -> 0.57226977 | L33: =1/((1+$B$59)^(L35-2021)) -> 0.5284116 | ... AC33: =1/((1+$B$59)^(AC35-2021)) -> 0.13623496
B35: 2019 (Real) | C35: 2020 (Real) | D35: 2021 | E35: =D35+1 -> 2022 | F35: =E35+1 -> 2023 | G35: =F35+1 -> 2024 | H35: =G35+1 -> 2025 | I35: =H35+1 -> 2026 | J35: =I35+1 -> 2027 | K35: =J35+1 -> 2028 | L35: =K35+1 -> 2029 | ... AC35: =AB35+1 -> 2046
A36: Crecimiento | B36: =OP!N34 -> -0.15440775 | C36: =OP!N35 -> 0.060281955 | D36: 0.35 | E36: 0.034 | F36: 0.095 | G36: 0.095 | H36: 0.095 | I36: 0.095 | J36: 0.095 | K36: 0.08 | L36: 0.06 | M36: 0.05 | N36: 0.04 | O36: 0.035 | P36: 0.035 | Q36: 0.035 | R36: 0.035 | S36: 0.035 | T36: 0.035 | U36: 0.035 | V36: 0.035 | W36: 0.035 | X36: 0.035 | Y36: 0.035 | Z36: 0.035 | AA36: 0.035 | AB36: 0.035 | AC36: 0.035
A37: Ventas | B37: =OP!C34 -> 1024.917 | C37: =OP!C35 -> 1086.701 | D37: =OP!C34*(1+D36) -> 1383.638 | E37: =D37*(1+E36) -> 1430.6816 | F37: =E37*(1+F36) -> 1566.5964 | G37: =F37*(1+G36) -> 1715.4231 | H37: =G37*(1+H36) -> 1878.3882 | I37: =H37*(1+I36) -> 2056.8351 | J37: =I37*(1+J36) -> 2252.2345 | K37: =J37*(1+K36) -> 2432.4132 | L37: =K37*(1+L36) -> 2578.358 | ... AC37: =AB37*(1+AC36) -> 4717.0568
A38: Margen Operativo | B38: =+OP!D34 -> 0.094481797 | C38: =+OP!D35 -> 0.13237588 | D38: =108166.4/365513.2 -> 0.29593022 | E38: =108162.8/377959.8 -> 0.28617541 | F38: 0.27 | G38: 0.275 | H38: 0.26 | I38: 0.255 | J38: 0.25 | K38: 0.25 | L38: 0.25 | M38: 0.25 | N38: 0.25 | O38: 0.25 | P38: 0.25 | Q38: 0.25 | R38: 0.25 | S38: 0.25 | T38: 0.25 | U38: 0.25 | V38: 0.25 | W38: 0.25 | X38: 0.25 | Y38: 0.25 | Z38: 0.25 | AA38: 0.25 | AB38: 0.25 | AC38: 0.25
A39: EBIT | B39: 63930 | C39: 66288 | D39: =D37*D38 -> 409.46028 | E39: =E37*E38 -> 409.4259 | F39: =F37*F38 -> 422.98103 | G39: =G37*G38 -> 471.74134 | H39: =H37*H38 -> 488.38094 | I39: =I37*I38 -> 524.49296 | J39: =J37*J38 -> 563.05862 | K39: =K37*K38 -> 608.10331 | ... AC39: =AC37*AC38 -> 1179.2642
A40: Dep&Amort | B40: =OP!H33 -> 193.356 | C40: =OP!H34 -> 143.516 | D40: 11000 | E40: =D40*(1+E36*$H$59) -> 11374 | F40: =E40*(1+F36*$H$59) -> 12454.53 | G40: =F40*(1+G36*$H$59) -> 13637.71 | H40: =G40*(1+H36*$H$59) -> 14933.293 | I40: =H40*(1+I36*$I$59) -> 16351.956 | J40: =I40*(1+J36*$I$59) -> 17905.391 | K40: =J40*(1+K36*$I$59) -> 19337.823 | L40: =K40*(1+L36*$I$59) -> 20498.092 | M40: =L40*(1+M36*$I$59) -> 21522.997 | N40: =M40*(1+N36*$I$59) -> 22383.917 | O40: =N40*(1+O36*$I$59) -> 23167.354 | P40: =O40*(1+P36*$I$59) -> 23978.211 | ... AC40: =AB40*(1+AC36*$I$59) -> 37500.868
A41: EBIDTA | B41: =+B39+B40 -> 64123.356 | C41: =+C39+C40 -> 66431.516 | D41: =D39+D40 -> 11409.46 | E41: =E39+E40 -> 11783.426 | F41: =F39+F40 -> 12877.511 | G41: =G39+G40 -> 14109.452 | H41: =H39+H40 -> 15421.674 | I41: =I39+I40 -> 16876.449 | J41: =J39+J40 -> 18468.45 | K41: =K39+K40 -> 19945.926 | ... AC41: =AC39+AC40 -> 38680.133
A42: CIF | B42: -1385 | C42: -890 | D42: =(C48)*$H$60 -> -1124.36 | E42: =(D48)*$H$60 -> -1113.1164 | F42: =(E48)*$H$60 -> -1113.1164 | G42: =(F48)*$H$60 -> -1113.1164 | H42: =(G48)*$H$60 -> -1113.1164 | I42: =(H48)*$H$60 -> -1113.1164 | J42: =(I48)*$H$60 -> -1113.1164 | K42: =(J48)*$H$60 -> -1113.1164 | ... AC42: =(AB48)*$H$60 -> -1113.1164
A43: Otros Gastos | B43: =-422-2817 -> -3239 | C43: =87-3634 -> -3547 | D43: =-C43*(1+D36) -> 4788.45 | E43: =D43*(1+E36*0.5) -> 4869.8537 | F43: =E43*(1+F36*0.5) -> 5101.1717 | G43: =F43*(1+G36*0.5) -> 5343.4774 | H43: =G43*(1+H36*0.5) -> 5597.2925 | I43: =H43*(1+I36*0.5) -> 5863.1639 | J43: =I43*(1+J36*0.5) -> 6141.6642 | K43: =J43*(1+K36*0.5) -> 6387.3308 | L43: =K43*(1+L36*0.5) -> 6578.9507 | ... AC43: =AB43*(1+AC36*0.5) -> 8922.7133
A44: Utilidad antes de Impuestos | B44: =B39-B42-B43 -> 68554 | C44: =C39-C42-C43 -> 70725 | D44: =D39-D42-D43 -> -3254.6297 | E44: =E39-E42-E43 -> -3347.3113 | F44: =F39-F42-F43 -> -3565.0743 | G44: =G39-G42-G43 -> -3758.6196 | H44: =H39-H42-H43 -> -3995.7952 | I44: =I39-I42-I43 -> -4225.5546 | ... AC44: =AC39-AC42-AC43 -> -6630.3327
A45: ISR & PTU | B45: 10481 | C45: 9680 | D45: =$H$61*D44 -> -683.47224 | E45: =$H$61*E44 -> -702.93538 | F45: =$H$61*F44 -> -748.6656 | G45: =$I$61*G44 -> -864.48251 | H45: =$I$61*H44 -> -919.03289 | I45: =$I$61*I44 -> -971.87755 | J45: =$I$61*J44 -> -1027.0625 | K45: =$I$61*K44 -> -1073.2055 | L45: =$I$61*L44 -> -1108.8863 | M45: =$I$61*M44 -> -1139.3025 | N45: =$I$61*N44 -> -1164.0955 | ... AC45: =$I$61*AC44 -> -1524.9765
A46: Utilidad Neta | B46: =B44-B45 -> 58073 | C46: =C44-C45 -> 61045 | D46: =D44-D45 -> -2571.1575 | E46: =E44-E45 -> -2644.376 | F46: =F44-F45 -> -2816.4087 | G46: =G44-G45 -> -2894.1371 | H46: =H44-H45 -> -3076.7623 | I46: =I44-I45 -> -3253.677 | ... AC46: =AC44-AC45 -> -5105.3562
A47: Inversiones y Capex | B47: =OP!#REF! -> #REF! | C47: =OP!#REF! -> #REF! | D47: 10000 | E47: =D47*(1+E36*$H$62) -> 10408 | F47: =E47*(1+F36*$H$62) -> 11594.512 | G47: =F47*(1+G36*$H$62) -> 12916.286 | H47: =G47*(1+H36*$H$62) -> 14388.743 | I47: =H47*(1+I36*$H$62) -> 16029.06 | J47: =I47*(1+J36*$H$62) -> 17856.373 | K47: =J47*(1+K36*$H$62) -> 19570.584 | L47: =K47*(1+L36*$H$62) -> 20979.666 | ... AC47: =AB47*(1+AC36*$H$62) -> 43199.777
A48: Deuda + Lease Liabilities | B48: 108047 | C48: 112436 | D48: =C48*0.99 -> 111311.64 | E48: =D48 -> 111311.64 | F48: =E48 -> 111311.64 | G48: =F48 -> 111311.64 | H48: =G48 -> 111311.64 | I48: =H48 -> 111311.64 | J48: =I48 -> 111311.64 | K48: =J48 -> 111311.64 | L48: =K48 -> 111311.64 | ... AC48: =AB48 -> 111311.64
A49: Deuda/EBITDA | B49: =B48/B41 -> 1.6849867 | C49: =C48/C41 -> 1.6925099 | D49: =D48/D41 -> 9.7560829 | E49: =E48/E41 -> 9.4464582
A50: FNP | B50: =OP!F34 -> -60.086 | C50: =OP!F35 -> -44.601 | D50: =D41-D42-D43-D45-D47+D48-C48 -> -2695.5175 | E50: =E41-E42-E43-E45-E47+E48-D48 -> -1678.376 | F50: =F41-F42-F43-F45-F47+F48-E48 -> -1956.3907 | G50: =G41-G42-G43-G45-G47+G48-F48 -> -2172.7131 | H50: =H41-H42-H43-H45-H47+H48-G48 -> -2532.2125 | I50: =I41-I42-I43-I45-I47+I48-H48 -> -2930.7811 | J50: =J41-J42-J43-J45-J47+J48-I48 -> -3389.4078 | K50: =K41-K42-K43-K45-K47+K48-J48 -> -3825.6671 | ... AC50: =AC41-AC42-AC43-AC45-AC47+AC48-AB48 -> -10804.265
A51: F(t) | B51: 0 | C51: 0 | D51: =C51*(1+$B$59)+D50 -> -2695.5175 | E51: =D51*(1+$B$59)+E50 -> -4597.6214 | F51: =E51*(1+$B$59)+F50 -> -6935.6146 | G51: =F51*(1+$B$59)+G50 -> -9683.9838 | H51: =G51*(1+$B$59)+H50 -> -13019.967 | I51: =H51*(1+$B$59)+I50 -> -17031.405 | J51: =I51*(1+$B$59)+J50 -> -21834.42 | K51: =J51*(1+$B$59)+K50 -> -27472.344 | ... AC51: =AB51*(1+$B$59)+AC50 -> -359621.23
AB52: =AB51-AB48 -> -433395.64 | AC52: =AC50/(B59-AC36) -> -225088.86
A53: EPS | C53: =1000000*C46/OP!$C$8 -> 4.1424889e+08 | D53: =1000000*D46/OP!$C$8 -> -17447770 | E53: =1000000*E46/OP!$C$8 -> -17944628 | F53: =1000000*F46/OP!$C$8 -> -19112035
A54: Consenso EPS | C54: 3.3 | D54: 5.6 | E54: 5.6
A55: E$/UN | D55: =$B$61/D46 -> 34.890361 | E55: =$B$61/E46 -> 33.924303 | F55: =$B$61/F46 -> 31.852129
A56: EEV/EBIDA | D56: =($B$61+D48-D51)/D41 -> 2.1296841 | E56: =($B$61+E48-E51)/E41 -> 2.2235172 | F56: =($B$61+F48-F51)/F41 -> 2.2161614
C58: "TELP" | D58: CER | E58: D Analista | H58: CP | I58: LP
A59: Tasa de descuento: | B59: =SUM(C59:E59) -> 0.083 | C59: 0.0307 | D59: 0.0523 | E59: 0 | G59: Factor D&A | H59: 1 | I59: 1
G60: Factor CIF | H60: -0.01
A61: VPN*@i% | B61: =C62+C63 -> -89708.612 | C61: Normal | D61: =D31 -> 0.001 | E61: =D32 -> 0.005 | G61: Factor ISR | H61: 0.21 | I61: 0.23
A62: DCF 25Y | B62: =C62/B61 -> 0.65817136 | C62: =AB52/(1+B59)^25 -> -59043.639 | D62: =SUMPRODUCT(E50:AB50,E31:AB31) -> -44326.249 | E62: =SUMPRODUCT(E50:AB50,E32:AB32) -> -42404.098 | G62: Factor inv | H62: 1.2
A63: Perpetuidad | B63: =1-B62 -> 0.34182864 | C63: =AC52/(1+B59)^25 -> -30664.973 | D63: =(AC50/($B$59+D31-$AC$36))*AC31 -> -29353.987 | E63: =(AC50/($B$59+D32-$AC$36))*AC32 -> -24751.241 | G63: Suma D&A | H63: =SUM(40:40) -> 628766.44
A64: VPN/Acción | B64: =1000000*B61/OP!C8 -> -6.0875899e+08 | D64: =1000000*SUM(D62:D63)/OP!C8 -> -4.9999108e+08 | E64: =1000000*SUM(E62:E63)/OP!C8 -> -4.557134e+08 | G64: Suma Inv. | H64: =SUM(47:47) -> #REF!
B65: =B64/OP!C7-1 -> -20197711 | D65: =D64/B64-1 -> -0.17867154 | E65: =E64/B64-1 -> -0.25140588 | G65: Inv.+Goodwill | H65: =SUM(47:47)+(OP!E12*OP!E7) -> #REF!
A67: Duración | B67: =B62*D68+B63*D69 -> 21.007164 | E67: 1 | F67: 2 | G67: 3 | H67: 4 | I67: 5 | J67: 6 | K67: 7 | L67: 8 | M67: 9 | N67: 10 | O67: 11 | P67: 12 | Q67: 13 | R67: 14 | S67: 15 | T67: 16 | U67: 17 | V67: 18 | W67: 19 | X67: 20 | Y67: 21 | Z67: 22 | AA67: 23 | AB67: 24 | AC67: 25
A68: 0.001 | B68: =-$B$67*A68 -> -0.021007164 | D68: =SUM(E68:AB68)/SUMPRODUCT(E50:AB50,E33:AB33) -> 12.156716 | E68: =E67*E50*E33 -> -1549.747 | F68: =F67*F50*F33 -> -3336.0202 | G68: =G67*G50*G33 -> -5131.4284 | H68: =H67*H50*H33 -> -7362.856 | I68: =I67*I50*I33 -> -9835.832 | J68: =J67*J50*J33 -> -12603.882 | K68: =K67*K50*K33 -> -15325.195 | L68: =L67*L50*L33 -> -17728.982 | ... AC68: =AC67*AC50*AC33 -> -36797.967
A69: 0.005 | B69: =-$B$67*A69 -> -0.10503582 | D69: =(1+B59)/B59+AC67 -> 38.048193

Sheet DCFF
C1: VALUATION MODEL
D3: =D19/D6 -> 0.012974709 | E3: =E19/E6 -> 0.0093604405 | F3: =F19/F6 -> 0.0070644811 | G3: 0 | H3: 0.25 | I3: =H3+1 -> 1.25 | J3: =I3+1 -> 2.25 | K3: =J3+1 -> 3.25 | L3: =K3+1 -> 4.25 | M3: =L3+1 -> 5.25 | N3: =M3+1 -> 6.25 | O3: =N3+1 -> 7.25 | P3: =O3+1 -> 8.25 | ... AF3: =AE3+1 -> 24.25
A4: Section | B4: Line # | C4: ITEM | D4: 2020 (Real) | E4: 2021 (Real) | F4: 2022 (Real) | G4: 2023 (Real) | H4: 2024 | I4: =+H4+1 -> 2025 | J4: =+I4+1 -> 2026 | K4: =+J4+1 -> 2027 | L4: =+K4+1 -> 2028 | M4: =+L4+1 -> 2029 | N4: =+M4+1 -> 2030 | O4: =+N4+1 -> 2031 | P4: =+O4+1 -> 2032 | ... AF4: =+AE4+1 -> 2048 | AG4: Notes
A5: INCOME STATEMENT | B5: 1 | C5: Growth | D5: =Cifras_en_Millones!F6 -> -0.15440775 | E5: =Cifras_en_Millones!E6 -> 0.060281955 | F5: =Cifras_en_Millones!D6 -> 0.14315805 | G5: =Cifras_en_Millones!C6 -> 0.1948182 | H5: =H6/G6-1 -> 0.055455545 | I5: =I6/H6-1 -> 0.056896128 | J5: =J6/I6-1 -> 0.055742409 | K5: =K6/J6-1 -> 0.054479126 | L5: =L6/K6-1 -> 0.055439618 | M5: =M6/L6-1 -> 0.053592005 | N5: =N6/M6-1 -> 0.05179442 | O5: =O6/N6-1 -> 0.050048725 | ... AE5: =AE6/AD6-1 -> 0.024183497 | AF5: 0.02
B6: 2 | C6: Revenues/Sales | D6: =Cifras_en_Millones!F5 -> 1024.917 | E6: =Cifras_en_Millones!E5 -> 1086.701 | F6: =Cifras_en_Millones!D5 -> 1242.271 | G6: =Cifras_en_Millones!C5 -> 1484.288 | H6: =I82 -> 1566.6 | I6: =J82 -> 1655.7335 | J6: =K82 -> 1748.028 | K6: =L82 -> 1843.2591 | L6: =M82 -> 1945.4487 | M6: =N82 -> 2049.7092 | N6: =O82 -> 2155.8727 | O6: =P82 -> 2263.7713 | ... AF6: =AG82 -> 4029.1541
B7: 3 | C7: EBIT/Operating Margin | D7: =Cifras_en_Millones!F11/Cifras_en_Millones!F5 -> 0.094481797 | E7: =Cifras_en_Millones!E11/Cifras_en_Millones!E5 -> 0.13237588 | F7: =Cifras_en_Millones!D11/Cifras_en_Millones!D5 -> 0.21807802 | G7: =Cifras_en_Millones!C11/Cifras_en_Millones!C5 -> 0.23036095 | H7: 0.225 | I7: =H7*0.995 -> 0.223875 | J7: =I7*0.995 -> 0.22275562 | K7: =J7*0.995 -> 0.22164185 | L7: =K7*0.995 -> 0.22053364 | M7: 0.23 | N7: =23%*0.995 -> 0.22885 | O7: =N7*0.995 -> 0.22770575 | P7: =O7*0.995 -> 0.22656722 | Q7: =P7*0.995 -> 0.22543439 | R7: =Q7*0.995 -> 0.22430721 | S7: =R7*0.995 -> 0.22318568 | T7: 0.21 | U7: =T7*0.95 -> 0.1995 | V7: 0.21 | W7: 0.21 | X7: 0.21 | Y7: 0.21 | Z7: 0.21 | AA7: 0.21 | AB7: 0.21 | AC7: 0.21 | AD7: 0.21 | AE7: 0.21 | AF7: 0.21
B8: 4 | C8: EBIT | D8: =D6*D7 -> 96.836 | E8: =E6*E7 -> 143.853 | F8: =F6*F7 -> 270.912 | G8: =G7*G6 -> 341.922 | H8: =H7*H6 -> 352.485 | I8: =I7*I6 -> 370.67733 | J8: =J7*J6 -> 389.38308 | K8: =K7*K6 -> 408.54335 | L8: =L7*L6 -> 429.03687 | M8: =M7*M6 -> 471.43311 | N8: =N7*N6 -> 493.37146 | ... AF8: =AF7*AF6 -> 846.12236
B9: 5a | C9: (Dep&Amort) | D9: =-Cifras_en_Millones!F17 -> -143.516 | E9: =-Cifras_en_Millones!E17 -> -101.178 | F9: =-Cifras_en_Millones!D17 -> -59.132 | G9: =-Cifras_en_Millones!C17 -> -69.618 | H9: {=G9*0.7+0.3*(-$D$50*AVERAGE(-1*(D22:G22)))} -> -40.689357 | I9: {=H9*0.7+0.3*(-$D$50*AVERAGE(-1*(E22:H22)))} -> -22.621126 | J9: {=I9*0.7+0.3*(-$D$50*AVERAGE(-1*(F22:I22)))} -> -16.671868 | K9: {=J9*0.7+0.3*(-$D$50*AVERAGE(-1*(G22:J22)))} -> -13.018888 | L9: {=K9*0.7+0.3*(-$D$50*AVERAGE(-1*(H22:K22)))} -> -10.748491 | M9: {=L9*0.7+0.3*(-$D$50*AVERAGE(-1*(I22:L22)))} -> -9.1334093 | N9: {=M9*0.7+0.3*(-$D$50*AVERAGE(-1*(J22:M22)))} -> -7.9744238 | O9: {=N9*0.7+0.3*(-$D$50*AVERAGE(-1*(K22:N22)))} -> -7.1316644 | ... AF9: {=AE9*0.7+0.3*(-$D$50*AVERAGE(-1*(AB22:AE22)))} -> -8.5455291
B10: 5b | C10: (Stock based compensation) | D10: =-D19 -> -13.298 | E10: =-E19 -> -10.172 | F10: =-F19 -> -8.776 | G10: =-G19 -> -7.114 | H10: =-$D$51*H6 -> -6.0742571 | I10: =-$D$51*I6 -> -6.4198588 | J10: =-$D$51*J6 -> -6.7777172 | K10: =-$D$51*K6 -> -7.1469613 | L10: =-$E$51*L6 -> -19.454487 | M10: =-$E$51*M6 -> -20.497092 | N10: =-$E$51*N6 -> -21.558727 | O10: =-$E$51*O6 -> -22.637713 | P10: =-$E$51*P6 -> -23.732388 | Q10: =-$E$51*Q6 -> -24.841112 | R10: =-$E$51*R6 -> -25.962286 | S10: =-$E$51*S6 -> -27.094353 | ... AF10: =-$E$51*AF6 -> -40.291541
B11: 6 | C11: EBIDTA | D11: =-D9+D8 -> 240.352 | E11: =-E9+E8 -> 245.031 | F11: =-F9+F8 -> 330.044 | G11: =-G9+G8 -> 411.54 | H11: =-H9+H8 -> 393.17436 | I11: =-I9+I8 -> 393.29846 | J11: =-J9+J8 -> 406.05495 | K11: =-K9+K8 -> 421.56224 | ... AF11: =-AF9+AF8 -> 854.66789
B12: 7 | C12: (Net financing cost) | D12: =-Cifras_en_Millones!F14 -> -85.225 | E12: =-Cifras_en_Millones!E14 -> -28.097 | F12: =-Cifras_en_Millones!D14 -> -26.251 | G12: =-Cifras_en_Millones!C14 -> -87.6 | H12: =-$D$53*G37+G36*$D$54 -> -13.68147 | I12: =-$D$53*H37+H36*$D$54 -> -11.487073 | J12: =-$D$53*I37+I36*$D$54 -> -11.108987 | K12: =-$D$53*J37+J36*$D$54 -> -10.277606 | L12: =-$D$53*K37+K36*$D$54 -> -9.3424863 | M12: =-$D$53*L37+L36*$D$54 -> -8.2742336 | N12: =-$D$53*M37+M36*$D$54 -> -6.3449658 | O12: =-$E$53*N37+N36*E54 -> -25.55263 | P12: =-$E$53*O37+O36*$E$54 -> -25.57044 | Q12: =-$E$53*P37+P36*$E$54 -> -25.58527 | R12: =-$E$53*Q37+Q36*$E$54 -> -25.596895 | S12: =-$E$53*R37+R36*$E$54 -> -25.60354 | T12: =-$E$53*S37+S36*$E$54 -> -25.603904 | U12: =-$E$53*T37+T36*$E$54 -> -23.354713 | V12: =-$E$53*U37+U36*$E$54 -> -23.010608 | W12: =-$E$53*V37+V36*$E$54 -> -23.367026 | ... AF12: =-$E$53*AE37+AE36*$E$54 -> -23.831081
B13: 8 | C13: Other income/(cost) | D13: =Cifras_en_Millones!F15 -> 755 | E13: =Cifras_en_Millones!E15 -> -222.3 | F13: =Cifras_en_Millones!D15 -> -9.5 | G13: =Cifras_en_Millones!C15 -> 8.9 | H13: =-0.03*H6 -> -46.998 | I13: =-0.03*I6 -> -49.672004 | J13: =-0.03*J6 -> -52.440841 | K13: =-0.03*K6 -> -55.297773 | L13: =-0.03*L6 -> -58.36346 | M13: =-0.03*M6 -> -61.491275 | N13: =-0.03*N6 -> -64.67618 | O13: =-0.03*O6 -> -67.91314 | ... AF13: =-0.03*AF6 -> -120.87462
B14: 9 | C14: Earnings before taxes | D14: =D8+D12-13 -> -1.389 | E14: =E8+E12-E13 -> 338.056 | F14: =F8+F12-F13 -> 254.161 | G14: =G8+G12-G13 -> 245.422 | H14: =H8+H12+H13 -> 291.80553 | I14: =I8+I12+I13 -> 309.51825 | J14: =J8+J12+J13 -> 325.83325 | K14: =K8+K12+K13 -> 342.96797 | L14: =L8+L12+L13 -> 361.33093 | M14: =M8+M12+M13 -> 401.6676 | N14: =N8+N12+N13 -> 422.35031 | O14: =O8+O12+O13 -> 422.00798 | ... AF14: =AF8+AF12+AF13 -> 701.41666
B15: 10 | C15: (Income tax) | D15: =-Cifras_en_Millones!F21 -> 130.1 | E15: =-Cifras_en_Millones!E21 -> -145.6 | F15: =-Cifras_en_Millones!D21 -> -184.591 | G15: =-Cifras_en_Millones!C21 -> -137.803 | H15: =(-1*$D$52)*H14 -> -87.541659 | I15: =(-1*$D$52)*I14 -> -92.855476 | J15: =(-1*$D$52)*J14 -> -97.749975 | K15: =(-1*$D$52)*K14 -> -102.89039 | L15: =(-1*$E$52)*L14 -> -108.39928 | M15: =(-1*$E$52)*M14 -> -120.50028 | N15: =(-1*$E$52)*N14 -> -126.70509 | O15: =(-1*$E$52)*O14 -> -126.60239 | P15: =(-1*$E$52)*P14 -> -132.27915 | Q15: =(-1*$E$52)*Q14 -> -137.96864 | R15: =(-1*$E$52)*R14 -> -143.66071 | S15: =(-1*$E$52)*S14 -> -149.34617 | ... AF15: =(-1*$E$52)*AF14 -> -210.425
B16: 11 | C16: Net income | D16: =D14+D15 -> 128.711 | E16: =E14+E15 -> 192.456 | F16: =F14+F15 -> 69.57 | G16: =G14+G15 -> 107.619 | H16: =H14+H15 -> 204.26387 | I16: =I14+I15 -> 216.66278 | J16: =J14+J15 -> 228.08328 | K16: =K14+K15 -> 240.07758 | ... AF16: =AF14+AF15 -> 490.99166
A18: CASH FLOW STATEMENT | B18: 12 | C18: Operating cash flows before WK | D18: =259.6-D19-D20 -> 309.584 | E18: =-156.1-E19-E20 -> -285.575 | F18: =178.2-F19-F20 -> -8.592 | G18: =250.78-G20-G19 -> 285.604 | H18: =H11+H12+H13+H15 -> 244.95323 | I18: =I11+I12+I13+I15 -> 239.2839 | J18: =J11+J12+J13+J15 -> 244.75514 | K18: =K11+K12+K13+K15 -> 253.09647 | L18: =L11+L12+L13+L15 -> 263.68014 | M18: =M11+M12+M13+M15 -> 290.30073 | N18: =N11+N12+N13+N15 -> 303.61964 | O18: =O11+O12+O13+O15 -> 302.53725 | ... AF18: =AF11+AF12+AF13+AF15 -> 499.53719
B19: 13 | C19: (Stock-based compensation) | D19: 13.298 | E19: 10.172 | F19: 8.776 | G19: 7.114 | H19: =$D$55*H10 -> -0.023552023 | I19: =$D$55*I10 -> -0.024892042 | J19: =$D$55*J10 -> -0.026279585 | K19: =$D$55*K10 -> -0.027711273 | L19: =$D$55*L10 -> -0.075431861 | M19: =$D$55*M10 -> -0.079474406 | N19: =$D$55*N10 -> -0.083590737 | O19: =$D$55*O10 -> -0.087774347 | ... AF19: =$D$55*AF10 -> -0.15622442
B20: 14 | C20: (Working Capital Flows) | D20: =Cifras_Originales!E12-Cifras_Originales!F12 -> -63.282 | E20: =Cifras_Originales!D12-Cifras_Originales!E12 -> 119.303 | F20: =Cifras_Originales!C12-Cifras_Originales!D12 -> 178.016 | G20: =Cifras_Originales!B12-Cifras_Originales!C12 -> -41.938 | H20: =$D$56*(H6-G6) -> 49.3872 | I20: =$D$56*(I6-H6) -> 53.480084 | J20: =$D$56*(J6-I6) -> 55.376744 | K20: =$D$56*(K6-J6) -> 57.138625 | L20: =$E$56*(L6-K6) -> 30.656874 | M20: =$E$56*(M6-L6) -> 31.278148 | N20: =$E$56*(N6-M6) -> 31.849049 | O20: =$E$56*(O6-N6) -> 32.369603 | P20: =$E$56*(P6-O6) -> 32.840235 | Q20: =$E$56*(Q6-P6) -> 33.261732 | R20: =$E$56*(R6-Q6) -> 33.635198 | S20: =$E$56*(S6-R6) -> 33.962019 | ... AF20: =$E$56*(AF6-AE6) -> 29.220599
B21: 15 | C21: -Total Operating Cash Flow | D21: =D18+D19+D20 -> 259.6 | E21: =E18+E19+E20 -> -156.1 | F21: =F18+F19+F20 -> 178.2 | G21: =G18+G19+G20 -> 250.78 | H21: =H18+H19+H20 -> 294.31688 | I21: =I18+I19+I20 -> 292.7391 | J21: =J18+J19+J20 -> 300.10561 | K21: =K18+K19+K20 -> 310.20738 | ... AF21: =AF18+AF19+AF20 -> 528.60156
B22: 16 | C22: (CAPEX and Acquisitions) | D22: =Cifras_Originales!E13 -> 601.945 | E22: =Cifras_Originales!D13 -> 2100.376 | F22: =Cifras_Originales!C13 -> 30.658 | G22: =Cifras_Originales!B13 -> -51.898 | H22: =-$D$57*H6 -> -125.328 | I22: =-$D$57*I6 -> -132.45868 | J22: =-$D$57*J6 -> -139.84224 | K22: =-$D$57*K6 -> -147.46073 | L22: =-$E$57*L6 -> -116.72692 | M22: =-$E$57*M6 -> -122.98255 | N22: =-$E$57*N6 -> -129.35236 | O22: =-$E$57*O6 -> -135.82628 | P22: =-$E$57*P6 -> -142.39433 | Q22: =-$E$57*Q6 -> -149.04667 | R22: =-$E$57*R6 -> -155.77371 | S22: =-$E$57*S6 -> -162.56612 | ... AF22: =-$E$57*AF6 -> -241.74925
B23: 17 | C23: (Other investing flows) | D23: =587.4-D22 -> -14.545 | E23: =2044.2-E22 -> -56.176 | F23: =30.3-F22 -> -0.358 | G23: =-51.9-G22 -> -0.002 | H23: 0 | I23: 0 | J23: 0 | K23: 0 | L23: 0 | M23: 0 | N23: 0 | O23: 0 | P23: 0 | Q23: 0 | R23: 0 | S23: 0 | T23: 0 | U23: 0 | V23: 0 | W23: 0 | X23: 0 | Y23: 0 | Z23: 0 | AA23: 0 | AB23: 0 | AC23: 0 | AD23: 0 | AE23: 0 | AF23: 0
B24: 18 | C24: -Total Investing Flows | D24: =D22+D23 -> 587.4 | E24: =E22+E23 -> 2044.2 | F24: =F22+F23 -> 30.3 | G24: =G22+G23 -> -51.9 | H24: =H22+H23 -> -125.328 | I24: =I22+I23 -> -132.45868 | J24: =J22+J23 -> -139.84224 | K24: =K22+K23 -> -147.46073 | ... AF24: =AF22+AF23 -> -241.74925
B25: 19 | C25: (Flows related to leases) | H25: 0 | I25: 0 | J25: 0 | K25: 0 | L25: 0 | M25: 0 | N25: 0 | O25: 0 | P25: 0 | Q25: 0 | R25: 0 | S25: 0 | T25: 0 | U25: 0 | V25: 0 | W25: 0 | X25: 0 | Y25: 0 | Z25: 0 | AA25: 0 | AB25: 0 | AC25: 0 | AD25: 0 | AE25: 0 | AF25: 0
B26: 20 | C26: Flows related to debt | D26: =528.382-705.353-0.779 -> -177.75 | E26: =46.493-942.03-32.98 -> -928.517 | F26: =496.253-433.705 -> 62.548 | G26: =153.772-243.438-1.306 -> -90.972 | H26: =(H37-G37) -> 109.71984 | I26: =(I37-H37) -> 0.22338071 | J26: =(J37-I37) -> 22.961684 | K26: =(K37-J37) -> 27.91312 | L26: =(L37-K37) -> 32.801626 | M26: =(M37-L37) -> 73.406078 | N26: =(N37-M37) -> -163.13549 | O26: =(O37-N37) -> 29.763345 | ... AF26: =(AF37-AE37) -> 22.760061
B27: 21 | C27: (Respurchases)/Issuance of stock | D27: -99.523 | E27: -380.505 | F27: -282.151 | G27: 0 | H27: =(H21+H24+H28)*-1 -> -166.98888 | I27: =(I21+I24+I28)*-0.95 -> -141.97492 | J27: =(J21+J24+J28)*-0.95 -> -141.41624 | K27: =(K21+K24+K28)*-0.95 -> -143.20564 | L27: =(L21+L24+L28)*-0.95 -> -156.64367 | M27: =(M21+M24+M28)*-0.95 -> -175.23556 | N27: =(N21+N24+N28)*-0.95 -> -181.68796 | O27: =(O21+O24+O28)*-0.95 -> -132.9161 | P27: =(P21+P24+P28)*-0.95 -> -136.59272 | ... AF27: =(AF21+AF24+AF28)*-0.95 -> -85.932871
B28: 22 | C28: (Dividends) | D28: 0 | E28: 0 | F28: 0 | G28: 0 | H28: -2 | I28: =0.05*I16*(-1) -> -10.833139 | J28: =0.05*J16*(-1) -> -11.404164 | K28: =0.05*K16*(-1) -> -12.003879 | L28: =0.05*L16*(-1) -> -12.646582 | M28: =0.05*M16*(-1) -> -14.058366 | N28: =0.05*N16*(-1) -> -14.782261 | O28: =0.2*O16*(-1) -> -59.081117 | P28: =0.2*P16*(-1) -> -61.730272 | Q28: =0.2*Q16*(-1) -> -64.385367 | R28: =0.2*R16*(-1) -> -67.041666 | S28: =0.2*S16*(-1) -> -69.694877 | T28: =0.2*T16*(-1) -> -67.467998 | U28: =0.2*U16*(-1) -> -66.175182 | V28: =0.3*V16*(-1) -> -109.70654 | W28: =0.3*W16*(-1) -> -113.42776 | X28: =0.3*X16*(-1) -> -117.51653 | Y28: =0.4*Y16*(-1) -> -162.01318 | Z28: =0.4*Z16*(-1) -> -167.19625 | AA28: =0.4*AA16*(-1) -> -172.26438 | AB28: =0.4*AB16*(-1) -> -177.22281 | AC28: =0.4*AC16*(-1) -> -182.07734 | AD28: =0.4*AD16*(-1) -> -186.83411 | AE28: =0.4*AE16*(-1) -> -191.49947 | AF28: =0.4*AF16*(-1) -> -196.39666
B29: 23 | C29: Other financing flows | D29: =-77.5-D25-D26-D27-D28 -> 199.773 | E29: =-2698-E25-E26-E27-E28 -> -1388.978 | F29: =-460.4-F25-F26-F27-F28 -> -240.797 | G29: =-195.7-G25-G26-G27-G28 -> -104.728 | H29: 0 | I29: 0 | J29: 0 | K29: 0 | L29: 0 | M29: 0 | N29: 0 | O29: 0 | P29: 0 | Q29: 0 | R29: 0 | S29: 0 | T29: 0 | U29: 0 | V29: 0 | W29: 0 | X29: 0 | Y29: 0 | Z29: 0 | AA29: 0 | AB29: 0 | AC29: 0 | AD29: 0 | AE29: 0 | AF29: 0
B30: 24 | C30: -Total Financing flows | D30: =SUM(D25:D29) -> -77.5 | E30: =SUM(E25:E29) -> -2698 | F30: =SUM(F25:F29) -> -460.4 | G30: =SUM(G25:G29) -> -195.7 | H30: =SUM(H25:H29) -> -59.269033 | I30: =SUM(I25:I29) -> -152.58467 | J30: =SUM(J25:J29) -> -129.85872 | K30: =SUM(K25:K29) -> -127.2964 | ... AF30: =SUM(AF25:AF29) -> -259.56947
A32: SUMMARY | B32: 25 | C32: Cash before shareholder returns | D32: =D21+D24+D25+D26+D29 -> 869.023 | E32: =E21+E24+E25+E26+E29 -> -429.395 | F32: =F21+F24+F25+F26+F29 -> 30.251 | G32: =G21+G24+G25+G26+G29 -> 3.18 | H32: =H21+H24+H25+H26+H29 -> 278.70872 | I32: =I21+I24+I25+I26+I29 -> 160.5038 | J32: =J21+J24+J25+J26+J29 -> 183.22505 | K32: =K21+K24+K25+K26+K29 -> 190.65977 | ... AF32: =AF21+AF24+AF25+AF26+AF29 -> 309.61238
B33: 26 | C33: Returns to shareholders | D33: =-1*(D27+D28) -> 99.523 | E33: =-1*(E27+E28) -> 380.505 | F33: =-1*(F27+F28) -> 282.151 | G33: =-1*(G27+G28) -> 0 | H33: =-1*(H27+H28) -> 168.98888 | I33: =-1*(I27+I28) -> 152.80805 | J33: =-1*(J27+J28) -> 152.8204 | K33: =-1*(K27+K28) -> 155.20952 | ... AF33: =-1*(AF27+AF28) -> 282.32954
B34: 27 | C34: Excess cash acumulation | D34: =D32-D33 -> 769.5 | E34: =E32-E33 -> -809.9 | F34: =F32-F33 -> -251.9 | G34: =G32-G33 -> 3.18 | H34: =H32-H33 -> 109.71984 | I34: =I32-I33 -> 7.6957447 | J34: =J32-J33 -> 30.404644 | K34: =K32-K33 -> 35.450258 | ... AF34: =AF32-AF33 -> 27.282844
A36: CASH & DEBT & DISCOUNTING | B36: 28 | C36: Ending cash balance | D36: =Cifras_Originales!E22 -> 61.576 | E36: =Cifras_Originales!D22 -> 750.147 | F36: =Cifras_Originales!C22 -> 324.801 | G36: =Cifras_Originales!B22 -> 85.167 | H36: =G36+H34 -> 194.88684 | I36: =H36+I34 -> 202.58259 | J36: =I36+J34 -> 232.98723 | K36: =J36+K34 -> 268.43749 | L36: =K36+L34 -> 309.48352 | M36: =L36+M34 -> 392.11252 | N36: =M36+N34 -> 238.53955 | O36: =N36+O34 -> 275.29848 | ... AF36: =AE36+AF34 -> 578.2241
B37: 29 | C37: Total Debt | D37: =Cifras_en_Millones!F60 -> 1664.634 | E37: =Cifras_en_Millones!E60 -> 1424.466 | F37: =Cifras_en_Millones!D60 -> 525.099 | G37: =Cifras_en_Millones!C60 -> 597.994 | H37: =$D$219*H11 -> 707.71384 | I37: =$D$219*I11 -> 707.93722 | J37: =$D$219*J11 -> 730.89891 | K37: =$D$219*K11 -> 758.81203 | L37: =$D$219*L11 -> 791.61365 | M37: =$D$219*M11 -> 865.01973 | N37: =$E$219*N11 -> 701.88424 | O37: =$E$219*O11 -> 731.64758 | P37: =$E$219*P11 -> 761.88693 | Q37: =$E$219*Q11 -> 792.61075 | R37: =$E$219*R11 -> 823.65523 | S37: =$E$219*S11 -> 854.89171 | T37: =$F$219*T11 -> 657.8932 | U37: =$F$219*U11 -> 648.91654 | V37: =$F$219*V11 -> 706.84115 | W37: =$F$219*W11 -> 730.24884 | X37: =$F$219*X11 -> 755.47547 | Y37: =$F$219*Y11 -> 780.14201 | Z37: =$F$219*Z11 -> 804.2605 | AA37: =$F$219*AA11 -> 827.84894 | ... AF37: =$F$219*AF11 -> 940.13468
B38: 30 | C38: Discount factor | G38: =1/((1+$D$47)^G3) -> 1 | H38: =1/((1+$D$47)^H3) -> 0.97812563 | I38: =1/((1+$D$47)^I3) -> 0.8953095 | J38: =1/((1+$D$47)^J3) -> 0.81950526 | K38: =1/((1+$D$47)^K3) -> 0.75011923 | L38: =1/((1+$D$47)^L3) -> 0.68660799 | M38: =1/((1+$D$47)^M3) -> 0.62847414 | N38: =1/((1+$D$47)^N3) -> 0.57526237 | ... AF38: =1/((1+$D$47)^AF3) -> 0.11702535
F39: =1/((1+$D$48+0.001)^F$3) -> 0.99999294 | G39: =1/((1+$D$47+0.001)^G$3) -> 1 | H39: =1/((1+$D$47+0.001)^H$3) -> 0.97790193 | I39: =1/((1+$D$47+0.001)^I$3) -> 0.89428617 | J39: =1/((1+$D$47+0.001)^J$3) -> 0.81782 | K39: =1/((1+$D$47+0.001)^K$3) -> 0.74789209 | L39: =1/((1+$D$47+0.001)^L$3) -> 0.68394339 | M39: =1/((1+$D$47+0.001)^M$3) -> 0.62546263 | N39: =1/((1+$D$47+0.001)^N$3) -> 0.57198229 | ... AE39: =1/((1+$D$47+0.001)^AE$3) -> 0.12515932
F40: =1/((1+$D$48+0.005)^F$3) -> 0.99996477 | G40: =1/((1+$D$47+0.005)^G$3) -> 1 | H40: =1/((1+$D$47+0.005)^H$3) -> 0.97700968 | I40: =1/((1+$D$47+0.005)^I$3) -> 0.89021383 | J40: =1/((1+$D$47+0.005)^J$3) -> 0.81112878 | K40: =1/((1+$D$47+0.005)^K$3) -> 0.7390695 | L40: =1/((1+$D$47+0.005)^L$3) -> 0.67341185 | M40: =1/((1+$D$47+0.005)^M$3) -> 0.6135871 | N40: =1/((1+$D$47+0.005)^N$3) -> 0.55907709 | ... AE40: =1/((1+$D$47+0.005)^AE$3) -> 0.11497269
C42: EPS | H42: =H16/OP!C8 -> 1.3861263 | I42: =I16/OP!$C8 -> 1.4702648 | J42: =J16/OP!$C8 -> 1.5477638
C43: Consenso EPS
C44: E$/UN | H44: =$D$64/H16 -> 11.742713 | I44: =$D$64/I16 -> 11.070716
A46: Discount rate | D46: Total | E46: Risk free rate | F46: Equity premium | G46: Firm premium
...

Sheet ESG
B2: Análisis ESG | J2: PARÁMETROS
C3: Impacto | D3: ¿Reporta? | E3: Ranking | F3: Mitigación | G3: Semáforo | H3: Comentarios | J3: IMPACTO | L3: RANKING | M3: MITIGACIÓN
B4: Ambiental | J4: NONE | K4: 0 | L4: "Best in class" | M4: Is there evidence of progam/plan/etc…
B5: Emisiones directas CO2 | C5: Low | D5: Yes | E5: Medium High | F5: Yes | H5: Despite implementing mitigation strategies for the category, the company does not publicly report specific data: To minimize greenhouse gas emissions, UPN has implemented initiatives including waste segregation stations, LED lighting, eco-efficient faucets and urinals, renewable energy sources, parking spaces for sustainable mobility, and the use of solar energy and drip irrigation. | J5: LOW | K5: 1 | L5: Medium high
B6: Uso total de agua | C6: Low | D6: Yes | E6: Medium High | F6: Yes | H6: To further reduce water consumption, Laureate Education has implemented water catchment systems in covered parking lots, allowing for the collection of rainwater, as well as low-flow taps across its campuses | J6: MEDIUM | K6: 2 | L6: Medium
B7: Total Energy Consumption | C7: Medium | D7: Yes | E7: Medium High | F7: Yes | H7: Laureate Education is actively addressing energy consumption by integrating energy-efficient practices across its campuses. Key initiatives include replacing fluorescent and luminescent lights with LED lights, and the implementation of solar systems | J7: HIGH | K7: 3 | L7: "Villain"
B8: Waste Management | C8: Low | D8: Yes | E8: Best in class | F8: Yes | H8: Organic waste is treated through composting, contributing to a circular approach that minimizes waste and enhances sustainability on campus
B9: Land Degradation/Deforestation/Biodiversity loss/Animal sufering/… | C9: Low | D9: No | F9: No | H9: The company promotes biodiversity through audits of campus flora and fauna, as well as the establishment of pollinator and hydroponic gardens | J9: TRAFFIC LIGHTS
B10: Social
B11: % Rotación de empleados | C11: Medium | D11: No | F11: Yes
B12: Sueldos y compensaciones | C12: Medium | D12: No | E12: Medium | F12: Yes
B13: Temas de reputación | C13: Medium | D13: No | F13: Yes | H13: Laureate previously scaled back operations in various regions (e.g., divesting universities in the U.S. and other countries), which raised concerns about long-term commitments to students and communities.
B14: Temas de discriminación | C14: Low | D14: Yes | E14: Best in class | F14: Yes | H14: The report highlights Laureate’s Silver-Level Certification for Labor Equality and Non-Discrimination awarded to UNITEC
B15: Seguridad laboral | C15: Low | D15: No | E15: Best in class | F15: Yes
B16: Daños a la salud | C16: Low | D16: No | E16: Best in class | F16: Yes
B17: PXP?
B18: Supply chain | C18: Medium | D18: No | F18: Yes | H18: No specific details are provided in the report
B19: Community involvement | C19: Low | D19: Yes | E19: Best in class | F19: Yes | H19: Strongly emphasized with over 1.05 million volunteer hours dedicated to social initiatives, making this a high-impact area.
B20: Public Sector | C20: Medium | D20: No | F20: Yes | H20: While the company engages with the public sector through educational and healthcare programs, clearer reporting on government collaborations and regulatory compliance would enhance stakeholder confidence
B21: Litigios | C21: Low | D21: No | F21: Yes | H21: No major legal disputes were mentioned
B22: Gobierno
B23: Diversidad (Género, edad, industria, región) | C23: Low | D23: Yes | E23: Medium High | F23: Yes | H23: The company has made notable progress in gender diversity, with women comprising 47% of employees, 52% of students, and 29% of senior leadership—an increase from the previous year. Additionally, the presence of international teams across multiple countries suggests an emphasis on cultural diversity - Laureate has received notable recognition for its diversity and inclusion efforts—such as UNITEC’s Silver-Level Certification for Labor Equality and Non-Discrimination
B24: % independientes
B25: tiempo promedio como consejeros independientes
B26: Salidas recientes de consejeros/C-level executives?
B27: CEO/Chairman
B28: Transparencia (segmentos, fuente de riqueza, adquisiciones, otros)
B29: Tiempo que tardan en reportar luego del final del trimestre/año
B30: Participación adicional del CEO en otros consejos o excesiva del Ch.
B31: Auditoría/Consultoría | D31: Yes | H31: The audit of Laureate Education is overseen by an independent auditor
B32: Esquemas de compensación al management | D32: Yes | H32: The Compensation Committee, among other things, monitors and assesses the Company’s compensation programs and policies. In consultation with its independent compensation consultant and with management regarding such matters

Sheet Cifras_en_Millones
A1: =Cifras_Originales!G3 -> #VALUE!
A2: =Cifras_Originales!C2 -> Cifras en Millones de USD
A4: Resultados | B4: 2024 | C4: =Cifras_Originales!B5 -> 2023 | D4: =Cifras_Originales!C5 -> 2022 | E4: =Cifras_Originales!D5 -> 2021 | F4: =Cifras_Originales!E5 -> 2020 | G4: =Cifras_Originales!F5 -> 2019 | H4: =Cifras_Originales!G5 -> 2018 | I4: =Cifras_Originales!H5 -> 2017 | J4: =Cifras_Originales!I5 -> 2016 | ... M4: =Cifras_Originales!L5 -> 2013
A5: Ventas Netas | C5: =Cifras_Originales!B6 -> 1484.288 | D5: =Cifras_Originales!C6 -> 1242.271 | E5: =Cifras_Originales!D6 -> 1086.701 | F5: =Cifras_Originales!E6 -> 1024.917 | G5: =Cifras_Originales!F6 -> 1212.07 | H5: =Cifras_Originales!G6 -> 3290.213 | I5: =Cifras_Originales!H6 -> 3385.876 | J5: =Cifras_Originales!I6 -> 4244.192 | ... M5: =Cifras_Originales!L6 -> 3913.881
A6: Crecimiento vs. Año pasado | B6: =B5/C5-1 -> -1 | C6: =C5/D5-1 -> 0.1948182 | D6: =D5/E5-1 -> 0.14315805 | E6: =E5/F5-1 -> 0.060281955 | F6: =F5/G5-1 -> -0.15440775 | G6: =G5/H5-1 -> -0.63161352 | H6: =H5/I5-1 -> -0.028253545 | I6: =I5/J5-1 -> -0.20223308 | ... L6: =L5/M5-1 -> 0.12795509
A7: Utilidad Bruta | C7: =Cifras_Originales!B7 -> 394.507 | D7: =Cifras_Originales!C7 -> 334.906 | E7: =Cifras_Originales!D7 -> 272.211 | F7: =Cifras_Originales!E7 -> 222.459 | G7: =Cifras_Originales!F7 -> 262.599 | H7: =Cifras_Originales!G7 -> 593.164 | I7: =Cifras_Originales!H7 -> 564.585 | J7: =Cifras_Originales!I7 -> 628.854 | ... M7: =Cifras_Originales!L7 -> 495.432
A8: porcentaje sobre ventas | B8: =B7/B5 -> #DIV/0! | C8: =C7/C5 -> 0.26578871 | D8: =D7/D5 -> 0.26959174 | E8: =E7/E5 -> 0.25049301 | F8: =F7/F5 -> 0.21705075 | G8: =G7/G5 -> 0.21665333 | H8: =H7/H5 -> 0.18028134 | I8: =I7/I5 -> 0.1667471 | ... M8: =M7/M5 -> 0.12658331
A9: Gastos de Operación | B9: =B5-B11 -> 0 | C9: =C5-C11 -> 1142.366 | D9: =D5-D11 -> 971.359 | E9: =E5-E11 -> 942.848 | F9: =F5-F11 -> 928.081 | G9: =G5-G11 -> 1833.844 | H9: =H5-H11 -> 2900.543 | I9: =I5-I11 -> 3036.562 | ... M9: =M5-M11 -> 3559.646
A10: porcentaje sobre ventas | B10: =B9/B5 -> #DIV/0! | C10: =C9/C5 -> 0.76963905 | D10: =D9/D5 -> 0.78192198 | E10: =E9/E5 -> 0.86762412 | F10: =F9/F5 -> 0.9055182 | G10: =G9/G5 -> 1.5129852 | H10: =H9/H5 -> 0.88156694 | I10: =I9/I5 -> 0.89683202 | ... M10: =M9/M5 -> 0.90949265
A11: Utilidad de Operación | C11: =Cifras_Originales!B8 -> 341.922 | D11: =Cifras_Originales!C8 -> 270.912 | E11: =Cifras_Originales!D8 -> 143.853 | F11: =Cifras_Originales!E8 -> 96.836 | G11: =Cifras_Originales!F8 -> -621.774 | H11: =Cifras_Originales!G8 -> 389.67 | I11: =Cifras_Originales!H8 -> 349.314 | J11: =Cifras_Originales!I8 -> 406.358 | ... M11: =Cifras_Originales!L8 -> 354.235
A12: porcentaje sobre ventas | B12: =B11/B5 -> #DIV/0! | C12: =C11/C5 -> 0.23036095 | D12: =D11/D5 -> 0.21807802 | E12: =E11/E5 -> 0.13237588 | F12: =F11/F5 -> 0.094481797 | G12: =G11/G5 -> -0.51298522 | H12: =H11/H5 -> 0.11843306 | I12: =I11/I5 -> 0.10316798 | ... M12: =M11/M5 -> 0.090507351
A13: Crecimiento vs año anterior | B13: =B11/C11-1 -> -1 | C13: =C11/D11-1 -> 0.26211464 | D13: =D11/E11-1 -> 0.88325582 | E13: =E11/F11-1 -> 0.48553224 | F13: =F11/G11-1 -> -1.1557415 | G13: =G11/H11-1 -> -2.5956425 | H13: =H11/I11-1 -> 0.11552929 | I13: =I11/J11-1 -> -0.14037868 | ... L13: =L11/M11-1 -> 0.20058153
A14: CIF (Productos Financieros) | C14: =Cifras_Originales!B9 -> 87.6 | D14: =Cifras_Originales!C9 -> 26.251 | E14: =Cifras_Originales!D9 -> 28.097 | F14: =Cifras_Originales!E9 -> 85.225 | G14: =Cifras_Originales!F9 -> 129.848 | H14: =Cifras_Originales!G9 -> 255.958 | I14: =Cifras_Originales!H9 -> 320.536 | J14: =Cifras_Originales!I9 -> 335.766 | ... M14: =Cifras_Originales!L9 -> 331.491
A15: Otros Gastos (Productos) | C15: =Cifras_Originales!B10 -> 8.9 | D15: =Cifras_Originales!C10 -> -9.5 | E15: =Cifras_Originales!D10 -> -222.3 | F15: =Cifras_Originales!E10 -> 755 | G15: =Cifras_Originales!F10 -> -1721.1 | H15: =Cifras_Originales!G10 -> -368.1 | I15: =Cifras_Originales!H10 -> 28.6 | J15: =Cifras_Originales!I10 -> -366.3 | ... M15: =Cifras_Originales!L10 -> 15.7
A16: Utilidad antes de Impuestos y partidas extra. | B16: =B11-B14-B15 -> 0 | C16: =C11-C14-C15 -> 245.422 | D16: =D11-D14-D15 -> 254.161 | E16: =E11-E14-E15 -> 338.056 | F16: =F11-F14-F15 -> -743.389 | G16: =G11-G14-G15 -> 969.478 | H16: =H11-H14-H15 -> 501.812 | I16: =I11-I14-I15 -> 0.178 | ... M16: =M11-M14-M15 -> 7.044
A17: Depreciación y amortización del ejercicio | C17: =Cifras_Originales!B11 -> 69.618 | D17: =Cifras_Originales!C11 -> 59.132 | E17: =Cifras_Originales!D11 -> 101.178 | F17: =Cifras_Originales!E11 -> 143.516 | G17: =Cifras_Originales!F11 -> 193.356 | H17: =Cifras_Originales!G11 -> 239.998 | I17: =Cifras_Originales!H11 -> 264.742 | J17: =Cifras_Originales!I11 -> 264.879 | ... M17: =Cifras_Originales!L11 -> 0
A18: Capital de Trabajo | C18: =Cifras_Originales!B12 -> -43.796 | D18: =Cifras_Originales!C12 -> -1.858 | E18: =Cifras_Originales!D12 -> -179.874 | F18: =Cifras_Originales!E12 -> -299.177 | G18: =Cifras_Originales!F12 -> -235.895 | H18: =Cifras_Originales!G12 -> -81.3 | I18: =Cifras_Originales!H12 -> -230.488 | J18: =Cifras_Originales!I12 -> -172.047 | ... M18: =Cifras_Originales!L12 -> -119.06
A19: EBITDA (flujo operativo) | B19: =B11-B15+B17 -> 0 | C19: =C11-C15+C17 -> 402.64 | D19: =D11-D15+D17 -> 339.544 | E19: =E11-E15+E17 -> 467.331 | F19: =F11-F15+F17 -> -514.648 | G19: =G11-G15+G17 -> 1292.682 | H19: =H11-H15+H17 -> 997.768 | I19: =I11-I15+I17 -> 585.456 | ... M19: =M11-M15+M17 -> 338.535
A20: porcentaje sobre ventas | B20: =B19/B5 -> #DIV/0! | C20: =C19/C5 -> 0.27126811 | D20: =D19/D5 -> 0.27332522 | E20: =E19/E5 -> 0.43004562 | F20: =F19/F5 -> -0.50213627 | G20: =G19/G5 -> 1.0665077 | H20: =H19/H5 -> 0.30325332 | I20: =I19/I5 -> 0.17291123 | ... M20: =M19/M5 -> 0.086495987
A21: I.S.R Y P.T.U. | C21: =Cifras_Originales!B15 -> 137.803 | D21: =Cifras_Originales!C15 -> 184.591 | E21: =Cifras_Originales!D15 -> 145.6 | F21: =Cifras_Originales!E15 -> -130.1 | G21: =Cifras_Originales!F15 -> 31.041 | H21: =Cifras_Originales!G15 -> 131.771 | I21: =Cifras_Originales!H15 -> -91.308 | J21: =Cifras_Originales!I15 -> 65.001 | ... M21: =Cifras_Originales!L15 -> 76.746
A22: % Tax | B22: =+B21/B16 -> #DIV/0! | C22: =+C21/C16 -> 0.56149408 | D22: =+D21/D16 -> 0.72627586 | E22: =+E21/E16 -> 0.43069787 | F22: =+F21/F16 -> 0.17500932 | G22: =+G21/G16 -> 0.032018261 | H22: =+H21/H16 -> 0.26259037 | I22: =+I21/I16 -> -512.96629 | ... M22: =+M21/M16 -> 10.89523
A23: Utilidad Neta | C23: =Cifras_Originales!B16 -> 107.59 | D23: =Cifras_Originales!C16 -> 69.573 | E23: =Cifras_Originales!D16 -> 192.446 | F23: =Cifras_Originales!E16 -> -613.331 | G23: =Cifras_Originales!F16 -> 938.484 | H23: =Cifras_Originales!G16 -> 370.067 | I23: =Cifras_Originales!H16 -> 91.465 | J23: =Cifras_Originales!I16 -> 371.847 | ... M23: =Cifras_Originales!L16 -> -69.7
A24: porcentaje sobre ventas | B24: =B23/B5 -> #DIV/0! | C24: =C23/C5 -> 0.072485933 | D24: =D23/D5 -> 0.056004688 | E24: =E23/E5 -> 0.17709195 | F24: =F23/F5 -> -0.59842016 | G24: =G23/G5 -> 0.77428201 | H24: =H23/H5 -> 0.11247509 | I24: =I23/I5 -> 0.027013689 | ... M24: =M23/M5 -> -0.017808411
A25: Crecimiento vs año anterior | B25: =B23/C23-1 -> -1 | C25: =C23/D23-1 -> 0.54643324 | D25: =D23/E23-1 -> -0.6384804 | E25: =E23/F23-1 -> -1.3137718 | F25: =F23/G23-1 -> -1.6535338 | G25: =G23/H23-1 -> 1.535984 | H25: =H23/I23-1 -> 3.0459957 | I25: =I23/J23-1 -> -0.75402518 | ... L25: =L23/M23-1 -> 1.271033
A26: Efectivo Generado | B26: =B40-C40 -> -85.167 | C26: =C40-D40 -> -239.634 | D26: =D40-E40 -> -425.346 | E26: =E40-F40 -> 688.571 | F26: =F40-G40 -> -326.914 | G26: =G40-H40 -> 67.923 | H26: =H40-I40 -> -144.398 | I26: =I40-J40 -> 6.292 | ... M26: =M40-N40 -> 0
A27: Dividendos | C27: =Cifras_Originales!B17 -> 0 | D27: =Cifras_Originales!C17 -> 0 | E27: =Cifras_Originales!D17 -> 0 | F27: =Cifras_Originales!E17 -> 0 | G27: =Cifras_Originales!F17 -> 0 | H27: =Cifras_Originales!G17 -> -11.103 | I27: =Cifras_Originales!H17 -> -19.371 | J27: =Cifras_Originales!I17 -> -2.159 | ... M27: =Cifras_Originales!L17 -> 0
B28: =B27/C27-1 -> #DIV/0! | C28: =C27/D27-1 -> #DIV/0! | D28: =D27/E27-1 -> #DIV/0! | E28: =E27/F27-1 -> #DIV/0! | F28: =F27/G27-1 -> #DIV/0! | G28: =G27/H27-1 -> -1 | H28: =H27/I27-1 -> -0.4268236 | I28: =I27/J27-1 -> 7.9722094 | ... L28: =L27/M27-1 -> #DIV/0!
A29: Recompra de Acciones | C29: =Cifras_Originales!B18 -> -112.478 | D29: =Cifras_Originales!C18 -> -535.339 | E29: =Cifras_Originales!D18 -> -380.505 | F29: =Cifras_Originales!E18 -> -264.03 | G29: =Cifras_Originales!F18 -> -99.253 | H29: =Cifras_Originales!G18 -> 0 | I29: =Cifras_Originales!H18 -> 0 | J29: =Cifras_Originales!I18 -> 0 | ... M29: =Cifras_Originales!L18 -> 0
