Workbook
Name Área_de_Impressão: Cifras_en_Millones!$A$1:$M$88
Name Benchmark: [1]ControlsH!$B$3
Name BestConsOv: #REF!
Name Broker_Name: OFFSET(#REF!,0,0,[1]ControlsH!$E$5, 1)
Name calCODE: [1]ControlsH!$C$4
Name Chart_Benchmark_100_Size: OFFSET(#REF!, 0, 0, [1]ControlsH!$E$3, 1)
Name Chart_Date_Size: OFFSET(#REF!, 0, 0, [1]ControlsH!$E$3, 1)
Name Chart_Date_VAL1_Size: OFFSET(#REF!, 0, 0, [1]ControlsH!$I$3, 1)
Name Chart_Date_VAL2_Size: OFFSET(#REF!, 0, 0, [1]ControlsH!$I$5, 1)
Name Chart_Peer_100_Size: OFFSET(#REF!, 0, 0, [1]ControlsH!$E$3, 1)
Name Chart_Price_100_Size: OFFSET(#REF!, 0, 0, [1]ControlsH!$E$3, 1)
Name Chart_Price_Size: OFFSET(#REF!, 0, 0, [1]ControlsH!$E$3, 1)
Name Chart_VAL1_FY1_Size: OFFSET(#REF!, 0, 0, [1]ControlsH!$F$3, 1)
Name Chart_VAL1_FY2_Size: OFFSET(#REF!, 0, 0, [1]ControlsH!$G$3, 1)
Name Chart_VAL1_FY3_Size: OFFSET(#REF!, 0, 0, [1]ControlsH!$H$3, 1)
Name Chart_VAL2_FY1_Size: OFFSET(#REF!, 0, 0, [1]ControlsH!$F$5, 1)
Name Chart_VAL2_FY2_Size: OFFSET(#REF!, 0, 0, [1]ControlsH!$G$5, 1)
Name Chart_VAL2_FY3_Size: OFFSET(#REF!, 0, 0, [1]ControlsH!$H$5, 1)
Name Chart_Volume_Size: OFFSET(#REF!, 0, 0, [1]ControlsH!$E$3, 1)
Name compNAME: [1]ControlsH!$B$6
Name CURRENCY: [1]ControlsH!$B$9
Name currPRICE: [1]Overview!$E$19
Name custBenchmark: [1]Overview!$C$9
Name custED: #REF!
Name custSD: #REF!
Name dayCODE: [1]ControlsH!$C$5
Name ED: [1]ControlsH!$B$5
Name ESTBrokersItem: #REF!
Name ESTBrokersPeriod: #REF!
Name ESTDetailBroker: #REF!
Name ESTDetailBroker2: #REF!
Name ESTDetailPeriod: #REF!
Name EstDetPerO: #REF!
Name EstDetPerT: #REF!
Name FinancialsPeriod: #REF!
Name fundTICKER: [1]ControlsH!$B$15
Name GraphValRatio1: #REF!
Name GraphValRatio2: #REF!
Name Index1: #REF!
Name Lang: [1]Overview!$D$11
Name newCrncy: [1]ControlsH!$B$21:$B$199
Name newEstBrokerPeriod: #REF!
Name newEstBrokersItem: #REF!
Name newEstDetailBroker: #REF!
Name newEstDetailBroker2: #REF!
Name newEstDetailPeriod: #REF!
Name newFinancialsPeriod: #REF!
Name newOverviewCon: #REF!
Name newOverviewYear: #REF!
Name newOwners: #REF!
Name newPeersRatio: #REF!
Name newPeriod: #REF!
Name newValRatio1: #REF!
Name newValRatio2: #REF!
Name OverviewValRatioPeriod: [1]Overview!$D$30
Name PeerDate1: [1]Peers!$S$11
Name peerHist1: #REF!
Name PeerIndex: [1]ControlsH!$F$35:$F$36
Name Peers: OFFSET([1]Peers!$C$18,0,0,MAX(COUNTA([1]Peers!$C$18:$C$47),1),1)
Name peersWEIGHT: [1]ControlsH!$B$13

Sheet OP
B2: 45761 | C2: Analista: Research | D2: Report (quarter): 26/02/2025 | E2: #VALUE! | K2: NASDAQ | L2: SIC: Sí
B3: #VALUE! | D3: {=_FV(E2,"Description")} -> Magnite, Inc. is an independent sell-side advertising company. The Company provides technology solutions to automate the purchase and sale of digital advertising inventory. Its platform features applications and services for sellers of digital advertising inventory, or publishers, that own and operate connected television (CTV) channels, applications, websites and other digital media properties, to manage and monetize their inventory; applications and services for buyers, including advertisers, agencies, agency trading desks, and demand side platforms, (DSPs), to buy digital advertising inventory; and a transparent, independent marketplace that brings buyers and sellers together and facilitates intelligent decision making and automated transaction execution at scale. The Company's streaming sell-side advertising platform (SSP) and ad server offers CTV sellers a holistic solution for workflow, yield management and monetization, across both programmatic and direct-sold video inventory.
D4: CEO & BOARD:. | Michael G. Barret, 62, CEO since 2017 , President from March (except April to June 2022), previous jobs (PJ): President of Ichabod Farm Ventures LLC (Jan 2014 - Dec 2015). CEO of Millennial Media (Jul 2012 - Dec 2012). Global Chief Revenue Officer at Yahoo! Inc. (Jan 2012 - Jul 2012). Director at Google Inc. (Nov 2008 - Dec 2011). CEO of AdMeld. Held senior positions at AOL, Fox Interactive, and Disney Online. Board member of Media Math (Jan 2013 - Apr 2020). | Paul Caine, 59, Chairman since 2020, PJ: President of IMG Events (Aug 2022 - present) and On Location (Jan 2020 - present). Non-executive Chairman of Telaria (Jan 2020 - Apr 2020). CEO and Founder of PC Ventures (Aug 2017 - present). Chief Global Revenue Officer at Bloomberg Media (Jun 2014 - Jul 2016). CEO of WestwoodOne (Apr 2013 - Jan 2014).Executive roles at Time Inc. (1989-2013), including EVP, Chief Revenue Officer, and Group President. | Directors: Sarah Harden, 52, Board member since Jul 2019, PJ: Executive roles at Otter Media/The Chernin Group (2013-2018), including President and EVP. Board member of ESPN-Star Sports, Star China Media, and The Moby Group. MBA from Harvard Business School. | Doug Knopper, 63, Board member since Apr 2020 , PJ: Co-Founder of FreeWheel Media, Inc. and Co-CEO (Feb 2007 - Sept 2017). CEO of BitPass Inc. (2005-2007). Senior VP at DoubleClick Inc. (2000-2005). Board member of Telaria (Oct 2018 - Apr 2020). BA from the University of Michigan, MBA from Georgetown University. | Rachel Lam, 57, PJ: Founder of Imagination Capital. Head of Time Warner Investments (2003-2017), leading investments in over 50 companies. Board member for several companies, including Magnite (NASDAQ: MGNI) and Porch Group (NASDAQ: PRCH). Former officer at Quetzal/Chase Capital Partners and CSFB Equity Partners. B.S. from UC Berkeley, MBA from Harvard Business School. Recognized by Gold House’s A100 List (2018) and BoardProspects (2024) . | David Pearson, 58, Board member since Mar 2022. PJ: CFO of Vonage Holdings Corp. (May 2013 - Aug 2020). Managing Director at Deutsche Bank Securities (2003-2012). Managing Director at Goldman Sachs & Co. (1993-2003). Board member of Lee Enterprises Inc. (Feb 2020 - present) and Potbelly Corporation (Apr 2022 - present). MBA from Harvard Business School, AB from Brown University. | James RosSMAN, 58, Board member since Apr 2020. PJ: Operating Partner at Silver Lake (present). Special Advisor at General Atlantic (Nov 2012 - Apr 2018). President & COO at AKQA Inc. (2009-2012). Chief Operating Officer at Digitas Inc. (2001-2009). BA in Economics from Trinity College, MBA from Kellogg School of Management. | Robert F. Spillane, 73, Board member since Apr 2014. Previous Roles: Managing Principal at DigaComm, LLC (1998-2017). CEO of Donnelley Marketing, Inc. (1991-1998). Senior VP of CBS, including for CBS Magazines (1985-1987). Early positions at Chesebrough Ponds Inc. (1972-1977). Expertise in publishing, advertising, and M&A. | Diane Yu, 50, Board member since Mar 2022. Current Role: Co-Founder and CEO of TidalWave Tech Inc. PJ: CTO of Better Holdco, Inc. (Jan 2021 - Apr 2022). Co-Founder and CTO of FreeWheel Media (2007-2014), later CTO of Comcast’s Advanced Advertising Division. VP of Engineering at DoubleClick (2005-2007). BA from Peking University, Master's in Mathematics from Ohio University.
B5: Millones de USD
B6: Acción | D6: Liquidez y Solvencia | F6: =Segments!B2 -> Regions (2023) | I6: Rentabilidad (2022) | K6: Múltiplos
B7: Último Precio | C7: {=_FV(E2,"Price")} -> 9.68 | D7: Activo: | E7: =Cifras_en_Millones!C45 -> 2689 | H7: %Vts; %Op.Mg.; D | I7: Año termina: | J7: 44926 | K7: Float: | L7: =138160000/C8 -> 0.96648231
B8: Outstanding Shares | C8: {=_FV(E2,"Shares outstanding",TRUE)} -> 142951400 | D8: Pasivo: | E8: =Cifras_en_Millones!C57 -> 1987 | F8: =Segments!B4 -> United States | H8: =+Segments!J4 -> 75%; N/A; 1% | K8: Insiders Own: | L8: 0.0233
B9: Market Cap. | C9: =C8*C7/1000000 -> 1383.7696 | D9: Cash/Precio | E9: =1000000*C11/C8 -> 2.2804953 | F9: =Segments!B5 -> Other Internationals | H9: =+Segments!J5 -> 25%; N/A; 1% | I9: EBIT | J9: =Cifras_Originales!D8 -> -112 | K9: b (Bloomberg; Yahoo) | L9: 2.52
B10: +Deuda Total | C10: =Cifras_Originales!D32+Cifras_Originales!D36 -> 726.3 | D10: Ebidta/CIF | E10: =Cifras_en_Millones!C19/Cifras_en_Millones!C14 -> 13.389167 | I10: +Dep&Amort | J10: =Cifras_Originales!D11 -> -216.1 | K10: Calificación (S&P) | L10: BB-
B11: -Cash | C11: =Cifras_Originales!D22 -> 326 | D11: Deuda/Ebidta | E11: =OP!C10/Cifras_en_Millones!C19 -> -1.6742391 | I11: =EBIDTA | J11: =J9+J10 -> -328.1 | K11: Precio/Valor en libros | L11: =((C7*C8)/1000000)/(E7-E8) -> 1.9711817
B12: =Enterprise Value | C12: =C9+C10-C11 -> 1784.0696 | D12: "Otros activos"/Activo | E12: =Cifras_en_Millones!C44/Cifras_en_Millones!C45 -> 0.42380067 | I12: Utilidad Neta | J12: =Cifras_Originales!D16 -> -130 | K12: FNP(p)/Activos | L12: =J18/E7 -> 0.025784059
B13: Tenencia % (nac/int'l) | C13: =L8/C8 -> 1.6299246e-10 | D13: Deuda/Activo | E13: =C10/E7 -> 0.27010041 | F13: =Segments!B15 -> Products (2023) | I13: UPA | J13: =1000000*J12/C7 -> -13429752 | K13: Precio/Utilidad(p) | L13: =C9/J17 -> -15.593878 | N13: =C10/J11 -> -2.2136544
B14: t liq. (Pos prom./Vol.) | C14: =C11-C10 -> -400.3 | D14: Margen de Operación (p) | E14: =AVERAGE(Cifras_en_Millones!C11/Cifras_en_Millones!C5,Cifras_en_Millones!D11/Cifras_en_Millones!D5,Cifras_en_Millones!E11/Cifras_en_Millones!E5) -> -0.20571283 | H14: %Vts; D | I14: ROA | J14: =J12/E7 -> -0.04834511 | K14: EV/Activos | L14: =C12/E7 -> 0.66346952
B15: % Short | C15: 0.0757 | D15: Margen neto (p) | E15: =AVERAGE(Cifras_en_Millones!C23/C37,Cifras_en_Millones!E23/C35) -> -0.1282185 | F15: =Segments!B17 -> Desktop | H15: =+Segments!J17 -> 17%; N/A; 1% | I15: ROIC | J15: =J12/(E7-(E8-C10)) -> -0.091017293 | K15: EV/Ebidta (p) | L15: =C12/J16 -> -6.1493982
B16: Semáforo ESG | D16: Ebidta/Ingresos(p) | E16: =AVERAGE(Cifras_en_Millones!C19/C37,Cifras_en_Millones!D19/C36,Cifras_en_Millones!E19/C35) -> -0.49783943 | F16: =Segments!B18 -> Mobile | H16: =+Segments!J18 -> 38%; N/A; 1% | I16: Ebidta(p) | J16: =AVERAGE(Cifras_en_Millones!B19:D19) -> -290.121 | K16: Precio/FNP (p) | L16: =C9/J18 -> 19.958215
B17: E | D17: CIF/Deuda Neta Promedio | E17: =Cifras_en_Millones!C14/AVERAGE(Cifras_en_Millones!C59:M59) -> -0.54049955 | F17: =Segments!B19 -> CTV | H17: =+Segments!J19 -> 46%; N/A; 1% | I17: Utilidad Neta (p) | J17: =AVERAGE(Cifras_en_Millones!B23:D23) -> -88.738 | K17: Bonos 1;5;40a (USD) | L17: 4.0%; 4.4%; 5% | N17: 12
B18: S | I18: FNP (p) | J18: =SUM(F35:F37)/3 -> 69.333333 | K18: TDY(p)/Precio | L18: =SUM(E35:E37)/(3*C9) -> 0
B19: G | I19: Tax (p) últ. 5a | J19: 0.16 | K19: Div. Yield: | L19: =K33/C9 -> 0
B20: Tesis de inversión | H20: Acuerdo | I20: Supuestos de valuación | L20: DCF Value
B21: Magnite positions itself as one of the leading independent ad tech platforms, particularly in the Connected TV (CTV) segment, which has shown robust growth. Its ongoing partnership with Disney and other major media companies strengthens its market position and expands its global reach. Furthermore, the growing trend toward programmatic advertising offers a favorable environment for the company’s growth. However, investors should consider the associated risks, including intense competition from major market players, the inherent volatility of the digital advertising sector, and challenges related to integrating recent acquisitions. Magnite’s ability to innovate, expand into new markets, and maintain strategic partnerships will be crucial for sustaining its growth and competitiveness in the sector. Financially, Magnite’s shares are currently trading at $15.79, with a variation of -$0.76 (-4.59%) compared to the previous close. The future performance of its stock will depend on the company’s ability to navigate the aforementioned challenges and capitalize on emerging opportunities in the digital advertising market. | H21: NO invertir | I21: VER DCF | L21: =DCFF!D66 -> 5.9849733
B23: KSF | H23: PO / Precio Stand By | L23: =DCFF!D65 -> -0.38171763
B24: Innovation in Programmatic Advertising: Continuous improvement in AI-driven ad placement and real-time bidding technologies to optimize revenue generation for clients. Strategic Partnerships: Strengthening long-term collaborations with major media players such as Disney, Roku, and other streaming platforms to maintain a competitive advantage. Market Expansion: Increasing Magnite’s presence in high-growth regions such as Asia-Pacific and Latin America through targeted investment and strategic acquisitions. Data-Driven Decision-Making: Utilizing big data and machine learning to enhance ad targeting, improve return on investment (ROI) for advertisers, and reduce inefficiencies. Operational Efficiency and Cost Management: Enhancing integration between recently acquired platforms (e.g., SpotX) to streamline operations and reduce costs. Regulatory Compliance and Data Privacy Measures: Ensuring compliance with international data protection laws while maintaining effective user data collection strategies. Customer Retention and Satisfaction: Strengthening customer relationships through high-quality service, reliable platform performance, and personalized advertising solutions. Cybersecurity and Infrastructure Investment: Allocating resources to strengthen security protocols and protect against potential cyber threats that could disrupt operations. | H24: =L21*0.8 -> 4.7879786 | I24: Tasa de descuento: | J24: =DCFF!D47 -> 0.085 | K24: Sell
B25: Año | C25: Ingresos | D25: Margen Operativo | E25: Div.+Recompra | F25: FNP | G25: Deuda/Activo | H25: Depreciación | I25: Capex + Adq | J25: Cash Flow
B26: 2012 | K26: 2023 | L26: =K26-1 -> 2022
B27: =B26+1 -> 2013 | C27: =Cifras_en_Millones!M5 -> 83.4 | D27: =Cifras_en_Millones!M11/C27 -> -0.04676259 | E27: =Cifras_Originales!M18 -> 0 | F27: =Cifras_en_Millones!M30 -> 29.97 | G27: =Cifras_en_Millones!M61 -> 0.028020773 | H27: =Cifras_Originales!M11 -> -8.4 | I27: =Cifras_en_Millones!M35 -> -19 | J27: Profit | K27: =Cifras_en_Millones!D23 -> -130 | L27: =Cifras_en_Millones!E23 -> 0.065 | N27: N/A | O27: N/A
B28: =B27+1 -> 2014 | C28: =Cifras_en_Millones!L5 -> 125.3 | D28: =Cifras_en_Millones!L11/C28 -> -0.1500399 | E28: =Cifras_Originales!L18 -> 0 | F28: =Cifras_en_Millones!L30 -> 67.23 | G28: =Cifras_en_Millones!L61 -> 0.00033783784 | H28: =Cifras_Originales!L11 -> -12.5 | I28: =Cifras_en_Millones!L35 -> -34 | J28: Cash Flow from Operations (BWC) | K28: =Cifras_en_Millones!D19-Cifras_Originales!E15 -> -465.1 | L28: =Cifras_en_Millones!E19-Cifras_Originales!F15 -> -70.59 | N28: =C28/C27-1 -> 0.50239808 | O28: =D28/D27-1 -> 2.2085456 | P28: 0 | Q28: =F28/F27-1 -> 1.2432432 | R28: =H28/H27-1 -> 0.48809524 | S28: =I28/I27-1 -> 0.78947368 | BT28: 4303
B29: =B28+1 -> 2015 | C29: =Cifras_en_Millones!K5 -> 248.4 | D29: =Cifras_en_Millones!K11/C29 -> -0.022544283 | E29: =Cifras_Originales!K18 -> 0 | F29: =Cifras_en_Millones!K30 -> 19.3 | G29: =Cifras_en_Millones!K61 -> 0 | H29: =Cifras_Originales!K11 -> -31 | I29: =Cifras_en_Millones!K35 -> -94.1 | J29: Working Capital | K29: =Cifras_en_Millones!D18 -> 43.345 | L29: =Cifras_en_Millones!E18 -> 48.877 | N29: =C29/C28-1 -> 0.98244214 | O29: =D29/D28-1 -> -0.84974475 | P29: 0 | Q29: =F29/F28-1 -> -0.71292578 | R29: =H29/H28-1 -> 1.48 | S29: =I29/I28-1 -> 1.7676471 | BT29: 3066
B30: =B29+1 -> 2016 | C30: =Cifras_en_Millones!J5 -> 278.2 | D30: =Cifras_en_Millones!J11/C30 -> -0.0891445 | E30: =Cifras_Originales!J18 -> 0 | F30: =Cifras_en_Millones!J30 -> 32.9 | G30: =Cifras_en_Millones!J61 -> 0 | H30: =Cifras_Originales!J11 -> -42.7 | I30: =Cifras_en_Millones!J35 -> -197 | J30: Investing Activities | K30: -65.2 | L30: -691 | N30: =C30/C29-1 -> 0.11996779 | O30: =D30/D29-1 -> 2.9541953 | P30: 0 | Q30: =F30/F29-1 -> 0.70466321 | R30: =H30/H29-1 -> 0.37741935 | S30: =I30/I29-1 -> 1.0935175 | BT30: 3283
B31: =B30+1 -> 2017 | C31: =Cifras_en_Millones!I5 -> 155.5 | D31: =Cifras_en_Millones!I11/C31 -> -1.0096463 | E31: =Cifras_Originales!I18 -> 0 | F31: =Cifras_en_Millones!I30 -> -72.8 | G31: =Cifras_en_Millones!I61 -> 0 | H31: =Cifras_Originales!I11 -> -36.2 | I31: =Cifras_en_Millones!I35 -> -125.3 | J31: Capex | K31: =Cifras_Originales!D13 -> -30.8 | L31: =Cifras_Originales!E13 -> -17.7 | N31: =C31/C30-1 -> -0.4410496 | O31: =D31/D30-1 -> 10.325952 | P31: 0 | Q31: =F31/F30-1 -> -3.212766 | R31: =H31/H30-1 -> -0.15222482 | S31: =I31/I30-1 -> -0.36395939
B32: =B31+1 -> 2018 | C32: =Cifras_en_Millones!H5 -> 124.6 | D32: =Cifras_en_Millones!H11/C32 -> -0.51364366 | E32: =Cifras_Originales!H18 -> 0 | F32: =Cifras_en_Millones!H30 -> 3.8 | G32: =Cifras_en_Millones!H61 -> 0 | H32: =Cifras_Originales!H11 -> -35.3 | I32: =Cifras_en_Millones!H35 -> -55.4 | J32: Adquisiones | K32: 20.8 | L32: 661.9 | N32: =C32/C31-1 -> -0.19871383 | O32: =D32/D31-1 -> -0.49126376 | P32: 0 | Q32: =F32/F31-1 -> -1.0521978 | R32: =H32/H31-1 -> -0.024861878 | S32: =I32/I31-1 -> -0.55786113
B33: =B32+1 -> 2019 | C33: =Cifras_en_Millones!G5 -> 156.4 | D33: =Cifras_en_Millones!G11/C33 -> -0.1758312 | E33: =Cifras_Originales!G18 -> 0 | F33: =Cifras_en_Millones!G30 -> 8.6 | G33: =Cifras_en_Millones!G61 -> 0.056962025 | H33: =Cifras_Originales!G11 -> -32.1 | I33: =Cifras_en_Millones!G35 -> -41.4 | J33: Dividends | K33: 0 | L33: 0 | N33: =C33/C32-1 -> 0.25521669 | O33: =D33/D32-1 -> -0.65767863 | P33: 0 | Q33: =F33/F32-1 -> 1.2631579 | R33: =H33/H32-1 -> -0.090651558 | S33: =I33/I32-1 -> -0.25270758
B34: =B33+1 -> 2020 | C34: =Cifras_en_Millones!F5 -> 221.6 | D34: =Cifras_en_Millones!F11/C34 -> -0.24368231 | E34: =Cifras_Originales!F18 -> 0 | F34: =Cifras_en_Millones!F30 -> 29 | G34: =Cifras_en_Millones!F61 -> 0.044839706 | H34: =Cifras_Originales!F11 -> -49.2 | I34: =Cifras_en_Millones!F35 -> -35.3 | J34: Stock Repurchases | K34: =Cifras_en_Millones!D29 -> 0 | L34: =Cifras_en_Millones!E29 -> 0 | N34: =C34/C33-1 -> 0.4168798 | O34: =D34/D33-1 -> 0.38588776 | P34: 0 | Q34: =F34/F33-1 -> 2.372093 | R34: =H34/H33-1 -> 0.53271028 | S34: =I34/I33-1 -> -0.147343
B35: =B34+1 -> 2021 | C35: =Cifras_en_Millones!E5 -> 468.4 | D35: =Cifras_en_Millones!E11/C35 -> -0.17292912 | E35: =Cifras_Originales!E18 -> 0 | F35: =Cifras_en_Millones!E30 -> 112 | G35: =Cifras_en_Millones!E61 -> 0.29831158 | H35: =Cifras_Originales!E11 -> -146.88 | I35: =Cifras_en_Millones!E35 -> -708.7 | J35: Endeudamiento Neto | K35: =Cifras_en_Millones!D59 -> 487.7 | L35: =Cifras_en_Millones!E59 -> 579.2 | N35: =C35/C34-1 -> 1.1137184 | O35: =D35/D34-1 -> -0.29035013 | P35: 0 | Q35: =F35/F34-1 -> 2.862069 | R35: =H35/H34-1 -> 1.9853659 | S35: =I35/I34-1 -> 19.076487
B36: =B35+1 -> 2022 | C36: =Cifras_en_Millones!D5 -> 577.1 | D36: =Cifras_en_Millones!D11/C36 -> -0.19407382 | E36: =Cifras_Originales!D18 -> 0 | F36: =Cifras_en_Millones!D30 -> 96 | G36: =Cifras_en_Millones!D61 -> 0.30003687 | H36: =Cifras_Originales!D11 -> -216.1 | I36: =Cifras_en_Millones!D35 -> -95.8 | J36: Otros Financiemientos | K36: -30.2 | L36: 678.1 | N36: =C36/C35-1 -> 0.23206661 | O36: =D36/D35-1 -> 0.12227378
B37: =B36+1 -> 2023 | C37: =Cifras_en_Millones!C5 -> 619.7 | D37: =Cifras_en_Millones!C11/C37 -> -0.25013555 | E37: =Cifras_Originales!C18 -> 0 | F37: =Cifras_en_Millones!C30 -> 0 | G37: =Cifras_en_Millones!C61 -> 0.22560803 | H37: =Cifras_Originales!C11 -> -240.8 | I37: =Cifras_en_Millones!C35 -> -64 | N37: =C37/C36-1 -> 0.073817363 | O37: =D37/D36-1 -> 0.28886809
B38: 2024 Est. | C38: =DCFF!H6 -> 672.9942 | D38: =DCFF!H7 -> 0.1
B39: CAGR | C39: =(C37/C32)^(1/5)-1 -> 0.37826488 | D39: =(D37/D27)^(1/11)-1 -> 0.16468099 | J39: FX | K39: 0 | L39: 0
B40: AAG | C40: =AVERAGE(N27:N37) -> 0.30567435 | D40: =AVERAGE(O27:O37) -> 1.3996685 | J40: D Cash and Equivalents | K40: =K28+K29+K30+K33+K34+K35+K36+K39 -> -29.455 | L40: =L28+L29+L30+L33+L34+L35+L36+L39 -> 544.587
B41: CVAR | C41: =STDEV(C26:C37)/AVERAGE(C26:C37) -> 0.68335684 | D41: =STDEV(D26:D37)/AVERAGE(D26:D37) -> -1.0770471 | J41: Inv/D Vts | K41: =SUM(I33:I37)/(C37-C32) -> -1.9091093 | L41: =(SUM(I33:I37)-SUM(H33:H37))/(C37-C32) -> -0.52538881
B42: Último Año | C42: =C37/C36-1 -> 0.073817363 | D42: =D37/D36-1 -> 0.28886809 | J42: t inversiones; t adq. neto dep. | K42: =K41/E14 -> 9.280458 | L42: =L41/E14 -> 2.5539915
...

Sheet COVID-19 impact
A1: https://www.apple.com/newsroom/2020/03/apples-covid-19-response/ | G1: https://glg.it/articles/how-might-the-wuhan-coronavirus-impact-apples-supply-chain/ | N1: https://www.cnbc.com/2020/02/18/the-significance-of-apples-coronavirus-warning.html
A2: March 13 | G2: January 29 | N2: Ferbuary 18
A23: Otros:
A24: https://www.macrumors.com/guide/covid-19-coronavirus/

Sheet Segments
B2: Regions (2023) | L2: Proyectado | N2: Escenario de estrés | X2: Escenario de estrés
C3: 2022 | D3: =C3-1 -> 2021 | E3: Ut. Operativa | F3: % Vts | G3: Margen | H3: Crec | L3: Crecimiento | M3: 2021 (Real) | N3: 2022 (Real) | O3: 2023 (Real) | P3: 2024 (Est) | Q3: 2025 | R3: 2026 | S3: 2027 | T3: 2028 | V3: Márgenes (regional) | W3: 2020 (Real) | X3: 2021 (Real) | Y3: 2022 (Real) | Z3: 2023 (Est) | AA3: 2024 | AB3: 2025 | AC3: 2026 | AD3: 2027
B4: United States | C4: 447.6 | D4: 365.2 | E4: N/A | F4: 0.7458 | G4: N/A | H4: 0.0108 | J4: =IF(C4="","",IF(F4=0,"NA",TEXT(F4,"0%"))&"; "&IF(G4=0,"NA",TEXT(G4,"0.0%"))&"; "&IF(H4=0,"NA",TEXT(H4,"0%"))) -> 75%; N/A; 1% | L4: Desktop | M4: 113 | N4: 111.7 | O4: 103.8 | P4: 105.6 | Q4: 107.6 | R4: 109.7 | S4: 116.9 | T4: - | V4: =B4 -> United States
B5: Other Internationals | C5: 129.4 | D5: 103.3 | E5: N/A | F5: 0.2542 | G5: N/A | H5: 0.0108 | J5: =IF(C5="","",IF(F5=0,"NA",TEXT(F5,"0%"))&"; "&IF(G5=0,"NA",TEXT(G5,"0.0%"))&"; "&IF(H5=0,"NA",TEXT(H5,"0%"))) -> 25%; N/A; 1% | L5: Mobile | M5: 160.1 | N5: 188.2 | O5: 226.8 | P5: 246.7 | Q5: 264 | R5: 283.7 | S5: 300.7 | T5: - | V5: =B5 -> Other Internationals
J6: =IF(C6="","",IF(F6=0,"NA",TEXT(F6,"0%"))&"; "&IF(G6=0,"NA",TEXT(G6,"0.0%"))&"; "&IF(H6=0,"NA",TEXT(H6,"0%"))) | L6: CTV | M6: 143.4 | N6: 214.8 | O6: 218.5 | P6: 258.7 | Q6: 302.9 | R6: 359.4 | S6: 459.7 | T6: - | V6: =B6 -> 0
J7: =IF(C7="","",IF(F7=0,"NA",TEXT(F7,"0%"))&"; "&IF(G7=0,"NA",TEXT(G7,"0.0%"))&"; "&IF(H7=0,"NA",TEXT(H7,"0%"))) | V7: =B7 -> 0
J8: =IF(C8="","",IF(F8=0,"NA",TEXT(F8,"0%"))&"; "&IF(G8=0,"NA",TEXT(G8,"0.0%"))&"; "&IF(H8=0,"NA",TEXT(H8,"0%"))) | V8: =B8 -> 0
J9: =IF(C9="","",IF(F9=0,"NA",TEXT(F9,"0%"))&"; "&IF(G9=0,"NA",TEXT(G9,"0.0%"))&"; "&IF(H9=0,"NA",TEXT(H9,"0%"))) | L9: % vts. | V9: Margen Operativp | W9: =(W4*W12+W5*W13+W6*W14+W7*W15+W8*W16)/SUM(W12:W16)+W10 -> 0 | X9: =(X4*X12+X5*X13+X6*X14+X7*X15+X8*X16)/SUM(X12:X16)+X10 -> 0 | Y9: =(Y4*Y12+Y5*Y13+Y6*Y14+Y7*Y15+Y8*Y16)/SUM(Y12:Y16)+Y10 -> 0 | Z9: =(Z4*Z12+Z5*Z13+Z6*Z14+Z7*Z15+Z8*Z16)/SUM(Z12:Z16)+Z10 -> 0 | AA9: =(AA4*AA12+AA5*AA13+AA6*AA14+AA7*AA15+AA8*AA16)/SUM(AA12:AA16)+AA10 -> 0 | AB9: =(AB4*AB12+AB5*AB13+AB6*AB14+AB7*AB15+AB8*AB16)/SUM(AB12:AB16)+AB10 -> 0 | AC9: =(AC4*AC12+AC5*AC13+AC6*AC14+AC7*AC15+AC8*AC16)/SUM(AC12:AC16)+AC10 -> 0 | AD9: =(AD4*AD12+AD5*AD13+AD6*AD14+AD7*AD15+AD8*AD16)/SUM(AD12:AD16)+AD10 -> #VALUE!
J10: =IF(C10="","",IF(F10=0,"NA",TEXT(F10,"0%"))&"; "&IF(G10=0,"NA",TEXT(G10,"0.0%"))&"; "&IF(H10=0,"NA",TEXT(H10,"0%"))) | L10: Desktop | M10: 0.2713 | N10: 0.2171 | O10: 0.1891 | P10: =105.6/678.5 -> 0.15563744 | Q10: =107.7/747.4 -> 0.14409955 | R10: =109.7/828.2 -> 0.13245593 | S10: =116.9/974.7 -> 0.11993434 | T10: - | V10: Ajuste R&D
J11: =IF(C11="","",IF(F11=0,"NA",TEXT(F11,"0%"))&"; "&IF(G11=0,"NA",TEXT(G11,"0.0%"))&"; "&IF(H11=0,"NA",TEXT(H11,"0%"))) | L11: Mobile | M11: 0.3843 | N11: 0.3656 | O11: 0.4131 | P11: =246.7/678.5 -> 0.36359617 | Q11: =264/747.4 -> 0.35322451 | R11: =283.7/828.2 -> 0.34255011 | S11: =300.7/974.7 -> 0.30850518 | T11: - | V11: % vts.
J12: =IF(C12="","",IF(F12=0,"NA",TEXT(F12,"0%"))&"; "&IF(G12=0,"NA",TEXT(G12,"0.0%"))&"; "&IF(H12=0,"NA",TEXT(H12,"0%"))) | L12: CTV | M12: 0.3443 | N12: 0.4147 | O12: 0.3979 | P12: =258.4/678.5 -> 0.38084009 | Q12: =302.9/747.4 -> 0.40527161 | R12: =359.4/828.2 -> 0.43395315 | S12: =459.7/974.7 -> 0.4716323 | T12: - | V12: =V4 -> United States | W12: 0.729 | X12: 0.7796 | Y12: 0.7757 | Z12: 0.7458 | AA12: 0.7461 | AB12: 0.7396 | AC12: 0.7291 | AD12: -
J13: =IF(C13="","",IF(F13=0,"NA",TEXT(F13,"0%"))&"; "&IF(G13=0,"NA",TEXT(G13,"0.0%"))&"; "&IF(H13=0,"NA",TEXT(H13,"0%"))) | V13: =V5 -> Other Internationals | W13: 0.271 | X13: 0.2204 | Y13: 0.2243 | Z13: 0.2542 | AA13: 0.2491 | AB13: 0.2517 | AC13: 0.2541 | AD13: -
B14: TOTAL | C14: =SUM(C4:C12) -> 577 | D14: =SUM(D4:D12) -> 468.5 | E14: =SUM(E4:E13) -> 0 | F14: =C14/SUM($C$4:$C$13) -> 1 | G14: =E14/C14 -> 0 | H14: =C14/D14-1 -> 0.23159018 | M14: - | N14: - | O14: - | P14: - | Q14: - | R14: - | S14: - | V14: =V6 -> 0
B15: Products (2023) | M15: =SUM(M10:M14) -> 0.9999 | N15: =SUM(N10:N14) -> 0.9974 | O15: =SUM(O10:O14) -> 1.0001 | P15: =SUM(P10:P14) -> 0.90007369 | Q15: =SUM(Q10:Q14) -> 0.90259566 | R15: =SUM(R10:R14) -> 0.90895919 | S15: =SUM(S10:S14) -> 0.90007182 | T15: =SUM(T10:T14) -> 0 | V15: =V7 -> 0
C16: =C3 -> 2022 | D16: =C16-1 -> 2021 | E16: Ut. Op. | F16: % Vts | G16: Margen | H16: Crec | N16: =N15/M15-1 -> -0.00250025 | O16: =O15/N15-1 -> 0.0027070383 | P16: =P15/O15-1 -> -0.10001631 | Q16: =Q15/P15-1 -> 0.0028019628 | R16: =R15/Q15-1 -> 0.0070502484 | S16: =S15/R15-1 -> -0.0097775255 | T16: =T15/S15-1 -> -1 | V16: =V8 -> 0
B17: Desktop | C17: 115.7 | D17: 118.2 | E17: N/A | F17: 0.1696 | G17: N/A | H17: 0.0101 | J17: =IF(C17="","",IF(F17=0,"NA",TEXT(F17,"0%"))&"; "&IF(G17=0,"NA",TEXT(G17,"0.0%"))&"; "&IF(H17=0,"NA",TEXT(H17,"0%"))) -> 17%; N/A; 1% | W17: =SUM(W12:W16) -> 1 | X17: =SUM(X12:X16) -> 1 | Y17: =SUM(Y12:Y16) -> 1 | Z17: =SUM(Z12:Z16) -> 1 | AA17: =SUM(AA12:AA16) -> 0.9952 | AB17: =SUM(AB12:AB16) -> 0.9913 | AC17: =SUM(AC12:AC16) -> 0.9832 | AD17: =SUM(AD12:AD16) -> 0
B18: Mobile | C18: 192.8 | D18: 165 | E18: N/A | F18: 0.3752 | G18: N/A | H18: 0.0105 | J18: =IF(C18="","",IF(F18=0,"NA",TEXT(F18,"0%"))&"; "&IF(G18=0,"NA",TEXT(G18,"0.0%"))&"; "&IF(H18=0,"NA",TEXT(H18,"0%"))) -> 38%; N/A; 1%
B19: CTV | C19: 268.6 | D19: 185.3 | E19: N/A | F19: 0.4553 | G19: N/A | H19: 0.0113 | J19: =IF(C19="","",IF(F19=0,"NA",TEXT(F19,"0%"))&"; "&IF(G19=0,"NA",TEXT(G19,"0.0%"))&"; "&IF(H19=0,"NA",TEXT(H19,"0%"))) -> 46%; N/A; 1%
J20: =IF(C20="","",IF(F20=0,"NA",TEXT(F20,"0%"))&"; "&IF(G20=0,"NA",TEXT(G20,"0.0%"))&"; "&IF(H20=0,"NA",TEXT(H20,"0%")))
J21: =IF(C21="","",IF(F21=0,"NA",TEXT(F21,"0%"))&"; "&IF(G21=0,"NA",TEXT(G21,"0.0%"))&"; "&IF(H21=0,"NA",TEXT(H21,"0%")))
J22: =IF(C22="","",IF(F22=0,"NA",TEXT(F22,"0%"))&"; "&IF(G22=0,"NA",TEXT(G22,"0.0%"))&"; "&IF(H22=0,"NA",TEXT(H22,"0%")))
J23: =IF(C23="","",IF(F23=0,"NA",TEXT(F23,"0%"))&"; "&IF(G23=0,"NA",TEXT(G23,"0.0%"))&"; "&IF(H23=0,"NA",TEXT(H23,"0%")))
J24: =IF(C24="","",IF(F24=0,"NA",TEXT(F24,"0%"))&"; "&IF(G24=0,"NA",TEXT(G24,"0.0%"))&"; "&IF(H24=0,"NA",TEXT(H24,"0%")))
J25: =IF(C25="","",IF(F25=0,"NA",TEXT(F25,"0%"))&"; "&IF(G25=0,"NA",TEXT(G25,"0.0%"))&"; "&IF(H25=0,"NA",TEXT(H25,"0%")))
J26: =IF(C26="","",IF(F26=0,"NA",TEXT(F26,"0%"))&"; "&IF(G26=0,"NA",TEXT(G26,"0.0%"))&"; "&IF(H26=0,"NA",TEXT(H26,"0%")))
B27: TOTAL | C27: =SUM(C17:C26) -> 577.1 | D27: =SUM(D17:D26) -> 468.5 | E27: =SUM(E17:E26) -> 0 | F27: =C27/SUM(C17:C26) -> 1 | G27: =E27/C27 -> 0 | H27: =C27/D27-1 -> 0.23180363

Sheet Peers
A2: Multiplos (USD) | B2: Magnite | C2: PubMatic Inc | D2: Taboola
B3: MGNI | C3: PUBM | D3: TBLA
A4: Ventas | B4: 661.13M | C4: 290.4M | D4: 1.69B
A5: Crecimiento Ult. Año fiscal | B5: 0.0739 | C5: 0.0415 | D5: 0.0275
A6: Crecimiento (vs 2019) | B6: 0.232 | C6: 0.1299 | D6: 0.0165
A7: Deuda | C7: 82110 | D7: 26772
A8: Activos | C8: 301311 | D8: 319616
A9: Deuda/Activos | B9: 0.2256 | C9: 0.0513 | D9: 0.128
A10: Deuda/EBITDA | B10: 2.67 | C10: 0.56 | D10: 2.39
A11: (Capex + Adq.)/Revenue | B11: =(52.7+0)/661.1 -> 0.079715625 | C11: =(34.5+0)/290.4 -> 0.11880165 | D11: =(37.4+0)/1695 -> 0.022064897
A12: ROA (p) | B12: -0.0589 | C12: 0.0266 | D12: -0.0195
A13: ROIC (p) | B13: -0.1071 | C13: 0.0232 | D13: -0.025
A14: Margen Operativo (p) | B14: -0.2501 | C14: 0.0328 | D14: -0.0074
A15: Margen Operativo | B15: -0.1954 | C15: 0.158 | D15: -0.0098
A16: Float | B16: 138.33M | C16: 36.65M | D16: 199.12M
A17: b | B17: 2.52 | C17: 2.1 | D17: 1.99
A18: Precio/Utilidad | B18: 134.77 | C18: 45.72 | D18: 7.62
A19: Precio/Ventas | B19: 3.86 | C19: 2.5 | D19: 0.75
A20: EV/Activos | B20: =2.8/2.68 -> 1.0447761 | C20: 6.56 | D20: 5.25
A21: EV/Ebitda | B21: 26.36 | C21: 9.47 | D21: =1241/89 -> 13.94382
A22: Div. Yield: | B22: - | C22: - | D22: -

Sheet Acuerdo
A1: Invertir
A2: NO invertir
A3: Mantener sin elevar posición
A4: Mantener (y seguir comprando)
A5: Liquidar
A6: PENDIENTE

Sheet ESG
B2: Análisis ESG | J2: PARÁMETROS
C3: Impacto | D3: ¿Reporta? | E3: Ranking | F3: Mitigación | G3: Semáforo | H3: Comentarios | J3: IMPACTO | L3: RANKING | M3: MITIGACIÓN
B4: Ambiental | C4: 0 | D4: No | E4: 'Best in class'' | F4: Yes | H4: Could not find any information. | J4: NONE | K4: 0 | L4: "Best in class" | M4: Is there evidence of progam/plan/etc…
B5: Emisiones directas CO2 | C5: 0 | D5: No | E5: 'Best in class'' | F5: Yes | H5: The company strives to reduce CO2 emissions by 15% in 2025 | J5: LOW | K5: 1 | L5: Medium high
B6: Uso total de agua | C6: 0 | D6: No | E6: 'Best in class'' | F6: No | H6: Could not find any information. | J6: MEDIUM | K6: 2 | L6: Medium
B7: Total Energy Consumption | C7: 0 | D7: No | E7: Medium | F7: Yes | H7: Magnite, Inc. acknowledges the energy-intensive nature of its operations, particularly due to substantial data processing requirements. The company works continuosly with experts to find solutions to reduce footprint | J7: HIGH | K7: 3 | L7: "Villain"
B8: Waste Management | C8: 0 | D8: No | E8: 'Best in class'' | F8: No | H8: Could not find any information.
B9: Land Degradation/Deforestation/Biodiversity loss/Animal sufering/… | C9: 0 | D9: No | E9: 'Best in class'' | F9: No | H9: Could not find any information. | J9: TRAFFIC LIGHTS
B10: Social
B11: % Rotación de empleados | C11: High | D11: Yes | E11: Medium | F11: No | H11: The company has a retention rate of 92%, a rotation of 8%
B12: Sueldos y compensaciones | C12: High | E12: Medium | F12: No | H12: Workers report a satisfaction of 3.7 out of 5, and there does not seem to be discrimination on women's salaries
B13: Temas de reputación | C13: High | E13: 'Best in class'' | F13: No
B14: Temas de discriminación | C14: High | E14: 'Best in class'' | F14: No | H14: The company strives for equality, diversity and inclusion, and does not show signs of discrimination
B15: Seguridad laboral | C15: High | E15: 'Best in class'' | F15: No | H15: The workers do not incur in any kind of labor unsafety
B16: Daños a la salud | C16: High | E16: 'Best in class'' | F16: No | H16: The service provided does not impose a negative externality on the consumer's health
B17: PXP? | D17: Yes | E17: 'Best in class'' | F17: No | H17: Magnite provides retirement plans for employees and pension plans. As well as other benefits, like a 15% discount on the company shares.
B18: Supply chain
B19: Community involvement | C19: High | D19: No | E19: 'Villain'' | F19: No | H19: There are no community involvement programs
B20: Public Sector | C20: 0 | E20: 'Best in class'' | F20: No | H20: Did not find any ties to the public sector
B21: Litigios | C21: 0 | E21: 'Best in class'' | F21: No | H21: There is no recent record
B22: Gobierno
B23: Diversidad (Género, edad, industria, región) | E23: Medium | F23: Yes | H23: 4 women to 7 men in Board members, and only two non-caucasian
B24: % independientes | E24: "Best in class" | F24: No | H24: Board members are independent, except for the CEO and Chairman
B25: tiempo promedio como consejeros independientes | E25: Medium high | F25: No | H25: Most members have a tenure of less that 6 and more than 3 years
B26: Salidas recientes de consejeros/C-level executives? | E26: "Best in class" | F26: No | H26: There were no recent departures
B27: CEO/Chairman | E27: "Best in class" | F27: No | H27: There is no CEO duality
B28: Transparencia (segmentos, fuente de riqueza, adquisiciones, otros) | E28: Medium high | F28: No | H28: There is some lack of transparency in ESG reporting
B29: Tiempo que tardan en reportar luego del final del trimestre/año | E29: Medium high | F29: No | H29: The company takes about 2 months to deliver the Annual Report
B30: Participación adicional del CEO en otros consejos o excesiva del Ch. | E30: "Best in class" | F30: No | H30: They do not participate in other boards
B31: Auditoría/Consultoría | D31: No | H31: Could not find relevant information
B32: Esquemas de compensación al management | D32: No | H32: In February 2024 the Company achieved CTV Contribution ex-TAC of $218.5 million, DV+ Contribution ex-TAC of $330.7 million and Adjusted EBITDA less capex of $132.5 million, which resulted in a weighted payout percentage of 83.14% of each named executive officers’ target bonus for 2023.

Sheet DCF
A1: Discounted Cash Flow
A3: Ventas | E3: Margen Operativo
A16: Inversiones | E16: Utilidad Neta
D31: 0.001 | E31: =1/((1+$B$59+$D31)^(E35-2021)) -> 0.92250923 | F31: =1/((1+$B$59+$D31)^(F35-2021)) -> 0.85102327 | G31: =1/((1+$B$59+$D31)^(G35-2021)) -> 0.78507682 | H31: =1/((1+$B$59+$D31)^(H35-2021)) -> 0.72424061 | I31: =1/((1+$B$59+$D31)^(I35-2021)) -> 0.66811864 | J31: =1/((1+$B$59+$D31)^(J35-2021)) -> 0.61634561 | K31: =1/((1+$B$59+$D31)^(K35-2021)) -> 0.56858451 | L31: =1/((1+$B$59+$D31)^(L35-2021)) -> 0.52452446 | ... AC31: =1/((1+$B$59+$D31)^(AC35-2021)) -> 0.13312755
D32: 0.005 | E32: =1/((1+$B$59+$D32)^(E35-2021)) -> 0.91911765 | F32: =1/((1+$B$59+$D32)^(F35-2021)) -> 0.84477725 | G32: =1/((1+$B$59+$D32)^(G35-2021)) -> 0.77644968 | H32: =1/((1+$B$59+$D32)^(H35-2021)) -> 0.7136486 | I32: =1/((1+$B$59+$D32)^(I35-2021)) -> 0.65592702 | J32: =1/((1+$B$59+$D32)^(J35-2021)) -> 0.6028741 | K32: =1/((1+$B$59+$D32)^(K35-2021)) -> 0.55411223 | L32: =1/((1+$B$59+$D32)^(L35-2021)) -> 0.50929433 | ... AC32: =1/((1+$B$59+$D32)^(AC35-2021)) -> 0.12141647
D33: Normal | E33: =1/((1+$B$59)^(E35-2021)) -> 0.92336103 | F33: =1/((1+$B$59)^(F35-2021)) -> 0.8525956 | G33: =1/((1+$B$59)^(G35-2021)) -> 0.78725355 | H33: =1/((1+$B$59)^(H35-2021)) -> 0.72691926 | I33: =1/((1+$B$59)^(I35-2021)) -> 0.67120892 | J33: =1/((1+$B$59)^(J35-2021)) -> 0.61976816 | K33: =1/((1+$B$59)^(K35-2021)) -> 0.57226977 | L33: =1/((1+$B$59)^(L35-2021)) -> 0.5284116 | ... AC33: =1/((1+$B$59)^(AC35-2021)) -> 0.13623496
B35: 2019 (Real) | C35: 2020 (Real) | D35: 2021 | E35: =D35+1 -> 2022 | F35: =E35+1 -> 2023 | G35: =F35+1 -> 2024 | H35: =G35+1 -> 2025 | I35: =H35+1 -> 2026 | J35: =I35+1 -> 2027 | K35: =J35+1 -> 2028 | L35: =K35+1 -> 2029 | ... AC35: =AB35+1 -> 2046
A36: Crecimiento | B36: =OP!N34 -> 0.4168798 | C36: =OP!N35 -> 1.1137184 | D36: 0.35 | E36: 0.034 | F36: 0.095 | G36: 0.095 | H36: 0.095 | I36: 0.095 | J36: 0.095 | K36: 0.08 | L36: 0.06 | M36: 0.05 | N36: 0.04 | O36: 0.035 | P36: 0.035 | Q36: 0.035 | R36: 0.035 | S36: 0.035 | T36: 0.035 | U36: 0.035 | V36: 0.035 | W36: 0.035 | X36: 0.035 | Y36: 0.035 | Z36: 0.035 | AA36: 0.035 | AB36: 0.035 | AC36: 0.035
A37: Ventas | B37: =OP!C34 -> 221.6 | C37: =OP!C35 -> 468.4 | D37: =OP!C34*(1+D36) -> 299.16 | E37: =D37*(1+E36) -> 309.33144 | F37: =E37*(1+F36) -> 338.71793 | G37: =F37*(1+G36) -> 370.89613 | H37: =G37*(1+H36) -> 406.13126 | I37: =H37*(1+I36) -> 444.71373 | J37: =I37*(1+J36) -> 486.96154 | K37: =J37*(1+K36) -> 525.91846 | L37: =K37*(1+L36) -> 557.47357 | ... AC37: =AB37*(1+AC36) -> 1019.8873
A38: Margen Operativo | B38: =+OP!D34 -> -0.24368231 | C38: =+OP!D35 -> -0.17292912 | D38: =108166.4/365513.2 -> 0.29593022 | E38: =108162.8/377959.8 -> 0.28617541 | F38: 0.27 | G38: 0.275 | H38: 0.26 | I38: 0.255 | J38: 0.25 | K38: 0.25 | L38: 0.25 | M38: 0.25 | N38: 0.25 | O38: 0.25 | P38: 0.25 | Q38: 0.25 | R38: 0.25 | S38: 0.25 | T38: 0.25 | U38: 0.25 | V38: 0.25 | W38: 0.25 | X38: 0.25 | Y38: 0.25 | Z38: 0.25 | AA38: 0.25 | AB38: 0.25 | AC38: 0.25
A39: EBIT | B39: 63930 | C39: 66288 | D39: =D37*D38 -> 88.530483 | E39: =E37*E38 -> 88.523051 | F39: =F37*F38 -> 91.45384 | G39: =G37*G38 -> 101.99644 | H39: =H37*H38 -> 105.59413 | I39: =I37*I38 -> 113.402 | J39: =J37*J38 -> 121.74038 | K39: =K37*K38 -> 131.47961 | ... AC39: =AC37*AC38 -> 254.97181
A40: Dep&Amort | B40: =OP!H34 -> -49.2 | C40: =OP!H35 -> -146.88 | D40: 11000 | E40: =D40*(1+E36*$H$59) -> 11374 | F40: =E40*(1+F36*$H$59) -> 12454.53 | G40: =F40*(1+G36*$H$59) -> 13637.71 | H40: =G40*(1+H36*$H$59) -> 14933.293 | I40: =H40*(1+I36*$I$59) -> 16351.956 | J40: =I40*(1+J36*$I$59) -> 17905.391 | K40: =J40*(1+K36*$I$59) -> 19337.823 | L40: =K40*(1+L36*$I$59) -> 20498.092 | M40: =L40*(1+M36*$I$59) -> 21522.997 | N40: =M40*(1+N36*$I$59) -> 22383.917 | O40: =N40*(1+O36*$I$59) -> 23167.354 | P40: =O40*(1+P36*$I$59) -> 23978.211 | ... AC40: =AB40*(1+AC36*$I$59) -> 37500.868
A41: EBIDTA | B41: =+B39+B40 -> 63880.8 | C41: =+C39+C40 -> 66141.12 | D41: =D39+D40 -> 11088.53 | E41: =E39+E40 -> 11462.523 | F41: =F39+F40 -> 12545.984 | G41: =G39+G40 -> 13739.707 | H41: =H39+H40 -> 15038.887 | I41: =I39+I40 -> 16465.358 | J41: =J39+J40 -> 18027.132 | K41: =K39+K40 -> 19469.302 | ... AC41: =AC39+AC40 -> 37755.84
A42: CIF | B42: -1385 | C42: -890 | D42: =(C48)*$H$60 -> -1124.36 | E42: =(D48)*$H$60 -> -1113.1164 | F42: =(E48)*$H$60 -> -1113.1164 | G42: =(F48)*$H$60 -> -1113.1164 | H42: =(G48)*$H$60 -> -1113.1164 | I42: =(H48)*$H$60 -> -1113.1164 | J42: =(I48)*$H$60 -> -1113.1164 | K42: =(J48)*$H$60 -> -1113.1164 | ... AC42: =(AB48)*$H$60 -> -1113.1164
A43: Otros Gastos | B43: =-422-2817 -> -3239 | C43: =87-3634 -> -3547 | D43: =-C43*(1+D36) -> 4788.45 | E43: =D43*(1+E36*0.5) -> 4869.8537 | F43: =E43*(1+F36*0.5) -> 5101.1717 | G43: =F43*(1+G36*0.5) -> 5343.4774 | H43: =G43*(1+H36*0.5) -> 5597.2925 | I43: =H43*(1+I36*0.5) -> 5863.1639 | J43: =I43*(1+J36*0.5) -> 6141.6642 | K43: =J43*(1+K36*0.5) -> 6387.3308 | L43: =K43*(1+L36*0.5) -> 6578.9507 | ... AC43: =AB43*(1+AC36*0.5) -> 8922.7133
A44: Utilidad antes de Impuestos | B44: =B39-B42-B43 -> 68554 | C44: =C39-C42-C43 -> 70725 | D44: =D39-D42-D43 -> -3575.5595 | E44: =E39-E42-E43 -> -3668.2142 | F44: =F39-F42-F43 -> -3896.6015 | G44: =G39-G42-G43 -> -4128.3645 | H44: =H39-H42-H43 -> -4378.582 | I44: =I39-I42-I43 -> -4636.6455 | ... AC44: =AC39-AC42-AC43 -> -7554.6251
A45: ISR & PTU | B45: 10481 | C45: 9680 | D45: =$H$61*D44 -> -750.8675 | E45: =$H$61*E44 -> -770.32498 | F45: =$H$61*F44 -> -818.28631 | G45: =$I$61*G44 -> -949.52384 | H45: =$I$61*H44 -> -1007.0739 | I45: =$I$61*I44 -> -1066.4285 | J45: =$I$61*J44 -> -1128.5657 | K45: =$I$61*K44 -> -1182.829 | L45: =$I$61*L44 -> -1225.0872 | M45: =$I$61*M44 -> -1261.3134 | N45: =$I$61*N44 -> -1290.9868 | ... AC45: =$I$61*AC44 -> -1737.5638
A46: Utilidad Neta | B46: =B44-B45 -> 58073 | C46: =C44-C45 -> 61045 | D46: =D44-D45 -> -2824.692 | E46: =E44-E45 -> -2897.8892 | F46: =F44-F45 -> -3078.3152 | G46: =G44-G45 -> -3178.8407 | H46: =H44-H45 -> -3371.5081 | I46: =I44-I45 -> -3570.2171 | ... AC46: =AC44-AC45 -> -5817.0613
A47: Inversiones y Capex | B47: =OP!I34 -> -35.3 | C47: =OP!I35 -> -708.7 | D47: 10000 | E47: =D47*(1+E36*$H$62) -> 10408 | F47: =E47*(1+F36*$H$62) -> 11594.512 | G47: =F47*(1+G36*$H$62) -> 12916.286 | H47: =G47*(1+H36*$H$62) -> 14388.743 | I47: =H47*(1+I36*$H$62) -> 16029.06 | J47: =I47*(1+J36*$H$62) -> 17856.373 | K47: =J47*(1+K36*$H$62) -> 19570.584 | L47: =K47*(1+L36*$H$62) -> 20979.666 | ... AC47: =AB47*(1+AC36*$H$62) -> 43199.777
A48: Deuda + Lease Liabilities | B48: 108047 | C48: 112436 | D48: =C48*0.99 -> 111311.64 | E48: =D48 -> 111311.64 | F48: =E48 -> 111311.64 | G48: =F48 -> 111311.64 | H48: =G48 -> 111311.64 | I48: =H48 -> 111311.64 | J48: =I48 -> 111311.64 | K48: =J48 -> 111311.64 | L48: =K48 -> 111311.64 | ... AC48: =AB48 -> 111311.64
A49: Deuda/EBITDA | B49: =B48/B41 -> 1.6913846 | C49: =C48/C41 -> 1.699941 | D49: =D48/D41 -> 10.038448 | E49: =E48/E41 -> 9.7109196
A50: FNP | B50: =OP!F34 -> 29 | C50: =OP!F35 -> 112 | D50: =D41-D42-D43-D45-D47+D48-C48 -> -2949.052 | E50: =E41-E42-E43-E45-E47+E48-D48 -> -1931.8892 | F50: =F41-F42-F43-F45-F47+F48-E48 -> -2218.2972 | G50: =G41-G42-G43-G45-G47+G48-F48 -> -2457.4167 | H50: =H41-H42-H43-H45-H47+H48-G48 -> -2826.9583 | I50: =I41-I42-I43-I45-I47+I48-H48 -> -3247.3211 | J50: =J41-J42-J43-J45-J47+J48-I48 -> -3729.2228 | K50: =K41-K42-K43-K45-K47+K48-J48 -> -4192.6673 | ... AC50: =AC41-AC42-AC43-AC45-AC47+AC48-AB48 -> -11515.97
A51: F(t) | B51: 0 | C51: 0 | D51: =C51*(1+$B$59)+D50 -> -2949.052 | E51: =D51*(1+$B$59)+E50 -> -5125.7126 | F51: =E51*(1+$B$59)+F50 -> -7769.4438 | G51: =F51*(1+$B$59)+G50 -> -10871.724 | H51: =G51*(1+$B$59)+H50 -> -14601.036 | I51: =H51*(1+$B$59)+I50 -> -19060.243 | J51: =I51*(1+$B$59)+J50 -> -24371.466 | K51: =J51*(1+$B$59)+K50 -> -30586.965 | ... AC51: =AB51*(1+$B$59)+AC50 -> -392026.51
AB52: =AB51-AB48 -> -462660.25 | AC52: =AC50/(B59-AC36) -> -239916.05
A53: EPS | C53: =1000000*C46/OP!$C$7 -> 6.3063017e+09 | D53: =1000000*D46/OP!$C$7 -> -2.9180703e+08 | E53: =1000000*E46/OP!$C$7 -> -2.9936872e+08 | F53: =1000000*F46/OP!$C$7 -> -3.1800776e+08
A54: Consenso EPS | C54: 3.3 | D54: 5.6 | E54: 5.6
A55: E$/UN | D55: =$B$61/D46 -> 33.885272 | E55: =$B$61/E46 -> 33.029371 | F55: =$B$61/F46 -> 31.093456
A56: EEV/EBIDA | D56: =($B$61+D48-D51)/D41 -> 1.67247 | E56: =($B$61+E48-E51)/E41 -> 1.8077953 | F56: =($B$61+F48-F51)/F41 -> 1.8623989
C58: "TELP" | D58: CER | E58: D Analista | H58: CP | I58: LP
A59: Tasa de descuento: | B59: =SUM(C59:E59) -> 0.083 | C59: 0.0307 | D59: 0.0523 | E59: 0 | G59: Factor D&A | H59: 1 | I59: 1
G60: Factor CIF | H60: -0.01
A61: VPN*@i% | B61: =C62+C63 -> -95715.457 | C61: Normal | D61: =D31 -> 0.001 | E61: =D32 -> 0.005 | G61: Factor ISR | H61: 0.21 | I61: 0.23
A62: DCF 25Y | B62: =C62/B61 -> 0.65851958 | C62: =AB52/(1+B59)^25 -> -63030.503 | D62: =SUMPRODUCT(E50:AB50,E31:AB31) -> -48350.272 | E62: =SUMPRODUCT(E50:AB50,E32:AB32) -> -46273.006 | G62: Factor inv | H62: 1.2
A63: Perpetuidad | B63: =1-B62 -> 0.34148042 | C63: =AC52/(1+B59)^25 -> -32684.954 | D63: =(AC50/($B$59+D31-$AC$36))*AC31 -> -31287.611 | E63: =(AC50/($B$59+D32-$AC$36))*AC32 -> -26381.67 | G63: Suma D&A | H63: =SUM(40:40) -> 628233.49
A64: VPN/Acción | B64: =1000000*B61/OP!C7 -> -9.8879604e+09 | D64: =1000000*SUM(D62:D63)/OP!C7 -> -8.227054e+09 | E64: =1000000*SUM(E62:E63)/OP!C7 -> -7.5056483e+09 | G64: Suma Inv. | H64: =SUM(47:47) -> 672101.39
B65: =B64/OP!#REF!-1 -> #REF! | D65: =D64/B64-1 -> -0.1679726 | E65: =E64/B64-1 -> -0.24093059 | G65: Inv.+Goodwill | H65: =SUM(47:47)+(OP!E12*OP!E7) -> 673240.99
A67: Duración | B67: =B62*D68+B63*D69 -> 20.92361 | E67: 1 | F67: 2 | G67: 3 | H67: 4 | I67: 5 | J67: 6 | K67: 7 | L67: 8 | M67: 9 | N67: 10 | O67: 11 | P67: 12 | Q67: 13 | R67: 14 | S67: 15 | T67: 16 | U67: 17 | V67: 18 | W67: 19 | X67: 20 | Y67: 21 | Z67: 22 | AA67: 23 | AB67: 24 | AC67: 25
A68: 0.001 | B68: =-$B$67*A68 -> -0.02092361 | D68: =SUM(E68:AB68)/SUMPRODUCT(E50:AB50,E33:AB33) -> 12.043526 | E68: =E67*E50*E33 -> -1783.8312 | F68: =F67*F50*F33 -> -3782.6208 | G68: =G67*G50*G33 -> -5803.8301 | H68: =H67*H50*H33 -> -8219.8818 | I68: =I67*I50*I33 -> -10898.154 | J68: =J67*J50*J33 -> -13867.521 | K68: =K67*K50*K33 -> -16795.357 | L68: =L67*L50*L33 -> -19373.484 | ... AC68: =AC67*AC50*AC33 -> -39221.945
A69: 0.005 | B69: =-$B$67*A69 -> -0.10461805 | D69: =(1+B59)/B59+AC67 -> 38.048193

Sheet DCFF
C1: VALUATION MODEL
C2: Año fiscal de Apple cierra en septiembre
G3: 0 | H3: 0.25 | I3: =H3+1 -> 1.25 | J3: =I3+1 -> 2.25 | K3: =J3+1 -> 3.25 | L3: =K3+1 -> 4.25 | M3: =L3+1 -> 5.25 | N3: =M3+1 -> 6.25 | O3: =N3+1 -> 7.25 | P3: =O3+1 -> 8.25 | ... AF3: =AE3+1 -> 24.25
A4: Section | B4: Line # | C4: ITEM | D4: 2020 (Real) | E4: 2021 (Real) | F4: 2022 (Real) | G4: 2023 (Real) | H4: 2024 | I4: =+H4+1 -> 2025 | J4: =+I4+1 -> 2026 | K4: =+J4+1 -> 2027 | L4: =+K4+1 -> 2028 | M4: =+L4+1 -> 2029 | N4: =+M4+1 -> 2030 | O4: =+N4+1 -> 2031 | P4: =+O4+1 -> 2032 | ... AF4: =+AE4+1 -> 2048 | AG4: Notes
A5: INCOME STATEMENT | B5: 1 | C5: Growth | D5: =Cifras_en_Millones!F6 -> 0.4168798 | E5: =Cifras_en_Millones!E6 -> 1.1137184 | F5: =Cifras_en_Millones!D6 -> 0.23206661 | G5: =Cifras_en_Millones!C6 -> 0.073817363 | H5: 0.086 | I5: 0.09 | J5: 0.09 | K5: 0.07 | L5: 0.055 | M5: 0.055 | N5: 0.055 | O5: 0.05 | P5: 0.05 | Q5: 0.05 | R5: 0.03 | S5: 0.03 | T5: 0.03 | U5: 0.03 | V5: 0.03 | W5: 0.02 | X5: 0.02 | Y5: 0.02 | Z5: 0.02 | AA5: 0.02 | AB5: 0.02 | AC5: 0.02 | AD5: 0.02 | AE5: 0.02 | AF5: 0.02
B6: 2 | C6: Revenues/Sales | D6: =Cifras_Originales!F6 -> 221.6 | E6: =Cifras_Originales!E6 -> 468.4 | F6: =Cifras_Originales!D6 -> 577.1 | G6: =Cifras_Originales!C6 -> 619.7 | H6: =G6*(1+H5) -> 672.9942 | I6: =H6*(1+I5) -> 733.56368 | J6: =I6*(1+J5) -> 799.58441 | K6: =J6*(1+K5) -> 855.55532 | L6: =K6*(1+L5) -> 902.61086 | M6: =L6*(1+M5) -> 952.25446 | N6: =M6*(1+N5) -> 1004.6285 | O6: =N6*(1+O5) -> 1054.8599 | ... AF6: =AE6*(1+AF5) -> 1643.4678
B7: 3 | C7: EBIT/Operating Margin | D7: =Cifras_en_Millones!F12 -> -0.24368231 | E7: =Cifras_en_Millones!E12 -> -0.17292912 | F7: =Cifras_en_Millones!D12 -> -0.19407382 | G7: =Cifras_en_Millones!C12 -> -0.25013555 | H7: 0.1 | I7: 0.11 | J7: 0.12 | K7: 0.13 | L7: 0.14 | M7: 0.15 | N7: 0.15 | O7: 0.15 | P7: 0.15 | Q7: 0.15 | R7: 0.15 | S7: 0.15 | T7: 0.15 | U7: 0.15 | V7: 0.15 | W7: 0.15 | X7: 0.15 | Y7: 0.15 | Z7: 0.15 | AA7: 0.15 | AB7: 0.15 | AC7: 0.15 | AD7: 0.15 | AE7: 0.15 | AF7: 0.15
B8: 4 | C8: EBIT | D8: =D6*D7 -> -54 | E8: =E6*E7 -> -81 | F8: =F6*F7 -> -112 | G8: =G7*G6 -> -155.009 | H8: =H7*H6 -> 67.29942 | I8: =I7*I6 -> 80.692005 | J8: =J7*J6 -> 95.950129 | K8: =K7*K6 -> 111.22219 | L8: =L7*L6 -> 126.36552 | M8: =M7*M6 -> 142.83817 | N8: =N7*N6 -> 150.69427 | ... AF8: =AF7*AF6 -> 246.52018
B9: 5a | C9: (Dep&Amort) | D9: =Cifras_Originales!F11 -> -49.2 | E9: =Cifras_Originales!E11 -> -146.88 | F9: =Cifras_Originales!D11 -> -216.1 | G9: =Cifras_Originales!C11 -> -240.8 | H9: {=(G9-164)*0.7+0.3*(0.1921*AVERAGE(-1*(F22:G22)))} -> -278.76401 | I9: {=H9*0.7+0.3*(-$D$50*AVERAGE(-1*(F22:H22)))} -> -190.58431 | J9: {=I9*0.7+0.3*(-$D$50*AVERAGE(-1*(F22:I22)))} -> -129.05534 | K9: {=J9*0.7+0.3*(-$D$50*AVERAGE(-1*(G22:J22)))} -> -86.324753 | L9: {=K9*0.7+0.3*(-$D$50*AVERAGE(-1*(H22:K22)))} -> -56.223815 | M9: {=L9*0.7+0.3*(-$D$50*AVERAGE(-1*(I22:L22)))} -> -35.264182 | N9: {=M9*0.7+0.3*(-$D$50*AVERAGE(-1*(J22:M22)))} -> -20.447664 | O9: {=N9*0.7+0.3*(-$D$50*AVERAGE(-1*(K22:N22)))} -> -9.9562923 | P9: {=O9*0.7+0.3*(-$D$50*AVERAGE(-1*(L22:O22)))} -> -2.5070415 | Q9: {=P9*0.7+0.3*(-$D$50*AVERAGE(-1*(M22:P22)))} -> 2.941125 | ... AF9: {=AE9*0.7+0.3*(-$D$50*AVERAGE(-1*(AB22:AE22)))} -> 22.648165
B10: 5b | C10: (Stock based compensation) | D10: =D19 -> -28.5 | E10: =E19 -> -40.7 | F10: =F19 -> -64.12 | G10: =G19 -> -72.617 | H10: -75 | I10: =-$D$51*I6 -> -81.790759 | J10: =-$D$51*J6 -> -89.151927 | K10: =-$D$51*K6 -> -95.392562 | L10: =-$E$51*L6 -> -100.63915 | M10: =-$E$51*M6 -> -106.17431 | N10: =-$E$51*N6 -> -112.01389 | O10: =-$E$51*O6 -> -117.61459 | P10: =-$E$51*P6 -> -123.49532 | Q10: =-$E$51*Q6 -> -129.67008 | R10: =-$E$51*R6 -> -133.56019 | S10: =-$E$51*S6 -> -137.56699 | ... AF10: =-$E$51*AF6 -> -183.2431
B11: 6 | C11: EBIDTA | D11: =D9+D8 -> -103.2 | E11: =E9+E8 -> -227.88 | F11: =F9+F8 -> -328.1 | G11: =G9+G8 -> -395.809 | H11: =H9+H8 -> -211.46459 | I11: =I9+I8 -> -109.8923 | J11: =J9+J8 -> -33.105214 | K11: =K9+K8 -> 24.897438 | ... AF11: =AF9+AF8 -> 269.16834
B12: 7 | C12: (Net financing cost) | D12: =Cifras_Originales!F9 -> 0.05 | E12: =Cifras_Originales!E9 -> -19.5 | F12: =Cifras_Originales!D9 -> -29.3 | G12: =Cifras_Originales!C9 -> -32.4 | H12: =-$D$53*G37+G36*$D$54 -> -40.844196 | I12: =-$D$53*H37+H36*$D$54 -> -55.345245 | J12: =-$D$53*I37+I36*$D$54 -> -76.266301 | K12: =-$D$53*J37+J36*$D$54 -> -80.547074 | L12: =-$D$53*K37+K36*$D$54 -> -86.05946 | M12: =-$D$53*L37+L36*$D$54 -> -89.25066 | N12: =-$D$53*M37+M36*$D$54 -> -89.297157 | O12: =-$D$53*N37+N36*$D$54 -> -100.00259 | ... AF12: =-$D$53*AE37+AE36*$D$54 -> -102.09247
B13: 8 | C13: Other income/(cost) | D13: =Cifras_Originales!F10 -> -0.4 | E13: =Cifras_Originales!E10 -> -156.6 | F13: =Cifras_Originales!D10 -> 42 | G13: =Cifras_Originales!C10 -> 38 | H13: 0 | I13: =H13*(1+I5) -> 0 | J13: =I13*(1+J5) -> 0 | K13: =J13*(1+K5) -> 0 | L13: =K13*(1+L5) -> 0 | M13: =L13*(1+M5) -> 0 | N13: =M13*(1+N5) -> 0 | O13: =N13*(1+O5) -> 0 | P13: =O13*(1+P5) -> 0 | ... AF13: =AE13*(1+AF5) -> 0
B14: 9 | C14: Earnings before taxes | D14: =D8+D12+D13 -> -54.35 | E14: =E8+E12+E13 -> -257.1 | F14: =F8+F12+F13 -> -99.3 | G14: =G8+G12+G13 -> -149.409 | H14: =H8+H12+H13 -> 26.455224 | I14: =I8+I12+I13 -> 25.34676 | J14: =J8+J12+J13 -> 19.683828 | K14: =K8+K12+K13 -> 30.675117 | ... AF14: =AF8+AF12+AF13 -> 144.42771
B15: 10 | C15: (Income tax) | D15: =Cifras_Originales!F15 -> -0.69 | E15: =Cifras_Originales!E15 -> 95 | F15: =Cifras_Originales!D15 -> 5.27 | G15: =Cifras_Originales!C15 -> -1.6 | H15: -3.698 | I15: =(-1*$D$52)*I14 -> -1.7742732 | J15: =(-1*$D$52)*J14 -> -1.377868 | K15: =(-1*$D$52)*K14 -> -2.1472582 | L15: =(-1*$E$52)*L14 -> -10.882636 | M15: =(-1*$E$52)*M14 -> -14.468627 | N15: =(-1*$E$52)*N14 -> -16.57722 | O15: =(-1*$E$52)*O14 -> -15.721127 | P15: =(-1*$E$52)*P14 -> -20.01234 | Q15: =(-1*$E$52)*Q14 -> -20.884204 | R15: =(-1*$E$52)*R14 -> -21.099374 | S15: =(-1*$E$52)*S14 -> -21.655621 | ... AF15: =(-1*$E$52)*AF14 -> -38.99548
B16: 11 | C16: Net income | D16: =D14+D15 -> -55.04 | E16: =E14+E15 -> -162.1 | F16: =F14+F15 -> -94.03 | G16: =G14+G15 -> -151.009 | H16: =H14+H15 -> 22.757224 | I16: =I14+I15 -> 23.572486 | J16: =J14+J15 -> 18.30596 | K16: =K14+K15 -> 28.527859 | ... AF16: =AF14+AF15 -> 105.43222
A18: CASH FLOW STATEMENT | B18: 12 | C18: Operating cash flows before WK | D18: -12 | E18: 126.6 | F18: 192.5 | G18: 214.37 | H18: =H11+H12+H13+H15 -> -256.00678 | I18: =I11+I12+I13+I15 -> -167.01182 | J18: =J11+J12+J13+J15 -> -110.74938 | K18: =K11+K12+K13+K15 -> -57.796894 | L18: =L11+L12+L13+L15 -> -26.800391 | M18: =M11+M12+M13+M15 -> 3.8546994 | N18: =N11+N12+N13+N15 -> 24.372227 | O18: =O11+O12+O13+O15 -> 32.548976 | ... AF18: =AF11+AF12+AF13+AF15 -> 128.08039
B19: 13 | C19: (Stock-based compensation) | D19: -28.5 | E19: -40.7 | F19: -64.12 | G19: -72.617 | H19: -76.519 | I19: =$D$55*I10 -> -9.1194922 | J19: =$D$55*J10 -> -9.9402465 | K19: =$D$55*K10 -> -10.636064 | L19: =$D$55*L10 -> -11.221047 | M19: =$D$55*M10 -> -11.838205 | N19: =$D$55*N10 -> -12.489306 | O19: =$D$55*O10 -> -13.113771 | P19: =$D$55*P10 -> -13.76946 | ... AF19: =$D$55*AF10 -> -20.431208
B20: 14 | C20: (Working Capital Flows) | D20: =Cifras_Originales!F12 -> -10.534 | E20: =Cifras_Originales!E12 -> 48.877 | F20: =Cifras_Originales!D12 -> 43.345 | G20: =Cifras_Originales!C12 -> 80.326 | H20: =Cifras_Originales!C74 -> 70.673 | I20: =$D$56*(I6-H6) -> 60.569478 | J20: =$D$56*0.83*(J6-I6) -> 54.797207 | K20: =$D$56*0.66*(K6-J6) -> 36.9408 | L20: =$E$56*(L6-K6) -> 23.527771 | M20: =$E$56*(M6-L6) -> 24.821799 | N20: =$E$56*(N6-M6) -> 26.186998 | O20: =$E$56*(O6-N6) -> 25.115711 | P20: =$E$56*(P6-O6) -> 26.371497 | Q20: =$E$56*(Q6-P6) -> 27.690072 | R20: =$E$56*(R6-Q6) -> 17.444745 | S20: =$E$56*(S6-R6) -> 17.968088 | ... AF20: =$E$56*(AF6-AE6) -> 16.11243
B21: 15 | C21: -Total Operating Cash Flow | D21: =D18+D19+D20 -> -51.034 | E21: =E18+E19+E20 -> 134.777 | F21: =F18+F19+F20 -> 171.725 | G21: =G18+G19+G20 -> 222.079 | H21: =H18+H19+H20 -> -261.85278 | I21: =I18+I19+I20 -> -115.56183 | J21: =J18+J19+J20 -> -65.892423 | K21: =K18+K19+K20 -> -31.492158 | ... AF21: =AF18+AF19+AF20 -> 123.76161
B22: 16 | C22: (CAPEX and Acquisitions) | D22: =Cifras_Originales!F13-21 -> -35.3 | E22: =Cifras_Originales!E13-691 -> -708.7 | F22: =Cifras_Originales!D13-65 -> -95.8 | G22: =Cifras_Originales!C13-37 -> -63.7 | H22: -80 | I22: =-$D$57*I6 -> -66.020731 | J22: =-$D$57*J6 -> -71.962597 | K22: =-$D$57*K6 -> -76.999979 | L22: =-$E$57*L6 -> -72.208869 | M22: =-$E$57*M6 -> -76.180357 | N22: =-$E$57*N6 -> -80.370276 | O22: =-$E$57*O6 -> -84.38879 | P22: =-$E$57*P6 -> -88.60823 | Q22: =-$E$57*Q6 -> -93.038641 | R22: =-$E$57*R6 -> -95.8298 | S22: =-$E$57*S6 -> -98.704694 | ... AF22: =-$E$57*AF6 -> -131.47743
B23: 17 | C23: (Other investing flows) | D23: =D24-D22 -> 67.3 | E23: =E24-E22 -> 17.7 | F23: =F24-F22 -> 30.8 | G23: =G24-G22 -> 26.3 | H23: =AVERAGE(D23,E23,F23,G23)*(1+H5) -> 38.58015 | I23: =AVERAGE(E23,F23,G23,H23)*(1+I5) -> 30.896091 | J23: =AVERAGE(F23,G23,H23,I23)*(1+J5) -> 34.492026 | K23: =AVERAGE(G23,H23,I23,J23)*(1+K5) -> 34.846761 | L23: =AVERAGE(H23,I23,J23,K23)*(1+L5) -> 36.612464 | M23: =AVERAGE(I23,J23,K23,L23)*(1+M5) -> 36.093486 | N23: =AVERAGE(J23,K23,L23,M23)*(1+N5) -> 37.464299 | O23: =AVERAGE(K23,L23,M23,N23)*(1+O5) -> 38.066965 | ... AF23: =AVERAGE(AB23,AC23,AD23,AE23)*(1+AF5) -> 44.969154
B24: 18 | C24: -Total Investing Flows | D24: 32 | E24: -691 | F24: -65 | G24: -37.4 | H24: =H22+H23 -> -41.41985 | I24: =I22+I23 -> -35.12464 | J24: =J22+J23 -> -37.470571 | K24: =K22+K23 -> -42.153217 | L24: =L22+L23 -> -35.596405 | M24: =M22+M23 -> -40.08687 | N24: =N22+N23 -> -42.905977 | O24: =O22+O23 -> -46.321825 | ... AF24: =AF22+AF23 -> -86.508274
B25: 19 | C25: (Flows related to leases) | D25: 0 | E25: 0 | F25: 0 | G25: 0 | H25: 0 | I25: 0 | J25: 0 | K25: 0 | L25: 0 | M25: 0 | N25: 0 | O25: 0 | P25: 0 | Q25: 0 | R25: 0 | S25: 0 | T25: 0 | U25: 0 | V25: 0 | W25: 0 | X25: 0 | Y25: 0 | Z25: 0 | AA25: 0 | AB25: 0 | AC25: 0 | AD25: 0 | AE25: 0 | AF25: 0
B26: 20 | C26: Flows related to debt | D26: 0 | E26: 749 | F26: -3.6 | G26: -3.6 | H26: =(H37-G37) -> 52.693804 | I26: =(I37-H37) -> 333.80262 | J26: =(J37-I37) -> 2.7411122 | K26: =(K37-J37) -> 56.228046 | L26: =(L37-K37) -> 23.614284 | M26: =(M37-L37) -> 0 | N26: =(N37-M37) -> 226.72617 | O26: =(O37-N37) -> -190.42087 | ... AF26: =(AF37-AE37) -> 26.593883
B27: 21 | C27: (Respurchases)/Issuance of stock | D27: 0 | E27: 0 | F27: 0 | G27: 0 | H27: =-50*1% -> -0.5 | I27: =-5*3% -> -0.15 | J27: =-12*5% -> -0.6 | K27: =-21*7% -> -1.47 | L27: =-32*10.5% -> -3.36 | M27: =(M21+M24+M28)*-0.95 -> 22.086148 | N27: -10 | O27: -11 | P27: -13 | Q27: -15 | R27: -16 | S27: -17 | T27: -19 | U27: -21 | V27: -22 | W27: -24 | X27: -26 | Y27: -28 | Z27: -31 | AA27: -33 | AB27: -35 | AC27: -38 | AD27: -41 | AE27: -44 | AF27: -45
B28: 22 | C28: (Dividends) | D28: 0 | E28: 0 | F28: 0 | G28: 0 | H28: =(1+$D$58)*G28 -> 0 | I28: =(1+$D$58)*H28 -> 0 | J28: =(1+$D$58)*I28 -> 0 | K28: =(1+$D$58)*J28 -> 0 | L28: =(1+$E$58)*K28 -> 0 | M28: =(1+$E$58)*L28 -> 0 | N28: =(1+$E$58)*M28 -> 0 | O28: =(1+$E$58)*N28 -> 0 | P28: =(1+$E$58)*O28 -> 0 | Q28: =(1+$E$58)*P28 -> 0 | R28: =(1+$E$58)*Q28 -> 0 | S28: =(1+$E$58)*R28 -> 0 | ... AF28: =(1+$E$58)*AE28 -> 0
B29: 23 | C29: Other financing flows | D29: =7 -> 7 | E29: =E30-E26 -> -71 | F29: -26 | G29: -174 | H29: 0 | I29: 0 | J29: 0 | K29: 0 | L29: 0 | M29: 0 | N29: 0 | O29: 0 | P29: 0 | Q29: 0 | R29: 0 | S29: 0 | T29: 0 | U29: 0 | V29: 0 | W29: 0 | X29: 0 | Y29: 0 | Z29: 0 | AA29: 0 | AB29: 0 | AC29: 0 | AD29: 0 | AE29: 0 | AF29: 0
B30: 24 | C30: -Total Financing flows | D30: 7 | E30: 678 | F30: -30.2 | G30: -177.8 | H30: =SUM(H25:H29) -> 52.193804 | I30: =SUM(I25:I29) -> 333.65262 | J30: =SUM(J25:J29) -> 2.1411122 | K30: =SUM(K25:K29) -> 54.758046 | L30: =SUM(L25:L29) -> 20.254284 | M30: =SUM(M25:M29) -> 22.086148 | N30: =SUM(N25:N29) -> 216.72617 | O30: =SUM(O25:O29) -> -201.42087 | ... AF30: =SUM(AF25:AF29) -> -18.406117
A32: SUMMARY | B32: 25 | C32: Cash before shareholder returns | D32: =D21+D24+D25+D26+D29 -> -12.034 | E32: =E21+E24+E25+E26+E29 -> 121.777 | F32: =F21+F24+F25+F26+F29 -> 77.125 | G32: =G21+G24+G25+G26+G29 -> 7.079 | H32: =H21+H24+H25+H26+H29 -> -250.57883 | I32: =I21+I24+I25+I26+I29 -> 183.11615 | J32: =J21+J24+J25+J26+J29 -> -100.62188 | K32: =K21+K24+K25+K26+K29 -> -17.41733 | ... AF32: =AF21+AF24+AF25+AF26+AF29 -> 63.84722
B33: 26 | C33: Returns to shareholders | D33: =-1*(D27+D28) -> 0 | E33: =-1*(E27+E28) -> 0 | F33: =-1*(F27+F28) -> 0 | G33: =-1*(G27+G28) -> 0 | H33: =-1*(H27+H28) -> 0.5 | I33: =-1*(I27+I28) -> 0.15 | J33: =-1*(J27+J28) -> 0.6 | K33: =-1*(K27+K28) -> 1.47 | ... AF33: =-1*(AF27+AF28) -> 45
B34: 27 | C34: Excess cash acumulation | D34: =D32-D33 -> -12.034 | E34: =E32-E33 -> 121.777 | F34: =F32-F33 -> 77.125 | G34: =G32-G33 -> 7.079 | H34: =H32-H33 -> -251.07883 | I34: =I32-I33 -> 182.96615 | J34: =J32-J33 -> -101.22188 | K34: =K32-K33 -> -18.88733 | ... AF34: =AF32-AF33 -> 18.84722
A36: CASH & DEBT & DISCOUNTING | B36: 28 | C36: Ending cash balance | D36: 56 | E36: =D36+E34 -> 177.777 | F36: =E36+F34 -> 254.902 | G36: =F36+G34 -> 261.981 | H36: =G36+H34 -> 10.902171 | I36: =H36+I34 -> 193.86832 | J36: =I36+J34 -> 92.646437 | K36: =J36+K34 -> 73.759107 | L36: =K36+L34 -> 43.923319 | ... AF36: =AE36+AF34 -> 256.74458
B37: 29 | C37: Total Debt | D37: =Cifras_en_Millones!F60 -> 42.1 | E37: =Cifras_en_Millones!E60 -> 809.2 | F37: =Cifras_en_Millones!D60 -> 813.7 | G37: =Cifras_en_Millones!C60 -> 606.66 | H37: =I11*-6 -> 659.3538 | I37: =J11*-30 -> 993.15643 | J37: =K11*40 -> 995.89754 | K37: =L11*15 -> 1052.1256 | L37: =M11*10 -> 1075.7399 | M37: =M11*10 -> 1075.7399 | N37: =N11*10 -> 1302.466 | O37: =O11*7.5 -> 1112.0452 | P37: =P11*7.5 -> 1227.2504 | Q37: =Q11*7.5 -> 1330.4143 | R37: =R11*7.5 -> 1400.0696 | S37: =S11*7.5 -> 1463.4333 | T37: =T11*7.5 -> 1522.6591 | U37: =U11*7.5 -> 1579.2543 | V37: =V11*5 -> 1089.5152 | W37: =W11*5 -> 1115.6547 | X37: =X11*5 -> 1141.2296 | Y37: =Y11*5 -> 1166.4846 | Z37: =Z11*5 -> 1191.5901 | AA37: =AA11*5 -> 1216.665 | AB37: =AB11*5 -> 1241.8684 | AC37: =AC11*5 -> 1267.3149 | ... AF37: =AF11*5 -> 1345.8417
B38: 30 | C38: Discount factor | G38: =1/((1+$D$47)^G3) -> 1 | H38: =1/((1+$D$47)^H3) -> 0.97981157 | I38: =1/((1+$D$47)^I3) -> 0.90305214 | J38: =1/((1+$D$47)^J3) -> 0.83230612 | K38: =1/((1+$D$47)^K3) -> 0.76710242 | L38: =1/((1+$D$47)^L3) -> 0.70700684 | M38: =1/((1+$D$47)^M3) -> 0.6516192 | N38: =1/((1+$D$47)^N3) -> 0.60057069 | ... AH38: =1/((1+$D$47)^AH3) -> 1
F39: =1/((1+$D$48+0.001)^F$3) -> 1 | G39: =1/((1+$D$47+0.001)^G$3) -> 1 | H39: =1/((1+$D$47+0.001)^H$3) -> 0.97958594 | I39: =1/((1+$D$47+0.001)^I$3) -> 0.90201284 | J39: =1/((1+$D$47+0.001)^J$3) -> 0.83058272 | K39: =1/((1+$D$47+0.001)^K$3) -> 0.76480914 | L39: =1/((1+$D$47+0.001)^L$3) -> 0.70424414 | M39: =1/((1+$D$47+0.001)^M$3) -> 0.64847527 | N39: =1/((1+$D$47+0.001)^N$3) -> 0.59712271 | ... AE39: =1/((1+$D$47+0.001)^AE$3) -> 0.14687794
F40: =1/((1+$D$48+0.005)^F$3) -> 1 | G40: =1/((1+$D$47+0.005)^G$3) -> 1 | H40: =1/((1+$D$47+0.005)^H$3) -> 0.978686 | I40: =1/((1+$D$47+0.005)^I$3) -> 0.89787706 | J40: =1/((1+$D$47+0.005)^J$3) -> 0.82374043 | K40: =1/((1+$D$47+0.005)^K$3) -> 0.75572516 | L40: =1/((1+$D$47+0.005)^L$3) -> 0.69332584 | M40: =1/((1+$D$47+0.005)^M$3) -> 0.63607875 | N40: =1/((1+$D$47+0.005)^N$3) -> 0.58355848 | ... AE40: =1/((1+$D$47+0.005)^AE$3) -> 0.13484471
C42: EPS | H42: =1000000*H16/OP!C7 -> 2350952.9 | I42: =1000000*I16/OP!$C7 -> 2435174.2 | J42: =1000000*J16/OP!$C7 -> 1891111.6
C43: Consenso EPS
C44: E$/UN | H44: =$D$64/H16 -> 3.7595109 | I44: =$D$64/I16 -> 3.6294869
...

Sheet Cifras_en_Millones
A1: =Cifras_Originales!H3 -> MAGNITE, INC.
A2: =Cifras_Originales!D2 -> Cifras en Millones de USD
A4: Resultados | B4: 2024 | C4: =Cifras_Originales!C5 -> 2023 | D4: =Cifras_Originales!D5 -> 2022 | E4: =Cifras_Originales!E5 -> 2021 | F4: =Cifras_Originales!F5 -> 2020 | G4: =Cifras_Originales!G5 -> 2019 | H4: =Cifras_Originales!H5 -> 2018 | I4: =Cifras_Originales!I5 -> 2017 | J4: =Cifras_Originales!J5 -> 2016 | ... M4: =Cifras_Originales!M5 -> 2013
A5: Ventas Netas | B5: =Cifras_Originales!B6 -> 668.17 | C5: =Cifras_Originales!C6 -> 619.7 | D5: =Cifras_Originales!D6 -> 577.1 | E5: =Cifras_Originales!E6 -> 468.4 | F5: =Cifras_Originales!F6 -> 221.6 | G5: =Cifras_Originales!G6 -> 156.4 | H5: =Cifras_Originales!H6 -> 124.6 | I5: =Cifras_Originales!I6 -> 155.5 | ... M5: =Cifras_Originales!M6 -> 83.4
A6: Crecimiento vs. Año pasado | B6: =B5/C5-1 -> 0.078215265 | C6: =C5/D5-1 -> 0.073817363 | D6: =D5/E5-1 -> 0.23206661 | E6: =E5/F5-1 -> 1.1137184 | F6: =F5/G5-1 -> 0.4168798 | G6: =G5/H5-1 -> 0.25521669 | H6: =H5/I5-1 -> -0.19871383 | I6: =I5/J5-1 -> -0.4410496 | ... L6: =L5/M5-1 -> 0.50239808
