Workbook
Name Sectors: '[1]Sector Impact'!$K$4:$K$16
Name Sectors: 'Sector Impact'!$K$4:$K$16

Sheet OP
B2: (Date of last update) | C2: Team 1 | D2: (Date of next Quarter/Annual Report) | E2: =Inputs!H3 -> #VALUE! | L2: {=_FV(E2,"Exchange")} -> London Stock Exchange | M2: SIC:
B3: #VALUE! | D3: COMPANY DESCRIPTION | H3: CEO & BOARD OF DIRECTORS
D4: {=_FV(Inputs!H3,"Description")} -> NEXT plc is a United Kingdom-based retailer selling clothing, homeware, and beauty products. The Company’s segments include NEXT Online, NEXT Finance, NEXT Retail, Total Platform, and Other Business Activities. The NEXT Online segment includes NEXT Online (UK) and NEXT Online (International). Its Total Platform brands include Reiss, FatFace and Joules. Other Business Activities (all other segments) which include the Property Management segment which holds property and property leases. The Company’s subsidiaries include Agratech Limited, Bridgetown Holdco Limited, Lipsy Limited, Next Beauty Limited, Next Brand Limited, Next Distribution Limited, Next Holdings Limited, Next Manufacturing Limited, Next Near East Limited, Next Properties Limited, Next Retail Limited, The Next Directory Limited, and Project Norwich Limited. | H4: Name, Age and Tenure | I4: Gender | J4: Executive? | L4: Other roles
H5: Lord Simon A. Wolfson, 56, 2001 | I5: M | J5: Y | L5: CEO & Executive Director
H6: Richard S V. Papp,57, 2018 | I6: M | J6: Y | L6: Group Merchandise & Operations Director and Executive Director
H7: Jeremy Stakol, 54, 2023 | I7: M | J7: Y | L7: Group Investments, Acquisitions & Third Party Brands Director and Executive Director
H8: Jane Shields, 60, 2013 | I8: F | J8: Y | L8: Group Sales, Marketing and HR Director
H9: Venetia Butterfield, 54, 2024 | I9: F | J9: N | L9: Independent Non-executive Director
H10: Jonathan Blanchard FCCA, 59, 2024 | I10: M | J10: Y | L10: CFO & Director
H11: Soumen Das, 48, 2021 | I11: M | J11: N | L11: Independent Non-Executive Director
H12: Michael Roney, 70, 2017 | I12: M | J12: Y | L12: Chairman
H13: Amy Stirling, 55 , 2024 | I13: F | J13: N | L13: Independent Non-executive Director
H14: Dame Tristia Harrison, 51, 2018 | I14: F | J14: N | L14: Independent Non-Executive Director
H15: Tom Hall, 57, 2020 | I15: M | J15: N | L15: Independent Non-Executive Director
B16: {=_FV(E2,"Currency")&" MILLIONS"} -> GBp MILLIONS | H16: Jonathan Bewes, 59, 2016 | I16: M | J16: N | L16: Senior Independent Director
B17: COMPANY OVERVIEW
B18: Stock | D18: Liquidity and Solvency | F18: Segments | I18: ="Profitability ("&J19&")" -> Profitability (2023) | L18: Multiples
B19: Last Price | C19: {=_FV(E2,"Price")} -> 13435 | D19: Total Assets | E19: =_xlfn.XLOOKUP(D19,'Fin. Data'!A:A,'Fin. Data'!B:B,,0) -> 4724.3 | F19: Regions | H19: % Sales | I19: Reporting Year | J19: 2023 | L19: Float | M19: =IF(Inputs!B82 <> "",Inputs!B82,"") -> 0.88814229
B20: Outstanding Shares | C20: {=_FV(E2,"Shares outstanding",TRUE)} -> 122436600 | D20: Total Liabilities | E20: =_xlfn.XLOOKUP(D20,'Fin. Data'!A:A,'Fin. Data'!B:B,,0) -> 3212.4 | F20: =Segments!C5 -> United Kingdom | H20: =Segments!B5 -> 0.83784374 | I20: End of Year | J20: 45291 | L20: Insiders Own | M20: =IF(Inputs!B83 <> "",Inputs!B83,"") -> 0.0699
B21: Market Cap. | C21: =C19*C20/1000000 -> 1644935.7 | D21: Cash/Share | E21: =_xlfn.XLOOKUP("Cash & Eq.",'Fin. Data'!A:A,'Fin. Data'!B:B,,0)*1000000/C20 -> 1.5379388 | F21: =Segments!C6 -> Rest of Europe | H21: =Segments!B6 -> 0.09504644 | I21: EBITDA | K21: =_xlfn.XLOOKUP(I21,'Fin. Data'!A:A,'Fin. Data'!B:B,,0) -> 1101.5 | L21: b (Yahoo) | M21: {=IF(_FV(E2,"Beta") <> "",_FV(E2,"Beta"),"")} -> 1.3444
B22: +Total Debt | C22: ='Fin. Data'!B58 -> 1916.7 | D22: EBITDA/Net Financial Cost (NFC) | E22: =IFERROR(_xlfn.XLOOKUP("EBITDA",'Fin. Data'!A:A,'Fin. Data'!B:B,,0)/_xlfn.XLOOKUP("Net Financial Cost",'Fin. Data'!A:A,'Fin. Data'!B:B,,0),"") -> -13.649318 | F22: =Segments!C7 -> Middle East | H22: =Segments!B7 -> 0.046439628 | I22: Depreciation & Amortization | K22: =_xlfn.XLOOKUP(I22,'Fin. Data'!A:A,'Fin. Data'!B:B,,0) -> 246.8 | L22: Score (S&P) | M22: =IF(Inputs!B84 <> "",Inputs!B84,"") -> BBB
B23: -Cash | C23: ='Fin. Data'!B39 -> 188.3 | D23: Debt/EBITDA | E23: =IFERROR(_xlfn.XLOOKUP("Total Debt",'Fin. Data'!A:A,'Fin. Data'!B:B,,0)/_xlfn.XLOOKUP("EBITDA",'Fin. Data'!A:A,'Fin. Data'!B:B,,0),"") -> 1.7400817 | F23: =Segments!C8 -> Asia | H23: =Segments!B8 -> 0.0076306684 | I23: EBIT | K23: =_xlfn.XLOOKUP(I23,'Fin. Data'!A:A,'Fin. Data'!B:B,,0) -> 854.7 | L23: Price/Book Value | M23: =IFERROR((C19*C20/(E19-E20))/1000000,"") -> 1087.9924
B24: =Enterprise Value | C24: =C21+C22-C23 -> 1646664.1 | D24: "Others Assets"/Asset | E24: =IFERROR(_xlfn.XLOOKUP("Other Assets",'Fin. Data'!A:A,'Fin. Data'!B:B,,0)/_xlfn.XLOOKUP("Total Assets",'Fin. Data'!A:A,'Fin. Data'!B:B,,0),"") -> 0.21982093 | F24: =Segments!C9 -> Rest of world | H24: =Segments!B9 -> 0.013039519 | I24: Net Income | K24: =_xlfn.XLOOKUP(I24,'Fin. Data'!A:A,'Fin. Data'!B:B,,0) -> 800.5 | L24: NCF(3y avg)/Asset | M24: =IFERROR(K30/E19,"") -> -0.016595051
B25: Holdings (nac/int'l) | C25: - | D25: Debt/Assets | E25: =_xlfn.XLOOKUP(D25,'Fin. Data'!A:A,'Fin. Data'!B:B,,0) -> 0.4057109 | F25: Categories | H25: % Sales | I25: EPS | K25: =1000000*K24/C20 -> 6.5380777 | L25: Price/Net Inc. (3y avg) | M25: =IFERROR(C21/K29,"") -> 2254.675
B26: t liq. (Holdings/Vol.) | C26: - | D26: EBITDA Margin (average) | E26: =IFERROR(AVERAGE(_xlfn.XLOOKUP("EBITDA Margin",'Fin. Data'!A:A,'Fin. Data'!B:D,,0)),"") -> 0.2222314 | F26: =Segments!C18 -> NEXT Online | H26: =Segments!B18 -> 0.52839191 | I26: ROA | K26: =IFERROR(K24/E19,"") -> 0.16944309 | L26: EV/Asset | M26: =IFERROR(C24/E19,"") -> 348.55198
B27: % Short | C27: 0 | D27: Operating Margin (average) | E27: =IFERROR(AVERAGE(_xlfn.XLOOKUP("Operating Margin",'Fin. Data'!A:A,'Fin. Data'!B:D,,0)),"") -> 0.18770746 | I27: ROIC | K27: =IFERROR(Peers!C18,"") -> 0.23796645 | L27: EV/Ebitda (3y average) | M27: =IFERROR(C24/K28,"") -> 1474.5806
B28: Traffic ESG | D28: Net Income Margin (average) | E28: =IFERROR(AVERAGE(_xlfn.XLOOKUP("Net Income Margin",'Fin. Data'!A:A,'Fin. Data'!B:D,,0)),"") -> 0.14447399 | F28: =Segments!C19 -> NEXT Retail | H28: =Segments!B19 -> 0.33576762 | I28: EBITDA (3y average) | K28: =AVERAGE(_xlfn.XLOOKUP("EBITDA",'Fin. Data'!A:A,'Fin. Data'!B:D,,0)) -> 1116.7 | L28: Price/NCF (3y average) | M28: =IFERROR(C21/K30,"") -> -20981.323
B29: E | I29: Net Income (3y average) | K29: =AVERAGE(_xlfn.XLOOKUP("Net Income",'Fin. Data'!A:A,'Fin. Data'!B:D,,0)) -> 729.56667 | L29: Bonds 1,3,5a (USD) | M29: -
B30: S | D30: Net Financial Cost/Avg Net Debt | E30: =IFERROR(-_xlfn.XLOOKUP("Net Financial Cost",'Fin. Data'!A:A,'Fin. Data'!B:B,,0)/AVERAGE(_xlfn.XLOOKUP("Net Debt",'Fin. Data'!A:A,'Fin. Data'!B:D,,0)),"") -> 0.046846882 | F30: =Segments!C20 -> NEXT Finance | H30: =Segments!B20 -> 0.053305409 | I30: NCF (3y average) | K30: =AVERAGE(_xlfn.XLOOKUP("Net Financial Cost",'Fin. Data'!A:A,'Fin. Data'!B:D,,0)) -> -78.4 | L30: Div+Rep.(3y avg)/Price | M30: =-IFERROR(SUM(E51:E53)/(3*C21),"") -> 0.0002522287
B31: G | F31: =Segments!C21 -> Other | H31: =Segments!B21 -> 0.082535057 | L31: Div. Yield | M31: =-IFERROR(L52/C21,"") -> 0.00015094815
B32: INVESTMENT THESIS
B33: Pillars of Recommendation | H33: Recommendation | I33: Valuation Assumptions
B34: Pillar | C34: Explanation | H34: Hold | I34: Check DCF
B35: Board resilience | C35: The leadership team shifted their focus away from retail growth after recognizing that online sales were the primary driver of the company's future growth. As another example, they also adapted their distribution strategy, leading to significant changes in how the warehouses operated. These decisions illustrate the CEO’s ability to identify key growth drivers and respond with strategic adjustments.
B36: E-commerce and digital | C36: E-commerce and digital will drive growth, meet changing consumer demands and expand its market reach in an increasingly digital retail environment.
B37: Strategic partnerships and product expansion | C37: Strategic partnerships and product expansion will diversify NEXT's revenue streams and enhance market reach, allowing the company to tap into new customer segments and boost overall sales growth.
B38: Risks of Investment | H38: Price Target | I38: Valuation
B39: Risk | C39: Explanation | H39: =IFERROR(DCF!D75,"") -> 9796.5195 | I39: Discount Rate | J39: =DCF!F50 -> 0.085 | L39: Price M. Upside | M39: =IFERROR(#REF!,"")
B40: Heavy dependence on the UK market | C40: Heavy dependence on the UK market exposes NEXT to local economic downturns.
B41: Intense competition either in Retail or ecommerce | C41: Intense competition from established retail and e-commerce players puts pressure on NEXT’s which could lead to margin erosion and impact its ability to maintain strong financial performance. | I41: Upside | J41: =IFERROR(DCF!D74,"") -> -0.27082103 | L41: EV M. Upside | M41: =IFERROR(#REF!,"")
...

Sheet Segments
B2: ="Regions "&"("&OP!$J$19&")" -> Regions (2023) | Q2: Products
D3: Nominal value | K3: YoY Growth
B4: Weight | C4: Region | D4: =OP!J19 -> 2023 | E4: =D4-1 -> 2022 | F4: =E4-1 -> 2021 | G4: =F4-1 -> 2020 | H4: =G4-1 -> 2019 | I4: =H4-1 -> 2018 | K4: =OP!J19 -> 2023 | L4: =K4-1 -> 2022 | M4: =L4-1 -> 2021 | N4: =M4-1 -> 2020 | O4: =N4-1 -> 2019 | P4: =O4-1 -> 2018
B5: =IFERROR(D5/$D$13,"") -> 0.83784374 | C5: United Kingdom | D5: 4600.6 | E5: 4290.7 | F5: 3837.5 | G5: 2931.5 | H5: 3665 | I5: 3656.9 | K5: =(D5-E5)/E5 -> 0.072225977 | L5: =(E5-F5)/F5 -> 0.11809772 | M5: =(F5-G5)/G5 -> 0.3090568 | N5: =(G5-H5)/H5 -> -0.20013643 | O5: =(H5-I5)/I5 -> 0.0022149908 | P5: -
B6: =IFERROR(D6/$D$13,"") -> 0.09504644 | C6: Rest of Europe | D6: 521.9 | E6: 415.3 | F6: 447 | G6: 311.6 | H6: 317.6 | I6: 279.2 | K6: =(D6-E6)/E6 -> 0.25668192 | L6: =(E6-F6)/F6 -> -0.070917226 | M6: =(F6-G6)/G6 -> 0.43453145 | N6: =(G6-H6)/H6 -> -0.018891688 | O6: =(H6-I6)/I6 -> 0.13753582 | P6: -
B7: =IFERROR(D7/$D$13,"") -> 0.046439628 | C7: Middle East | D7: 255 | E7: 235.6 | F7: 247 | G7: 215.8 | H7: 189.9 | I7: 138.7 | K7: =(D7-E7)/E7 -> 0.082342954 | L7: =(E7-F7)/F7 -> -0.046153846 | M7: =(F7-G7)/G7 -> 0.14457831 | N7: =(G7-H7)/H7 -> 0.13638757 | O7: =(H7-I7)/I7 -> 0.36914203 | P7: -
B8: =IFERROR(D8/$D$13,"") -> 0.0076306684 | C8: Asia | D8: 41.9 | E8: 48.5 | F8: 53 | G8: 43.3 | H8: 58.3 | I8: 56.1 | K8: =(D8-E8)/E8 -> -0.13608247 | L8: =(E8-F8)/F8 -> -0.08490566 | M8: =(F8-G8)/G8 -> 0.22401848 | N8: =(G8-H8)/H8 -> -0.25728988 | O8: =(H8-I8)/I8 -> 0.039215686 | P8: -
B9: =IFERROR(D9/$D$13,"") -> 0.013039519 | C9: Rest of world | D9: 71.6 | E9: 43.9 | F9: 41.4 | G9: 32.2 | H9: 35.4 | I9: 36.5 | K9: =(D9-E9)/E9 -> 0.6309795 | L9: =(E9-F9)/F9 -> 0.060386473 | M9: =(F9-G9)/G9 -> 0.28571429 | N9: =(G9-H9)/H9 -> -0.09039548 | O9: =(H9-I9)/I9 -> -0.030136986 | P9: -
B10: =IFERROR(D10/$D$13,"") -> 0 | K10: =(D10-E10)/E10 -> #DIV/0! | L10: =(E10-F10)/F10 -> #DIV/0! | M10: =(F10-G10)/G10 -> #DIV/0! | N10: =(G10-H10)/H10 -> #DIV/0! | O10: =(H10-I10)/I10 -> #DIV/0! | P10: -
B11: =IFERROR(D11/$D$13,"") -> 0
B12: =IFERROR(D12/$D$13,"") -> 0
B13: =SUM(B5:B12) -> 1 | C13: TOTAL | D13: =SUM(D5:D12) -> 5491 | E13: =SUM(E5:E12) -> 5034 | F13: =SUM(F5:F12) -> 4625.9 | G13: =SUM(G5:G12) -> 3534.4 | H13: =SUM(H5:H12) -> 4266.2 | I13: =SUM(I5:I12) -> 4167.4 | K13: =(D13-E13)/E13 -> 0.090782678 | L13: =(E13-F13)/F13 -> 0.088220671 | M13: =(F13-G13)/G13 -> 0.30882187 | N13: =(G13-H13)/H13 -> -0.17153439 | O13: =(H13-I13)/I13 -> 0.023707827 | P13: -
B15: ="Categories "&"("&OP!$J$19&")" -> Categories (2023)
D16: Nominal value | K16: YoY Growth
B17: Weight | C17: Category | D17: =OP!J19 -> 2023 | E17: =D17-1 -> 2022 | F17: =E17-1 -> 2021 | G17: =F17-1 -> 2020 | H17: =G17-1 -> 2019 | I17: =H17-1 -> 2018 | K17: =OP!J19 -> 2023 | L17: =K17-1 -> 2022 | M17: =L17-1 -> 2021 | N17: =M17-1 -> 2020 | O17: =N17-1 -> 2019 | P17: =O17-1 -> 2018
B18: =IFERROR(D18/$D$22,"") -> 0.52839191 | C18: NEXT Online | D18: =2911.9-10.5 -> 2901.4 | E18: =2744.2-0.6 -> 2743.6 | F18: =2874.4 -> 2874.4 | G18: =2279.5 -> 2279.5 | H18: =2056.3-1.6 -> 2054.7 | I18: =1864.6 -> 1864.6 | K18: =(D18-E18)/E18 -> 0.057515673 | L18: =(E18-F18)/F18 -> -0.045505149 | M18: =(F18-G18)/G18 -> 0.26097828 | N18: =(G18-H18)/H18 -> 0.1094077 | O18: =(H18-I18)/I18 -> 0.10195216 | P18: -
B19: =IFERROR(D19/$D$22,"") -> 0.33576762 | C19: NEXT Retail | D19: =1844.6-0.9 -> 1843.7 | E19: =1849.5-0.4 -> 1849.1 | F19: =1426.1-0.2+49.2 -> 1475.1 | G19: =952.2-0.3+33.2 -> 985.1 | H19: =1851.5-3.3+56.9 -> 1905.1 | I19: =1960.5-4.6+62.2 -> 2018.1 | K19: =(D19-E19)/E19 -> -0.0029203396 | L19: =(E19-F19)/F19 -> 0.25354213 | M19: =(F19-G19)/G19 -> 0.49741143 | N19: =(G19-H19)/H19 -> -0.48291428 | O19: =(H19-I19)/I19 -> -0.055993261 | P19: -
B20: =IFERROR(D20/$D$22,"") -> 0.053305409 | C20: NEXT Finance | D20: =292.7 -> 292.7 | E20: =274.4 -> 274.4 | F20: 249.4 | G20: 250.3 | H20: 268.7 | I20: =250.3 -> 250.3 | K20: =(D20-E20)/E20 -> 0.066690962 | L20: =(E20-F20)/F20 -> 0.10024058 | M20: =(F20-G20)/G20 -> -0.0035956852 | N20: =(G20-H20)/H20 -> -0.068477856 | O20: =(H20-I20)/I20 -> 0.073511786 | P20: -
B21: =IFERROR(D21/$D$22,"") -> 0.082535057 | C21: Other | D21: =363.8+192.4+543.8-170.9-475.9 -> 453.2 | E21: =75.7+175+602.5-156.1-530.2 -> 166.9 | F21: =134.1-130.3+1-0.8+180-167.3+495.5-485.2 -> 27 | G21: =401.4-394.6+79.3-74.1+0.7-0.6+200.6-193.2 -> 19.5 | H21: =542.9-533.4+94.9-81.8+211.3-196.2 -> 37.7 | I21: =550.1-543.2+95.4-80.4+215.4-202.9 -> 34.4 | K21: =(D21-E21)/E21 -> 1.7153984 | L21: =(E21-F21)/F21 -> 5.1814815 | M21: =(F21-G21)/G21 -> 0.38461538 | N21: =(G21-H21)/H21 -> -0.48275862 | O21: =(H21-I21)/I21 -> 0.095930233 | P21: -
B22: =SUM(B18:B21) -> 1 | C22: TOTAL | D22: =SUM(D18:D21) -> 5491 | E22: =SUM(E18:E21) -> 5034 | F22: =SUM(F18:F21) -> 4625.9 | G22: =SUM(G18:G21) -> 3534.4 | H22: =SUM(H18:H21) -> 4266.2 | I22: =SUM(I18:I21) -> 4167.4 | K22: =(D22-E22)/E22 -> 0.090782678 | L22: =(E22-F22)/F22 -> 0.088220671 | M22: =(F22-G22)/G22 -> 0.30882187 | N22: =(G22-H22)/H22 -> -0.17153439 | O22: =(H22-I22)/I22 -> 0.023707827 | P22: -
B24: Adjusted Profit of each category
D25: Nominal value | K25: YoY Growth
B26: Weight | C26: Category | D26: 2023 | E26: =D26-1 -> 2022 | F26: =E26-1 -> 2021 | G26: =F26-1 -> 2020 | H26: =G26-1 -> 2019 | I26: =H26-1 -> 2018 | K26: 2023 | L26: =K26-1 -> 2022 | M26: =L26-1 -> 2021 | N26: =M26-1 -> 2020 | O26: =N26-1 -> 2019 | P26: =O26-1 -> 2018
B27: =IFERROR(D27/$D$31,"") -> 0.52163825 | C27: NEXT Online | D27: 517.1 | E27: =467.3 -> 467.3 | F27: 588.5 | G27: 472.1 | H27: 399.6 | I27: 352.6 | K27: =(D27-E27)/E27 -> 0.10656966 | L27: =(E27-F27)/F27 -> -0.20594732 | M27: =(F27-G27)/G27 -> 0.24655793 | N27: =(G27-H27)/H27 -> 0.18143143 | O27: =(H27-I27)/I27 -> 0.13329552 | P27: -
B28: =IFERROR(D28/$D$31,"") -> 0.24684757 | C28: NEXT Retail | D28: 244.7 | E28: 240.5 | F28: =107+5.7 -> 112.7 | G28: =-205.9+3.4 -> -202.5 | H28: =163.9+6.2 -> 170.1 | I28: =212.3+6.2 -> 218.5 | K28: =(D28-E28)/E28 -> 0.017463617 | L28: =(E28-F28)/F28 -> 1.133984 | M28: =(F28-G28)/G28 -> -1.5565432 | N28: =(G28-H28)/H28 -> -2.1904762 | O28: =(H28-I28)/I28 -> -0.2215103 | P28: -
B29: =IFERROR(D29/$D$31,"") -> 0.16483406 | C29: NEXT Finance | D29: 163.4 | E29: 170.5 | F29: 141.8 | G29: 112.4 | H29: =127.3 -> 127.3 | I29: 127.3 | K29: =(D29-E29)/E29 -> -0.041642229 | L29: =(E29-F29)/F29 -> 0.20239774 | M29: =(F29-G29)/G29 -> 0.26156584 | N29: =(G29-H29)/H29 -> -0.11704635 | O29: =(H29-I29)/I29 -> 0 | P29: -
B30: =IFERROR(D30/$D$31,"") -> 0.066680117 | C30: Other | D30: =31.2+1.7+33.2 -> 66.1 | E30: =15.2+37+28.1 -> 80.3 | F30: =28+20.5+10.8 -> 59.3 | G30: =17.8+5.2-39.9 -> -16.9 | H30: =32+13-2.2 -> 42.8 | I30: =29.6+11+6.7 -> 47.3 | K30: =(D30-E30)/E30 -> -0.17683686 | L30: =(E30-F30)/F30 -> 0.35413153 | M30: =(F30-G30)/G30 -> -4.5088757 | N30: =(G30-H30)/H30 -> -1.3948598 | O30: =(H30-I30)/I30 -> -0.095137421 | P30: -
B31: =SUM(B27:B30) -> 1 | C31: TOTAL | D31: =SUM(D27:D30) -> 991.3 | E31: =SUM(E27:E30) -> 958.6 | F31: =SUM(F27:F30) -> 902.3 | G31: =SUM(G27:G30) -> 365.1 | H31: =SUM(H27:H30) -> 739.8 | I31: =SUM(I27:I30) -> 745.7 | K31: =(D31-E31)/E31 -> 0.034112247 | L31: =(E31-F31)/F31 -> 0.062396099 | M31: =(F31-G31)/G31 -> 1.4713777 | N31: =(G31-H31)/H31 -> -0.50648824 | O31: =(H31-I31)/I31 -> -0.007912029 | P31: -
B33: Categories | D33: Description | I33: Graphs
B34: NEXT Online | D34: The NEXT online segment offers a wide range of products via its digital platforms. It supports over 7.6 million UK customers and 1.7 million international customers, allowing them to shop from an extensive selection of NEXT-branded products and third-party brands. The segment integrates digital marketing systems, advanced warehousing, and distribution networks, ensuring efficient customer service and delivery. Additionally, NEXT stores play a complementary role by facilitating customer collections and returns .
B37: NEXT Retail | D37: The NEXT Retail segment encompasses the company's physical stores across the UK. It plays a vital role in supporting the brand’s omnichannel strategy, allowing customers to browse and purchase items in person, as well as facilitating collections and returns for online orders. The segment also includes a variety of store formats such as standalone retail outlets, shopping center locations, and retail park stores .
B38: NEXT Finance | D38: The NEXT Finance segment provides customers with flexible credit services. These credit accounts enable customers to purchase items from NEXT and spread payments over time, with interest applied. The segment plays a critical role in driving online and in-store sales by offering financing options and generating revenue through interest income. It also supports customer retention by providing a convenient purchasing method.
B39: Other | D39: The "Other" segment brings together several distinct operations under NEXT. It includes Total Platform, which offers comprehensive services such as e-commerce, warehousing, and logistics for partner brands like Reiss and FatFace, as well as third-party clients. Property management is another key component, managing and leasing properties that support both NEXT’s retail operations and external tenants. Additionally, the segment covers Franchise, Sourcing, and Other activities, focusing on global sourcing operations and franchise agreements to distribute NEXT products through international partnerships.
B41: Industry | J41: Graphs (Industry Forecasts)
B42: Drivers | D42: Description
B43: Digital Expansion and Ecommerce | D43: NEXT plc has significantly invested in its online platform, which has become a crucial pillar for growth. The company has developed a robust ecommerce infrastructure, including fast delivery services and options for in-store pickup. Additionally, NEXT has expanded its digital presence through a marketplace model, allowing other brands to sell through its platform. This strategy diversifies its product offerings and attracts a broader customer base, driving online sales, which now represent an increasingly large portion of the company’s total revenue.
B44: Product Expansion and Strategic Partnerships | D44: NEXT has formed partnerships with other brands and explored licensing opportunities, which helps it attract new market segments and expand its product offerings. These partnerships enable NEXT to reach a wider audience and enhance its market presence.
B45: Diversification of Revenue Streams + Leveraging Digital Infrastructure for Global Reach | D45: Expanding internationally would enable NEXT plc to diversify its revenue streams beyond the UK market, leverage its robust digital infrastructure for global reach, form strategic partnerships to adapt to local markets, and tap into the long-term potential of emerging regions as purchasing power increases.
B46: Sales forecast
B47: Source | D47: Market Growth CAGR | G47: Period
...

Sheet Peers
B1: Peer Logo | C1: Peer Name | D1: Description
C2: #VALUE! | D2: Leading British retailer with over 900 stores, mostly UK and Ireland. Founded in 1884, M&S sells clothing, beauty products, home goods, and food. In 2023 company employed over 72,000 people and reported an annual revenue of £11.931 billion. Company is known for it´s high-quality own-brand products, focus on sustainability through iniciatives. Is listed on the stock market exchange.
C3: #VALUE! | D3: Global retailer of sports fashion and outdoor brands, offers a wide range of products including apparel, footwear and accesories from diverse brands. Company was founded in 1981 by John Wardle and David Makin. In 2023 counted with 3400 stores across 38 territories, employing 90 000 individuals worlswide. Company is known for it´s competitive spirit and commitment to ethical practices.
C4: #VALUE! | D4: Polish multinational company with 2000 across all Europe, Asia and Africa. LP employes 30 000 individuals wordwide. Company was founded in 1991 by Marek Piechocki and Jerzy Lubianiec. LPP offers a wide range of products throught its five fashion brands, Reserved, House, Cropp and Sinsay. The company is known for its innovative designs and commitment for sustainability. Company is listed on the Warsaw stock exchange.
C5: #VALUE! | D5: H&M, a global fashion retailer with over 4000 stores in more than 75 markets,was founded in 1974 by Erlin Persson and emplys 100 000 individuals worldwide. Company offers a wide range of products like pieces of clothing, acessories, footwear, cosmetics and home textils. H&M has a bussiness of fast fashion and has a constant commitment to sustainability.
B8: In Millions USD | C8: =OP!E2 -> #VALUE! | D8: =C2 -> #VALUE! | E8: =C3 -> #VALUE! | F8: =C4 -> #VALUE! | G8: =C5 -> #VALUE! | I8: AVERAGE | J8: Deviation from Average
B9: Company Info | I9: =IFERROR(AVERAGE(C9:H9),"") | L9: TRAFFIC
B10: Market Cap | C10: {=_FV(C8,"Market cap",TRUE)/1000000} -> 16223.82 | D10: {=_FV(D8,"Market cap",TRUE)/1000000} -> 8356.428 | E10: {=_FV(E8,"Market cap",TRUE)/1000000} -> 4946.957 | F10: {=_FV(F8,"Market cap",TRUE)/1000000} -> 32199.69 | G10: {=_FV(G8,"Market cap",TRUE)/1000000} -> 251207.8 | I10: =IFERROR(AVERAGE(C10:H10),"") -> 62586.939 | J10: =SQRT((C10-I10)^2) -> 46363.119 | M10: Best Value
B11: Net Sales (current) | C11: =C59 -> 5491 | D11: =D59 -> 13040.1 | E11: =E59 -> 10397.2 | F11: =F59 -> 3419.324 | G11: =G59 -> 17945.741 | I11: =IFERROR(AVERAGE(C11:H11),"") -> 10058.673 | J11: =SQRT((C11-I11)^2) -> 4567.673
B12: Profitability | I12: =IFERROR(AVERAGE(C12:H12),"") | M12: Important Value
B13: Sales Growth (ttm) | C13: =C59/C58-1 -> 0.090782678 | D13: =D59/D57-1 -> 0.19850556 | E13: =E59/E58-1 -> 0.026883951 | F13: =F59/F58-1 -> 0.15092134 | G13: =G59/G58-1 -> 0.01626924 | I13: =IFERROR(AVERAGE(C13:H13),"") -> 0.096672553 | J13: =SQRT((C13-I13)^2) -> 0.005889875
B14: Sales Growth (36m) | C14: =C59/C57-1 -> 0.5535876 | D14: =D59/D57-1 -> 0.19850556 | E14: =E59/E57-1 -> 0.057561055 | F14: =F59/F57-1 -> 0.53919188 | G14: =G59/G57-1 -> -0.0906613 | I14: =IFERROR(AVERAGE(C14:H14),"") -> 0.25163696 | J14: =SQRT((C14-I14)^2) -> 0.30195064 | M14: Worst Value
B15: Operating Margin | C15: =C62/C59 -> 0.17767256 | D15: =D62/D59 -> 0.054769519 | E15: =E62/E59 -> 0.0029334821 | F15: =F62/F59 -> 0.058701895 | G15: =G62/G59 -> 0.083174106 | I15: =IFERROR(AVERAGE(C15:H15),"") -> 0.075450311 | J15: =SQRT((C15-I15)^2) -> 0.10222224
B16: Net Income Margin | C16: =C65/C59 -> 0.14578401 | D16: =D65/D59 -> 0.054769519 | E16: =E65/E59 -> 0.051821644 | F16: =F65/F59 -> 0.058701895 | G16: =G65/G59 -> 0.01835321 | I16: =IFERROR(AVERAGE(C16:H16),"") -> 0.065886056 | J16: =SQRT((C16-I16)^2) -> 0.079897954
B17: Return on Equity (RoE) | C17: =C65/C77 -> 0.57797834 | D17: =D65/D77 -> 0.25235857 | E17: =E65/E77 -> 0.18783991 | F17: =F65/F77 -> 0.23833955 | G17: =G65/G77 -> 0.091006491 | I17: =IFERROR(AVERAGE(C17:H17),"") -> 0.26950457 | J17: =SQRT((C17-I17)^2) -> 0.30847377
B18: Return on Invested Capital (ROIC) | C18: =(1+C64/(C62+C63))*C62/(C76+C77-C68) -> 0.23796645 | D18: =(1+D64/(D62+D63))*D62/(D76+D77-D68) -> 0.52728242 | E18: =(1+E64/(E62+E63))*E62/(E76+E77-E68) -> 0.0094420573 | F18: =(1+F64/(F62+F63))*F62/(F76+F77-F68) -> 0.33786385 | G18: =(1+G64/(G62+G63))*G62/(G76+G77-G68) -> 0.34040151 | I18: =IFERROR(AVERAGE(C18:H18),"") -> 0.29059126 | J18: =SQRT((C18-I18)^2) -> 0.052624806
B19: Solvency | I19: =IFERROR(AVERAGE(C19:H19),"")
B20: Debt/Assets | C20: =C76/C73 -> 0.4057109 | D20: =D76/D73 -> 0.0013475847 | E20: =E76/E73 -> 0.14059059 | F20: =F76/F73 -> 0.01658044 | G20: =G76/G73 -> 1.5960859 | I20: =IFERROR(AVERAGE(C20:H20),"") -> 0.43206308 | J20: =SQRT((C20-I20)^2) -> 0.026352184
B21: Net Debt/EBITDA | C21: =(C76-C68)/C61 -> 1.569133 | D21: =(D76-D68)/D61 -> -3.7712687 | E21: =(E76-E68)/E61 -> 1.0659857 | F21: =(F76-F68)/F61 -> -0.28211524 | G21: =(G76-G68)/G61 -> 0.49186734 | I21: =IFERROR(AVERAGE(C21:H21),"") -> -0.18527958 | J21: =SQRT((C21-I21)^2) -> 1.7544126
B22: Interest Coverage Ratio | C22: =-C61/C63 -> 13.649318 | D22: =-D61/D63 -> -42.539683 | E22: =-E61/E63 -> -2.4844167 | F22: =-F61/F63 -> -1.04619 | G22: =-G61/G63 -> -47.228182 | I22: =IFERROR(AVERAGE(C22:H22),"") -> -15.929831 | J22: =SQRT((C22-I22)^2) -> 29.579149
B23: Liquidity
B24: Current Ratio | C24: =C71/C75 -> 1.9649193 | D24: =D71/D75 -> 0.85577458 | E24: =E71/E75 -> 1.5241673 | F24: =F71/F75 -> 0.90857646 | G24: =G71/G75 -> 0.24692685 | I24: =IFERROR(AVERAGE(C24:H24),"") -> 1.1000729 | J24: =SQRT((C24-I24)^2) -> 0.86484642
B25: Quick Ratio | C25: =(C68+C69)/C75 -> 1.1693827 | D25: =(D68+D69)/D75 -> 0.66811064 | E25: =(E68+E69)/E75 -> 0.39539194 | F25: =(F68+F69)/F75 -> 0.22044769 | G25: =(G68+G69)/G75 -> 0.46386562 | I25: =IFERROR(AVERAGE(C25:H25),"") -> 0.58343971 | J25: =SQRT((C25-I25)^2) -> 0.58594296
B26: Activity | I26: =IFERROR(AVERAGE(C26:H26),"")
B27: Inventory Turnover | C27: =C60/C70 -> 3.9928479 | D27: =D60/D70 -> 0.0069507015 | E27: =E60/E70 -> 3.4494883 | F27: =F60/F70 -> 1.2476312 | G27: =G60/G70 -> 0.68046052 | I27: =IFERROR(AVERAGE(C27:H27),"") -> 1.8754757 | J27: =SQRT((C27-I27)^2) -> 2.1173721
B28: Acc. Receivable Turnover | C28: =C59/C69 -> 4.329076 | D28: =D59/D69 -> 19.796721 | E28: =E59/E69 -> 41.095652 | F28: =F59/F69 -> 48.904494 | G28: =G59/G69 -> 46.181765 | I28: =IFERROR(AVERAGE(C28:H28),"") -> 32.061542 | J28: =SQRT((C28-I28)^2) -> 27.732466
A29: Price/Sales | B29: Payables Turnover | C29: =C60/C74 -> 3.0958863 | D29: =D60/D74 -> 0.0025617914 | E29: =E60/E74 -> -3.799184 | F29: =F60/F74 -> 64.96 | G29: =G60/G74 -> 0.29795025 | I29: =IFERROR(AVERAGE(C29:H29),"") -> 12.911443 | J29: =SQRT((C29-I29)^2) -> 9.8155566
B30: Fixed Asset Turnover | C30: =C59/C72 -> 7.9869091 | D30: =D59/D72 -> 1.997289 | E30: =E59/E72 -> 2.0781931 | F30: =F59/F72 -> 1.9743706 | G30: =G59/G72 -> 485.66872 | I30: =IFERROR(AVERAGE(C30:H30),"") -> 99.941097 | J30: =SQRT((C30-I30)^2) -> 91.954188
B31: Total Asset Turnover | C31: =C59/C73 -> 1.1622886 | D31: =D59/D73 -> 1.501935 | E31: =E59/E73 -> 1.2921876 | F31: =F59/F73 -> 1.0852085 | G31: =G59/G73 -> 7.2516821 | I31: =IFERROR(AVERAGE(C31:H31),"") -> 2.4586604 | J31: =SQRT((C31-I31)^2) -> 1.2963718
B32: Valuation | I32: =IFERROR(AVERAGE(C32:H32),"")
B33: Price/Earnings | C33: =C10/C65 -> 20.267108 | D33: 10.7 | E33: 14.61 | F33: 5.44 | G33: 6.7 | I33: =IFERROR(AVERAGE(C33:H33),"") -> 11.543422 | J33: =SQRT((C33-I33)^2) -> 8.7236864
B34: Price/Sales | C34: =C10/C59 -> 2.9546203 | D34: =D10/D59 -> 0.64082545 | E34: =E10/E59 -> 0.47579704 | F34: =F10/F59 -> 9.4169754 | G34: =G10/G59 -> 13.998185 | I34: =IFERROR(AVERAGE(C34:H34),"") -> 5.4972806 | J34: =SQRT((C34-I34)^2) -> 2.5426603
B35: Price/Book | C35: =C10/C77 -> 11.713949 | D35: =D10/D77 -> 2.9526971 | E35: =E10/E77 -> 1.7246399 | F35: =F10/F77 -> 38.234501 | G35: =G10/G77 -> 69.4116 | I35: =IFERROR(AVERAGE(C35:H35),"") -> 24.807477 | J35: =SQRT((C35-I35)^2) -> 13.093528
B36: EV/Sales | C36: =(C76+C10-C68)/C59 -> 3.2693899 | D36: =(D76+D10-D68)/D59 -> 0.56331838 | E36: =(E76+E10-E68)/E59 -> 0.53300667 | F36: =(F76+F10-F68)/F59 -> 9.3520127 | G36: =(G76+G10-G68)/G59 -> 14.106444 | I36: =IFERROR(AVERAGE(C36:H36),"") -> 5.5648344 | J36: =SQRT((C36-I36)^2) -> 2.2954445
B37: EV/EBITDA | C37: 9.39 | D37: 6.61 | E37: =(E76+E10-E68)/E61 -> 9.9315 | F37: =(F76+F10-F68)/F61 -> 40.613256 | G37: =(G76+G10-G68)/G61 -> 64.091443 | I37: =IFERROR(AVERAGE(C37:H37),"") -> 31.00655 | J37: =SQRT((C37-I37)^2) -> 21.61655
B38: Stock Info | I38: =IFERROR(AVERAGE(C38:H38),"")
B39: Float | C39: =OP!M19 -> 0.88814229 | D39: 0.946 | E39: 0.477 | F39: 0.597 | G39: 0.37 | I39: =IFERROR(AVERAGE(C39:H39),"") -> 0.65562846 | J39: =SQRT((C39-I39)^2) -> 0.23251383
B40: b (Yahoo) | C40: =OP!M21 -> 1.3444 | D40: 1.62 | E40: 1.65 | F40: 1.14 | G40: 1.25 | I40: =IFERROR(AVERAGE(C40:H40),"") -> 1.40088 | J40: =SQRT((C40-I40)^2) -> 0.05648
B41: Dividend Yield (yahoo finance) | C41: =OP!M31 -> 0.00015094815 | D41: 0,80% | E41: 0.0058 | F41: 0.056 | G41: 0.0379 | I41: =IFERROR(AVERAGE(C41:H41),"") -> 0.024962737 | J41: =SQRT((C41-I41)^2) -> 0.024811789
B42: Stock Performance
...

Sheet Acuerdo
A1: Invertir
A2: NO invertir
A3: Mantener sin elevar posición
A4: Mantener (y seguir comprando)
A5: Liquidar
A6: PENDIENTE

Sheet ESG
B1: Company GICS Sector: | T1: Yes
B2: Consumer Discretionary | C2: <- Select Industry | T2: No
B3: ESG Analysis | K3: Relative ESG Analysis | T3: 2019 | U3: 2020 | V3: 2021 | W3: 2022 | X3: 2023 | Y3: 2019 | Z3: 2020 | AA3: 2021 | AB3: 2022 | AC3: 2023
B4: Parameters | C4: Impact | D4: Do they report? | E4: Ranking | F4: Mitigation Plan | G4: Traffic Lights | H4: Improvement over time? | I4: Targets / Goals? | J4: Comments | K4: Parameters | L4: =Peers!C8 -> #VALUE! | M4: =Peers!D8 -> #VALUE! | N4: =Peers!E8 -> #VALUE! | O4: =Peers!F8 -> #VALUE! | P4: =Peers!G8 -> #VALUE! | Q4: =Peers!H8 -> 0 | R4: AVERAGE | T4: 46.911 | U4: 45.739 | V4: 36.914 | W4: 42.616 | X4: 43.165 | Y4: 340.088 | Z4: 356.383 | AA4: 290.963 | AB4: 430.423 | AC4: 295.837
B5: Environmental | K5: Ratios
A6: 1 | B6: CO2 Direct Emissions | C6: =VLOOKUP($B$2,'Sector Impact'!$K$4:$AA$16,A6+1,FALSE) -> Low | K6: CO2 Emissions/$M Sales | L6: =L12/L$11 -> 7.4422414 | M6: =M12/M$11 -> 15.285326 | N6: =N12/N$11 -> 0.60634921 | O6: =O12/O$11 -> 3.7265096 | P6: =P12/P$11 -> 0.7274911 | Q6: =Q12/Q$11 -> 0.69087204 | R6: =IFERROR(AVERAGE(L6:Q6),"") -> 4.7464649
A7: 2 | B7: Total Water Consumption | C7: =VLOOKUP($B$2,'Sector Impact'!$K$4:$AA$16,A7+1,FALSE) -> Low | K7: Water Consumption/$M Sales | L7: =L13/L$11 -> 51.005172 | M7: =M13/M$11 -> #VALUE! | N7: =N13/N$11 -> #VALUE! | O7: =O13/O$11 -> #VALUE! | P7: =P13/P$11 -> #VALUE! | Q7: =Q13/Q$11 -> 44.57727 | R7: =IFERROR(AVERAGE(L7:Q7),"")
A8: 3 | B8: Total Energy Consumption | C8: =VLOOKUP($B$2,'Sector Impact'!$K$4:$AA$16,A8+1,FALSE) -> Medium | D8: Yes | E8: Medium | F8: Yes | J8: It's mentioned investment in measures, like LED light for the retail stores and the instalment of solar panels | K8: Energy Consumption/$M Sales | L8: =L14/L$11 -> 248.32345 | M8: =M14/M$11 -> 359.8784 | N8: =N14/N$11 -> 89.395397 | O8: =O14/O$11 -> 111.02762 | P8: =P14/P$11 -> 193.06206 | Q8: =Q14/Q$11 -> 58.540638 | R8: =IFERROR(AVERAGE(L8:Q8),"") -> 176.70459
A9: 4 | B9: Waste Management | C9: =VLOOKUP($B$2,'Sector Impact'!$K$4:$AA$16,A9+1,FALSE) -> Medium | D9: Yes | E9: Medium High | F9: Yes | J9: Usage of textile leftovers in Bangladesh | K9: Waste Production/$M Sales | L9: =L15/L$11 -> 5.8643103 | M9: =M15/M$11 -> 4.6875 | N9: =N15/N$11 -> 0.41880952 | O9: =O15/O$11 -> #VALUE! | P9: =P15/P$11 -> #VALUE! | Q9: =Q15/Q$11 -> 0.87736767 | R9: =IFERROR(AVERAGE(L9:Q9),"")
A10: 5 | B10: Land Degradation/Deforestation/Biodiversity loss/Animal sufering/… | C10: =VLOOKUP($B$2,'Sector Impact'!$K$4:$AA$16,A10+1,FALSE) -> Low | K10: Inputs
B11: Social | K11: Net Sales ($M) | L11: 5.8 | M11: 14.72 | N11: 12.6 | O11: 3.693 | P11: 22.48 | Q11: 21.593
A12: 6 | B12: Employee Turnover % | C12: =VLOOKUP($B$2,'Sector Impact'!$K$4:$AA$16,A12+1,FALSE) -> Medium | D12: No | E12: Medium | F12: Yes | J12: The employee turnover isn't reported, it is only mentioned that the employee turnover is monitored | K12: CO2 Emissions Total (Tonnes) | L12: 43.165 | M12: 225 | N12: 7.64 | O12: 13.762 | P12: 16.354 | Q12: 14.918
A13: 7 | B13: Salaries & Compensation | C13: =VLOOKUP($B$2,'Sector Impact'!$K$4:$AA$16,A13+1,FALSE) -> Medium | D13: No | E13: Medium | F13: No | J13: From what I found, only 40% of people think are fairly paid | K13: Water Consumption Total (Cubic Meters) | L13: 295.83 | M13: - | N13: ="-" -> - | O13: ="-" -> - | P13: ="-" -> - | Q13: 962.557
A14: 8 | B14: Reputation | C14: =VLOOKUP($B$2,'Sector Impact'!$K$4:$AA$16,A14+1,FALSE) -> Low | K14: Energy Consumption Total (Gigajoules) | L14: 1440.276 | M14: 5297.41 | N14: 1126.382 | O14: 410.025 | P14: 4340.035 | Q14: 1264.068
A15: 9 | B15: Discrimination Events | C15: =VLOOKUP($B$2,'Sector Impact'!$K$4:$AA$16,A15+1,FALSE) -> Low | F15: Yes | K15: Waste Production Total (Tonnes) | L15: 34.013 | M15: 69 | N15: 5.277 | O15: ="-" -> - | P15: ="-" -> - | Q15: 18.945
A16: 10 | B16: Work Safety | C16: =VLOOKUP($B$2,'Sector Impact'!$K$4:$AA$16,A16+1,FALSE) -> Medium | D16: Yes | E16: Medium High | F16: No | J16: Mentioned first-aid training, and a great concern for the safety of the employees | K16: ESG Scores
A17: 11 | B17: Damage to consumer health | C17: =VLOOKUP($B$2,'Sector Impact'!$K$4:$AA$16,A17+1,FALSE) -> Medium | D17: No | E17: "Best in class" | F17: No | K17: Refinitiv | L17: 71 (79/70/69) | M17: 72 (61/83/64) | N17: 34 (63/39/14) | O17: 69(89/69/58) | P17: 78 (92/75/74) | Q17: 77 (96/86/57) | S17: 2019 | T17: 2020 | U17: 2021 | V17: 2022 | W17: 2023
A18: 12 | B18: PXP? | C18: =VLOOKUP($B$2,'Sector Impact'!$K$4:$AA$16,A18+1,FALSE) -> Medium | D18: Yes | E18: Medium High | F18: No | J18: "The defined contribution section is administered by a Legal & General Master Trust... Members pay 5% of their pensionable earnings which is matched by the Company." | K18: Sustainalytics | L18: 18.7 (low risk) | M18: ="-" -> - | N18: 12.6 (low risk) | O18: 19.0 (low risk) | P18: 20.2 (medium risk) | Q18: 10.0 (low risk) | S18: 1039.954 | T18: 977.085 | U18: 823.319 | V18: 1434.492 | W18: 1440.276
A19: 13 | B19: Supply chain | C19: =VLOOKUP($B$2,'Sector Impact'!$K$4:$AA$16,A19+1,FALSE) -> High | D19: Yes | E19: Medium High | F19: Yes | J19: "NEXT has a well-established supply chain that is supported by our overseas sourcing operation, NEXT Sourcing Limited (NSL)... Tier 1 supply chain comprises circa 1.2 million workers." "Our commitment: We focus on ethical trading, traceability and responsible sourcing to ensure our products are made by workers who are treated fairly and whose safety, human rights and wellbeing are respected." | K19: ISS | L19: C+ | M19: C+ | N19: C | O19: C- | P19: B- | Q19: B | Y19: 2019 | Z19: 2020 | AA19: 2021 | AB19: 2022 | AC19: 2023
A20: 14 | B20: Community involvement | C20: =VLOOKUP($B$2,'Sector Impact'!$K$4:$AA$16,A20+1,FALSE) -> Low | K20: CDP | L20: B/C/B- | M20: B/F/F | N20: A-/C/B | O20: C/C | P20: A-/(C/D/C)/B | Q20: A/(A/A-)/A | Y20: 29.031 | Z20: 30.227 | AA20: 21.753 | AB20: 31.634 | AC20: 34.013
A21: 15 | B21: Public Sector | C21: =VLOOKUP($B$2,'Sector Impact'!$K$4:$AA$16,A21+1,FALSE) -> High | D21: Yes | E21: "Best in class" | F21: No
A22: 16 | B22: Litigation | C22: =VLOOKUP($B$2,'Sector Impact'!$K$4:$AA$16,A22+1,FALSE) -> Low | D22: Yes
B23: Corporate Governance | K23: PARAMETERS
A24: 17 | B24: Diversity (Gender, Age, Industry, Region) | E24: Medium | F24: Yes | J24: At the end of 2023, the board was composed of 4 women, and sevem men, all but one of its member is White British or other White (the other member is Asian/Asian British) | K24: IMPACT | L24: RANKING | M24: MITIGATION PLAN | O24: TRAFFIC
A25: 18 | B25: % Independence | E25: Medium High | F25: No | J25: Only one of the board members is not independent. | K25: Low | L25: "Best in class" | M25: Is there evidence of a plan/program ?
A26: 19 | B26: average time as independent directors | E26: Medium | F26: No | J26: The average time as director is 8,27 years, this is not because of a usual 8 years rotation, but because there are some directors that are in the position for a long time and others that are in the positions just for a couple of years. | K26: Medium | L26: Medium High
A27: 20 | B27: Recent departures of directors / C-level executives? | E27: "Best in class" | F27: No | J27: Amanda James was the only C-Level to leave, but because she is retiring. | K27: High | L27: Medium
A28: 21 | B28: CEO/Chairman duality | E28: "Best in class" | F28: No | K28: Very high | L28: "Villain"
A29: 22 | B29: Transparency (ESG, segments, acquisitions, other) | E29: "Best in class" | F29: No
A30: 23 | B30: Time taken to report after the end of the quarter / year | E30: "Best in class" | F30: No | J30: Realeased their 2023 report in January 2024
A31: 24 | B31: Additional participation of the CEO in other boards or excessive participation of Ch. | E31: Medium | F31: No | J31: The CEO only operates in the company, but the chairman is also Chairma of Grafton Group plc until 2 May 2024 and a Non-Executive Director of BrownForman Corporation (US firm)
A32: 25 | B32: Audit / Consulting | D32: Yes | E32: Medium High | F32: No | J32: "During the year FIT was paid circa £29k and Deloitte was paid circa £5k for the services described above, charged at their standard hourly rates." Their audit is made by an independent comitee.
A33: 26 | B33: ESG-compensation related | D33: No | E33: "Villain" | F33: No | J33: There is no ESG related compensation
A34: 27 | B34: Management compensation schemes | D34: Yes | E34: "Best in class" | F34: No | J34: In case of good performance, the board may approve compensation.

Sheet DCF
A1: VALUATION MODEL
G3: Short Term | K3: Long Term
A4: Section | B4: Line # | C4: ITEM | D4: 2021 (Real) | E4: 2022 (Real) | F4: 2023 (Real) | G4: 2024 | H4: =G4+1 -> 2025 | I4: =H4+1 -> 2026 | J4: =I4+1 -> 2027 | K4: =J4+1 -> 2028 | L4: =K4+1 -> 2029 | M4: =L4+1 -> 2030 | N4: =M4+1 -> 2031 | O4: =N4+1 -> 2032 | ... AF4: =AE4+1 -> 2049
A5: INCOME STATEMENT | B5: 1 | C5: Growth | D5: ='Fin. Data'!D6 -> 0.30882187 | E5: =+E6/D6-1 -> 0.088220671 | F5: =+F6/E6-1 -> 0.090782678 | G5: =Assumptions!D67 -> 0.065336915 | H5: =Assumptions!E67 -> 0.084694022 | I5: =Assumptions!F67 -> 0.05316128 | J5: =Assumptions!G67 -> 0.03756694 | K5: =Assumptions!H67 -> 0.028079378 | L5: =Assumptions!I67 -> 0.022427318 | M5: =Assumptions!J67 -> 0.022482329 | N5: =Assumptions!K67 -> 0.022537342 | ... AF5: =Assumptions!AC67 -> 0.015526513
B6: 2 | C6: Revenues/Sales | D6: =Inputs!D6 -> 4625.9 | E6: =Inputs!C6 -> 5034 | F6: =Inputs!B6 -> 5491 | G6: =Assumptions!D68 -> 5849.765 | H6: =Assumptions!E68 -> 6345.2051 | I6: =Assumptions!F68 -> 6682.5244 | J6: =Assumptions!G68 -> 6933.5663 | K6: =Assumptions!H68 -> 7128.2566 | L6: =Assumptions!I68 -> 7288.1243 | M6: =Assumptions!J68 -> 7451.9783 | N6: =Assumptions!K68 -> 7619.9261 | ... AF6: =Assumptions!AC68 -> 10318.748
B7: 3 | C7: EBIT/Operating Margin | D7: =D8/D6 -> 0.19518364 | E7: =E8/E6 -> 0.19026619 | F7: =F8/F6 -> 0.17767256 | G7: =Assumptions!D50 -> 0.18 | H7: =Assumptions!E50 -> 0.18 | I7: =Assumptions!F50 -> 0.18 | J7: =Assumptions!G50 -> 0.18 | K7: =Assumptions!H50 -> 0.18 | L7: =Assumptions!I50 -> 0.18 | M7: =Assumptions!J50 -> 0.18 | N7: =Assumptions!K50 -> 0.18 | ... AF7: =Assumptions!AC50 -> 0.18
B8: 4 | C8: EBIT | D8: ='Fin. Data'!D11 -> 902.9 | E8: ='Fin. Data'!C11 -> 957.8 | F8: ='Fin. Data'!B11 -> 975.6 | G8: =G7*G6 -> 1052.9577 | H8: =H7*H6 -> 1142.1369 | I8: =I7*I6 -> 1202.8544 | J8: =J7*J6 -> 1248.0419 | K8: =K7*K6 -> 1283.0862 | L8: =L7*L6 -> 1311.8624 | M8: =M7*M6 -> 1341.3561 | N8: =N7*N6 -> 1371.5867 | ... AF8: =AF7*AF6 -> 1857.3746
B9: 5a | C9: (Dep) | D9: -217.5 | E9: -208.1 | F9: -212.6 | G9: =$D$53*DCF!F40 -> -206.2045 | H9: =$D$53*DCF!G40 -> -240.13314 | I9: =$D$53*DCF!H40 -> -276.93533 | J9: =$D$53*DCF!I40 -> -315.69397 | K9: =$E$53*DCF!J40 -> -343.63594 | L9: =$E$53*DCF!K40 -> -381.55827 | M9: =$E$53*DCF!L40 -> -420.33109 | N9: =$E$53*DCF!M40 -> -459.97561 | O9: =$E$53*DCF!N40 -> -500.51362 | P9: =$E$53*DCF!O40 -> -541.96747 | Q9: =$E$53*DCF!P40 -> -584.36015 | R9: =$E$53*DCF!Q40 -> -627.71524 | ... AF9: =$E$53*DCF!AE40 -> -1314.216 | AG9: =SUM(D9:AF9) -> -19304.1
B10: 5b | C10: (Amort) | D10: -3.2 | E10: -11.9 | F10: -36.2 | G10: =F38*$D$54 -> -40.78 | H10: =G38*$D$54 -> -42.819 | I10: =H38*$D$54 -> -44.95995 | J10: =I38*$D$54 -> -47.207948 | K10: =J38*$E$54 -> -39.654676 | L10: =K38*$E$54 -> -41.240863 | M10: =L38*$E$54 -> -42.890497 | N10: =M38*$E$54 -> -44.606117 | O10: =N38*$E$54 -> -46.390362 | P10: =O38*$E$54 -> -48.245977 | Q10: =P38*$E$54 -> -50.175816 | R10: =Q38*$E$54 -> -52.182848 | ... AF10: =AE38*$E$54 -> -90.363809
B11: 5c | C11: (Stock based compensation) | D11: =D20 -> 0 | E11: =E20 -> 0 | F11: =F20 -> 0 | G11: =G6*$D$55 -> 0 | H11: =H6*$D$55 -> 0 | I11: =I6*$D$55 -> 0 | J11: =J6*$D$55 -> 0 | K11: =K6*$D$55 -> 0 | L11: =L6*$D$55 -> 0 | M11: =M6*$D$55 -> 0 | N11: =N6*$D$55 -> 0 | ... AF11: =AF6*$D$55 -> 0
B12: 6 | C12: EBITDA | D12: =D8-D9-D10 -> 1123.6 | E12: =E8-E9-E10 -> 1177.8 | F12: =F8-F9-F10 -> 1224.4 | G12: =G8-G9-G10 -> 1299.9422 | H12: =H8-H9-H10 -> 1425.0891 | I12: =I8-I9-I10 -> 1524.7497 | J12: =J8-J9-J10 -> 1610.9439 | K12: =K8-K9-K10 -> 1666.3768 | ... AF12: =AF8-AF9-AF10 -> 3261.9544
B13: 7 | C13: (Net financing cost) | D13: ='Fin. Data'!D14 -> -82.3 | E13: ='Fin. Data'!C14 -> -72.2 | F13: ='Fin. Data'!B14 -> -80.7 | G13: =F43*$D$58-F44*$D$57 -> -73.8208 | H13: =G43*$D$58-G44*$D$57 -> -71.577377 | I13: =H43*$D$58-H44*$D$57 -> -71.779398 | J13: =I43*$D$58-I44*$D$57 -> -73.551811 | K13: =J43*$E$58-J44*$E$57 -> -73.749169 | L13: =K43*$E$58-K44*$E$57 -> -83.442493 | M13: =L43*$E$58-L44*$E$57 -> -84.196456 | N13: =M43*$E$58-M44*$E$57 -> -86.324667 | O13: =N43*$E$58-N44*$E$57 -> -92.996445 | P13: =O43*$E$58-O44*$E$57 -> -93.042524 | Q13: =P43*$E$58-P44*$E$57 -> -84.823074 | R13: =Q43*$E$58-Q44*$E$57 -> -84.279417 | ... AF13: =AE43*$E$58-AE44*$E$57 -> 29.705304
B14: 8 | C14: Other income/(cost) | D14: ='Fin. Data'!D15 -> 2.5 | E14: ='Fin. Data'!C15 -> -16.3 | F14: ='Fin. Data'!B15 -> 120.9 | G14: =AVERAGE(D14:F14)*(1+G5) -> 38.032528 | H14: =AVERAGE(E14:G14)*(1+H5) -> 51.570883 | I14: =AVERAGE(F14:H14)*(1+I5) -> 73.898014 | J14: =AVERAGE(G14:I14)*(1+J5) -> 56.547891 | K14: =AVERAGE(H14:J14)*(1+K5) -> 62.375902 | L14: =AVERAGE(I14:K14)*(1+L5) -> 65.715428 | M14: =AVERAGE(J14:L14)*(1+M5) -> 62.930114 | N14: =AVERAGE(K14:M14)*(1+N5) -> 65.108853 | ... AF14: =AVERAGE(AC14:AE14)*(1+AF5) -> 75.443308
B15: 9 | C15: Earnings before taxes | D15: =D8+D13+D14 -> 823.1 | E15: =E8+E13+E14 -> 869.3 | F15: =F8+F13+F14 -> 1015.8 | G15: =G8+G13+G14 -> 1017.1694 | H15: =H8+H13+H14 -> 1122.1304 | I15: =I8+I13+I14 -> 1204.973 | J15: =J8+J13+J14 -> 1231.038 | K15: =K8+K13+K14 -> 1271.7129 | ... AF15: =AF8+AF13+AF14 -> 1962.5232
B16: 10 | C16: (Income tax) | D16: ='Fin. Data'!D21 -> -145.6 | E16: ='Fin. Data'!C21 -> -158.6 | F16: ='Fin. Data'!B21 -> -215.3 | G16: =-$D$56*G15 -> -305.15083 | H16: =-$D$56*H15 -> -336.63913 | I16: =-$D$56*I15 -> -361.4919 | J16: =-$D$56*J15 -> -369.31141 | K16: =-$E$56*K15 -> -381.51388 | L16: =-$E$56*L15 -> -388.24059 | M16: =-$E$56*M15 -> -396.02692 | N16: =-$E$56*N15 -> -405.11126 | O16: =-$E$56*O15 -> -412.68646 | P16: =-$E$56*P15 -> -422.23667 | Q16: =-$E$56*Q15 -> -434.80269 | R16: =-$E$56*R15 -> -445.20209 | ... AF16: =-$E$56*AF15 -> -588.75696
B17: 11 | C17: Net income | D17: ='Fin. Data'!D23 -> 677.5 | E17: ='Fin. Data'!C23 -> 710.7 | F17: ='Fin. Data'!B23 -> 800.5 | G17: =G16+G15 -> 712.0186 | H17: =H16+H15 -> 785.4913 | I17: =I16+I15 -> 843.4811 | J17: =J16+J15 -> 861.72662 | K17: =K16+K15 -> 890.19904 | L17: =L16+L15 -> 905.89471 | M17: =M16+M15 -> 924.06282 | N17: =N16+N15 -> 945.25961 | ... AF17: =AF16+AF15 -> 1373.7662
A19: CASH FLOW STATEMENT | B19: 12 | C19: Operating cash flows before WK | D19: =Inputs!D59-D20-D21 -> 671.6 | E19: =Inputs!C59-E20-E21 -> 608.3 | F19: =Inputs!B59-DCF!F20-DCF!F21 -> 1069.2 | G19: =G17-G10-G9-G11 -> 959.0031 | H19: =H17-H10-H9-H11 -> 1068.4434 | I19: =I17-I10-I9-I11 -> 1165.3764 | J19: =J17-J10-J9-J11 -> 1224.6285 | K19: =K17-K10-K9-K11 -> 1273.4897 | L19: =L17-L10-L9-L11 -> 1328.6938 | M19: =M17-M10-M9-M11 -> 1387.2844 | N19: =N17-N10-N9-N11 -> 1449.8413 | ... AF19: =AF17-AF10-AF9-AF11 -> 2778.3461
B20: 13 | C20: (Stock-based compensation) | D20: 0 | E20: 0 | F20: 0 | G20: =G11 -> 0 | H20: =H11 -> 0 | I20: =I11 -> 0 | J20: =J11 -> 0 | K20: =K11 -> 0 | L20: =L11 -> 0 | M20: =M11 -> 0 | N20: =N11 -> 0 | ... AF20: =AF11 -> 0
B21: 14 | C21: (Working Capital Flows) | D21: =Inputs!D62 -> 299.8 | E21: =Inputs!C62 -> 190.5 | F21: =Inputs!B62 -> 51.1 | G21: =$D$60*(G6-F6) -> 71.753 | H21: =$D$60*(H6-G6) -> 99.088025 | I21: =$D$60*(I6-H6) -> 67.463846 | J21: =$D$60*(J6-I6) -> 50.208398 | K21: =$E$60*(K6-J6) -> 38.938047 | L21: =$E$60*(L6-K6) -> 31.973536 | M21: =$E$60*(M6-L6) -> 32.770802 | N21: =$E$60*(N6-M6) -> 33.589557 | O21: =$E$60*(O6-N6) -> 34.430409 | P21: =$E$60*(P6-O6) -> 35.293984 | Q21: =$E$60*(Q6-P6) -> 36.180926 | R21: =$E$60*(R6-Q6) -> 37.091899 | ... AF21: =$E$60*(AF6-AE6) -> 31.552927
B22: 15 | C22: -Total Operating Cash Flow | D22: =D19+D20+D21 -> 971.4 | E22: =E19+E20+E21 -> 798.8 | F22: =F19+F20+F21 -> 1120.3 | G22: =G19+G20+G21 -> 1030.7561 | H22: =H19+H20+H21 -> 1167.5315 | I22: =I19+I20+I21 -> 1232.8402 | J22: =J19+J20+J21 -> 1274.8369 | K22: =K19+K20+K21 -> 1312.4277 | ... AF22: =AF19+AF20+AF21 -> 2809.899
B23: 16 | C23: (CAPEX) | D23: ='Fin. Data'!D32 -> -224.7 | E23: ='Fin. Data'!C32 -> -163.4 | F23: ='Fin. Data'!B32 -> -125.7 | G23: =G6*$D$62 -> -233.9906 | H23: =H6*$D$62 -> -253.80821 | I23: =I6*$D$62 -> -267.30097 | J23: =J6*$D$62 -> -277.34265 | K23: =K6*$E$62 -> -270.87375 | L23: =L6*$E$62 -> -276.94872 | M23: =M6*$E$62 -> -283.17517 | N23: =N6*$E$62 -> -289.55719 | O23: =O6*$E$62 -> -296.09897 | P23: =P6*$E$62 -> -302.80482 | Q23: =Q6*$E$62 -> -309.6792 | R23: =R6*$E$62 -> -316.72666 | ... AF23: =AF6*$E$62 -> -392.11241 | AG23: =SUM(D23:AF23) -> -8871.0697
B24: 17 | C24: Adq | D24: =Inputs!D66 -> -34.3 | E24: ='Fin. Data'!C33 -> -95.4 | F24: ='Fin. Data'!B33 -> -153.2 | G24: =G6*$D$63 -> -116.9953 | H24: =H6*$D$63 -> -126.9041 | I24: =I6*$D$63 -> -133.65049 | J24: =J6*$D$63 -> -138.67133 | K24: =K6*$E$63 -> -71.282566 | L24: =L6*$E$63 -> -72.881243 | M24: =M6*$E$63 -> -74.519783 | N24: =N6*$E$63 -> -76.199261 | O24: =O6*$E$63 -> -77.920781 | P24: =P6*$E$63 -> -79.68548 | Q24: =Q6*$E$63 -> -81.494526 | R24: =R6*$E$63 -> -83.349121 | ... AF24: =AF6*$E$63 -> -103.18748 | AH24: =AG9-AG23 -> -10433.03
B25: 18 | C25: (Other investing flows) | D25: =Inputs!D67 -> -33.5 | E25: =Inputs!C67 -> -12.6 | F25: =Inputs!B67 -> -55.5 | G25: =(1+G5)*AVERAGE(D25:F25) -> -36.07941 | H25: =(1+H5)*AVERAGE(E25:G25) -> -37.667594 | I25: =(1+I5)*AVERAGE(F25:H25) -> -45.372647 | J25: =(1+J5)*AVERAGE(G25:I25) -> -41.198204 | K25: =(1+K5)*AVERAGE(H25:J25) -> -42.575661 | L25: =(1+L5)*AVERAGE(I25:K25) -> -44.014307 | M25: =(1+M5)*AVERAGE(J25:L25) -> -43.553716 | N25: =(1+N5)*AVERAGE(K25:M25) -> -44.358926 | ... AF25: =(1+AF5)*AVERAGE(AC25:AE25) -> -51.516233
B26: 19 | C26: -Total Investing Flows | D26: =D23+D24+D25 -> -292.5 | E26: =E23+E24+E25 -> -271.4 | F26: =F23+F24+F25 -> -334.4 | G26: =G23+G24+G25 -> -387.06531 | H26: =H23+H24+H25 -> -418.3799 | I26: =I23+I24+I25 -> -446.32411 | J26: =J23+J24+J25 -> -457.21218 | K26: =K23+K24+K25 -> -384.73198 | ... AF26: =AF23+AF24+AF25 -> -546.81612
B27: 20 | C27: (Flows related to leases) | D27: =Inputs!D71+Inputs!D72 -> -172.3 | E27: =Inputs!C71+Inputs!C72 -> -157 | F27: =Inputs!B71+Inputs!B72 -> -156.1 | G27: =G6*$D$66 -> -146.24413 | H27: =H6*$D$66 -> -158.63013 | I27: =I6*$D$66 -> -167.06311 | J27: =J6*$D$66 -> -173.33916 | K27: =$E$66*K6 -> -142.56513 | L27: =$E$66*L6 -> -145.76249 | M27: =$E$66*M6 -> -149.03957 | N27: =$E$66*N6 -> -152.39852 | O27: =$E$66*O6 -> -155.84156 | P27: =$E$66*P6 -> -159.37096 | Q27: =$E$66*Q6 -> -162.98905 | R27: =$E$66*R6 -> -166.69824 | ... AF27: =$E$66*AF6 -> -206.37495
B28: 21 | C28: Flows related to debt | D28: =+SUM(Inputs!D69:D70) -> -325 | E28: =+SUM(Inputs!C69:C70) -> 0 | F28: =+SUM(Inputs!B69:B70) -> -2.5 | G28: =G44-F44 -> -91.7 | H28: =H44-G44 -> 0 | I28: =I44-H44 -> 50 | J28: =J44-I44 -> 0 | K28: =K44-J44 -> 275 | L28: =L44-K44 -> 0 | M28: =M44-L44 -> 50 | N28: =N44-M44 -> 200 | ... AF28: =AF44-AE44 -> 0
B29: 22 | C29: (Repurchases)/Issuance of stock | D29: ='Fin. Data'!D28 -> -8.7 | E29: ='Fin. Data'!C28 -> -228.5 | F29: ='Fin. Data'!B28 -> -177.3 | G29: =-G6*$D$65 -> -233.9906 | H29: =-H6*$D$65 -> -253.80821 | I29: =-I6*$D$65 -> -267.30097 | J29: =-J6*$D$65 -> -277.34265 | K29: =-1*K6*$E$65 -> -427.69539 | L29: =-1*L6*$E$65 -> -437.28746 | M29: =-1*M6*$E$65 -> -447.1187 | N29: =-1*N6*$E$65 -> -457.19556 | O29: =-1*O6*$E$65 -> -467.52469 | P29: =-1*P6*$E$65 -> -478.11288 | Q29: =-1*Q6*$E$65 -> -488.96716 | R29: =-1*R6*$E$65 -> -500.09473 | ... AF29: =-1*AF6*$E$65 -> -619.12486
B30: 23 | C30: (Dividends) | D30: ='Fin. Data'!D27 -> -344.5 | E30: ='Fin. Data'!C27 -> -237.4 | F30: ='Fin. Data'!B27 -> -248.3 | G30: =-$D$64*G6 -> -233.9906 | H30: =-$D$64*H6 -> -253.80821 | I30: =-$D$64*I6 -> -267.30097 | J30: =-$D$64*J6 -> -277.34265 | K30: =-$E$64*K6 -> -356.41283 | L30: =-$E$64*L6 -> -364.40621 | M30: =-$E$64*M6 -> -372.59891 | N30: =-$E$64*N6 -> -380.9963 | O30: =-$E$64*O6 -> -389.6039 | P30: =-$E$64*P6 -> -398.4274 | Q30: =-$E$64*Q6 -> -407.47263 | R30: =-$E$64*R6 -> -416.74561 | ... AF30: =-$E$64*AF6 -> -515.93738
B31: 24 | C31: Other financing flows | D31: =Inputs!D75 -> -142.9 | E31: =Inputs!C75 -> -104.2 | F31: =Inputs!B75 -> -79.1 | G31: =(1+G5)*AVERAGE(D31:F31) -> -115.83763 | H31: =(1+H5)*AVERAGE(E31:G31) -> -108.1576 | I31: =(1+I5)*AVERAGE(F31:H31) -> -106.40272 | J31: =(1+J5)*AVERAGE(G31:I31) -> -114.27 | K31: =(1+K5)*AVERAGE(H31:J31) -> -112.68789 | L31: =(1+L5)*AVERAGE(I31:K31) -> -113.61233 | M31: =(1+M5)*AVERAGE(J31:L31) -> -116.07568 | N31: =(1+N5)*AVERAGE(K31:M31) -> -116.69738 | ... AF31: =(1+AF5)*AVERAGE(AC31:AE31) -> -135.68308
B32: 25 | C32: -Total Financing flows | D32: =D27+D28+D29+D30+D31 -> -993.4 | E32: =E27+E28+E29+E30+E31 -> -727.1 | F32: =F27+F28+F29+F30+F31 -> -663.3 | G32: =G27+G28+G29+G30+G31 -> -821.76296 | H32: =H27+H28+H29+H30+H31 -> -774.40414 | I32: =I27+I28+I29+I30+I31 -> -758.06778 | J32: =J27+J28+J29+J30+J31 -> -842.29447 | K32: =K27+K28+K29+K30+K31 -> -764.36125 | ... AF32: =AF27+AF28+AF29+AF30+AF31 -> -1477.1203
A34: SUMMARY | B34: 26 | C34: Cash before shareholder returns | D34: =D22+D26+D27+D28+D31 -> 38.7 | E34: =E22+E26+E27+E28+E31 -> 266.2 | F34: =F22+F26+F27+F28+F31 -> 548.2 | G34: =G22+G26+G27+G28+G31 -> 289.90903 | H34: =H22+H26+H27+H28+H31 -> 482.36383 | I34: =I22+I26+I27+I28+I31 -> 563.05028 | J34: =J22+J26+J27+J28+J31 -> 530.01559 | K34: =K22+K26+K27+K28+K31 -> 947.44271 | ... AF34: =AF22+AF26+AF27+AF28+AF31 -> 1921.0248
B35: 27 | C35: Returns to shareholders | D35: =-1*(D29+D30) -> 353.2 | E35: =-1*(E29+E30) -> 465.9 | F35: =-1*(F29+F30) -> 425.6 | G35: =-1*(G29+G30) -> 467.9812 | H35: =-1*(H29+H30) -> 507.61641 | I35: =-1*(I29+I30) -> 534.60195 | J35: =-1*(J29+J30) -> 554.68531 | K35: =-1*(K29+K30) -> 784.10822 | ... AF35: =-1*(AF29+AF30) -> 1135.0622
B36: 28 | C36: Excess cash acumulation | D36: =D34-D35 -> -314.5 | E36: =E34-E35 -> -199.7 | F36: =F34-F35 -> 122.6 | G36: =G34-G35 -> -178.07217 | H36: =H34-H35 -> -25.252579 | I36: =I34-I35 -> 28.448335 | J36: =J34-J35 -> -24.669721 | K36: =K34-K35 -> 163.33448 | ... AF36: =AF34-AF35 -> 785.96259
A38: BALANCE SHEET | B38: 29 | C38: Intangible assets | D38: 89.2 | E38: 159.2 | F38: 815.6 | G38: =+F38+(-G10) -> 856.38 | H38: =+G38+(-H10) -> 899.199 | I38: =+H38+(-I10) -> 944.15895 | J38: =+I38+(-J10) -> 991.3669 | K38: =+J38+(-K10) -> 1031.0216 | L38: =+K38+(-L10) -> 1072.2624 | M38: =+L38+(-M10) -> 1115.1529 | N38: =+M38+(-N10) -> 1159.7591 | ... AF38: =+AE38+(-AF10) -> 2349.459 | AG38: =SUM(G38:AF38) -> 39001.501
B39: 30 | C39: Accumulated amortization | D39: 9.9 | E39: =D39+E10 -> -2 | F39: =E39+F10 -> -38.2 | G39: =F39-G10 -> 2.58 | H39: =G39-H10 -> 45.399 | I39: =H39-I10 -> 90.35895 | J39: =I39-J10 -> 137.5669 | K39: =J39-K10 -> 177.22157 | L39: =K39-L10 -> 218.46244 | M39: =L39-M10 -> 261.35293 | N39: =M39-N10 -> 305.95905 | ... AF39: =AE39-AF10 -> 1495.659 | AG39: =SUM(G39:AF39) -> 16802.701
B40: 31 | C40: PPE+Right of use Assets | D40: 1240.2 | E40: 1306.8 | F40: 1422.1 | G40: =F40+(-G23) -> 1656.0906 | H40: =G40+(-H23) -> 1909.8988 | I40: =H40+(-I23) -> 2177.1998 | J40: =I40+(-J23) -> 2454.5424 | K40: =J40+(-K23) -> 2725.4162 | L40: =K40+(-L23) -> 3002.3649 | M40: =L40+(-M23) -> 3285.5401 | N40: =M40+(-N23) -> 3575.0973 | ... AF40: =AE40+(-AF23) -> 9779.3697 | AG40: =SUM(G40:AF40) -> 141429.22
B41: 32 | C41: Accumulated depreciation | D41: 1451.2 | E41: =D41+E9 -> 1243.1 | F41: =E41+F9 -> 1030.5 | G41: =F41-G9 -> 1236.7045 | H41: =G41-H9 -> 1476.8376 | I41: =H41-I9 -> 1753.773 | J41: =I41-J9 -> 2069.4669 | K41: =J41-K9 -> 2413.1029 | L41: =K41-L9 -> 2794.6611 | M41: =L41-M9 -> 3214.9922 | N41: =M41-N9 -> 3674.9678 | ... AF41: =AE41-AF9 -> 19696.4 | AG41: =SUM(G41:AF41) -> 213792.23
A43: CASH & DEBT & DISCOUNTING | B43: 33 | C43: Ending cash balance | D43: ='Fin. Data'!D39 -> 433 | E43: =E36+D43 -> 233.3 | F43: =F36+E43 -> 355.9 | G43: =G36+F43 -> 177.82783 | H43: =H36+G43 -> 152.57525 | I43: =I36+H43 -> 181.02359 | J43: =J36+I43 -> 156.35387 | K43: =K36+J43 -> 319.68835 | L43: =L36+K43 -> 225.44297 | ... AF43: =AF36+AE43 -> 4499.1256
B44: 34 | C44: Total Debt | D44: ='Fin. Data'!D58 -> 2061.5 | E44: ='Fin. Data'!C58 -> 1916 | F44: ='Fin. Data'!B58 -> 1916.7 | G44: =Assumptions!C287 -> 1825 | H44: =Assumptions!D287 -> 1825 | I44: =Assumptions!E287 -> 1875 | J44: =Assumptions!F287 -> 1875 | K44: =Assumptions!G287 -> 2150 | L44: =Assumptions!H287 -> 2150 | M44: =Assumptions!I287 -> 2200 | N44: =Assumptions!J287 -> 2400 | ... AF44: =Assumptions!AB287 -> 0
B45: 35 | C45: Discount factor | F45: =1/((1+$F$50)^G50) -> 1 | G45: =1/((1+$F$50)^G49) -> 0.92165899 | H45: =1/((1+$F$50)^H49) -> 0.84945529 | I45: =1/((1+$F$50)^I49) -> 0.7829081 | J45: =1/((1+$F$50)^J49) -> 0.72157428 | K45: =1/((1+$F$50)^K49) -> 0.66504542 | L45: =1/((1+$F$50)^L49) -> 0.61294509 | M45: =1/((1+$F$50)^M49) -> 0.56492635 | N45: =1/((1+$F$50)^N49) -> 0.52066945 | ... AF45: =1/((1+$F$50)^AF49) -> 0.1199021
...

Sheet Assumptions
B2: Assumptions
B4: Prospects:
B6: Links:
D8: 2023 | E8: =D8-1 -> 2022 | F8: =E8-1 -> 2021 | G8: =F8-1 -> 2020 | H8: =G8-1 -> 2019 | I8: =H8-1 -> 2018 | J8: =I8-1 -> 2017 | K8: =J8-1 -> 2016 | L8: =K8-1 -> 2015 | N8: 9Y Average | O8: 5Y Average | P8: 3Y Average | R8: Short Term Forecast | S8: Long Term Forecast
B9: Revenue growth | D9: =(Inputs!B6-Inputs!C6)/Inputs!C6 -> 0.090782678 | E9: =(Inputs!C6-Inputs!D6)/Inputs!D6 -> 0.088220671 | F9: =(Inputs!D6-Inputs!E6)/Inputs!E6 -> 0.30882187 | G9: =(Inputs!E6-Inputs!F6)/Inputs!F6 -> -0.17153439 | H9: =(Inputs!F6-Inputs!G6)/Inputs!G6 -> 0.023707827 | I9: =(Inputs!G6-Inputs!H6)/Inputs!H6 -> 0.027592159 | J9: =(Inputs!H6-Inputs!I6)/Inputs!I6 -> -0.01020184 | K9: =(Inputs!I6-Inputs!J6)/Inputs!J6 -> -0.019057196 | L9: =(Inputs!J6-Inputs!K6)/Inputs!K6 -> 0.044277214 | N9: =AVERAGE(D9:L9) -> 0.04251211 | O9: =AVERAGE(D9:H9) -> 0.067999731 | P9: =AVERAGE(D9:F9) -> 0.1626084 | R9: 0.0574 | S9: 0.03
B10: Operating Margin | D10: =Inputs!B8/Inputs!B6 -> 0.17767256 | E10: =Inputs!C8/Inputs!C6 -> 0.19026619 | F10: =Inputs!D8/Inputs!D6 -> 0.19518364 | G10: =Inputs!E8/Inputs!E6 -> 0.12613173 | H10: =Inputs!F8/Inputs!F6 -> 0.20050631 | I10: =Inputs!G8/Inputs!G6 -> 0.20149254 | J10: =Inputs!H8/Inputs!H6 -> 0.18764641 | K10: =Inputs!I8/Inputs!I6 -> 0.20198667 | L10: =Inputs!J8/Inputs!J6 -> 0.2089588 | N10: =AVERAGE(D10:L10) -> 0.18776054 | O10: =AVERAGE(D10:H10) -> 0.17795208 | P10: =AVERAGE(D10:F10) -> 0.18770746
B13: Modelling Factors
D15: Last 9 years | Z15: Values in M. | AA15: 2023 | AB15: =AA15-1 -> 2022 | AC15: =AB15-1 -> 2021 | AD15: =AC15-1 -> 2020 | AE15: =AD15-1 -> 2019 | AF15: =AE15-1 -> 2018 | AG15: =AF15-1 -> 2017 | AH15: =AG15-1 -> 2016 | AI15: =AH15-1 -> 2015 | ... AK15: =AJ15-1 -> 2013
D16: =D8 -> 2023 | E16: =E8 -> 2022 | F16: =F8 -> 2021 | G16: =G8 -> 2020 | H16: =H8 -> 2019 | I16: =I8 -> 2018 | J16: =J8 -> 2017 | K16: =K8 -> 2016 | L16: =L8 -> 2015 | N16: =N8 -> 9Y Average | O16: =O8 -> 5Y Average | P16: =P8 -> 3Y Average | R16: Short Term Forecast | S16: Long Term Forecast | U16: Reference | Z16: Depreciation | AA16: 212.6 | AB16: 208.1 | AC16: 217.5 | AD16: 255.2 | AE16: 259.5 | AF16: 120.1 | AG16: 118.6 | AH16: 114.3 | AI16: 112.6 | AJ16: 112.6 | AK16: 112.6
B17: Depreciation factor | D17: =AA16/AA19 -> 0.14949722 | E17: =AB16/AB19 -> 0.15924395 | F17: =AC16/AC19 -> 0.17537494 | G17: =AD16/AD19 -> 0.21357436 | H17: =AE16/AE19 -> 0.18131638 | I17: =AF16/AF19 -> 0.212604 | J17: =AG16/AG19 -> 0.21220254 | K17: =AH16/AH19 -> 0.1975458 | L17: =AI16/AI19 -> 0.20991797 | N17: =AVERAGE(D17:L17) -> 0.19014191 | O17: =AVERAGE(D17:H17) -> 0.17580137 | P17: =AVERAGE(D17:F17) -> 0.16137204 | R17: -0.145 | S17: -0.14 | U17: % PPE | Z17: Amortization | AA17: 36.3 | AB17: 12.2 | AC17: 3.9 | AD17: 0.4 | AE17: 0 | AF17: 0.3 | AG17: 0.4 | AH17: 0.4 | AI17: 0.3 | AJ17: 0.3 | AK17: 0.3
B18: Amortization factor | D18: =AA17/AA18 -> 0.04452895 | E18: =AB17/AB18 -> 0.076633166 | F18: =AC17/AC18 -> 0.043721973 | G18: =AD17/AD18 -> 0.0060150376 | H18: =AE17/AE18 -> 0 | I18: =AF17/AF18 -> 0.0062240664 | J18: =AG17/AG18 -> 0.0082987552 | K18: =AH17/AH18 -> 0.0082987552 | L18: =AI17/AI18 -> 0.0059760956 | N18: =AVERAGE(D18:L18) -> 0.022188533 | O18: =AVERAGE(D18:H18) -> 0.034179825 | P18: =AVERAGE(D18:F18) -> 0.054961363 | R18: -0.05 | S18: -0.04 | U18: % IA | Z18: Intangible Assets (Gross) | AA18: 815.2 | AB18: 159.2 | AC18: 89.2 | AD18: 66.5 | AE18: 49.8 | AF18: 48.2 | AG18: 48.2 | AH18: 48.2 | AI18: 50.2 | AJ18: 50.2 | AK18: 50.2
B19: Stock-based comp | D19: =AA20/Inputs!B6 -> 0 | E19: =AB20/Inputs!C6 -> 0 | F19: =AC20/Inputs!D6 -> 0 | G19: =AD20/Inputs!E6 -> 0 | H19: =AE20/Inputs!F6 -> 0 | I19: =AF20/Inputs!G6 -> 0 | J19: =AG20/Inputs!H6 -> 0 | K19: =AH20/Inputs!I6 -> 0 | L19: =AI20/Inputs!J6 -> 0 | N19: =AVERAGE(D19:L19) -> 0 | O19: =AVERAGE(D19:H19) -> 0 | P19: =AVERAGE(D19:F19) -> 0 | R19: 0 | S19: 0 | U19: % Revenue | Z19: PPE+ROA (Gross) | AA19: 1422.1 | AB19: 1306.8 | AC19: 1240.2 | AD19: 1194.9 | AE19: 1431.2 | AF19: 564.9 | AG19: 558.9 | AH19: 578.6 | AI19: 536.4 | AJ19: 536.4 | AK19: 536.4
B20: Tax Rate | D20: ='Fin. Data'!B21/('Fin. Data'!B21+'Fin. Data'!B23) -> -0.36790841 | E20: ='Fin. Data'!C21/('Fin. Data'!C21+'Fin. Data'!C23) -> -0.2872668 | F20: ='Fin. Data'!D21/('Fin. Data'!D21+'Fin. Data'!D23) -> -0.27373566 | G20: ='Fin. Data'!E21/('Fin. Data'!E21+'Fin. Data'!E23) -> -0.24112554 | H20: ='Fin. Data'!F21/('Fin. Data'!F21+'Fin. Data'!F23) -> -0.29307057 | I20: ='Fin. Data'!G21/('Fin. Data'!G21+'Fin. Data'!G23) -> -0.28949634 | J20: ='Fin. Data'!H21/('Fin. Data'!H21+'Fin. Data'!H23) -> -0.29355191 | K20: ='Fin. Data'!I21/('Fin. Data'!I21+'Fin. Data'!I23) -> -0.32243963 | L20: ='Fin. Data'!J21/('Fin. Data'!J21+'Fin. Data'!J23) -> -0.34030151 | N20: =AVERAGE(D20:L20) -> -0.30098849 | O20: =AVERAGE(D20:H20) -> -0.2926214 | P20: =AVERAGE(D20:F20) -> -0.30963696 | R20: 0.3 | S20: 0.3 | U20: % EBT | Z20: Stock Based Compensation
B21: Interest Rate on debt | D21: 0.0366 | E21: 0.0366 | F21: 0.0406 | G21: 0.0406 | H21: 0.0483 | I21: 0.0483 | J21: 0.0483 | K21: - | L21: - | N21: =AVERAGE(D21:L21) -> 0.042757143 | O21: =AVERAGE(D21:H21) -> 0.04054 | P21: =AVERAGE(D21:F21) -> 0.037933333 | R21: 0.04 | S21: 0.04 | U21: % Debt | Z21: Interest expenses
