Workbook
Name Sectors: '[1]Sector Impact'!$K$4:$K$16
Name Sectors: 'Sector Impact'!$K$4:$K$16

Sheet OP
B2: (Date of last update) | C2: Team 1 | D2: (Date of next Quarter/Annual Report) | E2: =Inputs!H3 -> #VALUE! | L2: {=_FV(E2,"Exchange")} -> New York Stock Exchange | M2: SIC:
B3: #VALUE! | D3: COMPANY DESCRIPTION | H3: CEO & BOARD OF DIRECTORS
D4: Nucor Corporation is a manufacturer of steel and steel products, with operating facilities in the United States, Canada and Mexico. Its segments include steel mills, steel products, raw materials, and Nucor Data Systems. The Steel Mills segment produces sheet steel (hot-rolled, cold-rolled and galvanized), plate steel, structural steel (wide-flange beams, beam blanks, H-piling, and sheet piling) and bar steel (blooms, billets, concrete reinforcing bar, merchant bar and engineered special bar quality. The Steel products segment produces steel joists and joist girders, steel deck, galvanized torque tubes used in solar arrays, hollow structural section (HSS) steel tubing, electrical conduit, fabricated concrete reinforcing steel, cold finished steel, and steel fasteners. The Raw materials segment produces direct reduced iron (DRI), brokers ferrous and nonferrous metals, and pig iron. Nucor Data Systems serves its customers in the data center infrastructure industry. | H4: Name, Age and Tenure | I4: Gender | J4: Executive? | L4: Other roles
H5: Leon J. Topalian, 56, 2020 | I5: M | J5: Y | L5: President, CEO & Chairman of the Board
H6: Stephen D. Laxton,52 2022 | I6: M | J6: Y | L6: CFO, Treasurer & Executive VP
H7: David A. Sumoski, 57, 2021 | I7: M | J7: N | L7: Chief Operating Officer
H8: K. Rex Query, 58, 2021 | I8: M | J8: Y | L8: Executive Vice President of Sheet, Tubular Products & Talent Resources
H9: Norma B. Clayton, 66, 2021 | I9: W | J9: N | L9: Retired Vice President The Boeing Company
H10: Patrick J. Dempsey, 59, 2016 | I10: M | J10: N | L10: Retired President & CEO of Barnes Group Inc.
H11: Nicholas C. Gangestad, 56, 2023 | I11: M | J11: N | L11: Senior Vice President & Chief Financial Officer of Rockwell Automation, Inc.
H12: Christopher J. Kearney, 68, 2007 | I12: M | J12: N | L12: Lead Director of Nucor Corporation and Retired Chairman, CEO & President SPX FLOW, Inc.
H13: Laurette T. Koellner, 69, 2015 | I13: W | J13: N | L13: Retired President of Boeing International
H14: Michael W. Lamach, 60, 2022 | I14: M | J14: N | L14: Retired Executive Chair & CEO of Trane Technologies plc
B15: {=_FV(E2,"Currency")&" MILLIONS"} -> USD MILLIONS | H15: Nadja Y. West | I15: W | J15: N | L15: Lieutenant General, U.S. Army (Retired) & Former Commander of U.S. Army Medical Command
B18: COMPANY OVERVIEW
B19: Stock | D19: Liquidity and Solvency | F19: Segments | I19: ="Profitability ("&J20&")" -> Profitability (2023) | L19: Multiples
B20: Last Price | C20: {=_FV(E2,"Price")} -> 137.63 | D20: Total Assets | E20: =_xlfn.XLOOKUP(D20,'Fin. Data'!A:A,'Fin. Data'!B:B,,0) -> 35340.5 | F20: Regions | H20: % Sales | I20: Reporting Year | J20: 2023 | L20: Float | M20: =IF(Inputs!B80 <> "",Inputs!B80,"") -> 0.99169967
B21: Outstanding Shares | C21: {=_FV(E2,"Shares outstanding",TRUE)} -> 229535400 | D21: Total Liabilities | E21: =_xlfn.XLOOKUP(D21,'Fin. Data'!A:A,'Fin. Data'!B:B,,0) -> 13216.75 | F21: N/A | H21: =Segments!B5 -> NA | I21: End of Year | J21: 45291 | L21: Insiders Own | M21: =IF(Inputs!B81 <> "",Inputs!B81,"") -> 0.0051
B22: Market Cap. | C22: =C20*C21/1000000 -> 31590.957 | D22: Cash/Share | E22: =_xlfn.XLOOKUP("Cash & Eq.",'Fin. Data'!A:A,'Fin. Data'!B:B,,0)*1000000/C21 -> 27.809654 | I22: EBITDA | K22: =_xlfn.XLOOKUP(I22,'Fin. Data'!A:A,'Fin. Data'!B:B,,0) -> 7411.503 | L22: b (Yahoo) | M22: {=IF(_FV(E2,"Beta") <> "",_FV(E2,"Beta"),"")} -> 1.7855
B23: +Total Debt | C23: ='Fin. Data'!B63 -> 6842.183 | D23: EBITDA/Net Financial Cost (NFC) | E23: =IFERROR(_xlfn.XLOOKUP("EBITDA",'Fin. Data'!A:A,'Fin. Data'!B:B,,0)/_xlfn.XLOOKUP("Net Financial Cost",'Fin. Data'!A:A,'Fin. Data'!B:B,,0),"") -> 250.11822 | I23: Depreciation & Amortization | K23: =_xlfn.XLOOKUP(I23,'Fin. Data'!A:A,'Fin. Data'!B:B,,0) -> 1168.32 | L23: Score (S&P) | M23: =IF(Inputs!B82 <> "",Inputs!B82,"") -> A-
B24: -Cash | C24: ='Fin. Data'!B41 -> 6383.3 | D24: Debt/EBITDA | E24: =IFERROR(_xlfn.XLOOKUP("Total Debt",'Fin. Data'!A:A,'Fin. Data'!B:B,,0)/_xlfn.XLOOKUP("EBITDA",'Fin. Data'!A:A,'Fin. Data'!B:B,,0),"") -> 0.92318427 | I24: EBIT | K24: =_xlfn.XLOOKUP(I24,'Fin. Data'!A:A,'Fin. Data'!B:B,,0) -> 6243.183 | L24: Price/Book Value | M24: =IFERROR((C20*C21/(E20-E21))/1000000,"") -> 1.4279205
B25: =Enterprise Value | C25: =C22+C23-C24 -> 32049.84 | D25: "Others Assets"/Asset | E25: =IFERROR(_xlfn.XLOOKUP("Other Assets",'Fin. Data'!A:A,'Fin. Data'!B:B,,0)/_xlfn.XLOOKUP("Total Assets",'Fin. Data'!A:A,'Fin. Data'!B:B,,0),"") -> 0.26531487 | I25: Net Income | K25: =_xlfn.XLOOKUP(I25,'Fin. Data'!A:A,'Fin. Data'!B:B,,0) -> 4524.849 | L25: NCF(3y avg)/Asset | M25: =IFERROR(K31/E20,"") -> -0.0028243139
B26: Holdings (nac/int'l) | C26: - | D26: Debt/Assets | E26: =_xlfn.XLOOKUP(D26,'Fin. Data'!A:A,'Fin. Data'!B:B,,0) -> 0.19360742 | F26: Categories | H26: % Sales | I26: EPS | K26: =1000000*K25/C21 -> 19.713077 | L26: Price/Net Inc. (3y avg) | M26: =IFERROR(C22/K30,"") -> 4.9986635
B27: t liq. (Holdings/Vol.) | C27: - | D27: EBITDA Margin (average) | E27: =IFERROR(AVERAGE(_xlfn.XLOOKUP("EBITDA Margin",'Fin. Data'!A:A,'Fin. Data'!B:D,,0)),"") -> 0.256734 | F27: =Segments!C18 -> Steel mills | H27: =Segments!B18 -> 0.57881405 | I27: ROA | K27: =IFERROR(K25/E20,"") -> 0.12803579 | L27: EV/Asset | M27: =IFERROR(C25/E20,"") -> 0.906887
B28: % Short | C28: 0.0267 | D28: Operating Margin (average) | E28: =IFERROR(AVERAGE(_xlfn.XLOOKUP("Operating Margin",'Fin. Data'!A:A,'Fin. Data'!B:D,,0)),"") -> 0.22932636 | I28: ROIC | K28: =IFERROR(Peers!C18,"") -> 0.22789616 | L28: EV/Ebitda (3y average) | M28: =IFERROR(C25/K29,"") -> 3.3027171
D29: Net Income Margin (average) | E29: =IFERROR(AVERAGE(_xlfn.XLOOKUP("Net Income Margin",'Fin. Data'!A:A,'Fin. Data'!B:D,,0)),"") -> 0.16691229 | F29: =Segments!C19 -> Steel products | H29: =Segments!B19 -> 0.36754976 | I29: EBITDA (3y average) | K29: =AVERAGE(_xlfn.XLOOKUP("EBITDA",'Fin. Data'!A:A,'Fin. Data'!B:D,,0)) -> 9704.0827 | L29: Price/NCF (3y average) | M29: =IFERROR(C22/K31,"") -> -316.50249
B30: E | I30: Net Income (3y average) | K30: =AVERAGE(_xlfn.XLOOKUP("Net Income",'Fin. Data'!A:A,'Fin. Data'!B:D,,0)) -> 6319.8807 | L30: Bonds 1,3,5a (USD) | M30: -
B31: S | D31: Net Financial Cost/Avg Net Debt | E31: =IFERROR(-_xlfn.XLOOKUP("Net Financial Cost",'Fin. Data'!A:A,'Fin. Data'!B:B,,0)/AVERAGE(_xlfn.XLOOKUP("Net Debt",'Fin. Data'!A:A,'Fin. Data'!B:D,,0)),"") -> -0.014279817 | F31: =Segments!C20 -> Raw materials | H31: =Segments!B20 -> 0.053636192 | I31: NCF (3y average) | K31: =AVERAGE(_xlfn.XLOOKUP("Net Financial Cost",'Fin. Data'!A:A,'Fin. Data'!B:D,,0)) -> -99.812667 | L31: Div+Rep.(3y avg)/Price | M31: =-IFERROR(SUM(E52:E54)/(3*C22),"") -> 0.096346137
B32: G | L32: Div. Yield | M32: =-IFERROR(L53/C22,"") -> 0.016287256
B33: INVESTMENT THESIS
B34: Pillars of Recommendation | H34: Recommendation | I34: Valuation Assumptions
B35: Pillar | C35: Explanation | H35: HOLD | I35: Check DCF
B36: Market Leadership in the Steel Industry | C36: Nucor is the largest steel producer in the United States, benefiting from economies of scale, a vertically integrated business model, and operational efficiency.
B37: Sustainability and Innovation | C37: Nucor leads the industry in sustainable steel, leveraging electric arc furnace technology to produce steel with one of the lowest carbon footprints in the sector.
B38: Diversified Revenue Streams | C38: Nucor's product portfolio includes not only raw steel but also value-added steel products, ensuring more stability during fluctuations in specific sectors like automotive or construction.
B39: Risks of Investment | H39: Price Target | I39: Valuation
B40: Risk | C40: Explanation | H40: =IFERROR(DCF!D75,"") -> 203.10745 | I40: Discount Rate | L40: =DCF!F50 -> 0.1
B41: Volatility in Steel Prices | C41: Steel prices are highly cyclical, driven by global supply and demand dynamics, drops in steel prices adversely impact Nucor’s margins and revenue
B42: Competition from Chinese Steel Producers | C42: China is the world's largest steel producer and exporter, producing cheaper steel and potentially driving down prices and eroding profit margins. | I42: Upside | L42: =IFERROR(DCF!D74,"") -> 0.47574985
B43: Trade Policies and Tariffs | C43: Changes in trade policies, such as the removal of tariffs on imported steel, could increase competition from international producers
...

Sheet Segments
B2: ="Regions "&"("&OP!$J$20&")" -> Regions (2023) | Q2: Products
D3: Nominal value | K3: YoY Growth
B4: Weight | C4: Region | D4: =OP!J20 -> 2023 | E4: =D4-1 -> 2022 | F4: =E4-1 -> 2021 | G4: =F4-1 -> 2020 | H4: =G4-1 -> 2019 | I4: =H4-1 -> 2018 | K4: =OP!J20 -> 2023 | L4: =K4-1 -> 2022 | M4: =L4-1 -> 2021 | N4: =M4-1 -> 2020 | O4: =N4-1 -> 2019 | P4: =O4-1 -> 2018
B5: NA | C5: NA | D5: NA | E5: NA | F5: NA | G5: NA | H5: NA | I5: NA | K5: NA | L5: NA | M5: NA | N5: NA | O5: NA | P5: NA
P6: -
P7: -
P8: -
P9: -
P10: -
C13: TOTAL | P13: -
B15: ="Categories "&"("&OP!$J$20&")" -> Categories (2023)
D16: Nominal value | K16: YoY Growth
B17: Weight | C17: Category | D17: =OP!J20 -> 2023 | E17: =D17-1 -> 2022 | F17: =E17-1 -> 2021 | G17: =F17-1 -> 2020 | H17: =G17-1 -> 2019 | I17: =H17-1 -> 2018 | K17: =OP!J20 -> 2023 | L17: =K17-1 -> 2022 | M17: =L17-1 -> 2021 | N17: =M17-1 -> 2020 | O17: =N17-1 -> 2019 | P17: =O17-1 -> 2018
B18: =IFERROR(D18/$D$24,"") -> 0.57881405 | C18: Steel mills | D18: 20092662 | E18: 24189858 | F18: 24145396 | G18: 20139658 | H18: 22588858 | I18: 25067279 | K18: =(D18-E18)/E18 -> -0.1693766 | L18: =(E18-F18)/F18 -> 0.0018414277 | M18: =(F18-G18)/G18 -> 0.19889802 | N18: =(G18-H18)/H18 -> -0.10842514 | O18: =(H18-I18)/I18 -> -0.098870763 | P18: -
B19: =IFERROR(D19/$D$24,"") -> 0.36754976 | C19: Steel products | D19: 12758939 | E19: 15060328 | F19: 9727943 | G19: 6623068 | H19: 6990064 | I19: 6796501 | K19: =(D19-E19)/E19 -> -0.15281135 | L19: =(E19-F19)/F19 -> 0.54815134 | M19: =(F19-G19)/G19 -> 0.46879709 | N19: =(G19-H19)/H19 -> -0.052502524 | O19: =(H19-I19)/I19 -> 0.028479802 | P19: -
B20: =IFERROR(D20/$D$24,"") -> 0.053636192 | C20: Raw materials | D20: 1861900 | E20: 2262281 | F20: 2610600 | G20: 1407283 | H20: 1664844 | I20: 2025560 | K20: =(D20-E20)/E20 -> -0.17698111 | L20: =(E20-F20)/F20 -> -0.13342488 | M20: =(F20-G20)/G20 -> 0.85506398 | N20: =(G20-H20)/H20 -> -0.15470579 | O20: =(H20-I20)/I20 -> -0.17808211 | P20: -
B24: =SUM(B18:B23) -> 1 | C24: TOTAL | D24: =SUM(D18:D23) -> 34713501 | E24: =SUM(E18:E23) -> 41512467 | F24: =SUM(F18:F23) -> 36483939 | G24: =SUM(G18:G23) -> 28170009 | H24: =SUM(H18:H23) -> 31243766 | I24: =SUM(I18:I23) -> 33889340 | K24: =(D24-E24)/E24 -> -0.1637813 | L24: =(E24-F24)/F24 -> 0.13782854 | M24: =(F24-G24)/G24 -> 0.29513409 | N24: =(G24-H24)/H24 -> -0.09837985 | O24: =(H24-I24)/I24 -> -0.078065079 | P24: -
B26: ="Categories "&"("&OP!$J$20&")" -> Categories (2023) | I26: Graphs
C27: % of Sales
B28: Category | C28: 2023 | D28: 2022 | E28: 2021 | F28: 2020 | G28: 2019 | H28: 2018
B29: Steel mills | C29: =D18/$D$24 -> 0.57881405 | D29: =E18/$E$24 -> 0.58271309 | E29: =F18/$F$24 -> 0.66180891 | F29: =G18/$G$24 -> 0.71493261 | G29: =H18/$H$24 -> 0.72298768 | H29: =I18/$I$24 -> 0.73968035
B30: Steel products | C30: =D19/$D$24 -> 0.36754976 | D30: =E19/$E$24 -> 0.36279048 | E30: =F19/$F$24 -> 0.26663631 | F30: =G19/$G$24 -> 0.23511061 | G30: =H19/$H$24 -> 0.22372668 | H30: =I19/$I$24 -> 0.20054982
B31: Raw materials | C31: =D20/$D$24 -> 0.053636192 | D31: =E20/$E$24 -> 0.054496424 | E31: =F20/$F$24 -> 0.071554774 | F31: =G20/$G$24 -> 0.049956782 | G31: =H20/$H$24 -> 0.053285638 | H31: =I20/$I$24 -> 0.059769827
B35: TOTAL | C35: =SUM(C29:C34) -> 1 | D35: =SUM(D29:D34) -> 1 | E35: =SUM(E29:E34) -> 1 | F35: =SUM(F29:F34) -> 1 | G35: =SUM(G29:G34) -> 1 | H35: =SUM(H29:H34) -> 1
B37: Categories | D37: Description
B38: Steel mills | D38: Production of sheet steel, plate steel, structural steel and others mainly from scrap steel
B39: Steel products | D39: Steel structures ready to deliver to consumer markets, such as metal builoding systems, insulated metal panels, structures for communications and energy transmission, steel mesh and fasteners, etc.
B40: Raw Materials | D40: Scrap recycling and brokerage operations, direct reduced iron operations (focused providing value for steelmaking operations rather selling)
B45: Industry | J45: Graphs (Industry Forecasts)
B46: Drivers | D46: Description
B47: Urbanization and infrastructure | D47: Increasing demand for steel in urban housing and infrastructure projects
B48: Automotive industry | D48: Rising demand for lightweight, durable and costumised steel products in electrict vehicles
B49: Sales forecast
B50: Source | D50: Market Growth CAGR | G50: Period
B51: Precision Business Insights | D51: 0.029 | G51: 2024-2030
B52: Future Market Insights | D52: 0.033 | G52: 2023-2033
B53: Markets and Markets | D53: 0.038 | G53: 2022-2027
B54: Average | D54: =AVERAGE(D51:F53) -> 0.033333333
B55: Company's Strategy / Extra Notes
B56: The company is divisting from it's steel meels segment and shifting to steel products, which have a higher margin and growth expectations given the growth in Evs, datacenters, renewable energy, and others. This is complemented with strategic acquisitions as a way of gaining exposure to these businesses.
...

Sheet Acuerdo
A1: Invertir
A2: NO invertir
A3: Mantener sin elevar posición
A4: Mantener (y seguir comprando)
A5: Liquidar
A6: PENDIENTE

Sheet Peers
B1: Peer Logo | C1: Peer Name | D1: Description
C2: #VALUE! | D2: One of the largest U.S. steel producers and metal recyclers, founded in 1993 and headquartered in Fort Wayne, Indiana. The company operates through steel production, metals recycling, and steel fabrication, serving industries like automotive and construction. Known for its sustainability efforts, SDI uses Electric Arc Furnace (EAF) technology to recycle scrap steel, reducing environmental impact. Its vertically integrated structure ensures efficiency across its supply chain, while OmniSource, its metals recycling arm, is one of North America's largest. SDI emphasizes innovation, safety, and environmental responsibility.
C3: #VALUE! | D3: Founded in 1901, U.S. Steel is one of the largest steel producers in the U.S., headquartered in Pittsburgh, Pennsylvania. It operates integrated steel mills and produces a variety of steel products for industries such as automotive, construction, and energy. U.S. Steel is focused on innovation and sustainability, including the use of advanced manufacturing processes and clean energy solutions. The company is known for its legacy as a key player in America's industrial growth and its ongoing commitment to sustainable steelmaking practices.
C4: #VALUE! | D4: Founded in 1915 and headquartered in Irving, Texas, is a global leader in recycling, manufacturing, and fabricating steel and metal products. CMC operates through a network of steel mills, recycling facilities, and fabrication plants, primarily serving construction, infrastructure, and industrial markets. With a focus on sustainability, CMC heavily relies on Electric Arc Furnace (EAF) technology to recycle scrap metal into new steel products, reducing environmental impact and promoting resource efficiency.
C5: #VALUE! | D5: Founded in 1847 and headquartered in Cleveland, Ohio, is the largest flat-rolled steel producer and iron ore pellet supplier in North America. Originally focused on mining, the company expanded into steel production through acquisitions of AK Steel and ArcelorMittal USA. Cleveland-Cliffs is vertically integrated, from mining raw materials to producing steel for the automotive, infrastructure, and manufacturing industries. The company emphasizes sustainability, innovation, and reducing carbon emissions through advanced steelmaking technologies.
D6: {=_FV(C6,"Description")} -> #VALUE!
B8: In Millions USD | C8: =OP!E2 -> #VALUE! | D8: =C2 -> #VALUE! | E8: =C3 -> #VALUE! | F8: =C4 -> #VALUE! | G8: =C5 -> #VALUE! | H8: =C6 -> 0 | I8: AVERAGE | J8: Deviation from Average
B9: Company Info | I9: =IFERROR(AVERAGE(C9:H9),"") | L9: TRAFFIC
B10: Market Cap | C10: {=_FV(C8,"Market cap",TRUE)/1000000} -> 31590.957 | D10: {=_FV(D8,"Capitalização de mercado",TRUE)/1000000} -> 20721.256 | E10: {=_FV(E8,"Capitalização de mercado",TRUE)/1000000} -> 12416.823 | F10: {=_FV(F8,"Capitalização de mercado",TRUE)/1000000} -> 6733.1792 | G10: {=_FV(G8,"Capitalização de mercado",TRUE)/1000000} -> 5654.3673 | H10: {=_FV(H8,"Capitalização de mercado",TRUE)/1000000} -> #VALUE! | I10: =IFERROR(AVERAGE(C10:G10),"") -> 15423.317 | J10: =_xlfn.STDEV.S(C10:G10) -> 10833.405 | M10: Best Value
B11: Net Sales (current) | C11: =C56 -> 34714 | D11: =D56 -> 18795.316 | E11: =E56 -> 18053 | F11: =F56 -> 8799.533 | G11: =G56 -> 21996 | H11: =H56 -> 0 | I11: =IFERROR(AVERAGE(C11:H11),"") -> 17059.641 | J11: =_xlfn.STDEV.S(C11:G11) -> 9355.0315
B12: Profitability | I12: =IFERROR(AVERAGE(C12:H12),"") | M12: Important Value
B13: Sales Growth (ttm) | C13: =C56/C55-1 -> -0.16375988 | D13: =D56/D55-1 -> -0.15567554 | E13: =E56/E55-1 -> -0.142986 | F13: =F56/F55-1 -> -0.012783782 | G13: =G56/G55-1 -> -0.043194571 | H13: =H56/H55-1 -> #DIV/0! | I13: =AVERAGE(C13:G13) -> -0.10367995 | J13: =_xlfn.STDEV.S(C13:G13) -> 0.07031838
B14: Sales Growth (36m) | C14: =C56/C54-1 -> 0.72363456 | D14: =D56/D54-1 -> 0.96035896 | E14: =E56/E54-1 -> 1.0596691 | F14: =F56/F54-1 -> 0.30755525 | G14: =G56/G54-1 -> 3.1353638 | H14: =H56/H54-1 -> #DIV/0! | I14: =AVERAGE(C14:G14) -> 1.2373163 | J14: =_xlfn.STDEV.S(C14:G14) -> 1.099906 | M14: Worst Value
B15: Operating Margin | C15: =C59/C56 -> 0.17947802 | D15: =D59/D56 -> 0.16765778 | E15: =E59/E56 -> 0.044258572 | F15: =F59/F56 -> 0.13206314 | G15: =G59/G56 -> 0.030778323 | H15: =H59/H56 -> #DIV/0! | I15: =AVERAGE(C15:G15) -> 0.11084717 | J15: =_xlfn.STDEV.S(C15:G15) -> 0.069341219
B16: Net Income Margin | C16: =C62/C56 -> 0.13034652 | D16: =D62/D56 -> 0.13039855 | E16: =E62/E56 -> 0.056832659 | F16: =F62/F56 -> 0.097618817 | G16: =G62/G56 -> 0.018139662 | H16: =H62/H56 -> #DIV/0! | I16: =AVERAGE(C16:G16) -> 0.086667242 | J16: =_xlfn.STDEV.S(C16:G16) -> 0.048801576
B17: Return on Equity (RoE) | C17: =C62/C74 -> 0.21607968 | D17: =D62/D74 -> 0.2827403 | E17: =E62/E74 -> 0.092875894 | F17: =F62/F74 -> 0.20843879 | G17: =G62/G74 -> 0.049125831 | H17: =H62/H74 -> #DIV/0! | I17: =AVERAGE(C17:G17) -> 0.1698521 | J17: =_xlfn.STDEV.S(C17:G17) -> 0.096007599
B18: Return on Invested Capital (ROIC) | C18: =(1+C61/(C59+C60))*C59/(C73+C74-C65) -> 0.22789616 | D18: =(1+D61/(D59+D60))*D59/(D73+D74-D65) -> 0.22964938 | E18: =(1+E61/(E59+E60))*E59/(E73+E74-E65) -> 0.055732666 | F18: =(1+F61/(F59+F60))*F59/(F73+F74-F65) -> 0.1897214 | G18: =(1+G61/(G59+G60))*G59/(G73+G74-G65) -> 0.037672084 | H18: =(1+H61/(H59+H60))*H59/(H73+H74-H65) -> #DIV/0! | I18: =AVERAGE(C18:G18) -> 0.14813434 | J18: =_xlfn.STDEV.S(C18:G18) -> 0.094175519
B19: Solvency | I19: =IFERROR(AVERAGE(C19:H19),"")
B20: Debt/Assets | C20: =C73/C70 -> 0.19360742 | D20: =D73/D70 -> 0.20793619 | E20: =E73/E70 -> 0.20321745 | F20: =F73/F70 -> 0.17547439 | G20: =G73/G70 -> 0.18201517 | H20: =H73/H70 -> #DIV/0! | I20: =AVERAGE(C20:G20) -> 0.19245012 | J20: =_xlfn.STDEV.S(C20:G20) -> 0.013730954
B21: Net Debt/EBITDA | C21: =(C73-C65)/C58 -> 0.061914972 | D21: =(D73-D65)/D58 -> 0.47342438 | E21: =(E73-E65)/E58 -> 0.70437318 | F21: =(F73-F65)/F58 -> 0.41469263 | G21: =(G73-G65)/G58 -> 1.566719 | H21: =(H73-H65)/H58 -> #DIV/0! | I21: =AVERAGE(C21:G21) -> 0.64422483 | J21: =_xlfn.STDEV.S(C21:G21) -> 0.56470256
B22: Interest Coverage Ratio | C22: =-C58/C60 -> -250.11822 | D22: =-D58/D60 -> 46.924651 | E22: =-E58/E60 -> -6.9153226 | F22: =-F58/F60 -> 34.413836 | G22: =-G58/G60 -> 6.6124567 | H22: =-H58/H60 -> #DIV/0! | I22: =AVERAGE(C22:G22) -> -33.816519 | J22: =_xlfn.STDEV.S(C22:G22) -> 122.79975
B23: Liquidity
B24: Current Ratio | C24: =C68/C72 -> 3.5663999 | D24: =D68/D72 -> 2.9103621 | E24: =E68/E72 -> 1.758612 | F24: =F68/F72 -> 3.7265649 | G24: =G68/G72 -> 1.8916762 | H24: =H68/H72 -> #DIV/0! | I24: =AVERAGE(C24:G24) -> 2.770723 | J24: =_xlfn.STDEV.S(C24:G24) -> 0.91696874
B25: Quick Ratio | C25: =(C65+C66)/C72 -> 2.0321231 | D25: =(D65+D66)/D72 -> 1.2902282 | E25: =(E65+E66)/E72 -> 1.1388045 | F25: =(F65+F66)/F72 -> 2.1720026 | G25: =(G65+G66)/G72 -> 0.58095781 | H25: =(H65+H66)/H72 -> #DIV/0! | I25: =AVERAGE(C25:G25) -> 1.4428232 | J25: =_xlfn.STDEV.S(C25:G25) -> 0.65907162
B26: Activity | I26: =IFERROR(AVERAGE(C26:H26),"")
B27: Inventory Turnover | C27: =C57/C67 -> 4.8226528 | D27: =D57/D67 -> 5.0954432 | E27: =E57/E67 -> 7.4262218 | F27: =F57/F67 -> 6.7475275 | G27: =G57/G67 -> 4.6199552 | H27: =H57/H67 -> #DIV/0! | I27: =AVERAGE(C27:G27) -> 5.7423601 | J27: =_xlfn.STDEV.S(C27:G27) -> 1.2619338
B28: Acc. Receivable Turnover | C28: =C56/C66 -> 11.754269 | D28: =D56/D66 -> 11.686398 | E28: =E56/E66 -> 11.662145 | F28: =F56/F66 -> 7.0951559 | G28: =G56/G66 -> 11.954348 | H28: =H56/H66 -> #DIV/0! | I28: =AVERAGE(C28:G28) -> 10.830463 | J28: =_xlfn.STDEV.S(C28:G28) -> 2.091254
A29: Price/Sales | B29: Payables Turnover | C29: =C57/C71 -> 13.314722 | D29: =D57/D71 -> 13.552354 | E29: =E57/E71 -> 5.2189564 | F29: =F57/F71 -> 19.176207 | G29: =G57/G71 -> 9.8165793 | H29: =H57/H71 -> #DIV/0! | I29: =AVERAGE(C29:G29) -> 12.215764 | J29: =_xlfn.STDEV.S(C29:G29) -> 5.1515374
B30: Fixed Asset Turnover | C30: =C56/C69 -> 3.1416039 | D30: =D56/D69 -> 2.7910169 | E30: =E56/E69 -> 1.7370345 | F30: =F56/F69 -> 1.9408621 | G30: =G56/G69 -> 2.4728499 | H30: =H56/H69 -> #DIV/0! | I30: =AVERAGE(C30:G30) -> 2.4166735 | J30: =_xlfn.STDEV.S(C30:G30) -> 0.58247712
B31: Total Asset Turnover | C31: =C56/C70 -> 0.98227246 | D31: =D56/D70 -> 1.2607182 | E31: =E56/E70 -> 0.88274412 | F31: =F56/F70 -> 1.3254117 | G31: =G56/G70 -> 1.2542624 | H31: =H56/H70 -> #DIV/0! | I31: =AVERAGE(C31:G31) -> 1.1410818 | J31: =_xlfn.STDEV.S(C31:G31) -> 0.19561377
B32: Valuation | I32: =IFERROR(AVERAGE(C32:H32),"")
B33: Price/Earnings | C33: =C10/C62 -> 6.98166 | D33: =D10/D62 -> 8.4546117 | E33: =E10/E62 -> 12.102167 | F33: =F10/F62 -> 7.8383926 | G33: =G10/G62 -> 14.171347 | H33: =H10/H62 -> #VALUE! | I33: =AVERAGE(C33:G33) -> 9.9096356 | J33: =_xlfn.STDEV.S(C33:G33) -> 3.0801606
B34: Price/Sales | C34: =C10/C56 -> 0.91003506 | D34: =D10/D56 -> 1.1024691 | E34: =E10/E56 -> 0.68779834 | F34: =F10/F56 -> 0.76517461 | G34: =G10/G56 -> 0.25706343 | H34: =H10/H56 -> #VALUE! | I34: =AVERAGE(C34:G34) -> 0.74450811 | J34: =_xlfn.STDEV.S(C34:G34) -> 0.31495264
B35: Price/Book | C35: =C10/C74 -> 1.5085949 | D35: =D10/D74 -> 2.3904595 | E35: =E10/E74 -> 1.1239996 | F35: =F10/F74 -> 1.633825 | G35: =G10/G74 -> 0.69617918 | H35: =H10/H74 -> #VALUE! | I35: =AVERAGE(C35:G35) -> 1.4706116 | J35: =_xlfn.STDEV.S(C35:G35) -> 0.63128577
B36: EV/Sales | C36: =(C73+C10-C65)/C56 -> 0.92325402 | D36: =(D73+D10-D65)/D56 -> 1.19287 | E36: =(E73+E10-E65)/E56 -> 0.75471243 | F36: =(F73+F10-F65)/F56 -> 0.83025295 | G36: =(G73+G10-G65)/G56 -> 0.39317909 | H36: =(H73+H10-H65)/H56 -> #VALUE! | I36: =AVERAGE(C36:G36) -> 0.8188537 | J36: =_xlfn.STDEV.S(C36:G36) -> 0.28992695
B37: EV/EBITDA | C37: =(C73+C10-C65)/C58 -> 4.3243375 | D37: =(D73+D10-D65)/D58 -> 6.2469942 | E37: =(E73+E10-E65)/E58 -> 7.9445035 | F37: =(F73+F10-F65)/F58 -> 5.2905433 | G37: =(G73+G10-G65)/G58 -> 4.5255716 | H37: =(H73+H10-H65)/H58 -> #VALUE! | I37: =AVERAGE(C37:G37) -> 5.66639 | J37: =_xlfn.STDEV.S(C37:G37) -> 1.4807713
B38: Stock Info | I38: =IFERROR(AVERAGE(C38:H38),"")
B39: Float | C39: =OP!M20 -> 0.99169967 | D39: =143.93/154.3 -> 0.93279326 | E39: =202.58/224.96 -> 0.90051565 | F39: =114.03/114.99 -> 0.99165145 | G39: =458.79/468.04 -> 0.98023673 | I39: =IFERROR(AVERAGE(C39:H39),"") -> 0.95937935 | J39: =_xlfn.STDEV.S(C39:G39) -> 0.040905004
B40: b (Yahoo) | C40: =OP!M22 -> 1.7855 | D40: 1.97 | E40: 1.87 | F40: 1.14 | G40: 1.97 | I40: =IFERROR(AVERAGE(C40:H40),"") -> 1.7471 | J40: =_xlfn.STDEV.S(C40:G40) -> 0.34803671
B41: Dividend Yield (yahoo finance) | C41: =OP!M32 -> 0.016287256 | D41: 0 | E41: 0.0054 | F41: 0.0136 | G41: 0 | I41: =IFERROR(AVERAGE(C41:H41),"") -> 0.0070574512 | J41: =_xlfn.STDEV.S(C41:G41) -> 0.0075887518
...

Sheet ESG
B1: Company GICS Sector: | T1: Yes
B2: Materials | C2: <- Select Industry | T2: No
B3: ESG Analysis | K3: Relative ESG Analysis
B4: Parameters | C4: Impact | D4: Do they report? | E4: Ranking | F4: Mitigation Plan | G4: Traffic Lights | H4: Improvement over time? | I4: Targets / Goals? | J4: Comments | K4: Parameters | L4: =Peers!C8 -> #VALUE! | M4: =Peers!D8 -> #VALUE! | N4: =Peers!E8 -> #VALUE! | O4: =Peers!F8 -> #VALUE! | P4: =Peers!G8 -> #VALUE! | Q4: =Peers!H8 -> 0 | R4: AVERAGE
B5: Environmental | K5: Ratios
A6: 1 | B6: CO2 Direct Emissions | C6: =VLOOKUP($B$2,'Sector Impact'!$K$4:$AA$16,A6+1,FALSE) -> Very High | E6: Medium | K6: CO2 Emissions/$M Sales | L6: =L12/L$11 -> 195.88639 | M6: =M12/M$11 -> 109.415 | N6: =N12/N$11 -> 1508.3366 | O6: =O12/O$11 -> 120.0217 | P6: =P12/P$11 -> 1268.4124 | Q6: =Q12/Q$11 -> #VALUE! | R6: =IFERROR(AVERAGE(L6:P6),"") -> 640.41442 | Z6: 2018 | AA6: 2019 | AB6: 2020 | AC6: 2021 | AD6: 2022 | AE6: 2023
A7: 2 | B7: Total Water Consumption | C7: =VLOOKUP($B$2,'Sector Impact'!$K$4:$AA$16,A7+1,FALSE) -> Very High | E7: Medium High | K7: Water Consumption/$M Sales | L7: =L13/L$11 -> 863.05237 | M7: =M13/M$11 -> 971.90742 | N7: =N14/N$11 -> 19081.815 | O7: =O13/O$11 -> 722.1417 | P7: =P13/P$11 -> 47.291189 | Q7: =Q13/Q$11 -> #VALUE! | R7: =IFERROR(AVERAGE(L7:P7),"") -> 4337.2415 | Y7: CO2 Emissions Total (Tonnes) | Z7: 22417073 | AA7: 21208537 | AB7: 21208537 | AC7: 12800000 | AD7: 11500000 | AE7: =6.8*10^6 -> 6800000
A8: 3 | B8: Total Energy Consumption | C8: =VLOOKUP($B$2,'Sector Impact'!$K$4:$AA$16,A8+1,FALSE) -> Very High | E8: Medium | K8: Energy Consumption/$M Sales | L8: =L14/L$11 -> 3364.003 | M8: =M14/M$11 -> 2861.3269 | N8: =N14/N$11 -> 19081.815 | O8: =O14/O$11 -> 2232.5109 | P8: =P14/P$11 -> 18392.533 | Q8: =Q14/Q$11 -> #VALUE! | R8: =IFERROR(AVERAGE(L8:P8),"") -> 9186.4377 | Y8: Water Consumption Total (Cubic Meters) | Z8: 25000000 | AA8: 27000000 | AB8: 27000000 | AC8: 28000000 | AD8: 31000000 | AE8: 29960000
A9: 4 | B9: Waste Management | C9: =VLOOKUP($B$2,'Sector Impact'!$K$4:$AA$16,A9+1,FALSE) -> Very High | E9: Medium High | K9: Waste Production/$M Sales | L9: =L15/L$11 -> 37.045572 | M9: =M15/M$11 -> 22.923277 | N9: =N15/N$11 -> 126.84734 | O9: =O15/O$11 -> 116.60602 | P9: =P15/P$11 -> 99.06192 | Q9: =Q15/Q$11 -> #VALUE! | R9: =IFERROR(AVERAGE(L9:P9),"") -> 80.496826 | Y9: Energy Consumption Total (Gigajoules) | Z9: 120000000 | AA9: 112000000 | AB9: 112000000 | AC9: -- | AD9: -- | AE9: 116778000
A10: 5 | B10: Land Degradation/Deforestation/Biodiversity loss/Animal sufering/… | C10: =VLOOKUP($B$2,'Sector Impact'!$K$4:$AA$16,A10+1,FALSE) -> High | K10: Inputs | Y10: Waste Production Total (Tonnes) | AE10: 1286000
B11: Social | K11: Net Sales ($M) | L11: 34714 | M11: 18795 | N11: 18053 | O11: 8800 | P11: 21996 | Q11: ="-" -> -
A12: 6 | B12: Employee Turnover % | C12: =VLOOKUP($B$2,'Sector Impact'!$K$4:$AA$16,A12+1,FALSE) -> High | K12: CO2 Emissions Total (Tonnes) | L12: =6.8*10^6 -> 6800000 | M12: 2056455 | N12: =27.23*10^6 -> 27230000 | O12: 1056191 | P12: =27.9*10^6 -> 27900000 | Q12: ="-" -> -
A13: 7 | B13: Salaries & Compensation | C13: =VLOOKUP($B$2,'Sector Impact'!$K$4:$AA$16,A13+1,FALSE) -> High | K13: Water Consumption Total (Cubic Meters) | L13: 29960000 | M13: 18267000 | N13: 1162679000 | O13: 6354847 | P13: 1040217 | Q13: ="-" -> -
A14: 8 | B14: Reputation | C14: =VLOOKUP($B$2,'Sector Impact'!$K$4:$AA$16,A14+1,FALSE) -> Medium | K14: Energy Consumption Total (Gigajoules) | L14: 116778000 | M14: 53778640 | N14: 344484000 | O14: 19646096 | P14: 404562156 | Q14: ="-" -> -
A15: 9 | B15: Discrimination Events | C15: =VLOOKUP($B$2,'Sector Impact'!$K$4:$AA$16,A15+1,FALSE) -> High | F15: Yes | K15: Waste Production Total (Tonnes) | L15: 1286000 | M15: 430843 | N15: =2087486+202489 -> 2289975 | O15: 1026133 | P15: =561933+1617033 -> 2178966 | Q15: ="-" -> -
A16: 10 | B16: Work Safety | C16: =VLOOKUP($B$2,'Sector Impact'!$K$4:$AA$16,A16+1,FALSE) -> Low | K16: ESG Scores
A17: 11 | B17: Damage to consumer health | C17: =VLOOKUP($B$2,'Sector Impact'!$K$4:$AA$16,A17+1,FALSE) -> Very High | K17: Refinitiv | L17: 54 (55/66/35) | M17: 59 (65/45/73) | N17: 60 (62/63/53) | O17: 71 (74/68/74) | P17: 67 (71/55/83) | Q17: ="-" -> -
A18: 12 | B18: PXP? | C18: =VLOOKUP($B$2,'Sector Impact'!$K$4:$AA$16,A18+1,FALSE) -> Medium | K18: Sustainalytics | L18: 31.9 (high risk) | M18: 31.5 (high risk) | N18: 33.1 (high risk) | O18: 25.9 (medium risk) | P18: 36.6 (high risk) | Q18: ="-" -> -
A19: 13 | B19: Supply chain | C19: =VLOOKUP($B$2,'Sector Impact'!$K$4:$AA$16,A19+1,FALSE) -> Medium | K19: ISS | L19: C | M19: C | N19: C- | O19: B- | P19: C+ | Q19: ="-" -> -
A20: 14 | B20: Community involvement | C20: =VLOOKUP($B$2,'Sector Impact'!$K$4:$AA$16,A20+1,FALSE) -> Very High | K20: CDP | L20: F/D | M20: F/B- | N20: B/A- | O20: F/F | P20: B/B | Q20: ="-" -> -
A21: 15 | B21: Public Sector | C21: =VLOOKUP($B$2,'Sector Impact'!$K$4:$AA$16,A21+1,FALSE) -> High
A22: 16 | B22: Litigation | C22: =VLOOKUP($B$2,'Sector Impact'!$K$4:$AA$16,A22+1,FALSE) -> Medium | D22: Yes
B23: Corporate Governance | K23: PARAMETERS
A24: 17 | B24: Diversity (Gender, Age, Industry, Region) | K24: IMPACT | L24: RANKING | M24: MITIGATION PLAN | O24: TRAFFIC
A25: 18 | B25: % Independence | K25: Low | L25: "Best in class" | M25: Is there evidence of a plan/program ?
A26: 19 | B26: average time as independent directors | K26: Medium | L26: Medium High
A27: 20 | B27: Recent departures of directors / C-level executives? | K27: High | L27: Medium
A28: 21 | B28: CEO/Chairman duality | K28: Very high | L28: "Villain"
A29: 22 | B29: Transparency (ESG, segments, acquisitions, other)
A30: 23 | B30: Time taken to report after the end of the quarter / year
A31: 24 | B31: Additional participation of the CEO in other boards or excessive participation of Ch.
A32: 25 | B32: Audit / Consulting
A33: 26 | B33: ESG-compensation related
A34: 27 | B34: Management compensation schemes

Sheet DCF
A1: VALUATION MODEL
G3: Short Term | K3: Long Term
A4: Section | B4: Line # | C4: ITEM | D4: 2021 (Real) | E4: 2022 (Real) | F4: 2023 (Real) | G4: 2024 | H4: =G4+1 -> 2025 | I4: =H4+1 -> 2026 | J4: =I4+1 -> 2027 | K4: =J4+1 -> 2028 | L4: =K4+1 -> 2029 | M4: =L4+1 -> 2030 | N4: =M4+1 -> 2031 | O4: =N4+1 -> 2032 | ... AF4: =AE4+1 -> 2049
A5: INCOME STATEMENT | B5: 1 | C5: Growth | D5: ='Fin. Data'!D6 -> 0.81151936 | E5: =+E6/D6-1 -> 0.13781384 | F5: =+F6/E6-1 -> -0.16375988 | G5: =+G6/F6-1 -> -0.10541209 | H5: =+H6/G6-1 -> -0.035996523 | I5: =+I6/H6-1 -> -0.013013248 | J5: =+J6/I6-1 -> -0.012944607 | K5: =+K6/J6-1 -> 0.020795344 | L5: =+L6/K6-1 -> 0.020441751 | ... AE5: =+AE6/AD6-1 -> 0.055876363 | AF5: 0.02
B6: 2 | C6: Revenues/Sales | D6: =Inputs!D6 -> 36484 | E6: =Inputs!C6 -> 41512 | F6: =Inputs!B6 -> 34714 | G6: =Assumptions!K170 -> 31054.725 | H6: =Assumptions!L170 -> 29936.863 | I6: =Assumptions!M170 -> 29547.287 | J6: =Assumptions!N170 -> 29164.809 | K6: =Assumptions!O170 -> 29771.301 | L6: =Assumptions!P170 -> 30379.879 | M6: =Assumptions!Q170 -> 31097.595 | N6: =Assumptions!R170 -> 32453.664 | ... AE6: =Assumptions!AI170 -> 74563.147 | AF6: =AE6*(1+AF5) -> 76054.41
B7: 3 | C7: EBIT/Operating Margin | D7: =D8/D6 -> 0.25541087 | E7: =E8/E6 -> 0.25309019 | F7: =F8/F6 -> 0.17947802 | G7: =Assumptions!K181 -> 0.12904278 | H7: =Assumptions!L181 -> 0.14099639 | I7: =Assumptions!M181 -> 0.16202048 | J7: =Assumptions!N181 -> 0.17579154 | K7: =Assumptions!O181 -> 0.17640177 | L7: =Assumptions!P181 -> 0.17674056 | M7: =Assumptions!Q181 -> 0.1642265 | N7: =Assumptions!R181 -> 0.15697337 | ... AF7: =Assumptions!AJ181 -> 0.18831415
B8: 4 | C8: EBIT | D8: ='Fin. Data'!D11 -> 9318.41 | E8: ='Fin. Data'!C11 -> 10506.28 | F8: ='Fin. Data'!B11 -> 6230.4 | G8: =G7*G6 -> 4007.388 | H8: =H7*H6 -> 4220.9895 | I8: =I7*I6 -> 4787.2657 | J8: =J7*J6 -> 5126.9267 | K8: =K7*K6 -> 5251.7103 | L8: =L7*L6 -> 5369.3568 | M8: =M7*M6 -> 5107.0491 | N8: =N7*N6 -> 5094.3612 | ... AF8: =AF7*AF6 -> 14322.121
B9: 5a | C9: (Dep) | D9: 735.406 | E9: 826.692 | F9: 930.585 | G9: =$D$53*DCF!F40 -> -455.25052 | H9: =$D$53*DCF!G40 -> -544.81235 | I9: =$D$53*DCF!H40 -> -631.15026 | J9: =$D$53*DCF!I40 -> -716.36464 | K9: =$E$53*DCF!J40 -> -800.47595 | L9: =$E$53*DCF!K40 -> -861.80483 | M9: =$E$53*DCF!L40 -> -924.38738 | N9: =$E$53*DCF!M40 -> -988.44842 | O9: =$E$53*DCF!N40 -> -1055.303 | P9: =$E$53*DCF!O40 -> -1125.111 | Q9: =$E$53*DCF!P40 -> -1198.0656 | R9: =$E$53*DCF!Q40 -> -1274.3747 | ... AF9: =$E$53*DCF!AE40 -> -2844.9917 | AG9: =SUM(D9:AF9) -> -36428.82
B10: 5b | C10: (Amort) | D10: 129.154 | E10: 234.938 | F10: 237.735 | G10: =F38*$D$54 -> -353.8431 | H10: =G38*$D$54 -> -371.53526 | I10: =H38*$D$54 -> -390.11202 | J10: =I38*$D$54 -> -409.61762 | K10: =J38*$E$54 -> -387.08865 | L10: =K38*$E$54 -> -404.50764 | M10: =L38*$E$54 -> -422.71048 | N10: =M38*$E$54 -> -441.73245 | O10: =N38*$E$54 -> -461.61041 | P10: =O38*$E$54 -> -482.38288 | Q10: =P38*$E$54 -> -504.09011 | R10: =Q38*$E$54 -> -526.77417 | ... AF10: =AE38*$E$54 -> -975.55675
B11: 5c | C11: (Stock based compensation) | D11: 135.775 | E11: 136.834 | F11: 130.162 | G11: =G6*$D$55 -> -114.90248 | H11: =H6*$D$55 -> -110.76639 | I11: =I6*$D$55 -> -109.32496 | J11: =J6*$D$55 -> -107.90979 | K11: =K6*$D$55 -> -110.15381 | L11: =L6*$D$55 -> -112.40555 | M11: =M6*$D$55 -> -115.0611 | N11: =N6*$D$55 -> -120.07856 | ... AF11: =AF6*$D$55 -> -281.40132
B12: 6 | C12: EBITDA | D12: =D8-D9-D10 -> 8453.85 | E12: =E8-E9-E10 -> 9444.65 | F12: =F8-F9-F10 -> 5062.08 | G12: =G8-G9-G10 -> 4816.4816 | H12: =H8-H9-H10 -> 5137.3371 | I12: =I8-I9-I10 -> 5808.528 | J12: =J8-J9-J10 -> 6252.909 | K12: =K8-K9-K10 -> 6439.2749 | ... AF12: =AF8-AF9-AF10 -> 18142.67
B13: 7 | C13: (Net financing cost) | D13: ='Fin. Data'!D14 -> -158.854 | E13: ='Fin. Data'!C14 -> -170.216 | F13: ='Fin. Data'!B14 -> 29.632 | G13: 129.96314 | H13: =G43*$D$58-G44*$D$57 -> 451.85564 | I13: =H43*$D$58-H44*$D$57 -> 507.92127 | J13: =I43*$D$58-I44*$D$57 -> 620.12052 | K13: =J43*$E$58-J44*$E$57 -> 577.48263 | L13: =K43*$E$58-K44*$E$57 -> 542.0755 | M13: =L43*$E$58-L44*$E$57 -> 586.25829 | N13: =M43*$E$58-M44*$E$57 -> 613.64467 | O13: =N43*$E$58-N44*$E$57 -> 651.64939 | P13: =O43*$E$58-O44*$E$57 -> 706.84399 | Q13: =P43*$E$58-P44*$E$57 -> 767.28826 | R13: =Q43*$E$58-Q44*$E$57 -> 826.79829 | ... AF13: =AE43*$E$58-AE44*$E$57 -> 2199.0332
B14: 8 | C14: Other income/(cost) | D14: ='Fin. Data'!D15 -> -40.907 | E14: ='Fin. Data'!C15 -> 91.042 | F14: ='Fin. Data'!B15 -> -12.783 | G14: =AVERAGE(D14:F14)*(1+G5) -> 11.138216 | H14: =AVERAGE(E14:G14)*(1+H5) -> 28.726409 | I14: =AVERAGE(F14:H14)*(1+I5) -> 8.909735 | J14: =AVERAGE(G14:I14)*(1+J5) -> 16.047665 | K14: =AVERAGE(H14:J14)*(1+K5) -> 18.266727 | L14: =AVERAGE(I14:K14)*(1+L5) -> 14.702568 | M14: =AVERAGE(J14:L14)*(1+M5) -> 16.724991 | N14: =AVERAGE(K14:M14)*(1+N5) -> 17.2871 | ... AF14: =AVERAGE(AC14:AE14)*(1+AF5) -> 25.576067
B15: 9 | C15: Earnings before taxes | D15: =D8+D13+D14 -> 9118.649 | E15: =E8+E13+E14 -> 10427.106 | F15: =F8+F13+F14 -> 6247.249 | G15: =G8+G13+G14 -> 4148.4893 | H15: =H8+H13+H14 -> 4701.5715 | I15: =I8+I13+I14 -> 5304.0967 | J15: =J8+J13+J14 -> 5763.0949 | K15: =K8+K13+K14 -> 5847.4597 | ... AF15: =AF8+AF13+AF14 -> 16546.731
B16: 10 | C16: (Income tax) | D16: ='Fin. Data'!D21 -> -2078.488 | E16: ='Fin. Data'!C21 -> -2165.204 | F16: ='Fin. Data'!B21 -> -1359.966 | G16: =-$D$56*G15 -> -871.18276 | H16: =-$D$56*H15 -> -987.33002 | I16: =-$D$56*I15 -> -1113.8603 | J16: =-$D$56*J15 -> -1210.2499 | K16: =-$E$56*K15 -> -1227.9665 | L16: =-$E$56*L15 -> -1244.4883 | M16: =-$E$56*M15 -> -1199.1068 | N16: =-$E$56*N15 -> -1202.3115 | O16: =-$E$56*O15 -> -1280.0389 | P16: =-$E$56*P15 -> -1371.6445 | Q16: =-$E$56*Q15 -> -1446.2224 | R16: =-$E$56*R15 -> -1530.4897 | ... AF16: =-$E$56*AF15 -> -3474.8134
B17: 11 | C17: Net income | D17: ='Fin. Data'!D23 -> 6826.975 | E17: ='Fin. Data'!C23 -> 7607.818 | F17: ='Fin. Data'!B23 -> 4524.849 | G17: =G16+G15 -> 3277.3066 | H17: =H16+H15 -> 3714.2415 | I17: =I16+I15 -> 4190.2364 | J17: =J16+J15 -> 4552.845 | K17: =K16+K15 -> 4619.4931 | L17: =L16+L15 -> 4681.6466 | M17: =M16+M15 -> 4510.9256 | N17: =N16+N15 -> 4522.9815 | ... AF17: =AF16+AF15 -> 13071.917
A19: CASH FLOW STATEMENT | B19: 12 | C19: Operating cash flows before WK | D19: =Inputs!D59+Inputs!D60+Inputs!D62 -> 8093.69 | E19: =Inputs!C59+Inputs!C60+Inputs!C62 -> 9194.56 | F19: =Inputs!B59+Inputs!B60+Inputs!B62 -> 6253.49 | G19: =G17-G10-G9-G11 -> 4201.3027 | H19: =H17-H10-H9-H11 -> 4741.3555 | I19: =I17-I10-I9-I11 -> 5320.8236 | J19: =J17-J10-J9-J11 -> 5786.737 | K19: =K17-K10-K9-K11 -> 5917.2115 | L19: =L17-L10-L9-L11 -> 6060.3646 | M19: =M17-M10-M9-M11 -> 5973.0845 | N19: =N17-N10-N9-N11 -> 6073.2409 | ... AF19: =AF17-AF10-AF9-AF11 -> 17173.867
B20: 13 | C20: (Stock-based compensation) | D20: 135.775 | E20: 136.834 | F20: 130.162 | G20: =G11 -> -114.90248 | H20: =H11 -> -110.76639 | I20: =I11 -> -109.32496 | J20: =J11 -> -107.90979 | K20: =K11 -> -110.15381 | L20: =L11 -> -112.40555 | M20: =M11 -> -115.0611 | N20: =N11 -> -120.07856 | ... AF20: =AF11 -> -281.40132
B21: 14 | C21: (Working Capital Flows) | D21: =Inputs!D61 -> -1862.89 | E21: =Inputs!C61 -> 877.44 | F21: =Inputs!B61 -> 858.41 | G21: =G6*$D$60 -> 931.64174 | H21: =H6*$D$60 -> 898.10588 | I21: =I6*$D$60 -> 886.4186 | J21: =J6*$D$60 -> 874.94426 | K21: =K6*$E$60 -> 744.28253 | L21: =L6*$E$60 -> 759.49696 | M21: =M6*$E$60 -> 777.43988 | N21: =N6*$E$60 -> 811.34161 | O21: =O6*$E$60 -> 847.18523 | P21: =P6*$E$60 -> 885.37059 | Q21: =Q6*$E$60 -> 926.08154 | R21: =R6*$E$60 -> 969.51737 | ... AF21: =AF6*$E$60 -> 1901.3602
B22: 15 | C22: -Total Operating Cash Flow | D22: =D19+D20+D21 -> 6366.575 | E22: =E19+E20+E21 -> 10208.834 | F22: =F19+F20+F21 -> 7242.062 | G22: =G19+G20+G21 -> 5018.0419 | H22: =H19+H20+H21 -> 5528.695 | I22: =I19+I20+I21 -> 6097.9173 | J22: =J19+J20+J21 -> 6553.7715 | K22: =K19+K20+K21 -> 6551.3403 | ... AF22: =AF19+AF20+AF21 -> 18793.826
B23: 16 | C23: (CAPEX) | D23: ='Fin. Data'!D32 -> -1602.6 | E23: ='Fin. Data'!C32 -> -1915.6 | F23: ='Fin. Data'!B32 -> -2199.3 | G23: =G6*$D$62 -> -2173.8307 | H23: =H6*$D$62 -> -2095.5804 | I23: =I6*$D$62 -> -2068.3101 | J23: =J6*$D$62 -> -2041.5366 | K23: =K6*$E$62 -> -1488.5651 | L23: =L6*$E$62 -> -1518.9939 | M23: =M6*$E$62 -> -1554.8798 | N23: =N6*$E$62 -> -1622.6832 | O23: =O6*$E$62 -> -1694.3705 | P23: =P6*$E$62 -> -1770.7412 | Q23: =Q6*$E$62 -> -1852.1631 | R23: =R6*$E$62 -> -1939.0347 | ... AF23: =AF6*$E$62 -> -3802.7205 | AG23: =SUM(D23:AF23) -> -67523.648
B24: 17 | C24: Adq | D24: =Inputs!D65 -> -1271.426 | E24: ='Fin. Data'!C33 -> -3876.916 | F24: ='Fin. Data'!B33 -> -225.044 | G24: =G6*$D$63 -> -931.64174 | H24: =H6*$D$63 -> -898.10588 | I24: =I6*$D$63 -> -886.4186 | J24: =J6*$D$63 -> -874.94426 | K24: =K6*$E$63 -> -744.28253 | L24: =L6*$E$63 -> -759.49696 | M24: =M6*$E$63 -> -777.43988 | N24: =N6*$E$63 -> -811.34161 | O24: =O6*$E$63 -> -847.18523 | P24: =P6*$E$63 -> -885.37059 | Q24: =Q6*$E$63 -> -926.08154 | R24: =R6*$E$63 -> -969.51737 | ... AF24: =AF6*$E$63 -> -1901.3602 | AH24: =AG9-AG23 -> 31094.828
B25: 18 | C25: (Other investing flows) | D25: =Inputs!D66 -> 0.176 | E25: =Inputs!C66 -> 89.806 | F25: =Inputs!B66 -> -72.086 | G25: =(1+G5)*AVERAGE(D25:F25) -> 5.3365151 | H25: =(1+H5)*AVERAGE(E25:G25) -> 7.4088536 | I25: =(1+I5)*AVERAGE(F25:H25) -> -19.522806 | J25: =(1+J5)*AVERAGE(G25:I25) -> -2.2299019 | K25: =(1+K5)*AVERAGE(H25:J25) -> -4.8807131 | L25: =(1+L5)*AVERAGE(I25:K25) -> -9.0592848 | M25: =(1+M5)*AVERAGE(J25:L25) -> -5.5173032 | N25: =(1+N5)*AVERAGE(K25:M25) -> -6.7685912 | ... AF25: =(1+AF5)*AVERAGE(AC25:AE25) -> -10.341614
B26: 19 | C26: -Total Investing Flows | D26: =D23+D24+D25 -> -2873.85 | E26: =E23+E24+E25 -> -5702.71 | F26: =F23+F24+F25 -> -2496.43 | G26: =G23+G24+G25 -> -3100.136 | H26: =H23+H24+H25 -> -2986.2774 | I26: =I23+I24+I25 -> -2974.2515 | J26: =J23+J24+J25 -> -2918.7108 | K26: =K23+K24+K25 -> -2237.7283 | ... AF26: =AF23+AF24+AF25 -> -5714.4224
B27: 20 | C27: (Flows related to leases) | D27: =Inputs!D69+Inputs!D70 -> 11.425 | E27: =Inputs!C69+Inputs!C70 -> 16.008 | F27: =Inputs!B69+Inputs!B70 -> 16.84 | G27: =G6*$D$66 -> -15.527362 | H27: =H6*$D$66 -> -14.968431 | I27: =I6*$D$66 -> -14.773643 | J27: =J6*$D$66 -> -14.582404 | K27: =$E$66*K6 -> -14.885651 | L27: =$E$66*L6 -> -15.189939 | M27: =$E$66*M6 -> -15.548798 | N27: =$E$66*N6 -> -16.226832 | O27: =$E$66*O6 -> -16.943705 | P27: =$E$66*P6 -> -17.707412 | Q27: =$E$66*Q6 -> -18.521631 | R27: =$E$66*R6 -> -19.390347 | ... AF27: =$E$66*AF6 -> -38.027205
B28: 21 | C28: Flows related to debt | D28: =+SUM(Inputs!D68:D68) -> 246.81 | E28: =+SUM(Inputs!C68:C68) -> 922.29 | F28: =+SUM(Inputs!B68:B68) -> -34.87 | G28: =G44-F44 -> -580.75691 | H28: =H44-G44 -> 417.11212 | I28: 2500 | J28: =J44-I44 -> 577.69532 | K28: =K44-J44 -> -1689.5068 | L28: =L44-K44 -> 196.39437 | M28: =M44-L44 -> -181.52233 | N28: =N44-M44 -> 70.395156 | O28: =O44-N44 -> 419.18965 | P28: =P44-O44 -> 470.80357 | Q28: =Q44-P44 -> 388.97603 | ... AF28: =AF44-AE44 -> 834.63707
B29: 22 | C29: (Repurchases)/Issuance of stock | D29: ='Fin. Data'!D28 -> -3204.09 | E29: ='Fin. Data'!C28 -> -2803.8 | F29: ='Fin. Data'!B28 -> -1591.52 | G29: =G34*$D$65 -> -493.54477 | H29: =H34*$D$65 -> -1208.598 | I29: =I34*$D$65 -> -2383.0045 | J29: =J34*$D$65 -> -1771.1801 | K29: =K34*$E$65 -> -1162.6626 | L29: =L34*$E$65 -> -2154.3873 | M29: =M34*$E$65 -> -1907.235 | N29: =N34*$E$65 -> -2038.9531 | O29: =O34*$E$65 -> -2363.5054 | P29: =P34*$E$65 -> -2566.1572 | Q29: =Q34*$E$65 -> -2667.0758 | R29: =R34*$E$65 -> -2853.2878 | ... AF29: =AF34*$E$65 -> -6712.3366
B30: 23 | C30: (Dividends) | D30: ='Fin. Data'!D27 -> -483.47 | E30: ='Fin. Data'!C27 -> -533.59 | F30: ='Fin. Data'!B27 -> -514.53 | G30: =G34*$D$64 -> -109.67662 | H30: =H34*$D$64 -> -268.57734 | I30: =I34*$D$64 -> -529.55655 | J30: =J34*$D$64 -> -393.59558 | K30: =K34*$E$64 -> -348.79879 | L30: =L34*$E$64 -> -646.31618 | M30: =M34*$E$64 -> -572.17049 | N30: =N34*$E$64 -> -611.68592 | O30: =O34*$E$64 -> -709.05161 | P30: =P34*$E$64 -> -769.84717 | Q30: =Q34*$E$64 -> -800.12275 | R30: =R34*$E$64 -> -855.98634 | ... AF30: =AF34*$E$64 -> -2013.701
B31: 24 | C31: Other financing flows | D31: =Inputs!D73 -> -173.555 | E31: =Inputs!C73 -> -111.768 | F31: =Inputs!B73 -> -468.73 | G31: =(1+G5)*AVERAGE(D31:F31) -> -224.85557 | H31: =(1+H5)*AVERAGE(E31:G31) -> -258.78788 | I31: =(1+I5)*AVERAGE(F31:H31) -> -313.32666 | J31: =(1+J5)*AVERAGE(G31:I31) -> -262.21788 | K31: =(1+K5)*AVERAGE(H31:J31) -> -283.89422 | L31: =(1+L5)*AVERAGE(I31:K31) -> -292.33573 | M31: =(1+M5)*AVERAGE(J31:L31) -> -286.08531 | N31: =(1+N5)*AVERAGE(K31:M31) -> -299.97271 | ... AF31: =(1+AF5)*AVERAGE(AC31:AE31) -> -451.34026
B32: 25 | C32: -Total Financing flows | D32: =D27+D28+D29+D30+D31 -> -3602.88 | E32: =E27+E28+E29+E30+E31 -> -2510.86 | F32: =F27+F28+F29+F30+F31 -> -2592.81 | G32: =G27+G28+G29+G30+G31 -> -1424.3612 | H32: =H27+H28+H29+H30+H31 -> -1333.8196 | I32: =I27+I28+I29+I30+I31 -> -740.66133 | J32: =J27+J28+J29+J30+J31 -> -1863.8806 | K32: =K27+K28+K29+K30+K31 -> -3499.7481 | ... AF32: =AF27+AF28+AF29+AF30+AF31 -> -8380.768
A34: SUMMARY | B34: 26 | C34: Cash before shareholder returns | D34: =D22+D26+D27+D28+D31 -> 3577.405 | E34: =E22+E26+E27+E28+E31 -> 5332.654 | F34: =F22+F26+F27+F28+F31 -> 4258.872 | G34: =G22+G26+G27+G28+G31 -> 1096.7662 | H34: =H22+H26+H27+H28+H31 -> 2685.7734 | I34: =I22+I26+I27+I28+I31 -> 5295.5655 | J34: =J22+J26+J27+J28+J31 -> 3935.9558 | K34: =K22+K26+K27+K28+K31 -> 2325.3253 | ... AF34: =AF22+AF26+AF27+AF28+AF31 -> 13424.673
B35: 27 | C35: Returns to shareholders | D35: =-1*(D29+D30) -> 3687.56 | E35: =-1*(E29+E30) -> 3337.39 | F35: =-1*(F29+F30) -> 2106.05 | G35: =-1*(G29+G30) -> 603.22139 | H35: =-1*(H29+H30) -> 1477.1754 | I35: =-1*(I29+I30) -> 2912.561 | J35: =-1*(J29+J30) -> 2164.7757 | K35: =-1*(K29+K30) -> 1511.4614 | ... AF35: =-1*(AF29+AF30) -> 8726.0376
B36: 28 | C36: Excess cash acumulation | D36: =D34-D35 -> -110.155 | E36: =E34-E35 -> 1995.264 | F36: =F34-F35 -> 2152.822 | G36: =G34-G35 -> 493.54477 | H36: =H34-H35 -> 1208.598 | I36: =I34-I35 -> 2383.0045 | J36: =J34-J35 -> 1771.1801 | K36: =K34-K35 -> 813.86385 | ... AF36: =AF34-AF35 -> 4698.6356
A38: BALANCE SHEET | B38: 29 | C38: Intangible assets | D38: ='Fin. Data'!D49 -> 3931.003 | E38: ='Fin. Data'!C49 -> 7242.325 | F38: ='Fin. Data'!B49 -> 7076.862 | G38: =+F38+(-G10) -> 7430.7051 | H38: =+G38+(-H10) -> 7802.2404 | I38: =+H38+(-I10) -> 8192.3524 | J38: =+I38+(-J10) -> 8601.97 | K38: =+J38+(-K10) -> 8989.0586 | L38: =+K38+(-L10) -> 9393.5663 | M38: =+L38+(-M10) -> 9816.2768 | N38: =+M38+(-N10) -> 10258.009 | ... AF38: =+AE38+(-AF10) -> 22654.596 | AG38: =SUM(G38:AF38) -> 358360.46
B39: 30 | C39: Accumulated amortization | D39: 1091.366 | E39: 1326.311 | F39: 1564.041 | G39: =F39-G10 -> 1917.8841 | H39: =G39-H10 -> 2289.4194 | I39: =H39-I10 -> 2679.5314 | J39: =I39-J10 -> 3089.149 | K39: =J39-K10 -> 3476.2376 | L39: =K39-L10 -> 3880.7453 | M39: =L39-M10 -> 4303.4558 | N39: =M39-N10 -> 4745.1882 | ... AF39: =AE39-AF10 -> 17141.775 | AG39: =SUM(G39:AF39) -> 215027.12
B40: 31 | C40: PPE+Right of use Assets | D40: =Inputs!D33 -> 8114.82 | E40: =Inputs!C33 -> 9616.92 | F40: =Inputs!B33 -> 11049.77 | G40: =F40+(-G23) -> 13223.601 | H40: =G40+(-H23) -> 15319.181 | I40: =H40+(-I23) -> 17387.491 | J40: =I40+(-J23) -> 19429.028 | K40: =J40+(-K23) -> 20917.593 | L40: =K40+(-L23) -> 22436.587 | M40: =L40+(-M23) -> 23991.467 | N40: =M40+(-N23) -> 25614.15 | ... AF40: =AE40+(-AF23) -> 72855.918 | AG40: =SUM(G40:AF40) -> 1006502.8
B41: 32 | C41: Accumulated depreciation | D41: 10389.649 | E41: 11115.127 | F41: 11788.982 | G41: =F41-G9 -> 12244.233 | H41: =G41-H9 -> 12789.045 | I41: =H41-I9 -> 13420.195 | J41: =I41-J9 -> 14136.56 | K41: =J41-K9 -> 14937.036 | L41: =K41-L9 -> 15798.841 | M41: =L41-M9 -> 16723.228 | N41: =M41-N9 -> 17711.676 | ... AF41: =AE41-AF9 -> 50710.485 | AG41: =SUM(G41:AF41) -> 699665.53
A43: CASH & DEBT & DISCOUNTING | B43: 33 | C43: Ending cash balance | D43: ='Fin. Data'!D41 -> 2364.9 | E43: =E36+D43 -> 4360.164 | F43: =F36+E43 -> 6512.986 | G43: =G36+F43 -> 7006.5308 | H43: =H36+G43 -> 8215.1288 | I43: =I36+H43 -> 10598.133 | J43: =J36+I43 -> 12369.313 | K43: =K36+J43 -> 13183.177 | L43: =L36+K43 -> 14691.248 | ... AF43: =AF36+AE43 -> 69813.362
B44: 34 | C44: Total Debt | D44: ='Fin. Data'!D63 -> 5720.84 | E44: ='Fin. Data'!C63 -> 6691.367 | F44: ='Fin. Data'!B63 -> 6842.183 | G44: =G12*$D$67 -> 6261.4261 | H44: =H12*$D$67 -> 6678.5382 | I44: =I12*$D$67 -> 7551.0864 | J44: =J12*$D$67 -> 8128.7817 | K44: =K12*$E$67 -> 6439.2749 | L44: =L12*$E$67 -> 6635.6693 | M44: =M12*$E$67 -> 6454.1469 | N44: =N12*$E$67 -> 6524.5421 | O44: =O12*$E$67 -> 6943.7318 | P44: =P12*$E$67 -> 7414.5353 | Q44: =Q12*$E$67 -> 7803.5113 | R44: =R12*$E$67 -> 8243.957 | ... AF44: =AF12*$E$67 -> 18142.67
B45: 35 | C45: Discount factor | F45: =1/((1+$F$50)^G50) -> 1 | G45: =1/((1+$F$50)^G49) -> 0.90909091 | H45: =1/((1+$F$50)^H49) -> 0.82644628 | I45: =1/((1+$F$50)^I49) -> 0.7513148 | J45: =1/((1+$F$50)^J49) -> 0.68301346 | K45: =1/((1+$F$50)^K49) -> 0.62092132 | L45: =1/((1+$F$50)^L49) -> 0.56447393 | M45: =1/((1+$F$50)^M49) -> 0.51315812 | N45: =1/((1+$F$50)^N49) -> 0.46650738 | ... AF45: =1/((1+$F$50)^AF49) -> 0.083905453
...

Sheet Assumptions
B2: Assumptions
B4: Prospects:
B6: Links:
C8: 2023 | D8: =C8-1 -> 2022 | E8: =D8-1 -> 2021 | F8: =E8-1 -> 2020 | G8: =F8-1 -> 2019 | H8: =G8-1 -> 2018 | I8: =H8-1 -> 2017 | J8: =I8-1 -> 2016 | K8: =J8-1 -> 2015 | ... M8: =L8-1 -> 2013 | O8: 10Y Average | P8: 5Y Average | Q8: 3Y Average | S8: Short Term Forecast | T8: Long Term Forecast | V8: 0.025
B9: Revenue growth | C9: =(Inputs!B6-Inputs!C6)/Inputs!C6 -> -0.16375988 | D9: =(Inputs!C6-Inputs!D6)/Inputs!D6 -> 0.13781384 | E9: =(Inputs!D6-Inputs!E6)/Inputs!E6 -> 0.81151936 | F9: =(Inputs!E6-Inputs!F6)/Inputs!F6 -> -0.10841 | G9: =(Inputs!F6-Inputs!G6)/Inputs!G6 -> -0.098870763 | H9: =(Inputs!G6-Inputs!H6)/Inputs!H6 -> 0.23774405 | I9: =(Inputs!H6-Inputs!I6)/Inputs!I6 -> 0.24952126 | J9: =(Inputs!I6-Inputs!J6)/Inputs!J6 -> -0.014061082 | ... M9: =(Inputs!L6-Inputs!M6)/Inputs!M6 -> -0.019401616 | O9: =AVERAGE(C9:M9) -> 0.083525495 | P9: =AVERAGE(C9:G9) -> 0.11565851 | Q9: =AVERAGE(C9:E9) -> 0.26185777 | V9: 0.07
B10: Operating Margin | C10: =Inputs!B8/Inputs!B6 -> 0.17947802 | D10: =Inputs!C8/Inputs!C6 -> 0.25309019 | E10: =Inputs!D8/Inputs!D6 -> 0.25541087 | F10: =Inputs!E8/Inputs!E6 -> 0.080086892 | G10: =Inputs!F8/Inputs!F6 -> 0.087126582 | H10: =Inputs!G8/Inputs!G6 -> 0.13699133 | I10: =Inputs!H8/Inputs!H6 -> 0.09292729 | J10: =Inputs!I8/Inputs!I6 -> 0.088165674 | ... M10: =Inputs!L8/Inputs!L6 -> 0.049495996 | O10: =AVERAGE(C10:M10) -> 0.12050359 | P10: =AVERAGE(C10:G10) -> 0.17103851 | Q10: =AVERAGE(C10:E10) -> 0.22932636
B13: Modelling Factors
C15: Last 6 Years
C16: =C8 -> 2023 | D16: =D8 -> 2022 | E16: =E8 -> 2021 | F16: =F8 -> 2020 | G16: =G8 -> 2019 | H16: =H8 -> 2018 | J16: Average | L16: Short Term Forecast | M16: Long Term Forecast | O16: Reference
B17: Depreciation factor | C17: =B85 -> 0.040745883 | D17: =C85 -> 0.039875078 | E17: =D85 -> 0.03974208 | F17: =E85 -> 0.041905499 | G17: =F85 -> 0.041610777 | H17: =G85 -> 0.043433786 | J17: =AVERAGE(C17:H17) -> 0.041218851 | L17: -0.0412 | M17: -0.0412 | O17: % PPE
B18: Amortization factor | C18: =B79 -> 0.05088445 | D18: =C79 -> 0.050539778 | E18: =D79 -> 0.058836741 | F18: =E79 -> 0.050577951 | G18: =F79 -> 0.052313563 | H18: =G79 -> 0.05340241 | J18: =AVERAGE(C18:H18) -> 0.052759149 | L18: -0.05 | M18: -0.045 | O18: % IA
B19: Stock-based comp | C19: =B72 -> -0.0037495535 | D19: =C72 -> -0.0032962517 | E19: =D72 -> -0.0037214944 | F19: =E72 -> -0.0036669811 | G19: =F72 -> -0.004000158 | H19: =G72 -> -0.0029289976 | J19: =AVERAGE(C19:H19) -> -0.0035605727 | L19: -0.0037 | M19: -0.0037 | O19: % Revenue
B20: Tax Rate | C20: ='Fin. Data'!B21/('Fin. Data'!B21-'Fin. Data'!B23) -> 0.23109749 | D20: ='Fin. Data'!C21/('Fin. Data'!C21-'Fin. Data'!C23) -> 0.22154908 | E20: ='Fin. Data'!D21/('Fin. Data'!D21-'Fin. Data'!D23) -> 0.23339472 | F20: ='Fin. Data'!E21/('Fin. Data'!E21-'Fin. Data'!E23) -> -0.00068000872 | G20: ='Fin. Data'!F21/('Fin. Data'!F21-'Fin. Data'!F23) -> 0.24473103 | H20: ='Fin. Data'!G21/('Fin. Data'!G21-'Fin. Data'!G23) -> 0.24071342 | J20: =AVERAGE(C20:H20) -> 0.19513429 | L20: 0.21 | M20: 0.21 | O20: % EBT
B21: Interest Rate on debt | C21: =B90 -> 0.035946715 | D21: =C90 -> 0.032715438 | E21: =D90 -> 0.02851347 | F21: =E90 -> 0.031197437 | G21: =F90 -> 0.035901558 | H21: =G90 -> 0.037578773 | J21: =AVERAGE(C21:H21) -> 0.033642232 | L21: -0.033 | M21: -0.033 | O21: % Debt
B22: Interest Rate on cash | C22: =B95 -> 0.043172967 | D22: =C95 -> 0.011374945 | E22: =D95 -> 0.0018043046 | F22: =E95 -> 0.0050820169 | G22: =F95 -> 0.023415222 | H22: =G95 -> 0.018386589 | J22: =AVERAGE(C22:H22) -> 0.017206007 | L22: 0.035 | M22: 0.025 | O22: % Cash
B23: PPE+ROA | C23: =Inputs!B33/Inputs!C33-1 -> 0.14899261 | D23: =Inputs!C33/Inputs!D33-1 -> 0.18510577 | E23: =Inputs!D33/Inputs!E33-1 -> 0.17621258 | F23: =Inputs!E33/Inputs!F33-1 -> 0.11662102 | G23: =Inputs!F33/Inputs!G33-1 -> 0.15817236 | H23: =Inputs!G33/Inputs!H33-1 -> 0.047436262 | J23: =AVERAGE(C23:H23) -> 0.13875677 | L23: - - | M23: - - | O23: Growing with CAPEX
B24: Working capital flows | C24: =D108 -> 0 | D24: =E108 -> 0 | E24: =F108 -> 0 | F24: =G108 -> 0 | G24: =H108 -> 0 | H24: =I108 -> 0 | J24: =AVERAGE(C24:H24) -> 0 | O24: % Change in Revenues
B25: Intangible Assets | C25: =B77/C77-1 -> 0.0050510092 | D25: =C77/D77-1 -> 1.1176817 | E25: =D77/E77-1 -> 0.33187291 | F25: =E77/F77-1 -> 0.0056164213 | G25: =F77/G77-1 -> -0.013941265 | J25: =AVERAGE(C25:H25) -> 0.28925615 | L25: - - | M25: - - | O25: Growing with Amortization
B26: CAPEX | C26: =Inputs!B64/Inputs!B6 -> -0.063354842 | D26: =Inputs!C64/Inputs!C6 -> -0.046145693 | E26: =Inputs!D64/Inputs!D6 -> -0.043926105 | F26: =Inputs!E64/Inputs!E6 -> -0.07459285 | G26: =Inputs!F64/Inputs!F6 -> -0.063557883 | H26: =Inputs!G64/Inputs!G6 -> -0.037933914 | J26: =AVERAGE(C26:H26) -> -0.054918548 | L26: -0.07 | M26: -0.05 | O26: % Revenue
B27: Acquisition factor | C27: =Inputs!B65/Inputs!B6 -> -0.0064828023 | D27: =Inputs!C65/Inputs!C6 -> -0.093392658 | E27: =Inputs!D65/Inputs!D6 -> -0.034848865 | F27: =Inputs!E65/Inputs!E6 -> -0.0091564052 | G27: =Inputs!F65/Inputs!F6 -> -0.016961725 | H27: =Inputs!G65/Inputs!G6 -> 0.00067566169 | J27: =AVERAGE(C27:H27) -> -0.026694466 | O27: % Revenue
B28: Dividends | C28: =B257 -> -0.14382772 | D28: =C257 -> -0.10006087 | E28: =D257 -> -0.11352067 | J28: =AVERAGE(C28:H28) -> -0.11913642 | L28: -0.1 | M28: -0.15 | O28: % Cash before shareholder returns
B29: Repurchases | C29: =B248 -> -0.44488114 | D29: =C248 -> -0.52577947 | E29: =D248 -> -0.75233301 | L29: -0.45 | M29: -0.5 | O29: % Cash before shareholder returns
B30: Leases | C30: =Inputs!B70/Inputs!B6 -> 0.00048510687 | D30: =Inputs!C70/Inputs!C6 -> 0.00038562343 | E30: =Inputs!D70/Inputs!D6 -> 0.00031315097 | F30: =Inputs!E70/Inputs!E6 -> 0.00047373386 | G30: =Inputs!F70/Inputs!F6 -> 0.00040435864 | H30: =Inputs!G70/Inputs!G6 -> 0 | J30: =AVERAGE(C30:H30) -> 0.0003436623 | L30: -0.0005 | M30: -0.0005 | O30: % Revenue
B31: Total Debt | C31: ='Fin. Data'!B63/'Fin. Data'!B19 -> 0.92318427 | D31: ='Fin. Data'!C63/'Fin. Data'!C19 -> 0.58303075 | E31: ='Fin. Data'!D63/'Fin. Data'!D19 -> 0.55955681 | F31: ='Fin. Data'!E63/'Fin. Data'!E19 -> 3.0100651 | G31: ='Fin. Data'!F63/'Fin. Data'!F19 -> 1.660787 | H31: ='Fin. Data'!G63/'Fin. Data'!G19 -> 1.0507522 | J31: =AVERAGE(C31:H31) -> 1.297896 | L31: 1.3 | M31: 1 | O31: % EBITDA
B34: Forecasts
B37: 2023 | C37: 2022 | D37: 2021 | E37: 2020 | F37: 2019 | G37: 2018 | H37: 2017 | I37: 2016 | J37: 2015 | K37: 2014 | L37: 2013 | M37: 2012
A38: Net Sales | B38: 34714 | C38: 41512 | D38: 36484 | E38: 20140 | F38: 22588.858 | G38: 25067.279 | H38: 20252.393 | I38: 16208.122 | J38: 16439.276 | K38: 21105.141 | L38: 19052.046 | M38: 19429
A39: COGS | B39: =B38-B40 -> 26899.6 | C39: =C38-C40 -> 29008.72 | D39: =D38-D40 -> 25458.59 | E39: =E38-E40 -> 17912.05 | F39: =F38-F40 -> 19909.768 | G39: =G38-G40 -> 20772.279 | H39: =H38-H40 -> 17682.393 | I39: =I38-I40 -> 14182.122 | ... M39: =M38-M40 -> 17915.46
A40: Gross Profit | B40: 7814.4 | C40: 12503.28 | D40: 11025.41 | E40: 2227.95 | F40: 2679.09 | G40: 4295 | H40: 2570 | I40: 2026 | J40: 1114 | K40: 1849 | L40: 1411 | M40: 1513.54
B43: Crude oil prices | C43: 2024 | D43: 2023 | E43: 2022 | F43: 2021 | G43: 2020 | H43: 2019 | I43: 2018
C44: 70.49 | D44: 71.33 | E44: 80.51 | F44: 75.21 | G44: 48.52 | H44: 61.14 | I44: 45.15
C45: =C44/D44-1 -> -0.011776251 | D45: =D44/E44-1 -> -0.1140231 | E45: =E44/F44-1 -> 0.070469352 | F45: =F44/G44-1 -> 0.55008244 | G45: =G44/H44-1 -> -0.20641151 | H45: =H44/I44-1 -> 0.35415282
B46: COGS | D46: =B39 -> 26899.6 | E46: =C39 -> 29008.72 | F46: =D39 -> 25458.59 | G46: =E39 -> 17912.05 | H46: =F39 -> 19909.768 | I46: =G39 -> 20772.279
D47: =D46/E46-1 -> -0.072706414 | E47: =E46/F46-1 -> 0.13944724 | F47: =F46/G46-1 -> 0.42131079 | G47: =G46/H46-1 -> -0.10033859 | H47: =H46/I46-1 -> -0.041522213
B48: Correl | C48: =CORREL(D46:I46,D44:I44) -> 0.89265961
B50: NYSE Amercian Steel Index
C51: 1Q | D51: 2Q | E51: 3Q | F51: 4Q | G51: average
B52: 2024 | C52: 2168 | D52: 1979 | E52: 2087 | G52: =AVERAGE(C52:F52) -> 2078 | H52: =G52/G54-1 -> 0.046719557 | O52: US motor vehicle production (million units)
C53: =C52/F54-1 -> -0.025179856 | D53: =D52/C52-1 -> -0.087177122 | E53: =E52/D52-1 -> 0.054573017 | O53: Year | P53: 2023 | Q53: 2022 | R53: 2021 | S53: 2020 | T53: 2019 | U53: 2018 | V53: 2017 | W53: 2016
B54: 2023 | C54: 1900 | D54: 1891 | E54: 1926 | F54: 2224 | G54: =AVERAGE(C54:F54) -> 1985.25 | H54: =G54/G56-1 -> 0.21607963 | P54: 10.61 | Q54: 10.06 | R54: 9.16 | S54: 8.82 | T54: 10.89 | U54: 11.3 | V54: 11.19 | W54: 12.18
...

Sheet Fin. Data
A1: =Inputs!H3 -> #VALUE!
A2: =Inputs!G2 -> Figures in Millions of USD
A3: Results
B4: =OP!J20 -> 2023 | C4: =B4-1 -> 2022 | D4: =C4-1 -> 2021 | E4: =D4-1 -> 2020 | F4: =E4-1 -> 2019 | G4: =F4-1 -> 2018 | H4: =G4-1 -> 2017 | I4: =H4-1 -> 2016 | J4: =I4-1 -> 2015 | ... M4: =L4-1 -> 2012
A5: Net Sales | B5: =_xlfn.XLOOKUP($A5,Inputs!$A:$A,Inputs!B:B,,0) -> 34714 | C5: =_xlfn.XLOOKUP($A5,Inputs!$A:$A,Inputs!C:C,,0) -> 41512 | D5: =_xlfn.XLOOKUP($A5,Inputs!$A:$A,Inputs!D:D,,0) -> 36484 | E5: =_xlfn.XLOOKUP($A5,Inputs!$A:$A,Inputs!E:E,,0) -> 20140 | F5: =_xlfn.XLOOKUP($A5,Inputs!$A:$A,Inputs!F:F,,0) -> 22588.858 | G5: =_xlfn.XLOOKUP($A5,Inputs!$A:$A,Inputs!G:G,,0) -> 25067.279 | H5: =_xlfn.XLOOKUP($A5,Inputs!$A:$A,Inputs!H:H,,0) -> 20252.393 | I5: =_xlfn.XLOOKUP($A5,Inputs!$A:$A,Inputs!I:I,,0) -> 16208.122 | J5: =_xlfn.XLOOKUP($A5,Inputs!$A:$A,Inputs!J:J,,0) -> 16439.276 | K5: =_xlfn.XLOOKUP($A5,Inputs!$A:$A,Inputs!K:K,,0) -> 21105.141 | L5: =_xlfn.XLOOKUP($A5,Inputs!$A:$A,Inputs!L:L,,0) -> 19052.046 | M5: =_xlfn.XLOOKUP($A5,Inputs!$A:$A,Inputs!M:M,,0) -> 19429
A6: Growth vs. Previous year | B6: =IFERROR(B5/C5-1,"-") -> -0.16375988 | C6: =IFERROR(C5/D5-1,"-") -> 0.13781384 | D6: =IFERROR(D5/E5-1,"-") -> 0.81151936 | E6: =IFERROR(E5/F5-1,"-") -> -0.10841 | F6: =IFERROR(F5/G5-1,"-") -> -0.098870763 | G6: =IFERROR(G5/H5-1,"-") -> 0.23774405 | H6: =IFERROR(H5/I5-1,"-") -> 0.24952126 | I6: =IFERROR(I5/J5-1,"-") -> -0.014061082 | ... L6: =IFERROR(L5/M5-1,"-") -> -0.019401616 | M6: =IFERROR(M5/#REF!-1,"-") -> -
A7: Gross Profit | B7: =_xlfn.XLOOKUP($A7,Inputs!$A:$A,Inputs!B:B,,0) -> 7814.4 | C7: =_xlfn.XLOOKUP($A7,Inputs!$A:$A,Inputs!C:C,,0) -> 12503.28 | D7: =_xlfn.XLOOKUP($A7,Inputs!$A:$A,Inputs!D:D,,0) -> 11025.41 | E7: =_xlfn.XLOOKUP($A7,Inputs!$A:$A,Inputs!E:E,,0) -> 2227.95 | F7: =_xlfn.XLOOKUP($A7,Inputs!$A:$A,Inputs!F:F,,0) -> 2679.09 | G7: =_xlfn.XLOOKUP($A7,Inputs!$A:$A,Inputs!G:G,,0) -> 4295 | H7: =_xlfn.XLOOKUP($A7,Inputs!$A:$A,Inputs!H:H,,0) -> 2570 | I7: =_xlfn.XLOOKUP($A7,Inputs!$A:$A,Inputs!I:I,,0) -> 2026 | J7: =_xlfn.XLOOKUP($A7,Inputs!$A:$A,Inputs!J:J,,0) -> 1114 | K7: =_xlfn.XLOOKUP($A7,Inputs!$A:$A,Inputs!K:K,,0) -> 1849 | L7: =_xlfn.XLOOKUP($A7,Inputs!$A:$A,Inputs!L:L,,0) -> 1411 | M7: =_xlfn.XLOOKUP($A7,Inputs!$A:$A,Inputs!M:M,,0) -> 1513.54
A8: % over sales | B8: =IFERROR(B7/B$5,"-") -> 0.22510803 | C8: =IFERROR(C7/C$5,"-") -> 0.30119676 | D8: =IFERROR(D7/D$5,"-") -> 0.3021985 | E8: =IFERROR(E7/E$5,"-") -> 0.11062314 | F8: =IFERROR(F7/F$5,"-") -> 0.11860228 | G8: =IFERROR(G7/G$5,"-") -> 0.1713389 | H8: =IFERROR(H7/H$5,"-") -> 0.12689858 | I8: =IFERROR(I7/I$5,"-") -> 0.12499906 | ... M8: =IFERROR(M7/M$5,"-") -> 0.077901076
A9: Operating expenses | B9: =B5-B11 -> 28483.6 | C9: =C5-C11 -> 31005.72 | D9: =D5-D11 -> 27165.59 | E9: =E5-E11 -> 18527.05 | F9: =F5-F11 -> 20620.768 | G9: =G5-G11 -> 21633.279 | H9: =H5-H11 -> 18370.393 | I9: =I5-I11 -> 14779.122 | ... M9: =M5-M11 -> 18352.46
A10: % over sales | B10: =IFERROR(B9/B$5,"-") -> 0.82052198 | C10: =IFERROR(C9/C$5,"-") -> 0.74690981 | D10: =IFERROR(D9/D$5,"-") -> 0.74458913 | E10: =IFERROR(E9/E$5,"-") -> 0.91991311 | F10: =IFERROR(F9/F$5,"-") -> 0.91287342 | G10: =IFERROR(G9/G$5,"-") -> 0.86300867 | H10: =IFERROR(H9/H$5,"-") -> 0.90707271 | I10: =IFERROR(I9/I$5,"-") -> 0.91183433 | ... M10: =IFERROR(M9/M$5,"-") -> 0.94459108
