Workbook
Name Benchmark: [1]ControlsH!$B$3
Name BestConsOv: #REF!
Name Broker_Name: OFFSET(#REF!,0,0,[1]ControlsH!$E$5, 1)
Name calCODE: [1]ControlsH!$C$4
Name Chart_Benchmark_100_Size: OFFSET(#REF!, 0, 0, [1]ControlsH!$E$3, 1)
Name Chart_Date_Size: OFFSET(#REF!, 0, 0, [1]ControlsH!$E$3, 1)
Name Chart_Date_VAL1_Size: OFFSET(#REF!, 0, 0, [1]ControlsH!$I$3, 1)
Name Chart_Date_VAL2_Size: OFFSET(#REF!, 0, 0, [1]ControlsH!$I$5, 1)
Name Chart_Peer_100_Size: OFFSET(#REF!, 0, 0, [1]ControlsH!$E$3, 1)
Name Chart_Price_100_Size: OFFSET(#REF!, 0, 0, [1]ControlsH!$E$3, 1)
Name Chart_Price_Size: OFFSET(#REF!, 0, 0, [1]ControlsH!$E$3, 1)
Name Chart_VAL1_FY1_Size: OFFSET(#REF!, 0, 0, [1]ControlsH!$F$3, 1)
Name Chart_VAL1_FY2_Size: OFFSET(#REF!, 0, 0, [1]ControlsH!$G$3, 1)
Name Chart_VAL1_FY3_Size: OFFSET(#REF!, 0, 0, [1]ControlsH!$H$3, 1)
Name Chart_VAL2_FY1_Size: OFFSET(#REF!, 0, 0, [1]ControlsH!$F$5, 1)
Name Chart_VAL2_FY2_Size: OFFSET(#REF!, 0, 0, [1]ControlsH!$G$5, 1)
Name Chart_VAL2_FY3_Size: OFFSET(#REF!, 0, 0, [1]ControlsH!$H$5, 1)
Name Chart_Volume_Size: OFFSET(#REF!, 0, 0, [1]ControlsH!$E$3, 1)
Name compNAME: [1]ControlsH!$B$6
Name CURRENCY: [1]ControlsH!$B$9
Name currPRICE: [1]Overview!$E$19
Name custBenchmark: [1]Overview!$C$9
Name custED: #REF!
Name custSD: #REF!
Name dayCODE: [1]ControlsH!$C$5
Name ED: [1]ControlsH!$B$5
Name ESTBrokersItem: #REF!
Name ESTBrokersPeriod: #REF!
Name ESTDetailBroker: #REF!
Name ESTDetailBroker2: #REF!
Name ESTDetailPeriod: #REF!
Name EstDetPerO: #REF!
Name EstDetPerT: #REF!
Name FinancialsPeriod: #REF!
Name fundTICKER: [1]ControlsH!$B$15
Name GraphValRatio1: #REF!
Name GraphValRatio2: #REF!
Name Index1: #REF!
Name Lang: [1]Overview!$D$11
Name newCrncy: [1]ControlsH!$B$21:$B$199
Name newEstBrokerPeriod: #REF!
Name newEstBrokersItem: #REF!
Name newEstDetailBroker: #REF!
Name newEstDetailBroker2: #REF!
Name newEstDetailPeriod: #REF!
Name newFinancialsPeriod: #REF!
Name newOverviewCon: #REF!
Name newOverviewYear: #REF!
Name newOwners: #REF!
Name newPeersRatio: #REF!
Name newPeriod: #REF!
Name newValRatio1: #REF!
Name newValRatio2: #REF!
Name OverviewValRatioPeriod: [1]Overview!$D$30
Name PeerDate1: [1]Peers!$S$11
Name peerHist1: #REF!
Name PeerIndex: [1]ControlsH!$F$35:$F$36
Name Peers: OFFSET([1]Peers!$C$18,0,0,MAX(COUNTA([1]Peers!$C$18:$C$47),1),1)
Name peersWEIGHT: [1]ControlsH!$B$13
Name PERIODICITY: [1]ControlsH!$C$3

Sheet OP
B2: (date of last modification) | C2: Analista: Research | D2: The Company will release its full year and fourth quarter 2024 earnings results before the market opens on February 20, 2025 | E2: POOL | K2: XNAS | L2: SIC: Sí
B3: POOL | D3: Description: POOLCORP is the world's largest wholesale distributor of swimming pool and related outdoor living products operating approximately 440 sales centers in North America, Europe and Australia.
D4: CEO & BOARD: Peter D. Arvan, President and CEO of Pool Corporation since 2019, Mr. Arvan served as Chief Executive Officer of Roofing Supply Group from 2013 to 2015, and as President of SABIC Polymershapes from 2004 to 2013. Manuel J. Perez de la Mesa, Vice Chairman of the Board, Retired, Former President and Chief Executive Officer of Pool Corporation. John E. Stokely, Non-Executive Chairman of the Board, Director Since: 2000, Mr. Stokely served as President, Chief Executive Officer and Chairman of Richfood Holdings, Inc., a regional Fortune 500 wholesale food distributor and operator of retail grocery stores. Martha "Marty" S. Gervasi, Non-Executive Chairman, Ms. Gervasi served as Chief Human Resources Officer of The Hartford Financial Services Group from 2012 until her retirement in 2020. James "Jim" D. Hope, Non-Executive Chairman, Prior to his retirement in December of 2022, Mr. Hope served as the Chief Financial Officer of Performance Food Group Company. Kevin Murphy, Non-Executive Chairman, CEO at Ferguson. Debra S. Oler, Non-Executive Chairman, Retired, Former Senior Vice President/President North American Sales and Service of W.W. Grainger, Inc. Carlos A. Sabater, Non-Executive Chairman, Retired, Former Senior Global Partner at Deloitte & Touche LLP. David G. Whalen, Non-Executive Chairman, Retired, former President and Chief Executive Officer, A.T. Cross Company.
B5: Millones de USD
B6: Acción | D6: Liquidez y Solvencia | I6: Rentabilidad (2024) | K6: Múltiplos
B7: Último Precio | C7: 331.71 | D7: Activo: | E7: 3428 | I7: Año termina: | J7: 31/12/X | K7: Float: | L7: =36850000/C8 -> 0.96820809
B8: Outstanding Shares | C8: 38060000 | D8: Pasivo: | E8: 2115.281 | K8: Insiders Own: | L8: 0.0495
B9: Market Cap. | C9: =C7*C8/1000000 -> 12624.883 | D9: Cash/Precio | E9: =1000000*C11/C8 -> 2.4500788 | I9: EBIT | J9: 635.898 | K9: b (Bloomberg; Yahoo) | L9: 1.01
B10: +Deuda Total | C10: 1240 | D10: Ebidta/CIF | E10: =679.62/51.922 -> 13.089249 | I10: +Dep&Amort | J10: 43.722 | K10: Calificación (S&P) | L10: Consumer Discretionary
B11: -Cash | C11: 93.25 | D11: Deuda/Ebidta | E11: =C10/J11 -> 1.824549 | I11: =EBIDTA | J11: =J9+J10 -> 679.62 | K11: Precio/Valor en libros | L11: =((C7*C8)/1000000)/(E7-E8) -> 9.6173534
B12: =Enterprise Value | C12: =C9+C10-C11 -> 13771.633 | D12: "Otros activos"/Activo | E12: =(9.269+83.426)/E7 -> 0.027040548 | I12: Utilidad Neta | J12: 448.462 | K12: FNP(p)/Activos | L12: =J18/E7 -> 0.1944684
B13: Tenencia % (nac/int'l) | D13: Deuda/Activo | E13: =C10/E7 -> 0.36172695 | I13: UPA | J13: =1000000*J12/C8 -> 11.783027 | K13: Precio/Utilidad(p) | L13: =C9/J17 -> 28.15151 | N13: =C10/J11 -> 1.824549
B14: t liq. (Pos prom./Vol.) | D14: Margen de Operación (p) | E14: 0.1231 | I14: ROA | J14: =J12/E7 -> 0.13082322 | K14: EV/Activos | L14: =C12/E7 -> 4.0173957
B15: % Short | C15: =2760000/C8 -> 0.072517078 | D15: Margen neto (p) | E15: 0.0842 | I15: ROIC | J15: =J12/(E7-(E8-C10)) -> 0.17568013 | K15: EV/Ebidta (p) | L15: =C12/J16 -> 20.263725
B16: Semáforo ESG | D16: Ebidta/Ingresos(p) | E16: =J11/5326.524 -> 0.12759165 | I16: Ebidta(p) | J16: =J11 -> 679.62 | K16: Precio/FNP (p) | L16: =C9/J18 -> 18.938148
B17: E | D17: CIF/Deuda Neta Promedio | I17: Utilidad Neta (p) | J17: =J12 -> 448.462 | K17: Bonos 1;5;40a (USD) | L17: 4.0%; 4.4%; 5% | N17: 12
B18: S | I18: FNP (p) | J18: =SUM(626.83+888.229+484.854)/3 -> 666.63767 | K18: TDY(p)/Precio | L18: =L19/(C9) -> 1.1247629e-06
B19: G | I19: Tax (p) últ. 5a | J19: 0.16 | K19: Div. Yield: | L19: =1.42% -> 0.0142
B20: Tesis de inversión | H20: Acuerdo | I20: Supuestos de valuación | L20: DCF Value
B21: Pool Corporation is the world’s largest wholesale distributor of swimming pool and backyard products, operating over 440 sales centers across North America, Europe, and Australia. With strong market postion, the company generates constant shareholdervalue by re-acquiring shares and distribuiting dividends. This value delivered probably attracted warren buffet into the business, which he bought part. Pool have shown consistent growth in their operating margin, net sales and free cash flow over the past years. The balance sheet is robust, with total assets near $3.43B and total liabilities around $2.33B, they have healthy stockholders's equity that supports liquidity and growth iniatiatives. Pool Corporation’s resilient business model, efficient capital management, and strong cash generation, position it well for sustainable growth and attractive returns in a mature yet evolving industry. | H21: Mantener (y seguir comprando) | I21: VER DCF | L21: =#REF! -> #REF!
B23: KSF | H23: PO / Precio Stand By | L23: =#REF! -> #REF!
B24: Pool Corp’s key success factor is its extensive, efficient distribution network that ensures timely product availability and superior customer service, driving market leadership in the pool supplies industry. | H24: = | I24: Tasa de descuento: | J24: =#REF! -> #REF!
B25: Año | C25: Ingresos | D25: Margen Operativo | E25: Div.+Recompra | F25: FNP | G25: Deuda/Activo | H25: Depreciación | I25: Capex + Adq | J25: Cash Flow | M25: Deuda | N25: Activo | O25: Ingresos | P25: Margen | Q25: Div+Recompra | R25: FNP | S25: Depreciación | T25: Capex + Acq
B26: 2012 | C26: 1954 | D26: 0.0741 | E26: =(0.62*C8)/1000000 -> 23.5972 | F26: =(Ratios!C4*OP!$C$8)/1000000 -> 83.3514 | G26: =M26/N26 -> 0.2957981 | H26: 11.6 | I26: =16.3+4.7 -> 21 | K26: 2024 | L26: =K26-1 -> 2023 | M26: =230.9 -> 230.9 | N26: 780.6
B27: =B26+1 -> 2013 | C27: 2079.7 | D27: 0.0796 | E27: =(0.73*C8)/1000000 -> 27.7838 | F27: =(Ratios!D4*$C$8)/1000000 -> 71.1722 | G27: =M27/N27 -> 0.29910172 | H27: 13.4 | I27: =18.7+1.2 -> 19.9 | J27: Profit | K27: 448.5 | L27: 523.2 | M27: =246.4+0 -> 246.4 | N27: 823.8 | O27: =C27/C26-1 -> 0.06432958 | P27: =D27/D26-1 -> 0.074224022 | Q27: =E27/E26-1 -> 0.17741935 | R27: =F27/F26-1 -> -0.14611872 | S27: =G27/G26-1 -> 0.011168495 | T27: =I27/I26-1 -> -0.052380952
B28: =B27+1 -> 2014 | C28: 2246.6 | D28: 0.0841 | E28: =(0.85*C8)/1000000 -> 32.351 | F28: =(Ratios!E4*OP!$C$8)/1000000 -> 89.8216 | G28: =M28/N28 -> 0.35927875 | H28: 14.5 | I28: =17.3+10.6 -> 27.9 | J28: Cash Flow from Operations (BWC) | K28: 626.8 | L28: 888.2 | M28: =319.3+1.5 -> 320.8 | N28: 892.9 | O28: =C28/C27-1 -> 0.080251959 | P28: =D28/D27-1 -> 0.056532663 | Q28: =E28/E27-1 -> 0.16438356 | R28: =F28/F27-1 -> 0.26203209 | S28: =H28/H27-1 -> 0.082089552 | T28: =I28/I27-1 -> 0.40201005 | BT28: 4303
B29: =B28+1 -> 2015 | C29: 2363.1 | D29: 0.0915 | E29: =(1*C8)/1000000 -> 38.06 | F29: =(Ratios!F4*OP!$C$8)/1000000 -> 103.1426 | G29: =M29/N29 -> 0.3510274 | H29: 16.4 | I29: =29.1+4.5 -> 33.6 | J29: Working Capital | K29: =1815.4-770.8 -> 1044.6 | L29: =2019-675.7 -> 1343.3 | M29: =326.3+1.7 -> 328 | N29: 934.4 | O29: =C29/C28-1 -> 0.051856138 | P29: =D29/D28-1 -> 0.087990488 | Q29: =E29/E28-1 -> 0.17647059 | R29: =F29/F28-1 -> 0.14830508 | S29: =H29/H28-1 -> 0.13103448 | T29: =I29/I28-1 -> 0.20430108 | BT29: 3066
B30: =B29+1 -> 2016 | C30: 2570.8 | D30: 0.0995 | E30: =(1.19*C8)/1000000 -> 45.2914 | F30: =(Ratios!G4*OP!$C$8)/1000000 -> 119.1278 | G30: =M30/N30 -> 0.44059954 | H30: 20.3 | I30: =19.7+34.4 -> 54.1 | J30: Investing Activities | K30: 66.5 | L30: 71.6 | M30: =436.9+1.1 -> 438 | N30: 994.1 | O30: =C30/C29-1 -> 0.087893022 | P30: =D30/D29-1 -> 0.087431694 | Q30: =E30/E29-1 -> 0.19 | R30: =F30/F29-1 -> 0.15498155 | S30: =H30/H29-1 -> 0.23780488 | T30: =I30/I29-1 -> 0.61011905 | BT30: 3283
B31: =B30+1 -> 2017 | C31: 2788.2 | D31: 0.1021 | E31: =(1.42*C8)/1000000 -> 54.0452 | F31: =(Ratios!H4*OP!$C$8)/1000000 -> 126.7398 | G31: =M31/N31 -> 0.47189174 | H31: 24.2 | I31: =39.4+12.8 -> 52.2 | J31: Capex | K31: 63.1 | L31: 60.1 | M31: =508.8+10.8 -> 519.6 | N31: 1101.1 | O31: =C31/C30-1 -> 0.084565116 | P31: =D31/D30-1 -> 0.026130653 | Q31: =E31/E30-1 -> 0.19327731 | R31: =F31/F30-1 -> 0.063897764 | S31: =H31/H30-1 -> 0.19211823 | T31: =I31/I30-1 -> -0.035120148
B32: =B31+1 -> 2018 | C32: 2998.1 | D32: 0.1047 | E32: =(1.72*C8)/1000000 -> 65.4632 | F32: =(Ratios!I4*OP!$C$8)/1000000 -> 82.2096 | G32: =M32/N32 -> 0.53735192 | H32: 26.1 | I32: =31.6+2.6 -> 34.2 | J32: Adquisiones | K32: 4.5 | L32: 11.5 | M32: =657.6+9.2 -> 666.8 | N32: 1240.9 | O32: =C32/C31-1 -> 0.075281544 | P32: =D32/D31-1 -> 0.02546523 | Q32: =E32/E31-1 -> 0.21126761 | R32: =F32/F31-1 -> -0.35135135 | S32: =H32/H31-1 -> 0.078512397 | T32: =I32/I31-1 -> -0.34482759
B33: =B32+1 -> 2019 | C33: 3199.517 | D33: 0.1067 | E33: =(2.1*C8)/1000000 -> 79.926 | F33: =(Ratios!J4*OP!$C$8)/1000000 -> 253.4796 | G33: =M33/N33 -> 0.46504416 | H33: 27.885 | I33: =33.4+8.9 -> 42.3 | J33: Dividends | K33: 176.7 | L33: 167.5 | M33: =621.7+68.1 -> 689.8 | N33: 1483.3 | O33: =C33/C32-1 -> 0.067181548 | P33: =D33/D32-1 -> 0.019102197 | Q33: =E33/E32-1 -> 0.22093023 | R33: =F33/F32-1 -> 2.0833333 | S33: =H33/H32-1 -> 0.068390805 | T33: =I33/I32-1 -> 0.23684211
B34: =B33+1 -> 2020 | C34: 3936.623 | D34: 0.1179 | E34: =(2.29*C8)/1000000 -> 87.1574 | F34: =(Ratios!K4*OP!$C$8)/1000000 -> 356.6222 | G34: =M34/N34 -> 0.35856757 | H34: 27.967 | I34: =21.7+124.6 -> 146.3 | J34: Stock Repurchases | K34: 265.5 | L34: 295.9 | M34: =551+72.8 -> 623.8 | N34: 1739.7 | O34: =C34/C33-1 -> 0.2303804 | P34: =D34/D33-1 -> 0.1049672 | Q34: =E34/E33-1 -> 0.09047619 | R34: =F34/F33-1 -> 0.40690691 | S34: =H34/H33-1 -> 0.0029406491 | T34: =I34/I33-1 -> 2.4586288
B35: =B34+1 -> 2021 | C35: 5295.584 | D35: 0.1573 | E35: =(2.98*C8)/1000000 -> 113.4188 | F35: =(Ratios!L4*OP!$C$8)/1000000 -> 263.3752 | G35: =M35/N35 -> 0.44195765 | H35: 28.287 | I35: =37.7+812 -> 849.7 | J35: Endeudamiento Neto | K35: 1297.9 | L35: 1615.2 | M35: =1346.9+80.8 -> 1427.7 | N35: 3230.4 | O35: =C35/C34-1 -> 0.34520984 | P35: =D35/D34-1 -> 0.33418151 | Q35: =E35/E34-1 -> 0.30131004 | R35: =F35/F34-1 -> -0.26147279 | S35: =H35/H34-1 -> 0.011442057 | T35: =I35/I34-1 -> 4.8079289
B36: =B35+1 -> 2022 | C36: 6179.727 | D36: 0.166 | E36: =(3.8*C8)/1000000 -> 144.628 | F36: =(Ratios!M4*OP!$C$8)/1000000 -> 426.272 | G36: =M36/N36 -> 0.46581029 | H36: 30.381 | I36: =43.6+9.3 -> 52.9 | J36: Otros Financiemientos | K36: 1.7 | L36: 0.6 | M36: =1560.3+100.5 -> 1660.8 | N36: 3565.4 | O36: =C36/C35-1 -> 0.16695855 | P36: =D36/D35-1 -> 0.055308328 | Q36: =E36/E35-1 -> 0.27516779 | R36: =F36/F35-1 -> 0.61849711 | S36: =H36/H35-1 -> 0.074026938 | T36: =I36/I35-1 -> -0.93774273
B37: =B36+1 -> 2023 | C37: 5541.595 | D37: =746.567/C37 -> 0.1347206 | E37: =(4.3*C8)/1000000 -> 163.658 | F37: =(Ratios!N4*OP!$C$8)/1000000 -> 814.484 | G37: =M37/N37 -> 0.3980339 | H37: 31.585 | I37: =60.1+11.5 -> 71.6 | M37: =1237.1+127.4 -> 1364.5 | N37: 3428.1 | O37: =C37/C36-1 -> -0.10326217 | P37: =D37/D36-1 -> -0.18843012 | Q37: =E37/E36-1 -> 0.13157895 | R37: =F37/F36-1 -> 0.91071429 | S37: =H37/H36-1 -> 0.039630032 | T37: =I37/I36-1 -> 0.35349716
B38: 2024 Est. | C38: 5284.9 | D38: =635.898/C37 -> 0.11475 | E38: =(4.69*C8)/1000000 -> 178.5014 | F38: =(Ratios!O4*OP!$C$8)/1000000 -> 562.1462 | H38: 35.078 | I38: =63.1+4.5 -> 67.6 | O38: =C38/C37-1 -> -0.046321501 | P38: =D38/D37-1 -> -0.1482372 | Q38: =E38/E37-1 -> 0.090697674 | R38: =F38/F37-1 -> -0.30981308
B39: CAGR | C39: =(C37/C32)^(1/5)-1 -> 0.13072692 | D39: =(D38/D26)^(1/11)-1 -> 0.040559144 | E39: =(E38/E26)^(1/11)-1 -> 0.20195773 | F39: =(F38/F26)^(1/11)-1 -> 0.18948194 | G39: =(G38/G26)^(1/11)-1 -> -1 | H39: =(H38/H26)^(1/11)-1 -> 0.10583111 | I39: =(I38/I26)^(1/11)-1 -> 0.11213379 | J39: FX | K39: 0 | L39: 0
B40: AAG | C40: =AVERAGE(O27:O37) -> 0.10460414 | D40: =AVERAGE(P27:P37) -> 0.062082169 | J40: D Cash and Equivalents | K40: =K28+K29+K30+K33+K34+K35+K36+K39 -> 3479.7 | L40: =L28+L29+L30+L33+L34+L35+L36+L39 -> 4382.3
B41: CVAR | C41: =STDEV(C26:C37)/AVERAGE(C26:C37) -> 0.42789313 | D41: =STDEV(D26:D38)/AVERAGE(D26:D38) -> 0.25534221 | E41: =STDEV(E26:E38)/AVERAGE(E26:E38) -> 0.65715961 | F41: =STDEV(F26:F38)/AVERAGE(F26:F38) -> 0.88536133 | G41: =STDEV(G26:G38)/AVERAGE(G26:G38) -> 0.1847789 | H41: =STDEV(H26:H38)/AVERAGE(H26:H38) -> 0.3229337 | I41: =STDEV(I26:I38)/AVERAGE(I26:I38) -> 1.973495 | J41: Inv/D Vts | K41: =SUM(I33:I37)/(C37-C32) -> 0.45716622 | L41: =(SUM(I33:I37)-SUM(H33:H37))/(C37-C32) -> 0.39972361
B42: Último Año | C42: =C38/C37-1 -> -0.046321501 | D42: =D38/D37-1 -> -0.1482372 | E42: =E38/E37-1 -> 0.090697674 | F42: =F38/F37-1 -> -0.30981308 | G42: =G37/G36-1 -> -0.14550214 | H42: =H37/H36-1 -> 0.039630032 | I42: =I38/I37-1 -> -0.055865922 | J42: t inversiones; t adq. neto dep. | K42: =K41/E14 -> 3.7137792 | L42: =L41/E14 -> 3.2471455
...

Sheet COVID-19 impact
A1: https://www.apple.com/newsroom/2020/03/apples-covid-19-response/ | G1: https://glg.it/articles/how-might-the-wuhan-coronavirus-impact-apples-supply-chain/ | N1: https://www.cnbc.com/2020/02/18/the-significance-of-apples-coronavirus-warning.html
A2: March 13 | G2: January 29 | N2: Ferbuary 18
A23: Otros:
A24: https://www.macrumors.com/guide/covid-19-coronavirus/

Sheet Peers
A2: Multiplos (USD) | B2: (POOL) | C2: (SWIM) | D2: (HWKN) | E2: (HAYW)
B3: Pool Corporation | C3: Latham Group Inc. | D3: Hawkins Inc. | E3: Hayward Holdings Inc.
A4: Ventas | B4: =OP!C38*1000000 -> 5284900000 | C4: =566000*1000 -> 566000000 | D4: =919000*1000 -> 919000000 | E4: =992000*1000 -> 992000000
A5: Crecimiento (TTM) | B5: =(OP!C38-OP!C37)/OP!C37 -> -0.046321501 | C5: =C4/696000000 -1 -> -0.18678161 | D5: =D4/935000000-1 -> -0.017112299 | E5: =E4/1314000000-1 -> -0.24505327
A6: Crecimiento (1S24/1S20) | B6: =OP!C39 -> 0.13072692 | C6: =(C29/C30-1)/5 -> 0.13027276 | D6: =(D29/D30-1)/5 -> 0.1574428 | E6: =(E29/E30-1)/5 -> 0.054721681
A7: Deuda | B7: 122278 | C7: 82110 | D7: 26772 | E7: 100504
A8: Activos | B8: 323888 | C8: 301311 | D8: 319616 | E8: 321195
A9: Deuda/Activos | B9: =OP!C10/OP!E7 -> 0.36172695 | C9: =39.89% -> 0.3989 | D9: =16.45% -> 0.1645 | E9: 0.337
A10: Deuda/EBITDA | B10: =OP!C10/OP!J11 -> 1.824549 | C10: =4.34 -> 4.34 | D10: 0.77 | E10: 4.05
A11: (Capex + Adq.)/Revenue | B11: =OP!I37/OP!C37 -> 0.012920468 | C11: =(32000000)/C4 -> 0.056537102 | D11: =(57000000)/D4 -> 0.062023939 | E11: =26000000/E4 -> 0.026209677
A12: ROA (p) | B12: 0.117 | C12: 0.0133 | D12: 0.1211 | E12: 0.0277
A13: ROIC (p) | B13: 0.1804 | C13: 0.0435 | D13: 0.1523 | E13: 0.0582
A14: Margen Operativo 2023 | B14: =OP!D36 -> 0.166 | C14: 0.0285 | D14: 0.1143 | E14: 0.1766
A15: Margen Operativo 2024 | B15: 0.1231 | C15: 0.0435 | D15: 0.1204 | E15: 0.1872
A16: Float | B16: =OP!L7 -> 0.96820809 | C16: =40.21/115.78 -> 0.3472966 | D16: =19.21/20.93 -> 0.91782131 | E16: =214.52/215.91 -> 0.99356213
A17: b | B17: =OP!L9 -> 1.01 | C17: 1.88 | D17: 0.91 | E17: 1.17
A18: Precio/Utilidad | B18: 29.01 | C18: 0 | D18: 2.42 | E18: =2.92 -> 2.92
A19: Precio/Ventas | B19: 2.44 | C19: =302000000/C4 -> 0.5335689 | D19: 1.74 | E19: 30.18
A20: EV/Activos | B20: =OP!C12/OP!E7 -> 4.0173957 | C20: =537/835 -> 0.64311377 | D20: =2436/707 -> 3.4455446 | E20: =3866/2946 -> 1.3122878
A21: EV/Ebitda | B21: =OP!C12/OP!J11 -> 20.263725 | C21: =532/75 -> 7.0933333 | D21: 15.92 | E21: 15.51
A22: Div. Yield: | B22: =OP!L19 -> 0.0142 | C22: 0 | D22: 0.0082 | E22: 0
B24: *Nota: Estos múltiplos no consideran el promedio de los últimos 3 años, únicamente valores del último año reportado
B25: **Cifras en USD
A27: (You can make up a table with different indicators in order to link them to the multiples/ratios. At the end, put the table unvisible with white color)
A29: Sales 2024 1S | C29: 270751 | D29: 255879 | E29: 496962
A30: Sales 2020 1S | C30: 163956 | D30: 143172 | E30: 390200
A31: TTM | C31: 314847 | D31: 251120 | E31: 493679

Sheet Acuerdo
A1: Invertir
A2: NO invertir
A3: Mantener sin elevar posición
A4: Mantener (y seguir comprando)
A5: Liquidar
A6: PENDIENTE

Sheet ESG
B2: Análisis ESG | J2: PARÁMETROS
C3: Impacto | D3: ¿Reporta? | E3: Ranking | F3: Mitigación | G3: Semáforo | H3: Comentarios | J3: IMPACTO | L3: RANKING | M3: MITIGACIÓN
B4: Ambiental | J4: NONE | K4: 0 | L4: "Best in class" | M4: Is there evidence of progam/plan/etc…
B5: Emisiones directas CO2 | C5: 1 | E5: Best in Class | F5: Sí | H5: En 2022, las emisiones directas de gases de efecto invernadero (Alcance 1) de la flota de vehículos de Pool Corporation fueron 35,189 toneladas métricas de CO₂ equivalente (MtCO₂e). | J5: LOW | K5: 1 | L5: Medium high
B6: Uso total de agua | C6: 1 | E6: Medium High | F6: Sí | H6: Gastaron 10 veces minos de sus competidores | J6: MEDIUM | K6: 2 | L6: Medium
B7: Total Energy Consumption | C7: 0 | E7: Best in Class | F7: Sí | H7: 151,676 GJ en 2022; 60.7% provino de electricidad de la red. | J7: HIGH | K7: 3 | L7: "Villain"
B8: Waste Management | C8: 1 | E8: Best in Class | F8: Sí | H8: Se desviaron 7,857 toneladas de materiales de los vertederos, logrando una tasa de desviación del 17%.
B9: Land Degradation/Deforestation/Biodiversity loss/Animal sufering/… | C9: 1 | E9: Medium | F9: No | J9: TRAFFIC LIGHTS
B10: Social
B11: % Rotación de empleados | C11: 3 | D11: Sí(para in-store) | E11: Villain | F11: No | H11: In-Store: Tasa de rotación voluntaria: 36% (excluyendo trabajadores temporales). Tasa de rotación involuntaria: 10%.
B12: Sueldos y compensaciones | C12: 0 | D12: Sí | E12: Best in Class | F12: Sí | H12: Salario promedio por hora: $20.86 USD; 0% de los empleados de tienda ganan el salario mínimo
B13: Temas de reputación | C13: 0 | D13: No | E13: Best in Class | F13: Sí | H13: La empresa ha sido reconocida por su compromiso con la sostenibilidad y la seguridad.
B14: Temas de discriminación | C14: 0 | D14: Sí | E14: Best in Class | F14: Sí | H14: No se reportan litigios específicos por discriminación y tienen Ethics and Discrimination policies.
B15: Seguridad laboral | C15: 0 | D15: No | E15: Medium High | F15: Sí | H15: No se informaron incidentes graves y tienen un Health and Safety policy.
B16: Daños a la salud | C16: 0 | D16: No | E16: Medium High | F16: Sí | H16: Ningun reportado
B17: PXP? | D17: No | E17: Medium High | F17: No
B18: Supply chain | C18: 1 | D18: Sí | E18: Medium High | F18: No | H18: Mantiene relaciones estratégicas con proveedores globales.
B19: Community involvement | C19: 0 | D19: Sí | E19: Best in Class | F19: Sí | H19: A través del programa "Swimpact!", Pool Corp ha patrocinado 42,000 lecciones de natación y la capacitación de 3,000 salvavidas.
B20: Public Sector | C20: 0 | D20: No | E20: N/A | F20: No | H20: Sín envolvimento con setor público
B21: Litigios | C21: 0 | D21: No | E21: Best in Class | F21: Sí | H21: No se reportaron pérdidas monetarias por violaciones de leyes laborales.
B22: Gobierno
B23: Diversidad (Género, edad, industria, región) | E23: Medium | F23: Sí | H23: Género en Gerencia: 81% Hombre 19% Mujer; Demás Empleados: 81% Hombre 19% Mujer. Representación racial/étnica en Gerencia: 75% blanca, 1% asiática, 4% negra, 17% hispana, 3% otra; Demás Empleados: 55% blanca, 1% asiática, 14% negra, 26% hispana, 4% otra.
B24: % independientes | E24: Medium High | F24: Sí | H24: =8/9 -> 0.88888889
B25: tiempo promedio como consejeros independientes | E25: Medium | F25: No | H25: Informacíon no fue disponibilisada
B26: Salidas recientes de consejeros/C-level executives? | E26: No | F26: No
B27: CEO/Chairman | E27: No | F27: No | H27: Peter D. Arvan es el CEO y presidente de la empresa. El chairman es John E. Stokely y el Vice-Chairman es Manuel Perez de la Mesa (ex-CEO de POOL corp.) ningun de los dos es executivo.
B28: Transparencia (segmentos, fuente de riqueza, adquisiciones, otros) | E28: Best in Class | F28: Sí | H28: Se alinea con los estándares SASB y publica un Informe de Responsabilidad Corporativa detallado.
B29: Tiempo que tardan en reportar luego del final del trimestre/año | E29: Best in Class | F29: Sí | H29: Final de Febrebro (10k), 30/31-Abril,Junio, Octubre(10Q)
B30: Participación adicional del CEO en otros consejos o excesiva del Ch. | E30: Medium High | F30: No | H30: CEO no es el chairmain y está en el board de una LLC, Plaskolite
B31: Auditoría/Consultoría | D31: Sí | E31: Best in Class | F31: Sí | H31: Auditor(Ernst & Young) has been employed for over 30 years with company, audit committee is composed of only independent directors and receives no outside fees or bonuses
B32: Esquemas de compensación al management | D32: Sí | E32: Best in Class | F32: Sí | H32: Company has Executive and Director share ownership guidelines, half of the compensation is usually granted in Salaries and Bonuses(Non-Equity Incentives) and the other half in stock awards.

Sheet Ratios
A1: Column1 | B1: 2011 Y | C1: 2012 Y | D1: 2013 Y | E1: 2014 Y | F1: 2015 Y | G1: 2016 Y | H1: 2017 Y | I1: 2018 Y | J1: 2019 Y | K1: 2020 Y | L1: 2021 Y | M1: 2022 Y | N1: 2023 Y | O1: TTM
A2: Revenue per Share | B2: 37.24 | C2: 41.63 | D2: 44.94 | E2: 50.73 | F2: 54.82 | G2: 61.4 | H2: 68.27 | I2: 74.37 | J2: 80.32 | K2: 98.16 | L2: 132.8 | M2: 156.81 | N2: 143.18 | O2: 139.54
A3: Basic EPS, GAAP | B3: 1.49 | C3: 1.75 | D3: 2.1 | E3: 2.5 | F3: 2.98 | G3: 3.56 | H3: 4.69 | I3: 5.82 | J3: 6.57 | K3: 9.14 | L3: 16.32 | M3: 18.99 | N3: 13.52 | O3: 11.75
A4: Free Cash Flow per Basic Share | B4: 1.16 | C4: 2.19 | D4: 1.87 | E4: 2.36 | F4: 2.71 | G4: 3.13 | H4: 3.33 | I4: 2.16 | J4: 6.66 | K4: 9.37 | L4: 6.92 | M4: 11.2 | N4: 21.4 | O4: 14.77
A5: Dividend per Share | B5: 0.55 | C5: 0.62 | D5: 0.73 | E5: 0.85 | F5: 1 | G5: 1.19 | H5: 1.42 | I5: 1.72 | J5: 2.1 | K5: 2.29 | L5: 3 | M5: 3.82 | N5: 4.33 | O5: 4.63
A6: Book Value per Share | B6: 0.71 | C6: 0.12 | D6: -0.59 | E6: -2.05 | F6: -2.43 | G6: -4.39 | H6: -4.81 | I6: -5.42 | J6: -1.62 | K6: 3.34 | L6: 13.21 | M6: 16.58 | N6: 18.09 | O6: 21.02
A7: Tangible Book Value per Share | B7: 1.89 | C7: 2.14 | D7: 2.25 | E7: 1.32 | F7: 1.65 | G7: 0.17 | H7: 0.5 | I7: 0.57 | J7: 5.29 | K7: 8.95 | L7: 1.76 | M7: 6.03 | N7: 8.12 | O7: 11.52
A8: Basic Weighted Avg Shares | B8: 48 | C8: 47 | D8: 46 | E8: 44 | F8: 43 | G8: 42 | H8: 41 | I8: 40 | J8: 40 | K8: 40 | L8: 40 | M8: 39 | N8: 39 | O8: 38
A9: Sales/Revenue/Turnover | B9: 1793 | C9: 1954 | D9: 2,080 | E9: 2,247 | F9: 2,363 | G9: 2,571 | H9: 2,788 | I9: 2,998 | J9: 3,200 | K9: 3,937 | L9: 5296 | M9: 6180 | N9: 5542 | O9: 5327
A10: Operating Margin (%) | B10: 7.06 | C10: 7.77 | D10: 7.96 | E10: 8.41 | F10: 9.15 | G10: 9.95 | H10: 10.2 | I10: 10.47 | J10: 10.67 | K10: 11.96 | L10: 15.73 | M10: 16.6 | N10: 13.47 | O10: 11.94
A11: Depreciation Expense | B11: 11 | C11: 13 | D11: 15 | E11: 16 | F11: 17 | G11: 22 | H11: 26 | I11: 28 | J11: 29 | K11: 29 | L11: 30 | M11: 39 | N11: 40 | O11: 44
A12: Net Income, GAAP | B12: 72 | C12: 82 | D12: 97 | E12: 111 | F12: 128 | G12: 149 | H12: 192 | I12: 234 | J12: 262 | K12: 367 | L12: 651 | M12: 748 | N12: 523 | O12: 448
A13: Effective Tax Rate (%) | B13: 38.7 | C13: 41 | D13: 38.8 | E13: 38.9 | F13: 38.5 | G13: 38.5 | H13: 28.97 | I13: 20.06 | J13: 17.69 | K13: 18.87 | L13: 21.09 | M13: 24.04 | N13: 23.99 | O13: 23.23
... A20: Return on Common Equity (%) | B20: 141.06 | C20: 412.24 | D20: - - | E20: - - | F20: - - | G20: - - | H20: - - | I20: - - | J20: - - | K20: - - | L20: 196.91 | M20: 126.81 | N20: 77.31 | O20: 55.58
A22: Data extracted from: | B22: https://www.roic.ai/quote/POOL

Sheet DCF
A1: Discounted Cash Flow
A3: Ventas | E3: Margen Operativo
A16: Inversiones | E16: Utilidad Neta
D31: 0.001 | E31: =1/((1+$B$59+$D31)^(E35-2021)) -> 0.92250923 | F31: =1/((1+$B$59+$D31)^(F35-2021)) -> 0.85102327 | G31: =1/((1+$B$59+$D31)^(G35-2021)) -> 0.78507682 | H31: =1/((1+$B$59+$D31)^(H35-2021)) -> 0.72424061 | I31: =1/((1+$B$59+$D31)^(I35-2021)) -> 0.66811864 | J31: =1/((1+$B$59+$D31)^(J35-2021)) -> 0.61634561 | K31: =1/((1+$B$59+$D31)^(K35-2021)) -> 0.56858451 | L31: =1/((1+$B$59+$D31)^(L35-2021)) -> 0.52452446 | ... AC31: =1/((1+$B$59+$D31)^(AC35-2021)) -> 0.13312755
D32: 0.005 | E32: =1/((1+$B$59+$D32)^(E35-2021)) -> 0.91911765 | F32: =1/((1+$B$59+$D32)^(F35-2021)) -> 0.84477725 | G32: =1/((1+$B$59+$D32)^(G35-2021)) -> 0.77644968 | H32: =1/((1+$B$59+$D32)^(H35-2021)) -> 0.7136486 | I32: =1/((1+$B$59+$D32)^(I35-2021)) -> 0.65592702 | J32: =1/((1+$B$59+$D32)^(J35-2021)) -> 0.6028741 | K32: =1/((1+$B$59+$D32)^(K35-2021)) -> 0.55411223 | L32: =1/((1+$B$59+$D32)^(L35-2021)) -> 0.50929433 | ... AC32: =1/((1+$B$59+$D32)^(AC35-2021)) -> 0.12141647
D33: Normal | E33: =1/((1+$B$59)^(E35-2021)) -> 0.92336103 | F33: =1/((1+$B$59)^(F35-2021)) -> 0.8525956 | G33: =1/((1+$B$59)^(G35-2021)) -> 0.78725355 | H33: =1/((1+$B$59)^(H35-2021)) -> 0.72691926 | I33: =1/((1+$B$59)^(I35-2021)) -> 0.67120892 | J33: =1/((1+$B$59)^(J35-2021)) -> 0.61976816 | K33: =1/((1+$B$59)^(K35-2021)) -> 0.57226977 | L33: =1/((1+$B$59)^(L35-2021)) -> 0.5284116 | ... AC33: =1/((1+$B$59)^(AC35-2021)) -> 0.13623496
B35: 2019 (Real) | C35: 2020 (Real) | D35: 2021 | E35: =D35+1 -> 2022 | F35: =E35+1 -> 2023 | G35: =F35+1 -> 2024 | H35: =G35+1 -> 2025 | I35: =H35+1 -> 2026 | J35: =I35+1 -> 2027 | K35: =J35+1 -> 2028 | L35: =K35+1 -> 2029 | ... AC35: =AB35+1 -> 2046
A36: Crecimiento | B36: =OP!O34 -> 0.2303804 | C36: =OP!O35 -> 0.34520984 | D36: 0.35 | E36: 0.034 | F36: 0.095 | G36: 0.095 | H36: 0.095 | I36: 0.095 | J36: 0.095 | K36: 0.08 | L36: 0.06 | M36: 0.05 | N36: 0.04 | O36: 0.035 | P36: 0.035 | Q36: 0.035 | R36: 0.035 | S36: 0.035 | T36: 0.035 | U36: 0.035 | V36: 0.035 | W36: 0.035 | X36: 0.035 | Y36: 0.035 | Z36: 0.035 | AA36: 0.035 | AB36: 0.035 | AC36: 0.035
A37: Ventas | B37: =OP!C34 -> 3936.623 | C37: =OP!C35 -> 5295.584 | D37: =OP!C34*(1+D36) -> 5314.4411 | E37: =D37*(1+E36) -> 5495.132 | F37: =E37*(1+F36) -> 6017.1696 | G37: =F37*(1+G36) -> 6588.8007 | H37: =G37*(1+H36) -> 7214.7368 | I37: =H37*(1+I36) -> 7900.1368 | J37: =I37*(1+J36) -> 8650.6498 | K37: =J37*(1+K36) -> 9342.7017 | L37: =K37*(1+L36) -> 9903.2638 | ... AC37: =AB37*(1+AC36) -> 18117.832
A38: Margen Operativo | B38: =+OP!D34 -> 0.1179 | C38: =+OP!D35 -> 0.1573 | D38: =108166.4/365513.2 -> 0.29593022 | E38: =108162.8/377959.8 -> 0.28617541 | F38: 0.27 | G38: 0.275 | H38: 0.26 | I38: 0.255 | J38: 0.25 | K38: 0.25 | L38: 0.25 | M38: 0.25 | N38: 0.25 | O38: 0.25 | P38: 0.25 | Q38: 0.25 | R38: 0.25 | S38: 0.25 | T38: 0.25 | U38: 0.25 | V38: 0.25 | W38: 0.25 | X38: 0.25 | Y38: 0.25 | Z38: 0.25 | AA38: 0.25 | AB38: 0.25 | AC38: 0.25
A39: EBIT | B39: 63930 | C39: 66288 | D39: =D37*D38 -> 1572.7037 | E39: =E37*E38 -> 1572.5717 | F39: =F37*F38 -> 1624.6358 | G39: =G37*G38 -> 1811.9202 | H39: =H37*H38 -> 1875.8316 | I39: =I37*I38 -> 2014.5349 | J39: =J37*J38 -> 2162.6624 | K39: =K37*K38 -> 2335.6754 | ... AC39: =AC37*AC38 -> 4529.4581
A40: Dep&Amort | B40: =OP!H34 -> 27.967 | C40: =OP!H35 -> 28.287 | D40: 11000 | E40: =D40*(1+E36*$H$59) -> 11374 | F40: =E40*(1+F36*$H$59) -> 12454.53 | G40: =F40*(1+G36*$H$59) -> 13637.71 | H40: =G40*(1+H36*$H$59) -> 14933.293 | I40: =H40*(1+I36*$I$59) -> 16351.956 | J40: =I40*(1+J36*$I$59) -> 17905.391 | K40: =J40*(1+K36*$I$59) -> 19337.823 | L40: =K40*(1+L36*$I$59) -> 20498.092 | M40: =L40*(1+M36*$I$59) -> 21522.997 | N40: =M40*(1+N36*$I$59) -> 22383.917 | O40: =N40*(1+O36*$I$59) -> 23167.354 | P40: =O40*(1+P36*$I$59) -> 23978.211 | ... AC40: =AB40*(1+AC36*$I$59) -> 37500.868
A41: EBIDTA | B41: =+B39+B40 -> 63957.967 | C41: =+C39+C40 -> 66316.287 | D41: =D39+D40 -> 12572.704 | E41: =E39+E40 -> 12946.572 | F41: =F39+F40 -> 14079.166 | G41: =G39+G40 -> 15449.631 | H41: =H39+H40 -> 16809.124 | I41: =I39+I40 -> 18366.491 | J41: =J39+J40 -> 20068.054 | K41: =K39+K40 -> 21673.498 | ... AC41: =AC39+AC40 -> 42030.327
A42: CIF | B42: -1385 | C42: -890 | D42: =(C48)*$H$60 -> -1124.36 | E42: =(D48)*$H$60 -> -1113.1164 | F42: =(E48)*$H$60 -> -1113.1164 | G42: =(F48)*$H$60 -> -1113.1164 | H42: =(G48)*$H$60 -> -1113.1164 | I42: =(H48)*$H$60 -> -1113.1164 | J42: =(I48)*$H$60 -> -1113.1164 | K42: =(J48)*$H$60 -> -1113.1164 | ... AC42: =(AB48)*$H$60 -> -1113.1164
A43: Otros Gastos | B43: =-422-2817 -> -3239 | C43: =87-3634 -> -3547 | D43: =-C43*(1+D36) -> 4788.45 | E43: =D43*(1+E36*0.5) -> 4869.8537 | F43: =E43*(1+F36*0.5) -> 5101.1717 | G43: =F43*(1+G36*0.5) -> 5343.4774 | H43: =G43*(1+H36*0.5) -> 5597.2925 | I43: =H43*(1+I36*0.5) -> 5863.1639 | J43: =I43*(1+J36*0.5) -> 6141.6642 | K43: =J43*(1+K36*0.5) -> 6387.3308 | L43: =K43*(1+L36*0.5) -> 6578.9507 | ... AC43: =AB43*(1+AC36*0.5) -> 8922.7133
A44: Utilidad antes de Impuestos | B44: =B39-B42-B43 -> 68554 | C44: =C39-C42-C43 -> 70725 | D44: =D39-D42-D43 -> -2091.3863 | E44: =E39-E42-E43 -> -2184.1656 | F44: =F39-F42-F43 -> -2363.4195 | G44: =G39-G42-G43 -> -2418.4408 | H44: =H39-H42-H43 -> -2608.3446 | I44: =I39-I42-I43 -> -2735.5126 | ... AC44: =AC39-AC42-AC43 -> -3280.1388
A45: ISR & PTU | B45: 10481 | C45: 9680 | D45: =$H$61*D44 -> -439.19113 | E45: =$H$61*E44 -> -458.67477 | F45: =$H$61*F44 -> -496.3181 | G45: =$I$61*G44 -> -556.24138 | H45: =$I$61*H44 -> -599.91925 | I45: =$I$61*I44 -> -629.16791 | J45: =$I$61*J44 -> -659.15364 | K45: =$I$61*K44 -> -675.86396 | L45: =$I$61*L44 -> -687.70422 | M45: =$I$61*M44 -> -697.0613 | N45: =$I$61*N44 -> -704.16467 | ... AC45: =$I$61*AC44 -> -754.43193
A46: Utilidad Neta | B46: =B44-B45 -> 58073 | C46: =C44-C45 -> 61045 | D46: =D44-D45 -> -1652.1952 | E46: =E44-E45 -> -1725.4908 | F46: =F44-F45 -> -1867.1014 | G46: =G44-G45 -> -1862.1994 | H46: =H44-H45 -> -2008.4253 | I46: =I44-I45 -> -2106.3447 | ... AC46: =AC44-AC45 -> -2525.7069
A47: Inversiones y Capex | B47: =OP!I34 -> 146.3 | C47: =OP!I35 -> 849.7 | D47: 10000 | E47: =D47*(1+E36*$H$62) -> 10408 | F47: =E47*(1+F36*$H$62) -> 11594.512 | G47: =F47*(1+G36*$H$62) -> 12916.286 | H47: =G47*(1+H36*$H$62) -> 14388.743 | I47: =H47*(1+I36*$H$62) -> 16029.06 | J47: =I47*(1+J36*$H$62) -> 17856.373 | K47: =J47*(1+K36*$H$62) -> 19570.584 | L47: =K47*(1+L36*$H$62) -> 20979.666 | ... AC47: =AB47*(1+AC36*$H$62) -> 43199.777
A48: Deuda + Lease Liabilities | B48: 108047 | C48: 112436 | D48: =C48*0.99 -> 111311.64 | E48: =D48 -> 111311.64 | F48: =E48 -> 111311.64 | G48: =F48 -> 111311.64 | H48: =G48 -> 111311.64 | I48: =H48 -> 111311.64 | J48: =I48 -> 111311.64 | K48: =J48 -> 111311.64 | L48: =K48 -> 111311.64 | ... AC48: =AB48 -> 111311.64
A49: Deuda/EBITDA | B49: =B48/B41 -> 1.6893439 | C49: =C48/C41 -> 1.6954508 | D49: =D48/D41 -> 8.853437 | E49: =E48/E41 -> 8.5977696
A50: FNP | B50: =OP!F34 -> 356.6222 | C50: =OP!F35 -> 263.3752 | D50: =D41-D42-D43-D45-D47+D48-C48 -> -1776.5552 | E50: =E41-E42-E43-E45-E47+E48-D48 -> -759.49082 | F50: =F41-F42-F43-F45-F47+F48-E48 -> -1007.0834 | G50: =G41-G42-G43-G45-G47+G48-F48 -> -1140.7754 | H50: =H41-H42-H43-H45-H47+H48-G48 -> -1463.8755 | I50: =I41-I42-I43-I45-I47+I48-H48 -> -1783.4488 | J50: =J41-J42-J43-J45-J47+J48-I48 -> -2157.7128 | K50: =K41-K42-K43-K45-K47+K48-J48 -> -2495.4365 | ... AC50: =AC41-AC42-AC43-AC45-AC47+AC48-AB48 -> -8224.6159
A51: F(t) | B51: 0 | C51: 0 | D51: =C51*(1+$B$59)+D50 -> -1776.5552 | E51: =D51*(1+$B$59)+E50 -> -2683.5001 | F51: =E51*(1+$B$59)+F50 -> -3913.314 | G51: =F51*(1+$B$59)+G50 -> -5378.8945 | H51: =G51*(1+$B$59)+H50 -> -7289.2182 | I51: =H51*(1+$B$59)+I50 -> -9677.6721 | J51: =I51*(1+$B$59)+J50 -> -12638.632 | K51: =J51*(1+$B$59)+K50 -> -16183.075 | ... AC51: =AB51*(1+$B$59)+AC50 -> -242164.92
AB52: =AB51-AB48 -> -327323 | AC52: =AC50/(B59-AC36) -> -171346.16
A53: EPS | C53: =1000000*C46/OP!$C$8 -> 1603.9149 | D53: =1000000*D46/OP!$C$8 -> -43.410278 | E53: =1000000*E46/OP!$C$8 -> -45.33607 | F53: =1000000*F46/OP!$C$8 -> -49.05679
A54: Consenso EPS | C54: 3.3 | D54: 5.6 | E54: 5.6
A55: E$/UN | D55: =$B$61/D46 -> 41.118735 | E55: =$B$61/E46 -> 39.372088 | F55: =$B$61/F46 -> 36.385906
A56: EEV/EBIDA | D56: =($B$61+D48-D51)/D41 -> 3.5912736 | E56: =($B$61+E48-E51)/E41 -> 3.5576186 | F56: =($B$61+F48-F51)/F41 -> 3.3587769
C58: "TELP" | D58: CER | E58: D Analista | H58: CP | I58: LP
A59: Tasa de descuento: | B59: =SUM(C59:E59) -> 0.083 | C59: 0.0307 | D59: 0.0523 | E59: 0 | G59: Factor D&A | H59: 1 | I59: 1
G60: Factor CIF | H60: -0.01
A61: VPN*@i% | B61: =C62+C63 -> -67936.177 | C61: Normal | D61: =D31 -> 0.001 | E61: =D32 -> 0.005 | G61: Factor ISR | H61: 0.21 | I61: 0.23
A62: DCF 25Y | B62: =C62/B61 -> 0.65639311 | C62: =AB52/(1+B59)^25 -> -44592.838 | D62: =SUMPRODUCT(E50:AB50,E31:AB31) -> -29740.759 | E62: =SUMPRODUCT(E50:AB50,E32:AB32) -> -28380.84 | G62: Factor inv | H62: 1.2
A63: Perpetuidad | B63: =1-B62 -> 0.34360689 | C63: =AC52/(1+B59)^25 -> -23343.339 | D63: =(AC50/($B$59+D31-$AC$36))*AC31 -> -22345.367 | E63: =(AC50/($B$59+D32-$AC$36))*AC32 -> -18841.582 | G63: Suma D&A | H63: =SUM(40:40) -> 628485.83
A64: VPN/Acción | B64: =1000000*B61/OP!C8 -> -1784.9757 | D64: =1000000*SUM(D62:D63)/OP!C8 -> -1368.5267 | E64: =1000000*SUM(E62:E63)/OP!C8 -> -1240.7363 | G64: Suma Inv. | H64: =SUM(47:47) -> 673841.39
B65: =B64/OP!C7-1 -> -6.3811333 | D65: =D64/B64-1 -> -0.23330796 | E65: =E64/B64-1 -> -0.30490021 | G65: Inv.+Goodwill | H65: =SUM(47:47)+(OP!E12*OP!E7) -> 673934.09
A67: Duración | B67: =B62*D68+B63*D69 -> 21.490693 | E67: 1 | F67: 2 | G67: 3 | H67: 4 | I67: 5 | J67: 6 | K67: 7 | L67: 8 | M67: 9 | N67: 10 | O67: 11 | P67: 12 | Q67: 13 | R67: 14 | S67: 15 | T67: 16 | U67: 17 | V67: 18 | W67: 19 | X67: 20 | Y67: 21 | Z67: 22 | AA67: 23 | AB67: 24 | AC67: 25
A68: 0.001 | B68: =-$B$67*A68 -> -0.021490693 | D68: =SUM(E68:AB68)/SUMPRODUCT(E50:AB50,E33:AB33) -> 12.823218 | E68: =E67*E50*E33 -> -701.28423 | F68: =F67*F50*F33 -> -1717.2698 | G68: =G67*G50*G33 -> -2694.2385 | H68: =H67*H50*H33 -> -4256.4772 | I68: =I67*I50*I33 -> -5985.3337 | J68: =J67*J50*J33 -> -8023.6902 | K68: =K67*K50*K33 -> -9996.4402 | L68: =L67*L50*L33 -> -11768.311 | ... AC68: =AC67*AC50*AC33 -> -28012.006
A69: 0.005 | B69: =-$B$67*A69 -> -0.10745347 | D69: =(1+B59)/B59+AC67 -> 38.048193
