Workbook
Name Benchmark: [1]ControlsH!$B$3
Name BestConsOv: #REF!
Name Broker_Name: OFFSET(#REF!,0,0,[1]ControlsH!$E$5, 1)
Name calCODE: [1]ControlsH!$C$4
Name Chart_Benchmark_100_Size: OFFSET(#REF!, 0, 0, [1]ControlsH!$E$3, 1)
Name Chart_Date_Size: OFFSET(#REF!, 0, 0, [1]ControlsH!$E$3, 1)
Name Chart_Date_VAL1_Size: OFFSET(#REF!, 0, 0, [1]ControlsH!$I$3, 1)
Name Chart_Date_VAL2_Size: OFFSET(#REF!, 0, 0, [1]ControlsH!$I$5, 1)
Name Chart_Peer_100_Size: OFFSET(#REF!, 0, 0, [1]ControlsH!$E$3, 1)
Name Chart_Price_100_Size: OFFSET(#REF!, 0, 0, [1]ControlsH!$E$3, 1)
Name Chart_Price_Size: OFFSET(#REF!, 0, 0, [1]ControlsH!$E$3, 1)
Name Chart_VAL1_FY1_Size: OFFSET(#REF!, 0, 0, [1]ControlsH!$F$3, 1)
Name Chart_VAL1_FY2_Size: OFFSET(#REF!, 0, 0, [1]ControlsH!$G$3, 1)
Name Chart_VAL1_FY3_Size: OFFSET(#REF!, 0, 0, [1]ControlsH!$H$3, 1)
Name Chart_VAL2_FY1_Size: OFFSET(#REF!, 0, 0, [1]ControlsH!$F$5, 1)
Name Chart_VAL2_FY2_Size: OFFSET(#REF!, 0, 0, [1]ControlsH!$G$5, 1)
Name Chart_VAL2_FY3_Size: OFFSET(#REF!, 0, 0, [1]ControlsH!$H$5, 1)
Name Chart_Volume_Size: OFFSET(#REF!, 0, 0, [1]ControlsH!$E$3, 1)
Name compNAME: [1]ControlsH!$B$6
Name CURRENCY: [1]ControlsH!$B$9
Name currPRICE: [1]Overview!$E$19
Name custBenchmark: [1]Overview!$C$9
Name custED: #REF!
Name custSD: #REF!
Name dayCODE: [1]ControlsH!$C$5
Name ED: [1]ControlsH!$B$5
Name ESTBrokersItem: #REF!
Name ESTBrokersPeriod: #REF!
Name ESTDetailBroker: #REF!
Name ESTDetailBroker2: #REF!
Name ESTDetailPeriod: #REF!
Name EstDetPerO: #REF!
Name EstDetPerT: #REF!
Name FinancialsPeriod: #REF!
Name fundTICKER: [1]ControlsH!$B$15
Name GraphValRatio1: #REF!
Name GraphValRatio2: #REF!
Name Index1: #REF!
Name Lang: [1]Overview!$D$11
Name newCrncy: [1]ControlsH!$B$21:$B$199
Name newEstBrokerPeriod: #REF!
Name newEstBrokersItem: #REF!
Name newEstDetailBroker: #REF!
Name newEstDetailBroker2: #REF!
Name newEstDetailPeriod: #REF!
Name newFinancialsPeriod: #REF!
Name newOverviewCon: #REF!
Name newOverviewYear: #REF!
Name newOwners: #REF!
Name newPeersRatio: #REF!
Name newPeriod: #REF!
Name newValRatio1: #REF!
Name newValRatio2: #REF!
Name OverviewValRatioPeriod: [1]Overview!$D$30
Name PeerDate1: [1]Peers!$S$11
Name peerHist1: #REF!
Name PeerIndex: [1]ControlsH!$F$35:$F$36
Name Peers: OFFSET([1]Peers!$C$18,0,0,MAX(COUNTA([1]Peers!$C$18:$C$47),1),1)
Name peersWEIGHT: [1]ControlsH!$B$13
Name PERIODICITY: [1]ControlsH!$C$3

Sheet OP
B2: (date of last modification) | C2: Analista: Research | D2: Report (quarter): (date) | E2: Name of the Company (Ticker) | K2: (stock market) | L2: SIC: Sí
D3: DESCRIPTION: (write relevant information about the company, 1-2 lines is enough. If you find segments and key products relevant for this part, you can also write it here)
D4: CEO & BOARD: Name (Chairman or not; age; board member since; current board presence; previous jobs); note: *Independent members, green: new members
B5: Millones de USD
B6: Acción | D6: Liquidez y Solvencia | F6: =#REF! -> #REF! | I6: Rentabilidad (2022) | K6: Múltiplos
B7: Último Precio | D7: Activo: | H7: %Vts; %Op.Mg.; D | I7: Año termina: | K7: Float:
B8: Outstanding Shares | D8: Pasivo: | F8: =#REF! -> #REF! | H8: =+#REF! -> #REF! | K8: Insiders Own:
B9: Market Cap. | C9: =C7*C8/1000000 -> 0 | D9: Cash/Precio | E9: =1000000*#REF!/C8 -> #REF! | F9: =#REF! -> #REF! | H9: =+#REF! -> #REF! | I9: EBIT | K9: b (Bloomberg; Yahoo)
B10: +Deuda Total | D10: Ebidta/CIF | F10: =#REF! -> #REF! | H10: =+#REF! -> #REF! | I10: +Dep&Amort | K10: Calificación (S&P)
B11: -Cash | D11: Deuda/Ebidta | F11: =#REF! -> #REF! | H11: =+#REF! -> #REF! | I11: =EBIDTA | J11: =J9+J10 -> 0 | K11: Precio/Valor en libros | L11: =((C7*C8)/1000000)/(E7-E8) -> #DIV/0!
B12: =Enterprise Value | C12: =C9+C11-#REF! -> #REF! | D12: "Otros activos"/Activo | F12: =#REF! -> #REF! | H12: =+#REF! -> #REF! | I12: Utilidad Neta | K12: FNP(p)/Activos | L12: =J18/E7 -> #DIV/0!
B13: Tenencia % (nac/int'l) | D13: Deuda/Activo | E13: =C11/E7 -> #DIV/0! | F13: =#REF! -> #REF! | I13: UPA | J13: =1000000*J12/C8 -> #DIV/0! | K13: Precio/Utilidad(p) | L13: =C9/J17 -> #REF! | N13: =C11/J11 -> #DIV/0!
B14: t liq. (Pos prom./Vol.) | D14: Margen de Operación (p) | H14: %Vts; D | I14: ROA | J14: =J12/E7 -> #DIV/0! | K14: EV/Activos | L14: =C12/E7 -> #REF!
B15: % Short | D15: Margen neto (p) | F15: =#REF! -> #REF! | H15: =+#REF! -> #REF! | I15: ROIC | J15: =J12/(E7-(E8-C11)) -> #DIV/0! | K15: EV/Ebidta (p) | L15: =C12/J16 -> #REF!
B16: Semáforo ESG | D16: Ebidta/Ingresos(p) | F16: =#REF! -> #REF! | H16: =+#REF! -> #REF! | I16: Ebidta(p) | J16: =AVERAGE(#REF!) -> #REF! | K16: Precio/FNP (p) | L16: =C9/J18 -> #DIV/0!
B17: E | D17: CIF/Deuda Neta Promedio | F17: =#REF! -> #REF! | H17: =+#REF! -> #REF! | I17: Utilidad Neta (p) | J17: =AVERAGE(#REF!) -> #REF! | K17: Bonos 1;5;40a (USD) | L17: 4.0%; 4.4%; 5% | N17: 12
B18: S | F18: =#REF! -> #REF! | H18: =+#REF! -> #REF! | I18: FNP (p) | J18: =SUM(F35:F37)/3 -> 0 | K18: TDY(p)/Precio | L18: =SUM(E35:E37)/(3*C9) -> #DIV/0!
B19: G | F19: =#REF! -> #REF! | H19: =+#REF! -> #REF! | I19: Tax (p) últ. 5a | J19: 0.16 | K19: Div. Yield: | L19: =K33/C9 -> #DIV/0!
B20: Tesis de inversión | H20: Acuerdo | I20: Supuestos de valuación | L20: DCF Value
B21: Hold Position - Prada S.p.A. stands out as a globally recognized luxury brand with a strong reputation for quality, innovation, and sustainability. The company’s leadership in the high-end fashion market is supported by its iconic brand identity, premium pricing power, and strategic initiatives like the Re-Nylon project that aligns with growing consumer demand for environmentally conscious products. Prada’s gross margin of 72.7% demonstrates its ability to maintain profitability, even in a competitive luxury market. Additionally, its focus on sustainability and digital transformation positions the company to attract younger, ESG-conscious consumers, ensuring long-term brand relevance. However, while Prada has opportunities to grow in emerging markets and among ultra-high-net-worth individuals, its heavy reliance on China for 32.4% of its revenue exposes it to risks from geopolitical tensions, regulatory changes, and economic slowdowns. Despite Prada’s strong brand equity and profitability, the company faces challenges that warrant a cautious investment approach. Rising production and operational costs, driven by European labor expenses and sustainability investments, could pressure profit margins. Additionally, Prada trails competitors like Louis Vuitton and Hermès in digital engagement and revenue growth, with a CAGR of 8.5% (2021–2023) compared to higher rates among peers. Governance concerns, including shareholder engagement and financial disclosures, also weigh on investor sentiment. While Prada trades at an attractive EV/EBITDA multiple of 14.2x compared to peers like Hermès (21.0x) and Louis Vuitton (17.6x), these valuation discounts reflect the risks it faces. For investors, Prada represents a "Hold" position—an asset worth maintaining due to its strong fundamentals but not yet compelling enough to warrant additional investment until key risks are addressed. | H21: Mantener sin elevar posición | I21: VER DCF | L21: =#REF! -> #REF!
B23: KSF | H23: PO / Precio Stand By | L23: =#REF! -> #REF!
H24: =#REF! -> #REF! | I24: Tasa de descuento: | J24: =#REF! -> #REF!
B25: Año | C25: Ingresos | D25: Margen Operativo | E25: Div.+Recompra | F25: FNP | G25: Deuda/Activo | H25: Depreciación | I25: Capex + Adq | J25: Cash Flow
B26: 2012 | K26: 2022 | L26: =K26-1 -> 2021
B27: =B26+1 -> 2013 | J27: Profit | N27: =C27/C26-1 -> #DIV/0! | O27: =D27/D26-1 -> #DIV/0!
B28: =B27+1 -> 2014 | J28: Cash Flow from Operations (BWC) | N28: =C28/C27-1 -> #DIV/0! | O28: =D28/D27-1 -> #DIV/0! | P28: =E28/E27-1 -> #DIV/0! | Q28: =F28/F27-1 -> #DIV/0! | R28: =H28/H27-1 -> #DIV/0! | S28: =I28/I27-1 -> #DIV/0! | BT28: 4303
B29: =B28+1 -> 2015 | J29: Working Capital | N29: =C29/C28-1 -> #DIV/0! | O29: =D29/D28-1 -> #DIV/0! | P29: =E29/E28-1 -> #DIV/0! | Q29: =F29/F28-1 -> #DIV/0! | R29: =H29/H28-1 -> #DIV/0! | S29: =I29/I28-1 -> #DIV/0! | BT29: 3066
B30: =B29+1 -> 2016 | J30: Investing Activities | N30: =C30/C29-1 -> #DIV/0! | O30: =D30/D29-1 -> #DIV/0! | P30: =E30/E29-1 -> #DIV/0! | Q30: =F30/F29-1 -> #DIV/0! | R30: =H30/H29-1 -> #DIV/0! | S30: =I30/I29-1 -> #DIV/0! | BT30: 3283
B31: =B30+1 -> 2017 | J31: Capex | N31: =C31/C30-1 -> #DIV/0! | O31: =D31/D30-1 -> #DIV/0! | P31: =E31/E30-1 -> #DIV/0! | Q31: =F31/F30-1 -> #DIV/0! | R31: =H31/H30-1 -> #DIV/0! | S31: =I31/I30-1 -> #DIV/0!
B32: =B31+1 -> 2018 | J32: Adquisiones | N32: =C32/C31-1 -> #DIV/0! | O32: =D32/D31-1 -> #DIV/0! | P32: =E32/E31-1 -> #DIV/0! | Q32: =F32/F31-1 -> #DIV/0! | R32: =H32/H31-1 -> #DIV/0! | S32: =I32/I31-1 -> #DIV/0!
B33: =B32+1 -> 2019 | J33: Dividends | N33: =C33/C32-1 -> #DIV/0! | O33: =D33/D32-1 -> #DIV/0! | P33: =E33/E32-1 -> #DIV/0! | Q33: =F33/F32-1 -> #DIV/0! | R33: =H33/H32-1 -> #DIV/0! | S33: =I33/I32-1 -> #DIV/0!
B34: =B33+1 -> 2020 | J34: Stock Repurchases | N34: =C34/C33-1 -> #DIV/0! | O34: =D34/D33-1 -> #DIV/0! | P34: =E34/E33-1 -> #DIV/0! | Q34: =F34/F33-1 -> #DIV/0! | R34: =H34/H33-1 -> #DIV/0! | S34: =I34/I33-1 -> #DIV/0!
B35: =B34+1 -> 2021 | J35: Endeudamiento Neto | N35: =C35/C34-1 -> #DIV/0! | O35: =D35/D34-1 -> #DIV/0! | P35: =E35/E34-1 -> #DIV/0! | Q35: =F35/F34-1 -> #DIV/0! | R35: =H35/H34-1 -> #DIV/0! | S35: =I35/I34-1 -> #DIV/0!
B36: =B35+1 -> 2022 | J36: Otros Financiemientos | N36: =C36/C35-1 -> #DIV/0! | O36: =D36/D35-1 -> #DIV/0!
B37: =B36+1 -> 2023 | D37: =119500/C37 -> #DIV/0! | N37: =C37/C36-1 -> #DIV/0! | O37: =D37/D36-1 -> #DIV/0!
B38: 2024 Est. | C38: =#REF! -> #REF! | D38: =#REF! -> #REF!
B39: CAGR | C39: =(C37/C32)^(1/5)-1 -> #DIV/0! | D39: =(D37/D26)^(1/11)-1 -> #DIV/0! | J39: FX | K39: 0 | L39: 0
B40: AAG | C40: =AVERAGE(N27:N37) -> #DIV/0! | D40: =AVERAGE(O27:O37) -> #DIV/0! | J40: D Cash and Equivalents | K40: =K28+K29+K30+K33+K34+K35+K36+K39 -> 0 | L40: =L28+L29+L30+L33+L34+L35+L36+L39 -> 0
B41: CVAR | C41: =STDEV(C26:C37)/AVERAGE(C26:C37) -> #DIV/0! | D41: =STDEV(D26:D37)/AVERAGE(D26:D37) -> #DIV/0! | J41: Inv/D Vts | K41: =SUM(I33:I37)/(C37-C32) -> #DIV/0! | L41: =(SUM(I33:I37)-SUM(H33:H37))/(C37-C32) -> #DIV/0!
B42: Último Año | C42: =C37/C36-1 -> #DIV/0! | D42: =D37/D36-1 -> #DIV/0! | J42: t inversiones; t adq. neto dep. | K42: =K41/E14 -> #DIV/0! | L42: =L41/E14 -> #DIV/0!
...

Sheet COVID-19 impact
A1: https://www.apple.com/newsroom/2020/03/apples-covid-19-response/ | G1: https://glg.it/articles/how-might-the-wuhan-coronavirus-impact-apples-supply-chain/ | N1: https://www.cnbc.com/2020/02/18/the-significance-of-apples-coronavirus-warning.html
A2: March 13 | G2: January 29 | N2: Ferbuary 18
A23: Otros:
A24: https://www.macrumors.com/guide/covid-19-coronavirus/

Sheet Acuerdo
A1: Invertir
A2: NO invertir
A3: Mantener sin elevar posición
A4: Mantener (y seguir comprando)
A5: Liquidar
A6: PENDIENTE

Sheet DCF
A1: Discounted Cash Flow
A3: Ventas | E3: Margen Operativo
A16: Inversiones | E16: Utilidad Neta
D31: 0.001 | E31: =1/((1+$B$59+$D31)^(E35-2021)) -> 0.92250923 | F31: =1/((1+$B$59+$D31)^(F35-2021)) -> 0.85102327 | G31: =1/((1+$B$59+$D31)^(G35-2021)) -> 0.78507682 | H31: =1/((1+$B$59+$D31)^(H35-2021)) -> 0.72424061 | I31: =1/((1+$B$59+$D31)^(I35-2021)) -> 0.66811864 | J31: =1/((1+$B$59+$D31)^(J35-2021)) -> 0.61634561 | K31: =1/((1+$B$59+$D31)^(K35-2021)) -> 0.56858451 | L31: =1/((1+$B$59+$D31)^(L35-2021)) -> 0.52452446 | ... AC31: =1/((1+$B$59+$D31)^(AC35-2021)) -> 0.13312755
D32: 0.005 | E32: =1/((1+$B$59+$D32)^(E35-2021)) -> 0.91911765 | F32: =1/((1+$B$59+$D32)^(F35-2021)) -> 0.84477725 | G32: =1/((1+$B$59+$D32)^(G35-2021)) -> 0.77644968 | H32: =1/((1+$B$59+$D32)^(H35-2021)) -> 0.7136486 | I32: =1/((1+$B$59+$D32)^(I35-2021)) -> 0.65592702 | J32: =1/((1+$B$59+$D32)^(J35-2021)) -> 0.6028741 | K32: =1/((1+$B$59+$D32)^(K35-2021)) -> 0.55411223 | L32: =1/((1+$B$59+$D32)^(L35-2021)) -> 0.50929433 | ... AC32: =1/((1+$B$59+$D32)^(AC35-2021)) -> 0.12141647
D33: Normal | E33: =1/((1+$B$59)^(E35-2021)) -> 0.92336103 | F33: =1/((1+$B$59)^(F35-2021)) -> 0.8525956 | G33: =1/((1+$B$59)^(G35-2021)) -> 0.78725355 | H33: =1/((1+$B$59)^(H35-2021)) -> 0.72691926 | I33: =1/((1+$B$59)^(I35-2021)) -> 0.67120892 | J33: =1/((1+$B$59)^(J35-2021)) -> 0.61976816 | K33: =1/((1+$B$59)^(K35-2021)) -> 0.57226977 | L33: =1/((1+$B$59)^(L35-2021)) -> 0.5284116 | ... AC33: =1/((1+$B$59)^(AC35-2021)) -> 0.13623496
B35: 2019 (Real) | C35: 2020 (Real) | D35: 2021 | E35: =D35+1 -> 2022 | F35: =E35+1 -> 2023 | G35: =F35+1 -> 2024 | H35: =G35+1 -> 2025 | I35: =H35+1 -> 2026 | J35: =I35+1 -> 2027 | K35: =J35+1 -> 2028 | L35: =K35+1 -> 2029 | ... AC35: =AB35+1 -> 2046
A36: Crecimiento | B36: =OP!N34 -> #DIV/0! | C36: =OP!N35 -> #DIV/0! | D36: 0.35 | E36: 0.034 | F36: 0.095 | G36: 0.095 | H36: 0.095 | I36: 0.095 | J36: 0.095 | K36: 0.08 | L36: 0.06 | M36: 0.05 | N36: 0.04 | O36: 0.035 | P36: 0.035 | Q36: 0.035 | R36: 0.035 | S36: 0.035 | T36: 0.035 | U36: 0.035 | V36: 0.035 | W36: 0.035 | X36: 0.035 | Y36: 0.035 | Z36: 0.035 | AA36: 0.035 | AB36: 0.035 | AC36: 0.035
A37: Ventas | B37: =OP!C34 -> 0 | C37: =OP!C35 -> 0 | D37: =OP!C34*(1+D36) -> 0 | E37: =D37*(1+E36) -> 0 | F37: =E37*(1+F36) -> 0 | G37: =F37*(1+G36) -> 0 | H37: =G37*(1+H36) -> 0 | I37: =H37*(1+I36) -> 0 | J37: =I37*(1+J36) -> 0 | K37: =J37*(1+K36) -> 0 | L37: =K37*(1+L36) -> 0 | ... AC37: =AB37*(1+AC36) -> 0
A38: Margen Operativo | B38: =+OP!D34 -> 0 | C38: =+OP!D35 -> 0 | D38: =108166.4/365513.2 -> 0.29593022 | E38: =108162.8/377959.8 -> 0.28617541 | F38: 0.27 | G38: 0.275 | H38: 0.26 | I38: 0.255 | J38: 0.25 | K38: 0.25 | L38: 0.25 | M38: 0.25 | N38: 0.25 | O38: 0.25 | P38: 0.25 | Q38: 0.25 | R38: 0.25 | S38: 0.25 | T38: 0.25 | U38: 0.25 | V38: 0.25 | W38: 0.25 | X38: 0.25 | Y38: 0.25 | Z38: 0.25 | AA38: 0.25 | AB38: 0.25 | AC38: 0.25
A39: EBIT | B39: 63930 | C39: 66288 | D39: =D37*D38 -> 0 | E39: =E37*E38 -> 0 | F39: =F37*F38 -> 0 | G39: =G37*G38 -> 0 | H39: =H37*H38 -> 0 | I39: =I37*I38 -> 0 | J39: =J37*J38 -> 0 | K39: =K37*K38 -> 0 | ... AC39: =AC37*AC38 -> 0
A40: Dep&Amort | B40: =OP!H34 -> 0 | C40: =OP!H35 -> 0 | D40: 11000 | E40: =D40*(1+E36*$H$59) -> 11374 | F40: =E40*(1+F36*$H$59) -> 12454.53 | G40: =F40*(1+G36*$H$59) -> 13637.71 | H40: =G40*(1+H36*$H$59) -> 14933.293 | I40: =H40*(1+I36*$I$59) -> 16351.956 | J40: =I40*(1+J36*$I$59) -> 17905.391 | K40: =J40*(1+K36*$I$59) -> 19337.823 | L40: =K40*(1+L36*$I$59) -> 20498.092 | M40: =L40*(1+M36*$I$59) -> 21522.997 | N40: =M40*(1+N36*$I$59) -> 22383.917 | O40: =N40*(1+O36*$I$59) -> 23167.354 | P40: =O40*(1+P36*$I$59) -> 23978.211 | ... AC40: =AB40*(1+AC36*$I$59) -> 37500.868
A41: EBIDTA | B41: =+B39+B40 -> 63930 | C41: =+C39+C40 -> 66288 | D41: =D39+D40 -> 11000 | E41: =E39+E40 -> 11374 | F41: =F39+F40 -> 12454.53 | G41: =G39+G40 -> 13637.71 | H41: =H39+H40 -> 14933.293 | I41: =I39+I40 -> 16351.956 | J41: =J39+J40 -> 17905.391 | K41: =K39+K40 -> 19337.823 | ... AC41: =AC39+AC40 -> 37500.868
A42: CIF | B42: -1385 | C42: -890 | D42: =(C48)*$H$60 -> -1124.36 | E42: =(D48)*$H$60 -> -1113.1164 | F42: =(E48)*$H$60 -> -1113.1164 | G42: =(F48)*$H$60 -> -1113.1164 | H42: =(G48)*$H$60 -> -1113.1164 | I42: =(H48)*$H$60 -> -1113.1164 | J42: =(I48)*$H$60 -> -1113.1164 | K42: =(J48)*$H$60 -> -1113.1164 | ... AC42: =(AB48)*$H$60 -> -1113.1164
A43: Otros Gastos | B43: =-422-2817 -> -3239 | C43: =87-3634 -> -3547 | D43: =-C43*(1+D36) -> 4788.45 | E43: =D43*(1+E36*0.5) -> 4869.8537 | F43: =E43*(1+F36*0.5) -> 5101.1717 | G43: =F43*(1+G36*0.5) -> 5343.4774 | H43: =G43*(1+H36*0.5) -> 5597.2925 | I43: =H43*(1+I36*0.5) -> 5863.1639 | J43: =I43*(1+J36*0.5) -> 6141.6642 | K43: =J43*(1+K36*0.5) -> 6387.3308 | L43: =K43*(1+L36*0.5) -> 6578.9507 | ... AC43: =AB43*(1+AC36*0.5) -> 8922.7133
A44: Utilidad antes de Impuestos | B44: =B39-B42-B43 -> 68554 | C44: =C39-C42-C43 -> 70725 | D44: =D39-D42-D43 -> -3664.09 | E44: =E39-E42-E43 -> -3756.7373 | F44: =F39-F42-F43 -> -3988.0553 | G44: =G39-G42-G43 -> -4230.361 | H44: =H39-H42-H43 -> -4484.1761 | I44: =I39-I42-I43 -> -4750.0475 | ... AC44: =AC39-AC42-AC43 -> -7809.5969
A45: ISR & PTU | B45: 10481 | C45: 9680 | D45: =$H$61*D44 -> -769.4589 | E45: =$H$61*E44 -> -788.91482 | F45: =$H$61*F44 -> -837.49161 | G45: =$I$61*G44 -> -972.98302 | H45: =$I$61*H44 -> -1031.3605 | I45: =$I$61*I44 -> -1092.5109 | J45: =$I$61*J44 -> -1156.566 | K45: =$I$61*K44 -> -1213.0693 | L45: =$I$61*L44 -> -1257.1419 | M45: =$I$61*M44 -> -1294.9709 | N45: =$I$61*N44 -> -1325.9906 | ... AC45: =$I$61*AC44 -> -1796.2073
A46: Utilidad Neta | B46: =B44-B45 -> 58073 | C46: =C44-C45 -> 61045 | D46: =D44-D45 -> -2894.6311 | E46: =E44-E45 -> -2967.8224 | F46: =F44-F45 -> -3150.5637 | G46: =G44-G45 -> -3257.3779 | H46: =H44-H45 -> -3452.8156 | I46: =I44-I45 -> -3657.5366 | ... AC46: =AC44-AC45 -> -6013.3896
A47: Inversiones y Capex | B47: =OP!I34 -> 0 | C47: =OP!I35 -> 0 | D47: 10000 | E47: =D47*(1+E36*$H$62) -> 10408 | F47: =E47*(1+F36*$H$62) -> 11594.512 | G47: =F47*(1+G36*$H$62) -> 12916.286 | H47: =G47*(1+H36*$H$62) -> 14388.743 | I47: =H47*(1+I36*$H$62) -> 16029.06 | J47: =I47*(1+J36*$H$62) -> 17856.373 | K47: =J47*(1+K36*$H$62) -> 19570.584 | L47: =K47*(1+L36*$H$62) -> 20979.666 | ... AC47: =AB47*(1+AC36*$H$62) -> 43199.777
A48: Deuda + Lease Liabilities | B48: 108047 | C48: 112436 | D48: =C48*0.99 -> 111311.64 | E48: =D48 -> 111311.64 | F48: =E48 -> 111311.64 | G48: =F48 -> 111311.64 | H48: =G48 -> 111311.64 | I48: =H48 -> 111311.64 | J48: =I48 -> 111311.64 | K48: =J48 -> 111311.64 | L48: =K48 -> 111311.64 | ... AC48: =AB48 -> 111311.64
A49: Deuda/EBITDA | B49: =B48/B41 -> 1.6900829 | C49: =C48/C41 -> 1.6961743 | D49: =D48/D41 -> 10.11924 | E49: =E48/E41 -> 9.786499
A50: FNP | B50: =OP!F34 -> 0 | C50: =OP!F35 -> 0 | D50: =D41-D42-D43-D45-D47+D48-C48 -> -3018.9911 | E50: =E41-E42-E43-E45-E47+E48-D48 -> -2001.8224 | F50: =F41-F42-F43-F45-F47+F48-E48 -> -2290.5457 | G50: =G41-G42-G43-G45-G47+G48-F48 -> -2535.954 | H50: =H41-H42-H43-H45-H47+H48-G48 -> -2908.2658 | I50: =I41-I42-I43-I45-I47+I48-H48 -> -3334.6407 | J50: =J41-J42-J43-J45-J47+J48-I48 -> -3822.9629 | K50: =K41-K42-K43-K45-K47+K48-J48 -> -4293.9066 | ... AC50: =AC41-AC42-AC43-AC45-AC47+AC48-AB48 -> -11712.299
A51: F(t) | B51: 0 | C51: 0 | D51: =C51*(1+$B$59)+D50 -> -3018.9911 | E51: =D51*(1+$B$59)+E50 -> -5271.3898 | F51: =E51*(1+$B$59)+F50 -> -7999.4608 | G51: =F51*(1+$B$59)+G50 -> -11199.37 | H51: =G51*(1+$B$59)+H50 -> -15037.184 | I51: =H51*(1+$B$59)+I50 -> -19619.91 | J51: =I51*(1+$B$59)+J50 -> -25071.326 | K51: =J51*(1+$B$59)+K50 -> -31446.153 | ... AC51: =AB51*(1+$B$59)+AC50 -> -400965.71
AB52: =AB51-AB48 -> -470733.07 | AC52: =AC50/(B59-AC36) -> -244006.22
A53: EPS | C53: =1000000*C46/OP!$C$8 -> #DIV/0! | D53: =1000000*D46/OP!$C$8 -> #DIV/0! | E53: =1000000*E46/OP!$C$8 -> #DIV/0! | F53: =1000000*F46/OP!$C$8 -> #DIV/0!
A54: Consenso EPS | C54: 3.3 | D54: 5.6 | E54: 5.6
A55: E$/UN | D55: =$B$61/D46 -> 33.638996 | E55: =$B$61/E46 -> 32.809403 | F55: =$B$61/F46 -> 30.906369
A56: EEV/EBIDA | D56: =($B$61+D48-D51)/D41 -> 1.5416499 | E56: =($B$61+E48-E51)/E41 -> 1.6889878 | F56: =($B$61+F48-F51)/F41 -> 1.7614971
C58: "TELP" | D58: CER | E58: D Analista | H58: CP | I58: LP
A59: Tasa de descuento: | B59: =SUM(C59:E59) -> 0.083 | C59: 0.0307 | D59: 0.0523 | E59: 0 | G59: Factor D&A | H59: 1 | I59: 1
G60: Factor CIF | H60: -0.01
A61: VPN*@i% | B61: =C62+C63 -> -97372.483 | C61: Normal | D61: =D31 -> 0.001 | E61: =D32 -> 0.005 | G61: Factor ISR | H61: 0.21 | I61: 0.23
A62: DCF 25Y | B62: =C62/B61 -> 0.65860808 | C62: =AB52/(1+B59)^25 -> -64130.304 | D62: =SUMPRODUCT(E50:AB50,E31:AB31) -> -49460.323 | E62: =SUMPRODUCT(E50:AB50,E32:AB32) -> -47340.268 | G62: Factor inv | H62: 1.2
A63: Perpetuidad | B63: =1-B62 -> 0.34139192 | C63: =AC52/(1+B59)^25 -> -33242.179 | D63: =(AC50/($B$59+D31-$AC$36))*AC31 -> -31821.013 | E63: =(AC50/($B$59+D32-$AC$36))*AC32 -> -26831.434 | G63: Suma D&A | H63: =SUM(40:40) -> 628429.57
A64: VPN/Acción | B64: =1000000*B61/OP!C8 -> #DIV/0! | D64: =1000000*SUM(D62:D63)/OP!C8 -> #DIV/0! | E64: =1000000*SUM(E62:E63)/OP!C8 -> #DIV/0! | G64: Suma Inv. | H64: =SUM(47:47) -> 672845.39
B65: =B64/OP!C7-1 -> #DIV/0! | D65: =D64/B64-1 -> #DIV/0! | E65: =E64/B64-1 -> #DIV/0! | G65: Inv.+Goodwill | H65: =SUM(47:47)+(OP!E12*OP!E7) -> 672845.39
A67: Duración | B67: =B62*D68+B63*D69 -> 20.902877 | E67: 1 | F67: 2 | G67: 3 | H67: 4 | I67: 5 | J67: 6 | K67: 7 | L67: 8 | M67: 9 | N67: 10 | O67: 11 | P67: 12 | Q67: 13 | R67: 14 | S67: 15 | T67: 16 | U67: 17 | V67: 18 | W67: 19 | X67: 20 | Y67: 21 | Z67: 22 | AA67: 23 | AB67: 24 | AC67: 25
A68: 0.001 | B68: =-$B$67*A68 -> -0.020902877 | D68: =SUM(E68:AB68)/SUMPRODUCT(E50:AB50,E33:AB33) -> 12.015539 | E68: =E67*E50*E33 -> -1848.4048 | F68: =F67*F50*F33 -> -3905.8183 | G68: =G67*G50*G33 -> -5989.3163 | H68: =H67*H50*H33 -> -8456.2976 | I68: =I67*I50*I33 -> -11191.203 | J68: =J67*J50*J33 -> -14216.104 | K68: =K67*K50*K33 -> -17200.911 | L68: =L67*L50*L33 -> -19827.131 | ... AC68: =AC67*AC50*AC33 -> -39890.615
A69: 0.005 | B69: =-$B$67*A69 -> -0.10451438 | D69: =(1+B59)/B59+AC67 -> 38.048193
