Workbook
Name Sectors: '[1]Sector Impact'!$K$4:$K$16
Name Sectors: 'Sector Impact'!$K$4:$K$16

Sheet OP
B2: 45620 | C2: Team 1 | D2: 45657 | E2: =Inputs!H3 -> UNITED PARCEL SERVICE, INC. (XNYS:UPS) | L2: {=_FV(E2,"Exchange")} -> #VALUE! | M2: SIC:
D3: COMPANY DESCRIPTION | H3: CEO & BOARD OF DIRECTORS
D4: {=_FV(Inputs!H3,"Description")} -> #VALUE! | H4: Name, Age and Tenure | I4: Gender | J4: Executive? | L4: Other roles
H5: Carol Tome, 67, 2003 | I5: F | J5: Y | L5: Director at Verizon Communications
H6: Rodney Adkins, 65, 2013 | I6: M | J6: Y | L6: President of RRAM Group LLC
H7: Eva Boratto, 57, 2020 | I7: F | J7: N | L7: CFO Bath Body Works, Inc.
H8: Michael Burns, 72, 2005 | I8: M | J8: N | L8: -
H9: Wayne Hewett, 59, 2020 | I9: M | J9: N | L9: Senior Advisor to Permira
H10: Angela Hwang, 58, 2020 | I10: F | J10: N | L10: Advisor at Pfizer
H11: Kate Johnson, 56, 2020 | I11: F | J11: N | L11: President, CFO at Lumen Technologies Inc.
H12: William Johnson, 75, 2009 | I12: M | J12: Y | L12: Director at Sovos
H13: Franck Moison, 70, 2017 | I13: M | J13: N | L13: Chairman of Advisory Board of EDHEC BS
H14: Christiana Shi, 64, 2018 | I14: F | J14: N | L14: Director at Hanes Brand and SES France
H15: Russel Stokes, 52, 2020 | I15: M | J15: N | L15: CFO at GE AeroSpace
H16: Kevin Warsh, 53, 2012 | I16: M | J16: N | L16: Lecturer at Stanford Graduate School of Business
B17: {=_FV(E2,"Currency")&" MILLIONS"} -> #VALUE!
B18: COMPANY OVERVIEW
B19: Stock | D19: Liquidity and Solvency | F19: Segments | I19: ="Profitability ("&J20&")" -> Profitability (2023) | L19: Multiples
B20: Last Price | C20: {=_FV(E2,"Price")} -> #VALUE! | D20: Total Assets | E20: =_xlfn.XLOOKUP(D20,'Fin. Data'!A:A,'Fin. Data'!B:B,,0) -> 70857 | F20: Regions | H20: % Sales | I20: Reporting Year | J20: 2023 | L20: Float | M20: =IF(Inputs!B82 <> "",Inputs!B82,"") -> 0.99896
B21: Outstanding Shares | C21: {=_FV(E2,"Shares outstanding",TRUE)} -> #VALUE! | D21: Total Liabilities | E21: =_xlfn.XLOOKUP(D21,'Fin. Data'!A:A,'Fin. Data'!B:B,,0) -> 53543 | F21: =Segments!C5 -> U.S. | H21: =Segments!B5 -> 0.78881462 | I21: End of Year | J21: 45291 | L21: Insiders Own | M21: =IF(Inputs!B83 <> "",Inputs!B83,"") -> 0.0001
B22: Market Cap. | C22: =C20*C21/1000000 -> #VALUE! | D22: Cash/Share | E22: =_xlfn.XLOOKUP("Cash & Eq.",'Fin. Data'!A:A,'Fin. Data'!B:B,,0)*1000000/C21 -> #VALUE! | I22: EBITDA | K22: =_xlfn.XLOOKUP(I22,'Fin. Data'!A:A,'Fin. Data'!B:B,,0) -> 12507 | L22: b (Yahoo) | M22: {=IF(_FV(E2,"Beta") <> "",_FV(E2,"Beta"),"")} -> #VALUE!
B23: +Total Debt | C23: ='Fin. Data'!B58 -> 26729 | D23: EBITDA/Net Financial Cost (NFC) | E23: =IFERROR(_xlfn.XLOOKUP("EBITDA",'Fin. Data'!A:A,'Fin. Data'!B:B,,0)/_xlfn.XLOOKUP("Net Financial Cost",'Fin. Data'!A:A,'Fin. Data'!B:B,,0),"") -> -22.019366 | I23: Depreciation & Amortization | K23: =_xlfn.XLOOKUP(I23,'Fin. Data'!A:A,'Fin. Data'!B:B,,0) -> 3366 | L23: Score (S&P) | M23: =IF(Inputs!B84 <> "",Inputs!B84,"") -> A
B24: -Cash | C24: ='Fin. Data'!B39 -> 3206 | D24: Debt/EBITDA | E24: =IFERROR(_xlfn.XLOOKUP("Total Debt",'Fin. Data'!A:A,'Fin. Data'!B:B,,0)/_xlfn.XLOOKUP("EBITDA",'Fin. Data'!A:A,'Fin. Data'!B:B,,0),"") -> 2.1371232 | F24: =Segments!C6 -> Non-U.S. | H24: =Segments!B6 -> 0.21118538 | I24: EBIT | K24: =_xlfn.XLOOKUP(I24,'Fin. Data'!A:A,'Fin. Data'!B:B,,0) -> 9141 | L24: Price/Book Value | M24: =IFERROR((C20*C21/(E20-E21))/1000000,"")
B25: =Enterprise Value | C25: =C22+C23-C24 -> #VALUE! | D25: "Others Assets"/Asset | E25: =IFERROR(_xlfn.XLOOKUP("Other Assets",'Fin. Data'!A:A,'Fin. Data'!B:B,,0)/_xlfn.XLOOKUP("Total Assets",'Fin. Data'!A:A,'Fin. Data'!B:B,,0),"") -> 0.19928871 | I25: Net Income | K25: =_xlfn.XLOOKUP(I25,'Fin. Data'!A:A,'Fin. Data'!B:B,,0) -> 6708 | L25: NCF(3y avg)/Asset | M25: =IFERROR(K31/E20,"") -> -0.0092486746
B26: Holdings (nac/int'l) | C26: - | D26: Debt/Assets | E26: =_xlfn.XLOOKUP(D26,'Fin. Data'!A:A,'Fin. Data'!B:B,,0) -> 0.37722455 | F26: Categories | H26: % Sales | I26: EPS | K26: =1000000*K25/C21 -> #VALUE! | L26: Price/Net Inc. (3y avg) | M26: =IFERROR(C22/K30,"")
B27: t liq. (Holdings/Vol.) | C27: - | D27: EBITDA Margin (average) | E27: =IFERROR(AVERAGE(_xlfn.XLOOKUP("EBITDA Margin",'Fin. Data'!A:A,'Fin. Data'!B:D,,0)),"") -> 0.13049776 | F27: =Segments!C14 -> US Domestic Package | H27: =Segments!B14 -> 0.65918336 | I27: ROA | K27: =IFERROR(K25/E20,"") -> 0.094669546 | L27: EV/Asset | M27: =IFERROR(C25/E20,"")
B28: % Short | C28: 1,63% | D28: Operating Margin (average) | E28: =IFERROR(AVERAGE(_xlfn.XLOOKUP("Operating Margin",'Fin. Data'!A:A,'Fin. Data'!B:D,,0)),"") -> 0.12088937 | I28: ROIC | K28: =IFERROR(Peers!C18,"") -> 0.17517705 | L28: EV/Ebitda (3y average) | M28: =IFERROR(C25/K29,"")
B29: Traffic ESG | D29: Net Income Margin (average) | E29: =IFERROR(AVERAGE(_xlfn.XLOOKUP("Net Income Margin",'Fin. Data'!A:A,'Fin. Data'!B:D,,0)),"") -> 0.1071113 | F29: =Segments!C15 -> International Package | H29: =Segments!B15 -> 0.19603553 | I29: EBITDA (3y average) | K29: =AVERAGE(_xlfn.XLOOKUP("EBITDA",'Fin. Data'!A:A,'Fin. Data'!B:D,,0)) -> 12546 | L29: Price/NCF (3y average) | M29: =IFERROR(C22/K31,"")
B30: E | I30: Net Income (3y average) | K30: =AVERAGE(_xlfn.XLOOKUP("Net Income",'Fin. Data'!A:A,'Fin. Data'!B:D,,0)) -> 10382 | L30: Bonds 1,3,5a (USD) | M30: -
B31: S | D31: Net Financial Cost/Avg Net Debt | E31: =IFERROR(-_xlfn.XLOOKUP("Net Financial Cost",'Fin. Data'!A:A,'Fin. Data'!B:B,,0)/AVERAGE(_xlfn.XLOOKUP("Net Debt",'Fin. Data'!A:A,'Fin. Data'!B:D,,0)),"") -> 0.030098031 | F31: =Segments!C16 -> Supply Chain Solutions | H31: =Segments!B16 -> 0.14478111 | I31: NCF (3y average) | K31: =AVERAGE(_xlfn.XLOOKUP("Net Financial Cost",'Fin. Data'!A:A,'Fin. Data'!B:D,,0)) -> -655.33333 | L31: Div+Rep.(3y avg)/Price | M31: =-IFERROR(SUM(E52:E54)/(3*C22),"") -> #VALUE!
B32: G | L32: Div. Yield | M32: =-IFERROR(L53/C22,"") -> #VALUE!
B33: INVESTMENT THESIS
B34: Pillars of Recommendation | H34: Recommendation | I34: Valuation Assumptions
B35: Pillar | C35: Explanation | H35: BUY | I35: Check DCF
B36: Innovation | C36: Sofisticated systems optmizitation helps margins and revenue, and UPS is implementing this, in the robotization of its network.
B37: Global Presence | C37: UPS is an industry leader and has a strong reputation
B38: Ambitious Goals | C38: The revenue forecast is positive and the company is not stagnating in known markets. They are expanding into the healthcare market, for example, where they are striving to become leaders.
B39: Risks of Investment | H39: Price Target | I39: Valuation
B40: Risk | C40: Explanation | H40: =IFERROR(DCF!D75,"") | I40: Discount Rate | J40: =DCF!F50 -> 0.085 | L40: Upside | M40: =IFERROR(DCF!D74,"")
B41: Macroec. Outlook | C41: UPS revenue is extremely dependant on global consumer general consumption, which is something very volatile given differents phases of the economic cicle.
...

Sheet Segments
B2: ="Regions "&"("&OP!$J$20&")" -> Regions (2023) | Q2: Products
D3: Nominal value | K3: YoY Growth
B4: Weight | C4: Region | D4: =OP!J20 -> 2023 | E4: =D4-1 -> 2022 | F4: =E4-1 -> 2021 | G4: =F4-1 -> 2020 | H4: =G4-1 -> 2019 | I4: =H4-1 -> 2018 | K4: =OP!J20 -> 2023 | L4: =K4-1 -> 2022 | M4: =L4-1 -> 2021 | N4: =M4-1 -> 2020 | O4: =N4-1 -> 2019 | P4: =O4-1 -> 2018
B5: =IFERROR(D5/$D$9,"") -> 0.78881462 | C5: U.S. | D5: 71749 | E5: 78110 | F5: 74376 | G5: 66580 | H5: 58699 | I5: 56115 | K5: =(D5-E5)/E5 -> -0.081436436 | L5: =(E5-F5)/F5 -> 0.050204367 | M5: =(F5-G5)/G5 -> 0.11709222 | N5: =(G5-H5)/H5 -> 0.13426123 | O5: =(H5-I5)/I5 -> 0.046048294 | P5: -
B6: =IFERROR(D6/$D$9,"") -> 0.21118538 | C6: Non-U.S. | D6: 19209 | E6: 22228 | F6: 22911 | G6: 18048 | H6: 15395 | I6: 15746 | K6: =(D6-E6)/E6 -> -0.13581969 | L6: =(E6-F6)/F6 -> -0.029811008 | M6: =(F6-G6)/G6 -> 0.26944814 | N6: =(G6-H6)/H6 -> 0.17232868 | O6: =(H6-I6)/I6 -> -0.022291376 | P6: -
B7: =IFERROR(D7/$D$9,"") -> 0
B8: =IFERROR(D8/$D$9,"") -> 0
B9: =SUM(B5:B8) -> 1 | C9: TOTAL | D9: =SUM(D5:D8) -> 90958 | E9: =SUM(E5:E8) -> 100338 | F9: =SUM(F5:F8) -> 97287 | G9: =SUM(G5:G8) -> 84628 | H9: =SUM(H5:H8) -> 74094 | I9: =SUM(I5:I8) -> 71861 | K9: =(D9-E9)/E9 -> -0.093484024 | L9: =(E9-F9)/F9 -> 0.031360819 | M9: =(F9-G9)/G9 -> 0.14958406 | N9: =(G9-H9)/H9 -> 0.14217076 | O9: =(H9-I9)/I9 -> 0.031073879 | P9: -
B11: ="Categories "&"("&OP!$J$20&")" -> Categories (2023)
D12: Nominal value | K12: YoY Growth
B13: Weight | C13: Category | D13: =OP!J20 -> 2023 | E13: =D13-1 -> 2022 | F13: =E13-1 -> 2021 | G13: =F13-1 -> 2020 | H13: =G13-1 -> 2019 | I13: =H13-1 -> 2018 | K13: =OP!J20 -> 2023 | L13: =K13-1 -> 2022 | M13: =L13-1 -> 2021 | N13: =M13-1 -> 2020 | O13: =N13-1 -> 2019 | P13: =O13-1 -> 2018
B14: =IFERROR(D14/$D$17,"") -> 0.65918336 | C14: US Domestic Package | D14: 59958 | E14: 64209 | F14: 60137 | G14: 53499 | H14: 46493 | I14: 43593 | K14: =(D14-E14)/E14 -> -0.066205672 | L14: =(E14-F14)/F14 -> 0.067712057 | M14: =(F14-G14)/G14 -> 0.12407709 | N14: =(G14-H14)/H14 -> 0.15068935 | O14: =(H14-I14)/I14 -> 0.066524442 | P14: -
B15: =IFERROR(D15/$D$17,"") -> 0.19603553 | C15: International Package | D15: 17831 | E15: 19698 | F15: 19541 | G15: 15945 | H15: 14220 | I15: 14442 | K15: =(D15-E15)/E15 -> -0.094781196 | L15: =(E15-F15)/F15 -> 0.0080343892 | M15: =(F15-G15)/G15 -> 0.22552524 | N15: =(G15-H15)/H15 -> 0.12130802 | O15: =(H15-I15)/I15 -> -0.015371832 | P15: -
B16: =IFERROR(D16/$D$17,"") -> 0.14478111 | C16: Supply Chain Solutions | D16: 13169 | E16: 16431 | F16: 17429 | G16: 15184 | H16: 13381 | I16: 13826 | K16: =(D16-E16)/E16 -> -0.19852717 | L16: =(E16-F16)/F16 -> -0.057260887 | M16: =(F16-G16)/G16 -> 0.147853 | N16: =(G16-H16)/H16 -> 0.13474329 | O16: =(H16-I16)/I16 -> -0.032185737 | P16: -
B17: =SUM(B14:B16) -> 1 | C17: TOTAL | D17: =SUM(D14:D16) -> 90958 | E17: =SUM(E14:E16) -> 100338 | F17: =SUM(F14:F16) -> 97107 | G17: =SUM(G14:G16) -> 84628 | H17: =SUM(H14:H16) -> 74094 | I17: =SUM(I14:I16) -> 71861 | K17: =(D17-E17)/E17 -> -0.093484024 | L17: =(E17-F17)/F17 -> 0.033272576 | M17: =(F17-G17)/G17 -> 0.14745711 | N17: =(G17-H17)/H17 -> 0.14217076 | O17: =(H17-I17)/I17 -> 0.031073879 | P17: -
B19: Categories | D19: Description | I19: Graphs
B20: =C14 -> US Domestic Package | D20: U.S. Domestic Package operations include the time-definite delivery of letters, documents and packages throughout the United States. It includes a variety of services that cater to different shipping speeds, delivery times, and customer preferences.
B21: =C15 -> International Package | D21: International Package operations include delivery to more than 200 countries and territories worldwide, including shipments wholly outside the United States, as well as shipments with either origin or destination outside the United States. Our International Package reporting segment includes our operations in Europe, the Indian sub-continent, Middle East and Africa (together "EMEA"), Canada and Latin America (together "Americas") and Asia.
B22: =C16 -> Supply Chain Solutions | D22: Supply Chain Solutions includes Forwarding, Logistics, digital and other businesses. The Forwarding and Logistics businesses provide services in more than 200 countries and territories worldwide and include international air and ocean freight forwarding, truckload brokerage, customs brokerage, mail services, healthcare logistics, distribution and post-sales services. The digital businesses leverage technology to enable a range of on-demand services such as same-day delivery, end-to-end return services and integrated supply chain and high-value shipment insurance solutions.
B24: Industry | J24: Graphs (Industry Forecasts)
B25: Drivers | D25: Description
B26: E-commerce Growth | D26: The growth of e-commerce increases demand for fast deliveries and logistical efficiency, prompting the industry to adapt to meet customer expectations.
B27: Technological Advances | D27: Technological Advances sush as automation and robotics, AI and machine learning are crucial for this industry and enable cost reduction, higher efficiency and improved customer satisfaction.
B28: Supply Chain Trends | D28: Supply chain complexity increases the need for logistics providers that can manage global networks, promoting integrated logistics services and end-to-end solutions from manufacturing to last-mile delivery.
B29: Sales forecast
B30: Source | D30: Market Growth CAGR | G30: Period
B31: Statista | D31: 0.0839 | G31: 2023 - 2028
B32: Grand View Reseacrh | D32: 0.072 | G32: 2023 - 2030
B33: Precedence Research | D33: 0.0935 | G33: 2024 - 2033
B34: Average | D34: =AVERAGE(D31:F33) -> 0.083133333
B35: Company's Strategy / Extra Notes
B38: UPS reports that its strategy is rooted in the guiding principles - Customer First, People Led, Innovation Driven. This approach reflects the company’s commitment to enhancing customer experience while also emphasizing the importance of its workforce and the role of technological advancements in driving efficiency. In that sense, Costumer First focuses on meeting customers’ expectations and needs. UPS aims to provide customers with improved service delivery, by enhancing service seep and reliability, offering proactive customer support channels. The company also intends to grow its healthcare logistics, aspiring to become the leading provider of complex healthcare logistics in the world. Additionally, it aims to support small & medium business (SMBs), providing customized shipping solutions and strengthening customer relationships and loyalty. This is particularly important to UPS response to the post-pandemic slowdown in e-commerce while preparing for future challenges in the logistics market. Equally important to UPS’ strategy, People Led emphasizes its focus on its employees. The company believes that, by fostering a culture that prioritizes employee satisfaction and attracting and retaining talent, it can provide industry-leading services to their customers. Lastly, Innovation Driven summarizes the company’s focus and investments in automation, AI and machine learning, enabling them to optimize load planning, scheduling and volume flows. Such advancements are crucial to streamlining operations and improving cost efficiency, adapting to market changes and enhancing service delivery.

Sheet Acuerdo
A1: Invertir
A2: NO invertir
A3: Mantener sin elevar posición
A4: Mantener (y seguir comprando)
A5: Liquidar
A6: PENDIENTE

Sheet Peers
B1: Peer Logo | C1: Peer Name | D1: Description
C2: #VALUE! | D2: FedEx Corporation provides transportation, e-commerce, and business services in the United States and internationally. It operates through FedEx Express, FedEx Ground, FedEx Freight, and FedEx Services segments. The FedEx Express segment offers express transportation, small-package ground delivery, and freight transportation services; and time-critical transportation services. The FedEx Ground segment provides small-package ground delivery services. The FedEx Freight segment offers less-than-truckload freight transportation services. The FedEx Services segment provides sales, marketing, information technology, communications, customer service, technical support, billing and collection, and back-office support services. In addition, the company offers supply chain management solutions; and air and ocean freight forwarding and cargo transportation, specialty transportation, customs brokerage, third party logistics and supply chain, and document and business solutions, as well as provides trade management tools and data. The company was founded in 1971 and is headquartered in Memphis, Tennessee.
C3: #VALUE! | D3: Deutsche Post AG operates as a mail and logistics company in Germany, rest of Europe, the Americas, the Asia Pacific, the Middle East, and Africa. The company operates through five segments: Express; Global Forwarding, Freight; Supply Chain; eCommerce; and Post & Parcel Germany. The Express segment offers time-definite express services to business and private customers. The Global Forwarding, Freight segment provides air, ocean, and overland freight forwarding services; and offers multimodal and sector-specific solutions. The Supply Chain segment delivers customized logistics services and supply chain solutions to its customers. The eCommerce segment provides parcel delivery and non-time definite international cross-border services. The Post & Parcel Germany segment transports, sorts, and delivers mail communication, physical and hybrid letters, and goods; and offers additional services, such as registered mail, cash on delivery, and insured items. Deutsche Post AG is headquartered in Bonn, Germany.
C4: #VALUE! | D4: XPO, Inc. provides freight transportation services in the United States, rest of North America, France, the United Kingdom, rest of Europe, and internationally. The company operates in two segments, North American LTL and European Transportation. The North American LTL segment provides customers with less-than-truckload (LTL) services, such as geographic density and day-definite domestic services. This segment also offers cross-border U.S., Mexico, Canada, and the Caribbean, as well as engages in the operation of trailer manufacturing. The European Transportation segment offers dedicated truckload, LTL, truck brokerage, managed transportation, last mile, freight forwarding and multimodal solutions, such as road-rail and road-short sea combinations. It provides its services to customers in various industries, such as industrial and manufacturing, retail and e-commerce, food and beverage, logistics and transportation, and consumer goods. XPO, Inc. was incorporated in 2000 and is based in Greenwich, Connecticut.
C5: #VALUE! | D5: C.H. Robinson Worldwide, Inc provides freight transportation services, and related logistics and supply chain services in the United States and internationally. It operates through two segments: North American Surface Transportation and Global Forwarding. The company provides transportation and logistics services, including truckload and less-than-truckload brokerage, intermodal transportation and non-vessel operating common carrier and freight forwarding. It also offers air shipments, door-to-door services, customs brokerage, and other logistics solutions such as managed services, warehousing, and small parcel services. The company partners with around 45,000 transportation providers, including motor carriers, railroads, and ocean and air carriers. Additionally, under the Robinson Fresh brand, it buys, sells, and markets fresh produce for grocery retailers, restaurants, wholesalers, and foodservice distributors. The company was founded in 1905 and is headquartered in Eden Prairie, Minnesota.
D6: {=_FV(C6,"Description")} -> #VALUE!
B8: In Millions USD | C8: =OP!E2 -> UNITED PARCEL SERVICE, INC. (XNYS:UPS) | D8: =C2 -> #VALUE! | E8: =C3 -> #VALUE! | F8: =C4 -> #VALUE! | G8: =C5 -> #VALUE! | H8: =C6 -> 0 | I8: AVERAGE | J8: Deviation from Average
B9: Company Info | I9: =IFERROR(AVERAGE(C9:H9),"") | L9: TRAFFIC
B10: Market Cap | C10: {=_FV(C8,"Market cap",TRUE)/1000000} -> #VALUE! | D10: 65676 | E10: 43701 | F10: 12772 | G10: 12770 | H10: {=_FV(H8,"Market cap",TRUE)/1000000} -> #VALUE! | I10: =IFERROR(AVERAGE(C10:G10),"") | J10: =SQRT((C10-I10)^2) -> #VALUE! | M10: Best Value
B11: Net Sales (current) | C11: =C56 -> 90958 | D11: =D56 -> 87693 | E11: =E56 -> 90391.645 | F11: =F56 -> 7744 | G11: =G56 -> 17596 | H11: =H56 -> 0 | I11: =IFERROR(AVERAGE(C11:G11),"") -> 58876.529 | J11: =SQRT((C11-I11)^2) -> 32081.471
B12: Profitability | M12: Important Value
B13: Sales Growth (ttm) | C13: =C56/C55-1 -> -0.093484024 | D13: =D56/D55-1 -> -0.027308524 | E13: =E56/E55-1 -> -0.10711419 | F13: =F56/F55-1 -> 0.0033687484 | G13: =G56/G55-1 -> -0.2875248 | H13: =H56/H55-1 -> #DIV/0! | I13: =IFERROR(AVERAGE(C13:G13),"") -> -0.10241256 | J13: =SQRT((C13-I13)^2) -> 0.0089285345
B14: Sales Growth (36m) | C14: =C56/C54-1 -> 0.074797939 | D14: =D56/D54-1 -> 0.044474089 | E14: =E56/E54-1 -> 0.10909632 | F14: =F56/F54-1 -> 0.25551232 | G14: =G56/G54-1 -> 0.085703708 | H14: =H56/H54-1 -> #DIV/0! | I14: =IFERROR(AVERAGE(C14:G14),"") -> 0.11391688 | J14: =SQRT((C14-I14)^2) -> 0.039118937 | M14: Worst Value
B15: Operating Margin | C15: =C59/C56 -> 0.10049693 | D15: =D59/D56 -> 0.063391605 | E15: =E59/E56 -> 0.06803004 | F15: =F59/F56 -> 0.070118802 | G15: =G59/G56 -> 0.029268015 | H15: =H59/H56 -> #DIV/0! | I15: =IFERROR(AVERAGE(C15:G15),"") -> 0.066261079 | J15: =SQRT((C15-I15)^2) -> 0.034235854
B16: Net Income Margin | C16: =C62/C56 -> 0.073748323 | D16: =D62/D56 -> 0.049388207 | E16: =E62/E56 -> 0.048129847 | F16: =F62/F56 -> 0.024405992 | G16: =G62/G56 -> 0.053478063 | H16: =H62/H56 -> #DIV/0! | I16: =IFERROR(AVERAGE(C16:G16),"") -> 0.049830086 | J16: =SQRT((C16-I16)^2) -> 0.023918237
B17: Return on Equity (RoE) | C17: =C62/C74 -> 0.38759444 | D17: =D62/D74 -> 0.1570227 | E17: =E62/E74 -> 0.17190913 | F17: =F62/F74 -> 0.1492891 | G17: =G62/G74 -> 0.66314306 | H17: =H62/H74 -> #DIV/0! | I17: =IFERROR(AVERAGE(C17:G17),"") -> 0.30579168 | J17: =SQRT((C17-I17)^2) -> 0.081802752
B18: Return on Invested Capital (ROIC) | C18: =(1+C61/(C59+C60))*C59/(C73+C74-C65) -> 0.17517705 | D18: =(1+D61/(D59+D60))*D59/(D73+D74-D65) -> 0.067094071 | E18: =(1+E61/(E59+E60))*E59/(E73+E74-E65) -> 0.093277211 | F18: =(1+F61/(F59+F60))*F59/(F73+F74-F65) -> 0.089497886 | G18: =(1+G61/(G59+G60))*G59/(G73+G74-G65) -> 0.071621305 | H18: =(1+H61/(H59+H60))*H59/(H73+H74-H65) -> #DIV/0! | I18: =IFERROR(AVERAGE(C18:G18),"") -> 0.099333505 | J18: =SQRT((C18-I18)^2) -> 0.075843549
B19: Solvency
B20: Debt/Assets | C20: =C73/C70 -> 0.37722455 | D20: =D73/D70 -> 0.43351684 | E20: =E73/E70 -> 0.31174604 | F20: =F73/F70 -> 0.54898558 | G20: =G73/G70 -> 0.3737799 | H20: =H73/H70 -> #DIV/0! | I20: =IFERROR(AVERAGE(C20:G20),"") -> 0.40905058 | J20: =SQRT((C20-I20)^2) -> 0.031826034
B21: Net Debt/EBITDA | C21: =(C73-C65)/C58 -> 1.8807868 | D21: =(D73-D65)/D58 -> 2.8724696 | E21: =(E73-E65)/E58 -> 1.5848708 | F21: =(F73-F65)/F58 -> 4.3034884 | G21: =(G73-G65)/G58 -> 2.9446254 | H21: =(H73-H65)/H58 -> #DIV/0! | I21: =IFERROR(AVERAGE(C21:G21),"") -> 2.7172482 | J21: =SQRT((C21-I21)^2) -> 0.83646145
B22: Interest Coverage Ratio | C22: =-C58/C60 -> 22.019366 | D22: =-D58/D60 -> 28.981333 | E22: =-E58/E60 -> 14.609164 | F22: =-F58/F60 -> 5.1190476 | G22: =-G58/G60 -> 5.847619 | H22: =-H58/H60 -> #DIV/0! | I22: =IFERROR(AVERAGE(C22:G22),"") -> 15.315306 | J22: =SQRT((C22-I22)^2) -> 6.7040601
B23: Liquidity
B24: Current Ratio | C24: =C68/C72 -> 1.0982688 | D24: =D68/D72 -> 1.3633096 | E24: =E68/E72 -> 0.9454286 | F24: =F68/F72 -> 1.0018868 | G24: =G68/G72 -> 1.4035088 | H24: =H68/H72 -> #DIV/0! | I24: =IFERROR(AVERAGE(C24:G24),"") -> 1.1624805 | J24: =SQRT((C24-I24)^2) -> 0.064211686
B25: Quick Ratio | C25: =(C65+C66)/C72 -> 0.82303689 | D25: =(D65+D66)/D72 -> 1.2420816 | E25: =(E65+E66)/E72 -> 0.69806121 | F25: =(F65+F66)/F72 -> 0.87106918 | G25: =(G65+G66)/G72 -> 1.2314815 | H25: =(H65+H66)/H72 -> #DIV/0! | I25: =IFERROR(AVERAGE(C25:G25),"") -> 0.97314608 | J25: =SQRT((C25-I25)^2) -> 0.15010919
B26: Activity
B27: Inventory Turnover | C27: =C57/C67 -> 87.504813 | D27: =D57/D67 -> 111.95603 | E27: =E57/E67 -> 63.660697 | F27: N/A | G27: N/A | H27: =H57/H67 -> #DIV/0! | I27: =IFERROR(AVERAGE(C27:G27),"") -> 87.707179 | J27: =SQRT((C27-I27)^2) -> 0.20236595
B28: Acc. Receivable Turnover | C28: =C56/C66 -> 8.0195733 | D28: =D56/D66 -> 8.6936651 | E28: =E56/E66 -> 7.7591345 | F28: =F56/F66 -> 7.95889 | G28: =G56/G66 -> 7.3870697 | H28: =H56/H66 -> #DIV/0! | I28: =IFERROR(AVERAGE(C28:G28),"") -> 7.9636665 | J28: =SQRT((C28-I28)^2) -> 0.055906752
A29: Price/Sales | B29: Payables Turnover | C29: =C57/C71 -> 12.90489 | D29: =D57/D71 -> 21.55566 | E29: =E57/E71 -> 7.9660337 | F29: =F57/F71 -> 13.109023 | G29: =G57/G71 -> 13.099693 | H29: =H57/H71 -> #DIV/0! | I29: =IFERROR(AVERAGE(C29:G29),"") -> 13.72706 | J29: =SQRT((C29-I29)^2) -> 0.82217025
B30: Fixed Asset Turnover | C30: =C56/C69 -> 2.461984 | D30: =D56/D69 -> 3.2111392 | E30: =E56/E69 -> 1.717569 | F30: =F56/F69 -> 1.3127649 | G30: =G56/G69 -> 7.5036247 | H30: =H56/H69 -> #DIV/0! | I30: =IFERROR(AVERAGE(C30:G30),"") -> 3.2414164 | J30: =SQRT((C30-I30)^2) -> 0.77943233
B31: Total Asset Turnover | C31: =C56/C70 -> 1.283684 | D31: =D56/D70 -> 1.0078844 | E31: =E56/E70 -> 1.2236657 | F31: =F56/F70 -> 1.0336359 | G31: =G56/G70 -> 3.3676555 | H31: =H56/H70 -> #DIV/0! | I31: =IFERROR(AVERAGE(C31:G31),"") -> 1.5833051 | J31: =SQRT((C31-I31)^2) -> 0.29962107
B32: Valuation
B33: Price/Earnings | C33: =C10/C62 -> #VALUE! | D33: =D10/D62 -> 15.164165 | E33: =E10/E62 -> 10.044969 | F33: =F10/F62 -> 67.57672 | G33: =G10/G62 -> 13.57067 | H33: =H10/H62 -> #VALUE! | I33: =IFERROR(AVERAGE(C33:G33),"") | J33: =SQRT((C33-I33)^2) -> #VALUE!
B34: Price/Sales | C34: =C10/C56 -> #VALUE! | D34: =D10/D56 -> 0.74893093 | E34: =E10/E56 -> 0.48346283 | F34: =F10/F56 -> 1.6492769 | G34: =G10/G56 -> 0.72573312 | H34: =H10/H56 -> #VALUE! | I34: =IFERROR(AVERAGE(C34:G34),"") | J34: =SQRT((C34-I34)^2) -> #VALUE!
B35: Price/Book | C35: =C10/C74 -> #VALUE! | D35: =D10/D74 -> 2.3811181 | E35: =E10/E74 -> 1.7268219 | F35: =F10/F74 -> 10.088468 | G35: =G10/G74 -> 8.9992953 | H35: =H10/H74 -> #VALUE! | I35: =IFERROR(AVERAGE(C35:G35),"") | J35: =SQRT((C35-I35)^2) -> #VALUE!
B36: EV/Sales | C36: =(C73+C10-C65)/C56 -> #VALUE! | D36: =(D73+D10-D65)/D56 -> 1.1049229 | E36: =(E73+E10-E65)/E56 -> 0.69359517 | F36: =(F73+F10-F65)/F56 -> 2.1271952 | G36: =(G73+G10-G65)/G56 -> 0.82848375 | H36: =(H73+H10-H65)/H56 -> #VALUE! | I36: =IFERROR(AVERAGE(C36:G36),"") | J36: =SQRT((C36-I36)^2) -> #VALUE!
B37: EV/EBITDA | C37: =(C73+C10-C65)/C58 -> #VALUE! | D37: =(D73+D10-D65)/D58 -> 8.9155318 | E37: =(E73+E10-E65)/E58 -> 5.2312688 | F37: =(F73+F10-F65)/F58 -> 19.154651 | G37: =(G73+G10-G65)/G58 -> 23.742671 | H37: =(H73+H10-H65)/H58 -> #VALUE! | I37: =IFERROR(AVERAGE(C37:G37),"") | J37: =SQRT((C37-I37)^2) -> #VALUE!
B38: Stock Info
B39: Float | C39: =OP!M20 -> 0.99896 | D39: 0.917 | E39: 0.804 | F39: 0.8926 | G39: 0.997 | I39: =IFERROR(AVERAGE(C39:G39),"") -> 0.921912 | J39: =SQRT((C39-I39)^2) -> 0.077048
B40: b (Yahoo) | C40: =OP!M22 -> #VALUE! | D40: 1.18 | E40: 1.07 | F40: 1.96 | G40: 0.83 | I40: =IFERROR(AVERAGE(C40:G40),"") | J40: =SQRT((C40-I40)^2) -> #VALUE!
B41: Dividend Yield (yahoo finance) | C41: =OP!M32 -> #VALUE! | D41: 0.0225 | E41: 0.0486 | F41: 0 | G41: 0.0206 | I41: =IFERROR(AVERAGE(C41:G41),"") | J41: =SQRT((C41-I41)^2) -> #VALUE!
...

Sheet ESG
B1: Company GICS Sector: | S1: Yes
B2: Industrials | C2: <- Select Industry | S2: No
B3: ESG Analysis | K3: Relative ESG Analysis
B4: Parameters | C4: Impact | D4: Do they report? | E4: Ranking | F4: Mitigation Plan | G4: Traffic Lights | H4: Improvement over time? | I4: Targets / Goals? | J4: Comments | K4: Parameters | L4: =Peers!C8 -> UNITED PARCEL SERVICE, INC. (XNYS:UPS) | M4: =Peers!D8 -> #VALUE! | N4: =Peers!E8 -> #VALUE! | O4: =Peers!F8 -> #VALUE! | P4: =Peers!G8 -> #VALUE! | Q4: AVERAGE | S4: 2018 | T4: 2019 | U4: 2020 | V4: 2021 | W4: 2022 | X4: 2023
B5: Environmental | K5: Ratios | S5: 13851000 | T5: 14223000 | U5: 15088000 | V5: 15668000 | W5: 15845000 | X5: 14499000
A6: 1 | B6: CO2 Direct Emissions | C6: =VLOOKUP($B$2,'Sector Impact'!$K$4:$AA$16,A6+1,FALSE) -> Very High | D6: Yes | E6: "Villain" | F6: Yes | H6: 8.5% reduction in scope 1 emissions in 2023 compared to 2022. | I6: "40% alternative fuel in ground operations" by 2025 (current 28.8%); "50% reduction in CO₂e per global small package (2020 baseline)" by 2035; Reach carbon neutrality by 2050. | J6: Ranked 127 of 130 companies in Refinitiv. | K6: CO2 Emissions/$M Sales | L6: =L12/L$11 -> 159.40324 | M6: =M12/M$11 -> 178.5241 | N6: =N12/N$11 -> 81.421024 | O6: N/A | P6: =P12/P$11 -> 426.68788 | Q6: =IFERROR(AVERAGE(L6:P6),"") -> 211.50906
A7: 2 | B7: Total Water Consumption | C7: =VLOOKUP($B$2,'Sector Impact'!$K$4:$AA$16,A7+1,FALSE) -> Very High | D7: No | K7: Water Consumption/$M Sales | L7: N/A | M7: N/A | N7: N/A | O7: N/A | P7: N/A | Q7: =IFERROR(AVERAGE(L7:P7),"")
A8: 3 | B8: Total Energy Consumption | C8: =VLOOKUP($B$2,'Sector Impact'!$K$4:$AA$16,A8+1,FALSE) -> Very High | D8: Yes | E8: "Villain" | F8: Yes | H8: 7.8% reduction ir direct energy use in 2023 compared with 2022. | I8: 25% renewable electricity powering their facilities by 2025 reaching 100% in 2035 (current is 10.9%). | J8: Ranked 118 of 121 companies in Refinitiv. | K8: Energy Consumption/$M Sales | L8: =L14/L$11 -> 2346.4896 | M8: =M14/M$11 -> 3468.6805 | N8: =N14/N$11 -> 1244.0028 | O8: N/A | P8: =P14/P$11 -> 19.370766 | Q8: =IFERROR(AVERAGE(L8:P8),"") -> 1769.6359
A9: 4 | B9: Waste Management | C9: =VLOOKUP($B$2,'Sector Impact'!$K$4:$AA$16,A9+1,FALSE) -> High | D9: No | F9: No | H9: N/A | I9: N/A | J9: The waste in operations is considered not relevant in the report and is not reported. | K9: Waste Production/$M Sales | L9: N/A | M9: =M15/M$11 -> 6.4448474 | N9: =N14/N$11 -> 1244.0028 | O9: N/A | P9: N/A | Q9: =IFERROR(AVERAGE(L9:P9),"") -> 625.22384
A10: 5 | B10: Land Degradation/Deforestation/Biodiversity loss/Animal sufering/… | C10: =VLOOKUP($B$2,'Sector Impact'!$K$4:$AA$16,A10+1,FALSE) -> High | D10: No | F10: No | H10: N/A | I10: N/A | K10: Inputs
B11: Social | K11: Net Sales ($M) | L11: 90958 | M11: 87693 | N11: 101448 | O11: 7744 | P11: 17596
A12: 6 | B12: Employee Turnover % | C12: =VLOOKUP($B$2,'Sector Impact'!$K$4:$AA$16,A12+1,FALSE) -> Low | H12: N/A | I12: N/A | J12: "Global turnover rate = 25%" | K12: CO2 Emissions Total (Tonnes) | L12: 14499000 | M12: 15655314 | N12: 8260000 | O12: ="-" -> - | P12: =7.508 *10^6 -> 7508000
A13: 7 | B13: Salaries & Compensation | C13: =VLOOKUP($B$2,'Sector Impact'!$K$4:$AA$16,A13+1,FALSE) -> Medium | D13: No | E13: Medium | F13: No | H13: N/A | I13: N/A | J13: It's mentioned on the report that UPS offers competitive salaries with "industry-leading pay and benefits". It's also mentioned that UPS provides "for equal remuneration irrespective of gender or any other protected class". 53% think they are paid fairly (indeed.com). | K13: Water Consumption Total (Cubic Meters) | L13: ="-" -> - | M13: ="-" -> - | N13: 1400000 | O13: ="-" -> - | P13: ="-" -> - | R13: 2018 | S13: 2019 | T13: 2020 | U13: 2021 | V13: 2022 | W13: 2023
A14: 8 | B14: Reputation | C14: =VLOOKUP($B$2,'Sector Impact'!$K$4:$AA$16,A14+1,FALSE) -> High | D14: No | E14: Medium High | F14: No | H14: N/A | I14: N/A | J14: N/A | K14: Energy Consumption Total (Gigajoules) | L14: 213432000 | M14: 304179000 | N14: 126201600 | O14: ="-" -> - | P14: 340848 | R14: 198420000 | S14: 203929000 | T14: 216422000 | U14: 225544000 | V14: 229653000 | W14: 213432000
A15: 9 | B15: Discrimination Events | C15: =VLOOKUP($B$2,'Sector Impact'!$K$4:$AA$16,A15+1,FALSE) -> Very High | D15: Yes | E15: Medium High | F15: Yes | H15: N/A | I15: By 2025 UPS aims to have 40% ethnically diverse company management in the U.S. (current is 39%), 30% women in full-time management globally (current is 27%) and 1M volunteer hours dedicated to underserved Black communities (current is 983k) | J15: "UPS does not discriminate against any applicant for employment or any employee in any aspect of their employment at UPS because of age, race, religion, sex, disability, sexual orientation, gender identity" | K15: Waste Production Total (Tonnes) | L15: ="-" -> - | M15: 565168 | N15: ="-" -> - | O15: ="-" -> - | P15: ="-" -> -
A16: 10 | B16: Work Safety | C16: =VLOOKUP($B$2,'Sector Impact'!$K$4:$AA$16,A16+1,FALSE) -> Medium | D16: Yes | E16: Medium High | F16: Yes | H16: "The insights gained from incidents and audits are integrated into our broader global safety strategy, making the approach thorough and continually improving" | I16: N/A | J16: "UPS's health and safety programs are comprehensive and focus on building a culture of health and safety by: • Identifying and assessing risk, and auditing for compliance • Investing in safety training and new safety technology • Promoting well-being for all employees • Offering benefits that promote employee safety in the workplace and beyond" | K16: ESG Scores
A17: 11 | B17: Damage to consumer health | C17: =VLOOKUP($B$2,'Sector Impact'!$K$4:$AA$16,A17+1,FALSE) -> Very High | D17: No | E17: Medium | F17: No | H17: N/A | I17: N/A | J17: N/A | K17: Refinitiv | L17: 57 (48/63/71) | M17: 70 (74/65/71) | N17: 73 (73/71/76) | O17: 72 (51/80/88) | P17: 41(41/57/21)
A18: 12 | B18: PXP? | C18: =VLOOKUP($B$2,'Sector Impact'!$K$4:$AA$16,A18+1,FALSE) -> Medium | D18: Yes | E18: Medium High | F18: No | H18: N/A | I18: N/A | J18: "UPS offers comprehensive retirement plans, including pension plans for full-time employees and 401(k) plans with company contributions for part-time employees. The company remains committed to providing sustainable and competitive pension options for its workforce"​ | K18: Sustainalytics | L18: 18.8 (low risk) | M18: 19.0 (low risk) | N18: 13.1 (low risk) | O18: 24.0 (medium risk) | P18: 17.5 (low risk)
A19: 13 | B19: Supply chain | C19: =VLOOKUP($B$2,'Sector Impact'!$K$4:$AA$16,A19+1,FALSE) -> Very High | D19: Yes | E19: Medium High | F19: No | H19: N/A | I19: N/A | J19: "Our supply chain partners tend to be other service providers, rather than raw material or finished goods suppliers. Supply chain partners can be broadly grouped into three categories: Production Suppliers, Capacity Suppliers, and Support Suppliers"​ | K19: ISS | L19: C | M19: D+ | N19: C+ | O19: D+ | P19: D
A20: 14 | B20: Community involvement | C20: =VLOOKUP($B$2,'Sector Impact'!$K$4:$AA$16,A20+1,FALSE) -> Very High | D20: Yes | E20: Medium High | F20: Yes | H20: N/A | I20: N/A | J20: "232M+ lives positively impacted 175M+ vaccines delivered including lifesaving early childhood vaccine 342K volunteer hours recorded for underserved Black communities 50+ disasters and humanitarian crises supported around the world 35% of charitable funding spent in underserved and marginalized communities 1.9M volunteer hours recorded $60M provided in charitable contributions 12K+ small business owners trained through UPS’s Women Exporters Program 6M trees planted by UPSers" | K20: CDP | L20: B- | M20: C | N20: B | O20: F | P20: B
A21: 15 | B21: Public Sector | C21: =VLOOKUP($B$2,'Sector Impact'!$K$4:$AA$16,A21+1,FALSE) -> Very High | D21: No | E21: "Villain" | F21: No | H21: N/A | I21: N/A | J21: "Donated to federal lawmakers who opposed voting rights legislation during the 2022 election cycle Donated to federal lawmakers who objected to certifying the 2020 presidential election Donated to federal lawmakers who opposed creating a Congressional January 6th investigation Donated to state officials who voted for anti-voter legislation during the 2022 election cycle Donated to state officials who supported 2020 election audits Key company staff made large donations to anti-democracy federal legislators during the 2022 election cycle Is a member of the U.S. Chamber of Commerce, which opposed recent federal voting legislation" (American Democracy Scorecard)
A22: 16 | B22: Litigation | C22: =VLOOKUP($B$2,'Sector Impact'!$K$4:$AA$16,A22+1,FALSE) -> High | D22: No | E22: Medium | F22: No | H22: N/A | I22: N/A | J22: Found several litigation cases involving racial discrimination, hazardous residues and work safety violations. All of the cases are recent, the racial discrimination case occured this month.
B23: Corporate Governance | K23: PARAMETERS
A24: 17 | B24: Diversity (Gender, Age, Industry, Region) | E24: Medium | F24: No | H24: N/A | I24: N/A | J24: 42% of the directors are Female and 33% are Ethnically diverse. They have different bacgrounds in diverse areas of business. | K24: IMPACT | L24: RANKING | M24: MITIGATION PLAN | O24: TRAFFIC
A25: 18 | B25: % Independence | E25: Medium High | F25: No | H25: N/A | I25: N/A | J25: 92% of the directors are independent. | K25: Low | L25: "Best in class" | M25: Is there evidence of a plan/program ?
A26: 19 | B26: average time as independent directors | E26: Medium High | F26: No | H26: N/A | I26: N/A | J26: The average tenuere as a director is 8,9 years. | K26: Medium | L26: Medium High
A27: 20 | B27: Recent departures of directors / C-level executives? | E27: "Best in class" | F27: No | H27: N/A | I27: N/A | J27: There were 5 directors that retired since 2020. | K27: High | L27: Medium
A28: 21 | B28: CEO/Chairman duality | E28: "Best in class" | F28: No | H28: N/A | I28: N/A | J28: The roles of Chairman and CEO were separated in 2020. Carol Tomé is the CEO and Bill Johnson serves as the chairman. | K28: Very high | L28: "Villain"
A29: 22 | B29: Transparency (ESG, segments, acquisitions, other) | E29: Medium High | F29: No | H29: N/A | I29: N/A | J29: One of the things that makes me not giving "Best in class" in this category is that the waste is considered not relevant but there is litigations involving hazardous residues.
A30: 23 | B30: Time taken to report after the end of the quarter / year | E30: Medium | F30: No | H30: N/A | I30: N/A | J30: The proxy report was issued in March 18, 2024 and the ESG report was issued in March 20, 2024.
A31: 24 | B31: Additional participation of the CEO in other boards or excessive participation of Ch. | E31: Medium | F31: No | H31: N/A | I31: N/A | J31: The ceo participates in another board.
A32: 25 | B32: Audit / Consulting | D32: Yes | E32: Medium High | F32: No | H32: N/A | I32: N/A | J32: Deloitte & Touche LLP audited the ESG Report.
A33: 26 | B33: ESG-compensation related | D33: Yes | E33: Medium | F33: No | H33: N/A | I33: N/A | J33: N/A
A34: 27 | B34: Management compensation schemes | D34: Yes | E34: Medium High | F34: No | H34: N/A | I34: N/A | J34: N/A

Sheet DCF
A1: VALUATION MODEL
G3: Short Term | K3: Long Term
A4: Section | B4: Line # | C4: ITEM | D4: 2021 (Real) | E4: 2022 (Real) | F4: 2023 (Real) | G4: 2024 | H4: =G4+1 -> 2025 | I4: =H4+1 -> 2026 | J4: =I4+1 -> 2027 | K4: =J4+1 -> 2028 | L4: =K4+1 -> 2029 | M4: =L4+1 -> 2030 | N4: =M4+1 -> 2031 | O4: =N4+1 -> 2032 | ... AF4: =AE4+1 -> 2049
A5: INCOME STATEMENT | B5: 1 | C5: Growth | D5: ='Fin. Data'!D6 -> 0.14958406 | E5: =+E6/D6-1 -> 0.031360819 | F5: =+F6/E6-1 -> -0.093484024 | G5: =+G6/F6-1 -> 0.0015611601 | H5: =+H6/G6-1 -> 0.097694841 | I5: =+I6/H6-1 -> 0.1 | J5: =+J6/I6-1 -> 0.05 | K5: =+K6/J6-1 -> 0.05 | L5: =+L6/K6-1 -> 0.05 | ... AF5: =+AF6/AE6-1 -> 0.02
B6: 2 | C6: Revenues/Sales | D6: =Inputs!D6 -> 97287 | E6: =Inputs!C6 -> 100338 | F6: =Inputs!B6 -> 90958 | G6: =Assumptions!E43 -> 91100 | H6: =Assumptions!F43 -> 100000 | I6: =Assumptions!G43 -> 110000 | J6: =Assumptions!H43 -> 115500 | K6: =Assumptions!I43 -> 121275 | L6: =Assumptions!J43 -> 127338.75 | M6: =Assumptions!K43 -> 133705.69 | N6: =Assumptions!L43 -> 140390.97 | ... AF6: =Assumptions!AD43 -> 222087.19
B7: 3 | C7: EBIT/Operating Margin | D7: =D8/D6 -> 0.13167227 | E7: =E8/E6 -> 0.13049891 | F7: =F8/F6 -> 0.10049693 | G7: 0.096 | H7: =Assumptions!F44 -> 0.11 | I7: =Assumptions!G44 -> 0.13 | J7: 0.11 | K7: =Assumptions!I44 -> 0.11 | L7: =Assumptions!J44 -> 0.11 | M7: =Assumptions!K44 -> 0.11 | N7: =Assumptions!L44 -> 0.11 | O7: =Assumptions!M44 -> 0.11 | P7: =Assumptions!N44 -> 0.11 | Q7: =Assumptions!O44 -> 0.11 | R7: =Assumptions!P44 -> 0.11 | ... AF7: =Assumptions!AD44 -> 0.11
B8: 4 | C8: EBIT | D8: ='Fin. Data'!D11 -> 12810 | E8: ='Fin. Data'!C11 -> 13094 | F8: ='Fin. Data'!B11 -> 9141 | G8: =G7*G6 -> 8745.6 | H8: =H7*H6 -> 11000 | I8: =I7*I6 -> 14300 | J8: =J7*J6 -> 12705 | K8: =K7*K6 -> 13340.25 | L8: =L7*L6 -> 14007.263 | M8: =M7*M6 -> 14707.626 | N8: =N7*N6 -> 15443.007 | ... AF8: =AF7*AF6 -> 24429.591
B9: 5a | C9: (Dep) | D9: -3366 | E9: -3188 | F9: -2953 | G9: =$D$53*DCF!F40 -> -3217.734 | H9: =$D$53*DCF!G40 -> -3612.1059 | I9: =$D$53*DCF!H40 -> -4045.0059 | J9: =$D$53*DCF!I40 -> -4521.1959 | K9: =$E$53*DCF!J40 -> -5021.1954 | L9: =$E$53*DCF!K40 -> -5546.1949 | M9: =$E$53*DCF!L40 -> -6097.4443 | N9: =$E$53*DCF!M40 -> -6676.2562 | O9: =$E$53*DCF!N40 -> -7284.0088 | P9: =$E$53*DCF!O40 -> -7913.0326 | Q9: =$E$53*DCF!P40 -> -8564.0723 | R9: =$E$53*DCF!Q40 -> -9237.8984 | ... AF9: =$E$53*DCF!AE40 -> -20813.438 | AG9: =SUM(D9:AF9) -> -293279.68
B10: 5b | C10: (Amort) | D10: =-Assumptions!AB23 -> -294 | E10: =-Assumptions!AA23 -> -292 | F10: =-Assumptions!Z23 -> -500 | G10: =F38*$D$54 -> -312.45 | H10: =G38*$D$54 -> -328.0725 | I10: =H38*$D$54 -> -344.47613 | J10: =I38*$D$54 -> -361.69993 | K10: =J38*$E$54 -> -379.78493 | L10: =K38*$E$54 -> -398.77417 | M10: =L38*$E$54 -> -418.71288 | N10: =M38*$E$54 -> -439.64853 | O10: =N38*$E$54 -> -461.63095 | P10: =O38*$E$54 -> -484.7125 | Q10: =P38*$E$54 -> -508.94813 | R10: =Q38*$E$54 -> -534.39553 | ... AF10: =AE38*$E$54 -> -1058.0666
B11: 5c | C11: (Stock based compensation) | D11: =D20 -> 0 | E11: =E20 -> 0 | F11: =F20 -> 0 | G11: =G6*$D$55 -> 0 | H11: =H6*$D$55 -> 0 | I11: =I6*$D$55 -> 0 | J11: =J6*$D$55 -> 0 | K11: =K6*$D$55 -> 0 | L11: =L6*$D$55 -> 0 | M11: =M6*$D$55 -> 0 | N11: =N6*$D$55 -> 0 | ... AF11: =AF6*$D$55 -> 0
B12: 6 | C12: EBITDA | D12: =D8-D9-D10 -> 16470 | E12: =E8-E9-E10 -> 16574 | F12: =F8-F9-F10 -> 12594 | G12: =G8-G9-G10 -> 12275.784 | H12: =H8-H9-H10 -> 14940.178 | I12: =I8-I9-I10 -> 18689.482 | J12: =J8-J9-J10 -> 17587.896 | K12: =K8-K9-K10 -> 18741.23 | ... AF12: =AF8-AF9-AF10 -> 46301.096
B13: 7 | C13: (Net financing cost) | D13: ='Fin. Data'!D14 -> -694 | E13: ='Fin. Data'!C14 -> -704 | F13: ='Fin. Data'!B14 -> -568 | G13: =F43*$D$58-F44*$D$57 -> -649.9495 | H13: =G43*$D$58-G44*$D$57 -> -678.53227 | I13: =H43*$D$58-H44*$D$57 -> -724.68801 | J13: =I43*$D$58-I44*$D$57 -> -725.48048 | K13: =J43*$E$58-J44*$E$57 -> -703.30838 | L13: =K43*$E$58-K44*$E$57 -> -734.95833 | M13: =L43*$E$58-L44*$E$57 -> -762.57745 | N13: =M43*$E$58-M44*$E$57 -> -785.26243 | O13: =N43*$E$58-N44*$E$57 -> -803.42029 | P13: =O43*$E$58-O44*$E$57 -> -810.73871 | Q13: =P43*$E$58-P44*$E$57 -> -809.04804 | R13: =Q43*$E$58-Q44*$E$57 -> -797.93537 | ... AF13: =AE43*$E$58-AE44*$E$57 -> 906.63448
B14: 8 | C14: Other income/(cost) | D14: ='Fin. Data'!D15 -> 4479 | E14: ='Fin. Data'!C15 -> 2435 | F14: ='Fin. Data'!B15 -> 0 | G14: =AVERAGE(D14:F14)*(1+G5) -> 2308.2646 | H14: =AVERAGE(E14:G14)*(1+H5) -> 1735.5524 | I14: =AVERAGE(F14:H14)*(1+I5) -> 1482.7329 | J14: =AVERAGE(G14:I14)*(1+J5) -> 1934.2925 | K14: =AVERAGE(H14:J14)*(1+K5) -> 1803.4022 | L14: =AVERAGE(I14:K14)*(1+L5) -> 1827.1496 | M14: =AVERAGE(J14:L14)*(1+M5) -> 1947.6955 | N14: =AVERAGE(K14:M14)*(1+N5) -> 1952.3866 | ... AF14: =AVERAGE(AC14:AE14)*(1+AF5) -> 2444.5682
B15: 9 | C15: Earnings before taxes | D15: =D8+D13+D14 -> 16595 | E15: =E8+E13+E14 -> 14825 | F15: =F8+F13+F14 -> 8573 | G15: =G8+G13+G14 -> 10403.915 | H15: =H8+H13+H14 -> 12057.02 | I15: =I8+I13+I14 -> 15058.045 | J15: =J8+J13+J14 -> 13913.812 | K15: =K8+K13+K14 -> 14440.344 | ... AF15: =AF8+AF13+AF14 -> 27780.794
B16: 10 | C16: (Income tax) | D16: ='Fin. Data'!D21 -> -3705 | E16: ='Fin. Data'!C21 -> -3277 | F16: ='Fin. Data'!B21 -> -1865 | G16: =-$D$56*G15 -> -2288.8613 | H16: =-$D$56*H15 -> -2652.5444 | I16: =-$D$56*I15 -> -3312.7699 | J16: =-$D$56*J15 -> -3061.0386 | K16: =-$E$56*K15 -> -3754.4894 | L16: =-$E$56*L15 -> -3925.858 | M16: =-$E$56*M15 -> -4132.1134 | N16: =-$E$56*N15 -> -4318.6341 | O16: =-$E$56*O15 -> -4460.5566 | P16: =-$E$56*P15 -> -4617.4462 | Q16: =-$E$56*Q15 -> -4775.5591 | R16: =-$E$56*R15 -> -4943.4306 | ... AF16: =-$E$56*AF15 -> -7223.0065
B17: 11 | C17: Net income | D17: ='Fin. Data'!D23 -> 12890 | E17: ='Fin. Data'!C23 -> 11548 | F17: ='Fin. Data'!B23 -> 6708 | G17: =G16+G15 -> 8115.0538 | H17: =H16+H15 -> 9404.4757 | I17: =I16+I15 -> 11745.275 | J17: =J16+J15 -> 10852.773 | K17: =K16+K15 -> 10685.854 | L17: =L16+L15 -> 11173.596 | M17: =M16+M15 -> 11760.63 | N17: =N16+N15 -> 12291.497 | ... AF17: =AF16+AF15 -> 20557.788
A19: CASH FLOW STATEMENT | B19: 12 | C19: Operating cash flows before WK | D19: =Inputs!D59-D20-D21 -> 15649 | E19: =Inputs!C59-E20-E21 -> 14467 | F19: =Inputs!B59-F20-F21 -> 10752 | G19: =G17-G10-G9-G11 -> 11645.238 | H19: =H17-H10-H9-H11 -> 13344.654 | I19: =I17-I10-I9-I11 -> 16134.757 | J19: =J17-J10-J9-J11 -> 15735.669 | K19: =K17-K10-K9-K11 -> 16086.835 | L19: =L17-L10-L9-L11 -> 17118.565 | M19: =M17-M10-M9-M11 -> 18276.788 | N19: =N17-N10-N9-N11 -> 19407.402 | ... AF19: =AF17-AF10-AF9-AF11 -> 42429.292
B20: 13 | C20: (Stock-based compensation) | E20: 0 | F20: 0 | G20: =G11 -> 0 | H20: =H11 -> 0 | I20: =I11 -> 0 | J20: =J11 -> 0 | K20: =K11 -> 0 | L20: =L11 -> 0 | M20: =M11 -> 0 | N20: =N11 -> 0 | ... AF20: =AF11 -> 0
B21: 14 | C21: (Working Capital Flows) | D21: =Inputs!D62 -> -642 | E21: =Inputs!C62 -> -363 | F21: =Inputs!B62 -> -514 | G21: =$D$60*(G6-F6) -> -5.396 | H21: =$D$60*(H6-G6) -> -338.2 | I21: =$D$60*(I6-H6) -> -380 | J21: =$D$60*(J6-I6) -> -209 | K21: =$E$60*(K6-J6) -> -173.25 | L21: =$E$60*(L6-K6) -> -181.9125 | M21: =$E$60*(M6-L6) -> -191.00813 | N21: =$E$60*(N6-M6) -> -200.55853 | O21: =$E$60*(O6-N6) -> -147.41052 | P21: =$E$60*(P6-O6) -> -152.56989 | Q21: =$E$60*(Q6-P6) -> -157.90983 | R21: =$E$60*(R6-Q6) -> -163.43668 | ... AF21: =$E$60*(AF6-AE6) -> -130.63953
B22: 15 | C22: -Total Operating Cash Flow | D22: =D19+D20+D21 -> 15007 | E22: =E19+E20+E21 -> 14104 | F22: =F19+F20+F21 -> 10238 | G22: =G19+G20+G21 -> 11639.842 | H22: =H19+H20+H21 -> 13006.454 | I22: =I19+I20+I21 -> 15754.757 | J22: =J19+J20+J21 -> 15526.669 | K22: =K19+K20+K21 -> 15913.585 | ... AF22: =AF19+AF20+AF21 -> 42298.653
B23: 16 | C23: (CAPEX) | D23: ='Fin. Data'!D32 -> -4194 | E23: ='Fin. Data'!C32 -> -4769 | F23: ='Fin. Data'!B32 -> -5158 | G23: =G6*$D$62 -> -5056.05 | H23: =H6*$D$62 -> -5550 | I23: =I6*$D$62 -> -6105 | J23: =J6*$D$62 -> -6410.25 | K23: =K6*$E$62 -> -6730.7625 | L23: =L6*$E$62 -> -7067.3006 | M23: =M6*$E$62 -> -7420.6657 | N23: =N6*$E$62 -> -7791.6989 | O23: =O6*$E$62 -> -8064.4084 | P23: =P6*$E$62 -> -8346.6627 | Q23: =Q6*$E$62 -> -8638.7959 | R23: =R6*$E$62 -> -8941.1537 | ... AF23: =AF6*$E$62 -> -12325.839 | AG23: =SUM(D23:AF23) -> -252032.79
B24: 17 | C24: Adq | D24: =Inputs!D66 -> -602 | E24: ='Fin. Data'!C33 -> -755 | F24: ='Fin. Data'!B33 -> -1329 | G24: =G6*$D$63 -> -1366.5 | H24: =H6*$D$63 -> -1500 | I24: =I6*$D$63 -> -1650 | J24: =J6*$D$63 -> -1732.5 | K24: =K6*$E$63 -> -1819.125 | L24: =L6*$E$63 -> -1910.0812 | M24: =M6*$E$63 -> -2005.5853 | N24: =N6*$E$63 -> -2105.8646 | O24: =O6*$E$63 -> -2179.5698 | P24: =P6*$E$63 -> -2255.8548 | Q24: =Q6*$E$63 -> -2334.8097 | R24: =R6*$E$63 -> -2416.528 | ... AF24: =AF6*$E$63 -> -3331.3079 | AH24: =AG9-AG23 -> -41246.896
B25: 18 | C25: (Other investing flows) | D25: =Inputs!D67 -> 978 | E25: =Inputs!C67 -> -1948 | F25: =Inputs!B67 -> -646 | G25: =(1+G5)*AVERAGE(D25:F25) -> -539.50761 | H25: =(1+H5)*AVERAGE(E25:G25) -> -1146.545 | I25: =(1+I5)*AVERAGE(F25:H25) -> -855.08597 | J25: =(1+J5)*AVERAGE(G25:I25) -> -889.39852 | K25: =(1+K5)*AVERAGE(H25:J25) -> -1011.8603 | L25: =(1+L5)*AVERAGE(I25:K25) -> -964.72069 | M25: =(1+M5)*AVERAGE(J25:L25) -> -1003.0928 | N25: =(1+N5)*AVERAGE(K25:M25) -> -1042.8859 | ... AF25: =(1+AF5)*AVERAGE(AC25:AE25) -> -1287.593
B26: 19 | C26: -Total Investing Flows | D26: =D23+D24+D25 -> -3818 | E26: =E23+E24+E25 -> -7472 | F26: =F23+F24+F25 -> -7133 | G26: =G23+G24+G25 -> -6962.0576 | H26: =H23+H24+H25 -> -8196.545 | I26: =I23+I24+I25 -> -8610.086 | J26: =J23+J24+J25 -> -9032.1485 | K26: =K23+K24+K25 -> -9561.7478 | ... AF26: =AF23+AF24+AF25 -> -16944.74
B27: 20 | C27: (Flows related to leases) | D27: =Inputs!D71+Inputs!D72 -> 0 | E27: =Inputs!C71+Inputs!C72 -> 0 | F27: =Inputs!B71+Inputs!B72 -> 0 | G27: =G6*$D$66 -> 0 | H27: =H6*$D$66 -> 0 | I27: =I6*$D$66 -> 0 | J27: =J6*$D$66 -> 0 | K27: =$E$66*K6 -> 0 | L27: =$E$66*L6 -> 0 | M27: =$E$66*M6 -> 0 | N27: =$E$66*N6 -> 0 | O27: =$E$66*O6 -> 0 | P27: =$E$66*P6 -> 0 | Q27: =$E$66*Q6 -> 0 | R27: =$E$66*R6 -> 0 | ... AF27: =$E$66*AF6 -> 0
B28: 21 | C28: Flows related to debt | D28: =+SUM(Inputs!D69:D70) -> -2773 | E28: =+SUM(Inputs!C69:C70) -> -2304 | F28: =+SUM(Inputs!B69:B70) -> 1000 | G28: =G44-F44 -> -1563.6428 | H28: =H44-G44 -> 4714.9996 | I28: =I44-H44 -> 7498.6073 | J28: =J44-I44 -> -2203.1724 | K28: =K44-J44 -> 432.54596 | L28: =L44-K44 -> 2300.9023 | M28: =M44-L44 -> 2415.9474 | N28: =N44-M44 -> 2536.7448 | ... AF28: =AF44-AE44 -> 2796.7238
B29: 22 | C29: (Repurchases)/Issuance of stock | D29: ='Fin. Data'!D28 -> -500 | E29: ='Fin. Data'!C28 -> -3500 | F29: ='Fin. Data'!B28 -> -2250 | G29: =G6*$D$65 -> -1548.7 | H29: =H6*$D$65 -> -1700 | I29: =I6*$D$65 -> -1870 | J29: =J6*$D$65 -> -1963.5 | K29: =K6*$D$65 -> -2061.675 | L29: =L6*$D$65 -> -2164.7587 | M29: =M6*$D$65 -> -2272.9967 | N29: =N6*$D$65 -> -2386.6465 | ... AF29: =AF6*$D$65 -> -3775.4823
B30: 23 | C30: (Dividends) | D30: ='Fin. Data'!D27 -> -3437 | E30: ='Fin. Data'!C27 -> -5114 | F30: ='Fin. Data'!B27 -> -5372 | G30: =$D$64*G6 -> -4555 | H30: =$D$64*H6 -> -5000 | I30: =$D$64*I6 -> -5500 | J30: =$D$64*J6 -> -5775 | K30: =$D$64*K6 -> -6063.75 | L30: =$D$64*L6 -> -6366.9375 | M30: =$D$64*M6 -> -6685.2844 | N30: =$D$64*N6 -> -7019.5486 | ... AF30: =$D$64*AF6 -> -11104.36
B31: 24 | C31: Other financing flows | D31: =Inputs!D75 -> -113 | E31: =Inputs!C75 -> -267 | F31: =Inputs!B75 -> 1088 | G31: =(1+G5)*AVERAGE(D31:F31) -> 236.36843 | H31: =(1+H5)*AVERAGE(E31:G31) -> 386.88929 | I31: =(1+I5)*AVERAGE(F31:H31) -> 627.46117 | J31: =(1+J5)*AVERAGE(G31:I31) -> 437.75161 | K31: =(1+K5)*AVERAGE(H31:J31) -> 508.23572 | L31: =(1+L5)*AVERAGE(I31:K31) -> 550.70698 | M31: =(1+M5)*AVERAGE(J31:L31) -> 523.84301 | N31: =(1+N5)*AVERAGE(K31:M31) -> 553.975 | ... AF31: =(1+AF5)*AVERAGE(AC31:AE31) -> 688.3241
B32: 25 | C32: -Total Financing flows | D32: =D27+D28+D29+D30+D31 -> -6823 | E32: =E27+E28+E29+E30+E31 -> -11185 | F32: =F27+F28+F29+F30+F31 -> -5534 | G32: =G27+G28+G29+G30+G31 -> -7430.9744 | H32: =H27+H28+H29+H30+H31 -> -1598.1111 | I32: =I27+I28+I29+I30+I31 -> 756.06842 | J32: =J27+J28+J29+J30+J31 -> -9503.9208 | K32: =K27+K28+K29+K30+K31 -> -7184.6433 | ... AF32: =AF27+AF28+AF29+AF30+AF31 -> -11394.794
A34: SUMMARY | B34: 26 | C34: Cash before shareholder returns | D34: =D22+D26+D27+D28+D31 -> 8303 | E34: =E22+E26+E27+E28+E31 -> 4061 | F34: =F22+F26+F27+F28+F31 -> 5193 | G34: =G22+G26+G27+G28+G31 -> 3350.5098 | H34: =H22+H26+H27+H28+H31 -> 9911.7979 | I34: =I22+I26+I27+I28+I31 -> 15270.739 | J34: =J22+J26+J27+J28+J31 -> 4729.0999 | K34: =K22+K26+K27+K28+K31 -> 7292.6186 | ... AF34: =AF22+AF26+AF27+AF28+AF31 -> 28838.96
B35: 27 | C35: Returns to shareholders | D35: =-1*(D29+D30) -> 3937 | E35: =-1*(E29+E30) -> 8614 | F35: =-1*(F29+F30) -> 7622 | G35: =-1*(G29+G30) -> 6103.7 | H35: =-1*(H29+H30) -> 6700 | I35: =-1*(I29+I30) -> 7370 | J35: =-1*(J29+J30) -> 7738.5 | K35: =-1*(K29+K30) -> 8125.425 | ... AF35: =-1*(AF29+AF30) -> 14879.842
B36: 28 | C36: Excess cash acumulation | D36: =D34-D35 -> 4366 | E36: =E34-E35 -> -4553 | F36: =F34-F35 -> -2429 | G36: =G34-G35 -> -2753.1902 | H36: =H34-H35 -> 3211.7979 | I36: =I34-I35 -> 7900.7395 | J36: =J34-J35 -> -3009.4001 | K36: =K34-K35 -> -832.8064 | ... AF36: =AF34-AF35 -> 13959.118
A38: BALANCE SHEET | B38: 29 | C38: Intangible assets | D38: 7860 | E38: 6851 | F38: 6249 | G38: =+F38+(-G10) -> 6561.45 | H38: =+G38+(-H10) -> 6889.5225 | I38: =+H38+(-I10) -> 7233.9986 | J38: =+I38+(-J10) -> 7595.6986 | K38: =+J38+(-K10) -> 7975.4835 | L38: =+K38+(-L10) -> 8374.2577 | M38: =+L38+(-M10) -> 8792.9705 | N38: =+M38+(-N10) -> 9232.6191 | ... AF38: =+AE38+(-AF10) -> 22219.399 | AG38: =SUM(G38:AF38) -> 335378.37
B39: 30 | C39: Accumulated amortization | D39: =Assumptions!C101 -> 0 | E39: =Assumptions!Y18 -> PPE | F39: =Assumptions!Z18 -> 36945 | G39: =F39-G10 -> 37257.45 | H39: =G39-H10 -> 37585.522 | I39: =H39-I10 -> 37929.999 | J39: =I39-J10 -> 38291.699 | K39: =J39-K10 -> 38671.483 | L39: =K39-L10 -> 39070.258 | M39: =L39-M10 -> 39488.971 | N39: =M39-N10 -> 39928.619 | ... AF39: =AE39-AF10 -> 52915.399 | AG39: =SUM(G39:AF39) -> 1133474.4
B40: 31 | C40: PPE+Right of use Assets | D40: 37037 | E40: 38474 | F40: 41253 | G40: =F40+(-G23) -> 46309.05 | H40: =G40+(-H23) -> 51859.05 | I40: =H40+(-I23) -> 57964.05 | J40: =I40+(-J23) -> 64374.3 | K40: =J40+(-K23) -> 71105.062 | L40: =K40+(-L23) -> 78172.363 | M40: =L40+(-M23) -> 85593.029 | N40: =M40+(-N23) -> 93384.728 | ... AF40: =AE40+(-AF23) -> 279164.79 | AG40: =SUM(G40:AF40) -> 3876023.1
B41: 32 | C41: Accumulated depreciation | D41: =('[2]Income Statement'!$B$164-'[2]Income Statement'!$B$166)-D9 -> 5927.24 | E41: =D41-E9 -> 9115.24 | F41: =E41-F9 -> 12068.24 | G41: =F41-G9 -> 15285.974 | H41: =G41-H9 -> 18898.08 | I41: =H41-I9 -> 22943.086 | J41: =I41-J9 -> 27464.282 | K41: =J41-K9 -> 32485.477 | L41: =K41-L9 -> 38031.672 | ... AF41: =AE41-AF9 -> 295840.92 | AG41: =SUM(G41:AF41) -> 3105542.7
A43: CASH & DEBT & DISCOUNTING | B43: 33 | C43: Ending cash balance | D43: ='Fin. Data'!D39 -> 10255 | E43: =E36+D43 -> 5702 | F43: =F36+E43 -> 3273 | G43: =G36+F43 -> 519.80982 | H43: =H36+G43 -> 3731.6077 | I43: =I36+H43 -> 11632.347 | J43: =J36+I43 -> 8622.9471 | K43: =K36+J43 -> 7790.1407 | L43: =L36+K43 -> 9104.6035 | ... AF43: =AF36+AE43 -> 141354.78
B44: 34 | C44: Total Debt | D44: ='Fin. Data'!D58 -> 25528 | E44: ='Fin. Data'!C58 -> 23421 | F44: ='Fin. Data'!B58 -> 26729 | G44: =G12*($D$67+5%) -> 25165.357 | H44: =H12*$D$67 -> 29880.357 | I44: =I12*$D$67 -> 37378.964 | J44: =J12*$D$67 -> 35175.792 | K44: =K12*$E$67 -> 35608.338 | L44: =L12*$E$67 -> 37909.24 | M44: =M12*$E$67 -> 40325.187 | N44: =N12*$E$67 -> 42861.932 | O44: =O12*$E$67 -> 45085.389 | P44: =P12*$E$67 -> 47387.292 | Q44: =Q12*$E$67 -> 49770.421 | R44: =R12*$E$67 -> 52237.649 | ... AF44: =AF12*$E$67 -> 87972.082
B45: 35 | C45: Discount factor | F45: =1/((1+$F$50)^G50) -> 1 | G45: =1/((1+$F$50)^G49) -> 0.92165899 | H45: =1/((1+$F$50)^H49) -> 0.84945529 | I45: =1/((1+$F$50)^I49) -> 0.7829081 | J45: =1/((1+$F$50)^J49) -> 0.72157428 | K45: =1/((1+$F$50)^K49) -> 0.66504542 | L45: =1/((1+$F$50)^L49) -> 0.61294509 | M45: =1/((1+$F$50)^M49) -> 0.56492635 | N45: =1/((1+$F$50)^N49) -> 0.52066945 | ... AF45: =1/((1+$F$50)^AF49) -> 0.1199021
...

Sheet Assumptions
B2: Assumptions
B4: Prospects:
B6: Links:
C8: 2023 | D8: =C8-1 -> 2022 | E8: =D8-1 -> 2021 | F8: =E8-1 -> 2020 | G8: =F8-1 -> 2019 | H8: =G8-1 -> 2018 | I8: =H8-1 -> 2017 | J8: =I8-1 -> 2016 | K8: =J8-1 -> 2015 | ... M8: =L8-1 -> 2013 | O8: 10Y Average | P8: 5Y Average | Q8: 3Y Average | S8: Short Term Forecast | T8: Long Term Forecast
B9: Revenue growth | C9: =(Inputs!B6-Inputs!C6)/Inputs!C6 -> -0.093484024 | D9: =(Inputs!C6-Inputs!D6)/Inputs!D6 -> 0.031360819 | E9: =(Inputs!D6-Inputs!E6)/Inputs!E6 -> 0.14958406 | F9: =(Inputs!E6-Inputs!F6)/Inputs!F6 -> 0.14217076 | G9: =(Inputs!F6-Inputs!G6)/Inputs!G6 -> 0.031073879 | H9: =(Inputs!G6-Inputs!H6)/Inputs!H6 -> 0.090918752 | I9: =(Inputs!H6-Inputs!I6)/Inputs!I6 -> 0.081535481 | J9: =(Inputs!I6-Inputs!J6)/Inputs!J6 -> 0.043572126 | ... M9: =(Inputs!L6-Inputs!M6)/Inputs!M6 -> 0.024220814 | O9: =AVERAGE(C9:M9) -> 0.050327357 | P9: =AVERAGE(C9:G9) -> 0.052141098 | Q9: =AVERAGE(C9:E9) -> 0.029153619 | S9: 0.035 | T9: 0.05
B10: Operating Margin | C10: =Inputs!B8/Inputs!B6 -> 0.10049693 | D10: =Inputs!C8/Inputs!C6 -> 0.13049891 | E10: =Inputs!D8/Inputs!D6 -> 0.13167227 | F10: =Inputs!E8/Inputs!E6 -> 0.090797372 | G10: =Inputs!F8/Inputs!F6 -> 0.10524469 | H10: =Inputs!G8/Inputs!G6 -> 0.097744256 | I10: =Inputs!H8/Inputs!H6 -> 0.11429743 | J10: =Inputs!I8/Inputs!I6 -> 0.089761271 | ... M10: =Inputs!L8/Inputs!L6 -> 0.12688048 | O10: =AVERAGE(C10:M10) -> 0.10946292 | P10: =AVERAGE(C10:G10) -> 0.11174204 | Q10: =AVERAGE(C10:E10) -> 0.12088937 | S10: 0.116 | T10: 0.108
B13: Modelling Factors
C15: Last 10 Years
C16: =C8 -> 2023 | D16: =D8 -> 2022 | E16: =E8 -> 2021 | F16: =F8 -> 2020 | G16: =G8 -> 2019 | H16: =H8 -> 2018 | I16: =I8 -> 2017 | J16: =J8 -> 2016 | ... M16: =M8 -> 2013 | O16: =O8 -> 10Y Average | P16: =P8 -> 5Y Average | Q16: =Q8 -> 3Y Average | S16: Short Term Forecast | T16: Long Term Forecast | V16: Reference
B17: Depreciation factor | C17: =DCF!F9/DCF!F40 -> -0.071582673 | D17: =DCF!E9/DCF!E40 -> -0.082861153 | E17: =DCF!D9/DCF!D40 -> -0.090882091 | F17: =-('[2]Income Statement'!$B$164-'[2]Income Statement'!$B$166)/'Fin. Data'!B42 -> -0.069325754 | G17: =-('[2]Income Statement'!$B$164-'[2]Income Statement'!$B$166)/'Fin. Data'!C42 -> -0.073770558 | H17: =-('[2]Income Statement'!$B$164-'[2]Income Statement'!$B$166)/'Fin. Data'!D42 -> -0.076512024 | I17: =-('[2]Income Statement'!$B$164-'[2]Income Statement'!$B$166)/'Fin. Data'!E42 -> -0.079408445 | J17: =-('[2]Income Statement'!$B$164-'[2]Income Statement'!$B$166)/'Fin. Data'!F42 -> -0.08402467 | K17: =-('[2]Income Statement'!$B$164-'[2]Income Statement'!$B$166)/'Fin. Data'!G42 -> -0.096374172 | L17: =-('[2]Income Statement'!$B$164-'[2]Income Statement'!$B$166)/'Fin. Data'!H42 -> -0.1157989 | M17: =-('[2]Income Statement'!$B$164-'[2]Income Statement'!$B$166)/'Fin. Data'!I42 -> -0.13623617 | O17: =AVERAGE(C17:M17) -> -0.088797873 | P17: =AVERAGE(C17:G17) -> -0.077684446 | Q17: =AVERAGE(C17:E17) -> -0.081775306 | S17: -0.078 | T17: -0.085 | V17: % PPE | Z17: 2023 | AA17: 2022 | AB17: 2021 | AC17: 2020 | AD17: 2019 | AE17: 2018 | AF17: 2017 | AG17: 2016 | AI17: 2015 | AJ17: 2014 | AK17: 2013 | AL17: 2012
B18: Amortization factor | C18: =-Z23/Z21 -> -0.063613232 | D18: =-AA23/AA21 -> -0.042621515 | E18: =-AB23/AB21 -> -0.047047528 | F18: =-AC23/AC21 -> -0.050322131 | G18: =-AD23/AD21 -> -0.058537498 | H18: =-AE23/AE21 -> -0.051183492 | I18: =-AF23/AF21 -> -0.041284404 | J18: =-AG23/AG21 -> -0.035620368 | K18: - | L18: =-AJ23/AJ21 -> -0.046340684 | M18: =-AK23/AK21 -> -0.04532967 | O18: =AVERAGE(C18:M18) -> -0.048190052 | P18: =AVERAGE(C18:G18) -> -0.052428381 | Q18: =AVERAGE(C18:E18) -> -0.051094091 | S18: -0.05 | T18: -0.047 | V18: % IA | Y18: PPE | Z18: 36945 | AA18: 34719 | AB18: 33475 | AC18: 32245 | AD18: 30842 | AE18: 26576 | AF18: 22118 | AG18: 18800 | AI18: 18352 | AJ18: 18281 | AK18: 17961
B19: Stock-based comp | C19: =DCF!F11/DCF!F6 -> 0 | D19: =DCF!E11/DCF!E6 -> 0 | E19: =DCF!D11/DCF!D6 -> 0 | F19: 0 | G19: 0 | H19: 0 | I19: 0 | J19: 0 | K19: 0 | L19: 0 | M19: 0 | O19: =AVERAGE(C19:M19) -> 0 | P19: =AVERAGE(C19:G19) -> 0 | Q19: =AVERAGE(C19:E19) -> 0 | S19: 0 | T19: 0.03 | V19: % Revenue | Y19: ROA | Z19: 4308 | AA19: 3755 | AB19: 3562 | AC19: 3073 | AD19: 3073 | AE19: 3073 | AF19: 3073 | AG19: - | AI19: - | AJ19: - | AK19: - | AL19: -
B20: Tax Rate | C20: 0.218 | D20: 0.221 | E20: 0.223 | F20: 0.272 | G20: 0.214 | H20: 0.204 | I20: 0.313 | J20: 0.332 | K20: 0.34 | L20: 0.346 | M20: 0.345 | O20: =AVERAGE(C20:M20) -> 0.27527273 | P20: =AVERAGE(C20:G20) -> 0.2296 | Q20: =AVERAGE(C20:E20) -> 0.22066667 | S20: 0.22 | T20: 0.26 | V20: % EBT | Y20: Dep | Z20: =Z24-Z23 -> -500
B21: Interest Rate on debt | C21: =785/'Fin. Data'!B58 -> 0.02936885 | D21: =704/'Fin. Data'!C58 -> 0.030058495 | E21: =694/'Fin. Data'!D58 -> 0.027185835 | F21: =701/'Fin. Data'!E58 -> 0.025257621 | G21: =653/'Fin. Data'!F58 -> 0.023183158 | H21: =605/'Fin. Data'!G58 -> 0.026609782 | I21: =453/'Fin. Data'!H58 -> 0.018650418 | J21: =381/'Fin. Data'!I58 -> 0.0237014 | K21: =341/'Fin. Data'!J58 -> 0.023789591 | L21: =353/'Fin. Data'!K58 -> 0.032724576 | M21: =380/'Fin. Data'!L58 -> 0.034952171 | O21: =AVERAGE(C21:M21) -> 0.02686199 | P21: =AVERAGE(C21:G21) -> 0.027010792 | Q21: =AVERAGE(C21:E21) -> 0.02887106 | S21: 0.0275 | T21: 0.026 | V21: % Debt | Y21: Intang. Assets | Z21: 7860 | AA21: 6851 | AB21: 6249 | AC21: 5743 | AD21: 5347 | AE21: 4943 | AF21: 4578 | AG21: 4183 | AI21: 3825 | AJ21: 3129 | AK21: 2912 | AL21: 2608
B22: Interest Rate on cash | C22: 0 | D22: 0 | E22: 0 | F22: 0 | G22: 0 | H22: 0 | I22: 0 | J22: 0 | K22: 0 | L22: 0 | M22: 0 | O22: =AVERAGE(C22:M22) -> 0 | P22: =AVERAGE(C22:G22) -> 0 | Q22: =AVERAGE(C22:E22) -> 0 | S22: 0 | T22: 0 | V22: % Cash | Y22: Amort. accumulated | Z22: 4555 | AA22: 4055 | AB22: 3763 | AC22: 3469 | AD22: 3180 | AE22: 2867 | AF22: 2614 | AG22: 2425 | AI22: 2276 | AJ22: 2282 | AK22: 2137 | AL22: 2005
