Workbook
Name Benchmark: [1]ControlsH!$B$3
Name BestConsOv: #REF!
Name Broker_Name: OFFSET(#REF!,0,0,[1]ControlsH!$E$5, 1)
Name calCODE: [1]ControlsH!$C$4
Name Chart_Benchmark_100_Size: OFFSET(#REF!, 0, 0, [1]ControlsH!$E$3, 1)
Name Chart_Date_Size: OFFSET(#REF!, 0, 0, [1]ControlsH!$E$3, 1)
Name Chart_Date_VAL1_Size: OFFSET(#REF!, 0, 0, [1]ControlsH!$I$3, 1)
Name Chart_Date_VAL2_Size: OFFSET(#REF!, 0, 0, [1]ControlsH!$I$5, 1)
Name Chart_Peer_100_Size: OFFSET(#REF!, 0, 0, [1]ControlsH!$E$3, 1)
Name Chart_Price_100_Size: OFFSET(#REF!, 0, 0, [1]ControlsH!$E$3, 1)
Name Chart_Price_Size: OFFSET(#REF!, 0, 0, [1]ControlsH!$E$3, 1)
Name Chart_VAL1_FY1_Size: OFFSET(#REF!, 0, 0, [1]ControlsH!$F$3, 1)
Name Chart_VAL1_FY2_Size: OFFSET(#REF!, 0, 0, [1]ControlsH!$G$3, 1)
Name Chart_VAL1_FY3_Size: OFFSET(#REF!, 0, 0, [1]ControlsH!$H$3, 1)
Name Chart_VAL2_FY1_Size: OFFSET(#REF!, 0, 0, [1]ControlsH!$F$5, 1)
Name Chart_VAL2_FY2_Size: OFFSET(#REF!, 0, 0, [1]ControlsH!$G$5, 1)
Name Chart_VAL2_FY3_Size: OFFSET(#REF!, 0, 0, [1]ControlsH!$H$5, 1)
Name Chart_Volume_Size: OFFSET(#REF!, 0, 0, [1]ControlsH!$E$3, 1)
Name compNAME: [1]ControlsH!$B$6
Name CURRENCY: [1]ControlsH!$B$9
Name currPRICE: [1]Overview!$E$19
Name custBenchmark: [1]Overview!$C$9
Name custED: #REF!
Name custSD: #REF!
Name dayCODE: [1]ControlsH!$C$5
Name ED: [1]ControlsH!$B$5
Name ESTBrokersItem: #REF!
Name ESTBrokersPeriod: #REF!
Name ESTDetailBroker: #REF!
Name ESTDetailBroker2: #REF!
Name ESTDetailPeriod: #REF!
Name EstDetPerO: #REF!
Name EstDetPerT: #REF!
Name FinancialsPeriod: #REF!
Name fundTICKER: [1]ControlsH!$B$15
Name GraphValRatio1: #REF!
Name GraphValRatio2: #REF!
Name Index1: #REF!
Name Lang: [1]Overview!$D$11
Name newCrncy: [1]ControlsH!$B$21:$B$199
Name newEstBrokerPeriod: #REF!
Name newEstBrokersItem: #REF!
Name newEstDetailBroker: #REF!
Name newEstDetailBroker2: #REF!
Name newEstDetailPeriod: #REF!
Name newFinancialsPeriod: #REF!
Name newOverviewCon: #REF!
Name newOverviewYear: #REF!
Name newOwners: #REF!
Name newPeersRatio: #REF!
Name newPeriod: #REF!
Name newValRatio1: #REF!
Name newValRatio2: #REF!
Name OverviewValRatioPeriod: [1]Overview!$D$30
Name PeerDate1: [1]Peers!$S$11
Name peerHist1: #REF!
Name PeerIndex: [1]ControlsH!$F$35:$F$36
Name Peers: OFFSET([1]Peers!$C$18,0,0,MAX(COUNTA([1]Peers!$C$18:$C$47),1),1)
Name peersWEIGHT: [1]ControlsH!$B$13
Name PERIODICITY: [1]ControlsH!$C$3

Sheet COVID-19 impact
A1: https://www.apple.com/newsroom/2020/03/apples-covid-19-response/ | G1: https://glg.it/articles/how-might-the-wuhan-coronavirus-impact-apples-supply-chain/ | N1: https://www.cnbc.com/2020/02/18/the-significance-of-apples-coronavirus-warning.html
A2: March 13 | G2: January 29 | N2: Ferbuary 18
A23: Otros:
A24: https://www.macrumors.com/guide/covid-19-coronavirus/

Sheet OP
B2: (date of last modification) | C2: Analista: Research | D2: Report (quarter): 2024/11/07 | E2: #VALUE! | K2: NYSE | L2: SIC: Sí
B3: #VALUE! | D3: DESCRIPTION: YETI Holdings, Inc. is an American company specializing in premium outdoor lifestyle products, including high-performance coolers, drinkware, bags, and accessories. Founded in 2006, YETI is known for its durable, high-quality designs catering to outdoor enthusiasts, travelers, and professionals.
D4: CEO&BOARD: Robert K. Shearer (Ch; 69yo; dir. s. 2018; ex CFO of VF Corporation, Director at Church & Dwight Co., Inc.) ; Matthew J. Reintjes (President & CEO; 48yo; dir. s. 2016; ex Executive at Vista Outdoor Inc., President of Bushnell Outdoor Products); Alison Dean (60yo; dir.s. 2020; ex EVP, CFO & Treasurer at iRobot Corporation, Director at Everbridge, Inc.) ; Alison Dean (60yo; dir.s. 2020; ex EVP, CFO & Treasurer at iRobot Corporation, Director at Everbridge, Inc.); Dustan E. McCoy (75yo; dir.s. 2018; ex Chairman & CEO of Brunswick Corporation, Director at Freeport-McMoRan Inc.) ; Mary Lou Kelley (57yo; board member since 2019; ex President of eCommerce at Best Buy Co., Inc., Director at Vera Bradley, Inc.); Frank D. Gibeau (56yo; dir.s. 2020; CEO of Zynga Inc., ex EVP at Electronic Arts Inc.) ; Elizabeth Axelrod ( 61yo; dir.s. 2023; ex Global Head of Employee Experience at Airbnb, SVP of Human Resources at eBay.) ; Robert Katz (57yo; board member since 2023; Executive Chairperson of Vail Resorts, Inc., ex CEO of Vail Resorts).
B5: Millones de USD
B6: Acción | D6: Liquidez y Solvencia | F6: =[3]Segments!B2 -> Regions in Thousands (2023) | I6: Rentabilidad (2023) | K6: Múltiplos
B7: Último Precio | C7: {=_FV(E2,"price")} -> 37.12 | D7: Activo: | E7: =Cifras_Originales!B27 -> 1297.192 | H7: %Vts; %Op.Mg.; D | I7: Año termina: | J7: 45291 | K7: Float: | L7: =83.44/84.83 -> 0.98361429
B8: Outstanding Shares | C8: {=_FV(E2,"Shares outstanding",TRUE)} -> 84825450 | D8: Pasivo: | E8: =Cifras_Originales!B39 -> 573.582 | F8: =[2]Segments!B4 -> United States | H8: =+Segments!J4 -> 84%; -; 0% | K8: Insiders Own: | L8: 0.0052
B9: Market Cap. | C9: =C7*C8/1000000 -> 3148.7207 | D9: Cash/Precio | E9: =1000000*C11/C8 -> 5.174862 | F9: =[2]Segments!B5 -> Internacional | H9: =+Segments!J5 -> 16%; -; 29% | I9: EBIT | J9: =Cifras_Originales!B19+Cifras_Originales!B15+Cifras_Originales!B9 -> 224.028 | K9: b (Bloomberg; Yahoo) | L9: 2.14 | R9: 2023 | S9: 2022 | T9: 2021
B10: +Deuda Total | C10: =Cifras_en_Millones!C60 -> 176.113 | D10: Ebidta/CIF | E10: =(Cifras_Originales!B19-Cifras_Originales!B11-Cifras_Originales!B9-Cifras_Originales!B15)/Cifras_Originales!B9 -> -172.16136 | F10: =[2]Segments!B6 -> 0 | H10: =+[2]Segments!J6 | I10: +Dep&Amort | J10: =Cifras_Originales!B11 -> -46.434 | K10: Calificación (S&P) | L10: 0.33 | Q10: Operating margin | R10: =[3]Cifras_Originales!B8/[3]Cifras_Originales!B6 -> 0.13592345 | S10: =[3]Cifras_Originales!C8/[3]Cifras_Originales!C6 -> 0.079212172 | T10: =[3]Cifras_Originales!D8/[3]Cifras_Originales!D6 -> 0.19485481
B11: -Cash | C11: =Cifras_en_Millones!C40 -> 438.96 | D11: Deuda/Ebidta | E11: =(Cifras_Originales!B32+Cifras_Originales!B36)/(Cifras_Originales!B19-Cifras_Originales!B15-Cifras_Originales!B9-Cifras_Originales!B11) -> 0.52550316 | F11: =[2]Segments!B7 -> 0 | H11: =+[2]Segments!J7 | I11: =EBIDTA | J11: =J9+J10 -> 177.594 | K11: Precio/Valor en libros | L11: =((C7*C8)/1000000)/(E7-E8) -> 4.3514057 | Q11: Net income margin | R11: =[3]Cifras_Originales!B19/[3]Cifras_Originales!B6 -> 0.10241977 | S11: =[3]Cifras_Originales!C19/[3]Cifras_Originales!C6 -> 0.05622603 | T11: =[3]Cifras_Originales!D19/[3]Cifras_Originales!D6 -> 0.15067587
B12: =Enterprise Value | C12: =C9+C10-C11 -> 2885.8737 | D12: "Otros activos"/Activo | E12: =Cifras_Originales!B26/Cifras_Originales!B27 -> 0.2270566 | F12: =[2]Segments!B8 -> 0 | H12: =+[2]Segments!J8 | I12: Utilidad Neta | J12: =Cifras_Originales!B19 -> 169.885 | K12: FNP(p)/Activos | L12: =J18/E7 -> 0.047712546 | Q12: EBITDA | R12: =[3]Cifras_Originales!B19+[3]Cifras_Originales!B15+[3]Cifras_Originales!B11+[3]Cifras_Originales!B9 -> 177594 | S12: =[3]Cifras_Originales!C19+[3]Cifras_Originales!C15+[3]Cifras_Originales!C11+[3]Cifras_Originales!C9 -> 80796 | T12: =[3]Cifras_Originales!D19+[3]Cifras_Originales!D15+[3]Cifras_Originales!D11+[3]Cifras_Originales!D9 -> 239679
B13: Tenencia % (nac/int'l) | C13: - | D13: Deuda/Activo | E13: =C10/E7 -> 0.13576479 | F13: =[3]Segments!B15 -> Products in Thousands (2023) | I13: UPA | J13: =1000000*J12/C8 -> 2.0027598 | K13: Precio/Utilidad(p) | L13: =C9/J17 -> 20.005426 | N13: =C10/J11 -> 0.99166075 | Q13: EBITDA/net income | R13: =R12/[3]Cifras_Originales!B19 -> 1.0453778 | S13: =S12/[3]Cifras_Originales!C19 -> 0.90080608 | T13: =T12/[3]Cifras_Originales!D19 -> 1.12736
B14: t liq. (Pos prom./Vol.) | C14: - | D14: Margen de Operación (p) | E14: =AVERAGE(R10:T10) -> 0.13666348 | H14: %Vts; D | I14: ROA | J14: =J12/E7 -> 0.13096365 | K14: EV/Activos | L14: =C12/E7 -> 2.2247082 | Q14: NFC | R14: =[3]Cifras_Originales!B9 -> -942 | S14: =[3]Cifras_Originales!C9 -> -4466 | T14: =[3]Cifras_Originales!D9 -> -3339
B15: % Short | C15: =9.87/83.84 -> 0.11772424 | D15: Margen neto (p) | E15: =AVERAGE(R11:T11) -> 0.10310722 | F15: =[3]Segments!B17 -> Coolers & Equipment | H15: =+Segments!J17 -> 36%; -; -2% | I15: ROIC | J15: =J12/(E7-(E8-C10)) -> 0.18881923 | K15: EV/Ebidta (p) | L15: =C12/J16 -> 17.382373 | Q15: Net debt | R15: =[3]Cifras_en_Millones!B59 -> 132217 | S15: =[3]Cifras_en_Millones!C59 -> -70664 | T15: =[3]Cifras_en_Millones!D59 -> -125781
B16: Semáforo ESG | D16: Ebidta/Ingresos(p) | E16: =AVERAGE(R13:T13) -> 1.0245146 | F16: =[3]Segments!B18 -> Drinkware | H16: =+Segments!J18 -> 62%; -; 8% | I16: Ebidta(p) | J16: =AVERAGE(Cifras_en_Millones!C19:E19) -> 166.023 | K16: Precio/FNP (p) | L16: =C9/J18 -> 50.874164
B17: E | D17: CIF/Deuda Neta Promedio | E17: =AVERAGE(R15:T15) -> -21409.333 | F17: =[3]Segments!B19 -> Others | H17: =++Segments!J19 -> 2%; -; 8% | I17: Utilidad Neta (p) | J17: =AVERAGE(Cifras_en_Millones!C23:E23) -> 157.39333 | K17: Bonos 1;5;40a (USD) | L17: N/A | N17: 12
B18: S | F18: =[2]Segments!B20 -> 0 | H18: =+[2]Segments!J20 | I18: FNP (p) | J18: =SUM(F35:F37)/3 -> 61.892333 | K18: TDY(p)/Precio | L18: =SUM(E35:E37)/(3*C9) -> 0
B19: G | F19: =[2]Segments!B21 -> 0 | H19: =+[2]Segments!J21 | I19: Tax (p) últ. 5a | J19: 0.16 | K19: Div. Yield: | L19: =K33/C9 -> 0
B20: Tesis de inversión | H20: Acuerdo | I20: Supuestos de valuación | L20: DCF Value
B21: YETI Holdings is a premium brand with strong customer loyalty, expanding beyond coolers into outdoor gear. Its omnichannel strategy and global expansion drive growth, backed by solid financials. Key risks include competition, economic downturns, and supply chain challenges. Overall, YETI's premium positioning and market expansion make it a compelling long-term investment. | H21: Mantener sin elevar posición | I21: VER DCF | L21: =DCFF!D67 -> 330.44079
B23: KSF | H23: PO / Precio Stand By | L23: =DCFF!D66 -> 7.9019609
H24: =[2]DCFF!D71 -> 0 | I24: Tasa de descuento: | J24: =DCFF!D48 -> 0.085
B25: Año | C25: Ingresos | D25: Margen Operativo | E25: Div.+Recompra | F25: FNP | G25: Deuda/Activo | H25: Depreciación | I25: Capex + Adq | J25: Cash Flow
B26: 2012 | C26: N/A | D26: N/A | E26: N/A | F26: N/A | G26: N/A | H26: N/A | I26: N/A | K26: 2023 | L26: =K26-1 -> 2022
B27: =B26+1 -> 2013 | C27: =Cifras_Originales!L6 -> 89.9 | D27: =Cifras_Originales!L$8/OP!C27 -> 0.16907675 | E27: N/A | F27: N/A | G27: N/A | H27: N/A | I27: N/A | J27: Profit | K27: =Cifras_Originales!B19 -> 169.885 | L27: =Cifras_Originales!C19 -> 89.693 | N27: =C27/C26-1 -> #VALUE! | O27: =D27/D26-1 -> #VALUE!
B28: =B27+1 -> 2014 | C28: =Cifras_Originales!K6 -> 147.7 | D28: =Cifras_Originales!K$8/OP!C28 -> 0.17400135 | E28: N/A | F28: N/A | G28: N/A | H28: N/A | I28: N/A | J28: Cash Flow from Operations (BWC) | K28: 285.942 | L28: 100.894 | N28: =C28/C27-1 -> 0.6429366 | O28: =D28/D27-1 -> 0.02912643 | P28: =E28/E27-1 -> #VALUE! | Q28: =F28/#REF!-1 -> #VALUE! | R28: =H28/H27-1 -> #VALUE! | S28: =I28/I27-1 -> #VALUE! | BT28: 4303
B29: =B28+1 -> 2015 | C29: =Cifras_Originales!J6 -> 468.946 | D29: =Cifras_Originales!J$8/OP!C29 -> 0.27273929 | E29: N/A | F29: N/A | G29: N/A | H29: N/A | I29: N/A | J29: Working Capital | K29: =Cifras_Originales!B12 -> 31.698 | L29: =Cifras_Originales!C12 -> -28.037 | N29: =C29/C28-1 -> 2.1749898 | O29: =D29/D28-1 -> 0.567455 | P29: =E29/E28-1 -> #VALUE! | Q29: =F29/F28-1 -> #VALUE! | R29: =H29/H28-1 -> #VALUE! | S29: =I29/I28-1 -> #VALUE! | BT29: 3066
B30: =B29+1 -> 2016 | C30: =Cifras_Originales!I6 -> 818.914 | D30: =Cifras_Originales!I$8/OP!C30 -> 0.10771217 | E30: =[2]Cifras_Originales!I17+[2]Cifras_Originales!I18 -> 0 | F30: N/A | G30: N/A | H30: 6.3 | I30: =Cifras_Originales!I13+Cifras_Originales!I14 -> -35.588 | J30: Investing Activities | K30: =K31+K32 -> -72.824 | L30: =L31+L32 -> -56.91 | N30: =C30/C29-1 -> 0.74628635 | O30: =D30/D29-1 -> -0.6050728 | P30: =E30/E29-1 -> #VALUE! | Q30: =F30/F29-1 -> #VALUE! | R30: =H30/H29-1 -> #VALUE! | S30: =I30/I29-1 -> #VALUE! | BT30: 3283
B31: =B30+1 -> 2017 | C31: =Cifras_Originales!H6 -> 639.239 | D31: =Cifras_Originales!H$8/OP!C31 -> 0.10006742 | E31: =[2]Cifras_Originales!H17+[2]Cifras_Originales!H18 -> 0 | F31: =Cifras_Originales!H22-Cifras_Originales!I22+Cifras_Originales!H18+Cifras_Originales!H17 -> 32.359 | G31: =Cifras_en_Millones!I60/Cifras_en_Millones!I45 -> 0.92110211 | H31: 15.4 | I31: =Cifras_Originales!H13+Cifras_Originales!H14 -> -42.197 | J31: Capex | K31: -50.672 | L31: -45.929 | N31: =C31/C30-1 -> -0.21940643 | O31: =D31/D30-1 -> -0.070973796 | P31: =E31/E30-1 -> #DIV/0! | Q31: =F31/F30-1 -> #VALUE! | R31: =H31/H30-1 -> 1.4444444 | S31: =I31/I30-1 -> 0.18570867
B32: =B31+1 -> 2018 | C32: =Cifras_Originales!G6 -> 778.833 | D32: =Cifras_Originales!G$8/OP!C32 -> 0.13116547 | E32: =[2]Cifras_Originales!G17+[2]Cifras_Originales!G18 -> 0 | F32: =Cifras_Originales!G22-Cifras_Originales!H22+Cifras_Originales!G17+Cifras_Originales!G18 -> 26.401 | G32: =Cifras_en_Millones!H60/Cifras_en_Millones!H45 -> 0.63789519 | H32: 19.5 | I32: =Cifras_Originales!G13+Cifras_Originales!G14 -> -20.86 | J32: Adquisiones | K32: =-22.152 -> -22.152 | L32: -10.981 | N32: =C32/C31-1 -> 0.21837529 | O32: =D32/D31-1 -> 0.31077097 | P32: =E32/E31-1 -> #DIV/0! | Q32: =F32/F31-1 -> -0.18412188 | R32: =H32/H31-1 -> 0.26623377 | S32: =I32/I31-1 -> -0.50565206
B33: =B32+1 -> 2019 | C33: =Cifras_Originales!F6 -> 913.734 | D33: =Cifras_Originales!F$8/OP!C33 -> 0.098246317 | E33: =[2]Cifras_Originales!F17 -> 0 | F33: =Cifras_Originales!F22-Cifras_Originales!G22+Cifras_Originales!F18+Cifras_Originales!F17 -> -7.536 | G33: =Cifras_en_Millones!G60/Cifras_en_Millones!G45 -> 0.55098731 | H33: 23.2 | I33: =Cifras_Originales!F13+Cifras_Originales!F14 -> -32.077 | J33: Dividends | K33: 0 | L33: 0 | N33: =C33/C32-1 -> 0.17320915 | O33: =D33/D32-1 -> -0.25097426 | P33: =E33/E32-1 -> #DIV/0! | Q33: =F33/F32-1 -> -1.2854437 | R33: =H33/H32-1 -> 0.18974359 | S33: =I33/I32-1 -> 0.53772771
B34: =B33+1 -> 2020 | C34: =Cifras_Originales!E6 -> 1091.721 | D34: =Cifras_Originales!E$8/OP!C34 -> 0.1962342 | E34: 0 | F34: =Cifras_Originales!E22-Cifras_Originales!F22+Cifras_Originales!E18+Cifras_Originales!E17 -> 180.768 | G34: =Cifras_en_Millones!F60/Cifras_en_Millones!F45 -> 0.24218558 | H34: 24.6 | I34: =Cifras_Originales!E13+Cifras_Originales!E14 -> -15.566 | J34: Stock Repurchases | K34: =Cifras_Originales!B18 -> 0 | L34: =[2]Cifras_Originales!C18 -> 0 | N34: =C34/C33-1 -> 0.19479083 | O34: =D34/D33-1 -> 0.99736956 | P34: =E34/E33-1 -> #DIV/0! | Q34: =F34/F33-1 -> -24.987261 | R34: =H34/H33-1 -> 0.060344828 | S34: =I34/I33-1 -> -0.51473018
B35: =B34+1 -> 2021 | C35: =Cifras_Originales!D6 -> 1410.989 | D35: =Cifras_Originales!D$8/OP!C35 -> 0.19485481 | E35: 0 | F35: =Cifras_Originales!D22-Cifras_Originales!E22+Cifras_Originales!D17+Cifras_Originales!D18 -> 58.906 | G35: =Cifras_en_Millones!E60/Cifras_en_Millones!E45 -> 0.17002382 | H35: 25.7 | I35: =Cifras_Originales!D13+Cifras_Originales!D14 -> -56.121 | J35: Endeudamiento Neto | K35: =Cifras_en_Millones!C59 -> -262.847 | L35: =Cifras_en_Millones!D59 -> -70.664 | N35: =C35/C34-1 -> 0.29244468 | O35: =D35/D34-1 -> -0.007029295 | P35: =E35/E34-1 -> #DIV/0! | Q35: =F35/F34-1 -> -0.6741348 | R35: =H35/H34-1 -> 0.044715447 | S35: =I35/I34-1 -> 2.6053578
B36: =B35+1 -> 2022 | C36: =Cifras_Originales!C6 -> 1595.222 | D36: =Cifras_Originales!C$8/OP!C36 -> 0.079212172 | E36: 0 | F36: =Cifras_Originales!C22-Cifras_Originales!D22+Cifras_Originales!D17+Cifras_Originales!D18 -> -77.448 | G36: =Cifras_en_Millones!D60/Cifras_en_Millones!D45 -> 0.15237958 | H36: 32.8 | I36: =Cifras_Originales!C13+Cifras_Originales!C14 -> -45.929 | J36: Otros Financiemientos | N36: =C36/C35-1 -> 0.13057012 | O36: =D36/D35-1 -> -0.59348106
B37: =B36+1 -> 2023 | C37: =Cifras_Originales!B6 -> 1658.713 | D37: =Cifras_Originales!B$8/OP!C37 -> 0.13592345 | E37: 0 | F37: =Cifras_Originales!B22-Cifras_Originales!C22+Cifras_Originales!B17+Cifras_Originales!B18 -> 204.219 | G37: =Cifras_en_Millones!C60/Cifras_en_Millones!C45 -> 0.13576479 | H37: 41.2 | I37: =Cifras_Originales!B13+Cifras_Originales!B14 -> -50.672 | N37: =C37/C36-1 -> 0.03980073 | O37: =D37/D36-1 -> 0.7159415
B38: 2024 Est. | C38: =DCFF!H7 -> 1829.873 | D38: =DCFF!H8 -> 0.16
B39: CAGR | C39: =(C37/C32)^(1/5)-1 -> 0.16322943 | D39: =(D37/D30)^(1/7)-1 -> 0.033791142 | J39: FX
B40: AAG | C40: =AVERAGE(N30:N37) -> 0.19700884 | D40: =AVERAGE(O31:O37) -> 0.1573748 | J40: D Cash and Equivalents | K40: =K28+K29+K30+K33+K34+K35+K36+K39 -> -18.031 | L40: =L28+L29+L30+L33+L34+L35+L36+L39 -> -54.717
B41: CVAR | C41: =STDEV(C26:C37)/AVERAGE(C26:C37) -> 0.61048712 | D41: =STDEV(D26:D37)/AVERAGE(D26:D37) -> 0.37893357 | J41: Inv/D Vts | K41: =SUM(I33:I37)/(C37-C32) -> -0.22771855 | L41: =(SUM(I33:I37)-SUM(H33:H37))/(C37-C32) -> -0.39535505
B42: Último Año | C42: =C37/C36-1 -> 0.03980073 | D42: =D37/D36-1 -> 0.7159415 | J42: t inversiones; t adq. neto dep. | K42: =K41/E14 -> -1.6662722 | L42: =L41/E14 -> -2.8929093
...

Sheet Segments
B2: Regions in Thousands (2023) | L2: Proyectado | N2: Escenario de estrés | X2: Escenario de estrés
C3: 2023 | D3: =C3-1 -> 2022 | E3: Ut. Operativa | F3: % Vts | G3: Margen | H3: Crec | L3: Crecimiento | M3: 2021 (Real) | N3: 2022 (Real) | O3: 2023 (Real) | P3: 2024 (Est) | Q3: 2025 | R3: 2026 | S3: 2027 | T3: 2028 | V3: Márgenes (regional) | W3: 2021 (Real) | X3: 2022 (Real) | Y3: 2023 (Real) | Z3: 2024 (Est) | AA3: 2025 | AB3: 2026 | AC3: 2027 | AD3: 2028
B4: United States | C4: 1398925 | D4: 1394026 | F4: =$C$4/$C$14 -> 0.84337978 | G4: - | H4: =C4/D4-1 -> 0.0035142817 | J4: =IF(C4="","",IF(F4=0,"NA",TEXT(F4,"0%"))&"; "&IF(G4=0,"NA",TEXT(G4,"0.0%"))&"; "&IF(H4=0,"NA",TEXT(H4,"0%"))) -> 84%; -; 0% | L4: =B17 -> Coolers & Equipment | M4: 551861 | N4: 612525 | O4: 597511 | V4: =B4 -> United States | W4: 1277177 | X4: 1394026 | Y4: 1398925
B5: Internacional | C5: 259788 | D5: 201196 | F5: =$C$5/$C$14 -> 0.15662022 | G5: - | H5: =C5/D5-1 -> 0.29121851 | J5: =IF(C5="","",IF(F5=0,"NA",TEXT(F5,"0%"))&"; "&IF(G5=0,"NA",TEXT(G5,"0.0%"))&"; "&IF(H5=0,"NA",TEXT(H5,"0%"))) -> 16%; -; 29% | L5: =B18 -> Drinkware | M5: 832428 | N5: 947221 | O5: 1022982 | V5: =B5 -> Internacional | W5: 133812 | X5: 201196 | Y5: 259788
J6: =IF(C6="","",IF(F6=0,"NA",TEXT(F6,"0%"))&"; "&IF(G6=0,"NA",TEXT(G6,"0.0%"))&"; "&IF(H6=0,"NA",TEXT(H6,"0%"))) | L6: =B19 -> Others | M6: 26700 | N6: 35476 | O6: 38220 | V6: =B6 -> 0
J7: =IF(C7="","",IF(F7=0,"NA",TEXT(F7,"0%"))&"; "&IF(G7=0,"NA",TEXT(G7,"0.0%"))&"; "&IF(H7=0,"NA",TEXT(H7,"0%"))) | L7: =B20 -> 0 | V7: =B7 -> 0
J8: =IF(C8="","",IF(F8=0,"NA",TEXT(F8,"0%"))&"; "&IF(G8=0,"NA",TEXT(G8,"0.0%"))&"; "&IF(H8=0,"NA",TEXT(H8,"0%"))) | L8: =B21 -> 0 | V8: =B8 -> 0
J9: =IF(C9="","",IF(F9=0,"NA",TEXT(F9,"0%"))&"; "&IF(G9=0,"NA",TEXT(G9,"0.0%"))&"; "&IF(H9=0,"NA",TEXT(H9,"0%"))) | L9: % vts. | V9: Margen Operativp | W9: =(W4*W12+W5*W13+W6*W14+W7*W15+W8*W16)/SUM(W12:W16)+W10 -> 1176876.9 | X9: =(#REF!*#REF!+#REF!*#REF!+X6*X14+X7*X15+X8*X16)/SUM(X12:X16)+X10 -> #REF! | Y9: =(X4*X12+X5*X13+Y6*Y14+Y7*Y15+Y8*Y16)/SUM(Y12:Y16)+Y10 -> 1243581.3 | Z9: =(Y4*Y12+Y5*Y13+Z6*Z14+Z7*Z15+Z8*Z16)/SUM(Z12:Z16)+Z10 -> #DIV/0! | AA9: =(AA4*AA12+AA5*AA13+AA6*AA14+AA7*AA15+AA8*AA16)/SUM(AA12:AA16)+AA10 -> #DIV/0! | AB9: =(AB4*AB12+AB5*AB13+AB6*AB14+AB7*AB15+AB8*AB16)/SUM(AB12:AB16)+AB10 -> #DIV/0! | AC9: =(AC4*AC12+AC5*AC13+AC6*AC14+AC7*AC15+AC8*AC16)/SUM(AC12:AC16)+AC10 -> #DIV/0! | AD9: =(AD4*AD12+AD5*AD13+AD6*AD14+AD7*AD15+AD8*AD16)/SUM(AD12:AD16)+AD10 -> #DIV/0!
J10: =IF(C10="","",IF(F10=0,"NA",TEXT(F10,"0%"))&"; "&IF(G10=0,"NA",TEXT(G10,"0.0%"))&"; "&IF(H10=0,"NA",TEXT(H10,"0%"))) | L10: =B17 -> Coolers & Equipment | N10: =$D$17/$D$27 -> 0.38397477 | O10: =$C$17/$C$27 -> 0.36022567 | V10: Ajuste R&D | W10: =(-6200-18752)/274515 -> -0.090894851 | X10: =(-6143-21914)/365817 -> -0.076696818 | Y10: =(-7207-26251)/394328 -> -0.084848147 | Z10: -0.1 | AA10: -0.1 | AB10: -0.1 | AC10: -0.1 | AD10: -0.1
J11: =IF(C11="","",IF(F11=0,"NA",TEXT(F11,"0%"))&"; "&IF(G11=0,"NA",TEXT(G11,"0.0%"))&"; "&IF(H11=0,"NA",TEXT(H11,"0%"))) | L11: =B18 -> Drinkware | N11: =$D$18/$D$27 -> 0.59378632 | O11: =$C$18/$C$27 -> 0.61673237 | V11: % vts.
J12: =IF(C12="","",IF(F12=0,"NA",TEXT(F12,"0%"))&"; "&IF(G12=0,"NA",TEXT(G12,"0.0%"))&"; "&IF(H12=0,"NA",TEXT(H12,"0%"))) | L12: =B19 -> Others | N12: =$D$19/$D$27 -> 0.022238911 | O12: =$C$19/$C$27 -> 0.023041961 | V12: =V4 -> United States | W12: =1277177/1410989 -> 0.90516439 | X12: =$D$4/$D$14 -> 0.87387586 | Y12: =$C$4/C$14 -> 0.84337978
J13: =IF(C13="","",IF(F13=0,"NA",TEXT(F13,"0%"))&"; "&IF(G13=0,"NA",TEXT(G13,"0.0%"))&"; "&IF(H13=0,"NA",TEXT(H13,"0%"))) | L13: =B20 -> 0 | V13: =V5 -> Internacional | W13: =122812/1410989 -> 0.087039658 | X13: =$D$5/$D$14 -> 0.12612414 | Y13: =$C$5/$C$14 -> 0.15662022
B14: TOTAL | C14: =SUM(C4:C12) -> 1658713 | D14: =SUM(D4:D12) -> 1595222 | E14: 225458 | F14: =C14/SUM($C$4:$C$13) -> 1 | G14: =E14/C14 -> 0.13592345 | H14: =C14/D14-1 -> 0.03980073 | L14: =B21 -> 0 | V14: =V6 -> 0
B15: Products in Thousands (2023) | M15: =SUM(#REF!) -> #REF! | N15: =SUM(N10:N14) -> 1 | O15: =SUM(O10:O14) -> 1 | P15: =SUM(P10:P14) -> 0 | Q15: =SUM(Q10:Q14) -> 0 | R15: =SUM(R10:R14) -> 0 | S15: =SUM(S10:S14) -> 0 | T15: =SUM(T10:T14) -> 0 | V15: =V7 -> 0
C16: =C3 -> 2023 | D16: =C16-1 -> 2022 | E16: Ut. Op. | F16: % Vts | G16: Margen | H16: Crec | N16: =N15/M15-1 -> #REF! | O16: =O15/N15-1 -> 0 | P16: =P15/O15-1 -> -1 | Q16: =Q15/P15-1 -> #DIV/0! | R16: =R15/Q15-1 -> #DIV/0! | S16: =S15/R15-1 -> #DIV/0! | T16: =T15/S15-1 -> #DIV/0! | V16: =V8 -> 0
B17: Coolers & Equipment | C17: 597511 | D17: 612525 | F17: =$C$17/$C$27 -> 0.36022567 | G17: - | H17: =C17/D17-1 -> -0.024511653 | J17: =IF(C17="","",IF(F17=0,"NA",TEXT(F17,"0%"))&"; "&IF(G17=0,"NA",TEXT(G17,"0.0%"))&"; "&IF(H17=0,"NA",TEXT(H17,"0%"))) -> 36%; -; -2% | W17: =SUM(W12:W16) -> 0.99220405 | X17: =SUM(X12:X16) -> 1 | Y17: =SUM(Y12:Y16) -> 1 | Z17: =SUM(Z12:Z16) -> 0 | AA17: =SUM(AA12:AA16) -> 0 | AB17: =SUM(AB12:AB16) -> 0 | AC17: =SUM(AC12:AC16) -> 0 | AD17: =SUM(AD12:AD16) -> 0
B18: Drinkware | C18: 1022982 | D18: 947221 | F18: =$C$18/$C$27 -> 0.61673237 | G18: - | H18: =C18/D18-1 -> 0.079982391 | J18: =IF(C18="","",IF(F18=0,"NA",TEXT(F18,"0%"))&"; "&IF(G18=0,"NA",TEXT(G18,"0.0%"))&"; "&IF(H18=0,"NA",TEXT(H18,"0%"))) -> 62%; -; 8%
B19: Others | C19: 38220 | D19: 35476 | F19: =$C$19/$C$27 -> 0.023041961 | G19: - | H19: =C19/D19-1 -> 0.077348066 | J19: =IF(C19="","",IF(F19=0,"NA",TEXT(F19,"0%"))&"; "&IF(G19=0,"NA",TEXT(G19,"0.0%"))&"; "&IF(H19=0,"NA",TEXT(H19,"0%"))) -> 2%; -; 8%
J20: =IF(C20="","",IF(F20=0,"NA",TEXT(F20,"0%"))&"; "&IF(G20=0,"NA",TEXT(G20,"0.0%"))&"; "&IF(H20=0,"NA",TEXT(H20,"0%")))
J21: =IF(C21="","",IF(F21=0,"NA",TEXT(F21,"0%"))&"; "&IF(G21=0,"NA",TEXT(G21,"0.0%"))&"; "&IF(H21=0,"NA",TEXT(H21,"0%")))
J22: =IF(C22="","",IF(F22=0,"NA",TEXT(F22,"0%"))&"; "&IF(G22=0,"NA",TEXT(G22,"0.0%"))&"; "&IF(H22=0,"NA",TEXT(H22,"0%")))
J23: =IF(C23="","",IF(F23=0,"NA",TEXT(F23,"0%"))&"; "&IF(G23=0,"NA",TEXT(G23,"0.0%"))&"; "&IF(H23=0,"NA",TEXT(H23,"0%")))
J24: =IF(C24="","",IF(F24=0,"NA",TEXT(F24,"0%"))&"; "&IF(G24=0,"NA",TEXT(G24,"0.0%"))&"; "&IF(H24=0,"NA",TEXT(H24,"0%")))
J25: =IF(C25="","",IF(F25=0,"NA",TEXT(F25,"0%"))&"; "&IF(G25=0,"NA",TEXT(G25,"0.0%"))&"; "&IF(H25=0,"NA",TEXT(H25,"0%")))
J26: =IF(C26="","",IF(F26=0,"NA",TEXT(F26,"0%"))&"; "&IF(G26=0,"NA",TEXT(G26,"0.0%"))&"; "&IF(H26=0,"NA",TEXT(H26,"0%")))
B27: TOTAL | C27: =SUM(C17:C26) -> 1658713 | D27: =SUM(D17:D26) -> 1595222 | E27: 225458 | F27: =C27/SUM(C17:C26) -> 1 | G27: =E27/C27 -> 0.13592345 | H27: =C27/D27-1 -> 0.03980073

Sheet Peers
A2: Multiplos (USD) | B2: #VALUE! | C2: #VALUE! | D2: #VALUE! | E2: VSTO
B3: Yeti Holdings, Inc. | C3: Domestic Group AB | D3: Acushnet Holdings Corp. | E3: Vista Outdoor Inc.
A4: Ventas 2024 | B4: =B27 -> 1658.713 | C4: =C27 -> 27775 | D4: =D27 -> 2381.995 | E4: =E27 -> 2746.063
A5: Crecimiento 2024 | B5: =B28/B29-1 -> 0.03980073 | C5: =C28/C29-1 -> -0.066825695 | D5: =D28/D29-1 -> 0.049181707 | E5: =E28/E29-1 -> -0.10836523
A6: Crecimiento (48 meses) | B6: =B28/B31-1 -> 0.51935614 | C6: =C28/C31-1 -> 0.71376566 | D6: =D28/D31-1 -> 0.47750949 | E6: =E28/E31-1 -> 0.56393209
A7: Deuda/Activos | B7: 122278 | C7: 122278 | D7: 122278 | E7: 122278
A8: Deuda/EBITDA | B8: 323888 | C8: 323888 | D8: 323888 | E8: 323888
A9: (Capex + Adq.)/Revenue | B9: =-(B35+B36)/B28 -> -0.043903918 | C9: =-(C35+C36)/C28 -> -0.010513051 | D9: =-(D35+D36)/D28 -> -0.042233086 | E9: =-(E35+E36)/E28 -> -0.017119782
A10: ROA (p) | B10: =B37/B33 -> 0.13096365 | C10: =C37/C33 -> 0.023216886 | D10: =D37/D33 -> 0.090331853 | E10: =E37/E33 -> -0.0022914776
A11: ROIC (p) | B11: =B38/B35 -> 3.3430099 | C11: =C38/C35 -> 0.75899281 | D11: =D38/D35 -> 3.2152221 | E11: =E38/E35 -> 1.9464204
A12: Margen Operativo (p) | B12: =AVERAGE(B39:B41) -> 0.13666348 | C12: =AVERAGE(C39:C41) -> 0.13610568 | D12: =AVERAGE(D39:D41) -> 0.11647496 | E12: =AVERAGE(E39:E41) -> 0.088547764
A13: Margen Operativo 2023 | B13: =B39 -> 0.13592345 | C13: =C39 -> 0.11866787 | D13: =D39 -> 0.11977565 | E13: =E39 -> 0.018372849
A14: Float | B14: =B42 -> 0.98361429 | C14: =C42 -> 0.93020344 | D14: =D42 -> 0.45509868 | E14: N/A
A15: b | B15: =B43 -> 2.14 | C15: =C43 -> 1.68 | D15: =D43 -> 0.87 | E15: N/A
A16: Precio/Utilidad | B16: 18.98 | C16: 15.72 | D16: 21.05 | E16: NA
A17: Precio/Ventas | B17: {=_FV(B2,"Market cap",TRUE)/(1000000*B4)} -> 1.8982914 | C17: {=_FV(C2,"Market cap",TRUE)/(1000000*C4)} -> 0.041496346 | D17: {=_FV(D2,"Market cap",TRUE)/(1000000*D4)} -> 1.6877832 | E17: N/A
A18: EV/Activos | B18: =B45/B33 -> 3.3765241 | C18: =C45/C33 -> 1.9379272 | D18: =D45/D33 -> 0.21259481 | E18: N/A
A19: EV/EBITDA | B19: =B45/B34 -> 16.080476 | C19: =C45/C34 -> 51.289157 | D19: =D45/D34 -> 1.3979274 | E19: N/A
A20: Div. Yield | B20: =B46 -> N/A | C20: =C46 -> 0.0351 | D20: =D46 -> 0.0131 | E20: N/A
A21: Año Fiscal | B21: 12-2023 | C21: 12-2023 | D21: 12-2023 | E21: 03-2024
B23: *p = average for the last 3 years
B24: **in USD
C25: In millions SEK
A26: in millions USD | B26: YETI holdings | C26: Dometic Group AB | D26: =D3 -> Acushnet Holdings Corp. | E26: =E3 -> Vista Outdoor Inc.
A27: Total Revenue | B27: 1658.713 | C27: 27775 | D27: 2381.995 | E27: 2746.063
A28: Revenue from 23 | B28: 1658.713 | C28: 27775 | D28: 2381.995 | E28: 2746.063
A29: Revenue from 22 | B29: 1595.222 | C29: 29764 | D29: 2270.336 | E29: 3079.807
A30: Revenue from 21 | B30: 1410.989 | C30: 21516 | D30: 2147.93 | E30: 3044.621
A31: Revenue from 20 | B31: 1091.721 | C31: 16207 | D31: 1612.169 | E31: 1755.871
A32: Debt | B32: 78.645 | C32: 12029 | D32: 701.167 | E32: 717.238
A33: Assets | B33: 1297.192 | C33: 2196.677 | D33: 2196.667 | E33: 2402.38
A34: EBITDA | B34: =169.885+56.061+46.434 -> 272.38 | C34: 83 | D34: =198.429+42.993+41.288+51.356 -> 334.066 | E34: =-5.505-8.979+62.949+49.145+50.146 -> 147.756
A35: CAPEX | B35: 50.672 | C35: 278 | D35: 75.364 | E35: 30.534
A36: Acquisitions | B36: 22.152 | C36: 14 | D36: 25.235 | E36: 16.478
A37: Net income | B37: 169.885 | C37: 51 | D37: 198.429 | E37: -5.505
A38: net operating profit after taxes | B38: =225.458-56.061 -> 169.397 | C38: =242-31 -> 211 | D38: =285.305-42.993 -> 242.312 | E38: =50.453+8.979 -> 59.432
A39: Operating margin 23 | B39: =225.458/1658.713 -> 0.13592345 | C39: =3296/C28 -> 0.11866787 | D39: =285.305/D28 -> 0.11977565 | E39: =50.453/E28 -> 0.018372849
A40: Operating margin 2022 | B40: =126.361/1595.222 -> 0.079212172 | C40: =3399/C29 -> 0.11419836 | D40: =259.435/D29 -> 0.11427163 | E40: =107.855/E29 -> 0.035020052
A41: Operating margin 21 | B41: =274.938/B30 -> 0.19485481 | C41: =3775/C30 -> 0.17545083 | D41: =247.823/D30 -> 0.1153776 | E41: =646.222/E30 -> 0.21225039
A42: float | B42: =83.44/84.83 -> 0.98361429 | C42: =297.2/319.5 -> 0.93020344 | D42: =27.67/60.8 -> 0.45509868
...

Sheet Acuerdo
A1: Invertir
A2: NO invertir
A3: Mantener sin elevar posición
A4: Mantener (y seguir comprando)
A5: Liquidar
A6: PENDIENTE

Sheet DCF
A1: Discounted Cash Flow
A3: Ventas | E3: Margen Operativo
A16: Inversiones | E16: Utilidad Neta
D31: 0.001 | E31: =1/((1+$B$59+$D31)^(E35-2021)) -> 0.92250923 | F31: =1/((1+$B$59+$D31)^(F35-2021)) -> 0.85102327 | G31: =1/((1+$B$59+$D31)^(G35-2021)) -> 0.78507682 | H31: =1/((1+$B$59+$D31)^(H35-2021)) -> 0.72424061 | I31: =1/((1+$B$59+$D31)^(I35-2021)) -> 0.66811864 | J31: =1/((1+$B$59+$D31)^(J35-2021)) -> 0.61634561 | K31: =1/((1+$B$59+$D31)^(K35-2021)) -> 0.56858451 | L31: =1/((1+$B$59+$D31)^(L35-2021)) -> 0.52452446 | ... AC31: =1/((1+$B$59+$D31)^(AC35-2021)) -> 0.13312755
D32: 0.005 | E32: =1/((1+$B$59+$D32)^(E35-2021)) -> 0.91911765 | F32: =1/((1+$B$59+$D32)^(F35-2021)) -> 0.84477725 | G32: =1/((1+$B$59+$D32)^(G35-2021)) -> 0.77644968 | H32: =1/((1+$B$59+$D32)^(H35-2021)) -> 0.7136486 | I32: =1/((1+$B$59+$D32)^(I35-2021)) -> 0.65592702 | J32: =1/((1+$B$59+$D32)^(J35-2021)) -> 0.6028741 | K32: =1/((1+$B$59+$D32)^(K35-2021)) -> 0.55411223 | L32: =1/((1+$B$59+$D32)^(L35-2021)) -> 0.50929433 | ... AC32: =1/((1+$B$59+$D32)^(AC35-2021)) -> 0.12141647
D33: Normal | E33: =1/((1+$B$59)^(E35-2021)) -> 0.92336103 | F33: =1/((1+$B$59)^(F35-2021)) -> 0.8525956 | G33: =1/((1+$B$59)^(G35-2021)) -> 0.78725355 | H33: =1/((1+$B$59)^(H35-2021)) -> 0.72691926 | I33: =1/((1+$B$59)^(I35-2021)) -> 0.67120892 | J33: =1/((1+$B$59)^(J35-2021)) -> 0.61976816 | K33: =1/((1+$B$59)^(K35-2021)) -> 0.57226977 | L33: =1/((1+$B$59)^(L35-2021)) -> 0.5284116 | ... AC33: =1/((1+$B$59)^(AC35-2021)) -> 0.13623496
B35: 2019 (Real) | C35: 2020 (Real) | D35: 2021 | E35: =D35+1 -> 2022 | F35: =E35+1 -> 2023 | G35: =F35+1 -> 2024 | H35: =G35+1 -> 2025 | I35: =H35+1 -> 2026 | J35: =I35+1 -> 2027 | K35: =J35+1 -> 2028 | L35: =K35+1 -> 2029 | ... AC35: =AB35+1 -> 2046
A36: Crecimiento | B36: =#REF! -> #REF! | C36: =#REF! -> #REF! | D36: 0.35 | E36: 0.034 | F36: 0.095 | G36: 0.095 | H36: 0.095 | I36: 0.095 | J36: 0.095 | K36: 0.08 | L36: 0.06 | M36: 0.05 | N36: 0.04 | O36: 0.035 | P36: 0.035 | Q36: 0.035 | R36: 0.035 | S36: 0.035 | T36: 0.035 | U36: 0.035 | V36: 0.035 | W36: 0.035 | X36: 0.035 | Y36: 0.035 | Z36: 0.035 | AA36: 0.035 | AB36: 0.035 | AC36: 0.035
A37: Ventas | B37: =#REF! -> #REF! | C37: =#REF! -> #REF! | D37: =#REF!*(1+D36) -> #REF! | E37: =D37*(1+E36) -> #REF! | F37: =E37*(1+F36) -> #REF! | G37: =F37*(1+G36) -> #REF! | H37: =G37*(1+H36) -> #REF! | I37: =H37*(1+I36) -> #REF! | J37: =I37*(1+J36) -> #REF! | K37: =J37*(1+K36) -> #REF! | L37: =K37*(1+L36) -> #REF! | ... AC37: =AB37*(1+AC36) -> #REF!
A38: Margen Operativo | B38: =+#REF! -> #REF! | C38: =+#REF! -> #REF! | D38: =108166.4/365513.2 -> 0.29593022 | E38: =108162.8/377959.8 -> 0.28617541 | F38: 0.27 | G38: 0.275 | H38: 0.26 | I38: 0.255 | J38: 0.25 | K38: 0.25 | L38: 0.25 | M38: 0.25 | N38: 0.25 | O38: 0.25 | P38: 0.25 | Q38: 0.25 | R38: 0.25 | S38: 0.25 | T38: 0.25 | U38: 0.25 | V38: 0.25 | W38: 0.25 | X38: 0.25 | Y38: 0.25 | Z38: 0.25 | AA38: 0.25 | AB38: 0.25 | AC38: 0.25
A39: EBIT | B39: 63930 | C39: 66288 | D39: =D37*D38 -> #REF! | E39: =E37*E38 -> #REF! | F39: =F37*F38 -> #REF! | G39: =G37*G38 -> #REF! | H39: =H37*H38 -> #REF! | I39: =I37*I38 -> #REF! | J39: =J37*J38 -> #REF! | K39: =K37*K38 -> #REF! | ... AC39: =AC37*AC38 -> #REF!
A40: Dep&Amort | B40: =#REF! -> #REF! | C40: =#REF! -> #REF! | D40: 11000 | E40: =D40*(1+E36*$H$59) -> 11374 | F40: =E40*(1+F36*$H$59) -> 12454.53 | G40: =F40*(1+G36*$H$59) -> 13637.71 | H40: =G40*(1+H36*$H$59) -> 14933.293 | I40: =H40*(1+I36*$I$59) -> 16351.956 | J40: =I40*(1+J36*$I$59) -> 17905.391 | K40: =J40*(1+K36*$I$59) -> 19337.823 | L40: =K40*(1+L36*$I$59) -> 20498.092 | M40: =L40*(1+M36*$I$59) -> 21522.997 | N40: =M40*(1+N36*$I$59) -> 22383.917 | O40: =N40*(1+O36*$I$59) -> 23167.354 | P40: =O40*(1+P36*$I$59) -> 23978.211 | ... AC40: =AB40*(1+AC36*$I$59) -> 37500.868
A41: EBIDTA | B41: =+B39+B40 -> #REF! | C41: =+C39+C40 -> #REF! | D41: =D39+D40 -> #REF! | E41: =E39+E40 -> #REF! | F41: =F39+F40 -> #REF! | G41: =G39+G40 -> #REF! | H41: =H39+H40 -> #REF! | I41: =I39+I40 -> #REF! | J41: =J39+J40 -> #REF! | K41: =K39+K40 -> #REF! | ... AC41: =AC39+AC40 -> #REF!
A42: CIF | B42: -1385 | C42: -890 | D42: =(C48)*$H$60 -> -1124.36 | E42: =(D48)*$H$60 -> -1113.1164 | F42: =(E48)*$H$60 -> -1113.1164 | G42: =(F48)*$H$60 -> -1113.1164 | H42: =(G48)*$H$60 -> -1113.1164 | I42: =(H48)*$H$60 -> -1113.1164 | J42: =(I48)*$H$60 -> -1113.1164 | K42: =(J48)*$H$60 -> -1113.1164 | ... AC42: =(AB48)*$H$60 -> -1113.1164
A43: Otros Gastos | B43: =-422-2817 -> -3239 | C43: =87-3634 -> -3547 | D43: =-C43*(1+D36) -> 4788.45 | E43: =D43*(1+E36*0.5) -> 4869.8537 | F43: =E43*(1+F36*0.5) -> 5101.1717 | G43: =F43*(1+G36*0.5) -> 5343.4774 | H43: =G43*(1+H36*0.5) -> 5597.2925 | I43: =H43*(1+I36*0.5) -> 5863.1639 | J43: =I43*(1+J36*0.5) -> 6141.6642 | K43: =J43*(1+K36*0.5) -> 6387.3308 | L43: =K43*(1+L36*0.5) -> 6578.9507 | ... AC43: =AB43*(1+AC36*0.5) -> 8922.7133
A44: Utilidad antes de Impuestos | B44: =B39-B42-B43 -> 68554 | C44: =C39-C42-C43 -> 70725 | D44: =D39-D42-D43 -> #REF! | E44: =E39-E42-E43 -> #REF! | F44: =F39-F42-F43 -> #REF! | G44: =G39-G42-G43 -> #REF! | H44: =H39-H42-H43 -> #REF! | I44: =I39-I42-I43 -> #REF! | ... AC44: =AC39-AC42-AC43 -> #REF!
A45: ISR & PTU | B45: 10481 | C45: 9680 | D45: =$H$61*D44 -> #REF! | E45: =$H$61*E44 -> #REF! | F45: =$H$61*F44 -> #REF! | G45: =$I$61*G44 -> #REF! | H45: =$I$61*H44 -> #REF! | I45: =$I$61*I44 -> #REF! | J45: =$I$61*J44 -> #REF! | K45: =$I$61*K44 -> #REF! | L45: =$I$61*L44 -> #REF! | M45: =$I$61*M44 -> #REF! | N45: =$I$61*N44 -> #REF! | ... AC45: =$I$61*AC44 -> #REF!
A46: Utilidad Neta | B46: =B44-B45 -> 58073 | C46: =C44-C45 -> 61045 | D46: =D44-D45 -> #REF! | E46: =E44-E45 -> #REF! | F46: =F44-F45 -> #REF! | G46: =G44-G45 -> #REF! | H46: =H44-H45 -> #REF! | I46: =I44-I45 -> #REF! | ... AC46: =AC44-AC45 -> #REF!
A47: Inversiones y Capex | B47: =#REF! -> #REF! | C47: =#REF! -> #REF! | D47: 10000 | E47: =D47*(1+E36*$H$62) -> 10408 | F47: =E47*(1+F36*$H$62) -> 11594.512 | G47: =F47*(1+G36*$H$62) -> 12916.286 | H47: =G47*(1+H36*$H$62) -> 14388.743 | I47: =H47*(1+I36*$H$62) -> 16029.06 | J47: =I47*(1+J36*$H$62) -> 17856.373 | K47: =J47*(1+K36*$H$62) -> 19570.584 | L47: =K47*(1+L36*$H$62) -> 20979.666 | ... AC47: =AB47*(1+AC36*$H$62) -> 43199.777
A48: Deuda + Lease Liabilities | B48: 108047 | C48: 112436 | D48: =C48*0.99 -> 111311.64 | E48: =D48 -> 111311.64 | F48: =E48 -> 111311.64 | G48: =F48 -> 111311.64 | H48: =G48 -> 111311.64 | I48: =H48 -> 111311.64 | J48: =I48 -> 111311.64 | K48: =J48 -> 111311.64 | L48: =K48 -> 111311.64 | ... AC48: =AB48 -> 111311.64
A49: Deuda/EBITDA | B49: =B48/B41 -> #REF! | C49: =C48/C41 -> #REF! | D49: =D48/D41 -> #REF! | E49: =E48/E41 -> #REF!
A50: FNP | B50: =#REF! -> #REF! | C50: =#REF! -> #REF! | D50: =D41-D42-D43-D45-D47+D48-C48 -> #REF! | E50: =E41-E42-E43-E45-E47+E48-D48 -> #REF! | F50: =F41-F42-F43-F45-F47+F48-E48 -> #REF! | G50: =G41-G42-G43-G45-G47+G48-F48 -> #REF! | H50: =H41-H42-H43-H45-H47+H48-G48 -> #REF! | I50: =I41-I42-I43-I45-I47+I48-H48 -> #REF! | J50: =J41-J42-J43-J45-J47+J48-I48 -> #REF! | K50: =K41-K42-K43-K45-K47+K48-J48 -> #REF! | ... AC50: =AC41-AC42-AC43-AC45-AC47+AC48-AB48 -> #REF!
A51: F(t) | B51: 0 | C51: 0 | D51: =C51*(1+$B$59)+D50 -> #REF! | E51: =D51*(1+$B$59)+E50 -> #REF! | F51: =E51*(1+$B$59)+F50 -> #REF! | G51: =F51*(1+$B$59)+G50 -> #REF! | H51: =G51*(1+$B$59)+H50 -> #REF! | I51: =H51*(1+$B$59)+I50 -> #REF! | J51: =I51*(1+$B$59)+J50 -> #REF! | K51: =J51*(1+$B$59)+K50 -> #REF! | ... AC51: =AB51*(1+$B$59)+AC50 -> #REF!
AB52: =AB51-AB48 -> #REF! | AC52: =AC50/(B59-AC36) -> #REF!
A53: EPS | C53: =1000000*C46/#REF! -> #REF! | D53: =1000000*D46/#REF! -> #REF! | E53: =1000000*E46/#REF! -> #REF! | F53: =1000000*F46/#REF! -> #REF!
A54: Consenso EPS | C54: 3.3 | D54: 5.6 | E54: 5.6
A55: E$/UN | D55: =$B$61/D46 -> #REF! | E55: =$B$61/E46 -> #REF! | F55: =$B$61/F46 -> #REF!
A56: EEV/EBIDA | D56: =($B$61+D48-D51)/D41 -> #REF! | E56: =($B$61+E48-E51)/E41 -> #REF! | F56: =($B$61+F48-F51)/F41 -> #REF!
C58: "TELP" | D58: CER | E58: D Analista | H58: CP | I58: LP
A59: Tasa de descuento: | B59: =SUM(C59:E59) -> 0.083 | C59: 0.0307 | D59: 0.0523 | E59: 0 | G59: Factor D&A | H59: 1 | I59: 1
G60: Factor CIF | H60: -0.01
A61: VPN*@i% | B61: =C62+C63 -> #REF! | C61: Normal | D61: =D31 -> 0.001 | E61: =D32 -> 0.005 | G61: Factor ISR | H61: 0.21 | I61: 0.23
A62: DCF 25Y | B62: =C62/B61 -> #REF! | C62: =AB52/(1+B59)^25 -> #REF! | D62: =SUMPRODUCT(E50:AB50,E31:AB31) -> #REF! | E62: =SUMPRODUCT(E50:AB50,E32:AB32) -> #REF! | G62: Factor inv | H62: 1.2
A63: Perpetuidad | B63: =1-B62 -> #REF! | C63: =AC52/(1+B59)^25 -> #REF! | D63: =(AC50/($B$59+D31-$AC$36))*AC31 -> #REF! | E63: =(AC50/($B$59+D32-$AC$36))*AC32 -> #REF! | G63: Suma D&A | H63: =SUM(40:40) -> #REF!
A64: VPN/Acción | B64: =1000000*B61/#REF! -> #REF! | D64: =1000000*SUM(D62:D63)/#REF! -> #REF! | E64: =1000000*SUM(E62:E63)/#REF! -> #REF! | G64: Suma Inv. | H64: =SUM(47:47) -> #REF!
B65: =B64/#REF!-1 -> #REF! | D65: =D64/B64-1 -> #REF! | E65: =E64/B64-1 -> #REF! | G65: Inv.+Goodwill | H65: =SUM(47:47)+(#REF!*#REF!) -> #REF!
A67: Duración | B67: =B62*D68+B63*D69 -> #REF! | E67: 1 | F67: 2 | G67: 3 | H67: 4 | I67: 5 | J67: 6 | K67: 7 | L67: 8 | M67: 9 | N67: 10 | O67: 11 | P67: 12 | Q67: 13 | R67: 14 | S67: 15 | T67: 16 | U67: 17 | V67: 18 | W67: 19 | X67: 20 | Y67: 21 | Z67: 22 | AA67: 23 | AB67: 24 | AC67: 25
A68: 0.001 | B68: =-$B$67*A68 -> #REF! | D68: =SUM(E68:AB68)/SUMPRODUCT(E50:AB50,E33:AB33) -> #REF! | E68: =E67*E50*E33 -> #REF! | F68: =F67*F50*F33 -> #REF! | G68: =G67*G50*G33 -> #REF! | H68: =H67*H50*H33 -> #REF! | I68: =I67*I50*I33 -> #REF! | J68: =J67*J50*J33 -> #REF! | K68: =K67*K50*K33 -> #REF! | L68: =L67*L50*L33 -> #REF! | ... AC68: =AC67*AC50*AC33 -> #REF!
A69: 0.005 | B69: =-$B$67*A69 -> #REF! | D69: =(1+B59)/B59+AC67 -> 38.048193

Sheet ESG
B2: Análisis ESG | J2: PARÁMETROS
C3: Impacto | D3: ¿Reporta? | E3: Ranking | F3: Mitigación | G3: Semáforo | H3: Comentarios | J3: IMPACTO | L3: RANKING | M3: MITIGACIÓN
B4: Ambiental | J4: NONE | K4: 0 | L4: "Best in class" | M4: Is there evidence of progam/plan/etc…
B5: Emisiones directas CO2 | C5: Low | D5: Yes | E5: Medium High | F5: Yes | H5: Scope 1 and 2 has been declining for the past 3 years | J5: LOW | K5: 1 | L5: Medium high
B6: Uso total de agua | C6: High | D6: Yes | E6: Medium | F6: No | H6: No mention of measures regarding. | J6: MEDIUM | K6: 2 | L6: Medium
B7: Total Energy Consumption | C7: Medium | D7: Yes | E7: Medium High | F7: Yes | H7: U.S operations are powered through 100% renewable energy. Globally, are purchasing REC's (Renewable Energy Certificates). In 2023, Renewable Energy makes 56% of total in use within the organization. | J7: HIGH | K7: 3 | L7: "Villain"
B8: Waste Management | C8: Medium | D8: Yes | E8: Medium | F8: Yes | H8: Has been decreasing since 2020 due to waste reduction efforts
B9: Land Degradation/Deforestation/Biodiversity loss/Animal sufering/… | C9: High | D9: No | E9: Medium | F9: No | H9: No policies in place | J9: TRAFFIC LIGHTS
B10: Social
B11: % Rotación de empleados | C11: Medium | D11: No | E11: Medium | F11: No | H11: Specifics are not disclosed, but is seen as a derirable employeer.
B12: Sueldos y compensaciones | C12: Low | D12: No | E12: Medium High | F12: Yes | H12: Provides market-competitive compensation, healthcare, 401(k) program, paid time off, bonding leave, as well as health, wellness, and financial planning programs.
B13: Temas de reputación | C13: Low | D13: N/A | E13: "Best in Class" | F13: Yes | H13: Selected as one of the Best Places to Work in 2024 by Glassdor.
B14: Temas de discriminación | C14: Medium | D14: Yes | E14: Medium | F14: Yes | H14: The company provides Employee Resource Groups that actively educate and discuss topics, widening perspetives. However, higher-up management positions are male dominated (only 30% women).
B15: Seguridad laboral | C15: Low | D15: Yes | E15: Medium High | F15: Yes | H15: Since 2021, 100% of U.S. employees in offices, stores and warehouses are covered by occupational health and safety management system. They also "report a 93% completion rate of safety training for relevant employees in the U.S."
B16: Daños a la salud | C16: Medium | D16: Yes | E16: Medium High | F16: Yes | H16: Cases of facilities not being compliant with expectations have risen in the past 4 years, with non-compliances becoming more and more severe (comparing critical and non-priority), with the biggest issue being Health, Safety, & Hygiene.
B17: PXP? | D17: Yes | E17: Medium High | F17: Yes | H17: "We provide a 401(k)-defined contribution plan covering substantially all our employees (…). Our contributions totaled approximately $2.0 million, $1.5 million, and $1.2 million for 2023, 2022, and 2021, respectively."
B18: Supply chain | C18: High | D18: Yes | E18: Medium | F18: No | H18: Yeti does not own any of the manufacturing facilities, having third-parties in China (the biggest), the Philippines, Vietnam, Taiwan, Poland, Mexico, Thailand and Malaysia.
B19: Community involvement | C19: Low | D19: Yes | E19: "Best in Class" | F19: Yes | H19: Has partherships with many foundations, promoting activities ranging from beach clean-ups, conservation and restoration programs; Donated $2.3 million to support organizations and individuals working to preserve the wild.
B20: Public Sector | C20: Medium | D20: Yes | E20: Medium High | F20: Yes | H20: No political contribuitions, corruption or customer privacy violations.
B21: Litigios | C21: Low | D21: Yes | E21: Medium | F21: Yes | H21: The company had to recall more than 1.9 million coolers and cases as their magnets could detach, posing a deadly risk if swallowed. No injuries were reported, refunds and replacements were offered (March, 2023).Yeti sued TerraCycle US, who instead of destroying and recycling branded merchandise, illicitly sold them (July, 2023).
B22: Gobierno
B23: Diversidad (Género, edad, industria, región) | E23: Medium | F23: Yes | H23: As of 2023. out of all 11 directors, 10 are non executives and independent, 4 women on board, lacking in non-white representation.
B24: % independientes | E24: Medium High | F24: Yes | H24: 0.9091
B25: tiempo promedio como consejeros independientes | E25: Medium High | F25: Yes | H25: Average Director Tenure is 3.75 years.
B26: Salidas recientes de consejeros/C-level executives? | E26: Medium High | F26: Yes | H26: In 2022, Yeti announced the departure of the long-time CFO, this transition being part of a planned succession strategy
B27: CEO/Chairman | E27: Medium High | F27: Yes | H27: Stable leadership
B28: Transparencia (segmentos, fuente de riqueza, adquisiciones, otros) | E28: Medium | F28: No | H28: In the Sustainability Report, Water Use and Employee Turnover were not present. The 10k lacks certain detailed metrics.
B29: Tiempo que tardan en reportar luego del final del trimestre/año | E29: Medium High | F29: Yes | H29: Within expected window (3 months)
B30: Participación adicional del CEO en otros consejos o excesiva del Ch. | E30: "Best in Class" | F30: Yes | H30: No external commitments
B31: Auditoría/Consultoría | D31: Yes | E31: Medium High | F31: Yes | H31: PricewaterhouseCoopers LLp (one of the Big 4, stellar reputation) has been Yeti's auditor since 2021. No over-riliance on external consultants.
B32: Esquemas de compensación al management | C32: Low | D32: Yes | E32: Medium High | F32: Yes | H32: Pay-for-performance aligment (Cash/Short Term - net sales/operating income targets; Equity/Long term PBRSUs [Performance-Based Restricted Stock Units] requiring 90% target performance, with 200% cap, excludes stock options to reduce excessive risk taking)

Sheet DCFF
C1: VALUATION MODEL
H3: SHORT TERM | M3: MEDIUM TERM | W3: LONG TERM
D4: =D20/D7 -> 0.0082521084 | E4: =E20/E7 -> 0.010966776 | F4: =F20/F7 -> 0.011157695 | G4: =G20/G7 -> 0.017965736 | H4: =H20/H7 -> 0.022252364 | I4: =I20/I7 -> 0.02 | J4: =J20/J7 -> 0.02 | K4: =K20/K7 -> 0.02 | ... AF4: =AF20/AF7 -> 0.015
A5: Section | B5: Line # | C5: ITEM | D5: 2020 (Real) | E5: 2021 (Real) | F5: 2022 (Real) | G5: 2023 (Real) | H5: 2024 | I5: =+H5+1 -> 2025 | J5: =+I5+1 -> 2026 | K5: =+J5+1 -> 2027 | L5: =+K5+1 -> 2028 | M5: =+L5+1 -> 2029 | N5: =+M5+1 -> 2030 | O5: =+N5+1 -> 2031 | P5: =+O5+1 -> 2032 | ... AF5: =+AE5+1 -> 2048 | AG5: Notes
A6: INCOME STATEMENT | B6: 1 | C6: Growth | D6: =Cifras_en_Millones!F6 -> 0.19479083 | E6: =Cifras_en_Millones!E6 -> 0.29244468 | F6: =Cifras_en_Millones!D6 -> 0.13057012 | G6: =Cifras_en_Millones!C6 -> 0.03980073 | H6: 0.10318844 | I6: 0.18 | J6: 0.16 | K6: 0.14 | L6: 0.13 | M6: 0.11 | N6: 0.1 | O6: 0.09 | P6: 0.08 | Q6: 0.07 | R6: 0.07 | S6: 0.07 | T6: 0.06 | U6: 0.06 | V6: 0.05 | W6: 0.05 | X6: 0.05 | Y6: 0.05 | Z6: 0.04 | AA6: 0.04 | AB6: 0.04 | AC6: 0.04 | AD6: 0.03 | AE6: 0.03 | AF6: 0.03
B7: 2 | C7: Revenues/Sales | D7: =Cifras_Originales!E6 -> 1091.721 | E7: =Cifras_Originales!D6 -> 1410.989 | F7: =Cifras_Originales!C6 -> 1595.222 | G7: =Cifras_Originales!B6 -> 1658.713 | H7: =G7*(1+H6) -> 1829.873 | I7: =H7*(1+I6) -> 2159.2501 | J7: =I7*(1+J6) -> 2504.7302 | K7: =J7*(1+K6) -> 2855.3924 | L7: =K7*(1+L6) -> 3226.5934 | M7: =L7*(1+M6) -> 3581.5187 | N7: =M7*(1+N6) -> 3939.6705 | O7: =N7*(1+O6) -> 4294.2409 | ... AF7: =AE7*(1+AF6) -> 9919.1726
B8: 3 | C8: EBIT/Operating Margin | D8: 0.1972 | E8: 0.1982 | F8: 0.1608 | G8: 0.1398 | H8: 0.16 | I8: 0.16 | J8: 0.16 | K8: 0.16 | L8: 0.16 | M8: 0.16 | N8: 0.16 | O8: 0.16 | P8: 0.16 | Q8: 0.16 | R8: 0.16 | S8: 0.16 | T8: 0.16 | U8: 0.16 | V8: 0.16 | W8: 0.16 | X8: 0.16 | Y8: 0.16 | Z8: 0.16 | AA8: 0.16 | AB8: 0.16 | AC8: 0.16 | AD8: 0.16 | AE8: 0.16 | AF8: 0.16
B9: 4 | C9: EBIT | D9: =D7*D8 -> 215.28738 | E9: =E7*E8 -> 279.65802 | F9: =F7*F8 -> 256.5117 | G9: =G8*G7 -> 231.88808 | H9: =H8*H7 -> 292.77968 | I9: =I8*I7 -> 345.48002 | J9: =J8*J7 -> 400.75683 | K9: =K8*K7 -> 456.86278 | L9: =L8*L7 -> 516.25494 | M9: =M8*M7 -> 573.04299 | N9: =N8*N7 -> 630.34729 | ... AF9: =AF8*AF7 -> 1587.0676
B10: 5a | C10: (Dep&Amort) | D10: =Cifras_Originales!E11 -> -30.535 | E10: =Cifras_Originales!D11 -> -32.07 | F10: =Cifras_Originales!C11 -> -39.847 | G10: =Cifras_Originales!B11 -> -46.434 | H10: -48.132 | I10: {=H10*0.7+0.3*(-$D$51*AVERAGE(-1*(E23:H23)))} -> -44.07471 | J10: {=I10*0.7+0.3*(-$D$51*AVERAGE(-1*(F23:I23)))} -> -42.595812 | K10: {=J10*0.7+0.3*(-$D$51*AVERAGE(-1*(G23:J23)))} -> -44.002293 | L10: {=K10*0.7+0.3*(-$D$51*AVERAGE(-1*(H23:K23)))} -> -47.846296 | M10: {=L10*0.7+0.3*(-$D$51*AVERAGE(-1*(I23:L23)))} -> -52.835146 | N10: {=M10*0.7+0.3*(-$D$51*AVERAGE(-1*(J23:M23)))} -> -62.110791 | O10: {=N10*0.7+0.3*(-$D$51*AVERAGE(-1*(K23:N23)))} -> -74.732339 | P10: {=O10*0.7+0.3*(-$D$51*AVERAGE(-1*(L23:O23)))} -> -90.022167 | ... V10: {=U10*0.7+0.3*(-$D$51*AVERAGE(-1*(R23:U23)))} -> -179.35383 | W10: {=V10*0.7+0.3*(-$F$51*AVERAGE(-1*(S23:V23)))} -> -192.48191 | X10: {=W10*0.7+0.3*(-$F$51*AVERAGE(-1*(T23:W23)))} -> -211.66852 | Y10: {=X10*0.7+0.3*(-$F$51*AVERAGE(-1*(U23:X23)))} -> -235.44255 | Z10: {=Y10*0.7+0.3*(-$F$51*AVERAGE(-1*(V23:Y23)))} -> -262.78234 | AA10: {=Z10*0.7+0.3*(-$F$51*AVERAGE(-1*(W23:Z23)))} -> -292.87372 | AB10: {=AA10*0.7+0.3*(-$F$51*AVERAGE(-1*(X23:AA23)))} -> -318.81413 | AC10: {=AB10*0.7+0.3*(-$F$51*AVERAGE(-1*(Y23:AB23)))} -> -341.79056 | AD10: {=AC10*0.7+0.3*(-$F$51*AVERAGE(-1*(Z23:AC23)))} -> -362.61889 | ... AF10: {=AE10*0.7+0.3*(-$F$51*AVERAGE(-1*(AB23:AE23)))} -> -399.69346
B11: 5b | C11: (Stock based compensation) | D11: =-D20 -> -9.009 | E11: =-E20 -> -15.474 | F11: =-F20 -> -17.799 | G11: =-G20 -> -29.8 | H11: -40.719 | I11: =-$D$52*I7 -> -43.185003 | J11: =-$D$52*J7 -> -50.094603 | K11: =-$D$52*K7 -> -57.107848 | L11: =-$D$52*L7 -> -64.531868 | M11: =-$E$52*M7 -> -35.815187 | N11: =-$E$52*N7 -> -39.396705 | O11: =-$E$52*O7 -> -42.942409 | P11: =-$E$52*P7 -> -46.377802 | Q11: =-$E$52*Q7 -> -49.624248 | R11: =-$E$52*R7 -> -53.097945 | S11: =-$E$52*S7 -> -56.814801 | T11: =-$E$52*T7 -> -60.223689 | ... V11: =-$E$52*V7 -> -67.028966 | W11: =-$F$52*W7 -> -105.57062 | X11: =-$F$52*X7 -> -110.84915 | Y11: =-$F$52*Y7 -> -116.39161 | Z11: =-$F$52*Z7 -> -121.04727 | AA11: =-$F$52*AA7 -> -125.88917 | AB11: =-$F$52*AB7 -> -130.92473 | AC11: =-$F$52*AC7 -> -136.16172 | AD11: =-$F$52*AD7 -> -140.24657 | ... AF11: =-$F$52*AF7 -> -148.78759
B12: 6 | C12: EBIDTA | D12: =-D10+D9 -> 245.82238 | E12: =-E10+E9 -> 311.72802 | F12: =-F10+F9 -> 296.3587 | G12: =-G10+G9 -> 278.32208 | H12: =-H10+H9 -> 340.91168 | I12: =-I10+I9 -> 389.55473 | J12: =-J10+J9 -> 443.35264 | K12: =-K10+K9 -> 500.86507 | ... AF12: =-AF10+AF9 -> 1986.7611
B13: 7 | C13: (Net financing cost) | D13: =Cifras_Originales!E9 -> -9.155 | E13: =Cifras_Originales!D9 -> -3.339 | F13: =Cifras_Originales!C9 -> -4.466 | G13: =Cifras_Originales!B9 -> -0.942 | H13: =-$D$54*G38+G37*$D$55 -> -3.52226 | I13: =-$D$54*H38+H37*$D$55 -> -3.52226 | J13: =-$D$54*I38+I37*$D$55 -> -3.43786 | K13: =-$D$54*J38+J37*$D$55 -> -9.35346 | L13: =-$D$54*K38+K37*$D$55 -> -8.66906 | M13: =-$E$54*L38+L37*$E$55 -> -4.5547199 | N13: =-$E$54*M38+M37*$E$55 -> -3.3424452 | O13: =-$E$54*N38+N37*$E$55 -> -1.6066142 | P13: =-$E$54*O38+O37*$E$55 -> 1.4076075 | Q13: =-$E$54*P38+P37*$E$55 -> 1.7253311 | R13: =-$E$54*Q38+Q37*$E$55 -> 2.2732944 | S13: =-$E$54*R38+R37*$E$55 -> 2.5010553 | T13: =-$E$54*S38+S37*$E$55 -> 3.1580184 | ... V13: =-$E$54*U38+U37*$E$55 -> 5.2753978 | W13: =-$F$54*V38+V37*$F$55 -> 13.4803 | X13: =-$F$54*W38+W37*$F$55 -> 15.623977 | Y13: =-$F$54*X38+X37*$F$55 -> 18.148062 | Z13: =-$F$54*Y38+Y37*$F$55 -> 21.111599 | AA13: =-$F$54*Z38+Z37*$F$55 -> 24.675564 | AB13: =-$F$54*AA38+AA37*$F$55 -> 28.432466 | AC13: =-$F$54*AB38+AB37*$F$55 -> 32.450094 | AD13: =-$F$54*AC38+AC37*$F$55 -> 36.708902 | ... AF13: =-$F$54*AE38+AE37*$F$55 -> 45.822157
B14: 8 | C14: Other income/(cost) | D14: =Cifras_Originales!E10 -> 0.123 | E14: =Cifras_Originales!D10 -> 3.189 | F14: =Cifras_Originales!C10 -> 5.718 | G14: =Cifras_Originales!B10 -> 1.43 | H14: =AVERAGE(E14:G14)*(1+H6) -> 3.8012196 | I14: =AVERAGE(F14:H14)*(1+I6) -> 4.3066931 | J14: =AVERAGE(G14:I14)*(1+J6) -> 3.6879929 | K14: =AVERAGE(H14:J14)*(1+K6) -> 4.4824441 | L14: =AVERAGE(I14:K14)*(1+L6) -> 4.699719 | M14: =AVERAGE(J14:L14)*(1+M6) -> 4.7619577 | N14: =AVERAGE(K14:M14)*(1+N6) -> 5.1128443 | O14: =AVERAGE(L14:N14)*(1+O6) -> 5.2954093 | ... AF14: =AVERAGE(AC14:AE14)*(1+AF6) -> 7.9139693
B15: 9 | C15: Earnings before taxes | D15: =D9+D13+D14 -> 206.25538 | E15: =E9+E13+E14 -> 279.50802 | F15: =F9+F13+F14 -> 257.7637 | G15: =G9+G13+G14 -> 232.37608 | H15: =H9+H13+H14 -> 293.05864 | I15: =I9+I13+I14 -> 346.26446 | J15: =J9+J13+J14 -> 401.00696 | K15: =K9+K13+K14 -> 451.99177 | ... AF15: =AF9+AF13+AF14 -> 1640.8037
B16: 10 | C16: (Income tax) | D16: -49.4 | E16: -55.808 | F16: -26.484 | G16: -56.061 | H16: =(-1*$D$53)*H15 -> -58.611728 | I16: =(-1*$D$53)*I15 -> -69.252891 | J16: =(-1*$D$53)*J15 -> -80.201392 | K16: =(-1*$D$53)*K15 -> -90.398353 | L16: =(-1*$E$53)*L15 -> -102.45712 | M16: =(-1*$E$53)*M15 -> -114.65004 | N16: =(-1*$E$53)*N15 -> -126.42354 | O16: =(-1*$E$53)*O15 -> -138.15347 | P16: =(-1*$E$53)*P15 -> -149.78274 | Q16: =(-1*$E$53)*Q15 -> -160.27469 | R16: =(-1*$E$53)*R15 -> -171.53915 | S16: =(-1*$E$53)*S15 -> -183.51858 | ... V16: =(-1*$E$53)*V15 -> -216.85433 | W16: =(-1*$F$53)*W15 -> -229.25339 | X16: =(-1*$F$53)*X15 -> -240.97742 | Y16: =(-1*$F$53)*Y15 -> -253.33907 | Z16: =(-1*$F$53)*Z15 -> -263.88539 | AA16: =(-1*$F$53)*AA15 -> -274.95837 | AB16: =(-1*$F$53)*AB15 -> -286.48185 | AC16: =(-1*$F$53)*AC15 -> -298.48601 | AD16: =(-1*$F$53)*AD15 -> -308.06801 | ... AF16: =(-1*$F$53)*AF15 -> -328.16075
B17: 11 | C17: Net income | D17: =D15+D16 -> 156.85538 | E17: =E15+E16 -> 223.70002 | F17: =F15+F16 -> 231.2797 | G17: =G15+G16 -> 176.31508 | H17: =H15+H16 -> 234.44691 | I17: =I15+I16 -> 277.01156 | J17: =J15+J16 -> 320.80557 | K17: =K15+K16 -> 361.59341 | ... AF17: =AF15+AF16 -> 1312.643
A19: CASH FLOW STATEMENT | B19: 12 | C19: Operating cash flows before WK | D19: =155.801+30.535+0.935-3.827+1.051+1.064-0.074 -> 185.485 | E19: =212.602+32.07+0.679+5.147+2.473+1.022 -> 253.993 | F19: =89.693+39.847+0.601-0.403+1.229+97.176+2.039 -> 230.182 | G19: =169.885+46.434+0.604+25.561+2.927+0.33+1.895-6.163 -> 241.473 | H19: =H12+H13+H14+H16 -> 282.57891 | I19: =I12+I13+I14+I16 -> 321.08627 | J19: =J12+J13+J14+J16 -> 363.40138 | K19: =K12+K13+K14+K16 -> 405.59571 | L19: =L12+L13+L14+L16 -> 457.67478 | M19: =M12+M13+M14+M16 -> 511.43533 | N19: =N12+N13+N14+N16 -> 567.80494 | O19: =O12+O13+O14+O16 -> 627.34621 | ... AF19: =AF12+AF13+AF14+AF16 -> 1712.3365
B20: 13 | C20: (Stock-based compensation) | D20: 9.009 | E20: 15.474 | F20: 17.799 | G20: 29.8 | H20: =-H11 -> 40.719 | I20: =-I11 -> 43.185003 | J20: =-J11 -> 50.094603 | K20: =-K11 -> 57.107848 | L20: =-L11 -> 64.531868 | M20: =-M11 -> 35.815187 | N20: =-N11 -> 39.396705 | O20: =-O11 -> 42.942409 | ... AF20: =-AF11 -> 148.78759
B21: 14 | C21: (Working Capital Flows) | D21: =16.353+46.052+1.982+89.125+14.943+3.478 -> 171.933 | E21: =-44.681-179.803-10.587+112.773-3.781+3.132 -> -122.947 | F21: =30.448-91.624-2.187-86.242+0.439+2.079 -> -147.087 | G21: =-15.683+33.675-7.933-15.144+18.156+1.598 -> 14.669 | H21: -16.692 | I21: =$D$57*(I7-H7) -> -98.813142 | J21: =$D$57*(J7-I7) -> -103.64401 | K21: =$D$57*(K7-J7) -> -105.19867 | L21: =$E$57*(L7-K7) -> -92.800253 | M21: =$E$57*(M7-L7) -> -88.731318 | N21: =$E$57*(N7-M7) -> -89.537967 | O21: =$E$57*(O7-N7) -> -88.642587 | P21: =$E$57*(P7-O7) -> -85.884818 | Q21: =$E$57*(Q7-P7) -> -81.161153 | R21: =$E$57*(R7-Q7) -> -86.842433 | S21: =$E$57*(S7-R7) -> -92.921404 | ... V21: =$E$57*(V7-U7) -> -79.796388 | W21: =$F$57*(W7-V7) -> -67.028966 | X21: =$F$57*(X7-W7) -> -70.380414 | Y21: =$F$57*(Y7-X7) -> -73.899435 | Z21: =$F$57*(Z7-Y7) -> -62.075525 | AA21: =$F$57*(AA7-Z7) -> -64.558547 | AB21: =$F$57*(AB7-AA7) -> -67.140888 | AC21: =$F$57*(AC7-AB7) -> -69.826524 | AD21: =$F$57*(AD7-AC7) -> -54.464689 | ... AF21: =$F$57*(AF7-AE7) -> -57.781588
B22: 15 | C22: -Total Operating Cash Flow | D22: =D19+D20+D21 -> 366.427 | E22: =E19+E20+E21 -> 146.52 | F22: =F19+F20+F21 -> 100.894 | G22: =G19+G20+G21 -> 285.942 | H22: =H19+H20+H21 -> 306.60591 | I22: =I19+I20+I21 -> 265.45814 | J22: =J19+J20+J21 -> 309.85198 | K22: =K19+K20+K21 -> 357.50489 | ... AF22: =AF19+AF20+AF21 -> 1803.3425
B23: 16 | C23: (CAPEX and Acquisitions) | D23: =Cifras_Originales!E13 -> -15.566 | E23: =Cifras_Originales!D13 -> -56.121 | F23: =Cifras_Originales!C13 -> -45.929 | G23: =Cifras_Originales!B13 -> -50.672 | H23: =-41.832-36.164 -> -77.996 | I23: =-$D$58*I7 -> -86.370006 | J23: =-$D$58*J7 -> -100.18921 | K23: =-$D$58*K7 -> -114.2157 | L23: =-$D$58*L7 -> -129.06374 | M23: =-$E$58*M7 -> -214.89112 | N23: =-$E$58*N7 -> -236.38023 | O23: =-$E$58*O7 -> -257.65445 | P23: =-$E$58*P7 -> -278.26681 | Q23: =-$E$58*Q7 -> -297.74549 | R23: =-$E$58*R7 -> -318.58767 | S23: =-$E$58*S7 -> -340.88881 | T23: =-$E$58*T7 -> -361.34214 | ... V23: =-$E$58*V7 -> -402.1738 | W23: =-$F$58*W7 -> -563.04332 | X23: =-$F$58*X7 -> -591.19548 | Y23: =-$F$58*Y7 -> -620.75525 | Z23: =-$F$58*Z7 -> -645.58547 | AA23: =-$F$58*AA7 -> -671.40888 | AB23: =-$F$58*AB7 -> -698.26524 | AC23: =-$F$58*AC7 -> -726.19585 | AD23: =-$F$58*AD7 -> -747.98172 | ... AF23: =-$F$58*AF7 -> -793.53381
B24: 17 | C24: (Other investing flows) | D24: -7.378 | E24: -9.635 | F24: -10.981 | G24: -22.152 | H24: -53.452 | I24: =(1+I6)*AVERAGE(F24:H24) -> -34.056767 | J24: =(1+J6)*AVERAGE(G24:I24) -> -42.402163 | K24: =(1+K6)*AVERAGE(H24:J24) -> -49.366153 | L24: =(1+L6)*AVERAGE(I24:K24) -> -47.394115 | M24: =(1+M6)*AVERAGE(J24:L24) -> -51.490099 | N24: =(1+N6)*AVERAGE(K24:M24) -> -54.358468 | O24: =(1+O6)*AVERAGE(L24:N24) -> -55.678175 | P24: =(1+P6)*AVERAGE(M24:O24) -> -58.149627 | ... AF24: =(1+AF6)*AVERAGE(AC24:AE24) -> -83.894545
B25: 18 | C25: -Total Investing Flows | D25: =D23+D24 -> -22.944 | E25: =E23+E24 -> -65.756 | F25: =F23+F24 -> -56.91 | G25: =G23+G24 -> -72.824 | H25: 131.448 | I25: =I23+I24 -> -120.42677 | J25: =J23+J24 -> -142.59137 | K25: =K23+K24 -> -163.58185 | L25: =L23+L24 -> -176.45785 | M25: =M23+M24 -> -266.38122 | N25: =N23+N24 -> -290.7387 | O25: =O23+O24 -> -313.33263 | P25: =P23+P24 -> -336.41644 | ... AF25: =AF23+AF24 -> -877.42836
B26: 19 | C26: (Flows related to leases) | D26: -0.185 | E26: -1.108 | F26: -2.063 | G26: -2.13 | H26: 0 | I26: 0 | J26: -300 | K26: 0 | L26: 0 | M26: 0 | N26: 0 | O26: 0 | P26: 0 | Q26: 0 | R26: 0 | S26: 0 | T26: 0 | U26: 0 | V26: 0 | W26: 0 | X26: 0 | Y26: 0 | Z26: 0 | AA26: 0 | AB26: 0 | AC26: 0 | AD26: 0 | AE26: 0 | AF26: 0
B27: 20 | C27: Flows related to debt | D27: -165 | E27: -22.5 | F27: -22.5 | G27: -7.734 | H27: -4.219 | I27: =(I38-H38) -> -4.22 | J27: =(J38-I38) -> 295.78 | K27: =(K38-J38) -> -34.22 | L27: =(L38-K38) -> -115.39 | M27: =(M38-L38) -> -50 | N27: =(N38-M38) -> -90 | O27: =(O38-N38) -> -178.063 | P27: =(P38-O38) -> 0.003 | ... AF27: =(AF38-AE38) -> 0
B28: 21 | C28: (Respurchases)/Issuance of stock | D28: 0 | E28: 0 | F28: -100 | G28: 0 | H28: -200 | I28: -250 | J28: -300 | K28: -200 | L28: -150 | M28: -100 | N28: -150 | O28: -200 | P28: -250 | Q28: -250 | R28: -150 | S28: -100 | T28: -75 | U28: -75 | V28: -50 | W28: -50 | X28: -50 | Y28: -50 | Z28: -50 | AA28: -50 | AB28: -50 | AC28: -50 | AD28: -50 | AE28: -50 | AF28: -50
B29: 22 | C29: (Dividends) | D29: 0 | E29: 0 | F29: 0 | G29: 0 | H29: 0 | I29: 0 | J29: 0 | K29: 0 | L29: 0 | M29: 0 | N29: 0 | O29: 0 | P29: 0 | Q29: 0 | R29: -200 | S29: -200 | T29: -200 | U29: -220 | V29: -220 | W29: -250 | X29: -250 | Y29: -250 | Z29: -250 | AA29: -280 | AB29: -300 | AC29: -320 | AD29: -350 | AE29: -380 | AF29: -400
B30: 23 | C30: Other financing flows | D30: =3.022-1.028+50-50 -> 1.994 | E30: =4.095-3.506-0 -> 0.589 | F30: =3.821-1.861-0 -> 1.96 | G30: =1.573-2.481-2.824 -> -3.732 | H30: =-1.169 -> -1.169 | I30: =(1+I6)*(AVERAGE(E30:F30,H30)) -> 0.5428 | J30: =(1+J6)*AVERAGE(F30,H30:I30) -> 0.515736 | K30: =(1+K6)*AVERAGE(H30:J30) -> -0.04197632 | L30: =(1+L6)*AVERAGE(I30:K30) -> 0.38290415 | M30: =(1+M6)*AVERAGE(J30:L30) -> 0.31696562 | N30: =(1+N6)*AVERAGE(K30:M30) -> 0.2412276 | O30: =(1+O6)*AVERAGE(L30:N30) -> 0.34193204 | P30: =(1+P6)*AVERAGE(M30:O30) -> 0.32404509 | Q30: =(1+Q6)*AVERAGE(N30:P30) -> 0.32356969 | R30: =(1+R6)*AVERAGE(O30:Q30) -> 0.35293836 | ... AF30: =(1+AF6)*AVERAGE(AC30:AE30) -> 0.46766331
B31: 24 | C31: -Total Financing flows | D31: =SUM(D26:D30) -> -163.191 | E31: =SUM(E26:E30) -> -23.019 | F31: =SUM(F26:F30) -> -122.603 | G31: =SUM(G26:G30) -> -13.596 | H31: =SUM(H26:H30) -> -205.388 | I31: =SUM(I26:I30) -> -253.6772 | J31: =SUM(J26:J30) -> -303.70426 | K31: =SUM(K26:K30) -> -234.26198 | ... AF31: =SUM(AF26:AF30) -> -449.53234
A33: SUMMARY | B33: 25 | C33: Cash before shareholder returns | D33: =D22+D25+D26+D27+D30 -> 180.292 | E33: =E22+E25+E26+E27+E30 -> 57.745 | F33: =F22+F25+F26+F27+F30 -> 21.381 | G33: =G22+G25+G26+G27+G30 -> 199.522 | H33: =H22+H25+H26+H27+H30 -> 432.66591 | I33: =I22+I25+I26+I27+I30 -> 141.35416 | J33: =J22+J25+J26+J27+J30 -> 163.55634 | K33: =K22+K25+K26+K27+K30 -> 159.66106 | ... AF33: =AF22+AF25+AF26+AF27+AF30 -> 926.38177
B34: 26 | C34: Returns to shareholders | D34: =-1*(D28+D29) -> 0 | E34: =-1*(E28+E29) -> 0 | F34: =-1*(F28+F29) -> 100 | G34: =-1*(G28+G29) -> 0 | H34: =-1*(H28+H29) -> 200 | I34: =-1*(I28+I29) -> 250 | J34: =-1*(J28+J29) -> 300 | K34: =-1*(K28+K29) -> 200 | ... AF34: =-1*(AF28+AF29) -> 450
B35: 27 | C35: Excess cash acumulation | D35: =D33-D34 -> 180.292 | E35: =E33-E34 -> 57.745 | F35: =F33-F34 -> -78.619 | G35: =G33-G34 -> 199.522 | H35: =H33-H34 -> 232.66591 | I35: =I33-I34 -> -108.64584 | J35: =J33-J34 -> -136.44366 | K35: =K33-K34 -> -40.338938 | ... AF35: =AF33-AF34 -> 476.38177
